{"ts_recv":"2026-04-07T01:06:15.391262436Z","hd":{"ts_event":"2026-04-07T01:06:15.391246685Z","rtype":160,"publisher_id":101,"instrument_id":436},"action":"C","side":"A","price":"1.157700000","size":20,"channel_id":23,"order_id":"1775523952809966619","flags":128,"ts_in_delta":1595,"sequence":114442,"symbol":"FCEU SI 20260615 PS"}
{"ts_recv":"2026-04-07T01:06:15.434866236Z","hd":{"ts_event":"2026-04-07T01:06:15.434851021Z","rtype":160,"publisher_id":101,"instrument_id":436},"action":"A","side":"A","price":"1.157800000","size":20,"channel_id":23,"order_id":"1775523975434857374","flags":128,"ts_in_delta":1214,"sequence":114446,"symbol":"FCEU SI 20260615 PS"}
{"ts_recv":"2026-04-07T01:06:21.392373515Z","hd":{"ts_event":"2026-04-07T01:06:21.392350447Z","rtype":160,"publisher_id":101,"instrument_id":436},"action":"C","side":"B","price":"1.157400000","size":20,"channel_id":23,"order_id":"10998896012154149638","flags":128,"ts_in_delta":1363,"sequence":114505,"symbol":"FCEU SI 20260615 PS"}
{"ts_recv":"2026-04-07T01:06:21.435704959Z","hd":{"ts_event":"2026-04-07T01:06:21.435683551Z","rtype":160,"publisher_id":101,"instrument_id":436},"action":"A","side":"B","price":"1.157300000","size":20,"channel_id":23,"order_id":"10998896018290470478","flags":128,"ts_in_delta":866,"sequence":114506,"symbol":"FCEU SI 20260615 PS"}
{"ts_recv":"2026-04-07T01:06:22.092117112Z","hd":{"ts_event":"2026-04-07T01:06:22.092098681Z","rtype":160,"publisher_id":101,"instrument_id":436},"action":"A","side":"B","price":"1.157400000","size":20,"channel_id":23,"order_id":"10998896018946883097","flags":128,"ts_in_delta":1427,"sequence":114509,"symbol":"FCEU SI 20260615 PS"}
{"ts_recv":"2026-04-07T01:06:22.092125813Z","hd":{"ts_event":"2026-04-07T01:06:22.092114827Z","rtype":160,"publisher_id":101,"instrument_id":436},"action":"C","side":"B","price":"1.157300000","size":20,"channel_id":23,"order_id":"10998896018290470478","flags":128,"ts_in_delta":851,"sequence":114510,"symbol":"FCEU SI 20260615 PS"}
{"ts_recv":"2026-04-07T01:06:27.091847436Z","hd":{"ts_event":"2026-04-07T01:06:27.091825205Z","rtype":160,"publisher_id":101,"instrument_id":436},"action":"C","side":"B","price":"1.157400000","size":20,"channel_id":23,"order_id":"10998896018946883097","flags":128,"ts_in_delta":903,"sequence":114544,"symbol":"FCEU SI 20260615 PS"}
{"ts_recv":"2026-04-07T01:06:27.134180600Z","hd":{"ts_event":"2026-04-07T01:06:27.134164461Z","rtype":160,"publisher_id":101,"instrument_id":436},"action":"A","side":"B","price":"1.157300000","size":20,"channel_id":23,"order_id":"10998896023988946593","flags":128,"ts_in_delta":1074,"sequence":114545,"symbol":"FCEU SI 20260615 PS"}
{"ts_recv":"2026-04-07T01:06:35.039198711Z","hd":{"ts_event":"2026-04-07T01:06:35.039177683Z","rtype":160,"publisher_id":101,"instrument_id":436},"action":"A","side":"B","price":"1.157400000","size":20,"channel_id":23,"order_id":"10998896031893964812","flags":128,"ts_in_delta":827,"sequence":114592,"symbol":"FCEU SI 20260615 PS"}
{"ts_recv":"2026-04-07T01:06:35.039216259Z","hd":{"ts_event":"2026-04-07T01:06:35.039203603Z","rtype":160,"publisher_id":101,"instrument_id":436},"action":"C","side":"B","price":"1.157300000","size":20,"channel_id":23,"order_id":"10998896023988946593","flags":128,"ts_in_delta":811,"sequence":114593,"symbol":"FCEU SI 20260615 PS"}
{"ts_recv":"2026-04-07T01:06:46.917266812Z","hd":{"ts_event":"2026-04-07T01:06:46.917252975Z","rtype":160,"publisher_id":101,"instrument_id":436},"action":"C","side":"B","price":"1.157400000","size":20,"channel_id":23,"order_id":"10998896031893964812","flags":128,"ts_in_delta":1021,"sequence":114684,"symbol":"FCEU SI 20260615 PS"}
{"ts_recv":"2026-04-07T01:06:46.960218607Z","hd":{"ts_event":"2026-04-07T01:06:46.960205585Z","rtype":160,"publisher_id":101,"instrument_id":436},"action":"A","side":"B","price":"1.157300000","size":20,"channel_id":23,"order_id":"10998896043814987446","flags":128,"ts_in_delta":859,"sequence":114689,"symbol":"FCEU SI 20260615 PS"}
{"ts_recv":"2026-04-07T01:06:48.289634863Z","hd":{"ts_event":"2026-04-07T01:06:48.289612199Z","rtype":160,"publisher_id":101,"instrument_id":436},"action":"A","side":"B","price":"1.157400000","size":20,"channel_id":23,"order_id":"10998896045144399082","flags":128,"ts_in_delta":1130,"sequence":114705,"symbol":"FCEU SI 20260615 PS"}
{"ts_recv":"2026-04-07T01:06:48.289645446Z","hd":{"ts_event":"2026-04-07T01:06:48.289632103Z","rtype":160,"publisher_id":101,"instrument_id":436},"action":"C","side":"B","price":"1.157300000","size":20,"channel_id":23,"order_id":"10998896043814987446","flags":128,"ts_in_delta":835,"sequence":114706,"symbol":"FCEU SI 20260615 PS"}
{"ts_recv":"2026-04-07T01:06:55.580869117Z","hd":{"ts_event":"2026-04-07T01:06:55.580847053Z","rtype":160,"publisher_id":101,"instrument_id":436},"action":"C","side":"B","price":"1.157400000","size":20,"channel_id":23,"order_id":"10998896045144399082","flags":128,"ts_in_delta":1434,"sequence":114754,"symbol":"FCEU SI 20260615 PS"}
{"ts_recv":"2026-04-07T01:06:55.624169051Z","hd":{"ts_event":"2026-04-07T01:06:55.624154389Z","rtype":160,"publisher_id":101,"instrument_id":436},"action":"A","side":"B","price":"1.157300000","size":20,"channel_id":23,"order_id":"10998896052478936352","flags":128,"ts_in_delta":650,"sequence":114757,"symbol":"FCEU SI 20260615 PS"}
{"ts_recv":"2026-04-07T01:07:22.438339769Z","hd":{"ts_event":"2026-04-07T01:07:22.438323727Z","rtype":160,"publisher_id":101,"instrument_id":436},"action":"A","side":"B","price":"1.157400000","size":20,"channel_id":23,"order_id":"10998896079293105487","flags":128,"ts_in_delta":899,"sequence":114948,"symbol":"FCEU SI 20260615 PS"}
{"ts_recv":"2026-04-07T01:07:22.438386922Z","hd":{"ts_event":"2026-04-07T01:07:22.438374271Z","rtype":160,"publisher_id":101,"instrument_id":436},"action":"C","side":"B","price":"1.157300000","size":20,"channel_id":23,"order_id":"10998896052478936352","flags":128,"ts_in_delta":691,"sequence":114950,"symbol":"FCEU SI 20260615 PS"}
{"ts_recv":"2026-04-07T01:07:40.874106091Z","hd":{"ts_event":"2026-04-07T01:07:40.874090409Z","rtype":160,"publisher_id":101,"instrument_id":436},"action":"C","side":"A","price":"1.157800000","size":20,"channel_id":23,"order_id":"1775523975434857374","flags":128,"ts_in_delta":653,"sequence":115089,"symbol":"FCEU SI 20260615 PS"}
{"ts_recv":"2026-04-07T01:07:40.917169110Z","hd":{"ts_event":"2026-04-07T01:07:40.917152281Z","rtype":160,"publisher_id":101,"instrument_id":436},"action":"A","side":"A","price":"1.157900000","size":20,"channel_id":23,"order_id":"1775524060917158159","flags":128,"ts_in_delta":1155,"sequence":115096,"symbol":"FCEU SI 20260615 PS"}
{"ts_recv":"2026-04-07T01:07:41.422175204Z","hd":{"ts_event":"2026-04-07T01:07:41.422160173Z","rtype":160,"publisher_id":101,"instrument_id":436},"action":"A","side":"B","price":"1.157500000","size":20,"channel_id":23,"order_id":"10998896098276941767","flags":128,"ts_in_delta":858,"sequence":115109,"symbol":"FCEU SI 20260615 PS"}
{"ts_recv":"2026-04-07T01:07:41.422238200Z","hd":{"ts_event":"2026-04-07T01:07:41.422224313Z","rtype":160,"publisher_id":101,"instrument_id":436},"action":"C","side":"B","price":"1.157400000","size":20,"channel_id":23,"order_id":"10998896079293105487","flags":128,"ts_in_delta":863,"sequence":115110,"symbol":"FCEU SI 20260615 PS"}
{"ts_recv":"2026-04-07T01:07:46.421641325Z","hd":{"ts_event":"2026-04-07T01:07:46.421617591Z","rtype":160,"publisher_id":101,"instrument_id":436},"action":"C","side":"B","price":"1.157500000","size":20,"channel_id":23,"order_id":"10998896098276941767","flags":128,"ts_in_delta":1269,"sequence":115144,"symbol":"FCEU SI 20260615 PS"}
{"ts_recv":"2026-04-07T01:07:46.464101384Z","hd":{"ts_event":"2026-04-07T01:07:46.464086819Z","rtype":160,"publisher_id":101,"instrument_id":436},"action":"A","side":"B","price":"1.157400000","size":20,"channel_id":23,"order_id":"10998896103318868774","flags":128,"ts_in_delta":876,"sequence":115145,"symbol":"FCEU SI 20260615 PS"}
{"ts_recv":"2026-04-07T01:08:16.934223799Z","hd":{"ts_event":"2026-04-07T01:08:16.934198425Z","rtype":160,"publisher_id":101,"instrument_id":436},"action":"A","side":"A","price":"1.157800000","size":20,"channel_id":23,"order_id":"1775524096934209440","flags":128,"ts_in_delta":916,"sequence":115379,"symbol":"FCEU SI 20260615 PS"}
{"ts_recv":"2026-04-07T01:08:16.934244435Z","hd":{"ts_event":"2026-04-07T01:08:16.934230637Z","rtype":160,"publisher_id":101,"instrument_id":436},"action":"C","side":"A","price":"1.157900000","size":20,"channel_id":23,"order_id":"1775524060917158159","flags":128,"ts_in_delta":929,"sequence":115381,"symbol":"FCEU SI 20260615 PS"}
{"ts_recv":"2026-04-07T01:08:33.255320719Z","hd":{"ts_event":"2026-04-07T01:08:33.255307087Z","rtype":160,"publisher_id":101,"instrument_id":436},"action":"C","side":"B","price":"1.157400000","size":20,"channel_id":23,"order_id":"10998896103318868774","flags":128,"ts_in_delta":1126,"sequence":115502,"symbol":"FCEU SI 20260615 PS"}
{"ts_recv":"2026-04-07T01:08:33.298573048Z","hd":{"ts_event":"2026-04-07T01:08:33.298558619Z","rtype":160,"publisher_id":101,"instrument_id":436},"action":"A","side":"B","price":"1.157300000","size":20,"channel_id":23,"order_id":"10998896150153340395","flags":128,"ts_in_delta":839,"sequence":115509,"symbol":"FCEU SI 20260615 PS"}
{"ts_recv":"2026-04-07T01:08:44.194555221Z","hd":{"ts_event":"2026-04-07T01:08:44.194534429Z","rtype":160,"publisher_id":101,"instrument_id":436},"action":"A","side":"A","price":"1.157700000","size":20,"channel_id":23,"order_id":"1775524124194544982","flags":128,"ts_in_delta":860,"sequence":115661,"symbol":"FCEU SI 20260615 PS"}
{"ts_recv":"2026-04-07T01:08:44.195064911Z","hd":{"ts_event":"2026-04-07T01:08:44.195051059Z","rtype":160,"publisher_id":101,"instrument_id":436},"action":"C","side":"A","price":"1.157800000","size":20,"channel_id":23,"order_id":"1775524096934209440","flags":128,"ts_in_delta":900,"sequence":115662,"symbol":"FCEU SI 20260615 PS"}
{"ts_recv":"2026-04-07T01:09:16.999547490Z","hd":{"ts_event":"2026-04-07T01:09:16.999529537Z","rtype":160,"publisher_id":101,"instrument_id":436},"action":"A","side":"B","price":"1.157400000","size":20,"channel_id":23,"order_id":"10998896193854311841","flags":128,"ts_in_delta":866,"sequence":115889,"symbol":"FCEU SI 20260615 PS"}
{"ts_recv":"2026-04-07T01:09:16.999586503Z","hd":{"ts_event":"2026-04-07T01:09:16.999573097Z","rtype":160,"publisher_id":101,"instrument_id":436},"action":"C","side":"B","price":"1.157300000","size":20,"channel_id":23,"order_id":"10998896150153340395","flags":128,"ts_in_delta":856,"sequence":115891,"symbol":"FCEU SI 20260615 PS"}
{"ts_recv":"2026-04-07T01:09:21.446997714Z","hd":{"ts_event":"2026-04-07T01:09:21.446984703Z","rtype":160,"publisher_id":101,"instrument_id":436},"action":"C","side":"A","price":"1.157700000","size":20,"channel_id":23,"order_id":"1775524124194544982","flags":128,"ts_in_delta":839,"sequence":115914,"symbol":"FCEU SI 20260615 PS"}
{"ts_recv":"2026-04-07T01:09:21.489782793Z","hd":{"ts_event":"2026-04-07T01:09:21.489767805Z","rtype":160,"publisher_id":101,"instrument_id":436},"action":"A","side":"A","price":"1.157800000","size":20,"channel_id":23,"order_id":"1775524161489774143","flags":128,"ts_in_delta":828,"sequence":115916,"symbol":"FCEU SI 20260615 PS"}
{"ts_recv":"2026-04-07T01:09:32.090723224Z","hd":{"ts_event":"2026-04-07T01:09:32.090702699Z","rtype":160,"publisher_id":101,"instrument_id":436},"action":"C","side":"B","price":"1.157400000","size":20,"channel_id":23,"order_id":"10998896193854311841","flags":128,"ts_in_delta":921,"sequence":115977,"symbol":"FCEU SI 20260615 PS"}
{"ts_recv":"2026-04-07T01:09:32.133132504Z","hd":{"ts_event":"2026-04-07T01:09:32.133116735Z","rtype":160,"publisher_id":101,"instrument_id":436},"action":"A","side":"B","price":"1.157300000","size":20,"channel_id":23,"order_id":"10998896208987898598","flags":128,"ts_in_delta":1037,"sequence":115989,"symbol":"FCEU SI 20260615 PS"}
{"ts_recv":"2026-04-07T01:09:32.726343246Z","hd":{"ts_event":"2026-04-07T01:09:32.726315295Z","rtype":160,"publisher_id":101,"instrument_id":436},"action":"A","side":"A","price":"1.157700000","size":20,"channel_id":23,"order_id":"1775524172726328937","flags":128,"ts_in_delta":1231,"sequence":115999,"symbol":"FCEU SI 20260615 PS"}
{"ts_recv":"2026-04-07T01:09:32.726346878Z","hd":{"ts_event":"2026-04-07T01:09:32.726327283Z","rtype":160,"publisher_id":101,"instrument_id":436},"action":"C","side":"A","price":"1.157800000","size":20,"channel_id":23,"order_id":"1775524161489774143","flags":128,"ts_in_delta":1004,"sequence":116000,"symbol":"FCEU SI 20260615 PS"}
{"ts_recv":"2026-04-07T01:09:39.420609411Z","hd":{"ts_event":"2026-04-07T01:09:39.420595997Z","rtype":160,"publisher_id":101,"instrument_id":436},"action":"C","side":"B","price":"1.157300000","size":20,"channel_id":23,"order_id":"10998896208987898598","flags":128,"ts_in_delta":844,"sequence":116114,"symbol":"FCEU SI 20260615 PS"}
{"ts_recv":"2026-04-07T01:09:39.463552670Z","hd":{"ts_event":"2026-04-07T01:09:39.463535737Z","rtype":160,"publisher_id":101,"instrument_id":436},"action":"A","side":"B","price":"1.157200000","size":20,"channel_id":23,"order_id":"10998896216318317689","flags":128,"ts_in_delta":1343,"sequence":116119,"symbol":"FCEU SI 20260615 PS"}
{"ts_recv":"2026-04-07T01:09:44.269812202Z","hd":{"ts_event":"2026-04-07T01:09:44.269797603Z","rtype":160,"publisher_id":101,"instrument_id":436},"action":"A","side":"A","price":"1.157600000","size":20,"channel_id":23,"order_id":"1775524184269803547","flags":128,"ts_in_delta":804,"sequence":116195,"symbol":"FCEU SI 20260615 PS"}
{"ts_recv":"2026-04-07T01:09:44.269951395Z","hd":{"ts_event":"2026-04-07T01:09:44.269940969Z","rtype":160,"publisher_id":101,"instrument_id":436},"action":"C","side":"A","price":"1.157700000","size":20,"channel_id":23,"order_id":"1775524172726328937","flags":128,"ts_in_delta":817,"sequence":116196,"symbol":"FCEU SI 20260615 PS"}
{"ts_recv":"2026-04-07T01:09:48.333695752Z","hd":{"ts_event":"2026-04-07T01:09:48.333681731Z","rtype":160,"publisher_id":101,"instrument_id":436},"action":"C","side":"B","price":"1.157200000","size":20,"channel_id":23,"order_id":"10998896216318317689","flags":128,"ts_in_delta":1284,"sequence":116254,"symbol":"FCEU SI 20260615 PS"}
{"ts_recv":"2026-04-07T01:09:48.376884595Z","hd":{"ts_event":"2026-04-07T01:09:48.376868155Z","rtype":160,"publisher_id":101,"instrument_id":436},"action":"A","side":"B","price":"1.157100000","size":20,"channel_id":23,"order_id":"10998896225231650233","flags":128,"ts_in_delta":1074,"sequence":116258,"symbol":"FCEU SI 20260615 PS"}
{"ts_recv":"2026-04-07T01:09:56.643962947Z","hd":{"ts_event":"2026-04-07T01:09:56.643947651Z","rtype":160,"publisher_id":101,"instrument_id":436},"action":"A","side":"A","price":"1.157500000","size":20,"channel_id":23,"order_id":"1775524196643953648","flags":128,"ts_in_delta":979,"sequence":116388,"symbol":"FCEU SI 20260615 PS"}
{"ts_recv":"2026-04-07T01:09:56.644024384Z","hd":{"ts_event":"2026-04-07T01:09:56.644011177Z","rtype":160,"publisher_id":101,"instrument_id":436},"action":"C","side":"A","price":"1.157600000","size":20,"channel_id":23,"order_id":"1775524184269803547","flags":128,"ts_in_delta":822,"sequence":116390,"symbol":"FCEU SI 20260615 PS"}
{"ts_recv":"2026-04-07T01:10:00.847167703Z","hd":{"ts_event":"2026-04-07T01:10:00.847153097Z","rtype":160,"publisher_id":101,"instrument_id":436},"action":"A","side":"B","price":"1.157200000","size":20,"channel_id":23,"order_id":"10998896237701934966","flags":128,"ts_in_delta":901,"sequence":116442,"symbol":"FCEU SI 20260615 PS"}
{"ts_recv":"2026-04-07T01:10:00.847213574Z","hd":{"ts_event":"2026-04-07T01:10:00.847202671Z","rtype":160,"publisher_id":101,"instrument_id":436},"action":"C","side":"B","price":"1.157100000","size":20,"channel_id":23,"order_id":"10998896225231650233","flags":128,"ts_in_delta":911,"sequence":116444,"symbol":"FCEU SI 20260615 PS"}
{"ts_recv":"2026-04-07T01:10:05.847092895Z","hd":{"ts_event":"2026-04-07T01:10:05.847077825Z","rtype":160,"publisher_id":101,"instrument_id":436},"action":"C","side":"B","price":"1.157200000","size":20,"channel_id":23,"order_id":"10998896237701934966","flags":128,"ts_in_delta":819,"sequence":116506,"symbol":"FCEU SI 20260615 PS"}
{"ts_recv":"2026-04-07T01:10:05.889662542Z","hd":{"ts_event":"2026-04-07T01:10:05.889642151Z","rtype":160,"publisher_id":101,"instrument_id":436},"action":"A","side":"B","price":"1.157100000","size":20,"channel_id":23,"order_id":"10998896242744428631","flags":128,"ts_in_delta":1020,"sequence":116507,"symbol":"FCEU SI 20260615 PS"}
{"ts_recv":"2026-04-07T01:10:34.193444581Z","hd":{"ts_event":"2026-04-07T01:10:34.193431247Z","rtype":160,"publisher_id":101,"instrument_id":436},"action":"C","side":"B","price":"1.157100000","size":20,"channel_id":23,"order_id":"10998896242744428631","flags":128,"ts_in_delta":918,"sequence":116753,"symbol":"FCEU SI 20260615 PS"}
{"ts_recv":"2026-04-07T01:10:34.238091383Z","hd":{"ts_event":"2026-04-07T01:10:34.238074795Z","rtype":160,"publisher_id":101,"instrument_id":436},"action":"A","side":"B","price":"1.157100000","size":20,"channel_id":23,"order_id":"10998896271092856587","flags":128,"ts_in_delta":1138,"sequence":116754,"symbol":"FCEU SI 20260615 PS"}
{"ts_recv":"2026-04-07T01:10:41.895165761Z","hd":{"ts_event":"2026-04-07T01:10:41.895152243Z","rtype":160,"publisher_id":101,"instrument_id":436},"action":"C","side":"B","price":"1.157100000","size":20,"channel_id":23,"order_id":"10998896271092856587","flags":128,"ts_in_delta":908,"sequence":116822,"symbol":"FCEU SI 20260615 PS"}
{"ts_recv":"2026-04-07T01:10:41.974593455Z","hd":{"ts_event":"2026-04-07T01:10:41.974577979Z","rtype":160,"publisher_id":101,"instrument_id":436},"action":"A","side":"B","price":"1.157100000","size":20,"channel_id":23,"order_id":"10998896278829359771","flags":128,"ts_in_delta":829,"sequence":116827,"symbol":"FCEU SI 20260615 PS"}
{"ts_recv":"2026-04-07T01:10:48.229010995Z","hd":{"ts_event":"2026-04-07T01:10:48.228998181Z","rtype":160,"publisher_id":101,"instrument_id":436},"action":"C","side":"B","price":"1.157100000","size":20,"channel_id":23,"order_id":"10998896278829359771","flags":128,"ts_in_delta":912,"sequence":116906,"symbol":"FCEU SI 20260615 PS"}
{"ts_recv":"2026-04-07T01:10:48.510537424Z","hd":{"ts_event":"2026-04-07T01:10:48.510516977Z","rtype":160,"publisher_id":101,"instrument_id":436},"action":"A","side":"B","price":"1.157100000","size":20,"channel_id":23,"order_id":"10998896285365303775","flags":128,"ts_in_delta":1056,"sequence":116920,"symbol":"FCEU SI 20260615 PS"}
{"ts_recv":"2026-04-07T01:11:00.646397240Z","hd":{"ts_event":"2026-04-07T01:11:00.646374801Z","rtype":160,"publisher_id":101,"instrument_id":436},"action":"A","side":"B","price":"1.157200000","size":20,"channel_id":23,"order_id":"10998896297501161397","flags":128,"ts_in_delta":1120,"sequence":117140,"symbol":"FCEU SI 20260615 PS"}
{"ts_recv":"2026-04-07T01:11:00.646408275Z","hd":{"ts_event":"2026-04-07T01:11:00.646395325Z","rtype":160,"publisher_id":101,"instrument_id":436},"action":"C","side":"B","price":"1.157100000","size":20,"channel_id":23,"order_id":"10998896285365303775","flags":128,"ts_in_delta":863,"sequence":117141,"symbol":"FCEU SI 20260615 PS"}
{"ts_recv":"2026-04-07T01:11:06.248346586Z","hd":{"ts_event":"2026-04-07T01:11:06.248333371Z","rtype":160,"publisher_id":101,"instrument_id":436},"action":"C","side":"B","price":"1.157200000","size":20,"channel_id":23,"order_id":"10998896297501161397","flags":128,"ts_in_delta":937,"sequence":117192,"symbol":"FCEU SI 20260615 PS"}
{"ts_recv":"2026-04-07T01:11:06.292103953Z","hd":{"ts_event":"2026-04-07T01:11:06.292078673Z","rtype":160,"publisher_id":101,"instrument_id":436},"action":"A","side":"B","price":"1.157100000","size":20,"channel_id":23,"order_id":"10998896303146866434","flags":128,"ts_in_delta":954,"sequence":117193,"symbol":"FCEU SI 20260615 PS"}
{"ts_recv":"2026-04-07T01:11:19.779701866Z","hd":{"ts_event":"2026-04-07T01:11:19.779687405Z","rtype":160,"publisher_id":101,"instrument_id":436},"action":"C","side":"A","price":"1.157500000","size":20,"channel_id":23,"order_id":"1775524196643953648","flags":128,"ts_in_delta":987,"sequence":117371,"symbol":"FCEU SI 20260615 PS"}
{"ts_recv":"2026-04-07T01:11:19.822162237Z","hd":{"ts_event":"2026-04-07T01:11:19.822147731Z","rtype":160,"publisher_id":101,"instrument_id":436},"action":"A","side":"A","price":"1.157600000","size":20,"channel_id":23,"order_id":"1775524279822153618","flags":128,"ts_in_delta":999,"sequence":117374,"symbol":"FCEU SI 20260615 PS"}
{"ts_recv":"2026-04-07T01:11:22.011577624Z","hd":{"ts_event":"2026-04-07T01:11:22.011554473Z","rtype":160,"publisher_id":101,"instrument_id":436},"action":"A","side":"B","price":"1.157200000","size":20,"channel_id":23,"order_id":"10998896318866341117","flags":128,"ts_in_delta":1142,"sequence":117402,"symbol":"FCEU SI 20260615 PS"}
{"ts_recv":"2026-04-07T01:11:22.011580665Z","hd":{"ts_event":"2026-04-07T01:11:22.011566377Z","rtype":160,"publisher_id":101,"instrument_id":436},"action":"C","side":"B","price":"1.157100000","size":20,"channel_id":23,"order_id":"10998896303146866434","flags":128,"ts_in_delta":805,"sequence":117403,"symbol":"FCEU SI 20260615 PS"}
{"ts_recv":"2026-04-07T01:11:27.010704365Z","hd":{"ts_event":"2026-04-07T01:11:27.010685119Z","rtype":160,"publisher_id":101,"instrument_id":436},"action":"C","side":"B","price":"1.157200000","size":20,"channel_id":23,"order_id":"10998896318866341117","flags":128,"ts_in_delta":1341,"sequence":117444,"symbol":"FCEU SI 20260615 PS"}
{"ts_recv":"2026-04-07T01:11:27.053166841Z","hd":{"ts_event":"2026-04-07T01:11:27.053145527Z","rtype":160,"publisher_id":101,"instrument_id":436},"action":"A","side":"B","price":"1.157100000","size":20,"channel_id":23,"order_id":"10998896323907932435","flags":128,"ts_in_delta":1589,"sequence":117445,"symbol":"FCEU SI 20260615 PS"}
{"ts_recv":"2026-04-07T01:11:30.837608070Z","hd":{"ts_event":"2026-04-07T01:11:30.837594013Z","rtype":160,"publisher_id":101,"instrument_id":436},"action":"A","side":"A","price":"1.157500000","size":20,"channel_id":23,"order_id":"1775524290837599997","flags":128,"ts_in_delta":648,"sequence":117478,"symbol":"FCEU SI 20260615 PS"}
{"ts_recv":"2026-04-07T01:11:30.837730239Z","hd":{"ts_event":"2026-04-07T01:11:30.837717885Z","rtype":160,"publisher_id":101,"instrument_id":436},"action":"C","side":"A","price":"1.157600000","size":20,"channel_id":23,"order_id":"1775524279822153618","flags":128,"ts_in_delta":667,"sequence":117480,"symbol":"FCEU SI 20260615 PS"}
{"ts_recv":"2026-04-07T01:11:41.499609195Z","hd":{"ts_event":"2026-04-07T01:11:41.499595315Z","rtype":160,"publisher_id":101,"instrument_id":436},"action":"C","side":"A","price":"1.157500000","size":20,"channel_id":23,"order_id":"1775524290837599997","flags":128,"ts_in_delta":863,"sequence":117588,"symbol":"FCEU SI 20260615 PS"}
{"ts_recv":"2026-04-07T01:11:41.543730230Z","hd":{"ts_event":"2026-04-07T01:11:41.543714245Z","rtype":160,"publisher_id":101,"instrument_id":436},"action":"A","side":"A","price":"1.157600000","size":20,"channel_id":23,"order_id":"1775524301543720293","flags":128,"ts_in_delta":1538,"sequence":117592,"symbol":"FCEU SI 20260615 PS"}
{"ts_recv":"2026-04-07T01:11:47.176288259Z","hd":{"ts_event":"2026-04-07T01:11:47.176273231Z","rtype":160,"publisher_id":101,"instrument_id":436},"action":"A","side":"B","price":"1.157200000","size":20,"channel_id":23,"order_id":"10998896344031054803","flags":128,"ts_in_delta":831,"sequence":117634,"symbol":"FCEU SI 20260615 PS"}
{"ts_recv":"2026-04-07T01:11:47.176335052Z","hd":{"ts_event":"2026-04-07T01:11:47.176320669Z","rtype":160,"publisher_id":101,"instrument_id":436},"action":"C","side":"B","price":"1.157100000","size":20,"channel_id":23,"order_id":"10998896323907932435","flags":128,"ts_in_delta":1002,"sequence":117636,"symbol":"FCEU SI 20260615 PS"}
{"ts_recv":"2026-04-07T01:11:52.175320208Z","hd":{"ts_event":"2026-04-07T01:11:52.175297381Z","rtype":160,"publisher_id":101,"instrument_id":436},"action":"C","side":"B","price":"1.157200000","size":20,"channel_id":23,"order_id":"10998896344031054803","flags":128,"ts_in_delta":1250,"sequence":117684,"symbol":"FCEU SI 20260615 PS"}
{"ts_recv":"2026-04-07T01:11:52.218441643Z","hd":{"ts_event":"2026-04-07T01:11:52.218421051Z","rtype":160,"publisher_id":101,"instrument_id":436},"action":"A","side":"B","price":"1.157100000","size":20,"channel_id":23,"order_id":"10998896349073207671","flags":128,"ts_in_delta":1349,"sequence":117685,"symbol":"FCEU SI 20260615 PS"}
{"ts_recv":"2026-04-07T01:12:05.250246936Z","hd":{"ts_event":"2026-04-07T01:12:05.250229371Z","rtype":160,"publisher_id":101,"instrument_id":436},"action":"A","side":"B","price":"1.157200000","size":20,"channel_id":23,"order_id":"10998896362105012935","flags":128,"ts_in_delta":1029,"sequence":117769,"symbol":"FCEU SI 20260615 PS"}
{"ts_recv":"2026-04-07T01:12:05.250263508Z","hd":{"ts_event":"2026-04-07T01:12:05.250250467Z","rtype":160,"publisher_id":101,"instrument_id":436},"action":"C","side":"B","price":"1.157100000","size":20,"channel_id":23,"order_id":"10998896349073207671","flags":128,"ts_in_delta":982,"sequence":117770,"symbol":"FCEU SI 20260615 PS"}
{"ts_recv":"2026-04-07T01:12:10.712317245Z","hd":{"ts_event":"2026-04-07T01:12:10.712304091Z","rtype":160,"publisher_id":101,"instrument_id":436},"action":"C","side":"B","price":"1.157200000","size":20,"channel_id":23,"order_id":"10998896362105012935","flags":128,"ts_in_delta":1310,"sequence":117822,"symbol":"FCEU SI 20260615 PS"}
{"ts_recv":"2026-04-07T01:12:10.754581748Z","hd":{"ts_event":"2026-04-07T01:12:10.754560129Z","rtype":160,"publisher_id":101,"instrument_id":436},"action":"A","side":"B","price":"1.157100000","size":20,"channel_id":23,"order_id":"10998896367609347085","flags":128,"ts_in_delta":1294,"sequence":117823,"symbol":"FCEU SI 20260615 PS"}
{"ts_recv":"2026-04-07T01:12:13.782336917Z","hd":{"ts_event":"2026-04-07T01:12:13.782323393Z","rtype":160,"publisher_id":101,"instrument_id":436},"action":"A","side":"B","price":"1.157200000","size":20,"channel_id":23,"order_id":"10998896370637104793","flags":128,"ts_in_delta":1020,"sequence":117865,"symbol":"FCEU SI 20260615 PS"}
{"ts_recv":"2026-04-07T01:12:13.782406810Z","hd":{"ts_event":"2026-04-07T01:12:13.782395449Z","rtype":160,"publisher_id":101,"instrument_id":436},"action":"C","side":"B","price":"1.157100000","size":20,"channel_id":23,"order_id":"10998896367609347085","flags":128,"ts_in_delta":1015,"sequence":117867,"symbol":"FCEU SI 20260615 PS"}
{"ts_recv":"2026-04-07T01:12:37.720519646Z","hd":{"ts_event":"2026-04-07T01:12:37.720505957Z","rtype":160,"publisher_id":101,"instrument_id":436},"action":"C","side":"B","price":"1.157200000","size":20,"channel_id":23,"order_id":"10998896370637104793","flags":128,"ts_in_delta":1002,"sequence":118046,"symbol":"FCEU SI 20260615 PS"}
{"ts_recv":"2026-04-07T01:12:37.764527817Z","hd":{"ts_event":"2026-04-07T01:12:37.764512139Z","rtype":160,"publisher_id":101,"instrument_id":436},"action":"A","side":"B","price":"1.157100000","size":20,"channel_id":23,"order_id":"10998896394619294469","flags":128,"ts_in_delta":1018,"sequence":118050,"symbol":"FCEU SI 20260615 PS"}
{"ts_recv":"2026-04-07T01:12:38.012898102Z","hd":{"ts_event":"2026-04-07T01:12:38.012883285Z","rtype":160,"publisher_id":101,"instrument_id":436},"action":"A","side":"B","price":"1.157200000","size":20,"channel_id":23,"order_id":"10998896394867665288","flags":128,"ts_in_delta":878,"sequence":118063,"symbol":"FCEU SI 20260615 PS"}
{"ts_recv":"2026-04-07T01:12:38.012917671Z","hd":{"ts_event":"2026-04-07T01:12:38.012906069Z","rtype":160,"publisher_id":101,"instrument_id":436},"action":"C","side":"B","price":"1.157100000","size":20,"channel_id":23,"order_id":"10998896394619294469","flags":128,"ts_in_delta":962,"sequence":118064,"symbol":"FCEU SI 20260615 PS"}
{"ts_recv":"2026-04-07T01:12:44.292410550Z","hd":{"ts_event":"2026-04-07T01:12:44.292396669Z","rtype":160,"publisher_id":101,"instrument_id":436},"action":"C","side":"B","price":"1.157200000","size":20,"channel_id":23,"order_id":"10998896394867665288","flags":128,"ts_in_delta":920,"sequence":118094,"symbol":"FCEU SI 20260615 PS"}
{"ts_recv":"2026-04-07T01:12:44.336059026Z","hd":{"ts_event":"2026-04-07T01:12:44.336043719Z","rtype":160,"publisher_id":101,"instrument_id":436},"action":"A","side":"B","price":"1.157100000","size":20,"channel_id":23,"order_id":"10998896401190825988","flags":128,"ts_in_delta":1752,"sequence":118098,"symbol":"FCEU SI 20260615 PS"}
{"ts_recv":"2026-04-07T01:12:44.721560804Z","hd":{"ts_event":"2026-04-07T01:12:44.721545535Z","rtype":160,"publisher_id":101,"instrument_id":436},"action":"A","side":"B","price":"1.157200000","size":20,"channel_id":23,"order_id":"10998896401576327595","flags":128,"ts_in_delta":715,"sequence":118106,"symbol":"FCEU SI 20260615 PS"}
{"ts_recv":"2026-04-07T01:12:44.721571371Z","hd":{"ts_event":"2026-04-07T01:12:44.721559391Z","rtype":160,"publisher_id":101,"instrument_id":436},"action":"C","side":"B","price":"1.157100000","size":20,"channel_id":23,"order_id":"10998896401190825988","flags":128,"ts_in_delta":674,"sequence":118107,"symbol":"FCEU SI 20260615 PS"}
{"ts_recv":"2026-04-07T01:12:50.894700739Z","hd":{"ts_event":"2026-04-07T01:12:50.894688073Z","rtype":160,"publisher_id":101,"instrument_id":436},"action":"C","side":"B","price":"1.157200000","size":20,"channel_id":23,"order_id":"10998896401576327595","flags":128,"ts_in_delta":908,"sequence":118137,"symbol":"FCEU SI 20260615 PS"}
{"ts_recv":"2026-04-07T01:12:50.937854311Z","hd":{"ts_event":"2026-04-07T01:12:50.937836569Z","rtype":160,"publisher_id":101,"instrument_id":436},"action":"A","side":"B","price":"1.157100000","size":20,"channel_id":23,"order_id":"10998896407792618476","flags":128,"ts_in_delta":913,"sequence":118138,"symbol":"FCEU SI 20260615 PS"}
{"ts_recv":"2026-04-07T01:12:54.862958852Z","hd":{"ts_event":"2026-04-07T01:12:54.862944075Z","rtype":160,"publisher_id":101,"instrument_id":436},"action":"A","side":"B","price":"1.157200000","size":20,"channel_id":23,"order_id":"10998896411717726167","flags":128,"ts_in_delta":1088,"sequence":118171,"symbol":"FCEU SI 20260615 PS"}
{"ts_recv":"2026-04-07T01:12:54.862991752Z","hd":{"ts_event":"2026-04-07T01:12:54.862978981Z","rtype":160,"publisher_id":101,"instrument_id":436},"action":"C","side":"B","price":"1.157100000","size":20,"channel_id":23,"order_id":"10998896407792618476","flags":128,"ts_in_delta":860,"sequence":118172,"symbol":"FCEU SI 20260615 PS"}
{"ts_recv":"2026-04-07T01:13:42.123294811Z","hd":{"ts_event":"2026-04-07T01:13:42.123280421Z","rtype":160,"publisher_id":101,"instrument_id":436},"action":"C","side":"B","price":"1.157200000","size":20,"channel_id":23,"order_id":"10998896411717726167","flags":128,"ts_in_delta":898,"sequence":118465,"symbol":"FCEU SI 20260615 PS"}
{"ts_recv":"2026-04-07T01:13:42.166341167Z","hd":{"ts_event":"2026-04-07T01:13:42.166325217Z","rtype":160,"publisher_id":101,"instrument_id":436},"action":"A","side":"B","price":"1.157100000","size":20,"channel_id":23,"order_id":"10998896459021107031","flags":128,"ts_in_delta":948,"sequence":118480,"symbol":"FCEU SI 20260615 PS"}
{"ts_recv":"2026-04-07T01:13:47.059604865Z","hd":{"ts_event":"2026-04-07T01:13:47.059588167Z","rtype":160,"publisher_id":101,"instrument_id":436},"action":"A","side":"A","price":"1.157500000","size":20,"channel_id":23,"order_id":"1775524427059594262","flags":128,"ts_in_delta":864,"sequence":118537,"symbol":"FCEU SI 20260615 PS"}
{"ts_recv":"2026-04-07T01:13:47.060164220Z","hd":{"ts_event":"2026-04-07T01:13:47.060152147Z","rtype":160,"publisher_id":101,"instrument_id":436},"action":"C","side":"A","price":"1.157600000","size":20,"channel_id":23,"order_id":"1775524301543720293","flags":128,"ts_in_delta":838,"sequence":118539,"symbol":"FCEU SI 20260615 PS"}
{"ts_recv":"2026-04-07T01:14:01.324507375Z","hd":{"ts_event":"2026-04-07T01:14:01.324493125Z","rtype":160,"publisher_id":101,"instrument_id":436},"action":"C","side":"B","price":"1.157100000","size":20,"channel_id":23,"order_id":"10998896459021107031","flags":128,"ts_in_delta":697,"sequence":118663,"symbol":"FCEU SI 20260615 PS"}
{"ts_recv":"2026-04-07T01:14:01.371658963Z","hd":{"ts_event":"2026-04-07T01:14:01.371642151Z","rtype":160,"publisher_id":101,"instrument_id":436},"action":"A","side":"B","price":"1.157100000","size":20,"channel_id":23,"order_id":"10998896478226423877","flags":128,"ts_in_delta":861,"sequence":118674,"symbol":"FCEU SI 20260615 PS"}
{"ts_recv":"2026-04-07T01:14:13.105218218Z","hd":{"ts_event":"2026-04-07T01:14:13.105204755Z","rtype":160,"publisher_id":101,"instrument_id":436},"action":"C","side":"B","price":"1.157100000","size":20,"channel_id":23,"order_id":"10998896478226423877","flags":128,"ts_in_delta":877,"sequence":118776,"symbol":"FCEU SI 20260615 PS"}
{"ts_recv":"2026-04-07T01:14:13.148311997Z","hd":{"ts_event":"2026-04-07T01:14:13.148297975Z","rtype":160,"publisher_id":101,"instrument_id":436},"action":"A","side":"B","price":"1.157000000","size":20,"channel_id":23,"order_id":"10998896490003079878","flags":128,"ts_in_delta":1023,"sequence":118778,"symbol":"FCEU SI 20260615 PS"}
{"ts_recv":"2026-04-07T01:14:54.031436894Z","hd":{"ts_event":"2026-04-07T01:14:54.031419187Z","rtype":160,"publisher_id":101,"instrument_id":436},"action":"A","side":"B","price":"1.157100000","size":20,"channel_id":23,"order_id":"10998896530886201423","flags":128,"ts_in_delta":885,"sequence":119148,"symbol":"FCEU SI 20260615 PS"}
{"ts_recv":"2026-04-07T01:14:54.031477519Z","hd":{"ts_event":"2026-04-07T01:14:54.031464851Z","rtype":160,"publisher_id":101,"instrument_id":436},"action":"C","side":"B","price":"1.157000000","size":20,"channel_id":23,"order_id":"10998896490003079878","flags":128,"ts_in_delta":874,"sequence":119149,"symbol":"FCEU SI 20260615 PS"}
{"ts_recv":"2026-04-07T01:15:06.329379274Z","hd":{"ts_event":"2026-04-07T01:15:06.329366593Z","rtype":160,"publisher_id":101,"instrument_id":436},"action":"C","side":"B","price":"1.157100000","size":20,"channel_id":23,"order_id":"10998896530886201423","flags":128,"ts_in_delta":844,"sequence":119263,"symbol":"FCEU SI 20260615 PS"}
{"ts_recv":"2026-04-07T01:15:06.464199495Z","hd":{"ts_event":"2026-04-07T01:15:06.464177499Z","rtype":160,"publisher_id":101,"instrument_id":436},"action":"A","side":"B","price":"1.157100000","size":20,"channel_id":23,"order_id":"10998896543318964141","flags":128,"ts_in_delta":1552,"sequence":119269,"symbol":"FCEU SI 20260615 PS"}
{"ts_recv":"2026-04-07T01:15:12.191183597Z","hd":{"ts_event":"2026-04-07T01:15:12.191164157Z","rtype":160,"publisher_id":101,"instrument_id":436},"action":"C","side":"B","price":"1.157100000","size":20,"channel_id":23,"order_id":"10998896543318964141","flags":128,"ts_in_delta":1263,"sequence":119297,"symbol":"FCEU SI 20260615 PS"}
{"ts_recv":"2026-04-07T01:15:12.264617028Z","hd":{"ts_event":"2026-04-07T01:15:12.264601159Z","rtype":160,"publisher_id":101,"instrument_id":436},"action":"A","side":"B","price":"1.157100000","size":20,"channel_id":23,"order_id":"10998896549119383648","flags":128,"ts_in_delta":1048,"sequence":119300,"symbol":"FCEU SI 20260615 PS"}
{"ts_recv":"2026-04-07T01:15:21.318629832Z","hd":{"ts_event":"2026-04-07T01:15:21.318614295Z","rtype":160,"publisher_id":101,"instrument_id":436},"action":"C","side":"B","price":"1.157100000","size":20,"channel_id":23,"order_id":"10998896549119383648","flags":128,"ts_in_delta":861,"sequence":119373,"symbol":"FCEU SI 20260615 PS"}
{"ts_recv":"2026-04-07T01:15:21.361429422Z","hd":{"ts_event":"2026-04-07T01:15:21.361413543Z","rtype":160,"publisher_id":101,"instrument_id":436},"action":"A","side":"B","price":"1.157000000","size":20,"channel_id":23,"order_id":"10998896558216195366","flags":128,"ts_in_delta":908,"sequence":119375,"symbol":"FCEU SI 20260615 PS"}
{"ts_recv":"2026-04-07T01:15:21.731269417Z","hd":{"ts_event":"2026-04-07T01:15:21.731246375Z","rtype":160,"publisher_id":101,"instrument_id":436},"action":"A","side":"B","price":"1.157100000","size":20,"channel_id":23,"order_id":"10998896558586035339","flags":128,"ts_in_delta":1336,"sequence":119383,"symbol":"FCEU SI 20260615 PS"}
{"ts_recv":"2026-04-07T01:15:21.731283125Z","hd":{"ts_event":"2026-04-07T01:15:21.731272001Z","rtype":160,"publisher_id":101,"instrument_id":436},"action":"C","side":"B","price":"1.157000000","size":20,"channel_id":23,"order_id":"10998896558216195366","flags":128,"ts_in_delta":751,"sequence":119384,"symbol":"FCEU SI 20260615 PS"}
{"ts_recv":"2026-04-07T01:15:43.825229297Z","hd":{"ts_event":"2026-04-07T01:15:43.825214565Z","rtype":160,"publisher_id":101,"instrument_id":436},"action":"C","side":"A","price":"1.157500000","size":20,"channel_id":23,"order_id":"1775524427059594262","flags":128,"ts_in_delta":868,"sequence":119527,"symbol":"FCEU SI 20260615 PS"}
{"ts_recv":"2026-04-07T01:15:43.868394956Z","hd":{"ts_event":"2026-04-07T01:15:43.868378033Z","rtype":160,"publisher_id":101,"instrument_id":436},"action":"A","side":"A","price":"1.157600000","size":20,"channel_id":23,"order_id":"1775524543868384058","flags":128,"ts_in_delta":832,"sequence":119535,"symbol":"FCEU SI 20260615 PS"}
{"ts_recv":"2026-04-07T01:16:19.105990480Z","hd":{"ts_event":"2026-04-07T01:16:19.105972435Z","rtype":160,"publisher_id":101,"instrument_id":436},"action":"A","side":"B","price":"1.157200000","size":20,"channel_id":23,"order_id":"10998896615960754463","flags":128,"ts_in_delta":819,"sequence":119813,"symbol":"FCEU SI 20260615 PS"}
{"ts_recv":"2026-04-07T01:16:19.106279066Z","hd":{"ts_event":"2026-04-07T01:16:19.106266255Z","rtype":160,"publisher_id":101,"instrument_id":436},"action":"C","side":"B","price":"1.157100000","size":20,"channel_id":23,"order_id":"10998896558586035339","flags":128,"ts_in_delta":628,"sequence":119814,"symbol":"FCEU SI 20260615 PS"}
{"ts_recv":"2026-04-07T01:16:27.464262520Z","hd":{"ts_event":"2026-04-07T01:16:27.464248959Z","rtype":160,"publisher_id":101,"instrument_id":436},"action":"C","side":"B","price":"1.157200000","size":20,"channel_id":23,"order_id":"10998896615960754463","flags":128,"ts_in_delta":936,"sequence":119885,"symbol":"FCEU SI 20260615 PS"}
{"ts_recv":"2026-04-07T01:16:27.507483145Z","hd":{"ts_event":"2026-04-07T01:16:27.507467951Z","rtype":160,"publisher_id":101,"instrument_id":436},"action":"A","side":"B","price":"1.157100000","size":20,"channel_id":23,"order_id":"10998896624362249579","flags":128,"ts_in_delta":887,"sequence":119892,"symbol":"FCEU SI 20260615 PS"}
{"ts_recv":"2026-04-07T01:16:30.544221323Z","hd":{"ts_event":"2026-04-07T01:16:30.544205753Z","rtype":160,"publisher_id":101,"instrument_id":436},"action":"A","side":"B","price":"1.157200000","size":20,"channel_id":23,"order_id":"10998896627398987679","flags":128,"ts_in_delta":999,"sequence":119912,"symbol":"FCEU SI 20260615 PS"}
{"ts_recv":"2026-04-07T01:16:30.544239923Z","hd":{"ts_event":"2026-04-07T01:16:30.544225651Z","rtype":160,"publisher_id":101,"instrument_id":436},"action":"C","side":"B","price":"1.157100000","size":20,"channel_id":23,"order_id":"10998896624362249579","flags":128,"ts_in_delta":1017,"sequence":119913,"symbol":"FCEU SI 20260615 PS"}
{"ts_recv":"2026-04-07T01:16:50.340200232Z","hd":{"ts_event":"2026-04-07T01:16:50.340185819Z","rtype":160,"publisher_id":101,"instrument_id":436},"action":"C","side":"B","price":"1.157200000","size":20,"channel_id":23,"order_id":"10998896627398987679","flags":128,"ts_in_delta":1459,"sequence":120139,"symbol":"FCEU SI 20260615 PS"}
{"ts_recv":"2026-04-07T01:16:50.383719577Z","hd":{"ts_event":"2026-04-07T01:16:50.383704427Z","rtype":160,"publisher_id":101,"instrument_id":436},"action":"A","side":"B","price":"1.157100000","size":20,"channel_id":23,"order_id":"10998896647238486075","flags":128,"ts_in_delta":853,"sequence":120143,"symbol":"FCEU SI 20260615 PS"}
{"ts_recv":"2026-04-07T01:16:50.932221536Z","hd":{"ts_event":"2026-04-07T01:16:50.932206829Z","rtype":160,"publisher_id":101,"instrument_id":436},"action":"A","side":"B","price":"1.157200000","size":20,"channel_id":23,"order_id":"10998896647786988625","flags":128,"ts_in_delta":760,"sequence":120166,"symbol":"FCEU SI 20260615 PS"}
{"ts_recv":"2026-04-07T01:16:50.932272652Z","hd":{"ts_event":"2026-04-07T01:16:50.932260201Z","rtype":160,"publisher_id":101,"instrument_id":436},"action":"C","side":"B","price":"1.157100000","size":20,"channel_id":23,"order_id":"10998896647238486075","flags":128,"ts_in_delta":949,"sequence":120167,"symbol":"FCEU SI 20260615 PS"}
{"ts_recv":"2026-04-07T01:16:57.770871594Z","hd":{"ts_event":"2026-04-07T01:16:57.770852339Z","rtype":160,"publisher_id":101,"instrument_id":436},"action":"C","side":"B","price":"1.157200000","size":20,"channel_id":23,"order_id":"10998896647786988625","flags":128,"ts_in_delta":1004,"sequence":120249,"symbol":"FCEU SI 20260615 PS"}
{"ts_recv":"2026-04-07T01:16:57.868707140Z","hd":{"ts_event":"2026-04-07T01:16:57.868693509Z","rtype":160,"publisher_id":101,"instrument_id":436},"action":"A","side":"B","price":"1.157100000","size":20,"channel_id":23,"order_id":"10998896654723475502","flags":128,"ts_in_delta":1016,"sequence":120255,"symbol":"FCEU SI 20260615 PS"}
{"ts_recv":"2026-04-07T01:17:00.521333407Z","hd":{"ts_event":"2026-04-07T01:17:00.521310797Z","rtype":160,"publisher_id":101,"instrument_id":436},"action":"A","side":"B","price":"1.157200000","size":20,"channel_id":23,"order_id":"10998896657376097716","flags":128,"ts_in_delta":1436,"sequence":120290,"symbol":"FCEU SI 20260615 PS"}
{"ts_recv":"2026-04-07T01:17:00.521336748Z","hd":{"ts_event":"2026-04-07T01:17:00.521322937Z","rtype":160,"publisher_id":101,"instrument_id":436},"action":"C","side":"B","price":"1.157100000","size":20,"channel_id":23,"order_id":"10998896654723475502","flags":128,"ts_in_delta":1169,"sequence":120291,"symbol":"FCEU SI 20260615 PS"}
{"ts_recv":"2026-04-07T01:17:07.478609103Z","hd":{"ts_event":"2026-04-07T01:17:07.478597223Z","rtype":160,"publisher_id":101,"instrument_id":436},"action":"C","side":"B","price":"1.157200000","size":20,"channel_id":23,"order_id":"10998896657376097716","flags":128,"ts_in_delta":1062,"sequence":120361,"symbol":"FCEU SI 20260615 PS"}
{"ts_recv":"2026-04-07T01:17:07.521480256Z","hd":{"ts_event":"2026-04-07T01:17:07.521466845Z","rtype":160,"publisher_id":101,"instrument_id":436},"action":"A","side":"B","price":"1.157100000","size":20,"channel_id":23,"order_id":"10998896664376248693","flags":128,"ts_in_delta":892,"sequence":120369,"symbol":"FCEU SI 20260615 PS"}
{"ts_recv":"2026-04-07T01:17:37.565100358Z","hd":{"ts_event":"2026-04-07T01:17:37.565084741Z","rtype":160,"publisher_id":101,"instrument_id":436},"action":"A","side":"B","price":"1.157200000","size":20,"channel_id":23,"order_id":"10998896694419866511","flags":128,"ts_in_delta":830,"sequence":120510,"symbol":"FCEU SI 20260615 PS"}
{"ts_recv":"2026-04-07T01:17:37.565114788Z","hd":{"ts_event":"2026-04-07T01:17:37.565103577Z","rtype":160,"publisher_id":101,"instrument_id":436},"action":"C","side":"B","price":"1.157100000","size":20,"channel_id":23,"order_id":"10998896664376248693","flags":128,"ts_in_delta":982,"sequence":120511,"symbol":"FCEU SI 20260615 PS"}
{"ts_recv":"2026-04-07T01:17:47.700379644Z","hd":{"ts_event":"2026-04-07T01:17:47.700365781Z","rtype":160,"publisher_id":101,"instrument_id":436},"action":"C","side":"B","price":"1.157200000","size":20,"channel_id":23,"order_id":"10998896694419866511","flags":128,"ts_in_delta":965,"sequence":120605,"symbol":"FCEU SI 20260615 PS"}
{"ts_recv":"2026-04-07T01:17:47.764552167Z","hd":{"ts_event":"2026-04-07T01:17:47.764530983Z","rtype":160,"publisher_id":101,"instrument_id":436},"action":"A","side":"B","price":"1.157200000","size":20,"channel_id":23,"order_id":"10998896704619318053","flags":128,"ts_in_delta":1504,"sequence":120608,"symbol":"FCEU SI 20260615 PS"}
{"ts_recv":"2026-04-07T01:18:05.198750364Z","hd":{"ts_event":"2026-04-07T01:18:05.198730177Z","rtype":160,"publisher_id":101,"instrument_id":436},"action":"C","side":"A","price":"1.157600000","size":20,"channel_id":23,"order_id":"1775524543868384058","flags":128,"ts_in_delta":5470,"sequence":120739,"symbol":"FCEU SI 20260615 PS"}
{"ts_recv":"2026-04-07T01:18:05.242470939Z","hd":{"ts_event":"2026-04-07T01:18:05.242453423Z","rtype":160,"publisher_id":101,"instrument_id":436},"action":"A","side":"A","price":"1.157700000","size":20,"channel_id":23,"order_id":"1775524685242459593","flags":128,"ts_in_delta":879,"sequence":120742,"symbol":"FCEU SI 20260615 PS"}
{"ts_recv":"2026-04-07T01:18:35.760107651Z","hd":{"ts_event":"2026-04-07T01:18:35.760083737Z","rtype":160,"publisher_id":101,"instrument_id":436},"action":"A","side":"A","price":"1.157600000","size":20,"channel_id":23,"order_id":"1775524715760094546","flags":128,"ts_in_delta":1455,"sequence":120934,"symbol":"FCEU SI 20260615 PS"}
{"ts_recv":"2026-04-07T01:18:35.760224320Z","hd":{"ts_event":"2026-04-07T01:18:35.760209599Z","rtype":160,"publisher_id":101,"instrument_id":436},"action":"C","side":"A","price":"1.157700000","size":20,"channel_id":23,"order_id":"1775524685242459593","flags":128,"ts_in_delta":1013,"sequence":120935,"symbol":"FCEU SI 20260615 PS"}
{"ts_recv":"2026-04-07T01:19:02.756140134Z","hd":{"ts_event":"2026-04-07T01:19:02.756118059Z","rtype":160,"publisher_id":101,"instrument_id":436},"action":"C","side":"B","price":"1.157200000","size":20,"channel_id":23,"order_id":"10998896704619318053","flags":128,"ts_in_delta":1033,"sequence":121068,"symbol":"FCEU SI 20260615 PS"}
{"ts_recv":"2026-04-07T01:19:02.799393555Z","hd":{"ts_event":"2026-04-07T01:19:02.799376075Z","rtype":160,"publisher_id":101,"instrument_id":436},"action":"A","side":"B","price":"1.157100000","size":20,"channel_id":23,"order_id":"10998896779654158161","flags":128,"ts_in_delta":892,"sequence":121071,"symbol":"FCEU SI 20260615 PS"}
{"ts_recv":"2026-04-07T01:19:14.173617351Z","hd":{"ts_event":"2026-04-07T01:19:14.173599351Z","rtype":160,"publisher_id":101,"instrument_id":436},"action":"A","side":"B","price":"1.157200000","size":20,"channel_id":23,"order_id":"10998896791028381315","flags":128,"ts_in_delta":1783,"sequence":121191,"symbol":"FCEU SI 20260615 PS"}
{"ts_recv":"2026-04-07T01:19:14.173688813Z","hd":{"ts_event":"2026-04-07T01:19:14.173675051Z","rtype":160,"publisher_id":101,"instrument_id":436},"action":"C","side":"B","price":"1.157100000","size":20,"channel_id":23,"order_id":"10998896779654158161","flags":128,"ts_in_delta":918,"sequence":121192,"symbol":"FCEU SI 20260615 PS"}
{"ts_recv":"2026-04-07T01:19:20.287191915Z","hd":{"ts_event":"2026-04-07T01:19:20.287170281Z","rtype":160,"publisher_id":101,"instrument_id":436},"action":"C","side":"B","price":"1.157200000","size":20,"channel_id":23,"order_id":"10998896791028381315","flags":128,"ts_in_delta":1705,"sequence":121234,"symbol":"FCEU SI 20260615 PS"}
{"ts_recv":"2026-04-07T01:19:20.329764103Z","hd":{"ts_event":"2026-04-07T01:19:20.329743255Z","rtype":160,"publisher_id":101,"instrument_id":436},"action":"A","side":"B","price":"1.157100000","size":20,"channel_id":23,"order_id":"10998896797184530522","flags":128,"ts_in_delta":1093,"sequence":121235,"symbol":"FCEU SI 20260615 PS"}
{"ts_recv":"2026-04-07T01:19:21.865579600Z","hd":{"ts_event":"2026-04-07T01:19:21.865561515Z","rtype":160,"publisher_id":101,"instrument_id":436},"action":"A","side":"B","price":"1.157200000","size":20,"channel_id":23,"order_id":"10998896798720343560","flags":128,"ts_in_delta":819,"sequence":121241,"symbol":"FCEU SI 20260615 PS"}
{"ts_recv":"2026-04-07T01:19:21.865593953Z","hd":{"ts_event":"2026-04-07T01:19:21.865582349Z","rtype":160,"publisher_id":101,"instrument_id":436},"action":"C","side":"B","price":"1.157100000","size":20,"channel_id":23,"order_id":"10998896797184530522","flags":128,"ts_in_delta":960,"sequence":121242,"symbol":"FCEU SI 20260615 PS"}
{"ts_recv":"2026-04-07T01:20:29.562638879Z","hd":{"ts_event":"2026-04-07T01:20:29.562618731Z","rtype":160,"publisher_id":101,"instrument_id":436},"action":"C","side":"B","price":"1.157200000","size":20,"channel_id":23,"order_id":"10998896798720343560","flags":128,"ts_in_delta":1137,"sequence":121807,"symbol":"FCEU SI 20260615 PS"}
{"ts_recv":"2026-04-07T01:20:29.606289460Z","hd":{"ts_event":"2026-04-07T01:20:29.606268097Z","rtype":160,"publisher_id":101,"instrument_id":436},"action":"A","side":"B","price":"1.157100000","size":20,"channel_id":23,"order_id":"10998896866461054867","flags":128,"ts_in_delta":1128,"sequence":121808,"symbol":"FCEU SI 20260615 PS"}
{"ts_recv":"2026-04-07T01:20:30.486223659Z","hd":{"ts_event":"2026-04-07T01:20:30.486210379Z","rtype":160,"publisher_id":101,"instrument_id":436},"action":"A","side":"B","price":"1.157200000","size":20,"channel_id":23,"order_id":"10998896867340992452","flags":128,"ts_in_delta":858,"sequence":121826,"symbol":"FCEU SI 20260615 PS"}
{"ts_recv":"2026-04-07T01:20:30.486247258Z","hd":{"ts_event":"2026-04-07T01:20:30.486231373Z","rtype":160,"publisher_id":101,"instrument_id":436},"action":"C","side":"B","price":"1.157100000","size":20,"channel_id":23,"order_id":"10998896866461054867","flags":128,"ts_in_delta":878,"sequence":121827,"symbol":"FCEU SI 20260615 PS"}
{"ts_recv":"2026-04-07T01:20:39.049513419Z","hd":{"ts_event":"2026-04-07T01:20:39.049488517Z","rtype":160,"publisher_id":101,"instrument_id":436},"action":"C","side":"B","price":"1.157200000","size":20,"channel_id":23,"order_id":"10998896867340992452","flags":128,"ts_in_delta":1501,"sequence":121896,"symbol":"FCEU SI 20260615 PS"}
{"ts_recv":"2026-04-07T01:20:39.092435143Z","hd":{"ts_event":"2026-04-07T01:20:39.092418263Z","rtype":160,"publisher_id":101,"instrument_id":436},"action":"A","side":"B","price":"1.157100000","size":20,"channel_id":23,"order_id":"10998896875947200338","flags":128,"ts_in_delta":863,"sequence":121898,"symbol":"FCEU SI 20260615 PS"}
{"ts_recv":"2026-04-07T01:20:50.808660878Z","hd":{"ts_event":"2026-04-07T01:20:50.808636157Z","rtype":160,"publisher_id":101,"instrument_id":436},"action":"A","side":"B","price":"1.157200000","size":20,"channel_id":23,"order_id":"10998896887663422548","flags":128,"ts_in_delta":813,"sequence":121950,"symbol":"FCEU SI 20260615 PS"}
{"ts_recv":"2026-04-07T01:20:50.808672567Z","hd":{"ts_event":"2026-04-07T01:20:50.808660937Z","rtype":160,"publisher_id":101,"instrument_id":436},"action":"C","side":"B","price":"1.157100000","size":20,"channel_id":23,"order_id":"10998896875947200338","flags":128,"ts_in_delta":789,"sequence":121951,"symbol":"FCEU SI 20260615 PS"}
{"ts_recv":"2026-04-07T01:21:27.350394200Z","hd":{"ts_event":"2026-04-07T01:21:27.350380197Z","rtype":160,"publisher_id":101,"instrument_id":436},"action":"C","side":"B","price":"1.157200000","size":20,"channel_id":23,"order_id":"10998896887663422548","flags":128,"ts_in_delta":828,"sequence":122208,"symbol":"FCEU SI 20260615 PS"}
{"ts_recv":"2026-04-07T01:21:27.395324537Z","hd":{"ts_event":"2026-04-07T01:21:27.395309413Z","rtype":160,"publisher_id":101,"instrument_id":436},"action":"A","side":"B","price":"1.157200000","size":20,"channel_id":23,"order_id":"10998896924250091149","flags":128,"ts_in_delta":649,"sequence":122216,"symbol":"FCEU SI 20260615 PS"}
{"ts_recv":"2026-04-07T01:22:06.246031059Z","hd":{"ts_event":"2026-04-07T01:22:06.246017049Z","rtype":160,"publisher_id":101,"instrument_id":436},"action":"C","side":"B","price":"1.157200000","size":20,"channel_id":23,"order_id":"10998896924250091149","flags":128,"ts_in_delta":962,"sequence":122463,"symbol":"FCEU SI 20260615 PS"}
{"ts_recv":"2026-04-07T01:22:06.289384678Z","hd":{"ts_event":"2026-04-07T01:22:06.289361625Z","rtype":160,"publisher_id":101,"instrument_id":436},"action":"A","side":"B","price":"1.157100000","size":20,"channel_id":23,"order_id":"10998896963144148110","flags":128,"ts_in_delta":989,"sequence":122466,"symbol":"FCEU SI 20260615 PS"}
{"ts_recv":"2026-04-07T01:22:09.485154719Z","hd":{"ts_event":"2026-04-07T01:22:09.485126171Z","rtype":160,"publisher_id":101,"instrument_id":436},"action":"A","side":"B","price":"1.157200000","size":20,"channel_id":23,"order_id":"10998896966339916641","flags":128,"ts_in_delta":1222,"sequence":122486,"symbol":"FCEU SI 20260615 PS"}
{"ts_recv":"2026-04-07T01:22:09.485158121Z","hd":{"ts_event":"2026-04-07T01:22:09.485133943Z","rtype":160,"publisher_id":101,"instrument_id":436},"action":"C","side":"B","price":"1.157100000","size":20,"channel_id":23,"order_id":"10998896963144148110","flags":128,"ts_in_delta":924,"sequence":122487,"symbol":"FCEU SI 20260615 PS"}
{"ts_recv":"2026-04-07T01:22:57.656969622Z","hd":{"ts_event":"2026-04-07T01:22:57.656953429Z","rtype":160,"publisher_id":101,"instrument_id":436},"action":"C","side":"B","price":"1.157200000","size":20,"channel_id":23,"order_id":"10998896966339916641","flags":128,"ts_in_delta":852,"sequence":122789,"symbol":"FCEU SI 20260615 PS"}
{"ts_recv":"2026-04-07T01:22:57.699801536Z","hd":{"ts_event":"2026-04-07T01:22:57.699785105Z","rtype":160,"publisher_id":101,"instrument_id":436},"action":"A","side":"B","price":"1.157100000","size":20,"channel_id":23,"order_id":"10998897014554566997","flags":128,"ts_in_delta":870,"sequence":122801,"symbol":"FCEU SI 20260615 PS"}
{"ts_recv":"2026-04-07T01:23:04.172755710Z","hd":{"ts_event":"2026-04-07T01:23:04.172732283Z","rtype":160,"publisher_id":101,"instrument_id":436},"action":"A","side":"B","price":"1.157200000","size":20,"channel_id":23,"order_id":"10998897021027519496","flags":128,"ts_in_delta":1138,"sequence":122872,"symbol":"FCEU SI 20260615 PS"}
{"ts_recv":"2026-04-07T01:23:04.172768727Z","hd":{"ts_event":"2026-04-07T01:23:04.172756033Z","rtype":160,"publisher_id":101,"instrument_id":436},"action":"C","side":"B","price":"1.157100000","size":20,"channel_id":23,"order_id":"10998897014554566997","flags":128,"ts_in_delta":1006,"sequence":122873,"symbol":"FCEU SI 20260615 PS"}
{"ts_recv":"2026-04-07T01:23:09.172453345Z","hd":{"ts_event":"2026-04-07T01:23:09.172433925Z","rtype":160,"publisher_id":101,"instrument_id":436},"action":"C","side":"B","price":"1.157200000","size":20,"channel_id":23,"order_id":"10998897021027519496","flags":128,"ts_in_delta":1011,"sequence":122912,"symbol":"FCEU SI 20260615 PS"}
{"ts_recv":"2026-04-07T01:23:09.216008471Z","hd":{"ts_event":"2026-04-07T01:23:09.215991105Z","rtype":160,"publisher_id":101,"instrument_id":436},"action":"A","side":"B","price":"1.157100000","size":20,"channel_id":23,"order_id":"10998897026070772836","flags":128,"ts_in_delta":1418,"sequence":122913,"symbol":"FCEU SI 20260615 PS"}
{"ts_recv":"2026-04-07T01:23:19.307657455Z","hd":{"ts_event":"2026-04-07T01:23:19.307641207Z","rtype":160,"publisher_id":101,"instrument_id":436},"action":"A","side":"A","price":"1.157500000","size":20,"channel_id":23,"order_id":"1775524999307647072","flags":128,"ts_in_delta":977,"sequence":122988,"symbol":"FCEU SI 20260615 PS"}
{"ts_recv":"2026-04-07T01:23:19.307678789Z","hd":{"ts_event":"2026-04-07T01:23:19.307664119Z","rtype":160,"publisher_id":101,"instrument_id":436},"action":"C","side":"A","price":"1.157600000","size":20,"channel_id":23,"order_id":"1775524715760094546","flags":128,"ts_in_delta":961,"sequence":122989,"symbol":"FCEU SI 20260615 PS"}
{"ts_recv":"2026-04-07T01:23:31.688807732Z","hd":{"ts_event":"2026-04-07T01:23:31.688794243Z","rtype":160,"publisher_id":101,"instrument_id":436},"action":"C","side":"B","price":"1.157100000","size":20,"channel_id":23,"order_id":"10998897026070772836","flags":128,"ts_in_delta":866,"sequence":123064,"symbol":"FCEU SI 20260615 PS"}
{"ts_recv":"2026-04-07T01:23:31.774161936Z","hd":{"ts_event":"2026-04-07T01:23:31.774144735Z","rtype":160,"publisher_id":101,"instrument_id":436},"action":"A","side":"B","price":"1.157100000","size":20,"channel_id":23,"order_id":"10998897048628926575","flags":128,"ts_in_delta":1534,"sequence":123073,"symbol":"FCEU SI 20260615 PS"}
{"ts_recv":"2026-04-07T01:23:48.492542833Z","hd":{"ts_event":"2026-04-07T01:23:48.492530893Z","rtype":160,"publisher_id":101,"instrument_id":436},"action":"C","side":"B","price":"1.157100000","size":20,"channel_id":23,"order_id":"10998897048628926575","flags":128,"ts_in_delta":838,"sequence":123155,"symbol":"FCEU SI 20260615 PS"}
{"ts_recv":"2026-04-07T01:23:48.536454110Z","hd":{"ts_event":"2026-04-07T01:23:48.536439263Z","rtype":160,"publisher_id":101,"instrument_id":436},"action":"A","side":"B","price":"1.157000000","size":20,"channel_id":23,"order_id":"10998897065391221028","flags":128,"ts_in_delta":614,"sequence":123169,"symbol":"FCEU SI 20260615 PS"}
{"ts_recv":"2026-04-07T01:23:49.861649677Z","hd":{"ts_event":"2026-04-07T01:23:49.861630123Z","rtype":160,"publisher_id":101,"instrument_id":436},"action":"A","side":"B","price":"1.157100000","size":20,"channel_id":23,"order_id":"10998897066716414426","flags":128,"ts_in_delta":1503,"sequence":123200,"symbol":"FCEU SI 20260615 PS"}
{"ts_recv":"2026-04-07T01:23:49.861653685Z","hd":{"ts_event":"2026-04-07T01:23:49.861639607Z","rtype":160,"publisher_id":101,"instrument_id":436},"action":"C","side":"B","price":"1.157000000","size":20,"channel_id":23,"order_id":"10998897065391221028","flags":128,"ts_in_delta":793,"sequence":123201,"symbol":"FCEU SI 20260615 PS"}
{"ts_recv":"2026-04-07T01:24:20.216914151Z","hd":{"ts_event":"2026-04-07T01:24:20.216899185Z","rtype":160,"publisher_id":101,"instrument_id":436},"action":"C","side":"A","price":"1.157500000","size":20,"channel_id":23,"order_id":"1775524999307647072","flags":128,"ts_in_delta":906,"sequence":123356,"symbol":"FCEU SI 20260615 PS"}
{"ts_recv":"2026-04-07T01:24:20.259601244Z","hd":{"ts_event":"2026-04-07T01:24:20.259586553Z","rtype":160,"publisher_id":101,"instrument_id":436},"action":"A","side":"A","price":"1.157600000","size":20,"channel_id":23,"order_id":"1775525060259592615","flags":128,"ts_in_delta":879,"sequence":123358,"symbol":"FCEU SI 20260615 PS"}
{"ts_recv":"2026-04-07T01:24:52.425757785Z","hd":{"ts_event":"2026-04-07T01:24:52.425733303Z","rtype":160,"publisher_id":101,"instrument_id":436},"action":"A","side":"A","price":"1.157500000","size":20,"channel_id":23,"order_id":"1775525092425744533","flags":128,"ts_in_delta":1263,"sequence":123578,"symbol":"FCEU SI 20260615 PS"}
{"ts_recv":"2026-04-07T01:24:52.425770610Z","hd":{"ts_event":"2026-04-07T01:24:52.425756701Z","rtype":160,"publisher_id":101,"instrument_id":436},"action":"C","side":"A","price":"1.157600000","size":20,"channel_id":23,"order_id":"1775525060259592615","flags":128,"ts_in_delta":821,"sequence":123579,"symbol":"FCEU SI 20260615 PS"}
{"ts_recv":"2026-04-07T01:25:08.753275140Z","hd":{"ts_event":"2026-04-07T01:25:08.753261497Z","rtype":160,"publisher_id":101,"instrument_id":436},"action":"C","side":"A","price":"1.157500000","size":20,"channel_id":23,"order_id":"1775525092425744533","flags":128,"ts_in_delta":1038,"sequence":123664,"symbol":"FCEU SI 20260615 PS"}
{"ts_recv":"2026-04-07T01:25:08.796473043Z","hd":{"ts_event":"2026-04-07T01:25:08.796458153Z","rtype":160,"publisher_id":101,"instrument_id":436},"action":"A","side":"A","price":"1.157600000","size":20,"channel_id":23,"order_id":"1775525108796464177","flags":128,"ts_in_delta":1284,"sequence":123671,"symbol":"FCEU SI 20260615 PS"}
{"ts_recv":"2026-04-07T01:25:27.227223391Z","hd":{"ts_event":"2026-04-07T01:25:27.227209047Z","rtype":160,"publisher_id":101,"instrument_id":436},"action":"A","side":"A","price":"1.157500000","size":20,"channel_id":23,"order_id":"1775525127227214966","flags":128,"ts_in_delta":930,"sequence":123777,"symbol":"FCEU SI 20260615 PS"}
{"ts_recv":"2026-04-07T01:25:27.227246254Z","hd":{"ts_event":"2026-04-07T01:25:27.227229763Z","rtype":160,"publisher_id":101,"instrument_id":436},"action":"C","side":"A","price":"1.157600000","size":20,"channel_id":23,"order_id":"1775525108796464177","flags":128,"ts_in_delta":900,"sequence":123778,"symbol":"FCEU SI 20260615 PS"}
{"ts_recv":"2026-04-07T01:25:49.035623616Z","hd":{"ts_event":"2026-04-07T01:25:49.035608143Z","rtype":160,"publisher_id":101,"instrument_id":436},"action":"C","side":"B","price":"1.157100000","size":20,"channel_id":23,"order_id":"10998897066716414426","flags":128,"ts_in_delta":805,"sequence":123941,"symbol":"FCEU SI 20260615 PS"}
{"ts_recv":"2026-04-07T01:25:49.079117962Z","hd":{"ts_event":"2026-04-07T01:25:49.079102835Z","rtype":160,"publisher_id":101,"instrument_id":436},"action":"A","side":"B","price":"1.157000000","size":20,"channel_id":23,"order_id":"10998897185933884694","flags":128,"ts_in_delta":950,"sequence":123956,"symbol":"FCEU SI 20260615 PS"}
{"ts_recv":"2026-04-07T01:25:50.089642213Z","hd":{"ts_event":"2026-04-07T01:25:50.089625433Z","rtype":160,"publisher_id":101,"instrument_id":436},"action":"A","side":"B","price":"1.157100000","size":20,"channel_id":23,"order_id":"10998897186944408679","flags":128,"ts_in_delta":1303,"sequence":123963,"symbol":"FCEU SI 20260615 PS"}
{"ts_recv":"2026-04-07T01:25:50.089655629Z","hd":{"ts_event":"2026-04-07T01:25:50.089644731Z","rtype":160,"publisher_id":101,"instrument_id":436},"action":"C","side":"B","price":"1.157000000","size":20,"channel_id":23,"order_id":"10998897185933884694","flags":128,"ts_in_delta":847,"sequence":123964,"symbol":"FCEU SI 20260615 PS"}
{"ts_recv":"2026-04-07T01:25:57.111070062Z","hd":{"ts_event":"2026-04-07T01:25:57.111056421Z","rtype":160,"publisher_id":101,"instrument_id":436},"action":"C","side":"B","price":"1.157100000","size":20,"channel_id":23,"order_id":"10998897186944408679","flags":128,"ts_in_delta":793,"sequence":124010,"symbol":"FCEU SI 20260615 PS"}
{"ts_recv":"2026-04-07T01:25:57.174411699Z","hd":{"ts_event":"2026-04-07T01:25:57.174390251Z","rtype":160,"publisher_id":101,"instrument_id":436},"action":"A","side":"B","price":"1.157100000","size":20,"channel_id":23,"order_id":"10998897194029177077","flags":128,"ts_in_delta":982,"sequence":124018,"symbol":"FCEU SI 20260615 PS"}
{"ts_recv":"2026-04-07T01:26:06.639477188Z","hd":{"ts_event":"2026-04-07T01:26:06.639463807Z","rtype":160,"publisher_id":101,"instrument_id":436},"action":"C","side":"B","price":"1.157100000","size":20,"channel_id":23,"order_id":"10998897194029177077","flags":128,"ts_in_delta":1408,"sequence":124063,"symbol":"FCEU SI 20260615 PS"}
{"ts_recv":"2026-04-07T01:26:06.683308849Z","hd":{"ts_event":"2026-04-07T01:26:06.683291619Z","rtype":160,"publisher_id":101,"instrument_id":436},"action":"A","side":"B","price":"1.157000000","size":20,"channel_id":23,"order_id":"10998897203538073777","flags":128,"ts_in_delta":2327,"sequence":124067,"symbol":"FCEU SI 20260615 PS"}
{"ts_recv":"2026-04-07T01:26:17.319237774Z","hd":{"ts_event":"2026-04-07T01:26:17.319219049Z","rtype":160,"publisher_id":101,"instrument_id":436},"action":"A","side":"A","price":"1.157400000","size":20,"channel_id":23,"order_id":"1775525177319225093","flags":128,"ts_in_delta":971,"sequence":124143,"symbol":"FCEU SI 20260615 PS"}
{"ts_recv":"2026-04-07T01:26:17.319252650Z","hd":{"ts_event":"2026-04-07T01:26:17.319241161Z","rtype":160,"publisher_id":101,"instrument_id":436},"action":"C","side":"A","price":"1.157500000","size":20,"channel_id":23,"order_id":"1775525127227214966","flags":128,"ts_in_delta":1177,"sequence":124144,"symbol":"FCEU SI 20260615 PS"}
{"ts_recv":"2026-04-07T01:26:49.973600458Z","hd":{"ts_event":"2026-04-07T01:26:49.973576097Z","rtype":160,"publisher_id":101,"instrument_id":436},"action":"C","side":"A","price":"1.157400000","size":20,"channel_id":23,"order_id":"1775525177319225093","flags":128,"ts_in_delta":1412,"sequence":124407,"symbol":"FCEU SI 20260615 PS"}
{"ts_recv":"2026-04-07T01:26:50.016980965Z","hd":{"ts_event":"2026-04-07T01:26:50.016966143Z","rtype":160,"publisher_id":101,"instrument_id":436},"action":"A","side":"A","price":"1.157500000","size":20,"channel_id":23,"order_id":"1775525210016972726","flags":128,"ts_in_delta":853,"sequence":124410,"symbol":"FCEU SI 20260615 PS"}
{"ts_recv":"2026-04-07T01:26:50.582556805Z","hd":{"ts_event":"2026-04-07T01:26:50.582540557Z","rtype":160,"publisher_id":101,"instrument_id":436},"action":"A","side":"B","price":"1.157100000","size":20,"channel_id":23,"order_id":"10998897247437322327","flags":128,"ts_in_delta":804,"sequence":124439,"symbol":"FCEU SI 20260615 PS"}
{"ts_recv":"2026-04-07T01:26:50.582669320Z","hd":{"ts_event":"2026-04-07T01:26:50.582656711Z","rtype":160,"publisher_id":101,"instrument_id":436},"action":"C","side":"B","price":"1.157000000","size":20,"channel_id":23,"order_id":"10998897203538073777","flags":128,"ts_in_delta":826,"sequence":124441,"symbol":"FCEU SI 20260615 PS"}
{"ts_recv":"2026-04-07T01:27:46.241072012Z","hd":{"ts_event":"2026-04-07T01:27:46.241056725Z","rtype":160,"publisher_id":101,"instrument_id":436},"action":"C","side":"A","price":"1.157500000","size":20,"channel_id":23,"order_id":"1775525210016972726","flags":128,"ts_in_delta":1060,"sequence":124861,"symbol":"FCEU SI 20260615 PS"}
{"ts_recv":"2026-04-07T01:27:46.284523894Z","hd":{"ts_event":"2026-04-07T01:27:46.284498619Z","rtype":160,"publisher_id":101,"instrument_id":436},"action":"A","side":"A","price":"1.157600000","size":20,"channel_id":23,"order_id":"1775525266284509683","flags":128,"ts_in_delta":898,"sequence":124863,"symbol":"FCEU SI 20260615 PS"}
{"ts_recv":"2026-04-07T01:28:19.267672221Z","hd":{"ts_event":"2026-04-07T01:28:19.267653667Z","rtype":160,"publisher_id":101,"instrument_id":436},"action":"A","side":"A","price":"1.157500000","size":20,"channel_id":23,"order_id":"1775525299267659951","flags":128,"ts_in_delta":883,"sequence":125086,"symbol":"FCEU SI 20260615 PS"}
{"ts_recv":"2026-04-07T01:28:19.267716971Z","hd":{"ts_event":"2026-04-07T01:28:19.267703287Z","rtype":160,"publisher_id":101,"instrument_id":436},"action":"C","side":"A","price":"1.157600000","size":20,"channel_id":23,"order_id":"1775525266284509683","flags":128,"ts_in_delta":828,"sequence":125088,"symbol":"FCEU SI 20260615 PS"}
{"ts_recv":"2026-04-07T01:28:34.247382845Z","hd":{"ts_event":"2026-04-07T01:28:34.247368205Z","rtype":160,"publisher_id":101,"instrument_id":436},"action":"C","side":"A","price":"1.157500000","size":20,"channel_id":23,"order_id":"1775525299267659951","flags":128,"ts_in_delta":1003,"sequence":125182,"symbol":"FCEU SI 20260615 PS"}
{"ts_recv":"2026-04-07T01:28:34.290052603Z","hd":{"ts_event":"2026-04-07T01:28:34.290036205Z","rtype":160,"publisher_id":101,"instrument_id":436},"action":"A","side":"A","price":"1.157600000","size":20,"channel_id":23,"order_id":"1775525314290042783","flags":128,"ts_in_delta":1018,"sequence":125184,"symbol":"FCEU SI 20260615 PS"}
{"ts_recv":"2026-04-07T01:29:47.480554821Z","hd":{"ts_event":"2026-04-07T01:29:47.480528559Z","rtype":160,"publisher_id":101,"instrument_id":436},"action":"A","side":"A","price":"1.157500000","size":20,"channel_id":23,"order_id":"1775525387480539357","flags":128,"ts_in_delta":1190,"sequence":125553,"symbol":"FCEU SI 20260615 PS"}
{"ts_recv":"2026-04-07T01:29:47.480621727Z","hd":{"ts_event":"2026-04-07T01:29:47.480609513Z","rtype":160,"publisher_id":101,"instrument_id":436},"action":"C","side":"A","price":"1.157600000","size":20,"channel_id":23,"order_id":"1775525314290042783","flags":128,"ts_in_delta":1007,"sequence":125556,"symbol":"FCEU SI 20260615 PS"}
{"ts_recv":"2026-04-07T01:29:55.658420678Z","hd":{"ts_event":"2026-04-07T01:29:55.658406361Z","rtype":160,"publisher_id":101,"instrument_id":436},"action":"C","side":"A","price":"1.157500000","size":20,"channel_id":23,"order_id":"1775525387480539357","flags":128,"ts_in_delta":870,"sequence":125622,"symbol":"FCEU SI 20260615 PS"}
{"ts_recv":"2026-04-07T01:29:55.701407177Z","hd":{"ts_event":"2026-04-07T01:29:55.701394519Z","rtype":160,"publisher_id":101,"instrument_id":436},"action":"A","side":"A","price":"1.157600000","size":20,"channel_id":23,"order_id":"1775525395701400144","flags":128,"ts_in_delta":855,"sequence":125631,"symbol":"FCEU SI 20260615 PS"}
{"ts_recv":"2026-04-07T01:31:19.815202711Z","hd":{"ts_event":"2026-04-07T01:31:19.815183687Z","rtype":160,"publisher_id":101,"instrument_id":436},"action":"A","side":"A","price":"1.157500000","size":20,"channel_id":23,"order_id":"1775525479815189988","flags":128,"ts_in_delta":807,"sequence":126155,"symbol":"FCEU SI 20260615 PS"}
{"ts_recv":"2026-04-07T01:31:19.815306402Z","hd":{"ts_event":"2026-04-07T01:31:19.815294837Z","rtype":160,"publisher_id":101,"instrument_id":436},"action":"C","side":"A","price":"1.157600000","size":20,"channel_id":23,"order_id":"1775525395701400144","flags":128,"ts_in_delta":1130,"sequence":126156,"symbol":"FCEU SI 20260615 PS"}
{"ts_recv":"2026-04-07T01:31:22.120609701Z","hd":{"ts_event":"2026-04-07T01:31:22.120593653Z","rtype":160,"publisher_id":101,"instrument_id":436},"action":"C","side":"B","price":"1.157100000","size":20,"channel_id":23,"order_id":"10998897247437322327","flags":128,"ts_in_delta":1043,"sequence":126185,"symbol":"FCEU SI 20260615 PS"}
{"ts_recv":"2026-04-07T01:31:22.190166442Z","hd":{"ts_event":"2026-04-07T01:31:22.190150455Z","rtype":160,"publisher_id":101,"instrument_id":436},"action":"A","side":"B","price":"1.157000000","size":20,"channel_id":23,"order_id":"10998897519044932702","flags":128,"ts_in_delta":962,"sequence":126197,"symbol":"FCEU SI 20260615 PS"}
{"ts_recv":"2026-04-07T01:31:32.566910657Z","hd":{"ts_event":"2026-04-07T01:31:32.566884937Z","rtype":160,"publisher_id":101,"instrument_id":436},"action":"A","side":"B","price":"1.157100000","size":20,"channel_id":23,"order_id":"10998897529421673838","flags":128,"ts_in_delta":865,"sequence":126252,"symbol":"FCEU SI 20260615 PS"}
{"ts_recv":"2026-04-07T01:31:32.566919242Z","hd":{"ts_event":"2026-04-07T01:31:32.566907909Z","rtype":160,"publisher_id":101,"instrument_id":436},"action":"C","side":"B","price":"1.157000000","size":20,"channel_id":23,"order_id":"10998897519044932702","flags":128,"ts_in_delta":856,"sequence":126253,"symbol":"FCEU SI 20260615 PS"}
{"ts_recv":"2026-04-07T01:33:23.832180700Z","hd":{"ts_event":"2026-04-07T01:33:23.832161991Z","rtype":160,"publisher_id":101,"instrument_id":436},"action":"C","side":"A","price":"1.157500000","size":20,"channel_id":23,"order_id":"1775525479815189988","flags":128,"ts_in_delta":891,"sequence":126951,"symbol":"FCEU SI 20260615 PS"}
{"ts_recv":"2026-04-07T01:33:23.875259013Z","hd":{"ts_event":"2026-04-07T01:33:23.875242205Z","rtype":160,"publisher_id":101,"instrument_id":436},"action":"A","side":"A","price":"1.157600000","size":20,"channel_id":23,"order_id":"1775525603875248548","flags":128,"ts_in_delta":942,"sequence":126956,"symbol":"FCEU SI 20260615 PS"}
{"ts_recv":"2026-04-07T01:33:26.987449490Z","hd":{"ts_event":"2026-04-07T01:33:26.987425323Z","rtype":160,"publisher_id":101,"instrument_id":436},"action":"A","side":"B","price":"1.157200000","size":20,"channel_id":23,"order_id":"10998897643842210261","flags":128,"ts_in_delta":1439,"sequence":127001,"symbol":"FCEU SI 20260615 PS"}
{"ts_recv":"2026-04-07T01:33:26.987461324Z","hd":{"ts_event":"2026-04-07T01:33:26.987449535Z","rtype":160,"publisher_id":101,"instrument_id":436},"action":"C","side":"B","price":"1.157100000","size":20,"channel_id":23,"order_id":"10998897529421673838","flags":128,"ts_in_delta":914,"sequence":127002,"symbol":"FCEU SI 20260615 PS"}
{"ts_recv":"2026-04-07T01:33:31.986462536Z","hd":{"ts_event":"2026-04-07T01:33:31.986439213Z","rtype":160,"publisher_id":101,"instrument_id":436},"action":"C","side":"B","price":"1.157200000","size":20,"channel_id":23,"order_id":"10998897643842210261","flags":128,"ts_in_delta":1338,"sequence":127051,"symbol":"FCEU SI 20260615 PS"}
{"ts_recv":"2026-04-07T01:33:32.028823059Z","hd":{"ts_event":"2026-04-07T01:33:32.028801115Z","rtype":160,"publisher_id":101,"instrument_id":436},"action":"A","side":"B","price":"1.157100000","size":20,"channel_id":23,"order_id":"10998897648883587920","flags":128,"ts_in_delta":1379,"sequence":127052,"symbol":"FCEU SI 20260615 PS"}
{"ts_recv":"2026-04-07T01:34:11.848207969Z","hd":{"ts_event":"2026-04-07T01:34:11.848181923Z","rtype":160,"publisher_id":101,"instrument_id":436},"action":"A","side":"B","price":"1.157200000","size":20,"channel_id":23,"order_id":"10998897688702968619","flags":128,"ts_in_delta":825,"sequence":127276,"symbol":"FCEU SI 20260615 PS"}
{"ts_recv":"2026-04-07T01:34:11.848260529Z","hd":{"ts_event":"2026-04-07T01:34:11.848246603Z","rtype":160,"publisher_id":101,"instrument_id":436},"action":"C","side":"B","price":"1.157100000","size":20,"channel_id":23,"order_id":"10998897648883587920","flags":128,"ts_in_delta":831,"sequence":127277,"symbol":"FCEU SI 20260615 PS"}
{"ts_recv":"2026-04-07T01:34:34.275791641Z","hd":{"ts_event":"2026-04-07T01:34:34.275777023Z","rtype":160,"publisher_id":101,"instrument_id":436},"action":"C","side":"B","price":"1.157200000","size":20,"channel_id":23,"order_id":"10998897688702968619","flags":128,"ts_in_delta":862,"sequence":127396,"symbol":"FCEU SI 20260615 PS"}
{"ts_recv":"2026-04-07T01:34:34.318879588Z","hd":{"ts_event":"2026-04-07T01:34:34.318865495Z","rtype":160,"publisher_id":101,"instrument_id":436},"action":"A","side":"B","price":"1.157100000","size":20,"channel_id":23,"order_id":"10998897711173647392","flags":128,"ts_in_delta":844,"sequence":127409,"symbol":"FCEU SI 20260615 PS"}
{"ts_recv":"2026-04-07T01:34:51.285836060Z","hd":{"ts_event":"2026-04-07T01:34:51.285818111Z","rtype":160,"publisher_id":101,"instrument_id":436},"action":"A","side":"A","price":"1.157500000","size":20,"channel_id":23,"order_id":"1775525691285824214","flags":128,"ts_in_delta":853,"sequence":127546,"symbol":"FCEU SI 20260615 PS"}
{"ts_recv":"2026-04-07T01:34:51.285849638Z","hd":{"ts_event":"2026-04-07T01:34:51.285837439Z","rtype":160,"publisher_id":101,"instrument_id":436},"action":"C","side":"A","price":"1.157600000","size":20,"channel_id":23,"order_id":"1775525603875248548","flags":128,"ts_in_delta":830,"sequence":127547,"symbol":"FCEU SI 20260615 PS"}
{"ts_recv":"2026-04-07T01:35:31.878655070Z","hd":{"ts_event":"2026-04-07T01:35:31.878640403Z","rtype":160,"publisher_id":101,"instrument_id":436},"action":"C","side":"B","price":"1.157100000","size":20,"channel_id":23,"order_id":"10998897711173647392","flags":128,"ts_in_delta":852,"sequence":127785,"symbol":"FCEU SI 20260615 PS"}
{"ts_recv":"2026-04-07T01:35:31.943173083Z","hd":{"ts_event":"2026-04-07T01:35:31.943156003Z","rtype":160,"publisher_id":101,"instrument_id":436},"action":"A","side":"B","price":"1.157100000","size":20,"channel_id":23,"order_id":"10998897768797937758","flags":128,"ts_in_delta":1310,"sequence":127793,"symbol":"FCEU SI 20260615 PS"}
{"ts_recv":"2026-04-07T01:35:36.942226214Z","hd":{"ts_event":"2026-04-07T01:35:36.942208327Z","rtype":160,"publisher_id":101,"instrument_id":436},"action":"C","side":"B","price":"1.157100000","size":20,"channel_id":23,"order_id":"10998897768797937758","flags":128,"ts_in_delta":1318,"sequence":127817,"symbol":"FCEU SI 20260615 PS"}
{"ts_recv":"2026-04-07T01:35:36.985226490Z","hd":{"ts_event":"2026-04-07T01:35:36.985205951Z","rtype":160,"publisher_id":101,"instrument_id":436},"action":"A","side":"B","price":"1.157000000","size":20,"channel_id":23,"order_id":"10998897773839992963","flags":128,"ts_in_delta":1086,"sequence":127819,"symbol":"FCEU SI 20260615 PS"}
{"ts_recv":"2026-04-07T01:36:14.031654887Z","hd":{"ts_event":"2026-04-07T01:36:14.031634001Z","rtype":160,"publisher_id":101,"instrument_id":436},"action":"A","side":"A","price":"1.157400000","size":20,"channel_id":23,"order_id":"1775525774031642943","flags":128,"ts_in_delta":792,"sequence":128097,"symbol":"FCEU SI 20260615 PS"}
{"ts_recv":"2026-04-07T01:36:14.031701733Z","hd":{"ts_event":"2026-04-07T01:36:14.031687561Z","rtype":160,"publisher_id":101,"instrument_id":436},"action":"C","side":"A","price":"1.157500000","size":20,"channel_id":23,"order_id":"1775525691285824214","flags":128,"ts_in_delta":918,"sequence":128099,"symbol":"FCEU SI 20260615 PS"}
{"ts_recv":"2026-04-07T01:36:17.774759389Z","hd":{"ts_event":"2026-04-07T01:36:17.774743901Z","rtype":160,"publisher_id":101,"instrument_id":436},"action":"C","side":"B","price":"1.157000000","size":20,"channel_id":23,"order_id":"10998897773839992963","flags":128,"ts_in_delta":1053,"sequence":128133,"symbol":"FCEU SI 20260615 PS"}
{"ts_recv":"2026-04-07T01:36:17.818276178Z","hd":{"ts_event":"2026-04-07T01:36:17.818259767Z","rtype":160,"publisher_id":101,"instrument_id":436},"action":"A","side":"B","price":"1.156900000","size":20,"channel_id":23,"order_id":"10998897814673041793","flags":128,"ts_in_delta":893,"sequence":128138,"symbol":"FCEU SI 20260615 PS"}
{"ts_recv":"2026-04-07T01:36:19.360299889Z","hd":{"ts_event":"2026-04-07T01:36:19.360284901Z","rtype":160,"publisher_id":101,"instrument_id":436},"action":"A","side":"B","price":"1.157000000","size":20,"channel_id":23,"order_id":"10998897816215066378","flags":128,"ts_in_delta":824,"sequence":128156,"symbol":"FCEU SI 20260615 PS"}
{"ts_recv":"2026-04-07T01:36:19.360330823Z","hd":{"ts_event":"2026-04-07T01:36:19.360317369Z","rtype":160,"publisher_id":101,"instrument_id":436},"action":"C","side":"B","price":"1.156900000","size":20,"channel_id":23,"order_id":"10998897814673041793","flags":128,"ts_in_delta":862,"sequence":128157,"symbol":"FCEU SI 20260615 PS"}
{"ts_recv":"2026-04-07T01:36:40.571031677Z","hd":{"ts_event":"2026-04-07T01:36:40.571017225Z","rtype":160,"publisher_id":101,"instrument_id":436},"action":"C","side":"A","price":"1.157400000","size":20,"channel_id":23,"order_id":"1775525774031642943","flags":128,"ts_in_delta":869,"sequence":128352,"symbol":"FCEU SI 20260615 PS"}
{"ts_recv":"2026-04-07T01:36:40.613748859Z","hd":{"ts_event":"2026-04-07T01:36:40.613732075Z","rtype":160,"publisher_id":101,"instrument_id":436},"action":"A","side":"A","price":"1.157500000","size":20,"channel_id":23,"order_id":"1775525800613738328","flags":128,"ts_in_delta":816,"sequence":128355,"symbol":"FCEU SI 20260615 PS"}
{"ts_recv":"2026-04-07T01:36:43.833518272Z","hd":{"ts_event":"2026-04-07T01:36:43.833503289Z","rtype":160,"publisher_id":101,"instrument_id":436},"action":"A","side":"A","price":"1.157400000","size":20,"channel_id":23,"order_id":"1775525803833509023","flags":128,"ts_in_delta":914,"sequence":128402,"symbol":"FCEU SI 20260615 PS"}
{"ts_recv":"2026-04-07T01:36:43.833583618Z","hd":{"ts_event":"2026-04-07T01:36:43.833570873Z","rtype":160,"publisher_id":101,"instrument_id":436},"action":"C","side":"A","price":"1.157500000","size":20,"channel_id":23,"order_id":"1775525800613738328","flags":128,"ts_in_delta":934,"sequence":128403,"symbol":"FCEU SI 20260615 PS"}
{"ts_recv":"2026-04-07T01:36:54.242106202Z","hd":{"ts_event":"2026-04-07T01:36:54.242093059Z","rtype":160,"publisher_id":101,"instrument_id":436},"action":"C","side":"A","price":"1.157400000","size":20,"channel_id":23,"order_id":"1775525803833509023","flags":128,"ts_in_delta":861,"sequence":128462,"symbol":"FCEU SI 20260615 PS"}
{"ts_recv":"2026-04-07T01:36:54.285138825Z","hd":{"ts_event":"2026-04-07T01:36:54.285122055Z","rtype":160,"publisher_id":101,"instrument_id":436},"action":"A","side":"A","price":"1.157500000","size":20,"channel_id":23,"order_id":"1775525814285128057","flags":128,"ts_in_delta":1040,"sequence":128467,"symbol":"FCEU SI 20260615 PS"}
{"ts_recv":"2026-04-07T01:37:02.958430613Z","hd":{"ts_event":"2026-04-07T01:37:02.958415195Z","rtype":160,"publisher_id":101,"instrument_id":436},"action":"A","side":"A","price":"1.157400000","size":20,"channel_id":23,"order_id":"1775525822958421084","flags":128,"ts_in_delta":872,"sequence":128552,"symbol":"FCEU SI 20260615 PS"}
{"ts_recv":"2026-04-07T01:37:02.958492849Z","hd":{"ts_event":"2026-04-07T01:37:02.958481819Z","rtype":160,"publisher_id":101,"instrument_id":436},"action":"C","side":"A","price":"1.157500000","size":20,"channel_id":23,"order_id":"1775525814285128057","flags":128,"ts_in_delta":903,"sequence":128553,"symbol":"FCEU SI 20260615 PS"}
{"ts_recv":"2026-04-07T01:37:03.140247592Z","hd":{"ts_event":"2026-04-07T01:37:03.140234181Z","rtype":160,"publisher_id":101,"instrument_id":436},"action":"C","side":"B","price":"1.157000000","size":20,"channel_id":23,"order_id":"10998897816215066378","flags":128,"ts_in_delta":892,"sequence":128568,"symbol":"FCEU SI 20260615 PS"}
{"ts_recv":"2026-04-07T01:37:03.220143271Z","hd":{"ts_event":"2026-04-07T01:37:03.220127649Z","rtype":160,"publisher_id":101,"instrument_id":436},"action":"A","side":"B","price":"1.157000000","size":20,"channel_id":23,"order_id":"10998897860074909507","flags":128,"ts_in_delta":1049,"sequence":128575,"symbol":"FCEU SI 20260615 PS"}
{"ts_recv":"2026-04-07T01:37:08.219351941Z","hd":{"ts_event":"2026-04-07T01:37:08.219338245Z","rtype":160,"publisher_id":101,"instrument_id":436},"action":"C","side":"B","price":"1.157000000","size":20,"channel_id":23,"order_id":"10998897860074909507","flags":128,"ts_in_delta":846,"sequence":128663,"symbol":"FCEU SI 20260615 PS"}
{"ts_recv":"2026-04-07T01:37:08.262492194Z","hd":{"ts_event":"2026-04-07T01:37:08.262476241Z","rtype":160,"publisher_id":101,"instrument_id":436},"action":"A","side":"B","price":"1.156900000","size":20,"channel_id":23,"order_id":"10998897865117258373","flags":128,"ts_in_delta":929,"sequence":128668,"symbol":"FCEU SI 20260615 PS"}
{"ts_recv":"2026-04-07T01:37:10.515776776Z","hd":{"ts_event":"2026-04-07T01:37:10.515761399Z","rtype":160,"publisher_id":101,"instrument_id":436},"action":"A","side":"B","price":"1.157000000","size":20,"channel_id":23,"order_id":"10998897867370543335","flags":128,"ts_in_delta":903,"sequence":128690,"symbol":"FCEU SI 20260615 PS"}
{"ts_recv":"2026-04-07T01:37:10.515854632Z","hd":{"ts_event":"2026-04-07T01:37:10.515842083Z","rtype":160,"publisher_id":101,"instrument_id":436},"action":"C","side":"B","price":"1.156900000","size":20,"channel_id":23,"order_id":"10998897865117258373","flags":128,"ts_in_delta":688,"sequence":128692,"symbol":"FCEU SI 20260615 PS"}
{"ts_recv":"2026-04-07T01:37:19.840982941Z","hd":{"ts_event":"2026-04-07T01:37:19.840970443Z","rtype":160,"publisher_id":101,"instrument_id":436},"action":"C","side":"B","price":"1.157000000","size":20,"channel_id":23,"order_id":"10998897867370543335","flags":128,"ts_in_delta":841,"sequence":128764,"symbol":"FCEU SI 20260615 PS"}
{"ts_recv":"2026-04-07T01:37:19.884303570Z","hd":{"ts_event":"2026-04-07T01:37:19.884290889Z","rtype":160,"publisher_id":101,"instrument_id":436},"action":"A","side":"B","price":"1.156900000","size":20,"channel_id":23,"order_id":"10998897876739072540","flags":128,"ts_in_delta":804,"sequence":128774,"symbol":"FCEU SI 20260615 PS"}
{"ts_recv":"2026-04-07T01:37:24.850356609Z","hd":{"ts_event":"2026-04-07T01:37:24.850340779Z","rtype":160,"publisher_id":101,"instrument_id":436},"action":"A","side":"A","price":"1.157300000","size":20,"channel_id":23,"order_id":"1775525844850346928","flags":128,"ts_in_delta":877,"sequence":128856,"symbol":"FCEU SI 20260615 PS"}
{"ts_recv":"2026-04-07T01:37:24.850534492Z","hd":{"ts_event":"2026-04-07T01:37:24.850523295Z","rtype":160,"publisher_id":101,"instrument_id":436},"action":"C","side":"A","price":"1.157400000","size":20,"channel_id":23,"order_id":"1775525822958421084","flags":128,"ts_in_delta":845,"sequence":128858,"symbol":"FCEU SI 20260615 PS"}
{"ts_recv":"2026-04-07T01:37:32.345072757Z","hd":{"ts_event":"2026-04-07T01:37:32.345058343Z","rtype":160,"publisher_id":101,"instrument_id":436},"action":"C","side":"B","price":"1.156900000","size":20,"channel_id":23,"order_id":"10998897876739072540","flags":128,"ts_in_delta":2935,"sequence":128909,"symbol":"FCEU SI 20260615 PS"}
{"ts_recv":"2026-04-07T01:37:32.388356534Z","hd":{"ts_event":"2026-04-07T01:37:32.388342369Z","rtype":160,"publisher_id":101,"instrument_id":436},"action":"A","side":"B","price":"1.156800000","size":20,"channel_id":23,"order_id":"10998897889243124244","flags":128,"ts_in_delta":810,"sequence":128918,"symbol":"FCEU SI 20260615 PS"}
{"ts_recv":"2026-04-07T01:37:57.412764939Z","hd":{"ts_event":"2026-04-07T01:37:57.412747227Z","rtype":160,"publisher_id":101,"instrument_id":436},"action":"A","side":"B","price":"1.156900000","size":20,"channel_id":23,"order_id":"10998897914267529139","flags":128,"ts_in_delta":960,"sequence":129231,"symbol":"FCEU SI 20260615 PS"}
{"ts_recv":"2026-04-07T01:37:57.412801648Z","hd":{"ts_event":"2026-04-07T01:37:57.412788199Z","rtype":160,"publisher_id":101,"instrument_id":436},"action":"C","side":"B","price":"1.156800000","size":20,"channel_id":23,"order_id":"10998897889243124244","flags":128,"ts_in_delta":923,"sequence":129232,"symbol":"FCEU SI 20260615 PS"}
{"ts_recv":"2026-04-07T01:38:02.717362079Z","hd":{"ts_event":"2026-04-07T01:38:02.717349701Z","rtype":160,"publisher_id":101,"instrument_id":436},"action":"C","side":"B","price":"1.156900000","size":20,"channel_id":23,"order_id":"10998897914267529139","flags":128,"ts_in_delta":1079,"sequence":129285,"symbol":"FCEU SI 20260615 PS"}
{"ts_recv":"2026-04-07T01:38:02.760326205Z","hd":{"ts_event":"2026-04-07T01:38:02.760310485Z","rtype":160,"publisher_id":101,"instrument_id":436},"action":"A","side":"B","price":"1.156800000","size":20,"channel_id":23,"order_id":"10998897919615092628","flags":128,"ts_in_delta":870,"sequence":129288,"symbol":"FCEU SI 20260615 PS"}
{"ts_recv":"2026-04-07T01:38:03.427930005Z","hd":{"ts_event":"2026-04-07T01:38:03.427914351Z","rtype":160,"publisher_id":101,"instrument_id":436},"action":"A","side":"B","price":"1.156900000","size":20,"channel_id":23,"order_id":"10998897920282696350","flags":128,"ts_in_delta":875,"sequence":129308,"symbol":"FCEU SI 20260615 PS"}
{"ts_recv":"2026-04-07T01:38:03.427982188Z","hd":{"ts_event":"2026-04-07T01:38:03.427969783Z","rtype":160,"publisher_id":101,"instrument_id":436},"action":"C","side":"B","price":"1.156800000","size":20,"channel_id":23,"order_id":"10998897919615092628","flags":128,"ts_in_delta":834,"sequence":129310,"symbol":"FCEU SI 20260615 PS"}
{"ts_recv":"2026-04-07T01:38:11.323692836Z","hd":{"ts_event":"2026-04-07T01:38:11.323671401Z","rtype":160,"publisher_id":101,"instrument_id":436},"action":"C","side":"B","price":"1.156900000","size":20,"channel_id":23,"order_id":"10998897920282696350","flags":128,"ts_in_delta":1405,"sequence":129387,"symbol":"FCEU SI 20260615 PS"}
{"ts_recv":"2026-04-07T01:38:11.366772537Z","hd":{"ts_event":"2026-04-07T01:38:11.366758535Z","rtype":160,"publisher_id":101,"instrument_id":436},"action":"A","side":"B","price":"1.156800000","size":20,"channel_id":23,"order_id":"10998897928221540764","flags":128,"ts_in_delta":859,"sequence":129390,"symbol":"FCEU SI 20260615 PS"}
{"ts_recv":"2026-04-07T01:38:25.766249319Z","hd":{"ts_event":"2026-04-07T01:38:25.766223449Z","rtype":160,"publisher_id":101,"instrument_id":436},"action":"A","side":"B","price":"1.156900000","size":20,"channel_id":23,"order_id":"10998897942621013499","flags":128,"ts_in_delta":1410,"sequence":129515,"symbol":"FCEU SI 20260615 PS"}
{"ts_recv":"2026-04-07T01:38:25.766256384Z","hd":{"ts_event":"2026-04-07T01:38:25.766242369Z","rtype":160,"publisher_id":101,"instrument_id":436},"action":"C","side":"B","price":"1.156800000","size":20,"channel_id":23,"order_id":"10998897928221540764","flags":128,"ts_in_delta":810,"sequence":129516,"symbol":"FCEU SI 20260615 PS"}
{"ts_recv":"2026-04-07T01:38:33.265293223Z","hd":{"ts_event":"2026-04-07T01:38:33.265280697Z","rtype":160,"publisher_id":101,"instrument_id":436},"action":"C","side":"B","price":"1.156900000","size":20,"channel_id":23,"order_id":"10998897942621013499","flags":128,"ts_in_delta":895,"sequence":129569,"symbol":"FCEU SI 20260615 PS"}
{"ts_recv":"2026-04-07T01:38:33.308458064Z","hd":{"ts_event":"2026-04-07T01:38:33.308443083Z","rtype":160,"publisher_id":101,"instrument_id":436},"action":"A","side":"B","price":"1.156800000","size":20,"channel_id":23,"order_id":"10998897950163224897","flags":128,"ts_in_delta":1142,"sequence":129575,"symbol":"FCEU SI 20260615 PS"}
{"ts_recv":"2026-04-07T01:38:38.238440049Z","hd":{"ts_event":"2026-04-07T01:38:38.238421411Z","rtype":160,"publisher_id":101,"instrument_id":436},"action":"A","side":"A","price":"1.157200000","size":20,"channel_id":23,"order_id":"1775525918238427694","flags":128,"ts_in_delta":2402,"sequence":129657,"symbol":"FCEU SI 20260615 PS"}
{"ts_recv":"2026-04-07T01:38:38.238506073Z","hd":{"ts_event":"2026-04-07T01:38:38.238492759Z","rtype":160,"publisher_id":101,"instrument_id":436},"action":"C","side":"A","price":"1.157300000","size":20,"channel_id":23,"order_id":"1775525844850346928","flags":128,"ts_in_delta":889,"sequence":129658,"symbol":"FCEU SI 20260615 PS"}
{"ts_recv":"2026-04-07T01:38:38.577081132Z","hd":{"ts_event":"2026-04-07T01:38:38.577067547Z","rtype":160,"publisher_id":101,"instrument_id":436},"action":"C","side":"B","price":"1.156800000","size":20,"channel_id":23,"order_id":"10998897950163224897","flags":128,"ts_in_delta":909,"sequence":129684,"symbol":"FCEU SI 20260615 PS"}
{"ts_recv":"2026-04-07T01:38:38.619574456Z","hd":{"ts_event":"2026-04-07T01:38:38.619558537Z","rtype":160,"publisher_id":101,"instrument_id":436},"action":"A","side":"B","price":"1.156700000","size":20,"channel_id":23,"order_id":"10998897955474340426","flags":128,"ts_in_delta":728,"sequence":129691,"symbol":"FCEU SI 20260615 PS"}
{"ts_recv":"2026-04-07T01:38:42.018559548Z","hd":{"ts_event":"2026-04-07T01:38:42.018544137Z","rtype":160,"publisher_id":101,"instrument_id":436},"action":"A","side":"B","price":"1.156800000","size":20,"channel_id":23,"order_id":"10998897958873325957","flags":128,"ts_in_delta":1185,"sequence":129774,"symbol":"FCEU SI 20260615 PS"}
{"ts_recv":"2026-04-07T01:38:42.018592049Z","hd":{"ts_event":"2026-04-07T01:38:42.018578813Z","rtype":160,"publisher_id":101,"instrument_id":436},"action":"C","side":"B","price":"1.156700000","size":20,"channel_id":23,"order_id":"10998897955474340426","flags":128,"ts_in_delta":1201,"sequence":129775,"symbol":"FCEU SI 20260615 PS"}
{"ts_recv":"2026-04-07T01:38:47.018064901Z","hd":{"ts_event":"2026-04-07T01:38:47.018042537Z","rtype":160,"publisher_id":101,"instrument_id":436},"action":"C","side":"B","price":"1.156800000","size":20,"channel_id":23,"order_id":"10998897958873325957","flags":128,"ts_in_delta":1315,"sequence":129821,"symbol":"FCEU SI 20260615 PS"}
{"ts_recv":"2026-04-07T01:38:47.060401356Z","hd":{"ts_event":"2026-04-07T01:38:47.060380809Z","rtype":160,"publisher_id":101,"instrument_id":436},"action":"A","side":"B","price":"1.156700000","size":20,"channel_id":23,"order_id":"10998897963915167591","flags":128,"ts_in_delta":910,"sequence":129822,"symbol":"FCEU SI 20260615 PS"}
{"ts_recv":"2026-04-07T01:39:02.168861615Z","hd":{"ts_event":"2026-04-07T01:39:02.168844837Z","rtype":160,"publisher_id":101,"instrument_id":436},"action":"A","side":"A","price":"1.157100000","size":20,"channel_id":23,"order_id":"1775525942168850817","flags":128,"ts_in_delta":1046,"sequence":130005,"symbol":"FCEU SI 20260615 PS"}
{"ts_recv":"2026-04-07T01:39:02.168945385Z","hd":{"ts_event":"2026-04-07T01:39:02.168931065Z","rtype":160,"publisher_id":101,"instrument_id":436},"action":"C","side":"A","price":"1.157200000","size":20,"channel_id":23,"order_id":"1775525918238427694","flags":128,"ts_in_delta":846,"sequence":130007,"symbol":"FCEU SI 20260615 PS"}
{"ts_recv":"2026-04-07T01:39:03.181040258Z","hd":{"ts_event":"2026-04-07T01:39:03.181027307Z","rtype":160,"publisher_id":101,"instrument_id":436},"action":"C","side":"B","price":"1.156700000","size":20,"channel_id":23,"order_id":"10998897963915167591","flags":128,"ts_in_delta":835,"sequence":130025,"symbol":"FCEU SI 20260615 PS"}
{"ts_recv":"2026-04-07T01:39:03.223404786Z","hd":{"ts_event":"2026-04-07T01:39:03.223388723Z","rtype":160,"publisher_id":101,"instrument_id":436},"action":"A","side":"B","price":"1.156600000","size":20,"channel_id":23,"order_id":"10998897980078170612","flags":128,"ts_in_delta":811,"sequence":130036,"symbol":"FCEU SI 20260615 PS"}
{"ts_recv":"2026-04-07T01:39:22.310690699Z","hd":{"ts_event":"2026-04-07T01:39:22.310674493Z","rtype":160,"publisher_id":101,"instrument_id":436},"action":"A","side":"B","price":"1.156700000","size":20,"channel_id":23,"order_id":"10998897999165456488","flags":128,"ts_in_delta":953,"sequence":130238,"symbol":"FCEU SI 20260615 PS"}
{"ts_recv":"2026-04-07T01:39:22.310721855Z","hd":{"ts_event":"2026-04-07T01:39:22.310708547Z","rtype":160,"publisher_id":101,"instrument_id":436},"action":"C","side":"B","price":"1.156600000","size":20,"channel_id":23,"order_id":"10998897980078170612","flags":128,"ts_in_delta":945,"sequence":130239,"symbol":"FCEU SI 20260615 PS"}
{"ts_recv":"2026-04-07T01:39:22.689095224Z","hd":{"ts_event":"2026-04-07T01:39:22.689082323Z","rtype":160,"publisher_id":101,"instrument_id":436},"action":"C","side":"B","price":"1.156700000","size":20,"channel_id":23,"order_id":"10998897999165456488","flags":128,"ts_in_delta":793,"sequence":130270,"symbol":"FCEU SI 20260615 PS"}
{"ts_recv":"2026-04-07T01:39:22.721315386Z","hd":{"ts_event":"2026-04-07T01:39:22.721299143Z","rtype":160,"publisher_id":101,"instrument_id":436},"action":"A","side":"A","price":"1.157000000","size":20,"channel_id":23,"order_id":"1775525962721305200","flags":128,"ts_in_delta":1127,"sequence":130277,"symbol":"FCEU SI 20260615 PS"}
{"ts_recv":"2026-04-07T01:39:22.722012499Z","hd":{"ts_event":"2026-04-07T01:39:22.721999401Z","rtype":160,"publisher_id":101,"instrument_id":436},"action":"C","side":"A","price":"1.157100000","size":20,"channel_id":23,"order_id":"1775525942168850817","flags":128,"ts_in_delta":907,"sequence":130278,"symbol":"FCEU SI 20260615 PS"}
{"ts_recv":"2026-04-07T01:39:22.732240023Z","hd":{"ts_event":"2026-04-07T01:39:22.732224319Z","rtype":160,"publisher_id":101,"instrument_id":436},"action":"A","side":"B","price":"1.156500000","size":20,"channel_id":23,"order_id":"10998897999587005948","flags":128,"ts_in_delta":1263,"sequence":130280,"symbol":"FCEU SI 20260615 PS"}
{"ts_recv":"2026-04-07T01:39:22.790442517Z","hd":{"ts_event":"2026-04-07T01:39:22.790429381Z","rtype":160,"publisher_id":101,"instrument_id":436},"action":"A","side":"B","price":"1.156600000","size":20,"channel_id":23,"order_id":"10998897999645211075","flags":128,"ts_in_delta":935,"sequence":130298,"symbol":"FCEU SI 20260615 PS"}
{"ts_recv":"2026-04-07T01:39:22.790590880Z","hd":{"ts_event":"2026-04-07T01:39:22.790579675Z","rtype":160,"publisher_id":101,"instrument_id":436},"action":"C","side":"B","price":"1.156500000","size":20,"channel_id":23,"order_id":"10998897999587005948","flags":128,"ts_in_delta":967,"sequence":130301,"symbol":"FCEU SI 20260615 PS"}
{"ts_recv":"2026-04-07T01:39:40.429582943Z","hd":{"ts_event":"2026-04-07T01:39:40.429563871Z","rtype":160,"publisher_id":101,"instrument_id":436},"action":"C","side":"A","price":"1.157000000","size":20,"channel_id":23,"order_id":"1775525962721305200","flags":128,"ts_in_delta":1430,"sequence":130502,"symbol":"FCEU SI 20260615 PS"}
{"ts_recv":"2026-04-07T01:39:40.472144848Z","hd":{"ts_event":"2026-04-07T01:39:40.472127897Z","rtype":160,"publisher_id":101,"instrument_id":436},"action":"A","side":"A","price":"1.157100000","size":20,"channel_id":23,"order_id":"1775525980472134255","flags":128,"ts_in_delta":759,"sequence":130505,"symbol":"FCEU SI 20260615 PS"}
{"ts_recv":"2026-04-07T01:39:58.192780997Z","hd":{"ts_event":"2026-04-07T01:39:58.192763915Z","rtype":160,"publisher_id":101,"instrument_id":436},"action":"A","side":"B","price":"1.156700000","size":20,"channel_id":23,"order_id":"10998898035047545873","flags":128,"ts_in_delta":810,"sequence":130745,"symbol":"FCEU SI 20260615 PS"}
{"ts_recv":"2026-04-07T01:39:58.192880225Z","hd":{"ts_event":"2026-04-07T01:39:58.192866253Z","rtype":160,"publisher_id":101,"instrument_id":436},"action":"C","side":"B","price":"1.156600000","size":20,"channel_id":23,"order_id":"10998897999645211075","flags":128,"ts_in_delta":793,"sequence":130746,"symbol":"FCEU SI 20260615 PS"}
{"ts_recv":"2026-04-07T01:40:07.196295139Z","hd":{"ts_event":"2026-04-07T01:40:07.196281521Z","rtype":160,"publisher_id":101,"instrument_id":436},"action":"C","side":"B","price":"1.156700000","size":20,"channel_id":23,"order_id":"10998898035047545873","flags":128,"ts_in_delta":806,"sequence":130936,"symbol":"FCEU SI 20260615 PS"}
{"ts_recv":"2026-04-07T01:40:07.240065231Z","hd":{"ts_event":"2026-04-07T01:40:07.240051675Z","rtype":160,"publisher_id":101,"instrument_id":436},"action":"A","side":"B","price":"1.156600000","size":20,"channel_id":23,"order_id":"10998898044094833305","flags":128,"ts_in_delta":980,"sequence":130942,"symbol":"FCEU SI 20260615 PS"}
{"ts_recv":"2026-04-07T01:40:08.022688240Z","hd":{"ts_event":"2026-04-07T01:40:08.022672435Z","rtype":160,"publisher_id":101,"instrument_id":436},"action":"A","side":"A","price":"1.157000000","size":20,"channel_id":23,"order_id":"1775526008022678274","flags":128,"ts_in_delta":737,"sequence":130969,"symbol":"FCEU SI 20260615 PS"}
{"ts_recv":"2026-04-07T01:40:08.022735985Z","hd":{"ts_event":"2026-04-07T01:40:08.022722695Z","rtype":160,"publisher_id":101,"instrument_id":436},"action":"C","side":"A","price":"1.157100000","size":20,"channel_id":23,"order_id":"1775525980472134255","flags":128,"ts_in_delta":778,"sequence":130971,"symbol":"FCEU SI 20260615 PS"}
{"ts_recv":"2026-04-07T01:40:15.261111897Z","hd":{"ts_event":"2026-04-07T01:40:15.261095045Z","rtype":160,"publisher_id":101,"instrument_id":436},"action":"C","side":"B","price":"1.156600000","size":20,"channel_id":23,"order_id":"10998898044094833305","flags":128,"ts_in_delta":5164,"sequence":131066,"symbol":"FCEU SI 20260615 PS"}
{"ts_recv":"2026-04-07T01:40:15.304543753Z","hd":{"ts_event":"2026-04-07T01:40:15.304527981Z","rtype":160,"publisher_id":101,"instrument_id":436},"action":"A","side":"B","price":"1.156500000","size":20,"channel_id":23,"order_id":"10998898052159309850","flags":128,"ts_in_delta":819,"sequence":131071,"symbol":"FCEU SI 20260615 PS"}
{"ts_recv":"2026-04-07T01:40:30.080152540Z","hd":{"ts_event":"2026-04-07T01:40:30.080136891Z","rtype":160,"publisher_id":101,"instrument_id":436},"action":"A","side":"B","price":"1.156600000","size":20,"channel_id":23,"order_id":"10998898066934918756","flags":128,"ts_in_delta":1277,"sequence":131282,"symbol":"FCEU SI 20260615 PS"}
{"ts_recv":"2026-04-07T01:40:30.080202457Z","hd":{"ts_event":"2026-04-07T01:40:30.080189583Z","rtype":160,"publisher_id":101,"instrument_id":436},"action":"C","side":"B","price":"1.156500000","size":20,"channel_id":23,"order_id":"10998898052159309850","flags":128,"ts_in_delta":1066,"sequence":131284,"symbol":"FCEU SI 20260615 PS"}
{"ts_recv":"2026-04-07T01:40:55.065019245Z","hd":{"ts_event":"2026-04-07T01:40:55.065004439Z","rtype":160,"publisher_id":101,"instrument_id":436},"action":"C","side":"B","price":"1.156600000","size":20,"channel_id":23,"order_id":"10998898066934918756","flags":128,"ts_in_delta":817,"sequence":131548,"symbol":"FCEU SI 20260615 PS"}
{"ts_recv":"2026-04-07T01:40:55.229662384Z","hd":{"ts_event":"2026-04-07T01:40:55.229644901Z","rtype":160,"publisher_id":101,"instrument_id":436},"action":"A","side":"B","price":"1.156600000","size":20,"channel_id":23,"order_id":"10998898092084426856","flags":128,"ts_in_delta":1025,"sequence":131553,"symbol":"FCEU SI 20260615 PS"}
{"ts_recv":"2026-04-07T01:41:00.537424674Z","hd":{"ts_event":"2026-04-07T01:41:00.537410835Z","rtype":160,"publisher_id":101,"instrument_id":436},"action":"C","side":"B","price":"1.156600000","size":20,"channel_id":23,"order_id":"10998898092084426856","flags":128,"ts_in_delta":901,"sequence":131596,"symbol":"FCEU SI 20260615 PS"}
{"ts_recv":"2026-04-07T01:41:00.581513342Z","hd":{"ts_event":"2026-04-07T01:41:00.581499831Z","rtype":160,"publisher_id":101,"instrument_id":436},"action":"A","side":"B","price":"1.156500000","size":20,"channel_id":23,"order_id":"10998898097436281552","flags":128,"ts_in_delta":861,"sequence":131617,"symbol":"FCEU SI 20260615 PS"}
{"ts_recv":"2026-04-07T01:41:06.549419491Z","hd":{"ts_event":"2026-04-07T01:41:06.549404493Z","rtype":160,"publisher_id":101,"instrument_id":436},"action":"A","side":"B","price":"1.156600000","size":20,"channel_id":23,"order_id":"10998898103404186460","flags":128,"ts_in_delta":1170,"sequence":131734,"symbol":"FCEU SI 20260615 PS"}
{"ts_recv":"2026-04-07T01:41:06.549436923Z","hd":{"ts_event":"2026-04-07T01:41:06.549424263Z","rtype":160,"publisher_id":101,"instrument_id":436},"action":"C","side":"B","price":"1.156500000","size":20,"channel_id":23,"order_id":"10998898097436281552","flags":128,"ts_in_delta":858,"sequence":131735,"symbol":"FCEU SI 20260615 PS"}
{"ts_recv":"2026-04-07T01:41:32.590211278Z","hd":{"ts_event":"2026-04-07T01:41:32.590196691Z","rtype":160,"publisher_id":101,"instrument_id":436},"action":"C","side":"B","price":"1.156600000","size":20,"channel_id":23,"order_id":"10998898103404186460","flags":128,"ts_in_delta":853,"sequence":132029,"symbol":"FCEU SI 20260615 PS"}
{"ts_recv":"2026-04-07T01:41:32.654551039Z","hd":{"ts_event":"2026-04-07T01:41:32.654532711Z","rtype":160,"publisher_id":101,"instrument_id":436},"action":"A","side":"B","price":"1.156600000","size":20,"channel_id":23,"order_id":"10998898129509314837","flags":128,"ts_in_delta":1306,"sequence":132030,"symbol":"FCEU SI 20260615 PS"}
{"ts_recv":"2026-04-07T01:41:56.760498946Z","hd":{"ts_event":"2026-04-07T01:41:56.760478283Z","rtype":160,"publisher_id":101,"instrument_id":436},"action":"C","side":"B","price":"1.156600000","size":20,"channel_id":23,"order_id":"10998898129509314837","flags":128,"ts_in_delta":1401,"sequence":132210,"symbol":"FCEU SI 20260615 PS"}
{"ts_recv":"2026-04-07T01:41:56.803537775Z","hd":{"ts_event":"2026-04-07T01:41:56.803524233Z","rtype":160,"publisher_id":101,"instrument_id":436},"action":"A","side":"B","price":"1.156500000","size":20,"channel_id":23,"order_id":"10998898153658306027","flags":128,"ts_in_delta":1055,"sequence":132215,"symbol":"FCEU SI 20260615 PS"}
{"ts_recv":"2026-04-07T01:42:14.988207426Z","hd":{"ts_event":"2026-04-07T01:42:14.988190595Z","rtype":160,"publisher_id":101,"instrument_id":436},"action":"A","side":"B","price":"1.156600000","size":20,"channel_id":23,"order_id":"10998898171842972799","flags":128,"ts_in_delta":863,"sequence":132412,"symbol":"FCEU SI 20260615 PS"}
{"ts_recv":"2026-04-07T01:42:14.988222501Z","hd":{"ts_event":"2026-04-07T01:42:14.988209219Z","rtype":160,"publisher_id":101,"instrument_id":436},"action":"C","side":"B","price":"1.156500000","size":20,"channel_id":23,"order_id":"10998898153658306027","flags":128,"ts_in_delta":832,"sequence":132413,"symbol":"FCEU SI 20260615 PS"}
{"ts_recv":"2026-04-07T01:42:39.901020083Z","hd":{"ts_event":"2026-04-07T01:42:39.901004927Z","rtype":160,"publisher_id":101,"instrument_id":436},"action":"C","side":"B","price":"1.156600000","size":20,"channel_id":23,"order_id":"10998898171842972799","flags":128,"ts_in_delta":975,"sequence":132603,"symbol":"FCEU SI 20260615 PS"}
{"ts_recv":"2026-04-07T01:42:39.944682948Z","hd":{"ts_event":"2026-04-07T01:42:39.944666457Z","rtype":160,"publisher_id":101,"instrument_id":436},"action":"A","side":"B","price":"1.156500000","size":20,"channel_id":23,"order_id":"10998898196799448363","flags":128,"ts_in_delta":889,"sequence":132606,"symbol":"FCEU SI 20260615 PS"}
{"ts_recv":"2026-04-07T01:42:56.882597896Z","hd":{"ts_event":"2026-04-07T01:42:56.882579045Z","rtype":160,"publisher_id":101,"instrument_id":436},"action":"A","side":"A","price":"1.156900000","size":20,"channel_id":23,"order_id":"1775526176882585385","flags":128,"ts_in_delta":872,"sequence":132804,"symbol":"FCEU SI 20260615 PS"}
{"ts_recv":"2026-04-07T01:42:56.883237372Z","hd":{"ts_event":"2026-04-07T01:42:56.883220829Z","rtype":160,"publisher_id":101,"instrument_id":436},"action":"C","side":"A","price":"1.157000000","size":20,"channel_id":23,"order_id":"1775526008022678274","flags":128,"ts_in_delta":853,"sequence":132805,"symbol":"FCEU SI 20260615 PS"}
{"ts_recv":"2026-04-07T01:43:03.315679423Z","hd":{"ts_event":"2026-04-07T01:43:03.315665251Z","rtype":160,"publisher_id":101,"instrument_id":436},"action":"C","side":"A","price":"1.156900000","size":20,"channel_id":23,"order_id":"1775526176882585385","flags":128,"ts_in_delta":985,"sequence":132907,"symbol":"FCEU SI 20260615 PS"}
{"ts_recv":"2026-04-07T01:43:03.358554569Z","hd":{"ts_event":"2026-04-07T01:43:03.358538929Z","rtype":160,"publisher_id":101,"instrument_id":436},"action":"A","side":"A","price":"1.157000000","size":20,"channel_id":23,"order_id":"1775526183358545272","flags":128,"ts_in_delta":922,"sequence":132909,"symbol":"FCEU SI 20260615 PS"}
{"ts_recv":"2026-04-07T01:43:19.422901898Z","hd":{"ts_event":"2026-04-07T01:43:19.422884071Z","rtype":160,"publisher_id":101,"instrument_id":436},"action":"A","side":"B","price":"1.156600000","size":20,"channel_id":23,"order_id":"10998898236277666122","flags":128,"ts_in_delta":1026,"sequence":133016,"symbol":"FCEU SI 20260615 PS"}
{"ts_recv":"2026-04-07T01:43:19.422977643Z","hd":{"ts_event":"2026-04-07T01:43:19.422964429Z","rtype":160,"publisher_id":101,"instrument_id":436},"action":"C","side":"B","price":"1.156500000","size":20,"channel_id":23,"order_id":"10998898196799448363","flags":128,"ts_in_delta":860,"sequence":133017,"symbol":"FCEU SI 20260615 PS"}
{"ts_recv":"2026-04-07T01:43:25.627246945Z","hd":{"ts_event":"2026-04-07T01:43:25.627228303Z","rtype":160,"publisher_id":101,"instrument_id":436},"action":"C","side":"B","price":"1.156600000","size":20,"channel_id":23,"order_id":"10998898236277666122","flags":128,"ts_in_delta":1224,"sequence":133083,"symbol":"FCEU SI 20260615 PS"}
{"ts_recv":"2026-04-07T01:43:25.670853959Z","hd":{"ts_event":"2026-04-07T01:43:25.670833431Z","rtype":160,"publisher_id":101,"instrument_id":436},"action":"A","side":"B","price":"1.156500000","size":20,"channel_id":23,"order_id":"10998898242525620441","flags":128,"ts_in_delta":802,"sequence":133085,"symbol":"FCEU SI 20260615 PS"}
{"ts_recv":"2026-04-07T01:44:12.319397815Z","hd":{"ts_event":"2026-04-07T01:44:12.319375901Z","rtype":160,"publisher_id":101,"instrument_id":436},"action":"A","side":"B","price":"1.156600000","size":20,"channel_id":23,"order_id":"10998898289174157990","flags":128,"ts_in_delta":3864,"sequence":133369,"symbol":"FCEU SI 20260615 PS"}
{"ts_recv":"2026-04-07T01:44:12.319413167Z","hd":{"ts_event":"2026-04-07T01:44:12.319399223Z","rtype":160,"publisher_id":101,"instrument_id":436},"action":"C","side":"B","price":"1.156500000","size":20,"channel_id":23,"order_id":"10998898242525620441","flags":128,"ts_in_delta":1006,"sequence":133370,"symbol":"FCEU SI 20260615 PS"}
{"ts_recv":"2026-04-07T01:44:17.319314052Z","hd":{"ts_event":"2026-04-07T01:44:17.319291269Z","rtype":160,"publisher_id":101,"instrument_id":436},"action":"C","side":"B","price":"1.156600000","size":20,"channel_id":23,"order_id":"10998898289174157990","flags":128,"ts_in_delta":1640,"sequence":133422,"symbol":"FCEU SI 20260615 PS"}
{"ts_recv":"2026-04-07T01:44:17.362223230Z","hd":{"ts_event":"2026-04-07T01:44:17.362200979Z","rtype":160,"publisher_id":101,"instrument_id":436},"action":"A","side":"B","price":"1.156500000","size":20,"channel_id":23,"order_id":"10998898294216987460","flags":128,"ts_in_delta":1162,"sequence":133423,"symbol":"FCEU SI 20260615 PS"}
{"ts_recv":"2026-04-07T01:44:34.087220664Z","hd":{"ts_event":"2026-04-07T01:44:34.087192621Z","rtype":160,"publisher_id":101,"instrument_id":436},"action":"A","side":"A","price":"1.156900000","size":20,"channel_id":23,"order_id":"1775526274087205798","flags":128,"ts_in_delta":1196,"sequence":133580,"symbol":"FCEU SI 20260615 PS"}
{"ts_recv":"2026-04-07T01:44:34.087223629Z","hd":{"ts_event":"2026-04-07T01:44:34.087204397Z","rtype":160,"publisher_id":101,"instrument_id":436},"action":"C","side":"A","price":"1.157000000","size":20,"channel_id":23,"order_id":"1775526183358545272","flags":128,"ts_in_delta":897,"sequence":133581,"symbol":"FCEU SI 20260615 PS"}
{"ts_recv":"2026-04-07T01:44:46.542161529Z","hd":{"ts_event":"2026-04-07T01:44:46.542133999Z","rtype":160,"publisher_id":101,"instrument_id":436},"action":"C","side":"A","price":"1.156900000","size":20,"channel_id":23,"order_id":"1775526274087205798","flags":128,"ts_in_delta":1383,"sequence":133661,"symbol":"FCEU SI 20260615 PS"}
{"ts_recv":"2026-04-07T01:44:46.585279135Z","hd":{"ts_event":"2026-04-07T01:44:46.585257749Z","rtype":160,"publisher_id":101,"instrument_id":436},"action":"A","side":"A","price":"1.157000000","size":20,"channel_id":23,"order_id":"1775526286585268522","flags":128,"ts_in_delta":1035,"sequence":133662,"symbol":"FCEU SI 20260615 PS"}
{"ts_recv":"2026-04-07T01:44:55.104608170Z","hd":{"ts_event":"2026-04-07T01:44:55.104589833Z","rtype":160,"publisher_id":101,"instrument_id":436},"action":"A","side":"B","price":"1.156600000","size":20,"channel_id":23,"order_id":"10998898331959374490","flags":128,"ts_in_delta":762,"sequence":133726,"symbol":"FCEU SI 20260615 PS"}
{"ts_recv":"2026-04-07T01:44:55.104652643Z","hd":{"ts_event":"2026-04-07T01:44:55.104638877Z","rtype":160,"publisher_id":101,"instrument_id":436},"action":"C","side":"B","price":"1.156500000","size":20,"channel_id":23,"order_id":"10998898294216987460","flags":128,"ts_in_delta":693,"sequence":133728,"symbol":"FCEU SI 20260615 PS"}
{"ts_recv":"2026-04-07T01:45:00.812493540Z","hd":{"ts_event":"2026-04-07T01:45:00.812479639Z","rtype":160,"publisher_id":101,"instrument_id":436},"action":"C","side":"B","price":"1.156600000","size":20,"channel_id":23,"order_id":"10998898331959374490","flags":128,"ts_in_delta":961,"sequence":133774,"symbol":"FCEU SI 20260615 PS"}
{"ts_recv":"2026-04-07T01:45:00.864127221Z","hd":{"ts_event":"2026-04-07T01:45:00.864112297Z","rtype":160,"publisher_id":101,"instrument_id":436},"action":"A","side":"B","price":"1.156600000","size":20,"channel_id":23,"order_id":"10998898337718893956","flags":128,"ts_in_delta":833,"sequence":133778,"symbol":"FCEU SI 20260615 PS"}
{"ts_recv":"2026-04-07T01:45:47.111802866Z","hd":{"ts_event":"2026-04-07T01:45:47.111786623Z","rtype":160,"publisher_id":101,"instrument_id":436},"action":"C","side":"B","price":"1.156600000","size":20,"channel_id":23,"order_id":"10998898337718893956","flags":128,"ts_in_delta":883,"sequence":134045,"symbol":"FCEU SI 20260615 PS"}
{"ts_recv":"2026-04-07T01:45:47.174624698Z","hd":{"ts_event":"2026-04-07T01:45:47.174610051Z","rtype":160,"publisher_id":101,"instrument_id":436},"action":"A","side":"B","price":"1.156600000","size":20,"channel_id":23,"order_id":"10998898384029391860","flags":128,"ts_in_delta":837,"sequence":134052,"symbol":"FCEU SI 20260615 PS"}
{"ts_recv":"2026-04-07T01:45:52.174529230Z","hd":{"ts_event":"2026-04-07T01:45:52.174507987Z","rtype":160,"publisher_id":101,"instrument_id":436},"action":"C","side":"B","price":"1.156600000","size":20,"channel_id":23,"order_id":"10998898384029391860","flags":128,"ts_in_delta":946,"sequence":134130,"symbol":"FCEU SI 20260615 PS"}
{"ts_recv":"2026-04-07T01:45:52.218136259Z","hd":{"ts_event":"2026-04-07T01:45:52.218119681Z","rtype":160,"publisher_id":101,"instrument_id":436},"action":"A","side":"B","price":"1.156500000","size":20,"channel_id":23,"order_id":"10998898389072901951","flags":128,"ts_in_delta":1247,"sequence":134131,"symbol":"FCEU SI 20260615 PS"}
{"ts_recv":"2026-04-07T01:46:12.230613401Z","hd":{"ts_event":"2026-04-07T01:46:12.230594753Z","rtype":160,"publisher_id":101,"instrument_id":436},"action":"A","side":"B","price":"1.156600000","size":20,"channel_id":23,"order_id":"10998898409085377201","flags":128,"ts_in_delta":778,"sequence":134280,"symbol":"FCEU SI 20260615 PS"}
{"ts_recv":"2026-04-07T01:46:12.230699751Z","hd":{"ts_event":"2026-04-07T01:46:12.230685735Z","rtype":160,"publisher_id":101,"instrument_id":436},"action":"C","side":"B","price":"1.156500000","size":20,"channel_id":23,"order_id":"10998898389072901951","flags":128,"ts_in_delta":797,"sequence":134281,"symbol":"FCEU SI 20260615 PS"}
{"ts_recv":"2026-04-07T01:46:18.131045479Z","hd":{"ts_event":"2026-04-07T01:46:18.131029615Z","rtype":160,"publisher_id":101,"instrument_id":436},"action":"C","side":"B","price":"1.156600000","size":20,"channel_id":23,"order_id":"10998898409085377201","flags":128,"ts_in_delta":1267,"sequence":134324,"symbol":"FCEU SI 20260615 PS"}
{"ts_recv":"2026-04-07T01:46:18.174255523Z","hd":{"ts_event":"2026-04-07T01:46:18.174231687Z","rtype":160,"publisher_id":101,"instrument_id":436},"action":"A","side":"B","price":"1.156500000","size":20,"channel_id":23,"order_id":"10998898415029019005","flags":128,"ts_in_delta":1105,"sequence":134325,"symbol":"FCEU SI 20260615 PS"}
{"ts_recv":"2026-04-07T01:46:19.019123966Z","hd":{"ts_event":"2026-04-07T01:46:19.019100821Z","rtype":160,"publisher_id":101,"instrument_id":436},"action":"A","side":"B","price":"1.156600000","size":20,"channel_id":23,"order_id":"10998898415873888960","flags":128,"ts_in_delta":1343,"sequence":134331,"symbol":"FCEU SI 20260615 PS"}
{"ts_recv":"2026-04-07T01:46:19.019127852Z","hd":{"ts_event":"2026-04-07T01:46:19.019112557Z","rtype":160,"publisher_id":101,"instrument_id":436},"action":"C","side":"B","price":"1.156500000","size":20,"channel_id":23,"order_id":"10998898415029019005","flags":128,"ts_in_delta":1164,"sequence":134332,"symbol":"FCEU SI 20260615 PS"}
{"ts_recv":"2026-04-07T01:46:25.520758493Z","hd":{"ts_event":"2026-04-07T01:46:25.520735805Z","rtype":160,"publisher_id":101,"instrument_id":436},"action":"C","side":"B","price":"1.156600000","size":20,"channel_id":23,"order_id":"10998898415873888960","flags":128,"ts_in_delta":1110,"sequence":134377,"symbol":"FCEU SI 20260615 PS"}
{"ts_recv":"2026-04-07T01:46:25.564229618Z","hd":{"ts_event":"2026-04-07T01:46:25.564208797Z","rtype":160,"publisher_id":101,"instrument_id":436},"action":"A","side":"B","price":"1.156500000","size":20,"channel_id":23,"order_id":"10998898422418995324","flags":128,"ts_in_delta":1238,"sequence":134378,"symbol":"FCEU SI 20260615 PS"}
{"ts_recv":"2026-04-07T01:46:26.668351497Z","hd":{"ts_event":"2026-04-07T01:46:26.668335881Z","rtype":160,"publisher_id":101,"instrument_id":436},"action":"A","side":"B","price":"1.156600000","size":20,"channel_id":23,"order_id":"10998898423523117895","flags":128,"ts_in_delta":847,"sequence":134383,"symbol":"FCEU SI 20260615 PS"}
{"ts_recv":"2026-04-07T01:46:26.668465370Z","hd":{"ts_event":"2026-04-07T01:46:26.668453231Z","rtype":160,"publisher_id":101,"instrument_id":436},"action":"C","side":"B","price":"1.156500000","size":20,"channel_id":23,"order_id":"10998898422418995324","flags":128,"ts_in_delta":967,"sequence":134384,"symbol":"FCEU SI 20260615 PS"}
{"ts_recv":"2026-04-07T01:49:01.237761925Z","hd":{"ts_event":"2026-04-07T01:49:01.237743777Z","rtype":160,"publisher_id":101,"instrument_id":436},"action":"C","side":"B","price":"1.156600000","size":20,"channel_id":23,"order_id":"10998898423523117895","flags":128,"ts_in_delta":981,"sequence":135581,"symbol":"FCEU SI 20260615 PS"}
{"ts_recv":"2026-04-07T01:49:01.281280217Z","hd":{"ts_event":"2026-04-07T01:49:01.281262537Z","rtype":160,"publisher_id":101,"instrument_id":436},"action":"A","side":"B","price":"1.156500000","size":20,"channel_id":23,"order_id":"10998898578136044407","flags":128,"ts_in_delta":835,"sequence":135586,"symbol":"FCEU SI 20260615 PS"}
{"ts_recv":"2026-04-07T01:49:12.091840750Z","hd":{"ts_event":"2026-04-07T01:49:12.091820187Z","rtype":160,"publisher_id":101,"instrument_id":436},"action":"A","side":"A","price":"1.156900000","size":20,"channel_id":23,"order_id":"1775526552091828968","flags":128,"ts_in_delta":909,"sequence":135697,"symbol":"FCEU SI 20260615 PS"}
{"ts_recv":"2026-04-07T01:49:12.091950400Z","hd":{"ts_event":"2026-04-07T01:49:12.091938081Z","rtype":160,"publisher_id":101,"instrument_id":436},"action":"C","side":"A","price":"1.157000000","size":20,"channel_id":23,"order_id":"1775526286585268522","flags":128,"ts_in_delta":851,"sequence":135698,"symbol":"FCEU SI 20260615 PS"}
{"ts_recv":"2026-04-07T01:50:14.625672662Z","hd":{"ts_event":"2026-04-07T01:50:14.625654779Z","rtype":160,"publisher_id":101,"instrument_id":436},"action":"C","side":"B","price":"1.156500000","size":20,"channel_id":23,"order_id":"10998898578136044407","flags":128,"ts_in_delta":826,"sequence":136176,"symbol":"FCEU SI 20260615 PS"}
{"ts_recv":"2026-04-07T01:50:14.669166953Z","hd":{"ts_event":"2026-04-07T01:50:14.669148417Z","rtype":160,"publisher_id":101,"instrument_id":436},"action":"A","side":"B","price":"1.156400000","size":20,"channel_id":23,"order_id":"10998898651523930056","flags":128,"ts_in_delta":837,"sequence":136180,"symbol":"FCEU SI 20260615 PS"}
{"ts_recv":"2026-04-07T01:50:19.957202175Z","hd":{"ts_event":"2026-04-07T01:50:19.957186299Z","rtype":160,"publisher_id":101,"instrument_id":436},"action":"A","side":"B","price":"1.156500000","size":20,"channel_id":23,"order_id":"10998898656811968119","flags":128,"ts_in_delta":902,"sequence":136243,"symbol":"FCEU SI 20260615 PS"}
{"ts_recv":"2026-04-07T01:50:19.957229822Z","hd":{"ts_event":"2026-04-07T01:50:19.957218817Z","rtype":160,"publisher_id":101,"instrument_id":436},"action":"C","side":"B","price":"1.156400000","size":20,"channel_id":23,"order_id":"10998898651523930056","flags":128,"ts_in_delta":798,"sequence":136244,"symbol":"FCEU SI 20260615 PS"}
{"ts_recv":"2026-04-07T01:50:27.041738902Z","hd":{"ts_event":"2026-04-07T01:50:27.041713601Z","rtype":160,"publisher_id":101,"instrument_id":436},"action":"C","side":"B","price":"1.156500000","size":20,"channel_id":23,"order_id":"10998898656811968119","flags":128,"ts_in_delta":1398,"sequence":136327,"symbol":"FCEU SI 20260615 PS"}
{"ts_recv":"2026-04-07T01:50:27.084693345Z","hd":{"ts_event":"2026-04-07T01:50:27.084671897Z","rtype":160,"publisher_id":101,"instrument_id":436},"action":"A","side":"B","price":"1.156400000","size":20,"channel_id":23,"order_id":"10998898663939458770","flags":128,"ts_in_delta":829,"sequence":136328,"symbol":"FCEU SI 20260615 PS"}
{"ts_recv":"2026-04-07T01:50:29.049990156Z","hd":{"ts_event":"2026-04-07T01:50:29.049973137Z","rtype":160,"publisher_id":101,"instrument_id":436},"action":"A","side":"A","price":"1.156800000","size":20,"channel_id":23,"order_id":"1775526629049978965","flags":128,"ts_in_delta":994,"sequence":136369,"symbol":"FCEU SI 20260615 PS"}
{"ts_recv":"2026-04-07T01:50:29.050032432Z","hd":{"ts_event":"2026-04-07T01:50:29.050019491Z","rtype":160,"publisher_id":101,"instrument_id":436},"action":"C","side":"A","price":"1.156900000","size":20,"channel_id":23,"order_id":"1775526552091828968","flags":128,"ts_in_delta":815,"sequence":136370,"symbol":"FCEU SI 20260615 PS"}
{"ts_recv":"2026-04-07T01:50:33.644676631Z","hd":{"ts_event":"2026-04-07T01:50:33.644661393Z","rtype":160,"publisher_id":101,"instrument_id":436},"action":"C","side":"B","price":"1.156400000","size":20,"channel_id":23,"order_id":"10998898663939458770","flags":128,"ts_in_delta":811,"sequence":136456,"symbol":"FCEU SI 20260615 PS"}
{"ts_recv":"2026-04-07T01:50:33.704579922Z","hd":{"ts_event":"2026-04-07T01:50:33.704563967Z","rtype":160,"publisher_id":101,"instrument_id":436},"action":"A","side":"B","price":"1.156400000","size":20,"channel_id":23,"order_id":"10998898670559345618","flags":128,"ts_in_delta":805,"sequence":136459,"symbol":"FCEU SI 20260615 PS"}
{"ts_recv":"2026-04-07T01:51:00.133152609Z","hd":{"ts_event":"2026-04-07T01:51:00.133131337Z","rtype":160,"publisher_id":101,"instrument_id":436},"action":"C","side":"A","price":"1.156800000","size":20,"channel_id":23,"order_id":"1775526629049978965","flags":128,"ts_in_delta":1347,"sequence":136685,"symbol":"FCEU SI 20260615 PS"}
{"ts_recv":"2026-04-07T01:51:00.176418024Z","hd":{"ts_event":"2026-04-07T01:51:00.176399951Z","rtype":160,"publisher_id":101,"instrument_id":436},"action":"A","side":"A","price":"1.156900000","size":20,"channel_id":23,"order_id":"1775526660176406302","flags":128,"ts_in_delta":963,"sequence":136692,"symbol":"FCEU SI 20260615 PS"}
{"ts_recv":"2026-04-07T01:51:24.125177219Z","hd":{"ts_event":"2026-04-07T01:51:24.125158275Z","rtype":160,"publisher_id":101,"instrument_id":436},"action":"A","side":"B","price":"1.156500000","size":20,"channel_id":23,"order_id":"10998898720979940332","flags":128,"ts_in_delta":872,"sequence":136853,"symbol":"FCEU SI 20260615 PS"}
{"ts_recv":"2026-04-07T01:51:24.125194951Z","hd":{"ts_event":"2026-04-07T01:51:24.125183271Z","rtype":160,"publisher_id":101,"instrument_id":436},"action":"C","side":"B","price":"1.156400000","size":20,"channel_id":23,"order_id":"10998898670559345618","flags":128,"ts_in_delta":793,"sequence":136854,"symbol":"FCEU SI 20260615 PS"}
{"ts_recv":"2026-04-07T01:51:41.451217230Z","hd":{"ts_event":"2026-04-07T01:51:41.451203539Z","rtype":160,"publisher_id":101,"instrument_id":436},"action":"C","side":"B","price":"1.156500000","size":20,"channel_id":23,"order_id":"10998898720979940332","flags":128,"ts_in_delta":829,"sequence":136975,"symbol":"FCEU SI 20260615 PS"}
{"ts_recv":"2026-04-07T01:51:41.493478025Z","hd":{"ts_event":"2026-04-07T01:51:41.493463153Z","rtype":160,"publisher_id":101,"instrument_id":436},"action":"A","side":"B","price":"1.156400000","size":20,"channel_id":23,"order_id":"10998898738348244876","flags":128,"ts_in_delta":808,"sequence":136990,"symbol":"FCEU SI 20260615 PS"}
{"ts_recv":"2026-04-07T01:51:43.457297105Z","hd":{"ts_event":"2026-04-07T01:51:43.457274907Z","rtype":160,"publisher_id":101,"instrument_id":436},"action":"A","side":"A","price":"1.156800000","size":20,"channel_id":23,"order_id":"1775526703457284029","flags":128,"ts_in_delta":1161,"sequence":137022,"symbol":"FCEU SI 20260615 PS"}
{"ts_recv":"2026-04-07T01:51:43.457303770Z","hd":{"ts_event":"2026-04-07T01:51:43.457288141Z","rtype":160,"publisher_id":101,"instrument_id":436},"action":"C","side":"A","price":"1.156900000","size":20,"channel_id":23,"order_id":"1775526660176406302","flags":128,"ts_in_delta":808,"sequence":137023,"symbol":"FCEU SI 20260615 PS"}
{"ts_recv":"2026-04-07T01:52:20.413471964Z","hd":{"ts_event":"2026-04-07T01:52:20.413457593Z","rtype":160,"publisher_id":101,"instrument_id":436},"action":"C","side":"B","price":"1.156400000","size":20,"channel_id":23,"order_id":"10998898738348244876","flags":128,"ts_in_delta":1224,"sequence":137237,"symbol":"FCEU SI 20260615 PS"}
{"ts_recv":"2026-04-07T01:52:20.456147349Z","hd":{"ts_event":"2026-04-07T01:52:20.456129493Z","rtype":160,"publisher_id":101,"instrument_id":436},"action":"A","side":"B","price":"1.156300000","size":20,"channel_id":23,"order_id":"10998898777310911412","flags":128,"ts_in_delta":1127,"sequence":137247,"symbol":"FCEU SI 20260615 PS"}
{"ts_recv":"2026-04-07T01:52:22.054606575Z","hd":{"ts_event":"2026-04-07T01:52:22.054590931Z","rtype":160,"publisher_id":101,"instrument_id":436},"action":"A","side":"A","price":"1.156700000","size":20,"channel_id":23,"order_id":"1775526742054597237","flags":128,"ts_in_delta":991,"sequence":137283,"symbol":"FCEU SI 20260615 PS"}
{"ts_recv":"2026-04-07T01:52:22.054681305Z","hd":{"ts_event":"2026-04-07T01:52:22.054669721Z","rtype":160,"publisher_id":101,"instrument_id":436},"action":"C","side":"A","price":"1.156800000","size":20,"channel_id":23,"order_id":"1775526703457284029","flags":128,"ts_in_delta":1019,"sequence":137284,"symbol":"FCEU SI 20260615 PS"}
{"ts_recv":"2026-04-07T01:52:27.995279957Z","hd":{"ts_event":"2026-04-07T01:52:27.995259355Z","rtype":160,"publisher_id":101,"instrument_id":436},"action":"C","side":"B","price":"1.156300000","size":20,"channel_id":23,"order_id":"10998898777310911412","flags":128,"ts_in_delta":1664,"sequence":137350,"symbol":"FCEU SI 20260615 PS"}
{"ts_recv":"2026-04-07T01:52:28.045616777Z","hd":{"ts_event":"2026-04-07T01:52:28.045600091Z","rtype":160,"publisher_id":101,"instrument_id":436},"action":"A","side":"B","price":"1.156300000","size":20,"channel_id":23,"order_id":"10998898784900382114","flags":128,"ts_in_delta":938,"sequence":137357,"symbol":"FCEU SI 20260615 PS"}
{"ts_recv":"2026-04-07T01:52:33.062855464Z","hd":{"ts_event":"2026-04-07T01:52:33.062841945Z","rtype":160,"publisher_id":101,"instrument_id":436},"action":"C","side":"B","price":"1.156300000","size":20,"channel_id":23,"order_id":"10998898784900382114","flags":128,"ts_in_delta":900,"sequence":137424,"symbol":"FCEU SI 20260615 PS"}
{"ts_recv":"2026-04-07T01:52:33.105277691Z","hd":{"ts_event":"2026-04-07T01:52:33.105262983Z","rtype":160,"publisher_id":101,"instrument_id":436},"action":"A","side":"B","price":"1.156200000","size":20,"channel_id":23,"order_id":"10998898789960044699","flags":128,"ts_in_delta":887,"sequence":137427,"symbol":"FCEU SI 20260615 PS"}
{"ts_recv":"2026-04-07T01:52:33.165252767Z","hd":{"ts_event":"2026-04-07T01:52:33.165239785Z","rtype":160,"publisher_id":101,"instrument_id":436},"action":"A","side":"B","price":"1.156300000","size":20,"channel_id":23,"order_id":"10998898790020021572","flags":128,"ts_in_delta":844,"sequence":137431,"symbol":"FCEU SI 20260615 PS"}
{"ts_recv":"2026-04-07T01:52:33.165274662Z","hd":{"ts_event":"2026-04-07T01:52:33.165260771Z","rtype":160,"publisher_id":101,"instrument_id":436},"action":"C","side":"B","price":"1.156200000","size":20,"channel_id":23,"order_id":"10998898789960044699","flags":128,"ts_in_delta":1000,"sequence":137432,"symbol":"FCEU SI 20260615 PS"}
{"ts_recv":"2026-04-07T01:52:38.164993492Z","hd":{"ts_event":"2026-04-07T01:52:38.164971363Z","rtype":160,"publisher_id":101,"instrument_id":436},"action":"C","side":"B","price":"1.156300000","size":20,"channel_id":23,"order_id":"10998898790020021572","flags":128,"ts_in_delta":1627,"sequence":137480,"symbol":"FCEU SI 20260615 PS"}
{"ts_recv":"2026-04-07T01:52:38.208228196Z","hd":{"ts_event":"2026-04-07T01:52:38.208206859Z","rtype":160,"publisher_id":101,"instrument_id":436},"action":"A","side":"B","price":"1.156200000","size":20,"channel_id":23,"order_id":"10998898795062993471","flags":128,"ts_in_delta":923,"sequence":137481,"symbol":"FCEU SI 20260615 PS"}
{"ts_recv":"2026-04-07T01:52:47.043876487Z","hd":{"ts_event":"2026-04-07T01:52:47.043860721Z","rtype":160,"publisher_id":101,"instrument_id":436},"action":"A","side":"B","price":"1.156300000","size":20,"channel_id":23,"order_id":"10998898803898643087","flags":128,"ts_in_delta":668,"sequence":137597,"symbol":"FCEU SI 20260615 PS"}
{"ts_recv":"2026-04-07T01:52:47.043945128Z","hd":{"ts_event":"2026-04-07T01:52:47.043932261Z","rtype":160,"publisher_id":101,"instrument_id":436},"action":"C","side":"B","price":"1.156200000","size":20,"channel_id":23,"order_id":"10998898795062993471","flags":128,"ts_in_delta":929,"sequence":137598,"symbol":"FCEU SI 20260615 PS"}
{"ts_recv":"2026-04-07T01:52:52.209570609Z","hd":{"ts_event":"2026-04-07T01:52:52.209549947Z","rtype":160,"publisher_id":101,"instrument_id":436},"action":"C","side":"B","price":"1.156300000","size":20,"channel_id":23,"order_id":"10998898803898643087","flags":128,"ts_in_delta":1025,"sequence":137653,"symbol":"FCEU SI 20260615 PS"}
{"ts_recv":"2026-04-07T01:52:52.252307219Z","hd":{"ts_event":"2026-04-07T01:52:52.252291965Z","rtype":160,"publisher_id":101,"instrument_id":436},"action":"A","side":"B","price":"1.156200000","size":20,"channel_id":23,"order_id":"10998898809107073967","flags":128,"ts_in_delta":838,"sequence":137655,"symbol":"FCEU SI 20260615 PS"}
{"ts_recv":"2026-04-07T01:52:52.331583792Z","hd":{"ts_event":"2026-04-07T01:52:52.331571233Z","rtype":160,"publisher_id":101,"instrument_id":436},"action":"A","side":"B","price":"1.156300000","size":20,"channel_id":23,"order_id":"10998898809186353137","flags":128,"ts_in_delta":805,"sequence":137657,"symbol":"FCEU SI 20260615 PS"}
{"ts_recv":"2026-04-07T01:52:52.331611032Z","hd":{"ts_event":"2026-04-07T01:52:52.331597705Z","rtype":160,"publisher_id":101,"instrument_id":436},"action":"C","side":"B","price":"1.156200000","size":20,"channel_id":23,"order_id":"10998898809107073967","flags":128,"ts_in_delta":805,"sequence":137658,"symbol":"FCEU SI 20260615 PS"}
{"ts_recv":"2026-04-07T01:53:00.482586122Z","hd":{"ts_event":"2026-04-07T01:53:00.482572101Z","rtype":160,"publisher_id":101,"instrument_id":436},"action":"C","side":"B","price":"1.156300000","size":20,"channel_id":23,"order_id":"10998898809186353137","flags":128,"ts_in_delta":849,"sequence":137727,"symbol":"FCEU SI 20260615 PS"}
{"ts_recv":"2026-04-07T01:53:00.541302235Z","hd":{"ts_event":"2026-04-07T01:53:00.541284069Z","rtype":160,"publisher_id":101,"instrument_id":436},"action":"A","side":"B","price":"1.156300000","size":20,"channel_id":23,"order_id":"10998898817396066490","flags":128,"ts_in_delta":1169,"sequence":137730,"symbol":"FCEU SI 20260615 PS"}
{"ts_recv":"2026-04-07T01:54:23.143637209Z","hd":{"ts_event":"2026-04-07T01:54:23.143620241Z","rtype":160,"publisher_id":101,"instrument_id":436},"action":"C","side":"B","price":"1.156300000","size":20,"channel_id":23,"order_id":"10998898817396066490","flags":128,"ts_in_delta":907,"sequence":138272,"symbol":"FCEU SI 20260615 PS"}
{"ts_recv":"2026-04-07T01:54:23.189236009Z","hd":{"ts_event":"2026-04-07T01:54:23.189215611Z","rtype":160,"publisher_id":101,"instrument_id":436},"action":"A","side":"B","price":"1.156300000","size":20,"channel_id":23,"order_id":"10998898900043997923","flags":128,"ts_in_delta":841,"sequence":138279,"symbol":"FCEU SI 20260615 PS"}
{"ts_recv":"2026-04-07T01:54:32.620883717Z","hd":{"ts_event":"2026-04-07T01:54:32.620870599Z","rtype":160,"publisher_id":101,"instrument_id":436},"action":"C","side":"B","price":"1.156300000","size":20,"channel_id":23,"order_id":"10998898900043997923","flags":128,"ts_in_delta":799,"sequence":138340,"symbol":"FCEU SI 20260615 PS"}
{"ts_recv":"2026-04-07T01:54:32.666504181Z","hd":{"ts_event":"2026-04-07T01:54:32.666488421Z","rtype":160,"publisher_id":101,"instrument_id":436},"action":"A","side":"B","price":"1.156300000","size":20,"channel_id":23,"order_id":"10998898909521270107","flags":128,"ts_in_delta":823,"sequence":138346,"symbol":"FCEU SI 20260615 PS"}
{"ts_recv":"2026-04-07T01:54:38.022630983Z","hd":{"ts_event":"2026-04-07T01:54:38.022618211Z","rtype":160,"publisher_id":101,"instrument_id":436},"action":"C","side":"B","price":"1.156300000","size":20,"channel_id":23,"order_id":"10998898909521270107","flags":128,"ts_in_delta":969,"sequence":138387,"symbol":"FCEU SI 20260615 PS"}
{"ts_recv":"2026-04-07T01:54:38.065667045Z","hd":{"ts_event":"2026-04-07T01:54:38.065653573Z","rtype":160,"publisher_id":101,"instrument_id":436},"action":"A","side":"B","price":"1.156200000","size":20,"channel_id":23,"order_id":"10998898914920435305","flags":128,"ts_in_delta":802,"sequence":138392,"symbol":"FCEU SI 20260615 PS"}
{"ts_recv":"2026-04-07T01:54:40.163273103Z","hd":{"ts_event":"2026-04-07T01:54:40.163256975Z","rtype":160,"publisher_id":101,"instrument_id":436},"action":"A","side":"B","price":"1.156300000","size":20,"channel_id":23,"order_id":"10998898917018039511","flags":128,"ts_in_delta":786,"sequence":138427,"symbol":"FCEU SI 20260615 PS"}
{"ts_recv":"2026-04-07T01:54:40.163282473Z","hd":{"ts_event":"2026-04-07T01:54:40.163269341Z","rtype":160,"publisher_id":101,"instrument_id":436},"action":"C","side":"B","price":"1.156200000","size":20,"channel_id":23,"order_id":"10998898914920435305","flags":128,"ts_in_delta":1070,"sequence":138428,"symbol":"FCEU SI 20260615 PS"}
{"ts_recv":"2026-04-07T01:55:20.640498298Z","hd":{"ts_event":"2026-04-07T01:55:20.640475365Z","rtype":160,"publisher_id":101,"instrument_id":436},"action":"C","side":"A","price":"1.156700000","size":20,"channel_id":23,"order_id":"1775526742054597237","flags":128,"ts_in_delta":1532,"sequence":138708,"symbol":"FCEU SI 20260615 PS"}
{"ts_recv":"2026-04-07T01:55:20.683403977Z","hd":{"ts_event":"2026-04-07T01:55:20.683385033Z","rtype":160,"publisher_id":101,"instrument_id":436},"action":"A","side":"A","price":"1.156800000","size":20,"channel_id":23,"order_id":"1775526920683391378","flags":128,"ts_in_delta":988,"sequence":138712,"symbol":"FCEU SI 20260615 PS"}
{"ts_recv":"2026-04-07T01:55:55.202265900Z","hd":{"ts_event":"2026-04-07T01:55:55.202247597Z","rtype":160,"publisher_id":101,"instrument_id":436},"action":"A","side":"B","price":"1.156400000","size":20,"channel_id":23,"order_id":"10998898992057029437","flags":128,"ts_in_delta":862,"sequence":138965,"symbol":"FCEU SI 20260615 PS"}