{"ts_recv":"2026-04-07T03:29:21.867931541Z","hd":{"ts_event":"2026-04-07T03:29:21.867911923Z","rtype":160,"publisher_id":101,"instrument_id":436},"action":"C","side":"B","price":"1.156740000","size":30,"channel_id":23,"order_id":"10998904598718917473","flags":0,"ts_in_delta":747,"sequence":190615,"symbol":"FCEU SI 20260615 PS"}
{"ts_recv":"2026-04-07T03:29:21.867931541Z","hd":{"ts_event":"2026-04-07T03:29:21.867911923Z","rtype":160,"publisher_id":101,"instrument_id":436},"action":"A","side":"B","price":"1.156750000","size":30,"channel_id":23,"order_id":"10998904598722693753","flags":0,"ts_in_delta":747,"sequence":190615,"symbol":"FCEU SI 20260615 PS"}
{"ts_recv":"2026-04-07T03:29:21.867931541Z","hd":{"ts_event":"2026-04-07T03:29:21.867911923Z","rtype":160,"publisher_id":101,"instrument_id":436},"action":"C","side":"A","price":"1.156840000","size":30,"channel_id":23,"order_id":"1775532561864141665","flags":0,"ts_in_delta":747,"sequence":190615,"symbol":"FCEU SI 20260615 PS"}
{"ts_recv":"2026-04-07T03:29:21.867931541Z","hd":{"ts_event":"2026-04-07T03:29:21.867911923Z","rtype":160,"publisher_id":101,"instrument_id":436},"action":"A","side":"A","price":"1.156850000","size":30,"channel_id":23,"order_id":"1775532561867917945","flags":128,"ts_in_delta":747,"sequence":190615,"symbol":"FCEU SI 20260615 PS"}
{"ts_recv":"2026-04-07T03:29:21.867989568Z","hd":{"ts_event":"2026-04-07T03:29:21.867971347Z","rtype":160,"publisher_id":101,"instrument_id":436},"action":"C","side":"B","price":"1.156730000","size":30,"channel_id":23,"order_id":"10998904585974084719","flags":0,"ts_in_delta":966,"sequence":190616,"symbol":"FCEU SI 20260615 PS"}
{"ts_recv":"2026-04-07T03:29:21.867989568Z","hd":{"ts_event":"2026-04-07T03:29:21.867971347Z","rtype":160,"publisher_id":101,"instrument_id":436},"action":"A","side":"B","price":"1.156750000","size":30,"channel_id":23,"order_id":"10998904598722752987","flags":0,"ts_in_delta":966,"sequence":190616,"symbol":"FCEU SI 20260615 PS"}
{"ts_recv":"2026-04-07T03:29:21.867989568Z","hd":{"ts_event":"2026-04-07T03:29:21.867971347Z","rtype":160,"publisher_id":101,"instrument_id":436},"action":"C","side":"A","price":"1.156830000","size":30,"channel_id":23,"order_id":"1775532549119308911","flags":0,"ts_in_delta":966,"sequence":190616,"symbol":"FCEU SI 20260615 PS"}
{"ts_recv":"2026-04-07T03:29:21.867989568Z","hd":{"ts_event":"2026-04-07T03:29:21.867971347Z","rtype":160,"publisher_id":101,"instrument_id":436},"action":"A","side":"A","price":"1.156850000","size":30,"channel_id":23,"order_id":"1775532561867977179","flags":128,"ts_in_delta":966,"sequence":190616,"symbol":"FCEU SI 20260615 PS"}
{"ts_recv":"2026-04-07T03:29:21.868016823Z","hd":{"ts_event":"2026-04-07T03:29:21.867997613Z","rtype":160,"publisher_id":101,"instrument_id":436},"action":"C","side":"B","price":"1.156750000","size":30,"channel_id":23,"order_id":"10998904598722693753","flags":0,"ts_in_delta":952,"sequence":190617,"symbol":"FCEU SI 20260615 PS"}
{"ts_recv":"2026-04-07T03:29:21.868016823Z","hd":{"ts_event":"2026-04-07T03:29:21.867997613Z","rtype":160,"publisher_id":101,"instrument_id":436},"action":"A","side":"B","price":"1.156740000","size":30,"channel_id":23,"order_id":"10998904598722779408","flags":0,"ts_in_delta":952,"sequence":190617,"symbol":"FCEU SI 20260615 PS"}
{"ts_recv":"2026-04-07T03:29:21.868016823Z","hd":{"ts_event":"2026-04-07T03:29:21.867997613Z","rtype":160,"publisher_id":101,"instrument_id":436},"action":"C","side":"A","price":"1.156850000","size":30,"channel_id":23,"order_id":"1775532561867917945","flags":0,"ts_in_delta":952,"sequence":190617,"symbol":"FCEU SI 20260615 PS"}
{"ts_recv":"2026-04-07T03:29:21.868016823Z","hd":{"ts_event":"2026-04-07T03:29:21.867997613Z","rtype":160,"publisher_id":101,"instrument_id":436},"action":"A","side":"A","price":"1.156840000","size":30,"channel_id":23,"order_id":"1775532561868003600","flags":128,"ts_in_delta":952,"sequence":190617,"symbol":"FCEU SI 20260615 PS"}
{"ts_recv":"2026-04-07T03:29:21.868074382Z","hd":{"ts_event":"2026-04-07T03:29:21.868056801Z","rtype":160,"publisher_id":101,"instrument_id":436},"action":"C","side":"B","price":"1.156740000","size":30,"channel_id":23,"order_id":"10998904598722779408","flags":0,"ts_in_delta":1037,"sequence":190618,"symbol":"FCEU SI 20260615 PS"}
{"ts_recv":"2026-04-07T03:29:21.868074382Z","hd":{"ts_event":"2026-04-07T03:29:21.868056801Z","rtype":160,"publisher_id":101,"instrument_id":436},"action":"A","side":"B","price":"1.156750000","size":30,"channel_id":23,"order_id":"10998904598722838710","flags":0,"ts_in_delta":1037,"sequence":190618,"symbol":"FCEU SI 20260615 PS"}
{"ts_recv":"2026-04-07T03:29:21.868074382Z","hd":{"ts_event":"2026-04-07T03:29:21.868056801Z","rtype":160,"publisher_id":101,"instrument_id":436},"action":"C","side":"A","price":"1.156840000","size":30,"channel_id":23,"order_id":"1775532561868003600","flags":0,"ts_in_delta":1037,"sequence":190618,"symbol":"FCEU SI 20260615 PS"}
{"ts_recv":"2026-04-07T03:29:21.868074382Z","hd":{"ts_event":"2026-04-07T03:29:21.868056801Z","rtype":160,"publisher_id":101,"instrument_id":436},"action":"A","side":"A","price":"1.156850000","size":30,"channel_id":23,"order_id":"1775532561868062902","flags":128,"ts_in_delta":1037,"sequence":190618,"symbol":"FCEU SI 20260615 PS"}
{"ts_recv":"2026-04-07T03:29:29.741057836Z","hd":{"ts_event":"2026-04-07T03:29:29.741031281Z","rtype":160,"publisher_id":101,"instrument_id":436},"action":"C","side":"B","price":"1.156750000","size":30,"channel_id":23,"order_id":"10998904598722838710","flags":0,"ts_in_delta":1002,"sequence":190653,"symbol":"FCEU SI 20260615 PS"}
{"ts_recv":"2026-04-07T03:29:29.741057836Z","hd":{"ts_event":"2026-04-07T03:29:29.741031281Z","rtype":160,"publisher_id":101,"instrument_id":436},"action":"A","side":"B","price":"1.156740000","size":30,"channel_id":23,"order_id":"10998904606595816838","flags":0,"ts_in_delta":1002,"sequence":190653,"symbol":"FCEU SI 20260615 PS"}
{"ts_recv":"2026-04-07T03:29:29.741057836Z","hd":{"ts_event":"2026-04-07T03:29:29.741031281Z","rtype":160,"publisher_id":101,"instrument_id":436},"action":"C","side":"A","price":"1.156850000","size":30,"channel_id":23,"order_id":"1775532561868062902","flags":0,"ts_in_delta":1002,"sequence":190653,"symbol":"FCEU SI 20260615 PS"}
{"ts_recv":"2026-04-07T03:29:29.741057836Z","hd":{"ts_event":"2026-04-07T03:29:29.741031281Z","rtype":160,"publisher_id":101,"instrument_id":436},"action":"A","side":"A","price":"1.156840000","size":30,"channel_id":23,"order_id":"1775532569741041030","flags":128,"ts_in_delta":1002,"sequence":190653,"symbol":"FCEU SI 20260615 PS"}
{"ts_recv":"2026-04-07T03:29:29.746852329Z","hd":{"ts_event":"2026-04-07T03:29:29.746833399Z","rtype":160,"publisher_id":101,"instrument_id":436},"action":"C","side":"B","price":"1.156750000","size":30,"channel_id":23,"order_id":"10998904598722752987","flags":0,"ts_in_delta":958,"sequence":190655,"symbol":"FCEU SI 20260615 PS"}
{"ts_recv":"2026-04-07T03:29:29.746852329Z","hd":{"ts_event":"2026-04-07T03:29:29.746833399Z","rtype":160,"publisher_id":101,"instrument_id":436},"action":"A","side":"B","price":"1.156730000","size":30,"channel_id":23,"order_id":"10998904606601615399","flags":0,"ts_in_delta":958,"sequence":190655,"symbol":"FCEU SI 20260615 PS"}
{"ts_recv":"2026-04-07T03:29:29.746852329Z","hd":{"ts_event":"2026-04-07T03:29:29.746833399Z","rtype":160,"publisher_id":101,"instrument_id":436},"action":"C","side":"A","price":"1.156850000","size":30,"channel_id":23,"order_id":"1775532561867977179","flags":0,"ts_in_delta":958,"sequence":190655,"symbol":"FCEU SI 20260615 PS"}
{"ts_recv":"2026-04-07T03:29:29.746852329Z","hd":{"ts_event":"2026-04-07T03:29:29.746833399Z","rtype":160,"publisher_id":101,"instrument_id":436},"action":"A","side":"A","price":"1.156830000","size":30,"channel_id":23,"order_id":"1775532569746839591","flags":128,"ts_in_delta":958,"sequence":190655,"symbol":"FCEU SI 20260615 PS"}
{"ts_recv":"2026-04-07T03:29:29.746923773Z","hd":{"ts_event":"2026-04-07T03:29:29.746904163Z","rtype":160,"publisher_id":101,"instrument_id":436},"action":"C","side":"B","price":"1.156740000","size":30,"channel_id":23,"order_id":"10998904606595816838","flags":0,"ts_in_delta":946,"sequence":190656,"symbol":"FCEU SI 20260615 PS"}
{"ts_recv":"2026-04-07T03:29:29.746923773Z","hd":{"ts_event":"2026-04-07T03:29:29.746904163Z","rtype":160,"publisher_id":101,"instrument_id":436},"action":"A","side":"B","price":"1.156730000","size":30,"channel_id":23,"order_id":"10998904606601685843","flags":0,"ts_in_delta":946,"sequence":190656,"symbol":"FCEU SI 20260615 PS"}
{"ts_recv":"2026-04-07T03:29:29.746923773Z","hd":{"ts_event":"2026-04-07T03:29:29.746904163Z","rtype":160,"publisher_id":101,"instrument_id":436},"action":"C","side":"A","price":"1.156840000","size":30,"channel_id":23,"order_id":"1775532569741041030","flags":0,"ts_in_delta":946,"sequence":190656,"symbol":"FCEU SI 20260615 PS"}
{"ts_recv":"2026-04-07T03:29:29.746923773Z","hd":{"ts_event":"2026-04-07T03:29:29.746904163Z","rtype":160,"publisher_id":101,"instrument_id":436},"action":"A","side":"A","price":"1.156830000","size":30,"channel_id":23,"order_id":"1775532569746910035","flags":128,"ts_in_delta":946,"sequence":190656,"symbol":"FCEU SI 20260615 PS"}
{"ts_recv":"2026-04-07T03:30:47.504957763Z","hd":{"ts_event":"2026-04-07T03:30:47.504931563Z","rtype":160,"publisher_id":101,"instrument_id":436},"action":"C","side":"B","price":"1.156730000","size":30,"channel_id":23,"order_id":"10998904606601685843","flags":0,"ts_in_delta":765,"sequence":191089,"symbol":"FCEU SI 20260615 PS"}
{"ts_recv":"2026-04-07T03:30:47.504957763Z","hd":{"ts_event":"2026-04-07T03:30:47.504931563Z","rtype":160,"publisher_id":101,"instrument_id":436},"action":"A","side":"B","price":"1.156740000","size":30,"channel_id":23,"order_id":"10998904684359713957","flags":0,"ts_in_delta":765,"sequence":191089,"symbol":"FCEU SI 20260615 PS"}
{"ts_recv":"2026-04-07T03:30:47.504957763Z","hd":{"ts_event":"2026-04-07T03:30:47.504931563Z","rtype":160,"publisher_id":101,"instrument_id":436},"action":"C","side":"A","price":"1.156830000","size":30,"channel_id":23,"order_id":"1775532569746910035","flags":0,"ts_in_delta":765,"sequence":191089,"symbol":"FCEU SI 20260615 PS"}
{"ts_recv":"2026-04-07T03:30:47.504957763Z","hd":{"ts_event":"2026-04-07T03:30:47.504931563Z","rtype":160,"publisher_id":101,"instrument_id":436},"action":"A","side":"A","price":"1.156840000","size":30,"channel_id":23,"order_id":"1775532647504938149","flags":128,"ts_in_delta":765,"sequence":191089,"symbol":"FCEU SI 20260615 PS"}
{"ts_recv":"2026-04-07T03:30:47.505038154Z","hd":{"ts_event":"2026-04-07T03:30:47.505020151Z","rtype":160,"publisher_id":101,"instrument_id":436},"action":"C","side":"B","price":"1.156740000","size":30,"channel_id":23,"order_id":"10998904684359713957","flags":0,"ts_in_delta":794,"sequence":191090,"symbol":"FCEU SI 20260615 PS"}
{"ts_recv":"2026-04-07T03:30:47.505038154Z","hd":{"ts_event":"2026-04-07T03:30:47.505020151Z","rtype":160,"publisher_id":101,"instrument_id":436},"action":"A","side":"B","price":"1.156750000","size":30,"channel_id":23,"order_id":"10998904684359801900","flags":0,"ts_in_delta":794,"sequence":191090,"symbol":"FCEU SI 20260615 PS"}
{"ts_recv":"2026-04-07T03:30:47.505038154Z","hd":{"ts_event":"2026-04-07T03:30:47.505020151Z","rtype":160,"publisher_id":101,"instrument_id":436},"action":"C","side":"A","price":"1.156840000","size":30,"channel_id":23,"order_id":"1775532647504938149","flags":0,"ts_in_delta":794,"sequence":191090,"symbol":"FCEU SI 20260615 PS"}
{"ts_recv":"2026-04-07T03:30:47.505038154Z","hd":{"ts_event":"2026-04-07T03:30:47.505020151Z","rtype":160,"publisher_id":101,"instrument_id":436},"action":"A","side":"A","price":"1.156850000","size":30,"channel_id":23,"order_id":"1775532647505026092","flags":128,"ts_in_delta":794,"sequence":191090,"symbol":"FCEU SI 20260615 PS"}
{"ts_recv":"2026-04-07T03:30:47.505095828Z","hd":{"ts_event":"2026-04-07T03:30:47.505073047Z","rtype":160,"publisher_id":101,"instrument_id":436},"action":"C","side":"B","price":"1.156730000","size":30,"channel_id":23,"order_id":"10998904606601615399","flags":0,"ts_in_delta":746,"sequence":191091,"symbol":"FCEU SI 20260615 PS"}
{"ts_recv":"2026-04-07T03:30:47.505095828Z","hd":{"ts_event":"2026-04-07T03:30:47.505073047Z","rtype":160,"publisher_id":101,"instrument_id":436},"action":"A","side":"B","price":"1.156750000","size":30,"channel_id":23,"order_id":"10998904684359855226","flags":0,"ts_in_delta":746,"sequence":191091,"symbol":"FCEU SI 20260615 PS"}
{"ts_recv":"2026-04-07T03:30:47.505095828Z","hd":{"ts_event":"2026-04-07T03:30:47.505073047Z","rtype":160,"publisher_id":101,"instrument_id":436},"action":"C","side":"A","price":"1.156830000","size":30,"channel_id":23,"order_id":"1775532569746839591","flags":0,"ts_in_delta":746,"sequence":191091,"symbol":"FCEU SI 20260615 PS"}
{"ts_recv":"2026-04-07T03:30:47.505095828Z","hd":{"ts_event":"2026-04-07T03:30:47.505073047Z","rtype":160,"publisher_id":101,"instrument_id":436},"action":"A","side":"A","price":"1.156850000","size":30,"channel_id":23,"order_id":"1775532647505079418","flags":128,"ts_in_delta":746,"sequence":191091,"symbol":"FCEU SI 20260615 PS"}
{"ts_recv":"2026-04-07T03:30:47.505107094Z","hd":{"ts_event":"2026-04-07T03:30:47.505081919Z","rtype":160,"publisher_id":101,"instrument_id":436},"action":"C","side":"B","price":"1.156750000","size":30,"channel_id":23,"order_id":"10998904684359801900","flags":0,"ts_in_delta":745,"sequence":191092,"symbol":"FCEU SI 20260615 PS"}
{"ts_recv":"2026-04-07T03:30:47.505107094Z","hd":{"ts_event":"2026-04-07T03:30:47.505081919Z","rtype":160,"publisher_id":101,"instrument_id":436},"action":"A","side":"B","price":"1.156740000","size":30,"channel_id":23,"order_id":"10998904684359867168","flags":0,"ts_in_delta":745,"sequence":191092,"symbol":"FCEU SI 20260615 PS"}
{"ts_recv":"2026-04-07T03:30:47.505107094Z","hd":{"ts_event":"2026-04-07T03:30:47.505081919Z","rtype":160,"publisher_id":101,"instrument_id":436},"action":"C","side":"A","price":"1.156850000","size":30,"channel_id":23,"order_id":"1775532647505026092","flags":0,"ts_in_delta":745,"sequence":191092,"symbol":"FCEU SI 20260615 PS"}
{"ts_recv":"2026-04-07T03:30:47.505107094Z","hd":{"ts_event":"2026-04-07T03:30:47.505081919Z","rtype":160,"publisher_id":101,"instrument_id":436},"action":"A","side":"A","price":"1.156840000","size":30,"channel_id":23,"order_id":"1775532647505091360","flags":128,"ts_in_delta":745,"sequence":191092,"symbol":"FCEU SI 20260615 PS"}
{"ts_recv":"2026-04-07T03:30:47.505160252Z","hd":{"ts_event":"2026-04-07T03:30:47.505145259Z","rtype":160,"publisher_id":101,"instrument_id":436},"action":"C","side":"B","price":"1.156740000","size":30,"channel_id":23,"order_id":"10998904684359867168","flags":0,"ts_in_delta":771,"sequence":191093,"symbol":"FCEU SI 20260615 PS"}
{"ts_recv":"2026-04-07T03:30:47.505160252Z","hd":{"ts_event":"2026-04-07T03:30:47.505145259Z","rtype":160,"publisher_id":101,"instrument_id":436},"action":"A","side":"B","price":"1.156750000","size":30,"channel_id":23,"order_id":"10998904684359926699","flags":0,"ts_in_delta":771,"sequence":191093,"symbol":"FCEU SI 20260615 PS"}
{"ts_recv":"2026-04-07T03:30:47.505160252Z","hd":{"ts_event":"2026-04-07T03:30:47.505145259Z","rtype":160,"publisher_id":101,"instrument_id":436},"action":"C","side":"A","price":"1.156840000","size":30,"channel_id":23,"order_id":"1775532647505091360","flags":0,"ts_in_delta":771,"sequence":191093,"symbol":"FCEU SI 20260615 PS"}
{"ts_recv":"2026-04-07T03:30:47.505160252Z","hd":{"ts_event":"2026-04-07T03:30:47.505145259Z","rtype":160,"publisher_id":101,"instrument_id":436},"action":"A","side":"A","price":"1.156850000","size":30,"channel_id":23,"order_id":"1775532647505150891","flags":128,"ts_in_delta":771,"sequence":191093,"symbol":"FCEU SI 20260615 PS"}
{"ts_recv":"2026-04-07T03:31:11.812237145Z","hd":{"ts_event":"2026-04-07T03:31:11.812211313Z","rtype":160,"publisher_id":101,"instrument_id":436},"action":"C","side":"B","price":"1.156750000","size":30,"channel_id":23,"order_id":"10998904684359926699","flags":0,"ts_in_delta":954,"sequence":191297,"symbol":"FCEU SI 20260615 PS"}
{"ts_recv":"2026-04-07T03:31:11.812237145Z","hd":{"ts_event":"2026-04-07T03:31:11.812211313Z","rtype":160,"publisher_id":101,"instrument_id":436},"action":"A","side":"B","price":"1.156760000","size":30,"channel_id":23,"order_id":"10998904708666993586","flags":0,"ts_in_delta":954,"sequence":191297,"symbol":"FCEU SI 20260615 PS"}
{"ts_recv":"2026-04-07T03:31:11.812237145Z","hd":{"ts_event":"2026-04-07T03:31:11.812211313Z","rtype":160,"publisher_id":101,"instrument_id":436},"action":"C","side":"A","price":"1.156850000","size":30,"channel_id":23,"order_id":"1775532647505150891","flags":0,"ts_in_delta":954,"sequence":191297,"symbol":"FCEU SI 20260615 PS"}
{"ts_recv":"2026-04-07T03:31:11.812237145Z","hd":{"ts_event":"2026-04-07T03:31:11.812211313Z","rtype":160,"publisher_id":101,"instrument_id":436},"action":"A","side":"A","price":"1.156860000","size":30,"channel_id":23,"order_id":"1775532671812217778","flags":128,"ts_in_delta":954,"sequence":191297,"symbol":"FCEU SI 20260615 PS"}
{"ts_recv":"2026-04-07T03:31:11.812296063Z","hd":{"ts_event":"2026-04-07T03:31:11.812274615Z","rtype":160,"publisher_id":101,"instrument_id":436},"action":"C","side":"B","price":"1.156750000","size":30,"channel_id":23,"order_id":"10998904684359855226","flags":0,"ts_in_delta":1056,"sequence":191298,"symbol":"FCEU SI 20260615 PS"}
{"ts_recv":"2026-04-07T03:31:11.812296063Z","hd":{"ts_event":"2026-04-07T03:31:11.812274615Z","rtype":160,"publisher_id":101,"instrument_id":436},"action":"A","side":"B","price":"1.156770000","size":30,"channel_id":23,"order_id":"10998904708667056379","flags":0,"ts_in_delta":1056,"sequence":191298,"symbol":"FCEU SI 20260615 PS"}
{"ts_recv":"2026-04-07T03:31:11.812296063Z","hd":{"ts_event":"2026-04-07T03:31:11.812274615Z","rtype":160,"publisher_id":101,"instrument_id":436},"action":"C","side":"A","price":"1.156850000","size":30,"channel_id":23,"order_id":"1775532647505079418","flags":0,"ts_in_delta":1056,"sequence":191298,"symbol":"FCEU SI 20260615 PS"}
{"ts_recv":"2026-04-07T03:31:11.812296063Z","hd":{"ts_event":"2026-04-07T03:31:11.812274615Z","rtype":160,"publisher_id":101,"instrument_id":436},"action":"A","side":"A","price":"1.156870000","size":30,"channel_id":23,"order_id":"1775532671812280571","flags":128,"ts_in_delta":1056,"sequence":191298,"symbol":"FCEU SI 20260615 PS"}
{"ts_recv":"2026-04-07T03:31:11.812355127Z","hd":{"ts_event":"2026-04-07T03:31:11.812335539Z","rtype":160,"publisher_id":101,"instrument_id":436},"action":"C","side":"B","price":"1.156760000","size":30,"channel_id":23,"order_id":"10998904708666993586","flags":0,"ts_in_delta":891,"sequence":191299,"symbol":"FCEU SI 20260615 PS"}
{"ts_recv":"2026-04-07T03:31:11.812355127Z","hd":{"ts_event":"2026-04-07T03:31:11.812335539Z","rtype":160,"publisher_id":101,"instrument_id":436},"action":"A","side":"B","price":"1.156770000","size":30,"channel_id":23,"order_id":"10998904708667117417","flags":0,"ts_in_delta":891,"sequence":191299,"symbol":"FCEU SI 20260615 PS"}
{"ts_recv":"2026-04-07T03:31:11.812355127Z","hd":{"ts_event":"2026-04-07T03:31:11.812335539Z","rtype":160,"publisher_id":101,"instrument_id":436},"action":"C","side":"A","price":"1.156860000","size":30,"channel_id":23,"order_id":"1775532671812217778","flags":0,"ts_in_delta":891,"sequence":191299,"symbol":"FCEU SI 20260615 PS"}
{"ts_recv":"2026-04-07T03:31:11.812355127Z","hd":{"ts_event":"2026-04-07T03:31:11.812335539Z","rtype":160,"publisher_id":101,"instrument_id":436},"action":"A","side":"A","price":"1.156870000","size":30,"channel_id":23,"order_id":"1775532671812341609","flags":128,"ts_in_delta":891,"sequence":191299,"symbol":"FCEU SI 20260615 PS"}
{"ts_recv":"2026-04-07T03:31:11.827248966Z","hd":{"ts_event":"2026-04-07T03:31:11.827228571Z","rtype":160,"publisher_id":101,"instrument_id":436},"action":"C","side":"B","price":"1.156770000","size":30,"channel_id":23,"order_id":"10998904708667117417","flags":0,"ts_in_delta":745,"sequence":191308,"symbol":"FCEU SI 20260615 PS"}
{"ts_recv":"2026-04-07T03:31:11.827248966Z","hd":{"ts_event":"2026-04-07T03:31:11.827228571Z","rtype":160,"publisher_id":101,"instrument_id":436},"action":"A","side":"B","price":"1.156760000","size":30,"channel_id":23,"order_id":"10998904708682012157","flags":0,"ts_in_delta":745,"sequence":191308,"symbol":"FCEU SI 20260615 PS"}
{"ts_recv":"2026-04-07T03:31:11.827248966Z","hd":{"ts_event":"2026-04-07T03:31:11.827228571Z","rtype":160,"publisher_id":101,"instrument_id":436},"action":"C","side":"A","price":"1.156870000","size":30,"channel_id":23,"order_id":"1775532671812341609","flags":0,"ts_in_delta":745,"sequence":191308,"symbol":"FCEU SI 20260615 PS"}
{"ts_recv":"2026-04-07T03:31:11.827248966Z","hd":{"ts_event":"2026-04-07T03:31:11.827228571Z","rtype":160,"publisher_id":101,"instrument_id":436},"action":"A","side":"A","price":"1.156860000","size":30,"channel_id":23,"order_id":"1775532671827236349","flags":128,"ts_in_delta":745,"sequence":191308,"symbol":"FCEU SI 20260615 PS"}
{"ts_recv":"2026-04-07T03:31:11.827331822Z","hd":{"ts_event":"2026-04-07T03:31:11.827311777Z","rtype":160,"publisher_id":101,"instrument_id":436},"action":"C","side":"B","price":"1.156760000","size":30,"channel_id":23,"order_id":"10998904708682012157","flags":0,"ts_in_delta":772,"sequence":191309,"symbol":"FCEU SI 20260615 PS"}
{"ts_recv":"2026-04-07T03:31:11.827331822Z","hd":{"ts_event":"2026-04-07T03:31:11.827311777Z","rtype":160,"publisher_id":101,"instrument_id":436},"action":"A","side":"B","price":"1.156750000","size":30,"channel_id":23,"order_id":"10998904708682093842","flags":0,"ts_in_delta":772,"sequence":191309,"symbol":"FCEU SI 20260615 PS"}
{"ts_recv":"2026-04-07T03:31:11.827331822Z","hd":{"ts_event":"2026-04-07T03:31:11.827311777Z","rtype":160,"publisher_id":101,"instrument_id":436},"action":"C","side":"A","price":"1.156860000","size":30,"channel_id":23,"order_id":"1775532671827236349","flags":0,"ts_in_delta":772,"sequence":191309,"symbol":"FCEU SI 20260615 PS"}
{"ts_recv":"2026-04-07T03:31:11.827331822Z","hd":{"ts_event":"2026-04-07T03:31:11.827311777Z","rtype":160,"publisher_id":101,"instrument_id":436},"action":"A","side":"A","price":"1.156850000","size":30,"channel_id":23,"order_id":"1775532671827318034","flags":128,"ts_in_delta":772,"sequence":191309,"symbol":"FCEU SI 20260615 PS"}
{"ts_recv":"2026-04-07T03:31:11.827381855Z","hd":{"ts_event":"2026-04-07T03:31:11.827363491Z","rtype":160,"publisher_id":101,"instrument_id":436},"action":"C","side":"B","price":"1.156770000","size":30,"channel_id":23,"order_id":"10998904708667056379","flags":0,"ts_in_delta":768,"sequence":191310,"symbol":"FCEU SI 20260615 PS"}
{"ts_recv":"2026-04-07T03:31:11.827381855Z","hd":{"ts_event":"2026-04-07T03:31:11.827363491Z","rtype":160,"publisher_id":101,"instrument_id":436},"action":"A","side":"B","price":"1.156750000","size":30,"channel_id":23,"order_id":"10998904708682145197","flags":0,"ts_in_delta":768,"sequence":191310,"symbol":"FCEU SI 20260615 PS"}
{"ts_recv":"2026-04-07T03:31:11.827381855Z","hd":{"ts_event":"2026-04-07T03:31:11.827363491Z","rtype":160,"publisher_id":101,"instrument_id":436},"action":"C","side":"A","price":"1.156870000","size":30,"channel_id":23,"order_id":"1775532671812280571","flags":0,"ts_in_delta":768,"sequence":191310,"symbol":"FCEU SI 20260615 PS"}
{"ts_recv":"2026-04-07T03:31:11.827381855Z","hd":{"ts_event":"2026-04-07T03:31:11.827363491Z","rtype":160,"publisher_id":101,"instrument_id":436},"action":"A","side":"A","price":"1.156850000","size":30,"channel_id":23,"order_id":"1775532671827369389","flags":128,"ts_in_delta":768,"sequence":191310,"symbol":"FCEU SI 20260615 PS"}
{"ts_recv":"2026-04-07T03:31:11.827391539Z","hd":{"ts_event":"2026-04-07T03:31:11.827371363Z","rtype":160,"publisher_id":101,"instrument_id":436},"action":"C","side":"B","price":"1.156750000","size":30,"channel_id":23,"order_id":"10998904708682093842","flags":0,"ts_in_delta":755,"sequence":191311,"symbol":"FCEU SI 20260615 PS"}
{"ts_recv":"2026-04-07T03:31:11.827391539Z","hd":{"ts_event":"2026-04-07T03:31:11.827371363Z","rtype":160,"publisher_id":101,"instrument_id":436},"action":"A","side":"B","price":"1.156760000","size":30,"channel_id":23,"order_id":"10998904708682154565","flags":0,"ts_in_delta":755,"sequence":191311,"symbol":"FCEU SI 20260615 PS"}
{"ts_recv":"2026-04-07T03:31:11.827391539Z","hd":{"ts_event":"2026-04-07T03:31:11.827371363Z","rtype":160,"publisher_id":101,"instrument_id":436},"action":"C","side":"A","price":"1.156850000","size":30,"channel_id":23,"order_id":"1775532671827318034","flags":0,"ts_in_delta":755,"sequence":191311,"symbol":"FCEU SI 20260615 PS"}
{"ts_recv":"2026-04-07T03:31:11.827391539Z","hd":{"ts_event":"2026-04-07T03:31:11.827371363Z","rtype":160,"publisher_id":101,"instrument_id":436},"action":"A","side":"A","price":"1.156860000","size":30,"channel_id":23,"order_id":"1775532671827378757","flags":128,"ts_in_delta":755,"sequence":191311,"symbol":"FCEU SI 20260615 PS"}
{"ts_recv":"2026-04-07T03:31:11.827447056Z","hd":{"ts_event":"2026-04-07T03:31:11.827431779Z","rtype":160,"publisher_id":101,"instrument_id":436},"action":"C","side":"B","price":"1.156760000","size":30,"channel_id":23,"order_id":"10998904708682154565","flags":0,"ts_in_delta":746,"sequence":191312,"symbol":"FCEU SI 20260615 PS"}
{"ts_recv":"2026-04-07T03:31:11.827447056Z","hd":{"ts_event":"2026-04-07T03:31:11.827431779Z","rtype":160,"publisher_id":101,"instrument_id":436},"action":"A","side":"B","price":"1.156750000","size":30,"channel_id":23,"order_id":"10998904708682213448","flags":0,"ts_in_delta":746,"sequence":191312,"symbol":"FCEU SI 20260615 PS"}
{"ts_recv":"2026-04-07T03:31:11.827447056Z","hd":{"ts_event":"2026-04-07T03:31:11.827431779Z","rtype":160,"publisher_id":101,"instrument_id":436},"action":"C","side":"A","price":"1.156860000","size":30,"channel_id":23,"order_id":"1775532671827378757","flags":0,"ts_in_delta":746,"sequence":191312,"symbol":"FCEU SI 20260615 PS"}
{"ts_recv":"2026-04-07T03:31:11.827447056Z","hd":{"ts_event":"2026-04-07T03:31:11.827431779Z","rtype":160,"publisher_id":101,"instrument_id":436},"action":"A","side":"A","price":"1.156850000","size":30,"channel_id":23,"order_id":"1775532671827437640","flags":128,"ts_in_delta":746,"sequence":191312,"symbol":"FCEU SI 20260615 PS"}
{"ts_recv":"2026-04-07T03:31:13.193307298Z","hd":{"ts_event":"2026-04-07T03:31:13.193278061Z","rtype":160,"publisher_id":101,"instrument_id":436},"action":"C","side":"B","price":"1.156750000","size":30,"channel_id":23,"order_id":"10998904708682213448","flags":0,"ts_in_delta":1202,"sequence":191348,"symbol":"FCEU SI 20260615 PS"}
{"ts_recv":"2026-04-07T03:31:13.193307298Z","hd":{"ts_event":"2026-04-07T03:31:13.193278061Z","rtype":160,"publisher_id":101,"instrument_id":436},"action":"A","side":"B","price":"1.156760000","size":30,"channel_id":23,"order_id":"10998904710048067053","flags":0,"ts_in_delta":1202,"sequence":191348,"symbol":"FCEU SI 20260615 PS"}
{"ts_recv":"2026-04-07T03:31:13.193307298Z","hd":{"ts_event":"2026-04-07T03:31:13.193278061Z","rtype":160,"publisher_id":101,"instrument_id":436},"action":"C","side":"A","price":"1.156850000","size":30,"channel_id":23,"order_id":"1775532671827437640","flags":0,"ts_in_delta":1202,"sequence":191348,"symbol":"FCEU SI 20260615 PS"}
{"ts_recv":"2026-04-07T03:31:13.193307298Z","hd":{"ts_event":"2026-04-07T03:31:13.193278061Z","rtype":160,"publisher_id":101,"instrument_id":436},"action":"A","side":"A","price":"1.156860000","size":30,"channel_id":23,"order_id":"1775532673193291245","flags":128,"ts_in_delta":1202,"sequence":191348,"symbol":"FCEU SI 20260615 PS"}
{"ts_recv":"2026-04-07T03:31:13.193370071Z","hd":{"ts_event":"2026-04-07T03:31:13.193349901Z","rtype":160,"publisher_id":101,"instrument_id":436},"action":"C","side":"B","price":"1.156750000","size":30,"channel_id":23,"order_id":"10998904708682145197","flags":0,"ts_in_delta":979,"sequence":191349,"symbol":"FCEU SI 20260615 PS"}
{"ts_recv":"2026-04-07T03:31:13.193370071Z","hd":{"ts_event":"2026-04-07T03:31:13.193349901Z","rtype":160,"publisher_id":101,"instrument_id":436},"action":"A","side":"B","price":"1.156770000","size":30,"channel_id":23,"order_id":"10998904710048131846","flags":0,"ts_in_delta":979,"sequence":191349,"symbol":"FCEU SI 20260615 PS"}
{"ts_recv":"2026-04-07T03:31:13.193370071Z","hd":{"ts_event":"2026-04-07T03:31:13.193349901Z","rtype":160,"publisher_id":101,"instrument_id":436},"action":"C","side":"A","price":"1.156850000","size":30,"channel_id":23,"order_id":"1775532671827369389","flags":0,"ts_in_delta":979,"sequence":191349,"symbol":"FCEU SI 20260615 PS"}
{"ts_recv":"2026-04-07T03:31:13.193370071Z","hd":{"ts_event":"2026-04-07T03:31:13.193349901Z","rtype":160,"publisher_id":101,"instrument_id":436},"action":"A","side":"A","price":"1.156870000","size":30,"channel_id":23,"order_id":"1775532673193356038","flags":128,"ts_in_delta":979,"sequence":191349,"symbol":"FCEU SI 20260615 PS"}
{"ts_recv":"2026-04-07T03:31:13.193376668Z","hd":{"ts_event":"2026-04-07T03:31:13.193358663Z","rtype":160,"publisher_id":101,"instrument_id":436},"action":"C","side":"B","price":"1.156760000","size":30,"channel_id":23,"order_id":"10998904710048067053","flags":0,"ts_in_delta":984,"sequence":191350,"symbol":"FCEU SI 20260615 PS"}
{"ts_recv":"2026-04-07T03:31:13.193376668Z","hd":{"ts_event":"2026-04-07T03:31:13.193358663Z","rtype":160,"publisher_id":101,"instrument_id":436},"action":"A","side":"B","price":"1.156770000","size":30,"channel_id":23,"order_id":"10998904710048141329","flags":0,"ts_in_delta":984,"sequence":191350,"symbol":"FCEU SI 20260615 PS"}
{"ts_recv":"2026-04-07T03:31:13.193376668Z","hd":{"ts_event":"2026-04-07T03:31:13.193358663Z","rtype":160,"publisher_id":101,"instrument_id":436},"action":"C","side":"A","price":"1.156860000","size":30,"channel_id":23,"order_id":"1775532673193291245","flags":0,"ts_in_delta":984,"sequence":191350,"symbol":"FCEU SI 20260615 PS"}
{"ts_recv":"2026-04-07T03:31:13.193376668Z","hd":{"ts_event":"2026-04-07T03:31:13.193358663Z","rtype":160,"publisher_id":101,"instrument_id":436},"action":"A","side":"A","price":"1.156870000","size":30,"channel_id":23,"order_id":"1775532673193365521","flags":128,"ts_in_delta":984,"sequence":191350,"symbol":"FCEU SI 20260615 PS"}
{"ts_recv":"2026-04-07T03:31:15.114841731Z","hd":{"ts_event":"2026-04-07T03:31:15.114816033Z","rtype":160,"publisher_id":101,"instrument_id":436},"action":"C","side":"B","price":"1.156770000","size":30,"channel_id":23,"order_id":"10998904710048141329","flags":0,"ts_in_delta":1338,"sequence":191382,"symbol":"FCEU SI 20260615 PS"}
{"ts_recv":"2026-04-07T03:31:15.114841731Z","hd":{"ts_event":"2026-04-07T03:31:15.114816033Z","rtype":160,"publisher_id":101,"instrument_id":436},"action":"A","side":"B","price":"1.156760000","size":30,"channel_id":23,"order_id":"10998904711969602512","flags":0,"ts_in_delta":1338,"sequence":191382,"symbol":"FCEU SI 20260615 PS"}
{"ts_recv":"2026-04-07T03:31:15.114841731Z","hd":{"ts_event":"2026-04-07T03:31:15.114816033Z","rtype":160,"publisher_id":101,"instrument_id":436},"action":"C","side":"A","price":"1.156870000","size":30,"channel_id":23,"order_id":"1775532673193365521","flags":0,"ts_in_delta":1338,"sequence":191382,"symbol":"FCEU SI 20260615 PS"}
{"ts_recv":"2026-04-07T03:31:15.114841731Z","hd":{"ts_event":"2026-04-07T03:31:15.114816033Z","rtype":160,"publisher_id":101,"instrument_id":436},"action":"A","side":"A","price":"1.156860000","size":30,"channel_id":23,"order_id":"1775532675114826704","flags":128,"ts_in_delta":1338,"sequence":191382,"symbol":"FCEU SI 20260615 PS"}
{"ts_recv":"2026-04-07T03:31:15.114909604Z","hd":{"ts_event":"2026-04-07T03:31:15.114889589Z","rtype":160,"publisher_id":101,"instrument_id":436},"action":"C","side":"B","price":"1.156760000","size":30,"channel_id":23,"order_id":"10998904711969602512","flags":0,"ts_in_delta":1071,"sequence":191383,"symbol":"FCEU SI 20260615 PS"}
{"ts_recv":"2026-04-07T03:31:15.114909604Z","hd":{"ts_event":"2026-04-07T03:31:15.114889589Z","rtype":160,"publisher_id":101,"instrument_id":436},"action":"A","side":"B","price":"1.156750000","size":30,"channel_id":23,"order_id":"10998904711969671337","flags":0,"ts_in_delta":1071,"sequence":191383,"symbol":"FCEU SI 20260615 PS"}
{"ts_recv":"2026-04-07T03:31:15.114909604Z","hd":{"ts_event":"2026-04-07T03:31:15.114889589Z","rtype":160,"publisher_id":101,"instrument_id":436},"action":"C","side":"A","price":"1.156860000","size":30,"channel_id":23,"order_id":"1775532675114826704","flags":0,"ts_in_delta":1071,"sequence":191383,"symbol":"FCEU SI 20260615 PS"}
{"ts_recv":"2026-04-07T03:31:15.114909604Z","hd":{"ts_event":"2026-04-07T03:31:15.114889589Z","rtype":160,"publisher_id":101,"instrument_id":436},"action":"A","side":"A","price":"1.156850000","size":30,"channel_id":23,"order_id":"1775532675114895529","flags":128,"ts_in_delta":1071,"sequence":191383,"symbol":"FCEU SI 20260615 PS"}
{"ts_recv":"2026-04-07T03:31:15.114966894Z","hd":{"ts_event":"2026-04-07T03:31:15.114949059Z","rtype":160,"publisher_id":101,"instrument_id":436},"action":"C","side":"B","price":"1.156770000","size":30,"channel_id":23,"order_id":"10998904710048131846","flags":0,"ts_in_delta":1115,"sequence":191384,"symbol":"FCEU SI 20260615 PS"}
{"ts_recv":"2026-04-07T03:31:15.114966894Z","hd":{"ts_event":"2026-04-07T03:31:15.114949059Z","rtype":160,"publisher_id":101,"instrument_id":436},"action":"A","side":"B","price":"1.156750000","size":30,"channel_id":23,"order_id":"10998904711969730956","flags":0,"ts_in_delta":1115,"sequence":191384,"symbol":"FCEU SI 20260615 PS"}
{"ts_recv":"2026-04-07T03:31:15.114966894Z","hd":{"ts_event":"2026-04-07T03:31:15.114949059Z","rtype":160,"publisher_id":101,"instrument_id":436},"action":"C","side":"A","price":"1.156870000","size":30,"channel_id":23,"order_id":"1775532673193356038","flags":0,"ts_in_delta":1115,"sequence":191384,"symbol":"FCEU SI 20260615 PS"}
{"ts_recv":"2026-04-07T03:31:15.114966894Z","hd":{"ts_event":"2026-04-07T03:31:15.114949059Z","rtype":160,"publisher_id":101,"instrument_id":436},"action":"A","side":"A","price":"1.156850000","size":30,"channel_id":23,"order_id":"1775532675114955148","flags":128,"ts_in_delta":1115,"sequence":191384,"symbol":"FCEU SI 20260615 PS"}
{"ts_recv":"2026-04-07T03:31:15.114977446Z","hd":{"ts_event":"2026-04-07T03:31:15.114951969Z","rtype":160,"publisher_id":101,"instrument_id":436},"action":"C","side":"B","price":"1.156750000","size":30,"channel_id":23,"order_id":"10998904711969671337","flags":0,"ts_in_delta":927,"sequence":191385,"symbol":"FCEU SI 20260615 PS"}
{"ts_recv":"2026-04-07T03:31:15.114977446Z","hd":{"ts_event":"2026-04-07T03:31:15.114951969Z","rtype":160,"publisher_id":101,"instrument_id":436},"action":"A","side":"B","price":"1.156760000","size":30,"channel_id":23,"order_id":"10998904711969739020","flags":0,"ts_in_delta":927,"sequence":191385,"symbol":"FCEU SI 20260615 PS"}
{"ts_recv":"2026-04-07T03:31:15.114977446Z","hd":{"ts_event":"2026-04-07T03:31:15.114951969Z","rtype":160,"publisher_id":101,"instrument_id":436},"action":"C","side":"A","price":"1.156850000","size":30,"channel_id":23,"order_id":"1775532675114895529","flags":0,"ts_in_delta":927,"sequence":191385,"symbol":"FCEU SI 20260615 PS"}
{"ts_recv":"2026-04-07T03:31:15.114977446Z","hd":{"ts_event":"2026-04-07T03:31:15.114951969Z","rtype":160,"publisher_id":101,"instrument_id":436},"action":"A","side":"A","price":"1.156860000","size":30,"channel_id":23,"order_id":"1775532675114963212","flags":128,"ts_in_delta":927,"sequence":191385,"symbol":"FCEU SI 20260615 PS"}
{"ts_recv":"2026-04-07T03:31:15.115032171Z","hd":{"ts_event":"2026-04-07T03:31:15.115014909Z","rtype":160,"publisher_id":101,"instrument_id":436},"action":"C","side":"B","price":"1.156760000","size":30,"channel_id":23,"order_id":"10998904711969739020","flags":0,"ts_in_delta":936,"sequence":191386,"symbol":"FCEU SI 20260615 PS"}
{"ts_recv":"2026-04-07T03:31:15.115032171Z","hd":{"ts_event":"2026-04-07T03:31:15.115014909Z","rtype":160,"publisher_id":101,"instrument_id":436},"action":"A","side":"B","price":"1.156750000","size":30,"channel_id":23,"order_id":"10998904711969796830","flags":0,"ts_in_delta":936,"sequence":191386,"symbol":"FCEU SI 20260615 PS"}
{"ts_recv":"2026-04-07T03:31:15.115032171Z","hd":{"ts_event":"2026-04-07T03:31:15.115014909Z","rtype":160,"publisher_id":101,"instrument_id":436},"action":"C","side":"A","price":"1.156860000","size":30,"channel_id":23,"order_id":"1775532675114963212","flags":0,"ts_in_delta":936,"sequence":191386,"symbol":"FCEU SI 20260615 PS"}
{"ts_recv":"2026-04-07T03:31:15.115032171Z","hd":{"ts_event":"2026-04-07T03:31:15.115014909Z","rtype":160,"publisher_id":101,"instrument_id":436},"action":"A","side":"A","price":"1.156850000","size":30,"channel_id":23,"order_id":"1775532675115021022","flags":128,"ts_in_delta":936,"sequence":191386,"symbol":"FCEU SI 20260615 PS"}
{"ts_recv":"2026-04-07T03:31:18.651762919Z","hd":{"ts_event":"2026-04-07T03:31:18.651742757Z","rtype":160,"publisher_id":101,"instrument_id":436},"action":"C","side":"B","price":"1.156750000","size":30,"channel_id":23,"order_id":"10998904711969796830","flags":0,"ts_in_delta":718,"sequence":191453,"symbol":"FCEU SI 20260615 PS"}
{"ts_recv":"2026-04-07T03:31:18.651762919Z","hd":{"ts_event":"2026-04-07T03:31:18.651742757Z","rtype":160,"publisher_id":101,"instrument_id":436},"action":"A","side":"B","price":"1.156760000","size":30,"channel_id":23,"order_id":"10998904715506524787","flags":0,"ts_in_delta":718,"sequence":191453,"symbol":"FCEU SI 20260615 PS"}
{"ts_recv":"2026-04-07T03:31:18.651762919Z","hd":{"ts_event":"2026-04-07T03:31:18.651742757Z","rtype":160,"publisher_id":101,"instrument_id":436},"action":"C","side":"A","price":"1.156850000","size":30,"channel_id":23,"order_id":"1775532675115021022","flags":0,"ts_in_delta":718,"sequence":191453,"symbol":"FCEU SI 20260615 PS"}
{"ts_recv":"2026-04-07T03:31:18.651762919Z","hd":{"ts_event":"2026-04-07T03:31:18.651742757Z","rtype":160,"publisher_id":101,"instrument_id":436},"action":"A","side":"A","price":"1.156860000","size":30,"channel_id":23,"order_id":"1775532678651748979","flags":128,"ts_in_delta":718,"sequence":191453,"symbol":"FCEU SI 20260615 PS"}
{"ts_recv":"2026-04-07T03:31:21.252068928Z","hd":{"ts_event":"2026-04-07T03:31:21.252046739Z","rtype":160,"publisher_id":101,"instrument_id":436},"action":"C","side":"B","price":"1.156760000","size":30,"channel_id":23,"order_id":"10998904715506524787","flags":0,"ts_in_delta":1036,"sequence":191479,"symbol":"FCEU SI 20260615 PS"}
{"ts_recv":"2026-04-07T03:31:21.252068928Z","hd":{"ts_event":"2026-04-07T03:31:21.252046739Z","rtype":160,"publisher_id":101,"instrument_id":436},"action":"A","side":"B","price":"1.156750000","size":30,"channel_id":23,"order_id":"10998904718106830692","flags":0,"ts_in_delta":1036,"sequence":191479,"symbol":"FCEU SI 20260615 PS"}
{"ts_recv":"2026-04-07T03:31:21.252068928Z","hd":{"ts_event":"2026-04-07T03:31:21.252046739Z","rtype":160,"publisher_id":101,"instrument_id":436},"action":"C","side":"A","price":"1.156860000","size":30,"channel_id":23,"order_id":"1775532678651748979","flags":0,"ts_in_delta":1036,"sequence":191479,"symbol":"FCEU SI 20260615 PS"}
{"ts_recv":"2026-04-07T03:31:21.252068928Z","hd":{"ts_event":"2026-04-07T03:31:21.252046739Z","rtype":160,"publisher_id":101,"instrument_id":436},"action":"A","side":"A","price":"1.156850000","size":30,"channel_id":23,"order_id":"1775532681252054884","flags":128,"ts_in_delta":1036,"sequence":191479,"symbol":"FCEU SI 20260615 PS"}
{"ts_recv":"2026-04-07T03:31:37.465286211Z","hd":{"ts_event":"2026-04-07T03:31:37.465254273Z","rtype":160,"publisher_id":101,"instrument_id":436},"action":"C","side":"B","price":"1.156750000","size":30,"channel_id":23,"order_id":"10998904718106830692","flags":0,"ts_in_delta":1652,"sequence":191556,"symbol":"FCEU SI 20260615 PS"}
{"ts_recv":"2026-04-07T03:31:37.465286211Z","hd":{"ts_event":"2026-04-07T03:31:37.465254273Z","rtype":160,"publisher_id":101,"instrument_id":436},"action":"A","side":"B","price":"1.156740000","size":30,"channel_id":23,"order_id":"10998904734320040819","flags":0,"ts_in_delta":1652,"sequence":191556,"symbol":"FCEU SI 20260615 PS"}
{"ts_recv":"2026-04-07T03:31:37.465286211Z","hd":{"ts_event":"2026-04-07T03:31:37.465254273Z","rtype":160,"publisher_id":101,"instrument_id":436},"action":"C","side":"A","price":"1.156850000","size":30,"channel_id":23,"order_id":"1775532681252054884","flags":0,"ts_in_delta":1652,"sequence":191556,"symbol":"FCEU SI 20260615 PS"}
{"ts_recv":"2026-04-07T03:31:37.465286211Z","hd":{"ts_event":"2026-04-07T03:31:37.465254273Z","rtype":160,"publisher_id":101,"instrument_id":436},"action":"A","side":"A","price":"1.156840000","size":30,"channel_id":23,"order_id":"1775532697465265011","flags":128,"ts_in_delta":1652,"sequence":191556,"symbol":"FCEU SI 20260615 PS"}
{"ts_recv":"2026-04-07T03:31:42.854024319Z","hd":{"ts_event":"2026-04-07T03:31:42.853993779Z","rtype":160,"publisher_id":101,"instrument_id":436},"action":"C","side":"B","price":"1.156750000","size":30,"channel_id":23,"order_id":"10998904711969730956","flags":0,"ts_in_delta":1011,"sequence":191588,"symbol":"FCEU SI 20260615 PS"}
{"ts_recv":"2026-04-07T03:31:42.854024319Z","hd":{"ts_event":"2026-04-07T03:31:42.853993779Z","rtype":160,"publisher_id":101,"instrument_id":436},"action":"A","side":"B","price":"1.156730000","size":30,"channel_id":23,"order_id":"10998904739708782364","flags":0,"ts_in_delta":1011,"sequence":191588,"symbol":"FCEU SI 20260615 PS"}
{"ts_recv":"2026-04-07T03:31:42.854024319Z","hd":{"ts_event":"2026-04-07T03:31:42.853993779Z","rtype":160,"publisher_id":101,"instrument_id":436},"action":"C","side":"A","price":"1.156850000","size":30,"channel_id":23,"order_id":"1775532675114955148","flags":0,"ts_in_delta":1011,"sequence":191588,"symbol":"FCEU SI 20260615 PS"}
{"ts_recv":"2026-04-07T03:31:42.854024319Z","hd":{"ts_event":"2026-04-07T03:31:42.853993779Z","rtype":160,"publisher_id":101,"instrument_id":436},"action":"A","side":"A","price":"1.156830000","size":30,"channel_id":23,"order_id":"1775532702854006556","flags":128,"ts_in_delta":1011,"sequence":191588,"symbol":"FCEU SI 20260615 PS"}
{"ts_recv":"2026-04-07T03:31:42.854128508Z","hd":{"ts_event":"2026-04-07T03:31:42.854111759Z","rtype":160,"publisher_id":101,"instrument_id":436},"action":"C","side":"B","price":"1.156740000","size":30,"channel_id":23,"order_id":"10998904734320040819","flags":0,"ts_in_delta":1106,"sequence":191589,"symbol":"FCEU SI 20260615 PS"}
{"ts_recv":"2026-04-07T03:31:42.854128508Z","hd":{"ts_event":"2026-04-07T03:31:42.854111759Z","rtype":160,"publisher_id":101,"instrument_id":436},"action":"A","side":"B","price":"1.156730000","size":30,"channel_id":23,"order_id":"10998904739708893725","flags":0,"ts_in_delta":1106,"sequence":191589,"symbol":"FCEU SI 20260615 PS"}
{"ts_recv":"2026-04-07T03:31:42.854128508Z","hd":{"ts_event":"2026-04-07T03:31:42.854111759Z","rtype":160,"publisher_id":101,"instrument_id":436},"action":"C","side":"A","price":"1.156840000","size":30,"channel_id":23,"order_id":"1775532697465265011","flags":0,"ts_in_delta":1106,"sequence":191589,"symbol":"FCEU SI 20260615 PS"}
{"ts_recv":"2026-04-07T03:31:42.854128508Z","hd":{"ts_event":"2026-04-07T03:31:42.854111759Z","rtype":160,"publisher_id":101,"instrument_id":436},"action":"A","side":"A","price":"1.156830000","size":30,"channel_id":23,"order_id":"1775532702854117917","flags":128,"ts_in_delta":1106,"sequence":191589,"symbol":"FCEU SI 20260615 PS"}
{"ts_recv":"2026-04-07T03:31:51.785623281Z","hd":{"ts_event":"2026-04-07T03:31:51.785602093Z","rtype":160,"publisher_id":101,"instrument_id":436},"action":"C","side":"B","price":"1.156730000","size":30,"channel_id":23,"order_id":"10998904739708893725","flags":0,"ts_in_delta":964,"sequence":191645,"symbol":"FCEU SI 20260615 PS"}
{"ts_recv":"2026-04-07T03:31:51.785623281Z","hd":{"ts_event":"2026-04-07T03:31:51.785602093Z","rtype":160,"publisher_id":101,"instrument_id":436},"action":"A","side":"B","price":"1.156720000","size":30,"channel_id":23,"order_id":"10998904748640384015","flags":0,"ts_in_delta":964,"sequence":191645,"symbol":"FCEU SI 20260615 PS"}
{"ts_recv":"2026-04-07T03:31:51.785623281Z","hd":{"ts_event":"2026-04-07T03:31:51.785602093Z","rtype":160,"publisher_id":101,"instrument_id":436},"action":"C","side":"A","price":"1.156830000","size":30,"channel_id":23,"order_id":"1775532702854117917","flags":0,"ts_in_delta":964,"sequence":191645,"symbol":"FCEU SI 20260615 PS"}
{"ts_recv":"2026-04-07T03:31:51.785623281Z","hd":{"ts_event":"2026-04-07T03:31:51.785602093Z","rtype":160,"publisher_id":101,"instrument_id":436},"action":"A","side":"A","price":"1.156820000","size":30,"channel_id":23,"order_id":"1775532711785608207","flags":128,"ts_in_delta":964,"sequence":191645,"symbol":"FCEU SI 20260615 PS"}
{"ts_recv":"2026-04-07T03:31:51.785706420Z","hd":{"ts_event":"2026-04-07T03:31:51.785688553Z","rtype":160,"publisher_id":101,"instrument_id":436},"action":"C","side":"B","price":"1.156720000","size":30,"channel_id":23,"order_id":"10998904748640384015","flags":0,"ts_in_delta":933,"sequence":191646,"symbol":"FCEU SI 20260615 PS"}
{"ts_recv":"2026-04-07T03:31:51.785706420Z","hd":{"ts_event":"2026-04-07T03:31:51.785688553Z","rtype":160,"publisher_id":101,"instrument_id":436},"action":"A","side":"B","price":"1.156710000","size":30,"channel_id":23,"order_id":"10998904748640470720","flags":0,"ts_in_delta":933,"sequence":191646,"symbol":"FCEU SI 20260615 PS"}
{"ts_recv":"2026-04-07T03:31:51.785706420Z","hd":{"ts_event":"2026-04-07T03:31:51.785688553Z","rtype":160,"publisher_id":101,"instrument_id":436},"action":"C","side":"A","price":"1.156820000","size":30,"channel_id":23,"order_id":"1775532711785608207","flags":0,"ts_in_delta":933,"sequence":191646,"symbol":"FCEU SI 20260615 PS"}
{"ts_recv":"2026-04-07T03:31:51.785706420Z","hd":{"ts_event":"2026-04-07T03:31:51.785688553Z","rtype":160,"publisher_id":101,"instrument_id":436},"action":"A","side":"A","price":"1.156810000","size":30,"channel_id":23,"order_id":"1775532711785694912","flags":128,"ts_in_delta":933,"sequence":191646,"symbol":"FCEU SI 20260615 PS"}
{"ts_recv":"2026-04-07T03:31:51.785771597Z","hd":{"ts_event":"2026-04-07T03:31:51.785752701Z","rtype":160,"publisher_id":101,"instrument_id":436},"action":"C","side":"B","price":"1.156710000","size":30,"channel_id":23,"order_id":"10998904748640470720","flags":0,"ts_in_delta":890,"sequence":191647,"symbol":"FCEU SI 20260615 PS"}
{"ts_recv":"2026-04-07T03:31:51.785771597Z","hd":{"ts_event":"2026-04-07T03:31:51.785752701Z","rtype":160,"publisher_id":101,"instrument_id":436},"action":"A","side":"B","price":"1.156720000","size":30,"channel_id":23,"order_id":"10998904748640534439","flags":0,"ts_in_delta":890,"sequence":191647,"symbol":"FCEU SI 20260615 PS"}
{"ts_recv":"2026-04-07T03:31:51.785771597Z","hd":{"ts_event":"2026-04-07T03:31:51.785752701Z","rtype":160,"publisher_id":101,"instrument_id":436},"action":"C","side":"A","price":"1.156810000","size":30,"channel_id":23,"order_id":"1775532711785694912","flags":0,"ts_in_delta":890,"sequence":191647,"symbol":"FCEU SI 20260615 PS"}
{"ts_recv":"2026-04-07T03:31:51.785771597Z","hd":{"ts_event":"2026-04-07T03:31:51.785752701Z","rtype":160,"publisher_id":101,"instrument_id":436},"action":"A","side":"A","price":"1.156820000","size":30,"channel_id":23,"order_id":"1775532711785758631","flags":128,"ts_in_delta":890,"sequence":191647,"symbol":"FCEU SI 20260615 PS"}
{"ts_recv":"2026-04-07T03:31:51.785783647Z","hd":{"ts_event":"2026-04-07T03:31:51.785753883Z","rtype":160,"publisher_id":101,"instrument_id":436},"action":"C","side":"B","price":"1.156730000","size":30,"channel_id":23,"order_id":"10998904739708782364","flags":0,"ts_in_delta":905,"sequence":191648,"symbol":"FCEU SI 20260615 PS"}
{"ts_recv":"2026-04-07T03:31:51.785783647Z","hd":{"ts_event":"2026-04-07T03:31:51.785753883Z","rtype":160,"publisher_id":101,"instrument_id":436},"action":"A","side":"B","price":"1.156710000","size":30,"channel_id":23,"order_id":"10998904748640544396","flags":0,"ts_in_delta":905,"sequence":191648,"symbol":"FCEU SI 20260615 PS"}
{"ts_recv":"2026-04-07T03:31:51.785783647Z","hd":{"ts_event":"2026-04-07T03:31:51.785753883Z","rtype":160,"publisher_id":101,"instrument_id":436},"action":"C","side":"A","price":"1.156830000","size":30,"channel_id":23,"order_id":"1775532702854006556","flags":0,"ts_in_delta":905,"sequence":191648,"symbol":"FCEU SI 20260615 PS"}
{"ts_recv":"2026-04-07T03:31:51.785783647Z","hd":{"ts_event":"2026-04-07T03:31:51.785753883Z","rtype":160,"publisher_id":101,"instrument_id":436},"action":"A","side":"A","price":"1.156810000","size":30,"channel_id":23,"order_id":"1775532711785768588","flags":128,"ts_in_delta":905,"sequence":191648,"symbol":"FCEU SI 20260615 PS"}
{"ts_recv":"2026-04-07T03:31:51.785846190Z","hd":{"ts_event":"2026-04-07T03:31:51.785828841Z","rtype":160,"publisher_id":101,"instrument_id":436},"action":"C","side":"B","price":"1.156720000","size":30,"channel_id":23,"order_id":"10998904748640534439","flags":0,"ts_in_delta":923,"sequence":191649,"symbol":"FCEU SI 20260615 PS"}
{"ts_recv":"2026-04-07T03:31:51.785846190Z","hd":{"ts_event":"2026-04-07T03:31:51.785828841Z","rtype":160,"publisher_id":101,"instrument_id":436},"action":"A","side":"B","price":"1.156710000","size":30,"channel_id":23,"order_id":"10998904748640610958","flags":0,"ts_in_delta":923,"sequence":191649,"symbol":"FCEU SI 20260615 PS"}
{"ts_recv":"2026-04-07T03:31:51.785846190Z","hd":{"ts_event":"2026-04-07T03:31:51.785828841Z","rtype":160,"publisher_id":101,"instrument_id":436},"action":"C","side":"A","price":"1.156820000","size":30,"channel_id":23,"order_id":"1775532711785758631","flags":0,"ts_in_delta":923,"sequence":191649,"symbol":"FCEU SI 20260615 PS"}
{"ts_recv":"2026-04-07T03:31:51.785846190Z","hd":{"ts_event":"2026-04-07T03:31:51.785828841Z","rtype":160,"publisher_id":101,"instrument_id":436},"action":"A","side":"A","price":"1.156810000","size":30,"channel_id":23,"order_id":"1775532711785835150","flags":128,"ts_in_delta":923,"sequence":191649,"symbol":"FCEU SI 20260615 PS"}
{"ts_recv":"2026-04-07T03:31:59.764793043Z","hd":{"ts_event":"2026-04-07T03:31:59.764770455Z","rtype":160,"publisher_id":101,"instrument_id":436},"action":"C","side":"B","price":"1.156710000","size":30,"channel_id":23,"order_id":"10998904748640610958","flags":0,"ts_in_delta":876,"sequence":191708,"symbol":"FCEU SI 20260615 PS"}
{"ts_recv":"2026-04-07T03:31:59.764793043Z","hd":{"ts_event":"2026-04-07T03:31:59.764770455Z","rtype":160,"publisher_id":101,"instrument_id":436},"action":"A","side":"B","price":"1.156720000","size":30,"channel_id":23,"order_id":"10998904756619552707","flags":0,"ts_in_delta":876,"sequence":191708,"symbol":"FCEU SI 20260615 PS"}
{"ts_recv":"2026-04-07T03:31:59.764793043Z","hd":{"ts_event":"2026-04-07T03:31:59.764770455Z","rtype":160,"publisher_id":101,"instrument_id":436},"action":"C","side":"A","price":"1.156810000","size":30,"channel_id":23,"order_id":"1775532711785835150","flags":0,"ts_in_delta":876,"sequence":191708,"symbol":"FCEU SI 20260615 PS"}
{"ts_recv":"2026-04-07T03:31:59.764793043Z","hd":{"ts_event":"2026-04-07T03:31:59.764770455Z","rtype":160,"publisher_id":101,"instrument_id":436},"action":"A","side":"A","price":"1.156820000","size":30,"channel_id":23,"order_id":"1775532719764776899","flags":128,"ts_in_delta":876,"sequence":191708,"symbol":"FCEU SI 20260615 PS"}
{"ts_recv":"2026-04-07T03:31:59.772170282Z","hd":{"ts_event":"2026-04-07T03:31:59.772149427Z","rtype":160,"publisher_id":101,"instrument_id":436},"action":"C","side":"B","price":"1.156710000","size":30,"channel_id":23,"order_id":"10998904748640544396","flags":0,"ts_in_delta":1028,"sequence":191709,"symbol":"FCEU SI 20260615 PS"}
{"ts_recv":"2026-04-07T03:31:59.772170282Z","hd":{"ts_event":"2026-04-07T03:31:59.772149427Z","rtype":160,"publisher_id":101,"instrument_id":436},"action":"A","side":"B","price":"1.156730000","size":30,"channel_id":23,"order_id":"10998904756626931653","flags":0,"ts_in_delta":1028,"sequence":191709,"symbol":"FCEU SI 20260615 PS"}
{"ts_recv":"2026-04-07T03:31:59.772170282Z","hd":{"ts_event":"2026-04-07T03:31:59.772149427Z","rtype":160,"publisher_id":101,"instrument_id":436},"action":"C","side":"A","price":"1.156810000","size":30,"channel_id":23,"order_id":"1775532711785768588","flags":0,"ts_in_delta":1028,"sequence":191709,"symbol":"FCEU SI 20260615 PS"}
{"ts_recv":"2026-04-07T03:31:59.772170282Z","hd":{"ts_event":"2026-04-07T03:31:59.772149427Z","rtype":160,"publisher_id":101,"instrument_id":436},"action":"A","side":"A","price":"1.156830000","size":30,"channel_id":23,"order_id":"1775532719772155845","flags":128,"ts_in_delta":1028,"sequence":191709,"symbol":"FCEU SI 20260615 PS"}
{"ts_recv":"2026-04-07T03:31:59.772239199Z","hd":{"ts_event":"2026-04-07T03:31:59.772221545Z","rtype":160,"publisher_id":101,"instrument_id":436},"action":"C","side":"B","price":"1.156720000","size":30,"channel_id":23,"order_id":"10998904756619552707","flags":0,"ts_in_delta":997,"sequence":191710,"symbol":"FCEU SI 20260615 PS"}
{"ts_recv":"2026-04-07T03:31:59.772239199Z","hd":{"ts_event":"2026-04-07T03:31:59.772221545Z","rtype":160,"publisher_id":101,"instrument_id":436},"action":"A","side":"B","price":"1.156730000","size":30,"channel_id":23,"order_id":"10998904756627003233","flags":0,"ts_in_delta":997,"sequence":191710,"symbol":"FCEU SI 20260615 PS"}
{"ts_recv":"2026-04-07T03:31:59.772239199Z","hd":{"ts_event":"2026-04-07T03:31:59.772221545Z","rtype":160,"publisher_id":101,"instrument_id":436},"action":"C","side":"A","price":"1.156820000","size":30,"channel_id":23,"order_id":"1775532719764776899","flags":0,"ts_in_delta":997,"sequence":191710,"symbol":"FCEU SI 20260615 PS"}
{"ts_recv":"2026-04-07T03:31:59.772239199Z","hd":{"ts_event":"2026-04-07T03:31:59.772221545Z","rtype":160,"publisher_id":101,"instrument_id":436},"action":"A","side":"A","price":"1.156830000","size":30,"channel_id":23,"order_id":"1775532719772227425","flags":128,"ts_in_delta":997,"sequence":191710,"symbol":"FCEU SI 20260615 PS"}
{"ts_recv":"2026-04-07T03:32:03.461390796Z","hd":{"ts_event":"2026-04-07T03:32:03.461368821Z","rtype":160,"publisher_id":101,"instrument_id":436},"action":"C","side":"B","price":"1.156730000","size":30,"channel_id":23,"order_id":"10998904756627003233","flags":0,"ts_in_delta":926,"sequence":191757,"symbol":"FCEU SI 20260615 PS"}
{"ts_recv":"2026-04-07T03:32:03.461390796Z","hd":{"ts_event":"2026-04-07T03:32:03.461368821Z","rtype":160,"publisher_id":101,"instrument_id":436},"action":"A","side":"B","price":"1.156740000","size":30,"channel_id":23,"order_id":"10998904760316150655","flags":0,"ts_in_delta":926,"sequence":191757,"symbol":"FCEU SI 20260615 PS"}
{"ts_recv":"2026-04-07T03:32:03.461390796Z","hd":{"ts_event":"2026-04-07T03:32:03.461368821Z","rtype":160,"publisher_id":101,"instrument_id":436},"action":"C","side":"A","price":"1.156830000","size":30,"channel_id":23,"order_id":"1775532719772227425","flags":0,"ts_in_delta":926,"sequence":191757,"symbol":"FCEU SI 20260615 PS"}
{"ts_recv":"2026-04-07T03:32:03.461390796Z","hd":{"ts_event":"2026-04-07T03:32:03.461368821Z","rtype":160,"publisher_id":101,"instrument_id":436},"action":"A","side":"A","price":"1.156840000","size":30,"channel_id":23,"order_id":"1775532723461374847","flags":128,"ts_in_delta":926,"sequence":191757,"symbol":"FCEU SI 20260615 PS"}
{"ts_recv":"2026-04-07T03:32:03.461455689Z","hd":{"ts_event":"2026-04-07T03:32:03.461436999Z","rtype":160,"publisher_id":101,"instrument_id":436},"action":"C","side":"B","price":"1.156730000","size":30,"channel_id":23,"order_id":"10998904756626931653","flags":0,"ts_in_delta":918,"sequence":191758,"symbol":"FCEU SI 20260615 PS"}
{"ts_recv":"2026-04-07T03:32:03.461455689Z","hd":{"ts_event":"2026-04-07T03:32:03.461436999Z","rtype":160,"publisher_id":101,"instrument_id":436},"action":"A","side":"B","price":"1.156750000","size":30,"channel_id":23,"order_id":"10998904760316219168","flags":0,"ts_in_delta":918,"sequence":191758,"symbol":"FCEU SI 20260615 PS"}
{"ts_recv":"2026-04-07T03:32:03.461455689Z","hd":{"ts_event":"2026-04-07T03:32:03.461436999Z","rtype":160,"publisher_id":101,"instrument_id":436},"action":"C","side":"A","price":"1.156830000","size":30,"channel_id":23,"order_id":"1775532719772155845","flags":0,"ts_in_delta":918,"sequence":191758,"symbol":"FCEU SI 20260615 PS"}
{"ts_recv":"2026-04-07T03:32:03.461455689Z","hd":{"ts_event":"2026-04-07T03:32:03.461436999Z","rtype":160,"publisher_id":101,"instrument_id":436},"action":"A","side":"A","price":"1.156850000","size":30,"channel_id":23,"order_id":"1775532723461443360","flags":128,"ts_in_delta":918,"sequence":191758,"symbol":"FCEU SI 20260615 PS"}
{"ts_recv":"2026-04-07T03:32:03.461515306Z","hd":{"ts_event":"2026-04-07T03:32:03.461496865Z","rtype":160,"publisher_id":101,"instrument_id":436},"action":"C","side":"B","price":"1.156740000","size":30,"channel_id":23,"order_id":"10998904760316150655","flags":0,"ts_in_delta":921,"sequence":191759,"symbol":"FCEU SI 20260615 PS"}
{"ts_recv":"2026-04-07T03:32:03.461515306Z","hd":{"ts_event":"2026-04-07T03:32:03.461496865Z","rtype":160,"publisher_id":101,"instrument_id":436},"action":"A","side":"B","price":"1.156750000","size":30,"channel_id":23,"order_id":"10998904760316278397","flags":0,"ts_in_delta":921,"sequence":191759,"symbol":"FCEU SI 20260615 PS"}
{"ts_recv":"2026-04-07T03:32:03.461515306Z","hd":{"ts_event":"2026-04-07T03:32:03.461496865Z","rtype":160,"publisher_id":101,"instrument_id":436},"action":"C","side":"A","price":"1.156840000","size":30,"channel_id":23,"order_id":"1775532723461374847","flags":0,"ts_in_delta":921,"sequence":191759,"symbol":"FCEU SI 20260615 PS"}
{"ts_recv":"2026-04-07T03:32:03.461515306Z","hd":{"ts_event":"2026-04-07T03:32:03.461496865Z","rtype":160,"publisher_id":101,"instrument_id":436},"action":"A","side":"A","price":"1.156850000","size":30,"channel_id":23,"order_id":"1775532723461502589","flags":128,"ts_in_delta":921,"sequence":191759,"symbol":"FCEU SI 20260615 PS"}
{"ts_recv":"2026-04-07T03:32:14.189644720Z","hd":{"ts_event":"2026-04-07T03:32:14.189620147Z","rtype":160,"publisher_id":101,"instrument_id":436},"action":"C","side":"B","price":"1.156750000","size":30,"channel_id":23,"order_id":"10998904760316278397","flags":0,"ts_in_delta":977,"sequence":191847,"symbol":"FCEU SI 20260615 PS"}
{"ts_recv":"2026-04-07T03:32:14.189644720Z","hd":{"ts_event":"2026-04-07T03:32:14.189620147Z","rtype":160,"publisher_id":101,"instrument_id":436},"action":"A","side":"B","price":"1.156760000","size":30,"channel_id":23,"order_id":"10998904771044403404","flags":0,"ts_in_delta":977,"sequence":191847,"symbol":"FCEU SI 20260615 PS"}
{"ts_recv":"2026-04-07T03:32:14.189644720Z","hd":{"ts_event":"2026-04-07T03:32:14.189620147Z","rtype":160,"publisher_id":101,"instrument_id":436},"action":"C","side":"A","price":"1.156850000","size":30,"channel_id":23,"order_id":"1775532723461502589","flags":0,"ts_in_delta":977,"sequence":191847,"symbol":"FCEU SI 20260615 PS"}
{"ts_recv":"2026-04-07T03:32:14.189644720Z","hd":{"ts_event":"2026-04-07T03:32:14.189620147Z","rtype":160,"publisher_id":101,"instrument_id":436},"action":"A","side":"A","price":"1.156860000","size":30,"channel_id":23,"order_id":"1775532734189627596","flags":128,"ts_in_delta":977,"sequence":191847,"symbol":"FCEU SI 20260615 PS"}
{"ts_recv":"2026-04-07T03:32:22.769885895Z","hd":{"ts_event":"2026-04-07T03:32:22.769855001Z","rtype":160,"publisher_id":101,"instrument_id":436},"action":"C","side":"B","price":"1.156750000","size":30,"channel_id":23,"order_id":"10998904760316219168","flags":0,"ts_in_delta":1203,"sequence":191896,"symbol":"FCEU SI 20260615 PS"}
{"ts_recv":"2026-04-07T03:32:22.769885895Z","hd":{"ts_event":"2026-04-07T03:32:22.769855001Z","rtype":160,"publisher_id":101,"instrument_id":436},"action":"A","side":"B","price":"1.156770000","size":30,"channel_id":23,"order_id":"10998904779624643943","flags":0,"ts_in_delta":1203,"sequence":191896,"symbol":"FCEU SI 20260615 PS"}
{"ts_recv":"2026-04-07T03:32:22.769885895Z","hd":{"ts_event":"2026-04-07T03:32:22.769855001Z","rtype":160,"publisher_id":101,"instrument_id":436},"action":"C","side":"A","price":"1.156850000","size":30,"channel_id":23,"order_id":"1775532723461443360","flags":0,"ts_in_delta":1203,"sequence":191896,"symbol":"FCEU SI 20260615 PS"}
{"ts_recv":"2026-04-07T03:32:22.769885895Z","hd":{"ts_event":"2026-04-07T03:32:22.769855001Z","rtype":160,"publisher_id":101,"instrument_id":436},"action":"A","side":"A","price":"1.156870000","size":30,"channel_id":23,"order_id":"1775532742769868135","flags":128,"ts_in_delta":1203,"sequence":191896,"symbol":"FCEU SI 20260615 PS"}
{"ts_recv":"2026-04-07T03:32:22.769987451Z","hd":{"ts_event":"2026-04-07T03:32:22.769969829Z","rtype":160,"publisher_id":101,"instrument_id":436},"action":"C","side":"B","price":"1.156760000","size":30,"channel_id":23,"order_id":"10998904771044403404","flags":0,"ts_in_delta":927,"sequence":191897,"symbol":"FCEU SI 20260615 PS"}
{"ts_recv":"2026-04-07T03:32:22.769987451Z","hd":{"ts_event":"2026-04-07T03:32:22.769969829Z","rtype":160,"publisher_id":101,"instrument_id":436},"action":"A","side":"B","price":"1.156770000","size":30,"channel_id":23,"order_id":"10998904779624752201","flags":0,"ts_in_delta":927,"sequence":191897,"symbol":"FCEU SI 20260615 PS"}
{"ts_recv":"2026-04-07T03:32:22.769987451Z","hd":{"ts_event":"2026-04-07T03:32:22.769969829Z","rtype":160,"publisher_id":101,"instrument_id":436},"action":"C","side":"A","price":"1.156860000","size":30,"channel_id":23,"order_id":"1775532734189627596","flags":0,"ts_in_delta":927,"sequence":191897,"symbol":"FCEU SI 20260615 PS"}
{"ts_recv":"2026-04-07T03:32:22.769987451Z","hd":{"ts_event":"2026-04-07T03:32:22.769969829Z","rtype":160,"publisher_id":101,"instrument_id":436},"action":"A","side":"A","price":"1.156870000","size":30,"channel_id":23,"order_id":"1775532742769976393","flags":128,"ts_in_delta":927,"sequence":191897,"symbol":"FCEU SI 20260615 PS"}
{"ts_recv":"2026-04-07T03:32:22.860129475Z","hd":{"ts_event":"2026-04-07T03:32:22.860111629Z","rtype":160,"publisher_id":101,"instrument_id":436},"action":"C","side":"B","price":"1.156770000","size":30,"channel_id":23,"order_id":"10998904779624752201","flags":0,"ts_in_delta":933,"sequence":191908,"symbol":"FCEU SI 20260615 PS"}
{"ts_recv":"2026-04-07T03:32:22.860129475Z","hd":{"ts_event":"2026-04-07T03:32:22.860111629Z","rtype":160,"publisher_id":101,"instrument_id":436},"action":"A","side":"B","price":"1.156760000","size":30,"channel_id":23,"order_id":"10998904779714893243","flags":0,"ts_in_delta":933,"sequence":191908,"symbol":"FCEU SI 20260615 PS"}
{"ts_recv":"2026-04-07T03:32:22.860129475Z","hd":{"ts_event":"2026-04-07T03:32:22.860111629Z","rtype":160,"publisher_id":101,"instrument_id":436},"action":"C","side":"A","price":"1.156870000","size":30,"channel_id":23,"order_id":"1775532742769976393","flags":0,"ts_in_delta":933,"sequence":191908,"symbol":"FCEU SI 20260615 PS"}
{"ts_recv":"2026-04-07T03:32:22.860129475Z","hd":{"ts_event":"2026-04-07T03:32:22.860111629Z","rtype":160,"publisher_id":101,"instrument_id":436},"action":"A","side":"A","price":"1.156860000","size":30,"channel_id":23,"order_id":"1775532742860117435","flags":128,"ts_in_delta":933,"sequence":191908,"symbol":"FCEU SI 20260615 PS"}
{"ts_recv":"2026-04-07T03:32:22.860211470Z","hd":{"ts_event":"2026-04-07T03:32:22.860193709Z","rtype":160,"publisher_id":101,"instrument_id":436},"action":"C","side":"B","price":"1.156760000","size":30,"channel_id":23,"order_id":"10998904779714893243","flags":0,"ts_in_delta":1126,"sequence":191909,"symbol":"FCEU SI 20260615 PS"}
{"ts_recv":"2026-04-07T03:32:22.860211470Z","hd":{"ts_event":"2026-04-07T03:32:22.860193709Z","rtype":160,"publisher_id":101,"instrument_id":436},"action":"A","side":"B","price":"1.156750000","size":30,"channel_id":23,"order_id":"10998904779714975623","flags":0,"ts_in_delta":1126,"sequence":191909,"symbol":"FCEU SI 20260615 PS"}
{"ts_recv":"2026-04-07T03:32:22.860211470Z","hd":{"ts_event":"2026-04-07T03:32:22.860193709Z","rtype":160,"publisher_id":101,"instrument_id":436},"action":"C","side":"A","price":"1.156860000","size":30,"channel_id":23,"order_id":"1775532742860117435","flags":0,"ts_in_delta":1126,"sequence":191909,"symbol":"FCEU SI 20260615 PS"}
{"ts_recv":"2026-04-07T03:32:22.860211470Z","hd":{"ts_event":"2026-04-07T03:32:22.860193709Z","rtype":160,"publisher_id":101,"instrument_id":436},"action":"A","side":"A","price":"1.156850000","size":30,"channel_id":23,"order_id":"1775532742860199815","flags":128,"ts_in_delta":1126,"sequence":191909,"symbol":"FCEU SI 20260615 PS"}
{"ts_recv":"2026-04-07T03:32:22.860270419Z","hd":{"ts_event":"2026-04-07T03:32:22.860251521Z","rtype":160,"publisher_id":101,"instrument_id":436},"action":"C","side":"B","price":"1.156770000","size":30,"channel_id":23,"order_id":"10998904779624643943","flags":0,"ts_in_delta":1116,"sequence":191910,"symbol":"FCEU SI 20260615 PS"}
{"ts_recv":"2026-04-07T03:32:22.860270419Z","hd":{"ts_event":"2026-04-07T03:32:22.860251521Z","rtype":160,"publisher_id":101,"instrument_id":436},"action":"A","side":"B","price":"1.156750000","size":30,"channel_id":23,"order_id":"10998904779715033251","flags":0,"ts_in_delta":1116,"sequence":191910,"symbol":"FCEU SI 20260615 PS"}
{"ts_recv":"2026-04-07T03:32:22.860270419Z","hd":{"ts_event":"2026-04-07T03:32:22.860251521Z","rtype":160,"publisher_id":101,"instrument_id":436},"action":"C","side":"A","price":"1.156870000","size":30,"channel_id":23,"order_id":"1775532742769868135","flags":0,"ts_in_delta":1116,"sequence":191910,"symbol":"FCEU SI 20260615 PS"}
{"ts_recv":"2026-04-07T03:32:22.860270419Z","hd":{"ts_event":"2026-04-07T03:32:22.860251521Z","rtype":160,"publisher_id":101,"instrument_id":436},"action":"A","side":"A","price":"1.156850000","size":30,"channel_id":23,"order_id":"1775532742860257443","flags":128,"ts_in_delta":1116,"sequence":191910,"symbol":"FCEU SI 20260615 PS"}
{"ts_recv":"2026-04-07T03:32:22.860281071Z","hd":{"ts_event":"2026-04-07T03:32:22.860254729Z","rtype":160,"publisher_id":101,"instrument_id":436},"action":"C","side":"B","price":"1.156750000","size":30,"channel_id":23,"order_id":"10998904779714975623","flags":0,"ts_in_delta":1107,"sequence":191911,"symbol":"FCEU SI 20260615 PS"}
{"ts_recv":"2026-04-07T03:32:22.860281071Z","hd":{"ts_event":"2026-04-07T03:32:22.860254729Z","rtype":160,"publisher_id":101,"instrument_id":436},"action":"A","side":"B","price":"1.156760000","size":30,"channel_id":23,"order_id":"10998904779715042999","flags":0,"ts_in_delta":1107,"sequence":191911,"symbol":"FCEU SI 20260615 PS"}
{"ts_recv":"2026-04-07T03:32:22.860281071Z","hd":{"ts_event":"2026-04-07T03:32:22.860254729Z","rtype":160,"publisher_id":101,"instrument_id":436},"action":"C","side":"A","price":"1.156850000","size":30,"channel_id":23,"order_id":"1775532742860199815","flags":0,"ts_in_delta":1107,"sequence":191911,"symbol":"FCEU SI 20260615 PS"}
{"ts_recv":"2026-04-07T03:32:22.860281071Z","hd":{"ts_event":"2026-04-07T03:32:22.860254729Z","rtype":160,"publisher_id":101,"instrument_id":436},"action":"A","side":"A","price":"1.156860000","size":30,"channel_id":23,"order_id":"1775532742860267191","flags":128,"ts_in_delta":1107,"sequence":191911,"symbol":"FCEU SI 20260615 PS"}
{"ts_recv":"2026-04-07T03:32:22.860337700Z","hd":{"ts_event":"2026-04-07T03:32:22.860318741Z","rtype":160,"publisher_id":101,"instrument_id":436},"action":"C","side":"B","price":"1.156760000","size":30,"channel_id":23,"order_id":"10998904779715042999","flags":0,"ts_in_delta":1052,"sequence":191912,"symbol":"FCEU SI 20260615 PS"}
{"ts_recv":"2026-04-07T03:32:22.860337700Z","hd":{"ts_event":"2026-04-07T03:32:22.860318741Z","rtype":160,"publisher_id":101,"instrument_id":436},"action":"A","side":"B","price":"1.156750000","size":30,"channel_id":23,"order_id":"10998904779715100291","flags":0,"ts_in_delta":1052,"sequence":191912,"symbol":"FCEU SI 20260615 PS"}
{"ts_recv":"2026-04-07T03:32:22.860337700Z","hd":{"ts_event":"2026-04-07T03:32:22.860318741Z","rtype":160,"publisher_id":101,"instrument_id":436},"action":"C","side":"A","price":"1.156860000","size":30,"channel_id":23,"order_id":"1775532742860267191","flags":0,"ts_in_delta":1052,"sequence":191912,"symbol":"FCEU SI 20260615 PS"}
{"ts_recv":"2026-04-07T03:32:22.860337700Z","hd":{"ts_event":"2026-04-07T03:32:22.860318741Z","rtype":160,"publisher_id":101,"instrument_id":436},"action":"A","side":"A","price":"1.156850000","size":30,"channel_id":23,"order_id":"1775532742860324483","flags":128,"ts_in_delta":1052,"sequence":191912,"symbol":"FCEU SI 20260615 PS"}
{"ts_recv":"2026-04-07T03:32:25.094836724Z","hd":{"ts_event":"2026-04-07T03:32:25.094815955Z","rtype":160,"publisher_id":101,"instrument_id":436},"action":"C","side":"B","price":"1.156750000","size":30,"channel_id":23,"order_id":"10998904779715100291","flags":0,"ts_in_delta":920,"sequence":191947,"symbol":"FCEU SI 20260615 PS"}
{"ts_recv":"2026-04-07T03:32:25.094836724Z","hd":{"ts_event":"2026-04-07T03:32:25.094815955Z","rtype":160,"publisher_id":101,"instrument_id":436},"action":"A","side":"B","price":"1.156740000","size":30,"channel_id":23,"order_id":"10998904781949597635","flags":0,"ts_in_delta":920,"sequence":191947,"symbol":"FCEU SI 20260615 PS"}
{"ts_recv":"2026-04-07T03:32:25.094836724Z","hd":{"ts_event":"2026-04-07T03:32:25.094815955Z","rtype":160,"publisher_id":101,"instrument_id":436},"action":"C","side":"A","price":"1.156850000","size":30,"channel_id":23,"order_id":"1775532742860324483","flags":0,"ts_in_delta":920,"sequence":191947,"symbol":"FCEU SI 20260615 PS"}
{"ts_recv":"2026-04-07T03:32:25.094836724Z","hd":{"ts_event":"2026-04-07T03:32:25.094815955Z","rtype":160,"publisher_id":101,"instrument_id":436},"action":"A","side":"A","price":"1.156840000","size":30,"channel_id":23,"order_id":"1775532745094821827","flags":128,"ts_in_delta":920,"sequence":191947,"symbol":"FCEU SI 20260615 PS"}
{"ts_recv":"2026-04-07T03:32:25.094892631Z","hd":{"ts_event":"2026-04-07T03:32:25.094874151Z","rtype":160,"publisher_id":101,"instrument_id":436},"action":"C","side":"B","price":"1.156750000","size":30,"channel_id":23,"order_id":"10998904779715033251","flags":0,"ts_in_delta":862,"sequence":191948,"symbol":"FCEU SI 20260615 PS"}
{"ts_recv":"2026-04-07T03:32:25.094892631Z","hd":{"ts_event":"2026-04-07T03:32:25.094874151Z","rtype":160,"publisher_id":101,"instrument_id":436},"action":"A","side":"B","price":"1.156730000","size":30,"channel_id":23,"order_id":"10998904781949655993","flags":0,"ts_in_delta":862,"sequence":191948,"symbol":"FCEU SI 20260615 PS"}
{"ts_recv":"2026-04-07T03:32:25.094892631Z","hd":{"ts_event":"2026-04-07T03:32:25.094874151Z","rtype":160,"publisher_id":101,"instrument_id":436},"action":"C","side":"A","price":"1.156850000","size":30,"channel_id":23,"order_id":"1775532742860257443","flags":0,"ts_in_delta":862,"sequence":191948,"symbol":"FCEU SI 20260615 PS"}
{"ts_recv":"2026-04-07T03:32:25.094892631Z","hd":{"ts_event":"2026-04-07T03:32:25.094874151Z","rtype":160,"publisher_id":101,"instrument_id":436},"action":"A","side":"A","price":"1.156830000","size":30,"channel_id":23,"order_id":"1775532745094880185","flags":128,"ts_in_delta":862,"sequence":191948,"symbol":"FCEU SI 20260615 PS"}
{"ts_recv":"2026-04-07T03:32:25.094945606Z","hd":{"ts_event":"2026-04-07T03:32:25.094929983Z","rtype":160,"publisher_id":101,"instrument_id":436},"action":"C","side":"B","price":"1.156740000","size":30,"channel_id":23,"order_id":"10998904781949597635","flags":0,"ts_in_delta":846,"sequence":191949,"symbol":"FCEU SI 20260615 PS"}
{"ts_recv":"2026-04-07T03:32:25.094945606Z","hd":{"ts_event":"2026-04-07T03:32:25.094929983Z","rtype":160,"publisher_id":101,"instrument_id":436},"action":"A","side":"B","price":"1.156730000","size":30,"channel_id":23,"order_id":"10998904781949711736","flags":0,"ts_in_delta":846,"sequence":191949,"symbol":"FCEU SI 20260615 PS"}
{"ts_recv":"2026-04-07T03:32:25.094945606Z","hd":{"ts_event":"2026-04-07T03:32:25.094929983Z","rtype":160,"publisher_id":101,"instrument_id":436},"action":"C","side":"A","price":"1.156840000","size":30,"channel_id":23,"order_id":"1775532745094821827","flags":0,"ts_in_delta":846,"sequence":191949,"symbol":"FCEU SI 20260615 PS"}
{"ts_recv":"2026-04-07T03:32:25.094945606Z","hd":{"ts_event":"2026-04-07T03:32:25.094929983Z","rtype":160,"publisher_id":101,"instrument_id":436},"action":"A","side":"A","price":"1.156830000","size":30,"channel_id":23,"order_id":"1775532745094935928","flags":128,"ts_in_delta":846,"sequence":191949,"symbol":"FCEU SI 20260615 PS"}
{"ts_recv":"2026-04-07T03:32:54.163243208Z","hd":{"ts_event":"2026-04-07T03:32:54.163219939Z","rtype":160,"publisher_id":101,"instrument_id":436},"action":"C","side":"B","price":"1.156730000","size":30,"channel_id":23,"order_id":"10998904781949711736","flags":0,"ts_in_delta":979,"sequence":192109,"symbol":"FCEU SI 20260615 PS"}
{"ts_recv":"2026-04-07T03:32:54.163243208Z","hd":{"ts_event":"2026-04-07T03:32:54.163219939Z","rtype":160,"publisher_id":101,"instrument_id":436},"action":"A","side":"B","price":"1.156740000","size":30,"channel_id":23,"order_id":"10998904811018001750","flags":0,"ts_in_delta":979,"sequence":192109,"symbol":"FCEU SI 20260615 PS"}
{"ts_recv":"2026-04-07T03:32:54.163243208Z","hd":{"ts_event":"2026-04-07T03:32:54.163219939Z","rtype":160,"publisher_id":101,"instrument_id":436},"action":"C","side":"A","price":"1.156830000","size":30,"channel_id":23,"order_id":"1775532745094935928","flags":0,"ts_in_delta":979,"sequence":192109,"symbol":"FCEU SI 20260615 PS"}
{"ts_recv":"2026-04-07T03:32:54.163243208Z","hd":{"ts_event":"2026-04-07T03:32:54.163219939Z","rtype":160,"publisher_id":101,"instrument_id":436},"action":"A","side":"A","price":"1.156840000","size":30,"channel_id":23,"order_id":"1775532774163225942","flags":128,"ts_in_delta":979,"sequence":192109,"symbol":"FCEU SI 20260615 PS"}
{"ts_recv":"2026-04-07T03:32:54.163729912Z","hd":{"ts_event":"2026-04-07T03:32:54.163707917Z","rtype":160,"publisher_id":101,"instrument_id":436},"action":"C","side":"B","price":"1.156730000","size":30,"channel_id":23,"order_id":"10998904781949655993","flags":0,"ts_in_delta":1021,"sequence":192110,"symbol":"FCEU SI 20260615 PS"}
{"ts_recv":"2026-04-07T03:32:54.163729912Z","hd":{"ts_event":"2026-04-07T03:32:54.163707917Z","rtype":160,"publisher_id":101,"instrument_id":436},"action":"A","side":"B","price":"1.156750000","size":30,"channel_id":23,"order_id":"10998904811018489875","flags":0,"ts_in_delta":1021,"sequence":192110,"symbol":"FCEU SI 20260615 PS"}
{"ts_recv":"2026-04-07T03:32:54.163729912Z","hd":{"ts_event":"2026-04-07T03:32:54.163707917Z","rtype":160,"publisher_id":101,"instrument_id":436},"action":"C","side":"A","price":"1.156830000","size":30,"channel_id":23,"order_id":"1775532745094880185","flags":0,"ts_in_delta":1021,"sequence":192110,"symbol":"FCEU SI 20260615 PS"}
{"ts_recv":"2026-04-07T03:32:54.163729912Z","hd":{"ts_event":"2026-04-07T03:32:54.163707917Z","rtype":160,"publisher_id":101,"instrument_id":436},"action":"A","side":"A","price":"1.156850000","size":30,"channel_id":23,"order_id":"1775532774163714067","flags":128,"ts_in_delta":1021,"sequence":192110,"symbol":"FCEU SI 20260615 PS"}
{"ts_recv":"2026-04-07T03:32:54.163788232Z","hd":{"ts_event":"2026-04-07T03:32:54.163768001Z","rtype":160,"publisher_id":101,"instrument_id":436},"action":"C","side":"B","price":"1.156740000","size":30,"channel_id":23,"order_id":"10998904811018001750","flags":0,"ts_in_delta":1134,"sequence":192111,"symbol":"FCEU SI 20260615 PS"}
{"ts_recv":"2026-04-07T03:32:54.163788232Z","hd":{"ts_event":"2026-04-07T03:32:54.163768001Z","rtype":160,"publisher_id":101,"instrument_id":436},"action":"A","side":"B","price":"1.156750000","size":30,"channel_id":23,"order_id":"10998904811018549882","flags":0,"ts_in_delta":1134,"sequence":192111,"symbol":"FCEU SI 20260615 PS"}
{"ts_recv":"2026-04-07T03:32:54.163788232Z","hd":{"ts_event":"2026-04-07T03:32:54.163768001Z","rtype":160,"publisher_id":101,"instrument_id":436},"action":"C","side":"A","price":"1.156840000","size":30,"channel_id":23,"order_id":"1775532774163225942","flags":0,"ts_in_delta":1134,"sequence":192111,"symbol":"FCEU SI 20260615 PS"}
{"ts_recv":"2026-04-07T03:32:54.163788232Z","hd":{"ts_event":"2026-04-07T03:32:54.163768001Z","rtype":160,"publisher_id":101,"instrument_id":436},"action":"A","side":"A","price":"1.156850000","size":30,"channel_id":23,"order_id":"1775532774163774074","flags":128,"ts_in_delta":1134,"sequence":192111,"symbol":"FCEU SI 20260615 PS"}
{"ts_recv":"2026-04-07T03:32:54.175790476Z","hd":{"ts_event":"2026-04-07T03:32:54.175770265Z","rtype":160,"publisher_id":101,"instrument_id":436},"action":"C","side":"B","price":"1.156750000","size":30,"channel_id":23,"order_id":"10998904811018549882","flags":0,"ts_in_delta":1537,"sequence":192115,"symbol":"FCEU SI 20260615 PS"}
{"ts_recv":"2026-04-07T03:32:54.175790476Z","hd":{"ts_event":"2026-04-07T03:32:54.175770265Z","rtype":160,"publisher_id":101,"instrument_id":436},"action":"A","side":"B","price":"1.156760000","size":30,"channel_id":23,"order_id":"10998904811030552420","flags":0,"ts_in_delta":1537,"sequence":192115,"symbol":"FCEU SI 20260615 PS"}
{"ts_recv":"2026-04-07T03:32:54.175790476Z","hd":{"ts_event":"2026-04-07T03:32:54.175770265Z","rtype":160,"publisher_id":101,"instrument_id":436},"action":"C","side":"A","price":"1.156850000","size":30,"channel_id":23,"order_id":"1775532774163774074","flags":0,"ts_in_delta":1537,"sequence":192115,"symbol":"FCEU SI 20260615 PS"}
{"ts_recv":"2026-04-07T03:32:54.175790476Z","hd":{"ts_event":"2026-04-07T03:32:54.175770265Z","rtype":160,"publisher_id":101,"instrument_id":436},"action":"A","side":"A","price":"1.156860000","size":30,"channel_id":23,"order_id":"1775532774175776612","flags":128,"ts_in_delta":1537,"sequence":192115,"symbol":"FCEU SI 20260615 PS"}
{"ts_recv":"2026-04-07T03:32:56.147242292Z","hd":{"ts_event":"2026-04-07T03:32:56.147218107Z","rtype":160,"publisher_id":101,"instrument_id":436},"action":"C","side":"B","price":"1.156760000","size":30,"channel_id":23,"order_id":"10998904811030552420","flags":0,"ts_in_delta":1365,"sequence":192133,"symbol":"FCEU SI 20260615 PS"}
{"ts_recv":"2026-04-07T03:32:56.147242292Z","hd":{"ts_event":"2026-04-07T03:32:56.147218107Z","rtype":160,"publisher_id":101,"instrument_id":436},"action":"A","side":"B","price":"1.156750000","size":30,"channel_id":23,"order_id":"10998904813002004349","flags":0,"ts_in_delta":1365,"sequence":192133,"symbol":"FCEU SI 20260615 PS"}
{"ts_recv":"2026-04-07T03:32:56.147242292Z","hd":{"ts_event":"2026-04-07T03:32:56.147218107Z","rtype":160,"publisher_id":101,"instrument_id":436},"action":"C","side":"A","price":"1.156860000","size":30,"channel_id":23,"order_id":"1775532774175776612","flags":0,"ts_in_delta":1365,"sequence":192133,"symbol":"FCEU SI 20260615 PS"}
{"ts_recv":"2026-04-07T03:32:56.147242292Z","hd":{"ts_event":"2026-04-07T03:32:56.147218107Z","rtype":160,"publisher_id":101,"instrument_id":436},"action":"A","side":"A","price":"1.156850000","size":30,"channel_id":23,"order_id":"1775532776147228541","flags":128,"ts_in_delta":1365,"sequence":192133,"symbol":"FCEU SI 20260615 PS"}
{"ts_recv":"2026-04-07T03:33:16.566335261Z","hd":{"ts_event":"2026-04-07T03:33:16.566304043Z","rtype":160,"publisher_id":101,"instrument_id":436},"action":"C","side":"B","price":"1.156750000","size":30,"channel_id":23,"order_id":"10998904813002004349","flags":0,"ts_in_delta":1208,"sequence":192205,"symbol":"FCEU SI 20260615 PS"}
{"ts_recv":"2026-04-07T03:33:16.566335261Z","hd":{"ts_event":"2026-04-07T03:33:16.566304043Z","rtype":160,"publisher_id":101,"instrument_id":436},"action":"A","side":"B","price":"1.156760000","size":30,"channel_id":23,"order_id":"10998904833421092809","flags":0,"ts_in_delta":1208,"sequence":192205,"symbol":"FCEU SI 20260615 PS"}
{"ts_recv":"2026-04-07T03:33:16.566335261Z","hd":{"ts_event":"2026-04-07T03:33:16.566304043Z","rtype":160,"publisher_id":101,"instrument_id":436},"action":"C","side":"A","price":"1.156850000","size":30,"channel_id":23,"order_id":"1775532776147228541","flags":0,"ts_in_delta":1208,"sequence":192205,"symbol":"FCEU SI 20260615 PS"}
{"ts_recv":"2026-04-07T03:33:16.566335261Z","hd":{"ts_event":"2026-04-07T03:33:16.566304043Z","rtype":160,"publisher_id":101,"instrument_id":436},"action":"A","side":"A","price":"1.156860000","size":30,"channel_id":23,"order_id":"1775532796566317001","flags":128,"ts_in_delta":1208,"sequence":192205,"symbol":"FCEU SI 20260615 PS"}
{"ts_recv":"2026-04-07T03:33:24.036563324Z","hd":{"ts_event":"2026-04-07T03:33:24.036540455Z","rtype":160,"publisher_id":101,"instrument_id":436},"action":"C","side":"B","price":"1.156750000","size":30,"channel_id":23,"order_id":"10998904811018489875","flags":0,"ts_in_delta":903,"sequence":192245,"symbol":"FCEU SI 20260615 PS"}
{"ts_recv":"2026-04-07T03:33:24.036563324Z","hd":{"ts_event":"2026-04-07T03:33:24.036540455Z","rtype":160,"publisher_id":101,"instrument_id":436},"action":"A","side":"B","price":"1.156770000","size":30,"channel_id":23,"order_id":"10998904840891322515","flags":0,"ts_in_delta":903,"sequence":192245,"symbol":"FCEU SI 20260615 PS"}
{"ts_recv":"2026-04-07T03:33:24.036563324Z","hd":{"ts_event":"2026-04-07T03:33:24.036540455Z","rtype":160,"publisher_id":101,"instrument_id":436},"action":"C","side":"A","price":"1.156850000","size":30,"channel_id":23,"order_id":"1775532774163714067","flags":0,"ts_in_delta":903,"sequence":192245,"symbol":"FCEU SI 20260615 PS"}
{"ts_recv":"2026-04-07T03:33:24.036563324Z","hd":{"ts_event":"2026-04-07T03:33:24.036540455Z","rtype":160,"publisher_id":101,"instrument_id":436},"action":"A","side":"A","price":"1.156870000","size":30,"channel_id":23,"order_id":"1775532804036546707","flags":128,"ts_in_delta":903,"sequence":192245,"symbol":"FCEU SI 20260615 PS"}
{"ts_recv":"2026-04-07T03:33:24.036679179Z","hd":{"ts_event":"2026-04-07T03:33:24.036661257Z","rtype":160,"publisher_id":101,"instrument_id":436},"action":"C","side":"B","price":"1.156760000","size":30,"channel_id":23,"order_id":"10998904833421092809","flags":0,"ts_in_delta":858,"sequence":192246,"symbol":"FCEU SI 20260615 PS"}
{"ts_recv":"2026-04-07T03:33:24.036679179Z","hd":{"ts_event":"2026-04-07T03:33:24.036661257Z","rtype":160,"publisher_id":101,"instrument_id":436},"action":"A","side":"B","price":"1.156770000","size":30,"channel_id":23,"order_id":"10998904840891443388","flags":0,"ts_in_delta":858,"sequence":192246,"symbol":"FCEU SI 20260615 PS"}
{"ts_recv":"2026-04-07T03:33:24.036679179Z","hd":{"ts_event":"2026-04-07T03:33:24.036661257Z","rtype":160,"publisher_id":101,"instrument_id":436},"action":"C","side":"A","price":"1.156860000","size":30,"channel_id":23,"order_id":"1775532796566317001","flags":0,"ts_in_delta":858,"sequence":192246,"symbol":"FCEU SI 20260615 PS"}
{"ts_recv":"2026-04-07T03:33:24.036679179Z","hd":{"ts_event":"2026-04-07T03:33:24.036661257Z","rtype":160,"publisher_id":101,"instrument_id":436},"action":"A","side":"A","price":"1.156870000","size":30,"channel_id":23,"order_id":"1775532804036667580","flags":128,"ts_in_delta":858,"sequence":192246,"symbol":"FCEU SI 20260615 PS"}
{"ts_recv":"2026-04-07T03:33:32.174100830Z","hd":{"ts_event":"2026-04-07T03:33:32.174078363Z","rtype":160,"publisher_id":101,"instrument_id":436},"action":"C","side":"B","price":"1.156770000","size":30,"channel_id":23,"order_id":"10998904840891443388","flags":0,"ts_in_delta":1097,"sequence":192337,"symbol":"FCEU SI 20260615 PS"}
{"ts_recv":"2026-04-07T03:33:32.174100830Z","hd":{"ts_event":"2026-04-07T03:33:32.174078363Z","rtype":160,"publisher_id":101,"instrument_id":436},"action":"A","side":"B","price":"1.156760000","size":30,"channel_id":23,"order_id":"10998904849028860404","flags":0,"ts_in_delta":1097,"sequence":192337,"symbol":"FCEU SI 20260615 PS"}
{"ts_recv":"2026-04-07T03:33:32.174100830Z","hd":{"ts_event":"2026-04-07T03:33:32.174078363Z","rtype":160,"publisher_id":101,"instrument_id":436},"action":"C","side":"A","price":"1.156870000","size":30,"channel_id":23,"order_id":"1775532804036667580","flags":0,"ts_in_delta":1097,"sequence":192337,"symbol":"FCEU SI 20260615 PS"}
{"ts_recv":"2026-04-07T03:33:32.174100830Z","hd":{"ts_event":"2026-04-07T03:33:32.174078363Z","rtype":160,"publisher_id":101,"instrument_id":436},"action":"A","side":"A","price":"1.156860000","size":30,"channel_id":23,"order_id":"1775532812174084596","flags":128,"ts_in_delta":1097,"sequence":192337,"symbol":"FCEU SI 20260615 PS"}
{"ts_recv":"2026-04-07T03:33:32.193725609Z","hd":{"ts_event":"2026-04-07T03:33:32.193706579Z","rtype":160,"publisher_id":101,"instrument_id":436},"action":"C","side":"B","price":"1.156770000","size":30,"channel_id":23,"order_id":"10998904840891322515","flags":0,"ts_in_delta":713,"sequence":192341,"symbol":"FCEU SI 20260615 PS"}
{"ts_recv":"2026-04-07T03:33:32.193725609Z","hd":{"ts_event":"2026-04-07T03:33:32.193706579Z","rtype":160,"publisher_id":101,"instrument_id":436},"action":"A","side":"B","price":"1.156750000","size":30,"channel_id":23,"order_id":"10998904849048488668","flags":0,"ts_in_delta":713,"sequence":192341,"symbol":"FCEU SI 20260615 PS"}
{"ts_recv":"2026-04-07T03:33:32.193725609Z","hd":{"ts_event":"2026-04-07T03:33:32.193706579Z","rtype":160,"publisher_id":101,"instrument_id":436},"action":"C","side":"A","price":"1.156870000","size":30,"channel_id":23,"order_id":"1775532804036546707","flags":0,"ts_in_delta":713,"sequence":192341,"symbol":"FCEU SI 20260615 PS"}
{"ts_recv":"2026-04-07T03:33:32.193725609Z","hd":{"ts_event":"2026-04-07T03:33:32.193706579Z","rtype":160,"publisher_id":101,"instrument_id":436},"action":"A","side":"A","price":"1.156850000","size":30,"channel_id":23,"order_id":"1775532812193712860","flags":128,"ts_in_delta":713,"sequence":192341,"symbol":"FCEU SI 20260615 PS"}
{"ts_recv":"2026-04-07T03:33:32.193786709Z","hd":{"ts_event":"2026-04-07T03:33:32.193767309Z","rtype":160,"publisher_id":101,"instrument_id":436},"action":"C","side":"B","price":"1.156760000","size":30,"channel_id":23,"order_id":"10998904849028860404","flags":0,"ts_in_delta":938,"sequence":192342,"symbol":"FCEU SI 20260615 PS"}
{"ts_recv":"2026-04-07T03:33:32.193786709Z","hd":{"ts_event":"2026-04-07T03:33:32.193767309Z","rtype":160,"publisher_id":101,"instrument_id":436},"action":"A","side":"B","price":"1.156750000","size":30,"channel_id":23,"order_id":"10998904849048549476","flags":0,"ts_in_delta":938,"sequence":192342,"symbol":"FCEU SI 20260615 PS"}
{"ts_recv":"2026-04-07T03:33:32.193786709Z","hd":{"ts_event":"2026-04-07T03:33:32.193767309Z","rtype":160,"publisher_id":101,"instrument_id":436},"action":"C","side":"A","price":"1.156860000","size":30,"channel_id":23,"order_id":"1775532812174084596","flags":0,"ts_in_delta":938,"sequence":192342,"symbol":"FCEU SI 20260615 PS"}
{"ts_recv":"2026-04-07T03:33:32.193786709Z","hd":{"ts_event":"2026-04-07T03:33:32.193767309Z","rtype":160,"publisher_id":101,"instrument_id":436},"action":"A","side":"A","price":"1.156850000","size":30,"channel_id":23,"order_id":"1775532812193773668","flags":128,"ts_in_delta":938,"sequence":192342,"symbol":"FCEU SI 20260615 PS"}
{"ts_recv":"2026-04-07T03:33:39.974031379Z","hd":{"ts_event":"2026-04-07T03:33:39.974008561Z","rtype":160,"publisher_id":101,"instrument_id":436},"action":"C","side":"B","price":"1.156750000","size":30,"channel_id":23,"order_id":"10998904849048488668","flags":0,"ts_in_delta":1020,"sequence":192421,"symbol":"FCEU SI 20260615 PS"}
{"ts_recv":"2026-04-07T03:33:39.974031379Z","hd":{"ts_event":"2026-04-07T03:33:39.974008561Z","rtype":160,"publisher_id":101,"instrument_id":436},"action":"A","side":"B","price":"1.156770000","size":30,"channel_id":23,"order_id":"10998904856828790466","flags":0,"ts_in_delta":1020,"sequence":192421,"symbol":"FCEU SI 20260615 PS"}
{"ts_recv":"2026-04-07T03:33:39.974031379Z","hd":{"ts_event":"2026-04-07T03:33:39.974008561Z","rtype":160,"publisher_id":101,"instrument_id":436},"action":"C","side":"A","price":"1.156850000","size":30,"channel_id":23,"order_id":"1775532812193712860","flags":0,"ts_in_delta":1020,"sequence":192421,"symbol":"FCEU SI 20260615 PS"}
{"ts_recv":"2026-04-07T03:33:39.974031379Z","hd":{"ts_event":"2026-04-07T03:33:39.974008561Z","rtype":160,"publisher_id":101,"instrument_id":436},"action":"A","side":"A","price":"1.156870000","size":30,"channel_id":23,"order_id":"1775532819974014658","flags":128,"ts_in_delta":1020,"sequence":192421,"symbol":"FCEU SI 20260615 PS"}
{"ts_recv":"2026-04-07T03:33:39.974217180Z","hd":{"ts_event":"2026-04-07T03:33:39.974201081Z","rtype":160,"publisher_id":101,"instrument_id":436},"action":"C","side":"B","price":"1.156750000","size":30,"channel_id":23,"order_id":"10998904849048549476","flags":0,"ts_in_delta":902,"sequence":192423,"symbol":"FCEU SI 20260615 PS"}
{"ts_recv":"2026-04-07T03:33:39.974217180Z","hd":{"ts_event":"2026-04-07T03:33:39.974201081Z","rtype":160,"publisher_id":101,"instrument_id":436},"action":"A","side":"B","price":"1.156760000","size":30,"channel_id":23,"order_id":"10998904856828982949","flags":0,"ts_in_delta":902,"sequence":192423,"symbol":"FCEU SI 20260615 PS"}
{"ts_recv":"2026-04-07T03:33:39.974217180Z","hd":{"ts_event":"2026-04-07T03:33:39.974201081Z","rtype":160,"publisher_id":101,"instrument_id":436},"action":"C","side":"A","price":"1.156850000","size":30,"channel_id":23,"order_id":"1775532812193773668","flags":0,"ts_in_delta":902,"sequence":192423,"symbol":"FCEU SI 20260615 PS"}
{"ts_recv":"2026-04-07T03:33:39.974217180Z","hd":{"ts_event":"2026-04-07T03:33:39.974201081Z","rtype":160,"publisher_id":101,"instrument_id":436},"action":"A","side":"A","price":"1.156860000","size":30,"channel_id":23,"order_id":"1775532819974207141","flags":128,"ts_in_delta":902,"sequence":192423,"symbol":"FCEU SI 20260615 PS"}
{"ts_recv":"2026-04-07T03:33:39.975986049Z","hd":{"ts_event":"2026-04-07T03:33:39.975970175Z","rtype":160,"publisher_id":101,"instrument_id":436},"action":"C","side":"B","price":"1.156760000","size":30,"channel_id":23,"order_id":"10998904856828982949","flags":0,"ts_in_delta":865,"sequence":192426,"symbol":"FCEU SI 20260615 PS"}
{"ts_recv":"2026-04-07T03:33:39.975986049Z","hd":{"ts_event":"2026-04-07T03:33:39.975970175Z","rtype":160,"publisher_id":101,"instrument_id":436},"action":"A","side":"B","price":"1.156770000","size":30,"channel_id":23,"order_id":"10998904856830752248","flags":0,"ts_in_delta":865,"sequence":192426,"symbol":"FCEU SI 20260615 PS"}
{"ts_recv":"2026-04-07T03:33:39.975986049Z","hd":{"ts_event":"2026-04-07T03:33:39.975970175Z","rtype":160,"publisher_id":101,"instrument_id":436},"action":"C","side":"A","price":"1.156860000","size":30,"channel_id":23,"order_id":"1775532819974207141","flags":0,"ts_in_delta":865,"sequence":192426,"symbol":"FCEU SI 20260615 PS"}
{"ts_recv":"2026-04-07T03:33:39.975986049Z","hd":{"ts_event":"2026-04-07T03:33:39.975970175Z","rtype":160,"publisher_id":101,"instrument_id":436},"action":"A","side":"A","price":"1.156870000","size":30,"channel_id":23,"order_id":"1775532819975976440","flags":128,"ts_in_delta":865,"sequence":192426,"symbol":"FCEU SI 20260615 PS"}
{"ts_recv":"2026-04-07T03:33:39.983081468Z","hd":{"ts_event":"2026-04-07T03:33:39.983063411Z","rtype":160,"publisher_id":101,"instrument_id":436},"action":"C","side":"B","price":"1.156770000","size":30,"channel_id":23,"order_id":"10998904856830752248","flags":0,"ts_in_delta":882,"sequence":192429,"symbol":"FCEU SI 20260615 PS"}
{"ts_recv":"2026-04-07T03:33:39.983081468Z","hd":{"ts_event":"2026-04-07T03:33:39.983063411Z","rtype":160,"publisher_id":101,"instrument_id":436},"action":"A","side":"B","price":"1.156780000","size":30,"channel_id":23,"order_id":"10998904856837845184","flags":0,"ts_in_delta":882,"sequence":192429,"symbol":"FCEU SI 20260615 PS"}
{"ts_recv":"2026-04-07T03:33:39.983081468Z","hd":{"ts_event":"2026-04-07T03:33:39.983063411Z","rtype":160,"publisher_id":101,"instrument_id":436},"action":"C","side":"A","price":"1.156870000","size":30,"channel_id":23,"order_id":"1775532819975976440","flags":0,"ts_in_delta":882,"sequence":192429,"symbol":"FCEU SI 20260615 PS"}
{"ts_recv":"2026-04-07T03:33:39.983081468Z","hd":{"ts_event":"2026-04-07T03:33:39.983063411Z","rtype":160,"publisher_id":101,"instrument_id":436},"action":"A","side":"A","price":"1.156880000","size":30,"channel_id":23,"order_id":"1775532819983069376","flags":128,"ts_in_delta":882,"sequence":192429,"symbol":"FCEU SI 20260615 PS"}
{"ts_recv":"2026-04-07T03:33:39.989687018Z","hd":{"ts_event":"2026-04-07T03:33:39.989670717Z","rtype":160,"publisher_id":101,"instrument_id":436},"action":"C","side":"B","price":"1.156780000","size":30,"channel_id":23,"order_id":"10998904856837845184","flags":0,"ts_in_delta":860,"sequence":192431,"symbol":"FCEU SI 20260615 PS"}
{"ts_recv":"2026-04-07T03:33:39.989687018Z","hd":{"ts_event":"2026-04-07T03:33:39.989670717Z","rtype":160,"publisher_id":101,"instrument_id":436},"action":"A","side":"B","price":"1.156770000","size":30,"channel_id":23,"order_id":"10998904856844452588","flags":0,"ts_in_delta":860,"sequence":192431,"symbol":"FCEU SI 20260615 PS"}
{"ts_recv":"2026-04-07T03:33:39.989687018Z","hd":{"ts_event":"2026-04-07T03:33:39.989670717Z","rtype":160,"publisher_id":101,"instrument_id":436},"action":"C","side":"A","price":"1.156880000","size":30,"channel_id":23,"order_id":"1775532819983069376","flags":0,"ts_in_delta":860,"sequence":192431,"symbol":"FCEU SI 20260615 PS"}
{"ts_recv":"2026-04-07T03:33:39.989687018Z","hd":{"ts_event":"2026-04-07T03:33:39.989670717Z","rtype":160,"publisher_id":101,"instrument_id":436},"action":"A","side":"A","price":"1.156870000","size":30,"channel_id":23,"order_id":"1775532819989676780","flags":128,"ts_in_delta":860,"sequence":192431,"symbol":"FCEU SI 20260615 PS"}
{"ts_recv":"2026-04-07T03:33:39.994546062Z","hd":{"ts_event":"2026-04-07T03:33:39.994523713Z","rtype":160,"publisher_id":101,"instrument_id":436},"action":"C","side":"B","price":"1.156770000","size":30,"channel_id":23,"order_id":"10998904856844452588","flags":0,"ts_in_delta":861,"sequence":192436,"symbol":"FCEU SI 20260615 PS"}
{"ts_recv":"2026-04-07T03:33:39.994546062Z","hd":{"ts_event":"2026-04-07T03:33:39.994523713Z","rtype":160,"publisher_id":101,"instrument_id":436},"action":"A","side":"B","price":"1.156760000","size":30,"channel_id":23,"order_id":"10998904856849305457","flags":0,"ts_in_delta":861,"sequence":192436,"symbol":"FCEU SI 20260615 PS"}
{"ts_recv":"2026-04-07T03:33:39.994546062Z","hd":{"ts_event":"2026-04-07T03:33:39.994523713Z","rtype":160,"publisher_id":101,"instrument_id":436},"action":"C","side":"A","price":"1.156870000","size":30,"channel_id":23,"order_id":"1775532819989676780","flags":0,"ts_in_delta":861,"sequence":192436,"symbol":"FCEU SI 20260615 PS"}
{"ts_recv":"2026-04-07T03:33:39.994546062Z","hd":{"ts_event":"2026-04-07T03:33:39.994523713Z","rtype":160,"publisher_id":101,"instrument_id":436},"action":"A","side":"A","price":"1.156860000","size":30,"channel_id":23,"order_id":"1775532819994529649","flags":128,"ts_in_delta":861,"sequence":192436,"symbol":"FCEU SI 20260615 PS"}
{"ts_recv":"2026-04-07T03:33:44.734969608Z","hd":{"ts_event":"2026-04-07T03:33:44.734945565Z","rtype":160,"publisher_id":101,"instrument_id":436},"action":"C","side":"B","price":"1.156770000","size":30,"channel_id":23,"order_id":"10998904856828790466","flags":0,"ts_in_delta":1462,"sequence":192469,"symbol":"FCEU SI 20260615 PS"}
{"ts_recv":"2026-04-07T03:33:44.734969608Z","hd":{"ts_event":"2026-04-07T03:33:44.734945565Z","rtype":160,"publisher_id":101,"instrument_id":436},"action":"A","side":"B","price":"1.156750000","size":30,"channel_id":23,"order_id":"10998904861589729630","flags":0,"ts_in_delta":1462,"sequence":192469,"symbol":"FCEU SI 20260615 PS"}
{"ts_recv":"2026-04-07T03:33:44.734969608Z","hd":{"ts_event":"2026-04-07T03:33:44.734945565Z","rtype":160,"publisher_id":101,"instrument_id":436},"action":"C","side":"A","price":"1.156870000","size":30,"channel_id":23,"order_id":"1775532819974014658","flags":0,"ts_in_delta":1462,"sequence":192469,"symbol":"FCEU SI 20260615 PS"}
{"ts_recv":"2026-04-07T03:33:44.734969608Z","hd":{"ts_event":"2026-04-07T03:33:44.734945565Z","rtype":160,"publisher_id":101,"instrument_id":436},"action":"A","side":"A","price":"1.156850000","size":30,"channel_id":23,"order_id":"1775532824734953822","flags":128,"ts_in_delta":1462,"sequence":192469,"symbol":"FCEU SI 20260615 PS"}
{"ts_recv":"2026-04-07T03:33:44.735065358Z","hd":{"ts_event":"2026-04-07T03:33:44.735048561Z","rtype":160,"publisher_id":101,"instrument_id":436},"action":"C","side":"B","price":"1.156760000","size":30,"channel_id":23,"order_id":"10998904856849305457","flags":0,"ts_in_delta":1077,"sequence":192470,"symbol":"FCEU SI 20260615 PS"}
{"ts_recv":"2026-04-07T03:33:44.735065358Z","hd":{"ts_event":"2026-04-07T03:33:44.735048561Z","rtype":160,"publisher_id":101,"instrument_id":436},"action":"A","side":"B","price":"1.156750000","size":30,"channel_id":23,"order_id":"10998904861589830400","flags":0,"ts_in_delta":1077,"sequence":192470,"symbol":"FCEU SI 20260615 PS"}
{"ts_recv":"2026-04-07T03:33:44.735065358Z","hd":{"ts_event":"2026-04-07T03:33:44.735048561Z","rtype":160,"publisher_id":101,"instrument_id":436},"action":"C","side":"A","price":"1.156860000","size":30,"channel_id":23,"order_id":"1775532819994529649","flags":0,"ts_in_delta":1077,"sequence":192470,"symbol":"FCEU SI 20260615 PS"}
{"ts_recv":"2026-04-07T03:33:44.735065358Z","hd":{"ts_event":"2026-04-07T03:33:44.735048561Z","rtype":160,"publisher_id":101,"instrument_id":436},"action":"A","side":"A","price":"1.156850000","size":30,"channel_id":23,"order_id":"1775532824735054592","flags":128,"ts_in_delta":1077,"sequence":192470,"symbol":"FCEU SI 20260615 PS"}
{"ts_recv":"2026-04-07T03:33:49.994856123Z","hd":{"ts_event":"2026-04-07T03:33:49.994829355Z","rtype":160,"publisher_id":101,"instrument_id":436},"action":"C","side":"B","price":"1.156750000","size":30,"channel_id":23,"order_id":"10998904861589830400","flags":0,"ts_in_delta":1459,"sequence":192499,"symbol":"FCEU SI 20260615 PS"}
{"ts_recv":"2026-04-07T03:33:49.994856123Z","hd":{"ts_event":"2026-04-07T03:33:49.994829355Z","rtype":160,"publisher_id":101,"instrument_id":436},"action":"A","side":"B","price":"1.156760000","size":30,"channel_id":23,"order_id":"10998904866849614167","flags":0,"ts_in_delta":1459,"sequence":192499,"symbol":"FCEU SI 20260615 PS"}
{"ts_recv":"2026-04-07T03:33:49.994856123Z","hd":{"ts_event":"2026-04-07T03:33:49.994829355Z","rtype":160,"publisher_id":101,"instrument_id":436},"action":"C","side":"A","price":"1.156850000","size":30,"channel_id":23,"order_id":"1775532824735054592","flags":0,"ts_in_delta":1459,"sequence":192499,"symbol":"FCEU SI 20260615 PS"}
{"ts_recv":"2026-04-07T03:33:49.994856123Z","hd":{"ts_event":"2026-04-07T03:33:49.994829355Z","rtype":160,"publisher_id":101,"instrument_id":436},"action":"A","side":"A","price":"1.156860000","size":30,"channel_id":23,"order_id":"1775532829994838359","flags":128,"ts_in_delta":1459,"sequence":192499,"symbol":"FCEU SI 20260615 PS"}
{"ts_recv":"2026-04-07T03:33:57.926332525Z","hd":{"ts_event":"2026-04-07T03:33:57.926311967Z","rtype":160,"publisher_id":101,"instrument_id":436},"action":"C","side":"B","price":"1.156750000","size":30,"channel_id":23,"order_id":"10998904861589729630","flags":0,"ts_in_delta":755,"sequence":192548,"symbol":"FCEU SI 20260615 PS"}
{"ts_recv":"2026-04-07T03:33:57.926332525Z","hd":{"ts_event":"2026-04-07T03:33:57.926311967Z","rtype":160,"publisher_id":101,"instrument_id":436},"action":"A","side":"B","price":"1.156770000","size":30,"channel_id":23,"order_id":"10998904874781093985","flags":0,"ts_in_delta":755,"sequence":192548,"symbol":"FCEU SI 20260615 PS"}
{"ts_recv":"2026-04-07T03:33:57.926332525Z","hd":{"ts_event":"2026-04-07T03:33:57.926311967Z","rtype":160,"publisher_id":101,"instrument_id":436},"action":"C","side":"A","price":"1.156850000","size":30,"channel_id":23,"order_id":"1775532824734953822","flags":0,"ts_in_delta":755,"sequence":192548,"symbol":"FCEU SI 20260615 PS"}
{"ts_recv":"2026-04-07T03:33:57.926332525Z","hd":{"ts_event":"2026-04-07T03:33:57.926311967Z","rtype":160,"publisher_id":101,"instrument_id":436},"action":"A","side":"A","price":"1.156870000","size":30,"channel_id":23,"order_id":"1775532837926318177","flags":128,"ts_in_delta":755,"sequence":192548,"symbol":"FCEU SI 20260615 PS"}
{"ts_recv":"2026-04-07T03:33:57.926396857Z","hd":{"ts_event":"2026-04-07T03:33:57.926378303Z","rtype":160,"publisher_id":101,"instrument_id":436},"action":"C","side":"B","price":"1.156760000","size":30,"channel_id":23,"order_id":"10998904866849614167","flags":0,"ts_in_delta":731,"sequence":192549,"symbol":"FCEU SI 20260615 PS"}
{"ts_recv":"2026-04-07T03:33:57.926396857Z","hd":{"ts_event":"2026-04-07T03:33:57.926378303Z","rtype":160,"publisher_id":101,"instrument_id":436},"action":"A","side":"B","price":"1.156770000","size":30,"channel_id":23,"order_id":"10998904874781159659","flags":0,"ts_in_delta":731,"sequence":192549,"symbol":"FCEU SI 20260615 PS"}
{"ts_recv":"2026-04-07T03:33:57.926396857Z","hd":{"ts_event":"2026-04-07T03:33:57.926378303Z","rtype":160,"publisher_id":101,"instrument_id":436},"action":"C","side":"A","price":"1.156860000","size":30,"channel_id":23,"order_id":"1775532829994838359","flags":0,"ts_in_delta":731,"sequence":192549,"symbol":"FCEU SI 20260615 PS"}
{"ts_recv":"2026-04-07T03:33:57.926396857Z","hd":{"ts_event":"2026-04-07T03:33:57.926378303Z","rtype":160,"publisher_id":101,"instrument_id":436},"action":"A","side":"A","price":"1.156870000","size":30,"channel_id":23,"order_id":"1775532837926383851","flags":128,"ts_in_delta":731,"sequence":192549,"symbol":"FCEU SI 20260615 PS"}
{"ts_recv":"2026-04-07T03:33:59.015103433Z","hd":{"ts_event":"2026-04-07T03:33:59.015082915Z","rtype":160,"publisher_id":101,"instrument_id":436},"action":"C","side":"B","price":"1.156770000","size":30,"channel_id":23,"order_id":"10998904874781159659","flags":0,"ts_in_delta":1107,"sequence":192568,"symbol":"FCEU SI 20260615 PS"}
{"ts_recv":"2026-04-07T03:33:59.015103433Z","hd":{"ts_event":"2026-04-07T03:33:59.015082915Z","rtype":160,"publisher_id":101,"instrument_id":436},"action":"A","side":"B","price":"1.156780000","size":30,"channel_id":23,"order_id":"10998904875869864621","flags":0,"ts_in_delta":1107,"sequence":192568,"symbol":"FCEU SI 20260615 PS"}
{"ts_recv":"2026-04-07T03:33:59.015103433Z","hd":{"ts_event":"2026-04-07T03:33:59.015082915Z","rtype":160,"publisher_id":101,"instrument_id":436},"action":"C","side":"A","price":"1.156870000","size":30,"channel_id":23,"order_id":"1775532837926383851","flags":0,"ts_in_delta":1107,"sequence":192568,"symbol":"FCEU SI 20260615 PS"}
{"ts_recv":"2026-04-07T03:33:59.015103433Z","hd":{"ts_event":"2026-04-07T03:33:59.015082915Z","rtype":160,"publisher_id":101,"instrument_id":436},"action":"A","side":"A","price":"1.156880000","size":30,"channel_id":23,"order_id":"1775532839015088813","flags":128,"ts_in_delta":1107,"sequence":192568,"symbol":"FCEU SI 20260615 PS"}
{"ts_recv":"2026-04-07T03:33:59.021243005Z","hd":{"ts_event":"2026-04-07T03:33:59.021224995Z","rtype":160,"publisher_id":101,"instrument_id":436},"action":"C","side":"B","price":"1.156780000","size":30,"channel_id":23,"order_id":"10998904875869864621","flags":0,"ts_in_delta":962,"sequence":192571,"symbol":"FCEU SI 20260615 PS"}
{"ts_recv":"2026-04-07T03:33:59.021243005Z","hd":{"ts_event":"2026-04-07T03:33:59.021224995Z","rtype":160,"publisher_id":101,"instrument_id":436},"action":"A","side":"B","price":"1.156760000","size":30,"channel_id":23,"order_id":"10998904875876006764","flags":0,"ts_in_delta":962,"sequence":192571,"symbol":"FCEU SI 20260615 PS"}
{"ts_recv":"2026-04-07T03:33:59.021243005Z","hd":{"ts_event":"2026-04-07T03:33:59.021224995Z","rtype":160,"publisher_id":101,"instrument_id":436},"action":"C","side":"A","price":"1.156880000","size":30,"channel_id":23,"order_id":"1775532839015088813","flags":0,"ts_in_delta":962,"sequence":192571,"symbol":"FCEU SI 20260615 PS"}
{"ts_recv":"2026-04-07T03:33:59.021243005Z","hd":{"ts_event":"2026-04-07T03:33:59.021224995Z","rtype":160,"publisher_id":101,"instrument_id":436},"action":"A","side":"A","price":"1.156860000","size":30,"channel_id":23,"order_id":"1775532839021230956","flags":128,"ts_in_delta":962,"sequence":192571,"symbol":"FCEU SI 20260615 PS"}
{"ts_recv":"2026-04-07T03:33:59.021323887Z","hd":{"ts_event":"2026-04-07T03:33:59.021305327Z","rtype":160,"publisher_id":101,"instrument_id":436},"action":"C","side":"B","price":"1.156760000","size":30,"channel_id":23,"order_id":"10998904875876006764","flags":0,"ts_in_delta":983,"sequence":192573,"symbol":"FCEU SI 20260615 PS"}
{"ts_recv":"2026-04-07T03:33:59.021323887Z","hd":{"ts_event":"2026-04-07T03:33:59.021305327Z","rtype":160,"publisher_id":101,"instrument_id":436},"action":"A","side":"B","price":"1.156770000","size":30,"channel_id":23,"order_id":"10998904875876086800","flags":0,"ts_in_delta":983,"sequence":192573,"symbol":"FCEU SI 20260615 PS"}
{"ts_recv":"2026-04-07T03:33:59.021323887Z","hd":{"ts_event":"2026-04-07T03:33:59.021305327Z","rtype":160,"publisher_id":101,"instrument_id":436},"action":"C","side":"A","price":"1.156860000","size":30,"channel_id":23,"order_id":"1775532839021230956","flags":0,"ts_in_delta":983,"sequence":192573,"symbol":"FCEU SI 20260615 PS"}
{"ts_recv":"2026-04-07T03:33:59.021323887Z","hd":{"ts_event":"2026-04-07T03:33:59.021305327Z","rtype":160,"publisher_id":101,"instrument_id":436},"action":"A","side":"A","price":"1.156870000","size":30,"channel_id":23,"order_id":"1775532839021310992","flags":128,"ts_in_delta":983,"sequence":192573,"symbol":"FCEU SI 20260615 PS"}
{"ts_recv":"2026-04-07T03:34:02.221859070Z","hd":{"ts_event":"2026-04-07T03:34:02.221832553Z","rtype":160,"publisher_id":101,"instrument_id":436},"action":"C","side":"B","price":"1.156770000","size":30,"channel_id":23,"order_id":"10998904875876086800","flags":0,"ts_in_delta":912,"sequence":192631,"symbol":"FCEU SI 20260615 PS"}
{"ts_recv":"2026-04-07T03:34:02.221859070Z","hd":{"ts_event":"2026-04-07T03:34:02.221832553Z","rtype":160,"publisher_id":101,"instrument_id":436},"action":"A","side":"B","price":"1.156760000","size":30,"channel_id":23,"order_id":"10998904879076618861","flags":0,"ts_in_delta":912,"sequence":192631,"symbol":"FCEU SI 20260615 PS"}
{"ts_recv":"2026-04-07T03:34:02.221859070Z","hd":{"ts_event":"2026-04-07T03:34:02.221832553Z","rtype":160,"publisher_id":101,"instrument_id":436},"action":"C","side":"A","price":"1.156870000","size":30,"channel_id":23,"order_id":"1775532839021310992","flags":0,"ts_in_delta":912,"sequence":192631,"symbol":"FCEU SI 20260615 PS"}
{"ts_recv":"2026-04-07T03:34:02.221859070Z","hd":{"ts_event":"2026-04-07T03:34:02.221832553Z","rtype":160,"publisher_id":101,"instrument_id":436},"action":"A","side":"A","price":"1.156860000","size":30,"channel_id":23,"order_id":"1775532842221843053","flags":128,"ts_in_delta":912,"sequence":192631,"symbol":"FCEU SI 20260615 PS"}
{"ts_recv":"2026-04-07T03:34:02.221924301Z","hd":{"ts_event":"2026-04-07T03:34:02.221905975Z","rtype":160,"publisher_id":101,"instrument_id":436},"action":"C","side":"B","price":"1.156770000","size":30,"channel_id":23,"order_id":"10998904874781093985","flags":0,"ts_in_delta":933,"sequence":192632,"symbol":"FCEU SI 20260615 PS"}
{"ts_recv":"2026-04-07T03:34:02.221924301Z","hd":{"ts_event":"2026-04-07T03:34:02.221905975Z","rtype":160,"publisher_id":101,"instrument_id":436},"action":"A","side":"B","price":"1.156750000","size":30,"channel_id":23,"order_id":"10998904879076687935","flags":0,"ts_in_delta":933,"sequence":192632,"symbol":"FCEU SI 20260615 PS"}
{"ts_recv":"2026-04-07T03:34:02.221924301Z","hd":{"ts_event":"2026-04-07T03:34:02.221905975Z","rtype":160,"publisher_id":101,"instrument_id":436},"action":"C","side":"A","price":"1.156870000","size":30,"channel_id":23,"order_id":"1775532837926318177","flags":0,"ts_in_delta":933,"sequence":192632,"symbol":"FCEU SI 20260615 PS"}
{"ts_recv":"2026-04-07T03:34:02.221924301Z","hd":{"ts_event":"2026-04-07T03:34:02.221905975Z","rtype":160,"publisher_id":101,"instrument_id":436},"action":"A","side":"A","price":"1.156850000","size":30,"channel_id":23,"order_id":"1775532842221912127","flags":128,"ts_in_delta":933,"sequence":192632,"symbol":"FCEU SI 20260615 PS"}
{"ts_recv":"2026-04-07T03:34:02.221964650Z","hd":{"ts_event":"2026-04-07T03:34:02.221946639Z","rtype":160,"publisher_id":101,"instrument_id":436},"action":"C","side":"B","price":"1.156760000","size":30,"channel_id":23,"order_id":"10998904879076618861","flags":0,"ts_in_delta":955,"sequence":192633,"symbol":"FCEU SI 20260615 PS"}
{"ts_recv":"2026-04-07T03:34:02.221964650Z","hd":{"ts_event":"2026-04-07T03:34:02.221946639Z","rtype":160,"publisher_id":101,"instrument_id":436},"action":"A","side":"B","price":"1.156750000","size":30,"channel_id":23,"order_id":"10998904879076728540","flags":0,"ts_in_delta":955,"sequence":192633,"symbol":"FCEU SI 20260615 PS"}
{"ts_recv":"2026-04-07T03:34:02.221964650Z","hd":{"ts_event":"2026-04-07T03:34:02.221946639Z","rtype":160,"publisher_id":101,"instrument_id":436},"action":"C","side":"A","price":"1.156860000","size":30,"channel_id":23,"order_id":"1775532842221843053","flags":0,"ts_in_delta":955,"sequence":192633,"symbol":"FCEU SI 20260615 PS"}
{"ts_recv":"2026-04-07T03:34:02.221964650Z","hd":{"ts_event":"2026-04-07T03:34:02.221946639Z","rtype":160,"publisher_id":101,"instrument_id":436},"action":"A","side":"A","price":"1.156850000","size":30,"channel_id":23,"order_id":"1775532842221952732","flags":128,"ts_in_delta":955,"sequence":192633,"symbol":"FCEU SI 20260615 PS"}
{"ts_recv":"2026-04-07T03:34:06.600778217Z","hd":{"ts_event":"2026-04-07T03:34:06.600757803Z","rtype":160,"publisher_id":101,"instrument_id":436},"action":"C","side":"B","price":"1.156750000","size":30,"channel_id":23,"order_id":"10998904879076728540","flags":0,"ts_in_delta":910,"sequence":192684,"symbol":"FCEU SI 20260615 PS"}
{"ts_recv":"2026-04-07T03:34:06.600778217Z","hd":{"ts_event":"2026-04-07T03:34:06.600757803Z","rtype":160,"publisher_id":101,"instrument_id":436},"action":"A","side":"B","price":"1.156740000","size":30,"channel_id":23,"order_id":"10998904883455539288","flags":0,"ts_in_delta":910,"sequence":192684,"symbol":"FCEU SI 20260615 PS"}
{"ts_recv":"2026-04-07T03:34:06.600778217Z","hd":{"ts_event":"2026-04-07T03:34:06.600757803Z","rtype":160,"publisher_id":101,"instrument_id":436},"action":"C","side":"A","price":"1.156850000","size":30,"channel_id":23,"order_id":"1775532842221952732","flags":0,"ts_in_delta":910,"sequence":192684,"symbol":"FCEU SI 20260615 PS"}
{"ts_recv":"2026-04-07T03:34:06.600778217Z","hd":{"ts_event":"2026-04-07T03:34:06.600757803Z","rtype":160,"publisher_id":101,"instrument_id":436},"action":"A","side":"A","price":"1.156840000","size":30,"channel_id":23,"order_id":"1775532846600763480","flags":128,"ts_in_delta":910,"sequence":192684,"symbol":"FCEU SI 20260615 PS"}
{"ts_recv":"2026-04-07T03:34:06.603040895Z","hd":{"ts_event":"2026-04-07T03:34:06.603020911Z","rtype":160,"publisher_id":101,"instrument_id":436},"action":"C","side":"B","price":"1.156750000","size":30,"channel_id":23,"order_id":"10998904879076687935","flags":0,"ts_in_delta":934,"sequence":192688,"symbol":"FCEU SI 20260615 PS"}
{"ts_recv":"2026-04-07T03:34:06.603040895Z","hd":{"ts_event":"2026-04-07T03:34:06.603020911Z","rtype":160,"publisher_id":101,"instrument_id":436},"action":"A","side":"B","price":"1.156730000","size":30,"channel_id":23,"order_id":"10998904883457802569","flags":0,"ts_in_delta":934,"sequence":192688,"symbol":"FCEU SI 20260615 PS"}
{"ts_recv":"2026-04-07T03:34:06.603040895Z","hd":{"ts_event":"2026-04-07T03:34:06.603020911Z","rtype":160,"publisher_id":101,"instrument_id":436},"action":"C","side":"A","price":"1.156850000","size":30,"channel_id":23,"order_id":"1775532842221912127","flags":0,"ts_in_delta":934,"sequence":192688,"symbol":"FCEU SI 20260615 PS"}
{"ts_recv":"2026-04-07T03:34:06.603040895Z","hd":{"ts_event":"2026-04-07T03:34:06.603020911Z","rtype":160,"publisher_id":101,"instrument_id":436},"action":"A","side":"A","price":"1.156830000","size":30,"channel_id":23,"order_id":"1775532846603026761","flags":128,"ts_in_delta":934,"sequence":192688,"symbol":"FCEU SI 20260615 PS"}
{"ts_recv":"2026-04-07T03:34:06.603095029Z","hd":{"ts_event":"2026-04-07T03:34:06.603078455Z","rtype":160,"publisher_id":101,"instrument_id":436},"action":"C","side":"B","price":"1.156740000","size":30,"channel_id":23,"order_id":"10998904883455539288","flags":0,"ts_in_delta":910,"sequence":192689,"symbol":"FCEU SI 20260615 PS"}
{"ts_recv":"2026-04-07T03:34:06.603095029Z","hd":{"ts_event":"2026-04-07T03:34:06.603078455Z","rtype":160,"publisher_id":101,"instrument_id":436},"action":"A","side":"B","price":"1.156730000","size":30,"channel_id":23,"order_id":"10998904883457860359","flags":0,"ts_in_delta":910,"sequence":192689,"symbol":"FCEU SI 20260615 PS"}
{"ts_recv":"2026-04-07T03:34:06.603095029Z","hd":{"ts_event":"2026-04-07T03:34:06.603078455Z","rtype":160,"publisher_id":101,"instrument_id":436},"action":"C","side":"A","price":"1.156840000","size":30,"channel_id":23,"order_id":"1775532846600763480","flags":0,"ts_in_delta":910,"sequence":192689,"symbol":"FCEU SI 20260615 PS"}
{"ts_recv":"2026-04-07T03:34:06.603095029Z","hd":{"ts_event":"2026-04-07T03:34:06.603078455Z","rtype":160,"publisher_id":101,"instrument_id":436},"action":"A","side":"A","price":"1.156830000","size":30,"channel_id":23,"order_id":"1775532846603084551","flags":128,"ts_in_delta":910,"sequence":192689,"symbol":"FCEU SI 20260615 PS"}
{"ts_recv":"2026-04-07T03:34:18.505095287Z","hd":{"ts_event":"2026-04-07T03:34:18.505074807Z","rtype":160,"publisher_id":101,"instrument_id":436},"action":"C","side":"B","price":"1.156730000","size":30,"channel_id":23,"order_id":"10998904883457860359","flags":0,"ts_in_delta":976,"sequence":192758,"symbol":"FCEU SI 20260615 PS"}
{"ts_recv":"2026-04-07T03:34:18.505095287Z","hd":{"ts_event":"2026-04-07T03:34:18.505074807Z","rtype":160,"publisher_id":101,"instrument_id":436},"action":"A","side":"B","price":"1.156740000","size":30,"channel_id":23,"order_id":"10998904895359856391","flags":0,"ts_in_delta":976,"sequence":192758,"symbol":"FCEU SI 20260615 PS"}
{"ts_recv":"2026-04-07T03:34:18.505095287Z","hd":{"ts_event":"2026-04-07T03:34:18.505074807Z","rtype":160,"publisher_id":101,"instrument_id":436},"action":"C","side":"A","price":"1.156830000","size":30,"channel_id":23,"order_id":"1775532846603084551","flags":0,"ts_in_delta":976,"sequence":192758,"symbol":"FCEU SI 20260615 PS"}
{"ts_recv":"2026-04-07T03:34:18.505095287Z","hd":{"ts_event":"2026-04-07T03:34:18.505074807Z","rtype":160,"publisher_id":101,"instrument_id":436},"action":"A","side":"A","price":"1.156840000","size":30,"channel_id":23,"order_id":"1775532858505080583","flags":128,"ts_in_delta":976,"sequence":192758,"symbol":"FCEU SI 20260615 PS"}
{"ts_recv":"2026-04-07T03:34:23.434883855Z","hd":{"ts_event":"2026-04-07T03:34:23.434855817Z","rtype":160,"publisher_id":101,"instrument_id":436},"action":"C","side":"B","price":"1.156740000","size":30,"channel_id":23,"order_id":"10998904895359856391","flags":0,"ts_in_delta":1406,"sequence":192785,"symbol":"FCEU SI 20260615 PS"}
{"ts_recv":"2026-04-07T03:34:23.434883855Z","hd":{"ts_event":"2026-04-07T03:34:23.434855817Z","rtype":160,"publisher_id":101,"instrument_id":436},"action":"A","side":"B","price":"1.156730000","size":30,"channel_id":23,"order_id":"10998904900289642177","flags":0,"ts_in_delta":1406,"sequence":192785,"symbol":"FCEU SI 20260615 PS"}
{"ts_recv":"2026-04-07T03:34:23.434883855Z","hd":{"ts_event":"2026-04-07T03:34:23.434855817Z","rtype":160,"publisher_id":101,"instrument_id":436},"action":"C","side":"A","price":"1.156840000","size":30,"channel_id":23,"order_id":"1775532858505080583","flags":0,"ts_in_delta":1406,"sequence":192785,"symbol":"FCEU SI 20260615 PS"}
{"ts_recv":"2026-04-07T03:34:23.434883855Z","hd":{"ts_event":"2026-04-07T03:34:23.434855817Z","rtype":160,"publisher_id":101,"instrument_id":436},"action":"A","side":"A","price":"1.156830000","size":30,"channel_id":23,"order_id":"1775532863434866369","flags":128,"ts_in_delta":1406,"sequence":192785,"symbol":"FCEU SI 20260615 PS"}
{"ts_recv":"2026-04-07T03:34:26.615132014Z","hd":{"ts_event":"2026-04-07T03:34:26.615099163Z","rtype":160,"publisher_id":101,"instrument_id":436},"action":"C","side":"B","price":"1.156730000","size":30,"channel_id":23,"order_id":"10998904900289642177","flags":0,"ts_in_delta":1751,"sequence":192818,"symbol":"FCEU SI 20260615 PS"}
{"ts_recv":"2026-04-07T03:34:26.615132014Z","hd":{"ts_event":"2026-04-07T03:34:26.615099163Z","rtype":160,"publisher_id":101,"instrument_id":436},"action":"A","side":"B","price":"1.156740000","size":30,"channel_id":23,"order_id":"10998904903469888186","flags":0,"ts_in_delta":1751,"sequence":192818,"symbol":"FCEU SI 20260615 PS"}
{"ts_recv":"2026-04-07T03:34:26.615132014Z","hd":{"ts_event":"2026-04-07T03:34:26.615099163Z","rtype":160,"publisher_id":101,"instrument_id":436},"action":"C","side":"A","price":"1.156830000","size":30,"channel_id":23,"order_id":"1775532863434866369","flags":0,"ts_in_delta":1751,"sequence":192818,"symbol":"FCEU SI 20260615 PS"}
{"ts_recv":"2026-04-07T03:34:26.615132014Z","hd":{"ts_event":"2026-04-07T03:34:26.615099163Z","rtype":160,"publisher_id":101,"instrument_id":436},"action":"A","side":"A","price":"1.156840000","size":30,"channel_id":23,"order_id":"1775532866615112378","flags":128,"ts_in_delta":1751,"sequence":192818,"symbol":"FCEU SI 20260615 PS"}
{"ts_recv":"2026-04-07T03:34:26.621709517Z","hd":{"ts_event":"2026-04-07T03:34:26.621690963Z","rtype":160,"publisher_id":101,"instrument_id":436},"action":"C","side":"B","price":"1.156730000","size":30,"channel_id":23,"order_id":"10998904883457802569","flags":0,"ts_in_delta":912,"sequence":192819,"symbol":"FCEU SI 20260615 PS"}
{"ts_recv":"2026-04-07T03:34:26.621709517Z","hd":{"ts_event":"2026-04-07T03:34:26.621690963Z","rtype":160,"publisher_id":101,"instrument_id":436},"action":"A","side":"B","price":"1.156750000","size":30,"channel_id":23,"order_id":"10998904903476472907","flags":0,"ts_in_delta":912,"sequence":192819,"symbol":"FCEU SI 20260615 PS"}
{"ts_recv":"2026-04-07T03:34:26.621709517Z","hd":{"ts_event":"2026-04-07T03:34:26.621690963Z","rtype":160,"publisher_id":101,"instrument_id":436},"action":"C","side":"A","price":"1.156830000","size":30,"channel_id":23,"order_id":"1775532846603026761","flags":0,"ts_in_delta":912,"sequence":192819,"symbol":"FCEU SI 20260615 PS"}
{"ts_recv":"2026-04-07T03:34:26.621709517Z","hd":{"ts_event":"2026-04-07T03:34:26.621690963Z","rtype":160,"publisher_id":101,"instrument_id":436},"action":"A","side":"A","price":"1.156850000","size":30,"channel_id":23,"order_id":"1775532866621697099","flags":128,"ts_in_delta":912,"sequence":192819,"symbol":"FCEU SI 20260615 PS"}
{"ts_recv":"2026-04-07T03:34:26.621767791Z","hd":{"ts_event":"2026-04-07T03:34:26.621752383Z","rtype":160,"publisher_id":101,"instrument_id":436},"action":"C","side":"B","price":"1.156740000","size":30,"channel_id":23,"order_id":"10998904903469888186","flags":0,"ts_in_delta":824,"sequence":192820,"symbol":"FCEU SI 20260615 PS"}
{"ts_recv":"2026-04-07T03:34:26.621767791Z","hd":{"ts_event":"2026-04-07T03:34:26.621752383Z","rtype":160,"publisher_id":101,"instrument_id":436},"action":"A","side":"B","price":"1.156750000","size":30,"channel_id":23,"order_id":"10998904903476534316","flags":0,"ts_in_delta":824,"sequence":192820,"symbol":"FCEU SI 20260615 PS"}
{"ts_recv":"2026-04-07T03:34:26.621767791Z","hd":{"ts_event":"2026-04-07T03:34:26.621752383Z","rtype":160,"publisher_id":101,"instrument_id":436},"action":"C","side":"A","price":"1.156840000","size":30,"channel_id":23,"order_id":"1775532866615112378","flags":0,"ts_in_delta":824,"sequence":192820,"symbol":"FCEU SI 20260615 PS"}
{"ts_recv":"2026-04-07T03:34:26.621767791Z","hd":{"ts_event":"2026-04-07T03:34:26.621752383Z","rtype":160,"publisher_id":101,"instrument_id":436},"action":"A","side":"A","price":"1.156850000","size":30,"channel_id":23,"order_id":"1775532866621758508","flags":128,"ts_in_delta":824,"sequence":192820,"symbol":"FCEU SI 20260615 PS"}
{"ts_recv":"2026-04-07T03:34:26.629958642Z","hd":{"ts_event":"2026-04-07T03:34:26.629939153Z","rtype":160,"publisher_id":101,"instrument_id":436},"action":"C","side":"B","price":"1.156750000","size":30,"channel_id":23,"order_id":"10998904903476534316","flags":0,"ts_in_delta":916,"sequence":192824,"symbol":"FCEU SI 20260615 PS"}
{"ts_recv":"2026-04-07T03:34:26.629958642Z","hd":{"ts_event":"2026-04-07T03:34:26.629939153Z","rtype":160,"publisher_id":101,"instrument_id":436},"action":"A","side":"B","price":"1.156760000","size":30,"channel_id":23,"order_id":"10998904903484720784","flags":0,"ts_in_delta":916,"sequence":192824,"symbol":"FCEU SI 20260615 PS"}
{"ts_recv":"2026-04-07T03:34:26.629958642Z","hd":{"ts_event":"2026-04-07T03:34:26.629939153Z","rtype":160,"publisher_id":101,"instrument_id":436},"action":"C","side":"A","price":"1.156850000","size":30,"channel_id":23,"order_id":"1775532866621758508","flags":0,"ts_in_delta":916,"sequence":192824,"symbol":"FCEU SI 20260615 PS"}
{"ts_recv":"2026-04-07T03:34:26.629958642Z","hd":{"ts_event":"2026-04-07T03:34:26.629939153Z","rtype":160,"publisher_id":101,"instrument_id":436},"action":"A","side":"A","price":"1.156860000","size":30,"channel_id":23,"order_id":"1775532866629944976","flags":128,"ts_in_delta":916,"sequence":192824,"symbol":"FCEU SI 20260615 PS"}
{"ts_recv":"2026-04-07T03:34:26.630041774Z","hd":{"ts_event":"2026-04-07T03:34:26.630020523Z","rtype":160,"publisher_id":101,"instrument_id":436},"action":"C","side":"B","price":"1.156760000","size":30,"channel_id":23,"order_id":"10998904903484720784","flags":0,"ts_in_delta":937,"sequence":192825,"symbol":"FCEU SI 20260615 PS"}
{"ts_recv":"2026-04-07T03:34:26.630041774Z","hd":{"ts_event":"2026-04-07T03:34:26.630020523Z","rtype":160,"publisher_id":101,"instrument_id":436},"action":"A","side":"B","price":"1.156770000","size":30,"channel_id":23,"order_id":"10998904903484802406","flags":0,"ts_in_delta":937,"sequence":192825,"symbol":"FCEU SI 20260615 PS"}
{"ts_recv":"2026-04-07T03:34:26.630041774Z","hd":{"ts_event":"2026-04-07T03:34:26.630020523Z","rtype":160,"publisher_id":101,"instrument_id":436},"action":"C","side":"A","price":"1.156860000","size":30,"channel_id":23,"order_id":"1775532866629944976","flags":0,"ts_in_delta":937,"sequence":192825,"symbol":"FCEU SI 20260615 PS"}
{"ts_recv":"2026-04-07T03:34:26.630041774Z","hd":{"ts_event":"2026-04-07T03:34:26.630020523Z","rtype":160,"publisher_id":101,"instrument_id":436},"action":"A","side":"A","price":"1.156870000","size":30,"channel_id":23,"order_id":"1775532866630026598","flags":128,"ts_in_delta":937,"sequence":192825,"symbol":"FCEU SI 20260615 PS"}
{"ts_recv":"2026-04-07T03:34:26.630095539Z","hd":{"ts_event":"2026-04-07T03:34:26.630078409Z","rtype":160,"publisher_id":101,"instrument_id":436},"action":"C","side":"B","price":"1.156750000","size":30,"channel_id":23,"order_id":"10998904903476472907","flags":0,"ts_in_delta":923,"sequence":192826,"symbol":"FCEU SI 20260615 PS"}
{"ts_recv":"2026-04-07T03:34:26.630095539Z","hd":{"ts_event":"2026-04-07T03:34:26.630078409Z","rtype":160,"publisher_id":101,"instrument_id":436},"action":"A","side":"B","price":"1.156770000","size":30,"channel_id":23,"order_id":"10998904903484860747","flags":0,"ts_in_delta":923,"sequence":192826,"symbol":"FCEU SI 20260615 PS"}
{"ts_recv":"2026-04-07T03:34:26.630095539Z","hd":{"ts_event":"2026-04-07T03:34:26.630078409Z","rtype":160,"publisher_id":101,"instrument_id":436},"action":"C","side":"A","price":"1.156850000","size":30,"channel_id":23,"order_id":"1775532866621697099","flags":0,"ts_in_delta":923,"sequence":192826,"symbol":"FCEU SI 20260615 PS"}
{"ts_recv":"2026-04-07T03:34:26.630095539Z","hd":{"ts_event":"2026-04-07T03:34:26.630078409Z","rtype":160,"publisher_id":101,"instrument_id":436},"action":"A","side":"A","price":"1.156870000","size":30,"channel_id":23,"order_id":"1775532866630084939","flags":128,"ts_in_delta":923,"sequence":192826,"symbol":"FCEU SI 20260615 PS"}
{"ts_recv":"2026-04-07T03:34:26.630105407Z","hd":{"ts_event":"2026-04-07T03:34:26.630080867Z","rtype":160,"publisher_id":101,"instrument_id":436},"action":"C","side":"B","price":"1.156770000","size":30,"channel_id":23,"order_id":"10998904903484802406","flags":0,"ts_in_delta":899,"sequence":192827,"symbol":"FCEU SI 20260615 PS"}
{"ts_recv":"2026-04-07T03:34:26.630105407Z","hd":{"ts_event":"2026-04-07T03:34:26.630080867Z","rtype":160,"publisher_id":101,"instrument_id":436},"action":"A","side":"B","price":"1.156760000","size":30,"channel_id":23,"order_id":"10998904903484868246","flags":0,"ts_in_delta":899,"sequence":192827,"symbol":"FCEU SI 20260615 PS"}
{"ts_recv":"2026-04-07T03:34:26.630105407Z","hd":{"ts_event":"2026-04-07T03:34:26.630080867Z","rtype":160,"publisher_id":101,"instrument_id":436},"action":"C","side":"A","price":"1.156870000","size":30,"channel_id":23,"order_id":"1775532866630026598","flags":0,"ts_in_delta":899,"sequence":192827,"symbol":"FCEU SI 20260615 PS"}
{"ts_recv":"2026-04-07T03:34:26.630105407Z","hd":{"ts_event":"2026-04-07T03:34:26.630080867Z","rtype":160,"publisher_id":101,"instrument_id":436},"action":"A","side":"A","price":"1.156860000","size":30,"channel_id":23,"order_id":"1775532866630092438","flags":128,"ts_in_delta":899,"sequence":192827,"symbol":"FCEU SI 20260615 PS"}
{"ts_recv":"2026-04-07T03:34:26.630158236Z","hd":{"ts_event":"2026-04-07T03:34:26.630140791Z","rtype":160,"publisher_id":101,"instrument_id":436},"action":"C","side":"B","price":"1.156760000","size":30,"channel_id":23,"order_id":"10998904903484868246","flags":0,"ts_in_delta":887,"sequence":192828,"symbol":"FCEU SI 20260615 PS"}
{"ts_recv":"2026-04-07T03:34:26.630158236Z","hd":{"ts_event":"2026-04-07T03:34:26.630140791Z","rtype":160,"publisher_id":101,"instrument_id":436},"action":"A","side":"B","price":"1.156770000","size":30,"channel_id":23,"order_id":"10998904903484922760","flags":0,"ts_in_delta":887,"sequence":192828,"symbol":"FCEU SI 20260615 PS"}
{"ts_recv":"2026-04-07T03:34:26.630158236Z","hd":{"ts_event":"2026-04-07T03:34:26.630140791Z","rtype":160,"publisher_id":101,"instrument_id":436},"action":"C","side":"A","price":"1.156860000","size":30,"channel_id":23,"order_id":"1775532866630092438","flags":0,"ts_in_delta":887,"sequence":192828,"symbol":"FCEU SI 20260615 PS"}
{"ts_recv":"2026-04-07T03:34:26.630158236Z","hd":{"ts_event":"2026-04-07T03:34:26.630140791Z","rtype":160,"publisher_id":101,"instrument_id":436},"action":"A","side":"A","price":"1.156870000","size":30,"channel_id":23,"order_id":"1775532866630146952","flags":128,"ts_in_delta":887,"sequence":192828,"symbol":"FCEU SI 20260615 PS"}
{"ts_recv":"2026-04-07T03:34:26.735692885Z","hd":{"ts_event":"2026-04-07T03:34:26.735667483Z","rtype":160,"publisher_id":101,"instrument_id":436},"action":"C","side":"B","price":"1.156770000","size":30,"channel_id":23,"order_id":"10998904903484922760","flags":0,"ts_in_delta":1060,"sequence":192836,"symbol":"FCEU SI 20260615 PS"}
{"ts_recv":"2026-04-07T03:34:26.735692885Z","hd":{"ts_event":"2026-04-07T03:34:26.735667483Z","rtype":160,"publisher_id":101,"instrument_id":436},"action":"A","side":"B","price":"1.156760000","size":30,"channel_id":23,"order_id":"10998904903590454122","flags":0,"ts_in_delta":1060,"sequence":192836,"symbol":"FCEU SI 20260615 PS"}
{"ts_recv":"2026-04-07T03:34:26.735692885Z","hd":{"ts_event":"2026-04-07T03:34:26.735667483Z","rtype":160,"publisher_id":101,"instrument_id":436},"action":"C","side":"A","price":"1.156870000","size":30,"channel_id":23,"order_id":"1775532866630146952","flags":0,"ts_in_delta":1060,"sequence":192836,"symbol":"FCEU SI 20260615 PS"}
{"ts_recv":"2026-04-07T03:34:26.735692885Z","hd":{"ts_event":"2026-04-07T03:34:26.735667483Z","rtype":160,"publisher_id":101,"instrument_id":436},"action":"A","side":"A","price":"1.156860000","size":30,"channel_id":23,"order_id":"1775532866735678314","flags":128,"ts_in_delta":1060,"sequence":192836,"symbol":"FCEU SI 20260615 PS"}
{"ts_recv":"2026-04-07T03:34:26.735746657Z","hd":{"ts_event":"2026-04-07T03:34:26.735726581Z","rtype":160,"publisher_id":101,"instrument_id":436},"action":"C","side":"B","price":"1.156770000","size":30,"channel_id":23,"order_id":"10998904903484860747","flags":0,"ts_in_delta":780,"sequence":192837,"symbol":"FCEU SI 20260615 PS"}
{"ts_recv":"2026-04-07T03:34:26.735746657Z","hd":{"ts_event":"2026-04-07T03:34:26.735726581Z","rtype":160,"publisher_id":101,"instrument_id":436},"action":"A","side":"B","price":"1.156750000","size":30,"channel_id":23,"order_id":"10998904903590508277","flags":0,"ts_in_delta":780,"sequence":192837,"symbol":"FCEU SI 20260615 PS"}
{"ts_recv":"2026-04-07T03:34:26.735746657Z","hd":{"ts_event":"2026-04-07T03:34:26.735726581Z","rtype":160,"publisher_id":101,"instrument_id":436},"action":"C","side":"A","price":"1.156870000","size":30,"channel_id":23,"order_id":"1775532866630084939","flags":0,"ts_in_delta":780,"sequence":192837,"symbol":"FCEU SI 20260615 PS"}
{"ts_recv":"2026-04-07T03:34:26.735746657Z","hd":{"ts_event":"2026-04-07T03:34:26.735726581Z","rtype":160,"publisher_id":101,"instrument_id":436},"action":"A","side":"A","price":"1.156850000","size":30,"channel_id":23,"order_id":"1775532866735732469","flags":128,"ts_in_delta":780,"sequence":192837,"symbol":"FCEU SI 20260615 PS"}
{"ts_recv":"2026-04-07T03:34:26.735754590Z","hd":{"ts_event":"2026-04-07T03:34:26.735736147Z","rtype":160,"publisher_id":101,"instrument_id":436},"action":"C","side":"B","price":"1.156760000","size":30,"channel_id":23,"order_id":"10998904903590454122","flags":0,"ts_in_delta":717,"sequence":192838,"symbol":"FCEU SI 20260615 PS"}
{"ts_recv":"2026-04-07T03:34:26.735754590Z","hd":{"ts_event":"2026-04-07T03:34:26.735736147Z","rtype":160,"publisher_id":101,"instrument_id":436},"action":"A","side":"B","price":"1.156750000","size":30,"channel_id":23,"order_id":"10998904903590519357","flags":0,"ts_in_delta":717,"sequence":192838,"symbol":"FCEU SI 20260615 PS"}
{"ts_recv":"2026-04-07T03:34:26.735754590Z","hd":{"ts_event":"2026-04-07T03:34:26.735736147Z","rtype":160,"publisher_id":101,"instrument_id":436},"action":"C","side":"A","price":"1.156860000","size":30,"channel_id":23,"order_id":"1775532866735678314","flags":0,"ts_in_delta":717,"sequence":192838,"symbol":"FCEU SI 20260615 PS"}