{"ts_recv":"2026-04-07T03:21:39.024909148Z","hd":{"ts_event":"2026-04-07T03:21:39.024888045Z","rtype":160,"publisher_id":101,"instrument_id":436},"action":"A","side":"A","price":"1.156780000","size":30,"channel_id":23,"order_id":"1775532099024893988","flags":128,"ts_in_delta":931,"sequence":187256,"symbol":"FCEU SI 20260615 PS"}
{"ts_recv":"2026-04-07T03:21:39.024972621Z","hd":{"ts_event":"2026-04-07T03:21:39.024954741Z","rtype":160,"publisher_id":101,"instrument_id":436},"action":"C","side":"B","price":"1.156670000","size":30,"channel_id":23,"order_id":"10998904130985687707","flags":0,"ts_in_delta":907,"sequence":187257,"symbol":"FCEU SI 20260615 PS"}
{"ts_recv":"2026-04-07T03:21:39.024972621Z","hd":{"ts_event":"2026-04-07T03:21:39.024954741Z","rtype":160,"publisher_id":101,"instrument_id":436},"action":"A","side":"B","price":"1.156680000","size":30,"channel_id":23,"order_id":"10998904135879736288","flags":0,"ts_in_delta":907,"sequence":187257,"symbol":"FCEU SI 20260615 PS"}
{"ts_recv":"2026-04-07T03:21:39.024972621Z","hd":{"ts_event":"2026-04-07T03:21:39.024954741Z","rtype":160,"publisher_id":101,"instrument_id":436},"action":"C","side":"A","price":"1.156770000","size":30,"channel_id":23,"order_id":"1775532094130911899","flags":0,"ts_in_delta":907,"sequence":187257,"symbol":"FCEU SI 20260615 PS"}
{"ts_recv":"2026-04-07T03:21:39.024972621Z","hd":{"ts_event":"2026-04-07T03:21:39.024954741Z","rtype":160,"publisher_id":101,"instrument_id":436},"action":"A","side":"A","price":"1.156780000","size":30,"channel_id":23,"order_id":"1775532099024960480","flags":128,"ts_in_delta":907,"sequence":187257,"symbol":"FCEU SI 20260615 PS"}
{"ts_recv":"2026-04-07T03:21:43.425953365Z","hd":{"ts_event":"2026-04-07T03:21:43.425933149Z","rtype":160,"publisher_id":101,"instrument_id":436},"action":"C","side":"B","price":"1.156680000","size":30,"channel_id":23,"order_id":"10998904135879736288","flags":0,"ts_in_delta":972,"sequence":187328,"symbol":"FCEU SI 20260615 PS"}
{"ts_recv":"2026-04-07T03:21:43.425953365Z","hd":{"ts_event":"2026-04-07T03:21:43.425933149Z","rtype":160,"publisher_id":101,"instrument_id":436},"action":"A","side":"B","price":"1.156670000","size":30,"channel_id":23,"order_id":"10998904140280715078","flags":0,"ts_in_delta":972,"sequence":187328,"symbol":"FCEU SI 20260615 PS"}
{"ts_recv":"2026-04-07T03:21:43.425953365Z","hd":{"ts_event":"2026-04-07T03:21:43.425933149Z","rtype":160,"publisher_id":101,"instrument_id":436},"action":"C","side":"A","price":"1.156780000","size":30,"channel_id":23,"order_id":"1775532099024960480","flags":0,"ts_in_delta":972,"sequence":187328,"symbol":"FCEU SI 20260615 PS"}
{"ts_recv":"2026-04-07T03:21:43.425953365Z","hd":{"ts_event":"2026-04-07T03:21:43.425933149Z","rtype":160,"publisher_id":101,"instrument_id":436},"action":"A","side":"A","price":"1.156770000","size":30,"channel_id":23,"order_id":"1775532103425939270","flags":128,"ts_in_delta":972,"sequence":187328,"symbol":"FCEU SI 20260615 PS"}
{"ts_recv":"2026-04-07T03:21:43.426035068Z","hd":{"ts_event":"2026-04-07T03:21:43.426015345Z","rtype":160,"publisher_id":101,"instrument_id":436},"action":"C","side":"B","price":"1.156670000","size":30,"channel_id":23,"order_id":"10998904140280715078","flags":0,"ts_in_delta":924,"sequence":187329,"symbol":"FCEU SI 20260615 PS"}
{"ts_recv":"2026-04-07T03:21:43.426035068Z","hd":{"ts_event":"2026-04-07T03:21:43.426015345Z","rtype":160,"publisher_id":101,"instrument_id":436},"action":"A","side":"B","price":"1.156660000","size":30,"channel_id":23,"order_id":"10998904140280797100","flags":0,"ts_in_delta":924,"sequence":187329,"symbol":"FCEU SI 20260615 PS"}
{"ts_recv":"2026-04-07T03:21:43.426035068Z","hd":{"ts_event":"2026-04-07T03:21:43.426015345Z","rtype":160,"publisher_id":101,"instrument_id":436},"action":"C","side":"A","price":"1.156770000","size":30,"channel_id":23,"order_id":"1775532103425939270","flags":0,"ts_in_delta":924,"sequence":187329,"symbol":"FCEU SI 20260615 PS"}
{"ts_recv":"2026-04-07T03:21:43.426035068Z","hd":{"ts_event":"2026-04-07T03:21:43.426015345Z","rtype":160,"publisher_id":101,"instrument_id":436},"action":"A","side":"A","price":"1.156760000","size":30,"channel_id":23,"order_id":"1775532103426021292","flags":128,"ts_in_delta":924,"sequence":187329,"symbol":"FCEU SI 20260615 PS"}
{"ts_recv":"2026-04-07T03:21:43.426086776Z","hd":{"ts_event":"2026-04-07T03:21:43.426067389Z","rtype":160,"publisher_id":101,"instrument_id":436},"action":"C","side":"B","price":"1.156680000","size":30,"channel_id":23,"order_id":"10998904135879669796","flags":0,"ts_in_delta":988,"sequence":187331,"symbol":"FCEU SI 20260615 PS"}
{"ts_recv":"2026-04-07T03:21:43.426086776Z","hd":{"ts_event":"2026-04-07T03:21:43.426067389Z","rtype":160,"publisher_id":101,"instrument_id":436},"action":"A","side":"B","price":"1.156660000","size":30,"channel_id":23,"order_id":"10998904140280849350","flags":0,"ts_in_delta":988,"sequence":187331,"symbol":"FCEU SI 20260615 PS"}
{"ts_recv":"2026-04-07T03:21:43.426086776Z","hd":{"ts_event":"2026-04-07T03:21:43.426067389Z","rtype":160,"publisher_id":101,"instrument_id":436},"action":"C","side":"A","price":"1.156780000","size":30,"channel_id":23,"order_id":"1775532099024893988","flags":0,"ts_in_delta":988,"sequence":187331,"symbol":"FCEU SI 20260615 PS"}
{"ts_recv":"2026-04-07T03:21:43.426086776Z","hd":{"ts_event":"2026-04-07T03:21:43.426067389Z","rtype":160,"publisher_id":101,"instrument_id":436},"action":"A","side":"A","price":"1.156760000","size":30,"channel_id":23,"order_id":"1775532103426073542","flags":128,"ts_in_delta":988,"sequence":187331,"symbol":"FCEU SI 20260615 PS"}
{"ts_recv":"2026-04-07T03:21:43.426095968Z","hd":{"ts_event":"2026-04-07T03:21:43.426077647Z","rtype":160,"publisher_id":101,"instrument_id":436},"action":"C","side":"B","price":"1.156660000","size":30,"channel_id":23,"order_id":"10998904140280797100","flags":0,"ts_in_delta":940,"sequence":187332,"symbol":"FCEU SI 20260615 PS"}
{"ts_recv":"2026-04-07T03:21:43.426095968Z","hd":{"ts_event":"2026-04-07T03:21:43.426077647Z","rtype":160,"publisher_id":101,"instrument_id":436},"action":"A","side":"B","price":"1.156670000","size":30,"channel_id":23,"order_id":"10998904140280859090","flags":0,"ts_in_delta":940,"sequence":187332,"symbol":"FCEU SI 20260615 PS"}
{"ts_recv":"2026-04-07T03:21:43.426095968Z","hd":{"ts_event":"2026-04-07T03:21:43.426077647Z","rtype":160,"publisher_id":101,"instrument_id":436},"action":"C","side":"A","price":"1.156760000","size":30,"channel_id":23,"order_id":"1775532103426021292","flags":0,"ts_in_delta":940,"sequence":187332,"symbol":"FCEU SI 20260615 PS"}
{"ts_recv":"2026-04-07T03:21:43.426095968Z","hd":{"ts_event":"2026-04-07T03:21:43.426077647Z","rtype":160,"publisher_id":101,"instrument_id":436},"action":"A","side":"A","price":"1.156770000","size":30,"channel_id":23,"order_id":"1775532103426083282","flags":128,"ts_in_delta":940,"sequence":187332,"symbol":"FCEU SI 20260615 PS"}
{"ts_recv":"2026-04-07T03:21:43.426153297Z","hd":{"ts_event":"2026-04-07T03:21:43.426136465Z","rtype":160,"publisher_id":101,"instrument_id":436},"action":"C","side":"B","price":"1.156670000","size":30,"channel_id":23,"order_id":"10998904140280859090","flags":0,"ts_in_delta":934,"sequence":187333,"symbol":"FCEU SI 20260615 PS"}
{"ts_recv":"2026-04-07T03:21:43.426153297Z","hd":{"ts_event":"2026-04-07T03:21:43.426136465Z","rtype":160,"publisher_id":101,"instrument_id":436},"action":"A","side":"B","price":"1.156660000","size":30,"channel_id":23,"order_id":"10998904140280918174","flags":0,"ts_in_delta":934,"sequence":187333,"symbol":"FCEU SI 20260615 PS"}
{"ts_recv":"2026-04-07T03:21:43.426153297Z","hd":{"ts_event":"2026-04-07T03:21:43.426136465Z","rtype":160,"publisher_id":101,"instrument_id":436},"action":"C","side":"A","price":"1.156770000","size":30,"channel_id":23,"order_id":"1775532103426083282","flags":0,"ts_in_delta":934,"sequence":187333,"symbol":"FCEU SI 20260615 PS"}
{"ts_recv":"2026-04-07T03:21:43.426153297Z","hd":{"ts_event":"2026-04-07T03:21:43.426136465Z","rtype":160,"publisher_id":101,"instrument_id":436},"action":"A","side":"A","price":"1.156760000","size":30,"channel_id":23,"order_id":"1775532103426142366","flags":128,"ts_in_delta":934,"sequence":187333,"symbol":"FCEU SI 20260615 PS"}
{"ts_recv":"2026-04-07T03:22:02.937595009Z","hd":{"ts_event":"2026-04-07T03:22:02.937570953Z","rtype":160,"publisher_id":101,"instrument_id":436},"action":"C","side":"B","price":"1.156660000","size":30,"channel_id":23,"order_id":"10998904140280918174","flags":0,"ts_in_delta":1342,"sequence":187467,"symbol":"FCEU SI 20260615 PS"}
{"ts_recv":"2026-04-07T03:22:02.937595009Z","hd":{"ts_event":"2026-04-07T03:22:02.937570953Z","rtype":160,"publisher_id":101,"instrument_id":436},"action":"A","side":"B","price":"1.156670000","size":30,"channel_id":23,"order_id":"10998904159792352920","flags":0,"ts_in_delta":1342,"sequence":187467,"symbol":"FCEU SI 20260615 PS"}
{"ts_recv":"2026-04-07T03:22:02.937595009Z","hd":{"ts_event":"2026-04-07T03:22:02.937570953Z","rtype":160,"publisher_id":101,"instrument_id":436},"action":"C","side":"A","price":"1.156760000","size":30,"channel_id":23,"order_id":"1775532103426142366","flags":0,"ts_in_delta":1342,"sequence":187467,"symbol":"FCEU SI 20260615 PS"}
{"ts_recv":"2026-04-07T03:22:02.937595009Z","hd":{"ts_event":"2026-04-07T03:22:02.937570953Z","rtype":160,"publisher_id":101,"instrument_id":436},"action":"A","side":"A","price":"1.156770000","size":30,"channel_id":23,"order_id":"1775532122937577112","flags":128,"ts_in_delta":1342,"sequence":187467,"symbol":"FCEU SI 20260615 PS"}
{"ts_recv":"2026-04-07T03:22:02.969766957Z","hd":{"ts_event":"2026-04-07T03:22:02.969745445Z","rtype":160,"publisher_id":101,"instrument_id":436},"action":"C","side":"B","price":"1.156660000","size":30,"channel_id":23,"order_id":"10998904140280849350","flags":0,"ts_in_delta":978,"sequence":187477,"symbol":"FCEU SI 20260615 PS"}
{"ts_recv":"2026-04-07T03:22:02.969766957Z","hd":{"ts_event":"2026-04-07T03:22:02.969745445Z","rtype":160,"publisher_id":101,"instrument_id":436},"action":"A","side":"B","price":"1.156680000","size":30,"channel_id":23,"order_id":"10998904159824527254","flags":0,"ts_in_delta":978,"sequence":187477,"symbol":"FCEU SI 20260615 PS"}
{"ts_recv":"2026-04-07T03:22:02.969766957Z","hd":{"ts_event":"2026-04-07T03:22:02.969745445Z","rtype":160,"publisher_id":101,"instrument_id":436},"action":"C","side":"A","price":"1.156760000","size":30,"channel_id":23,"order_id":"1775532103426073542","flags":0,"ts_in_delta":978,"sequence":187477,"symbol":"FCEU SI 20260615 PS"}
{"ts_recv":"2026-04-07T03:22:02.969766957Z","hd":{"ts_event":"2026-04-07T03:22:02.969745445Z","rtype":160,"publisher_id":101,"instrument_id":436},"action":"A","side":"A","price":"1.156780000","size":30,"channel_id":23,"order_id":"1775532122969751446","flags":128,"ts_in_delta":978,"sequence":187477,"symbol":"FCEU SI 20260615 PS"}
{"ts_recv":"2026-04-07T03:22:02.969828993Z","hd":{"ts_event":"2026-04-07T03:22:02.969812767Z","rtype":160,"publisher_id":101,"instrument_id":436},"action":"C","side":"B","price":"1.156670000","size":30,"channel_id":23,"order_id":"10998904159792352920","flags":0,"ts_in_delta":1008,"sequence":187478,"symbol":"FCEU SI 20260615 PS"}
{"ts_recv":"2026-04-07T03:22:02.969828993Z","hd":{"ts_event":"2026-04-07T03:22:02.969812767Z","rtype":160,"publisher_id":101,"instrument_id":436},"action":"A","side":"B","price":"1.156680000","size":30,"channel_id":23,"order_id":"10998904159824594629","flags":0,"ts_in_delta":1008,"sequence":187478,"symbol":"FCEU SI 20260615 PS"}
{"ts_recv":"2026-04-07T03:22:02.969828993Z","hd":{"ts_event":"2026-04-07T03:22:02.969812767Z","rtype":160,"publisher_id":101,"instrument_id":436},"action":"C","side":"A","price":"1.156770000","size":30,"channel_id":23,"order_id":"1775532122937577112","flags":0,"ts_in_delta":1008,"sequence":187478,"symbol":"FCEU SI 20260615 PS"}
{"ts_recv":"2026-04-07T03:22:02.969828993Z","hd":{"ts_event":"2026-04-07T03:22:02.969812767Z","rtype":160,"publisher_id":101,"instrument_id":436},"action":"A","side":"A","price":"1.156780000","size":30,"channel_id":23,"order_id":"1775532122969818821","flags":128,"ts_in_delta":1008,"sequence":187478,"symbol":"FCEU SI 20260615 PS"}
{"ts_recv":"2026-04-07T03:22:09.603345236Z","hd":{"ts_event":"2026-04-07T03:22:09.603321227Z","rtype":160,"publisher_id":101,"instrument_id":436},"action":"C","side":"B","price":"1.156680000","size":30,"channel_id":23,"order_id":"10998904159824594629","flags":0,"ts_in_delta":942,"sequence":187521,"symbol":"FCEU SI 20260615 PS"}
{"ts_recv":"2026-04-07T03:22:09.603345236Z","hd":{"ts_event":"2026-04-07T03:22:09.603321227Z","rtype":160,"publisher_id":101,"instrument_id":436},"action":"A","side":"B","price":"1.156690000","size":30,"channel_id":23,"order_id":"10998904166458103368","flags":0,"ts_in_delta":942,"sequence":187521,"symbol":"FCEU SI 20260615 PS"}
{"ts_recv":"2026-04-07T03:22:09.603345236Z","hd":{"ts_event":"2026-04-07T03:22:09.603321227Z","rtype":160,"publisher_id":101,"instrument_id":436},"action":"C","side":"A","price":"1.156780000","size":30,"channel_id":23,"order_id":"1775532122969818821","flags":0,"ts_in_delta":942,"sequence":187521,"symbol":"FCEU SI 20260615 PS"}
{"ts_recv":"2026-04-07T03:22:09.603345236Z","hd":{"ts_event":"2026-04-07T03:22:09.603321227Z","rtype":160,"publisher_id":101,"instrument_id":436},"action":"A","side":"A","price":"1.156790000","size":30,"channel_id":23,"order_id":"1775532129603327560","flags":128,"ts_in_delta":942,"sequence":187521,"symbol":"FCEU SI 20260615 PS"}
{"ts_recv":"2026-04-07T03:22:09.615255894Z","hd":{"ts_event":"2026-04-07T03:22:09.615233771Z","rtype":160,"publisher_id":101,"instrument_id":436},"action":"C","side":"B","price":"1.156680000","size":30,"channel_id":23,"order_id":"10998904159824527254","flags":0,"ts_in_delta":962,"sequence":187523,"symbol":"FCEU SI 20260615 PS"}
{"ts_recv":"2026-04-07T03:22:09.615255894Z","hd":{"ts_event":"2026-04-07T03:22:09.615233771Z","rtype":160,"publisher_id":101,"instrument_id":436},"action":"A","side":"B","price":"1.156700000","size":30,"channel_id":23,"order_id":"10998904166470015674","flags":0,"ts_in_delta":962,"sequence":187523,"symbol":"FCEU SI 20260615 PS"}
{"ts_recv":"2026-04-07T03:22:09.615255894Z","hd":{"ts_event":"2026-04-07T03:22:09.615233771Z","rtype":160,"publisher_id":101,"instrument_id":436},"action":"C","side":"A","price":"1.156780000","size":30,"channel_id":23,"order_id":"1775532122969751446","flags":0,"ts_in_delta":962,"sequence":187523,"symbol":"FCEU SI 20260615 PS"}
{"ts_recv":"2026-04-07T03:22:09.615255894Z","hd":{"ts_event":"2026-04-07T03:22:09.615233771Z","rtype":160,"publisher_id":101,"instrument_id":436},"action":"A","side":"A","price":"1.156800000","size":30,"channel_id":23,"order_id":"1775532129615239866","flags":128,"ts_in_delta":962,"sequence":187523,"symbol":"FCEU SI 20260615 PS"}
{"ts_recv":"2026-04-07T03:22:09.615324872Z","hd":{"ts_event":"2026-04-07T03:22:09.615308171Z","rtype":160,"publisher_id":101,"instrument_id":436},"action":"C","side":"B","price":"1.156690000","size":30,"channel_id":23,"order_id":"10998904166458103368","flags":0,"ts_in_delta":955,"sequence":187524,"symbol":"FCEU SI 20260615 PS"}
{"ts_recv":"2026-04-07T03:22:09.615324872Z","hd":{"ts_event":"2026-04-07T03:22:09.615308171Z","rtype":160,"publisher_id":101,"instrument_id":436},"action":"A","side":"B","price":"1.156700000","size":30,"channel_id":23,"order_id":"10998904166470089929","flags":0,"ts_in_delta":955,"sequence":187524,"symbol":"FCEU SI 20260615 PS"}
{"ts_recv":"2026-04-07T03:22:09.615324872Z","hd":{"ts_event":"2026-04-07T03:22:09.615308171Z","rtype":160,"publisher_id":101,"instrument_id":436},"action":"C","side":"A","price":"1.156790000","size":30,"channel_id":23,"order_id":"1775532129603327560","flags":0,"ts_in_delta":955,"sequence":187524,"symbol":"FCEU SI 20260615 PS"}
{"ts_recv":"2026-04-07T03:22:09.615324872Z","hd":{"ts_event":"2026-04-07T03:22:09.615308171Z","rtype":160,"publisher_id":101,"instrument_id":436},"action":"A","side":"A","price":"1.156800000","size":30,"channel_id":23,"order_id":"1775532129615314121","flags":128,"ts_in_delta":955,"sequence":187524,"symbol":"FCEU SI 20260615 PS"}
{"ts_recv":"2026-04-07T03:22:09.687467138Z","hd":{"ts_event":"2026-04-07T03:22:09.687446667Z","rtype":160,"publisher_id":101,"instrument_id":436},"action":"C","side":"B","price":"1.156700000","size":30,"channel_id":23,"order_id":"10998904166470089929","flags":0,"ts_in_delta":1226,"sequence":187530,"symbol":"FCEU SI 20260615 PS"}
{"ts_recv":"2026-04-07T03:22:09.687467138Z","hd":{"ts_event":"2026-04-07T03:22:09.687446667Z","rtype":160,"publisher_id":101,"instrument_id":436},"action":"A","side":"B","price":"1.156690000","size":30,"channel_id":23,"order_id":"10998904166542228749","flags":0,"ts_in_delta":1226,"sequence":187530,"symbol":"FCEU SI 20260615 PS"}
{"ts_recv":"2026-04-07T03:22:09.687467138Z","hd":{"ts_event":"2026-04-07T03:22:09.687446667Z","rtype":160,"publisher_id":101,"instrument_id":436},"action":"C","side":"A","price":"1.156800000","size":30,"channel_id":23,"order_id":"1775532129615314121","flags":0,"ts_in_delta":1226,"sequence":187530,"symbol":"FCEU SI 20260615 PS"}
{"ts_recv":"2026-04-07T03:22:09.687467138Z","hd":{"ts_event":"2026-04-07T03:22:09.687446667Z","rtype":160,"publisher_id":101,"instrument_id":436},"action":"A","side":"A","price":"1.156790000","size":30,"channel_id":23,"order_id":"1775532129687452941","flags":128,"ts_in_delta":1226,"sequence":187530,"symbol":"FCEU SI 20260615 PS"}
{"ts_recv":"2026-04-07T03:22:09.687551368Z","hd":{"ts_event":"2026-04-07T03:22:09.687530149Z","rtype":160,"publisher_id":101,"instrument_id":436},"action":"C","side":"B","price":"1.156690000","size":30,"channel_id":23,"order_id":"10998904166542228749","flags":0,"ts_in_delta":925,"sequence":187531,"symbol":"FCEU SI 20260615 PS"}
{"ts_recv":"2026-04-07T03:22:09.687551368Z","hd":{"ts_event":"2026-04-07T03:22:09.687530149Z","rtype":160,"publisher_id":101,"instrument_id":436},"action":"A","side":"B","price":"1.156680000","size":30,"channel_id":23,"order_id":"10998904166542311844","flags":0,"ts_in_delta":925,"sequence":187531,"symbol":"FCEU SI 20260615 PS"}
{"ts_recv":"2026-04-07T03:22:09.687551368Z","hd":{"ts_event":"2026-04-07T03:22:09.687530149Z","rtype":160,"publisher_id":101,"instrument_id":436},"action":"C","side":"A","price":"1.156790000","size":30,"channel_id":23,"order_id":"1775532129687452941","flags":0,"ts_in_delta":925,"sequence":187531,"symbol":"FCEU SI 20260615 PS"}
{"ts_recv":"2026-04-07T03:22:09.687551368Z","hd":{"ts_event":"2026-04-07T03:22:09.687530149Z","rtype":160,"publisher_id":101,"instrument_id":436},"action":"A","side":"A","price":"1.156780000","size":30,"channel_id":23,"order_id":"1775532129687536036","flags":128,"ts_in_delta":925,"sequence":187531,"symbol":"FCEU SI 20260615 PS"}
{"ts_recv":"2026-04-07T03:22:09.687604189Z","hd":{"ts_event":"2026-04-07T03:22:09.687586581Z","rtype":160,"publisher_id":101,"instrument_id":436},"action":"C","side":"B","price":"1.156700000","size":30,"channel_id":23,"order_id":"10998904166470015674","flags":0,"ts_in_delta":935,"sequence":187532,"symbol":"FCEU SI 20260615 PS"}
{"ts_recv":"2026-04-07T03:22:09.687604189Z","hd":{"ts_event":"2026-04-07T03:22:09.687586581Z","rtype":160,"publisher_id":101,"instrument_id":436},"action":"A","side":"B","price":"1.156680000","size":30,"channel_id":23,"order_id":"10998904166542368710","flags":0,"ts_in_delta":935,"sequence":187532,"symbol":"FCEU SI 20260615 PS"}
{"ts_recv":"2026-04-07T03:22:09.687604189Z","hd":{"ts_event":"2026-04-07T03:22:09.687586581Z","rtype":160,"publisher_id":101,"instrument_id":436},"action":"C","side":"A","price":"1.156800000","size":30,"channel_id":23,"order_id":"1775532129615239866","flags":0,"ts_in_delta":935,"sequence":187532,"symbol":"FCEU SI 20260615 PS"}
{"ts_recv":"2026-04-07T03:22:09.687604189Z","hd":{"ts_event":"2026-04-07T03:22:09.687586581Z","rtype":160,"publisher_id":101,"instrument_id":436},"action":"A","side":"A","price":"1.156780000","size":30,"channel_id":23,"order_id":"1775532129687592902","flags":128,"ts_in_delta":935,"sequence":187532,"symbol":"FCEU SI 20260615 PS"}
{"ts_recv":"2026-04-07T03:22:09.687613320Z","hd":{"ts_event":"2026-04-07T03:22:09.687591073Z","rtype":160,"publisher_id":101,"instrument_id":436},"action":"C","side":"B","price":"1.156680000","size":30,"channel_id":23,"order_id":"10998904166542311844","flags":0,"ts_in_delta":922,"sequence":187533,"symbol":"FCEU SI 20260615 PS"}
{"ts_recv":"2026-04-07T03:22:09.687613320Z","hd":{"ts_event":"2026-04-07T03:22:09.687591073Z","rtype":160,"publisher_id":101,"instrument_id":436},"action":"A","side":"B","price":"1.156690000","size":30,"channel_id":23,"order_id":"10998904166542376679","flags":0,"ts_in_delta":922,"sequence":187533,"symbol":"FCEU SI 20260615 PS"}
{"ts_recv":"2026-04-07T03:22:09.687613320Z","hd":{"ts_event":"2026-04-07T03:22:09.687591073Z","rtype":160,"publisher_id":101,"instrument_id":436},"action":"C","side":"A","price":"1.156780000","size":30,"channel_id":23,"order_id":"1775532129687536036","flags":0,"ts_in_delta":922,"sequence":187533,"symbol":"FCEU SI 20260615 PS"}
{"ts_recv":"2026-04-07T03:22:09.687613320Z","hd":{"ts_event":"2026-04-07T03:22:09.687591073Z","rtype":160,"publisher_id":101,"instrument_id":436},"action":"A","side":"A","price":"1.156790000","size":30,"channel_id":23,"order_id":"1775532129687600871","flags":128,"ts_in_delta":922,"sequence":187533,"symbol":"FCEU SI 20260615 PS"}
{"ts_recv":"2026-04-07T03:22:09.687665058Z","hd":{"ts_event":"2026-04-07T03:22:09.687649499Z","rtype":160,"publisher_id":101,"instrument_id":436},"action":"C","side":"B","price":"1.156690000","size":30,"channel_id":23,"order_id":"10998904166542376679","flags":0,"ts_in_delta":946,"sequence":187534,"symbol":"FCEU SI 20260615 PS"}
{"ts_recv":"2026-04-07T03:22:09.687665058Z","hd":{"ts_event":"2026-04-07T03:22:09.687649499Z","rtype":160,"publisher_id":101,"instrument_id":436},"action":"A","side":"B","price":"1.156680000","size":30,"channel_id":23,"order_id":"10998904166542431466","flags":0,"ts_in_delta":946,"sequence":187534,"symbol":"FCEU SI 20260615 PS"}
{"ts_recv":"2026-04-07T03:22:09.687665058Z","hd":{"ts_event":"2026-04-07T03:22:09.687649499Z","rtype":160,"publisher_id":101,"instrument_id":436},"action":"C","side":"A","price":"1.156790000","size":30,"channel_id":23,"order_id":"1775532129687600871","flags":0,"ts_in_delta":946,"sequence":187534,"symbol":"FCEU SI 20260615 PS"}
{"ts_recv":"2026-04-07T03:22:09.687665058Z","hd":{"ts_event":"2026-04-07T03:22:09.687649499Z","rtype":160,"publisher_id":101,"instrument_id":436},"action":"A","side":"A","price":"1.156780000","size":30,"channel_id":23,"order_id":"1775532129687655658","flags":128,"ts_in_delta":946,"sequence":187534,"symbol":"FCEU SI 20260615 PS"}
{"ts_recv":"2026-04-07T03:22:26.847273484Z","hd":{"ts_event":"2026-04-07T03:22:26.847251487Z","rtype":160,"publisher_id":101,"instrument_id":436},"action":"C","side":"B","price":"1.156680000","size":30,"channel_id":23,"order_id":"10998904166542431466","flags":0,"ts_in_delta":960,"sequence":187629,"symbol":"FCEU SI 20260615 PS"}
{"ts_recv":"2026-04-07T03:22:26.847273484Z","hd":{"ts_event":"2026-04-07T03:22:26.847251487Z","rtype":160,"publisher_id":101,"instrument_id":436},"action":"A","side":"B","price":"1.156690000","size":30,"channel_id":23,"order_id":"10998904183702033907","flags":0,"ts_in_delta":960,"sequence":187629,"symbol":"FCEU SI 20260615 PS"}
{"ts_recv":"2026-04-07T03:22:26.847273484Z","hd":{"ts_event":"2026-04-07T03:22:26.847251487Z","rtype":160,"publisher_id":101,"instrument_id":436},"action":"C","side":"A","price":"1.156780000","size":30,"channel_id":23,"order_id":"1775532129687655658","flags":0,"ts_in_delta":960,"sequence":187629,"symbol":"FCEU SI 20260615 PS"}
{"ts_recv":"2026-04-07T03:22:26.847273484Z","hd":{"ts_event":"2026-04-07T03:22:26.847251487Z","rtype":160,"publisher_id":101,"instrument_id":436},"action":"A","side":"A","price":"1.156790000","size":30,"channel_id":23,"order_id":"1775532146847258099","flags":128,"ts_in_delta":960,"sequence":187629,"symbol":"FCEU SI 20260615 PS"}
{"ts_recv":"2026-04-07T03:22:26.847335366Z","hd":{"ts_event":"2026-04-07T03:22:26.847317235Z","rtype":160,"publisher_id":101,"instrument_id":436},"action":"C","side":"B","price":"1.156680000","size":30,"channel_id":23,"order_id":"10998904166542368710","flags":0,"ts_in_delta":966,"sequence":187630,"symbol":"FCEU SI 20260615 PS"}
{"ts_recv":"2026-04-07T03:22:26.847335366Z","hd":{"ts_event":"2026-04-07T03:22:26.847317235Z","rtype":160,"publisher_id":101,"instrument_id":436},"action":"A","side":"B","price":"1.156700000","size":30,"channel_id":23,"order_id":"10998904183702099215","flags":0,"ts_in_delta":966,"sequence":187630,"symbol":"FCEU SI 20260615 PS"}
{"ts_recv":"2026-04-07T03:22:26.847335366Z","hd":{"ts_event":"2026-04-07T03:22:26.847317235Z","rtype":160,"publisher_id":101,"instrument_id":436},"action":"C","side":"A","price":"1.156780000","size":30,"channel_id":23,"order_id":"1775532129687592902","flags":0,"ts_in_delta":966,"sequence":187630,"symbol":"FCEU SI 20260615 PS"}
{"ts_recv":"2026-04-07T03:22:26.847335366Z","hd":{"ts_event":"2026-04-07T03:22:26.847317235Z","rtype":160,"publisher_id":101,"instrument_id":436},"action":"A","side":"A","price":"1.156800000","size":30,"channel_id":23,"order_id":"1775532146847323407","flags":128,"ts_in_delta":966,"sequence":187630,"symbol":"FCEU SI 20260615 PS"}
{"ts_recv":"2026-04-07T03:22:26.847404698Z","hd":{"ts_event":"2026-04-07T03:22:26.847381729Z","rtype":160,"publisher_id":101,"instrument_id":436},"action":"C","side":"B","price":"1.156690000","size":30,"channel_id":23,"order_id":"10998904183702033907","flags":0,"ts_in_delta":923,"sequence":187631,"symbol":"FCEU SI 20260615 PS"}
{"ts_recv":"2026-04-07T03:22:26.847404698Z","hd":{"ts_event":"2026-04-07T03:22:26.847381729Z","rtype":160,"publisher_id":101,"instrument_id":436},"action":"A","side":"B","price":"1.156700000","size":30,"channel_id":23,"order_id":"10998904183702163908","flags":0,"ts_in_delta":923,"sequence":187631,"symbol":"FCEU SI 20260615 PS"}
{"ts_recv":"2026-04-07T03:22:26.847404698Z","hd":{"ts_event":"2026-04-07T03:22:26.847381729Z","rtype":160,"publisher_id":101,"instrument_id":436},"action":"C","side":"A","price":"1.156790000","size":30,"channel_id":23,"order_id":"1775532146847258099","flags":0,"ts_in_delta":923,"sequence":187631,"symbol":"FCEU SI 20260615 PS"}
{"ts_recv":"2026-04-07T03:22:26.847404698Z","hd":{"ts_event":"2026-04-07T03:22:26.847381729Z","rtype":160,"publisher_id":101,"instrument_id":436},"action":"A","side":"A","price":"1.156800000","size":30,"channel_id":23,"order_id":"1775532146847388100","flags":128,"ts_in_delta":923,"sequence":187631,"symbol":"FCEU SI 20260615 PS"}
{"ts_recv":"2026-04-07T03:22:26.851999425Z","hd":{"ts_event":"2026-04-07T03:22:26.851980073Z","rtype":160,"publisher_id":101,"instrument_id":436},"action":"C","side":"B","price":"1.156700000","size":30,"channel_id":23,"order_id":"10998904183702163908","flags":0,"ts_in_delta":779,"sequence":187632,"symbol":"FCEU SI 20260615 PS"}
{"ts_recv":"2026-04-07T03:22:26.851999425Z","hd":{"ts_event":"2026-04-07T03:22:26.851980073Z","rtype":160,"publisher_id":101,"instrument_id":436},"action":"A","side":"B","price":"1.156710000","size":30,"channel_id":23,"order_id":"10998904183706761972","flags":0,"ts_in_delta":779,"sequence":187632,"symbol":"FCEU SI 20260615 PS"}
{"ts_recv":"2026-04-07T03:22:26.851999425Z","hd":{"ts_event":"2026-04-07T03:22:26.851980073Z","rtype":160,"publisher_id":101,"instrument_id":436},"action":"C","side":"A","price":"1.156800000","size":30,"channel_id":23,"order_id":"1775532146847388100","flags":0,"ts_in_delta":779,"sequence":187632,"symbol":"FCEU SI 20260615 PS"}
{"ts_recv":"2026-04-07T03:22:26.851999425Z","hd":{"ts_event":"2026-04-07T03:22:26.851980073Z","rtype":160,"publisher_id":101,"instrument_id":436},"action":"A","side":"A","price":"1.156810000","size":30,"channel_id":23,"order_id":"1775532146851986164","flags":128,"ts_in_delta":779,"sequence":187632,"symbol":"FCEU SI 20260615 PS"}
{"ts_recv":"2026-04-07T03:22:26.903302307Z","hd":{"ts_event":"2026-04-07T03:22:26.903280799Z","rtype":160,"publisher_id":101,"instrument_id":436},"action":"A","side":"B","price":"1.156600000","size":20,"channel_id":23,"order_id":"10998904183758064535","flags":128,"ts_in_delta":1018,"sequence":187637,"symbol":"FCEU SI 20260615 PS"}
{"ts_recv":"2026-04-07T03:22:26.903307199Z","hd":{"ts_event":"2026-04-07T03:22:26.903291345Z","rtype":160,"publisher_id":101,"instrument_id":436},"action":"C","side":"B","price":"1.156500000","size":20,"channel_id":23,"order_id":"10998904074507879950","flags":128,"ts_in_delta":997,"sequence":187638,"symbol":"FCEU SI 20260615 PS"}
{"ts_recv":"2026-04-07T03:22:26.995918042Z","hd":{"ts_event":"2026-04-07T03:22:26.995894735Z","rtype":160,"publisher_id":101,"instrument_id":436},"action":"C","side":"B","price":"1.156710000","size":30,"channel_id":23,"order_id":"10998904183706761972","flags":0,"ts_in_delta":946,"sequence":187641,"symbol":"FCEU SI 20260615 PS"}
{"ts_recv":"2026-04-07T03:22:26.995918042Z","hd":{"ts_event":"2026-04-07T03:22:26.995894735Z","rtype":160,"publisher_id":101,"instrument_id":436},"action":"A","side":"B","price":"1.156700000","size":30,"channel_id":23,"order_id":"10998904183850681159","flags":0,"ts_in_delta":946,"sequence":187641,"symbol":"FCEU SI 20260615 PS"}
{"ts_recv":"2026-04-07T03:22:26.995918042Z","hd":{"ts_event":"2026-04-07T03:22:26.995894735Z","rtype":160,"publisher_id":101,"instrument_id":436},"action":"C","side":"A","price":"1.156810000","size":30,"channel_id":23,"order_id":"1775532146851986164","flags":0,"ts_in_delta":946,"sequence":187641,"symbol":"FCEU SI 20260615 PS"}
{"ts_recv":"2026-04-07T03:22:26.995918042Z","hd":{"ts_event":"2026-04-07T03:22:26.995894735Z","rtype":160,"publisher_id":101,"instrument_id":436},"action":"A","side":"A","price":"1.156800000","size":30,"channel_id":23,"order_id":"1775532146995905351","flags":128,"ts_in_delta":946,"sequence":187641,"symbol":"FCEU SI 20260615 PS"}
{"ts_recv":"2026-04-07T03:22:37.517525965Z","hd":{"ts_event":"2026-04-07T03:22:37.517503143Z","rtype":160,"publisher_id":101,"instrument_id":436},"action":"C","side":"B","price":"1.156700000","size":30,"channel_id":23,"order_id":"10998904183850681159","flags":0,"ts_in_delta":907,"sequence":187707,"symbol":"FCEU SI 20260615 PS"}
{"ts_recv":"2026-04-07T03:22:37.517525965Z","hd":{"ts_event":"2026-04-07T03:22:37.517503143Z","rtype":160,"publisher_id":101,"instrument_id":436},"action":"A","side":"B","price":"1.156710000","size":30,"channel_id":23,"order_id":"10998904194372284899","flags":0,"ts_in_delta":907,"sequence":187707,"symbol":"FCEU SI 20260615 PS"}
{"ts_recv":"2026-04-07T03:22:37.517525965Z","hd":{"ts_event":"2026-04-07T03:22:37.517503143Z","rtype":160,"publisher_id":101,"instrument_id":436},"action":"C","side":"A","price":"1.156800000","size":30,"channel_id":23,"order_id":"1775532146995905351","flags":0,"ts_in_delta":907,"sequence":187707,"symbol":"FCEU SI 20260615 PS"}
{"ts_recv":"2026-04-07T03:22:37.517525965Z","hd":{"ts_event":"2026-04-07T03:22:37.517503143Z","rtype":160,"publisher_id":101,"instrument_id":436},"action":"A","side":"A","price":"1.156810000","size":30,"channel_id":23,"order_id":"1775532157517509091","flags":128,"ts_in_delta":907,"sequence":187707,"symbol":"FCEU SI 20260615 PS"}
{"ts_recv":"2026-04-07T03:22:37.574370816Z","hd":{"ts_event":"2026-04-07T03:22:37.574351983Z","rtype":160,"publisher_id":101,"instrument_id":436},"action":"C","side":"B","price":"1.156710000","size":30,"channel_id":23,"order_id":"10998904194372284899","flags":0,"ts_in_delta":704,"sequence":187712,"symbol":"FCEU SI 20260615 PS"}
{"ts_recv":"2026-04-07T03:22:37.574370816Z","hd":{"ts_event":"2026-04-07T03:22:37.574351983Z","rtype":160,"publisher_id":101,"instrument_id":436},"action":"A","side":"B","price":"1.156700000","size":30,"channel_id":23,"order_id":"10998904194429133917","flags":0,"ts_in_delta":704,"sequence":187712,"symbol":"FCEU SI 20260615 PS"}
{"ts_recv":"2026-04-07T03:22:37.574370816Z","hd":{"ts_event":"2026-04-07T03:22:37.574351983Z","rtype":160,"publisher_id":101,"instrument_id":436},"action":"C","side":"A","price":"1.156810000","size":30,"channel_id":23,"order_id":"1775532157517509091","flags":0,"ts_in_delta":704,"sequence":187712,"symbol":"FCEU SI 20260615 PS"}
{"ts_recv":"2026-04-07T03:22:37.574370816Z","hd":{"ts_event":"2026-04-07T03:22:37.574351983Z","rtype":160,"publisher_id":101,"instrument_id":436},"action":"A","side":"A","price":"1.156800000","size":30,"channel_id":23,"order_id":"1775532157574358109","flags":128,"ts_in_delta":704,"sequence":187712,"symbol":"FCEU SI 20260615 PS"}
{"ts_recv":"2026-04-07T03:22:37.835241443Z","hd":{"ts_event":"2026-04-07T03:22:37.835219771Z","rtype":160,"publisher_id":101,"instrument_id":436},"action":"C","side":"B","price":"1.156700000","size":30,"channel_id":23,"order_id":"10998904194429133917","flags":0,"ts_in_delta":944,"sequence":187726,"symbol":"FCEU SI 20260615 PS"}
{"ts_recv":"2026-04-07T03:22:37.835241443Z","hd":{"ts_event":"2026-04-07T03:22:37.835219771Z","rtype":160,"publisher_id":101,"instrument_id":436},"action":"A","side":"B","price":"1.156710000","size":30,"channel_id":23,"order_id":"10998904194690001599","flags":0,"ts_in_delta":944,"sequence":187726,"symbol":"FCEU SI 20260615 PS"}
{"ts_recv":"2026-04-07T03:22:37.835241443Z","hd":{"ts_event":"2026-04-07T03:22:37.835219771Z","rtype":160,"publisher_id":101,"instrument_id":436},"action":"C","side":"A","price":"1.156800000","size":30,"channel_id":23,"order_id":"1775532157574358109","flags":0,"ts_in_delta":944,"sequence":187726,"symbol":"FCEU SI 20260615 PS"}
{"ts_recv":"2026-04-07T03:22:37.835241443Z","hd":{"ts_event":"2026-04-07T03:22:37.835219771Z","rtype":160,"publisher_id":101,"instrument_id":436},"action":"A","side":"A","price":"1.156810000","size":30,"channel_id":23,"order_id":"1775532157835225791","flags":128,"ts_in_delta":944,"sequence":187726,"symbol":"FCEU SI 20260615 PS"}
{"ts_recv":"2026-04-07T03:22:37.835293941Z","hd":{"ts_event":"2026-04-07T03:22:37.835273685Z","rtype":160,"publisher_id":101,"instrument_id":436},"action":"C","side":"B","price":"1.156700000","size":30,"channel_id":23,"order_id":"10998904183702099215","flags":0,"ts_in_delta":885,"sequence":187727,"symbol":"FCEU SI 20260615 PS"}
{"ts_recv":"2026-04-07T03:22:37.835293941Z","hd":{"ts_event":"2026-04-07T03:22:37.835273685Z","rtype":160,"publisher_id":101,"instrument_id":436},"action":"A","side":"B","price":"1.156720000","size":30,"channel_id":23,"order_id":"10998904194690055850","flags":0,"ts_in_delta":885,"sequence":187727,"symbol":"FCEU SI 20260615 PS"}
{"ts_recv":"2026-04-07T03:22:37.835293941Z","hd":{"ts_event":"2026-04-07T03:22:37.835273685Z","rtype":160,"publisher_id":101,"instrument_id":436},"action":"C","side":"A","price":"1.156800000","size":30,"channel_id":23,"order_id":"1775532146847323407","flags":0,"ts_in_delta":885,"sequence":187727,"symbol":"FCEU SI 20260615 PS"}
{"ts_recv":"2026-04-07T03:22:37.835293941Z","hd":{"ts_event":"2026-04-07T03:22:37.835273685Z","rtype":160,"publisher_id":101,"instrument_id":436},"action":"A","side":"A","price":"1.156820000","size":30,"channel_id":23,"order_id":"1775532157835280042","flags":128,"ts_in_delta":885,"sequence":187727,"symbol":"FCEU SI 20260615 PS"}
{"ts_recv":"2026-04-07T03:22:37.835347322Z","hd":{"ts_event":"2026-04-07T03:22:37.835328771Z","rtype":160,"publisher_id":101,"instrument_id":436},"action":"C","side":"B","price":"1.156710000","size":30,"channel_id":23,"order_id":"10998904194690001599","flags":0,"ts_in_delta":1968,"sequence":187728,"symbol":"FCEU SI 20260615 PS"}
{"ts_recv":"2026-04-07T03:22:37.835347322Z","hd":{"ts_event":"2026-04-07T03:22:37.835328771Z","rtype":160,"publisher_id":101,"instrument_id":436},"action":"A","side":"B","price":"1.156720000","size":30,"channel_id":23,"order_id":"10998904194690110491","flags":0,"ts_in_delta":1968,"sequence":187728,"symbol":"FCEU SI 20260615 PS"}
{"ts_recv":"2026-04-07T03:22:37.835347322Z","hd":{"ts_event":"2026-04-07T03:22:37.835328771Z","rtype":160,"publisher_id":101,"instrument_id":436},"action":"C","side":"A","price":"1.156810000","size":30,"channel_id":23,"order_id":"1775532157835225791","flags":0,"ts_in_delta":1968,"sequence":187728,"symbol":"FCEU SI 20260615 PS"}
{"ts_recv":"2026-04-07T03:22:37.835347322Z","hd":{"ts_event":"2026-04-07T03:22:37.835328771Z","rtype":160,"publisher_id":101,"instrument_id":436},"action":"A","side":"A","price":"1.156820000","size":30,"channel_id":23,"order_id":"1775532157835334683","flags":128,"ts_in_delta":1968,"sequence":187728,"symbol":"FCEU SI 20260615 PS"}
{"ts_recv":"2026-04-07T03:22:37.839908749Z","hd":{"ts_event":"2026-04-07T03:22:37.839888887Z","rtype":160,"publisher_id":101,"instrument_id":436},"action":"C","side":"B","price":"1.156720000","size":30,"channel_id":23,"order_id":"10998904194690110491","flags":0,"ts_in_delta":970,"sequence":187731,"symbol":"FCEU SI 20260615 PS"}
{"ts_recv":"2026-04-07T03:22:37.839908749Z","hd":{"ts_event":"2026-04-07T03:22:37.839888887Z","rtype":160,"publisher_id":101,"instrument_id":436},"action":"A","side":"B","price":"1.156730000","size":30,"channel_id":23,"order_id":"10998904194694670700","flags":0,"ts_in_delta":970,"sequence":187731,"symbol":"FCEU SI 20260615 PS"}
{"ts_recv":"2026-04-07T03:22:37.839908749Z","hd":{"ts_event":"2026-04-07T03:22:37.839888887Z","rtype":160,"publisher_id":101,"instrument_id":436},"action":"C","side":"A","price":"1.156820000","size":30,"channel_id":23,"order_id":"1775532157835334683","flags":0,"ts_in_delta":970,"sequence":187731,"symbol":"FCEU SI 20260615 PS"}
{"ts_recv":"2026-04-07T03:22:37.839908749Z","hd":{"ts_event":"2026-04-07T03:22:37.839888887Z","rtype":160,"publisher_id":101,"instrument_id":436},"action":"A","side":"A","price":"1.156830000","size":30,"channel_id":23,"order_id":"1775532157839894892","flags":128,"ts_in_delta":970,"sequence":187731,"symbol":"FCEU SI 20260615 PS"}
{"ts_recv":"2026-04-07T03:22:37.844717714Z","hd":{"ts_event":"2026-04-07T03:22:37.844700053Z","rtype":160,"publisher_id":101,"instrument_id":436},"action":"C","side":"B","price":"1.156730000","size":30,"channel_id":23,"order_id":"10998904194694670700","flags":0,"ts_in_delta":1131,"sequence":187736,"symbol":"FCEU SI 20260615 PS"}
{"ts_recv":"2026-04-07T03:22:37.844717714Z","hd":{"ts_event":"2026-04-07T03:22:37.844700053Z","rtype":160,"publisher_id":101,"instrument_id":436},"action":"A","side":"B","price":"1.156720000","size":30,"channel_id":23,"order_id":"10998904194699481864","flags":0,"ts_in_delta":1131,"sequence":187736,"symbol":"FCEU SI 20260615 PS"}
{"ts_recv":"2026-04-07T03:22:37.844717714Z","hd":{"ts_event":"2026-04-07T03:22:37.844700053Z","rtype":160,"publisher_id":101,"instrument_id":436},"action":"C","side":"A","price":"1.156830000","size":30,"channel_id":23,"order_id":"1775532157839894892","flags":0,"ts_in_delta":1131,"sequence":187736,"symbol":"FCEU SI 20260615 PS"}
{"ts_recv":"2026-04-07T03:22:37.844717714Z","hd":{"ts_event":"2026-04-07T03:22:37.844700053Z","rtype":160,"publisher_id":101,"instrument_id":436},"action":"A","side":"A","price":"1.156820000","size":30,"channel_id":23,"order_id":"1775532157844706056","flags":128,"ts_in_delta":1131,"sequence":187736,"symbol":"FCEU SI 20260615 PS"}
{"ts_recv":"2026-04-07T03:22:37.849704232Z","hd":{"ts_event":"2026-04-07T03:22:37.849684467Z","rtype":160,"publisher_id":101,"instrument_id":436},"action":"C","side":"B","price":"1.156720000","size":30,"channel_id":23,"order_id":"10998904194699481864","flags":0,"ts_in_delta":1156,"sequence":187740,"symbol":"FCEU SI 20260615 PS"}
{"ts_recv":"2026-04-07T03:22:37.849704232Z","hd":{"ts_event":"2026-04-07T03:22:37.849684467Z","rtype":160,"publisher_id":101,"instrument_id":436},"action":"A","side":"B","price":"1.156710000","size":30,"channel_id":23,"order_id":"10998904194704465986","flags":0,"ts_in_delta":1156,"sequence":187740,"symbol":"FCEU SI 20260615 PS"}
{"ts_recv":"2026-04-07T03:22:37.849704232Z","hd":{"ts_event":"2026-04-07T03:22:37.849684467Z","rtype":160,"publisher_id":101,"instrument_id":436},"action":"C","side":"A","price":"1.156820000","size":30,"channel_id":23,"order_id":"1775532157844706056","flags":0,"ts_in_delta":1156,"sequence":187740,"symbol":"FCEU SI 20260615 PS"}
{"ts_recv":"2026-04-07T03:22:37.849704232Z","hd":{"ts_event":"2026-04-07T03:22:37.849684467Z","rtype":160,"publisher_id":101,"instrument_id":436},"action":"A","side":"A","price":"1.156810000","size":30,"channel_id":23,"order_id":"1775532157849690178","flags":128,"ts_in_delta":1156,"sequence":187740,"symbol":"FCEU SI 20260615 PS"}
{"ts_recv":"2026-04-07T03:22:37.849785736Z","hd":{"ts_event":"2026-04-07T03:22:37.849766623Z","rtype":160,"publisher_id":101,"instrument_id":436},"action":"C","side":"B","price":"1.156710000","size":30,"channel_id":23,"order_id":"10998904194704465986","flags":0,"ts_in_delta":873,"sequence":187741,"symbol":"FCEU SI 20260615 PS"}
{"ts_recv":"2026-04-07T03:22:37.849785736Z","hd":{"ts_event":"2026-04-07T03:22:37.849766623Z","rtype":160,"publisher_id":101,"instrument_id":436},"action":"A","side":"B","price":"1.156700000","size":30,"channel_id":23,"order_id":"10998904194704548511","flags":0,"ts_in_delta":873,"sequence":187741,"symbol":"FCEU SI 20260615 PS"}
{"ts_recv":"2026-04-07T03:22:37.849785736Z","hd":{"ts_event":"2026-04-07T03:22:37.849766623Z","rtype":160,"publisher_id":101,"instrument_id":436},"action":"C","side":"A","price":"1.156810000","size":30,"channel_id":23,"order_id":"1775532157849690178","flags":0,"ts_in_delta":873,"sequence":187741,"symbol":"FCEU SI 20260615 PS"}
{"ts_recv":"2026-04-07T03:22:37.849785736Z","hd":{"ts_event":"2026-04-07T03:22:37.849766623Z","rtype":160,"publisher_id":101,"instrument_id":436},"action":"A","side":"A","price":"1.156800000","size":30,"channel_id":23,"order_id":"1775532157849772703","flags":128,"ts_in_delta":873,"sequence":187741,"symbol":"FCEU SI 20260615 PS"}
{"ts_recv":"2026-04-07T03:22:37.849839286Z","hd":{"ts_event":"2026-04-07T03:22:37.849824783Z","rtype":160,"publisher_id":101,"instrument_id":436},"action":"C","side":"B","price":"1.156700000","size":30,"channel_id":23,"order_id":"10998904194704548511","flags":0,"ts_in_delta":896,"sequence":187742,"symbol":"FCEU SI 20260615 PS"}
{"ts_recv":"2026-04-07T03:22:37.849839286Z","hd":{"ts_event":"2026-04-07T03:22:37.849824783Z","rtype":160,"publisher_id":101,"instrument_id":436},"action":"A","side":"B","price":"1.156710000","size":30,"channel_id":23,"order_id":"10998904194704606265","flags":0,"ts_in_delta":896,"sequence":187742,"symbol":"FCEU SI 20260615 PS"}
{"ts_recv":"2026-04-07T03:22:37.849839286Z","hd":{"ts_event":"2026-04-07T03:22:37.849824783Z","rtype":160,"publisher_id":101,"instrument_id":436},"action":"C","side":"A","price":"1.156800000","size":30,"channel_id":23,"order_id":"1775532157849772703","flags":0,"ts_in_delta":896,"sequence":187742,"symbol":"FCEU SI 20260615 PS"}
{"ts_recv":"2026-04-07T03:22:37.849839286Z","hd":{"ts_event":"2026-04-07T03:22:37.849824783Z","rtype":160,"publisher_id":101,"instrument_id":436},"action":"A","side":"A","price":"1.156810000","size":30,"channel_id":23,"order_id":"1775532157849830457","flags":128,"ts_in_delta":896,"sequence":187742,"symbol":"FCEU SI 20260615 PS"}
{"ts_recv":"2026-04-07T03:22:39.354858594Z","hd":{"ts_event":"2026-04-07T03:22:39.354841005Z","rtype":160,"publisher_id":101,"instrument_id":436},"action":"C","side":"B","price":"1.156710000","size":30,"channel_id":23,"order_id":"10998904194704606265","flags":0,"ts_in_delta":992,"sequence":187789,"symbol":"FCEU SI 20260615 PS"}
{"ts_recv":"2026-04-07T03:22:39.354858594Z","hd":{"ts_event":"2026-04-07T03:22:39.354841005Z","rtype":160,"publisher_id":101,"instrument_id":436},"action":"A","side":"B","price":"1.156720000","size":30,"channel_id":23,"order_id":"10998904196209623052","flags":0,"ts_in_delta":992,"sequence":187789,"symbol":"FCEU SI 20260615 PS"}
{"ts_recv":"2026-04-07T03:22:39.354858594Z","hd":{"ts_event":"2026-04-07T03:22:39.354841005Z","rtype":160,"publisher_id":101,"instrument_id":436},"action":"C","side":"A","price":"1.156810000","size":30,"channel_id":23,"order_id":"1775532157849830457","flags":0,"ts_in_delta":992,"sequence":187789,"symbol":"FCEU SI 20260615 PS"}
{"ts_recv":"2026-04-07T03:22:39.354858594Z","hd":{"ts_event":"2026-04-07T03:22:39.354841005Z","rtype":160,"publisher_id":101,"instrument_id":436},"action":"A","side":"A","price":"1.156820000","size":30,"channel_id":23,"order_id":"1775532159354847244","flags":128,"ts_in_delta":992,"sequence":187789,"symbol":"FCEU SI 20260615 PS"}
{"ts_recv":"2026-04-07T03:22:47.249601251Z","hd":{"ts_event":"2026-04-07T03:22:47.249569019Z","rtype":160,"publisher_id":101,"instrument_id":436},"action":"C","side":"B","price":"1.156720000","size":30,"channel_id":23,"order_id":"10998904196209623052","flags":0,"ts_in_delta":1478,"sequence":187841,"symbol":"FCEU SI 20260615 PS"}
{"ts_recv":"2026-04-07T03:22:47.249601251Z","hd":{"ts_event":"2026-04-07T03:22:47.249569019Z","rtype":160,"publisher_id":101,"instrument_id":436},"action":"A","side":"B","price":"1.156710000","size":30,"channel_id":23,"order_id":"10998904204104358117","flags":0,"ts_in_delta":1478,"sequence":187841,"symbol":"FCEU SI 20260615 PS"}
{"ts_recv":"2026-04-07T03:22:47.249601251Z","hd":{"ts_event":"2026-04-07T03:22:47.249569019Z","rtype":160,"publisher_id":101,"instrument_id":436},"action":"C","side":"A","price":"1.156820000","size":30,"channel_id":23,"order_id":"1775532159354847244","flags":0,"ts_in_delta":1478,"sequence":187841,"symbol":"FCEU SI 20260615 PS"}
{"ts_recv":"2026-04-07T03:22:47.249601251Z","hd":{"ts_event":"2026-04-07T03:22:47.249569019Z","rtype":160,"publisher_id":101,"instrument_id":436},"action":"A","side":"A","price":"1.156810000","size":30,"channel_id":23,"order_id":"1775532167249582309","flags":128,"ts_in_delta":1478,"sequence":187841,"symbol":"FCEU SI 20260615 PS"}
{"ts_recv":"2026-04-07T03:22:47.249706409Z","hd":{"ts_event":"2026-04-07T03:22:47.249685225Z","rtype":160,"publisher_id":101,"instrument_id":436},"action":"C","side":"B","price":"1.156710000","size":30,"channel_id":23,"order_id":"10998904204104358117","flags":0,"ts_in_delta":1061,"sequence":187843,"symbol":"FCEU SI 20260615 PS"}
{"ts_recv":"2026-04-07T03:22:47.249706409Z","hd":{"ts_event":"2026-04-07T03:22:47.249685225Z","rtype":160,"publisher_id":101,"instrument_id":436},"action":"A","side":"B","price":"1.156700000","size":30,"channel_id":23,"order_id":"10998904204104466980","flags":0,"ts_in_delta":1061,"sequence":187843,"symbol":"FCEU SI 20260615 PS"}
{"ts_recv":"2026-04-07T03:22:47.249706409Z","hd":{"ts_event":"2026-04-07T03:22:47.249685225Z","rtype":160,"publisher_id":101,"instrument_id":436},"action":"C","side":"A","price":"1.156810000","size":30,"channel_id":23,"order_id":"1775532167249582309","flags":0,"ts_in_delta":1061,"sequence":187843,"symbol":"FCEU SI 20260615 PS"}
{"ts_recv":"2026-04-07T03:22:47.249706409Z","hd":{"ts_event":"2026-04-07T03:22:47.249685225Z","rtype":160,"publisher_id":101,"instrument_id":436},"action":"A","side":"A","price":"1.156800000","size":30,"channel_id":23,"order_id":"1775532167249691172","flags":128,"ts_in_delta":1061,"sequence":187843,"symbol":"FCEU SI 20260615 PS"}
{"ts_recv":"2026-04-07T03:22:47.249764744Z","hd":{"ts_event":"2026-04-07T03:22:47.249743593Z","rtype":160,"publisher_id":101,"instrument_id":436},"action":"C","side":"B","price":"1.156720000","size":30,"channel_id":23,"order_id":"10998904194690055850","flags":0,"ts_in_delta":1072,"sequence":187844,"symbol":"FCEU SI 20260615 PS"}
{"ts_recv":"2026-04-07T03:22:47.249764744Z","hd":{"ts_event":"2026-04-07T03:22:47.249743593Z","rtype":160,"publisher_id":101,"instrument_id":436},"action":"A","side":"B","price":"1.156700000","size":30,"channel_id":23,"order_id":"10998904204104525760","flags":0,"ts_in_delta":1072,"sequence":187844,"symbol":"FCEU SI 20260615 PS"}
{"ts_recv":"2026-04-07T03:22:47.249764744Z","hd":{"ts_event":"2026-04-07T03:22:47.249743593Z","rtype":160,"publisher_id":101,"instrument_id":436},"action":"C","side":"A","price":"1.156820000","size":30,"channel_id":23,"order_id":"1775532157835280042","flags":0,"ts_in_delta":1072,"sequence":187844,"symbol":"FCEU SI 20260615 PS"}
{"ts_recv":"2026-04-07T03:22:47.249764744Z","hd":{"ts_event":"2026-04-07T03:22:47.249743593Z","rtype":160,"publisher_id":101,"instrument_id":436},"action":"A","side":"A","price":"1.156800000","size":30,"channel_id":23,"order_id":"1775532167249749952","flags":128,"ts_in_delta":1072,"sequence":187844,"symbol":"FCEU SI 20260615 PS"}
{"ts_recv":"2026-04-07T03:22:47.249774589Z","hd":{"ts_event":"2026-04-07T03:22:47.249754321Z","rtype":160,"publisher_id":101,"instrument_id":436},"action":"C","side":"B","price":"1.156700000","size":30,"channel_id":23,"order_id":"10998904204104466980","flags":0,"ts_in_delta":1022,"sequence":187845,"symbol":"FCEU SI 20260615 PS"}
{"ts_recv":"2026-04-07T03:22:47.249774589Z","hd":{"ts_event":"2026-04-07T03:22:47.249754321Z","rtype":160,"publisher_id":101,"instrument_id":436},"action":"A","side":"B","price":"1.156710000","size":30,"channel_id":23,"order_id":"10998904204104537243","flags":0,"ts_in_delta":1022,"sequence":187845,"symbol":"FCEU SI 20260615 PS"}
{"ts_recv":"2026-04-07T03:22:47.249774589Z","hd":{"ts_event":"2026-04-07T03:22:47.249754321Z","rtype":160,"publisher_id":101,"instrument_id":436},"action":"C","side":"A","price":"1.156800000","size":30,"channel_id":23,"order_id":"1775532167249691172","flags":0,"ts_in_delta":1022,"sequence":187845,"symbol":"FCEU SI 20260615 PS"}
{"ts_recv":"2026-04-07T03:22:47.249774589Z","hd":{"ts_event":"2026-04-07T03:22:47.249754321Z","rtype":160,"publisher_id":101,"instrument_id":436},"action":"A","side":"A","price":"1.156810000","size":30,"channel_id":23,"order_id":"1775532167249761435","flags":128,"ts_in_delta":1022,"sequence":187845,"symbol":"FCEU SI 20260615 PS"}
{"ts_recv":"2026-04-07T03:22:47.249832002Z","hd":{"ts_event":"2026-04-07T03:22:47.249816715Z","rtype":160,"publisher_id":101,"instrument_id":436},"action":"C","side":"B","price":"1.156710000","size":30,"channel_id":23,"order_id":"10998904204104537243","flags":0,"ts_in_delta":993,"sequence":187846,"symbol":"FCEU SI 20260615 PS"}
{"ts_recv":"2026-04-07T03:22:47.249832002Z","hd":{"ts_event":"2026-04-07T03:22:47.249816715Z","rtype":160,"publisher_id":101,"instrument_id":436},"action":"A","side":"B","price":"1.156700000","size":30,"channel_id":23,"order_id":"10998904204104598308","flags":0,"ts_in_delta":993,"sequence":187846,"symbol":"FCEU SI 20260615 PS"}
{"ts_recv":"2026-04-07T03:22:47.249832002Z","hd":{"ts_event":"2026-04-07T03:22:47.249816715Z","rtype":160,"publisher_id":101,"instrument_id":436},"action":"C","side":"A","price":"1.156810000","size":30,"channel_id":23,"order_id":"1775532167249761435","flags":0,"ts_in_delta":993,"sequence":187846,"symbol":"FCEU SI 20260615 PS"}
{"ts_recv":"2026-04-07T03:22:47.249832002Z","hd":{"ts_event":"2026-04-07T03:22:47.249816715Z","rtype":160,"publisher_id":101,"instrument_id":436},"action":"A","side":"A","price":"1.156800000","size":30,"channel_id":23,"order_id":"1775532167249822500","flags":128,"ts_in_delta":993,"sequence":187846,"symbol":"FCEU SI 20260615 PS"}
{"ts_recv":"2026-04-07T03:22:47.456083172Z","hd":{"ts_event":"2026-04-07T03:22:47.456056311Z","rtype":160,"publisher_id":101,"instrument_id":436},"action":"C","side":"B","price":"1.156700000","size":30,"channel_id":23,"order_id":"10998904204104598308","flags":0,"ts_in_delta":1454,"sequence":187854,"symbol":"FCEU SI 20260615 PS"}
{"ts_recv":"2026-04-07T03:22:47.456083172Z","hd":{"ts_event":"2026-04-07T03:22:47.456056311Z","rtype":160,"publisher_id":101,"instrument_id":436},"action":"A","side":"B","price":"1.156710000","size":30,"channel_id":23,"order_id":"10998904204310842275","flags":0,"ts_in_delta":1454,"sequence":187854,"symbol":"FCEU SI 20260615 PS"}
{"ts_recv":"2026-04-07T03:22:47.456083172Z","hd":{"ts_event":"2026-04-07T03:22:47.456056311Z","rtype":160,"publisher_id":101,"instrument_id":436},"action":"C","side":"A","price":"1.156800000","size":30,"channel_id":23,"order_id":"1775532167249822500","flags":0,"ts_in_delta":1454,"sequence":187854,"symbol":"FCEU SI 20260615 PS"}
{"ts_recv":"2026-04-07T03:22:47.456083172Z","hd":{"ts_event":"2026-04-07T03:22:47.456056311Z","rtype":160,"publisher_id":101,"instrument_id":436},"action":"A","side":"A","price":"1.156810000","size":30,"channel_id":23,"order_id":"1775532167456066467","flags":128,"ts_in_delta":1454,"sequence":187854,"symbol":"FCEU SI 20260615 PS"}
{"ts_recv":"2026-04-07T03:22:57.183522901Z","hd":{"ts_event":"2026-04-07T03:22:57.183491699Z","rtype":160,"publisher_id":101,"instrument_id":436},"action":"C","side":"B","price":"1.156710000","size":30,"channel_id":23,"order_id":"10998904204310842275","flags":0,"ts_in_delta":1532,"sequence":187889,"symbol":"FCEU SI 20260615 PS"}
{"ts_recv":"2026-04-07T03:22:57.183522901Z","hd":{"ts_event":"2026-04-07T03:22:57.183491699Z","rtype":160,"publisher_id":101,"instrument_id":436},"action":"A","side":"B","price":"1.156700000","size":30,"channel_id":23,"order_id":"10998904214038280871","flags":0,"ts_in_delta":1532,"sequence":187889,"symbol":"FCEU SI 20260615 PS"}
{"ts_recv":"2026-04-07T03:22:57.183522901Z","hd":{"ts_event":"2026-04-07T03:22:57.183491699Z","rtype":160,"publisher_id":101,"instrument_id":436},"action":"C","side":"A","price":"1.156810000","size":30,"channel_id":23,"order_id":"1775532167456066467","flags":0,"ts_in_delta":1532,"sequence":187889,"symbol":"FCEU SI 20260615 PS"}
{"ts_recv":"2026-04-07T03:22:57.183522901Z","hd":{"ts_event":"2026-04-07T03:22:57.183491699Z","rtype":160,"publisher_id":101,"instrument_id":436},"action":"A","side":"A","price":"1.156800000","size":30,"channel_id":23,"order_id":"1775532177183505063","flags":128,"ts_in_delta":1532,"sequence":187889,"symbol":"FCEU SI 20260615 PS"}
{"ts_recv":"2026-04-07T03:23:03.681601368Z","hd":{"ts_event":"2026-04-07T03:23:03.681573401Z","rtype":160,"publisher_id":101,"instrument_id":436},"action":"C","side":"B","price":"1.156700000","size":30,"channel_id":23,"order_id":"10998904214038280871","flags":0,"ts_in_delta":1203,"sequence":187910,"symbol":"FCEU SI 20260615 PS"}
{"ts_recv":"2026-04-07T03:23:03.681601368Z","hd":{"ts_event":"2026-04-07T03:23:03.681573401Z","rtype":160,"publisher_id":101,"instrument_id":436},"action":"A","side":"B","price":"1.156710000","size":30,"channel_id":23,"order_id":"10998904220536359938","flags":0,"ts_in_delta":1203,"sequence":187910,"symbol":"FCEU SI 20260615 PS"}
{"ts_recv":"2026-04-07T03:23:03.681601368Z","hd":{"ts_event":"2026-04-07T03:23:03.681573401Z","rtype":160,"publisher_id":101,"instrument_id":436},"action":"C","side":"A","price":"1.156800000","size":30,"channel_id":23,"order_id":"1775532177183505063","flags":0,"ts_in_delta":1203,"sequence":187910,"symbol":"FCEU SI 20260615 PS"}
{"ts_recv":"2026-04-07T03:23:03.681601368Z","hd":{"ts_event":"2026-04-07T03:23:03.681573401Z","rtype":160,"publisher_id":101,"instrument_id":436},"action":"A","side":"A","price":"1.156810000","size":30,"channel_id":23,"order_id":"1775532183681584130","flags":128,"ts_in_delta":1203,"sequence":187910,"symbol":"FCEU SI 20260615 PS"}
{"ts_recv":"2026-04-07T03:23:06.888437977Z","hd":{"ts_event":"2026-04-07T03:23:06.888408989Z","rtype":160,"publisher_id":101,"instrument_id":436},"action":"C","side":"B","price":"1.156710000","size":30,"channel_id":23,"order_id":"10998904220536359938","flags":0,"ts_in_delta":1260,"sequence":187929,"symbol":"FCEU SI 20260615 PS"}
{"ts_recv":"2026-04-07T03:23:06.888437977Z","hd":{"ts_event":"2026-04-07T03:23:06.888408989Z","rtype":160,"publisher_id":101,"instrument_id":436},"action":"A","side":"B","price":"1.156700000","size":30,"channel_id":23,"order_id":"10998904223743198070","flags":0,"ts_in_delta":1260,"sequence":187929,"symbol":"FCEU SI 20260615 PS"}
{"ts_recv":"2026-04-07T03:23:06.888437977Z","hd":{"ts_event":"2026-04-07T03:23:06.888408989Z","rtype":160,"publisher_id":101,"instrument_id":436},"action":"C","side":"A","price":"1.156810000","size":30,"channel_id":23,"order_id":"1775532183681584130","flags":0,"ts_in_delta":1260,"sequence":187929,"symbol":"FCEU SI 20260615 PS"}
{"ts_recv":"2026-04-07T03:23:06.888437977Z","hd":{"ts_event":"2026-04-07T03:23:06.888408989Z","rtype":160,"publisher_id":101,"instrument_id":436},"action":"A","side":"A","price":"1.156800000","size":30,"channel_id":23,"order_id":"1775532186888422262","flags":128,"ts_in_delta":1260,"sequence":187929,"symbol":"FCEU SI 20260615 PS"}
{"ts_recv":"2026-04-07T03:23:10.540405533Z","hd":{"ts_event":"2026-04-07T03:23:10.540384591Z","rtype":160,"publisher_id":101,"instrument_id":436},"action":"C","side":"B","price":"1.156700000","size":30,"channel_id":23,"order_id":"10998904223743198070","flags":0,"ts_in_delta":946,"sequence":187947,"symbol":"FCEU SI 20260615 PS"}
{"ts_recv":"2026-04-07T03:23:10.540405533Z","hd":{"ts_event":"2026-04-07T03:23:10.540384591Z","rtype":160,"publisher_id":101,"instrument_id":436},"action":"A","side":"B","price":"1.156690000","size":30,"channel_id":23,"order_id":"10998904227395166542","flags":0,"ts_in_delta":946,"sequence":187947,"symbol":"FCEU SI 20260615 PS"}
{"ts_recv":"2026-04-07T03:23:10.540405533Z","hd":{"ts_event":"2026-04-07T03:23:10.540384591Z","rtype":160,"publisher_id":101,"instrument_id":436},"action":"C","side":"A","price":"1.156800000","size":30,"channel_id":23,"order_id":"1775532186888422262","flags":0,"ts_in_delta":946,"sequence":187947,"symbol":"FCEU SI 20260615 PS"}
{"ts_recv":"2026-04-07T03:23:10.540405533Z","hd":{"ts_event":"2026-04-07T03:23:10.540384591Z","rtype":160,"publisher_id":101,"instrument_id":436},"action":"A","side":"A","price":"1.156790000","size":30,"channel_id":23,"order_id":"1775532190540390734","flags":128,"ts_in_delta":946,"sequence":187947,"symbol":"FCEU SI 20260615 PS"}
{"ts_recv":"2026-04-07T03:23:14.359614485Z","hd":{"ts_event":"2026-04-07T03:23:14.359592193Z","rtype":160,"publisher_id":101,"instrument_id":436},"action":"C","side":"B","price":"1.156700000","size":30,"channel_id":23,"order_id":"10998904204104525760","flags":0,"ts_in_delta":965,"sequence":188007,"symbol":"FCEU SI 20260615 PS"}
{"ts_recv":"2026-04-07T03:23:14.359614485Z","hd":{"ts_event":"2026-04-07T03:23:14.359592193Z","rtype":160,"publisher_id":101,"instrument_id":436},"action":"A","side":"B","price":"1.156680000","size":30,"channel_id":23,"order_id":"10998904231214374072","flags":0,"ts_in_delta":965,"sequence":188007,"symbol":"FCEU SI 20260615 PS"}
{"ts_recv":"2026-04-07T03:23:14.359614485Z","hd":{"ts_event":"2026-04-07T03:23:14.359592193Z","rtype":160,"publisher_id":101,"instrument_id":436},"action":"C","side":"A","price":"1.156800000","size":30,"channel_id":23,"order_id":"1775532167249749952","flags":0,"ts_in_delta":965,"sequence":188007,"symbol":"FCEU SI 20260615 PS"}
{"ts_recv":"2026-04-07T03:23:14.359614485Z","hd":{"ts_event":"2026-04-07T03:23:14.359592193Z","rtype":160,"publisher_id":101,"instrument_id":436},"action":"A","side":"A","price":"1.156780000","size":30,"channel_id":23,"order_id":"1775532194359598264","flags":128,"ts_in_delta":965,"sequence":188007,"symbol":"FCEU SI 20260615 PS"}
{"ts_recv":"2026-04-07T03:23:14.359685022Z","hd":{"ts_event":"2026-04-07T03:23:14.359666451Z","rtype":160,"publisher_id":101,"instrument_id":436},"action":"C","side":"B","price":"1.156690000","size":30,"channel_id":23,"order_id":"10998904227395166542","flags":0,"ts_in_delta":966,"sequence":188008,"symbol":"FCEU SI 20260615 PS"}
{"ts_recv":"2026-04-07T03:23:14.359685022Z","hd":{"ts_event":"2026-04-07T03:23:14.359666451Z","rtype":160,"publisher_id":101,"instrument_id":436},"action":"A","side":"B","price":"1.156680000","size":30,"channel_id":23,"order_id":"10998904231214448342","flags":0,"ts_in_delta":966,"sequence":188008,"symbol":"FCEU SI 20260615 PS"}
{"ts_recv":"2026-04-07T03:23:14.359685022Z","hd":{"ts_event":"2026-04-07T03:23:14.359666451Z","rtype":160,"publisher_id":101,"instrument_id":436},"action":"C","side":"A","price":"1.156790000","size":30,"channel_id":23,"order_id":"1775532190540390734","flags":0,"ts_in_delta":966,"sequence":188008,"symbol":"FCEU SI 20260615 PS"}
{"ts_recv":"2026-04-07T03:23:14.359685022Z","hd":{"ts_event":"2026-04-07T03:23:14.359666451Z","rtype":160,"publisher_id":101,"instrument_id":436},"action":"A","side":"A","price":"1.156780000","size":30,"channel_id":23,"order_id":"1775532194359672534","flags":128,"ts_in_delta":966,"sequence":188008,"symbol":"FCEU SI 20260615 PS"}
{"ts_recv":"2026-04-07T03:23:15.545607691Z","hd":{"ts_event":"2026-04-07T03:23:15.545587147Z","rtype":160,"publisher_id":101,"instrument_id":436},"action":"C","side":"B","price":"1.156680000","size":30,"channel_id":23,"order_id":"10998904231214448342","flags":0,"ts_in_delta":1048,"sequence":188022,"symbol":"FCEU SI 20260615 PS"}
{"ts_recv":"2026-04-07T03:23:15.545607691Z","hd":{"ts_event":"2026-04-07T03:23:15.545587147Z","rtype":160,"publisher_id":101,"instrument_id":436},"action":"A","side":"B","price":"1.156690000","size":30,"channel_id":23,"order_id":"10998904232400368952","flags":0,"ts_in_delta":1048,"sequence":188022,"symbol":"FCEU SI 20260615 PS"}
{"ts_recv":"2026-04-07T03:23:15.545607691Z","hd":{"ts_event":"2026-04-07T03:23:15.545587147Z","rtype":160,"publisher_id":101,"instrument_id":436},"action":"C","side":"A","price":"1.156780000","size":30,"channel_id":23,"order_id":"1775532194359672534","flags":0,"ts_in_delta":1048,"sequence":188022,"symbol":"FCEU SI 20260615 PS"}
{"ts_recv":"2026-04-07T03:23:15.545607691Z","hd":{"ts_event":"2026-04-07T03:23:15.545587147Z","rtype":160,"publisher_id":101,"instrument_id":436},"action":"A","side":"A","price":"1.156790000","size":30,"channel_id":23,"order_id":"1775532195545593144","flags":128,"ts_in_delta":1048,"sequence":188022,"symbol":"FCEU SI 20260615 PS"}
{"ts_recv":"2026-04-07T03:23:15.545689679Z","hd":{"ts_event":"2026-04-07T03:23:15.545671975Z","rtype":160,"publisher_id":101,"instrument_id":436},"action":"C","side":"B","price":"1.156690000","size":30,"channel_id":23,"order_id":"10998904232400368952","flags":0,"ts_in_delta":955,"sequence":188023,"symbol":"FCEU SI 20260615 PS"}
{"ts_recv":"2026-04-07T03:23:15.545689679Z","hd":{"ts_event":"2026-04-07T03:23:15.545671975Z","rtype":160,"publisher_id":101,"instrument_id":436},"action":"A","side":"B","price":"1.156700000","size":30,"channel_id":23,"order_id":"10998904232400453839","flags":0,"ts_in_delta":955,"sequence":188023,"symbol":"FCEU SI 20260615 PS"}
{"ts_recv":"2026-04-07T03:23:15.545689679Z","hd":{"ts_event":"2026-04-07T03:23:15.545671975Z","rtype":160,"publisher_id":101,"instrument_id":436},"action":"C","side":"A","price":"1.156790000","size":30,"channel_id":23,"order_id":"1775532195545593144","flags":0,"ts_in_delta":955,"sequence":188023,"symbol":"FCEU SI 20260615 PS"}
{"ts_recv":"2026-04-07T03:23:15.545689679Z","hd":{"ts_event":"2026-04-07T03:23:15.545671975Z","rtype":160,"publisher_id":101,"instrument_id":436},"action":"A","side":"A","price":"1.156800000","size":30,"channel_id":23,"order_id":"1775532195545678031","flags":128,"ts_in_delta":955,"sequence":188023,"symbol":"FCEU SI 20260615 PS"}
{"ts_recv":"2026-04-07T03:23:15.545739481Z","hd":{"ts_event":"2026-04-07T03:23:15.545723163Z","rtype":160,"publisher_id":101,"instrument_id":436},"action":"C","side":"B","price":"1.156680000","size":30,"channel_id":23,"order_id":"10998904231214374072","flags":0,"ts_in_delta":968,"sequence":188024,"symbol":"FCEU SI 20260615 PS"}
{"ts_recv":"2026-04-07T03:23:15.545739481Z","hd":{"ts_event":"2026-04-07T03:23:15.545723163Z","rtype":160,"publisher_id":101,"instrument_id":436},"action":"A","side":"B","price":"1.156700000","size":30,"channel_id":23,"order_id":"10998904232400505132","flags":0,"ts_in_delta":968,"sequence":188024,"symbol":"FCEU SI 20260615 PS"}
{"ts_recv":"2026-04-07T03:23:15.545739481Z","hd":{"ts_event":"2026-04-07T03:23:15.545723163Z","rtype":160,"publisher_id":101,"instrument_id":436},"action":"C","side":"A","price":"1.156780000","size":30,"channel_id":23,"order_id":"1775532194359598264","flags":0,"ts_in_delta":968,"sequence":188024,"symbol":"FCEU SI 20260615 PS"}
{"ts_recv":"2026-04-07T03:23:15.545739481Z","hd":{"ts_event":"2026-04-07T03:23:15.545723163Z","rtype":160,"publisher_id":101,"instrument_id":436},"action":"A","side":"A","price":"1.156800000","size":30,"channel_id":23,"order_id":"1775532195545729324","flags":128,"ts_in_delta":968,"sequence":188024,"symbol":"FCEU SI 20260615 PS"}
{"ts_recv":"2026-04-07T03:23:15.545751500Z","hd":{"ts_event":"2026-04-07T03:23:15.545731689Z","rtype":160,"publisher_id":101,"instrument_id":436},"action":"C","side":"B","price":"1.156700000","size":30,"channel_id":23,"order_id":"10998904232400453839","flags":0,"ts_in_delta":928,"sequence":188025,"symbol":"FCEU SI 20260615 PS"}
{"ts_recv":"2026-04-07T03:23:15.545751500Z","hd":{"ts_event":"2026-04-07T03:23:15.545731689Z","rtype":160,"publisher_id":101,"instrument_id":436},"action":"A","side":"B","price":"1.156690000","size":30,"channel_id":23,"order_id":"10998904232400513110","flags":0,"ts_in_delta":928,"sequence":188025,"symbol":"FCEU SI 20260615 PS"}
{"ts_recv":"2026-04-07T03:23:15.545751500Z","hd":{"ts_event":"2026-04-07T03:23:15.545731689Z","rtype":160,"publisher_id":101,"instrument_id":436},"action":"C","side":"A","price":"1.156800000","size":30,"channel_id":23,"order_id":"1775532195545678031","flags":0,"ts_in_delta":928,"sequence":188025,"symbol":"FCEU SI 20260615 PS"}
{"ts_recv":"2026-04-07T03:23:15.545751500Z","hd":{"ts_event":"2026-04-07T03:23:15.545731689Z","rtype":160,"publisher_id":101,"instrument_id":436},"action":"A","side":"A","price":"1.156790000","size":30,"channel_id":23,"order_id":"1775532195545737302","flags":128,"ts_in_delta":928,"sequence":188025,"symbol":"FCEU SI 20260615 PS"}
{"ts_recv":"2026-04-07T03:23:15.545806371Z","hd":{"ts_event":"2026-04-07T03:23:15.545789249Z","rtype":160,"publisher_id":101,"instrument_id":436},"action":"C","side":"B","price":"1.156690000","size":30,"channel_id":23,"order_id":"10998904232400513110","flags":0,"ts_in_delta":962,"sequence":188026,"symbol":"FCEU SI 20260615 PS"}
{"ts_recv":"2026-04-07T03:23:15.545806371Z","hd":{"ts_event":"2026-04-07T03:23:15.545789249Z","rtype":160,"publisher_id":101,"instrument_id":436},"action":"A","side":"B","price":"1.156700000","size":30,"channel_id":23,"order_id":"10998904232400571402","flags":0,"ts_in_delta":962,"sequence":188026,"symbol":"FCEU SI 20260615 PS"}
{"ts_recv":"2026-04-07T03:23:15.545806371Z","hd":{"ts_event":"2026-04-07T03:23:15.545789249Z","rtype":160,"publisher_id":101,"instrument_id":436},"action":"C","side":"A","price":"1.156790000","size":30,"channel_id":23,"order_id":"1775532195545737302","flags":0,"ts_in_delta":962,"sequence":188026,"symbol":"FCEU SI 20260615 PS"}
{"ts_recv":"2026-04-07T03:23:15.545806371Z","hd":{"ts_event":"2026-04-07T03:23:15.545789249Z","rtype":160,"publisher_id":101,"instrument_id":436},"action":"A","side":"A","price":"1.156800000","size":30,"channel_id":23,"order_id":"1775532195545795594","flags":128,"ts_in_delta":962,"sequence":188026,"symbol":"FCEU SI 20260615 PS"}
{"ts_recv":"2026-04-07T03:23:30.233753381Z","hd":{"ts_event":"2026-04-07T03:23:30.233721811Z","rtype":160,"publisher_id":101,"instrument_id":436},"action":"C","side":"B","price":"1.156700000","size":30,"channel_id":23,"order_id":"10998904232400571402","flags":0,"ts_in_delta":1302,"sequence":188111,"symbol":"FCEU SI 20260615 PS"}
{"ts_recv":"2026-04-07T03:23:30.233753381Z","hd":{"ts_event":"2026-04-07T03:23:30.233721811Z","rtype":160,"publisher_id":101,"instrument_id":436},"action":"A","side":"B","price":"1.156690000","size":30,"channel_id":23,"order_id":"10998904247088508524","flags":0,"ts_in_delta":1302,"sequence":188111,"symbol":"FCEU SI 20260615 PS"}
{"ts_recv":"2026-04-07T03:23:30.233753381Z","hd":{"ts_event":"2026-04-07T03:23:30.233721811Z","rtype":160,"publisher_id":101,"instrument_id":436},"action":"C","side":"A","price":"1.156800000","size":30,"channel_id":23,"order_id":"1775532195545795594","flags":0,"ts_in_delta":1302,"sequence":188111,"symbol":"FCEU SI 20260615 PS"}
{"ts_recv":"2026-04-07T03:23:30.233753381Z","hd":{"ts_event":"2026-04-07T03:23:30.233721811Z","rtype":160,"publisher_id":101,"instrument_id":436},"action":"A","side":"A","price":"1.156790000","size":30,"channel_id":23,"order_id":"1775532210233732716","flags":128,"ts_in_delta":1302,"sequence":188111,"symbol":"FCEU SI 20260615 PS"}
{"ts_recv":"2026-04-07T03:23:34.266836499Z","hd":{"ts_event":"2026-04-07T03:23:34.266816389Z","rtype":160,"publisher_id":101,"instrument_id":436},"action":"C","side":"B","price":"1.156700000","size":30,"channel_id":23,"order_id":"10998904232400505132","flags":0,"ts_in_delta":1232,"sequence":188148,"symbol":"FCEU SI 20260615 PS"}
{"ts_recv":"2026-04-07T03:23:34.266836499Z","hd":{"ts_event":"2026-04-07T03:23:34.266816389Z","rtype":160,"publisher_id":101,"instrument_id":436},"action":"A","side":"B","price":"1.156680000","size":30,"channel_id":23,"order_id":"10998904251121598176","flags":0,"ts_in_delta":1232,"sequence":188148,"symbol":"FCEU SI 20260615 PS"}
{"ts_recv":"2026-04-07T03:23:34.266836499Z","hd":{"ts_event":"2026-04-07T03:23:34.266816389Z","rtype":160,"publisher_id":101,"instrument_id":436},"action":"C","side":"A","price":"1.156800000","size":30,"channel_id":23,"order_id":"1775532195545729324","flags":0,"ts_in_delta":1232,"sequence":188148,"symbol":"FCEU SI 20260615 PS"}
{"ts_recv":"2026-04-07T03:23:34.266836499Z","hd":{"ts_event":"2026-04-07T03:23:34.266816389Z","rtype":160,"publisher_id":101,"instrument_id":436},"action":"A","side":"A","price":"1.156780000","size":30,"channel_id":23,"order_id":"1775532214266822368","flags":128,"ts_in_delta":1232,"sequence":188148,"symbol":"FCEU SI 20260615 PS"}
{"ts_recv":"2026-04-07T03:23:34.266908543Z","hd":{"ts_event":"2026-04-07T03:23:34.266889021Z","rtype":160,"publisher_id":101,"instrument_id":436},"action":"C","side":"B","price":"1.156690000","size":30,"channel_id":23,"order_id":"10998904247088508524","flags":0,"ts_in_delta":923,"sequence":188149,"symbol":"FCEU SI 20260615 PS"}
{"ts_recv":"2026-04-07T03:23:34.266908543Z","hd":{"ts_event":"2026-04-07T03:23:34.266889021Z","rtype":160,"publisher_id":101,"instrument_id":436},"action":"A","side":"B","price":"1.156680000","size":30,"channel_id":23,"order_id":"10998904251121670714","flags":0,"ts_in_delta":923,"sequence":188149,"symbol":"FCEU SI 20260615 PS"}
{"ts_recv":"2026-04-07T03:23:34.266908543Z","hd":{"ts_event":"2026-04-07T03:23:34.266889021Z","rtype":160,"publisher_id":101,"instrument_id":436},"action":"C","side":"A","price":"1.156790000","size":30,"channel_id":23,"order_id":"1775532210233732716","flags":0,"ts_in_delta":923,"sequence":188149,"symbol":"FCEU SI 20260615 PS"}
{"ts_recv":"2026-04-07T03:23:34.266908543Z","hd":{"ts_event":"2026-04-07T03:23:34.266889021Z","rtype":160,"publisher_id":101,"instrument_id":436},"action":"A","side":"A","price":"1.156780000","size":30,"channel_id":23,"order_id":"1775532214266894906","flags":128,"ts_in_delta":923,"sequence":188149,"symbol":"FCEU SI 20260615 PS"}
{"ts_recv":"2026-04-07T03:23:45.203999679Z","hd":{"ts_event":"2026-04-07T03:23:45.203965393Z","rtype":160,"publisher_id":101,"instrument_id":436},"action":"C","side":"B","price":"1.156680000","size":30,"channel_id":23,"order_id":"10998904251121670714","flags":0,"ts_in_delta":1215,"sequence":188207,"symbol":"FCEU SI 20260615 PS"}
{"ts_recv":"2026-04-07T03:23:45.203999679Z","hd":{"ts_event":"2026-04-07T03:23:45.203965393Z","rtype":160,"publisher_id":101,"instrument_id":436},"action":"A","side":"B","price":"1.156690000","size":30,"channel_id":23,"order_id":"10998904262058755646","flags":0,"ts_in_delta":1215,"sequence":188207,"symbol":"FCEU SI 20260615 PS"}
{"ts_recv":"2026-04-07T03:23:45.203999679Z","hd":{"ts_event":"2026-04-07T03:23:45.203965393Z","rtype":160,"publisher_id":101,"instrument_id":436},"action":"C","side":"A","price":"1.156780000","size":30,"channel_id":23,"order_id":"1775532214266894906","flags":0,"ts_in_delta":1215,"sequence":188207,"symbol":"FCEU SI 20260615 PS"}
{"ts_recv":"2026-04-07T03:23:45.203999679Z","hd":{"ts_event":"2026-04-07T03:23:45.203965393Z","rtype":160,"publisher_id":101,"instrument_id":436},"action":"A","side":"A","price":"1.156790000","size":30,"channel_id":23,"order_id":"1775532225203979838","flags":128,"ts_in_delta":1215,"sequence":188207,"symbol":"FCEU SI 20260615 PS"}
{"ts_recv":"2026-04-07T03:23:45.204055810Z","hd":{"ts_event":"2026-04-07T03:23:45.204036861Z","rtype":160,"publisher_id":101,"instrument_id":436},"action":"C","side":"B","price":"1.156680000","size":30,"channel_id":23,"order_id":"10998904251121598176","flags":0,"ts_in_delta":1032,"sequence":188208,"symbol":"FCEU SI 20260615 PS"}
{"ts_recv":"2026-04-07T03:23:45.204055810Z","hd":{"ts_event":"2026-04-07T03:23:45.204036861Z","rtype":160,"publisher_id":101,"instrument_id":436},"action":"A","side":"B","price":"1.156700000","size":30,"channel_id":23,"order_id":"10998904262058819020","flags":0,"ts_in_delta":1032,"sequence":188208,"symbol":"FCEU SI 20260615 PS"}
{"ts_recv":"2026-04-07T03:23:45.204055810Z","hd":{"ts_event":"2026-04-07T03:23:45.204036861Z","rtype":160,"publisher_id":101,"instrument_id":436},"action":"C","side":"A","price":"1.156780000","size":30,"channel_id":23,"order_id":"1775532214266822368","flags":0,"ts_in_delta":1032,"sequence":188208,"symbol":"FCEU SI 20260615 PS"}
{"ts_recv":"2026-04-07T03:23:45.204055810Z","hd":{"ts_event":"2026-04-07T03:23:45.204036861Z","rtype":160,"publisher_id":101,"instrument_id":436},"action":"A","side":"A","price":"1.156800000","size":30,"channel_id":23,"order_id":"1775532225204043212","flags":128,"ts_in_delta":1032,"sequence":188208,"symbol":"FCEU SI 20260615 PS"}
{"ts_recv":"2026-04-07T03:23:45.204114175Z","hd":{"ts_event":"2026-04-07T03:23:45.204097055Z","rtype":160,"publisher_id":101,"instrument_id":436},"action":"C","side":"B","price":"1.156690000","size":30,"channel_id":23,"order_id":"10998904262058755646","flags":0,"ts_in_delta":1143,"sequence":188209,"symbol":"FCEU SI 20260615 PS"}
{"ts_recv":"2026-04-07T03:23:45.204114175Z","hd":{"ts_event":"2026-04-07T03:23:45.204097055Z","rtype":160,"publisher_id":101,"instrument_id":436},"action":"A","side":"B","price":"1.156700000","size":30,"channel_id":23,"order_id":"10998904262058879049","flags":0,"ts_in_delta":1143,"sequence":188209,"symbol":"FCEU SI 20260615 PS"}
{"ts_recv":"2026-04-07T03:23:45.204114175Z","hd":{"ts_event":"2026-04-07T03:23:45.204097055Z","rtype":160,"publisher_id":101,"instrument_id":436},"action":"C","side":"A","price":"1.156790000","size":30,"channel_id":23,"order_id":"1775532225203979838","flags":0,"ts_in_delta":1143,"sequence":188209,"symbol":"FCEU SI 20260615 PS"}
{"ts_recv":"2026-04-07T03:23:45.204114175Z","hd":{"ts_event":"2026-04-07T03:23:45.204097055Z","rtype":160,"publisher_id":101,"instrument_id":436},"action":"A","side":"A","price":"1.156800000","size":30,"channel_id":23,"order_id":"1775532225204103241","flags":128,"ts_in_delta":1143,"sequence":188209,"symbol":"FCEU SI 20260615 PS"}
{"ts_recv":"2026-04-07T03:24:01.672981044Z","hd":{"ts_event":"2026-04-07T03:24:01.672947851Z","rtype":160,"publisher_id":101,"instrument_id":436},"action":"C","side":"B","price":"1.156700000","size":30,"channel_id":23,"order_id":"10998904262058879049","flags":0,"ts_in_delta":1161,"sequence":188307,"symbol":"FCEU SI 20260615 PS"}
{"ts_recv":"2026-04-07T03:24:01.672981044Z","hd":{"ts_event":"2026-04-07T03:24:01.672947851Z","rtype":160,"publisher_id":101,"instrument_id":436},"action":"A","side":"B","price":"1.156690000","size":30,"channel_id":23,"order_id":"10998904278527737426","flags":0,"ts_in_delta":1161,"sequence":188307,"symbol":"FCEU SI 20260615 PS"}
{"ts_recv":"2026-04-07T03:24:01.672981044Z","hd":{"ts_event":"2026-04-07T03:24:01.672947851Z","rtype":160,"publisher_id":101,"instrument_id":436},"action":"C","side":"A","price":"1.156800000","size":30,"channel_id":23,"order_id":"1775532225204103241","flags":0,"ts_in_delta":1161,"sequence":188307,"symbol":"FCEU SI 20260615 PS"}
{"ts_recv":"2026-04-07T03:24:01.672981044Z","hd":{"ts_event":"2026-04-07T03:24:01.672947851Z","rtype":160,"publisher_id":101,"instrument_id":436},"action":"A","side":"A","price":"1.156790000","size":30,"channel_id":23,"order_id":"1775532241672961618","flags":128,"ts_in_delta":1161,"sequence":188307,"symbol":"FCEU SI 20260615 PS"}
{"ts_recv":"2026-04-07T03:24:02.093840017Z","hd":{"ts_event":"2026-04-07T03:24:02.093811483Z","rtype":160,"publisher_id":101,"instrument_id":436},"action":"C","side":"B","price":"1.156690000","size":30,"channel_id":23,"order_id":"10998904278527737426","flags":0,"ts_in_delta":1519,"sequence":188312,"symbol":"FCEU SI 20260615 PS"}
{"ts_recv":"2026-04-07T03:24:02.093840017Z","hd":{"ts_event":"2026-04-07T03:24:02.093811483Z","rtype":160,"publisher_id":101,"instrument_id":436},"action":"A","side":"B","price":"1.156700000","size":30,"channel_id":23,"order_id":"10998904278948598123","flags":0,"ts_in_delta":1519,"sequence":188312,"symbol":"FCEU SI 20260615 PS"}
{"ts_recv":"2026-04-07T03:24:02.093840017Z","hd":{"ts_event":"2026-04-07T03:24:02.093811483Z","rtype":160,"publisher_id":101,"instrument_id":436},"action":"C","side":"A","price":"1.156790000","size":30,"channel_id":23,"order_id":"1775532241672961618","flags":0,"ts_in_delta":1519,"sequence":188312,"symbol":"FCEU SI 20260615 PS"}
{"ts_recv":"2026-04-07T03:24:02.093840017Z","hd":{"ts_event":"2026-04-07T03:24:02.093811483Z","rtype":160,"publisher_id":101,"instrument_id":436},"action":"A","side":"A","price":"1.156800000","size":30,"channel_id":23,"order_id":"1775532242093822315","flags":128,"ts_in_delta":1519,"sequence":188312,"symbol":"FCEU SI 20260615 PS"}
{"ts_recv":"2026-04-07T03:24:16.954970549Z","hd":{"ts_event":"2026-04-07T03:24:16.954946929Z","rtype":160,"publisher_id":101,"instrument_id":436},"action":"C","side":"B","price":"1.156700000","size":30,"channel_id":23,"order_id":"10998904278948598123","flags":0,"ts_in_delta":996,"sequence":188395,"symbol":"FCEU SI 20260615 PS"}
{"ts_recv":"2026-04-07T03:24:16.954970549Z","hd":{"ts_event":"2026-04-07T03:24:16.954946929Z","rtype":160,"publisher_id":101,"instrument_id":436},"action":"A","side":"B","price":"1.156690000","size":30,"channel_id":23,"order_id":"10998904293809729162","flags":0,"ts_in_delta":996,"sequence":188395,"symbol":"FCEU SI 20260615 PS"}
{"ts_recv":"2026-04-07T03:24:16.954970549Z","hd":{"ts_event":"2026-04-07T03:24:16.954946929Z","rtype":160,"publisher_id":101,"instrument_id":436},"action":"C","side":"A","price":"1.156800000","size":30,"channel_id":23,"order_id":"1775532242093822315","flags":0,"ts_in_delta":996,"sequence":188395,"symbol":"FCEU SI 20260615 PS"}
{"ts_recv":"2026-04-07T03:24:16.954970549Z","hd":{"ts_event":"2026-04-07T03:24:16.954946929Z","rtype":160,"publisher_id":101,"instrument_id":436},"action":"A","side":"A","price":"1.156790000","size":30,"channel_id":23,"order_id":"1775532256954953354","flags":128,"ts_in_delta":996,"sequence":188395,"symbol":"FCEU SI 20260615 PS"}
{"ts_recv":"2026-04-07T03:24:17.054658876Z","hd":{"ts_event":"2026-04-07T03:24:17.054631363Z","rtype":160,"publisher_id":101,"instrument_id":436},"action":"C","side":"B","price":"1.156700000","size":30,"channel_id":23,"order_id":"10998904262058819020","flags":0,"ts_in_delta":1258,"sequence":188396,"symbol":"FCEU SI 20260615 PS"}
{"ts_recv":"2026-04-07T03:24:17.054658876Z","hd":{"ts_event":"2026-04-07T03:24:17.054631363Z","rtype":160,"publisher_id":101,"instrument_id":436},"action":"A","side":"B","price":"1.156680000","size":30,"channel_id":23,"order_id":"10998904293909418648","flags":0,"ts_in_delta":1258,"sequence":188396,"symbol":"FCEU SI 20260615 PS"}
{"ts_recv":"2026-04-07T03:24:17.054658876Z","hd":{"ts_event":"2026-04-07T03:24:17.054631363Z","rtype":160,"publisher_id":101,"instrument_id":436},"action":"C","side":"A","price":"1.156800000","size":30,"channel_id":23,"order_id":"1775532225204043212","flags":0,"ts_in_delta":1258,"sequence":188396,"symbol":"FCEU SI 20260615 PS"}
{"ts_recv":"2026-04-07T03:24:17.054658876Z","hd":{"ts_event":"2026-04-07T03:24:17.054631363Z","rtype":160,"publisher_id":101,"instrument_id":436},"action":"A","side":"A","price":"1.156780000","size":30,"channel_id":23,"order_id":"1775532257054642840","flags":128,"ts_in_delta":1258,"sequence":188396,"symbol":"FCEU SI 20260615 PS"}
{"ts_recv":"2026-04-07T03:24:17.054726380Z","hd":{"ts_event":"2026-04-07T03:24:17.054702859Z","rtype":160,"publisher_id":101,"instrument_id":436},"action":"C","side":"B","price":"1.156690000","size":30,"channel_id":23,"order_id":"10998904293809729162","flags":0,"ts_in_delta":1275,"sequence":188397,"symbol":"FCEU SI 20260615 PS"}
{"ts_recv":"2026-04-07T03:24:17.054726380Z","hd":{"ts_event":"2026-04-07T03:24:17.054702859Z","rtype":160,"publisher_id":101,"instrument_id":436},"action":"A","side":"B","price":"1.156680000","size":30,"channel_id":23,"order_id":"10998904293909485390","flags":0,"ts_in_delta":1275,"sequence":188397,"symbol":"FCEU SI 20260615 PS"}
{"ts_recv":"2026-04-07T03:24:17.054726380Z","hd":{"ts_event":"2026-04-07T03:24:17.054702859Z","rtype":160,"publisher_id":101,"instrument_id":436},"action":"C","side":"A","price":"1.156790000","size":30,"channel_id":23,"order_id":"1775532256954953354","flags":0,"ts_in_delta":1275,"sequence":188397,"symbol":"FCEU SI 20260615 PS"}
{"ts_recv":"2026-04-07T03:24:17.054726380Z","hd":{"ts_event":"2026-04-07T03:24:17.054702859Z","rtype":160,"publisher_id":101,"instrument_id":436},"action":"A","side":"A","price":"1.156780000","size":30,"channel_id":23,"order_id":"1775532257054709582","flags":128,"ts_in_delta":1275,"sequence":188397,"symbol":"FCEU SI 20260615 PS"}
{"ts_recv":"2026-04-07T03:24:34.721892470Z","hd":{"ts_event":"2026-04-07T03:24:34.721869771Z","rtype":160,"publisher_id":101,"instrument_id":436},"action":"C","side":"B","price":"1.156680000","size":30,"channel_id":23,"order_id":"10998904293909485390","flags":0,"ts_in_delta":963,"sequence":188510,"symbol":"FCEU SI 20260615 PS"}
{"ts_recv":"2026-04-07T03:24:34.721892470Z","hd":{"ts_event":"2026-04-07T03:24:34.721869771Z","rtype":160,"publisher_id":101,"instrument_id":436},"action":"A","side":"B","price":"1.156670000","size":30,"channel_id":23,"order_id":"10998904311576651948","flags":0,"ts_in_delta":963,"sequence":188510,"symbol":"FCEU SI 20260615 PS"}
{"ts_recv":"2026-04-07T03:24:34.721892470Z","hd":{"ts_event":"2026-04-07T03:24:34.721869771Z","rtype":160,"publisher_id":101,"instrument_id":436},"action":"C","side":"A","price":"1.156780000","size":30,"channel_id":23,"order_id":"1775532257054709582","flags":0,"ts_in_delta":963,"sequence":188510,"symbol":"FCEU SI 20260615 PS"}
{"ts_recv":"2026-04-07T03:24:34.721892470Z","hd":{"ts_event":"2026-04-07T03:24:34.721869771Z","rtype":160,"publisher_id":101,"instrument_id":436},"action":"A","side":"A","price":"1.156770000","size":30,"channel_id":23,"order_id":"1775532274721876140","flags":128,"ts_in_delta":963,"sequence":188510,"symbol":"FCEU SI 20260615 PS"}
{"ts_recv":"2026-04-07T03:24:34.722175173Z","hd":{"ts_event":"2026-04-07T03:24:34.722154097Z","rtype":160,"publisher_id":101,"instrument_id":436},"action":"C","side":"B","price":"1.156680000","size":30,"channel_id":23,"order_id":"10998904293909418648","flags":0,"ts_in_delta":985,"sequence":188512,"symbol":"FCEU SI 20260615 PS"}
{"ts_recv":"2026-04-07T03:24:34.722175173Z","hd":{"ts_event":"2026-04-07T03:24:34.722154097Z","rtype":160,"publisher_id":101,"instrument_id":436},"action":"A","side":"B","price":"1.156660000","size":30,"channel_id":23,"order_id":"10998904311576936108","flags":0,"ts_in_delta":985,"sequence":188512,"symbol":"FCEU SI 20260615 PS"}
{"ts_recv":"2026-04-07T03:24:34.722175173Z","hd":{"ts_event":"2026-04-07T03:24:34.722154097Z","rtype":160,"publisher_id":101,"instrument_id":436},"action":"C","side":"A","price":"1.156780000","size":30,"channel_id":23,"order_id":"1775532257054642840","flags":0,"ts_in_delta":985,"sequence":188512,"symbol":"FCEU SI 20260615 PS"}
{"ts_recv":"2026-04-07T03:24:34.722175173Z","hd":{"ts_event":"2026-04-07T03:24:34.722154097Z","rtype":160,"publisher_id":101,"instrument_id":436},"action":"A","side":"A","price":"1.156760000","size":30,"channel_id":23,"order_id":"1775532274722160300","flags":128,"ts_in_delta":985,"sequence":188512,"symbol":"FCEU SI 20260615 PS"}
{"ts_recv":"2026-04-07T03:24:34.722232494Z","hd":{"ts_event":"2026-04-07T03:24:34.722212513Z","rtype":160,"publisher_id":101,"instrument_id":436},"action":"C","side":"B","price":"1.156670000","size":30,"channel_id":23,"order_id":"10998904311576651948","flags":0,"ts_in_delta":998,"sequence":188513,"symbol":"FCEU SI 20260615 PS"}
{"ts_recv":"2026-04-07T03:24:34.722232494Z","hd":{"ts_event":"2026-04-07T03:24:34.722212513Z","rtype":160,"publisher_id":101,"instrument_id":436},"action":"A","side":"B","price":"1.156660000","size":30,"channel_id":23,"order_id":"10998904311576994125","flags":0,"ts_in_delta":998,"sequence":188513,"symbol":"FCEU SI 20260615 PS"}
{"ts_recv":"2026-04-07T03:24:34.722232494Z","hd":{"ts_event":"2026-04-07T03:24:34.722212513Z","rtype":160,"publisher_id":101,"instrument_id":436},"action":"C","side":"A","price":"1.156770000","size":30,"channel_id":23,"order_id":"1775532274721876140","flags":0,"ts_in_delta":998,"sequence":188513,"symbol":"FCEU SI 20260615 PS"}
{"ts_recv":"2026-04-07T03:24:34.722232494Z","hd":{"ts_event":"2026-04-07T03:24:34.722212513Z","rtype":160,"publisher_id":101,"instrument_id":436},"action":"A","side":"A","price":"1.156760000","size":30,"channel_id":23,"order_id":"1775532274722218317","flags":128,"ts_in_delta":998,"sequence":188513,"symbol":"FCEU SI 20260615 PS"}
{"ts_recv":"2026-04-07T03:24:34.727429573Z","hd":{"ts_event":"2026-04-07T03:24:34.727407949Z","rtype":160,"publisher_id":101,"instrument_id":436},"action":"C","side":"B","price":"1.156660000","size":30,"channel_id":23,"order_id":"10998904311576994125","flags":0,"ts_in_delta":1272,"sequence":188520,"symbol":"FCEU SI 20260615 PS"}
{"ts_recv":"2026-04-07T03:24:34.727429573Z","hd":{"ts_event":"2026-04-07T03:24:34.727407949Z","rtype":160,"publisher_id":101,"instrument_id":436},"action":"A","side":"B","price":"1.156650000","size":30,"channel_id":23,"order_id":"10998904311582189857","flags":0,"ts_in_delta":1272,"sequence":188520,"symbol":"FCEU SI 20260615 PS"}
{"ts_recv":"2026-04-07T03:24:34.727429573Z","hd":{"ts_event":"2026-04-07T03:24:34.727407949Z","rtype":160,"publisher_id":101,"instrument_id":436},"action":"C","side":"A","price":"1.156760000","size":30,"channel_id":23,"order_id":"1775532274722218317","flags":0,"ts_in_delta":1272,"sequence":188520,"symbol":"FCEU SI 20260615 PS"}
{"ts_recv":"2026-04-07T03:24:34.727429573Z","hd":{"ts_event":"2026-04-07T03:24:34.727407949Z","rtype":160,"publisher_id":101,"instrument_id":436},"action":"A","side":"A","price":"1.156750000","size":30,"channel_id":23,"order_id":"1775532274727414049","flags":128,"ts_in_delta":1272,"sequence":188520,"symbol":"FCEU SI 20260615 PS"}
{"ts_recv":"2026-04-07T03:24:34.727515953Z","hd":{"ts_event":"2026-04-07T03:24:34.727495239Z","rtype":160,"publisher_id":101,"instrument_id":436},"action":"C","side":"B","price":"1.156650000","size":30,"channel_id":23,"order_id":"10998904311582189857","flags":0,"ts_in_delta":964,"sequence":188521,"symbol":"FCEU SI 20260615 PS"}
{"ts_recv":"2026-04-07T03:24:34.727515953Z","hd":{"ts_event":"2026-04-07T03:24:34.727495239Z","rtype":160,"publisher_id":101,"instrument_id":436},"action":"A","side":"B","price":"1.156640000","size":30,"channel_id":23,"order_id":"10998904311582276835","flags":0,"ts_in_delta":964,"sequence":188521,"symbol":"FCEU SI 20260615 PS"}
{"ts_recv":"2026-04-07T03:24:34.727515953Z","hd":{"ts_event":"2026-04-07T03:24:34.727495239Z","rtype":160,"publisher_id":101,"instrument_id":436},"action":"C","side":"A","price":"1.156750000","size":30,"channel_id":23,"order_id":"1775532274727414049","flags":0,"ts_in_delta":964,"sequence":188521,"symbol":"FCEU SI 20260615 PS"}
{"ts_recv":"2026-04-07T03:24:34.727515953Z","hd":{"ts_event":"2026-04-07T03:24:34.727495239Z","rtype":160,"publisher_id":101,"instrument_id":436},"action":"A","side":"A","price":"1.156740000","size":30,"channel_id":23,"order_id":"1775532274727501027","flags":128,"ts_in_delta":964,"sequence":188521,"symbol":"FCEU SI 20260615 PS"}
{"ts_recv":"2026-04-07T03:24:34.727571193Z","hd":{"ts_event":"2026-04-07T03:24:34.727556077Z","rtype":160,"publisher_id":101,"instrument_id":436},"action":"C","side":"B","price":"1.156640000","size":30,"channel_id":23,"order_id":"10998904311582276835","flags":0,"ts_in_delta":959,"sequence":188522,"symbol":"FCEU SI 20260615 PS"}
{"ts_recv":"2026-04-07T03:24:34.727571193Z","hd":{"ts_event":"2026-04-07T03:24:34.727556077Z","rtype":160,"publisher_id":101,"instrument_id":436},"action":"A","side":"B","price":"1.156650000","size":30,"channel_id":23,"order_id":"10998904311582337648","flags":0,"ts_in_delta":959,"sequence":188522,"symbol":"FCEU SI 20260615 PS"}
{"ts_recv":"2026-04-07T03:24:34.727571193Z","hd":{"ts_event":"2026-04-07T03:24:34.727556077Z","rtype":160,"publisher_id":101,"instrument_id":436},"action":"C","side":"A","price":"1.156740000","size":30,"channel_id":23,"order_id":"1775532274727501027","flags":0,"ts_in_delta":959,"sequence":188522,"symbol":"FCEU SI 20260615 PS"}
{"ts_recv":"2026-04-07T03:24:34.727571193Z","hd":{"ts_event":"2026-04-07T03:24:34.727556077Z","rtype":160,"publisher_id":101,"instrument_id":436},"action":"A","side":"A","price":"1.156750000","size":30,"channel_id":23,"order_id":"1775532274727561840","flags":128,"ts_in_delta":959,"sequence":188522,"symbol":"FCEU SI 20260615 PS"}
{"ts_recv":"2026-04-07T03:24:34.733431656Z","hd":{"ts_event":"2026-04-07T03:24:34.733411943Z","rtype":160,"publisher_id":101,"instrument_id":436},"action":"C","side":"B","price":"1.156660000","size":30,"channel_id":23,"order_id":"10998904311576936108","flags":0,"ts_in_delta":993,"sequence":188526,"symbol":"FCEU SI 20260615 PS"}
{"ts_recv":"2026-04-07T03:24:34.733431656Z","hd":{"ts_event":"2026-04-07T03:24:34.733411943Z","rtype":160,"publisher_id":101,"instrument_id":436},"action":"A","side":"B","price":"1.156640000","size":30,"channel_id":23,"order_id":"10998904311588193690","flags":0,"ts_in_delta":993,"sequence":188526,"symbol":"FCEU SI 20260615 PS"}
{"ts_recv":"2026-04-07T03:24:34.733431656Z","hd":{"ts_event":"2026-04-07T03:24:34.733411943Z","rtype":160,"publisher_id":101,"instrument_id":436},"action":"C","side":"A","price":"1.156760000","size":30,"channel_id":23,"order_id":"1775532274722160300","flags":0,"ts_in_delta":993,"sequence":188526,"symbol":"FCEU SI 20260615 PS"}
{"ts_recv":"2026-04-07T03:24:34.733431656Z","hd":{"ts_event":"2026-04-07T03:24:34.733411943Z","rtype":160,"publisher_id":101,"instrument_id":436},"action":"A","side":"A","price":"1.156740000","size":30,"channel_id":23,"order_id":"1775532274733417882","flags":128,"ts_in_delta":993,"sequence":188526,"symbol":"FCEU SI 20260615 PS"}
{"ts_recv":"2026-04-07T03:24:34.733490597Z","hd":{"ts_event":"2026-04-07T03:24:34.733472769Z","rtype":160,"publisher_id":101,"instrument_id":436},"action":"C","side":"B","price":"1.156650000","size":30,"channel_id":23,"order_id":"10998904311582337648","flags":0,"ts_in_delta":1039,"sequence":188527,"symbol":"FCEU SI 20260615 PS"}
{"ts_recv":"2026-04-07T03:24:34.733490597Z","hd":{"ts_event":"2026-04-07T03:24:34.733472769Z","rtype":160,"publisher_id":101,"instrument_id":436},"action":"A","side":"B","price":"1.156640000","size":30,"channel_id":23,"order_id":"10998904311588254369","flags":0,"ts_in_delta":1039,"sequence":188527,"symbol":"FCEU SI 20260615 PS"}
{"ts_recv":"2026-04-07T03:24:34.733490597Z","hd":{"ts_event":"2026-04-07T03:24:34.733472769Z","rtype":160,"publisher_id":101,"instrument_id":436},"action":"C","side":"A","price":"1.156750000","size":30,"channel_id":23,"order_id":"1775532274727561840","flags":0,"ts_in_delta":1039,"sequence":188527,"symbol":"FCEU SI 20260615 PS"}
{"ts_recv":"2026-04-07T03:24:34.733490597Z","hd":{"ts_event":"2026-04-07T03:24:34.733472769Z","rtype":160,"publisher_id":101,"instrument_id":436},"action":"A","side":"A","price":"1.156740000","size":30,"channel_id":23,"order_id":"1775532274733478561","flags":128,"ts_in_delta":1039,"sequence":188527,"symbol":"FCEU SI 20260615 PS"}
{"ts_recv":"2026-04-07T03:24:39.034013602Z","hd":{"ts_event":"2026-04-07T03:24:39.033985727Z","rtype":160,"publisher_id":101,"instrument_id":436},"action":"C","side":"B","price":"1.156640000","size":30,"channel_id":23,"order_id":"10998904311588193690","flags":0,"ts_in_delta":1431,"sequence":188584,"symbol":"FCEU SI 20260615 PS"}
{"ts_recv":"2026-04-07T03:24:39.034013602Z","hd":{"ts_event":"2026-04-07T03:24:39.033985727Z","rtype":160,"publisher_id":101,"instrument_id":436},"action":"A","side":"B","price":"1.156660000","size":30,"channel_id":23,"order_id":"10998904315888770578","flags":0,"ts_in_delta":1431,"sequence":188584,"symbol":"FCEU SI 20260615 PS"}
{"ts_recv":"2026-04-07T03:24:39.034013602Z","hd":{"ts_event":"2026-04-07T03:24:39.033985727Z","rtype":160,"publisher_id":101,"instrument_id":436},"action":"C","side":"A","price":"1.156740000","size":30,"channel_id":23,"order_id":"1775532274733417882","flags":0,"ts_in_delta":1431,"sequence":188584,"symbol":"FCEU SI 20260615 PS"}
{"ts_recv":"2026-04-07T03:24:39.034013602Z","hd":{"ts_event":"2026-04-07T03:24:39.033985727Z","rtype":160,"publisher_id":101,"instrument_id":436},"action":"A","side":"A","price":"1.156760000","size":30,"channel_id":23,"order_id":"1775532279033994770","flags":128,"ts_in_delta":1431,"sequence":188584,"symbol":"FCEU SI 20260615 PS"}
{"ts_recv":"2026-04-07T03:24:39.034129895Z","hd":{"ts_event":"2026-04-07T03:24:39.034112677Z","rtype":160,"publisher_id":101,"instrument_id":436},"action":"C","side":"B","price":"1.156640000","size":30,"channel_id":23,"order_id":"10998904311588254369","flags":0,"ts_in_delta":1045,"sequence":188585,"symbol":"FCEU SI 20260615 PS"}
{"ts_recv":"2026-04-07T03:24:39.034129895Z","hd":{"ts_event":"2026-04-07T03:24:39.034112677Z","rtype":160,"publisher_id":101,"instrument_id":436},"action":"A","side":"B","price":"1.156650000","size":30,"channel_id":23,"order_id":"10998904315888894558","flags":0,"ts_in_delta":1045,"sequence":188585,"symbol":"FCEU SI 20260615 PS"}
{"ts_recv":"2026-04-07T03:24:39.034129895Z","hd":{"ts_event":"2026-04-07T03:24:39.034112677Z","rtype":160,"publisher_id":101,"instrument_id":436},"action":"C","side":"A","price":"1.156740000","size":30,"channel_id":23,"order_id":"1775532274733478561","flags":0,"ts_in_delta":1045,"sequence":188585,"symbol":"FCEU SI 20260615 PS"}
{"ts_recv":"2026-04-07T03:24:39.034129895Z","hd":{"ts_event":"2026-04-07T03:24:39.034112677Z","rtype":160,"publisher_id":101,"instrument_id":436},"action":"A","side":"A","price":"1.156750000","size":30,"channel_id":23,"order_id":"1775532279034118750","flags":128,"ts_in_delta":1045,"sequence":188585,"symbol":"FCEU SI 20260615 PS"}
{"ts_recv":"2026-04-07T03:24:39.038840705Z","hd":{"ts_event":"2026-04-07T03:24:39.038825219Z","rtype":160,"publisher_id":101,"instrument_id":436},"action":"C","side":"B","price":"1.156650000","size":30,"channel_id":23,"order_id":"10998904315888894558","flags":0,"ts_in_delta":957,"sequence":188586,"symbol":"FCEU SI 20260615 PS"}
{"ts_recv":"2026-04-07T03:24:39.038840705Z","hd":{"ts_event":"2026-04-07T03:24:39.038825219Z","rtype":160,"publisher_id":101,"instrument_id":436},"action":"A","side":"B","price":"1.156660000","size":30,"channel_id":23,"order_id":"10998904315893606618","flags":0,"ts_in_delta":957,"sequence":188586,"symbol":"FCEU SI 20260615 PS"}
{"ts_recv":"2026-04-07T03:24:39.038840705Z","hd":{"ts_event":"2026-04-07T03:24:39.038825219Z","rtype":160,"publisher_id":101,"instrument_id":436},"action":"C","side":"A","price":"1.156750000","size":30,"channel_id":23,"order_id":"1775532279034118750","flags":0,"ts_in_delta":957,"sequence":188586,"symbol":"FCEU SI 20260615 PS"}
{"ts_recv":"2026-04-07T03:24:39.038840705Z","hd":{"ts_event":"2026-04-07T03:24:39.038825219Z","rtype":160,"publisher_id":101,"instrument_id":436},"action":"A","side":"A","price":"1.156760000","size":30,"channel_id":23,"order_id":"1775532279038830810","flags":128,"ts_in_delta":957,"sequence":188586,"symbol":"FCEU SI 20260615 PS"}
{"ts_recv":"2026-04-07T03:24:42.459119711Z","hd":{"ts_event":"2026-04-07T03:24:42.459100341Z","rtype":160,"publisher_id":101,"instrument_id":436},"action":"C","side":"B","price":"1.156660000","size":30,"channel_id":23,"order_id":"10998904315893606618","flags":0,"ts_in_delta":790,"sequence":188619,"symbol":"FCEU SI 20260615 PS"}
{"ts_recv":"2026-04-07T03:24:42.459119711Z","hd":{"ts_event":"2026-04-07T03:24:42.459100341Z","rtype":160,"publisher_id":101,"instrument_id":436},"action":"A","side":"B","price":"1.156670000","size":30,"channel_id":23,"order_id":"10998904319313882206","flags":0,"ts_in_delta":790,"sequence":188619,"symbol":"FCEU SI 20260615 PS"}
{"ts_recv":"2026-04-07T03:24:42.459119711Z","hd":{"ts_event":"2026-04-07T03:24:42.459100341Z","rtype":160,"publisher_id":101,"instrument_id":436},"action":"C","side":"A","price":"1.156760000","size":30,"channel_id":23,"order_id":"1775532279038830810","flags":0,"ts_in_delta":790,"sequence":188619,"symbol":"FCEU SI 20260615 PS"}
{"ts_recv":"2026-04-07T03:24:42.459119711Z","hd":{"ts_event":"2026-04-07T03:24:42.459100341Z","rtype":160,"publisher_id":101,"instrument_id":436},"action":"A","side":"A","price":"1.156770000","size":30,"channel_id":23,"order_id":"1775532282459106398","flags":128,"ts_in_delta":790,"sequence":188619,"symbol":"FCEU SI 20260615 PS"}
{"ts_recv":"2026-04-07T03:24:42.459176924Z","hd":{"ts_event":"2026-04-07T03:24:42.459156405Z","rtype":160,"publisher_id":101,"instrument_id":436},"action":"C","side":"B","price":"1.156660000","size":30,"channel_id":23,"order_id":"10998904315888770578","flags":0,"ts_in_delta":904,"sequence":188620,"symbol":"FCEU SI 20260615 PS"}
{"ts_recv":"2026-04-07T03:24:42.459176924Z","hd":{"ts_event":"2026-04-07T03:24:42.459156405Z","rtype":160,"publisher_id":101,"instrument_id":436},"action":"A","side":"B","price":"1.156680000","size":30,"channel_id":23,"order_id":"10998904319313938516","flags":0,"ts_in_delta":904,"sequence":188620,"symbol":"FCEU SI 20260615 PS"}
{"ts_recv":"2026-04-07T03:24:42.459176924Z","hd":{"ts_event":"2026-04-07T03:24:42.459156405Z","rtype":160,"publisher_id":101,"instrument_id":436},"action":"C","side":"A","price":"1.156760000","size":30,"channel_id":23,"order_id":"1775532279033994770","flags":0,"ts_in_delta":904,"sequence":188620,"symbol":"FCEU SI 20260615 PS"}
{"ts_recv":"2026-04-07T03:24:42.459176924Z","hd":{"ts_event":"2026-04-07T03:24:42.459156405Z","rtype":160,"publisher_id":101,"instrument_id":436},"action":"A","side":"A","price":"1.156780000","size":30,"channel_id":23,"order_id":"1775532282459162708","flags":128,"ts_in_delta":904,"sequence":188620,"symbol":"FCEU SI 20260615 PS"}
{"ts_recv":"2026-04-07T03:24:42.459239229Z","hd":{"ts_event":"2026-04-07T03:24:42.459218269Z","rtype":160,"publisher_id":101,"instrument_id":436},"action":"C","side":"B","price":"1.156670000","size":30,"channel_id":23,"order_id":"10998904319313882206","flags":0,"ts_in_delta":908,"sequence":188621,"symbol":"FCEU SI 20260615 PS"}
{"ts_recv":"2026-04-07T03:24:42.459239229Z","hd":{"ts_event":"2026-04-07T03:24:42.459218269Z","rtype":160,"publisher_id":101,"instrument_id":436},"action":"A","side":"B","price":"1.156680000","size":30,"channel_id":23,"order_id":"10998904319314000075","flags":0,"ts_in_delta":908,"sequence":188621,"symbol":"FCEU SI 20260615 PS"}
{"ts_recv":"2026-04-07T03:24:42.459239229Z","hd":{"ts_event":"2026-04-07T03:24:42.459218269Z","rtype":160,"publisher_id":101,"instrument_id":436},"action":"C","side":"A","price":"1.156770000","size":30,"channel_id":23,"order_id":"1775532282459106398","flags":0,"ts_in_delta":908,"sequence":188621,"symbol":"FCEU SI 20260615 PS"}
{"ts_recv":"2026-04-07T03:24:42.459239229Z","hd":{"ts_event":"2026-04-07T03:24:42.459218269Z","rtype":160,"publisher_id":101,"instrument_id":436},"action":"A","side":"A","price":"1.156780000","size":30,"channel_id":23,"order_id":"1775532282459224267","flags":128,"ts_in_delta":908,"sequence":188621,"symbol":"FCEU SI 20260615 PS"}
{"ts_recv":"2026-04-07T03:25:35.237951251Z","hd":{"ts_event":"2026-04-07T03:25:35.237916651Z","rtype":160,"publisher_id":101,"instrument_id":436},"action":"C","side":"B","price":"1.156680000","size":30,"channel_id":23,"order_id":"10998904319314000075","flags":0,"ts_in_delta":1446,"sequence":188876,"symbol":"FCEU SI 20260615 PS"}
{"ts_recv":"2026-04-07T03:25:35.237951251Z","hd":{"ts_event":"2026-04-07T03:25:35.237916651Z","rtype":160,"publisher_id":101,"instrument_id":436},"action":"A","side":"B","price":"1.156670000","size":30,"channel_id":23,"order_id":"10998904372092705601","flags":0,"ts_in_delta":1446,"sequence":188876,"symbol":"FCEU SI 20260615 PS"}
{"ts_recv":"2026-04-07T03:25:35.237951251Z","hd":{"ts_event":"2026-04-07T03:25:35.237916651Z","rtype":160,"publisher_id":101,"instrument_id":436},"action":"C","side":"A","price":"1.156780000","size":30,"channel_id":23,"order_id":"1775532282459224267","flags":0,"ts_in_delta":1446,"sequence":188876,"symbol":"FCEU SI 20260615 PS"}
{"ts_recv":"2026-04-07T03:25:35.237951251Z","hd":{"ts_event":"2026-04-07T03:25:35.237916651Z","rtype":160,"publisher_id":101,"instrument_id":436},"action":"A","side":"A","price":"1.156770000","size":30,"channel_id":23,"order_id":"1775532335237929793","flags":128,"ts_in_delta":1446,"sequence":188876,"symbol":"FCEU SI 20260615 PS"}
{"ts_recv":"2026-04-07T03:25:35.238036288Z","hd":{"ts_event":"2026-04-07T03:25:35.238018241Z","rtype":160,"publisher_id":101,"instrument_id":436},"action":"C","side":"B","price":"1.156670000","size":30,"channel_id":23,"order_id":"10998904372092705601","flags":0,"ts_in_delta":1058,"sequence":188877,"symbol":"FCEU SI 20260615 PS"}
{"ts_recv":"2026-04-07T03:25:35.238036288Z","hd":{"ts_event":"2026-04-07T03:25:35.238018241Z","rtype":160,"publisher_id":101,"instrument_id":436},"action":"A","side":"B","price":"1.156650000","size":30,"channel_id":23,"order_id":"10998904372092800038","flags":0,"ts_in_delta":1058,"sequence":188877,"symbol":"FCEU SI 20260615 PS"}
{"ts_recv":"2026-04-07T03:25:35.238036288Z","hd":{"ts_event":"2026-04-07T03:25:35.238018241Z","rtype":160,"publisher_id":101,"instrument_id":436},"action":"C","side":"A","price":"1.156770000","size":30,"channel_id":23,"order_id":"1775532335237929793","flags":0,"ts_in_delta":1058,"sequence":188877,"symbol":"FCEU SI 20260615 PS"}
{"ts_recv":"2026-04-07T03:25:35.238036288Z","hd":{"ts_event":"2026-04-07T03:25:35.238018241Z","rtype":160,"publisher_id":101,"instrument_id":436},"action":"A","side":"A","price":"1.156750000","size":30,"channel_id":23,"order_id":"1775532335238024230","flags":128,"ts_in_delta":1058,"sequence":188877,"symbol":"FCEU SI 20260615 PS"}
{"ts_recv":"2026-04-07T03:25:35.238095344Z","hd":{"ts_event":"2026-04-07T03:25:35.238075535Z","rtype":160,"publisher_id":101,"instrument_id":436},"action":"C","side":"B","price":"1.156680000","size":30,"channel_id":23,"order_id":"10998904319313938516","flags":0,"ts_in_delta":940,"sequence":188878,"symbol":"FCEU SI 20260615 PS"}
{"ts_recv":"2026-04-07T03:25:35.238095344Z","hd":{"ts_event":"2026-04-07T03:25:35.238075535Z","rtype":160,"publisher_id":101,"instrument_id":436},"action":"A","side":"B","price":"1.156660000","size":30,"channel_id":23,"order_id":"10998904372092857892","flags":0,"ts_in_delta":940,"sequence":188878,"symbol":"FCEU SI 20260615 PS"}
{"ts_recv":"2026-04-07T03:25:35.238095344Z","hd":{"ts_event":"2026-04-07T03:25:35.238075535Z","rtype":160,"publisher_id":101,"instrument_id":436},"action":"C","side":"A","price":"1.156780000","size":30,"channel_id":23,"order_id":"1775532282459162708","flags":0,"ts_in_delta":940,"sequence":188878,"symbol":"FCEU SI 20260615 PS"}
{"ts_recv":"2026-04-07T03:25:35.238095344Z","hd":{"ts_event":"2026-04-07T03:25:35.238075535Z","rtype":160,"publisher_id":101,"instrument_id":436},"action":"A","side":"A","price":"1.156760000","size":30,"channel_id":23,"order_id":"1775532335238082084","flags":128,"ts_in_delta":940,"sequence":188878,"symbol":"FCEU SI 20260615 PS"}
{"ts_recv":"2026-04-07T03:25:35.238105504Z","hd":{"ts_event":"2026-04-07T03:25:35.238080391Z","rtype":160,"publisher_id":101,"instrument_id":436},"action":"C","side":"B","price":"1.156650000","size":30,"channel_id":23,"order_id":"10998904372092800038","flags":0,"ts_in_delta":951,"sequence":188879,"symbol":"FCEU SI 20260615 PS"}
{"ts_recv":"2026-04-07T03:25:35.238105504Z","hd":{"ts_event":"2026-04-07T03:25:35.238080391Z","rtype":160,"publisher_id":101,"instrument_id":436},"action":"A","side":"B","price":"1.156670000","size":30,"channel_id":23,"order_id":"10998904372092867989","flags":0,"ts_in_delta":951,"sequence":188879,"symbol":"FCEU SI 20260615 PS"}
{"ts_recv":"2026-04-07T03:25:35.238105504Z","hd":{"ts_event":"2026-04-07T03:25:35.238080391Z","rtype":160,"publisher_id":101,"instrument_id":436},"action":"C","side":"A","price":"1.156750000","size":30,"channel_id":23,"order_id":"1775532335238024230","flags":0,"ts_in_delta":951,"sequence":188879,"symbol":"FCEU SI 20260615 PS"}
{"ts_recv":"2026-04-07T03:25:35.238105504Z","hd":{"ts_event":"2026-04-07T03:25:35.238080391Z","rtype":160,"publisher_id":101,"instrument_id":436},"action":"A","side":"A","price":"1.156770000","size":30,"channel_id":23,"order_id":"1775532335238092181","flags":128,"ts_in_delta":951,"sequence":188879,"symbol":"FCEU SI 20260615 PS"}
{"ts_recv":"2026-04-07T03:25:35.238165221Z","hd":{"ts_event":"2026-04-07T03:25:35.238145691Z","rtype":160,"publisher_id":101,"instrument_id":436},"action":"C","side":"B","price":"1.156670000","size":30,"channel_id":23,"order_id":"10998904372092867989","flags":0,"ts_in_delta":974,"sequence":188880,"symbol":"FCEU SI 20260615 PS"}
{"ts_recv":"2026-04-07T03:25:35.238165221Z","hd":{"ts_event":"2026-04-07T03:25:35.238145691Z","rtype":160,"publisher_id":101,"instrument_id":436},"action":"A","side":"B","price":"1.156660000","size":30,"channel_id":23,"order_id":"10998904372092927385","flags":0,"ts_in_delta":974,"sequence":188880,"symbol":"FCEU SI 20260615 PS"}
{"ts_recv":"2026-04-07T03:25:35.238165221Z","hd":{"ts_event":"2026-04-07T03:25:35.238145691Z","rtype":160,"publisher_id":101,"instrument_id":436},"action":"C","side":"A","price":"1.156770000","size":30,"channel_id":23,"order_id":"1775532335238092181","flags":0,"ts_in_delta":974,"sequence":188880,"symbol":"FCEU SI 20260615 PS"}
{"ts_recv":"2026-04-07T03:25:35.238165221Z","hd":{"ts_event":"2026-04-07T03:25:35.238145691Z","rtype":160,"publisher_id":101,"instrument_id":436},"action":"A","side":"A","price":"1.156760000","size":30,"channel_id":23,"order_id":"1775532335238151577","flags":128,"ts_in_delta":974,"sequence":188880,"symbol":"FCEU SI 20260615 PS"}
{"ts_recv":"2026-04-07T03:25:36.010676140Z","hd":{"ts_event":"2026-04-07T03:25:36.010657639Z","rtype":160,"publisher_id":101,"instrument_id":436},"action":"C","side":"B","price":"1.156660000","size":30,"channel_id":23,"order_id":"10998904372092927385","flags":0,"ts_in_delta":950,"sequence":188905,"symbol":"FCEU SI 20260615 PS"}
{"ts_recv":"2026-04-07T03:25:36.010676140Z","hd":{"ts_event":"2026-04-07T03:25:36.010657639Z","rtype":160,"publisher_id":101,"instrument_id":436},"action":"A","side":"B","price":"1.156650000","size":30,"channel_id":23,"order_id":"10998904372865439556","flags":0,"ts_in_delta":950,"sequence":188905,"symbol":"FCEU SI 20260615 PS"}
{"ts_recv":"2026-04-07T03:25:36.010676140Z","hd":{"ts_event":"2026-04-07T03:25:36.010657639Z","rtype":160,"publisher_id":101,"instrument_id":436},"action":"C","side":"A","price":"1.156760000","size":30,"channel_id":23,"order_id":"1775532335238151577","flags":0,"ts_in_delta":950,"sequence":188905,"symbol":"FCEU SI 20260615 PS"}
{"ts_recv":"2026-04-07T03:25:36.010676140Z","hd":{"ts_event":"2026-04-07T03:25:36.010657639Z","rtype":160,"publisher_id":101,"instrument_id":436},"action":"A","side":"A","price":"1.156750000","size":30,"channel_id":23,"order_id":"1775532336010663748","flags":128,"ts_in_delta":950,"sequence":188905,"symbol":"FCEU SI 20260615 PS"}
{"ts_recv":"2026-04-07T03:25:36.029351576Z","hd":{"ts_event":"2026-04-07T03:25:36.029332029Z","rtype":160,"publisher_id":101,"instrument_id":436},"action":"C","side":"B","price":"1.156660000","size":30,"channel_id":23,"order_id":"10998904372092857892","flags":0,"ts_in_delta":933,"sequence":188914,"symbol":"FCEU SI 20260615 PS"}
{"ts_recv":"2026-04-07T03:25:36.029351576Z","hd":{"ts_event":"2026-04-07T03:25:36.029332029Z","rtype":160,"publisher_id":101,"instrument_id":436},"action":"A","side":"B","price":"1.156640000","size":30,"channel_id":23,"order_id":"10998904372884114176","flags":0,"ts_in_delta":933,"sequence":188914,"symbol":"FCEU SI 20260615 PS"}
{"ts_recv":"2026-04-07T03:25:36.029351576Z","hd":{"ts_event":"2026-04-07T03:25:36.029332029Z","rtype":160,"publisher_id":101,"instrument_id":436},"action":"C","side":"A","price":"1.156760000","size":30,"channel_id":23,"order_id":"1775532335238082084","flags":0,"ts_in_delta":933,"sequence":188914,"symbol":"FCEU SI 20260615 PS"}
{"ts_recv":"2026-04-07T03:25:36.029351576Z","hd":{"ts_event":"2026-04-07T03:25:36.029332029Z","rtype":160,"publisher_id":101,"instrument_id":436},"action":"A","side":"A","price":"1.156740000","size":30,"channel_id":23,"order_id":"1775532336029338368","flags":128,"ts_in_delta":933,"sequence":188914,"symbol":"FCEU SI 20260615 PS"}
{"ts_recv":"2026-04-07T03:25:36.029414556Z","hd":{"ts_event":"2026-04-07T03:25:36.029398987Z","rtype":160,"publisher_id":101,"instrument_id":436},"action":"C","side":"B","price":"1.156650000","size":30,"channel_id":23,"order_id":"10998904372865439556","flags":0,"ts_in_delta":955,"sequence":188915,"symbol":"FCEU SI 20260615 PS"}
{"ts_recv":"2026-04-07T03:25:36.029414556Z","hd":{"ts_event":"2026-04-07T03:25:36.029398987Z","rtype":160,"publisher_id":101,"instrument_id":436},"action":"A","side":"B","price":"1.156640000","size":30,"channel_id":23,"order_id":"10998904372884180476","flags":0,"ts_in_delta":955,"sequence":188915,"symbol":"FCEU SI 20260615 PS"}
{"ts_recv":"2026-04-07T03:25:36.029414556Z","hd":{"ts_event":"2026-04-07T03:25:36.029398987Z","rtype":160,"publisher_id":101,"instrument_id":436},"action":"C","side":"A","price":"1.156750000","size":30,"channel_id":23,"order_id":"1775532336010663748","flags":0,"ts_in_delta":955,"sequence":188915,"symbol":"FCEU SI 20260615 PS"}
{"ts_recv":"2026-04-07T03:25:36.029414556Z","hd":{"ts_event":"2026-04-07T03:25:36.029398987Z","rtype":160,"publisher_id":101,"instrument_id":436},"action":"A","side":"A","price":"1.156740000","size":30,"channel_id":23,"order_id":"1775532336029404668","flags":128,"ts_in_delta":955,"sequence":188915,"symbol":"FCEU SI 20260615 PS"}
{"ts_recv":"2026-04-07T03:25:37.229244347Z","hd":{"ts_event":"2026-04-07T03:25:37.229213967Z","rtype":160,"publisher_id":101,"instrument_id":436},"action":"C","side":"B","price":"1.156640000","size":30,"channel_id":23,"order_id":"10998904372884180476","flags":0,"ts_in_delta":1401,"sequence":188940,"symbol":"FCEU SI 20260615 PS"}
{"ts_recv":"2026-04-07T03:25:37.229244347Z","hd":{"ts_event":"2026-04-07T03:25:37.229213967Z","rtype":160,"publisher_id":101,"instrument_id":436},"action":"A","side":"B","price":"1.156630000","size":30,"channel_id":23,"order_id":"10998904374084002651","flags":0,"ts_in_delta":1401,"sequence":188940,"symbol":"FCEU SI 20260615 PS"}
{"ts_recv":"2026-04-07T03:25:37.229244347Z","hd":{"ts_event":"2026-04-07T03:25:37.229213967Z","rtype":160,"publisher_id":101,"instrument_id":436},"action":"C","side":"A","price":"1.156740000","size":30,"channel_id":23,"order_id":"1775532336029404668","flags":0,"ts_in_delta":1401,"sequence":188940,"symbol":"FCEU SI 20260615 PS"}
{"ts_recv":"2026-04-07T03:25:37.229244347Z","hd":{"ts_event":"2026-04-07T03:25:37.229213967Z","rtype":160,"publisher_id":101,"instrument_id":436},"action":"A","side":"A","price":"1.156730000","size":30,"channel_id":23,"order_id":"1775532337229226843","flags":128,"ts_in_delta":1401,"sequence":188940,"symbol":"FCEU SI 20260615 PS"}
{"ts_recv":"2026-04-07T03:25:37.229314815Z","hd":{"ts_event":"2026-04-07T03:25:37.229296253Z","rtype":160,"publisher_id":101,"instrument_id":436},"action":"C","side":"B","price":"1.156640000","size":30,"channel_id":23,"order_id":"10998904372884114176","flags":0,"ts_in_delta":994,"sequence":188941,"symbol":"FCEU SI 20260615 PS"}
{"ts_recv":"2026-04-07T03:25:37.229314815Z","hd":{"ts_event":"2026-04-07T03:25:37.229296253Z","rtype":160,"publisher_id":101,"instrument_id":436},"action":"A","side":"B","price":"1.156620000","size":30,"channel_id":23,"order_id":"10998904374084078303","flags":0,"ts_in_delta":994,"sequence":188941,"symbol":"FCEU SI 20260615 PS"}
{"ts_recv":"2026-04-07T03:25:37.229314815Z","hd":{"ts_event":"2026-04-07T03:25:37.229296253Z","rtype":160,"publisher_id":101,"instrument_id":436},"action":"C","side":"A","price":"1.156740000","size":30,"channel_id":23,"order_id":"1775532336029338368","flags":0,"ts_in_delta":994,"sequence":188941,"symbol":"FCEU SI 20260615 PS"}
{"ts_recv":"2026-04-07T03:25:37.229314815Z","hd":{"ts_event":"2026-04-07T03:25:37.229296253Z","rtype":160,"publisher_id":101,"instrument_id":436},"action":"A","side":"A","price":"1.156720000","size":30,"channel_id":23,"order_id":"1775532337229302495","flags":128,"ts_in_delta":994,"sequence":188941,"symbol":"FCEU SI 20260615 PS"}
{"ts_recv":"2026-04-07T03:25:37.229332993Z","hd":{"ts_event":"2026-04-07T03:25:37.229315133Z","rtype":160,"publisher_id":101,"instrument_id":436},"action":"C","side":"B","price":"1.156630000","size":30,"channel_id":23,"order_id":"10998904374084002651","flags":0,"ts_in_delta":904,"sequence":188942,"symbol":"FCEU SI 20260615 PS"}
{"ts_recv":"2026-04-07T03:25:37.229332993Z","hd":{"ts_event":"2026-04-07T03:25:37.229315133Z","rtype":160,"publisher_id":101,"instrument_id":436},"action":"A","side":"B","price":"1.156620000","size":30,"channel_id":23,"order_id":"10998904374084098991","flags":0,"ts_in_delta":904,"sequence":188942,"symbol":"FCEU SI 20260615 PS"}
{"ts_recv":"2026-04-07T03:25:37.229332993Z","hd":{"ts_event":"2026-04-07T03:25:37.229315133Z","rtype":160,"publisher_id":101,"instrument_id":436},"action":"C","side":"A","price":"1.156730000","size":30,"channel_id":23,"order_id":"1775532337229226843","flags":0,"ts_in_delta":904,"sequence":188942,"symbol":"FCEU SI 20260615 PS"}
{"ts_recv":"2026-04-07T03:25:37.229332993Z","hd":{"ts_event":"2026-04-07T03:25:37.229315133Z","rtype":160,"publisher_id":101,"instrument_id":436},"action":"A","side":"A","price":"1.156720000","size":30,"channel_id":23,"order_id":"1775532337229323183","flags":128,"ts_in_delta":904,"sequence":188942,"symbol":"FCEU SI 20260615 PS"}
{"ts_recv":"2026-04-07T03:25:37.242461991Z","hd":{"ts_event":"2026-04-07T03:25:37.242440733Z","rtype":160,"publisher_id":101,"instrument_id":436},"action":"C","side":"B","price":"1.156620000","size":30,"channel_id":23,"order_id":"10998904374084098991","flags":0,"ts_in_delta":992,"sequence":188950,"symbol":"FCEU SI 20260615 PS"}
{"ts_recv":"2026-04-07T03:25:37.242461991Z","hd":{"ts_event":"2026-04-07T03:25:37.242440733Z","rtype":160,"publisher_id":101,"instrument_id":436},"action":"A","side":"B","price":"1.156610000","size":30,"channel_id":23,"order_id":"10998904374097222617","flags":0,"ts_in_delta":992,"sequence":188950,"symbol":"FCEU SI 20260615 PS"}
{"ts_recv":"2026-04-07T03:25:37.242461991Z","hd":{"ts_event":"2026-04-07T03:25:37.242440733Z","rtype":160,"publisher_id":101,"instrument_id":436},"action":"C","side":"A","price":"1.156720000","size":30,"channel_id":23,"order_id":"1775532337229323183","flags":0,"ts_in_delta":992,"sequence":188950,"symbol":"FCEU SI 20260615 PS"}
{"ts_recv":"2026-04-07T03:25:37.242461991Z","hd":{"ts_event":"2026-04-07T03:25:37.242440733Z","rtype":160,"publisher_id":101,"instrument_id":436},"action":"A","side":"A","price":"1.156710000","size":30,"channel_id":23,"order_id":"1775532337242446809","flags":128,"ts_in_delta":992,"sequence":188950,"symbol":"FCEU SI 20260615 PS"}
{"ts_recv":"2026-04-07T03:25:37.242524334Z","hd":{"ts_event":"2026-04-07T03:25:37.242504779Z","rtype":160,"publisher_id":101,"instrument_id":436},"action":"C","side":"B","price":"1.156610000","size":30,"channel_id":23,"order_id":"10998904374097222617","flags":0,"ts_in_delta":912,"sequence":188951,"symbol":"FCEU SI 20260615 PS"}
{"ts_recv":"2026-04-07T03:25:37.242524334Z","hd":{"ts_event":"2026-04-07T03:25:37.242504779Z","rtype":160,"publisher_id":101,"instrument_id":436},"action":"A","side":"B","price":"1.156600000","size":30,"channel_id":23,"order_id":"10998904374097286304","flags":0,"ts_in_delta":912,"sequence":188951,"symbol":"FCEU SI 20260615 PS"}
{"ts_recv":"2026-04-07T03:25:37.242524334Z","hd":{"ts_event":"2026-04-07T03:25:37.242504779Z","rtype":160,"publisher_id":101,"instrument_id":436},"action":"C","side":"A","price":"1.156710000","size":30,"channel_id":23,"order_id":"1775532337242446809","flags":0,"ts_in_delta":912,"sequence":188951,"symbol":"FCEU SI 20260615 PS"}
{"ts_recv":"2026-04-07T03:25:37.242524334Z","hd":{"ts_event":"2026-04-07T03:25:37.242504779Z","rtype":160,"publisher_id":101,"instrument_id":436},"action":"A","side":"A","price":"1.156700000","size":30,"channel_id":23,"order_id":"1775532337242510496","flags":128,"ts_in_delta":912,"sequence":188951,"symbol":"FCEU SI 20260615 PS"}
{"ts_recv":"2026-04-07T03:25:37.242574774Z","hd":{"ts_event":"2026-04-07T03:25:37.242557431Z","rtype":160,"publisher_id":101,"instrument_id":436},"action":"C","side":"B","price":"1.156620000","size":30,"channel_id":23,"order_id":"10998904374084078303","flags":0,"ts_in_delta":925,"sequence":188952,"symbol":"FCEU SI 20260615 PS"}
{"ts_recv":"2026-04-07T03:25:37.242574774Z","hd":{"ts_event":"2026-04-07T03:25:37.242557431Z","rtype":160,"publisher_id":101,"instrument_id":436},"action":"A","side":"B","price":"1.156600000","size":30,"channel_id":23,"order_id":"10998904374097339232","flags":0,"ts_in_delta":925,"sequence":188952,"symbol":"FCEU SI 20260615 PS"}
{"ts_recv":"2026-04-07T03:25:37.242574774Z","hd":{"ts_event":"2026-04-07T03:25:37.242557431Z","rtype":160,"publisher_id":101,"instrument_id":436},"action":"C","side":"A","price":"1.156720000","size":30,"channel_id":23,"order_id":"1775532337229302495","flags":0,"ts_in_delta":925,"sequence":188952,"symbol":"FCEU SI 20260615 PS"}
{"ts_recv":"2026-04-07T03:25:37.242574774Z","hd":{"ts_event":"2026-04-07T03:25:37.242557431Z","rtype":160,"publisher_id":101,"instrument_id":436},"action":"A","side":"A","price":"1.156700000","size":30,"channel_id":23,"order_id":"1775532337242563424","flags":128,"ts_in_delta":925,"sequence":188952,"symbol":"FCEU SI 20260615 PS"}
{"ts_recv":"2026-04-07T03:25:37.242584843Z","hd":{"ts_event":"2026-04-07T03:25:37.242563685Z","rtype":160,"publisher_id":101,"instrument_id":436},"action":"C","side":"B","price":"1.156600000","size":30,"channel_id":23,"order_id":"10998904374097286304","flags":0,"ts_in_delta":1001,"sequence":188953,"symbol":"FCEU SI 20260615 PS"}
{"ts_recv":"2026-04-07T03:25:37.242584843Z","hd":{"ts_event":"2026-04-07T03:25:37.242563685Z","rtype":160,"publisher_id":101,"instrument_id":436},"action":"A","side":"B","price":"1.156610000","size":30,"channel_id":23,"order_id":"10998904374097347557","flags":0,"ts_in_delta":1001,"sequence":188953,"symbol":"FCEU SI 20260615 PS"}
{"ts_recv":"2026-04-07T03:25:37.242584843Z","hd":{"ts_event":"2026-04-07T03:25:37.242563685Z","rtype":160,"publisher_id":101,"instrument_id":436},"action":"C","side":"A","price":"1.156700000","size":30,"channel_id":23,"order_id":"1775532337242510496","flags":0,"ts_in_delta":1001,"sequence":188953,"symbol":"FCEU SI 20260615 PS"}
{"ts_recv":"2026-04-07T03:25:37.242584843Z","hd":{"ts_event":"2026-04-07T03:25:37.242563685Z","rtype":160,"publisher_id":101,"instrument_id":436},"action":"A","side":"A","price":"1.156710000","size":30,"channel_id":23,"order_id":"1775532337242571749","flags":128,"ts_in_delta":1001,"sequence":188953,"symbol":"FCEU SI 20260615 PS"}
{"ts_recv":"2026-04-07T03:25:37.242639629Z","hd":{"ts_event":"2026-04-07T03:25:37.242622317Z","rtype":160,"publisher_id":101,"instrument_id":436},"action":"C","side":"B","price":"1.156610000","size":30,"channel_id":23,"order_id":"10998904374097347557","flags":0,"ts_in_delta":930,"sequence":188954,"symbol":"FCEU SI 20260615 PS"}
{"ts_recv":"2026-04-07T03:25:37.242639629Z","hd":{"ts_event":"2026-04-07T03:25:37.242622317Z","rtype":160,"publisher_id":101,"instrument_id":436},"action":"A","side":"B","price":"1.156600000","size":30,"channel_id":23,"order_id":"10998904374097404248","flags":0,"ts_in_delta":930,"sequence":188954,"symbol":"FCEU SI 20260615 PS"}
{"ts_recv":"2026-04-07T03:25:37.242639629Z","hd":{"ts_event":"2026-04-07T03:25:37.242622317Z","rtype":160,"publisher_id":101,"instrument_id":436},"action":"C","side":"A","price":"1.156710000","size":30,"channel_id":23,"order_id":"1775532337242571749","flags":0,"ts_in_delta":930,"sequence":188954,"symbol":"FCEU SI 20260615 PS"}
{"ts_recv":"2026-04-07T03:25:37.242639629Z","hd":{"ts_event":"2026-04-07T03:25:37.242622317Z","rtype":160,"publisher_id":101,"instrument_id":436},"action":"A","side":"A","price":"1.156700000","size":30,"channel_id":23,"order_id":"1775532337242628440","flags":128,"ts_in_delta":930,"sequence":188954,"symbol":"FCEU SI 20260615 PS"}
{"ts_recv":"2026-04-07T03:25:37.268249239Z","hd":{"ts_event":"2026-04-07T03:25:37.268233923Z","rtype":160,"publisher_id":101,"instrument_id":436},"action":"C","side":"B","price":"1.156600000","size":20,"channel_id":23,"order_id":"10998904183758064535","flags":128,"ts_in_delta":940,"sequence":188966,"symbol":"FCEU SI 20260615 PS"}
{"ts_recv":"2026-04-07T03:25:37.330114802Z","hd":{"ts_event":"2026-04-07T03:25:37.330101457Z","rtype":160,"publisher_id":101,"instrument_id":436},"action":"A","side":"B","price":"1.156500000","size":20,"channel_id":23,"order_id":"10998904374184883287","flags":128,"ts_in_delta":983,"sequence":188983,"symbol":"FCEU SI 20260615 PS"}
{"ts_recv":"2026-04-07T03:25:52.353724082Z","hd":{"ts_event":"2026-04-07T03:25:52.353700387Z","rtype":160,"publisher_id":101,"instrument_id":436},"action":"C","side":"B","price":"1.156600000","size":30,"channel_id":23,"order_id":"10998904374097404248","flags":0,"ts_in_delta":1088,"sequence":189143,"symbol":"FCEU SI 20260615 PS"}
{"ts_recv":"2026-04-07T03:25:52.353724082Z","hd":{"ts_event":"2026-04-07T03:25:52.353700387Z","rtype":160,"publisher_id":101,"instrument_id":436},"action":"A","side":"B","price":"1.156610000","size":30,"channel_id":23,"order_id":"10998904389208482587","flags":0,"ts_in_delta":1088,"sequence":189143,"symbol":"FCEU SI 20260615 PS"}
{"ts_recv":"2026-04-07T03:25:52.353724082Z","hd":{"ts_event":"2026-04-07T03:25:52.353700387Z","rtype":160,"publisher_id":101,"instrument_id":436},"action":"C","side":"A","price":"1.156700000","size":30,"channel_id":23,"order_id":"1775532337242628440","flags":0,"ts_in_delta":1088,"sequence":189143,"symbol":"FCEU SI 20260615 PS"}
{"ts_recv":"2026-04-07T03:25:52.353724082Z","hd":{"ts_event":"2026-04-07T03:25:52.353700387Z","rtype":160,"publisher_id":101,"instrument_id":436},"action":"A","side":"A","price":"1.156710000","size":30,"channel_id":23,"order_id":"1775532352353706779","flags":128,"ts_in_delta":1088,"sequence":189143,"symbol":"FCEU SI 20260615 PS"}
{"ts_recv":"2026-04-07T03:25:54.078382452Z","hd":{"ts_event":"2026-04-07T03:25:54.078356137Z","rtype":160,"publisher_id":101,"instrument_id":436},"action":"C","side":"B","price":"1.156600000","size":30,"channel_id":23,"order_id":"10998904374097339232","flags":0,"ts_in_delta":1161,"sequence":189169,"symbol":"FCEU SI 20260615 PS"}
{"ts_recv":"2026-04-07T03:25:54.078382452Z","hd":{"ts_event":"2026-04-07T03:25:54.078356137Z","rtype":160,"publisher_id":101,"instrument_id":436},"action":"A","side":"B","price":"1.156620000","size":30,"channel_id":23,"order_id":"10998904390933142828","flags":0,"ts_in_delta":1161,"sequence":189169,"symbol":"FCEU SI 20260615 PS"}
{"ts_recv":"2026-04-07T03:25:54.078382452Z","hd":{"ts_event":"2026-04-07T03:25:54.078356137Z","rtype":160,"publisher_id":101,"instrument_id":436},"action":"C","side":"A","price":"1.156700000","size":30,"channel_id":23,"order_id":"1775532337242563424","flags":0,"ts_in_delta":1161,"sequence":189169,"symbol":"FCEU SI 20260615 PS"}
{"ts_recv":"2026-04-07T03:25:54.078382452Z","hd":{"ts_event":"2026-04-07T03:25:54.078356137Z","rtype":160,"publisher_id":101,"instrument_id":436},"action":"A","side":"A","price":"1.156720000","size":30,"channel_id":23,"order_id":"1775532354078367020","flags":128,"ts_in_delta":1161,"sequence":189169,"symbol":"FCEU SI 20260615 PS"}
{"ts_recv":"2026-04-07T03:25:54.078454149Z","hd":{"ts_event":"2026-04-07T03:25:54.078434107Z","rtype":160,"publisher_id":101,"instrument_id":436},"action":"C","side":"B","price":"1.156610000","size":30,"channel_id":23,"order_id":"10998904389208482587","flags":0,"ts_in_delta":1155,"sequence":189170,"symbol":"FCEU SI 20260615 PS"}
{"ts_recv":"2026-04-07T03:25:54.078454149Z","hd":{"ts_event":"2026-04-07T03:25:54.078434107Z","rtype":160,"publisher_id":101,"instrument_id":436},"action":"A","side":"B","price":"1.156620000","size":30,"channel_id":23,"order_id":"10998904390933216037","flags":0,"ts_in_delta":1155,"sequence":189170,"symbol":"FCEU SI 20260615 PS"}
{"ts_recv":"2026-04-07T03:25:54.078454149Z","hd":{"ts_event":"2026-04-07T03:25:54.078434107Z","rtype":160,"publisher_id":101,"instrument_id":436},"action":"C","side":"A","price":"1.156710000","size":30,"channel_id":23,"order_id":"1775532352353706779","flags":0,"ts_in_delta":1155,"sequence":189170,"symbol":"FCEU SI 20260615 PS"}
{"ts_recv":"2026-04-07T03:25:54.078454149Z","hd":{"ts_event":"2026-04-07T03:25:54.078434107Z","rtype":160,"publisher_id":101,"instrument_id":436},"action":"A","side":"A","price":"1.156720000","size":30,"channel_id":23,"order_id":"1775532354078440229","flags":128,"ts_in_delta":1155,"sequence":189170,"symbol":"FCEU SI 20260615 PS"}
{"ts_recv":"2026-04-07T03:26:00.521548867Z","hd":{"ts_event":"2026-04-07T03:26:00.521529419Z","rtype":160,"publisher_id":101,"instrument_id":436},"action":"C","side":"B","price":"1.156620000","size":30,"channel_id":23,"order_id":"10998904390933216037","flags":0,"ts_in_delta":961,"sequence":189232,"symbol":"FCEU SI 20260615 PS"}
{"ts_recv":"2026-04-07T03:26:00.521548867Z","hd":{"ts_event":"2026-04-07T03:26:00.521529419Z","rtype":160,"publisher_id":101,"instrument_id":436},"action":"A","side":"B","price":"1.156630000","size":30,"channel_id":23,"order_id":"10998904397376311185","flags":0,"ts_in_delta":961,"sequence":189232,"symbol":"FCEU SI 20260615 PS"}
{"ts_recv":"2026-04-07T03:26:00.521548867Z","hd":{"ts_event":"2026-04-07T03:26:00.521529419Z","rtype":160,"publisher_id":101,"instrument_id":436},"action":"C","side":"A","price":"1.156720000","size":30,"channel_id":23,"order_id":"1775532354078440229","flags":0,"ts_in_delta":961,"sequence":189232,"symbol":"FCEU SI 20260615 PS"}
{"ts_recv":"2026-04-07T03:26:00.521548867Z","hd":{"ts_event":"2026-04-07T03:26:00.521529419Z","rtype":160,"publisher_id":101,"instrument_id":436},"action":"A","side":"A","price":"1.156730000","size":30,"channel_id":23,"order_id":"1775532360521535377","flags":128,"ts_in_delta":961,"sequence":189232,"symbol":"FCEU SI 20260615 PS"}
{"ts_recv":"2026-04-07T03:26:00.540191896Z","hd":{"ts_event":"2026-04-07T03:26:00.540169161Z","rtype":160,"publisher_id":101,"instrument_id":436},"action":"C","side":"B","price":"1.156620000","size":30,"channel_id":23,"order_id":"10998904390933142828","flags":0,"ts_in_delta":919,"sequence":189236,"symbol":"FCEU SI 20260615 PS"}
{"ts_recv":"2026-04-07T03:26:00.540191896Z","hd":{"ts_event":"2026-04-07T03:26:00.540169161Z","rtype":160,"publisher_id":101,"instrument_id":436},"action":"A","side":"B","price":"1.156640000","size":30,"channel_id":23,"order_id":"10998904397394951474","flags":0,"ts_in_delta":919,"sequence":189236,"symbol":"FCEU SI 20260615 PS"}
{"ts_recv":"2026-04-07T03:26:00.540191896Z","hd":{"ts_event":"2026-04-07T03:26:00.540169161Z","rtype":160,"publisher_id":101,"instrument_id":436},"action":"C","side":"A","price":"1.156720000","size":30,"channel_id":23,"order_id":"1775532354078367020","flags":0,"ts_in_delta":919,"sequence":189236,"symbol":"FCEU SI 20260615 PS"}
{"ts_recv":"2026-04-07T03:26:00.540191896Z","hd":{"ts_event":"2026-04-07T03:26:00.540169161Z","rtype":160,"publisher_id":101,"instrument_id":436},"action":"A","side":"A","price":"1.156740000","size":30,"channel_id":23,"order_id":"1775532360540175666","flags":128,"ts_in_delta":919,"sequence":189236,"symbol":"FCEU SI 20260615 PS"}
{"ts_recv":"2026-04-07T03:26:00.540254454Z","hd":{"ts_event":"2026-04-07T03:26:00.540237685Z","rtype":160,"publisher_id":101,"instrument_id":436},"action":"C","side":"B","price":"1.156630000","size":30,"channel_id":23,"order_id":"10998904397376311185","flags":0,"ts_in_delta":939,"sequence":189237,"symbol":"FCEU SI 20260615 PS"}
{"ts_recv":"2026-04-07T03:26:00.540254454Z","hd":{"ts_event":"2026-04-07T03:26:00.540237685Z","rtype":160,"publisher_id":101,"instrument_id":436},"action":"A","side":"B","price":"1.156640000","size":30,"channel_id":23,"order_id":"10998904397395019553","flags":0,"ts_in_delta":939,"sequence":189237,"symbol":"FCEU SI 20260615 PS"}
{"ts_recv":"2026-04-07T03:26:00.540254454Z","hd":{"ts_event":"2026-04-07T03:26:00.540237685Z","rtype":160,"publisher_id":101,"instrument_id":436},"action":"C","side":"A","price":"1.156730000","size":30,"channel_id":23,"order_id":"1775532360521535377","flags":0,"ts_in_delta":939,"sequence":189237,"symbol":"FCEU SI 20260615 PS"}
{"ts_recv":"2026-04-07T03:26:00.540254454Z","hd":{"ts_event":"2026-04-07T03:26:00.540237685Z","rtype":160,"publisher_id":101,"instrument_id":436},"action":"A","side":"A","price":"1.156740000","size":30,"channel_id":23,"order_id":"1775532360540243745","flags":128,"ts_in_delta":939,"sequence":189237,"symbol":"FCEU SI 20260615 PS"}
{"ts_recv":"2026-04-07T03:26:02.748818993Z","hd":{"ts_event":"2026-04-07T03:26:02.748797159Z","rtype":160,"publisher_id":101,"instrument_id":436},"action":"C","side":"B","price":"1.156640000","size":30,"channel_id":23,"order_id":"10998904397395019553","flags":0,"ts_in_delta":1027,"sequence":189274,"symbol":"FCEU SI 20260615 PS"}
{"ts_recv":"2026-04-07T03:26:02.748818993Z","hd":{"ts_event":"2026-04-07T03:26:02.748797159Z","rtype":160,"publisher_id":101,"instrument_id":436},"action":"A","side":"B","price":"1.156630000","size":30,"channel_id":23,"order_id":"10998904399603579345","flags":0,"ts_in_delta":1027,"sequence":189274,"symbol":"FCEU SI 20260615 PS"}
{"ts_recv":"2026-04-07T03:26:02.748818993Z","hd":{"ts_event":"2026-04-07T03:26:02.748797159Z","rtype":160,"publisher_id":101,"instrument_id":436},"action":"C","side":"A","price":"1.156740000","size":30,"channel_id":23,"order_id":"1775532360540243745","flags":0,"ts_in_delta":1027,"sequence":189274,"symbol":"FCEU SI 20260615 PS"}
{"ts_recv":"2026-04-07T03:26:02.748818993Z","hd":{"ts_event":"2026-04-07T03:26:02.748797159Z","rtype":160,"publisher_id":101,"instrument_id":436},"action":"A","side":"A","price":"1.156730000","size":30,"channel_id":23,"order_id":"1775532362748803537","flags":128,"ts_in_delta":1027,"sequence":189274,"symbol":"FCEU SI 20260615 PS"}
{"ts_recv":"2026-04-07T03:26:02.748903246Z","hd":{"ts_event":"2026-04-07T03:26:02.748883425Z","rtype":160,"publisher_id":101,"instrument_id":436},"action":"C","side":"B","price":"1.156630000","size":30,"channel_id":23,"order_id":"10998904399603579345","flags":0,"ts_in_delta":992,"sequence":189275,"symbol":"FCEU SI 20260615 PS"}
{"ts_recv":"2026-04-07T03:26:02.748903246Z","hd":{"ts_event":"2026-04-07T03:26:02.748883425Z","rtype":160,"publisher_id":101,"instrument_id":436},"action":"A","side":"B","price":"1.156620000","size":30,"channel_id":23,"order_id":"10998904399603664819","flags":0,"ts_in_delta":992,"sequence":189275,"symbol":"FCEU SI 20260615 PS"}
{"ts_recv":"2026-04-07T03:26:02.748903246Z","hd":{"ts_event":"2026-04-07T03:26:02.748883425Z","rtype":160,"publisher_id":101,"instrument_id":436},"action":"C","side":"A","price":"1.156730000","size":30,"channel_id":23,"order_id":"1775532362748803537","flags":0,"ts_in_delta":992,"sequence":189275,"symbol":"FCEU SI 20260615 PS"}
{"ts_recv":"2026-04-07T03:26:02.748903246Z","hd":{"ts_event":"2026-04-07T03:26:02.748883425Z","rtype":160,"publisher_id":101,"instrument_id":436},"action":"A","side":"A","price":"1.156720000","size":30,"channel_id":23,"order_id":"1775532362748889011","flags":128,"ts_in_delta":992,"sequence":189275,"symbol":"FCEU SI 20260615 PS"}
{"ts_recv":"2026-04-07T03:26:02.748956312Z","hd":{"ts_event":"2026-04-07T03:26:02.748941583Z","rtype":160,"publisher_id":101,"instrument_id":436},"action":"C","side":"B","price":"1.156620000","size":30,"channel_id":23,"order_id":"10998904399603664819","flags":0,"ts_in_delta":994,"sequence":189276,"symbol":"FCEU SI 20260615 PS"}
{"ts_recv":"2026-04-07T03:26:02.748956312Z","hd":{"ts_event":"2026-04-07T03:26:02.748941583Z","rtype":160,"publisher_id":101,"instrument_id":436},"action":"A","side":"B","price":"1.156630000","size":30,"channel_id":23,"order_id":"10998904399603723129","flags":0,"ts_in_delta":994,"sequence":189276,"symbol":"FCEU SI 20260615 PS"}
{"ts_recv":"2026-04-07T03:26:02.748956312Z","hd":{"ts_event":"2026-04-07T03:26:02.748941583Z","rtype":160,"publisher_id":101,"instrument_id":436},"action":"C","side":"A","price":"1.156720000","size":30,"channel_id":23,"order_id":"1775532362748889011","flags":0,"ts_in_delta":994,"sequence":189276,"symbol":"FCEU SI 20260615 PS"}
{"ts_recv":"2026-04-07T03:26:02.748956312Z","hd":{"ts_event":"2026-04-07T03:26:02.748941583Z","rtype":160,"publisher_id":101,"instrument_id":436},"action":"A","side":"A","price":"1.156730000","size":30,"channel_id":23,"order_id":"1775532362748947321","flags":128,"ts_in_delta":994,"sequence":189276,"symbol":"FCEU SI 20260615 PS"}
{"ts_recv":"2026-04-07T03:26:09.007392399Z","hd":{"ts_event":"2026-04-07T03:26:09.007373345Z","rtype":160,"publisher_id":101,"instrument_id":436},"action":"C","side":"B","price":"1.156630000","size":30,"channel_id":23,"order_id":"10998904399603723129","flags":0,"ts_in_delta":1138,"sequence":189318,"symbol":"FCEU SI 20260615 PS"}
{"ts_recv":"2026-04-07T03:26:09.007392399Z","hd":{"ts_event":"2026-04-07T03:26:09.007373345Z","rtype":160,"publisher_id":101,"instrument_id":436},"action":"A","side":"B","price":"1.156640000","size":30,"channel_id":23,"order_id":"10998904405862155421","flags":0,"ts_in_delta":1138,"sequence":189318,"symbol":"FCEU SI 20260615 PS"}
{"ts_recv":"2026-04-07T03:26:09.007392399Z","hd":{"ts_event":"2026-04-07T03:26:09.007373345Z","rtype":160,"publisher_id":101,"instrument_id":436},"action":"C","side":"A","price":"1.156730000","size":30,"channel_id":23,"order_id":"1775532362748947321","flags":0,"ts_in_delta":1138,"sequence":189318,"symbol":"FCEU SI 20260615 PS"}
{"ts_recv":"2026-04-07T03:26:09.007392399Z","hd":{"ts_event":"2026-04-07T03:26:09.007373345Z","rtype":160,"publisher_id":101,"instrument_id":436},"action":"A","side":"A","price":"1.156740000","size":30,"channel_id":23,"order_id":"1775532369007379613","flags":128,"ts_in_delta":1138,"sequence":189318,"symbol":"FCEU SI 20260615 PS"}
{"ts_recv":"2026-04-07T03:26:19.826208584Z","hd":{"ts_event":"2026-04-07T03:26:19.826186377Z","rtype":160,"publisher_id":101,"instrument_id":436},"action":"C","side":"B","price":"1.156640000","size":30,"channel_id":23,"order_id":"10998904405862155421","flags":0,"ts_in_delta":944,"sequence":189366,"symbol":"FCEU SI 20260615 PS"}
{"ts_recv":"2026-04-07T03:26:19.826208584Z","hd":{"ts_event":"2026-04-07T03:26:19.826186377Z","rtype":160,"publisher_id":101,"instrument_id":436},"action":"A","side":"B","price":"1.156630000","size":30,"channel_id":23,"order_id":"10998904416680968483","flags":0,"ts_in_delta":944,"sequence":189366,"symbol":"FCEU SI 20260615 PS"}
{"ts_recv":"2026-04-07T03:26:19.826208584Z","hd":{"ts_event":"2026-04-07T03:26:19.826186377Z","rtype":160,"publisher_id":101,"instrument_id":436},"action":"C","side":"A","price":"1.156740000","size":30,"channel_id":23,"order_id":"1775532369007379613","flags":0,"ts_in_delta":944,"sequence":189366,"symbol":"FCEU SI 20260615 PS"}
{"ts_recv":"2026-04-07T03:26:19.826208584Z","hd":{"ts_event":"2026-04-07T03:26:19.826186377Z","rtype":160,"publisher_id":101,"instrument_id":436},"action":"A","side":"A","price":"1.156730000","size":30,"channel_id":23,"order_id":"1775532379826192675","flags":128,"ts_in_delta":944,"sequence":189366,"symbol":"FCEU SI 20260615 PS"}
{"ts_recv":"2026-04-07T03:26:24.901179738Z","hd":{"ts_event":"2026-04-07T03:26:24.901154169Z","rtype":160,"publisher_id":101,"instrument_id":436},"action":"C","side":"B","price":"1.156630000","size":30,"channel_id":23,"order_id":"10998904416680968483","flags":0,"ts_in_delta":1434,"sequence":189397,"symbol":"FCEU SI 20260615 PS"}
{"ts_recv":"2026-04-07T03:26:24.901179738Z","hd":{"ts_event":"2026-04-07T03:26:24.901154169Z","rtype":160,"publisher_id":101,"instrument_id":436},"action":"A","side":"B","price":"1.156640000","size":30,"channel_id":23,"order_id":"10998904421755941312","flags":0,"ts_in_delta":1434,"sequence":189397,"symbol":"FCEU SI 20260615 PS"}
{"ts_recv":"2026-04-07T03:26:24.901179738Z","hd":{"ts_event":"2026-04-07T03:26:24.901154169Z","rtype":160,"publisher_id":101,"instrument_id":436},"action":"C","side":"A","price":"1.156730000","size":30,"channel_id":23,"order_id":"1775532379826192675","flags":0,"ts_in_delta":1434,"sequence":189397,"symbol":"FCEU SI 20260615 PS"}
{"ts_recv":"2026-04-07T03:26:24.901179738Z","hd":{"ts_event":"2026-04-07T03:26:24.901154169Z","rtype":160,"publisher_id":101,"instrument_id":436},"action":"A","side":"A","price":"1.156740000","size":30,"channel_id":23,"order_id":"1775532384901165504","flags":128,"ts_in_delta":1434,"sequence":189397,"symbol":"FCEU SI 20260615 PS"}
{"ts_recv":"2026-04-07T03:26:37.824527238Z","hd":{"ts_event":"2026-04-07T03:26:37.824505695Z","rtype":160,"publisher_id":101,"instrument_id":436},"action":"C","side":"B","price":"1.156640000","size":30,"channel_id":23,"order_id":"10998904421755941312","flags":0,"ts_in_delta":989,"sequence":189460,"symbol":"FCEU SI 20260615 PS"}
{"ts_recv":"2026-04-07T03:26:37.824527238Z","hd":{"ts_event":"2026-04-07T03:26:37.824505695Z","rtype":160,"publisher_id":101,"instrument_id":436},"action":"A","side":"B","price":"1.156630000","size":30,"channel_id":23,"order_id":"10998904434679287467","flags":0,"ts_in_delta":989,"sequence":189460,"symbol":"FCEU SI 20260615 PS"}
{"ts_recv":"2026-04-07T03:26:37.824527238Z","hd":{"ts_event":"2026-04-07T03:26:37.824505695Z","rtype":160,"publisher_id":101,"instrument_id":436},"action":"C","side":"A","price":"1.156740000","size":30,"channel_id":23,"order_id":"1775532384901165504","flags":0,"ts_in_delta":989,"sequence":189460,"symbol":"FCEU SI 20260615 PS"}
{"ts_recv":"2026-04-07T03:26:37.824527238Z","hd":{"ts_event":"2026-04-07T03:26:37.824505695Z","rtype":160,"publisher_id":101,"instrument_id":436},"action":"A","side":"A","price":"1.156730000","size":30,"channel_id":23,"order_id":"1775532397824511659","flags":128,"ts_in_delta":989,"sequence":189460,"symbol":"FCEU SI 20260615 PS"}
{"ts_recv":"2026-04-07T03:26:37.824612122Z","hd":{"ts_event":"2026-04-07T03:26:37.824594207Z","rtype":160,"publisher_id":101,"instrument_id":436},"action":"C","side":"B","price":"1.156630000","size":30,"channel_id":23,"order_id":"10998904434679287467","flags":0,"ts_in_delta":986,"sequence":189461,"symbol":"FCEU SI 20260615 PS"}
{"ts_recv":"2026-04-07T03:26:37.824612122Z","hd":{"ts_event":"2026-04-07T03:26:37.824594207Z","rtype":160,"publisher_id":101,"instrument_id":436},"action":"A","side":"B","price":"1.156620000","size":30,"channel_id":23,"order_id":"10998904434679376281","flags":0,"ts_in_delta":986,"sequence":189461,"symbol":"FCEU SI 20260615 PS"}
{"ts_recv":"2026-04-07T03:26:37.824612122Z","hd":{"ts_event":"2026-04-07T03:26:37.824594207Z","rtype":160,"publisher_id":101,"instrument_id":436},"action":"C","side":"A","price":"1.156730000","size":30,"channel_id":23,"order_id":"1775532397824511659","flags":0,"ts_in_delta":986,"sequence":189461,"symbol":"FCEU SI 20260615 PS"}
{"ts_recv":"2026-04-07T03:26:37.824612122Z","hd":{"ts_event":"2026-04-07T03:26:37.824594207Z","rtype":160,"publisher_id":101,"instrument_id":436},"action":"A","side":"A","price":"1.156720000","size":30,"channel_id":23,"order_id":"1775532397824600473","flags":128,"ts_in_delta":986,"sequence":189461,"symbol":"FCEU SI 20260615 PS"}
{"ts_recv":"2026-04-07T03:26:37.824678774Z","hd":{"ts_event":"2026-04-07T03:26:37.824655135Z","rtype":160,"publisher_id":101,"instrument_id":436},"action":"C","side":"B","price":"1.156620000","size":30,"channel_id":23,"order_id":"10998904434679376281","flags":0,"ts_in_delta":1070,"sequence":189462,"symbol":"FCEU SI 20260615 PS"}
{"ts_recv":"2026-04-07T03:26:37.824678774Z","hd":{"ts_event":"2026-04-07T03:26:37.824655135Z","rtype":160,"publisher_id":101,"instrument_id":436},"action":"A","side":"B","price":"1.156630000","size":30,"channel_id":23,"order_id":"10998904434679437257","flags":0,"ts_in_delta":1070,"sequence":189462,"symbol":"FCEU SI 20260615 PS"}
{"ts_recv":"2026-04-07T03:26:37.824678774Z","hd":{"ts_event":"2026-04-07T03:26:37.824655135Z","rtype":160,"publisher_id":101,"instrument_id":436},"action":"C","side":"A","price":"1.156720000","size":30,"channel_id":23,"order_id":"1775532397824600473","flags":0,"ts_in_delta":1070,"sequence":189462,"symbol":"FCEU SI 20260615 PS"}
{"ts_recv":"2026-04-07T03:26:37.824678774Z","hd":{"ts_event":"2026-04-07T03:26:37.824655135Z","rtype":160,"publisher_id":101,"instrument_id":436},"action":"A","side":"A","price":"1.156730000","size":30,"channel_id":23,"order_id":"1775532397824661449","flags":128,"ts_in_delta":1070,"sequence":189462,"symbol":"FCEU SI 20260615 PS"}
{"ts_recv":"2026-04-07T03:26:46.681377947Z","hd":{"ts_event":"2026-04-07T03:26:46.681357815Z","rtype":160,"publisher_id":101,"instrument_id":436},"action":"C","side":"B","price":"1.156630000","size":30,"channel_id":23,"order_id":"10998904434679437257","flags":0,"ts_in_delta":928,"sequence":189504,"symbol":"FCEU SI 20260615 PS"}
{"ts_recv":"2026-04-07T03:26:46.681377947Z","hd":{"ts_event":"2026-04-07T03:26:46.681357815Z","rtype":160,"publisher_id":101,"instrument_id":436},"action":"A","side":"B","price":"1.156640000","size":30,"channel_id":23,"order_id":"10998904443536139972","flags":0,"ts_in_delta":928,"sequence":189504,"symbol":"FCEU SI 20260615 PS"}
{"ts_recv":"2026-04-07T03:26:46.681377947Z","hd":{"ts_event":"2026-04-07T03:26:46.681357815Z","rtype":160,"publisher_id":101,"instrument_id":436},"action":"C","side":"A","price":"1.156730000","size":30,"channel_id":23,"order_id":"1775532397824661449","flags":0,"ts_in_delta":928,"sequence":189504,"symbol":"FCEU SI 20260615 PS"}
{"ts_recv":"2026-04-07T03:26:46.681377947Z","hd":{"ts_event":"2026-04-07T03:26:46.681357815Z","rtype":160,"publisher_id":101,"instrument_id":436},"action":"A","side":"A","price":"1.156740000","size":30,"channel_id":23,"order_id":"1775532406681364164","flags":128,"ts_in_delta":928,"sequence":189504,"symbol":"FCEU SI 20260615 PS"}
{"ts_recv":"2026-04-07T03:27:03.542160780Z","hd":{"ts_event":"2026-04-07T03:27:03.542136735Z","rtype":160,"publisher_id":101,"instrument_id":436},"action":"C","side":"B","price":"1.156640000","size":30,"channel_id":23,"order_id":"10998904443536139972","flags":0,"ts_in_delta":1001,"sequence":189602,"symbol":"FCEU SI 20260615 PS"}
{"ts_recv":"2026-04-07T03:27:03.542160780Z","hd":{"ts_event":"2026-04-07T03:27:03.542136735Z","rtype":160,"publisher_id":101,"instrument_id":436},"action":"A","side":"B","price":"1.156650000","size":30,"channel_id":23,"order_id":"10998904460396918909","flags":0,"ts_in_delta":1001,"sequence":189602,"symbol":"FCEU SI 20260615 PS"}
{"ts_recv":"2026-04-07T03:27:03.542160780Z","hd":{"ts_event":"2026-04-07T03:27:03.542136735Z","rtype":160,"publisher_id":101,"instrument_id":436},"action":"C","side":"A","price":"1.156740000","size":30,"channel_id":23,"order_id":"1775532406681364164","flags":0,"ts_in_delta":1001,"sequence":189602,"symbol":"FCEU SI 20260615 PS"}
{"ts_recv":"2026-04-07T03:27:03.542160780Z","hd":{"ts_event":"2026-04-07T03:27:03.542136735Z","rtype":160,"publisher_id":101,"instrument_id":436},"action":"A","side":"A","price":"1.156750000","size":30,"channel_id":23,"order_id":"1775532423542143101","flags":128,"ts_in_delta":1001,"sequence":189602,"symbol":"FCEU SI 20260615 PS"}
{"ts_recv":"2026-04-07T03:27:03.542222086Z","hd":{"ts_event":"2026-04-07T03:27:03.542202975Z","rtype":160,"publisher_id":101,"instrument_id":436},"action":"C","side":"B","price":"1.156640000","size":30,"channel_id":23,"order_id":"10998904397394951474","flags":0,"ts_in_delta":934,"sequence":189603,"symbol":"FCEU SI 20260615 PS"}
{"ts_recv":"2026-04-07T03:27:03.542222086Z","hd":{"ts_event":"2026-04-07T03:27:03.542202975Z","rtype":160,"publisher_id":101,"instrument_id":436},"action":"A","side":"B","price":"1.156660000","size":30,"channel_id":23,"order_id":"10998904460396985008","flags":0,"ts_in_delta":934,"sequence":189603,"symbol":"FCEU SI 20260615 PS"}
{"ts_recv":"2026-04-07T03:27:03.542222086Z","hd":{"ts_event":"2026-04-07T03:27:03.542202975Z","rtype":160,"publisher_id":101,"instrument_id":436},"action":"C","side":"A","price":"1.156740000","size":30,"channel_id":23,"order_id":"1775532360540175666","flags":0,"ts_in_delta":934,"sequence":189603,"symbol":"FCEU SI 20260615 PS"}
{"ts_recv":"2026-04-07T03:27:03.542222086Z","hd":{"ts_event":"2026-04-07T03:27:03.542202975Z","rtype":160,"publisher_id":101,"instrument_id":436},"action":"A","side":"A","price":"1.156760000","size":30,"channel_id":23,"order_id":"1775532423542209200","flags":128,"ts_in_delta":934,"sequence":189603,"symbol":"FCEU SI 20260615 PS"}
{"ts_recv":"2026-04-07T03:27:03.542277326Z","hd":{"ts_event":"2026-04-07T03:27:03.542258963Z","rtype":160,"publisher_id":101,"instrument_id":436},"action":"C","side":"B","price":"1.156650000","size":30,"channel_id":23,"order_id":"10998904460396918909","flags":0,"ts_in_delta":1037,"sequence":189604,"symbol":"FCEU SI 20260615 PS"}
{"ts_recv":"2026-04-07T03:27:03.542277326Z","hd":{"ts_event":"2026-04-07T03:27:03.542258963Z","rtype":160,"publisher_id":101,"instrument_id":436},"action":"A","side":"B","price":"1.156660000","size":30,"channel_id":23,"order_id":"10998904460397040436","flags":0,"ts_in_delta":1037,"sequence":189604,"symbol":"FCEU SI 20260615 PS"}
{"ts_recv":"2026-04-07T03:27:03.542277326Z","hd":{"ts_event":"2026-04-07T03:27:03.542258963Z","rtype":160,"publisher_id":101,"instrument_id":436},"action":"C","side":"A","price":"1.156750000","size":30,"channel_id":23,"order_id":"1775532423542143101","flags":0,"ts_in_delta":1037,"sequence":189604,"symbol":"FCEU SI 20260615 PS"}
{"ts_recv":"2026-04-07T03:27:03.542277326Z","hd":{"ts_event":"2026-04-07T03:27:03.542258963Z","rtype":160,"publisher_id":101,"instrument_id":436},"action":"A","side":"A","price":"1.156760000","size":30,"channel_id":23,"order_id":"1775532423542264628","flags":128,"ts_in_delta":1037,"sequence":189604,"symbol":"FCEU SI 20260615 PS"}
{"ts_recv":"2026-04-07T03:27:11.098265514Z","hd":{"ts_event":"2026-04-07T03:27:11.098233395Z","rtype":160,"publisher_id":101,"instrument_id":436},"action":"C","side":"B","price":"1.156660000","size":30,"channel_id":23,"order_id":"10998904460397040436","flags":0,"ts_in_delta":1446,"sequence":189688,"symbol":"FCEU SI 20260615 PS"}
{"ts_recv":"2026-04-07T03:27:11.098265514Z","hd":{"ts_event":"2026-04-07T03:27:11.098233395Z","rtype":160,"publisher_id":101,"instrument_id":436},"action":"A","side":"B","price":"1.156670000","size":30,"channel_id":23,"order_id":"10998904467953022912","flags":0,"ts_in_delta":1446,"sequence":189688,"symbol":"FCEU SI 20260615 PS"}
{"ts_recv":"2026-04-07T03:27:11.098265514Z","hd":{"ts_event":"2026-04-07T03:27:11.098233395Z","rtype":160,"publisher_id":101,"instrument_id":436},"action":"C","side":"A","price":"1.156760000","size":30,"channel_id":23,"order_id":"1775532423542264628","flags":0,"ts_in_delta":1446,"sequence":189688,"symbol":"FCEU SI 20260615 PS"}
{"ts_recv":"2026-04-07T03:27:11.098265514Z","hd":{"ts_event":"2026-04-07T03:27:11.098233395Z","rtype":160,"publisher_id":101,"instrument_id":436},"action":"A","side":"A","price":"1.156770000","size":30,"channel_id":23,"order_id":"1775532431098247104","flags":128,"ts_in_delta":1446,"sequence":189688,"symbol":"FCEU SI 20260615 PS"}
{"ts_recv":"2026-04-07T03:27:11.098348861Z","hd":{"ts_event":"2026-04-07T03:27:11.098330535Z","rtype":160,"publisher_id":101,"instrument_id":436},"action":"C","side":"B","price":"1.156670000","size":30,"channel_id":23,"order_id":"10998904467953022912","flags":0,"ts_in_delta":988,"sequence":189689,"symbol":"FCEU SI 20260615 PS"}
{"ts_recv":"2026-04-07T03:27:11.098348861Z","hd":{"ts_event":"2026-04-07T03:27:11.098330535Z","rtype":160,"publisher_id":101,"instrument_id":436},"action":"A","side":"B","price":"1.156680000","size":30,"channel_id":23,"order_id":"10998904467953112401","flags":0,"ts_in_delta":988,"sequence":189689,"symbol":"FCEU SI 20260615 PS"}
{"ts_recv":"2026-04-07T03:27:11.098348861Z","hd":{"ts_event":"2026-04-07T03:27:11.098330535Z","rtype":160,"publisher_id":101,"instrument_id":436},"action":"C","side":"A","price":"1.156770000","size":30,"channel_id":23,"order_id":"1775532431098247104","flags":0,"ts_in_delta":988,"sequence":189689,"symbol":"FCEU SI 20260615 PS"}
{"ts_recv":"2026-04-07T03:27:11.098348861Z","hd":{"ts_event":"2026-04-07T03:27:11.098330535Z","rtype":160,"publisher_id":101,"instrument_id":436},"action":"A","side":"A","price":"1.156780000","size":30,"channel_id":23,"order_id":"1775532431098336593","flags":128,"ts_in_delta":988,"sequence":189689,"symbol":"FCEU SI 20260615 PS"}
{"ts_recv":"2026-04-07T03:27:11.098409231Z","hd":{"ts_event":"2026-04-07T03:27:11.098392199Z","rtype":160,"publisher_id":101,"instrument_id":436},"action":"C","side":"B","price":"1.156660000","size":30,"channel_id":23,"order_id":"10998904460396985008","flags":0,"ts_in_delta":927,"sequence":189690,"symbol":"FCEU SI 20260615 PS"}
{"ts_recv":"2026-04-07T03:27:11.098409231Z","hd":{"ts_event":"2026-04-07T03:27:11.098392199Z","rtype":160,"publisher_id":101,"instrument_id":436},"action":"A","side":"B","price":"1.156680000","size":30,"channel_id":23,"order_id":"10998904467953174546","flags":0,"ts_in_delta":927,"sequence":189690,"symbol":"FCEU SI 20260615 PS"}
{"ts_recv":"2026-04-07T03:27:11.098409231Z","hd":{"ts_event":"2026-04-07T03:27:11.098392199Z","rtype":160,"publisher_id":101,"instrument_id":436},"action":"C","side":"A","price":"1.156760000","size":30,"channel_id":23,"order_id":"1775532423542209200","flags":0,"ts_in_delta":927,"sequence":189690,"symbol":"FCEU SI 20260615 PS"}
{"ts_recv":"2026-04-07T03:27:11.098409231Z","hd":{"ts_event":"2026-04-07T03:27:11.098392199Z","rtype":160,"publisher_id":101,"instrument_id":436},"action":"A","side":"A","price":"1.156780000","size":30,"channel_id":23,"order_id":"1775532431098398738","flags":128,"ts_in_delta":927,"sequence":189690,"symbol":"FCEU SI 20260615 PS"}
{"ts_recv":"2026-04-07T03:27:11.098421595Z","hd":{"ts_event":"2026-04-07T03:27:11.098392411Z","rtype":160,"publisher_id":101,"instrument_id":436},"action":"C","side":"B","price":"1.156680000","size":30,"channel_id":23,"order_id":"10998904467953112401","flags":0,"ts_in_delta":1159,"sequence":189691,"symbol":"FCEU SI 20260615 PS"}
{"ts_recv":"2026-04-07T03:27:11.098421595Z","hd":{"ts_event":"2026-04-07T03:27:11.098392411Z","rtype":160,"publisher_id":101,"instrument_id":436},"action":"A","side":"B","price":"1.156670000","size":30,"channel_id":23,"order_id":"10998904467953181876","flags":0,"ts_in_delta":1159,"sequence":189691,"symbol":"FCEU SI 20260615 PS"}
{"ts_recv":"2026-04-07T03:27:11.098421595Z","hd":{"ts_event":"2026-04-07T03:27:11.098392411Z","rtype":160,"publisher_id":101,"instrument_id":436},"action":"C","side":"A","price":"1.156780000","size":30,"channel_id":23,"order_id":"1775532431098336593","flags":0,"ts_in_delta":1159,"sequence":189691,"symbol":"FCEU SI 20260615 PS"}
{"ts_recv":"2026-04-07T03:27:11.098421595Z","hd":{"ts_event":"2026-04-07T03:27:11.098392411Z","rtype":160,"publisher_id":101,"instrument_id":436},"action":"A","side":"A","price":"1.156770000","size":30,"channel_id":23,"order_id":"1775532431098406068","flags":128,"ts_in_delta":1159,"sequence":189691,"symbol":"FCEU SI 20260615 PS"}
{"ts_recv":"2026-04-07T03:27:11.098476827Z","hd":{"ts_event":"2026-04-07T03:27:11.098457095Z","rtype":160,"publisher_id":101,"instrument_id":436},"action":"C","side":"B","price":"1.156670000","size":30,"channel_id":23,"order_id":"10998904467953181876","flags":0,"ts_in_delta":1048,"sequence":189692,"symbol":"FCEU SI 20260615 PS"}
{"ts_recv":"2026-04-07T03:27:11.098476827Z","hd":{"ts_event":"2026-04-07T03:27:11.098457095Z","rtype":160,"publisher_id":101,"instrument_id":436},"action":"A","side":"B","price":"1.156680000","size":30,"channel_id":23,"order_id":"10998904467953239237","flags":0,"ts_in_delta":1048,"sequence":189692,"symbol":"FCEU SI 20260615 PS"}
{"ts_recv":"2026-04-07T03:27:11.098476827Z","hd":{"ts_event":"2026-04-07T03:27:11.098457095Z","rtype":160,"publisher_id":101,"instrument_id":436},"action":"C","side":"A","price":"1.156770000","size":30,"channel_id":23,"order_id":"1775532431098406068","flags":0,"ts_in_delta":1048,"sequence":189692,"symbol":"FCEU SI 20260615 PS"}
{"ts_recv":"2026-04-07T03:27:11.098476827Z","hd":{"ts_event":"2026-04-07T03:27:11.098457095Z","rtype":160,"publisher_id":101,"instrument_id":436},"action":"A","side":"A","price":"1.156780000","size":30,"channel_id":23,"order_id":"1775532431098463429","flags":128,"ts_in_delta":1048,"sequence":189692,"symbol":"FCEU SI 20260615 PS"}
{"ts_recv":"2026-04-07T03:27:11.104348732Z","hd":{"ts_event":"2026-04-07T03:27:11.104326753Z","rtype":160,"publisher_id":101,"instrument_id":436},"action":"C","side":"B","price":"1.156680000","size":30,"channel_id":23,"order_id":"10998904467953239237","flags":0,"ts_in_delta":1069,"sequence":189693,"symbol":"FCEU SI 20260615 PS"}
{"ts_recv":"2026-04-07T03:27:11.104348732Z","hd":{"ts_event":"2026-04-07T03:27:11.104326753Z","rtype":160,"publisher_id":101,"instrument_id":436},"action":"A","side":"B","price":"1.156690000","size":30,"channel_id":23,"order_id":"10998904467959108636","flags":0,"ts_in_delta":1069,"sequence":189693,"symbol":"FCEU SI 20260615 PS"}
{"ts_recv":"2026-04-07T03:27:11.104348732Z","hd":{"ts_event":"2026-04-07T03:27:11.104326753Z","rtype":160,"publisher_id":101,"instrument_id":436},"action":"C","side":"A","price":"1.156780000","size":30,"channel_id":23,"order_id":"1775532431098463429","flags":0,"ts_in_delta":1069,"sequence":189693,"symbol":"FCEU SI 20260615 PS"}
{"ts_recv":"2026-04-07T03:27:11.104348732Z","hd":{"ts_event":"2026-04-07T03:27:11.104326753Z","rtype":160,"publisher_id":101,"instrument_id":436},"action":"A","side":"A","price":"1.156790000","size":30,"channel_id":23,"order_id":"1775532431104332828","flags":128,"ts_in_delta":1069,"sequence":189693,"symbol":"FCEU SI 20260615 PS"}
{"ts_recv":"2026-04-07T03:27:11.147856024Z","hd":{"ts_event":"2026-04-07T03:27:11.147840493Z","rtype":160,"publisher_id":101,"instrument_id":436},"action":"A","side":"B","price":"1.156600000","size":20,"channel_id":23,"order_id":"10998904468002622535","flags":128,"ts_in_delta":910,"sequence":189702,"symbol":"FCEU SI 20260615 PS"}
{"ts_recv":"2026-04-07T03:27:11.147899529Z","hd":{"ts_event":"2026-04-07T03:27:11.147884717Z","rtype":160,"publisher_id":101,"instrument_id":436},"action":"C","side":"B","price":"1.156500000","size":20,"channel_id":23,"order_id":"10998904374184883287","flags":128,"ts_in_delta":907,"sequence":189704,"symbol":"FCEU SI 20260615 PS"}
{"ts_recv":"2026-04-07T03:27:18.568928062Z","hd":{"ts_event":"2026-04-07T03:27:18.568906377Z","rtype":160,"publisher_id":101,"instrument_id":436},"action":"C","side":"B","price":"1.156690000","size":30,"channel_id":23,"order_id":"10998904467959108636","flags":0,"ts_in_delta":1071,"sequence":189730,"symbol":"FCEU SI 20260615 PS"}
{"ts_recv":"2026-04-07T03:27:18.568928062Z","hd":{"ts_event":"2026-04-07T03:27:18.568906377Z","rtype":160,"publisher_id":101,"instrument_id":436},"action":"A","side":"B","price":"1.156680000","size":30,"channel_id":23,"order_id":"10998904475423688825","flags":0,"ts_in_delta":1071,"sequence":189730,"symbol":"FCEU SI 20260615 PS"}
{"ts_recv":"2026-04-07T03:27:18.568928062Z","hd":{"ts_event":"2026-04-07T03:27:18.568906377Z","rtype":160,"publisher_id":101,"instrument_id":436},"action":"C","side":"A","price":"1.156790000","size":30,"channel_id":23,"order_id":"1775532431104332828","flags":0,"ts_in_delta":1071,"sequence":189730,"symbol":"FCEU SI 20260615 PS"}
{"ts_recv":"2026-04-07T03:27:18.568928062Z","hd":{"ts_event":"2026-04-07T03:27:18.568906377Z","rtype":160,"publisher_id":101,"instrument_id":436},"action":"A","side":"A","price":"1.156780000","size":30,"channel_id":23,"order_id":"1775532438568913017","flags":128,"ts_in_delta":1071,"sequence":189730,"symbol":"FCEU SI 20260615 PS"}
{"ts_recv":"2026-04-07T03:27:30.392458479Z","hd":{"ts_event":"2026-04-07T03:27:30.392437327Z","rtype":160,"publisher_id":101,"instrument_id":436},"action":"C","side":"B","price":"1.156680000","size":30,"channel_id":23,"order_id":"10998904475423688825","flags":0,"ts_in_delta":961,"sequence":189857,"symbol":"FCEU SI 20260615 PS"}
{"ts_recv":"2026-04-07T03:27:30.392458479Z","hd":{"ts_event":"2026-04-07T03:27:30.392437327Z","rtype":160,"publisher_id":101,"instrument_id":436},"action":"A","side":"B","price":"1.156670000","size":30,"channel_id":23,"order_id":"10998904487247219202","flags":0,"ts_in_delta":961,"sequence":189857,"symbol":"FCEU SI 20260615 PS"}
{"ts_recv":"2026-04-07T03:27:30.392458479Z","hd":{"ts_event":"2026-04-07T03:27:30.392437327Z","rtype":160,"publisher_id":101,"instrument_id":436},"action":"C","side":"A","price":"1.156780000","size":30,"channel_id":23,"order_id":"1775532438568913017","flags":0,"ts_in_delta":961,"sequence":189857,"symbol":"FCEU SI 20260615 PS"}
{"ts_recv":"2026-04-07T03:27:30.392458479Z","hd":{"ts_event":"2026-04-07T03:27:30.392437327Z","rtype":160,"publisher_id":101,"instrument_id":436},"action":"A","side":"A","price":"1.156770000","size":30,"channel_id":23,"order_id":"1775532450392443394","flags":128,"ts_in_delta":961,"sequence":189857,"symbol":"FCEU SI 20260615 PS"}
{"ts_recv":"2026-04-07T03:27:30.392988951Z","hd":{"ts_event":"2026-04-07T03:27:30.392970223Z","rtype":160,"publisher_id":101,"instrument_id":436},"action":"C","side":"B","price":"1.156680000","size":30,"channel_id":23,"order_id":"10998904467953174546","flags":0,"ts_in_delta":917,"sequence":189858,"symbol":"FCEU SI 20260615 PS"}
{"ts_recv":"2026-04-07T03:27:30.392988951Z","hd":{"ts_event":"2026-04-07T03:27:30.392970223Z","rtype":160,"publisher_id":101,"instrument_id":436},"action":"A","side":"B","price":"1.156660000","size":30,"channel_id":23,"order_id":"10998904487247752385","flags":0,"ts_in_delta":917,"sequence":189858,"symbol":"FCEU SI 20260615 PS"}
{"ts_recv":"2026-04-07T03:27:30.392988951Z","hd":{"ts_event":"2026-04-07T03:27:30.392970223Z","rtype":160,"publisher_id":101,"instrument_id":436},"action":"C","side":"A","price":"1.156780000","size":30,"channel_id":23,"order_id":"1775532431098398738","flags":0,"ts_in_delta":917,"sequence":189858,"symbol":"FCEU SI 20260615 PS"}
{"ts_recv":"2026-04-07T03:27:30.392988951Z","hd":{"ts_event":"2026-04-07T03:27:30.392970223Z","rtype":160,"publisher_id":101,"instrument_id":436},"action":"A","side":"A","price":"1.156760000","size":30,"channel_id":23,"order_id":"1775532450392976577","flags":128,"ts_in_delta":917,"sequence":189858,"symbol":"FCEU SI 20260615 PS"}
{"ts_recv":"2026-04-07T03:27:30.393055756Z","hd":{"ts_event":"2026-04-07T03:27:30.393036621Z","rtype":160,"publisher_id":101,"instrument_id":436},"action":"C","side":"B","price":"1.156670000","size":30,"channel_id":23,"order_id":"10998904487247219202","flags":0,"ts_in_delta":942,"sequence":189859,"symbol":"FCEU SI 20260615 PS"}
{"ts_recv":"2026-04-07T03:27:30.393055756Z","hd":{"ts_event":"2026-04-07T03:27:30.393036621Z","rtype":160,"publisher_id":101,"instrument_id":436},"action":"A","side":"B","price":"1.156660000","size":30,"channel_id":23,"order_id":"10998904487247818481","flags":0,"ts_in_delta":942,"sequence":189859,"symbol":"FCEU SI 20260615 PS"}
{"ts_recv":"2026-04-07T03:27:30.393055756Z","hd":{"ts_event":"2026-04-07T03:27:30.393036621Z","rtype":160,"publisher_id":101,"instrument_id":436},"action":"C","side":"A","price":"1.156770000","size":30,"channel_id":23,"order_id":"1775532450392443394","flags":0,"ts_in_delta":942,"sequence":189859,"symbol":"FCEU SI 20260615 PS"}
{"ts_recv":"2026-04-07T03:27:30.393055756Z","hd":{"ts_event":"2026-04-07T03:27:30.393036621Z","rtype":160,"publisher_id":101,"instrument_id":436},"action":"A","side":"A","price":"1.156760000","size":30,"channel_id":23,"order_id":"1775532450393042673","flags":128,"ts_in_delta":942,"sequence":189859,"symbol":"FCEU SI 20260615 PS"}
{"ts_recv":"2026-04-07T03:27:30.585533139Z","hd":{"ts_event":"2026-04-07T03:27:30.585514009Z","rtype":160,"publisher_id":101,"instrument_id":436},"action":"C","side":"B","price":"1.156660000","size":30,"channel_id":23,"order_id":"10998904487247818481","flags":0,"ts_in_delta":758,"sequence":189907,"symbol":"FCEU SI 20260615 PS"}
{"ts_recv":"2026-04-07T03:27:30.585533139Z","hd":{"ts_event":"2026-04-07T03:27:30.585514009Z","rtype":160,"publisher_id":101,"instrument_id":436},"action":"A","side":"B","price":"1.156670000","size":30,"channel_id":23,"order_id":"10998904487440296062","flags":0,"ts_in_delta":758,"sequence":189907,"symbol":"FCEU SI 20260615 PS"}
{"ts_recv":"2026-04-07T03:27:30.585533139Z","hd":{"ts_event":"2026-04-07T03:27:30.585514009Z","rtype":160,"publisher_id":101,"instrument_id":436},"action":"C","side":"A","price":"1.156760000","size":30,"channel_id":23,"order_id":"1775532450393042673","flags":0,"ts_in_delta":758,"sequence":189907,"symbol":"FCEU SI 20260615 PS"}
{"ts_recv":"2026-04-07T03:27:30.585533139Z","hd":{"ts_event":"2026-04-07T03:27:30.585514009Z","rtype":160,"publisher_id":101,"instrument_id":436},"action":"A","side":"A","price":"1.156770000","size":30,"channel_id":23,"order_id":"1775532450585520254","flags":128,"ts_in_delta":758,"sequence":189907,"symbol":"FCEU SI 20260615 PS"}
{"ts_recv":"2026-04-07T03:27:30.645245190Z","hd":{"ts_event":"2026-04-07T03:27:30.645228773Z","rtype":160,"publisher_id":101,"instrument_id":436},"action":"C","side":"B","price":"1.156670000","size":30,"channel_id":23,"order_id":"10998904487440296062","flags":0,"ts_in_delta":1214,"sequence":189912,"symbol":"FCEU SI 20260615 PS"}
{"ts_recv":"2026-04-07T03:27:30.645245190Z","hd":{"ts_event":"2026-04-07T03:27:30.645228773Z","rtype":160,"publisher_id":101,"instrument_id":436},"action":"A","side":"B","price":"1.156660000","size":30,"channel_id":23,"order_id":"10998904487500010781","flags":0,"ts_in_delta":1214,"sequence":189912,"symbol":"FCEU SI 20260615 PS"}
{"ts_recv":"2026-04-07T03:27:30.645245190Z","hd":{"ts_event":"2026-04-07T03:27:30.645228773Z","rtype":160,"publisher_id":101,"instrument_id":436},"action":"C","side":"A","price":"1.156770000","size":30,"channel_id":23,"order_id":"1775532450585520254","flags":0,"ts_in_delta":1214,"sequence":189912,"symbol":"FCEU SI 20260615 PS"}
{"ts_recv":"2026-04-07T03:27:30.645245190Z","hd":{"ts_event":"2026-04-07T03:27:30.645228773Z","rtype":160,"publisher_id":101,"instrument_id":436},"action":"A","side":"A","price":"1.156760000","size":30,"channel_id":23,"order_id":"1775532450645234973","flags":128,"ts_in_delta":1214,"sequence":189912,"symbol":"FCEU SI 20260615 PS"}
{"ts_recv":"2026-04-07T03:27:38.713386505Z","hd":{"ts_event":"2026-04-07T03:27:38.713350079Z","rtype":160,"publisher_id":101,"instrument_id":436},"action":"C","side":"B","price":"1.156660000","size":30,"channel_id":23,"order_id":"10998904487500010781","flags":0,"ts_in_delta":1751,"sequence":189943,"symbol":"FCEU SI 20260615 PS"}
{"ts_recv":"2026-04-07T03:27:38.713386505Z","hd":{"ts_event":"2026-04-07T03:27:38.713350079Z","rtype":160,"publisher_id":101,"instrument_id":436},"action":"A","side":"B","price":"1.156670000","size":30,"channel_id":23,"order_id":"10998904495568140249","flags":0,"ts_in_delta":1751,"sequence":189943,"symbol":"FCEU SI 20260615 PS"}
{"ts_recv":"2026-04-07T03:27:38.713386505Z","hd":{"ts_event":"2026-04-07T03:27:38.713350079Z","rtype":160,"publisher_id":101,"instrument_id":436},"action":"C","side":"A","price":"1.156760000","size":30,"channel_id":23,"order_id":"1775532450645234973","flags":0,"ts_in_delta":1751,"sequence":189943,"symbol":"FCEU SI 20260615 PS"}
{"ts_recv":"2026-04-07T03:27:38.713386505Z","hd":{"ts_event":"2026-04-07T03:27:38.713350079Z","rtype":160,"publisher_id":101,"instrument_id":436},"action":"A","side":"A","price":"1.156770000","size":30,"channel_id":23,"order_id":"1775532458713364441","flags":128,"ts_in_delta":1751,"sequence":189943,"symbol":"FCEU SI 20260615 PS"}
{"ts_recv":"2026-04-07T03:27:42.180014205Z","hd":{"ts_event":"2026-04-07T03:27:42.179979165Z","rtype":160,"publisher_id":101,"instrument_id":436},"action":"C","side":"B","price":"1.156660000","size":30,"channel_id":23,"order_id":"10998904487247752385","flags":0,"ts_in_delta":1200,"sequence":189963,"symbol":"FCEU SI 20260615 PS"}
{"ts_recv":"2026-04-07T03:27:42.180014205Z","hd":{"ts_event":"2026-04-07T03:27:42.179979165Z","rtype":160,"publisher_id":101,"instrument_id":436},"action":"A","side":"B","price":"1.156680000","size":30,"channel_id":23,"order_id":"10998904499034769633","flags":0,"ts_in_delta":1200,"sequence":189963,"symbol":"FCEU SI 20260615 PS"}
{"ts_recv":"2026-04-07T03:27:42.180014205Z","hd":{"ts_event":"2026-04-07T03:27:42.179979165Z","rtype":160,"publisher_id":101,"instrument_id":436},"action":"C","side":"A","price":"1.156760000","size":30,"channel_id":23,"order_id":"1775532450392976577","flags":0,"ts_in_delta":1200,"sequence":189963,"symbol":"FCEU SI 20260615 PS"}
{"ts_recv":"2026-04-07T03:27:42.180014205Z","hd":{"ts_event":"2026-04-07T03:27:42.179979165Z","rtype":160,"publisher_id":101,"instrument_id":436},"action":"A","side":"A","price":"1.156780000","size":30,"channel_id":23,"order_id":"1775532462179993825","flags":128,"ts_in_delta":1200,"sequence":189963,"symbol":"FCEU SI 20260615 PS"}
{"ts_recv":"2026-04-07T03:27:42.180123602Z","hd":{"ts_event":"2026-04-07T03:27:42.180107261Z","rtype":160,"publisher_id":101,"instrument_id":436},"action":"C","side":"B","price":"1.156670000","size":30,"channel_id":23,"order_id":"10998904495568140249","flags":0,"ts_in_delta":920,"sequence":189964,"symbol":"FCEU SI 20260615 PS"}
{"ts_recv":"2026-04-07T03:27:42.180123602Z","hd":{"ts_event":"2026-04-07T03:27:42.180107261Z","rtype":160,"publisher_id":101,"instrument_id":436},"action":"A","side":"B","price":"1.156680000","size":30,"channel_id":23,"order_id":"10998904499034889089","flags":0,"ts_in_delta":920,"sequence":189964,"symbol":"FCEU SI 20260615 PS"}
{"ts_recv":"2026-04-07T03:27:42.180123602Z","hd":{"ts_event":"2026-04-07T03:27:42.180107261Z","rtype":160,"publisher_id":101,"instrument_id":436},"action":"C","side":"A","price":"1.156770000","size":30,"channel_id":23,"order_id":"1775532458713364441","flags":0,"ts_in_delta":920,"sequence":189964,"symbol":"FCEU SI 20260615 PS"}
{"ts_recv":"2026-04-07T03:27:42.180123602Z","hd":{"ts_event":"2026-04-07T03:27:42.180107261Z","rtype":160,"publisher_id":101,"instrument_id":436},"action":"A","side":"A","price":"1.156780000","size":30,"channel_id":23,"order_id":"1775532462180113281","flags":128,"ts_in_delta":920,"sequence":189964,"symbol":"FCEU SI 20260615 PS"}
{"ts_recv":"2026-04-07T03:28:28.177765568Z","hd":{"ts_event":"2026-04-07T03:28:28.177727233Z","rtype":160,"publisher_id":101,"instrument_id":436},"action":"C","side":"B","price":"1.156680000","size":30,"channel_id":23,"order_id":"10998904499034889089","flags":0,"ts_in_delta":1508,"sequence":190190,"symbol":"FCEU SI 20260615 PS"}
{"ts_recv":"2026-04-07T03:28:28.177765568Z","hd":{"ts_event":"2026-04-07T03:28:28.177727233Z","rtype":160,"publisher_id":101,"instrument_id":436},"action":"A","side":"B","price":"1.156690000","size":30,"channel_id":23,"order_id":"10998904545032516637","flags":0,"ts_in_delta":1508,"sequence":190190,"symbol":"FCEU SI 20260615 PS"}
{"ts_recv":"2026-04-07T03:28:28.177765568Z","hd":{"ts_event":"2026-04-07T03:28:28.177727233Z","rtype":160,"publisher_id":101,"instrument_id":436},"action":"C","side":"A","price":"1.156780000","size":30,"channel_id":23,"order_id":"1775532462180113281","flags":0,"ts_in_delta":1508,"sequence":190190,"symbol":"FCEU SI 20260615 PS"}
{"ts_recv":"2026-04-07T03:28:28.177765568Z","hd":{"ts_event":"2026-04-07T03:28:28.177727233Z","rtype":160,"publisher_id":101,"instrument_id":436},"action":"A","side":"A","price":"1.156790000","size":30,"channel_id":23,"order_id":"1775532508177740829","flags":128,"ts_in_delta":1508,"sequence":190190,"symbol":"FCEU SI 20260615 PS"}
{"ts_recv":"2026-04-07T03:28:33.608048989Z","hd":{"ts_event":"2026-04-07T03:28:33.608029197Z","rtype":160,"publisher_id":101,"instrument_id":436},"action":"C","side":"B","price":"1.156680000","size":30,"channel_id":23,"order_id":"10998904499034769633","flags":0,"ts_in_delta":993,"sequence":190214,"symbol":"FCEU SI 20260615 PS"}
{"ts_recv":"2026-04-07T03:28:33.608048989Z","hd":{"ts_event":"2026-04-07T03:28:33.608029197Z","rtype":160,"publisher_id":101,"instrument_id":436},"action":"A","side":"B","price":"1.156700000","size":30,"channel_id":23,"order_id":"10998904550462811678","flags":0,"ts_in_delta":993,"sequence":190214,"symbol":"FCEU SI 20260615 PS"}
{"ts_recv":"2026-04-07T03:28:33.608048989Z","hd":{"ts_event":"2026-04-07T03:28:33.608029197Z","rtype":160,"publisher_id":101,"instrument_id":436},"action":"C","side":"A","price":"1.156780000","size":30,"channel_id":23,"order_id":"1775532462179993825","flags":0,"ts_in_delta":993,"sequence":190214,"symbol":"FCEU SI 20260615 PS"}
{"ts_recv":"2026-04-07T03:28:33.608048989Z","hd":{"ts_event":"2026-04-07T03:28:33.608029197Z","rtype":160,"publisher_id":101,"instrument_id":436},"action":"A","side":"A","price":"1.156800000","size":30,"channel_id":23,"order_id":"1775532513608035870","flags":128,"ts_in_delta":993,"sequence":190214,"symbol":"FCEU SI 20260615 PS"}
{"ts_recv":"2026-04-07T03:28:33.608169352Z","hd":{"ts_event":"2026-04-07T03:28:33.608144525Z","rtype":160,"publisher_id":101,"instrument_id":436},"action":"C","side":"B","price":"1.156690000","size":30,"channel_id":23,"order_id":"10998904545032516637","flags":0,"ts_in_delta":963,"sequence":190215,"symbol":"FCEU SI 20260615 PS"}
{"ts_recv":"2026-04-07T03:28:33.608169352Z","hd":{"ts_event":"2026-04-07T03:28:33.608144525Z","rtype":160,"publisher_id":101,"instrument_id":436},"action":"A","side":"B","price":"1.156700000","size":30,"channel_id":23,"order_id":"10998904550462926525","flags":0,"ts_in_delta":963,"sequence":190215,"symbol":"FCEU SI 20260615 PS"}
{"ts_recv":"2026-04-07T03:28:33.608169352Z","hd":{"ts_event":"2026-04-07T03:28:33.608144525Z","rtype":160,"publisher_id":101,"instrument_id":436},"action":"C","side":"A","price":"1.156790000","size":30,"channel_id":23,"order_id":"1775532508177740829","flags":0,"ts_in_delta":963,"sequence":190215,"symbol":"FCEU SI 20260615 PS"}
{"ts_recv":"2026-04-07T03:28:33.608169352Z","hd":{"ts_event":"2026-04-07T03:28:33.608144525Z","rtype":160,"publisher_id":101,"instrument_id":436},"action":"A","side":"A","price":"1.156800000","size":30,"channel_id":23,"order_id":"1775532513608150717","flags":128,"ts_in_delta":963,"sequence":190215,"symbol":"FCEU SI 20260615 PS"}
{"ts_recv":"2026-04-07T03:28:36.850762980Z","hd":{"ts_event":"2026-04-07T03:28:36.850727731Z","rtype":160,"publisher_id":101,"instrument_id":436},"action":"C","side":"B","price":"1.156700000","size":30,"channel_id":23,"order_id":"10998904550462926525","flags":0,"ts_in_delta":9613,"sequence":190236,"symbol":"FCEU SI 20260615 PS"}
{"ts_recv":"2026-04-07T03:28:36.850762980Z","hd":{"ts_event":"2026-04-07T03:28:36.850727731Z","rtype":160,"publisher_id":101,"instrument_id":436},"action":"A","side":"B","price":"1.156710000","size":30,"channel_id":23,"order_id":"10998904553705512533","flags":0,"ts_in_delta":9613,"sequence":190236,"symbol":"FCEU SI 20260615 PS"}
{"ts_recv":"2026-04-07T03:28:36.850762980Z","hd":{"ts_event":"2026-04-07T03:28:36.850727731Z","rtype":160,"publisher_id":101,"instrument_id":436},"action":"C","side":"A","price":"1.156800000","size":30,"channel_id":23,"order_id":"1775532513608150717","flags":0,"ts_in_delta":9613,"sequence":190236,"symbol":"FCEU SI 20260615 PS"}
{"ts_recv":"2026-04-07T03:28:36.850762980Z","hd":{"ts_event":"2026-04-07T03:28:36.850727731Z","rtype":160,"publisher_id":101,"instrument_id":436},"action":"A","side":"A","price":"1.156810000","size":30,"channel_id":23,"order_id":"1775532516850736725","flags":128,"ts_in_delta":9613,"sequence":190236,"symbol":"FCEU SI 20260615 PS"}
{"ts_recv":"2026-04-07T03:28:36.850830138Z","hd":{"ts_event":"2026-04-07T03:28:36.850811027Z","rtype":160,"publisher_id":101,"instrument_id":436},"action":"C","side":"B","price":"1.156700000","size":30,"channel_id":23,"order_id":"10998904550462811678","flags":0,"ts_in_delta":964,"sequence":190237,"symbol":"FCEU SI 20260615 PS"}
{"ts_recv":"2026-04-07T03:28:36.850830138Z","hd":{"ts_event":"2026-04-07T03:28:36.850811027Z","rtype":160,"publisher_id":101,"instrument_id":436},"action":"A","side":"B","price":"1.156720000","size":30,"channel_id":23,"order_id":"10998904553705593155","flags":0,"ts_in_delta":964,"sequence":190237,"symbol":"FCEU SI 20260615 PS"}
{"ts_recv":"2026-04-07T03:28:36.850830138Z","hd":{"ts_event":"2026-04-07T03:28:36.850811027Z","rtype":160,"publisher_id":101,"instrument_id":436},"action":"C","side":"A","price":"1.156800000","size":30,"channel_id":23,"order_id":"1775532513608035870","flags":0,"ts_in_delta":964,"sequence":190237,"symbol":"FCEU SI 20260615 PS"}
{"ts_recv":"2026-04-07T03:28:36.850830138Z","hd":{"ts_event":"2026-04-07T03:28:36.850811027Z","rtype":160,"publisher_id":101,"instrument_id":436},"action":"A","side":"A","price":"1.156820000","size":30,"channel_id":23,"order_id":"1775532516850817347","flags":128,"ts_in_delta":964,"sequence":190237,"symbol":"FCEU SI 20260615 PS"}
{"ts_recv":"2026-04-07T03:28:36.850895155Z","hd":{"ts_event":"2026-04-07T03:28:36.850878975Z","rtype":160,"publisher_id":101,"instrument_id":436},"action":"C","side":"B","price":"1.156710000","size":30,"channel_id":23,"order_id":"10998904553705512533","flags":0,"ts_in_delta":973,"sequence":190238,"symbol":"FCEU SI 20260615 PS"}
{"ts_recv":"2026-04-07T03:28:36.850895155Z","hd":{"ts_event":"2026-04-07T03:28:36.850878975Z","rtype":160,"publisher_id":101,"instrument_id":436},"action":"A","side":"B","price":"1.156720000","size":30,"channel_id":23,"order_id":"10998904553705660779","flags":0,"ts_in_delta":973,"sequence":190238,"symbol":"FCEU SI 20260615 PS"}
{"ts_recv":"2026-04-07T03:28:36.850895155Z","hd":{"ts_event":"2026-04-07T03:28:36.850878975Z","rtype":160,"publisher_id":101,"instrument_id":436},"action":"C","side":"A","price":"1.156810000","size":30,"channel_id":23,"order_id":"1775532516850736725","flags":0,"ts_in_delta":973,"sequence":190238,"symbol":"FCEU SI 20260615 PS"}
{"ts_recv":"2026-04-07T03:28:36.850895155Z","hd":{"ts_event":"2026-04-07T03:28:36.850878975Z","rtype":160,"publisher_id":101,"instrument_id":436},"action":"A","side":"A","price":"1.156820000","size":30,"channel_id":23,"order_id":"1775532516850884971","flags":128,"ts_in_delta":973,"sequence":190238,"symbol":"FCEU SI 20260615 PS"}
{"ts_recv":"2026-04-07T03:28:41.512886960Z","hd":{"ts_event":"2026-04-07T03:28:41.512862571Z","rtype":160,"publisher_id":101,"instrument_id":436},"action":"C","side":"B","price":"1.156720000","size":30,"channel_id":23,"order_id":"10998904553705660779","flags":0,"ts_in_delta":1003,"sequence":190260,"symbol":"FCEU SI 20260615 PS"}
{"ts_recv":"2026-04-07T03:28:41.512886960Z","hd":{"ts_event":"2026-04-07T03:28:41.512862571Z","rtype":160,"publisher_id":101,"instrument_id":436},"action":"A","side":"B","price":"1.156730000","size":30,"channel_id":23,"order_id":"10998904558367644700","flags":0,"ts_in_delta":1003,"sequence":190260,"symbol":"FCEU SI 20260615 PS"}
{"ts_recv":"2026-04-07T03:28:41.512886960Z","hd":{"ts_event":"2026-04-07T03:28:41.512862571Z","rtype":160,"publisher_id":101,"instrument_id":436},"action":"C","side":"A","price":"1.156820000","size":30,"channel_id":23,"order_id":"1775532516850884971","flags":0,"ts_in_delta":1003,"sequence":190260,"symbol":"FCEU SI 20260615 PS"}
{"ts_recv":"2026-04-07T03:28:41.512886960Z","hd":{"ts_event":"2026-04-07T03:28:41.512862571Z","rtype":160,"publisher_id":101,"instrument_id":436},"action":"A","side":"A","price":"1.156830000","size":30,"channel_id":23,"order_id":"1775532521512868892","flags":128,"ts_in_delta":1003,"sequence":190260,"symbol":"FCEU SI 20260615 PS"}
{"ts_recv":"2026-04-07T03:28:58.345965478Z","hd":{"ts_event":"2026-04-07T03:28:58.345949671Z","rtype":160,"publisher_id":101,"instrument_id":436},"action":"C","side":"A","price":"1.156900000","size":20,"channel_id":23,"order_id":"1775532035227187679","flags":128,"ts_in_delta":788,"sequence":190390,"symbol":"FCEU SI 20260615 PS"}
{"ts_recv":"2026-04-07T03:28:58.406530360Z","hd":{"ts_event":"2026-04-07T03:28:58.406514251Z","rtype":160,"publisher_id":101,"instrument_id":436},"action":"A","side":"A","price":"1.157000000","size":20,"channel_id":23,"order_id":"1775532538406520802","flags":128,"ts_in_delta":792,"sequence":190396,"symbol":"FCEU SI 20260615 PS"}
{"ts_recv":"2026-04-07T03:29:01.712417429Z","hd":{"ts_event":"2026-04-07T03:29:01.712394115Z","rtype":160,"publisher_id":101,"instrument_id":436},"action":"C","side":"B","price":"1.156730000","size":30,"channel_id":23,"order_id":"10998904558367644700","flags":0,"ts_in_delta":754,"sequence":190438,"symbol":"FCEU SI 20260615 PS"}
{"ts_recv":"2026-04-07T03:29:01.712417429Z","hd":{"ts_event":"2026-04-07T03:29:01.712394115Z","rtype":160,"publisher_id":101,"instrument_id":436},"action":"A","side":"B","price":"1.156710000","size":30,"channel_id":23,"order_id":"10998904578567175993","flags":0,"ts_in_delta":754,"sequence":190438,"symbol":"FCEU SI 20260615 PS"}
{"ts_recv":"2026-04-07T03:29:01.712417429Z","hd":{"ts_event":"2026-04-07T03:29:01.712394115Z","rtype":160,"publisher_id":101,"instrument_id":436},"action":"C","side":"A","price":"1.156830000","size":30,"channel_id":23,"order_id":"1775532521512868892","flags":0,"ts_in_delta":754,"sequence":190438,"symbol":"FCEU SI 20260615 PS"}
{"ts_recv":"2026-04-07T03:29:01.712417429Z","hd":{"ts_event":"2026-04-07T03:29:01.712394115Z","rtype":160,"publisher_id":101,"instrument_id":436},"action":"A","side":"A","price":"1.156810000","size":30,"channel_id":23,"order_id":"1775532541712400185","flags":128,"ts_in_delta":754,"sequence":190438,"symbol":"FCEU SI 20260615 PS"}
{"ts_recv":"2026-04-07T03:29:01.886370621Z","hd":{"ts_event":"2026-04-07T03:29:01.886344201Z","rtype":160,"publisher_id":101,"instrument_id":436},"action":"C","side":"B","price":"1.156720000","size":30,"channel_id":23,"order_id":"10998904553705593155","flags":0,"ts_in_delta":1085,"sequence":190451,"symbol":"FCEU SI 20260615 PS"}
{"ts_recv":"2026-04-07T03:29:01.886370621Z","hd":{"ts_event":"2026-04-07T03:29:01.886344201Z","rtype":160,"publisher_id":101,"instrument_id":436},"action":"A","side":"B","price":"1.156700000","size":30,"channel_id":23,"order_id":"10998904578741131162","flags":0,"ts_in_delta":1085,"sequence":190451,"symbol":"FCEU SI 20260615 PS"}
{"ts_recv":"2026-04-07T03:29:01.886370621Z","hd":{"ts_event":"2026-04-07T03:29:01.886344201Z","rtype":160,"publisher_id":101,"instrument_id":436},"action":"C","side":"A","price":"1.156820000","size":30,"channel_id":23,"order_id":"1775532516850817347","flags":0,"ts_in_delta":1085,"sequence":190451,"symbol":"FCEU SI 20260615 PS"}
{"ts_recv":"2026-04-07T03:29:01.886370621Z","hd":{"ts_event":"2026-04-07T03:29:01.886344201Z","rtype":160,"publisher_id":101,"instrument_id":436},"action":"A","side":"A","price":"1.156800000","size":30,"channel_id":23,"order_id":"1775532541886355354","flags":128,"ts_in_delta":1085,"sequence":190451,"symbol":"FCEU SI 20260615 PS"}
{"ts_recv":"2026-04-07T03:29:01.886435000Z","hd":{"ts_event":"2026-04-07T03:29:01.886419215Z","rtype":160,"publisher_id":101,"instrument_id":436},"action":"C","side":"B","price":"1.156710000","size":30,"channel_id":23,"order_id":"10998904578567175993","flags":0,"ts_in_delta":892,"sequence":190452,"symbol":"FCEU SI 20260615 PS"}
{"ts_recv":"2026-04-07T03:29:01.886435000Z","hd":{"ts_event":"2026-04-07T03:29:01.886419215Z","rtype":160,"publisher_id":101,"instrument_id":436},"action":"A","side":"B","price":"1.156700000","size":30,"channel_id":23,"order_id":"10998904578741201088","flags":0,"ts_in_delta":892,"sequence":190452,"symbol":"FCEU SI 20260615 PS"}
{"ts_recv":"2026-04-07T03:29:01.886435000Z","hd":{"ts_event":"2026-04-07T03:29:01.886419215Z","rtype":160,"publisher_id":101,"instrument_id":436},"action":"C","side":"A","price":"1.156810000","size":30,"channel_id":23,"order_id":"1775532541712400185","flags":0,"ts_in_delta":892,"sequence":190452,"symbol":"FCEU SI 20260615 PS"}
{"ts_recv":"2026-04-07T03:29:01.886435000Z","hd":{"ts_event":"2026-04-07T03:29:01.886419215Z","rtype":160,"publisher_id":101,"instrument_id":436},"action":"A","side":"A","price":"1.156800000","size":30,"channel_id":23,"order_id":"1775532541886425280","flags":128,"ts_in_delta":892,"sequence":190452,"symbol":"FCEU SI 20260615 PS"}
{"ts_recv":"2026-04-07T03:29:01.936270065Z","hd":{"ts_event":"2026-04-07T03:29:01.936241113Z","rtype":160,"publisher_id":101,"instrument_id":436},"action":"C","side":"B","price":"1.156700000","size":30,"channel_id":23,"order_id":"10998904578741201088","flags":0,"ts_in_delta":1196,"sequence":190453,"symbol":"FCEU SI 20260615 PS"}
{"ts_recv":"2026-04-07T03:29:01.936270065Z","hd":{"ts_event":"2026-04-07T03:29:01.936241113Z","rtype":160,"publisher_id":101,"instrument_id":436},"action":"A","side":"B","price":"1.156720000","size":30,"channel_id":23,"order_id":"10998904578791027528","flags":0,"ts_in_delta":1196,"sequence":190453,"symbol":"FCEU SI 20260615 PS"}
{"ts_recv":"2026-04-07T03:29:01.936270065Z","hd":{"ts_event":"2026-04-07T03:29:01.936241113Z","rtype":160,"publisher_id":101,"instrument_id":436},"action":"C","side":"A","price":"1.156800000","size":30,"channel_id":23,"order_id":"1775532541886425280","flags":0,"ts_in_delta":1196,"sequence":190453,"symbol":"FCEU SI 20260615 PS"}
{"ts_recv":"2026-04-07T03:29:01.936270065Z","hd":{"ts_event":"2026-04-07T03:29:01.936241113Z","rtype":160,"publisher_id":101,"instrument_id":436},"action":"A","side":"A","price":"1.156820000","size":30,"channel_id":23,"order_id":"1775532541936251720","flags":128,"ts_in_delta":1196,"sequence":190453,"symbol":"FCEU SI 20260615 PS"}
{"ts_recv":"2026-04-07T03:29:01.936319729Z","hd":{"ts_event":"2026-04-07T03:29:01.936302789Z","rtype":160,"publisher_id":101,"instrument_id":436},"action":"C","side":"B","price":"1.156700000","size":30,"channel_id":23,"order_id":"10998904578741131162","flags":0,"ts_in_delta":1111,"sequence":190454,"symbol":"FCEU SI 20260615 PS"}
{"ts_recv":"2026-04-07T03:29:01.936319729Z","hd":{"ts_event":"2026-04-07T03:29:01.936302789Z","rtype":160,"publisher_id":101,"instrument_id":436},"action":"A","side":"B","price":"1.156720000","size":30,"channel_id":23,"order_id":"10998904578791084636","flags":0,"ts_in_delta":1111,"sequence":190454,"symbol":"FCEU SI 20260615 PS"}
{"ts_recv":"2026-04-07T03:29:01.936319729Z","hd":{"ts_event":"2026-04-07T03:29:01.936302789Z","rtype":160,"publisher_id":101,"instrument_id":436},"action":"C","side":"A","price":"1.156800000","size":30,"channel_id":23,"order_id":"1775532541886355354","flags":0,"ts_in_delta":1111,"sequence":190454,"symbol":"FCEU SI 20260615 PS"}
{"ts_recv":"2026-04-07T03:29:01.936319729Z","hd":{"ts_event":"2026-04-07T03:29:01.936302789Z","rtype":160,"publisher_id":101,"instrument_id":436},"action":"A","side":"A","price":"1.156820000","size":30,"channel_id":23,"order_id":"1775532541936308828","flags":128,"ts_in_delta":1111,"sequence":190454,"symbol":"FCEU SI 20260615 PS"}
{"ts_recv":"2026-04-07T03:29:01.936355140Z","hd":{"ts_event":"2026-04-07T03:29:01.936333401Z","rtype":160,"publisher_id":101,"instrument_id":436},"action":"C","side":"B","price":"1.156720000","size":30,"channel_id":23,"order_id":"10998904578791027528","flags":0,"ts_in_delta":1074,"sequence":190455,"symbol":"FCEU SI 20260615 PS"}
{"ts_recv":"2026-04-07T03:29:01.936355140Z","hd":{"ts_event":"2026-04-07T03:29:01.936333401Z","rtype":160,"publisher_id":101,"instrument_id":436},"action":"A","side":"B","price":"1.156730000","size":30,"channel_id":23,"order_id":"10998904578791115595","flags":0,"ts_in_delta":1074,"sequence":190455,"symbol":"FCEU SI 20260615 PS"}
{"ts_recv":"2026-04-07T03:29:01.936355140Z","hd":{"ts_event":"2026-04-07T03:29:01.936333401Z","rtype":160,"publisher_id":101,"instrument_id":436},"action":"C","side":"A","price":"1.156820000","size":30,"channel_id":23,"order_id":"1775532541936251720","flags":0,"ts_in_delta":1074,"sequence":190455,"symbol":"FCEU SI 20260615 PS"}
{"ts_recv":"2026-04-07T03:29:01.936355140Z","hd":{"ts_event":"2026-04-07T03:29:01.936333401Z","rtype":160,"publisher_id":101,"instrument_id":436},"action":"A","side":"A","price":"1.156830000","size":30,"channel_id":23,"order_id":"1775532541936339787","flags":128,"ts_in_delta":1074,"sequence":190455,"symbol":"FCEU SI 20260615 PS"}
{"ts_recv":"2026-04-07T03:29:03.792487646Z","hd":{"ts_event":"2026-04-07T03:29:03.792458639Z","rtype":160,"publisher_id":101,"instrument_id":436},"action":"C","side":"B","price":"1.156730000","size":30,"channel_id":23,"order_id":"10998904578791115595","flags":0,"ts_in_delta":1037,"sequence":190476,"symbol":"FCEU SI 20260615 PS"}
{"ts_recv":"2026-04-07T03:29:03.792487646Z","hd":{"ts_event":"2026-04-07T03:29:03.792458639Z","rtype":160,"publisher_id":101,"instrument_id":436},"action":"A","side":"B","price":"1.156740000","size":30,"channel_id":23,"order_id":"10998904580647247948","flags":0,"ts_in_delta":1037,"sequence":190476,"symbol":"FCEU SI 20260615 PS"}
{"ts_recv":"2026-04-07T03:29:03.792487646Z","hd":{"ts_event":"2026-04-07T03:29:03.792458639Z","rtype":160,"publisher_id":101,"instrument_id":436},"action":"C","side":"A","price":"1.156830000","size":30,"channel_id":23,"order_id":"1775532541936339787","flags":0,"ts_in_delta":1037,"sequence":190476,"symbol":"FCEU SI 20260615 PS"}
{"ts_recv":"2026-04-07T03:29:03.792487646Z","hd":{"ts_event":"2026-04-07T03:29:03.792458639Z","rtype":160,"publisher_id":101,"instrument_id":436},"action":"A","side":"A","price":"1.156840000","size":30,"channel_id":23,"order_id":"1775532543792472140","flags":128,"ts_in_delta":1037,"sequence":190476,"symbol":"FCEU SI 20260615 PS"}
{"ts_recv":"2026-04-07T03:29:03.792554459Z","hd":{"ts_event":"2026-04-07T03:29:03.792535099Z","rtype":160,"publisher_id":101,"instrument_id":436},"action":"C","side":"B","price":"1.156720000","size":30,"channel_id":23,"order_id":"10998904578791084636","flags":0,"ts_in_delta":934,"sequence":190477,"symbol":"FCEU SI 20260615 PS"}
{"ts_recv":"2026-04-07T03:29:03.792554459Z","hd":{"ts_event":"2026-04-07T03:29:03.792535099Z","rtype":160,"publisher_id":101,"instrument_id":436},"action":"A","side":"B","price":"1.156750000","size":30,"channel_id":23,"order_id":"10998904580647316912","flags":0,"ts_in_delta":934,"sequence":190477,"symbol":"FCEU SI 20260615 PS"}
{"ts_recv":"2026-04-07T03:29:03.792554459Z","hd":{"ts_event":"2026-04-07T03:29:03.792535099Z","rtype":160,"publisher_id":101,"instrument_id":436},"action":"C","side":"A","price":"1.156820000","size":30,"channel_id":23,"order_id":"1775532541936308828","flags":0,"ts_in_delta":934,"sequence":190477,"symbol":"FCEU SI 20260615 PS"}
{"ts_recv":"2026-04-07T03:29:03.792554459Z","hd":{"ts_event":"2026-04-07T03:29:03.792535099Z","rtype":160,"publisher_id":101,"instrument_id":436},"action":"A","side":"A","price":"1.156850000","size":30,"channel_id":23,"order_id":"1775532543792541104","flags":128,"ts_in_delta":934,"sequence":190477,"symbol":"FCEU SI 20260615 PS"}
{"ts_recv":"2026-04-07T03:29:03.792615919Z","hd":{"ts_event":"2026-04-07T03:29:03.792598077Z","rtype":160,"publisher_id":101,"instrument_id":436},"action":"C","side":"B","price":"1.156740000","size":30,"channel_id":23,"order_id":"10998904580647247948","flags":0,"ts_in_delta":897,"sequence":190478,"symbol":"FCEU SI 20260615 PS"}
{"ts_recv":"2026-04-07T03:29:03.792615919Z","hd":{"ts_event":"2026-04-07T03:29:03.792598077Z","rtype":160,"publisher_id":101,"instrument_id":436},"action":"A","side":"B","price":"1.156750000","size":30,"channel_id":23,"order_id":"10998904580647380305","flags":0,"ts_in_delta":897,"sequence":190478,"symbol":"FCEU SI 20260615 PS"}
{"ts_recv":"2026-04-07T03:29:03.792615919Z","hd":{"ts_event":"2026-04-07T03:29:03.792598077Z","rtype":160,"publisher_id":101,"instrument_id":436},"action":"C","side":"A","price":"1.156840000","size":30,"channel_id":23,"order_id":"1775532543792472140","flags":0,"ts_in_delta":897,"sequence":190478,"symbol":"FCEU SI 20260615 PS"}
{"ts_recv":"2026-04-07T03:29:03.792615919Z","hd":{"ts_event":"2026-04-07T03:29:03.792598077Z","rtype":160,"publisher_id":101,"instrument_id":436},"action":"A","side":"A","price":"1.156850000","size":30,"channel_id":23,"order_id":"1775532543792604497","flags":128,"ts_in_delta":897,"sequence":190478,"symbol":"FCEU SI 20260615 PS"}
{"ts_recv":"2026-04-07T03:29:03.797013354Z","hd":{"ts_event":"2026-04-07T03:29:03.796993387Z","rtype":160,"publisher_id":101,"instrument_id":436},"action":"C","side":"B","price":"1.156750000","size":30,"channel_id":23,"order_id":"10998904580647380305","flags":0,"ts_in_delta":930,"sequence":190480,"symbol":"FCEU SI 20260615 PS"}
{"ts_recv":"2026-04-07T03:29:03.797013354Z","hd":{"ts_event":"2026-04-07T03:29:03.796993387Z","rtype":160,"publisher_id":101,"instrument_id":436},"action":"A","side":"B","price":"1.156760000","size":30,"channel_id":23,"order_id":"10998904580651775319","flags":0,"ts_in_delta":930,"sequence":190480,"symbol":"FCEU SI 20260615 PS"}
{"ts_recv":"2026-04-07T03:29:03.797013354Z","hd":{"ts_event":"2026-04-07T03:29:03.796993387Z","rtype":160,"publisher_id":101,"instrument_id":436},"action":"C","side":"A","price":"1.156850000","size":30,"channel_id":23,"order_id":"1775532543792604497","flags":0,"ts_in_delta":930,"sequence":190480,"symbol":"FCEU SI 20260615 PS"}
{"ts_recv":"2026-04-07T03:29:03.797013354Z","hd":{"ts_event":"2026-04-07T03:29:03.796993387Z","rtype":160,"publisher_id":101,"instrument_id":436},"action":"A","side":"A","price":"1.156860000","size":30,"channel_id":23,"order_id":"1775532543796999511","flags":128,"ts_in_delta":930,"sequence":190480,"symbol":"FCEU SI 20260615 PS"}
{"ts_recv":"2026-04-07T03:29:03.797085589Z","hd":{"ts_event":"2026-04-07T03:29:03.797067851Z","rtype":160,"publisher_id":101,"instrument_id":436},"action":"C","side":"B","price":"1.156760000","size":30,"channel_id":23,"order_id":"10998904580651775319","flags":0,"ts_in_delta":929,"sequence":190481,"symbol":"FCEU SI 20260615 PS"}
{"ts_recv":"2026-04-07T03:29:03.797085589Z","hd":{"ts_event":"2026-04-07T03:29:03.797067851Z","rtype":160,"publisher_id":101,"instrument_id":436},"action":"A","side":"B","price":"1.156770000","size":30,"channel_id":23,"order_id":"10998904580651849538","flags":0,"ts_in_delta":929,"sequence":190481,"symbol":"FCEU SI 20260615 PS"}
{"ts_recv":"2026-04-07T03:29:03.797085589Z","hd":{"ts_event":"2026-04-07T03:29:03.797067851Z","rtype":160,"publisher_id":101,"instrument_id":436},"action":"C","side":"A","price":"1.156860000","size":30,"channel_id":23,"order_id":"1775532543796999511","flags":0,"ts_in_delta":929,"sequence":190481,"symbol":"FCEU SI 20260615 PS"}
{"ts_recv":"2026-04-07T03:29:03.797085589Z","hd":{"ts_event":"2026-04-07T03:29:03.797067851Z","rtype":160,"publisher_id":101,"instrument_id":436},"action":"A","side":"A","price":"1.156870000","size":30,"channel_id":23,"order_id":"1775532543797073730","flags":128,"ts_in_delta":929,"sequence":190481,"symbol":"FCEU SI 20260615 PS"}
{"ts_recv":"2026-04-07T03:29:03.797139132Z","hd":{"ts_event":"2026-04-07T03:29:03.797124101Z","rtype":160,"publisher_id":101,"instrument_id":436},"action":"C","side":"B","price":"1.156770000","size":30,"channel_id":23,"order_id":"10998904580651849538","flags":0,"ts_in_delta":924,"sequence":190482,"symbol":"FCEU SI 20260615 PS"}
{"ts_recv":"2026-04-07T03:29:03.797139132Z","hd":{"ts_event":"2026-04-07T03:29:03.797124101Z","rtype":160,"publisher_id":101,"instrument_id":436},"action":"A","side":"B","price":"1.156760000","size":30,"channel_id":23,"order_id":"10998904580651905777","flags":0,"ts_in_delta":924,"sequence":190482,"symbol":"FCEU SI 20260615 PS"}
{"ts_recv":"2026-04-07T03:29:03.797139132Z","hd":{"ts_event":"2026-04-07T03:29:03.797124101Z","rtype":160,"publisher_id":101,"instrument_id":436},"action":"C","side":"A","price":"1.156870000","size":30,"channel_id":23,"order_id":"1775532543797073730","flags":0,"ts_in_delta":924,"sequence":190482,"symbol":"FCEU SI 20260615 PS"}
{"ts_recv":"2026-04-07T03:29:03.797139132Z","hd":{"ts_event":"2026-04-07T03:29:03.797124101Z","rtype":160,"publisher_id":101,"instrument_id":436},"action":"A","side":"A","price":"1.156860000","size":30,"channel_id":23,"order_id":"1775532543797129969","flags":128,"ts_in_delta":924,"sequence":190482,"symbol":"FCEU SI 20260615 PS"}
{"ts_recv":"2026-04-07T03:29:03.809212321Z","hd":{"ts_event":"2026-04-07T03:29:03.809195255Z","rtype":160,"publisher_id":101,"instrument_id":436},"action":"C","side":"B","price":"1.156760000","size":30,"channel_id":23,"order_id":"10998904580651905777","flags":0,"ts_in_delta":1235,"sequence":190488,"symbol":"FCEU SI 20260615 PS"}
{"ts_recv":"2026-04-07T03:29:03.809212321Z","hd":{"ts_event":"2026-04-07T03:29:03.809195255Z","rtype":160,"publisher_id":101,"instrument_id":436},"action":"A","side":"B","price":"1.156750000","size":30,"channel_id":23,"order_id":"10998904580663976717","flags":0,"ts_in_delta":1235,"sequence":190488,"symbol":"FCEU SI 20260615 PS"}
{"ts_recv":"2026-04-07T03:29:03.809212321Z","hd":{"ts_event":"2026-04-07T03:29:03.809195255Z","rtype":160,"publisher_id":101,"instrument_id":436},"action":"C","side":"A","price":"1.156860000","size":30,"channel_id":23,"order_id":"1775532543797129969","flags":0,"ts_in_delta":1235,"sequence":190488,"symbol":"FCEU SI 20260615 PS"}
{"ts_recv":"2026-04-07T03:29:03.809212321Z","hd":{"ts_event":"2026-04-07T03:29:03.809195255Z","rtype":160,"publisher_id":101,"instrument_id":436},"action":"A","side":"A","price":"1.156850000","size":30,"channel_id":23,"order_id":"1775532543809200909","flags":128,"ts_in_delta":1235,"sequence":190488,"symbol":"FCEU SI 20260615 PS"}
{"ts_recv":"2026-04-07T03:29:09.119229688Z","hd":{"ts_event":"2026-04-07T03:29:09.119195407Z","rtype":160,"publisher_id":101,"instrument_id":436},"action":"C","side":"B","price":"1.156750000","size":30,"channel_id":23,"order_id":"10998904580663976717","flags":0,"ts_in_delta":1203,"sequence":190522,"symbol":"FCEU SI 20260615 PS"}
{"ts_recv":"2026-04-07T03:29:09.119229688Z","hd":{"ts_event":"2026-04-07T03:29:09.119195407Z","rtype":160,"publisher_id":101,"instrument_id":436},"action":"A","side":"B","price":"1.156740000","size":30,"channel_id":23,"order_id":"10998904585973985370","flags":0,"ts_in_delta":1203,"sequence":190522,"symbol":"FCEU SI 20260615 PS"}
{"ts_recv":"2026-04-07T03:29:09.119229688Z","hd":{"ts_event":"2026-04-07T03:29:09.119195407Z","rtype":160,"publisher_id":101,"instrument_id":436},"action":"C","side":"A","price":"1.156850000","size":30,"channel_id":23,"order_id":"1775532543809200909","flags":0,"ts_in_delta":1203,"sequence":190522,"symbol":"FCEU SI 20260615 PS"}
{"ts_recv":"2026-04-07T03:29:09.119229688Z","hd":{"ts_event":"2026-04-07T03:29:09.119195407Z","rtype":160,"publisher_id":101,"instrument_id":436},"action":"A","side":"A","price":"1.156840000","size":30,"channel_id":23,"order_id":"1775532549119209562","flags":128,"ts_in_delta":1203,"sequence":190522,"symbol":"FCEU SI 20260615 PS"}
{"ts_recv":"2026-04-07T03:29:09.119321298Z","hd":{"ts_event":"2026-04-07T03:29:09.119302411Z","rtype":160,"publisher_id":101,"instrument_id":436},"action":"C","side":"B","price":"1.156750000","size":30,"channel_id":23,"order_id":"10998904580647316912","flags":0,"ts_in_delta":914,"sequence":190523,"symbol":"FCEU SI 20260615 PS"}
{"ts_recv":"2026-04-07T03:29:09.119321298Z","hd":{"ts_event":"2026-04-07T03:29:09.119302411Z","rtype":160,"publisher_id":101,"instrument_id":436},"action":"A","side":"B","price":"1.156730000","size":30,"channel_id":23,"order_id":"10998904585974084719","flags":0,"ts_in_delta":914,"sequence":190523,"symbol":"FCEU SI 20260615 PS"}
{"ts_recv":"2026-04-07T03:29:09.119321298Z","hd":{"ts_event":"2026-04-07T03:29:09.119302411Z","rtype":160,"publisher_id":101,"instrument_id":436},"action":"C","side":"A","price":"1.156850000","size":30,"channel_id":23,"order_id":"1775532543792541104","flags":0,"ts_in_delta":914,"sequence":190523,"symbol":"FCEU SI 20260615 PS"}
{"ts_recv":"2026-04-07T03:29:09.119321298Z","hd":{"ts_event":"2026-04-07T03:29:09.119302411Z","rtype":160,"publisher_id":101,"instrument_id":436},"action":"A","side":"A","price":"1.156830000","size":30,"channel_id":23,"order_id":"1775532549119308911","flags":128,"ts_in_delta":914,"sequence":190523,"symbol":"FCEU SI 20260615 PS"}
{"ts_recv":"2026-04-07T03:29:09.119384380Z","hd":{"ts_event":"2026-04-07T03:29:09.119365099Z","rtype":160,"publisher_id":101,"instrument_id":436},"action":"C","side":"B","price":"1.156740000","size":30,"channel_id":23,"order_id":"10998904585973985370","flags":0,"ts_in_delta":903,"sequence":190524,"symbol":"FCEU SI 20260615 PS"}
{"ts_recv":"2026-04-07T03:29:09.119384380Z","hd":{"ts_event":"2026-04-07T03:29:09.119365099Z","rtype":160,"publisher_id":101,"instrument_id":436},"action":"A","side":"B","price":"1.156730000","size":30,"channel_id":23,"order_id":"10998904585974147489","flags":0,"ts_in_delta":903,"sequence":190524,"symbol":"FCEU SI 20260615 PS"}
{"ts_recv":"2026-04-07T03:29:09.119384380Z","hd":{"ts_event":"2026-04-07T03:29:09.119365099Z","rtype":160,"publisher_id":101,"instrument_id":436},"action":"C","side":"A","price":"1.156840000","size":30,"channel_id":23,"order_id":"1775532549119209562","flags":0,"ts_in_delta":903,"sequence":190524,"symbol":"FCEU SI 20260615 PS"}
{"ts_recv":"2026-04-07T03:29:09.119384380Z","hd":{"ts_event":"2026-04-07T03:29:09.119365099Z","rtype":160,"publisher_id":101,"instrument_id":436},"action":"A","side":"A","price":"1.156830000","size":30,"channel_id":23,"order_id":"1775532549119371681","flags":128,"ts_in_delta":903,"sequence":190524,"symbol":"FCEU SI 20260615 PS"}
{"ts_recv":"2026-04-07T03:29:21.864156764Z","hd":{"ts_event":"2026-04-07T03:29:21.864135645Z","rtype":160,"publisher_id":101,"instrument_id":436},"action":"C","side":"B","price":"1.156730000","size":30,"channel_id":23,"order_id":"10998904585974147489","flags":0,"ts_in_delta":970,"sequence":190605,"symbol":"FCEU SI 20260615 PS"}
{"ts_recv":"2026-04-07T03:29:21.864156764Z","hd":{"ts_event":"2026-04-07T03:29:21.864135645Z","rtype":160,"publisher_id":101,"instrument_id":436},"action":"A","side":"B","price":"1.156740000","size":30,"channel_id":23,"order_id":"10998904598718917473","flags":0,"ts_in_delta":970,"sequence":190605,"symbol":"FCEU SI 20260615 PS"}
{"ts_recv":"2026-04-07T03:29:21.864156764Z","hd":{"ts_event":"2026-04-07T03:29:21.864135645Z","rtype":160,"publisher_id":101,"instrument_id":436},"action":"C","side":"A","price":"1.156830000","size":30,"channel_id":23,"order_id":"1775532549119371681","flags":0,"ts_in_delta":970,"sequence":190605,"symbol":"FCEU SI 20260615 PS"}
{"ts_recv":"2026-04-07T03:29:21.864156764Z","hd":{"ts_event":"2026-04-07T03:29:21.864135645Z","rtype":160,"publisher_id":101,"instrument_id":436},"action":"A","side":"A","price":"1.156840000","size":30,"channel_id":23,"order_id":"1775532561864141665","flags":128,"ts_in_delta":970,"sequence":190605,"symbol":"FCEU SI 20260615 PS"}
