{"ts_recv":"2026-04-07T02:03:09.800538271Z","hd":{"ts_event":"2026-04-07T02:03:09.800516133Z","rtype":160,"publisher_id":101,"instrument_id":436},"action":"C","side":"A","price":"1.156710000","size":30,"channel_id":23,"order_id":"1775527384191474462","flags":0,"ts_in_delta":1246,"sequence":143573,"symbol":"FCEU SI 20260615 PS"}
{"ts_recv":"2026-04-07T02:03:09.800538271Z","hd":{"ts_event":"2026-04-07T02:03:09.800516133Z","rtype":160,"publisher_id":101,"instrument_id":436},"action":"A","side":"A","price":"1.156730000","size":30,"channel_id":23,"order_id":"1775527389800522437","flags":128,"ts_in_delta":1246,"sequence":143573,"symbol":"FCEU SI 20260615 PS"}
{"ts_recv":"2026-04-07T02:03:09.800599094Z","hd":{"ts_event":"2026-04-07T02:03:09.800581163Z","rtype":160,"publisher_id":101,"instrument_id":436},"action":"C","side":"B","price":"1.156620000","size":30,"channel_id":23,"order_id":"10998899426589935398","flags":0,"ts_in_delta":892,"sequence":143574,"symbol":"FCEU SI 20260615 PS"}
{"ts_recv":"2026-04-07T02:03:09.800599094Z","hd":{"ts_event":"2026-04-07T02:03:09.800581163Z","rtype":160,"publisher_id":101,"instrument_id":436},"action":"A","side":"B","price":"1.156630000","size":30,"channel_id":23,"order_id":"10998899426655363013","flags":0,"ts_in_delta":892,"sequence":143574,"symbol":"FCEU SI 20260615 PS"}
{"ts_recv":"2026-04-07T02:03:09.800599094Z","hd":{"ts_event":"2026-04-07T02:03:09.800581163Z","rtype":160,"publisher_id":101,"instrument_id":436},"action":"C","side":"A","price":"1.156720000","size":30,"channel_id":23,"order_id":"1775527389735159590","flags":0,"ts_in_delta":892,"sequence":143574,"symbol":"FCEU SI 20260615 PS"}
{"ts_recv":"2026-04-07T02:03:09.800599094Z","hd":{"ts_event":"2026-04-07T02:03:09.800581163Z","rtype":160,"publisher_id":101,"instrument_id":436},"action":"A","side":"A","price":"1.156730000","size":30,"channel_id":23,"order_id":"1775527389800587205","flags":128,"ts_in_delta":892,"sequence":143574,"symbol":"FCEU SI 20260615 PS"}
{"ts_recv":"2026-04-07T02:03:16.378938908Z","hd":{"ts_event":"2026-04-07T02:03:16.378917649Z","rtype":160,"publisher_id":101,"instrument_id":436},"action":"C","side":"B","price":"1.156630000","size":30,"channel_id":23,"order_id":"10998899426655363013","flags":0,"ts_in_delta":986,"sequence":143664,"symbol":"FCEU SI 20260615 PS"}
{"ts_recv":"2026-04-07T02:03:16.378938908Z","hd":{"ts_event":"2026-04-07T02:03:16.378917649Z","rtype":160,"publisher_id":101,"instrument_id":436},"action":"A","side":"B","price":"1.156620000","size":30,"channel_id":23,"order_id":"10998899433233699605","flags":0,"ts_in_delta":986,"sequence":143664,"symbol":"FCEU SI 20260615 PS"}
{"ts_recv":"2026-04-07T02:03:16.378938908Z","hd":{"ts_event":"2026-04-07T02:03:16.378917649Z","rtype":160,"publisher_id":101,"instrument_id":436},"action":"C","side":"A","price":"1.156730000","size":30,"channel_id":23,"order_id":"1775527389800587205","flags":0,"ts_in_delta":986,"sequence":143664,"symbol":"FCEU SI 20260615 PS"}
{"ts_recv":"2026-04-07T02:03:16.378938908Z","hd":{"ts_event":"2026-04-07T02:03:16.378917649Z","rtype":160,"publisher_id":101,"instrument_id":436},"action":"A","side":"A","price":"1.156720000","size":30,"channel_id":23,"order_id":"1775527396378923797","flags":128,"ts_in_delta":986,"sequence":143664,"symbol":"FCEU SI 20260615 PS"}
{"ts_recv":"2026-04-07T02:03:16.382975015Z","hd":{"ts_event":"2026-04-07T02:03:16.382956303Z","rtype":160,"publisher_id":101,"instrument_id":436},"action":"C","side":"B","price":"1.156630000","size":30,"channel_id":23,"order_id":"10998899426655298245","flags":0,"ts_in_delta":917,"sequence":143665,"symbol":"FCEU SI 20260615 PS"}
{"ts_recv":"2026-04-07T02:03:16.382975015Z","hd":{"ts_event":"2026-04-07T02:03:16.382956303Z","rtype":160,"publisher_id":101,"instrument_id":436},"action":"A","side":"B","price":"1.156610000","size":30,"channel_id":23,"order_id":"10998899433237738565","flags":0,"ts_in_delta":917,"sequence":143665,"symbol":"FCEU SI 20260615 PS"}
{"ts_recv":"2026-04-07T02:03:16.382975015Z","hd":{"ts_event":"2026-04-07T02:03:16.382956303Z","rtype":160,"publisher_id":101,"instrument_id":436},"action":"C","side":"A","price":"1.156730000","size":30,"channel_id":23,"order_id":"1775527389800522437","flags":0,"ts_in_delta":917,"sequence":143665,"symbol":"FCEU SI 20260615 PS"}
{"ts_recv":"2026-04-07T02:03:16.382975015Z","hd":{"ts_event":"2026-04-07T02:03:16.382956303Z","rtype":160,"publisher_id":101,"instrument_id":436},"action":"A","side":"A","price":"1.156710000","size":30,"channel_id":23,"order_id":"1775527396382962757","flags":128,"ts_in_delta":917,"sequence":143665,"symbol":"FCEU SI 20260615 PS"}
{"ts_recv":"2026-04-07T02:03:16.383044731Z","hd":{"ts_event":"2026-04-07T02:03:16.383025635Z","rtype":160,"publisher_id":101,"instrument_id":436},"action":"C","side":"B","price":"1.156620000","size":30,"channel_id":23,"order_id":"10998899433233699605","flags":0,"ts_in_delta":883,"sequence":143666,"symbol":"FCEU SI 20260615 PS"}
{"ts_recv":"2026-04-07T02:03:16.383044731Z","hd":{"ts_event":"2026-04-07T02:03:16.383025635Z","rtype":160,"publisher_id":101,"instrument_id":436},"action":"A","side":"B","price":"1.156610000","size":30,"channel_id":23,"order_id":"10998899433237807445","flags":0,"ts_in_delta":883,"sequence":143666,"symbol":"FCEU SI 20260615 PS"}
{"ts_recv":"2026-04-07T02:03:16.383044731Z","hd":{"ts_event":"2026-04-07T02:03:16.383025635Z","rtype":160,"publisher_id":101,"instrument_id":436},"action":"C","side":"A","price":"1.156720000","size":30,"channel_id":23,"order_id":"1775527396378923797","flags":0,"ts_in_delta":883,"sequence":143666,"symbol":"FCEU SI 20260615 PS"}
{"ts_recv":"2026-04-07T02:03:16.383044731Z","hd":{"ts_event":"2026-04-07T02:03:16.383025635Z","rtype":160,"publisher_id":101,"instrument_id":436},"action":"A","side":"A","price":"1.156710000","size":30,"channel_id":23,"order_id":"1775527396383031637","flags":128,"ts_in_delta":883,"sequence":143666,"symbol":"FCEU SI 20260615 PS"}
{"ts_recv":"2026-04-07T02:03:25.774442277Z","hd":{"ts_event":"2026-04-07T02:03:25.774421031Z","rtype":160,"publisher_id":101,"instrument_id":436},"action":"C","side":"B","price":"1.156610000","size":30,"channel_id":23,"order_id":"10998899433237807445","flags":0,"ts_in_delta":944,"sequence":143781,"symbol":"FCEU SI 20260615 PS"}
{"ts_recv":"2026-04-07T02:03:25.774442277Z","hd":{"ts_event":"2026-04-07T02:03:25.774421031Z","rtype":160,"publisher_id":101,"instrument_id":436},"action":"A","side":"B","price":"1.156600000","size":30,"channel_id":23,"order_id":"10998899442629203323","flags":0,"ts_in_delta":944,"sequence":143781,"symbol":"FCEU SI 20260615 PS"}
{"ts_recv":"2026-04-07T02:03:25.774442277Z","hd":{"ts_event":"2026-04-07T02:03:25.774421031Z","rtype":160,"publisher_id":101,"instrument_id":436},"action":"C","side":"A","price":"1.156710000","size":30,"channel_id":23,"order_id":"1775527396383031637","flags":0,"ts_in_delta":944,"sequence":143781,"symbol":"FCEU SI 20260615 PS"}
{"ts_recv":"2026-04-07T02:03:25.774442277Z","hd":{"ts_event":"2026-04-07T02:03:25.774421031Z","rtype":160,"publisher_id":101,"instrument_id":436},"action":"A","side":"A","price":"1.156700000","size":30,"channel_id":23,"order_id":"1775527405774427515","flags":128,"ts_in_delta":944,"sequence":143781,"symbol":"FCEU SI 20260615 PS"}
{"ts_recv":"2026-04-07T02:03:25.799218533Z","hd":{"ts_event":"2026-04-07T02:03:25.799194545Z","rtype":160,"publisher_id":101,"instrument_id":436},"action":"C","side":"B","price":"1.156610000","size":30,"channel_id":23,"order_id":"10998899433237738565","flags":0,"ts_in_delta":1102,"sequence":143787,"symbol":"FCEU SI 20260615 PS"}
{"ts_recv":"2026-04-07T02:03:25.799218533Z","hd":{"ts_event":"2026-04-07T02:03:25.799194545Z","rtype":160,"publisher_id":101,"instrument_id":436},"action":"A","side":"B","price":"1.156590000","size":30,"channel_id":23,"order_id":"10998899442653978957","flags":0,"ts_in_delta":1102,"sequence":143787,"symbol":"FCEU SI 20260615 PS"}
{"ts_recv":"2026-04-07T02:03:25.799218533Z","hd":{"ts_event":"2026-04-07T02:03:25.799194545Z","rtype":160,"publisher_id":101,"instrument_id":436},"action":"C","side":"A","price":"1.156710000","size":30,"channel_id":23,"order_id":"1775527396382962757","flags":0,"ts_in_delta":1102,"sequence":143787,"symbol":"FCEU SI 20260615 PS"}
{"ts_recv":"2026-04-07T02:03:25.799218533Z","hd":{"ts_event":"2026-04-07T02:03:25.799194545Z","rtype":160,"publisher_id":101,"instrument_id":436},"action":"A","side":"A","price":"1.156690000","size":30,"channel_id":23,"order_id":"1775527405799203149","flags":128,"ts_in_delta":1102,"sequence":143787,"symbol":"FCEU SI 20260615 PS"}
{"ts_recv":"2026-04-07T02:03:25.799278765Z","hd":{"ts_event":"2026-04-07T02:03:25.799262391Z","rtype":160,"publisher_id":101,"instrument_id":436},"action":"C","side":"B","price":"1.156600000","size":30,"channel_id":23,"order_id":"10998899442629203323","flags":0,"ts_in_delta":1003,"sequence":143788,"symbol":"FCEU SI 20260615 PS"}
{"ts_recv":"2026-04-07T02:03:25.799278765Z","hd":{"ts_event":"2026-04-07T02:03:25.799262391Z","rtype":160,"publisher_id":101,"instrument_id":436},"action":"A","side":"B","price":"1.156590000","size":30,"channel_id":23,"order_id":"10998899442654044073","flags":0,"ts_in_delta":1003,"sequence":143788,"symbol":"FCEU SI 20260615 PS"}
{"ts_recv":"2026-04-07T02:03:25.799278765Z","hd":{"ts_event":"2026-04-07T02:03:25.799262391Z","rtype":160,"publisher_id":101,"instrument_id":436},"action":"C","side":"A","price":"1.156700000","size":30,"channel_id":23,"order_id":"1775527405774427515","flags":0,"ts_in_delta":1003,"sequence":143788,"symbol":"FCEU SI 20260615 PS"}
{"ts_recv":"2026-04-07T02:03:25.799278765Z","hd":{"ts_event":"2026-04-07T02:03:25.799262391Z","rtype":160,"publisher_id":101,"instrument_id":436},"action":"A","side":"A","price":"1.156690000","size":30,"channel_id":23,"order_id":"1775527405799268265","flags":128,"ts_in_delta":1003,"sequence":143788,"symbol":"FCEU SI 20260615 PS"}
{"ts_recv":"2026-04-07T02:03:37.388299483Z","hd":{"ts_event":"2026-04-07T02:03:37.388279061Z","rtype":160,"publisher_id":101,"instrument_id":436},"action":"C","side":"B","price":"1.156590000","size":30,"channel_id":23,"order_id":"10998899442654044073","flags":0,"ts_in_delta":771,"sequence":143881,"symbol":"FCEU SI 20260615 PS"}
{"ts_recv":"2026-04-07T02:03:37.388299483Z","hd":{"ts_event":"2026-04-07T02:03:37.388279061Z","rtype":160,"publisher_id":101,"instrument_id":436},"action":"A","side":"B","price":"1.156600000","size":30,"channel_id":23,"order_id":"10998899454243061001","flags":0,"ts_in_delta":771,"sequence":143881,"symbol":"FCEU SI 20260615 PS"}
{"ts_recv":"2026-04-07T02:03:37.388299483Z","hd":{"ts_event":"2026-04-07T02:03:37.388279061Z","rtype":160,"publisher_id":101,"instrument_id":436},"action":"C","side":"A","price":"1.156690000","size":30,"channel_id":23,"order_id":"1775527405799268265","flags":0,"ts_in_delta":771,"sequence":143881,"symbol":"FCEU SI 20260615 PS"}
{"ts_recv":"2026-04-07T02:03:37.388299483Z","hd":{"ts_event":"2026-04-07T02:03:37.388279061Z","rtype":160,"publisher_id":101,"instrument_id":436},"action":"A","side":"A","price":"1.156700000","size":30,"channel_id":23,"order_id":"1775527417388285193","flags":128,"ts_in_delta":771,"sequence":143881,"symbol":"FCEU SI 20260615 PS"}
{"ts_recv":"2026-04-07T02:03:37.388908118Z","hd":{"ts_event":"2026-04-07T02:03:37.388889511Z","rtype":160,"publisher_id":101,"instrument_id":436},"action":"C","side":"B","price":"1.156590000","size":30,"channel_id":23,"order_id":"10998899442653978957","flags":0,"ts_in_delta":780,"sequence":143883,"symbol":"FCEU SI 20260615 PS"}
{"ts_recv":"2026-04-07T02:03:37.388908118Z","hd":{"ts_event":"2026-04-07T02:03:37.388889511Z","rtype":160,"publisher_id":101,"instrument_id":436},"action":"A","side":"B","price":"1.156610000","size":30,"channel_id":23,"order_id":"10998899454243671457","flags":0,"ts_in_delta":780,"sequence":143883,"symbol":"FCEU SI 20260615 PS"}
{"ts_recv":"2026-04-07T02:03:37.388908118Z","hd":{"ts_event":"2026-04-07T02:03:37.388889511Z","rtype":160,"publisher_id":101,"instrument_id":436},"action":"C","side":"A","price":"1.156690000","size":30,"channel_id":23,"order_id":"1775527405799203149","flags":0,"ts_in_delta":780,"sequence":143883,"symbol":"FCEU SI 20260615 PS"}
{"ts_recv":"2026-04-07T02:03:37.388908118Z","hd":{"ts_event":"2026-04-07T02:03:37.388889511Z","rtype":160,"publisher_id":101,"instrument_id":436},"action":"A","side":"A","price":"1.156710000","size":30,"channel_id":23,"order_id":"1775527417388895649","flags":128,"ts_in_delta":780,"sequence":143883,"symbol":"FCEU SI 20260615 PS"}
{"ts_recv":"2026-04-07T02:03:37.388972043Z","hd":{"ts_event":"2026-04-07T02:03:37.388952117Z","rtype":160,"publisher_id":101,"instrument_id":436},"action":"C","side":"B","price":"1.156600000","size":30,"channel_id":23,"order_id":"10998899454243061001","flags":0,"ts_in_delta":940,"sequence":143884,"symbol":"FCEU SI 20260615 PS"}
{"ts_recv":"2026-04-07T02:03:37.388972043Z","hd":{"ts_event":"2026-04-07T02:03:37.388952117Z","rtype":160,"publisher_id":101,"instrument_id":436},"action":"A","side":"B","price":"1.156610000","size":30,"channel_id":23,"order_id":"10998899454243733551","flags":0,"ts_in_delta":940,"sequence":143884,"symbol":"FCEU SI 20260615 PS"}
{"ts_recv":"2026-04-07T02:03:37.388972043Z","hd":{"ts_event":"2026-04-07T02:03:37.388952117Z","rtype":160,"publisher_id":101,"instrument_id":436},"action":"C","side":"A","price":"1.156700000","size":30,"channel_id":23,"order_id":"1775527417388285193","flags":0,"ts_in_delta":940,"sequence":143884,"symbol":"FCEU SI 20260615 PS"}
{"ts_recv":"2026-04-07T02:03:37.388972043Z","hd":{"ts_event":"2026-04-07T02:03:37.388952117Z","rtype":160,"publisher_id":101,"instrument_id":436},"action":"A","side":"A","price":"1.156710000","size":30,"channel_id":23,"order_id":"1775527417388957743","flags":128,"ts_in_delta":940,"sequence":143884,"symbol":"FCEU SI 20260615 PS"}
{"ts_recv":"2026-04-07T02:03:59.394723881Z","hd":{"ts_event":"2026-04-07T02:03:59.394693609Z","rtype":160,"publisher_id":101,"instrument_id":436},"action":"C","side":"B","price":"1.156610000","size":30,"channel_id":23,"order_id":"10998899454243733551","flags":0,"ts_in_delta":1309,"sequence":143993,"symbol":"FCEU SI 20260615 PS"}
{"ts_recv":"2026-04-07T02:03:59.394723881Z","hd":{"ts_event":"2026-04-07T02:03:59.394693609Z","rtype":160,"publisher_id":101,"instrument_id":436},"action":"A","side":"B","price":"1.156600000","size":30,"channel_id":23,"order_id":"10998899476249480782","flags":0,"ts_in_delta":1309,"sequence":143993,"symbol":"FCEU SI 20260615 PS"}
{"ts_recv":"2026-04-07T02:03:59.394723881Z","hd":{"ts_event":"2026-04-07T02:03:59.394693609Z","rtype":160,"publisher_id":101,"instrument_id":436},"action":"C","side":"A","price":"1.156710000","size":30,"channel_id":23,"order_id":"1775527417388957743","flags":0,"ts_in_delta":1309,"sequence":143993,"symbol":"FCEU SI 20260615 PS"}
{"ts_recv":"2026-04-07T02:03:59.394723881Z","hd":{"ts_event":"2026-04-07T02:03:59.394693609Z","rtype":160,"publisher_id":101,"instrument_id":436},"action":"A","side":"A","price":"1.156700000","size":30,"channel_id":23,"order_id":"1775527439394704974","flags":128,"ts_in_delta":1309,"sequence":143993,"symbol":"FCEU SI 20260615 PS"}
{"ts_recv":"2026-04-07T02:03:59.420624793Z","hd":{"ts_event":"2026-04-07T02:03:59.420602663Z","rtype":160,"publisher_id":101,"instrument_id":436},"action":"C","side":"B","price":"1.156610000","size":30,"channel_id":23,"order_id":"10998899454243671457","flags":0,"ts_in_delta":908,"sequence":143999,"symbol":"FCEU SI 20260615 PS"}
{"ts_recv":"2026-04-07T02:03:59.420624793Z","hd":{"ts_event":"2026-04-07T02:03:59.420602663Z","rtype":160,"publisher_id":101,"instrument_id":436},"action":"A","side":"B","price":"1.156590000","size":30,"channel_id":23,"order_id":"10998899476275384292","flags":0,"ts_in_delta":908,"sequence":143999,"symbol":"FCEU SI 20260615 PS"}
{"ts_recv":"2026-04-07T02:03:59.420624793Z","hd":{"ts_event":"2026-04-07T02:03:59.420602663Z","rtype":160,"publisher_id":101,"instrument_id":436},"action":"C","side":"A","price":"1.156710000","size":30,"channel_id":23,"order_id":"1775527417388895649","flags":0,"ts_in_delta":908,"sequence":143999,"symbol":"FCEU SI 20260615 PS"}
{"ts_recv":"2026-04-07T02:03:59.420624793Z","hd":{"ts_event":"2026-04-07T02:03:59.420602663Z","rtype":160,"publisher_id":101,"instrument_id":436},"action":"A","side":"A","price":"1.156690000","size":30,"channel_id":23,"order_id":"1775527439420608484","flags":128,"ts_in_delta":908,"sequence":143999,"symbol":"FCEU SI 20260615 PS"}
{"ts_recv":"2026-04-07T02:03:59.420688104Z","hd":{"ts_event":"2026-04-07T02:03:59.420669005Z","rtype":160,"publisher_id":101,"instrument_id":436},"action":"C","side":"B","price":"1.156600000","size":30,"channel_id":23,"order_id":"10998899476249480782","flags":0,"ts_in_delta":917,"sequence":144000,"symbol":"FCEU SI 20260615 PS"}
{"ts_recv":"2026-04-07T02:03:59.420688104Z","hd":{"ts_event":"2026-04-07T02:03:59.420669005Z","rtype":160,"publisher_id":101,"instrument_id":436},"action":"A","side":"B","price":"1.156590000","size":30,"channel_id":23,"order_id":"10998899476275450993","flags":0,"ts_in_delta":917,"sequence":144000,"symbol":"FCEU SI 20260615 PS"}
{"ts_recv":"2026-04-07T02:03:59.420688104Z","hd":{"ts_event":"2026-04-07T02:03:59.420669005Z","rtype":160,"publisher_id":101,"instrument_id":436},"action":"C","side":"A","price":"1.156700000","size":30,"channel_id":23,"order_id":"1775527439394704974","flags":0,"ts_in_delta":917,"sequence":144000,"symbol":"FCEU SI 20260615 PS"}
{"ts_recv":"2026-04-07T02:03:59.420688104Z","hd":{"ts_event":"2026-04-07T02:03:59.420669005Z","rtype":160,"publisher_id":101,"instrument_id":436},"action":"A","side":"A","price":"1.156690000","size":30,"channel_id":23,"order_id":"1775527439420675185","flags":128,"ts_in_delta":917,"sequence":144000,"symbol":"FCEU SI 20260615 PS"}
{"ts_recv":"2026-04-07T02:04:06.092134734Z","hd":{"ts_event":"2026-04-07T02:04:06.092112243Z","rtype":160,"publisher_id":101,"instrument_id":436},"action":"C","side":"B","price":"1.156590000","size":30,"channel_id":23,"order_id":"10998899476275450993","flags":0,"ts_in_delta":873,"sequence":144111,"symbol":"FCEU SI 20260615 PS"}
{"ts_recv":"2026-04-07T02:04:06.092134734Z","hd":{"ts_event":"2026-04-07T02:04:06.092112243Z","rtype":160,"publisher_id":101,"instrument_id":436},"action":"A","side":"B","price":"1.156580000","size":30,"channel_id":23,"order_id":"10998899482946894153","flags":0,"ts_in_delta":873,"sequence":144111,"symbol":"FCEU SI 20260615 PS"}
{"ts_recv":"2026-04-07T02:04:06.092134734Z","hd":{"ts_event":"2026-04-07T02:04:06.092112243Z","rtype":160,"publisher_id":101,"instrument_id":436},"action":"C","side":"A","price":"1.156690000","size":30,"channel_id":23,"order_id":"1775527439420675185","flags":0,"ts_in_delta":873,"sequence":144111,"symbol":"FCEU SI 20260615 PS"}
{"ts_recv":"2026-04-07T02:04:06.092134734Z","hd":{"ts_event":"2026-04-07T02:04:06.092112243Z","rtype":160,"publisher_id":101,"instrument_id":436},"action":"A","side":"A","price":"1.156680000","size":30,"channel_id":23,"order_id":"1775527446092118345","flags":128,"ts_in_delta":873,"sequence":144111,"symbol":"FCEU SI 20260615 PS"}
{"ts_recv":"2026-04-07T02:04:06.092186932Z","hd":{"ts_event":"2026-04-07T02:04:06.092169313Z","rtype":160,"publisher_id":101,"instrument_id":436},"action":"C","side":"B","price":"1.156590000","size":30,"channel_id":23,"order_id":"10998899476275384292","flags":0,"ts_in_delta":897,"sequence":144112,"symbol":"FCEU SI 20260615 PS"}
{"ts_recv":"2026-04-07T02:04:06.092186932Z","hd":{"ts_event":"2026-04-07T02:04:06.092169313Z","rtype":160,"publisher_id":101,"instrument_id":436},"action":"A","side":"B","price":"1.156570000","size":30,"channel_id":23,"order_id":"10998899482946951106","flags":0,"ts_in_delta":897,"sequence":144112,"symbol":"FCEU SI 20260615 PS"}
{"ts_recv":"2026-04-07T02:04:06.092186932Z","hd":{"ts_event":"2026-04-07T02:04:06.092169313Z","rtype":160,"publisher_id":101,"instrument_id":436},"action":"C","side":"A","price":"1.156690000","size":30,"channel_id":23,"order_id":"1775527439420608484","flags":0,"ts_in_delta":897,"sequence":144112,"symbol":"FCEU SI 20260615 PS"}
{"ts_recv":"2026-04-07T02:04:06.092186932Z","hd":{"ts_event":"2026-04-07T02:04:06.092169313Z","rtype":160,"publisher_id":101,"instrument_id":436},"action":"A","side":"A","price":"1.156670000","size":30,"channel_id":23,"order_id":"1775527446092175298","flags":128,"ts_in_delta":897,"sequence":144112,"symbol":"FCEU SI 20260615 PS"}
{"ts_recv":"2026-04-07T02:04:06.092246188Z","hd":{"ts_event":"2026-04-07T02:04:06.092226415Z","rtype":160,"publisher_id":101,"instrument_id":436},"action":"C","side":"B","price":"1.156580000","size":30,"channel_id":23,"order_id":"10998899482946894153","flags":0,"ts_in_delta":952,"sequence":144113,"symbol":"FCEU SI 20260615 PS"}
{"ts_recv":"2026-04-07T02:04:06.092246188Z","hd":{"ts_event":"2026-04-07T02:04:06.092226415Z","rtype":160,"publisher_id":101,"instrument_id":436},"action":"A","side":"B","price":"1.156570000","size":30,"channel_id":23,"order_id":"10998899482947008500","flags":0,"ts_in_delta":952,"sequence":144113,"symbol":"FCEU SI 20260615 PS"}
{"ts_recv":"2026-04-07T02:04:06.092246188Z","hd":{"ts_event":"2026-04-07T02:04:06.092226415Z","rtype":160,"publisher_id":101,"instrument_id":436},"action":"C","side":"A","price":"1.156680000","size":30,"channel_id":23,"order_id":"1775527446092118345","flags":0,"ts_in_delta":952,"sequence":144113,"symbol":"FCEU SI 20260615 PS"}
{"ts_recv":"2026-04-07T02:04:06.092246188Z","hd":{"ts_event":"2026-04-07T02:04:06.092226415Z","rtype":160,"publisher_id":101,"instrument_id":436},"action":"A","side":"A","price":"1.156670000","size":30,"channel_id":23,"order_id":"1775527446092232692","flags":128,"ts_in_delta":952,"sequence":144113,"symbol":"FCEU SI 20260615 PS"}
{"ts_recv":"2026-04-07T02:04:23.988838330Z","hd":{"ts_event":"2026-04-07T02:04:23.988815163Z","rtype":160,"publisher_id":101,"instrument_id":436},"action":"C","side":"B","price":"1.156570000","size":30,"channel_id":23,"order_id":"10998899482947008500","flags":0,"ts_in_delta":898,"sequence":144250,"symbol":"FCEU SI 20260615 PS"}
{"ts_recv":"2026-04-07T02:04:23.988838330Z","hd":{"ts_event":"2026-04-07T02:04:23.988815163Z","rtype":160,"publisher_id":101,"instrument_id":436},"action":"A","side":"B","price":"1.156580000","size":30,"channel_id":23,"order_id":"10998899500843596991","flags":0,"ts_in_delta":898,"sequence":144250,"symbol":"FCEU SI 20260615 PS"}
{"ts_recv":"2026-04-07T02:04:23.988838330Z","hd":{"ts_event":"2026-04-07T02:04:23.988815163Z","rtype":160,"publisher_id":101,"instrument_id":436},"action":"C","side":"A","price":"1.156670000","size":30,"channel_id":23,"order_id":"1775527446092232692","flags":0,"ts_in_delta":898,"sequence":144250,"symbol":"FCEU SI 20260615 PS"}
{"ts_recv":"2026-04-07T02:04:23.988838330Z","hd":{"ts_event":"2026-04-07T02:04:23.988815163Z","rtype":160,"publisher_id":101,"instrument_id":436},"action":"A","side":"A","price":"1.156680000","size":30,"channel_id":23,"order_id":"1775527463988821183","flags":128,"ts_in_delta":898,"sequence":144250,"symbol":"FCEU SI 20260615 PS"}
{"ts_recv":"2026-04-07T02:04:29.098560605Z","hd":{"ts_event":"2026-04-07T02:04:29.098538629Z","rtype":160,"publisher_id":101,"instrument_id":436},"action":"C","side":"B","price":"1.156570000","size":30,"channel_id":23,"order_id":"10998899482946951106","flags":0,"ts_in_delta":920,"sequence":144269,"symbol":"FCEU SI 20260615 PS"}
{"ts_recv":"2026-04-07T02:04:29.098560605Z","hd":{"ts_event":"2026-04-07T02:04:29.098538629Z","rtype":160,"publisher_id":101,"instrument_id":436},"action":"A","side":"B","price":"1.156590000","size":30,"channel_id":23,"order_id":"10998899505953320602","flags":0,"ts_in_delta":920,"sequence":144269,"symbol":"FCEU SI 20260615 PS"}
{"ts_recv":"2026-04-07T02:04:29.098560605Z","hd":{"ts_event":"2026-04-07T02:04:29.098538629Z","rtype":160,"publisher_id":101,"instrument_id":436},"action":"C","side":"A","price":"1.156670000","size":30,"channel_id":23,"order_id":"1775527446092175298","flags":0,"ts_in_delta":920,"sequence":144269,"symbol":"FCEU SI 20260615 PS"}
{"ts_recv":"2026-04-07T02:04:29.098560605Z","hd":{"ts_event":"2026-04-07T02:04:29.098538629Z","rtype":160,"publisher_id":101,"instrument_id":436},"action":"A","side":"A","price":"1.156690000","size":30,"channel_id":23,"order_id":"1775527469098544794","flags":128,"ts_in_delta":920,"sequence":144269,"symbol":"FCEU SI 20260615 PS"}
{"ts_recv":"2026-04-07T02:04:29.098639598Z","hd":{"ts_event":"2026-04-07T02:04:29.098618265Z","rtype":160,"publisher_id":101,"instrument_id":436},"action":"C","side":"B","price":"1.156580000","size":30,"channel_id":23,"order_id":"10998899500843596991","flags":0,"ts_in_delta":930,"sequence":144270,"symbol":"FCEU SI 20260615 PS"}
{"ts_recv":"2026-04-07T02:04:29.098639598Z","hd":{"ts_event":"2026-04-07T02:04:29.098618265Z","rtype":160,"publisher_id":101,"instrument_id":436},"action":"A","side":"B","price":"1.156590000","size":30,"channel_id":23,"order_id":"10998899505953400166","flags":0,"ts_in_delta":930,"sequence":144270,"symbol":"FCEU SI 20260615 PS"}
{"ts_recv":"2026-04-07T02:04:29.098639598Z","hd":{"ts_event":"2026-04-07T02:04:29.098618265Z","rtype":160,"publisher_id":101,"instrument_id":436},"action":"C","side":"A","price":"1.156680000","size":30,"channel_id":23,"order_id":"1775527463988821183","flags":0,"ts_in_delta":930,"sequence":144270,"symbol":"FCEU SI 20260615 PS"}
{"ts_recv":"2026-04-07T02:04:29.098639598Z","hd":{"ts_event":"2026-04-07T02:04:29.098618265Z","rtype":160,"publisher_id":101,"instrument_id":436},"action":"A","side":"A","price":"1.156690000","size":30,"channel_id":23,"order_id":"1775527469098624358","flags":128,"ts_in_delta":930,"sequence":144270,"symbol":"FCEU SI 20260615 PS"}
{"ts_recv":"2026-04-07T02:04:29.589532386Z","hd":{"ts_event":"2026-04-07T02:04:29.589511573Z","rtype":160,"publisher_id":101,"instrument_id":436},"action":"C","side":"B","price":"1.156590000","size":30,"channel_id":23,"order_id":"10998899505953400166","flags":0,"ts_in_delta":1095,"sequence":144308,"symbol":"FCEU SI 20260615 PS"}
{"ts_recv":"2026-04-07T02:04:29.589532386Z","hd":{"ts_event":"2026-04-07T02:04:29.589511573Z","rtype":160,"publisher_id":101,"instrument_id":436},"action":"A","side":"B","price":"1.156600000","size":30,"channel_id":23,"order_id":"10998899506444293327","flags":0,"ts_in_delta":1095,"sequence":144308,"symbol":"FCEU SI 20260615 PS"}
{"ts_recv":"2026-04-07T02:04:29.589532386Z","hd":{"ts_event":"2026-04-07T02:04:29.589511573Z","rtype":160,"publisher_id":101,"instrument_id":436},"action":"C","side":"A","price":"1.156690000","size":30,"channel_id":23,"order_id":"1775527469098624358","flags":0,"ts_in_delta":1095,"sequence":144308,"symbol":"FCEU SI 20260615 PS"}
{"ts_recv":"2026-04-07T02:04:29.589532386Z","hd":{"ts_event":"2026-04-07T02:04:29.589511573Z","rtype":160,"publisher_id":101,"instrument_id":436},"action":"A","side":"A","price":"1.156700000","size":30,"channel_id":23,"order_id":"1775527469589517519","flags":128,"ts_in_delta":1095,"sequence":144308,"symbol":"FCEU SI 20260615 PS"}
{"ts_recv":"2026-04-07T02:04:29.589588916Z","hd":{"ts_event":"2026-04-07T02:04:29.589567293Z","rtype":160,"publisher_id":101,"instrument_id":436},"action":"C","side":"B","price":"1.156590000","size":30,"channel_id":23,"order_id":"10998899505953320602","flags":0,"ts_in_delta":946,"sequence":144309,"symbol":"FCEU SI 20260615 PS"}
{"ts_recv":"2026-04-07T02:04:29.589588916Z","hd":{"ts_event":"2026-04-07T02:04:29.589567293Z","rtype":160,"publisher_id":101,"instrument_id":436},"action":"A","side":"B","price":"1.156610000","size":30,"channel_id":23,"order_id":"10998899506444349271","flags":0,"ts_in_delta":946,"sequence":144309,"symbol":"FCEU SI 20260615 PS"}
{"ts_recv":"2026-04-07T02:04:29.589588916Z","hd":{"ts_event":"2026-04-07T02:04:29.589567293Z","rtype":160,"publisher_id":101,"instrument_id":436},"action":"C","side":"A","price":"1.156690000","size":30,"channel_id":23,"order_id":"1775527469098544794","flags":0,"ts_in_delta":946,"sequence":144309,"symbol":"FCEU SI 20260615 PS"}
{"ts_recv":"2026-04-07T02:04:29.589588916Z","hd":{"ts_event":"2026-04-07T02:04:29.589567293Z","rtype":160,"publisher_id":101,"instrument_id":436},"action":"A","side":"A","price":"1.156710000","size":30,"channel_id":23,"order_id":"1775527469589573463","flags":128,"ts_in_delta":946,"sequence":144309,"symbol":"FCEU SI 20260615 PS"}
{"ts_recv":"2026-04-07T02:04:29.589645868Z","hd":{"ts_event":"2026-04-07T02:04:29.589627119Z","rtype":160,"publisher_id":101,"instrument_id":436},"action":"C","side":"B","price":"1.156600000","size":30,"channel_id":23,"order_id":"10998899506444293327","flags":0,"ts_in_delta":926,"sequence":144310,"symbol":"FCEU SI 20260615 PS"}
{"ts_recv":"2026-04-07T02:04:29.589645868Z","hd":{"ts_event":"2026-04-07T02:04:29.589627119Z","rtype":160,"publisher_id":101,"instrument_id":436},"action":"A","side":"B","price":"1.156610000","size":30,"channel_id":23,"order_id":"10998899506444409665","flags":0,"ts_in_delta":926,"sequence":144310,"symbol":"FCEU SI 20260615 PS"}
{"ts_recv":"2026-04-07T02:04:29.589645868Z","hd":{"ts_event":"2026-04-07T02:04:29.589627119Z","rtype":160,"publisher_id":101,"instrument_id":436},"action":"C","side":"A","price":"1.156700000","size":30,"channel_id":23,"order_id":"1775527469589517519","flags":0,"ts_in_delta":926,"sequence":144310,"symbol":"FCEU SI 20260615 PS"}
{"ts_recv":"2026-04-07T02:04:29.589645868Z","hd":{"ts_event":"2026-04-07T02:04:29.589627119Z","rtype":160,"publisher_id":101,"instrument_id":436},"action":"A","side":"A","price":"1.156710000","size":30,"channel_id":23,"order_id":"1775527469589633857","flags":128,"ts_in_delta":926,"sequence":144310,"symbol":"FCEU SI 20260615 PS"}
{"ts_recv":"2026-04-07T02:04:33.540554851Z","hd":{"ts_event":"2026-04-07T02:04:33.540535221Z","rtype":160,"publisher_id":101,"instrument_id":436},"action":"C","side":"B","price":"1.156610000","size":30,"channel_id":23,"order_id":"10998899506444409665","flags":0,"ts_in_delta":1039,"sequence":144361,"symbol":"FCEU SI 20260615 PS"}
{"ts_recv":"2026-04-07T02:04:33.540554851Z","hd":{"ts_event":"2026-04-07T02:04:33.540535221Z","rtype":160,"publisher_id":101,"instrument_id":436},"action":"A","side":"B","price":"1.156600000","size":30,"channel_id":23,"order_id":"10998899510395316990","flags":0,"ts_in_delta":1039,"sequence":144361,"symbol":"FCEU SI 20260615 PS"}
{"ts_recv":"2026-04-07T02:04:33.540554851Z","hd":{"ts_event":"2026-04-07T02:04:33.540535221Z","rtype":160,"publisher_id":101,"instrument_id":436},"action":"C","side":"A","price":"1.156710000","size":30,"channel_id":23,"order_id":"1775527469589633857","flags":0,"ts_in_delta":1039,"sequence":144361,"symbol":"FCEU SI 20260615 PS"}
{"ts_recv":"2026-04-07T02:04:33.540554851Z","hd":{"ts_event":"2026-04-07T02:04:33.540535221Z","rtype":160,"publisher_id":101,"instrument_id":436},"action":"A","side":"A","price":"1.156700000","size":30,"channel_id":23,"order_id":"1775527473540541182","flags":128,"ts_in_delta":1039,"sequence":144361,"symbol":"FCEU SI 20260615 PS"}
{"ts_recv":"2026-04-07T02:04:33.740979015Z","hd":{"ts_event":"2026-04-07T02:04:33.740962499Z","rtype":160,"publisher_id":101,"instrument_id":436},"action":"C","side":"B","price":"1.156600000","size":30,"channel_id":23,"order_id":"10998899510395316990","flags":0,"ts_in_delta":971,"sequence":144390,"symbol":"FCEU SI 20260615 PS"}
{"ts_recv":"2026-04-07T02:04:33.740979015Z","hd":{"ts_event":"2026-04-07T02:04:33.740962499Z","rtype":160,"publisher_id":101,"instrument_id":436},"action":"A","side":"B","price":"1.156610000","size":30,"channel_id":23,"order_id":"10998899510595744366","flags":0,"ts_in_delta":971,"sequence":144390,"symbol":"FCEU SI 20260615 PS"}
{"ts_recv":"2026-04-07T02:04:33.740979015Z","hd":{"ts_event":"2026-04-07T02:04:33.740962499Z","rtype":160,"publisher_id":101,"instrument_id":436},"action":"C","side":"A","price":"1.156700000","size":30,"channel_id":23,"order_id":"1775527473540541182","flags":0,"ts_in_delta":971,"sequence":144390,"symbol":"FCEU SI 20260615 PS"}
{"ts_recv":"2026-04-07T02:04:33.740979015Z","hd":{"ts_event":"2026-04-07T02:04:33.740962499Z","rtype":160,"publisher_id":101,"instrument_id":436},"action":"A","side":"A","price":"1.156710000","size":30,"channel_id":23,"order_id":"1775527473740968558","flags":128,"ts_in_delta":971,"sequence":144390,"symbol":"FCEU SI 20260615 PS"}
{"ts_recv":"2026-04-07T02:04:36.050987141Z","hd":{"ts_event":"2026-04-07T02:04:36.050966401Z","rtype":160,"publisher_id":101,"instrument_id":436},"action":"C","side":"B","price":"1.156610000","size":30,"channel_id":23,"order_id":"10998899510595744366","flags":0,"ts_in_delta":934,"sequence":144436,"symbol":"FCEU SI 20260615 PS"}
{"ts_recv":"2026-04-07T02:04:36.050987141Z","hd":{"ts_event":"2026-04-07T02:04:36.050966401Z","rtype":160,"publisher_id":101,"instrument_id":436},"action":"A","side":"B","price":"1.156600000","size":30,"channel_id":23,"order_id":"10998899512905748440","flags":0,"ts_in_delta":934,"sequence":144436,"symbol":"FCEU SI 20260615 PS"}
{"ts_recv":"2026-04-07T02:04:36.050987141Z","hd":{"ts_event":"2026-04-07T02:04:36.050966401Z","rtype":160,"publisher_id":101,"instrument_id":436},"action":"C","side":"A","price":"1.156710000","size":30,"channel_id":23,"order_id":"1775527473740968558","flags":0,"ts_in_delta":934,"sequence":144436,"symbol":"FCEU SI 20260615 PS"}
{"ts_recv":"2026-04-07T02:04:36.050987141Z","hd":{"ts_event":"2026-04-07T02:04:36.050966401Z","rtype":160,"publisher_id":101,"instrument_id":436},"action":"A","side":"A","price":"1.156700000","size":30,"channel_id":23,"order_id":"1775527476050972632","flags":128,"ts_in_delta":934,"sequence":144436,"symbol":"FCEU SI 20260615 PS"}
{"ts_recv":"2026-04-07T02:04:36.069239530Z","hd":{"ts_event":"2026-04-07T02:04:36.069220065Z","rtype":160,"publisher_id":101,"instrument_id":436},"action":"C","side":"B","price":"1.156600000","size":30,"channel_id":23,"order_id":"10998899512905748440","flags":0,"ts_in_delta":894,"sequence":144437,"symbol":"FCEU SI 20260615 PS"}
{"ts_recv":"2026-04-07T02:04:36.069239530Z","hd":{"ts_event":"2026-04-07T02:04:36.069220065Z","rtype":160,"publisher_id":101,"instrument_id":436},"action":"A","side":"B","price":"1.156610000","size":30,"channel_id":23,"order_id":"10998899512924001691","flags":0,"ts_in_delta":894,"sequence":144437,"symbol":"FCEU SI 20260615 PS"}
{"ts_recv":"2026-04-07T02:04:36.069239530Z","hd":{"ts_event":"2026-04-07T02:04:36.069220065Z","rtype":160,"publisher_id":101,"instrument_id":436},"action":"C","side":"A","price":"1.156700000","size":30,"channel_id":23,"order_id":"1775527476050972632","flags":0,"ts_in_delta":894,"sequence":144437,"symbol":"FCEU SI 20260615 PS"}
{"ts_recv":"2026-04-07T02:04:36.069239530Z","hd":{"ts_event":"2026-04-07T02:04:36.069220065Z","rtype":160,"publisher_id":101,"instrument_id":436},"action":"A","side":"A","price":"1.156710000","size":30,"channel_id":23,"order_id":"1775527476069225883","flags":128,"ts_in_delta":894,"sequence":144437,"symbol":"FCEU SI 20260615 PS"}
{"ts_recv":"2026-04-07T02:04:41.688745011Z","hd":{"ts_event":"2026-04-07T02:04:41.688724719Z","rtype":160,"publisher_id":101,"instrument_id":436},"action":"C","side":"B","price":"1.156610000","size":30,"channel_id":23,"order_id":"10998899512924001691","flags":0,"ts_in_delta":996,"sequence":144497,"symbol":"FCEU SI 20260615 PS"}
{"ts_recv":"2026-04-07T02:04:41.688745011Z","hd":{"ts_event":"2026-04-07T02:04:41.688724719Z","rtype":160,"publisher_id":101,"instrument_id":436},"action":"A","side":"B","price":"1.156600000","size":30,"channel_id":23,"order_id":"10998899518543506561","flags":0,"ts_in_delta":996,"sequence":144497,"symbol":"FCEU SI 20260615 PS"}
{"ts_recv":"2026-04-07T02:04:41.688745011Z","hd":{"ts_event":"2026-04-07T02:04:41.688724719Z","rtype":160,"publisher_id":101,"instrument_id":436},"action":"C","side":"A","price":"1.156710000","size":30,"channel_id":23,"order_id":"1775527476069225883","flags":0,"ts_in_delta":996,"sequence":144497,"symbol":"FCEU SI 20260615 PS"}
{"ts_recv":"2026-04-07T02:04:41.688745011Z","hd":{"ts_event":"2026-04-07T02:04:41.688724719Z","rtype":160,"publisher_id":101,"instrument_id":436},"action":"A","side":"A","price":"1.156700000","size":30,"channel_id":23,"order_id":"1775527481688730753","flags":128,"ts_in_delta":996,"sequence":144497,"symbol":"FCEU SI 20260615 PS"}
{"ts_recv":"2026-04-07T02:04:42.279510169Z","hd":{"ts_event":"2026-04-07T02:04:42.279492223Z","rtype":160,"publisher_id":101,"instrument_id":436},"action":"C","side":"B","price":"1.156600000","size":30,"channel_id":23,"order_id":"10998899518543506561","flags":0,"ts_in_delta":979,"sequence":144508,"symbol":"FCEU SI 20260615 PS"}
{"ts_recv":"2026-04-07T02:04:42.279510169Z","hd":{"ts_event":"2026-04-07T02:04:42.279492223Z","rtype":160,"publisher_id":101,"instrument_id":436},"action":"A","side":"B","price":"1.156610000","size":30,"channel_id":23,"order_id":"10998899519134274185","flags":0,"ts_in_delta":979,"sequence":144508,"symbol":"FCEU SI 20260615 PS"}
{"ts_recv":"2026-04-07T02:04:42.279510169Z","hd":{"ts_event":"2026-04-07T02:04:42.279492223Z","rtype":160,"publisher_id":101,"instrument_id":436},"action":"C","side":"A","price":"1.156700000","size":30,"channel_id":23,"order_id":"1775527481688730753","flags":0,"ts_in_delta":979,"sequence":144508,"symbol":"FCEU SI 20260615 PS"}
{"ts_recv":"2026-04-07T02:04:42.279510169Z","hd":{"ts_event":"2026-04-07T02:04:42.279492223Z","rtype":160,"publisher_id":101,"instrument_id":436},"action":"A","side":"A","price":"1.156710000","size":30,"channel_id":23,"order_id":"1775527482279498377","flags":128,"ts_in_delta":979,"sequence":144508,"symbol":"FCEU SI 20260615 PS"}
{"ts_recv":"2026-04-07T02:04:43.585138148Z","hd":{"ts_event":"2026-04-07T02:04:43.585113081Z","rtype":160,"publisher_id":101,"instrument_id":436},"action":"C","side":"B","price":"1.156610000","size":30,"channel_id":23,"order_id":"10998899519134274185","flags":0,"ts_in_delta":1815,"sequence":144519,"symbol":"FCEU SI 20260615 PS"}
{"ts_recv":"2026-04-07T02:04:43.585138148Z","hd":{"ts_event":"2026-04-07T02:04:43.585113081Z","rtype":160,"publisher_id":101,"instrument_id":436},"action":"A","side":"B","price":"1.156600000","size":30,"channel_id":23,"order_id":"10998899520439897119","flags":0,"ts_in_delta":1815,"sequence":144519,"symbol":"FCEU SI 20260615 PS"}
{"ts_recv":"2026-04-07T02:04:43.585138148Z","hd":{"ts_event":"2026-04-07T02:04:43.585113081Z","rtype":160,"publisher_id":101,"instrument_id":436},"action":"C","side":"A","price":"1.156710000","size":30,"channel_id":23,"order_id":"1775527482279498377","flags":0,"ts_in_delta":1815,"sequence":144519,"symbol":"FCEU SI 20260615 PS"}
{"ts_recv":"2026-04-07T02:04:43.585138148Z","hd":{"ts_event":"2026-04-07T02:04:43.585113081Z","rtype":160,"publisher_id":101,"instrument_id":436},"action":"A","side":"A","price":"1.156700000","size":30,"channel_id":23,"order_id":"1775527483585121311","flags":128,"ts_in_delta":1815,"sequence":144519,"symbol":"FCEU SI 20260615 PS"}
{"ts_recv":"2026-04-07T02:04:43.586341818Z","hd":{"ts_event":"2026-04-07T02:04:43.586320339Z","rtype":160,"publisher_id":101,"instrument_id":436},"action":"C","side":"B","price":"1.156610000","size":30,"channel_id":23,"order_id":"10998899506444349271","flags":0,"ts_in_delta":936,"sequence":144521,"symbol":"FCEU SI 20260615 PS"}
{"ts_recv":"2026-04-07T02:04:43.586341818Z","hd":{"ts_event":"2026-04-07T02:04:43.586320339Z","rtype":160,"publisher_id":101,"instrument_id":436},"action":"A","side":"B","price":"1.156590000","size":30,"channel_id":23,"order_id":"10998899520441102933","flags":0,"ts_in_delta":936,"sequence":144521,"symbol":"FCEU SI 20260615 PS"}
{"ts_recv":"2026-04-07T02:04:43.586341818Z","hd":{"ts_event":"2026-04-07T02:04:43.586320339Z","rtype":160,"publisher_id":101,"instrument_id":436},"action":"C","side":"A","price":"1.156710000","size":30,"channel_id":23,"order_id":"1775527469589573463","flags":0,"ts_in_delta":936,"sequence":144521,"symbol":"FCEU SI 20260615 PS"}
{"ts_recv":"2026-04-07T02:04:43.586341818Z","hd":{"ts_event":"2026-04-07T02:04:43.586320339Z","rtype":160,"publisher_id":101,"instrument_id":436},"action":"A","side":"A","price":"1.156690000","size":30,"channel_id":23,"order_id":"1775527483586327125","flags":128,"ts_in_delta":936,"sequence":144521,"symbol":"FCEU SI 20260615 PS"}
{"ts_recv":"2026-04-07T02:04:43.586405199Z","hd":{"ts_event":"2026-04-07T02:04:43.586388041Z","rtype":160,"publisher_id":101,"instrument_id":436},"action":"C","side":"B","price":"1.156600000","size":30,"channel_id":23,"order_id":"10998899520439897119","flags":0,"ts_in_delta":1063,"sequence":144522,"symbol":"FCEU SI 20260615 PS"}
{"ts_recv":"2026-04-07T02:04:43.586405199Z","hd":{"ts_event":"2026-04-07T02:04:43.586388041Z","rtype":160,"publisher_id":101,"instrument_id":436},"action":"A","side":"B","price":"1.156590000","size":30,"channel_id":23,"order_id":"10998899520441169843","flags":0,"ts_in_delta":1063,"sequence":144522,"symbol":"FCEU SI 20260615 PS"}
{"ts_recv":"2026-04-07T02:04:43.586405199Z","hd":{"ts_event":"2026-04-07T02:04:43.586388041Z","rtype":160,"publisher_id":101,"instrument_id":436},"action":"C","side":"A","price":"1.156700000","size":30,"channel_id":23,"order_id":"1775527483585121311","flags":0,"ts_in_delta":1063,"sequence":144522,"symbol":"FCEU SI 20260615 PS"}
{"ts_recv":"2026-04-07T02:04:43.586405199Z","hd":{"ts_event":"2026-04-07T02:04:43.586388041Z","rtype":160,"publisher_id":101,"instrument_id":436},"action":"A","side":"A","price":"1.156690000","size":30,"channel_id":23,"order_id":"1775527483586394035","flags":128,"ts_in_delta":1063,"sequence":144522,"symbol":"FCEU SI 20260615 PS"}
{"ts_recv":"2026-04-07T02:04:43.589886583Z","hd":{"ts_event":"2026-04-07T02:04:43.589868745Z","rtype":160,"publisher_id":101,"instrument_id":436},"action":"C","side":"B","price":"1.156590000","size":30,"channel_id":23,"order_id":"10998899520441169843","flags":0,"ts_in_delta":947,"sequence":144526,"symbol":"FCEU SI 20260615 PS"}
{"ts_recv":"2026-04-07T02:04:43.589886583Z","hd":{"ts_event":"2026-04-07T02:04:43.589868745Z","rtype":160,"publisher_id":101,"instrument_id":436},"action":"A","side":"B","price":"1.156580000","size":30,"channel_id":23,"order_id":"10998899520444650849","flags":0,"ts_in_delta":947,"sequence":144526,"symbol":"FCEU SI 20260615 PS"}
{"ts_recv":"2026-04-07T02:04:43.589886583Z","hd":{"ts_event":"2026-04-07T02:04:43.589868745Z","rtype":160,"publisher_id":101,"instrument_id":436},"action":"C","side":"A","price":"1.156690000","size":30,"channel_id":23,"order_id":"1775527483586394035","flags":0,"ts_in_delta":947,"sequence":144526,"symbol":"FCEU SI 20260615 PS"}
{"ts_recv":"2026-04-07T02:04:43.589886583Z","hd":{"ts_event":"2026-04-07T02:04:43.589868745Z","rtype":160,"publisher_id":101,"instrument_id":436},"action":"A","side":"A","price":"1.156680000","size":30,"channel_id":23,"order_id":"1775527483589875041","flags":128,"ts_in_delta":947,"sequence":144526,"symbol":"FCEU SI 20260615 PS"}
{"ts_recv":"2026-04-07T02:04:43.633479888Z","hd":{"ts_event":"2026-04-07T02:04:43.633458467Z","rtype":160,"publisher_id":101,"instrument_id":436},"action":"C","side":"B","price":"1.156590000","size":30,"channel_id":23,"order_id":"10998899520441102933","flags":0,"ts_in_delta":953,"sequence":144539,"symbol":"FCEU SI 20260615 PS"}
{"ts_recv":"2026-04-07T02:04:43.633479888Z","hd":{"ts_event":"2026-04-07T02:04:43.633458467Z","rtype":160,"publisher_id":101,"instrument_id":436},"action":"A","side":"B","price":"1.156570000","size":30,"channel_id":23,"order_id":"10998899520488240623","flags":0,"ts_in_delta":953,"sequence":144539,"symbol":"FCEU SI 20260615 PS"}
{"ts_recv":"2026-04-07T02:04:43.633479888Z","hd":{"ts_event":"2026-04-07T02:04:43.633458467Z","rtype":160,"publisher_id":101,"instrument_id":436},"action":"C","side":"A","price":"1.156690000","size":30,"channel_id":23,"order_id":"1775527483586327125","flags":0,"ts_in_delta":953,"sequence":144539,"symbol":"FCEU SI 20260615 PS"}
{"ts_recv":"2026-04-07T02:04:43.633479888Z","hd":{"ts_event":"2026-04-07T02:04:43.633458467Z","rtype":160,"publisher_id":101,"instrument_id":436},"action":"A","side":"A","price":"1.156670000","size":30,"channel_id":23,"order_id":"1775527483633464815","flags":128,"ts_in_delta":953,"sequence":144539,"symbol":"FCEU SI 20260615 PS"}
{"ts_recv":"2026-04-07T02:04:43.633540627Z","hd":{"ts_event":"2026-04-07T02:04:43.633525015Z","rtype":160,"publisher_id":101,"instrument_id":436},"action":"C","side":"B","price":"1.156580000","size":30,"channel_id":23,"order_id":"10998899520444650849","flags":0,"ts_in_delta":929,"sequence":144540,"symbol":"FCEU SI 20260615 PS"}
{"ts_recv":"2026-04-07T02:04:43.633540627Z","hd":{"ts_event":"2026-04-07T02:04:43.633525015Z","rtype":160,"publisher_id":101,"instrument_id":436},"action":"A","side":"B","price":"1.156570000","size":30,"channel_id":23,"order_id":"10998899520488306641","flags":0,"ts_in_delta":929,"sequence":144540,"symbol":"FCEU SI 20260615 PS"}
{"ts_recv":"2026-04-07T02:04:43.633540627Z","hd":{"ts_event":"2026-04-07T02:04:43.633525015Z","rtype":160,"publisher_id":101,"instrument_id":436},"action":"C","side":"A","price":"1.156680000","size":30,"channel_id":23,"order_id":"1775527483589875041","flags":0,"ts_in_delta":929,"sequence":144540,"symbol":"FCEU SI 20260615 PS"}
{"ts_recv":"2026-04-07T02:04:43.633540627Z","hd":{"ts_event":"2026-04-07T02:04:43.633525015Z","rtype":160,"publisher_id":101,"instrument_id":436},"action":"A","side":"A","price":"1.156670000","size":30,"channel_id":23,"order_id":"1775527483633530833","flags":128,"ts_in_delta":929,"sequence":144540,"symbol":"FCEU SI 20260615 PS"}
{"ts_recv":"2026-04-07T02:04:56.533898479Z","hd":{"ts_event":"2026-04-07T02:04:56.533869257Z","rtype":160,"publisher_id":101,"instrument_id":436},"action":"C","side":"B","price":"1.156570000","size":30,"channel_id":23,"order_id":"10998899520488306641","flags":0,"ts_in_delta":1314,"sequence":144600,"symbol":"FCEU SI 20260615 PS"}
{"ts_recv":"2026-04-07T02:04:56.533898479Z","hd":{"ts_event":"2026-04-07T02:04:56.533869257Z","rtype":160,"publisher_id":101,"instrument_id":436},"action":"A","side":"B","price":"1.156560000","size":30,"channel_id":23,"order_id":"10998899533388655788","flags":0,"ts_in_delta":1314,"sequence":144600,"symbol":"FCEU SI 20260615 PS"}
{"ts_recv":"2026-04-07T02:04:56.533898479Z","hd":{"ts_event":"2026-04-07T02:04:56.533869257Z","rtype":160,"publisher_id":101,"instrument_id":436},"action":"C","side":"A","price":"1.156670000","size":30,"channel_id":23,"order_id":"1775527483633530833","flags":0,"ts_in_delta":1314,"sequence":144600,"symbol":"FCEU SI 20260615 PS"}
{"ts_recv":"2026-04-07T02:04:56.533898479Z","hd":{"ts_event":"2026-04-07T02:04:56.533869257Z","rtype":160,"publisher_id":101,"instrument_id":436},"action":"A","side":"A","price":"1.156660000","size":30,"channel_id":23,"order_id":"1775527496533879980","flags":128,"ts_in_delta":1314,"sequence":144600,"symbol":"FCEU SI 20260615 PS"}
{"ts_recv":"2026-04-07T02:04:56.533965330Z","hd":{"ts_event":"2026-04-07T02:04:56.533944061Z","rtype":160,"publisher_id":101,"instrument_id":436},"action":"C","side":"B","price":"1.156570000","size":30,"channel_id":23,"order_id":"10998899520488240623","flags":0,"ts_in_delta":891,"sequence":144601,"symbol":"FCEU SI 20260615 PS"}
{"ts_recv":"2026-04-07T02:04:56.533965330Z","hd":{"ts_event":"2026-04-07T02:04:56.533944061Z","rtype":160,"publisher_id":101,"instrument_id":436},"action":"A","side":"B","price":"1.156550000","size":30,"channel_id":23,"order_id":"10998899533388726607","flags":0,"ts_in_delta":891,"sequence":144601,"symbol":"FCEU SI 20260615 PS"}
{"ts_recv":"2026-04-07T02:04:56.533965330Z","hd":{"ts_event":"2026-04-07T02:04:56.533944061Z","rtype":160,"publisher_id":101,"instrument_id":436},"action":"C","side":"A","price":"1.156670000","size":30,"channel_id":23,"order_id":"1775527483633464815","flags":0,"ts_in_delta":891,"sequence":144601,"symbol":"FCEU SI 20260615 PS"}
{"ts_recv":"2026-04-07T02:04:56.533965330Z","hd":{"ts_event":"2026-04-07T02:04:56.533944061Z","rtype":160,"publisher_id":101,"instrument_id":436},"action":"A","side":"A","price":"1.156650000","size":30,"channel_id":23,"order_id":"1775527496533950799","flags":128,"ts_in_delta":891,"sequence":144601,"symbol":"FCEU SI 20260615 PS"}
{"ts_recv":"2026-04-07T02:04:56.534027889Z","hd":{"ts_event":"2026-04-07T02:04:56.534010473Z","rtype":160,"publisher_id":101,"instrument_id":436},"action":"C","side":"B","price":"1.156560000","size":30,"channel_id":23,"order_id":"10998899533388655788","flags":0,"ts_in_delta":881,"sequence":144602,"symbol":"FCEU SI 20260615 PS"}
{"ts_recv":"2026-04-07T02:04:56.534027889Z","hd":{"ts_event":"2026-04-07T02:04:56.534010473Z","rtype":160,"publisher_id":101,"instrument_id":436},"action":"A","side":"B","price":"1.156550000","size":30,"channel_id":23,"order_id":"10998899533388792523","flags":0,"ts_in_delta":881,"sequence":144602,"symbol":"FCEU SI 20260615 PS"}
{"ts_recv":"2026-04-07T02:04:56.534027889Z","hd":{"ts_event":"2026-04-07T02:04:56.534010473Z","rtype":160,"publisher_id":101,"instrument_id":436},"action":"C","side":"A","price":"1.156660000","size":30,"channel_id":23,"order_id":"1775527496533879980","flags":0,"ts_in_delta":881,"sequence":144602,"symbol":"FCEU SI 20260615 PS"}
{"ts_recv":"2026-04-07T02:04:56.534027889Z","hd":{"ts_event":"2026-04-07T02:04:56.534010473Z","rtype":160,"publisher_id":101,"instrument_id":436},"action":"A","side":"A","price":"1.156650000","size":30,"channel_id":23,"order_id":"1775527496534016715","flags":128,"ts_in_delta":881,"sequence":144602,"symbol":"FCEU SI 20260615 PS"}
{"ts_recv":"2026-04-07T02:05:16.711541939Z","hd":{"ts_event":"2026-04-07T02:05:16.711510175Z","rtype":160,"publisher_id":101,"instrument_id":436},"action":"C","side":"B","price":"1.156550000","size":30,"channel_id":23,"order_id":"10998899533388792523","flags":0,"ts_in_delta":1405,"sequence":144836,"symbol":"FCEU SI 20260615 PS"}
{"ts_recv":"2026-04-07T02:05:16.711541939Z","hd":{"ts_event":"2026-04-07T02:05:16.711510175Z","rtype":160,"publisher_id":101,"instrument_id":436},"action":"A","side":"B","price":"1.156540000","size":30,"channel_id":23,"order_id":"10998899553566298879","flags":0,"ts_in_delta":1405,"sequence":144836,"symbol":"FCEU SI 20260615 PS"}
{"ts_recv":"2026-04-07T02:05:16.711541939Z","hd":{"ts_event":"2026-04-07T02:05:16.711510175Z","rtype":160,"publisher_id":101,"instrument_id":436},"action":"C","side":"A","price":"1.156650000","size":30,"channel_id":23,"order_id":"1775527496534016715","flags":0,"ts_in_delta":1405,"sequence":144836,"symbol":"FCEU SI 20260615 PS"}
{"ts_recv":"2026-04-07T02:05:16.711541939Z","hd":{"ts_event":"2026-04-07T02:05:16.711510175Z","rtype":160,"publisher_id":101,"instrument_id":436},"action":"A","side":"A","price":"1.156640000","size":30,"channel_id":23,"order_id":"1775527516711523071","flags":128,"ts_in_delta":1405,"sequence":144836,"symbol":"FCEU SI 20260615 PS"}
{"ts_recv":"2026-04-07T02:05:16.711624380Z","hd":{"ts_event":"2026-04-07T02:05:16.711606421Z","rtype":160,"publisher_id":101,"instrument_id":436},"action":"C","side":"B","price":"1.156540000","size":30,"channel_id":23,"order_id":"10998899553566298879","flags":0,"ts_in_delta":986,"sequence":144837,"symbol":"FCEU SI 20260615 PS"}
{"ts_recv":"2026-04-07T02:05:16.711624380Z","hd":{"ts_event":"2026-04-07T02:05:16.711606421Z","rtype":160,"publisher_id":101,"instrument_id":436},"action":"A","side":"B","price":"1.156530000","size":30,"channel_id":23,"order_id":"10998899553566388221","flags":0,"ts_in_delta":986,"sequence":144837,"symbol":"FCEU SI 20260615 PS"}
{"ts_recv":"2026-04-07T02:05:16.711624380Z","hd":{"ts_event":"2026-04-07T02:05:16.711606421Z","rtype":160,"publisher_id":101,"instrument_id":436},"action":"C","side":"A","price":"1.156640000","size":30,"channel_id":23,"order_id":"1775527516711523071","flags":0,"ts_in_delta":986,"sequence":144837,"symbol":"FCEU SI 20260615 PS"}
{"ts_recv":"2026-04-07T02:05:16.711624380Z","hd":{"ts_event":"2026-04-07T02:05:16.711606421Z","rtype":160,"publisher_id":101,"instrument_id":436},"action":"A","side":"A","price":"1.156630000","size":30,"channel_id":23,"order_id":"1775527516711612413","flags":128,"ts_in_delta":986,"sequence":144837,"symbol":"FCEU SI 20260615 PS"}
{"ts_recv":"2026-04-07T02:05:16.711674973Z","hd":{"ts_event":"2026-04-07T02:05:16.711658995Z","rtype":160,"publisher_id":101,"instrument_id":436},"action":"C","side":"B","price":"1.156550000","size":30,"channel_id":23,"order_id":"10998899533388726607","flags":0,"ts_in_delta":957,"sequence":144838,"symbol":"FCEU SI 20260615 PS"}
{"ts_recv":"2026-04-07T02:05:16.711674973Z","hd":{"ts_event":"2026-04-07T02:05:16.711658995Z","rtype":160,"publisher_id":101,"instrument_id":436},"action":"A","side":"B","price":"1.156530000","size":30,"channel_id":23,"order_id":"10998899553566440625","flags":0,"ts_in_delta":957,"sequence":144838,"symbol":"FCEU SI 20260615 PS"}
{"ts_recv":"2026-04-07T02:05:16.711674973Z","hd":{"ts_event":"2026-04-07T02:05:16.711658995Z","rtype":160,"publisher_id":101,"instrument_id":436},"action":"C","side":"A","price":"1.156650000","size":30,"channel_id":23,"order_id":"1775527496533950799","flags":0,"ts_in_delta":957,"sequence":144838,"symbol":"FCEU SI 20260615 PS"}
{"ts_recv":"2026-04-07T02:05:16.711674973Z","hd":{"ts_event":"2026-04-07T02:05:16.711658995Z","rtype":160,"publisher_id":101,"instrument_id":436},"action":"A","side":"A","price":"1.156630000","size":30,"channel_id":23,"order_id":"1775527516711664817","flags":128,"ts_in_delta":957,"sequence":144838,"symbol":"FCEU SI 20260615 PS"}
{"ts_recv":"2026-04-07T02:05:16.711688405Z","hd":{"ts_event":"2026-04-07T02:05:16.711666107Z","rtype":160,"publisher_id":101,"instrument_id":436},"action":"C","side":"B","price":"1.156530000","size":30,"channel_id":23,"order_id":"10998899553566388221","flags":0,"ts_in_delta":937,"sequence":144839,"symbol":"FCEU SI 20260615 PS"}
{"ts_recv":"2026-04-07T02:05:16.711688405Z","hd":{"ts_event":"2026-04-07T02:05:16.711666107Z","rtype":160,"publisher_id":101,"instrument_id":436},"action":"A","side":"B","price":"1.156540000","size":30,"channel_id":23,"order_id":"10998899553566448116","flags":0,"ts_in_delta":937,"sequence":144839,"symbol":"FCEU SI 20260615 PS"}
{"ts_recv":"2026-04-07T02:05:16.711688405Z","hd":{"ts_event":"2026-04-07T02:05:16.711666107Z","rtype":160,"publisher_id":101,"instrument_id":436},"action":"C","side":"A","price":"1.156630000","size":30,"channel_id":23,"order_id":"1775527516711612413","flags":0,"ts_in_delta":937,"sequence":144839,"symbol":"FCEU SI 20260615 PS"}
{"ts_recv":"2026-04-07T02:05:16.711688405Z","hd":{"ts_event":"2026-04-07T02:05:16.711666107Z","rtype":160,"publisher_id":101,"instrument_id":436},"action":"A","side":"A","price":"1.156640000","size":30,"channel_id":23,"order_id":"1775527516711672308","flags":128,"ts_in_delta":937,"sequence":144839,"symbol":"FCEU SI 20260615 PS"}
{"ts_recv":"2026-04-07T02:05:16.711745196Z","hd":{"ts_event":"2026-04-07T02:05:16.711725545Z","rtype":160,"publisher_id":101,"instrument_id":436},"action":"C","side":"B","price":"1.156540000","size":30,"channel_id":23,"order_id":"10998899553566448116","flags":0,"ts_in_delta":1147,"sequence":144840,"symbol":"FCEU SI 20260615 PS"}
{"ts_recv":"2026-04-07T02:05:16.711745196Z","hd":{"ts_event":"2026-04-07T02:05:16.711725545Z","rtype":160,"publisher_id":101,"instrument_id":436},"action":"A","side":"B","price":"1.156530000","size":30,"channel_id":23,"order_id":"10998899553566507347","flags":0,"ts_in_delta":1147,"sequence":144840,"symbol":"FCEU SI 20260615 PS"}
{"ts_recv":"2026-04-07T02:05:16.711745196Z","hd":{"ts_event":"2026-04-07T02:05:16.711725545Z","rtype":160,"publisher_id":101,"instrument_id":436},"action":"C","side":"A","price":"1.156640000","size":30,"channel_id":23,"order_id":"1775527516711672308","flags":0,"ts_in_delta":1147,"sequence":144840,"symbol":"FCEU SI 20260615 PS"}
{"ts_recv":"2026-04-07T02:05:16.711745196Z","hd":{"ts_event":"2026-04-07T02:05:16.711725545Z","rtype":160,"publisher_id":101,"instrument_id":436},"action":"A","side":"A","price":"1.156630000","size":30,"channel_id":23,"order_id":"1775527516711731539","flags":128,"ts_in_delta":1147,"sequence":144840,"symbol":"FCEU SI 20260615 PS"}
{"ts_recv":"2026-04-07T02:05:19.084425366Z","hd":{"ts_event":"2026-04-07T02:05:19.084405193Z","rtype":160,"publisher_id":101,"instrument_id":436},"action":"C","side":"B","price":"1.156530000","size":30,"channel_id":23,"order_id":"10998899553566507347","flags":0,"ts_in_delta":965,"sequence":144865,"symbol":"FCEU SI 20260615 PS"}
{"ts_recv":"2026-04-07T02:05:19.084425366Z","hd":{"ts_event":"2026-04-07T02:05:19.084405193Z","rtype":160,"publisher_id":101,"instrument_id":436},"action":"A","side":"B","price":"1.156540000","size":30,"channel_id":23,"order_id":"10998899555939186942","flags":0,"ts_in_delta":965,"sequence":144865,"symbol":"FCEU SI 20260615 PS"}
{"ts_recv":"2026-04-07T02:05:19.084425366Z","hd":{"ts_event":"2026-04-07T02:05:19.084405193Z","rtype":160,"publisher_id":101,"instrument_id":436},"action":"C","side":"A","price":"1.156630000","size":30,"channel_id":23,"order_id":"1775527516711731539","flags":0,"ts_in_delta":965,"sequence":144865,"symbol":"FCEU SI 20260615 PS"}
{"ts_recv":"2026-04-07T02:05:19.084425366Z","hd":{"ts_event":"2026-04-07T02:05:19.084405193Z","rtype":160,"publisher_id":101,"instrument_id":436},"action":"A","side":"A","price":"1.156640000","size":30,"channel_id":23,"order_id":"1775527519084411134","flags":128,"ts_in_delta":965,"sequence":144865,"symbol":"FCEU SI 20260615 PS"}
{"ts_recv":"2026-04-07T02:05:25.139552561Z","hd":{"ts_event":"2026-04-07T02:05:25.139526445Z","rtype":160,"publisher_id":101,"instrument_id":436},"action":"C","side":"B","price":"1.156530000","size":30,"channel_id":23,"order_id":"10998899553566440625","flags":0,"ts_in_delta":967,"sequence":144945,"symbol":"FCEU SI 20260615 PS"}
{"ts_recv":"2026-04-07T02:05:25.139552561Z","hd":{"ts_event":"2026-04-07T02:05:25.139526445Z","rtype":160,"publisher_id":101,"instrument_id":436},"action":"A","side":"B","price":"1.156550000","size":30,"channel_id":23,"order_id":"10998899561994313069","flags":0,"ts_in_delta":967,"sequence":144945,"symbol":"FCEU SI 20260615 PS"}
{"ts_recv":"2026-04-07T02:05:25.139552561Z","hd":{"ts_event":"2026-04-07T02:05:25.139526445Z","rtype":160,"publisher_id":101,"instrument_id":436},"action":"C","side":"A","price":"1.156630000","size":30,"channel_id":23,"order_id":"1775527516711664817","flags":0,"ts_in_delta":967,"sequence":144945,"symbol":"FCEU SI 20260615 PS"}
{"ts_recv":"2026-04-07T02:05:25.139552561Z","hd":{"ts_event":"2026-04-07T02:05:25.139526445Z","rtype":160,"publisher_id":101,"instrument_id":436},"action":"A","side":"A","price":"1.156650000","size":30,"channel_id":23,"order_id":"1775527525139537261","flags":128,"ts_in_delta":967,"sequence":144945,"symbol":"FCEU SI 20260615 PS"}
{"ts_recv":"2026-04-07T02:05:25.139624211Z","hd":{"ts_event":"2026-04-07T02:05:25.139607847Z","rtype":160,"publisher_id":101,"instrument_id":436},"action":"C","side":"B","price":"1.156540000","size":30,"channel_id":23,"order_id":"10998899555939186942","flags":0,"ts_in_delta":926,"sequence":144946,"symbol":"FCEU SI 20260615 PS"}
{"ts_recv":"2026-04-07T02:05:25.139624211Z","hd":{"ts_event":"2026-04-07T02:05:25.139607847Z","rtype":160,"publisher_id":101,"instrument_id":436},"action":"A","side":"B","price":"1.156550000","size":30,"channel_id":23,"order_id":"10998899561994389957","flags":0,"ts_in_delta":926,"sequence":144946,"symbol":"FCEU SI 20260615 PS"}
{"ts_recv":"2026-04-07T02:05:25.139624211Z","hd":{"ts_event":"2026-04-07T02:05:25.139607847Z","rtype":160,"publisher_id":101,"instrument_id":436},"action":"C","side":"A","price":"1.156640000","size":30,"channel_id":23,"order_id":"1775527519084411134","flags":0,"ts_in_delta":926,"sequence":144946,"symbol":"FCEU SI 20260615 PS"}
{"ts_recv":"2026-04-07T02:05:25.139624211Z","hd":{"ts_event":"2026-04-07T02:05:25.139607847Z","rtype":160,"publisher_id":101,"instrument_id":436},"action":"A","side":"A","price":"1.156650000","size":30,"channel_id":23,"order_id":"1775527525139614149","flags":128,"ts_in_delta":926,"sequence":144946,"symbol":"FCEU SI 20260615 PS"}
{"ts_recv":"2026-04-07T02:05:31.346567537Z","hd":{"ts_event":"2026-04-07T02:05:31.346542749Z","rtype":160,"publisher_id":101,"instrument_id":436},"action":"C","side":"B","price":"1.156550000","size":30,"channel_id":23,"order_id":"10998899561994389957","flags":0,"ts_in_delta":1208,"sequence":145014,"symbol":"FCEU SI 20260615 PS"}
{"ts_recv":"2026-04-07T02:05:31.346567537Z","hd":{"ts_event":"2026-04-07T02:05:31.346542749Z","rtype":160,"publisher_id":101,"instrument_id":436},"action":"A","side":"B","price":"1.156560000","size":30,"channel_id":23,"order_id":"10998899568201324818","flags":0,"ts_in_delta":1208,"sequence":145014,"symbol":"FCEU SI 20260615 PS"}
{"ts_recv":"2026-04-07T02:05:31.346567537Z","hd":{"ts_event":"2026-04-07T02:05:31.346542749Z","rtype":160,"publisher_id":101,"instrument_id":436},"action":"C","side":"A","price":"1.156650000","size":30,"channel_id":23,"order_id":"1775527525139614149","flags":0,"ts_in_delta":1208,"sequence":145014,"symbol":"FCEU SI 20260615 PS"}
{"ts_recv":"2026-04-07T02:05:31.346567537Z","hd":{"ts_event":"2026-04-07T02:05:31.346542749Z","rtype":160,"publisher_id":101,"instrument_id":436},"action":"A","side":"A","price":"1.156660000","size":30,"channel_id":23,"order_id":"1775527531346549010","flags":128,"ts_in_delta":1208,"sequence":145014,"symbol":"FCEU SI 20260615 PS"}
{"ts_recv":"2026-04-07T02:05:31.346625565Z","hd":{"ts_event":"2026-04-07T02:05:31.346603197Z","rtype":160,"publisher_id":101,"instrument_id":436},"action":"C","side":"B","price":"1.156550000","size":30,"channel_id":23,"order_id":"10998899561994313069","flags":0,"ts_in_delta":1135,"sequence":145015,"symbol":"FCEU SI 20260615 PS"}
{"ts_recv":"2026-04-07T02:05:31.346625565Z","hd":{"ts_event":"2026-04-07T02:05:31.346603197Z","rtype":160,"publisher_id":101,"instrument_id":436},"action":"A","side":"B","price":"1.156570000","size":30,"channel_id":23,"order_id":"10998899568201385305","flags":0,"ts_in_delta":1135,"sequence":145015,"symbol":"FCEU SI 20260615 PS"}
{"ts_recv":"2026-04-07T02:05:31.346625565Z","hd":{"ts_event":"2026-04-07T02:05:31.346603197Z","rtype":160,"publisher_id":101,"instrument_id":436},"action":"C","side":"A","price":"1.156650000","size":30,"channel_id":23,"order_id":"1775527525139537261","flags":0,"ts_in_delta":1135,"sequence":145015,"symbol":"FCEU SI 20260615 PS"}
{"ts_recv":"2026-04-07T02:05:31.346625565Z","hd":{"ts_event":"2026-04-07T02:05:31.346603197Z","rtype":160,"publisher_id":101,"instrument_id":436},"action":"A","side":"A","price":"1.156670000","size":30,"channel_id":23,"order_id":"1775527531346609497","flags":128,"ts_in_delta":1135,"sequence":145015,"symbol":"FCEU SI 20260615 PS"}
{"ts_recv":"2026-04-07T02:05:31.346681012Z","hd":{"ts_event":"2026-04-07T02:05:31.346661815Z","rtype":160,"publisher_id":101,"instrument_id":436},"action":"C","side":"B","price":"1.156560000","size":30,"channel_id":23,"order_id":"10998899568201324818","flags":0,"ts_in_delta":1092,"sequence":145016,"symbol":"FCEU SI 20260615 PS"}
{"ts_recv":"2026-04-07T02:05:31.346681012Z","hd":{"ts_event":"2026-04-07T02:05:31.346661815Z","rtype":160,"publisher_id":101,"instrument_id":436},"action":"A","side":"B","price":"1.156570000","size":30,"channel_id":23,"order_id":"10998899568201444196","flags":0,"ts_in_delta":1092,"sequence":145016,"symbol":"FCEU SI 20260615 PS"}
{"ts_recv":"2026-04-07T02:05:31.346681012Z","hd":{"ts_event":"2026-04-07T02:05:31.346661815Z","rtype":160,"publisher_id":101,"instrument_id":436},"action":"C","side":"A","price":"1.156660000","size":30,"channel_id":23,"order_id":"1775527531346549010","flags":0,"ts_in_delta":1092,"sequence":145016,"symbol":"FCEU SI 20260615 PS"}
{"ts_recv":"2026-04-07T02:05:31.346681012Z","hd":{"ts_event":"2026-04-07T02:05:31.346661815Z","rtype":160,"publisher_id":101,"instrument_id":436},"action":"A","side":"A","price":"1.156670000","size":30,"channel_id":23,"order_id":"1775527531346668388","flags":128,"ts_in_delta":1092,"sequence":145016,"symbol":"FCEU SI 20260615 PS"}
{"ts_recv":"2026-04-07T02:05:32.306429547Z","hd":{"ts_event":"2026-04-07T02:05:32.306402715Z","rtype":160,"publisher_id":101,"instrument_id":436},"action":"C","side":"B","price":"1.156570000","size":30,"channel_id":23,"order_id":"10998899568201444196","flags":0,"ts_in_delta":1180,"sequence":145035,"symbol":"FCEU SI 20260615 PS"}
{"ts_recv":"2026-04-07T02:05:32.306429547Z","hd":{"ts_event":"2026-04-07T02:05:32.306402715Z","rtype":160,"publisher_id":101,"instrument_id":436},"action":"A","side":"B","price":"1.156560000","size":30,"channel_id":23,"order_id":"10998899569161189862","flags":0,"ts_in_delta":1180,"sequence":145035,"symbol":"FCEU SI 20260615 PS"}
{"ts_recv":"2026-04-07T02:05:32.306429547Z","hd":{"ts_event":"2026-04-07T02:05:32.306402715Z","rtype":160,"publisher_id":101,"instrument_id":436},"action":"C","side":"A","price":"1.156670000","size":30,"channel_id":23,"order_id":"1775527531346668388","flags":0,"ts_in_delta":1180,"sequence":145035,"symbol":"FCEU SI 20260615 PS"}
{"ts_recv":"2026-04-07T02:05:32.306429547Z","hd":{"ts_event":"2026-04-07T02:05:32.306402715Z","rtype":160,"publisher_id":101,"instrument_id":436},"action":"A","side":"A","price":"1.156660000","size":30,"channel_id":23,"order_id":"1775527532306414054","flags":128,"ts_in_delta":1180,"sequence":145035,"symbol":"FCEU SI 20260615 PS"}
{"ts_recv":"2026-04-07T02:05:32.306516197Z","hd":{"ts_event":"2026-04-07T02:05:32.306496201Z","rtype":160,"publisher_id":101,"instrument_id":436},"action":"C","side":"B","price":"1.156560000","size":30,"channel_id":23,"order_id":"10998899569161189862","flags":0,"ts_in_delta":763,"sequence":145036,"symbol":"FCEU SI 20260615 PS"}
{"ts_recv":"2026-04-07T02:05:32.306516197Z","hd":{"ts_event":"2026-04-07T02:05:32.306496201Z","rtype":160,"publisher_id":101,"instrument_id":436},"action":"A","side":"B","price":"1.156550000","size":30,"channel_id":23,"order_id":"10998899569161278028","flags":0,"ts_in_delta":763,"sequence":145036,"symbol":"FCEU SI 20260615 PS"}
{"ts_recv":"2026-04-07T02:05:32.306516197Z","hd":{"ts_event":"2026-04-07T02:05:32.306496201Z","rtype":160,"publisher_id":101,"instrument_id":436},"action":"C","side":"A","price":"1.156660000","size":30,"channel_id":23,"order_id":"1775527532306414054","flags":0,"ts_in_delta":763,"sequence":145036,"symbol":"FCEU SI 20260615 PS"}
{"ts_recv":"2026-04-07T02:05:32.306516197Z","hd":{"ts_event":"2026-04-07T02:05:32.306496201Z","rtype":160,"publisher_id":101,"instrument_id":436},"action":"A","side":"A","price":"1.156650000","size":30,"channel_id":23,"order_id":"1775527532306502220","flags":128,"ts_in_delta":763,"sequence":145036,"symbol":"FCEU SI 20260615 PS"}
{"ts_recv":"2026-04-07T02:05:32.306568119Z","hd":{"ts_event":"2026-04-07T02:05:32.306550807Z","rtype":160,"publisher_id":101,"instrument_id":436},"action":"C","side":"B","price":"1.156570000","size":30,"channel_id":23,"order_id":"10998899568201385305","flags":0,"ts_in_delta":750,"sequence":145037,"symbol":"FCEU SI 20260615 PS"}
{"ts_recv":"2026-04-07T02:05:32.306568119Z","hd":{"ts_event":"2026-04-07T02:05:32.306550807Z","rtype":160,"publisher_id":101,"instrument_id":436},"action":"A","side":"B","price":"1.156550000","size":30,"channel_id":23,"order_id":"10998899569161332922","flags":0,"ts_in_delta":750,"sequence":145037,"symbol":"FCEU SI 20260615 PS"}
{"ts_recv":"2026-04-07T02:05:32.306568119Z","hd":{"ts_event":"2026-04-07T02:05:32.306550807Z","rtype":160,"publisher_id":101,"instrument_id":436},"action":"C","side":"A","price":"1.156670000","size":30,"channel_id":23,"order_id":"1775527531346609497","flags":0,"ts_in_delta":750,"sequence":145037,"symbol":"FCEU SI 20260615 PS"}
{"ts_recv":"2026-04-07T02:05:32.306568119Z","hd":{"ts_event":"2026-04-07T02:05:32.306550807Z","rtype":160,"publisher_id":101,"instrument_id":436},"action":"A","side":"A","price":"1.156650000","size":30,"channel_id":23,"order_id":"1775527532306557114","flags":128,"ts_in_delta":750,"sequence":145037,"symbol":"FCEU SI 20260615 PS"}
{"ts_recv":"2026-04-07T02:05:32.306578532Z","hd":{"ts_event":"2026-04-07T02:05:32.306559697Z","rtype":160,"publisher_id":101,"instrument_id":436},"action":"C","side":"B","price":"1.156550000","size":30,"channel_id":23,"order_id":"10998899569161278028","flags":0,"ts_in_delta":932,"sequence":145038,"symbol":"FCEU SI 20260615 PS"}
{"ts_recv":"2026-04-07T02:05:32.306578532Z","hd":{"ts_event":"2026-04-07T02:05:32.306559697Z","rtype":160,"publisher_id":101,"instrument_id":436},"action":"A","side":"B","price":"1.156560000","size":30,"channel_id":23,"order_id":"10998899569161341495","flags":0,"ts_in_delta":932,"sequence":145038,"symbol":"FCEU SI 20260615 PS"}
{"ts_recv":"2026-04-07T02:05:32.306578532Z","hd":{"ts_event":"2026-04-07T02:05:32.306559697Z","rtype":160,"publisher_id":101,"instrument_id":436},"action":"C","side":"A","price":"1.156650000","size":30,"channel_id":23,"order_id":"1775527532306502220","flags":0,"ts_in_delta":932,"sequence":145038,"symbol":"FCEU SI 20260615 PS"}
{"ts_recv":"2026-04-07T02:05:32.306578532Z","hd":{"ts_event":"2026-04-07T02:05:32.306559697Z","rtype":160,"publisher_id":101,"instrument_id":436},"action":"A","side":"A","price":"1.156660000","size":30,"channel_id":23,"order_id":"1775527532306565687","flags":128,"ts_in_delta":932,"sequence":145038,"symbol":"FCEU SI 20260615 PS"}
{"ts_recv":"2026-04-07T02:05:32.306630132Z","hd":{"ts_event":"2026-04-07T02:05:32.306614801Z","rtype":160,"publisher_id":101,"instrument_id":436},"action":"C","side":"B","price":"1.156560000","size":30,"channel_id":23,"order_id":"10998899569161341495","flags":0,"ts_in_delta":1072,"sequence":145039,"symbol":"FCEU SI 20260615 PS"}
{"ts_recv":"2026-04-07T02:05:32.306630132Z","hd":{"ts_event":"2026-04-07T02:05:32.306614801Z","rtype":160,"publisher_id":101,"instrument_id":436},"action":"A","side":"B","price":"1.156550000","size":30,"channel_id":23,"order_id":"10998899569161396686","flags":0,"ts_in_delta":1072,"sequence":145039,"symbol":"FCEU SI 20260615 PS"}
{"ts_recv":"2026-04-07T02:05:32.306630132Z","hd":{"ts_event":"2026-04-07T02:05:32.306614801Z","rtype":160,"publisher_id":101,"instrument_id":436},"action":"C","side":"A","price":"1.156660000","size":30,"channel_id":23,"order_id":"1775527532306565687","flags":0,"ts_in_delta":1072,"sequence":145039,"symbol":"FCEU SI 20260615 PS"}
{"ts_recv":"2026-04-07T02:05:32.306630132Z","hd":{"ts_event":"2026-04-07T02:05:32.306614801Z","rtype":160,"publisher_id":101,"instrument_id":436},"action":"A","side":"A","price":"1.156650000","size":30,"channel_id":23,"order_id":"1775527532306620878","flags":128,"ts_in_delta":1072,"sequence":145039,"symbol":"FCEU SI 20260615 PS"}
{"ts_recv":"2026-04-07T02:05:32.312968844Z","hd":{"ts_event":"2026-04-07T02:05:32.312949859Z","rtype":160,"publisher_id":101,"instrument_id":436},"action":"C","side":"B","price":"1.156550000","size":30,"channel_id":23,"order_id":"10998899569161396686","flags":0,"ts_in_delta":921,"sequence":145042,"symbol":"FCEU SI 20260615 PS"}
{"ts_recv":"2026-04-07T02:05:32.312968844Z","hd":{"ts_event":"2026-04-07T02:05:32.312949859Z","rtype":160,"publisher_id":101,"instrument_id":436},"action":"A","side":"B","price":"1.156540000","size":30,"channel_id":23,"order_id":"10998899569167731552","flags":0,"ts_in_delta":921,"sequence":145042,"symbol":"FCEU SI 20260615 PS"}
{"ts_recv":"2026-04-07T02:05:32.312968844Z","hd":{"ts_event":"2026-04-07T02:05:32.312949859Z","rtype":160,"publisher_id":101,"instrument_id":436},"action":"C","side":"A","price":"1.156650000","size":30,"channel_id":23,"order_id":"1775527532306620878","flags":0,"ts_in_delta":921,"sequence":145042,"symbol":"FCEU SI 20260615 PS"}
{"ts_recv":"2026-04-07T02:05:32.312968844Z","hd":{"ts_event":"2026-04-07T02:05:32.312949859Z","rtype":160,"publisher_id":101,"instrument_id":436},"action":"A","side":"A","price":"1.156640000","size":30,"channel_id":23,"order_id":"1775527532312955744","flags":128,"ts_in_delta":921,"sequence":145042,"symbol":"FCEU SI 20260615 PS"}
{"ts_recv":"2026-04-07T02:05:32.317985589Z","hd":{"ts_event":"2026-04-07T02:05:32.317970833Z","rtype":160,"publisher_id":101,"instrument_id":436},"action":"C","side":"B","price":"1.156500000","size":20,"channel_id":23,"order_id":"10998899144657142423","flags":128,"ts_in_delta":854,"sequence":145050,"symbol":"FCEU SI 20260615 PS"}
{"ts_recv":"2026-04-07T02:05:32.361415777Z","hd":{"ts_event":"2026-04-07T02:05:32.361400503Z","rtype":160,"publisher_id":101,"instrument_id":436},"action":"A","side":"B","price":"1.156400000","size":20,"channel_id":23,"order_id":"10998899569216182573","flags":128,"ts_in_delta":879,"sequence":145056,"symbol":"FCEU SI 20260615 PS"}
{"ts_recv":"2026-04-07T02:05:33.624256137Z","hd":{"ts_event":"2026-04-07T02:05:33.624230629Z","rtype":160,"publisher_id":101,"instrument_id":436},"action":"C","side":"B","price":"1.156540000","size":30,"channel_id":23,"order_id":"10998899569167731552","flags":0,"ts_in_delta":1300,"sequence":145082,"symbol":"FCEU SI 20260615 PS"}
{"ts_recv":"2026-04-07T02:05:33.624256137Z","hd":{"ts_event":"2026-04-07T02:05:33.624230629Z","rtype":160,"publisher_id":101,"instrument_id":436},"action":"A","side":"B","price":"1.156550000","size":30,"channel_id":23,"order_id":"10998899570479017411","flags":0,"ts_in_delta":1300,"sequence":145082,"symbol":"FCEU SI 20260615 PS"}
{"ts_recv":"2026-04-07T02:05:33.624256137Z","hd":{"ts_event":"2026-04-07T02:05:33.624230629Z","rtype":160,"publisher_id":101,"instrument_id":436},"action":"C","side":"A","price":"1.156640000","size":30,"channel_id":23,"order_id":"1775527532312955744","flags":0,"ts_in_delta":1300,"sequence":145082,"symbol":"FCEU SI 20260615 PS"}
{"ts_recv":"2026-04-07T02:05:33.624256137Z","hd":{"ts_event":"2026-04-07T02:05:33.624230629Z","rtype":160,"publisher_id":101,"instrument_id":436},"action":"A","side":"A","price":"1.156650000","size":30,"channel_id":23,"order_id":"1775527533624241603","flags":128,"ts_in_delta":1300,"sequence":145082,"symbol":"FCEU SI 20260615 PS"}
{"ts_recv":"2026-04-07T02:05:45.802515261Z","hd":{"ts_event":"2026-04-07T02:05:45.802494263Z","rtype":160,"publisher_id":101,"instrument_id":436},"action":"C","side":"B","price":"1.156550000","size":30,"channel_id":23,"order_id":"10998899570479017411","flags":0,"ts_in_delta":993,"sequence":145204,"symbol":"FCEU SI 20260615 PS"}
{"ts_recv":"2026-04-07T02:05:45.802515261Z","hd":{"ts_event":"2026-04-07T02:05:45.802494263Z","rtype":160,"publisher_id":101,"instrument_id":436},"action":"A","side":"B","price":"1.156560000","size":30,"channel_id":23,"order_id":"10998899582657275859","flags":0,"ts_in_delta":993,"sequence":145204,"symbol":"FCEU SI 20260615 PS"}
{"ts_recv":"2026-04-07T02:05:45.802515261Z","hd":{"ts_event":"2026-04-07T02:05:45.802494263Z","rtype":160,"publisher_id":101,"instrument_id":436},"action":"C","side":"A","price":"1.156650000","size":30,"channel_id":23,"order_id":"1775527533624241603","flags":0,"ts_in_delta":993,"sequence":145204,"symbol":"FCEU SI 20260615 PS"}
{"ts_recv":"2026-04-07T02:05:45.802515261Z","hd":{"ts_event":"2026-04-07T02:05:45.802494263Z","rtype":160,"publisher_id":101,"instrument_id":436},"action":"A","side":"A","price":"1.156660000","size":30,"channel_id":23,"order_id":"1775527545802500051","flags":128,"ts_in_delta":993,"sequence":145204,"symbol":"FCEU SI 20260615 PS"}
{"ts_recv":"2026-04-07T02:05:45.954587112Z","hd":{"ts_event":"2026-04-07T02:05:45.954566797Z","rtype":160,"publisher_id":101,"instrument_id":436},"action":"C","side":"B","price":"1.156550000","size":30,"channel_id":23,"order_id":"10998899569161332922","flags":0,"ts_in_delta":935,"sequence":145223,"symbol":"FCEU SI 20260615 PS"}
{"ts_recv":"2026-04-07T02:05:45.954587112Z","hd":{"ts_event":"2026-04-07T02:05:45.954566797Z","rtype":160,"publisher_id":101,"instrument_id":436},"action":"A","side":"B","price":"1.156570000","size":30,"channel_id":23,"order_id":"10998899582809348524","flags":0,"ts_in_delta":935,"sequence":145223,"symbol":"FCEU SI 20260615 PS"}
{"ts_recv":"2026-04-07T02:05:45.954587112Z","hd":{"ts_event":"2026-04-07T02:05:45.954566797Z","rtype":160,"publisher_id":101,"instrument_id":436},"action":"C","side":"A","price":"1.156650000","size":30,"channel_id":23,"order_id":"1775527532306557114","flags":0,"ts_in_delta":935,"sequence":145223,"symbol":"FCEU SI 20260615 PS"}
{"ts_recv":"2026-04-07T02:05:45.954587112Z","hd":{"ts_event":"2026-04-07T02:05:45.954566797Z","rtype":160,"publisher_id":101,"instrument_id":436},"action":"A","side":"A","price":"1.156670000","size":30,"channel_id":23,"order_id":"1775527545954572716","flags":128,"ts_in_delta":935,"sequence":145223,"symbol":"FCEU SI 20260615 PS"}
{"ts_recv":"2026-04-07T02:05:45.954645132Z","hd":{"ts_event":"2026-04-07T02:05:45.954629179Z","rtype":160,"publisher_id":101,"instrument_id":436},"action":"C","side":"B","price":"1.156560000","size":30,"channel_id":23,"order_id":"10998899582657275859","flags":0,"ts_in_delta":923,"sequence":145224,"symbol":"FCEU SI 20260615 PS"}
{"ts_recv":"2026-04-07T02:05:45.954645132Z","hd":{"ts_event":"2026-04-07T02:05:45.954629179Z","rtype":160,"publisher_id":101,"instrument_id":436},"action":"A","side":"B","price":"1.156570000","size":30,"channel_id":23,"order_id":"10998899582809410829","flags":0,"ts_in_delta":923,"sequence":145224,"symbol":"FCEU SI 20260615 PS"}
{"ts_recv":"2026-04-07T02:05:45.954645132Z","hd":{"ts_event":"2026-04-07T02:05:45.954629179Z","rtype":160,"publisher_id":101,"instrument_id":436},"action":"C","side":"A","price":"1.156660000","size":30,"channel_id":23,"order_id":"1775527545802500051","flags":0,"ts_in_delta":923,"sequence":145224,"symbol":"FCEU SI 20260615 PS"}
{"ts_recv":"2026-04-07T02:05:45.954645132Z","hd":{"ts_event":"2026-04-07T02:05:45.954629179Z","rtype":160,"publisher_id":101,"instrument_id":436},"action":"A","side":"A","price":"1.156670000","size":30,"channel_id":23,"order_id":"1775527545954635021","flags":128,"ts_in_delta":923,"sequence":145224,"symbol":"FCEU SI 20260615 PS"}
{"ts_recv":"2026-04-07T02:05:54.107826399Z","hd":{"ts_event":"2026-04-07T02:05:54.107806029Z","rtype":160,"publisher_id":101,"instrument_id":436},"action":"C","side":"B","price":"1.156570000","size":30,"channel_id":23,"order_id":"10998899582809410829","flags":0,"ts_in_delta":911,"sequence":145298,"symbol":"FCEU SI 20260615 PS"}
{"ts_recv":"2026-04-07T02:05:54.107826399Z","hd":{"ts_event":"2026-04-07T02:05:54.107806029Z","rtype":160,"publisher_id":101,"instrument_id":436},"action":"A","side":"B","price":"1.156560000","size":30,"channel_id":23,"order_id":"10998899590962587931","flags":0,"ts_in_delta":911,"sequence":145298,"symbol":"FCEU SI 20260615 PS"}
{"ts_recv":"2026-04-07T02:05:54.107826399Z","hd":{"ts_event":"2026-04-07T02:05:54.107806029Z","rtype":160,"publisher_id":101,"instrument_id":436},"action":"C","side":"A","price":"1.156670000","size":30,"channel_id":23,"order_id":"1775527545954635021","flags":0,"ts_in_delta":911,"sequence":145298,"symbol":"FCEU SI 20260615 PS"}
{"ts_recv":"2026-04-07T02:05:54.107826399Z","hd":{"ts_event":"2026-04-07T02:05:54.107806029Z","rtype":160,"publisher_id":101,"instrument_id":436},"action":"A","side":"A","price":"1.156660000","size":30,"channel_id":23,"order_id":"1775527554107812123","flags":128,"ts_in_delta":911,"sequence":145298,"symbol":"FCEU SI 20260615 PS"}
{"ts_recv":"2026-04-07T02:05:54.107894018Z","hd":{"ts_event":"2026-04-07T02:05:54.107872211Z","rtype":160,"publisher_id":101,"instrument_id":436},"action":"C","side":"B","price":"1.156570000","size":30,"channel_id":23,"order_id":"10998899582809348524","flags":0,"ts_in_delta":907,"sequence":145299,"symbol":"FCEU SI 20260615 PS"}
{"ts_recv":"2026-04-07T02:05:54.107894018Z","hd":{"ts_event":"2026-04-07T02:05:54.107872211Z","rtype":160,"publisher_id":101,"instrument_id":436},"action":"A","side":"B","price":"1.156550000","size":30,"channel_id":23,"order_id":"10998899590962654389","flags":0,"ts_in_delta":907,"sequence":145299,"symbol":"FCEU SI 20260615 PS"}
{"ts_recv":"2026-04-07T02:05:54.107894018Z","hd":{"ts_event":"2026-04-07T02:05:54.107872211Z","rtype":160,"publisher_id":101,"instrument_id":436},"action":"C","side":"A","price":"1.156670000","size":30,"channel_id":23,"order_id":"1775527545954572716","flags":0,"ts_in_delta":907,"sequence":145299,"symbol":"FCEU SI 20260615 PS"}
{"ts_recv":"2026-04-07T02:05:54.107894018Z","hd":{"ts_event":"2026-04-07T02:05:54.107872211Z","rtype":160,"publisher_id":101,"instrument_id":436},"action":"A","side":"A","price":"1.156650000","size":30,"channel_id":23,"order_id":"1775527554107878581","flags":128,"ts_in_delta":907,"sequence":145299,"symbol":"FCEU SI 20260615 PS"}
{"ts_recv":"2026-04-07T02:05:54.107955647Z","hd":{"ts_event":"2026-04-07T02:05:54.107935125Z","rtype":160,"publisher_id":101,"instrument_id":436},"action":"C","side":"B","price":"1.156560000","size":30,"channel_id":23,"order_id":"10998899590962587931","flags":0,"ts_in_delta":910,"sequence":145300,"symbol":"FCEU SI 20260615 PS"}
{"ts_recv":"2026-04-07T02:05:54.107955647Z","hd":{"ts_event":"2026-04-07T02:05:54.107935125Z","rtype":160,"publisher_id":101,"instrument_id":436},"action":"A","side":"B","price":"1.156550000","size":30,"channel_id":23,"order_id":"10998899590962716746","flags":0,"ts_in_delta":910,"sequence":145300,"symbol":"FCEU SI 20260615 PS"}
{"ts_recv":"2026-04-07T02:05:54.107955647Z","hd":{"ts_event":"2026-04-07T02:05:54.107935125Z","rtype":160,"publisher_id":101,"instrument_id":436},"action":"C","side":"A","price":"1.156660000","size":30,"channel_id":23,"order_id":"1775527554107812123","flags":0,"ts_in_delta":910,"sequence":145300,"symbol":"FCEU SI 20260615 PS"}
{"ts_recv":"2026-04-07T02:05:54.107955647Z","hd":{"ts_event":"2026-04-07T02:05:54.107935125Z","rtype":160,"publisher_id":101,"instrument_id":436},"action":"A","side":"A","price":"1.156650000","size":30,"channel_id":23,"order_id":"1775527554107940938","flags":128,"ts_in_delta":910,"sequence":145300,"symbol":"FCEU SI 20260615 PS"}
{"ts_recv":"2026-04-07T02:05:54.121236561Z","hd":{"ts_event":"2026-04-07T02:05:54.121216427Z","rtype":160,"publisher_id":101,"instrument_id":436},"action":"C","side":"B","price":"1.156550000","size":30,"channel_id":23,"order_id":"10998899590962716746","flags":0,"ts_in_delta":900,"sequence":145312,"symbol":"FCEU SI 20260615 PS"}
{"ts_recv":"2026-04-07T02:05:54.121236561Z","hd":{"ts_event":"2026-04-07T02:05:54.121216427Z","rtype":160,"publisher_id":101,"instrument_id":436},"action":"A","side":"B","price":"1.156540000","size":30,"channel_id":23,"order_id":"10998899590975998024","flags":0,"ts_in_delta":900,"sequence":145312,"symbol":"FCEU SI 20260615 PS"}
{"ts_recv":"2026-04-07T02:05:54.121236561Z","hd":{"ts_event":"2026-04-07T02:05:54.121216427Z","rtype":160,"publisher_id":101,"instrument_id":436},"action":"C","side":"A","price":"1.156650000","size":30,"channel_id":23,"order_id":"1775527554107940938","flags":0,"ts_in_delta":900,"sequence":145312,"symbol":"FCEU SI 20260615 PS"}
{"ts_recv":"2026-04-07T02:05:54.121236561Z","hd":{"ts_event":"2026-04-07T02:05:54.121216427Z","rtype":160,"publisher_id":101,"instrument_id":436},"action":"A","side":"A","price":"1.156640000","size":30,"channel_id":23,"order_id":"1775527554121222216","flags":128,"ts_in_delta":900,"sequence":145312,"symbol":"FCEU SI 20260615 PS"}
{"ts_recv":"2026-04-07T02:05:59.146344060Z","hd":{"ts_event":"2026-04-07T02:05:59.146325649Z","rtype":160,"publisher_id":101,"instrument_id":436},"action":"C","side":"B","price":"1.156540000","size":30,"channel_id":23,"order_id":"10998899590975998024","flags":0,"ts_in_delta":938,"sequence":145383,"symbol":"FCEU SI 20260615 PS"}
{"ts_recv":"2026-04-07T02:05:59.146344060Z","hd":{"ts_event":"2026-04-07T02:05:59.146325649Z","rtype":160,"publisher_id":101,"instrument_id":436},"action":"A","side":"B","price":"1.156550000","size":30,"channel_id":23,"order_id":"10998899596001107536","flags":0,"ts_in_delta":938,"sequence":145383,"symbol":"FCEU SI 20260615 PS"}
{"ts_recv":"2026-04-07T02:05:59.146344060Z","hd":{"ts_event":"2026-04-07T02:05:59.146325649Z","rtype":160,"publisher_id":101,"instrument_id":436},"action":"C","side":"A","price":"1.156640000","size":30,"channel_id":23,"order_id":"1775527554121222216","flags":0,"ts_in_delta":938,"sequence":145383,"symbol":"FCEU SI 20260615 PS"}
{"ts_recv":"2026-04-07T02:05:59.146344060Z","hd":{"ts_event":"2026-04-07T02:05:59.146325649Z","rtype":160,"publisher_id":101,"instrument_id":436},"action":"A","side":"A","price":"1.156650000","size":30,"channel_id":23,"order_id":"1775527559146331728","flags":128,"ts_in_delta":938,"sequence":145383,"symbol":"FCEU SI 20260615 PS"}
{"ts_recv":"2026-04-07T02:05:59.283915637Z","hd":{"ts_event":"2026-04-07T02:05:59.283895083Z","rtype":160,"publisher_id":101,"instrument_id":436},"action":"C","side":"B","price":"1.156550000","size":30,"channel_id":23,"order_id":"10998899596001107536","flags":0,"ts_in_delta":982,"sequence":145397,"symbol":"FCEU SI 20260615 PS"}
{"ts_recv":"2026-04-07T02:05:59.283915637Z","hd":{"ts_event":"2026-04-07T02:05:59.283895083Z","rtype":160,"publisher_id":101,"instrument_id":436},"action":"A","side":"B","price":"1.156560000","size":30,"channel_id":23,"order_id":"10998899596138676871","flags":0,"ts_in_delta":982,"sequence":145397,"symbol":"FCEU SI 20260615 PS"}
{"ts_recv":"2026-04-07T02:05:59.283915637Z","hd":{"ts_event":"2026-04-07T02:05:59.283895083Z","rtype":160,"publisher_id":101,"instrument_id":436},"action":"C","side":"A","price":"1.156650000","size":30,"channel_id":23,"order_id":"1775527559146331728","flags":0,"ts_in_delta":982,"sequence":145397,"symbol":"FCEU SI 20260615 PS"}
{"ts_recv":"2026-04-07T02:05:59.283915637Z","hd":{"ts_event":"2026-04-07T02:05:59.283895083Z","rtype":160,"publisher_id":101,"instrument_id":436},"action":"A","side":"A","price":"1.156660000","size":30,"channel_id":23,"order_id":"1775527559283901063","flags":128,"ts_in_delta":982,"sequence":145397,"symbol":"FCEU SI 20260615 PS"}
{"ts_recv":"2026-04-07T02:06:01.013857763Z","hd":{"ts_event":"2026-04-07T02:06:01.013825363Z","rtype":160,"publisher_id":101,"instrument_id":436},"action":"C","side":"B","price":"1.156550000","size":30,"channel_id":23,"order_id":"10998899590962654389","flags":0,"ts_in_delta":1279,"sequence":145430,"symbol":"FCEU SI 20260615 PS"}
{"ts_recv":"2026-04-07T02:06:01.013857763Z","hd":{"ts_event":"2026-04-07T02:06:01.013825363Z","rtype":160,"publisher_id":101,"instrument_id":436},"action":"A","side":"B","price":"1.156570000","size":30,"channel_id":23,"order_id":"10998899597868607871","flags":0,"ts_in_delta":1279,"sequence":145430,"symbol":"FCEU SI 20260615 PS"}
{"ts_recv":"2026-04-07T02:06:01.013857763Z","hd":{"ts_event":"2026-04-07T02:06:01.013825363Z","rtype":160,"publisher_id":101,"instrument_id":436},"action":"C","side":"A","price":"1.156650000","size":30,"channel_id":23,"order_id":"1775527554107878581","flags":0,"ts_in_delta":1279,"sequence":145430,"symbol":"FCEU SI 20260615 PS"}
{"ts_recv":"2026-04-07T02:06:01.013857763Z","hd":{"ts_event":"2026-04-07T02:06:01.013825363Z","rtype":160,"publisher_id":101,"instrument_id":436},"action":"A","side":"A","price":"1.156670000","size":30,"channel_id":23,"order_id":"1775527561013832063","flags":128,"ts_in_delta":1279,"sequence":145430,"symbol":"FCEU SI 20260615 PS"}
{"ts_recv":"2026-04-07T02:06:01.013940027Z","hd":{"ts_event":"2026-04-07T02:06:01.013923135Z","rtype":160,"publisher_id":101,"instrument_id":436},"action":"C","side":"B","price":"1.156560000","size":30,"channel_id":23,"order_id":"10998899596138676871","flags":0,"ts_in_delta":1051,"sequence":145431,"symbol":"FCEU SI 20260615 PS"}
{"ts_recv":"2026-04-07T02:06:01.013940027Z","hd":{"ts_event":"2026-04-07T02:06:01.013923135Z","rtype":160,"publisher_id":101,"instrument_id":436},"action":"A","side":"B","price":"1.156570000","size":30,"channel_id":23,"order_id":"10998899597868704789","flags":0,"ts_in_delta":1051,"sequence":145431,"symbol":"FCEU SI 20260615 PS"}
{"ts_recv":"2026-04-07T02:06:01.013940027Z","hd":{"ts_event":"2026-04-07T02:06:01.013923135Z","rtype":160,"publisher_id":101,"instrument_id":436},"action":"C","side":"A","price":"1.156660000","size":30,"channel_id":23,"order_id":"1775527559283901063","flags":0,"ts_in_delta":1051,"sequence":145431,"symbol":"FCEU SI 20260615 PS"}
{"ts_recv":"2026-04-07T02:06:01.013940027Z","hd":{"ts_event":"2026-04-07T02:06:01.013923135Z","rtype":160,"publisher_id":101,"instrument_id":436},"action":"A","side":"A","price":"1.156670000","size":30,"channel_id":23,"order_id":"1775527561013928981","flags":128,"ts_in_delta":1051,"sequence":145431,"symbol":"FCEU SI 20260615 PS"}
{"ts_recv":"2026-04-07T02:06:01.026879120Z","hd":{"ts_event":"2026-04-07T02:06:01.026860019Z","rtype":160,"publisher_id":101,"instrument_id":436},"action":"C","side":"B","price":"1.156570000","size":30,"channel_id":23,"order_id":"10998899597868704789","flags":0,"ts_in_delta":914,"sequence":145441,"symbol":"FCEU SI 20260615 PS"}
{"ts_recv":"2026-04-07T02:06:01.026879120Z","hd":{"ts_event":"2026-04-07T02:06:01.026860019Z","rtype":160,"publisher_id":101,"instrument_id":436},"action":"A","side":"B","price":"1.156580000","size":30,"channel_id":23,"order_id":"10998899597881641574","flags":0,"ts_in_delta":914,"sequence":145441,"symbol":"FCEU SI 20260615 PS"}
{"ts_recv":"2026-04-07T02:06:01.026879120Z","hd":{"ts_event":"2026-04-07T02:06:01.026860019Z","rtype":160,"publisher_id":101,"instrument_id":436},"action":"C","side":"A","price":"1.156670000","size":30,"channel_id":23,"order_id":"1775527561013928981","flags":0,"ts_in_delta":914,"sequence":145441,"symbol":"FCEU SI 20260615 PS"}
{"ts_recv":"2026-04-07T02:06:01.026879120Z","hd":{"ts_event":"2026-04-07T02:06:01.026860019Z","rtype":160,"publisher_id":101,"instrument_id":436},"action":"A","side":"A","price":"1.156680000","size":30,"channel_id":23,"order_id":"1775527561026865766","flags":128,"ts_in_delta":914,"sequence":145441,"symbol":"FCEU SI 20260615 PS"}
{"ts_recv":"2026-04-07T02:06:01.657759891Z","hd":{"ts_event":"2026-04-07T02:06:01.657741187Z","rtype":160,"publisher_id":101,"instrument_id":436},"action":"C","side":"B","price":"1.156580000","size":30,"channel_id":23,"order_id":"10998899597881641574","flags":0,"ts_in_delta":1072,"sequence":145460,"symbol":"FCEU SI 20260615 PS"}
{"ts_recv":"2026-04-07T02:06:01.657759891Z","hd":{"ts_event":"2026-04-07T02:06:01.657741187Z","rtype":160,"publisher_id":101,"instrument_id":436},"action":"A","side":"B","price":"1.156570000","size":30,"channel_id":23,"order_id":"10998899598512523025","flags":0,"ts_in_delta":1072,"sequence":145460,"symbol":"FCEU SI 20260615 PS"}
{"ts_recv":"2026-04-07T02:06:01.657759891Z","hd":{"ts_event":"2026-04-07T02:06:01.657741187Z","rtype":160,"publisher_id":101,"instrument_id":436},"action":"C","side":"A","price":"1.156680000","size":30,"channel_id":23,"order_id":"1775527561026865766","flags":0,"ts_in_delta":1072,"sequence":145460,"symbol":"FCEU SI 20260615 PS"}
{"ts_recv":"2026-04-07T02:06:01.657759891Z","hd":{"ts_event":"2026-04-07T02:06:01.657741187Z","rtype":160,"publisher_id":101,"instrument_id":436},"action":"A","side":"A","price":"1.156670000","size":30,"channel_id":23,"order_id":"1775527561657747217","flags":128,"ts_in_delta":1072,"sequence":145460,"symbol":"FCEU SI 20260615 PS"}
{"ts_recv":"2026-04-07T02:06:09.893914424Z","hd":{"ts_event":"2026-04-07T02:06:09.893890139Z","rtype":160,"publisher_id":101,"instrument_id":436},"action":"C","side":"B","price":"1.156570000","size":30,"channel_id":23,"order_id":"10998899598512523025","flags":0,"ts_in_delta":1032,"sequence":145516,"symbol":"FCEU SI 20260615 PS"}
{"ts_recv":"2026-04-07T02:06:09.893914424Z","hd":{"ts_event":"2026-04-07T02:06:09.893890139Z","rtype":160,"publisher_id":101,"instrument_id":436},"action":"A","side":"B","price":"1.156580000","size":30,"channel_id":23,"order_id":"10998899606748672261","flags":0,"ts_in_delta":1032,"sequence":145516,"symbol":"FCEU SI 20260615 PS"}
{"ts_recv":"2026-04-07T02:06:09.893914424Z","hd":{"ts_event":"2026-04-07T02:06:09.893890139Z","rtype":160,"publisher_id":101,"instrument_id":436},"action":"C","side":"A","price":"1.156670000","size":30,"channel_id":23,"order_id":"1775527561657747217","flags":0,"ts_in_delta":1032,"sequence":145516,"symbol":"FCEU SI 20260615 PS"}
{"ts_recv":"2026-04-07T02:06:09.893914424Z","hd":{"ts_event":"2026-04-07T02:06:09.893890139Z","rtype":160,"publisher_id":101,"instrument_id":436},"action":"A","side":"A","price":"1.156680000","size":30,"channel_id":23,"order_id":"1775527569893896453","flags":128,"ts_in_delta":1032,"sequence":145516,"symbol":"FCEU SI 20260615 PS"}
{"ts_recv":"2026-04-07T02:06:10.537902411Z","hd":{"ts_event":"2026-04-07T02:06:10.537881097Z","rtype":160,"publisher_id":101,"instrument_id":436},"action":"C","side":"B","price":"1.156570000","size":30,"channel_id":23,"order_id":"10998899597868607871","flags":0,"ts_in_delta":897,"sequence":145531,"symbol":"FCEU SI 20260615 PS"}
{"ts_recv":"2026-04-07T02:06:10.537902411Z","hd":{"ts_event":"2026-04-07T02:06:10.537881097Z","rtype":160,"publisher_id":101,"instrument_id":436},"action":"A","side":"B","price":"1.156590000","size":30,"channel_id":23,"order_id":"10998899607392662928","flags":0,"ts_in_delta":897,"sequence":145531,"symbol":"FCEU SI 20260615 PS"}
{"ts_recv":"2026-04-07T02:06:10.537902411Z","hd":{"ts_event":"2026-04-07T02:06:10.537881097Z","rtype":160,"publisher_id":101,"instrument_id":436},"action":"C","side":"A","price":"1.156670000","size":30,"channel_id":23,"order_id":"1775527561013832063","flags":0,"ts_in_delta":897,"sequence":145531,"symbol":"FCEU SI 20260615 PS"}
{"ts_recv":"2026-04-07T02:06:10.537902411Z","hd":{"ts_event":"2026-04-07T02:06:10.537881097Z","rtype":160,"publisher_id":101,"instrument_id":436},"action":"A","side":"A","price":"1.156690000","size":30,"channel_id":23,"order_id":"1775527570537887120","flags":128,"ts_in_delta":897,"sequence":145531,"symbol":"FCEU SI 20260615 PS"}
{"ts_recv":"2026-04-07T02:06:10.537974077Z","hd":{"ts_event":"2026-04-07T02:06:10.537956867Z","rtype":160,"publisher_id":101,"instrument_id":436},"action":"C","side":"B","price":"1.156580000","size":30,"channel_id":23,"order_id":"10998899606748672261","flags":0,"ts_in_delta":907,"sequence":145532,"symbol":"FCEU SI 20260615 PS"}
{"ts_recv":"2026-04-07T02:06:10.537974077Z","hd":{"ts_event":"2026-04-07T02:06:10.537956867Z","rtype":160,"publisher_id":101,"instrument_id":436},"action":"A","side":"B","price":"1.156590000","size":30,"channel_id":23,"order_id":"10998899607392738639","flags":0,"ts_in_delta":907,"sequence":145532,"symbol":"FCEU SI 20260615 PS"}
{"ts_recv":"2026-04-07T02:06:10.537974077Z","hd":{"ts_event":"2026-04-07T02:06:10.537956867Z","rtype":160,"publisher_id":101,"instrument_id":436},"action":"C","side":"A","price":"1.156680000","size":30,"channel_id":23,"order_id":"1775527569893896453","flags":0,"ts_in_delta":907,"sequence":145532,"symbol":"FCEU SI 20260615 PS"}
{"ts_recv":"2026-04-07T02:06:10.537974077Z","hd":{"ts_event":"2026-04-07T02:06:10.537956867Z","rtype":160,"publisher_id":101,"instrument_id":436},"action":"A","side":"A","price":"1.156690000","size":30,"channel_id":23,"order_id":"1775527570537962831","flags":128,"ts_in_delta":907,"sequence":145532,"symbol":"FCEU SI 20260615 PS"}
{"ts_recv":"2026-04-07T02:06:10.544246092Z","hd":{"ts_event":"2026-04-07T02:06:10.544226303Z","rtype":160,"publisher_id":101,"instrument_id":436},"action":"C","side":"B","price":"1.156590000","size":30,"channel_id":23,"order_id":"10998899607392738639","flags":0,"ts_in_delta":924,"sequence":145536,"symbol":"FCEU SI 20260615 PS"}
{"ts_recv":"2026-04-07T02:06:10.544246092Z","hd":{"ts_event":"2026-04-07T02:06:10.544226303Z","rtype":160,"publisher_id":101,"instrument_id":436},"action":"A","side":"B","price":"1.156600000","size":30,"channel_id":23,"order_id":"10998899607399007699","flags":0,"ts_in_delta":924,"sequence":145536,"symbol":"FCEU SI 20260615 PS"}
{"ts_recv":"2026-04-07T02:06:10.544246092Z","hd":{"ts_event":"2026-04-07T02:06:10.544226303Z","rtype":160,"publisher_id":101,"instrument_id":436},"action":"C","side":"A","price":"1.156690000","size":30,"channel_id":23,"order_id":"1775527570537962831","flags":0,"ts_in_delta":924,"sequence":145536,"symbol":"FCEU SI 20260615 PS"}
{"ts_recv":"2026-04-07T02:06:10.544246092Z","hd":{"ts_event":"2026-04-07T02:06:10.544226303Z","rtype":160,"publisher_id":101,"instrument_id":436},"action":"A","side":"A","price":"1.156700000","size":30,"channel_id":23,"order_id":"1775527570544231891","flags":128,"ts_in_delta":924,"sequence":145536,"symbol":"FCEU SI 20260615 PS"}
{"ts_recv":"2026-04-07T02:06:10.548958025Z","hd":{"ts_event":"2026-04-07T02:06:10.548939957Z","rtype":160,"publisher_id":101,"instrument_id":436},"action":"C","side":"B","price":"1.156600000","size":30,"channel_id":23,"order_id":"10998899607399007699","flags":0,"ts_in_delta":931,"sequence":145538,"symbol":"FCEU SI 20260615 PS"}
{"ts_recv":"2026-04-07T02:06:10.548958025Z","hd":{"ts_event":"2026-04-07T02:06:10.548939957Z","rtype":160,"publisher_id":101,"instrument_id":436},"action":"A","side":"B","price":"1.156630000","size":30,"channel_id":23,"order_id":"10998899607403721734","flags":0,"ts_in_delta":931,"sequence":145538,"symbol":"FCEU SI 20260615 PS"}
{"ts_recv":"2026-04-07T02:06:10.548958025Z","hd":{"ts_event":"2026-04-07T02:06:10.548939957Z","rtype":160,"publisher_id":101,"instrument_id":436},"action":"C","side":"A","price":"1.156700000","size":30,"channel_id":23,"order_id":"1775527570544231891","flags":0,"ts_in_delta":931,"sequence":145538,"symbol":"FCEU SI 20260615 PS"}
{"ts_recv":"2026-04-07T02:06:10.548958025Z","hd":{"ts_event":"2026-04-07T02:06:10.548939957Z","rtype":160,"publisher_id":101,"instrument_id":436},"action":"A","side":"A","price":"1.156730000","size":30,"channel_id":23,"order_id":"1775527570548945926","flags":128,"ts_in_delta":931,"sequence":145538,"symbol":"FCEU SI 20260615 PS"}
{"ts_recv":"2026-04-07T02:06:10.549011015Z","hd":{"ts_event":"2026-04-07T02:06:10.548992449Z","rtype":160,"publisher_id":101,"instrument_id":436},"action":"C","side":"B","price":"1.156590000","size":30,"channel_id":23,"order_id":"10998899607392662928","flags":0,"ts_in_delta":896,"sequence":145539,"symbol":"FCEU SI 20260615 PS"}
{"ts_recv":"2026-04-07T02:06:10.549011015Z","hd":{"ts_event":"2026-04-07T02:06:10.548992449Z","rtype":160,"publisher_id":101,"instrument_id":436},"action":"A","side":"B","price":"1.156620000","size":30,"channel_id":23,"order_id":"10998899607403774161","flags":0,"ts_in_delta":896,"sequence":145539,"symbol":"FCEU SI 20260615 PS"}
{"ts_recv":"2026-04-07T02:06:10.549011015Z","hd":{"ts_event":"2026-04-07T02:06:10.548992449Z","rtype":160,"publisher_id":101,"instrument_id":436},"action":"C","side":"A","price":"1.156690000","size":30,"channel_id":23,"order_id":"1775527570537887120","flags":0,"ts_in_delta":896,"sequence":145539,"symbol":"FCEU SI 20260615 PS"}
{"ts_recv":"2026-04-07T02:06:10.549011015Z","hd":{"ts_event":"2026-04-07T02:06:10.548992449Z","rtype":160,"publisher_id":101,"instrument_id":436},"action":"A","side":"A","price":"1.156720000","size":30,"channel_id":23,"order_id":"1775527570548998353","flags":128,"ts_in_delta":896,"sequence":145539,"symbol":"FCEU SI 20260615 PS"}
{"ts_recv":"2026-04-07T02:06:10.549039453Z","hd":{"ts_event":"2026-04-07T02:06:10.549020629Z","rtype":160,"publisher_id":101,"instrument_id":436},"action":"C","side":"B","price":"1.156630000","size":30,"channel_id":23,"order_id":"10998899607403721734","flags":0,"ts_in_delta":907,"sequence":145540,"symbol":"FCEU SI 20260615 PS"}
{"ts_recv":"2026-04-07T02:06:10.549039453Z","hd":{"ts_event":"2026-04-07T02:06:10.549020629Z","rtype":160,"publisher_id":101,"instrument_id":436},"action":"A","side":"B","price":"1.156610000","size":30,"channel_id":23,"order_id":"10998899607403802535","flags":0,"ts_in_delta":907,"sequence":145540,"symbol":"FCEU SI 20260615 PS"}
{"ts_recv":"2026-04-07T02:06:10.549039453Z","hd":{"ts_event":"2026-04-07T02:06:10.549020629Z","rtype":160,"publisher_id":101,"instrument_id":436},"action":"C","side":"A","price":"1.156730000","size":30,"channel_id":23,"order_id":"1775527570548945926","flags":0,"ts_in_delta":907,"sequence":145540,"symbol":"FCEU SI 20260615 PS"}
{"ts_recv":"2026-04-07T02:06:10.549039453Z","hd":{"ts_event":"2026-04-07T02:06:10.549020629Z","rtype":160,"publisher_id":101,"instrument_id":436},"action":"A","side":"A","price":"1.156710000","size":30,"channel_id":23,"order_id":"1775527570549026727","flags":128,"ts_in_delta":907,"sequence":145540,"symbol":"FCEU SI 20260615 PS"}
{"ts_recv":"2026-04-07T02:06:10.549093733Z","hd":{"ts_event":"2026-04-07T02:06:10.549078641Z","rtype":160,"publisher_id":101,"instrument_id":436},"action":"C","side":"B","price":"1.156610000","size":30,"channel_id":23,"order_id":"10998899607403802535","flags":0,"ts_in_delta":879,"sequence":145541,"symbol":"FCEU SI 20260615 PS"}
{"ts_recv":"2026-04-07T02:06:10.549093733Z","hd":{"ts_event":"2026-04-07T02:06:10.549078641Z","rtype":160,"publisher_id":101,"instrument_id":436},"action":"A","side":"B","price":"1.156620000","size":30,"channel_id":23,"order_id":"10998899607403860111","flags":0,"ts_in_delta":879,"sequence":145541,"symbol":"FCEU SI 20260615 PS"}
{"ts_recv":"2026-04-07T02:06:10.549093733Z","hd":{"ts_event":"2026-04-07T02:06:10.549078641Z","rtype":160,"publisher_id":101,"instrument_id":436},"action":"C","side":"A","price":"1.156710000","size":30,"channel_id":23,"order_id":"1775527570549026727","flags":0,"ts_in_delta":879,"sequence":145541,"symbol":"FCEU SI 20260615 PS"}
{"ts_recv":"2026-04-07T02:06:10.549093733Z","hd":{"ts_event":"2026-04-07T02:06:10.549078641Z","rtype":160,"publisher_id":101,"instrument_id":436},"action":"A","side":"A","price":"1.156720000","size":30,"channel_id":23,"order_id":"1775527570549084303","flags":128,"ts_in_delta":879,"sequence":145541,"symbol":"FCEU SI 20260615 PS"}
{"ts_recv":"2026-04-07T02:06:10.582250406Z","hd":{"ts_event":"2026-04-07T02:06:10.582235051Z","rtype":160,"publisher_id":101,"instrument_id":436},"action":"A","side":"B","price":"1.156500000","size":20,"channel_id":23,"order_id":"10998899607437016903","flags":128,"ts_in_delta":946,"sequence":145551,"symbol":"FCEU SI 20260615 PS"}
{"ts_recv":"2026-04-07T02:06:10.582491577Z","hd":{"ts_event":"2026-04-07T02:06:10.582478591Z","rtype":160,"publisher_id":101,"instrument_id":436},"action":"C","side":"B","price":"1.156400000","size":20,"channel_id":23,"order_id":"10998899569216182573","flags":128,"ts_in_delta":815,"sequence":145552,"symbol":"FCEU SI 20260615 PS"}
{"ts_recv":"2026-04-07T02:06:13.752777582Z","hd":{"ts_event":"2026-04-07T02:06:13.752746529Z","rtype":160,"publisher_id":101,"instrument_id":436},"action":"C","side":"B","price":"1.156620000","size":30,"channel_id":23,"order_id":"10998899607403860111","flags":0,"ts_in_delta":1646,"sequence":145594,"symbol":"FCEU SI 20260615 PS"}
{"ts_recv":"2026-04-07T02:06:13.752777582Z","hd":{"ts_event":"2026-04-07T02:06:13.752746529Z","rtype":160,"publisher_id":101,"instrument_id":436},"action":"A","side":"B","price":"1.156610000","size":30,"channel_id":23,"order_id":"10998899610607536129","flags":0,"ts_in_delta":1646,"sequence":145594,"symbol":"FCEU SI 20260615 PS"}
{"ts_recv":"2026-04-07T02:06:13.752777582Z","hd":{"ts_event":"2026-04-07T02:06:13.752746529Z","rtype":160,"publisher_id":101,"instrument_id":436},"action":"C","side":"A","price":"1.156720000","size":30,"channel_id":23,"order_id":"1775527570549084303","flags":0,"ts_in_delta":1646,"sequence":145594,"symbol":"FCEU SI 20260615 PS"}
{"ts_recv":"2026-04-07T02:06:13.752777582Z","hd":{"ts_event":"2026-04-07T02:06:13.752746529Z","rtype":160,"publisher_id":101,"instrument_id":436},"action":"A","side":"A","price":"1.156710000","size":30,"channel_id":23,"order_id":"1775527573752760321","flags":128,"ts_in_delta":1646,"sequence":145594,"symbol":"FCEU SI 20260615 PS"}
{"ts_recv":"2026-04-07T02:06:13.758086531Z","hd":{"ts_event":"2026-04-07T02:06:13.758065155Z","rtype":160,"publisher_id":101,"instrument_id":436},"action":"C","side":"B","price":"1.156620000","size":30,"channel_id":23,"order_id":"10998899607403774161","flags":0,"ts_in_delta":1019,"sequence":145596,"symbol":"FCEU SI 20260615 PS"}
{"ts_recv":"2026-04-07T02:06:13.758086531Z","hd":{"ts_event":"2026-04-07T02:06:13.758065155Z","rtype":160,"publisher_id":101,"instrument_id":436},"action":"A","side":"B","price":"1.156600000","size":30,"channel_id":23,"order_id":"10998899610612846779","flags":0,"ts_in_delta":1019,"sequence":145596,"symbol":"FCEU SI 20260615 PS"}
{"ts_recv":"2026-04-07T02:06:13.758086531Z","hd":{"ts_event":"2026-04-07T02:06:13.758065155Z","rtype":160,"publisher_id":101,"instrument_id":436},"action":"C","side":"A","price":"1.156720000","size":30,"channel_id":23,"order_id":"1775527570548998353","flags":0,"ts_in_delta":1019,"sequence":145596,"symbol":"FCEU SI 20260615 PS"}
{"ts_recv":"2026-04-07T02:06:13.758086531Z","hd":{"ts_event":"2026-04-07T02:06:13.758065155Z","rtype":160,"publisher_id":101,"instrument_id":436},"action":"A","side":"A","price":"1.156700000","size":30,"channel_id":23,"order_id":"1775527573758070971","flags":128,"ts_in_delta":1019,"sequence":145596,"symbol":"FCEU SI 20260615 PS"}
{"ts_recv":"2026-04-07T02:06:13.758153651Z","hd":{"ts_event":"2026-04-07T02:06:13.758136847Z","rtype":160,"publisher_id":101,"instrument_id":436},"action":"C","side":"B","price":"1.156610000","size":30,"channel_id":23,"order_id":"10998899610607536129","flags":0,"ts_in_delta":990,"sequence":145597,"symbol":"FCEU SI 20260615 PS"}
{"ts_recv":"2026-04-07T02:06:13.758153651Z","hd":{"ts_event":"2026-04-07T02:06:13.758136847Z","rtype":160,"publisher_id":101,"instrument_id":436},"action":"A","side":"B","price":"1.156600000","size":30,"channel_id":23,"order_id":"10998899610612918628","flags":0,"ts_in_delta":990,"sequence":145597,"symbol":"FCEU SI 20260615 PS"}
{"ts_recv":"2026-04-07T02:06:13.758153651Z","hd":{"ts_event":"2026-04-07T02:06:13.758136847Z","rtype":160,"publisher_id":101,"instrument_id":436},"action":"C","side":"A","price":"1.156710000","size":30,"channel_id":23,"order_id":"1775527573752760321","flags":0,"ts_in_delta":990,"sequence":145597,"symbol":"FCEU SI 20260615 PS"}
{"ts_recv":"2026-04-07T02:06:13.758153651Z","hd":{"ts_event":"2026-04-07T02:06:13.758136847Z","rtype":160,"publisher_id":101,"instrument_id":436},"action":"A","side":"A","price":"1.156700000","size":30,"channel_id":23,"order_id":"1775527573758142820","flags":128,"ts_in_delta":990,"sequence":145597,"symbol":"FCEU SI 20260615 PS"}
{"ts_recv":"2026-04-07T02:06:13.916715983Z","hd":{"ts_event":"2026-04-07T02:06:13.916696727Z","rtype":160,"publisher_id":101,"instrument_id":436},"action":"C","side":"B","price":"1.156600000","size":30,"channel_id":23,"order_id":"10998899610612918628","flags":0,"ts_in_delta":1146,"sequence":145624,"symbol":"FCEU SI 20260615 PS"}
{"ts_recv":"2026-04-07T02:06:13.916715983Z","hd":{"ts_event":"2026-04-07T02:06:13.916696727Z","rtype":160,"publisher_id":101,"instrument_id":436},"action":"A","side":"B","price":"1.156590000","size":30,"channel_id":23,"order_id":"10998899610771478345","flags":0,"ts_in_delta":1146,"sequence":145624,"symbol":"FCEU SI 20260615 PS"}
{"ts_recv":"2026-04-07T02:06:13.916715983Z","hd":{"ts_event":"2026-04-07T02:06:13.916696727Z","rtype":160,"publisher_id":101,"instrument_id":436},"action":"C","side":"A","price":"1.156700000","size":30,"channel_id":23,"order_id":"1775527573758142820","flags":0,"ts_in_delta":1146,"sequence":145624,"symbol":"FCEU SI 20260615 PS"}
{"ts_recv":"2026-04-07T02:06:13.916715983Z","hd":{"ts_event":"2026-04-07T02:06:13.916696727Z","rtype":160,"publisher_id":101,"instrument_id":436},"action":"A","side":"A","price":"1.156690000","size":30,"channel_id":23,"order_id":"1775527573916702537","flags":128,"ts_in_delta":1146,"sequence":145624,"symbol":"FCEU SI 20260615 PS"}
{"ts_recv":"2026-04-07T02:06:13.926211684Z","hd":{"ts_event":"2026-04-07T02:06:13.926192393Z","rtype":160,"publisher_id":101,"instrument_id":436},"action":"C","side":"B","price":"1.156600000","size":30,"channel_id":23,"order_id":"10998899610612846779","flags":0,"ts_in_delta":977,"sequence":145633,"symbol":"FCEU SI 20260615 PS"}
{"ts_recv":"2026-04-07T02:06:13.926211684Z","hd":{"ts_event":"2026-04-07T02:06:13.926192393Z","rtype":160,"publisher_id":101,"instrument_id":436},"action":"A","side":"B","price":"1.156580000","size":30,"channel_id":23,"order_id":"10998899610780974070","flags":0,"ts_in_delta":977,"sequence":145633,"symbol":"FCEU SI 20260615 PS"}
{"ts_recv":"2026-04-07T02:06:13.926211684Z","hd":{"ts_event":"2026-04-07T02:06:13.926192393Z","rtype":160,"publisher_id":101,"instrument_id":436},"action":"C","side":"A","price":"1.156700000","size":30,"channel_id":23,"order_id":"1775527573758070971","flags":0,"ts_in_delta":977,"sequence":145633,"symbol":"FCEU SI 20260615 PS"}
{"ts_recv":"2026-04-07T02:06:13.926211684Z","hd":{"ts_event":"2026-04-07T02:06:13.926192393Z","rtype":160,"publisher_id":101,"instrument_id":436},"action":"A","side":"A","price":"1.156680000","size":30,"channel_id":23,"order_id":"1775527573926198262","flags":128,"ts_in_delta":977,"sequence":145633,"symbol":"FCEU SI 20260615 PS"}
{"ts_recv":"2026-04-07T02:06:13.926271071Z","hd":{"ts_event":"2026-04-07T02:06:13.926252105Z","rtype":160,"publisher_id":101,"instrument_id":436},"action":"C","side":"B","price":"1.156590000","size":30,"channel_id":23,"order_id":"10998899610771478345","flags":0,"ts_in_delta":1312,"sequence":145634,"symbol":"FCEU SI 20260615 PS"}
{"ts_recv":"2026-04-07T02:06:13.926271071Z","hd":{"ts_event":"2026-04-07T02:06:13.926252105Z","rtype":160,"publisher_id":101,"instrument_id":436},"action":"A","side":"B","price":"1.156580000","size":30,"channel_id":23,"order_id":"10998899610781033763","flags":0,"ts_in_delta":1312,"sequence":145634,"symbol":"FCEU SI 20260615 PS"}
{"ts_recv":"2026-04-07T02:06:13.926271071Z","hd":{"ts_event":"2026-04-07T02:06:13.926252105Z","rtype":160,"publisher_id":101,"instrument_id":436},"action":"C","side":"A","price":"1.156690000","size":30,"channel_id":23,"order_id":"1775527573916702537","flags":0,"ts_in_delta":1312,"sequence":145634,"symbol":"FCEU SI 20260615 PS"}
{"ts_recv":"2026-04-07T02:06:13.926271071Z","hd":{"ts_event":"2026-04-07T02:06:13.926252105Z","rtype":160,"publisher_id":101,"instrument_id":436},"action":"A","side":"A","price":"1.156680000","size":30,"channel_id":23,"order_id":"1775527573926257955","flags":128,"ts_in_delta":1312,"sequence":145634,"symbol":"FCEU SI 20260615 PS"}
{"ts_recv":"2026-04-07T02:06:24.128750449Z","hd":{"ts_event":"2026-04-07T02:06:24.128728459Z","rtype":160,"publisher_id":101,"instrument_id":436},"action":"C","side":"B","price":"1.156580000","size":30,"channel_id":23,"order_id":"10998899610781033763","flags":0,"ts_in_delta":893,"sequence":145750,"symbol":"FCEU SI 20260615 PS"}
{"ts_recv":"2026-04-07T02:06:24.128750449Z","hd":{"ts_event":"2026-04-07T02:06:24.128728459Z","rtype":160,"publisher_id":101,"instrument_id":436},"action":"A","side":"B","price":"1.156570000","size":30,"channel_id":23,"order_id":"10998899620983510313","flags":0,"ts_in_delta":893,"sequence":145750,"symbol":"FCEU SI 20260615 PS"}
{"ts_recv":"2026-04-07T02:06:24.128750449Z","hd":{"ts_event":"2026-04-07T02:06:24.128728459Z","rtype":160,"publisher_id":101,"instrument_id":436},"action":"C","side":"A","price":"1.156680000","size":30,"channel_id":23,"order_id":"1775527573926257955","flags":0,"ts_in_delta":893,"sequence":145750,"symbol":"FCEU SI 20260615 PS"}
{"ts_recv":"2026-04-07T02:06:24.128750449Z","hd":{"ts_event":"2026-04-07T02:06:24.128728459Z","rtype":160,"publisher_id":101,"instrument_id":436},"action":"A","side":"A","price":"1.156670000","size":30,"channel_id":23,"order_id":"1775527584128734505","flags":128,"ts_in_delta":893,"sequence":145750,"symbol":"FCEU SI 20260615 PS"}
{"ts_recv":"2026-04-07T02:06:24.128817830Z","hd":{"ts_event":"2026-04-07T02:06:24.128795775Z","rtype":160,"publisher_id":101,"instrument_id":436},"action":"C","side":"B","price":"1.156580000","size":30,"channel_id":23,"order_id":"10998899610780974070","flags":0,"ts_in_delta":897,"sequence":145751,"symbol":"FCEU SI 20260615 PS"}
{"ts_recv":"2026-04-07T02:06:24.128817830Z","hd":{"ts_event":"2026-04-07T02:06:24.128795775Z","rtype":160,"publisher_id":101,"instrument_id":436},"action":"A","side":"B","price":"1.156560000","size":30,"channel_id":23,"order_id":"10998899620983578081","flags":0,"ts_in_delta":897,"sequence":145751,"symbol":"FCEU SI 20260615 PS"}
{"ts_recv":"2026-04-07T02:06:24.128817830Z","hd":{"ts_event":"2026-04-07T02:06:24.128795775Z","rtype":160,"publisher_id":101,"instrument_id":436},"action":"C","side":"A","price":"1.156680000","size":30,"channel_id":23,"order_id":"1775527573926198262","flags":0,"ts_in_delta":897,"sequence":145751,"symbol":"FCEU SI 20260615 PS"}
{"ts_recv":"2026-04-07T02:06:24.128817830Z","hd":{"ts_event":"2026-04-07T02:06:24.128795775Z","rtype":160,"publisher_id":101,"instrument_id":436},"action":"A","side":"A","price":"1.156660000","size":30,"channel_id":23,"order_id":"1775527584128802273","flags":128,"ts_in_delta":897,"sequence":145751,"symbol":"FCEU SI 20260615 PS"}
{"ts_recv":"2026-04-07T02:06:24.128875674Z","hd":{"ts_event":"2026-04-07T02:06:24.128859371Z","rtype":160,"publisher_id":101,"instrument_id":436},"action":"C","side":"B","price":"1.156570000","size":30,"channel_id":23,"order_id":"10998899620983510313","flags":0,"ts_in_delta":911,"sequence":145752,"symbol":"FCEU SI 20260615 PS"}
{"ts_recv":"2026-04-07T02:06:24.128875674Z","hd":{"ts_event":"2026-04-07T02:06:24.128859371Z","rtype":160,"publisher_id":101,"instrument_id":436},"action":"A","side":"B","price":"1.156560000","size":30,"channel_id":23,"order_id":"10998899620983641317","flags":0,"ts_in_delta":911,"sequence":145752,"symbol":"FCEU SI 20260615 PS"}
{"ts_recv":"2026-04-07T02:06:24.128875674Z","hd":{"ts_event":"2026-04-07T02:06:24.128859371Z","rtype":160,"publisher_id":101,"instrument_id":436},"action":"C","side":"A","price":"1.156670000","size":30,"channel_id":23,"order_id":"1775527584128734505","flags":0,"ts_in_delta":911,"sequence":145752,"symbol":"FCEU SI 20260615 PS"}
{"ts_recv":"2026-04-07T02:06:24.128875674Z","hd":{"ts_event":"2026-04-07T02:06:24.128859371Z","rtype":160,"publisher_id":101,"instrument_id":436},"action":"A","side":"A","price":"1.156660000","size":30,"channel_id":23,"order_id":"1775527584128865509","flags":128,"ts_in_delta":911,"sequence":145752,"symbol":"FCEU SI 20260615 PS"}
{"ts_recv":"2026-04-07T02:06:24.141689343Z","hd":{"ts_event":"2026-04-07T02:06:24.141671581Z","rtype":160,"publisher_id":101,"instrument_id":436},"action":"C","side":"B","price":"1.156560000","size":30,"channel_id":23,"order_id":"10998899620983641317","flags":0,"ts_in_delta":712,"sequence":145759,"symbol":"FCEU SI 20260615 PS"}
{"ts_recv":"2026-04-07T02:06:24.141689343Z","hd":{"ts_event":"2026-04-07T02:06:24.141671581Z","rtype":160,"publisher_id":101,"instrument_id":436},"action":"A","side":"B","price":"1.156550000","size":30,"channel_id":23,"order_id":"10998899620996453426","flags":0,"ts_in_delta":712,"sequence":145759,"symbol":"FCEU SI 20260615 PS"}
{"ts_recv":"2026-04-07T02:06:24.141689343Z","hd":{"ts_event":"2026-04-07T02:06:24.141671581Z","rtype":160,"publisher_id":101,"instrument_id":436},"action":"C","side":"A","price":"1.156660000","size":30,"channel_id":23,"order_id":"1775527584128865509","flags":0,"ts_in_delta":712,"sequence":145759,"symbol":"FCEU SI 20260615 PS"}
{"ts_recv":"2026-04-07T02:06:24.141689343Z","hd":{"ts_event":"2026-04-07T02:06:24.141671581Z","rtype":160,"publisher_id":101,"instrument_id":436},"action":"A","side":"A","price":"1.156650000","size":30,"channel_id":23,"order_id":"1775527584141677618","flags":128,"ts_in_delta":712,"sequence":145759,"symbol":"FCEU SI 20260615 PS"}
{"ts_recv":"2026-04-07T02:06:24.152927401Z","hd":{"ts_event":"2026-04-07T02:06:24.152908131Z","rtype":160,"publisher_id":101,"instrument_id":436},"action":"C","side":"B","price":"1.156550000","size":30,"channel_id":23,"order_id":"10998899620996453426","flags":0,"ts_in_delta":906,"sequence":145762,"symbol":"FCEU SI 20260615 PS"}
{"ts_recv":"2026-04-07T02:06:24.152927401Z","hd":{"ts_event":"2026-04-07T02:06:24.152908131Z","rtype":160,"publisher_id":101,"instrument_id":436},"action":"A","side":"B","price":"1.156530000","size":30,"channel_id":23,"order_id":"10998899621007689970","flags":0,"ts_in_delta":906,"sequence":145762,"symbol":"FCEU SI 20260615 PS"}
{"ts_recv":"2026-04-07T02:06:24.152927401Z","hd":{"ts_event":"2026-04-07T02:06:24.152908131Z","rtype":160,"publisher_id":101,"instrument_id":436},"action":"C","side":"A","price":"1.156650000","size":30,"channel_id":23,"order_id":"1775527584141677618","flags":0,"ts_in_delta":906,"sequence":145762,"symbol":"FCEU SI 20260615 PS"}
{"ts_recv":"2026-04-07T02:06:24.152927401Z","hd":{"ts_event":"2026-04-07T02:06:24.152908131Z","rtype":160,"publisher_id":101,"instrument_id":436},"action":"A","side":"A","price":"1.156630000","size":30,"channel_id":23,"order_id":"1775527584152914162","flags":128,"ts_in_delta":906,"sequence":145762,"symbol":"FCEU SI 20260615 PS"}
{"ts_recv":"2026-04-07T02:06:24.152981366Z","hd":{"ts_event":"2026-04-07T02:06:24.152962411Z","rtype":160,"publisher_id":101,"instrument_id":436},"action":"C","side":"B","price":"1.156560000","size":30,"channel_id":23,"order_id":"10998899620983578081","flags":0,"ts_in_delta":1078,"sequence":145763,"symbol":"FCEU SI 20260615 PS"}
{"ts_recv":"2026-04-07T02:06:24.152981366Z","hd":{"ts_event":"2026-04-07T02:06:24.152962411Z","rtype":160,"publisher_id":101,"instrument_id":436},"action":"A","side":"B","price":"1.156530000","size":30,"channel_id":23,"order_id":"10998899621007744398","flags":0,"ts_in_delta":1078,"sequence":145763,"symbol":"FCEU SI 20260615 PS"}
{"ts_recv":"2026-04-07T02:06:24.152981366Z","hd":{"ts_event":"2026-04-07T02:06:24.152962411Z","rtype":160,"publisher_id":101,"instrument_id":436},"action":"C","side":"A","price":"1.156660000","size":30,"channel_id":23,"order_id":"1775527584128802273","flags":0,"ts_in_delta":1078,"sequence":145763,"symbol":"FCEU SI 20260615 PS"}
{"ts_recv":"2026-04-07T02:06:24.152981366Z","hd":{"ts_event":"2026-04-07T02:06:24.152962411Z","rtype":160,"publisher_id":101,"instrument_id":436},"action":"A","side":"A","price":"1.156630000","size":30,"channel_id":23,"order_id":"1775527584152968590","flags":128,"ts_in_delta":1078,"sequence":145763,"symbol":"FCEU SI 20260615 PS"}
{"ts_recv":"2026-04-07T02:06:24.153008997Z","hd":{"ts_event":"2026-04-07T02:06:24.152990135Z","rtype":160,"publisher_id":101,"instrument_id":436},"action":"C","side":"B","price":"1.156530000","size":30,"channel_id":23,"order_id":"10998899621007689970","flags":0,"ts_in_delta":898,"sequence":145764,"symbol":"FCEU SI 20260615 PS"}
{"ts_recv":"2026-04-07T02:06:24.153008997Z","hd":{"ts_event":"2026-04-07T02:06:24.152990135Z","rtype":160,"publisher_id":101,"instrument_id":436},"action":"A","side":"B","price":"1.156550000","size":30,"channel_id":23,"order_id":"10998899621007771884","flags":0,"ts_in_delta":898,"sequence":145764,"symbol":"FCEU SI 20260615 PS"}
{"ts_recv":"2026-04-07T02:06:24.153008997Z","hd":{"ts_event":"2026-04-07T02:06:24.152990135Z","rtype":160,"publisher_id":101,"instrument_id":436},"action":"C","side":"A","price":"1.156630000","size":30,"channel_id":23,"order_id":"1775527584152914162","flags":0,"ts_in_delta":898,"sequence":145764,"symbol":"FCEU SI 20260615 PS"}
{"ts_recv":"2026-04-07T02:06:24.153008997Z","hd":{"ts_event":"2026-04-07T02:06:24.152990135Z","rtype":160,"publisher_id":101,"instrument_id":436},"action":"A","side":"A","price":"1.156650000","size":30,"channel_id":23,"order_id":"1775527584152996076","flags":128,"ts_in_delta":898,"sequence":145764,"symbol":"FCEU SI 20260615 PS"}
{"ts_recv":"2026-04-07T02:06:24.153062809Z","hd":{"ts_event":"2026-04-07T02:06:24.153047697Z","rtype":160,"publisher_id":101,"instrument_id":436},"action":"C","side":"B","price":"1.156550000","size":30,"channel_id":23,"order_id":"10998899621007771884","flags":0,"ts_in_delta":868,"sequence":145765,"symbol":"FCEU SI 20260615 PS"}
{"ts_recv":"2026-04-07T02:06:24.153062809Z","hd":{"ts_event":"2026-04-07T02:06:24.153047697Z","rtype":160,"publisher_id":101,"instrument_id":436},"action":"A","side":"B","price":"1.156530000","size":30,"channel_id":23,"order_id":"10998899621007829368","flags":0,"ts_in_delta":868,"sequence":145765,"symbol":"FCEU SI 20260615 PS"}
{"ts_recv":"2026-04-07T02:06:24.153062809Z","hd":{"ts_event":"2026-04-07T02:06:24.153047697Z","rtype":160,"publisher_id":101,"instrument_id":436},"action":"C","side":"A","price":"1.156650000","size":30,"channel_id":23,"order_id":"1775527584152996076","flags":0,"ts_in_delta":868,"sequence":145765,"symbol":"FCEU SI 20260615 PS"}
{"ts_recv":"2026-04-07T02:06:24.153062809Z","hd":{"ts_event":"2026-04-07T02:06:24.153047697Z","rtype":160,"publisher_id":101,"instrument_id":436},"action":"A","side":"A","price":"1.156630000","size":30,"channel_id":23,"order_id":"1775527584153053560","flags":128,"ts_in_delta":868,"sequence":145765,"symbol":"FCEU SI 20260615 PS"}
{"ts_recv":"2026-04-07T02:06:27.684268408Z","hd":{"ts_event":"2026-04-07T02:06:27.684247173Z","rtype":160,"publisher_id":101,"instrument_id":436},"action":"C","side":"B","price":"1.156530000","size":30,"channel_id":23,"order_id":"10998899621007829368","flags":0,"ts_in_delta":888,"sequence":145813,"symbol":"FCEU SI 20260615 PS"}
{"ts_recv":"2026-04-07T02:06:27.684268408Z","hd":{"ts_event":"2026-04-07T02:06:27.684247173Z","rtype":160,"publisher_id":101,"instrument_id":436},"action":"A","side":"B","price":"1.156540000","size":30,"channel_id":23,"order_id":"10998899624539029032","flags":0,"ts_in_delta":888,"sequence":145813,"symbol":"FCEU SI 20260615 PS"}
{"ts_recv":"2026-04-07T02:06:27.684268408Z","hd":{"ts_event":"2026-04-07T02:06:27.684247173Z","rtype":160,"publisher_id":101,"instrument_id":436},"action":"C","side":"A","price":"1.156630000","size":30,"channel_id":23,"order_id":"1775527584153053560","flags":0,"ts_in_delta":888,"sequence":145813,"symbol":"FCEU SI 20260615 PS"}
{"ts_recv":"2026-04-07T02:06:27.684268408Z","hd":{"ts_event":"2026-04-07T02:06:27.684247173Z","rtype":160,"publisher_id":101,"instrument_id":436},"action":"A","side":"A","price":"1.156640000","size":30,"channel_id":23,"order_id":"1775527587684253224","flags":128,"ts_in_delta":888,"sequence":145813,"symbol":"FCEU SI 20260615 PS"}
{"ts_recv":"2026-04-07T02:06:27.685885089Z","hd":{"ts_event":"2026-04-07T02:06:27.685866551Z","rtype":160,"publisher_id":101,"instrument_id":436},"action":"C","side":"B","price":"1.156530000","size":30,"channel_id":23,"order_id":"10998899621007744398","flags":0,"ts_in_delta":901,"sequence":145814,"symbol":"FCEU SI 20260615 PS"}
{"ts_recv":"2026-04-07T02:06:27.685885089Z","hd":{"ts_event":"2026-04-07T02:06:27.685866551Z","rtype":160,"publisher_id":101,"instrument_id":436},"action":"A","side":"B","price":"1.156550000","size":30,"channel_id":23,"order_id":"10998899624540648608","flags":0,"ts_in_delta":901,"sequence":145814,"symbol":"FCEU SI 20260615 PS"}
{"ts_recv":"2026-04-07T02:06:27.685885089Z","hd":{"ts_event":"2026-04-07T02:06:27.685866551Z","rtype":160,"publisher_id":101,"instrument_id":436},"action":"C","side":"A","price":"1.156630000","size":30,"channel_id":23,"order_id":"1775527584152968590","flags":0,"ts_in_delta":901,"sequence":145814,"symbol":"FCEU SI 20260615 PS"}
{"ts_recv":"2026-04-07T02:06:27.685885089Z","hd":{"ts_event":"2026-04-07T02:06:27.685866551Z","rtype":160,"publisher_id":101,"instrument_id":436},"action":"A","side":"A","price":"1.156650000","size":30,"channel_id":23,"order_id":"1775527587685872800","flags":128,"ts_in_delta":901,"sequence":145814,"symbol":"FCEU SI 20260615 PS"}
{"ts_recv":"2026-04-07T02:06:27.685943247Z","hd":{"ts_event":"2026-04-07T02:06:27.685924895Z","rtype":160,"publisher_id":101,"instrument_id":436},"action":"C","side":"B","price":"1.156540000","size":30,"channel_id":23,"order_id":"10998899624539029032","flags":0,"ts_in_delta":890,"sequence":145815,"symbol":"FCEU SI 20260615 PS"}
{"ts_recv":"2026-04-07T02:06:27.685943247Z","hd":{"ts_event":"2026-04-07T02:06:27.685924895Z","rtype":160,"publisher_id":101,"instrument_id":436},"action":"A","side":"B","price":"1.156550000","size":30,"channel_id":23,"order_id":"10998899624540706835","flags":0,"ts_in_delta":890,"sequence":145815,"symbol":"FCEU SI 20260615 PS"}
{"ts_recv":"2026-04-07T02:06:27.685943247Z","hd":{"ts_event":"2026-04-07T02:06:27.685924895Z","rtype":160,"publisher_id":101,"instrument_id":436},"action":"C","side":"A","price":"1.156640000","size":30,"channel_id":23,"order_id":"1775527587684253224","flags":0,"ts_in_delta":890,"sequence":145815,"symbol":"FCEU SI 20260615 PS"}
{"ts_recv":"2026-04-07T02:06:27.685943247Z","hd":{"ts_event":"2026-04-07T02:06:27.685924895Z","rtype":160,"publisher_id":101,"instrument_id":436},"action":"A","side":"A","price":"1.156650000","size":30,"channel_id":23,"order_id":"1775527587685931027","flags":128,"ts_in_delta":890,"sequence":145815,"symbol":"FCEU SI 20260615 PS"}
{"ts_recv":"2026-04-07T02:06:29.521470723Z","hd":{"ts_event":"2026-04-07T02:06:29.521449375Z","rtype":160,"publisher_id":101,"instrument_id":436},"action":"C","side":"B","price":"1.156550000","size":30,"channel_id":23,"order_id":"10998899624540706835","flags":0,"ts_in_delta":1072,"sequence":145865,"symbol":"FCEU SI 20260615 PS"}
{"ts_recv":"2026-04-07T02:06:29.521470723Z","hd":{"ts_event":"2026-04-07T02:06:29.521449375Z","rtype":160,"publisher_id":101,"instrument_id":436},"action":"A","side":"B","price":"1.156560000","size":30,"channel_id":23,"order_id":"10998899626376231234","flags":0,"ts_in_delta":1072,"sequence":145865,"symbol":"FCEU SI 20260615 PS"}
{"ts_recv":"2026-04-07T02:06:29.521470723Z","hd":{"ts_event":"2026-04-07T02:06:29.521449375Z","rtype":160,"publisher_id":101,"instrument_id":436},"action":"C","side":"A","price":"1.156650000","size":30,"channel_id":23,"order_id":"1775527587685931027","flags":0,"ts_in_delta":1072,"sequence":145865,"symbol":"FCEU SI 20260615 PS"}
{"ts_recv":"2026-04-07T02:06:29.521470723Z","hd":{"ts_event":"2026-04-07T02:06:29.521449375Z","rtype":160,"publisher_id":101,"instrument_id":436},"action":"A","side":"A","price":"1.156660000","size":30,"channel_id":23,"order_id":"1775527589521455426","flags":128,"ts_in_delta":1072,"sequence":145865,"symbol":"FCEU SI 20260615 PS"}
{"ts_recv":"2026-04-07T02:06:29.529887723Z","hd":{"ts_event":"2026-04-07T02:06:29.529867173Z","rtype":160,"publisher_id":101,"instrument_id":436},"action":"C","side":"B","price":"1.156550000","size":30,"channel_id":23,"order_id":"10998899624540648608","flags":0,"ts_in_delta":986,"sequence":145868,"symbol":"FCEU SI 20260615 PS"}
{"ts_recv":"2026-04-07T02:06:29.529887723Z","hd":{"ts_event":"2026-04-07T02:06:29.529867173Z","rtype":160,"publisher_id":101,"instrument_id":436},"action":"A","side":"B","price":"1.156570000","size":30,"channel_id":23,"order_id":"10998899626384648911","flags":0,"ts_in_delta":986,"sequence":145868,"symbol":"FCEU SI 20260615 PS"}
{"ts_recv":"2026-04-07T02:06:29.529887723Z","hd":{"ts_event":"2026-04-07T02:06:29.529867173Z","rtype":160,"publisher_id":101,"instrument_id":436},"action":"C","side":"A","price":"1.156650000","size":30,"channel_id":23,"order_id":"1775527587685872800","flags":0,"ts_in_delta":986,"sequence":145868,"symbol":"FCEU SI 20260615 PS"}
{"ts_recv":"2026-04-07T02:06:29.529887723Z","hd":{"ts_event":"2026-04-07T02:06:29.529867173Z","rtype":160,"publisher_id":101,"instrument_id":436},"action":"A","side":"A","price":"1.156670000","size":30,"channel_id":23,"order_id":"1775527589529873103","flags":128,"ts_in_delta":986,"sequence":145868,"symbol":"FCEU SI 20260615 PS"}
{"ts_recv":"2026-04-07T02:06:29.529947325Z","hd":{"ts_event":"2026-04-07T02:06:29.529929667Z","rtype":160,"publisher_id":101,"instrument_id":436},"action":"C","side":"B","price":"1.156560000","size":30,"channel_id":23,"order_id":"10998899626376231234","flags":0,"ts_in_delta":882,"sequence":145869,"symbol":"FCEU SI 20260615 PS"}
{"ts_recv":"2026-04-07T02:06:29.529947325Z","hd":{"ts_event":"2026-04-07T02:06:29.529929667Z","rtype":160,"publisher_id":101,"instrument_id":436},"action":"A","side":"B","price":"1.156570000","size":30,"channel_id":23,"order_id":"10998899626384711820","flags":0,"ts_in_delta":882,"sequence":145869,"symbol":"FCEU SI 20260615 PS"}
{"ts_recv":"2026-04-07T02:06:29.529947325Z","hd":{"ts_event":"2026-04-07T02:06:29.529929667Z","rtype":160,"publisher_id":101,"instrument_id":436},"action":"C","side":"A","price":"1.156660000","size":30,"channel_id":23,"order_id":"1775527589521455426","flags":0,"ts_in_delta":882,"sequence":145869,"symbol":"FCEU SI 20260615 PS"}
{"ts_recv":"2026-04-07T02:06:29.529947325Z","hd":{"ts_event":"2026-04-07T02:06:29.529929667Z","rtype":160,"publisher_id":101,"instrument_id":436},"action":"A","side":"A","price":"1.156670000","size":30,"channel_id":23,"order_id":"1775527589529936012","flags":128,"ts_in_delta":882,"sequence":145869,"symbol":"FCEU SI 20260615 PS"}
{"ts_recv":"2026-04-07T02:06:35.167147022Z","hd":{"ts_event":"2026-04-07T02:06:35.167124609Z","rtype":160,"publisher_id":101,"instrument_id":436},"action":"C","side":"B","price":"1.156570000","size":30,"channel_id":23,"order_id":"10998899626384711820","flags":0,"ts_in_delta":955,"sequence":145945,"symbol":"FCEU SI 20260615 PS"}
{"ts_recv":"2026-04-07T02:06:35.167147022Z","hd":{"ts_event":"2026-04-07T02:06:35.167124609Z","rtype":160,"publisher_id":101,"instrument_id":436},"action":"A","side":"B","price":"1.156580000","size":30,"channel_id":23,"order_id":"10998899632021906498","flags":0,"ts_in_delta":955,"sequence":145945,"symbol":"FCEU SI 20260615 PS"}
{"ts_recv":"2026-04-07T02:06:35.167147022Z","hd":{"ts_event":"2026-04-07T02:06:35.167124609Z","rtype":160,"publisher_id":101,"instrument_id":436},"action":"C","side":"A","price":"1.156670000","size":30,"channel_id":23,"order_id":"1775527589529936012","flags":0,"ts_in_delta":955,"sequence":145945,"symbol":"FCEU SI 20260615 PS"}
{"ts_recv":"2026-04-07T02:06:35.167147022Z","hd":{"ts_event":"2026-04-07T02:06:35.167124609Z","rtype":160,"publisher_id":101,"instrument_id":436},"action":"A","side":"A","price":"1.156680000","size":30,"channel_id":23,"order_id":"1775527595167130690","flags":128,"ts_in_delta":955,"sequence":145945,"symbol":"FCEU SI 20260615 PS"}
{"ts_recv":"2026-04-07T02:06:48.434409740Z","hd":{"ts_event":"2026-04-07T02:06:48.434381399Z","rtype":160,"publisher_id":101,"instrument_id":436},"action":"C","side":"B","price":"1.156570000","size":30,"channel_id":23,"order_id":"10998899626384648911","flags":0,"ts_in_delta":1345,"sequence":146057,"symbol":"FCEU SI 20260615 PS"}