{"ts_recv":"2026-04-07T01:55:55.202324342Z","hd":{"ts_event":"2026-04-07T01:55:55.202310427Z","rtype":160,"publisher_id":101,"instrument_id":436},"action":"C","side":"B","price":"1.156300000","size":20,"channel_id":23,"order_id":"10998898917018039511","flags":128,"ts_in_delta":610,"sequence":138966,"symbol":"FCEU SI 20260615 PS"}
{"ts_recv":"2026-04-07T01:56:04.341121734Z","hd":{"ts_event":"2026-04-07T01:56:04.341108435Z","rtype":160,"publisher_id":101,"instrument_id":436},"action":"C","side":"B","price":"1.156400000","size":20,"channel_id":23,"order_id":"10998898992057029437","flags":128,"ts_in_delta":1220,"sequence":139063,"symbol":"FCEU SI 20260615 PS"}
{"ts_recv":"2026-04-07T01:56:04.383755868Z","hd":{"ts_event":"2026-04-07T01:56:04.383739451Z","rtype":160,"publisher_id":101,"instrument_id":436},"action":"A","side":"B","price":"1.156300000","size":20,"channel_id":23,"order_id":"10998899001238521327","flags":128,"ts_in_delta":987,"sequence":139067,"symbol":"FCEU SI 20260615 PS"}
{"ts_recv":"2026-04-07T01:56:14.011566758Z","hd":{"ts_event":"2026-04-07T01:56:14.011541389Z","rtype":160,"publisher_id":101,"instrument_id":436},"action":"A","side":"A","price":"1.156700000","size":20,"channel_id":23,"order_id":"1775526974011552496","flags":128,"ts_in_delta":934,"sequence":139180,"symbol":"FCEU SI 20260615 PS"}
{"ts_recv":"2026-04-07T01:56:14.011575144Z","hd":{"ts_event":"2026-04-07T01:56:14.011563913Z","rtype":160,"publisher_id":101,"instrument_id":436},"action":"C","side":"A","price":"1.156800000","size":20,"channel_id":23,"order_id":"1775526920683391378","flags":128,"ts_in_delta":912,"sequence":139181,"symbol":"FCEU SI 20260615 PS"}
{"ts_recv":"2026-04-07T01:57:04.170261078Z","hd":{"ts_event":"2026-04-07T01:57:04.170233879Z","rtype":160,"publisher_id":101,"instrument_id":436},"action":"C","side":"B","price":"1.156300000","size":20,"channel_id":23,"order_id":"10998899001238521327","flags":128,"ts_in_delta":1370,"sequence":139673,"symbol":"FCEU SI 20260615 PS"}
{"ts_recv":"2026-04-07T01:57:04.213258520Z","hd":{"ts_event":"2026-04-07T01:57:04.213235241Z","rtype":160,"publisher_id":101,"instrument_id":436},"action":"A","side":"B","price":"1.156200000","size":20,"channel_id":23,"order_id":"10998899061068021894","flags":128,"ts_in_delta":914,"sequence":139674,"symbol":"FCEU SI 20260615 PS"}
{"ts_recv":"2026-04-07T01:57:08.143367027Z","hd":{"ts_event":"2026-04-07T01:57:08.143350767Z","rtype":160,"publisher_id":101,"instrument_id":436},"action":"A","side":"B","price":"1.156300000","size":20,"channel_id":23,"order_id":"10998899064998132810","flags":128,"ts_in_delta":1045,"sequence":139709,"symbol":"FCEU SI 20260615 PS"}
{"ts_recv":"2026-04-07T01:57:08.143421446Z","hd":{"ts_event":"2026-04-07T01:57:08.143408681Z","rtype":160,"publisher_id":101,"instrument_id":436},"action":"C","side":"B","price":"1.156200000","size":20,"channel_id":23,"order_id":"10998899061068021894","flags":128,"ts_in_delta":1036,"sequence":139710,"symbol":"FCEU SI 20260615 PS"}
{"ts_recv":"2026-04-07T01:57:13.128447423Z","hd":{"ts_event":"2026-04-07T01:57:13.128431919Z","rtype":160,"publisher_id":101,"instrument_id":436},"action":"C","side":"A","price":"1.156700000","size":20,"channel_id":23,"order_id":"1775526974011552496","flags":128,"ts_in_delta":794,"sequence":139804,"symbol":"FCEU SI 20260615 PS"}
{"ts_recv":"2026-04-07T01:57:13.171643585Z","hd":{"ts_event":"2026-04-07T01:57:13.171620871Z","rtype":160,"publisher_id":101,"instrument_id":436},"action":"A","side":"A","price":"1.156800000","size":20,"channel_id":23,"order_id":"1775527033171631277","flags":128,"ts_in_delta":828,"sequence":139805,"symbol":"FCEU SI 20260615 PS"}
{"ts_recv":"2026-04-07T01:57:13.176144112Z","hd":{"ts_event":"2026-04-07T01:57:13.176128539Z","rtype":160,"publisher_id":101,"instrument_id":436},"action":"A","side":"B","price":"1.156400000","size":20,"channel_id":23,"order_id":"10998899070030910577","flags":128,"ts_in_delta":783,"sequence":139808,"symbol":"FCEU SI 20260615 PS"}
{"ts_recv":"2026-04-07T01:57:13.176217719Z","hd":{"ts_event":"2026-04-07T01:57:13.176205749Z","rtype":160,"publisher_id":101,"instrument_id":436},"action":"C","side":"B","price":"1.156300000","size":20,"channel_id":23,"order_id":"10998899064998132810","flags":128,"ts_in_delta":1418,"sequence":139811,"symbol":"FCEU SI 20260615 PS"}
{"ts_recv":"2026-04-07T01:57:27.572527701Z","hd":{"ts_event":"2026-04-07T01:57:27.572506667Z","rtype":160,"publisher_id":101,"instrument_id":436},"action":"C","side":"B","price":"1.156400000","size":20,"channel_id":23,"order_id":"10998899070030910577","flags":128,"ts_in_delta":1722,"sequence":139892,"symbol":"FCEU SI 20260615 PS"}
{"ts_recv":"2026-04-07T01:57:27.615563199Z","hd":{"ts_event":"2026-04-07T01:57:27.615546775Z","rtype":160,"publisher_id":101,"instrument_id":436},"action":"A","side":"B","price":"1.156300000","size":20,"channel_id":23,"order_id":"10998899084470328583","flags":128,"ts_in_delta":844,"sequence":139897,"symbol":"FCEU SI 20260615 PS"}
{"ts_recv":"2026-04-07T01:57:31.773250984Z","hd":{"ts_event":"2026-04-07T01:57:31.773232107Z","rtype":160,"publisher_id":101,"instrument_id":436},"action":"A","side":"B","price":"1.156400000","size":20,"channel_id":23,"order_id":"10998899088628016126","flags":128,"ts_in_delta":1070,"sequence":139927,"symbol":"FCEU SI 20260615 PS"}
{"ts_recv":"2026-04-07T01:57:31.773327580Z","hd":{"ts_event":"2026-04-07T01:57:31.773315173Z","rtype":160,"publisher_id":101,"instrument_id":436},"action":"C","side":"B","price":"1.156300000","size":20,"channel_id":23,"order_id":"10998899084470328583","flags":128,"ts_in_delta":821,"sequence":139929,"symbol":"FCEU SI 20260615 PS"}
{"ts_recv":"2026-04-07T01:58:02.387775493Z","hd":{"ts_event":"2026-04-07T01:58:02.387754695Z","rtype":160,"publisher_id":101,"instrument_id":436},"action":"C","side":"A","price":"1.156800000","size":20,"channel_id":23,"order_id":"1775527033171631277","flags":128,"ts_in_delta":697,"sequence":140146,"symbol":"FCEU SI 20260615 PS"}
{"ts_recv":"2026-04-07T01:58:02.430325943Z","hd":{"ts_event":"2026-04-07T01:58:02.430307067Z","rtype":160,"publisher_id":101,"instrument_id":436},"action":"A","side":"A","price":"1.156900000","size":20,"channel_id":23,"order_id":"1775527082430313364","flags":128,"ts_in_delta":1582,"sequence":140147,"symbol":"FCEU SI 20260615 PS"}
{"ts_recv":"2026-04-07T01:58:04.016127571Z","hd":{"ts_event":"2026-04-07T01:58:04.016105599Z","rtype":160,"publisher_id":101,"instrument_id":436},"action":"A","side":"B","price":"1.156500000","size":20,"channel_id":23,"order_id":"10998899120870889623","flags":128,"ts_in_delta":892,"sequence":140156,"symbol":"FCEU SI 20260615 PS"}
{"ts_recv":"2026-04-07T01:58:04.016267978Z","hd":{"ts_event":"2026-04-07T01:58:04.016256465Z","rtype":160,"publisher_id":101,"instrument_id":436},"action":"C","side":"B","price":"1.156400000","size":20,"channel_id":23,"order_id":"10998899088628016126","flags":128,"ts_in_delta":930,"sequence":140157,"symbol":"FCEU SI 20260615 PS"}
{"ts_recv":"2026-04-07T01:58:13.252449698Z","hd":{"ts_event":"2026-04-07T01:58:13.252436669Z","rtype":160,"publisher_id":101,"instrument_id":436},"action":"C","side":"B","price":"1.156500000","size":20,"channel_id":23,"order_id":"10998899120870889623","flags":128,"ts_in_delta":998,"sequence":140211,"symbol":"FCEU SI 20260615 PS"}
{"ts_recv":"2026-04-07T01:58:13.295586121Z","hd":{"ts_event":"2026-04-07T01:58:13.295571733Z","rtype":160,"publisher_id":101,"instrument_id":436},"action":"A","side":"B","price":"1.156400000","size":20,"channel_id":23,"order_id":"10998899130150353101","flags":128,"ts_in_delta":1064,"sequence":140220,"symbol":"FCEU SI 20260615 PS"}
{"ts_recv":"2026-04-07T01:58:22.966941405Z","hd":{"ts_event":"2026-04-07T01:58:22.966815439Z","rtype":160,"publisher_id":101,"instrument_id":436},"action":"A","side":"B","price":"1.156600000","size":30,"channel_id":23,"order_id":"10998899139821655984","flags":0,"ts_in_delta":1419,"sequence":140283,"symbol":"FCEU SI 20260615 PS"}
{"ts_recv":"2026-04-07T01:58:22.966941405Z","hd":{"ts_event":"2026-04-07T01:58:22.966815439Z","rtype":160,"publisher_id":101,"instrument_id":436},"action":"A","side":"A","price":"1.156700000","size":30,"channel_id":23,"order_id":"1775527102966880176","flags":128,"ts_in_delta":1419,"sequence":140283,"symbol":"FCEU SI 20260615 PS"}
{"ts_recv":"2026-04-07T01:58:27.802382607Z","hd":{"ts_event":"2026-04-07T01:58:27.802353015Z","rtype":160,"publisher_id":101,"instrument_id":436},"action":"A","side":"B","price":"1.156500000","size":20,"channel_id":23,"order_id":"10998899144657142423","flags":128,"ts_in_delta":1699,"sequence":140293,"symbol":"FCEU SI 20260615 PS"}
{"ts_recv":"2026-04-07T01:58:27.802386040Z","hd":{"ts_event":"2026-04-07T01:58:27.802364057Z","rtype":160,"publisher_id":101,"instrument_id":436},"action":"C","side":"B","price":"1.156400000","size":20,"channel_id":23,"order_id":"10998899130150353101","flags":128,"ts_in_delta":900,"sequence":140294,"symbol":"FCEU SI 20260615 PS"}
{"ts_recv":"2026-04-07T01:58:30.121063484Z","hd":{"ts_event":"2026-04-07T01:58:30.121003975Z","rtype":160,"publisher_id":101,"instrument_id":436},"action":"C","side":"B","price":"1.156600000","size":30,"channel_id":23,"order_id":"10998899139821655984","flags":0,"ts_in_delta":1521,"sequence":140310,"symbol":"FCEU SI 20260615 PS"}
{"ts_recv":"2026-04-07T01:58:30.121063484Z","hd":{"ts_event":"2026-04-07T01:58:30.121003975Z","rtype":160,"publisher_id":101,"instrument_id":436},"action":"A","side":"B","price":"1.156610000","size":30,"channel_id":23,"order_id":"10998899146975794629","flags":0,"ts_in_delta":1521,"sequence":140310,"symbol":"FCEU SI 20260615 PS"}
{"ts_recv":"2026-04-07T01:58:30.121063484Z","hd":{"ts_event":"2026-04-07T01:58:30.121003975Z","rtype":160,"publisher_id":101,"instrument_id":436},"action":"C","side":"A","price":"1.156700000","size":30,"channel_id":23,"order_id":"1775527102966880176","flags":0,"ts_in_delta":1521,"sequence":140310,"symbol":"FCEU SI 20260615 PS"}
{"ts_recv":"2026-04-07T01:58:30.121063484Z","hd":{"ts_event":"2026-04-07T01:58:30.121003975Z","rtype":160,"publisher_id":101,"instrument_id":436},"action":"A","side":"A","price":"1.156710000","size":30,"channel_id":23,"order_id":"1775527110121018821","flags":128,"ts_in_delta":1521,"sequence":140310,"symbol":"FCEU SI 20260615 PS"}
{"ts_recv":"2026-04-07T01:58:30.126773909Z","hd":{"ts_event":"2026-04-07T01:58:30.126734423Z","rtype":160,"publisher_id":101,"instrument_id":436},"action":"C","side":"B","price":"1.156610000","size":30,"channel_id":23,"order_id":"10998899146975794629","flags":0,"ts_in_delta":962,"sequence":140313,"symbol":"FCEU SI 20260615 PS"}
{"ts_recv":"2026-04-07T01:58:30.126773909Z","hd":{"ts_event":"2026-04-07T01:58:30.126734423Z","rtype":160,"publisher_id":101,"instrument_id":436},"action":"A","side":"B","price":"1.156620000","size":30,"channel_id":23,"order_id":"10998899146981517492","flags":0,"ts_in_delta":962,"sequence":140313,"symbol":"FCEU SI 20260615 PS"}
{"ts_recv":"2026-04-07T01:58:30.126773909Z","hd":{"ts_event":"2026-04-07T01:58:30.126734423Z","rtype":160,"publisher_id":101,"instrument_id":436},"action":"C","side":"A","price":"1.156710000","size":30,"channel_id":23,"order_id":"1775527110121018821","flags":0,"ts_in_delta":962,"sequence":140313,"symbol":"FCEU SI 20260615 PS"}
{"ts_recv":"2026-04-07T01:58:30.126773909Z","hd":{"ts_event":"2026-04-07T01:58:30.126734423Z","rtype":160,"publisher_id":101,"instrument_id":436},"action":"A","side":"A","price":"1.156720000","size":30,"channel_id":23,"order_id":"1775527110126741684","flags":128,"ts_in_delta":962,"sequence":140313,"symbol":"FCEU SI 20260615 PS"}
{"ts_recv":"2026-04-07T01:58:31.941267827Z","hd":{"ts_event":"2026-04-07T01:58:31.941235951Z","rtype":160,"publisher_id":101,"instrument_id":436},"action":"C","side":"B","price":"1.156620000","size":30,"channel_id":23,"order_id":"10998899146981517492","flags":0,"ts_in_delta":1263,"sequence":140351,"symbol":"FCEU SI 20260615 PS"}
{"ts_recv":"2026-04-07T01:58:31.941267827Z","hd":{"ts_event":"2026-04-07T01:58:31.941235951Z","rtype":160,"publisher_id":101,"instrument_id":436},"action":"A","side":"B","price":"1.156610000","size":30,"channel_id":23,"order_id":"10998899148796023774","flags":0,"ts_in_delta":1263,"sequence":140351,"symbol":"FCEU SI 20260615 PS"}
{"ts_recv":"2026-04-07T01:58:31.941267827Z","hd":{"ts_event":"2026-04-07T01:58:31.941235951Z","rtype":160,"publisher_id":101,"instrument_id":436},"action":"C","side":"A","price":"1.156720000","size":30,"channel_id":23,"order_id":"1775527110126741684","flags":0,"ts_in_delta":1263,"sequence":140351,"symbol":"FCEU SI 20260615 PS"}
{"ts_recv":"2026-04-07T01:58:31.941267827Z","hd":{"ts_event":"2026-04-07T01:58:31.941235951Z","rtype":160,"publisher_id":101,"instrument_id":436},"action":"A","side":"A","price":"1.156710000","size":30,"channel_id":23,"order_id":"1775527111941247966","flags":128,"ts_in_delta":1263,"sequence":140351,"symbol":"FCEU SI 20260615 PS"}
{"ts_recv":"2026-04-07T01:58:34.702130336Z","hd":{"ts_event":"2026-04-07T01:58:34.702100971Z","rtype":160,"publisher_id":101,"instrument_id":436},"action":"C","side":"B","price":"1.156610000","size":30,"channel_id":23,"order_id":"10998899148796023774","flags":0,"ts_in_delta":1151,"sequence":140363,"symbol":"FCEU SI 20260615 PS"}
{"ts_recv":"2026-04-07T01:58:34.702130336Z","hd":{"ts_event":"2026-04-07T01:58:34.702100971Z","rtype":160,"publisher_id":101,"instrument_id":436},"action":"A","side":"B","price":"1.156620000","size":30,"channel_id":23,"order_id":"10998899151556884195","flags":0,"ts_in_delta":1151,"sequence":140363,"symbol":"FCEU SI 20260615 PS"}
{"ts_recv":"2026-04-07T01:58:34.702130336Z","hd":{"ts_event":"2026-04-07T01:58:34.702100971Z","rtype":160,"publisher_id":101,"instrument_id":436},"action":"C","side":"A","price":"1.156710000","size":30,"channel_id":23,"order_id":"1775527111941247966","flags":0,"ts_in_delta":1151,"sequence":140363,"symbol":"FCEU SI 20260615 PS"}
{"ts_recv":"2026-04-07T01:58:34.702130336Z","hd":{"ts_event":"2026-04-07T01:58:34.702100971Z","rtype":160,"publisher_id":101,"instrument_id":436},"action":"A","side":"A","price":"1.156720000","size":30,"channel_id":23,"order_id":"1775527114702108387","flags":128,"ts_in_delta":1151,"sequence":140363,"symbol":"FCEU SI 20260615 PS"}
{"ts_recv":"2026-04-07T01:58:38.258245813Z","hd":{"ts_event":"2026-04-07T01:58:38.258210253Z","rtype":160,"publisher_id":101,"instrument_id":436},"action":"C","side":"B","price":"1.156620000","size":30,"channel_id":23,"order_id":"10998899151556884195","flags":0,"ts_in_delta":1478,"sequence":140395,"symbol":"FCEU SI 20260615 PS"}
{"ts_recv":"2026-04-07T01:58:38.258245813Z","hd":{"ts_event":"2026-04-07T01:58:38.258210253Z","rtype":160,"publisher_id":101,"instrument_id":436},"action":"A","side":"B","price":"1.156610000","size":30,"channel_id":23,"order_id":"10998899155113000054","flags":0,"ts_in_delta":1478,"sequence":140395,"symbol":"FCEU SI 20260615 PS"}
{"ts_recv":"2026-04-07T01:58:38.258245813Z","hd":{"ts_event":"2026-04-07T01:58:38.258210253Z","rtype":160,"publisher_id":101,"instrument_id":436},"action":"C","side":"A","price":"1.156720000","size":30,"channel_id":23,"order_id":"1775527114702108387","flags":0,"ts_in_delta":1478,"sequence":140395,"symbol":"FCEU SI 20260615 PS"}
{"ts_recv":"2026-04-07T01:58:38.258245813Z","hd":{"ts_event":"2026-04-07T01:58:38.258210253Z","rtype":160,"publisher_id":101,"instrument_id":436},"action":"A","side":"A","price":"1.156710000","size":30,"channel_id":23,"order_id":"1775527118258224246","flags":128,"ts_in_delta":1478,"sequence":140395,"symbol":"FCEU SI 20260615 PS"}
{"ts_recv":"2026-04-07T01:58:39.198107924Z","hd":{"ts_event":"2026-04-07T01:58:39.198083603Z","rtype":160,"publisher_id":101,"instrument_id":436},"action":"C","side":"B","price":"1.156610000","size":30,"channel_id":23,"order_id":"10998899155113000054","flags":0,"ts_in_delta":1453,"sequence":140410,"symbol":"FCEU SI 20260615 PS"}
{"ts_recv":"2026-04-07T01:58:39.198107924Z","hd":{"ts_event":"2026-04-07T01:58:39.198083603Z","rtype":160,"publisher_id":101,"instrument_id":436},"action":"A","side":"B","price":"1.156620000","size":30,"channel_id":23,"order_id":"10998899156052866496","flags":0,"ts_in_delta":1453,"sequence":140410,"symbol":"FCEU SI 20260615 PS"}
{"ts_recv":"2026-04-07T01:58:39.198107924Z","hd":{"ts_event":"2026-04-07T01:58:39.198083603Z","rtype":160,"publisher_id":101,"instrument_id":436},"action":"C","side":"A","price":"1.156710000","size":30,"channel_id":23,"order_id":"1775527118258224246","flags":0,"ts_in_delta":1453,"sequence":140410,"symbol":"FCEU SI 20260615 PS"}
{"ts_recv":"2026-04-07T01:58:39.198107924Z","hd":{"ts_event":"2026-04-07T01:58:39.198083603Z","rtype":160,"publisher_id":101,"instrument_id":436},"action":"A","side":"A","price":"1.156720000","size":30,"channel_id":23,"order_id":"1775527119198090688","flags":128,"ts_in_delta":1453,"sequence":140410,"symbol":"FCEU SI 20260615 PS"}
{"ts_recv":"2026-04-07T01:58:39.430959498Z","hd":{"ts_event":"2026-04-07T01:58:39.430931863Z","rtype":160,"publisher_id":101,"instrument_id":436},"action":"C","side":"B","price":"1.156620000","size":30,"channel_id":23,"order_id":"10998899156052866496","flags":0,"ts_in_delta":1193,"sequence":140420,"symbol":"FCEU SI 20260615 PS"}
{"ts_recv":"2026-04-07T01:58:39.430959498Z","hd":{"ts_event":"2026-04-07T01:58:39.430931863Z","rtype":160,"publisher_id":101,"instrument_id":436},"action":"A","side":"B","price":"1.156610000","size":30,"channel_id":23,"order_id":"10998899156285718507","flags":0,"ts_in_delta":1193,"sequence":140420,"symbol":"FCEU SI 20260615 PS"}
{"ts_recv":"2026-04-07T01:58:39.430959498Z","hd":{"ts_event":"2026-04-07T01:58:39.430931863Z","rtype":160,"publisher_id":101,"instrument_id":436},"action":"C","side":"A","price":"1.156720000","size":30,"channel_id":23,"order_id":"1775527119198090688","flags":0,"ts_in_delta":1193,"sequence":140420,"symbol":"FCEU SI 20260615 PS"}
{"ts_recv":"2026-04-07T01:58:39.430959498Z","hd":{"ts_event":"2026-04-07T01:58:39.430931863Z","rtype":160,"publisher_id":101,"instrument_id":436},"action":"A","side":"A","price":"1.156710000","size":30,"channel_id":23,"order_id":"1775527119430942699","flags":128,"ts_in_delta":1193,"sequence":140420,"symbol":"FCEU SI 20260615 PS"}
{"ts_recv":"2026-04-07T01:58:39.456871692Z","hd":{"ts_event":"2026-04-07T01:58:39.456852707Z","rtype":160,"publisher_id":101,"instrument_id":436},"action":"C","side":"B","price":"1.156610000","size":30,"channel_id":23,"order_id":"10998899156285718507","flags":0,"ts_in_delta":1256,"sequence":140421,"symbol":"FCEU SI 20260615 PS"}
{"ts_recv":"2026-04-07T01:58:39.456871692Z","hd":{"ts_event":"2026-04-07T01:58:39.456852707Z","rtype":160,"publisher_id":101,"instrument_id":436},"action":"A","side":"B","price":"1.156620000","size":30,"channel_id":23,"order_id":"10998899156311634873","flags":0,"ts_in_delta":1256,"sequence":140421,"symbol":"FCEU SI 20260615 PS"}
{"ts_recv":"2026-04-07T01:58:39.456871692Z","hd":{"ts_event":"2026-04-07T01:58:39.456852707Z","rtype":160,"publisher_id":101,"instrument_id":436},"action":"C","side":"A","price":"1.156710000","size":30,"channel_id":23,"order_id":"1775527119430942699","flags":0,"ts_in_delta":1256,"sequence":140421,"symbol":"FCEU SI 20260615 PS"}
{"ts_recv":"2026-04-07T01:58:39.456871692Z","hd":{"ts_event":"2026-04-07T01:58:39.456852707Z","rtype":160,"publisher_id":101,"instrument_id":436},"action":"A","side":"A","price":"1.156720000","size":30,"channel_id":23,"order_id":"1775527119456859065","flags":128,"ts_in_delta":1256,"sequence":140421,"symbol":"FCEU SI 20260615 PS"}
{"ts_recv":"2026-04-07T01:58:40.078376454Z","hd":{"ts_event":"2026-04-07T01:58:40.078349823Z","rtype":160,"publisher_id":101,"instrument_id":436},"action":"C","side":"B","price":"1.156620000","size":30,"channel_id":23,"order_id":"10998899156311634873","flags":0,"ts_in_delta":1743,"sequence":140437,"symbol":"FCEU SI 20260615 PS"}
{"ts_recv":"2026-04-07T01:58:40.078376454Z","hd":{"ts_event":"2026-04-07T01:58:40.078349823Z","rtype":160,"publisher_id":101,"instrument_id":436},"action":"A","side":"B","price":"1.156610000","size":30,"channel_id":23,"order_id":"10998899156933134209","flags":0,"ts_in_delta":1743,"sequence":140437,"symbol":"FCEU SI 20260615 PS"}
{"ts_recv":"2026-04-07T01:58:40.078376454Z","hd":{"ts_event":"2026-04-07T01:58:40.078349823Z","rtype":160,"publisher_id":101,"instrument_id":436},"action":"C","side":"A","price":"1.156720000","size":30,"channel_id":23,"order_id":"1775527119456859065","flags":0,"ts_in_delta":1743,"sequence":140437,"symbol":"FCEU SI 20260615 PS"}
{"ts_recv":"2026-04-07T01:58:40.078376454Z","hd":{"ts_event":"2026-04-07T01:58:40.078349823Z","rtype":160,"publisher_id":101,"instrument_id":436},"action":"A","side":"A","price":"1.156710000","size":30,"channel_id":23,"order_id":"1775527120078358401","flags":128,"ts_in_delta":1743,"sequence":140437,"symbol":"FCEU SI 20260615 PS"}
{"ts_recv":"2026-04-07T01:58:40.086016573Z","hd":{"ts_event":"2026-04-07T01:58:40.085997247Z","rtype":160,"publisher_id":101,"instrument_id":436},"action":"C","side":"B","price":"1.156610000","size":30,"channel_id":23,"order_id":"10998899156933134209","flags":0,"ts_in_delta":1045,"sequence":140438,"symbol":"FCEU SI 20260615 PS"}
{"ts_recv":"2026-04-07T01:58:40.086016573Z","hd":{"ts_event":"2026-04-07T01:58:40.085997247Z","rtype":160,"publisher_id":101,"instrument_id":436},"action":"A","side":"B","price":"1.156590000","size":30,"channel_id":23,"order_id":"10998899156940779658","flags":0,"ts_in_delta":1045,"sequence":140438,"symbol":"FCEU SI 20260615 PS"}
{"ts_recv":"2026-04-07T01:58:40.086016573Z","hd":{"ts_event":"2026-04-07T01:58:40.085997247Z","rtype":160,"publisher_id":101,"instrument_id":436},"action":"C","side":"A","price":"1.156710000","size":30,"channel_id":23,"order_id":"1775527120078358401","flags":0,"ts_in_delta":1045,"sequence":140438,"symbol":"FCEU SI 20260615 PS"}
{"ts_recv":"2026-04-07T01:58:40.086016573Z","hd":{"ts_event":"2026-04-07T01:58:40.085997247Z","rtype":160,"publisher_id":101,"instrument_id":436},"action":"A","side":"A","price":"1.156690000","size":30,"channel_id":23,"order_id":"1775527120086003850","flags":128,"ts_in_delta":1045,"sequence":140438,"symbol":"FCEU SI 20260615 PS"}
{"ts_recv":"2026-04-07T01:58:40.093095157Z","hd":{"ts_event":"2026-04-07T01:58:40.093071425Z","rtype":160,"publisher_id":101,"instrument_id":436},"action":"C","side":"B","price":"1.156590000","size":30,"channel_id":23,"order_id":"10998899156940779658","flags":0,"ts_in_delta":915,"sequence":140440,"symbol":"FCEU SI 20260615 PS"}
{"ts_recv":"2026-04-07T01:58:40.093095157Z","hd":{"ts_event":"2026-04-07T01:58:40.093071425Z","rtype":160,"publisher_id":101,"instrument_id":436},"action":"A","side":"B","price":"1.156600000","size":30,"channel_id":23,"order_id":"10998899156947854713","flags":0,"ts_in_delta":915,"sequence":140440,"symbol":"FCEU SI 20260615 PS"}
{"ts_recv":"2026-04-07T01:58:40.093095157Z","hd":{"ts_event":"2026-04-07T01:58:40.093071425Z","rtype":160,"publisher_id":101,"instrument_id":436},"action":"C","side":"A","price":"1.156690000","size":30,"channel_id":23,"order_id":"1775527120086003850","flags":0,"ts_in_delta":915,"sequence":140440,"symbol":"FCEU SI 20260615 PS"}
{"ts_recv":"2026-04-07T01:58:40.093095157Z","hd":{"ts_event":"2026-04-07T01:58:40.093071425Z","rtype":160,"publisher_id":101,"instrument_id":436},"action":"A","side":"A","price":"1.156700000","size":30,"channel_id":23,"order_id":"1775527120093078905","flags":128,"ts_in_delta":915,"sequence":140440,"symbol":"FCEU SI 20260615 PS"}
{"ts_recv":"2026-04-07T01:58:44.920214013Z","hd":{"ts_event":"2026-04-07T01:58:44.920191355Z","rtype":160,"publisher_id":101,"instrument_id":436},"action":"C","side":"B","price":"1.156600000","size":30,"channel_id":23,"order_id":"10998899156947854713","flags":0,"ts_in_delta":978,"sequence":140477,"symbol":"FCEU SI 20260615 PS"}
{"ts_recv":"2026-04-07T01:58:44.920214013Z","hd":{"ts_event":"2026-04-07T01:58:44.920191355Z","rtype":160,"publisher_id":101,"instrument_id":436},"action":"A","side":"B","price":"1.156590000","size":30,"channel_id":23,"order_id":"10998899161774973738","flags":0,"ts_in_delta":978,"sequence":140477,"symbol":"FCEU SI 20260615 PS"}
{"ts_recv":"2026-04-07T01:58:44.920214013Z","hd":{"ts_event":"2026-04-07T01:58:44.920191355Z","rtype":160,"publisher_id":101,"instrument_id":436},"action":"C","side":"A","price":"1.156700000","size":30,"channel_id":23,"order_id":"1775527120093078905","flags":0,"ts_in_delta":978,"sequence":140477,"symbol":"FCEU SI 20260615 PS"}
{"ts_recv":"2026-04-07T01:58:44.920214013Z","hd":{"ts_event":"2026-04-07T01:58:44.920191355Z","rtype":160,"publisher_id":101,"instrument_id":436},"action":"A","side":"A","price":"1.156690000","size":30,"channel_id":23,"order_id":"1775527124920197930","flags":128,"ts_in_delta":978,"sequence":140477,"symbol":"FCEU SI 20260615 PS"}
{"ts_recv":"2026-04-07T01:58:47.926385822Z","hd":{"ts_event":"2026-04-07T01:58:47.926339593Z","rtype":160,"publisher_id":101,"instrument_id":436},"action":"C","side":"B","price":"1.156590000","size":30,"channel_id":23,"order_id":"10998899161774973738","flags":0,"ts_in_delta":1368,"sequence":140489,"symbol":"FCEU SI 20260615 PS"}
{"ts_recv":"2026-04-07T01:58:47.926385822Z","hd":{"ts_event":"2026-04-07T01:58:47.926339593Z","rtype":160,"publisher_id":101,"instrument_id":436},"action":"A","side":"B","price":"1.156600000","size":30,"channel_id":23,"order_id":"10998899164781128500","flags":0,"ts_in_delta":1368,"sequence":140489,"symbol":"FCEU SI 20260615 PS"}
{"ts_recv":"2026-04-07T01:58:47.926385822Z","hd":{"ts_event":"2026-04-07T01:58:47.926339593Z","rtype":160,"publisher_id":101,"instrument_id":436},"action":"C","side":"A","price":"1.156690000","size":30,"channel_id":23,"order_id":"1775527124920197930","flags":0,"ts_in_delta":1368,"sequence":140489,"symbol":"FCEU SI 20260615 PS"}
{"ts_recv":"2026-04-07T01:58:47.926385822Z","hd":{"ts_event":"2026-04-07T01:58:47.926339593Z","rtype":160,"publisher_id":101,"instrument_id":436},"action":"A","side":"A","price":"1.156700000","size":30,"channel_id":23,"order_id":"1775527127926352692","flags":128,"ts_in_delta":1368,"sequence":140489,"symbol":"FCEU SI 20260615 PS"}
{"ts_recv":"2026-04-07T01:58:52.274755734Z","hd":{"ts_event":"2026-04-07T01:58:52.274732713Z","rtype":160,"publisher_id":101,"instrument_id":436},"action":"C","side":"B","price":"1.156600000","size":30,"channel_id":23,"order_id":"10998899164781128500","flags":0,"ts_in_delta":979,"sequence":140533,"symbol":"FCEU SI 20260615 PS"}
{"ts_recv":"2026-04-07T01:58:52.274755734Z","hd":{"ts_event":"2026-04-07T01:58:52.274732713Z","rtype":160,"publisher_id":101,"instrument_id":436},"action":"A","side":"B","price":"1.156610000","size":30,"channel_id":23,"order_id":"10998899169129514730","flags":0,"ts_in_delta":979,"sequence":140533,"symbol":"FCEU SI 20260615 PS"}
{"ts_recv":"2026-04-07T01:58:52.274755734Z","hd":{"ts_event":"2026-04-07T01:58:52.274732713Z","rtype":160,"publisher_id":101,"instrument_id":436},"action":"C","side":"A","price":"1.156700000","size":30,"channel_id":23,"order_id":"1775527127926352692","flags":0,"ts_in_delta":979,"sequence":140533,"symbol":"FCEU SI 20260615 PS"}
{"ts_recv":"2026-04-07T01:58:52.274755734Z","hd":{"ts_event":"2026-04-07T01:58:52.274732713Z","rtype":160,"publisher_id":101,"instrument_id":436},"action":"A","side":"A","price":"1.156710000","size":30,"channel_id":23,"order_id":"1775527132274738922","flags":128,"ts_in_delta":979,"sequence":140533,"symbol":"FCEU SI 20260615 PS"}
{"ts_recv":"2026-04-07T01:59:07.419215637Z","hd":{"ts_event":"2026-04-07T01:59:07.419180363Z","rtype":160,"publisher_id":101,"instrument_id":436},"action":"C","side":"B","price":"1.156610000","size":30,"channel_id":23,"order_id":"10998899169129514730","flags":0,"ts_in_delta":1361,"sequence":140609,"symbol":"FCEU SI 20260615 PS"}
{"ts_recv":"2026-04-07T01:59:07.419215637Z","hd":{"ts_event":"2026-04-07T01:59:07.419180363Z","rtype":160,"publisher_id":101,"instrument_id":436},"action":"A","side":"B","price":"1.156620000","size":30,"channel_id":23,"order_id":"10998899184273970324","flags":0,"ts_in_delta":1361,"sequence":140609,"symbol":"FCEU SI 20260615 PS"}
{"ts_recv":"2026-04-07T01:59:07.419215637Z","hd":{"ts_event":"2026-04-07T01:59:07.419180363Z","rtype":160,"publisher_id":101,"instrument_id":436},"action":"C","side":"A","price":"1.156710000","size":30,"channel_id":23,"order_id":"1775527132274738922","flags":0,"ts_in_delta":1361,"sequence":140609,"symbol":"FCEU SI 20260615 PS"}
{"ts_recv":"2026-04-07T01:59:07.419215637Z","hd":{"ts_event":"2026-04-07T01:59:07.419180363Z","rtype":160,"publisher_id":101,"instrument_id":436},"action":"A","side":"A","price":"1.156720000","size":30,"channel_id":23,"order_id":"1775527147419194516","flags":128,"ts_in_delta":1361,"sequence":140609,"symbol":"FCEU SI 20260615 PS"}
{"ts_recv":"2026-04-07T01:59:14.884553703Z","hd":{"ts_event":"2026-04-07T01:59:14.884520431Z","rtype":160,"publisher_id":101,"instrument_id":436},"action":"C","side":"B","price":"1.156620000","size":30,"channel_id":23,"order_id":"10998899184273970324","flags":0,"ts_in_delta":1317,"sequence":140657,"symbol":"FCEU SI 20260615 PS"}
{"ts_recv":"2026-04-07T01:59:14.884553703Z","hd":{"ts_event":"2026-04-07T01:59:14.884520431Z","rtype":160,"publisher_id":101,"instrument_id":436},"action":"A","side":"B","price":"1.156640000","size":30,"channel_id":23,"order_id":"10998899191739311485","flags":0,"ts_in_delta":1317,"sequence":140657,"symbol":"FCEU SI 20260615 PS"}
{"ts_recv":"2026-04-07T01:59:14.884553703Z","hd":{"ts_event":"2026-04-07T01:59:14.884520431Z","rtype":160,"publisher_id":101,"instrument_id":436},"action":"C","side":"A","price":"1.156720000","size":30,"channel_id":23,"order_id":"1775527147419194516","flags":0,"ts_in_delta":1317,"sequence":140657,"symbol":"FCEU SI 20260615 PS"}
{"ts_recv":"2026-04-07T01:59:14.884553703Z","hd":{"ts_event":"2026-04-07T01:59:14.884520431Z","rtype":160,"publisher_id":101,"instrument_id":436},"action":"A","side":"A","price":"1.156740000","size":30,"channel_id":23,"order_id":"1775527154884535677","flags":128,"ts_in_delta":1317,"sequence":140657,"symbol":"FCEU SI 20260615 PS"}
{"ts_recv":"2026-04-07T01:59:15.002337916Z","hd":{"ts_event":"2026-04-07T01:59:15.002305007Z","rtype":160,"publisher_id":101,"instrument_id":436},"action":"C","side":"B","price":"1.156640000","size":30,"channel_id":23,"order_id":"10998899191739311485","flags":0,"ts_in_delta":1061,"sequence":140662,"symbol":"FCEU SI 20260615 PS"}
{"ts_recv":"2026-04-07T01:59:15.002337916Z","hd":{"ts_event":"2026-04-07T01:59:15.002305007Z","rtype":160,"publisher_id":101,"instrument_id":436},"action":"A","side":"B","price":"1.156620000","size":30,"channel_id":23,"order_id":"10998899191857092132","flags":0,"ts_in_delta":1061,"sequence":140662,"symbol":"FCEU SI 20260615 PS"}
{"ts_recv":"2026-04-07T01:59:15.002337916Z","hd":{"ts_event":"2026-04-07T01:59:15.002305007Z","rtype":160,"publisher_id":101,"instrument_id":436},"action":"C","side":"A","price":"1.156740000","size":30,"channel_id":23,"order_id":"1775527154884535677","flags":0,"ts_in_delta":1061,"sequence":140662,"symbol":"FCEU SI 20260615 PS"}
{"ts_recv":"2026-04-07T01:59:15.002337916Z","hd":{"ts_event":"2026-04-07T01:59:15.002305007Z","rtype":160,"publisher_id":101,"instrument_id":436},"action":"A","side":"A","price":"1.156720000","size":30,"channel_id":23,"order_id":"1775527155002316324","flags":128,"ts_in_delta":1061,"sequence":140662,"symbol":"FCEU SI 20260615 PS"}
{"ts_recv":"2026-04-07T01:59:15.008213269Z","hd":{"ts_event":"2026-04-07T01:59:15.008190401Z","rtype":160,"publisher_id":101,"instrument_id":436},"action":"C","side":"B","price":"1.156620000","size":30,"channel_id":23,"order_id":"10998899191857092132","flags":0,"ts_in_delta":985,"sequence":140664,"symbol":"FCEU SI 20260615 PS"}
{"ts_recv":"2026-04-07T01:59:15.008213269Z","hd":{"ts_event":"2026-04-07T01:59:15.008190401Z","rtype":160,"publisher_id":101,"instrument_id":436},"action":"A","side":"B","price":"1.156610000","size":30,"channel_id":23,"order_id":"10998899191862972550","flags":0,"ts_in_delta":985,"sequence":140664,"symbol":"FCEU SI 20260615 PS"}
{"ts_recv":"2026-04-07T01:59:15.008213269Z","hd":{"ts_event":"2026-04-07T01:59:15.008190401Z","rtype":160,"publisher_id":101,"instrument_id":436},"action":"C","side":"A","price":"1.156720000","size":30,"channel_id":23,"order_id":"1775527155002316324","flags":0,"ts_in_delta":985,"sequence":140664,"symbol":"FCEU SI 20260615 PS"}
{"ts_recv":"2026-04-07T01:59:15.008213269Z","hd":{"ts_event":"2026-04-07T01:59:15.008190401Z","rtype":160,"publisher_id":101,"instrument_id":436},"action":"A","side":"A","price":"1.156710000","size":30,"channel_id":23,"order_id":"1775527155008196742","flags":128,"ts_in_delta":985,"sequence":140664,"symbol":"FCEU SI 20260615 PS"}
{"ts_recv":"2026-04-07T01:59:15.127586979Z","hd":{"ts_event":"2026-04-07T01:59:15.127565139Z","rtype":160,"publisher_id":101,"instrument_id":436},"action":"C","side":"B","price":"1.156610000","size":30,"channel_id":23,"order_id":"10998899191862972550","flags":0,"ts_in_delta":1387,"sequence":140668,"symbol":"FCEU SI 20260615 PS"}
{"ts_recv":"2026-04-07T01:59:15.127586979Z","hd":{"ts_event":"2026-04-07T01:59:15.127565139Z","rtype":160,"publisher_id":101,"instrument_id":436},"action":"A","side":"B","price":"1.156620000","size":30,"channel_id":23,"order_id":"10998899191982347324","flags":0,"ts_in_delta":1387,"sequence":140668,"symbol":"FCEU SI 20260615 PS"}
{"ts_recv":"2026-04-07T01:59:15.127586979Z","hd":{"ts_event":"2026-04-07T01:59:15.127565139Z","rtype":160,"publisher_id":101,"instrument_id":436},"action":"C","side":"A","price":"1.156710000","size":30,"channel_id":23,"order_id":"1775527155008196742","flags":0,"ts_in_delta":1387,"sequence":140668,"symbol":"FCEU SI 20260615 PS"}
{"ts_recv":"2026-04-07T01:59:15.127586979Z","hd":{"ts_event":"2026-04-07T01:59:15.127565139Z","rtype":160,"publisher_id":101,"instrument_id":436},"action":"A","side":"A","price":"1.156720000","size":30,"channel_id":23,"order_id":"1775527155127571516","flags":128,"ts_in_delta":1387,"sequence":140668,"symbol":"FCEU SI 20260615 PS"}
{"ts_recv":"2026-04-07T01:59:20.512476238Z","hd":{"ts_event":"2026-04-07T01:59:20.512453253Z","rtype":160,"publisher_id":101,"instrument_id":436},"action":"C","side":"B","price":"1.156620000","size":30,"channel_id":23,"order_id":"10998899191982347324","flags":0,"ts_in_delta":951,"sequence":140692,"symbol":"FCEU SI 20260615 PS"}
{"ts_recv":"2026-04-07T01:59:20.512476238Z","hd":{"ts_event":"2026-04-07T01:59:20.512453253Z","rtype":160,"publisher_id":101,"instrument_id":436},"action":"A","side":"B","price":"1.156630000","size":30,"channel_id":23,"order_id":"10998899197367235374","flags":0,"ts_in_delta":951,"sequence":140692,"symbol":"FCEU SI 20260615 PS"}
{"ts_recv":"2026-04-07T01:59:20.512476238Z","hd":{"ts_event":"2026-04-07T01:59:20.512453253Z","rtype":160,"publisher_id":101,"instrument_id":436},"action":"C","side":"A","price":"1.156720000","size":30,"channel_id":23,"order_id":"1775527155127571516","flags":0,"ts_in_delta":951,"sequence":140692,"symbol":"FCEU SI 20260615 PS"}
{"ts_recv":"2026-04-07T01:59:20.512476238Z","hd":{"ts_event":"2026-04-07T01:59:20.512453253Z","rtype":160,"publisher_id":101,"instrument_id":436},"action":"A","side":"A","price":"1.156730000","size":30,"channel_id":23,"order_id":"1775527160512459566","flags":128,"ts_in_delta":951,"sequence":140692,"symbol":"FCEU SI 20260615 PS"}
{"ts_recv":"2026-04-07T01:59:23.379266821Z","hd":{"ts_event":"2026-04-07T01:59:23.379231245Z","rtype":160,"publisher_id":101,"instrument_id":436},"action":"C","side":"B","price":"1.156630000","size":30,"channel_id":23,"order_id":"10998899197367235374","flags":0,"ts_in_delta":1234,"sequence":140710,"symbol":"FCEU SI 20260615 PS"}
{"ts_recv":"2026-04-07T01:59:23.379266821Z","hd":{"ts_event":"2026-04-07T01:59:23.379231245Z","rtype":160,"publisher_id":101,"instrument_id":436},"action":"A","side":"B","price":"1.156620000","size":30,"channel_id":23,"order_id":"10998899200234021740","flags":0,"ts_in_delta":1234,"sequence":140710,"symbol":"FCEU SI 20260615 PS"}
{"ts_recv":"2026-04-07T01:59:23.379266821Z","hd":{"ts_event":"2026-04-07T01:59:23.379231245Z","rtype":160,"publisher_id":101,"instrument_id":436},"action":"C","side":"A","price":"1.156730000","size":30,"channel_id":23,"order_id":"1775527160512459566","flags":0,"ts_in_delta":1234,"sequence":140710,"symbol":"FCEU SI 20260615 PS"}
{"ts_recv":"2026-04-07T01:59:23.379266821Z","hd":{"ts_event":"2026-04-07T01:59:23.379231245Z","rtype":160,"publisher_id":101,"instrument_id":436},"action":"A","side":"A","price":"1.156720000","size":30,"channel_id":23,"order_id":"1775527163379245932","flags":128,"ts_in_delta":1234,"sequence":140710,"symbol":"FCEU SI 20260615 PS"}
{"ts_recv":"2026-04-07T01:59:24.274486724Z","hd":{"ts_event":"2026-04-07T01:59:24.274452517Z","rtype":160,"publisher_id":101,"instrument_id":436},"action":"C","side":"B","price":"1.156620000","size":30,"channel_id":23,"order_id":"10998899200234021740","flags":0,"ts_in_delta":1488,"sequence":140716,"symbol":"FCEU SI 20260615 PS"}
{"ts_recv":"2026-04-07T01:59:24.274486724Z","hd":{"ts_event":"2026-04-07T01:59:24.274452517Z","rtype":160,"publisher_id":101,"instrument_id":436},"action":"A","side":"B","price":"1.156630000","size":30,"channel_id":23,"order_id":"10998899201129242570","flags":0,"ts_in_delta":1488,"sequence":140716,"symbol":"FCEU SI 20260615 PS"}
{"ts_recv":"2026-04-07T01:59:24.274486724Z","hd":{"ts_event":"2026-04-07T01:59:24.274452517Z","rtype":160,"publisher_id":101,"instrument_id":436},"action":"C","side":"A","price":"1.156720000","size":30,"channel_id":23,"order_id":"1775527163379245932","flags":0,"ts_in_delta":1488,"sequence":140716,"symbol":"FCEU SI 20260615 PS"}
{"ts_recv":"2026-04-07T01:59:24.274486724Z","hd":{"ts_event":"2026-04-07T01:59:24.274452517Z","rtype":160,"publisher_id":101,"instrument_id":436},"action":"A","side":"A","price":"1.156730000","size":30,"channel_id":23,"order_id":"1775527164274466762","flags":128,"ts_in_delta":1488,"sequence":140716,"symbol":"FCEU SI 20260615 PS"}
{"ts_recv":"2026-04-07T01:59:25.932276793Z","hd":{"ts_event":"2026-04-07T01:59:25.932240929Z","rtype":160,"publisher_id":101,"instrument_id":436},"action":"C","side":"B","price":"1.156630000","size":30,"channel_id":23,"order_id":"10998899201129242570","flags":0,"ts_in_delta":1428,"sequence":140728,"symbol":"FCEU SI 20260615 PS"}
{"ts_recv":"2026-04-07T01:59:25.932276793Z","hd":{"ts_event":"2026-04-07T01:59:25.932240929Z","rtype":160,"publisher_id":101,"instrument_id":436},"action":"A","side":"B","price":"1.156620000","size":30,"channel_id":23,"order_id":"10998899202787031838","flags":0,"ts_in_delta":1428,"sequence":140728,"symbol":"FCEU SI 20260615 PS"}
{"ts_recv":"2026-04-07T01:59:25.932276793Z","hd":{"ts_event":"2026-04-07T01:59:25.932240929Z","rtype":160,"publisher_id":101,"instrument_id":436},"action":"C","side":"A","price":"1.156730000","size":30,"channel_id":23,"order_id":"1775527164274466762","flags":0,"ts_in_delta":1428,"sequence":140728,"symbol":"FCEU SI 20260615 PS"}
{"ts_recv":"2026-04-07T01:59:25.932276793Z","hd":{"ts_event":"2026-04-07T01:59:25.932240929Z","rtype":160,"publisher_id":101,"instrument_id":436},"action":"A","side":"A","price":"1.156720000","size":30,"channel_id":23,"order_id":"1775527165932256030","flags":128,"ts_in_delta":1428,"sequence":140728,"symbol":"FCEU SI 20260615 PS"}
{"ts_recv":"2026-04-07T01:59:26.872819205Z","hd":{"ts_event":"2026-04-07T01:59:26.872790357Z","rtype":160,"publisher_id":101,"instrument_id":436},"action":"C","side":"B","price":"1.156620000","size":30,"channel_id":23,"order_id":"10998899202787031838","flags":0,"ts_in_delta":1637,"sequence":140731,"symbol":"FCEU SI 20260615 PS"}
{"ts_recv":"2026-04-07T01:59:26.872819205Z","hd":{"ts_event":"2026-04-07T01:59:26.872790357Z","rtype":160,"publisher_id":101,"instrument_id":436},"action":"A","side":"B","price":"1.156630000","size":30,"channel_id":23,"order_id":"10998899203727576510","flags":0,"ts_in_delta":1637,"sequence":140731,"symbol":"FCEU SI 20260615 PS"}
{"ts_recv":"2026-04-07T01:59:26.872819205Z","hd":{"ts_event":"2026-04-07T01:59:26.872790357Z","rtype":160,"publisher_id":101,"instrument_id":436},"action":"C","side":"A","price":"1.156720000","size":30,"channel_id":23,"order_id":"1775527165932256030","flags":0,"ts_in_delta":1637,"sequence":140731,"symbol":"FCEU SI 20260615 PS"}
{"ts_recv":"2026-04-07T01:59:26.872819205Z","hd":{"ts_event":"2026-04-07T01:59:26.872790357Z","rtype":160,"publisher_id":101,"instrument_id":436},"action":"A","side":"A","price":"1.156730000","size":30,"channel_id":23,"order_id":"1775527166872800702","flags":128,"ts_in_delta":1637,"sequence":140731,"symbol":"FCEU SI 20260615 PS"}
{"ts_recv":"2026-04-07T01:59:26.884662652Z","hd":{"ts_event":"2026-04-07T01:59:26.884640805Z","rtype":160,"publisher_id":101,"instrument_id":436},"action":"C","side":"B","price":"1.156630000","size":30,"channel_id":23,"order_id":"10998899203727576510","flags":0,"ts_in_delta":1039,"sequence":140733,"symbol":"FCEU SI 20260615 PS"}
{"ts_recv":"2026-04-07T01:59:26.884662652Z","hd":{"ts_event":"2026-04-07T01:59:26.884640805Z","rtype":160,"publisher_id":101,"instrument_id":436},"action":"A","side":"B","price":"1.156640000","size":30,"channel_id":23,"order_id":"10998899203739422907","flags":0,"ts_in_delta":1039,"sequence":140733,"symbol":"FCEU SI 20260615 PS"}
{"ts_recv":"2026-04-07T01:59:26.884662652Z","hd":{"ts_event":"2026-04-07T01:59:26.884640805Z","rtype":160,"publisher_id":101,"instrument_id":436},"action":"C","side":"A","price":"1.156730000","size":30,"channel_id":23,"order_id":"1775527166872800702","flags":0,"ts_in_delta":1039,"sequence":140733,"symbol":"FCEU SI 20260615 PS"}
{"ts_recv":"2026-04-07T01:59:26.884662652Z","hd":{"ts_event":"2026-04-07T01:59:26.884640805Z","rtype":160,"publisher_id":101,"instrument_id":436},"action":"A","side":"A","price":"1.156740000","size":30,"channel_id":23,"order_id":"1775527166884647099","flags":128,"ts_in_delta":1039,"sequence":140733,"symbol":"FCEU SI 20260615 PS"}
{"ts_recv":"2026-04-07T01:59:29.529153431Z","hd":{"ts_event":"2026-04-07T01:59:29.529121773Z","rtype":160,"publisher_id":101,"instrument_id":436},"action":"C","side":"B","price":"1.156640000","size":30,"channel_id":23,"order_id":"10998899203739422907","flags":0,"ts_in_delta":1469,"sequence":140747,"symbol":"FCEU SI 20260615 PS"}
{"ts_recv":"2026-04-07T01:59:29.529153431Z","hd":{"ts_event":"2026-04-07T01:59:29.529121773Z","rtype":160,"publisher_id":101,"instrument_id":436},"action":"A","side":"B","price":"1.156650000","size":30,"channel_id":23,"order_id":"10998899206383910939","flags":0,"ts_in_delta":1469,"sequence":140747,"symbol":"FCEU SI 20260615 PS"}
{"ts_recv":"2026-04-07T01:59:29.529153431Z","hd":{"ts_event":"2026-04-07T01:59:29.529121773Z","rtype":160,"publisher_id":101,"instrument_id":436},"action":"C","side":"A","price":"1.156740000","size":30,"channel_id":23,"order_id":"1775527166884647099","flags":0,"ts_in_delta":1469,"sequence":140747,"symbol":"FCEU SI 20260615 PS"}
{"ts_recv":"2026-04-07T01:59:29.529153431Z","hd":{"ts_event":"2026-04-07T01:59:29.529121773Z","rtype":160,"publisher_id":101,"instrument_id":436},"action":"A","side":"A","price":"1.156750000","size":30,"channel_id":23,"order_id":"1775527169529135131","flags":128,"ts_in_delta":1469,"sequence":140747,"symbol":"FCEU SI 20260615 PS"}
{"ts_recv":"2026-04-07T01:59:35.606630021Z","hd":{"ts_event":"2026-04-07T01:59:35.606596677Z","rtype":160,"publisher_id":101,"instrument_id":436},"action":"C","side":"B","price":"1.156650000","size":30,"channel_id":23,"order_id":"10998899206383910939","flags":0,"ts_in_delta":1730,"sequence":140774,"symbol":"FCEU SI 20260615 PS"}
{"ts_recv":"2026-04-07T01:59:35.606630021Z","hd":{"ts_event":"2026-04-07T01:59:35.606596677Z","rtype":160,"publisher_id":101,"instrument_id":436},"action":"A","side":"B","price":"1.156640000","size":30,"channel_id":23,"order_id":"10998899212461385658","flags":0,"ts_in_delta":1730,"sequence":140774,"symbol":"FCEU SI 20260615 PS"}
{"ts_recv":"2026-04-07T01:59:35.606630021Z","hd":{"ts_event":"2026-04-07T01:59:35.606596677Z","rtype":160,"publisher_id":101,"instrument_id":436},"action":"C","side":"A","price":"1.156750000","size":30,"channel_id":23,"order_id":"1775527169529135131","flags":0,"ts_in_delta":1730,"sequence":140774,"symbol":"FCEU SI 20260615 PS"}
{"ts_recv":"2026-04-07T01:59:35.606630021Z","hd":{"ts_event":"2026-04-07T01:59:35.606596677Z","rtype":160,"publisher_id":101,"instrument_id":436},"action":"A","side":"A","price":"1.156740000","size":30,"channel_id":23,"order_id":"1775527175606609850","flags":128,"ts_in_delta":1730,"sequence":140774,"symbol":"FCEU SI 20260615 PS"}
{"ts_recv":"2026-04-07T01:59:37.200076979Z","hd":{"ts_event":"2026-04-07T01:59:37.200035707Z","rtype":160,"publisher_id":101,"instrument_id":436},"action":"C","side":"B","price":"1.156640000","size":30,"channel_id":23,"order_id":"10998899212461385658","flags":0,"ts_in_delta":1384,"sequence":140792,"symbol":"FCEU SI 20260615 PS"}
{"ts_recv":"2026-04-07T01:59:37.200076979Z","hd":{"ts_event":"2026-04-07T01:59:37.200035707Z","rtype":160,"publisher_id":101,"instrument_id":436},"action":"A","side":"B","price":"1.156650000","size":30,"channel_id":23,"order_id":"10998899214054825375","flags":0,"ts_in_delta":1384,"sequence":140792,"symbol":"FCEU SI 20260615 PS"}
{"ts_recv":"2026-04-07T01:59:37.200076979Z","hd":{"ts_event":"2026-04-07T01:59:37.200035707Z","rtype":160,"publisher_id":101,"instrument_id":436},"action":"C","side":"A","price":"1.156740000","size":30,"channel_id":23,"order_id":"1775527175606609850","flags":0,"ts_in_delta":1384,"sequence":140792,"symbol":"FCEU SI 20260615 PS"}
{"ts_recv":"2026-04-07T01:59:37.200076979Z","hd":{"ts_event":"2026-04-07T01:59:37.200035707Z","rtype":160,"publisher_id":101,"instrument_id":436},"action":"A","side":"A","price":"1.156750000","size":30,"channel_id":23,"order_id":"1775527177200049567","flags":128,"ts_in_delta":1384,"sequence":140792,"symbol":"FCEU SI 20260615 PS"}
{"ts_recv":"2026-04-07T01:59:39.082356760Z","hd":{"ts_event":"2026-04-07T01:59:39.082332559Z","rtype":160,"publisher_id":101,"instrument_id":436},"action":"C","side":"B","price":"1.156650000","size":30,"channel_id":23,"order_id":"10998899214054825375","flags":0,"ts_in_delta":1578,"sequence":140806,"symbol":"FCEU SI 20260615 PS"}
{"ts_recv":"2026-04-07T01:59:39.082356760Z","hd":{"ts_event":"2026-04-07T01:59:39.082332559Z","rtype":160,"publisher_id":101,"instrument_id":436},"action":"A","side":"B","price":"1.156640000","size":30,"channel_id":23,"order_id":"10998899215937115937","flags":0,"ts_in_delta":1578,"sequence":140806,"symbol":"FCEU SI 20260615 PS"}
{"ts_recv":"2026-04-07T01:59:39.082356760Z","hd":{"ts_event":"2026-04-07T01:59:39.082332559Z","rtype":160,"publisher_id":101,"instrument_id":436},"action":"C","side":"A","price":"1.156750000","size":30,"channel_id":23,"order_id":"1775527177200049567","flags":0,"ts_in_delta":1578,"sequence":140806,"symbol":"FCEU SI 20260615 PS"}
{"ts_recv":"2026-04-07T01:59:39.082356760Z","hd":{"ts_event":"2026-04-07T01:59:39.082332559Z","rtype":160,"publisher_id":101,"instrument_id":436},"action":"A","side":"A","price":"1.156740000","size":30,"channel_id":23,"order_id":"1775527179082340129","flags":128,"ts_in_delta":1578,"sequence":140806,"symbol":"FCEU SI 20260615 PS"}
{"ts_recv":"2026-04-07T01:59:41.714184220Z","hd":{"ts_event":"2026-04-07T01:59:41.714152165Z","rtype":160,"publisher_id":101,"instrument_id":436},"action":"C","side":"B","price":"1.156640000","size":30,"channel_id":23,"order_id":"10998899215937115937","flags":0,"ts_in_delta":940,"sequence":140822,"symbol":"FCEU SI 20260615 PS"}
{"ts_recv":"2026-04-07T01:59:41.714184220Z","hd":{"ts_event":"2026-04-07T01:59:41.714152165Z","rtype":160,"publisher_id":101,"instrument_id":436},"action":"A","side":"B","price":"1.156650000","size":30,"channel_id":23,"order_id":"10998899218568942119","flags":0,"ts_in_delta":940,"sequence":140822,"symbol":"FCEU SI 20260615 PS"}
{"ts_recv":"2026-04-07T01:59:41.714184220Z","hd":{"ts_event":"2026-04-07T01:59:41.714152165Z","rtype":160,"publisher_id":101,"instrument_id":436},"action":"C","side":"A","price":"1.156740000","size":30,"channel_id":23,"order_id":"1775527179082340129","flags":0,"ts_in_delta":940,"sequence":140822,"symbol":"FCEU SI 20260615 PS"}
{"ts_recv":"2026-04-07T01:59:41.714184220Z","hd":{"ts_event":"2026-04-07T01:59:41.714152165Z","rtype":160,"publisher_id":101,"instrument_id":436},"action":"A","side":"A","price":"1.156750000","size":30,"channel_id":23,"order_id":"1775527181714166311","flags":128,"ts_in_delta":940,"sequence":140822,"symbol":"FCEU SI 20260615 PS"}
{"ts_recv":"2026-04-07T01:59:46.515013309Z","hd":{"ts_event":"2026-04-07T01:59:46.514977903Z","rtype":160,"publisher_id":101,"instrument_id":436},"action":"C","side":"B","price":"1.156650000","size":30,"channel_id":23,"order_id":"10998899218568942119","flags":0,"ts_in_delta":1744,"sequence":140852,"symbol":"FCEU SI 20260615 PS"}
{"ts_recv":"2026-04-07T01:59:46.515013309Z","hd":{"ts_event":"2026-04-07T01:59:46.514977903Z","rtype":160,"publisher_id":101,"instrument_id":436},"action":"A","side":"B","price":"1.156640000","size":30,"channel_id":23,"order_id":"10998899223369767707","flags":0,"ts_in_delta":1744,"sequence":140852,"symbol":"FCEU SI 20260615 PS"}
{"ts_recv":"2026-04-07T01:59:46.515013309Z","hd":{"ts_event":"2026-04-07T01:59:46.514977903Z","rtype":160,"publisher_id":101,"instrument_id":436},"action":"C","side":"A","price":"1.156750000","size":30,"channel_id":23,"order_id":"1775527181714166311","flags":0,"ts_in_delta":1744,"sequence":140852,"symbol":"FCEU SI 20260615 PS"}
{"ts_recv":"2026-04-07T01:59:46.515013309Z","hd":{"ts_event":"2026-04-07T01:59:46.514977903Z","rtype":160,"publisher_id":101,"instrument_id":436},"action":"A","side":"A","price":"1.156740000","size":30,"channel_id":23,"order_id":"1775527186514991899","flags":128,"ts_in_delta":1744,"sequence":140852,"symbol":"FCEU SI 20260615 PS"}
{"ts_recv":"2026-04-07T01:59:52.237432872Z","hd":{"ts_event":"2026-04-07T01:59:52.237398343Z","rtype":160,"publisher_id":101,"instrument_id":436},"action":"C","side":"B","price":"1.156640000","size":30,"channel_id":23,"order_id":"10998899223369767707","flags":0,"ts_in_delta":1414,"sequence":140878,"symbol":"FCEU SI 20260615 PS"}
{"ts_recv":"2026-04-07T01:59:52.237432872Z","hd":{"ts_event":"2026-04-07T01:59:52.237398343Z","rtype":160,"publisher_id":101,"instrument_id":436},"action":"A","side":"B","price":"1.156650000","size":30,"channel_id":23,"order_id":"10998899229092187497","flags":0,"ts_in_delta":1414,"sequence":140878,"symbol":"FCEU SI 20260615 PS"}
{"ts_recv":"2026-04-07T01:59:52.237432872Z","hd":{"ts_event":"2026-04-07T01:59:52.237398343Z","rtype":160,"publisher_id":101,"instrument_id":436},"action":"C","side":"A","price":"1.156740000","size":30,"channel_id":23,"order_id":"1775527186514991899","flags":0,"ts_in_delta":1414,"sequence":140878,"symbol":"FCEU SI 20260615 PS"}
{"ts_recv":"2026-04-07T01:59:52.237432872Z","hd":{"ts_event":"2026-04-07T01:59:52.237398343Z","rtype":160,"publisher_id":101,"instrument_id":436},"action":"A","side":"A","price":"1.156750000","size":30,"channel_id":23,"order_id":"1775527192237411689","flags":128,"ts_in_delta":1414,"sequence":140878,"symbol":"FCEU SI 20260615 PS"}
{"ts_recv":"2026-04-07T01:59:53.407041831Z","hd":{"ts_event":"2026-04-07T01:59:53.407010107Z","rtype":160,"publisher_id":101,"instrument_id":436},"action":"C","side":"B","price":"1.156650000","size":30,"channel_id":23,"order_id":"10998899229092187497","flags":0,"ts_in_delta":1840,"sequence":140885,"symbol":"FCEU SI 20260615 PS"}
{"ts_recv":"2026-04-07T01:59:53.407041831Z","hd":{"ts_event":"2026-04-07T01:59:53.407010107Z","rtype":160,"publisher_id":101,"instrument_id":436},"action":"A","side":"B","price":"1.156640000","size":30,"channel_id":23,"order_id":"10998899230261796905","flags":0,"ts_in_delta":1840,"sequence":140885,"symbol":"FCEU SI 20260615 PS"}
{"ts_recv":"2026-04-07T01:59:53.407041831Z","hd":{"ts_event":"2026-04-07T01:59:53.407010107Z","rtype":160,"publisher_id":101,"instrument_id":436},"action":"C","side":"A","price":"1.156750000","size":30,"channel_id":23,"order_id":"1775527192237411689","flags":0,"ts_in_delta":1840,"sequence":140885,"symbol":"FCEU SI 20260615 PS"}
{"ts_recv":"2026-04-07T01:59:53.407041831Z","hd":{"ts_event":"2026-04-07T01:59:53.407010107Z","rtype":160,"publisher_id":101,"instrument_id":436},"action":"A","side":"A","price":"1.156740000","size":30,"channel_id":23,"order_id":"1775527193407021097","flags":128,"ts_in_delta":1840,"sequence":140885,"symbol":"FCEU SI 20260615 PS"}
{"ts_recv":"2026-04-07T01:59:53.417624163Z","hd":{"ts_event":"2026-04-07T01:59:53.417606237Z","rtype":160,"publisher_id":101,"instrument_id":436},"action":"C","side":"B","price":"1.156640000","size":30,"channel_id":23,"order_id":"10998899230261796905","flags":0,"ts_in_delta":997,"sequence":140886,"symbol":"FCEU SI 20260615 PS"}
{"ts_recv":"2026-04-07T01:59:53.417624163Z","hd":{"ts_event":"2026-04-07T01:59:53.417606237Z","rtype":160,"publisher_id":101,"instrument_id":436},"action":"A","side":"B","price":"1.156620000","size":30,"channel_id":23,"order_id":"10998899230272388051","flags":0,"ts_in_delta":997,"sequence":140886,"symbol":"FCEU SI 20260615 PS"}
{"ts_recv":"2026-04-07T01:59:53.417624163Z","hd":{"ts_event":"2026-04-07T01:59:53.417606237Z","rtype":160,"publisher_id":101,"instrument_id":436},"action":"C","side":"A","price":"1.156740000","size":30,"channel_id":23,"order_id":"1775527193407021097","flags":0,"ts_in_delta":997,"sequence":140886,"symbol":"FCEU SI 20260615 PS"}
{"ts_recv":"2026-04-07T01:59:53.417624163Z","hd":{"ts_event":"2026-04-07T01:59:53.417606237Z","rtype":160,"publisher_id":101,"instrument_id":436},"action":"A","side":"A","price":"1.156720000","size":30,"channel_id":23,"order_id":"1775527193417612243","flags":128,"ts_in_delta":997,"sequence":140886,"symbol":"FCEU SI 20260615 PS"}
{"ts_recv":"2026-04-07T01:59:53.422403039Z","hd":{"ts_event":"2026-04-07T01:59:53.422381121Z","rtype":160,"publisher_id":101,"instrument_id":436},"action":"C","side":"B","price":"1.156620000","size":30,"channel_id":23,"order_id":"10998899230272388051","flags":0,"ts_in_delta":1008,"sequence":140889,"symbol":"FCEU SI 20260615 PS"}
{"ts_recv":"2026-04-07T01:59:53.422403039Z","hd":{"ts_event":"2026-04-07T01:59:53.422381121Z","rtype":160,"publisher_id":101,"instrument_id":436},"action":"A","side":"B","price":"1.156610000","size":30,"channel_id":23,"order_id":"10998899230277162964","flags":0,"ts_in_delta":1008,"sequence":140889,"symbol":"FCEU SI 20260615 PS"}
{"ts_recv":"2026-04-07T01:59:53.422403039Z","hd":{"ts_event":"2026-04-07T01:59:53.422381121Z","rtype":160,"publisher_id":101,"instrument_id":436},"action":"C","side":"A","price":"1.156720000","size":30,"channel_id":23,"order_id":"1775527193417612243","flags":0,"ts_in_delta":1008,"sequence":140889,"symbol":"FCEU SI 20260615 PS"}
{"ts_recv":"2026-04-07T01:59:53.422403039Z","hd":{"ts_event":"2026-04-07T01:59:53.422381121Z","rtype":160,"publisher_id":101,"instrument_id":436},"action":"A","side":"A","price":"1.156710000","size":30,"channel_id":23,"order_id":"1775527193422387156","flags":128,"ts_in_delta":1008,"sequence":140889,"symbol":"FCEU SI 20260615 PS"}
{"ts_recv":"2026-04-07T01:59:54.009342975Z","hd":{"ts_event":"2026-04-07T01:59:54.009323405Z","rtype":160,"publisher_id":101,"instrument_id":436},"action":"C","side":"B","price":"1.156610000","size":30,"channel_id":23,"order_id":"10998899230277162964","flags":0,"ts_in_delta":1230,"sequence":140907,"symbol":"FCEU SI 20260615 PS"}
{"ts_recv":"2026-04-07T01:59:54.009342975Z","hd":{"ts_event":"2026-04-07T01:59:54.009323405Z","rtype":160,"publisher_id":101,"instrument_id":436},"action":"A","side":"B","price":"1.156620000","size":30,"channel_id":23,"order_id":"10998899230864105204","flags":0,"ts_in_delta":1230,"sequence":140907,"symbol":"FCEU SI 20260615 PS"}
{"ts_recv":"2026-04-07T01:59:54.009342975Z","hd":{"ts_event":"2026-04-07T01:59:54.009323405Z","rtype":160,"publisher_id":101,"instrument_id":436},"action":"C","side":"A","price":"1.156710000","size":30,"channel_id":23,"order_id":"1775527193422387156","flags":0,"ts_in_delta":1230,"sequence":140907,"symbol":"FCEU SI 20260615 PS"}
{"ts_recv":"2026-04-07T01:59:54.009342975Z","hd":{"ts_event":"2026-04-07T01:59:54.009323405Z","rtype":160,"publisher_id":101,"instrument_id":436},"action":"A","side":"A","price":"1.156720000","size":30,"channel_id":23,"order_id":"1775527194009329396","flags":128,"ts_in_delta":1230,"sequence":140907,"symbol":"FCEU SI 20260615 PS"}
{"ts_recv":"2026-04-07T01:59:54.022135225Z","hd":{"ts_event":"2026-04-07T01:59:54.022113221Z","rtype":160,"publisher_id":101,"instrument_id":436},"action":"C","side":"B","price":"1.156620000","size":30,"channel_id":23,"order_id":"10998899230864105204","flags":0,"ts_in_delta":968,"sequence":140908,"symbol":"FCEU SI 20260615 PS"}
{"ts_recv":"2026-04-07T01:59:54.022135225Z","hd":{"ts_event":"2026-04-07T01:59:54.022113221Z","rtype":160,"publisher_id":101,"instrument_id":436},"action":"A","side":"B","price":"1.156630000","size":30,"channel_id":23,"order_id":"10998899230876895088","flags":0,"ts_in_delta":968,"sequence":140908,"symbol":"FCEU SI 20260615 PS"}
{"ts_recv":"2026-04-07T01:59:54.022135225Z","hd":{"ts_event":"2026-04-07T01:59:54.022113221Z","rtype":160,"publisher_id":101,"instrument_id":436},"action":"C","side":"A","price":"1.156720000","size":30,"channel_id":23,"order_id":"1775527194009329396","flags":0,"ts_in_delta":968,"sequence":140908,"symbol":"FCEU SI 20260615 PS"}
{"ts_recv":"2026-04-07T01:59:54.022135225Z","hd":{"ts_event":"2026-04-07T01:59:54.022113221Z","rtype":160,"publisher_id":101,"instrument_id":436},"action":"A","side":"A","price":"1.156730000","size":30,"channel_id":23,"order_id":"1775527194022119280","flags":128,"ts_in_delta":968,"sequence":140908,"symbol":"FCEU SI 20260615 PS"}
{"ts_recv":"2026-04-07T01:59:56.993243476Z","hd":{"ts_event":"2026-04-07T01:59:56.993221809Z","rtype":160,"publisher_id":101,"instrument_id":436},"action":"C","side":"B","price":"1.156630000","size":30,"channel_id":23,"order_id":"10998899230876895088","flags":0,"ts_in_delta":947,"sequence":140916,"symbol":"FCEU SI 20260615 PS"}
{"ts_recv":"2026-04-07T01:59:56.993243476Z","hd":{"ts_event":"2026-04-07T01:59:56.993221809Z","rtype":160,"publisher_id":101,"instrument_id":436},"action":"A","side":"B","price":"1.156640000","size":30,"channel_id":23,"order_id":"10998899233848004627","flags":0,"ts_in_delta":947,"sequence":140916,"symbol":"FCEU SI 20260615 PS"}
{"ts_recv":"2026-04-07T01:59:56.993243476Z","hd":{"ts_event":"2026-04-07T01:59:56.993221809Z","rtype":160,"publisher_id":101,"instrument_id":436},"action":"C","side":"A","price":"1.156730000","size":30,"channel_id":23,"order_id":"1775527194022119280","flags":0,"ts_in_delta":947,"sequence":140916,"symbol":"FCEU SI 20260615 PS"}
{"ts_recv":"2026-04-07T01:59:56.993243476Z","hd":{"ts_event":"2026-04-07T01:59:56.993221809Z","rtype":160,"publisher_id":101,"instrument_id":436},"action":"A","side":"A","price":"1.156740000","size":30,"channel_id":23,"order_id":"1775527196993228819","flags":128,"ts_in_delta":947,"sequence":140916,"symbol":"FCEU SI 20260615 PS"}
{"ts_recv":"2026-04-07T01:59:59.174636456Z","hd":{"ts_event":"2026-04-07T01:59:59.174604481Z","rtype":160,"publisher_id":101,"instrument_id":436},"action":"C","side":"B","price":"1.156640000","size":30,"channel_id":23,"order_id":"10998899233848004627","flags":0,"ts_in_delta":1450,"sequence":140939,"symbol":"FCEU SI 20260615 PS"}
{"ts_recv":"2026-04-07T01:59:59.174636456Z","hd":{"ts_event":"2026-04-07T01:59:59.174604481Z","rtype":160,"publisher_id":101,"instrument_id":436},"action":"A","side":"B","price":"1.156660000","size":30,"channel_id":23,"order_id":"10998899236029394077","flags":0,"ts_in_delta":1450,"sequence":140939,"symbol":"FCEU SI 20260615 PS"}
{"ts_recv":"2026-04-07T01:59:59.174636456Z","hd":{"ts_event":"2026-04-07T01:59:59.174604481Z","rtype":160,"publisher_id":101,"instrument_id":436},"action":"C","side":"A","price":"1.156740000","size":30,"channel_id":23,"order_id":"1775527196993228819","flags":0,"ts_in_delta":1450,"sequence":140939,"symbol":"FCEU SI 20260615 PS"}
{"ts_recv":"2026-04-07T01:59:59.174636456Z","hd":{"ts_event":"2026-04-07T01:59:59.174604481Z","rtype":160,"publisher_id":101,"instrument_id":436},"action":"A","side":"A","price":"1.156760000","size":30,"channel_id":23,"order_id":"1775527199174618269","flags":128,"ts_in_delta":1450,"sequence":140939,"symbol":"FCEU SI 20260615 PS"}
{"ts_recv":"2026-04-07T02:00:00.053811130Z","hd":{"ts_event":"2026-04-07T02:00:00.053791281Z","rtype":160,"publisher_id":101,"instrument_id":436},"action":"C","side":"B","price":"1.156660000","size":30,"channel_id":23,"order_id":"10998899236029394077","flags":0,"ts_in_delta":877,"sequence":140952,"symbol":"FCEU SI 20260615 PS"}
{"ts_recv":"2026-04-07T02:00:00.053811130Z","hd":{"ts_event":"2026-04-07T02:00:00.053791281Z","rtype":160,"publisher_id":101,"instrument_id":436},"action":"A","side":"B","price":"1.156670000","size":30,"channel_id":23,"order_id":"10998899236908573126","flags":0,"ts_in_delta":877,"sequence":140952,"symbol":"FCEU SI 20260615 PS"}
{"ts_recv":"2026-04-07T02:00:00.053811130Z","hd":{"ts_event":"2026-04-07T02:00:00.053791281Z","rtype":160,"publisher_id":101,"instrument_id":436},"action":"C","side":"A","price":"1.156760000","size":30,"channel_id":23,"order_id":"1775527199174618269","flags":0,"ts_in_delta":877,"sequence":140952,"symbol":"FCEU SI 20260615 PS"}
{"ts_recv":"2026-04-07T02:00:00.053811130Z","hd":{"ts_event":"2026-04-07T02:00:00.053791281Z","rtype":160,"publisher_id":101,"instrument_id":436},"action":"A","side":"A","price":"1.156770000","size":30,"channel_id":23,"order_id":"1775527200053797318","flags":128,"ts_in_delta":877,"sequence":140952,"symbol":"FCEU SI 20260615 PS"}
{"ts_recv":"2026-04-07T02:00:00.316860430Z","hd":{"ts_event":"2026-04-07T02:00:00.316840611Z","rtype":160,"publisher_id":101,"instrument_id":436},"action":"C","side":"B","price":"1.156670000","size":30,"channel_id":23,"order_id":"10998899236908573126","flags":0,"ts_in_delta":873,"sequence":140959,"symbol":"FCEU SI 20260615 PS"}
{"ts_recv":"2026-04-07T02:00:00.316860430Z","hd":{"ts_event":"2026-04-07T02:00:00.316840611Z","rtype":160,"publisher_id":101,"instrument_id":436},"action":"A","side":"B","price":"1.156680000","size":30,"channel_id":23,"order_id":"10998899237171622993","flags":0,"ts_in_delta":873,"sequence":140959,"symbol":"FCEU SI 20260615 PS"}
{"ts_recv":"2026-04-07T02:00:00.316860430Z","hd":{"ts_event":"2026-04-07T02:00:00.316840611Z","rtype":160,"publisher_id":101,"instrument_id":436},"action":"C","side":"A","price":"1.156770000","size":30,"channel_id":23,"order_id":"1775527200053797318","flags":0,"ts_in_delta":873,"sequence":140959,"symbol":"FCEU SI 20260615 PS"}
{"ts_recv":"2026-04-07T02:00:00.316860430Z","hd":{"ts_event":"2026-04-07T02:00:00.316840611Z","rtype":160,"publisher_id":101,"instrument_id":436},"action":"A","side":"A","price":"1.156780000","size":30,"channel_id":23,"order_id":"1775527200316847185","flags":128,"ts_in_delta":873,"sequence":140959,"symbol":"FCEU SI 20260615 PS"}
{"ts_recv":"2026-04-07T02:00:00.321320577Z","hd":{"ts_event":"2026-04-07T02:00:00.321301987Z","rtype":160,"publisher_id":101,"instrument_id":436},"action":"C","side":"B","price":"1.156680000","size":30,"channel_id":23,"order_id":"10998899237171622993","flags":0,"ts_in_delta":905,"sequence":140962,"symbol":"FCEU SI 20260615 PS"}
{"ts_recv":"2026-04-07T02:00:00.321320577Z","hd":{"ts_event":"2026-04-07T02:00:00.321301987Z","rtype":160,"publisher_id":101,"instrument_id":436},"action":"A","side":"B","price":"1.156690000","size":30,"channel_id":23,"order_id":"10998899237176083497","flags":0,"ts_in_delta":905,"sequence":140962,"symbol":"FCEU SI 20260615 PS"}
{"ts_recv":"2026-04-07T02:00:00.321320577Z","hd":{"ts_event":"2026-04-07T02:00:00.321301987Z","rtype":160,"publisher_id":101,"instrument_id":436},"action":"C","side":"A","price":"1.156780000","size":30,"channel_id":23,"order_id":"1775527200316847185","flags":0,"ts_in_delta":905,"sequence":140962,"symbol":"FCEU SI 20260615 PS"}
{"ts_recv":"2026-04-07T02:00:00.321320577Z","hd":{"ts_event":"2026-04-07T02:00:00.321301987Z","rtype":160,"publisher_id":101,"instrument_id":436},"action":"A","side":"A","price":"1.156790000","size":30,"channel_id":23,"order_id":"1775527200321307689","flags":128,"ts_in_delta":905,"sequence":140962,"symbol":"FCEU SI 20260615 PS"}
{"ts_recv":"2026-04-07T02:00:00.507503344Z","hd":{"ts_event":"2026-04-07T02:00:00.507475563Z","rtype":160,"publisher_id":101,"instrument_id":436},"action":"C","side":"B","price":"1.156690000","size":30,"channel_id":23,"order_id":"10998899237176083497","flags":0,"ts_in_delta":1172,"sequence":140973,"symbol":"FCEU SI 20260615 PS"}
{"ts_recv":"2026-04-07T02:00:00.507503344Z","hd":{"ts_event":"2026-04-07T02:00:00.507475563Z","rtype":160,"publisher_id":101,"instrument_id":436},"action":"A","side":"B","price":"1.156680000","size":30,"channel_id":23,"order_id":"10998899237362263880","flags":0,"ts_in_delta":1172,"sequence":140973,"symbol":"FCEU SI 20260615 PS"}
{"ts_recv":"2026-04-07T02:00:00.507503344Z","hd":{"ts_event":"2026-04-07T02:00:00.507475563Z","rtype":160,"publisher_id":101,"instrument_id":436},"action":"C","side":"A","price":"1.156790000","size":30,"channel_id":23,"order_id":"1775527200321307689","flags":0,"ts_in_delta":1172,"sequence":140973,"symbol":"FCEU SI 20260615 PS"}
{"ts_recv":"2026-04-07T02:00:00.507503344Z","hd":{"ts_event":"2026-04-07T02:00:00.507475563Z","rtype":160,"publisher_id":101,"instrument_id":436},"action":"A","side":"A","price":"1.156780000","size":30,"channel_id":23,"order_id":"1775527200507488072","flags":128,"ts_in_delta":1172,"sequence":140973,"symbol":"FCEU SI 20260615 PS"}
{"ts_recv":"2026-04-07T02:00:00.582326115Z","hd":{"ts_event":"2026-04-07T02:00:00.582306041Z","rtype":160,"publisher_id":101,"instrument_id":436},"action":"C","side":"B","price":"1.156680000","size":30,"channel_id":23,"order_id":"10998899237362263880","flags":0,"ts_in_delta":909,"sequence":140981,"symbol":"FCEU SI 20260615 PS"}
{"ts_recv":"2026-04-07T02:00:00.582326115Z","hd":{"ts_event":"2026-04-07T02:00:00.582306041Z","rtype":160,"publisher_id":101,"instrument_id":436},"action":"A","side":"B","price":"1.156670000","size":30,"channel_id":23,"order_id":"10998899237437087915","flags":0,"ts_in_delta":909,"sequence":140981,"symbol":"FCEU SI 20260615 PS"}
{"ts_recv":"2026-04-07T02:00:00.582326115Z","hd":{"ts_event":"2026-04-07T02:00:00.582306041Z","rtype":160,"publisher_id":101,"instrument_id":436},"action":"C","side":"A","price":"1.156780000","size":30,"channel_id":23,"order_id":"1775527200507488072","flags":0,"ts_in_delta":909,"sequence":140981,"symbol":"FCEU SI 20260615 PS"}
{"ts_recv":"2026-04-07T02:00:00.582326115Z","hd":{"ts_event":"2026-04-07T02:00:00.582306041Z","rtype":160,"publisher_id":101,"instrument_id":436},"action":"A","side":"A","price":"1.156770000","size":30,"channel_id":23,"order_id":"1775527200582312107","flags":128,"ts_in_delta":909,"sequence":140981,"symbol":"FCEU SI 20260615 PS"}
{"ts_recv":"2026-04-07T02:00:01.086486835Z","hd":{"ts_event":"2026-04-07T02:00:01.086458959Z","rtype":160,"publisher_id":101,"instrument_id":436},"action":"C","side":"B","price":"1.156670000","size":30,"channel_id":23,"order_id":"10998899237437087915","flags":0,"ts_in_delta":1199,"sequence":140987,"symbol":"FCEU SI 20260615 PS"}
{"ts_recv":"2026-04-07T02:00:01.086486835Z","hd":{"ts_event":"2026-04-07T02:00:01.086458959Z","rtype":160,"publisher_id":101,"instrument_id":436},"action":"A","side":"B","price":"1.156660000","size":30,"channel_id":23,"order_id":"10998899237941246264","flags":0,"ts_in_delta":1199,"sequence":140987,"symbol":"FCEU SI 20260615 PS"}
{"ts_recv":"2026-04-07T02:00:01.086486835Z","hd":{"ts_event":"2026-04-07T02:00:01.086458959Z","rtype":160,"publisher_id":101,"instrument_id":436},"action":"C","side":"A","price":"1.156770000","size":30,"channel_id":23,"order_id":"1775527200582312107","flags":0,"ts_in_delta":1199,"sequence":140987,"symbol":"FCEU SI 20260615 PS"}
{"ts_recv":"2026-04-07T02:00:01.086486835Z","hd":{"ts_event":"2026-04-07T02:00:01.086458959Z","rtype":160,"publisher_id":101,"instrument_id":436},"action":"A","side":"A","price":"1.156760000","size":30,"channel_id":23,"order_id":"1775527201086470456","flags":128,"ts_in_delta":1199,"sequence":140987,"symbol":"FCEU SI 20260615 PS"}
{"ts_recv":"2026-04-07T02:00:02.028331161Z","hd":{"ts_event":"2026-04-07T02:00:02.028305005Z","rtype":160,"publisher_id":101,"instrument_id":436},"action":"C","side":"B","price":"1.156660000","size":30,"channel_id":23,"order_id":"10998899237941246264","flags":0,"ts_in_delta":1174,"sequence":140993,"symbol":"FCEU SI 20260615 PS"}
{"ts_recv":"2026-04-07T02:00:02.028331161Z","hd":{"ts_event":"2026-04-07T02:00:02.028305005Z","rtype":160,"publisher_id":101,"instrument_id":436},"action":"A","side":"B","price":"1.156640000","size":30,"channel_id":23,"order_id":"10998899238883087552","flags":0,"ts_in_delta":1174,"sequence":140993,"symbol":"FCEU SI 20260615 PS"}
{"ts_recv":"2026-04-07T02:00:02.028331161Z","hd":{"ts_event":"2026-04-07T02:00:02.028305005Z","rtype":160,"publisher_id":101,"instrument_id":436},"action":"C","side":"A","price":"1.156760000","size":30,"channel_id":23,"order_id":"1775527201086470456","flags":0,"ts_in_delta":1174,"sequence":140993,"symbol":"FCEU SI 20260615 PS"}
{"ts_recv":"2026-04-07T02:00:02.028331161Z","hd":{"ts_event":"2026-04-07T02:00:02.028305005Z","rtype":160,"publisher_id":101,"instrument_id":436},"action":"A","side":"A","price":"1.156740000","size":30,"channel_id":23,"order_id":"1775527202028311744","flags":128,"ts_in_delta":1174,"sequence":140993,"symbol":"FCEU SI 20260615 PS"}
{"ts_recv":"2026-04-07T02:00:03.359930829Z","hd":{"ts_event":"2026-04-07T02:00:03.359907639Z","rtype":160,"publisher_id":101,"instrument_id":436},"action":"C","side":"B","price":"1.156640000","size":30,"channel_id":23,"order_id":"10998899238883087552","flags":0,"ts_in_delta":882,"sequence":141006,"symbol":"FCEU SI 20260615 PS"}
{"ts_recv":"2026-04-07T02:00:03.359930829Z","hd":{"ts_event":"2026-04-07T02:00:03.359907639Z","rtype":160,"publisher_id":101,"instrument_id":436},"action":"A","side":"B","price":"1.156650000","size":30,"channel_id":23,"order_id":"10998899240214689884","flags":0,"ts_in_delta":882,"sequence":141006,"symbol":"FCEU SI 20260615 PS"}
{"ts_recv":"2026-04-07T02:00:03.359930829Z","hd":{"ts_event":"2026-04-07T02:00:03.359907639Z","rtype":160,"publisher_id":101,"instrument_id":436},"action":"C","side":"A","price":"1.156740000","size":30,"channel_id":23,"order_id":"1775527202028311744","flags":0,"ts_in_delta":882,"sequence":141006,"symbol":"FCEU SI 20260615 PS"}
{"ts_recv":"2026-04-07T02:00:03.359930829Z","hd":{"ts_event":"2026-04-07T02:00:03.359907639Z","rtype":160,"publisher_id":101,"instrument_id":436},"action":"A","side":"A","price":"1.156750000","size":30,"channel_id":23,"order_id":"1775527203359914076","flags":128,"ts_in_delta":882,"sequence":141006,"symbol":"FCEU SI 20260615 PS"}
{"ts_recv":"2026-04-07T02:00:03.365064597Z","hd":{"ts_event":"2026-04-07T02:00:03.365045399Z","rtype":160,"publisher_id":101,"instrument_id":436},"action":"C","side":"B","price":"1.156650000","size":30,"channel_id":23,"order_id":"10998899240214689884","flags":0,"ts_in_delta":673,"sequence":141012,"symbol":"FCEU SI 20260615 PS"}
{"ts_recv":"2026-04-07T02:00:03.365064597Z","hd":{"ts_event":"2026-04-07T02:00:03.365045399Z","rtype":160,"publisher_id":101,"instrument_id":436},"action":"A","side":"B","price":"1.156670000","size":30,"channel_id":23,"order_id":"10998899240219827040","flags":0,"ts_in_delta":673,"sequence":141012,"symbol":"FCEU SI 20260615 PS"}
{"ts_recv":"2026-04-07T02:00:03.365064597Z","hd":{"ts_event":"2026-04-07T02:00:03.365045399Z","rtype":160,"publisher_id":101,"instrument_id":436},"action":"C","side":"A","price":"1.156750000","size":30,"channel_id":23,"order_id":"1775527203359914076","flags":0,"ts_in_delta":673,"sequence":141012,"symbol":"FCEU SI 20260615 PS"}
{"ts_recv":"2026-04-07T02:00:03.365064597Z","hd":{"ts_event":"2026-04-07T02:00:03.365045399Z","rtype":160,"publisher_id":101,"instrument_id":436},"action":"A","side":"A","price":"1.156770000","size":30,"channel_id":23,"order_id":"1775527203365051232","flags":128,"ts_in_delta":673,"sequence":141012,"symbol":"FCEU SI 20260615 PS"}
{"ts_recv":"2026-04-07T02:00:03.728116751Z","hd":{"ts_event":"2026-04-07T02:00:03.728092349Z","rtype":160,"publisher_id":101,"instrument_id":436},"action":"C","side":"B","price":"1.156670000","size":30,"channel_id":23,"order_id":"10998899240219827040","flags":0,"ts_in_delta":1820,"sequence":141031,"symbol":"FCEU SI 20260615 PS"}
{"ts_recv":"2026-04-07T02:00:03.728116751Z","hd":{"ts_event":"2026-04-07T02:00:03.728092349Z","rtype":160,"publisher_id":101,"instrument_id":436},"action":"A","side":"B","price":"1.156680000","size":30,"channel_id":23,"order_id":"10998899240582876983","flags":0,"ts_in_delta":1820,"sequence":141031,"symbol":"FCEU SI 20260615 PS"}
{"ts_recv":"2026-04-07T02:00:03.728116751Z","hd":{"ts_event":"2026-04-07T02:00:03.728092349Z","rtype":160,"publisher_id":101,"instrument_id":436},"action":"C","side":"A","price":"1.156770000","size":30,"channel_id":23,"order_id":"1775527203365051232","flags":0,"ts_in_delta":1820,"sequence":141031,"symbol":"FCEU SI 20260615 PS"}
{"ts_recv":"2026-04-07T02:00:03.728116751Z","hd":{"ts_event":"2026-04-07T02:00:03.728092349Z","rtype":160,"publisher_id":101,"instrument_id":436},"action":"A","side":"A","price":"1.156780000","size":30,"channel_id":23,"order_id":"1775527203728101175","flags":128,"ts_in_delta":1820,"sequence":141031,"symbol":"FCEU SI 20260615 PS"}
{"ts_recv":"2026-04-07T02:00:04.977212027Z","hd":{"ts_event":"2026-04-07T02:00:04.977182927Z","rtype":160,"publisher_id":101,"instrument_id":436},"action":"C","side":"B","price":"1.156680000","size":30,"channel_id":23,"order_id":"10998899240582876983","flags":0,"ts_in_delta":1214,"sequence":141041,"symbol":"FCEU SI 20260615 PS"}
{"ts_recv":"2026-04-07T02:00:04.977212027Z","hd":{"ts_event":"2026-04-07T02:00:04.977182927Z","rtype":160,"publisher_id":101,"instrument_id":436},"action":"A","side":"B","price":"1.156660000","size":30,"channel_id":23,"order_id":"10998899241831967536","flags":0,"ts_in_delta":1214,"sequence":141041,"symbol":"FCEU SI 20260615 PS"}
{"ts_recv":"2026-04-07T02:00:04.977212027Z","hd":{"ts_event":"2026-04-07T02:00:04.977182927Z","rtype":160,"publisher_id":101,"instrument_id":436},"action":"C","side":"A","price":"1.156780000","size":30,"channel_id":23,"order_id":"1775527203728101175","flags":0,"ts_in_delta":1214,"sequence":141041,"symbol":"FCEU SI 20260615 PS"}
{"ts_recv":"2026-04-07T02:00:04.977212027Z","hd":{"ts_event":"2026-04-07T02:00:04.977182927Z","rtype":160,"publisher_id":101,"instrument_id":436},"action":"A","side":"A","price":"1.156760000","size":30,"channel_id":23,"order_id":"1775527204977191728","flags":128,"ts_in_delta":1214,"sequence":141041,"symbol":"FCEU SI 20260615 PS"}
{"ts_recv":"2026-04-07T02:00:05.063970680Z","hd":{"ts_event":"2026-04-07T02:00:05.063944833Z","rtype":160,"publisher_id":101,"instrument_id":436},"action":"C","side":"B","price":"1.156660000","size":30,"channel_id":23,"order_id":"10998899241831967536","flags":0,"ts_in_delta":932,"sequence":141051,"symbol":"FCEU SI 20260615 PS"}
{"ts_recv":"2026-04-07T02:00:05.063970680Z","hd":{"ts_event":"2026-04-07T02:00:05.063944833Z","rtype":160,"publisher_id":101,"instrument_id":436},"action":"A","side":"B","price":"1.156650000","size":30,"channel_id":23,"order_id":"10998899241918731586","flags":0,"ts_in_delta":932,"sequence":141051,"symbol":"FCEU SI 20260615 PS"}
{"ts_recv":"2026-04-07T02:00:05.063970680Z","hd":{"ts_event":"2026-04-07T02:00:05.063944833Z","rtype":160,"publisher_id":101,"instrument_id":436},"action":"C","side":"A","price":"1.156760000","size":30,"channel_id":23,"order_id":"1775527204977191728","flags":0,"ts_in_delta":932,"sequence":141051,"symbol":"FCEU SI 20260615 PS"}
{"ts_recv":"2026-04-07T02:00:05.063970680Z","hd":{"ts_event":"2026-04-07T02:00:05.063944833Z","rtype":160,"publisher_id":101,"instrument_id":436},"action":"A","side":"A","price":"1.156750000","size":30,"channel_id":23,"order_id":"1775527205063955778","flags":128,"ts_in_delta":932,"sequence":141051,"symbol":"FCEU SI 20260615 PS"}
{"ts_recv":"2026-04-07T02:00:05.719337420Z","hd":{"ts_event":"2026-04-07T02:00:05.719305061Z","rtype":160,"publisher_id":101,"instrument_id":436},"action":"C","side":"B","price":"1.156650000","size":30,"channel_id":23,"order_id":"10998899241918731586","flags":0,"ts_in_delta":1382,"sequence":141060,"symbol":"FCEU SI 20260615 PS"}
{"ts_recv":"2026-04-07T02:00:05.719337420Z","hd":{"ts_event":"2026-04-07T02:00:05.719305061Z","rtype":160,"publisher_id":101,"instrument_id":436},"action":"A","side":"B","price":"1.156640000","size":30,"channel_id":23,"order_id":"10998899242574093760","flags":0,"ts_in_delta":1382,"sequence":141060,"symbol":"FCEU SI 20260615 PS"}
{"ts_recv":"2026-04-07T02:00:05.719337420Z","hd":{"ts_event":"2026-04-07T02:00:05.719305061Z","rtype":160,"publisher_id":101,"instrument_id":436},"action":"C","side":"A","price":"1.156750000","size":30,"channel_id":23,"order_id":"1775527205063955778","flags":0,"ts_in_delta":1382,"sequence":141060,"symbol":"FCEU SI 20260615 PS"}
{"ts_recv":"2026-04-07T02:00:05.719337420Z","hd":{"ts_event":"2026-04-07T02:00:05.719305061Z","rtype":160,"publisher_id":101,"instrument_id":436},"action":"A","side":"A","price":"1.156740000","size":30,"channel_id":23,"order_id":"1775527205719317952","flags":128,"ts_in_delta":1382,"sequence":141060,"symbol":"FCEU SI 20260615 PS"}
{"ts_recv":"2026-04-07T02:00:09.692411934Z","hd":{"ts_event":"2026-04-07T02:00:09.692389571Z","rtype":160,"publisher_id":101,"instrument_id":436},"action":"C","side":"B","price":"1.156640000","size":30,"channel_id":23,"order_id":"10998899242574093760","flags":0,"ts_in_delta":911,"sequence":141077,"symbol":"FCEU SI 20260615 PS"}
{"ts_recv":"2026-04-07T02:00:09.692411934Z","hd":{"ts_event":"2026-04-07T02:00:09.692389571Z","rtype":160,"publisher_id":101,"instrument_id":436},"action":"A","side":"B","price":"1.156630000","size":30,"channel_id":23,"order_id":"10998899246547172995","flags":0,"ts_in_delta":911,"sequence":141077,"symbol":"FCEU SI 20260615 PS"}
{"ts_recv":"2026-04-07T02:00:09.692411934Z","hd":{"ts_event":"2026-04-07T02:00:09.692389571Z","rtype":160,"publisher_id":101,"instrument_id":436},"action":"C","side":"A","price":"1.156740000","size":30,"channel_id":23,"order_id":"1775527205719317952","flags":0,"ts_in_delta":911,"sequence":141077,"symbol":"FCEU SI 20260615 PS"}
{"ts_recv":"2026-04-07T02:00:09.692411934Z","hd":{"ts_event":"2026-04-07T02:00:09.692389571Z","rtype":160,"publisher_id":101,"instrument_id":436},"action":"A","side":"A","price":"1.156730000","size":30,"channel_id":23,"order_id":"1775527209692397187","flags":128,"ts_in_delta":911,"sequence":141077,"symbol":"FCEU SI 20260615 PS"}
{"ts_recv":"2026-04-07T02:00:09.702768777Z","hd":{"ts_event":"2026-04-07T02:00:09.702748187Z","rtype":160,"publisher_id":101,"instrument_id":436},"action":"C","side":"B","price":"1.156630000","size":30,"channel_id":23,"order_id":"10998899246547172995","flags":0,"ts_in_delta":911,"sequence":141079,"symbol":"FCEU SI 20260615 PS"}
{"ts_recv":"2026-04-07T02:00:09.702768777Z","hd":{"ts_event":"2026-04-07T02:00:09.702748187Z","rtype":160,"publisher_id":101,"instrument_id":436},"action":"A","side":"B","price":"1.156620000","size":30,"channel_id":23,"order_id":"10998899246557529906","flags":0,"ts_in_delta":911,"sequence":141079,"symbol":"FCEU SI 20260615 PS"}
{"ts_recv":"2026-04-07T02:00:09.702768777Z","hd":{"ts_event":"2026-04-07T02:00:09.702748187Z","rtype":160,"publisher_id":101,"instrument_id":436},"action":"C","side":"A","price":"1.156730000","size":30,"channel_id":23,"order_id":"1775527209692397187","flags":0,"ts_in_delta":911,"sequence":141079,"symbol":"FCEU SI 20260615 PS"}
{"ts_recv":"2026-04-07T02:00:09.702768777Z","hd":{"ts_event":"2026-04-07T02:00:09.702748187Z","rtype":160,"publisher_id":101,"instrument_id":436},"action":"A","side":"A","price":"1.156720000","size":30,"channel_id":23,"order_id":"1775527209702754098","flags":128,"ts_in_delta":911,"sequence":141079,"symbol":"FCEU SI 20260615 PS"}
{"ts_recv":"2026-04-07T02:00:10.214810598Z","hd":{"ts_event":"2026-04-07T02:00:10.214791591Z","rtype":160,"publisher_id":101,"instrument_id":436},"action":"C","side":"B","price":"1.156620000","size":30,"channel_id":23,"order_id":"10998899246557529906","flags":0,"ts_in_delta":1108,"sequence":141108,"symbol":"FCEU SI 20260615 PS"}
{"ts_recv":"2026-04-07T02:00:10.214810598Z","hd":{"ts_event":"2026-04-07T02:00:10.214791591Z","rtype":160,"publisher_id":101,"instrument_id":436},"action":"A","side":"B","price":"1.156610000","size":30,"channel_id":23,"order_id":"10998899247069573679","flags":0,"ts_in_delta":1108,"sequence":141108,"symbol":"FCEU SI 20260615 PS"}
{"ts_recv":"2026-04-07T02:00:10.214810598Z","hd":{"ts_event":"2026-04-07T02:00:10.214791591Z","rtype":160,"publisher_id":101,"instrument_id":436},"action":"C","side":"A","price":"1.156720000","size":30,"channel_id":23,"order_id":"1775527209702754098","flags":0,"ts_in_delta":1108,"sequence":141108,"symbol":"FCEU SI 20260615 PS"}
{"ts_recv":"2026-04-07T02:00:10.214810598Z","hd":{"ts_event":"2026-04-07T02:00:10.214791591Z","rtype":160,"publisher_id":101,"instrument_id":436},"action":"A","side":"A","price":"1.156710000","size":30,"channel_id":23,"order_id":"1775527210214797871","flags":128,"ts_in_delta":1108,"sequence":141108,"symbol":"FCEU SI 20260615 PS"}
{"ts_recv":"2026-04-07T02:00:10.224402156Z","hd":{"ts_event":"2026-04-07T02:00:10.224381691Z","rtype":160,"publisher_id":101,"instrument_id":436},"action":"C","side":"B","price":"1.156610000","size":30,"channel_id":23,"order_id":"10998899247069573679","flags":0,"ts_in_delta":890,"sequence":141112,"symbol":"FCEU SI 20260615 PS"}
{"ts_recv":"2026-04-07T02:00:10.224402156Z","hd":{"ts_event":"2026-04-07T02:00:10.224381691Z","rtype":160,"publisher_id":101,"instrument_id":436},"action":"A","side":"B","price":"1.156600000","size":30,"channel_id":23,"order_id":"10998899247079164042","flags":0,"ts_in_delta":890,"sequence":141112,"symbol":"FCEU SI 20260615 PS"}
{"ts_recv":"2026-04-07T02:00:10.224402156Z","hd":{"ts_event":"2026-04-07T02:00:10.224381691Z","rtype":160,"publisher_id":101,"instrument_id":436},"action":"C","side":"A","price":"1.156710000","size":30,"channel_id":23,"order_id":"1775527210214797871","flags":0,"ts_in_delta":890,"sequence":141112,"symbol":"FCEU SI 20260615 PS"}
{"ts_recv":"2026-04-07T02:00:10.224402156Z","hd":{"ts_event":"2026-04-07T02:00:10.224381691Z","rtype":160,"publisher_id":101,"instrument_id":436},"action":"A","side":"A","price":"1.156700000","size":30,"channel_id":23,"order_id":"1775527210224388234","flags":128,"ts_in_delta":890,"sequence":141112,"symbol":"FCEU SI 20260615 PS"}
{"ts_recv":"2026-04-07T02:00:11.209502373Z","hd":{"ts_event":"2026-04-07T02:00:11.209482779Z","rtype":160,"publisher_id":101,"instrument_id":436},"action":"C","side":"B","price":"1.156600000","size":30,"channel_id":23,"order_id":"10998899247079164042","flags":0,"ts_in_delta":915,"sequence":141122,"symbol":"FCEU SI 20260615 PS"}
{"ts_recv":"2026-04-07T02:00:11.209502373Z","hd":{"ts_event":"2026-04-07T02:00:11.209482779Z","rtype":160,"publisher_id":101,"instrument_id":436},"action":"A","side":"B","price":"1.156610000","size":30,"channel_id":23,"order_id":"10998899248064264894","flags":0,"ts_in_delta":915,"sequence":141122,"symbol":"FCEU SI 20260615 PS"}
{"ts_recv":"2026-04-07T02:00:11.209502373Z","hd":{"ts_event":"2026-04-07T02:00:11.209482779Z","rtype":160,"publisher_id":101,"instrument_id":436},"action":"C","side":"A","price":"1.156700000","size":30,"channel_id":23,"order_id":"1775527210224388234","flags":0,"ts_in_delta":915,"sequence":141122,"symbol":"FCEU SI 20260615 PS"}
{"ts_recv":"2026-04-07T02:00:11.209502373Z","hd":{"ts_event":"2026-04-07T02:00:11.209482779Z","rtype":160,"publisher_id":101,"instrument_id":436},"action":"A","side":"A","price":"1.156710000","size":30,"channel_id":23,"order_id":"1775527211209489086","flags":128,"ts_in_delta":915,"sequence":141122,"symbol":"FCEU SI 20260615 PS"}
{"ts_recv":"2026-04-07T02:00:11.215678507Z","hd":{"ts_event":"2026-04-07T02:00:11.215655543Z","rtype":160,"publisher_id":101,"instrument_id":436},"action":"C","side":"B","price":"1.156610000","size":30,"channel_id":23,"order_id":"10998899248064264894","flags":0,"ts_in_delta":884,"sequence":141127,"symbol":"FCEU SI 20260615 PS"}
{"ts_recv":"2026-04-07T02:00:11.215678507Z","hd":{"ts_event":"2026-04-07T02:00:11.215655543Z","rtype":160,"publisher_id":101,"instrument_id":436},"action":"A","side":"B","price":"1.156620000","size":30,"channel_id":23,"order_id":"10998899248070437273","flags":0,"ts_in_delta":884,"sequence":141127,"symbol":"FCEU SI 20260615 PS"}
{"ts_recv":"2026-04-07T02:00:11.215678507Z","hd":{"ts_event":"2026-04-07T02:00:11.215655543Z","rtype":160,"publisher_id":101,"instrument_id":436},"action":"C","side":"A","price":"1.156710000","size":30,"channel_id":23,"order_id":"1775527211209489086","flags":0,"ts_in_delta":884,"sequence":141127,"symbol":"FCEU SI 20260615 PS"}
{"ts_recv":"2026-04-07T02:00:11.215678507Z","hd":{"ts_event":"2026-04-07T02:00:11.215655543Z","rtype":160,"publisher_id":101,"instrument_id":436},"action":"A","side":"A","price":"1.156720000","size":30,"channel_id":23,"order_id":"1775527211215661465","flags":128,"ts_in_delta":884,"sequence":141127,"symbol":"FCEU SI 20260615 PS"}
{"ts_recv":"2026-04-07T02:00:15.427044525Z","hd":{"ts_event":"2026-04-07T02:00:15.427010861Z","rtype":160,"publisher_id":101,"instrument_id":436},"action":"C","side":"B","price":"1.156620000","size":30,"channel_id":23,"order_id":"10998899248070437273","flags":0,"ts_in_delta":1403,"sequence":141158,"symbol":"FCEU SI 20260615 PS"}
{"ts_recv":"2026-04-07T02:00:15.427044525Z","hd":{"ts_event":"2026-04-07T02:00:15.427010861Z","rtype":160,"publisher_id":101,"instrument_id":436},"action":"A","side":"B","price":"1.156610000","size":30,"channel_id":23,"order_id":"10998899252281800455","flags":0,"ts_in_delta":1403,"sequence":141158,"symbol":"FCEU SI 20260615 PS"}
{"ts_recv":"2026-04-07T02:00:15.427044525Z","hd":{"ts_event":"2026-04-07T02:00:15.427010861Z","rtype":160,"publisher_id":101,"instrument_id":436},"action":"C","side":"A","price":"1.156720000","size":30,"channel_id":23,"order_id":"1775527211215661465","flags":0,"ts_in_delta":1403,"sequence":141158,"symbol":"FCEU SI 20260615 PS"}
{"ts_recv":"2026-04-07T02:00:15.427044525Z","hd":{"ts_event":"2026-04-07T02:00:15.427010861Z","rtype":160,"publisher_id":101,"instrument_id":436},"action":"A","side":"A","price":"1.156710000","size":30,"channel_id":23,"order_id":"1775527215427024647","flags":128,"ts_in_delta":1403,"sequence":141158,"symbol":"FCEU SI 20260615 PS"}
{"ts_recv":"2026-04-07T02:00:16.769907249Z","hd":{"ts_event":"2026-04-07T02:00:16.769885683Z","rtype":160,"publisher_id":101,"instrument_id":436},"action":"C","side":"B","price":"1.156610000","size":30,"channel_id":23,"order_id":"10998899252281800455","flags":0,"ts_in_delta":1062,"sequence":141171,"symbol":"FCEU SI 20260615 PS"}
{"ts_recv":"2026-04-07T02:00:16.769907249Z","hd":{"ts_event":"2026-04-07T02:00:16.769885683Z","rtype":160,"publisher_id":101,"instrument_id":436},"action":"A","side":"B","price":"1.156600000","size":30,"channel_id":23,"order_id":"10998899253624667750","flags":0,"ts_in_delta":1062,"sequence":141171,"symbol":"FCEU SI 20260615 PS"}
{"ts_recv":"2026-04-07T02:00:16.769907249Z","hd":{"ts_event":"2026-04-07T02:00:16.769885683Z","rtype":160,"publisher_id":101,"instrument_id":436},"action":"C","side":"A","price":"1.156710000","size":30,"channel_id":23,"order_id":"1775527215427024647","flags":0,"ts_in_delta":1062,"sequence":141171,"symbol":"FCEU SI 20260615 PS"}
{"ts_recv":"2026-04-07T02:00:16.769907249Z","hd":{"ts_event":"2026-04-07T02:00:16.769885683Z","rtype":160,"publisher_id":101,"instrument_id":436},"action":"A","side":"A","price":"1.156700000","size":30,"channel_id":23,"order_id":"1775527216769891942","flags":128,"ts_in_delta":1062,"sequence":141171,"symbol":"FCEU SI 20260615 PS"}
{"ts_recv":"2026-04-07T02:00:18.337343954Z","hd":{"ts_event":"2026-04-07T02:00:18.337316611Z","rtype":160,"publisher_id":101,"instrument_id":436},"action":"C","side":"B","price":"1.156600000","size":30,"channel_id":23,"order_id":"10998899253624667750","flags":0,"ts_in_delta":1134,"sequence":141187,"symbol":"FCEU SI 20260615 PS"}
{"ts_recv":"2026-04-07T02:00:18.337343954Z","hd":{"ts_event":"2026-04-07T02:00:18.337316611Z","rtype":160,"publisher_id":101,"instrument_id":436},"action":"A","side":"B","price":"1.156610000","size":30,"channel_id":23,"order_id":"10998899255192104139","flags":0,"ts_in_delta":1134,"sequence":141187,"symbol":"FCEU SI 20260615 PS"}
{"ts_recv":"2026-04-07T02:00:18.337343954Z","hd":{"ts_event":"2026-04-07T02:00:18.337316611Z","rtype":160,"publisher_id":101,"instrument_id":436},"action":"C","side":"A","price":"1.156700000","size":30,"channel_id":23,"order_id":"1775527216769891942","flags":0,"ts_in_delta":1134,"sequence":141187,"symbol":"FCEU SI 20260615 PS"}
{"ts_recv":"2026-04-07T02:00:18.337343954Z","hd":{"ts_event":"2026-04-07T02:00:18.337316611Z","rtype":160,"publisher_id":101,"instrument_id":436},"action":"A","side":"A","price":"1.156710000","size":30,"channel_id":23,"order_id":"1775527218337328331","flags":128,"ts_in_delta":1134,"sequence":141187,"symbol":"FCEU SI 20260615 PS"}
{"ts_recv":"2026-04-07T02:00:19.143423216Z","hd":{"ts_event":"2026-04-07T02:00:19.143400111Z","rtype":160,"publisher_id":101,"instrument_id":436},"action":"C","side":"B","price":"1.156610000","size":30,"channel_id":23,"order_id":"10998899255192104139","flags":0,"ts_in_delta":918,"sequence":141201,"symbol":"FCEU SI 20260615 PS"}
{"ts_recv":"2026-04-07T02:00:19.143423216Z","hd":{"ts_event":"2026-04-07T02:00:19.143400111Z","rtype":160,"publisher_id":101,"instrument_id":436},"action":"A","side":"B","price":"1.156620000","size":30,"channel_id":23,"order_id":"10998899255998182628","flags":0,"ts_in_delta":918,"sequence":141201,"symbol":"FCEU SI 20260615 PS"}
{"ts_recv":"2026-04-07T02:00:19.143423216Z","hd":{"ts_event":"2026-04-07T02:00:19.143400111Z","rtype":160,"publisher_id":101,"instrument_id":436},"action":"C","side":"A","price":"1.156710000","size":30,"channel_id":23,"order_id":"1775527218337328331","flags":0,"ts_in_delta":918,"sequence":141201,"symbol":"FCEU SI 20260615 PS"}
{"ts_recv":"2026-04-07T02:00:19.143423216Z","hd":{"ts_event":"2026-04-07T02:00:19.143400111Z","rtype":160,"publisher_id":101,"instrument_id":436},"action":"A","side":"A","price":"1.156720000","size":30,"channel_id":23,"order_id":"1775527219143406820","flags":128,"ts_in_delta":918,"sequence":141201,"symbol":"FCEU SI 20260615 PS"}
{"ts_recv":"2026-04-07T02:00:19.285202349Z","hd":{"ts_event":"2026-04-07T02:00:19.285181187Z","rtype":160,"publisher_id":101,"instrument_id":436},"action":"C","side":"B","price":"1.156620000","size":30,"channel_id":23,"order_id":"10998899255998182628","flags":0,"ts_in_delta":1348,"sequence":141212,"symbol":"FCEU SI 20260615 PS"}
{"ts_recv":"2026-04-07T02:00:19.285202349Z","hd":{"ts_event":"2026-04-07T02:00:19.285181187Z","rtype":160,"publisher_id":101,"instrument_id":436},"action":"A","side":"B","price":"1.156610000","size":30,"channel_id":23,"order_id":"10998899256139963351","flags":0,"ts_in_delta":1348,"sequence":141212,"symbol":"FCEU SI 20260615 PS"}
{"ts_recv":"2026-04-07T02:00:19.285202349Z","hd":{"ts_event":"2026-04-07T02:00:19.285181187Z","rtype":160,"publisher_id":101,"instrument_id":436},"action":"C","side":"A","price":"1.156720000","size":30,"channel_id":23,"order_id":"1775527219143406820","flags":0,"ts_in_delta":1348,"sequence":141212,"symbol":"FCEU SI 20260615 PS"}
{"ts_recv":"2026-04-07T02:00:19.285202349Z","hd":{"ts_event":"2026-04-07T02:00:19.285181187Z","rtype":160,"publisher_id":101,"instrument_id":436},"action":"A","side":"A","price":"1.156710000","size":30,"channel_id":23,"order_id":"1775527219285187543","flags":128,"ts_in_delta":1348,"sequence":141212,"symbol":"FCEU SI 20260615 PS"}
{"ts_recv":"2026-04-07T02:00:19.289655055Z","hd":{"ts_event":"2026-04-07T02:00:19.289634705Z","rtype":160,"publisher_id":101,"instrument_id":436},"action":"C","side":"B","price":"1.156610000","size":30,"channel_id":23,"order_id":"10998899256139963351","flags":0,"ts_in_delta":917,"sequence":141213,"symbol":"FCEU SI 20260615 PS"}
{"ts_recv":"2026-04-07T02:00:19.289655055Z","hd":{"ts_event":"2026-04-07T02:00:19.289634705Z","rtype":160,"publisher_id":101,"instrument_id":436},"action":"A","side":"B","price":"1.156600000","size":30,"channel_id":23,"order_id":"10998899256144416581","flags":0,"ts_in_delta":917,"sequence":141213,"symbol":"FCEU SI 20260615 PS"}
{"ts_recv":"2026-04-07T02:00:19.289655055Z","hd":{"ts_event":"2026-04-07T02:00:19.289634705Z","rtype":160,"publisher_id":101,"instrument_id":436},"action":"C","side":"A","price":"1.156710000","size":30,"channel_id":23,"order_id":"1775527219285187543","flags":0,"ts_in_delta":917,"sequence":141213,"symbol":"FCEU SI 20260615 PS"}
{"ts_recv":"2026-04-07T02:00:19.289655055Z","hd":{"ts_event":"2026-04-07T02:00:19.289634705Z","rtype":160,"publisher_id":101,"instrument_id":436},"action":"A","side":"A","price":"1.156700000","size":30,"channel_id":23,"order_id":"1775527219289640773","flags":128,"ts_in_delta":917,"sequence":141213,"symbol":"FCEU SI 20260615 PS"}
{"ts_recv":"2026-04-07T02:00:19.315050429Z","hd":{"ts_event":"2026-04-07T02:00:19.315030907Z","rtype":160,"publisher_id":101,"instrument_id":436},"action":"C","side":"B","price":"1.156600000","size":30,"channel_id":23,"order_id":"10998899256144416581","flags":0,"ts_in_delta":871,"sequence":141215,"symbol":"FCEU SI 20260615 PS"}
{"ts_recv":"2026-04-07T02:00:19.315050429Z","hd":{"ts_event":"2026-04-07T02:00:19.315030907Z","rtype":160,"publisher_id":101,"instrument_id":436},"action":"A","side":"B","price":"1.156610000","size":30,"channel_id":23,"order_id":"10998899256169812633","flags":0,"ts_in_delta":871,"sequence":141215,"symbol":"FCEU SI 20260615 PS"}
{"ts_recv":"2026-04-07T02:00:19.315050429Z","hd":{"ts_event":"2026-04-07T02:00:19.315030907Z","rtype":160,"publisher_id":101,"instrument_id":436},"action":"C","side":"A","price":"1.156700000","size":30,"channel_id":23,"order_id":"1775527219289640773","flags":0,"ts_in_delta":871,"sequence":141215,"symbol":"FCEU SI 20260615 PS"}
{"ts_recv":"2026-04-07T02:00:19.315050429Z","hd":{"ts_event":"2026-04-07T02:00:19.315030907Z","rtype":160,"publisher_id":101,"instrument_id":436},"action":"A","side":"A","price":"1.156710000","size":30,"channel_id":23,"order_id":"1775527219315036825","flags":128,"ts_in_delta":871,"sequence":141215,"symbol":"FCEU SI 20260615 PS"}
{"ts_recv":"2026-04-07T02:00:20.786411798Z","hd":{"ts_event":"2026-04-07T02:00:20.786382985Z","rtype":160,"publisher_id":101,"instrument_id":436},"action":"C","side":"B","price":"1.156610000","size":30,"channel_id":23,"order_id":"10998899256169812633","flags":0,"ts_in_delta":1412,"sequence":141228,"symbol":"FCEU SI 20260615 PS"}
{"ts_recv":"2026-04-07T02:00:20.786411798Z","hd":{"ts_event":"2026-04-07T02:00:20.786382985Z","rtype":160,"publisher_id":101,"instrument_id":436},"action":"A","side":"B","price":"1.156600000","size":30,"channel_id":23,"order_id":"10998899257641171204","flags":0,"ts_in_delta":1412,"sequence":141228,"symbol":"FCEU SI 20260615 PS"}
{"ts_recv":"2026-04-07T02:00:20.786411798Z","hd":{"ts_event":"2026-04-07T02:00:20.786382985Z","rtype":160,"publisher_id":101,"instrument_id":436},"action":"C","side":"A","price":"1.156710000","size":30,"channel_id":23,"order_id":"1775527219315036825","flags":0,"ts_in_delta":1412,"sequence":141228,"symbol":"FCEU SI 20260615 PS"}
{"ts_recv":"2026-04-07T02:00:20.786411798Z","hd":{"ts_event":"2026-04-07T02:00:20.786382985Z","rtype":160,"publisher_id":101,"instrument_id":436},"action":"A","side":"A","price":"1.156700000","size":30,"channel_id":23,"order_id":"1775527220786395396","flags":128,"ts_in_delta":1412,"sequence":141228,"symbol":"FCEU SI 20260615 PS"}
{"ts_recv":"2026-04-07T02:00:21.563202134Z","hd":{"ts_event":"2026-04-07T02:00:21.563172951Z","rtype":160,"publisher_id":101,"instrument_id":436},"action":"C","side":"B","price":"1.156600000","size":30,"channel_id":23,"order_id":"10998899257641171204","flags":0,"ts_in_delta":1586,"sequence":141237,"symbol":"FCEU SI 20260615 PS"}
{"ts_recv":"2026-04-07T02:00:21.563202134Z","hd":{"ts_event":"2026-04-07T02:00:21.563172951Z","rtype":160,"publisher_id":101,"instrument_id":436},"action":"A","side":"B","price":"1.156610000","size":30,"channel_id":23,"order_id":"10998899258417959392","flags":0,"ts_in_delta":1586,"sequence":141237,"symbol":"FCEU SI 20260615 PS"}
{"ts_recv":"2026-04-07T02:00:21.563202134Z","hd":{"ts_event":"2026-04-07T02:00:21.563172951Z","rtype":160,"publisher_id":101,"instrument_id":436},"action":"C","side":"A","price":"1.156700000","size":30,"channel_id":23,"order_id":"1775527220786395396","flags":0,"ts_in_delta":1586,"sequence":141237,"symbol":"FCEU SI 20260615 PS"}
{"ts_recv":"2026-04-07T02:00:21.563202134Z","hd":{"ts_event":"2026-04-07T02:00:21.563172951Z","rtype":160,"publisher_id":101,"instrument_id":436},"action":"A","side":"A","price":"1.156710000","size":30,"channel_id":23,"order_id":"1775527221563183584","flags":128,"ts_in_delta":1586,"sequence":141237,"symbol":"FCEU SI 20260615 PS"}
{"ts_recv":"2026-04-07T02:00:24.175778410Z","hd":{"ts_event":"2026-04-07T02:00:24.175713447Z","rtype":160,"publisher_id":101,"instrument_id":436},"action":"A","side":"B","price":"1.156610000","size":30,"channel_id":23,"order_id":"10998899261030529586","flags":0,"ts_in_delta":1541,"sequence":141252,"symbol":"FCEU SI 20260615 PS"}
{"ts_recv":"2026-04-07T02:00:24.175778410Z","hd":{"ts_event":"2026-04-07T02:00:24.175713447Z","rtype":160,"publisher_id":101,"instrument_id":436},"action":"A","side":"A","price":"1.156710000","size":30,"channel_id":23,"order_id":"1775527224175753778","flags":128,"ts_in_delta":1541,"sequence":141252,"symbol":"FCEU SI 20260615 PS"}
{"ts_recv":"2026-04-07T02:00:33.142181373Z","hd":{"ts_event":"2026-04-07T02:00:33.142159981Z","rtype":160,"publisher_id":101,"instrument_id":436},"action":"C","side":"B","price":"1.156610000","size":30,"channel_id":23,"order_id":"10998899258417959392","flags":0,"ts_in_delta":962,"sequence":141333,"symbol":"FCEU SI 20260615 PS"}
{"ts_recv":"2026-04-07T02:00:33.142181373Z","hd":{"ts_event":"2026-04-07T02:00:33.142159981Z","rtype":160,"publisher_id":101,"instrument_id":436},"action":"A","side":"B","price":"1.156600000","size":30,"channel_id":23,"order_id":"10998899269996941509","flags":0,"ts_in_delta":962,"sequence":141333,"symbol":"FCEU SI 20260615 PS"}
{"ts_recv":"2026-04-07T02:00:33.142181373Z","hd":{"ts_event":"2026-04-07T02:00:33.142159981Z","rtype":160,"publisher_id":101,"instrument_id":436},"action":"C","side":"A","price":"1.156710000","size":30,"channel_id":23,"order_id":"1775527221563183584","flags":0,"ts_in_delta":962,"sequence":141333,"symbol":"FCEU SI 20260615 PS"}
{"ts_recv":"2026-04-07T02:00:33.142181373Z","hd":{"ts_event":"2026-04-07T02:00:33.142159981Z","rtype":160,"publisher_id":101,"instrument_id":436},"action":"A","side":"A","price":"1.156700000","size":30,"channel_id":23,"order_id":"1775527233142165701","flags":128,"ts_in_delta":962,"sequence":141333,"symbol":"FCEU SI 20260615 PS"}
{"ts_recv":"2026-04-07T02:00:33.151626188Z","hd":{"ts_event":"2026-04-07T02:00:33.151602035Z","rtype":160,"publisher_id":101,"instrument_id":436},"action":"C","side":"B","price":"1.156610000","size":30,"channel_id":23,"order_id":"10998899261030529586","flags":0,"ts_in_delta":970,"sequence":141337,"symbol":"FCEU SI 20260615 PS"}
{"ts_recv":"2026-04-07T02:00:33.151626188Z","hd":{"ts_event":"2026-04-07T02:00:33.151602035Z","rtype":160,"publisher_id":101,"instrument_id":436},"action":"A","side":"B","price":"1.156590000","size":30,"channel_id":23,"order_id":"10998899270006384532","flags":0,"ts_in_delta":970,"sequence":141337,"symbol":"FCEU SI 20260615 PS"}
{"ts_recv":"2026-04-07T02:00:33.151626188Z","hd":{"ts_event":"2026-04-07T02:00:33.151602035Z","rtype":160,"publisher_id":101,"instrument_id":436},"action":"C","side":"A","price":"1.156710000","size":30,"channel_id":23,"order_id":"1775527224175753778","flags":0,"ts_in_delta":970,"sequence":141337,"symbol":"FCEU SI 20260615 PS"}
{"ts_recv":"2026-04-07T02:00:33.151626188Z","hd":{"ts_event":"2026-04-07T02:00:33.151602035Z","rtype":160,"publisher_id":101,"instrument_id":436},"action":"A","side":"A","price":"1.156690000","size":30,"channel_id":23,"order_id":"1775527233151608724","flags":128,"ts_in_delta":970,"sequence":141337,"symbol":"FCEU SI 20260615 PS"}
{"ts_recv":"2026-04-07T02:00:33.151688062Z","hd":{"ts_event":"2026-04-07T02:00:33.151668161Z","rtype":160,"publisher_id":101,"instrument_id":436},"action":"C","side":"B","price":"1.156600000","size":30,"channel_id":23,"order_id":"10998899269996941509","flags":0,"ts_in_delta":1143,"sequence":141338,"symbol":"FCEU SI 20260615 PS"}
{"ts_recv":"2026-04-07T02:00:33.151688062Z","hd":{"ts_event":"2026-04-07T02:00:33.151668161Z","rtype":160,"publisher_id":101,"instrument_id":436},"action":"A","side":"B","price":"1.156590000","size":30,"channel_id":23,"order_id":"10998899270006451010","flags":0,"ts_in_delta":1143,"sequence":141338,"symbol":"FCEU SI 20260615 PS"}
{"ts_recv":"2026-04-07T02:00:33.151688062Z","hd":{"ts_event":"2026-04-07T02:00:33.151668161Z","rtype":160,"publisher_id":101,"instrument_id":436},"action":"C","side":"A","price":"1.156700000","size":30,"channel_id":23,"order_id":"1775527233142165701","flags":0,"ts_in_delta":1143,"sequence":141338,"symbol":"FCEU SI 20260615 PS"}
{"ts_recv":"2026-04-07T02:00:33.151688062Z","hd":{"ts_event":"2026-04-07T02:00:33.151668161Z","rtype":160,"publisher_id":101,"instrument_id":436},"action":"A","side":"A","price":"1.156690000","size":30,"channel_id":23,"order_id":"1775527233151675202","flags":128,"ts_in_delta":1143,"sequence":141338,"symbol":"FCEU SI 20260615 PS"}
{"ts_recv":"2026-04-07T02:00:35.431573841Z","hd":{"ts_event":"2026-04-07T02:00:35.431551511Z","rtype":160,"publisher_id":101,"instrument_id":436},"action":"C","side":"B","price":"1.156590000","size":30,"channel_id":23,"order_id":"10998899270006451010","flags":0,"ts_in_delta":899,"sequence":141377,"symbol":"FCEU SI 20260615 PS"}
{"ts_recv":"2026-04-07T02:00:35.431573841Z","hd":{"ts_event":"2026-04-07T02:00:35.431551511Z","rtype":160,"publisher_id":101,"instrument_id":436},"action":"A","side":"B","price":"1.156580000","size":30,"channel_id":23,"order_id":"10998899272286333898","flags":0,"ts_in_delta":899,"sequence":141377,"symbol":"FCEU SI 20260615 PS"}
{"ts_recv":"2026-04-07T02:00:35.431573841Z","hd":{"ts_event":"2026-04-07T02:00:35.431551511Z","rtype":160,"publisher_id":101,"instrument_id":436},"action":"C","side":"A","price":"1.156690000","size":30,"channel_id":23,"order_id":"1775527233151675202","flags":0,"ts_in_delta":899,"sequence":141377,"symbol":"FCEU SI 20260615 PS"}
{"ts_recv":"2026-04-07T02:00:35.431573841Z","hd":{"ts_event":"2026-04-07T02:00:35.431551511Z","rtype":160,"publisher_id":101,"instrument_id":436},"action":"A","side":"A","price":"1.156680000","size":30,"channel_id":23,"order_id":"1775527235431558090","flags":128,"ts_in_delta":899,"sequence":141377,"symbol":"FCEU SI 20260615 PS"}
{"ts_recv":"2026-04-07T02:00:35.447743509Z","hd":{"ts_event":"2026-04-07T02:00:35.447720475Z","rtype":160,"publisher_id":101,"instrument_id":436},"action":"C","side":"B","price":"1.156590000","size":30,"channel_id":23,"order_id":"10998899270006384532","flags":0,"ts_in_delta":1024,"sequence":141379,"symbol":"FCEU SI 20260615 PS"}
{"ts_recv":"2026-04-07T02:00:35.447743509Z","hd":{"ts_event":"2026-04-07T02:00:35.447720475Z","rtype":160,"publisher_id":101,"instrument_id":436},"action":"A","side":"B","price":"1.156570000","size":30,"channel_id":23,"order_id":"10998899272302502864","flags":0,"ts_in_delta":1024,"sequence":141379,"symbol":"FCEU SI 20260615 PS"}
{"ts_recv":"2026-04-07T02:00:35.447743509Z","hd":{"ts_event":"2026-04-07T02:00:35.447720475Z","rtype":160,"publisher_id":101,"instrument_id":436},"action":"C","side":"A","price":"1.156690000","size":30,"channel_id":23,"order_id":"1775527233151608724","flags":0,"ts_in_delta":1024,"sequence":141379,"symbol":"FCEU SI 20260615 PS"}
{"ts_recv":"2026-04-07T02:00:35.447743509Z","hd":{"ts_event":"2026-04-07T02:00:35.447720475Z","rtype":160,"publisher_id":101,"instrument_id":436},"action":"A","side":"A","price":"1.156670000","size":30,"channel_id":23,"order_id":"1775527235447727056","flags":128,"ts_in_delta":1024,"sequence":141379,"symbol":"FCEU SI 20260615 PS"}
{"ts_recv":"2026-04-07T02:00:35.447808940Z","hd":{"ts_event":"2026-04-07T02:00:35.447792405Z","rtype":160,"publisher_id":101,"instrument_id":436},"action":"C","side":"B","price":"1.156580000","size":30,"channel_id":23,"order_id":"10998899272286333898","flags":0,"ts_in_delta":943,"sequence":141380,"symbol":"FCEU SI 20260615 PS"}
{"ts_recv":"2026-04-07T02:00:35.447808940Z","hd":{"ts_event":"2026-04-07T02:00:35.447792405Z","rtype":160,"publisher_id":101,"instrument_id":436},"action":"A","side":"B","price":"1.156570000","size":30,"channel_id":23,"order_id":"10998899272302574137","flags":0,"ts_in_delta":943,"sequence":141380,"symbol":"FCEU SI 20260615 PS"}
{"ts_recv":"2026-04-07T02:00:35.447808940Z","hd":{"ts_event":"2026-04-07T02:00:35.447792405Z","rtype":160,"publisher_id":101,"instrument_id":436},"action":"C","side":"A","price":"1.156680000","size":30,"channel_id":23,"order_id":"1775527235431558090","flags":0,"ts_in_delta":943,"sequence":141380,"symbol":"FCEU SI 20260615 PS"}
{"ts_recv":"2026-04-07T02:00:35.447808940Z","hd":{"ts_event":"2026-04-07T02:00:35.447792405Z","rtype":160,"publisher_id":101,"instrument_id":436},"action":"A","side":"A","price":"1.156670000","size":30,"channel_id":23,"order_id":"1775527235447798329","flags":128,"ts_in_delta":943,"sequence":141380,"symbol":"FCEU SI 20260615 PS"}
{"ts_recv":"2026-04-07T02:00:55.345544784Z","hd":{"ts_event":"2026-04-07T02:00:55.345520089Z","rtype":160,"publisher_id":101,"instrument_id":436},"action":"C","side":"B","price":"1.156570000","size":30,"channel_id":23,"order_id":"10998899272302574137","flags":0,"ts_in_delta":879,"sequence":141537,"symbol":"FCEU SI 20260615 PS"}
{"ts_recv":"2026-04-07T02:00:55.345544784Z","hd":{"ts_event":"2026-04-07T02:00:55.345520089Z","rtype":160,"publisher_id":101,"instrument_id":436},"action":"A","side":"B","price":"1.156580000","size":30,"channel_id":23,"order_id":"10998899292200302068","flags":0,"ts_in_delta":879,"sequence":141537,"symbol":"FCEU SI 20260615 PS"}
{"ts_recv":"2026-04-07T02:00:55.345544784Z","hd":{"ts_event":"2026-04-07T02:00:55.345520089Z","rtype":160,"publisher_id":101,"instrument_id":436},"action":"C","side":"A","price":"1.156670000","size":30,"channel_id":23,"order_id":"1775527235447798329","flags":0,"ts_in_delta":879,"sequence":141537,"symbol":"FCEU SI 20260615 PS"}
{"ts_recv":"2026-04-07T02:00:55.345544784Z","hd":{"ts_event":"2026-04-07T02:00:55.345520089Z","rtype":160,"publisher_id":101,"instrument_id":436},"action":"A","side":"A","price":"1.156680000","size":30,"channel_id":23,"order_id":"1775527255345526260","flags":128,"ts_in_delta":879,"sequence":141537,"symbol":"FCEU SI 20260615 PS"}
{"ts_recv":"2026-04-07T02:00:55.978570090Z","hd":{"ts_event":"2026-04-07T02:00:55.978547343Z","rtype":160,"publisher_id":101,"instrument_id":436},"action":"C","side":"B","price":"1.156570000","size":30,"channel_id":23,"order_id":"10998899272302502864","flags":0,"ts_in_delta":1166,"sequence":141568,"symbol":"FCEU SI 20260615 PS"}
{"ts_recv":"2026-04-07T02:00:55.978570090Z","hd":{"ts_event":"2026-04-07T02:00:55.978547343Z","rtype":160,"publisher_id":101,"instrument_id":436},"action":"A","side":"B","price":"1.156590000","size":30,"channel_id":23,"order_id":"10998899292833329382","flags":0,"ts_in_delta":1166,"sequence":141568,"symbol":"FCEU SI 20260615 PS"}
{"ts_recv":"2026-04-07T02:00:55.978570090Z","hd":{"ts_event":"2026-04-07T02:00:55.978547343Z","rtype":160,"publisher_id":101,"instrument_id":436},"action":"C","side":"A","price":"1.156670000","size":30,"channel_id":23,"order_id":"1775527235447727056","flags":0,"ts_in_delta":1166,"sequence":141568,"symbol":"FCEU SI 20260615 PS"}
{"ts_recv":"2026-04-07T02:00:55.978570090Z","hd":{"ts_event":"2026-04-07T02:00:55.978547343Z","rtype":160,"publisher_id":101,"instrument_id":436},"action":"A","side":"A","price":"1.156690000","size":30,"channel_id":23,"order_id":"1775527255978553574","flags":128,"ts_in_delta":1166,"sequence":141568,"symbol":"FCEU SI 20260615 PS"}
{"ts_recv":"2026-04-07T02:00:55.978636327Z","hd":{"ts_event":"2026-04-07T02:00:55.978616655Z","rtype":160,"publisher_id":101,"instrument_id":436},"action":"C","side":"B","price":"1.156580000","size":30,"channel_id":23,"order_id":"10998899292200302068","flags":0,"ts_in_delta":928,"sequence":141569,"symbol":"FCEU SI 20260615 PS"}
{"ts_recv":"2026-04-07T02:00:55.978636327Z","hd":{"ts_event":"2026-04-07T02:00:55.978616655Z","rtype":160,"publisher_id":101,"instrument_id":436},"action":"A","side":"B","price":"1.156590000","size":30,"channel_id":23,"order_id":"10998899292833398552","flags":0,"ts_in_delta":928,"sequence":141569,"symbol":"FCEU SI 20260615 PS"}
{"ts_recv":"2026-04-07T02:00:55.978636327Z","hd":{"ts_event":"2026-04-07T02:00:55.978616655Z","rtype":160,"publisher_id":101,"instrument_id":436},"action":"C","side":"A","price":"1.156680000","size":30,"channel_id":23,"order_id":"1775527255345526260","flags":0,"ts_in_delta":928,"sequence":141569,"symbol":"FCEU SI 20260615 PS"}
{"ts_recv":"2026-04-07T02:00:55.978636327Z","hd":{"ts_event":"2026-04-07T02:00:55.978616655Z","rtype":160,"publisher_id":101,"instrument_id":436},"action":"A","side":"A","price":"1.156690000","size":30,"channel_id":23,"order_id":"1775527255978622744","flags":128,"ts_in_delta":928,"sequence":141569,"symbol":"FCEU SI 20260615 PS"}
{"ts_recv":"2026-04-07T02:00:56.542978500Z","hd":{"ts_event":"2026-04-07T02:00:56.542956329Z","rtype":160,"publisher_id":101,"instrument_id":436},"action":"C","side":"B","price":"1.156590000","size":30,"channel_id":23,"order_id":"10998899292833398552","flags":0,"ts_in_delta":1061,"sequence":141591,"symbol":"FCEU SI 20260615 PS"}
{"ts_recv":"2026-04-07T02:00:56.542978500Z","hd":{"ts_event":"2026-04-07T02:00:56.542956329Z","rtype":160,"publisher_id":101,"instrument_id":436},"action":"A","side":"B","price":"1.156600000","size":30,"channel_id":23,"order_id":"10998899293397738323","flags":0,"ts_in_delta":1061,"sequence":141591,"symbol":"FCEU SI 20260615 PS"}
{"ts_recv":"2026-04-07T02:00:56.542978500Z","hd":{"ts_event":"2026-04-07T02:00:56.542956329Z","rtype":160,"publisher_id":101,"instrument_id":436},"action":"C","side":"A","price":"1.156690000","size":30,"channel_id":23,"order_id":"1775527255978622744","flags":0,"ts_in_delta":1061,"sequence":141591,"symbol":"FCEU SI 20260615 PS"}
{"ts_recv":"2026-04-07T02:00:56.542978500Z","hd":{"ts_event":"2026-04-07T02:00:56.542956329Z","rtype":160,"publisher_id":101,"instrument_id":436},"action":"A","side":"A","price":"1.156700000","size":30,"channel_id":23,"order_id":"1775527256542962515","flags":128,"ts_in_delta":1061,"sequence":141591,"symbol":"FCEU SI 20260615 PS"}
{"ts_recv":"2026-04-07T02:00:56.552602113Z","hd":{"ts_event":"2026-04-07T02:00:56.552581469Z","rtype":160,"publisher_id":101,"instrument_id":436},"action":"C","side":"B","price":"1.156590000","size":30,"channel_id":23,"order_id":"10998899292833329382","flags":0,"ts_in_delta":915,"sequence":141595,"symbol":"FCEU SI 20260615 PS"}
{"ts_recv":"2026-04-07T02:00:56.552602113Z","hd":{"ts_event":"2026-04-07T02:00:56.552581469Z","rtype":160,"publisher_id":101,"instrument_id":436},"action":"A","side":"B","price":"1.156610000","size":30,"channel_id":23,"order_id":"10998899293407363179","flags":0,"ts_in_delta":915,"sequence":141595,"symbol":"FCEU SI 20260615 PS"}
{"ts_recv":"2026-04-07T02:00:56.552602113Z","hd":{"ts_event":"2026-04-07T02:00:56.552581469Z","rtype":160,"publisher_id":101,"instrument_id":436},"action":"C","side":"A","price":"1.156690000","size":30,"channel_id":23,"order_id":"1775527255978553574","flags":0,"ts_in_delta":915,"sequence":141595,"symbol":"FCEU SI 20260615 PS"}
{"ts_recv":"2026-04-07T02:00:56.552602113Z","hd":{"ts_event":"2026-04-07T02:00:56.552581469Z","rtype":160,"publisher_id":101,"instrument_id":436},"action":"A","side":"A","price":"1.156710000","size":30,"channel_id":23,"order_id":"1775527256552587371","flags":128,"ts_in_delta":915,"sequence":141595,"symbol":"FCEU SI 20260615 PS"}
{"ts_recv":"2026-04-07T02:00:56.552663750Z","hd":{"ts_event":"2026-04-07T02:00:56.552645241Z","rtype":160,"publisher_id":101,"instrument_id":436},"action":"C","side":"B","price":"1.156600000","size":30,"channel_id":23,"order_id":"10998899293397738323","flags":0,"ts_in_delta":929,"sequence":141596,"symbol":"FCEU SI 20260615 PS"}
{"ts_recv":"2026-04-07T02:00:56.552663750Z","hd":{"ts_event":"2026-04-07T02:00:56.552645241Z","rtype":160,"publisher_id":101,"instrument_id":436},"action":"A","side":"B","price":"1.156610000","size":30,"channel_id":23,"order_id":"10998899293407426857","flags":0,"ts_in_delta":929,"sequence":141596,"symbol":"FCEU SI 20260615 PS"}
{"ts_recv":"2026-04-07T02:00:56.552663750Z","hd":{"ts_event":"2026-04-07T02:00:56.552645241Z","rtype":160,"publisher_id":101,"instrument_id":436},"action":"C","side":"A","price":"1.156700000","size":30,"channel_id":23,"order_id":"1775527256542962515","flags":0,"ts_in_delta":929,"sequence":141596,"symbol":"FCEU SI 20260615 PS"}
{"ts_recv":"2026-04-07T02:00:56.552663750Z","hd":{"ts_event":"2026-04-07T02:00:56.552645241Z","rtype":160,"publisher_id":101,"instrument_id":436},"action":"A","side":"A","price":"1.156710000","size":30,"channel_id":23,"order_id":"1775527256552651049","flags":128,"ts_in_delta":929,"sequence":141596,"symbol":"FCEU SI 20260615 PS"}
{"ts_recv":"2026-04-07T02:01:04.240659859Z","hd":{"ts_event":"2026-04-07T02:01:04.240638485Z","rtype":160,"publisher_id":101,"instrument_id":436},"action":"C","side":"B","price":"1.156610000","size":30,"channel_id":23,"order_id":"10998899293407426857","flags":0,"ts_in_delta":942,"sequence":141735,"symbol":"FCEU SI 20260615 PS"}
{"ts_recv":"2026-04-07T02:01:04.240659859Z","hd":{"ts_event":"2026-04-07T02:01:04.240638485Z","rtype":160,"publisher_id":101,"instrument_id":436},"action":"A","side":"B","price":"1.156600000","size":30,"channel_id":23,"order_id":"10998899301095420134","flags":0,"ts_in_delta":942,"sequence":141735,"symbol":"FCEU SI 20260615 PS"}
{"ts_recv":"2026-04-07T02:01:04.240659859Z","hd":{"ts_event":"2026-04-07T02:01:04.240638485Z","rtype":160,"publisher_id":101,"instrument_id":436},"action":"C","side":"A","price":"1.156710000","size":30,"channel_id":23,"order_id":"1775527256552651049","flags":0,"ts_in_delta":942,"sequence":141735,"symbol":"FCEU SI 20260615 PS"}
{"ts_recv":"2026-04-07T02:01:04.240659859Z","hd":{"ts_event":"2026-04-07T02:01:04.240638485Z","rtype":160,"publisher_id":101,"instrument_id":436},"action":"A","side":"A","price":"1.156700000","size":30,"channel_id":23,"order_id":"1775527264240644326","flags":128,"ts_in_delta":942,"sequence":141735,"symbol":"FCEU SI 20260615 PS"}
{"ts_recv":"2026-04-07T02:01:04.240714669Z","hd":{"ts_event":"2026-04-07T02:01:04.240695637Z","rtype":160,"publisher_id":101,"instrument_id":436},"action":"C","side":"B","price":"1.156610000","size":30,"channel_id":23,"order_id":"10998899293407363179","flags":0,"ts_in_delta":952,"sequence":141736,"symbol":"FCEU SI 20260615 PS"}
{"ts_recv":"2026-04-07T02:01:04.240714669Z","hd":{"ts_event":"2026-04-07T02:01:04.240695637Z","rtype":160,"publisher_id":101,"instrument_id":436},"action":"A","side":"B","price":"1.156590000","size":30,"channel_id":23,"order_id":"10998899301095477635","flags":0,"ts_in_delta":952,"sequence":141736,"symbol":"FCEU SI 20260615 PS"}
{"ts_recv":"2026-04-07T02:01:04.240714669Z","hd":{"ts_event":"2026-04-07T02:01:04.240695637Z","rtype":160,"publisher_id":101,"instrument_id":436},"action":"C","side":"A","price":"1.156710000","size":30,"channel_id":23,"order_id":"1775527256552587371","flags":0,"ts_in_delta":952,"sequence":141736,"symbol":"FCEU SI 20260615 PS"}
{"ts_recv":"2026-04-07T02:01:04.240714669Z","hd":{"ts_event":"2026-04-07T02:01:04.240695637Z","rtype":160,"publisher_id":101,"instrument_id":436},"action":"A","side":"A","price":"1.156690000","size":30,"channel_id":23,"order_id":"1775527264240701827","flags":128,"ts_in_delta":952,"sequence":141736,"symbol":"FCEU SI 20260615 PS"}
{"ts_recv":"2026-04-07T02:01:04.240766391Z","hd":{"ts_event":"2026-04-07T02:01:04.240750761Z","rtype":160,"publisher_id":101,"instrument_id":436},"action":"C","side":"B","price":"1.156600000","size":30,"channel_id":23,"order_id":"10998899301095420134","flags":0,"ts_in_delta":943,"sequence":141737,"symbol":"FCEU SI 20260615 PS"}
{"ts_recv":"2026-04-07T02:01:04.240766391Z","hd":{"ts_event":"2026-04-07T02:01:04.240750761Z","rtype":160,"publisher_id":101,"instrument_id":436},"action":"A","side":"B","price":"1.156590000","size":30,"channel_id":23,"order_id":"10998899301095532512","flags":0,"ts_in_delta":943,"sequence":141737,"symbol":"FCEU SI 20260615 PS"}
{"ts_recv":"2026-04-07T02:01:04.240766391Z","hd":{"ts_event":"2026-04-07T02:01:04.240750761Z","rtype":160,"publisher_id":101,"instrument_id":436},"action":"C","side":"A","price":"1.156700000","size":30,"channel_id":23,"order_id":"1775527264240644326","flags":0,"ts_in_delta":943,"sequence":141737,"symbol":"FCEU SI 20260615 PS"}
{"ts_recv":"2026-04-07T02:01:04.240766391Z","hd":{"ts_event":"2026-04-07T02:01:04.240750761Z","rtype":160,"publisher_id":101,"instrument_id":436},"action":"A","side":"A","price":"1.156690000","size":30,"channel_id":23,"order_id":"1775527264240756704","flags":128,"ts_in_delta":943,"sequence":141737,"symbol":"FCEU SI 20260615 PS"}
{"ts_recv":"2026-04-07T02:01:14.301622544Z","hd":{"ts_event":"2026-04-07T02:01:14.301600927Z","rtype":160,"publisher_id":101,"instrument_id":436},"action":"C","side":"B","price":"1.156590000","size":30,"channel_id":23,"order_id":"10998899301095532512","flags":0,"ts_in_delta":906,"sequence":141865,"symbol":"FCEU SI 20260615 PS"}
{"ts_recv":"2026-04-07T02:01:14.301622544Z","hd":{"ts_event":"2026-04-07T02:01:14.301600927Z","rtype":160,"publisher_id":101,"instrument_id":436},"action":"A","side":"B","price":"1.156600000","size":30,"channel_id":23,"order_id":"10998899311156382959","flags":0,"ts_in_delta":906,"sequence":141865,"symbol":"FCEU SI 20260615 PS"}
{"ts_recv":"2026-04-07T02:01:14.301622544Z","hd":{"ts_event":"2026-04-07T02:01:14.301600927Z","rtype":160,"publisher_id":101,"instrument_id":436},"action":"C","side":"A","price":"1.156690000","size":30,"channel_id":23,"order_id":"1775527264240756704","flags":0,"ts_in_delta":906,"sequence":141865,"symbol":"FCEU SI 20260615 PS"}
{"ts_recv":"2026-04-07T02:01:14.301622544Z","hd":{"ts_event":"2026-04-07T02:01:14.301600927Z","rtype":160,"publisher_id":101,"instrument_id":436},"action":"A","side":"A","price":"1.156700000","size":30,"channel_id":23,"order_id":"1775527274301607151","flags":128,"ts_in_delta":906,"sequence":141865,"symbol":"FCEU SI 20260615 PS"}
{"ts_recv":"2026-04-07T02:01:14.337033616Z","hd":{"ts_event":"2026-04-07T02:01:14.337014795Z","rtype":160,"publisher_id":101,"instrument_id":436},"action":"C","side":"B","price":"1.156590000","size":30,"channel_id":23,"order_id":"10998899301095477635","flags":0,"ts_in_delta":1084,"sequence":141868,"symbol":"FCEU SI 20260615 PS"}
{"ts_recv":"2026-04-07T02:01:14.337033616Z","hd":{"ts_event":"2026-04-07T02:01:14.337014795Z","rtype":160,"publisher_id":101,"instrument_id":436},"action":"A","side":"B","price":"1.156610000","size":30,"channel_id":23,"order_id":"10998899311191796599","flags":0,"ts_in_delta":1084,"sequence":141868,"symbol":"FCEU SI 20260615 PS"}
{"ts_recv":"2026-04-07T02:01:14.337033616Z","hd":{"ts_event":"2026-04-07T02:01:14.337014795Z","rtype":160,"publisher_id":101,"instrument_id":436},"action":"C","side":"A","price":"1.156690000","size":30,"channel_id":23,"order_id":"1775527264240701827","flags":0,"ts_in_delta":1084,"sequence":141868,"symbol":"FCEU SI 20260615 PS"}
{"ts_recv":"2026-04-07T02:01:14.337033616Z","hd":{"ts_event":"2026-04-07T02:01:14.337014795Z","rtype":160,"publisher_id":101,"instrument_id":436},"action":"A","side":"A","price":"1.156710000","size":30,"channel_id":23,"order_id":"1775527274337020791","flags":128,"ts_in_delta":1084,"sequence":141868,"symbol":"FCEU SI 20260615 PS"}
{"ts_recv":"2026-04-07T02:01:14.337101143Z","hd":{"ts_event":"2026-04-07T02:01:14.337081169Z","rtype":160,"publisher_id":101,"instrument_id":436},"action":"C","side":"B","price":"1.156600000","size":30,"channel_id":23,"order_id":"10998899311156382959","flags":0,"ts_in_delta":927,"sequence":141869,"symbol":"FCEU SI 20260615 PS"}
{"ts_recv":"2026-04-07T02:01:14.337101143Z","hd":{"ts_event":"2026-04-07T02:01:14.337081169Z","rtype":160,"publisher_id":101,"instrument_id":436},"action":"A","side":"B","price":"1.156610000","size":30,"channel_id":23,"order_id":"10998899311191863071","flags":0,"ts_in_delta":927,"sequence":141869,"symbol":"FCEU SI 20260615 PS"}
{"ts_recv":"2026-04-07T02:01:14.337101143Z","hd":{"ts_event":"2026-04-07T02:01:14.337081169Z","rtype":160,"publisher_id":101,"instrument_id":436},"action":"C","side":"A","price":"1.156700000","size":30,"channel_id":23,"order_id":"1775527274301607151","flags":0,"ts_in_delta":927,"sequence":141869,"symbol":"FCEU SI 20260615 PS"}
{"ts_recv":"2026-04-07T02:01:14.337101143Z","hd":{"ts_event":"2026-04-07T02:01:14.337081169Z","rtype":160,"publisher_id":101,"instrument_id":436},"action":"A","side":"A","price":"1.156710000","size":30,"channel_id":23,"order_id":"1775527274337087263","flags":128,"ts_in_delta":927,"sequence":141869,"symbol":"FCEU SI 20260615 PS"}
{"ts_recv":"2026-04-07T02:01:21.094250789Z","hd":{"ts_event":"2026-04-07T02:01:21.094217365Z","rtype":160,"publisher_id":101,"instrument_id":436},"action":"C","side":"B","price":"1.156610000","size":30,"channel_id":23,"order_id":"10998899311191863071","flags":0,"ts_in_delta":1688,"sequence":141943,"symbol":"FCEU SI 20260615 PS"}
{"ts_recv":"2026-04-07T02:01:21.094250789Z","hd":{"ts_event":"2026-04-07T02:01:21.094217365Z","rtype":160,"publisher_id":101,"instrument_id":436},"action":"A","side":"B","price":"1.156600000","size":30,"channel_id":23,"order_id":"10998899317949007027","flags":0,"ts_in_delta":1688,"sequence":141943,"symbol":"FCEU SI 20260615 PS"}
{"ts_recv":"2026-04-07T02:01:21.094250789Z","hd":{"ts_event":"2026-04-07T02:01:21.094217365Z","rtype":160,"publisher_id":101,"instrument_id":436},"action":"C","side":"A","price":"1.156710000","size":30,"channel_id":23,"order_id":"1775527274337087263","flags":0,"ts_in_delta":1688,"sequence":141943,"symbol":"FCEU SI 20260615 PS"}
{"ts_recv":"2026-04-07T02:01:21.094250789Z","hd":{"ts_event":"2026-04-07T02:01:21.094217365Z","rtype":160,"publisher_id":101,"instrument_id":436},"action":"A","side":"A","price":"1.156700000","size":30,"channel_id":23,"order_id":"1775527281094231219","flags":128,"ts_in_delta":1688,"sequence":141943,"symbol":"FCEU SI 20260615 PS"}
{"ts_recv":"2026-04-07T02:01:21.094344242Z","hd":{"ts_event":"2026-04-07T02:01:21.094326403Z","rtype":160,"publisher_id":101,"instrument_id":436},"action":"C","side":"B","price":"1.156600000","size":30,"channel_id":23,"order_id":"10998899317949007027","flags":0,"ts_in_delta":1024,"sequence":141944,"symbol":"FCEU SI 20260615 PS"}
{"ts_recv":"2026-04-07T02:01:21.094344242Z","hd":{"ts_event":"2026-04-07T02:01:21.094326403Z","rtype":160,"publisher_id":101,"instrument_id":436},"action":"A","side":"B","price":"1.156590000","size":30,"channel_id":23,"order_id":"10998899317949108382","flags":0,"ts_in_delta":1024,"sequence":141944,"symbol":"FCEU SI 20260615 PS"}
{"ts_recv":"2026-04-07T02:01:21.094344242Z","hd":{"ts_event":"2026-04-07T02:01:21.094326403Z","rtype":160,"publisher_id":101,"instrument_id":436},"action":"C","side":"A","price":"1.156700000","size":30,"channel_id":23,"order_id":"1775527281094231219","flags":0,"ts_in_delta":1024,"sequence":141944,"symbol":"FCEU SI 20260615 PS"}
{"ts_recv":"2026-04-07T02:01:21.094344242Z","hd":{"ts_event":"2026-04-07T02:01:21.094326403Z","rtype":160,"publisher_id":101,"instrument_id":436},"action":"A","side":"A","price":"1.156690000","size":30,"channel_id":23,"order_id":"1775527281094332574","flags":128,"ts_in_delta":1024,"sequence":141944,"symbol":"FCEU SI 20260615 PS"}
{"ts_recv":"2026-04-07T02:01:21.094404950Z","hd":{"ts_event":"2026-04-07T02:01:21.094384963Z","rtype":160,"publisher_id":101,"instrument_id":436},"action":"C","side":"B","price":"1.156610000","size":30,"channel_id":23,"order_id":"10998899311191796599","flags":0,"ts_in_delta":983,"sequence":141945,"symbol":"FCEU SI 20260615 PS"}
{"ts_recv":"2026-04-07T02:01:21.094404950Z","hd":{"ts_event":"2026-04-07T02:01:21.094384963Z","rtype":160,"publisher_id":101,"instrument_id":436},"action":"A","side":"B","price":"1.156590000","size":30,"channel_id":23,"order_id":"10998899317949166913","flags":0,"ts_in_delta":983,"sequence":141945,"symbol":"FCEU SI 20260615 PS"}
{"ts_recv":"2026-04-07T02:01:21.094404950Z","hd":{"ts_event":"2026-04-07T02:01:21.094384963Z","rtype":160,"publisher_id":101,"instrument_id":436},"action":"C","side":"A","price":"1.156710000","size":30,"channel_id":23,"order_id":"1775527274337020791","flags":0,"ts_in_delta":983,"sequence":141945,"symbol":"FCEU SI 20260615 PS"}
{"ts_recv":"2026-04-07T02:01:21.094404950Z","hd":{"ts_event":"2026-04-07T02:01:21.094384963Z","rtype":160,"publisher_id":101,"instrument_id":436},"action":"A","side":"A","price":"1.156690000","size":30,"channel_id":23,"order_id":"1775527281094391105","flags":128,"ts_in_delta":983,"sequence":141945,"symbol":"FCEU SI 20260615 PS"}
{"ts_recv":"2026-04-07T02:01:21.094414764Z","hd":{"ts_event":"2026-04-07T02:01:21.094396291Z","rtype":160,"publisher_id":101,"instrument_id":436},"action":"C","side":"B","price":"1.156590000","size":30,"channel_id":23,"order_id":"10998899317949108382","flags":0,"ts_in_delta":929,"sequence":141946,"symbol":"FCEU SI 20260615 PS"}
{"ts_recv":"2026-04-07T02:01:21.094414764Z","hd":{"ts_event":"2026-04-07T02:01:21.094396291Z","rtype":160,"publisher_id":101,"instrument_id":436},"action":"A","side":"B","price":"1.156600000","size":30,"channel_id":23,"order_id":"10998899317949177968","flags":0,"ts_in_delta":929,"sequence":141946,"symbol":"FCEU SI 20260615 PS"}
{"ts_recv":"2026-04-07T02:01:21.094414764Z","hd":{"ts_event":"2026-04-07T02:01:21.094396291Z","rtype":160,"publisher_id":101,"instrument_id":436},"action":"C","side":"A","price":"1.156690000","size":30,"channel_id":23,"order_id":"1775527281094332574","flags":0,"ts_in_delta":929,"sequence":141946,"symbol":"FCEU SI 20260615 PS"}
{"ts_recv":"2026-04-07T02:01:21.094414764Z","hd":{"ts_event":"2026-04-07T02:01:21.094396291Z","rtype":160,"publisher_id":101,"instrument_id":436},"action":"A","side":"A","price":"1.156700000","size":30,"channel_id":23,"order_id":"1775527281094402160","flags":128,"ts_in_delta":929,"sequence":141946,"symbol":"FCEU SI 20260615 PS"}
{"ts_recv":"2026-04-07T02:01:21.094473959Z","hd":{"ts_event":"2026-04-07T02:01:21.094454039Z","rtype":160,"publisher_id":101,"instrument_id":436},"action":"C","side":"B","price":"1.156600000","size":30,"channel_id":23,"order_id":"10998899317949177968","flags":0,"ts_in_delta":941,"sequence":141947,"symbol":"FCEU SI 20260615 PS"}
{"ts_recv":"2026-04-07T02:01:21.094473959Z","hd":{"ts_event":"2026-04-07T02:01:21.094454039Z","rtype":160,"publisher_id":101,"instrument_id":436},"action":"A","side":"B","price":"1.156590000","size":30,"channel_id":23,"order_id":"10998899317949236050","flags":0,"ts_in_delta":941,"sequence":141947,"symbol":"FCEU SI 20260615 PS"}
{"ts_recv":"2026-04-07T02:01:21.094473959Z","hd":{"ts_event":"2026-04-07T02:01:21.094454039Z","rtype":160,"publisher_id":101,"instrument_id":436},"action":"C","side":"A","price":"1.156700000","size":30,"channel_id":23,"order_id":"1775527281094402160","flags":0,"ts_in_delta":941,"sequence":141947,"symbol":"FCEU SI 20260615 PS"}
{"ts_recv":"2026-04-07T02:01:21.094473959Z","hd":{"ts_event":"2026-04-07T02:01:21.094454039Z","rtype":160,"publisher_id":101,"instrument_id":436},"action":"A","side":"A","price":"1.156690000","size":30,"channel_id":23,"order_id":"1775527281094460242","flags":128,"ts_in_delta":941,"sequence":141947,"symbol":"FCEU SI 20260615 PS"}
{"ts_recv":"2026-04-07T02:01:25.843493379Z","hd":{"ts_event":"2026-04-07T02:01:25.843473441Z","rtype":160,"publisher_id":101,"instrument_id":436},"action":"C","side":"B","price":"1.156590000","size":30,"channel_id":23,"order_id":"10998899317949236050","flags":0,"ts_in_delta":1100,"sequence":142024,"symbol":"FCEU SI 20260615 PS"}
{"ts_recv":"2026-04-07T02:01:25.843493379Z","hd":{"ts_event":"2026-04-07T02:01:25.843473441Z","rtype":160,"publisher_id":101,"instrument_id":436},"action":"A","side":"B","price":"1.156600000","size":30,"channel_id":23,"order_id":"10998899322698255190","flags":0,"ts_in_delta":1100,"sequence":142024,"symbol":"FCEU SI 20260615 PS"}
{"ts_recv":"2026-04-07T02:01:25.843493379Z","hd":{"ts_event":"2026-04-07T02:01:25.843473441Z","rtype":160,"publisher_id":101,"instrument_id":436},"action":"C","side":"A","price":"1.156690000","size":30,"channel_id":23,"order_id":"1775527281094460242","flags":0,"ts_in_delta":1100,"sequence":142024,"symbol":"FCEU SI 20260615 PS"}
{"ts_recv":"2026-04-07T02:01:25.843493379Z","hd":{"ts_event":"2026-04-07T02:01:25.843473441Z","rtype":160,"publisher_id":101,"instrument_id":436},"action":"A","side":"A","price":"1.156700000","size":30,"channel_id":23,"order_id":"1775527285843479382","flags":128,"ts_in_delta":1100,"sequence":142024,"symbol":"FCEU SI 20260615 PS"}
{"ts_recv":"2026-04-07T02:01:26.973152822Z","hd":{"ts_event":"2026-04-07T02:01:26.973135619Z","rtype":160,"publisher_id":101,"instrument_id":436},"action":"C","side":"B","price":"1.156600000","size":30,"channel_id":23,"order_id":"10998899322698255190","flags":0,"ts_in_delta":887,"sequence":142032,"symbol":"FCEU SI 20260615 PS"}
{"ts_recv":"2026-04-07T02:01:26.973152822Z","hd":{"ts_event":"2026-04-07T02:01:26.973135619Z","rtype":160,"publisher_id":101,"instrument_id":436},"action":"A","side":"B","price":"1.156590000","size":30,"channel_id":23,"order_id":"10998899323827917291","flags":0,"ts_in_delta":887,"sequence":142032,"symbol":"FCEU SI 20260615 PS"}
{"ts_recv":"2026-04-07T02:01:26.973152822Z","hd":{"ts_event":"2026-04-07T02:01:26.973135619Z","rtype":160,"publisher_id":101,"instrument_id":436},"action":"C","side":"A","price":"1.156700000","size":30,"channel_id":23,"order_id":"1775527285843479382","flags":0,"ts_in_delta":887,"sequence":142032,"symbol":"FCEU SI 20260615 PS"}
{"ts_recv":"2026-04-07T02:01:26.973152822Z","hd":{"ts_event":"2026-04-07T02:01:26.973135619Z","rtype":160,"publisher_id":101,"instrument_id":436},"action":"A","side":"A","price":"1.156690000","size":30,"channel_id":23,"order_id":"1775527286973141483","flags":128,"ts_in_delta":887,"sequence":142032,"symbol":"FCEU SI 20260615 PS"}
{"ts_recv":"2026-04-07T02:01:29.299006826Z","hd":{"ts_event":"2026-04-07T02:01:29.298987759Z","rtype":160,"publisher_id":101,"instrument_id":436},"action":"C","side":"B","price":"1.156590000","size":30,"channel_id":23,"order_id":"10998899323827917291","flags":0,"ts_in_delta":881,"sequence":142053,"symbol":"FCEU SI 20260615 PS"}
{"ts_recv":"2026-04-07T02:01:29.299006826Z","hd":{"ts_event":"2026-04-07T02:01:29.298987759Z","rtype":160,"publisher_id":101,"instrument_id":436},"action":"A","side":"B","price":"1.156580000","size":30,"channel_id":23,"order_id":"10998899326153769713","flags":0,"ts_in_delta":881,"sequence":142053,"symbol":"FCEU SI 20260615 PS"}
{"ts_recv":"2026-04-07T02:01:29.299006826Z","hd":{"ts_event":"2026-04-07T02:01:29.298987759Z","rtype":160,"publisher_id":101,"instrument_id":436},"action":"C","side":"A","price":"1.156690000","size":30,"channel_id":23,"order_id":"1775527286973141483","flags":0,"ts_in_delta":881,"sequence":142053,"symbol":"FCEU SI 20260615 PS"}
{"ts_recv":"2026-04-07T02:01:29.299006826Z","hd":{"ts_event":"2026-04-07T02:01:29.298987759Z","rtype":160,"publisher_id":101,"instrument_id":436},"action":"A","side":"A","price":"1.156680000","size":30,"channel_id":23,"order_id":"1775527289298993905","flags":128,"ts_in_delta":881,"sequence":142053,"symbol":"FCEU SI 20260615 PS"}
{"ts_recv":"2026-04-07T02:01:29.299062104Z","hd":{"ts_event":"2026-04-07T02:01:29.299040059Z","rtype":160,"publisher_id":101,"instrument_id":436},"action":"C","side":"B","price":"1.156590000","size":30,"channel_id":23,"order_id":"10998899317949166913","flags":0,"ts_in_delta":885,"sequence":142054,"symbol":"FCEU SI 20260615 PS"}
{"ts_recv":"2026-04-07T02:01:29.299062104Z","hd":{"ts_event":"2026-04-07T02:01:29.299040059Z","rtype":160,"publisher_id":101,"instrument_id":436},"action":"A","side":"B","price":"1.156570000","size":30,"channel_id":23,"order_id":"10998899326153822121","flags":0,"ts_in_delta":885,"sequence":142054,"symbol":"FCEU SI 20260615 PS"}
{"ts_recv":"2026-04-07T02:01:29.299062104Z","hd":{"ts_event":"2026-04-07T02:01:29.299040059Z","rtype":160,"publisher_id":101,"instrument_id":436},"action":"C","side":"A","price":"1.156690000","size":30,"channel_id":23,"order_id":"1775527281094391105","flags":0,"ts_in_delta":885,"sequence":142054,"symbol":"FCEU SI 20260615 PS"}
{"ts_recv":"2026-04-07T02:01:29.299062104Z","hd":{"ts_event":"2026-04-07T02:01:29.299040059Z","rtype":160,"publisher_id":101,"instrument_id":436},"action":"A","side":"A","price":"1.156670000","size":30,"channel_id":23,"order_id":"1775527289299046313","flags":128,"ts_in_delta":885,"sequence":142054,"symbol":"FCEU SI 20260615 PS"}
{"ts_recv":"2026-04-07T02:01:29.299116890Z","hd":{"ts_event":"2026-04-07T02:01:29.299100143Z","rtype":160,"publisher_id":101,"instrument_id":436},"action":"C","side":"B","price":"1.156580000","size":30,"channel_id":23,"order_id":"10998899326153769713","flags":0,"ts_in_delta":902,"sequence":142055,"symbol":"FCEU SI 20260615 PS"}
{"ts_recv":"2026-04-07T02:01:29.299116890Z","hd":{"ts_event":"2026-04-07T02:01:29.299100143Z","rtype":160,"publisher_id":101,"instrument_id":436},"action":"A","side":"B","price":"1.156570000","size":30,"channel_id":23,"order_id":"10998899326153881641","flags":0,"ts_in_delta":902,"sequence":142055,"symbol":"FCEU SI 20260615 PS"}
{"ts_recv":"2026-04-07T02:01:29.299116890Z","hd":{"ts_event":"2026-04-07T02:01:29.299100143Z","rtype":160,"publisher_id":101,"instrument_id":436},"action":"C","side":"A","price":"1.156680000","size":30,"channel_id":23,"order_id":"1775527289298993905","flags":0,"ts_in_delta":902,"sequence":142055,"symbol":"FCEU SI 20260615 PS"}
{"ts_recv":"2026-04-07T02:01:29.299116890Z","hd":{"ts_event":"2026-04-07T02:01:29.299100143Z","rtype":160,"publisher_id":101,"instrument_id":436},"action":"A","side":"A","price":"1.156670000","size":30,"channel_id":23,"order_id":"1775527289299105833","flags":128,"ts_in_delta":902,"sequence":142055,"symbol":"FCEU SI 20260615 PS"}
{"ts_recv":"2026-04-07T02:01:31.823170243Z","hd":{"ts_event":"2026-04-07T02:01:31.823149145Z","rtype":160,"publisher_id":101,"instrument_id":436},"action":"C","side":"B","price":"1.156570000","size":30,"channel_id":23,"order_id":"10998899326153881641","flags":0,"ts_in_delta":1389,"sequence":142121,"symbol":"FCEU SI 20260615 PS"}
{"ts_recv":"2026-04-07T02:01:31.823170243Z","hd":{"ts_event":"2026-04-07T02:01:31.823149145Z","rtype":160,"publisher_id":101,"instrument_id":436},"action":"A","side":"B","price":"1.156580000","size":30,"channel_id":23,"order_id":"10998899328677931425","flags":0,"ts_in_delta":1389,"sequence":142121,"symbol":"FCEU SI 20260615 PS"}
{"ts_recv":"2026-04-07T02:01:31.823170243Z","hd":{"ts_event":"2026-04-07T02:01:31.823149145Z","rtype":160,"publisher_id":101,"instrument_id":436},"action":"C","side":"A","price":"1.156670000","size":30,"channel_id":23,"order_id":"1775527289299105833","flags":0,"ts_in_delta":1389,"sequence":142121,"symbol":"FCEU SI 20260615 PS"}
{"ts_recv":"2026-04-07T02:01:31.823170243Z","hd":{"ts_event":"2026-04-07T02:01:31.823149145Z","rtype":160,"publisher_id":101,"instrument_id":436},"action":"A","side":"A","price":"1.156680000","size":30,"channel_id":23,"order_id":"1775527291823155617","flags":128,"ts_in_delta":1389,"sequence":142121,"symbol":"FCEU SI 20260615 PS"}
{"ts_recv":"2026-04-07T02:01:34.830726976Z","hd":{"ts_event":"2026-04-07T02:01:34.830706331Z","rtype":160,"publisher_id":101,"instrument_id":436},"action":"C","side":"B","price":"1.156570000","size":30,"channel_id":23,"order_id":"10998899326153822121","flags":0,"ts_in_delta":943,"sequence":142169,"symbol":"FCEU SI 20260615 PS"}
{"ts_recv":"2026-04-07T02:01:34.830726976Z","hd":{"ts_event":"2026-04-07T02:01:34.830706331Z","rtype":160,"publisher_id":101,"instrument_id":436},"action":"A","side":"B","price":"1.156590000","size":30,"channel_id":23,"order_id":"10998899331685488194","flags":0,"ts_in_delta":943,"sequence":142169,"symbol":"FCEU SI 20260615 PS"}
{"ts_recv":"2026-04-07T02:01:34.830726976Z","hd":{"ts_event":"2026-04-07T02:01:34.830706331Z","rtype":160,"publisher_id":101,"instrument_id":436},"action":"C","side":"A","price":"1.156670000","size":30,"channel_id":23,"order_id":"1775527289299046313","flags":0,"ts_in_delta":943,"sequence":142169,"symbol":"FCEU SI 20260615 PS"}
{"ts_recv":"2026-04-07T02:01:34.830726976Z","hd":{"ts_event":"2026-04-07T02:01:34.830706331Z","rtype":160,"publisher_id":101,"instrument_id":436},"action":"A","side":"A","price":"1.156690000","size":30,"channel_id":23,"order_id":"1775527294830712386","flags":128,"ts_in_delta":943,"sequence":142169,"symbol":"FCEU SI 20260615 PS"}
{"ts_recv":"2026-04-07T02:01:34.830832195Z","hd":{"ts_event":"2026-04-07T02:01:34.830813795Z","rtype":160,"publisher_id":101,"instrument_id":436},"action":"C","side":"B","price":"1.156580000","size":30,"channel_id":23,"order_id":"10998899328677931425","flags":0,"ts_in_delta":949,"sequence":142170,"symbol":"FCEU SI 20260615 PS"}
{"ts_recv":"2026-04-07T02:01:34.830832195Z","hd":{"ts_event":"2026-04-07T02:01:34.830813795Z","rtype":160,"publisher_id":101,"instrument_id":436},"action":"A","side":"B","price":"1.156590000","size":30,"channel_id":23,"order_id":"10998899331685595802","flags":0,"ts_in_delta":949,"sequence":142170,"symbol":"FCEU SI 20260615 PS"}
{"ts_recv":"2026-04-07T02:01:34.830832195Z","hd":{"ts_event":"2026-04-07T02:01:34.830813795Z","rtype":160,"publisher_id":101,"instrument_id":436},"action":"C","side":"A","price":"1.156680000","size":30,"channel_id":23,"order_id":"1775527291823155617","flags":0,"ts_in_delta":949,"sequence":142170,"symbol":"FCEU SI 20260615 PS"}
{"ts_recv":"2026-04-07T02:01:34.830832195Z","hd":{"ts_event":"2026-04-07T02:01:34.830813795Z","rtype":160,"publisher_id":101,"instrument_id":436},"action":"A","side":"A","price":"1.156690000","size":30,"channel_id":23,"order_id":"1775527294830819994","flags":128,"ts_in_delta":949,"sequence":142170,"symbol":"FCEU SI 20260615 PS"}
{"ts_recv":"2026-04-07T02:01:34.848256278Z","hd":{"ts_event":"2026-04-07T02:01:34.848238045Z","rtype":160,"publisher_id":101,"instrument_id":436},"action":"C","side":"B","price":"1.156590000","size":30,"channel_id":23,"order_id":"10998899331685595802","flags":0,"ts_in_delta":955,"sequence":142172,"symbol":"FCEU SI 20260615 PS"}
{"ts_recv":"2026-04-07T02:01:34.848256278Z","hd":{"ts_event":"2026-04-07T02:01:34.848238045Z","rtype":160,"publisher_id":101,"instrument_id":436},"action":"A","side":"B","price":"1.156580000","size":30,"channel_id":23,"order_id":"10998899331703020092","flags":0,"ts_in_delta":955,"sequence":142172,"symbol":"FCEU SI 20260615 PS"}
{"ts_recv":"2026-04-07T02:01:34.848256278Z","hd":{"ts_event":"2026-04-07T02:01:34.848238045Z","rtype":160,"publisher_id":101,"instrument_id":436},"action":"C","side":"A","price":"1.156690000","size":30,"channel_id":23,"order_id":"1775527294830819994","flags":0,"ts_in_delta":955,"sequence":142172,"symbol":"FCEU SI 20260615 PS"}
{"ts_recv":"2026-04-07T02:01:34.848256278Z","hd":{"ts_event":"2026-04-07T02:01:34.848238045Z","rtype":160,"publisher_id":101,"instrument_id":436},"action":"A","side":"A","price":"1.156680000","size":30,"channel_id":23,"order_id":"1775527294848244284","flags":128,"ts_in_delta":955,"sequence":142172,"symbol":"FCEU SI 20260615 PS"}
{"ts_recv":"2026-04-07T02:01:35.060908928Z","hd":{"ts_event":"2026-04-07T02:01:35.060891035Z","rtype":160,"publisher_id":101,"instrument_id":436},"action":"C","side":"B","price":"1.156580000","size":30,"channel_id":23,"order_id":"10998899331703020092","flags":0,"ts_in_delta":1074,"sequence":142187,"symbol":"FCEU SI 20260615 PS"}
{"ts_recv":"2026-04-07T02:01:35.060908928Z","hd":{"ts_event":"2026-04-07T02:01:35.060891035Z","rtype":160,"publisher_id":101,"instrument_id":436},"action":"A","side":"B","price":"1.156590000","size":30,"channel_id":23,"order_id":"10998899331915672783","flags":0,"ts_in_delta":1074,"sequence":142187,"symbol":"FCEU SI 20260615 PS"}
{"ts_recv":"2026-04-07T02:01:35.060908928Z","hd":{"ts_event":"2026-04-07T02:01:35.060891035Z","rtype":160,"publisher_id":101,"instrument_id":436},"action":"C","side":"A","price":"1.156680000","size":30,"channel_id":23,"order_id":"1775527294848244284","flags":0,"ts_in_delta":1074,"sequence":142187,"symbol":"FCEU SI 20260615 PS"}
{"ts_recv":"2026-04-07T02:01:35.060908928Z","hd":{"ts_event":"2026-04-07T02:01:35.060891035Z","rtype":160,"publisher_id":101,"instrument_id":436},"action":"A","side":"A","price":"1.156690000","size":30,"channel_id":23,"order_id":"1775527295060896975","flags":128,"ts_in_delta":1074,"sequence":142187,"symbol":"FCEU SI 20260615 PS"}
{"ts_recv":"2026-04-07T02:01:51.741239658Z","hd":{"ts_event":"2026-04-07T02:01:51.741217145Z","rtype":160,"publisher_id":101,"instrument_id":436},"action":"C","side":"B","price":"1.156590000","size":30,"channel_id":23,"order_id":"10998899331915672783","flags":0,"ts_in_delta":1105,"sequence":142328,"symbol":"FCEU SI 20260615 PS"}
{"ts_recv":"2026-04-07T02:01:51.741239658Z","hd":{"ts_event":"2026-04-07T02:01:51.741217145Z","rtype":160,"publisher_id":101,"instrument_id":436},"action":"A","side":"B","price":"1.156580000","size":30,"channel_id":23,"order_id":"10998899348595999085","flags":0,"ts_in_delta":1105,"sequence":142328,"symbol":"FCEU SI 20260615 PS"}
{"ts_recv":"2026-04-07T02:01:51.741239658Z","hd":{"ts_event":"2026-04-07T02:01:51.741217145Z","rtype":160,"publisher_id":101,"instrument_id":436},"action":"C","side":"A","price":"1.156690000","size":30,"channel_id":23,"order_id":"1775527295060896975","flags":0,"ts_in_delta":1105,"sequence":142328,"symbol":"FCEU SI 20260615 PS"}
{"ts_recv":"2026-04-07T02:01:51.741239658Z","hd":{"ts_event":"2026-04-07T02:01:51.741217145Z","rtype":160,"publisher_id":101,"instrument_id":436},"action":"A","side":"A","price":"1.156680000","size":30,"channel_id":23,"order_id":"1775527311741223277","flags":128,"ts_in_delta":1105,"sequence":142328,"symbol":"FCEU SI 20260615 PS"}
{"ts_recv":"2026-04-07T02:01:51.741300980Z","hd":{"ts_event":"2026-04-07T02:01:51.741278951Z","rtype":160,"publisher_id":101,"instrument_id":436},"action":"C","side":"B","price":"1.156590000","size":30,"channel_id":23,"order_id":"10998899331685488194","flags":0,"ts_in_delta":884,"sequence":142329,"symbol":"FCEU SI 20260615 PS"}
{"ts_recv":"2026-04-07T02:01:51.741300980Z","hd":{"ts_event":"2026-04-07T02:01:51.741278951Z","rtype":160,"publisher_id":101,"instrument_id":436},"action":"A","side":"B","price":"1.156570000","size":30,"channel_id":23,"order_id":"10998899348596061325","flags":0,"ts_in_delta":884,"sequence":142329,"symbol":"FCEU SI 20260615 PS"}
{"ts_recv":"2026-04-07T02:01:51.741300980Z","hd":{"ts_event":"2026-04-07T02:01:51.741278951Z","rtype":160,"publisher_id":101,"instrument_id":436},"action":"C","side":"A","price":"1.156690000","size":30,"channel_id":23,"order_id":"1775527294830712386","flags":0,"ts_in_delta":884,"sequence":142329,"symbol":"FCEU SI 20260615 PS"}
{"ts_recv":"2026-04-07T02:01:51.741300980Z","hd":{"ts_event":"2026-04-07T02:01:51.741278951Z","rtype":160,"publisher_id":101,"instrument_id":436},"action":"A","side":"A","price":"1.156670000","size":30,"channel_id":23,"order_id":"1775527311741285517","flags":128,"ts_in_delta":884,"sequence":142329,"symbol":"FCEU SI 20260615 PS"}
{"ts_recv":"2026-04-07T02:01:51.741354238Z","hd":{"ts_event":"2026-04-07T02:01:51.741338297Z","rtype":160,"publisher_id":101,"instrument_id":436},"action":"C","side":"B","price":"1.156580000","size":30,"channel_id":23,"order_id":"10998899348595999085","flags":0,"ts_in_delta":1039,"sequence":142330,"symbol":"FCEU SI 20260615 PS"}
{"ts_recv":"2026-04-07T02:01:51.741354238Z","hd":{"ts_event":"2026-04-07T02:01:51.741338297Z","rtype":160,"publisher_id":101,"instrument_id":436},"action":"A","side":"B","price":"1.156570000","size":30,"channel_id":23,"order_id":"10998899348596119857","flags":0,"ts_in_delta":1039,"sequence":142330,"symbol":"FCEU SI 20260615 PS"}
{"ts_recv":"2026-04-07T02:01:51.741354238Z","hd":{"ts_event":"2026-04-07T02:01:51.741338297Z","rtype":160,"publisher_id":101,"instrument_id":436},"action":"C","side":"A","price":"1.156680000","size":30,"channel_id":23,"order_id":"1775527311741223277","flags":0,"ts_in_delta":1039,"sequence":142330,"symbol":"FCEU SI 20260615 PS"}
{"ts_recv":"2026-04-07T02:01:51.741354238Z","hd":{"ts_event":"2026-04-07T02:01:51.741338297Z","rtype":160,"publisher_id":101,"instrument_id":436},"action":"A","side":"A","price":"1.156670000","size":30,"channel_id":23,"order_id":"1775527311741344049","flags":128,"ts_in_delta":1039,"sequence":142330,"symbol":"FCEU SI 20260615 PS"}
{"ts_recv":"2026-04-07T02:01:51.755732489Z","hd":{"ts_event":"2026-04-07T02:01:51.755711619Z","rtype":160,"publisher_id":101,"instrument_id":436},"action":"C","side":"B","price":"1.156570000","size":30,"channel_id":23,"order_id":"10998899348596119857","flags":0,"ts_in_delta":897,"sequence":142339,"symbol":"FCEU SI 20260615 PS"}
{"ts_recv":"2026-04-07T02:01:51.755732489Z","hd":{"ts_event":"2026-04-07T02:01:51.755711619Z","rtype":160,"publisher_id":101,"instrument_id":436},"action":"A","side":"B","price":"1.156560000","size":30,"channel_id":23,"order_id":"10998899348610494036","flags":0,"ts_in_delta":897,"sequence":142339,"symbol":"FCEU SI 20260615 PS"}
{"ts_recv":"2026-04-07T02:01:51.755732489Z","hd":{"ts_event":"2026-04-07T02:01:51.755711619Z","rtype":160,"publisher_id":101,"instrument_id":436},"action":"C","side":"A","price":"1.156670000","size":30,"channel_id":23,"order_id":"1775527311741344049","flags":0,"ts_in_delta":897,"sequence":142339,"symbol":"FCEU SI 20260615 PS"}
{"ts_recv":"2026-04-07T02:01:51.755732489Z","hd":{"ts_event":"2026-04-07T02:01:51.755711619Z","rtype":160,"publisher_id":101,"instrument_id":436},"action":"A","side":"A","price":"1.156660000","size":30,"channel_id":23,"order_id":"1775527311755718228","flags":128,"ts_in_delta":897,"sequence":142339,"symbol":"FCEU SI 20260615 PS"}
{"ts_recv":"2026-04-07T02:01:51.971044616Z","hd":{"ts_event":"2026-04-07T02:01:51.971020429Z","rtype":160,"publisher_id":101,"instrument_id":436},"action":"C","side":"B","price":"1.156570000","size":30,"channel_id":23,"order_id":"10998899348596061325","flags":0,"ts_in_delta":1237,"sequence":142360,"symbol":"FCEU SI 20260615 PS"}
{"ts_recv":"2026-04-07T02:01:51.971044616Z","hd":{"ts_event":"2026-04-07T02:01:51.971020429Z","rtype":160,"publisher_id":101,"instrument_id":436},"action":"A","side":"B","price":"1.156550000","size":30,"channel_id":23,"order_id":"10998899348825802354","flags":0,"ts_in_delta":1237,"sequence":142360,"symbol":"FCEU SI 20260615 PS"}
{"ts_recv":"2026-04-07T02:01:51.971044616Z","hd":{"ts_event":"2026-04-07T02:01:51.971020429Z","rtype":160,"publisher_id":101,"instrument_id":436},"action":"C","side":"A","price":"1.156670000","size":30,"channel_id":23,"order_id":"1775527311741285517","flags":0,"ts_in_delta":1237,"sequence":142360,"symbol":"FCEU SI 20260615 PS"}
{"ts_recv":"2026-04-07T02:01:51.971044616Z","hd":{"ts_event":"2026-04-07T02:01:51.971020429Z","rtype":160,"publisher_id":101,"instrument_id":436},"action":"A","side":"A","price":"1.156650000","size":30,"channel_id":23,"order_id":"1775527311971026546","flags":128,"ts_in_delta":1237,"sequence":142360,"symbol":"FCEU SI 20260615 PS"}
{"ts_recv":"2026-04-07T02:01:51.971107719Z","hd":{"ts_event":"2026-04-07T02:01:51.971090261Z","rtype":160,"publisher_id":101,"instrument_id":436},"action":"C","side":"B","price":"1.156560000","size":30,"channel_id":23,"order_id":"10998899348610494036","flags":0,"ts_in_delta":1088,"sequence":142361,"symbol":"FCEU SI 20260615 PS"}
{"ts_recv":"2026-04-07T02:01:51.971107719Z","hd":{"ts_event":"2026-04-07T02:01:51.971090261Z","rtype":160,"publisher_id":101,"instrument_id":436},"action":"A","side":"B","price":"1.156550000","size":30,"channel_id":23,"order_id":"10998899348825872139","flags":0,"ts_in_delta":1088,"sequence":142361,"symbol":"FCEU SI 20260615 PS"}
{"ts_recv":"2026-04-07T02:01:51.971107719Z","hd":{"ts_event":"2026-04-07T02:01:51.971090261Z","rtype":160,"publisher_id":101,"instrument_id":436},"action":"C","side":"A","price":"1.156660000","size":30,"channel_id":23,"order_id":"1775527311755718228","flags":0,"ts_in_delta":1088,"sequence":142361,"symbol":"FCEU SI 20260615 PS"}
{"ts_recv":"2026-04-07T02:01:51.971107719Z","hd":{"ts_event":"2026-04-07T02:01:51.971090261Z","rtype":160,"publisher_id":101,"instrument_id":436},"action":"A","side":"A","price":"1.156650000","size":30,"channel_id":23,"order_id":"1775527311971096331","flags":128,"ts_in_delta":1088,"sequence":142361,"symbol":"FCEU SI 20260615 PS"}
{"ts_recv":"2026-04-07T02:01:52.322271224Z","hd":{"ts_event":"2026-04-07T02:01:52.322255707Z","rtype":160,"publisher_id":101,"instrument_id":436},"action":"A","side":"A","price":"1.156800000","size":20,"channel_id":23,"order_id":"1775527312322261988","flags":128,"ts_in_delta":714,"sequence":142378,"symbol":"FCEU SI 20260615 PS"}
{"ts_recv":"2026-04-07T02:01:52.322306989Z","hd":{"ts_event":"2026-04-07T02:01:52.322294537Z","rtype":160,"publisher_id":101,"instrument_id":436},"action":"C","side":"A","price":"1.156900000","size":20,"channel_id":23,"order_id":"1775527082430313364","flags":128,"ts_in_delta":690,"sequence":142379,"symbol":"FCEU SI 20260615 PS"}
{"ts_recv":"2026-04-07T02:01:56.306117268Z","hd":{"ts_event":"2026-04-07T02:01:56.306097043Z","rtype":160,"publisher_id":101,"instrument_id":436},"action":"C","side":"B","price":"1.156550000","size":30,"channel_id":23,"order_id":"10998899348825872139","flags":0,"ts_in_delta":886,"sequence":142463,"symbol":"FCEU SI 20260615 PS"}
{"ts_recv":"2026-04-07T02:01:56.306117268Z","hd":{"ts_event":"2026-04-07T02:01:56.306097043Z","rtype":160,"publisher_id":101,"instrument_id":436},"action":"A","side":"B","price":"1.156540000","size":30,"channel_id":23,"order_id":"10998899353160878801","flags":0,"ts_in_delta":886,"sequence":142463,"symbol":"FCEU SI 20260615 PS"}
{"ts_recv":"2026-04-07T02:01:56.306117268Z","hd":{"ts_event":"2026-04-07T02:01:56.306097043Z","rtype":160,"publisher_id":101,"instrument_id":436},"action":"C","side":"A","price":"1.156650000","size":30,"channel_id":23,"order_id":"1775527311971096331","flags":0,"ts_in_delta":886,"sequence":142463,"symbol":"FCEU SI 20260615 PS"}
{"ts_recv":"2026-04-07T02:01:56.306117268Z","hd":{"ts_event":"2026-04-07T02:01:56.306097043Z","rtype":160,"publisher_id":101,"instrument_id":436},"action":"A","side":"A","price":"1.156640000","size":30,"channel_id":23,"order_id":"1775527316306102993","flags":128,"ts_in_delta":886,"sequence":142463,"symbol":"FCEU SI 20260615 PS"}
{"ts_recv":"2026-04-07T02:01:56.306204493Z","hd":{"ts_event":"2026-04-07T02:01:56.306182675Z","rtype":160,"publisher_id":101,"instrument_id":436},"action":"C","side":"B","price":"1.156540000","size":30,"channel_id":23,"order_id":"10998899353160878801","flags":0,"ts_in_delta":861,"sequence":142464,"symbol":"FCEU SI 20260615 PS"}
{"ts_recv":"2026-04-07T02:01:56.306204493Z","hd":{"ts_event":"2026-04-07T02:01:56.306182675Z","rtype":160,"publisher_id":101,"instrument_id":436},"action":"A","side":"B","price":"1.156530000","size":30,"channel_id":23,"order_id":"10998899353160964849","flags":0,"ts_in_delta":861,"sequence":142464,"symbol":"FCEU SI 20260615 PS"}
{"ts_recv":"2026-04-07T02:01:56.306204493Z","hd":{"ts_event":"2026-04-07T02:01:56.306182675Z","rtype":160,"publisher_id":101,"instrument_id":436},"action":"C","side":"A","price":"1.156640000","size":30,"channel_id":23,"order_id":"1775527316306102993","flags":0,"ts_in_delta":861,"sequence":142464,"symbol":"FCEU SI 20260615 PS"}
{"ts_recv":"2026-04-07T02:01:56.306204493Z","hd":{"ts_event":"2026-04-07T02:01:56.306182675Z","rtype":160,"publisher_id":101,"instrument_id":436},"action":"A","side":"A","price":"1.156630000","size":30,"channel_id":23,"order_id":"1775527316306189041","flags":128,"ts_in_delta":861,"sequence":142464,"symbol":"FCEU SI 20260615 PS"}
{"ts_recv":"2026-04-07T02:01:56.306263450Z","hd":{"ts_event":"2026-04-07T02:01:56.306244633Z","rtype":160,"publisher_id":101,"instrument_id":436},"action":"C","side":"B","price":"1.156530000","size":30,"channel_id":23,"order_id":"10998899353160964849","flags":0,"ts_in_delta":947,"sequence":142465,"symbol":"FCEU SI 20260615 PS"}
{"ts_recv":"2026-04-07T02:01:56.306263450Z","hd":{"ts_event":"2026-04-07T02:01:56.306244633Z","rtype":160,"publisher_id":101,"instrument_id":436},"action":"A","side":"B","price":"1.156540000","size":30,"channel_id":23,"order_id":"10998899353161026657","flags":0,"ts_in_delta":947,"sequence":142465,"symbol":"FCEU SI 20260615 PS"}
{"ts_recv":"2026-04-07T02:01:56.306263450Z","hd":{"ts_event":"2026-04-07T02:01:56.306244633Z","rtype":160,"publisher_id":101,"instrument_id":436},"action":"C","side":"A","price":"1.156630000","size":30,"channel_id":23,"order_id":"1775527316306189041","flags":0,"ts_in_delta":947,"sequence":142465,"symbol":"FCEU SI 20260615 PS"}
{"ts_recv":"2026-04-07T02:01:56.306263450Z","hd":{"ts_event":"2026-04-07T02:01:56.306244633Z","rtype":160,"publisher_id":101,"instrument_id":436},"action":"A","side":"A","price":"1.156640000","size":30,"channel_id":23,"order_id":"1775527316306250849","flags":128,"ts_in_delta":947,"sequence":142465,"symbol":"FCEU SI 20260615 PS"}
{"ts_recv":"2026-04-07T02:01:56.306287464Z","hd":{"ts_event":"2026-04-07T02:01:56.306268077Z","rtype":160,"publisher_id":101,"instrument_id":436},"action":"C","side":"B","price":"1.156550000","size":30,"channel_id":23,"order_id":"10998899348825802354","flags":0,"ts_in_delta":1088,"sequence":142466,"symbol":"FCEU SI 20260615 PS"}
{"ts_recv":"2026-04-07T02:01:56.306287464Z","hd":{"ts_event":"2026-04-07T02:01:56.306268077Z","rtype":160,"publisher_id":101,"instrument_id":436},"action":"A","side":"B","price":"1.156530000","size":30,"channel_id":23,"order_id":"10998899353161049988","flags":0,"ts_in_delta":1088,"sequence":142466,"symbol":"FCEU SI 20260615 PS"}
{"ts_recv":"2026-04-07T02:01:56.306287464Z","hd":{"ts_event":"2026-04-07T02:01:56.306268077Z","rtype":160,"publisher_id":101,"instrument_id":436},"action":"C","side":"A","price":"1.156650000","size":30,"channel_id":23,"order_id":"1775527311971026546","flags":0,"ts_in_delta":1088,"sequence":142466,"symbol":"FCEU SI 20260615 PS"}
{"ts_recv":"2026-04-07T02:01:56.306287464Z","hd":{"ts_event":"2026-04-07T02:01:56.306268077Z","rtype":160,"publisher_id":101,"instrument_id":436},"action":"A","side":"A","price":"1.156630000","size":30,"channel_id":23,"order_id":"1775527316306274180","flags":128,"ts_in_delta":1088,"sequence":142466,"symbol":"FCEU SI 20260615 PS"}
{"ts_recv":"2026-04-07T02:01:56.306345414Z","hd":{"ts_event":"2026-04-07T02:01:56.306327251Z","rtype":160,"publisher_id":101,"instrument_id":436},"action":"C","side":"B","price":"1.156540000","size":30,"channel_id":23,"order_id":"10998899353161026657","flags":0,"ts_in_delta":940,"sequence":142467,"symbol":"FCEU SI 20260615 PS"}
{"ts_recv":"2026-04-07T02:01:56.306345414Z","hd":{"ts_event":"2026-04-07T02:01:56.306327251Z","rtype":160,"publisher_id":101,"instrument_id":436},"action":"A","side":"B","price":"1.156530000","size":30,"channel_id":23,"order_id":"10998899353161108911","flags":0,"ts_in_delta":940,"sequence":142467,"symbol":"FCEU SI 20260615 PS"}
{"ts_recv":"2026-04-07T02:01:56.306345414Z","hd":{"ts_event":"2026-04-07T02:01:56.306327251Z","rtype":160,"publisher_id":101,"instrument_id":436},"action":"C","side":"A","price":"1.156640000","size":30,"channel_id":23,"order_id":"1775527316306250849","flags":0,"ts_in_delta":940,"sequence":142467,"symbol":"FCEU SI 20260615 PS"}
{"ts_recv":"2026-04-07T02:01:56.306345414Z","hd":{"ts_event":"2026-04-07T02:01:56.306327251Z","rtype":160,"publisher_id":101,"instrument_id":436},"action":"A","side":"A","price":"1.156630000","size":30,"channel_id":23,"order_id":"1775527316306333103","flags":128,"ts_in_delta":940,"sequence":142467,"symbol":"FCEU SI 20260615 PS"}
{"ts_recv":"2026-04-07T02:01:56.333405744Z","hd":{"ts_event":"2026-04-07T02:01:56.333387119Z","rtype":160,"publisher_id":101,"instrument_id":436},"action":"C","side":"B","price":"1.156530000","size":30,"channel_id":23,"order_id":"10998899353161108911","flags":0,"ts_in_delta":949,"sequence":142470,"symbol":"FCEU SI 20260615 PS"}
{"ts_recv":"2026-04-07T02:01:56.333405744Z","hd":{"ts_event":"2026-04-07T02:01:56.333387119Z","rtype":160,"publisher_id":101,"instrument_id":436},"action":"A","side":"B","price":"1.156540000","size":30,"channel_id":23,"order_id":"10998899353188168729","flags":0,"ts_in_delta":949,"sequence":142470,"symbol":"FCEU SI 20260615 PS"}
{"ts_recv":"2026-04-07T02:01:56.333405744Z","hd":{"ts_event":"2026-04-07T02:01:56.333387119Z","rtype":160,"publisher_id":101,"instrument_id":436},"action":"C","side":"A","price":"1.156630000","size":30,"channel_id":23,"order_id":"1775527316306333103","flags":0,"ts_in_delta":949,"sequence":142470,"symbol":"FCEU SI 20260615 PS"}
{"ts_recv":"2026-04-07T02:01:56.333405744Z","hd":{"ts_event":"2026-04-07T02:01:56.333387119Z","rtype":160,"publisher_id":101,"instrument_id":436},"action":"A","side":"A","price":"1.156640000","size":30,"channel_id":23,"order_id":"1775527316333392921","flags":128,"ts_in_delta":949,"sequence":142470,"symbol":"FCEU SI 20260615 PS"}
{"ts_recv":"2026-04-07T02:01:57.053222662Z","hd":{"ts_event":"2026-04-07T02:01:57.053204675Z","rtype":160,"publisher_id":101,"instrument_id":436},"action":"C","side":"B","price":"1.156540000","size":30,"channel_id":23,"order_id":"10998899353188168729","flags":0,"ts_in_delta":956,"sequence":142478,"symbol":"FCEU SI 20260615 PS"}
{"ts_recv":"2026-04-07T02:01:57.053222662Z","hd":{"ts_event":"2026-04-07T02:01:57.053204675Z","rtype":160,"publisher_id":101,"instrument_id":436},"action":"A","side":"B","price":"1.156560000","size":30,"channel_id":23,"order_id":"10998899353907986445","flags":0,"ts_in_delta":956,"sequence":142478,"symbol":"FCEU SI 20260615 PS"}
{"ts_recv":"2026-04-07T02:01:57.053222662Z","hd":{"ts_event":"2026-04-07T02:01:57.053204675Z","rtype":160,"publisher_id":101,"instrument_id":436},"action":"C","side":"A","price":"1.156640000","size":30,"channel_id":23,"order_id":"1775527316333392921","flags":0,"ts_in_delta":956,"sequence":142478,"symbol":"FCEU SI 20260615 PS"}
{"ts_recv":"2026-04-07T02:01:57.053222662Z","hd":{"ts_event":"2026-04-07T02:01:57.053204675Z","rtype":160,"publisher_id":101,"instrument_id":436},"action":"A","side":"A","price":"1.156660000","size":30,"channel_id":23,"order_id":"1775527317053210637","flags":128,"ts_in_delta":956,"sequence":142478,"symbol":"FCEU SI 20260615 PS"}
{"ts_recv":"2026-04-07T02:01:57.053290964Z","hd":{"ts_event":"2026-04-07T02:01:57.053273719Z","rtype":160,"publisher_id":101,"instrument_id":436},"action":"C","side":"B","price":"1.156530000","size":30,"channel_id":23,"order_id":"10998899353161049988","flags":0,"ts_in_delta":866,"sequence":142479,"symbol":"FCEU SI 20260615 PS"}
{"ts_recv":"2026-04-07T02:01:57.053290964Z","hd":{"ts_event":"2026-04-07T02:01:57.053273719Z","rtype":160,"publisher_id":101,"instrument_id":436},"action":"A","side":"B","price":"1.156550000","size":30,"channel_id":23,"order_id":"10998899353908055374","flags":0,"ts_in_delta":866,"sequence":142479,"symbol":"FCEU SI 20260615 PS"}
{"ts_recv":"2026-04-07T02:01:57.053290964Z","hd":{"ts_event":"2026-04-07T02:01:57.053273719Z","rtype":160,"publisher_id":101,"instrument_id":436},"action":"C","side":"A","price":"1.156630000","size":30,"channel_id":23,"order_id":"1775527316306274180","flags":0,"ts_in_delta":866,"sequence":142479,"symbol":"FCEU SI 20260615 PS"}
{"ts_recv":"2026-04-07T02:01:57.053290964Z","hd":{"ts_event":"2026-04-07T02:01:57.053273719Z","rtype":160,"publisher_id":101,"instrument_id":436},"action":"A","side":"A","price":"1.156650000","size":30,"channel_id":23,"order_id":"1775527317053279566","flags":128,"ts_in_delta":866,"sequence":142479,"symbol":"FCEU SI 20260615 PS"}
{"ts_recv":"2026-04-07T02:01:57.053303498Z","hd":{"ts_event":"2026-04-07T02:01:57.053284549Z","rtype":160,"publisher_id":101,"instrument_id":436},"action":"C","side":"B","price":"1.156560000","size":30,"channel_id":23,"order_id":"10998899353907986445","flags":0,"ts_in_delta":935,"sequence":142480,"symbol":"FCEU SI 20260615 PS"}
{"ts_recv":"2026-04-07T02:01:57.053303498Z","hd":{"ts_event":"2026-04-07T02:01:57.053284549Z","rtype":160,"publisher_id":101,"instrument_id":436},"action":"A","side":"B","price":"1.156540000","size":30,"channel_id":23,"order_id":"10998899353908066078","flags":0,"ts_in_delta":935,"sequence":142480,"symbol":"FCEU SI 20260615 PS"}
{"ts_recv":"2026-04-07T02:01:57.053303498Z","hd":{"ts_event":"2026-04-07T02:01:57.053284549Z","rtype":160,"publisher_id":101,"instrument_id":436},"action":"C","side":"A","price":"1.156660000","size":30,"channel_id":23,"order_id":"1775527317053210637","flags":0,"ts_in_delta":935,"sequence":142480,"symbol":"FCEU SI 20260615 PS"}
{"ts_recv":"2026-04-07T02:01:57.053303498Z","hd":{"ts_event":"2026-04-07T02:01:57.053284549Z","rtype":160,"publisher_id":101,"instrument_id":436},"action":"A","side":"A","price":"1.156640000","size":30,"channel_id":23,"order_id":"1775527317053290270","flags":128,"ts_in_delta":935,"sequence":142480,"symbol":"FCEU SI 20260615 PS"}
{"ts_recv":"2026-04-07T02:01:57.053358399Z","hd":{"ts_event":"2026-04-07T02:01:57.053341265Z","rtype":160,"publisher_id":101,"instrument_id":436},"action":"C","side":"B","price":"1.156540000","size":30,"channel_id":23,"order_id":"10998899353908066078","flags":0,"ts_in_delta":988,"sequence":142481,"symbol":"FCEU SI 20260615 PS"}
{"ts_recv":"2026-04-07T02:01:57.053358399Z","hd":{"ts_event":"2026-04-07T02:01:57.053341265Z","rtype":160,"publisher_id":101,"instrument_id":436},"action":"A","side":"B","price":"1.156550000","size":30,"channel_id":23,"order_id":"10998899353908122962","flags":0,"ts_in_delta":988,"sequence":142481,"symbol":"FCEU SI 20260615 PS"}
{"ts_recv":"2026-04-07T02:01:57.053358399Z","hd":{"ts_event":"2026-04-07T02:01:57.053341265Z","rtype":160,"publisher_id":101,"instrument_id":436},"action":"C","side":"A","price":"1.156640000","size":30,"channel_id":23,"order_id":"1775527317053290270","flags":0,"ts_in_delta":988,"sequence":142481,"symbol":"FCEU SI 20260615 PS"}
{"ts_recv":"2026-04-07T02:01:57.053358399Z","hd":{"ts_event":"2026-04-07T02:01:57.053341265Z","rtype":160,"publisher_id":101,"instrument_id":436},"action":"A","side":"A","price":"1.156650000","size":30,"channel_id":23,"order_id":"1775527317053347154","flags":128,"ts_in_delta":988,"sequence":142481,"symbol":"FCEU SI 20260615 PS"}
{"ts_recv":"2026-04-07T02:01:58.698253838Z","hd":{"ts_event":"2026-04-07T02:01:58.698234625Z","rtype":160,"publisher_id":101,"instrument_id":436},"action":"C","side":"B","price":"1.156550000","size":30,"channel_id":23,"order_id":"10998899353908122962","flags":0,"ts_in_delta":756,"sequence":142508,"symbol":"FCEU SI 20260615 PS"}
{"ts_recv":"2026-04-07T02:01:58.698253838Z","hd":{"ts_event":"2026-04-07T02:01:58.698234625Z","rtype":160,"publisher_id":101,"instrument_id":436},"action":"A","side":"B","price":"1.156560000","size":30,"channel_id":23,"order_id":"10998899355553016425","flags":0,"ts_in_delta":756,"sequence":142508,"symbol":"FCEU SI 20260615 PS"}
{"ts_recv":"2026-04-07T02:01:58.698253838Z","hd":{"ts_event":"2026-04-07T02:01:58.698234625Z","rtype":160,"publisher_id":101,"instrument_id":436},"action":"C","side":"A","price":"1.156650000","size":30,"channel_id":23,"order_id":"1775527317053347154","flags":0,"ts_in_delta":756,"sequence":142508,"symbol":"FCEU SI 20260615 PS"}
{"ts_recv":"2026-04-07T02:01:58.698253838Z","hd":{"ts_event":"2026-04-07T02:01:58.698234625Z","rtype":160,"publisher_id":101,"instrument_id":436},"action":"A","side":"A","price":"1.156660000","size":30,"channel_id":23,"order_id":"1775527318698240617","flags":128,"ts_in_delta":756,"sequence":142508,"symbol":"FCEU SI 20260615 PS"}
{"ts_recv":"2026-04-07T02:01:58.698325773Z","hd":{"ts_event":"2026-04-07T02:01:58.698306969Z","rtype":160,"publisher_id":101,"instrument_id":436},"action":"C","side":"B","price":"1.156560000","size":30,"channel_id":23,"order_id":"10998899355553016425","flags":0,"ts_in_delta":729,"sequence":142509,"symbol":"FCEU SI 20260615 PS"}
{"ts_recv":"2026-04-07T02:01:58.698325773Z","hd":{"ts_event":"2026-04-07T02:01:58.698306969Z","rtype":160,"publisher_id":101,"instrument_id":436},"action":"A","side":"B","price":"1.156570000","size":30,"channel_id":23,"order_id":"10998899355553088579","flags":0,"ts_in_delta":729,"sequence":142509,"symbol":"FCEU SI 20260615 PS"}
{"ts_recv":"2026-04-07T02:01:58.698325773Z","hd":{"ts_event":"2026-04-07T02:01:58.698306969Z","rtype":160,"publisher_id":101,"instrument_id":436},"action":"C","side":"A","price":"1.156660000","size":30,"channel_id":23,"order_id":"1775527318698240617","flags":0,"ts_in_delta":729,"sequence":142509,"symbol":"FCEU SI 20260615 PS"}
{"ts_recv":"2026-04-07T02:01:58.698325773Z","hd":{"ts_event":"2026-04-07T02:01:58.698306969Z","rtype":160,"publisher_id":101,"instrument_id":436},"action":"A","side":"A","price":"1.156670000","size":30,"channel_id":23,"order_id":"1775527318698312771","flags":128,"ts_in_delta":729,"sequence":142509,"symbol":"FCEU SI 20260615 PS"}
{"ts_recv":"2026-04-07T02:01:58.698380844Z","hd":{"ts_event":"2026-04-07T02:01:58.698364301Z","rtype":160,"publisher_id":101,"instrument_id":436},"action":"C","side":"B","price":"1.156570000","size":30,"channel_id":23,"order_id":"10998899355553088579","flags":0,"ts_in_delta":758,"sequence":142510,"symbol":"FCEU SI 20260615 PS"}
{"ts_recv":"2026-04-07T02:01:58.698380844Z","hd":{"ts_event":"2026-04-07T02:01:58.698364301Z","rtype":160,"publisher_id":101,"instrument_id":436},"action":"A","side":"B","price":"1.156560000","size":30,"channel_id":23,"order_id":"10998899355553145962","flags":0,"ts_in_delta":758,"sequence":142510,"symbol":"FCEU SI 20260615 PS"}
{"ts_recv":"2026-04-07T02:01:58.698380844Z","hd":{"ts_event":"2026-04-07T02:01:58.698364301Z","rtype":160,"publisher_id":101,"instrument_id":436},"action":"C","side":"A","price":"1.156670000","size":30,"channel_id":23,"order_id":"1775527318698312771","flags":0,"ts_in_delta":758,"sequence":142510,"symbol":"FCEU SI 20260615 PS"}
{"ts_recv":"2026-04-07T02:01:58.698380844Z","hd":{"ts_event":"2026-04-07T02:01:58.698364301Z","rtype":160,"publisher_id":101,"instrument_id":436},"action":"A","side":"A","price":"1.156660000","size":30,"channel_id":23,"order_id":"1775527318698370154","flags":128,"ts_in_delta":758,"sequence":142510,"symbol":"FCEU SI 20260615 PS"}
{"ts_recv":"2026-04-07T02:01:58.698402662Z","hd":{"ts_event":"2026-04-07T02:01:58.698380967Z","rtype":160,"publisher_id":101,"instrument_id":436},"action":"C","side":"B","price":"1.156550000","size":30,"channel_id":23,"order_id":"10998899353908055374","flags":0,"ts_in_delta":742,"sequence":142511,"symbol":"FCEU SI 20260615 PS"}
{"ts_recv":"2026-04-07T02:01:58.698402662Z","hd":{"ts_event":"2026-04-07T02:01:58.698380967Z","rtype":160,"publisher_id":101,"instrument_id":436},"action":"A","side":"B","price":"1.156570000","size":30,"channel_id":23,"order_id":"10998899355553166749","flags":0,"ts_in_delta":742,"sequence":142511,"symbol":"FCEU SI 20260615 PS"}
{"ts_recv":"2026-04-07T02:01:58.698402662Z","hd":{"ts_event":"2026-04-07T02:01:58.698380967Z","rtype":160,"publisher_id":101,"instrument_id":436},"action":"C","side":"A","price":"1.156650000","size":30,"channel_id":23,"order_id":"1775527317053279566","flags":0,"ts_in_delta":742,"sequence":142511,"symbol":"FCEU SI 20260615 PS"}
{"ts_recv":"2026-04-07T02:01:58.698402662Z","hd":{"ts_event":"2026-04-07T02:01:58.698380967Z","rtype":160,"publisher_id":101,"instrument_id":436},"action":"A","side":"A","price":"1.156670000","size":30,"channel_id":23,"order_id":"1775527318698390941","flags":128,"ts_in_delta":742,"sequence":142511,"symbol":"FCEU SI 20260615 PS"}
{"ts_recv":"2026-04-07T02:01:58.698458447Z","hd":{"ts_event":"2026-04-07T02:01:58.698440987Z","rtype":160,"publisher_id":101,"instrument_id":436},"action":"C","side":"B","price":"1.156560000","size":30,"channel_id":23,"order_id":"10998899355553145962","flags":0,"ts_in_delta":935,"sequence":142512,"symbol":"FCEU SI 20260615 PS"}
{"ts_recv":"2026-04-07T02:01:58.698458447Z","hd":{"ts_event":"2026-04-07T02:01:58.698440987Z","rtype":160,"publisher_id":101,"instrument_id":436},"action":"A","side":"B","price":"1.156570000","size":30,"channel_id":23,"order_id":"10998899355553222830","flags":0,"ts_in_delta":935,"sequence":142512,"symbol":"FCEU SI 20260615 PS"}
{"ts_recv":"2026-04-07T02:01:58.698458447Z","hd":{"ts_event":"2026-04-07T02:01:58.698440987Z","rtype":160,"publisher_id":101,"instrument_id":436},"action":"C","side":"A","price":"1.156660000","size":30,"channel_id":23,"order_id":"1775527318698370154","flags":0,"ts_in_delta":935,"sequence":142512,"symbol":"FCEU SI 20260615 PS"}
{"ts_recv":"2026-04-07T02:01:58.698458447Z","hd":{"ts_event":"2026-04-07T02:01:58.698440987Z","rtype":160,"publisher_id":101,"instrument_id":436},"action":"A","side":"A","price":"1.156670000","size":30,"channel_id":23,"order_id":"1775527318698447022","flags":128,"ts_in_delta":935,"sequence":142512,"symbol":"FCEU SI 20260615 PS"}
{"ts_recv":"2026-04-07T02:02:03.676517261Z","hd":{"ts_event":"2026-04-07T02:02:03.676484189Z","rtype":160,"publisher_id":101,"instrument_id":436},"action":"C","side":"B","price":"1.156570000","size":30,"channel_id":23,"order_id":"10998899355553222830","flags":0,"ts_in_delta":2052,"sequence":142549,"symbol":"FCEU SI 20260615 PS"}
{"ts_recv":"2026-04-07T02:02:03.676517261Z","hd":{"ts_event":"2026-04-07T02:02:03.676484189Z","rtype":160,"publisher_id":101,"instrument_id":436},"action":"A","side":"B","price":"1.156580000","size":30,"channel_id":23,"order_id":"10998899360531273321","flags":0,"ts_in_delta":2052,"sequence":142549,"symbol":"FCEU SI 20260615 PS"}
{"ts_recv":"2026-04-07T02:02:03.676517261Z","hd":{"ts_event":"2026-04-07T02:02:03.676484189Z","rtype":160,"publisher_id":101,"instrument_id":436},"action":"C","side":"A","price":"1.156670000","size":30,"channel_id":23,"order_id":"1775527318698447022","flags":0,"ts_in_delta":2052,"sequence":142549,"symbol":"FCEU SI 20260615 PS"}
{"ts_recv":"2026-04-07T02:02:03.676517261Z","hd":{"ts_event":"2026-04-07T02:02:03.676484189Z","rtype":160,"publisher_id":101,"instrument_id":436},"action":"A","side":"A","price":"1.156680000","size":30,"channel_id":23,"order_id":"1775527323676497513","flags":128,"ts_in_delta":2052,"sequence":142549,"symbol":"FCEU SI 20260615 PS"}
{"ts_recv":"2026-04-07T02:02:07.585842680Z","hd":{"ts_event":"2026-04-07T02:02:07.585822057Z","rtype":160,"publisher_id":101,"instrument_id":436},"action":"C","side":"B","price":"1.156580000","size":30,"channel_id":23,"order_id":"10998899360531273321","flags":0,"ts_in_delta":906,"sequence":142619,"symbol":"FCEU SI 20260615 PS"}
{"ts_recv":"2026-04-07T02:02:07.585842680Z","hd":{"ts_event":"2026-04-07T02:02:07.585822057Z","rtype":160,"publisher_id":101,"instrument_id":436},"action":"A","side":"B","price":"1.156590000","size":30,"channel_id":23,"order_id":"10998899364440603863","flags":0,"ts_in_delta":906,"sequence":142619,"symbol":"FCEU SI 20260615 PS"}
{"ts_recv":"2026-04-07T02:02:07.585842680Z","hd":{"ts_event":"2026-04-07T02:02:07.585822057Z","rtype":160,"publisher_id":101,"instrument_id":436},"action":"C","side":"A","price":"1.156680000","size":30,"channel_id":23,"order_id":"1775527323676497513","flags":0,"ts_in_delta":906,"sequence":142619,"symbol":"FCEU SI 20260615 PS"}
{"ts_recv":"2026-04-07T02:02:07.585842680Z","hd":{"ts_event":"2026-04-07T02:02:07.585822057Z","rtype":160,"publisher_id":101,"instrument_id":436},"action":"A","side":"A","price":"1.156690000","size":30,"channel_id":23,"order_id":"1775527327585828055","flags":128,"ts_in_delta":906,"sequence":142619,"symbol":"FCEU SI 20260615 PS"}
{"ts_recv":"2026-04-07T02:02:07.585900001Z","hd":{"ts_event":"2026-04-07T02:02:07.585880563Z","rtype":160,"publisher_id":101,"instrument_id":436},"action":"C","side":"B","price":"1.156570000","size":30,"channel_id":23,"order_id":"10998899355553166749","flags":0,"ts_in_delta":919,"sequence":142620,"symbol":"FCEU SI 20260615 PS"}
{"ts_recv":"2026-04-07T02:02:07.585900001Z","hd":{"ts_event":"2026-04-07T02:02:07.585880563Z","rtype":160,"publisher_id":101,"instrument_id":436},"action":"A","side":"B","price":"1.156590000","size":30,"channel_id":23,"order_id":"10998899364440662571","flags":0,"ts_in_delta":919,"sequence":142620,"symbol":"FCEU SI 20260615 PS"}
{"ts_recv":"2026-04-07T02:02:07.585900001Z","hd":{"ts_event":"2026-04-07T02:02:07.585880563Z","rtype":160,"publisher_id":101,"instrument_id":436},"action":"C","side":"A","price":"1.156670000","size":30,"channel_id":23,"order_id":"1775527318698390941","flags":0,"ts_in_delta":919,"sequence":142620,"symbol":"FCEU SI 20260615 PS"}
{"ts_recv":"2026-04-07T02:02:07.585900001Z","hd":{"ts_event":"2026-04-07T02:02:07.585880563Z","rtype":160,"publisher_id":101,"instrument_id":436},"action":"A","side":"A","price":"1.156690000","size":30,"channel_id":23,"order_id":"1775527327585886763","flags":128,"ts_in_delta":919,"sequence":142620,"symbol":"FCEU SI 20260615 PS"}
{"ts_recv":"2026-04-07T02:02:19.063446001Z","hd":{"ts_event":"2026-04-07T02:02:19.063422365Z","rtype":160,"publisher_id":101,"instrument_id":436},"action":"C","side":"B","price":"1.156590000","size":30,"channel_id":23,"order_id":"10998899364440603863","flags":0,"ts_in_delta":927,"sequence":142787,"symbol":"FCEU SI 20260615 PS"}
{"ts_recv":"2026-04-07T02:02:19.063446001Z","hd":{"ts_event":"2026-04-07T02:02:19.063422365Z","rtype":160,"publisher_id":101,"instrument_id":436},"action":"A","side":"B","price":"1.156600000","size":30,"channel_id":23,"order_id":"10998899375918204220","flags":0,"ts_in_delta":927,"sequence":142787,"symbol":"FCEU SI 20260615 PS"}
{"ts_recv":"2026-04-07T02:02:19.063446001Z","hd":{"ts_event":"2026-04-07T02:02:19.063422365Z","rtype":160,"publisher_id":101,"instrument_id":436},"action":"C","side":"A","price":"1.156690000","size":30,"channel_id":23,"order_id":"1775527327585828055","flags":0,"ts_in_delta":927,"sequence":142787,"symbol":"FCEU SI 20260615 PS"}
{"ts_recv":"2026-04-07T02:02:19.063446001Z","hd":{"ts_event":"2026-04-07T02:02:19.063422365Z","rtype":160,"publisher_id":101,"instrument_id":436},"action":"A","side":"A","price":"1.156700000","size":30,"channel_id":23,"order_id":"1775527339063428412","flags":128,"ts_in_delta":927,"sequence":142787,"symbol":"FCEU SI 20260615 PS"}
{"ts_recv":"2026-04-07T02:02:25.650798660Z","hd":{"ts_event":"2026-04-07T02:02:25.650770369Z","rtype":160,"publisher_id":101,"instrument_id":436},"action":"C","side":"B","price":"1.156600000","size":30,"channel_id":23,"order_id":"10998899375918204220","flags":0,"ts_in_delta":1283,"sequence":142849,"symbol":"FCEU SI 20260615 PS"}
{"ts_recv":"2026-04-07T02:02:25.650798660Z","hd":{"ts_event":"2026-04-07T02:02:25.650770369Z","rtype":160,"publisher_id":101,"instrument_id":436},"action":"A","side":"B","price":"1.156590000","size":30,"channel_id":23,"order_id":"10998899382505557461","flags":0,"ts_in_delta":1283,"sequence":142849,"symbol":"FCEU SI 20260615 PS"}
{"ts_recv":"2026-04-07T02:02:25.650798660Z","hd":{"ts_event":"2026-04-07T02:02:25.650770369Z","rtype":160,"publisher_id":101,"instrument_id":436},"action":"C","side":"A","price":"1.156700000","size":30,"channel_id":23,"order_id":"1775527339063428412","flags":0,"ts_in_delta":1283,"sequence":142849,"symbol":"FCEU SI 20260615 PS"}
{"ts_recv":"2026-04-07T02:02:25.650798660Z","hd":{"ts_event":"2026-04-07T02:02:25.650770369Z","rtype":160,"publisher_id":101,"instrument_id":436},"action":"A","side":"A","price":"1.156690000","size":30,"channel_id":23,"order_id":"1775527345650781653","flags":128,"ts_in_delta":1283,"sequence":142849,"symbol":"FCEU SI 20260615 PS"}
{"ts_recv":"2026-04-07T02:02:36.879833171Z","hd":{"ts_event":"2026-04-07T02:02:36.879810807Z","rtype":160,"publisher_id":101,"instrument_id":436},"action":"C","side":"B","price":"1.156590000","size":30,"channel_id":23,"order_id":"10998899382505557461","flags":0,"ts_in_delta":931,"sequence":142958,"symbol":"FCEU SI 20260615 PS"}
{"ts_recv":"2026-04-07T02:02:36.879833171Z","hd":{"ts_event":"2026-04-07T02:02:36.879810807Z","rtype":160,"publisher_id":101,"instrument_id":436},"action":"A","side":"B","price":"1.156600000","size":30,"channel_id":23,"order_id":"10998899393734592981","flags":0,"ts_in_delta":931,"sequence":142958,"symbol":"FCEU SI 20260615 PS"}
{"ts_recv":"2026-04-07T02:02:36.879833171Z","hd":{"ts_event":"2026-04-07T02:02:36.879810807Z","rtype":160,"publisher_id":101,"instrument_id":436},"action":"C","side":"A","price":"1.156690000","size":30,"channel_id":23,"order_id":"1775527345650781653","flags":0,"ts_in_delta":931,"sequence":142958,"symbol":"FCEU SI 20260615 PS"}
{"ts_recv":"2026-04-07T02:02:36.879833171Z","hd":{"ts_event":"2026-04-07T02:02:36.879810807Z","rtype":160,"publisher_id":101,"instrument_id":436},"action":"A","side":"A","price":"1.156700000","size":30,"channel_id":23,"order_id":"1775527356879817173","flags":128,"ts_in_delta":931,"sequence":142958,"symbol":"FCEU SI 20260615 PS"}
{"ts_recv":"2026-04-07T02:02:36.890676994Z","hd":{"ts_event":"2026-04-07T02:02:36.890653293Z","rtype":160,"publisher_id":101,"instrument_id":436},"action":"C","side":"B","price":"1.156590000","size":30,"channel_id":23,"order_id":"10998899364440662571","flags":0,"ts_in_delta":929,"sequence":142959,"symbol":"FCEU SI 20260615 PS"}
{"ts_recv":"2026-04-07T02:02:36.890676994Z","hd":{"ts_event":"2026-04-07T02:02:36.890653293Z","rtype":160,"publisher_id":101,"instrument_id":436},"action":"A","side":"B","price":"1.156610000","size":30,"channel_id":23,"order_id":"10998899393745435492","flags":0,"ts_in_delta":929,"sequence":142959,"symbol":"FCEU SI 20260615 PS"}
{"ts_recv":"2026-04-07T02:02:36.890676994Z","hd":{"ts_event":"2026-04-07T02:02:36.890653293Z","rtype":160,"publisher_id":101,"instrument_id":436},"action":"C","side":"A","price":"1.156690000","size":30,"channel_id":23,"order_id":"1775527327585886763","flags":0,"ts_in_delta":929,"sequence":142959,"symbol":"FCEU SI 20260615 PS"}
{"ts_recv":"2026-04-07T02:02:36.890676994Z","hd":{"ts_event":"2026-04-07T02:02:36.890653293Z","rtype":160,"publisher_id":101,"instrument_id":436},"action":"A","side":"A","price":"1.156710000","size":30,"channel_id":23,"order_id":"1775527356890659684","flags":128,"ts_in_delta":929,"sequence":142959,"symbol":"FCEU SI 20260615 PS"}
{"ts_recv":"2026-04-07T02:02:36.890744844Z","hd":{"ts_event":"2026-04-07T02:02:36.890728537Z","rtype":160,"publisher_id":101,"instrument_id":436},"action":"C","side":"B","price":"1.156600000","size":30,"channel_id":23,"order_id":"10998899393734592981","flags":0,"ts_in_delta":900,"sequence":142960,"symbol":"FCEU SI 20260615 PS"}
{"ts_recv":"2026-04-07T02:02:36.890744844Z","hd":{"ts_event":"2026-04-07T02:02:36.890728537Z","rtype":160,"publisher_id":101,"instrument_id":436},"action":"A","side":"B","price":"1.156610000","size":30,"channel_id":23,"order_id":"10998899393745510358","flags":0,"ts_in_delta":900,"sequence":142960,"symbol":"FCEU SI 20260615 PS"}
{"ts_recv":"2026-04-07T02:02:36.890744844Z","hd":{"ts_event":"2026-04-07T02:02:36.890728537Z","rtype":160,"publisher_id":101,"instrument_id":436},"action":"C","side":"A","price":"1.156700000","size":30,"channel_id":23,"order_id":"1775527356879817173","flags":0,"ts_in_delta":900,"sequence":142960,"symbol":"FCEU SI 20260615 PS"}
{"ts_recv":"2026-04-07T02:02:36.890744844Z","hd":{"ts_event":"2026-04-07T02:02:36.890728537Z","rtype":160,"publisher_id":101,"instrument_id":436},"action":"A","side":"A","price":"1.156710000","size":30,"channel_id":23,"order_id":"1775527356890734550","flags":128,"ts_in_delta":900,"sequence":142960,"symbol":"FCEU SI 20260615 PS"}
{"ts_recv":"2026-04-07T02:02:38.705728542Z","hd":{"ts_event":"2026-04-07T02:02:38.705708399Z","rtype":160,"publisher_id":101,"instrument_id":436},"action":"C","side":"B","price":"1.156610000","size":30,"channel_id":23,"order_id":"10998899393745510358","flags":0,"ts_in_delta":1023,"sequence":142999,"symbol":"FCEU SI 20260615 PS"}
{"ts_recv":"2026-04-07T02:02:38.705728542Z","hd":{"ts_event":"2026-04-07T02:02:38.705708399Z","rtype":160,"publisher_id":101,"instrument_id":436},"action":"A","side":"B","price":"1.156620000","size":30,"channel_id":23,"order_id":"10998899395560490348","flags":0,"ts_in_delta":1023,"sequence":142999,"symbol":"FCEU SI 20260615 PS"}
{"ts_recv":"2026-04-07T02:02:38.705728542Z","hd":{"ts_event":"2026-04-07T02:02:38.705708399Z","rtype":160,"publisher_id":101,"instrument_id":436},"action":"C","side":"A","price":"1.156710000","size":30,"channel_id":23,"order_id":"1775527356890734550","flags":0,"ts_in_delta":1023,"sequence":142999,"symbol":"FCEU SI 20260615 PS"}
{"ts_recv":"2026-04-07T02:02:38.705728542Z","hd":{"ts_event":"2026-04-07T02:02:38.705708399Z","rtype":160,"publisher_id":101,"instrument_id":436},"action":"A","side":"A","price":"1.156720000","size":30,"channel_id":23,"order_id":"1775527358705714540","flags":128,"ts_in_delta":1023,"sequence":142999,"symbol":"FCEU SI 20260615 PS"}
{"ts_recv":"2026-04-07T02:02:38.770954494Z","hd":{"ts_event":"2026-04-07T02:02:38.770935529Z","rtype":160,"publisher_id":101,"instrument_id":436},"action":"C","side":"B","price":"1.156610000","size":30,"channel_id":23,"order_id":"10998899393745435492","flags":0,"ts_in_delta":921,"sequence":143002,"symbol":"FCEU SI 20260615 PS"}
{"ts_recv":"2026-04-07T02:02:38.770954494Z","hd":{"ts_event":"2026-04-07T02:02:38.770935529Z","rtype":160,"publisher_id":101,"instrument_id":436},"action":"A","side":"B","price":"1.156630000","size":30,"channel_id":23,"order_id":"10998899395625717471","flags":0,"ts_in_delta":921,"sequence":143002,"symbol":"FCEU SI 20260615 PS"}
{"ts_recv":"2026-04-07T02:02:38.770954494Z","hd":{"ts_event":"2026-04-07T02:02:38.770935529Z","rtype":160,"publisher_id":101,"instrument_id":436},"action":"C","side":"A","price":"1.156710000","size":30,"channel_id":23,"order_id":"1775527356890659684","flags":0,"ts_in_delta":921,"sequence":143002,"symbol":"FCEU SI 20260615 PS"}
{"ts_recv":"2026-04-07T02:02:38.770954494Z","hd":{"ts_event":"2026-04-07T02:02:38.770935529Z","rtype":160,"publisher_id":101,"instrument_id":436},"action":"A","side":"A","price":"1.156730000","size":30,"channel_id":23,"order_id":"1775527358770941663","flags":128,"ts_in_delta":921,"sequence":143002,"symbol":"FCEU SI 20260615 PS"}
{"ts_recv":"2026-04-07T02:02:38.771038679Z","hd":{"ts_event":"2026-04-07T02:02:38.771017981Z","rtype":160,"publisher_id":101,"instrument_id":436},"action":"C","side":"B","price":"1.156620000","size":30,"channel_id":23,"order_id":"10998899395560490348","flags":0,"ts_in_delta":1112,"sequence":143003,"symbol":"FCEU SI 20260615 PS"}
{"ts_recv":"2026-04-07T02:02:38.771038679Z","hd":{"ts_event":"2026-04-07T02:02:38.771017981Z","rtype":160,"publisher_id":101,"instrument_id":436},"action":"A","side":"B","price":"1.156630000","size":30,"channel_id":23,"order_id":"10998899395625799881","flags":0,"ts_in_delta":1112,"sequence":143003,"symbol":"FCEU SI 20260615 PS"}
{"ts_recv":"2026-04-07T02:02:38.771038679Z","hd":{"ts_event":"2026-04-07T02:02:38.771017981Z","rtype":160,"publisher_id":101,"instrument_id":436},"action":"C","side":"A","price":"1.156720000","size":30,"channel_id":23,"order_id":"1775527358705714540","flags":0,"ts_in_delta":1112,"sequence":143003,"symbol":"FCEU SI 20260615 PS"}
{"ts_recv":"2026-04-07T02:02:38.771038679Z","hd":{"ts_event":"2026-04-07T02:02:38.771017981Z","rtype":160,"publisher_id":101,"instrument_id":436},"action":"A","side":"A","price":"1.156730000","size":30,"channel_id":23,"order_id":"1775527358771024073","flags":128,"ts_in_delta":1112,"sequence":143003,"symbol":"FCEU SI 20260615 PS"}
{"ts_recv":"2026-04-07T02:02:58.706943885Z","hd":{"ts_event":"2026-04-07T02:02:58.706921561Z","rtype":160,"publisher_id":101,"instrument_id":436},"action":"C","side":"B","price":"1.156630000","size":30,"channel_id":23,"order_id":"10998899395625717471","flags":0,"ts_in_delta":776,"sequence":143279,"symbol":"FCEU SI 20260615 PS"}
{"ts_recv":"2026-04-07T02:02:58.706943885Z","hd":{"ts_event":"2026-04-07T02:02:58.706921561Z","rtype":160,"publisher_id":101,"instrument_id":436},"action":"A","side":"B","price":"1.156610000","size":30,"channel_id":23,"order_id":"10998899415561703273","flags":0,"ts_in_delta":776,"sequence":143279,"symbol":"FCEU SI 20260615 PS"}
{"ts_recv":"2026-04-07T02:02:58.706943885Z","hd":{"ts_event":"2026-04-07T02:02:58.706921561Z","rtype":160,"publisher_id":101,"instrument_id":436},"action":"C","side":"A","price":"1.156730000","size":30,"channel_id":23,"order_id":"1775527358770941663","flags":0,"ts_in_delta":776,"sequence":143279,"symbol":"FCEU SI 20260615 PS"}
{"ts_recv":"2026-04-07T02:02:58.706943885Z","hd":{"ts_event":"2026-04-07T02:02:58.706921561Z","rtype":160,"publisher_id":101,"instrument_id":436},"action":"A","side":"A","price":"1.156710000","size":30,"channel_id":23,"order_id":"1775527378706927465","flags":128,"ts_in_delta":776,"sequence":143279,"symbol":"FCEU SI 20260615 PS"}
{"ts_recv":"2026-04-07T02:02:58.707005883Z","hd":{"ts_event":"2026-04-07T02:02:58.706990199Z","rtype":160,"publisher_id":101,"instrument_id":436},"action":"C","side":"B","price":"1.156630000","size":30,"channel_id":23,"order_id":"10998899395625799881","flags":0,"ts_in_delta":801,"sequence":143280,"symbol":"FCEU SI 20260615 PS"}
{"ts_recv":"2026-04-07T02:02:58.707005883Z","hd":{"ts_event":"2026-04-07T02:02:58.706990199Z","rtype":160,"publisher_id":101,"instrument_id":436},"action":"A","side":"B","price":"1.156620000","size":30,"channel_id":23,"order_id":"10998899415561771707","flags":0,"ts_in_delta":801,"sequence":143280,"symbol":"FCEU SI 20260615 PS"}
{"ts_recv":"2026-04-07T02:02:58.707005883Z","hd":{"ts_event":"2026-04-07T02:02:58.706990199Z","rtype":160,"publisher_id":101,"instrument_id":436},"action":"C","side":"A","price":"1.156730000","size":30,"channel_id":23,"order_id":"1775527358771024073","flags":0,"ts_in_delta":801,"sequence":143280,"symbol":"FCEU SI 20260615 PS"}
{"ts_recv":"2026-04-07T02:02:58.707005883Z","hd":{"ts_event":"2026-04-07T02:02:58.706990199Z","rtype":160,"publisher_id":101,"instrument_id":436},"action":"A","side":"A","price":"1.156720000","size":30,"channel_id":23,"order_id":"1775527378706995899","flags":128,"ts_in_delta":801,"sequence":143280,"symbol":"FCEU SI 20260615 PS"}
{"ts_recv":"2026-04-07T02:02:58.707486997Z","hd":{"ts_event":"2026-04-07T02:02:58.707465243Z","rtype":160,"publisher_id":101,"instrument_id":436},"action":"C","side":"B","price":"1.156620000","size":30,"channel_id":23,"order_id":"10998899415561771707","flags":0,"ts_in_delta":789,"sequence":143281,"symbol":"FCEU SI 20260615 PS"}
{"ts_recv":"2026-04-07T02:02:58.707486997Z","hd":{"ts_event":"2026-04-07T02:02:58.707465243Z","rtype":160,"publisher_id":101,"instrument_id":436},"action":"A","side":"B","price":"1.156600000","size":30,"channel_id":23,"order_id":"10998899415562246960","flags":0,"ts_in_delta":789,"sequence":143281,"symbol":"FCEU SI 20260615 PS"}
{"ts_recv":"2026-04-07T02:02:58.707486997Z","hd":{"ts_event":"2026-04-07T02:02:58.707465243Z","rtype":160,"publisher_id":101,"instrument_id":436},"action":"C","side":"A","price":"1.156720000","size":30,"channel_id":23,"order_id":"1775527378706995899","flags":0,"ts_in_delta":789,"sequence":143281,"symbol":"FCEU SI 20260615 PS"}
{"ts_recv":"2026-04-07T02:02:58.707486997Z","hd":{"ts_event":"2026-04-07T02:02:58.707465243Z","rtype":160,"publisher_id":101,"instrument_id":436},"action":"A","side":"A","price":"1.156700000","size":30,"channel_id":23,"order_id":"1775527378707471152","flags":128,"ts_in_delta":789,"sequence":143281,"symbol":"FCEU SI 20260615 PS"}
{"ts_recv":"2026-04-07T02:02:58.717078056Z","hd":{"ts_event":"2026-04-07T02:02:58.717056193Z","rtype":160,"publisher_id":101,"instrument_id":436},"action":"C","side":"B","price":"1.156610000","size":30,"channel_id":23,"order_id":"10998899415561703273","flags":0,"ts_in_delta":982,"sequence":143289,"symbol":"FCEU SI 20260615 PS"}
{"ts_recv":"2026-04-07T02:02:58.717078056Z","hd":{"ts_event":"2026-04-07T02:02:58.717056193Z","rtype":160,"publisher_id":101,"instrument_id":436},"action":"A","side":"B","price":"1.156590000","size":30,"channel_id":23,"order_id":"10998899415571838139","flags":0,"ts_in_delta":982,"sequence":143289,"symbol":"FCEU SI 20260615 PS"}
{"ts_recv":"2026-04-07T02:02:58.717078056Z","hd":{"ts_event":"2026-04-07T02:02:58.717056193Z","rtype":160,"publisher_id":101,"instrument_id":436},"action":"C","side":"A","price":"1.156710000","size":30,"channel_id":23,"order_id":"1775527378706927465","flags":0,"ts_in_delta":982,"sequence":143289,"symbol":"FCEU SI 20260615 PS"}
{"ts_recv":"2026-04-07T02:02:58.717078056Z","hd":{"ts_event":"2026-04-07T02:02:58.717056193Z","rtype":160,"publisher_id":101,"instrument_id":436},"action":"A","side":"A","price":"1.156690000","size":30,"channel_id":23,"order_id":"1775527378717062331","flags":128,"ts_in_delta":982,"sequence":143289,"symbol":"FCEU SI 20260615 PS"}
{"ts_recv":"2026-04-07T02:02:58.717137389Z","hd":{"ts_event":"2026-04-07T02:02:58.717120459Z","rtype":160,"publisher_id":101,"instrument_id":436},"action":"C","side":"B","price":"1.156600000","size":30,"channel_id":23,"order_id":"10998899415562246960","flags":0,"ts_in_delta":985,"sequence":143290,"symbol":"FCEU SI 20260615 PS"}
{"ts_recv":"2026-04-07T02:02:58.717137389Z","hd":{"ts_event":"2026-04-07T02:02:58.717120459Z","rtype":160,"publisher_id":101,"instrument_id":436},"action":"A","side":"B","price":"1.156590000","size":30,"channel_id":23,"order_id":"10998899415571902117","flags":0,"ts_in_delta":985,"sequence":143290,"symbol":"FCEU SI 20260615 PS"}
{"ts_recv":"2026-04-07T02:02:58.717137389Z","hd":{"ts_event":"2026-04-07T02:02:58.717120459Z","rtype":160,"publisher_id":101,"instrument_id":436},"action":"C","side":"A","price":"1.156700000","size":30,"channel_id":23,"order_id":"1775527378707471152","flags":0,"ts_in_delta":985,"sequence":143290,"symbol":"FCEU SI 20260615 PS"}
{"ts_recv":"2026-04-07T02:02:58.717137389Z","hd":{"ts_event":"2026-04-07T02:02:58.717120459Z","rtype":160,"publisher_id":101,"instrument_id":436},"action":"A","side":"A","price":"1.156690000","size":30,"channel_id":23,"order_id":"1775527378717126309","flags":128,"ts_in_delta":985,"sequence":143290,"symbol":"FCEU SI 20260615 PS"}
{"ts_recv":"2026-04-07T02:03:04.157538232Z","hd":{"ts_event":"2026-04-07T02:03:04.157516177Z","rtype":160,"publisher_id":101,"instrument_id":436},"action":"C","side":"B","price":"1.156590000","size":30,"channel_id":23,"order_id":"10998899415571902117","flags":0,"ts_in_delta":1001,"sequence":143432,"symbol":"FCEU SI 20260615 PS"}
{"ts_recv":"2026-04-07T02:03:04.157538232Z","hd":{"ts_event":"2026-04-07T02:03:04.157516177Z","rtype":160,"publisher_id":101,"instrument_id":436},"action":"A","side":"B","price":"1.156600000","size":30,"channel_id":23,"order_id":"10998899421012298391","flags":0,"ts_in_delta":1001,"sequence":143432,"symbol":"FCEU SI 20260615 PS"}
{"ts_recv":"2026-04-07T02:03:04.157538232Z","hd":{"ts_event":"2026-04-07T02:03:04.157516177Z","rtype":160,"publisher_id":101,"instrument_id":436},"action":"C","side":"A","price":"1.156690000","size":30,"channel_id":23,"order_id":"1775527378717126309","flags":0,"ts_in_delta":1001,"sequence":143432,"symbol":"FCEU SI 20260615 PS"}
{"ts_recv":"2026-04-07T02:03:04.157538232Z","hd":{"ts_event":"2026-04-07T02:03:04.157516177Z","rtype":160,"publisher_id":101,"instrument_id":436},"action":"A","side":"A","price":"1.156700000","size":30,"channel_id":23,"order_id":"1775527384157522583","flags":128,"ts_in_delta":1001,"sequence":143432,"symbol":"FCEU SI 20260615 PS"}
{"ts_recv":"2026-04-07T02:03:04.191491068Z","hd":{"ts_event":"2026-04-07T02:03:04.191468377Z","rtype":160,"publisher_id":101,"instrument_id":436},"action":"C","side":"B","price":"1.156590000","size":30,"channel_id":23,"order_id":"10998899415571838139","flags":0,"ts_in_delta":895,"sequence":143446,"symbol":"FCEU SI 20260615 PS"}
{"ts_recv":"2026-04-07T02:03:04.191491068Z","hd":{"ts_event":"2026-04-07T02:03:04.191468377Z","rtype":160,"publisher_id":101,"instrument_id":436},"action":"A","side":"B","price":"1.156610000","size":30,"channel_id":23,"order_id":"10998899421046250270","flags":0,"ts_in_delta":895,"sequence":143446,"symbol":"FCEU SI 20260615 PS"}
{"ts_recv":"2026-04-07T02:03:04.191491068Z","hd":{"ts_event":"2026-04-07T02:03:04.191468377Z","rtype":160,"publisher_id":101,"instrument_id":436},"action":"C","side":"A","price":"1.156690000","size":30,"channel_id":23,"order_id":"1775527378717062331","flags":0,"ts_in_delta":895,"sequence":143446,"symbol":"FCEU SI 20260615 PS"}
{"ts_recv":"2026-04-07T02:03:04.191491068Z","hd":{"ts_event":"2026-04-07T02:03:04.191468377Z","rtype":160,"publisher_id":101,"instrument_id":436},"action":"A","side":"A","price":"1.156710000","size":30,"channel_id":23,"order_id":"1775527384191474462","flags":128,"ts_in_delta":895,"sequence":143446,"symbol":"FCEU SI 20260615 PS"}
{"ts_recv":"2026-04-07T02:03:04.191553534Z","hd":{"ts_event":"2026-04-07T02:03:04.191536825Z","rtype":160,"publisher_id":101,"instrument_id":436},"action":"C","side":"B","price":"1.156600000","size":30,"channel_id":23,"order_id":"10998899421012298391","flags":0,"ts_in_delta":951,"sequence":143447,"symbol":"FCEU SI 20260615 PS"}
{"ts_recv":"2026-04-07T02:03:04.191553534Z","hd":{"ts_event":"2026-04-07T02:03:04.191536825Z","rtype":160,"publisher_id":101,"instrument_id":436},"action":"A","side":"B","price":"1.156610000","size":30,"channel_id":23,"order_id":"10998899421046318775","flags":0,"ts_in_delta":951,"sequence":143447,"symbol":"FCEU SI 20260615 PS"}
{"ts_recv":"2026-04-07T02:03:04.191553534Z","hd":{"ts_event":"2026-04-07T02:03:04.191536825Z","rtype":160,"publisher_id":101,"instrument_id":436},"action":"C","side":"A","price":"1.156700000","size":30,"channel_id":23,"order_id":"1775527384157522583","flags":0,"ts_in_delta":951,"sequence":143447,"symbol":"FCEU SI 20260615 PS"}
{"ts_recv":"2026-04-07T02:03:04.191553534Z","hd":{"ts_event":"2026-04-07T02:03:04.191536825Z","rtype":160,"publisher_id":101,"instrument_id":436},"action":"A","side":"A","price":"1.156710000","size":30,"channel_id":23,"order_id":"1775527384191542967","flags":128,"ts_in_delta":951,"sequence":143447,"symbol":"FCEU SI 20260615 PS"}
{"ts_recv":"2026-04-07T02:03:04.348719871Z","hd":{"ts_event":"2026-04-07T02:03:04.348698949Z","rtype":160,"publisher_id":101,"instrument_id":436},"action":"C","side":"B","price":"1.156610000","size":30,"channel_id":23,"order_id":"10998899421046318775","flags":0,"ts_in_delta":901,"sequence":143481,"symbol":"FCEU SI 20260615 PS"}
{"ts_recv":"2026-04-07T02:03:04.348719871Z","hd":{"ts_event":"2026-04-07T02:03:04.348698949Z","rtype":160,"publisher_id":101,"instrument_id":436},"action":"A","side":"B","price":"1.156620000","size":30,"channel_id":23,"order_id":"10998899421203480963","flags":0,"ts_in_delta":901,"sequence":143481,"symbol":"FCEU SI 20260615 PS"}
{"ts_recv":"2026-04-07T02:03:04.348719871Z","hd":{"ts_event":"2026-04-07T02:03:04.348698949Z","rtype":160,"publisher_id":101,"instrument_id":436},"action":"C","side":"A","price":"1.156710000","size":30,"channel_id":23,"order_id":"1775527384191542967","flags":0,"ts_in_delta":901,"sequence":143481,"symbol":"FCEU SI 20260615 PS"}
{"ts_recv":"2026-04-07T02:03:04.348719871Z","hd":{"ts_event":"2026-04-07T02:03:04.348698949Z","rtype":160,"publisher_id":101,"instrument_id":436},"action":"A","side":"A","price":"1.156720000","size":30,"channel_id":23,"order_id":"1775527384348705155","flags":128,"ts_in_delta":901,"sequence":143481,"symbol":"FCEU SI 20260615 PS"}
{"ts_recv":"2026-04-07T02:03:05.159527401Z","hd":{"ts_event":"2026-04-07T02:03:05.159502589Z","rtype":160,"publisher_id":101,"instrument_id":436},"action":"C","side":"B","price":"1.156620000","size":30,"channel_id":23,"order_id":"10998899421203480963","flags":0,"ts_in_delta":1444,"sequence":143505,"symbol":"FCEU SI 20260615 PS"}
{"ts_recv":"2026-04-07T02:03:05.159527401Z","hd":{"ts_event":"2026-04-07T02:03:05.159502589Z","rtype":160,"publisher_id":101,"instrument_id":436},"action":"A","side":"B","price":"1.156610000","size":30,"channel_id":23,"order_id":"10998899422014289148","flags":0,"ts_in_delta":1444,"sequence":143505,"symbol":"FCEU SI 20260615 PS"}
{"ts_recv":"2026-04-07T02:03:05.159527401Z","hd":{"ts_event":"2026-04-07T02:03:05.159502589Z","rtype":160,"publisher_id":101,"instrument_id":436},"action":"C","side":"A","price":"1.156720000","size":30,"channel_id":23,"order_id":"1775527384348705155","flags":0,"ts_in_delta":1444,"sequence":143505,"symbol":"FCEU SI 20260615 PS"}
{"ts_recv":"2026-04-07T02:03:05.159527401Z","hd":{"ts_event":"2026-04-07T02:03:05.159502589Z","rtype":160,"publisher_id":101,"instrument_id":436},"action":"A","side":"A","price":"1.156710000","size":30,"channel_id":23,"order_id":"1775527385159513340","flags":128,"ts_in_delta":1444,"sequence":143505,"symbol":"FCEU SI 20260615 PS"}
{"ts_recv":"2026-04-07T02:03:09.735172844Z","hd":{"ts_event":"2026-04-07T02:03:09.735153711Z","rtype":160,"publisher_id":101,"instrument_id":436},"action":"C","side":"B","price":"1.156610000","size":30,"channel_id":23,"order_id":"10998899422014289148","flags":0,"ts_in_delta":920,"sequence":143561,"symbol":"FCEU SI 20260615 PS"}
{"ts_recv":"2026-04-07T02:03:09.735172844Z","hd":{"ts_event":"2026-04-07T02:03:09.735153711Z","rtype":160,"publisher_id":101,"instrument_id":436},"action":"A","side":"B","price":"1.156620000","size":30,"channel_id":23,"order_id":"10998899426589935398","flags":0,"ts_in_delta":920,"sequence":143561,"symbol":"FCEU SI 20260615 PS"}
{"ts_recv":"2026-04-07T02:03:09.735172844Z","hd":{"ts_event":"2026-04-07T02:03:09.735153711Z","rtype":160,"publisher_id":101,"instrument_id":436},"action":"C","side":"A","price":"1.156710000","size":30,"channel_id":23,"order_id":"1775527385159513340","flags":0,"ts_in_delta":920,"sequence":143561,"symbol":"FCEU SI 20260615 PS"}
{"ts_recv":"2026-04-07T02:03:09.735172844Z","hd":{"ts_event":"2026-04-07T02:03:09.735153711Z","rtype":160,"publisher_id":101,"instrument_id":436},"action":"A","side":"A","price":"1.156720000","size":30,"channel_id":23,"order_id":"1775527389735159590","flags":128,"ts_in_delta":920,"sequence":143561,"symbol":"FCEU SI 20260615 PS"}
{"ts_recv":"2026-04-07T02:03:09.800538271Z","hd":{"ts_event":"2026-04-07T02:03:09.800516133Z","rtype":160,"publisher_id":101,"instrument_id":436},"action":"C","side":"B","price":"1.156610000","size":30,"channel_id":23,"order_id":"10998899421046250270","flags":0,"ts_in_delta":1246,"sequence":143573,"symbol":"FCEU SI 20260615 PS"}
{"ts_recv":"2026-04-07T02:03:09.800538271Z","hd":{"ts_event":"2026-04-07T02:03:09.800516133Z","rtype":160,"publisher_id":101,"instrument_id":436},"action":"A","side":"B","price":"1.156630000","size":30,"channel_id":23,"order_id":"10998899426655298245","flags":0,"ts_in_delta":1246,"sequence":143573,"symbol":"FCEU SI 20260615 PS"}
