{"ts_recv":"2026-04-07T02:14:20.580721731Z","hd":{"ts_event":"2026-04-07T02:14:20.580705585Z","rtype":160,"publisher_id":101,"instrument_id":436},"action":"C","side":"B","price":"1.156320000","size":30,"channel_id":23,"order_id":"10998900083314287018","flags":0,"ts_in_delta":1041,"sequence":153307,"symbol":"FCEU SI 20260615 PS"}
{"ts_recv":"2026-04-07T02:14:20.580721731Z","hd":{"ts_event":"2026-04-07T02:14:20.580705585Z","rtype":160,"publisher_id":101,"instrument_id":436},"action":"A","side":"B","price":"1.156330000","size":30,"channel_id":23,"order_id":"10998900097435487374","flags":0,"ts_in_delta":1041,"sequence":153307,"symbol":"FCEU SI 20260615 PS"}
{"ts_recv":"2026-04-07T02:14:20.580721731Z","hd":{"ts_event":"2026-04-07T02:14:20.580705585Z","rtype":160,"publisher_id":101,"instrument_id":436},"action":"C","side":"A","price":"1.156420000","size":30,"channel_id":23,"order_id":"1775528046459511210","flags":0,"ts_in_delta":1041,"sequence":153307,"symbol":"FCEU SI 20260615 PS"}
{"ts_recv":"2026-04-07T02:14:20.580721731Z","hd":{"ts_event":"2026-04-07T02:14:20.580705585Z","rtype":160,"publisher_id":101,"instrument_id":436},"action":"A","side":"A","price":"1.156430000","size":30,"channel_id":23,"order_id":"1775528060580711566","flags":128,"ts_in_delta":1041,"sequence":153307,"symbol":"FCEU SI 20260615 PS"}
{"ts_recv":"2026-04-07T02:14:20.594156781Z","hd":{"ts_event":"2026-04-07T02:14:20.594140909Z","rtype":160,"publisher_id":101,"instrument_id":436},"action":"C","side":"B","price":"1.156330000","size":30,"channel_id":23,"order_id":"10998900097435487374","flags":0,"ts_in_delta":1096,"sequence":153310,"symbol":"FCEU SI 20260615 PS"}
{"ts_recv":"2026-04-07T02:14:20.594156781Z","hd":{"ts_event":"2026-04-07T02:14:20.594140909Z","rtype":160,"publisher_id":101,"instrument_id":436},"action":"A","side":"B","price":"1.156340000","size":30,"channel_id":23,"order_id":"10998900097448922734","flags":0,"ts_in_delta":1096,"sequence":153310,"symbol":"FCEU SI 20260615 PS"}
{"ts_recv":"2026-04-07T02:14:20.594156781Z","hd":{"ts_event":"2026-04-07T02:14:20.594140909Z","rtype":160,"publisher_id":101,"instrument_id":436},"action":"C","side":"A","price":"1.156430000","size":30,"channel_id":23,"order_id":"1775528060580711566","flags":0,"ts_in_delta":1096,"sequence":153310,"symbol":"FCEU SI 20260615 PS"}
{"ts_recv":"2026-04-07T02:14:20.594156781Z","hd":{"ts_event":"2026-04-07T02:14:20.594140909Z","rtype":160,"publisher_id":101,"instrument_id":436},"action":"A","side":"A","price":"1.156440000","size":30,"channel_id":23,"order_id":"1775528060594146926","flags":128,"ts_in_delta":1096,"sequence":153310,"symbol":"FCEU SI 20260615 PS"}
{"ts_recv":"2026-04-07T02:14:20.608621198Z","hd":{"ts_event":"2026-04-07T02:14:20.608603525Z","rtype":160,"publisher_id":101,"instrument_id":436},"action":"C","side":"B","price":"1.156340000","size":30,"channel_id":23,"order_id":"10998900097448922734","flags":0,"ts_in_delta":910,"sequence":153317,"symbol":"FCEU SI 20260615 PS"}
{"ts_recv":"2026-04-07T02:14:20.608621198Z","hd":{"ts_event":"2026-04-07T02:14:20.608603525Z","rtype":160,"publisher_id":101,"instrument_id":436},"action":"A","side":"B","price":"1.156350000","size":30,"channel_id":23,"order_id":"10998900097463385065","flags":0,"ts_in_delta":910,"sequence":153317,"symbol":"FCEU SI 20260615 PS"}
{"ts_recv":"2026-04-07T02:14:20.608621198Z","hd":{"ts_event":"2026-04-07T02:14:20.608603525Z","rtype":160,"publisher_id":101,"instrument_id":436},"action":"C","side":"A","price":"1.156440000","size":30,"channel_id":23,"order_id":"1775528060594146926","flags":0,"ts_in_delta":910,"sequence":153317,"symbol":"FCEU SI 20260615 PS"}
{"ts_recv":"2026-04-07T02:14:20.608621198Z","hd":{"ts_event":"2026-04-07T02:14:20.608603525Z","rtype":160,"publisher_id":101,"instrument_id":436},"action":"A","side":"A","price":"1.156450000","size":30,"channel_id":23,"order_id":"1775528060608609257","flags":128,"ts_in_delta":910,"sequence":153317,"symbol":"FCEU SI 20260615 PS"}
{"ts_recv":"2026-04-07T02:14:20.608678365Z","hd":{"ts_event":"2026-04-07T02:14:20.608655101Z","rtype":160,"publisher_id":101,"instrument_id":436},"action":"C","side":"B","price":"1.156340000","size":30,"channel_id":23,"order_id":"10998900097435409304","flags":0,"ts_in_delta":900,"sequence":153318,"symbol":"FCEU SI 20260615 PS"}
{"ts_recv":"2026-04-07T02:14:20.608678365Z","hd":{"ts_event":"2026-04-07T02:14:20.608655101Z","rtype":160,"publisher_id":101,"instrument_id":436},"action":"A","side":"B","price":"1.156360000","size":30,"channel_id":23,"order_id":"10998900097463436831","flags":0,"ts_in_delta":900,"sequence":153318,"symbol":"FCEU SI 20260615 PS"}
{"ts_recv":"2026-04-07T02:14:20.608678365Z","hd":{"ts_event":"2026-04-07T02:14:20.608655101Z","rtype":160,"publisher_id":101,"instrument_id":436},"action":"C","side":"A","price":"1.156440000","size":30,"channel_id":23,"order_id":"1775528060580633496","flags":0,"ts_in_delta":900,"sequence":153318,"symbol":"FCEU SI 20260615 PS"}
{"ts_recv":"2026-04-07T02:14:20.608678365Z","hd":{"ts_event":"2026-04-07T02:14:20.608655101Z","rtype":160,"publisher_id":101,"instrument_id":436},"action":"A","side":"A","price":"1.156460000","size":30,"channel_id":23,"order_id":"1775528060608661023","flags":128,"ts_in_delta":900,"sequence":153318,"symbol":"FCEU SI 20260615 PS"}
{"ts_recv":"2026-04-07T02:14:20.608733367Z","hd":{"ts_event":"2026-04-07T02:14:20.608715019Z","rtype":160,"publisher_id":101,"instrument_id":436},"action":"C","side":"B","price":"1.156350000","size":30,"channel_id":23,"order_id":"10998900097463385065","flags":0,"ts_in_delta":909,"sequence":153319,"symbol":"FCEU SI 20260615 PS"}
{"ts_recv":"2026-04-07T02:14:20.608733367Z","hd":{"ts_event":"2026-04-07T02:14:20.608715019Z","rtype":160,"publisher_id":101,"instrument_id":436},"action":"A","side":"B","price":"1.156360000","size":30,"channel_id":23,"order_id":"10998900097463496664","flags":0,"ts_in_delta":909,"sequence":153319,"symbol":"FCEU SI 20260615 PS"}
{"ts_recv":"2026-04-07T02:14:20.608733367Z","hd":{"ts_event":"2026-04-07T02:14:20.608715019Z","rtype":160,"publisher_id":101,"instrument_id":436},"action":"C","side":"A","price":"1.156450000","size":30,"channel_id":23,"order_id":"1775528060608609257","flags":0,"ts_in_delta":909,"sequence":153319,"symbol":"FCEU SI 20260615 PS"}
{"ts_recv":"2026-04-07T02:14:20.608733367Z","hd":{"ts_event":"2026-04-07T02:14:20.608715019Z","rtype":160,"publisher_id":101,"instrument_id":436},"action":"A","side":"A","price":"1.156460000","size":30,"channel_id":23,"order_id":"1775528060608720856","flags":128,"ts_in_delta":909,"sequence":153319,"symbol":"FCEU SI 20260615 PS"}
{"ts_recv":"2026-04-07T02:14:32.664342141Z","hd":{"ts_event":"2026-04-07T02:14:32.664319829Z","rtype":160,"publisher_id":101,"instrument_id":436},"action":"C","side":"B","price":"1.156360000","size":30,"channel_id":23,"order_id":"10998900097463496664","flags":0,"ts_in_delta":1040,"sequence":153435,"symbol":"FCEU SI 20260615 PS"}
{"ts_recv":"2026-04-07T02:14:32.664342141Z","hd":{"ts_event":"2026-04-07T02:14:32.664319829Z","rtype":160,"publisher_id":101,"instrument_id":436},"action":"A","side":"B","price":"1.156350000","size":30,"channel_id":23,"order_id":"10998900109519101726","flags":0,"ts_in_delta":1040,"sequence":153435,"symbol":"FCEU SI 20260615 PS"}
{"ts_recv":"2026-04-07T02:14:32.664342141Z","hd":{"ts_event":"2026-04-07T02:14:32.664319829Z","rtype":160,"publisher_id":101,"instrument_id":436},"action":"C","side":"A","price":"1.156460000","size":30,"channel_id":23,"order_id":"1775528060608720856","flags":0,"ts_in_delta":1040,"sequence":153435,"symbol":"FCEU SI 20260615 PS"}
{"ts_recv":"2026-04-07T02:14:32.664342141Z","hd":{"ts_event":"2026-04-07T02:14:32.664319829Z","rtype":160,"publisher_id":101,"instrument_id":436},"action":"A","side":"A","price":"1.156450000","size":30,"channel_id":23,"order_id":"1775528072664325918","flags":128,"ts_in_delta":1040,"sequence":153435,"symbol":"FCEU SI 20260615 PS"}
{"ts_recv":"2026-04-07T02:14:32.664427462Z","hd":{"ts_event":"2026-04-07T02:14:32.664406331Z","rtype":160,"publisher_id":101,"instrument_id":436},"action":"C","side":"B","price":"1.156350000","size":30,"channel_id":23,"order_id":"10998900109519101726","flags":0,"ts_in_delta":911,"sequence":153437,"symbol":"FCEU SI 20260615 PS"}
{"ts_recv":"2026-04-07T02:14:32.664427462Z","hd":{"ts_event":"2026-04-07T02:14:32.664406331Z","rtype":160,"publisher_id":101,"instrument_id":436},"action":"A","side":"B","price":"1.156340000","size":30,"channel_id":23,"order_id":"10998900109519188232","flags":0,"ts_in_delta":911,"sequence":153437,"symbol":"FCEU SI 20260615 PS"}
{"ts_recv":"2026-04-07T02:14:32.664427462Z","hd":{"ts_event":"2026-04-07T02:14:32.664406331Z","rtype":160,"publisher_id":101,"instrument_id":436},"action":"C","side":"A","price":"1.156450000","size":30,"channel_id":23,"order_id":"1775528072664325918","flags":0,"ts_in_delta":911,"sequence":153437,"symbol":"FCEU SI 20260615 PS"}
{"ts_recv":"2026-04-07T02:14:32.664427462Z","hd":{"ts_event":"2026-04-07T02:14:32.664406331Z","rtype":160,"publisher_id":101,"instrument_id":436},"action":"A","side":"A","price":"1.156440000","size":30,"channel_id":23,"order_id":"1775528072664412424","flags":128,"ts_in_delta":911,"sequence":153437,"symbol":"FCEU SI 20260615 PS"}
{"ts_recv":"2026-04-07T02:14:32.664482563Z","hd":{"ts_event":"2026-04-07T02:14:32.664467043Z","rtype":160,"publisher_id":101,"instrument_id":436},"action":"C","side":"B","price":"1.156340000","size":30,"channel_id":23,"order_id":"10998900109519188232","flags":0,"ts_in_delta":949,"sequence":153438,"symbol":"FCEU SI 20260615 PS"}
{"ts_recv":"2026-04-07T02:14:32.664482563Z","hd":{"ts_event":"2026-04-07T02:14:32.664467043Z","rtype":160,"publisher_id":101,"instrument_id":436},"action":"A","side":"B","price":"1.156350000","size":30,"channel_id":23,"order_id":"10998900109519248796","flags":0,"ts_in_delta":949,"sequence":153438,"symbol":"FCEU SI 20260615 PS"}
{"ts_recv":"2026-04-07T02:14:32.664482563Z","hd":{"ts_event":"2026-04-07T02:14:32.664467043Z","rtype":160,"publisher_id":101,"instrument_id":436},"action":"C","side":"A","price":"1.156440000","size":30,"channel_id":23,"order_id":"1775528072664412424","flags":0,"ts_in_delta":949,"sequence":153438,"symbol":"FCEU SI 20260615 PS"}
{"ts_recv":"2026-04-07T02:14:32.664482563Z","hd":{"ts_event":"2026-04-07T02:14:32.664467043Z","rtype":160,"publisher_id":101,"instrument_id":436},"action":"A","side":"A","price":"1.156450000","size":30,"channel_id":23,"order_id":"1775528072664472988","flags":128,"ts_in_delta":949,"sequence":153438,"symbol":"FCEU SI 20260615 PS"}
{"ts_recv":"2026-04-07T02:14:32.669299860Z","hd":{"ts_event":"2026-04-07T02:14:32.669279995Z","rtype":160,"publisher_id":101,"instrument_id":436},"action":"C","side":"B","price":"1.156350000","size":30,"channel_id":23,"order_id":"10998900109519248796","flags":0,"ts_in_delta":900,"sequence":153441,"symbol":"FCEU SI 20260615 PS"}
{"ts_recv":"2026-04-07T02:14:32.669299860Z","hd":{"ts_event":"2026-04-07T02:14:32.669279995Z","rtype":160,"publisher_id":101,"instrument_id":436},"action":"A","side":"B","price":"1.156340000","size":30,"channel_id":23,"order_id":"10998900109524061905","flags":0,"ts_in_delta":900,"sequence":153441,"symbol":"FCEU SI 20260615 PS"}
{"ts_recv":"2026-04-07T02:14:32.669299860Z","hd":{"ts_event":"2026-04-07T02:14:32.669279995Z","rtype":160,"publisher_id":101,"instrument_id":436},"action":"C","side":"A","price":"1.156450000","size":30,"channel_id":23,"order_id":"1775528072664472988","flags":0,"ts_in_delta":900,"sequence":153441,"symbol":"FCEU SI 20260615 PS"}
{"ts_recv":"2026-04-07T02:14:32.669299860Z","hd":{"ts_event":"2026-04-07T02:14:32.669279995Z","rtype":160,"publisher_id":101,"instrument_id":436},"action":"A","side":"A","price":"1.156440000","size":30,"channel_id":23,"order_id":"1775528072669286097","flags":128,"ts_in_delta":900,"sequence":153441,"symbol":"FCEU SI 20260615 PS"}
{"ts_recv":"2026-04-07T02:14:32.686990067Z","hd":{"ts_event":"2026-04-07T02:14:32.686968521Z","rtype":160,"publisher_id":101,"instrument_id":436},"action":"C","side":"B","price":"1.156360000","size":30,"channel_id":23,"order_id":"10998900097463436831","flags":0,"ts_in_delta":3273,"sequence":153453,"symbol":"FCEU SI 20260615 PS"}
{"ts_recv":"2026-04-07T02:14:32.686990067Z","hd":{"ts_event":"2026-04-07T02:14:32.686968521Z","rtype":160,"publisher_id":101,"instrument_id":436},"action":"A","side":"B","price":"1.156340000","size":30,"channel_id":23,"order_id":"10998900109541750175","flags":0,"ts_in_delta":3273,"sequence":153453,"symbol":"FCEU SI 20260615 PS"}
{"ts_recv":"2026-04-07T02:14:32.686990067Z","hd":{"ts_event":"2026-04-07T02:14:32.686968521Z","rtype":160,"publisher_id":101,"instrument_id":436},"action":"C","side":"A","price":"1.156460000","size":30,"channel_id":23,"order_id":"1775528060608661023","flags":0,"ts_in_delta":3273,"sequence":153453,"symbol":"FCEU SI 20260615 PS"}
{"ts_recv":"2026-04-07T02:14:32.686990067Z","hd":{"ts_event":"2026-04-07T02:14:32.686968521Z","rtype":160,"publisher_id":101,"instrument_id":436},"action":"A","side":"A","price":"1.156440000","size":30,"channel_id":23,"order_id":"1775528072686974367","flags":128,"ts_in_delta":3273,"sequence":153453,"symbol":"FCEU SI 20260615 PS"}
{"ts_recv":"2026-04-07T02:14:32.687050568Z","hd":{"ts_event":"2026-04-07T02:14:32.687031235Z","rtype":160,"publisher_id":101,"instrument_id":436},"action":"C","side":"B","price":"1.156340000","size":30,"channel_id":23,"order_id":"10998900109524061905","flags":0,"ts_in_delta":1054,"sequence":153454,"symbol":"FCEU SI 20260615 PS"}
{"ts_recv":"2026-04-07T02:14:32.687050568Z","hd":{"ts_event":"2026-04-07T02:14:32.687031235Z","rtype":160,"publisher_id":101,"instrument_id":436},"action":"A","side":"B","price":"1.156330000","size":30,"channel_id":23,"order_id":"10998900109541813025","flags":0,"ts_in_delta":1054,"sequence":153454,"symbol":"FCEU SI 20260615 PS"}
{"ts_recv":"2026-04-07T02:14:32.687050568Z","hd":{"ts_event":"2026-04-07T02:14:32.687031235Z","rtype":160,"publisher_id":101,"instrument_id":436},"action":"C","side":"A","price":"1.156440000","size":30,"channel_id":23,"order_id":"1775528072669286097","flags":0,"ts_in_delta":1054,"sequence":153454,"symbol":"FCEU SI 20260615 PS"}
{"ts_recv":"2026-04-07T02:14:32.687050568Z","hd":{"ts_event":"2026-04-07T02:14:32.687031235Z","rtype":160,"publisher_id":101,"instrument_id":436},"action":"A","side":"A","price":"1.156430000","size":30,"channel_id":23,"order_id":"1775528072687037217","flags":128,"ts_in_delta":1054,"sequence":153454,"symbol":"FCEU SI 20260615 PS"}
{"ts_recv":"2026-04-07T02:14:38.262481012Z","hd":{"ts_event":"2026-04-07T02:14:38.262461583Z","rtype":160,"publisher_id":101,"instrument_id":436},"action":"C","side":"B","price":"1.156330000","size":30,"channel_id":23,"order_id":"10998900109541813025","flags":0,"ts_in_delta":1068,"sequence":153522,"symbol":"FCEU SI 20260615 PS"}
{"ts_recv":"2026-04-07T02:14:38.262481012Z","hd":{"ts_event":"2026-04-07T02:14:38.262461583Z","rtype":160,"publisher_id":101,"instrument_id":436},"action":"A","side":"B","price":"1.156320000","size":30,"channel_id":23,"order_id":"10998900115117243179","flags":0,"ts_in_delta":1068,"sequence":153522,"symbol":"FCEU SI 20260615 PS"}
{"ts_recv":"2026-04-07T02:14:38.262481012Z","hd":{"ts_event":"2026-04-07T02:14:38.262461583Z","rtype":160,"publisher_id":101,"instrument_id":436},"action":"C","side":"A","price":"1.156430000","size":30,"channel_id":23,"order_id":"1775528072687037217","flags":0,"ts_in_delta":1068,"sequence":153522,"symbol":"FCEU SI 20260615 PS"}
{"ts_recv":"2026-04-07T02:14:38.262481012Z","hd":{"ts_event":"2026-04-07T02:14:38.262461583Z","rtype":160,"publisher_id":101,"instrument_id":436},"action":"A","side":"A","price":"1.156420000","size":30,"channel_id":23,"order_id":"1775528078262467371","flags":128,"ts_in_delta":1068,"sequence":153522,"symbol":"FCEU SI 20260615 PS"}
{"ts_recv":"2026-04-07T02:14:38.262537788Z","hd":{"ts_event":"2026-04-07T02:14:38.262518575Z","rtype":160,"publisher_id":101,"instrument_id":436},"action":"C","side":"B","price":"1.156340000","size":30,"channel_id":23,"order_id":"10998900109541750175","flags":0,"ts_in_delta":905,"sequence":153523,"symbol":"FCEU SI 20260615 PS"}
{"ts_recv":"2026-04-07T02:14:38.262537788Z","hd":{"ts_event":"2026-04-07T02:14:38.262518575Z","rtype":160,"publisher_id":101,"instrument_id":436},"action":"A","side":"B","price":"1.156320000","size":30,"channel_id":23,"order_id":"10998900115117300779","flags":0,"ts_in_delta":905,"sequence":153523,"symbol":"FCEU SI 20260615 PS"}
{"ts_recv":"2026-04-07T02:14:38.262537788Z","hd":{"ts_event":"2026-04-07T02:14:38.262518575Z","rtype":160,"publisher_id":101,"instrument_id":436},"action":"C","side":"A","price":"1.156440000","size":30,"channel_id":23,"order_id":"1775528072686974367","flags":0,"ts_in_delta":905,"sequence":153523,"symbol":"FCEU SI 20260615 PS"}
{"ts_recv":"2026-04-07T02:14:38.262537788Z","hd":{"ts_event":"2026-04-07T02:14:38.262518575Z","rtype":160,"publisher_id":101,"instrument_id":436},"action":"A","side":"A","price":"1.156420000","size":30,"channel_id":23,"order_id":"1775528078262524971","flags":128,"ts_in_delta":905,"sequence":153523,"symbol":"FCEU SI 20260615 PS"}
{"ts_recv":"2026-04-07T02:14:38.262547963Z","hd":{"ts_event":"2026-04-07T02:14:38.262527159Z","rtype":160,"publisher_id":101,"instrument_id":436},"action":"C","side":"B","price":"1.156320000","size":30,"channel_id":23,"order_id":"10998900115117243179","flags":0,"ts_in_delta":1094,"sequence":153524,"symbol":"FCEU SI 20260615 PS"}
{"ts_recv":"2026-04-07T02:14:38.262547963Z","hd":{"ts_event":"2026-04-07T02:14:38.262527159Z","rtype":160,"publisher_id":101,"instrument_id":436},"action":"A","side":"B","price":"1.156330000","size":30,"channel_id":23,"order_id":"10998900115117310385","flags":0,"ts_in_delta":1094,"sequence":153524,"symbol":"FCEU SI 20260615 PS"}
{"ts_recv":"2026-04-07T02:14:38.262547963Z","hd":{"ts_event":"2026-04-07T02:14:38.262527159Z","rtype":160,"publisher_id":101,"instrument_id":436},"action":"C","side":"A","price":"1.156420000","size":30,"channel_id":23,"order_id":"1775528078262467371","flags":0,"ts_in_delta":1094,"sequence":153524,"symbol":"FCEU SI 20260615 PS"}
{"ts_recv":"2026-04-07T02:14:38.262547963Z","hd":{"ts_event":"2026-04-07T02:14:38.262527159Z","rtype":160,"publisher_id":101,"instrument_id":436},"action":"A","side":"A","price":"1.156430000","size":30,"channel_id":23,"order_id":"1775528078262534577","flags":128,"ts_in_delta":1094,"sequence":153524,"symbol":"FCEU SI 20260615 PS"}
{"ts_recv":"2026-04-07T02:14:38.262625743Z","hd":{"ts_event":"2026-04-07T02:14:38.262608291Z","rtype":160,"publisher_id":101,"instrument_id":436},"action":"C","side":"B","price":"1.156330000","size":30,"channel_id":23,"order_id":"10998900115117310385","flags":0,"ts_in_delta":915,"sequence":153525,"symbol":"FCEU SI 20260615 PS"}
{"ts_recv":"2026-04-07T02:14:38.262625743Z","hd":{"ts_event":"2026-04-07T02:14:38.262608291Z","rtype":160,"publisher_id":101,"instrument_id":436},"action":"A","side":"B","price":"1.156320000","size":30,"channel_id":23,"order_id":"10998900115117390147","flags":0,"ts_in_delta":915,"sequence":153525,"symbol":"FCEU SI 20260615 PS"}
{"ts_recv":"2026-04-07T02:14:38.262625743Z","hd":{"ts_event":"2026-04-07T02:14:38.262608291Z","rtype":160,"publisher_id":101,"instrument_id":436},"action":"C","side":"A","price":"1.156430000","size":30,"channel_id":23,"order_id":"1775528078262534577","flags":0,"ts_in_delta":915,"sequence":153525,"symbol":"FCEU SI 20260615 PS"}
{"ts_recv":"2026-04-07T02:14:38.262625743Z","hd":{"ts_event":"2026-04-07T02:14:38.262608291Z","rtype":160,"publisher_id":101,"instrument_id":436},"action":"A","side":"A","price":"1.156420000","size":30,"channel_id":23,"order_id":"1775528078262614339","flags":128,"ts_in_delta":915,"sequence":153525,"symbol":"FCEU SI 20260615 PS"}
{"ts_recv":"2026-04-07T02:14:40.549627643Z","hd":{"ts_event":"2026-04-07T02:14:40.549607479Z","rtype":160,"publisher_id":101,"instrument_id":436},"action":"C","side":"B","price":"1.156320000","size":30,"channel_id":23,"order_id":"10998900115117390147","flags":0,"ts_in_delta":1083,"sequence":153562,"symbol":"FCEU SI 20260615 PS"}
{"ts_recv":"2026-04-07T02:14:40.549627643Z","hd":{"ts_event":"2026-04-07T02:14:40.549607479Z","rtype":160,"publisher_id":101,"instrument_id":436},"action":"A","side":"B","price":"1.156310000","size":30,"channel_id":23,"order_id":"10998900117404389152","flags":0,"ts_in_delta":1083,"sequence":153562,"symbol":"FCEU SI 20260615 PS"}
{"ts_recv":"2026-04-07T02:14:40.549627643Z","hd":{"ts_event":"2026-04-07T02:14:40.549607479Z","rtype":160,"publisher_id":101,"instrument_id":436},"action":"C","side":"A","price":"1.156420000","size":30,"channel_id":23,"order_id":"1775528078262614339","flags":0,"ts_in_delta":1083,"sequence":153562,"symbol":"FCEU SI 20260615 PS"}
{"ts_recv":"2026-04-07T02:14:40.549627643Z","hd":{"ts_event":"2026-04-07T02:14:40.549607479Z","rtype":160,"publisher_id":101,"instrument_id":436},"action":"A","side":"A","price":"1.156410000","size":30,"channel_id":23,"order_id":"1775528080549613344","flags":128,"ts_in_delta":1083,"sequence":153562,"symbol":"FCEU SI 20260615 PS"}
{"ts_recv":"2026-04-07T02:14:40.558063008Z","hd":{"ts_event":"2026-04-07T02:14:40.558043291Z","rtype":160,"publisher_id":101,"instrument_id":436},"action":"C","side":"B","price":"1.156310000","size":30,"channel_id":23,"order_id":"10998900117404389152","flags":0,"ts_in_delta":1075,"sequence":153566,"symbol":"FCEU SI 20260615 PS"}
{"ts_recv":"2026-04-07T02:14:40.558063008Z","hd":{"ts_event":"2026-04-07T02:14:40.558043291Z","rtype":160,"publisher_id":101,"instrument_id":436},"action":"A","side":"B","price":"1.156300000","size":30,"channel_id":23,"order_id":"10998900117412824982","flags":0,"ts_in_delta":1075,"sequence":153566,"symbol":"FCEU SI 20260615 PS"}
{"ts_recv":"2026-04-07T02:14:40.558063008Z","hd":{"ts_event":"2026-04-07T02:14:40.558043291Z","rtype":160,"publisher_id":101,"instrument_id":436},"action":"C","side":"A","price":"1.156410000","size":30,"channel_id":23,"order_id":"1775528080549613344","flags":0,"ts_in_delta":1075,"sequence":153566,"symbol":"FCEU SI 20260615 PS"}
{"ts_recv":"2026-04-07T02:14:40.558063008Z","hd":{"ts_event":"2026-04-07T02:14:40.558043291Z","rtype":160,"publisher_id":101,"instrument_id":436},"action":"A","side":"A","price":"1.156400000","size":30,"channel_id":23,"order_id":"1775528080558049174","flags":128,"ts_in_delta":1075,"sequence":153566,"symbol":"FCEU SI 20260615 PS"}
{"ts_recv":"2026-04-07T02:14:40.558124898Z","hd":{"ts_event":"2026-04-07T02:14:40.558109499Z","rtype":160,"publisher_id":101,"instrument_id":436},"action":"C","side":"B","price":"1.156300000","size":30,"channel_id":23,"order_id":"10998900117412824982","flags":0,"ts_in_delta":1027,"sequence":153567,"symbol":"FCEU SI 20260615 PS"}
{"ts_recv":"2026-04-07T02:14:40.558124898Z","hd":{"ts_event":"2026-04-07T02:14:40.558109499Z","rtype":160,"publisher_id":101,"instrument_id":436},"action":"A","side":"B","price":"1.156310000","size":30,"channel_id":23,"order_id":"10998900117412891202","flags":0,"ts_in_delta":1027,"sequence":153567,"symbol":"FCEU SI 20260615 PS"}
{"ts_recv":"2026-04-07T02:14:40.558124898Z","hd":{"ts_event":"2026-04-07T02:14:40.558109499Z","rtype":160,"publisher_id":101,"instrument_id":436},"action":"C","side":"A","price":"1.156400000","size":30,"channel_id":23,"order_id":"1775528080558049174","flags":0,"ts_in_delta":1027,"sequence":153567,"symbol":"FCEU SI 20260615 PS"}
{"ts_recv":"2026-04-07T02:14:40.558124898Z","hd":{"ts_event":"2026-04-07T02:14:40.558109499Z","rtype":160,"publisher_id":101,"instrument_id":436},"action":"A","side":"A","price":"1.156410000","size":30,"channel_id":23,"order_id":"1775528080558115394","flags":128,"ts_in_delta":1027,"sequence":153567,"symbol":"FCEU SI 20260615 PS"}
{"ts_recv":"2026-04-07T02:14:42.070166319Z","hd":{"ts_event":"2026-04-07T02:14:42.070148933Z","rtype":160,"publisher_id":101,"instrument_id":436},"action":"C","side":"B","price":"1.156310000","size":30,"channel_id":23,"order_id":"10998900117412891202","flags":0,"ts_in_delta":921,"sequence":153603,"symbol":"FCEU SI 20260615 PS"}
{"ts_recv":"2026-04-07T02:14:42.070166319Z","hd":{"ts_event":"2026-04-07T02:14:42.070148933Z","rtype":160,"publisher_id":101,"instrument_id":436},"action":"A","side":"B","price":"1.156320000","size":30,"channel_id":23,"order_id":"10998900118924930628","flags":0,"ts_in_delta":921,"sequence":153603,"symbol":"FCEU SI 20260615 PS"}
{"ts_recv":"2026-04-07T02:14:42.070166319Z","hd":{"ts_event":"2026-04-07T02:14:42.070148933Z","rtype":160,"publisher_id":101,"instrument_id":436},"action":"C","side":"A","price":"1.156410000","size":30,"channel_id":23,"order_id":"1775528080558115394","flags":0,"ts_in_delta":921,"sequence":153603,"symbol":"FCEU SI 20260615 PS"}
{"ts_recv":"2026-04-07T02:14:42.070166319Z","hd":{"ts_event":"2026-04-07T02:14:42.070148933Z","rtype":160,"publisher_id":101,"instrument_id":436},"action":"A","side":"A","price":"1.156420000","size":30,"channel_id":23,"order_id":"1775528082070154820","flags":128,"ts_in_delta":921,"sequence":153603,"symbol":"FCEU SI 20260615 PS"}
{"ts_recv":"2026-04-07T02:14:49.566373118Z","hd":{"ts_event":"2026-04-07T02:14:49.566341959Z","rtype":160,"publisher_id":101,"instrument_id":436},"action":"C","side":"B","price":"1.156320000","size":30,"channel_id":23,"order_id":"10998900115117300779","flags":0,"ts_in_delta":1296,"sequence":153668,"symbol":"FCEU SI 20260615 PS"}
{"ts_recv":"2026-04-07T02:14:49.566373118Z","hd":{"ts_event":"2026-04-07T02:14:49.566341959Z","rtype":160,"publisher_id":101,"instrument_id":436},"action":"A","side":"B","price":"1.156340000","size":30,"channel_id":23,"order_id":"10998900126421128682","flags":0,"ts_in_delta":1296,"sequence":153668,"symbol":"FCEU SI 20260615 PS"}
{"ts_recv":"2026-04-07T02:14:49.566373118Z","hd":{"ts_event":"2026-04-07T02:14:49.566341959Z","rtype":160,"publisher_id":101,"instrument_id":436},"action":"C","side":"A","price":"1.156420000","size":30,"channel_id":23,"order_id":"1775528078262524971","flags":0,"ts_in_delta":1296,"sequence":153668,"symbol":"FCEU SI 20260615 PS"}
{"ts_recv":"2026-04-07T02:14:49.566373118Z","hd":{"ts_event":"2026-04-07T02:14:49.566341959Z","rtype":160,"publisher_id":101,"instrument_id":436},"action":"A","side":"A","price":"1.156440000","size":30,"channel_id":23,"order_id":"1775528089566352874","flags":128,"ts_in_delta":1296,"sequence":153668,"symbol":"FCEU SI 20260615 PS"}
{"ts_recv":"2026-04-07T02:14:49.566456004Z","hd":{"ts_event":"2026-04-07T02:14:49.566432661Z","rtype":160,"publisher_id":101,"instrument_id":436},"action":"C","side":"B","price":"1.156340000","size":30,"channel_id":23,"order_id":"10998900126421128682","flags":0,"ts_in_delta":940,"sequence":153669,"symbol":"FCEU SI 20260615 PS"}
{"ts_recv":"2026-04-07T02:14:49.566456004Z","hd":{"ts_event":"2026-04-07T02:14:49.566432661Z","rtype":160,"publisher_id":101,"instrument_id":436},"action":"A","side":"B","price":"1.156360000","size":30,"channel_id":23,"order_id":"10998900126421215235","flags":0,"ts_in_delta":940,"sequence":153669,"symbol":"FCEU SI 20260615 PS"}
{"ts_recv":"2026-04-07T02:14:49.566456004Z","hd":{"ts_event":"2026-04-07T02:14:49.566432661Z","rtype":160,"publisher_id":101,"instrument_id":436},"action":"C","side":"A","price":"1.156440000","size":30,"channel_id":23,"order_id":"1775528089566352874","flags":0,"ts_in_delta":940,"sequence":153669,"symbol":"FCEU SI 20260615 PS"}
{"ts_recv":"2026-04-07T02:14:49.566456004Z","hd":{"ts_event":"2026-04-07T02:14:49.566432661Z","rtype":160,"publisher_id":101,"instrument_id":436},"action":"A","side":"A","price":"1.156460000","size":30,"channel_id":23,"order_id":"1775528089566439427","flags":128,"ts_in_delta":940,"sequence":153669,"symbol":"FCEU SI 20260615 PS"}
{"ts_recv":"2026-04-07T02:14:49.566466541Z","hd":{"ts_event":"2026-04-07T02:14:49.566443123Z","rtype":160,"publisher_id":101,"instrument_id":436},"action":"C","side":"B","price":"1.156320000","size":30,"channel_id":23,"order_id":"10998900118924930628","flags":0,"ts_in_delta":1108,"sequence":153670,"symbol":"FCEU SI 20260615 PS"}
{"ts_recv":"2026-04-07T02:14:49.566466541Z","hd":{"ts_event":"2026-04-07T02:14:49.566443123Z","rtype":160,"publisher_id":101,"instrument_id":436},"action":"A","side":"B","price":"1.156330000","size":30,"channel_id":23,"order_id":"10998900126421228526","flags":0,"ts_in_delta":1108,"sequence":153670,"symbol":"FCEU SI 20260615 PS"}
{"ts_recv":"2026-04-07T02:14:49.566466541Z","hd":{"ts_event":"2026-04-07T02:14:49.566443123Z","rtype":160,"publisher_id":101,"instrument_id":436},"action":"C","side":"A","price":"1.156420000","size":30,"channel_id":23,"order_id":"1775528082070154820","flags":0,"ts_in_delta":1108,"sequence":153670,"symbol":"FCEU SI 20260615 PS"}
{"ts_recv":"2026-04-07T02:14:49.566466541Z","hd":{"ts_event":"2026-04-07T02:14:49.566443123Z","rtype":160,"publisher_id":101,"instrument_id":436},"action":"A","side":"A","price":"1.156430000","size":30,"channel_id":23,"order_id":"1775528089566452718","flags":128,"ts_in_delta":1108,"sequence":153670,"symbol":"FCEU SI 20260615 PS"}
{"ts_recv":"2026-04-07T02:14:49.566507596Z","hd":{"ts_event":"2026-04-07T02:14:49.566491835Z","rtype":160,"publisher_id":101,"instrument_id":436},"action":"C","side":"B","price":"1.156360000","size":30,"channel_id":23,"order_id":"10998900126421215235","flags":0,"ts_in_delta":933,"sequence":153671,"symbol":"FCEU SI 20260615 PS"}
{"ts_recv":"2026-04-07T02:14:49.566507596Z","hd":{"ts_event":"2026-04-07T02:14:49.566491835Z","rtype":160,"publisher_id":101,"instrument_id":436},"action":"A","side":"B","price":"1.156340000","size":30,"channel_id":23,"order_id":"10998900126421273604","flags":0,"ts_in_delta":933,"sequence":153671,"symbol":"FCEU SI 20260615 PS"}
{"ts_recv":"2026-04-07T02:14:49.566507596Z","hd":{"ts_event":"2026-04-07T02:14:49.566491835Z","rtype":160,"publisher_id":101,"instrument_id":436},"action":"C","side":"A","price":"1.156460000","size":30,"channel_id":23,"order_id":"1775528089566439427","flags":0,"ts_in_delta":933,"sequence":153671,"symbol":"FCEU SI 20260615 PS"}
{"ts_recv":"2026-04-07T02:14:49.566507596Z","hd":{"ts_event":"2026-04-07T02:14:49.566491835Z","rtype":160,"publisher_id":101,"instrument_id":436},"action":"A","side":"A","price":"1.156440000","size":30,"channel_id":23,"order_id":"1775528089566497796","flags":128,"ts_in_delta":933,"sequence":153671,"symbol":"FCEU SI 20260615 PS"}
{"ts_recv":"2026-04-07T02:14:49.566550479Z","hd":{"ts_event":"2026-04-07T02:14:49.566532417Z","rtype":160,"publisher_id":101,"instrument_id":436},"action":"C","side":"B","price":"1.156330000","size":30,"channel_id":23,"order_id":"10998900126421228526","flags":0,"ts_in_delta":1104,"sequence":153672,"symbol":"FCEU SI 20260615 PS"}
{"ts_recv":"2026-04-07T02:14:49.566550479Z","hd":{"ts_event":"2026-04-07T02:14:49.566532417Z","rtype":160,"publisher_id":101,"instrument_id":436},"action":"A","side":"B","price":"1.156340000","size":30,"channel_id":23,"order_id":"10998900126421314227","flags":0,"ts_in_delta":1104,"sequence":153672,"symbol":"FCEU SI 20260615 PS"}
{"ts_recv":"2026-04-07T02:14:49.566550479Z","hd":{"ts_event":"2026-04-07T02:14:49.566532417Z","rtype":160,"publisher_id":101,"instrument_id":436},"action":"C","side":"A","price":"1.156430000","size":30,"channel_id":23,"order_id":"1775528089566452718","flags":0,"ts_in_delta":1104,"sequence":153672,"symbol":"FCEU SI 20260615 PS"}
{"ts_recv":"2026-04-07T02:14:49.566550479Z","hd":{"ts_event":"2026-04-07T02:14:49.566532417Z","rtype":160,"publisher_id":101,"instrument_id":436},"action":"A","side":"A","price":"1.156440000","size":30,"channel_id":23,"order_id":"1775528089566538419","flags":128,"ts_in_delta":1104,"sequence":153672,"symbol":"FCEU SI 20260615 PS"}
{"ts_recv":"2026-04-07T02:14:49.566612899Z","hd":{"ts_event":"2026-04-07T02:14:49.566592957Z","rtype":160,"publisher_id":101,"instrument_id":436},"action":"C","side":"B","price":"1.156340000","size":30,"channel_id":23,"order_id":"10998900126421314227","flags":0,"ts_in_delta":1037,"sequence":153673,"symbol":"FCEU SI 20260615 PS"}
{"ts_recv":"2026-04-07T02:14:49.566612899Z","hd":{"ts_event":"2026-04-07T02:14:49.566592957Z","rtype":160,"publisher_id":101,"instrument_id":436},"action":"A","side":"B","price":"1.156330000","size":30,"channel_id":23,"order_id":"10998900126421375327","flags":0,"ts_in_delta":1037,"sequence":153673,"symbol":"FCEU SI 20260615 PS"}
{"ts_recv":"2026-04-07T02:14:49.566612899Z","hd":{"ts_event":"2026-04-07T02:14:49.566592957Z","rtype":160,"publisher_id":101,"instrument_id":436},"action":"C","side":"A","price":"1.156440000","size":30,"channel_id":23,"order_id":"1775528089566538419","flags":0,"ts_in_delta":1037,"sequence":153673,"symbol":"FCEU SI 20260615 PS"}
{"ts_recv":"2026-04-07T02:14:49.566612899Z","hd":{"ts_event":"2026-04-07T02:14:49.566592957Z","rtype":160,"publisher_id":101,"instrument_id":436},"action":"A","side":"A","price":"1.156430000","size":30,"channel_id":23,"order_id":"1775528089566599519","flags":128,"ts_in_delta":1037,"sequence":153673,"symbol":"FCEU SI 20260615 PS"}
{"ts_recv":"2026-04-07T02:14:49.572101091Z","hd":{"ts_event":"2026-04-07T02:14:49.572083173Z","rtype":160,"publisher_id":101,"instrument_id":436},"action":"C","side":"B","price":"1.156330000","size":30,"channel_id":23,"order_id":"10998900126421375327","flags":0,"ts_in_delta":1000,"sequence":153677,"symbol":"FCEU SI 20260615 PS"}
{"ts_recv":"2026-04-07T02:14:49.572101091Z","hd":{"ts_event":"2026-04-07T02:14:49.572083173Z","rtype":160,"publisher_id":101,"instrument_id":436},"action":"A","side":"B","price":"1.156340000","size":30,"channel_id":23,"order_id":"10998900126426864895","flags":0,"ts_in_delta":1000,"sequence":153677,"symbol":"FCEU SI 20260615 PS"}
{"ts_recv":"2026-04-07T02:14:49.572101091Z","hd":{"ts_event":"2026-04-07T02:14:49.572083173Z","rtype":160,"publisher_id":101,"instrument_id":436},"action":"C","side":"A","price":"1.156430000","size":30,"channel_id":23,"order_id":"1775528089566599519","flags":0,"ts_in_delta":1000,"sequence":153677,"symbol":"FCEU SI 20260615 PS"}
{"ts_recv":"2026-04-07T02:14:49.572101091Z","hd":{"ts_event":"2026-04-07T02:14:49.572083173Z","rtype":160,"publisher_id":101,"instrument_id":436},"action":"A","side":"A","price":"1.156440000","size":30,"channel_id":23,"order_id":"1775528089572089087","flags":128,"ts_in_delta":1000,"sequence":153677,"symbol":"FCEU SI 20260615 PS"}
{"ts_recv":"2026-04-07T02:14:49.572152590Z","hd":{"ts_event":"2026-04-07T02:14:49.572132081Z","rtype":160,"publisher_id":101,"instrument_id":436},"action":"C","side":"B","price":"1.156340000","size":30,"channel_id":23,"order_id":"10998900126421273604","flags":0,"ts_in_delta":906,"sequence":153678,"symbol":"FCEU SI 20260615 PS"}
{"ts_recv":"2026-04-07T02:14:49.572152590Z","hd":{"ts_event":"2026-04-07T02:14:49.572132081Z","rtype":160,"publisher_id":101,"instrument_id":436},"action":"A","side":"B","price":"1.156360000","size":30,"channel_id":23,"order_id":"10998900126426913898","flags":0,"ts_in_delta":906,"sequence":153678,"symbol":"FCEU SI 20260615 PS"}
{"ts_recv":"2026-04-07T02:14:49.572152590Z","hd":{"ts_event":"2026-04-07T02:14:49.572132081Z","rtype":160,"publisher_id":101,"instrument_id":436},"action":"C","side":"A","price":"1.156440000","size":30,"channel_id":23,"order_id":"1775528089566497796","flags":0,"ts_in_delta":906,"sequence":153678,"symbol":"FCEU SI 20260615 PS"}
{"ts_recv":"2026-04-07T02:14:49.572152590Z","hd":{"ts_event":"2026-04-07T02:14:49.572132081Z","rtype":160,"publisher_id":101,"instrument_id":436},"action":"A","side":"A","price":"1.156460000","size":30,"channel_id":23,"order_id":"1775528089572138090","flags":128,"ts_in_delta":906,"sequence":153678,"symbol":"FCEU SI 20260615 PS"}
{"ts_recv":"2026-04-07T02:14:49.572205027Z","hd":{"ts_event":"2026-04-07T02:14:49.572188683Z","rtype":160,"publisher_id":101,"instrument_id":436},"action":"C","side":"B","price":"1.156340000","size":30,"channel_id":23,"order_id":"10998900126426864895","flags":0,"ts_in_delta":873,"sequence":153679,"symbol":"FCEU SI 20260615 PS"}
{"ts_recv":"2026-04-07T02:14:49.572205027Z","hd":{"ts_event":"2026-04-07T02:14:49.572188683Z","rtype":160,"publisher_id":101,"instrument_id":436},"action":"A","side":"B","price":"1.156350000","size":30,"channel_id":23,"order_id":"10998900126426970456","flags":0,"ts_in_delta":873,"sequence":153679,"symbol":"FCEU SI 20260615 PS"}
{"ts_recv":"2026-04-07T02:14:49.572205027Z","hd":{"ts_event":"2026-04-07T02:14:49.572188683Z","rtype":160,"publisher_id":101,"instrument_id":436},"action":"C","side":"A","price":"1.156440000","size":30,"channel_id":23,"order_id":"1775528089572089087","flags":0,"ts_in_delta":873,"sequence":153679,"symbol":"FCEU SI 20260615 PS"}
{"ts_recv":"2026-04-07T02:14:49.572205027Z","hd":{"ts_event":"2026-04-07T02:14:49.572188683Z","rtype":160,"publisher_id":101,"instrument_id":436},"action":"A","side":"A","price":"1.156450000","size":30,"channel_id":23,"order_id":"1775528089572194648","flags":128,"ts_in_delta":873,"sequence":153679,"symbol":"FCEU SI 20260615 PS"}
{"ts_recv":"2026-04-07T02:14:49.578244787Z","hd":{"ts_event":"2026-04-07T02:14:49.578228139Z","rtype":160,"publisher_id":101,"instrument_id":436},"action":"C","side":"B","price":"1.156350000","size":30,"channel_id":23,"order_id":"10998900126426970456","flags":0,"ts_in_delta":960,"sequence":153685,"symbol":"FCEU SI 20260615 PS"}
{"ts_recv":"2026-04-07T02:14:49.578244787Z","hd":{"ts_event":"2026-04-07T02:14:49.578228139Z","rtype":160,"publisher_id":101,"instrument_id":436},"action":"A","side":"B","price":"1.156360000","size":30,"channel_id":23,"order_id":"10998900126433009588","flags":0,"ts_in_delta":960,"sequence":153685,"symbol":"FCEU SI 20260615 PS"}
{"ts_recv":"2026-04-07T02:14:49.578244787Z","hd":{"ts_event":"2026-04-07T02:14:49.578228139Z","rtype":160,"publisher_id":101,"instrument_id":436},"action":"C","side":"A","price":"1.156450000","size":30,"channel_id":23,"order_id":"1775528089572194648","flags":0,"ts_in_delta":960,"sequence":153685,"symbol":"FCEU SI 20260615 PS"}
{"ts_recv":"2026-04-07T02:14:49.578244787Z","hd":{"ts_event":"2026-04-07T02:14:49.578228139Z","rtype":160,"publisher_id":101,"instrument_id":436},"action":"A","side":"A","price":"1.156460000","size":30,"channel_id":23,"order_id":"1775528089578233780","flags":128,"ts_in_delta":960,"sequence":153685,"symbol":"FCEU SI 20260615 PS"}
{"ts_recv":"2026-04-07T02:15:04.462515368Z","hd":{"ts_event":"2026-04-07T02:15:04.462493311Z","rtype":160,"publisher_id":101,"instrument_id":436},"action":"C","side":"B","price":"1.156360000","size":30,"channel_id":23,"order_id":"10998900126433009588","flags":0,"ts_in_delta":928,"sequence":153853,"symbol":"FCEU SI 20260615 PS"}
{"ts_recv":"2026-04-07T02:15:04.462515368Z","hd":{"ts_event":"2026-04-07T02:15:04.462493311Z","rtype":160,"publisher_id":101,"instrument_id":436},"action":"A","side":"B","price":"1.156350000","size":30,"channel_id":23,"order_id":"10998900141317275263","flags":0,"ts_in_delta":928,"sequence":153853,"symbol":"FCEU SI 20260615 PS"}
{"ts_recv":"2026-04-07T02:15:04.462515368Z","hd":{"ts_event":"2026-04-07T02:15:04.462493311Z","rtype":160,"publisher_id":101,"instrument_id":436},"action":"C","side":"A","price":"1.156460000","size":30,"channel_id":23,"order_id":"1775528089578233780","flags":0,"ts_in_delta":928,"sequence":153853,"symbol":"FCEU SI 20260615 PS"}
{"ts_recv":"2026-04-07T02:15:04.462515368Z","hd":{"ts_event":"2026-04-07T02:15:04.462493311Z","rtype":160,"publisher_id":101,"instrument_id":436},"action":"A","side":"A","price":"1.156450000","size":30,"channel_id":23,"order_id":"1775528104462499455","flags":128,"ts_in_delta":928,"sequence":153853,"symbol":"FCEU SI 20260615 PS"}
{"ts_recv":"2026-04-07T02:15:05.216896130Z","hd":{"ts_event":"2026-04-07T02:15:05.216865003Z","rtype":160,"publisher_id":101,"instrument_id":436},"action":"C","side":"B","price":"1.156350000","size":30,"channel_id":23,"order_id":"10998900141317275263","flags":0,"ts_in_delta":946,"sequence":153869,"symbol":"FCEU SI 20260615 PS"}
{"ts_recv":"2026-04-07T02:15:05.216896130Z","hd":{"ts_event":"2026-04-07T02:15:05.216865003Z","rtype":160,"publisher_id":101,"instrument_id":436},"action":"A","side":"B","price":"1.156340000","size":30,"channel_id":23,"order_id":"10998900142071658938","flags":0,"ts_in_delta":946,"sequence":153869,"symbol":"FCEU SI 20260615 PS"}
{"ts_recv":"2026-04-07T02:15:05.216896130Z","hd":{"ts_event":"2026-04-07T02:15:05.216865003Z","rtype":160,"publisher_id":101,"instrument_id":436},"action":"C","side":"A","price":"1.156450000","size":30,"channel_id":23,"order_id":"1775528104462499455","flags":0,"ts_in_delta":946,"sequence":153869,"symbol":"FCEU SI 20260615 PS"}
{"ts_recv":"2026-04-07T02:15:05.216896130Z","hd":{"ts_event":"2026-04-07T02:15:05.216865003Z","rtype":160,"publisher_id":101,"instrument_id":436},"action":"A","side":"A","price":"1.156440000","size":30,"channel_id":23,"order_id":"1775528105216883130","flags":128,"ts_in_delta":946,"sequence":153869,"symbol":"FCEU SI 20260615 PS"}
{"ts_recv":"2026-04-07T02:15:05.226395884Z","hd":{"ts_event":"2026-04-07T02:15:05.226376851Z","rtype":160,"publisher_id":101,"instrument_id":436},"action":"C","side":"B","price":"1.156360000","size":30,"channel_id":23,"order_id":"10998900126426913898","flags":0,"ts_in_delta":959,"sequence":153873,"symbol":"FCEU SI 20260615 PS"}
{"ts_recv":"2026-04-07T02:15:05.226395884Z","hd":{"ts_event":"2026-04-07T02:15:05.226376851Z","rtype":160,"publisher_id":101,"instrument_id":436},"action":"A","side":"B","price":"1.156340000","size":30,"channel_id":23,"order_id":"10998900142081158776","flags":0,"ts_in_delta":959,"sequence":153873,"symbol":"FCEU SI 20260615 PS"}
{"ts_recv":"2026-04-07T02:15:05.226395884Z","hd":{"ts_event":"2026-04-07T02:15:05.226376851Z","rtype":160,"publisher_id":101,"instrument_id":436},"action":"C","side":"A","price":"1.156460000","size":30,"channel_id":23,"order_id":"1775528089572138090","flags":0,"ts_in_delta":959,"sequence":153873,"symbol":"FCEU SI 20260615 PS"}
{"ts_recv":"2026-04-07T02:15:05.226395884Z","hd":{"ts_event":"2026-04-07T02:15:05.226376851Z","rtype":160,"publisher_id":101,"instrument_id":436},"action":"A","side":"A","price":"1.156440000","size":30,"channel_id":23,"order_id":"1775528105226382968","flags":128,"ts_in_delta":959,"sequence":153873,"symbol":"FCEU SI 20260615 PS"}
{"ts_recv":"2026-04-07T02:15:05.226455563Z","hd":{"ts_event":"2026-04-07T02:15:05.226435039Z","rtype":160,"publisher_id":101,"instrument_id":436},"action":"C","side":"B","price":"1.156340000","size":30,"channel_id":23,"order_id":"10998900142071658938","flags":0,"ts_in_delta":1135,"sequence":153874,"symbol":"FCEU SI 20260615 PS"}
{"ts_recv":"2026-04-07T02:15:05.226455563Z","hd":{"ts_event":"2026-04-07T02:15:05.226435039Z","rtype":160,"publisher_id":101,"instrument_id":436},"action":"A","side":"B","price":"1.156330000","size":30,"channel_id":23,"order_id":"10998900142081216849","flags":0,"ts_in_delta":1135,"sequence":153874,"symbol":"FCEU SI 20260615 PS"}
{"ts_recv":"2026-04-07T02:15:05.226455563Z","hd":{"ts_event":"2026-04-07T02:15:05.226435039Z","rtype":160,"publisher_id":101,"instrument_id":436},"action":"C","side":"A","price":"1.156440000","size":30,"channel_id":23,"order_id":"1775528105216883130","flags":0,"ts_in_delta":1135,"sequence":153874,"symbol":"FCEU SI 20260615 PS"}
{"ts_recv":"2026-04-07T02:15:05.226455563Z","hd":{"ts_event":"2026-04-07T02:15:05.226435039Z","rtype":160,"publisher_id":101,"instrument_id":436},"action":"A","side":"A","price":"1.156430000","size":30,"channel_id":23,"order_id":"1775528105226441041","flags":128,"ts_in_delta":1135,"sequence":153874,"symbol":"FCEU SI 20260615 PS"}
{"ts_recv":"2026-04-07T02:15:14.055187413Z","hd":{"ts_event":"2026-04-07T02:15:14.055166301Z","rtype":160,"publisher_id":101,"instrument_id":436},"action":"C","side":"B","price":"1.156330000","size":30,"channel_id":23,"order_id":"10998900142081216849","flags":0,"ts_in_delta":929,"sequence":153957,"symbol":"FCEU SI 20260615 PS"}
{"ts_recv":"2026-04-07T02:15:14.055187413Z","hd":{"ts_event":"2026-04-07T02:15:14.055166301Z","rtype":160,"publisher_id":101,"instrument_id":436},"action":"A","side":"B","price":"1.156320000","size":30,"channel_id":23,"order_id":"10998900150909948513","flags":0,"ts_in_delta":929,"sequence":153957,"symbol":"FCEU SI 20260615 PS"}
{"ts_recv":"2026-04-07T02:15:14.055187413Z","hd":{"ts_event":"2026-04-07T02:15:14.055166301Z","rtype":160,"publisher_id":101,"instrument_id":436},"action":"C","side":"A","price":"1.156430000","size":30,"channel_id":23,"order_id":"1775528105226441041","flags":0,"ts_in_delta":929,"sequence":153957,"symbol":"FCEU SI 20260615 PS"}
{"ts_recv":"2026-04-07T02:15:14.055187413Z","hd":{"ts_event":"2026-04-07T02:15:14.055166301Z","rtype":160,"publisher_id":101,"instrument_id":436},"action":"A","side":"A","price":"1.156420000","size":30,"channel_id":23,"order_id":"1775528114055172705","flags":128,"ts_in_delta":929,"sequence":153957,"symbol":"FCEU SI 20260615 PS"}
{"ts_recv":"2026-04-07T02:15:14.055274077Z","hd":{"ts_event":"2026-04-07T02:15:14.055258789Z","rtype":160,"publisher_id":101,"instrument_id":436},"action":"C","side":"B","price":"1.156320000","size":30,"channel_id":23,"order_id":"10998900150909948513","flags":0,"ts_in_delta":906,"sequence":153958,"symbol":"FCEU SI 20260615 PS"}
{"ts_recv":"2026-04-07T02:15:14.055274077Z","hd":{"ts_event":"2026-04-07T02:15:14.055258789Z","rtype":160,"publisher_id":101,"instrument_id":436},"action":"A","side":"B","price":"1.156330000","size":30,"channel_id":23,"order_id":"10998900150910040380","flags":0,"ts_in_delta":906,"sequence":153958,"symbol":"FCEU SI 20260615 PS"}
{"ts_recv":"2026-04-07T02:15:14.055274077Z","hd":{"ts_event":"2026-04-07T02:15:14.055258789Z","rtype":160,"publisher_id":101,"instrument_id":436},"action":"C","side":"A","price":"1.156420000","size":30,"channel_id":23,"order_id":"1775528114055172705","flags":0,"ts_in_delta":906,"sequence":153958,"symbol":"FCEU SI 20260615 PS"}
{"ts_recv":"2026-04-07T02:15:14.055274077Z","hd":{"ts_event":"2026-04-07T02:15:14.055258789Z","rtype":160,"publisher_id":101,"instrument_id":436},"action":"A","side":"A","price":"1.156430000","size":30,"channel_id":23,"order_id":"1775528114055264572","flags":128,"ts_in_delta":906,"sequence":153958,"symbol":"FCEU SI 20260615 PS"}
{"ts_recv":"2026-04-07T02:15:17.639539848Z","hd":{"ts_event":"2026-04-07T02:15:17.639512299Z","rtype":160,"publisher_id":101,"instrument_id":436},"action":"C","side":"B","price":"1.156340000","size":30,"channel_id":23,"order_id":"10998900142081158776","flags":0,"ts_in_delta":1495,"sequence":154016,"symbol":"FCEU SI 20260615 PS"}
{"ts_recv":"2026-04-07T02:15:17.639539848Z","hd":{"ts_event":"2026-04-07T02:15:17.639512299Z","rtype":160,"publisher_id":101,"instrument_id":436},"action":"A","side":"B","price":"1.156320000","size":30,"channel_id":23,"order_id":"10998900154494297139","flags":0,"ts_in_delta":1495,"sequence":154016,"symbol":"FCEU SI 20260615 PS"}
{"ts_recv":"2026-04-07T02:15:17.639539848Z","hd":{"ts_event":"2026-04-07T02:15:17.639512299Z","rtype":160,"publisher_id":101,"instrument_id":436},"action":"C","side":"A","price":"1.156440000","size":30,"channel_id":23,"order_id":"1775528105226382968","flags":0,"ts_in_delta":1495,"sequence":154016,"symbol":"FCEU SI 20260615 PS"}
{"ts_recv":"2026-04-07T02:15:17.639539848Z","hd":{"ts_event":"2026-04-07T02:15:17.639512299Z","rtype":160,"publisher_id":101,"instrument_id":436},"action":"A","side":"A","price":"1.156420000","size":30,"channel_id":23,"order_id":"1775528117639521331","flags":128,"ts_in_delta":1495,"sequence":154016,"symbol":"FCEU SI 20260615 PS"}
{"ts_recv":"2026-04-07T02:15:17.639624754Z","hd":{"ts_event":"2026-04-07T02:15:17.639608243Z","rtype":160,"publisher_id":101,"instrument_id":436},"action":"C","side":"B","price":"1.156330000","size":30,"channel_id":23,"order_id":"10998900150910040380","flags":0,"ts_in_delta":948,"sequence":154017,"symbol":"FCEU SI 20260615 PS"}
{"ts_recv":"2026-04-07T02:15:17.639624754Z","hd":{"ts_event":"2026-04-07T02:15:17.639608243Z","rtype":160,"publisher_id":101,"instrument_id":436},"action":"A","side":"B","price":"1.156320000","size":30,"channel_id":23,"order_id":"10998900154494389981","flags":0,"ts_in_delta":948,"sequence":154017,"symbol":"FCEU SI 20260615 PS"}
{"ts_recv":"2026-04-07T02:15:17.639624754Z","hd":{"ts_event":"2026-04-07T02:15:17.639608243Z","rtype":160,"publisher_id":101,"instrument_id":436},"action":"C","side":"A","price":"1.156430000","size":30,"channel_id":23,"order_id":"1775528114055264572","flags":0,"ts_in_delta":948,"sequence":154017,"symbol":"FCEU SI 20260615 PS"}
{"ts_recv":"2026-04-07T02:15:17.639624754Z","hd":{"ts_event":"2026-04-07T02:15:17.639608243Z","rtype":160,"publisher_id":101,"instrument_id":436},"action":"A","side":"A","price":"1.156420000","size":30,"channel_id":23,"order_id":"1775528117639614173","flags":128,"ts_in_delta":948,"sequence":154017,"symbol":"FCEU SI 20260615 PS"}
{"ts_recv":"2026-04-07T02:15:17.640896942Z","hd":{"ts_event":"2026-04-07T02:15:17.640879447Z","rtype":160,"publisher_id":101,"instrument_id":436},"action":"C","side":"B","price":"1.156320000","size":30,"channel_id":23,"order_id":"10998900154494389981","flags":0,"ts_in_delta":937,"sequence":154018,"symbol":"FCEU SI 20260615 PS"}
{"ts_recv":"2026-04-07T02:15:17.640896942Z","hd":{"ts_event":"2026-04-07T02:15:17.640879447Z","rtype":160,"publisher_id":101,"instrument_id":436},"action":"A","side":"B","price":"1.156310000","size":30,"channel_id":23,"order_id":"10998900154495661415","flags":0,"ts_in_delta":937,"sequence":154018,"symbol":"FCEU SI 20260615 PS"}
{"ts_recv":"2026-04-07T02:15:17.640896942Z","hd":{"ts_event":"2026-04-07T02:15:17.640879447Z","rtype":160,"publisher_id":101,"instrument_id":436},"action":"C","side":"A","price":"1.156420000","size":30,"channel_id":23,"order_id":"1775528117639614173","flags":0,"ts_in_delta":937,"sequence":154018,"symbol":"FCEU SI 20260615 PS"}
{"ts_recv":"2026-04-07T02:15:17.640896942Z","hd":{"ts_event":"2026-04-07T02:15:17.640879447Z","rtype":160,"publisher_id":101,"instrument_id":436},"action":"A","side":"A","price":"1.156410000","size":30,"channel_id":23,"order_id":"1775528117640885607","flags":128,"ts_in_delta":937,"sequence":154018,"symbol":"FCEU SI 20260615 PS"}
{"ts_recv":"2026-04-07T02:15:17.648292581Z","hd":{"ts_event":"2026-04-07T02:15:17.648271117Z","rtype":160,"publisher_id":101,"instrument_id":436},"action":"C","side":"B","price":"1.156310000","size":30,"channel_id":23,"order_id":"10998900154495661415","flags":0,"ts_in_delta":960,"sequence":154021,"symbol":"FCEU SI 20260615 PS"}
{"ts_recv":"2026-04-07T02:15:17.648292581Z","hd":{"ts_event":"2026-04-07T02:15:17.648271117Z","rtype":160,"publisher_id":101,"instrument_id":436},"action":"A","side":"B","price":"1.156300000","size":30,"channel_id":23,"order_id":"10998900154503052826","flags":0,"ts_in_delta":960,"sequence":154021,"symbol":"FCEU SI 20260615 PS"}
{"ts_recv":"2026-04-07T02:15:17.648292581Z","hd":{"ts_event":"2026-04-07T02:15:17.648271117Z","rtype":160,"publisher_id":101,"instrument_id":436},"action":"C","side":"A","price":"1.156410000","size":30,"channel_id":23,"order_id":"1775528117640885607","flags":0,"ts_in_delta":960,"sequence":154021,"symbol":"FCEU SI 20260615 PS"}
{"ts_recv":"2026-04-07T02:15:17.648292581Z","hd":{"ts_event":"2026-04-07T02:15:17.648271117Z","rtype":160,"publisher_id":101,"instrument_id":436},"action":"A","side":"A","price":"1.156400000","size":30,"channel_id":23,"order_id":"1775528117648277018","flags":128,"ts_in_delta":960,"sequence":154021,"symbol":"FCEU SI 20260615 PS"}
{"ts_recv":"2026-04-07T02:15:17.648342775Z","hd":{"ts_event":"2026-04-07T02:15:17.648325837Z","rtype":160,"publisher_id":101,"instrument_id":436},"action":"C","side":"B","price":"1.156320000","size":30,"channel_id":23,"order_id":"10998900154494297139","flags":0,"ts_in_delta":976,"sequence":154022,"symbol":"FCEU SI 20260615 PS"}
{"ts_recv":"2026-04-07T02:15:17.648342775Z","hd":{"ts_event":"2026-04-07T02:15:17.648325837Z","rtype":160,"publisher_id":101,"instrument_id":436},"action":"A","side":"B","price":"1.156300000","size":30,"channel_id":23,"order_id":"10998900154503107812","flags":0,"ts_in_delta":976,"sequence":154022,"symbol":"FCEU SI 20260615 PS"}
{"ts_recv":"2026-04-07T02:15:17.648342775Z","hd":{"ts_event":"2026-04-07T02:15:17.648325837Z","rtype":160,"publisher_id":101,"instrument_id":436},"action":"C","side":"A","price":"1.156420000","size":30,"channel_id":23,"order_id":"1775528117639521331","flags":0,"ts_in_delta":976,"sequence":154022,"symbol":"FCEU SI 20260615 PS"}
{"ts_recv":"2026-04-07T02:15:17.648342775Z","hd":{"ts_event":"2026-04-07T02:15:17.648325837Z","rtype":160,"publisher_id":101,"instrument_id":436},"action":"A","side":"A","price":"1.156400000","size":30,"channel_id":23,"order_id":"1775528117648332004","flags":128,"ts_in_delta":976,"sequence":154022,"symbol":"FCEU SI 20260615 PS"}
{"ts_recv":"2026-04-07T02:15:17.648373916Z","hd":{"ts_event":"2026-04-07T02:15:17.648356013Z","rtype":160,"publisher_id":101,"instrument_id":436},"action":"C","side":"B","price":"1.156300000","size":30,"channel_id":23,"order_id":"10998900154503052826","flags":0,"ts_in_delta":942,"sequence":154023,"symbol":"FCEU SI 20260615 PS"}
{"ts_recv":"2026-04-07T02:15:17.648373916Z","hd":{"ts_event":"2026-04-07T02:15:17.648356013Z","rtype":160,"publisher_id":101,"instrument_id":436},"action":"A","side":"B","price":"1.156310000","size":30,"channel_id":23,"order_id":"10998900154503137984","flags":0,"ts_in_delta":942,"sequence":154023,"symbol":"FCEU SI 20260615 PS"}
{"ts_recv":"2026-04-07T02:15:17.648373916Z","hd":{"ts_event":"2026-04-07T02:15:17.648356013Z","rtype":160,"publisher_id":101,"instrument_id":436},"action":"C","side":"A","price":"1.156400000","size":30,"channel_id":23,"order_id":"1775528117648277018","flags":0,"ts_in_delta":942,"sequence":154023,"symbol":"FCEU SI 20260615 PS"}
{"ts_recv":"2026-04-07T02:15:17.648373916Z","hd":{"ts_event":"2026-04-07T02:15:17.648356013Z","rtype":160,"publisher_id":101,"instrument_id":436},"action":"A","side":"A","price":"1.156410000","size":30,"channel_id":23,"order_id":"1775528117648362176","flags":128,"ts_in_delta":942,"sequence":154023,"symbol":"FCEU SI 20260615 PS"}
{"ts_recv":"2026-04-07T02:15:17.648437695Z","hd":{"ts_event":"2026-04-07T02:15:17.648419277Z","rtype":160,"publisher_id":101,"instrument_id":436},"action":"C","side":"B","price":"1.156310000","size":30,"channel_id":23,"order_id":"10998900154503137984","flags":0,"ts_in_delta":796,"sequence":154024,"symbol":"FCEU SI 20260615 PS"}
{"ts_recv":"2026-04-07T02:15:17.648437695Z","hd":{"ts_event":"2026-04-07T02:15:17.648419277Z","rtype":160,"publisher_id":101,"instrument_id":436},"action":"A","side":"B","price":"1.156300000","size":30,"channel_id":23,"order_id":"10998900154503201014","flags":0,"ts_in_delta":796,"sequence":154024,"symbol":"FCEU SI 20260615 PS"}
{"ts_recv":"2026-04-07T02:15:17.648437695Z","hd":{"ts_event":"2026-04-07T02:15:17.648419277Z","rtype":160,"publisher_id":101,"instrument_id":436},"action":"C","side":"A","price":"1.156410000","size":30,"channel_id":23,"order_id":"1775528117648362176","flags":0,"ts_in_delta":796,"sequence":154024,"symbol":"FCEU SI 20260615 PS"}
{"ts_recv":"2026-04-07T02:15:17.648437695Z","hd":{"ts_event":"2026-04-07T02:15:17.648419277Z","rtype":160,"publisher_id":101,"instrument_id":436},"action":"A","side":"A","price":"1.156400000","size":30,"channel_id":23,"order_id":"1775528117648425206","flags":128,"ts_in_delta":796,"sequence":154024,"symbol":"FCEU SI 20260615 PS"}
{"ts_recv":"2026-04-07T02:15:17.655982413Z","hd":{"ts_event":"2026-04-07T02:15:17.655964599Z","rtype":160,"publisher_id":101,"instrument_id":436},"action":"C","side":"B","price":"1.156300000","size":30,"channel_id":23,"order_id":"10998900154503201014","flags":0,"ts_in_delta":949,"sequence":154033,"symbol":"FCEU SI 20260615 PS"}
{"ts_recv":"2026-04-07T02:15:17.655982413Z","hd":{"ts_event":"2026-04-07T02:15:17.655964599Z","rtype":160,"publisher_id":101,"instrument_id":436},"action":"A","side":"B","price":"1.156290000","size":30,"channel_id":23,"order_id":"10998900154510746324","flags":0,"ts_in_delta":949,"sequence":154033,"symbol":"FCEU SI 20260615 PS"}
{"ts_recv":"2026-04-07T02:15:17.655982413Z","hd":{"ts_event":"2026-04-07T02:15:17.655964599Z","rtype":160,"publisher_id":101,"instrument_id":436},"action":"C","side":"A","price":"1.156400000","size":30,"channel_id":23,"order_id":"1775528117648425206","flags":0,"ts_in_delta":949,"sequence":154033,"symbol":"FCEU SI 20260615 PS"}
{"ts_recv":"2026-04-07T02:15:17.655982413Z","hd":{"ts_event":"2026-04-07T02:15:17.655964599Z","rtype":160,"publisher_id":101,"instrument_id":436},"action":"A","side":"A","price":"1.156390000","size":30,"channel_id":23,"order_id":"1775528117655970516","flags":128,"ts_in_delta":949,"sequence":154033,"symbol":"FCEU SI 20260615 PS"}
{"ts_recv":"2026-04-07T02:15:19.256730597Z","hd":{"ts_event":"2026-04-07T02:15:19.256711305Z","rtype":160,"publisher_id":101,"instrument_id":436},"action":"C","side":"B","price":"1.156290000","size":30,"channel_id":23,"order_id":"10998900154510746324","flags":0,"ts_in_delta":889,"sequence":154058,"symbol":"FCEU SI 20260615 PS"}
{"ts_recv":"2026-04-07T02:15:19.256730597Z","hd":{"ts_event":"2026-04-07T02:15:19.256711305Z","rtype":160,"publisher_id":101,"instrument_id":436},"action":"A","side":"B","price":"1.156300000","size":30,"channel_id":23,"order_id":"10998900156111493156","flags":0,"ts_in_delta":889,"sequence":154058,"symbol":"FCEU SI 20260615 PS"}
{"ts_recv":"2026-04-07T02:15:19.256730597Z","hd":{"ts_event":"2026-04-07T02:15:19.256711305Z","rtype":160,"publisher_id":101,"instrument_id":436},"action":"C","side":"A","price":"1.156390000","size":30,"channel_id":23,"order_id":"1775528117655970516","flags":0,"ts_in_delta":889,"sequence":154058,"symbol":"FCEU SI 20260615 PS"}
{"ts_recv":"2026-04-07T02:15:19.256730597Z","hd":{"ts_event":"2026-04-07T02:15:19.256711305Z","rtype":160,"publisher_id":101,"instrument_id":436},"action":"A","side":"A","price":"1.156400000","size":30,"channel_id":23,"order_id":"1775528119256717348","flags":128,"ts_in_delta":889,"sequence":154058,"symbol":"FCEU SI 20260615 PS"}
{"ts_recv":"2026-04-07T02:15:20.905463715Z","hd":{"ts_event":"2026-04-07T02:15:20.905445443Z","rtype":160,"publisher_id":101,"instrument_id":436},"action":"C","side":"B","price":"1.156300000","size":30,"channel_id":23,"order_id":"10998900156111493156","flags":0,"ts_in_delta":909,"sequence":154079,"symbol":"FCEU SI 20260615 PS"}
{"ts_recv":"2026-04-07T02:15:20.905463715Z","hd":{"ts_event":"2026-04-07T02:15:20.905445443Z","rtype":160,"publisher_id":101,"instrument_id":436},"action":"A","side":"B","price":"1.156290000","size":30,"channel_id":23,"order_id":"10998900157760226980","flags":0,"ts_in_delta":909,"sequence":154079,"symbol":"FCEU SI 20260615 PS"}
{"ts_recv":"2026-04-07T02:15:20.905463715Z","hd":{"ts_event":"2026-04-07T02:15:20.905445443Z","rtype":160,"publisher_id":101,"instrument_id":436},"action":"C","side":"A","price":"1.156400000","size":30,"channel_id":23,"order_id":"1775528119256717348","flags":0,"ts_in_delta":909,"sequence":154079,"symbol":"FCEU SI 20260615 PS"}
{"ts_recv":"2026-04-07T02:15:20.905463715Z","hd":{"ts_event":"2026-04-07T02:15:20.905445443Z","rtype":160,"publisher_id":101,"instrument_id":436},"action":"A","side":"A","price":"1.156390000","size":30,"channel_id":23,"order_id":"1775528120905451172","flags":128,"ts_in_delta":909,"sequence":154079,"symbol":"FCEU SI 20260615 PS"}
{"ts_recv":"2026-04-07T02:16:03.813774878Z","hd":{"ts_event":"2026-04-07T02:16:03.813750729Z","rtype":160,"publisher_id":101,"instrument_id":436},"action":"C","side":"B","price":"1.156290000","size":30,"channel_id":23,"order_id":"10998900157760226980","flags":0,"ts_in_delta":910,"sequence":154502,"symbol":"FCEU SI 20260615 PS"}
{"ts_recv":"2026-04-07T02:16:03.813774878Z","hd":{"ts_event":"2026-04-07T02:16:03.813750729Z","rtype":160,"publisher_id":101,"instrument_id":436},"action":"A","side":"B","price":"1.156300000","size":30,"channel_id":23,"order_id":"10998900200668532562","flags":0,"ts_in_delta":910,"sequence":154502,"symbol":"FCEU SI 20260615 PS"}
{"ts_recv":"2026-04-07T02:16:03.813774878Z","hd":{"ts_event":"2026-04-07T02:16:03.813750729Z","rtype":160,"publisher_id":101,"instrument_id":436},"action":"C","side":"A","price":"1.156390000","size":30,"channel_id":23,"order_id":"1775528120905451172","flags":0,"ts_in_delta":910,"sequence":154502,"symbol":"FCEU SI 20260615 PS"}
{"ts_recv":"2026-04-07T02:16:03.813774878Z","hd":{"ts_event":"2026-04-07T02:16:03.813750729Z","rtype":160,"publisher_id":101,"instrument_id":436},"action":"A","side":"A","price":"1.156400000","size":30,"channel_id":23,"order_id":"1775528163813756754","flags":128,"ts_in_delta":910,"sequence":154502,"symbol":"FCEU SI 20260615 PS"}
{"ts_recv":"2026-04-07T02:16:05.713051688Z","hd":{"ts_event":"2026-04-07T02:16:05.713032273Z","rtype":160,"publisher_id":101,"instrument_id":436},"action":"C","side":"B","price":"1.156300000","size":30,"channel_id":23,"order_id":"10998900200668532562","flags":0,"ts_in_delta":968,"sequence":154516,"symbol":"FCEU SI 20260615 PS"}
{"ts_recv":"2026-04-07T02:16:05.713051688Z","hd":{"ts_event":"2026-04-07T02:16:05.713032273Z","rtype":160,"publisher_id":101,"instrument_id":436},"action":"A","side":"B","price":"1.156310000","size":30,"channel_id":23,"order_id":"10998900202567814286","flags":0,"ts_in_delta":968,"sequence":154516,"symbol":"FCEU SI 20260615 PS"}
{"ts_recv":"2026-04-07T02:16:05.713051688Z","hd":{"ts_event":"2026-04-07T02:16:05.713032273Z","rtype":160,"publisher_id":101,"instrument_id":436},"action":"C","side":"A","price":"1.156400000","size":30,"channel_id":23,"order_id":"1775528163813756754","flags":0,"ts_in_delta":968,"sequence":154516,"symbol":"FCEU SI 20260615 PS"}
{"ts_recv":"2026-04-07T02:16:05.713051688Z","hd":{"ts_event":"2026-04-07T02:16:05.713032273Z","rtype":160,"publisher_id":101,"instrument_id":436},"action":"A","side":"A","price":"1.156410000","size":30,"channel_id":23,"order_id":"1775528165713038478","flags":128,"ts_in_delta":968,"sequence":154516,"symbol":"FCEU SI 20260615 PS"}
{"ts_recv":"2026-04-07T02:16:05.713114115Z","hd":{"ts_event":"2026-04-07T02:16:05.713091353Z","rtype":160,"publisher_id":101,"instrument_id":436},"action":"C","side":"B","price":"1.156300000","size":30,"channel_id":23,"order_id":"10998900154503107812","flags":0,"ts_in_delta":932,"sequence":154517,"symbol":"FCEU SI 20260615 PS"}
{"ts_recv":"2026-04-07T02:16:05.713114115Z","hd":{"ts_event":"2026-04-07T02:16:05.713091353Z","rtype":160,"publisher_id":101,"instrument_id":436},"action":"A","side":"B","price":"1.156320000","size":30,"channel_id":23,"order_id":"10998900202567873138","flags":0,"ts_in_delta":932,"sequence":154517,"symbol":"FCEU SI 20260615 PS"}
{"ts_recv":"2026-04-07T02:16:05.713114115Z","hd":{"ts_event":"2026-04-07T02:16:05.713091353Z","rtype":160,"publisher_id":101,"instrument_id":436},"action":"C","side":"A","price":"1.156400000","size":30,"channel_id":23,"order_id":"1775528117648332004","flags":0,"ts_in_delta":932,"sequence":154517,"symbol":"FCEU SI 20260615 PS"}
{"ts_recv":"2026-04-07T02:16:05.713114115Z","hd":{"ts_event":"2026-04-07T02:16:05.713091353Z","rtype":160,"publisher_id":101,"instrument_id":436},"action":"A","side":"A","price":"1.156420000","size":30,"channel_id":23,"order_id":"1775528165713097330","flags":128,"ts_in_delta":932,"sequence":154517,"symbol":"FCEU SI 20260615 PS"}
{"ts_recv":"2026-04-07T02:16:05.713167427Z","hd":{"ts_event":"2026-04-07T02:16:05.713151455Z","rtype":160,"publisher_id":101,"instrument_id":436},"action":"C","side":"B","price":"1.156310000","size":30,"channel_id":23,"order_id":"10998900202567814286","flags":0,"ts_in_delta":908,"sequence":154518,"symbol":"FCEU SI 20260615 PS"}
{"ts_recv":"2026-04-07T02:16:05.713167427Z","hd":{"ts_event":"2026-04-07T02:16:05.713151455Z","rtype":160,"publisher_id":101,"instrument_id":436},"action":"A","side":"B","price":"1.156320000","size":30,"channel_id":23,"order_id":"10998900202567932920","flags":0,"ts_in_delta":908,"sequence":154518,"symbol":"FCEU SI 20260615 PS"}
{"ts_recv":"2026-04-07T02:16:05.713167427Z","hd":{"ts_event":"2026-04-07T02:16:05.713151455Z","rtype":160,"publisher_id":101,"instrument_id":436},"action":"C","side":"A","price":"1.156410000","size":30,"channel_id":23,"order_id":"1775528165713038478","flags":0,"ts_in_delta":908,"sequence":154518,"symbol":"FCEU SI 20260615 PS"}
{"ts_recv":"2026-04-07T02:16:05.713167427Z","hd":{"ts_event":"2026-04-07T02:16:05.713151455Z","rtype":160,"publisher_id":101,"instrument_id":436},"action":"A","side":"A","price":"1.156420000","size":30,"channel_id":23,"order_id":"1775528165713157112","flags":128,"ts_in_delta":908,"sequence":154518,"symbol":"FCEU SI 20260615 PS"}
{"ts_recv":"2026-04-07T02:16:15.100453324Z","hd":{"ts_event":"2026-04-07T02:16:15.100428667Z","rtype":160,"publisher_id":101,"instrument_id":436},"action":"C","side":"B","price":"1.156320000","size":30,"channel_id":23,"order_id":"10998900202567932920","flags":0,"ts_in_delta":984,"sequence":154630,"symbol":"FCEU SI 20260615 PS"}
{"ts_recv":"2026-04-07T02:16:15.100453324Z","hd":{"ts_event":"2026-04-07T02:16:15.100428667Z","rtype":160,"publisher_id":101,"instrument_id":436},"action":"A","side":"B","price":"1.156330000","size":30,"channel_id":23,"order_id":"10998900211955210282","flags":0,"ts_in_delta":984,"sequence":154630,"symbol":"FCEU SI 20260615 PS"}
{"ts_recv":"2026-04-07T02:16:15.100453324Z","hd":{"ts_event":"2026-04-07T02:16:15.100428667Z","rtype":160,"publisher_id":101,"instrument_id":436},"action":"C","side":"A","price":"1.156420000","size":30,"channel_id":23,"order_id":"1775528165713157112","flags":0,"ts_in_delta":984,"sequence":154630,"symbol":"FCEU SI 20260615 PS"}
{"ts_recv":"2026-04-07T02:16:15.100453324Z","hd":{"ts_event":"2026-04-07T02:16:15.100428667Z","rtype":160,"publisher_id":101,"instrument_id":436},"action":"A","side":"A","price":"1.156430000","size":30,"channel_id":23,"order_id":"1775528175100434474","flags":128,"ts_in_delta":984,"sequence":154630,"symbol":"FCEU SI 20260615 PS"}
{"ts_recv":"2026-04-07T02:16:15.100519192Z","hd":{"ts_event":"2026-04-07T02:16:15.100496883Z","rtype":160,"publisher_id":101,"instrument_id":436},"action":"C","side":"B","price":"1.156320000","size":30,"channel_id":23,"order_id":"10998900202567873138","flags":0,"ts_in_delta":962,"sequence":154631,"symbol":"FCEU SI 20260615 PS"}
{"ts_recv":"2026-04-07T02:16:15.100519192Z","hd":{"ts_event":"2026-04-07T02:16:15.100496883Z","rtype":160,"publisher_id":101,"instrument_id":436},"action":"A","side":"B","price":"1.156340000","size":30,"channel_id":23,"order_id":"10998900211955279016","flags":0,"ts_in_delta":962,"sequence":154631,"symbol":"FCEU SI 20260615 PS"}
{"ts_recv":"2026-04-07T02:16:15.100519192Z","hd":{"ts_event":"2026-04-07T02:16:15.100496883Z","rtype":160,"publisher_id":101,"instrument_id":436},"action":"C","side":"A","price":"1.156420000","size":30,"channel_id":23,"order_id":"1775528165713097330","flags":0,"ts_in_delta":962,"sequence":154631,"symbol":"FCEU SI 20260615 PS"}
{"ts_recv":"2026-04-07T02:16:15.100519192Z","hd":{"ts_event":"2026-04-07T02:16:15.100496883Z","rtype":160,"publisher_id":101,"instrument_id":436},"action":"A","side":"A","price":"1.156440000","size":30,"channel_id":23,"order_id":"1775528175100503208","flags":128,"ts_in_delta":962,"sequence":154631,"symbol":"FCEU SI 20260615 PS"}
{"ts_recv":"2026-04-07T02:16:15.100574133Z","hd":{"ts_event":"2026-04-07T02:16:15.100556595Z","rtype":160,"publisher_id":101,"instrument_id":436},"action":"C","side":"B","price":"1.156330000","size":30,"channel_id":23,"order_id":"10998900211955210282","flags":0,"ts_in_delta":975,"sequence":154632,"symbol":"FCEU SI 20260615 PS"}
{"ts_recv":"2026-04-07T02:16:15.100574133Z","hd":{"ts_event":"2026-04-07T02:16:15.100556595Z","rtype":160,"publisher_id":101,"instrument_id":436},"action":"A","side":"B","price":"1.156340000","size":30,"channel_id":23,"order_id":"10998900211955338628","flags":0,"ts_in_delta":975,"sequence":154632,"symbol":"FCEU SI 20260615 PS"}
{"ts_recv":"2026-04-07T02:16:15.100574133Z","hd":{"ts_event":"2026-04-07T02:16:15.100556595Z","rtype":160,"publisher_id":101,"instrument_id":436},"action":"C","side":"A","price":"1.156430000","size":30,"channel_id":23,"order_id":"1775528175100434474","flags":0,"ts_in_delta":975,"sequence":154632,"symbol":"FCEU SI 20260615 PS"}
{"ts_recv":"2026-04-07T02:16:15.100574133Z","hd":{"ts_event":"2026-04-07T02:16:15.100556595Z","rtype":160,"publisher_id":101,"instrument_id":436},"action":"A","side":"A","price":"1.156440000","size":30,"channel_id":23,"order_id":"1775528175100562820","flags":128,"ts_in_delta":975,"sequence":154632,"symbol":"FCEU SI 20260615 PS"}
{"ts_recv":"2026-04-07T02:16:19.551945551Z","hd":{"ts_event":"2026-04-07T02:16:19.551918187Z","rtype":160,"publisher_id":101,"instrument_id":436},"action":"C","side":"B","price":"1.156340000","size":30,"channel_id":23,"order_id":"10998900211955338628","flags":0,"ts_in_delta":1408,"sequence":154717,"symbol":"FCEU SI 20260615 PS"}
{"ts_recv":"2026-04-07T02:16:19.551945551Z","hd":{"ts_event":"2026-04-07T02:16:19.551918187Z","rtype":160,"publisher_id":101,"instrument_id":436},"action":"A","side":"B","price":"1.156330000","size":30,"channel_id":23,"order_id":"10998900216406701887","flags":0,"ts_in_delta":1408,"sequence":154717,"symbol":"FCEU SI 20260615 PS"}
{"ts_recv":"2026-04-07T02:16:19.551945551Z","hd":{"ts_event":"2026-04-07T02:16:19.551918187Z","rtype":160,"publisher_id":101,"instrument_id":436},"action":"C","side":"A","price":"1.156440000","size":30,"channel_id":23,"order_id":"1775528175100562820","flags":0,"ts_in_delta":1408,"sequence":154717,"symbol":"FCEU SI 20260615 PS"}
{"ts_recv":"2026-04-07T02:16:19.551945551Z","hd":{"ts_event":"2026-04-07T02:16:19.551918187Z","rtype":160,"publisher_id":101,"instrument_id":436},"action":"A","side":"A","price":"1.156430000","size":30,"channel_id":23,"order_id":"1775528179551926079","flags":128,"ts_in_delta":1408,"sequence":154717,"symbol":"FCEU SI 20260615 PS"}
{"ts_recv":"2026-04-07T02:16:20.575496686Z","hd":{"ts_event":"2026-04-07T02:16:20.575469827Z","rtype":160,"publisher_id":101,"instrument_id":436},"action":"C","side":"B","price":"1.156330000","size":30,"channel_id":23,"order_id":"10998900216406701887","flags":0,"ts_in_delta":1434,"sequence":154726,"symbol":"FCEU SI 20260615 PS"}
{"ts_recv":"2026-04-07T02:16:20.575496686Z","hd":{"ts_event":"2026-04-07T02:16:20.575469827Z","rtype":160,"publisher_id":101,"instrument_id":436},"action":"A","side":"B","price":"1.156340000","size":30,"channel_id":23,"order_id":"10998900217430258601","flags":0,"ts_in_delta":1434,"sequence":154726,"symbol":"FCEU SI 20260615 PS"}
{"ts_recv":"2026-04-07T02:16:20.575496686Z","hd":{"ts_event":"2026-04-07T02:16:20.575469827Z","rtype":160,"publisher_id":101,"instrument_id":436},"action":"C","side":"A","price":"1.156430000","size":30,"channel_id":23,"order_id":"1775528179551926079","flags":0,"ts_in_delta":1434,"sequence":154726,"symbol":"FCEU SI 20260615 PS"}
{"ts_recv":"2026-04-07T02:16:20.575496686Z","hd":{"ts_event":"2026-04-07T02:16:20.575469827Z","rtype":160,"publisher_id":101,"instrument_id":436},"action":"A","side":"A","price":"1.156440000","size":30,"channel_id":23,"order_id":"1775528180575482793","flags":128,"ts_in_delta":1434,"sequence":154726,"symbol":"FCEU SI 20260615 PS"}
{"ts_recv":"2026-04-07T02:16:21.987528978Z","hd":{"ts_event":"2026-04-07T02:16:21.987505569Z","rtype":160,"publisher_id":101,"instrument_id":436},"action":"C","side":"B","price":"1.156340000","size":30,"channel_id":23,"order_id":"10998900217430258601","flags":0,"ts_in_delta":908,"sequence":154734,"symbol":"FCEU SI 20260615 PS"}
{"ts_recv":"2026-04-07T02:16:21.987528978Z","hd":{"ts_event":"2026-04-07T02:16:21.987505569Z","rtype":160,"publisher_id":101,"instrument_id":436},"action":"A","side":"B","price":"1.156330000","size":30,"channel_id":23,"order_id":"10998900218842288038","flags":0,"ts_in_delta":908,"sequence":154734,"symbol":"FCEU SI 20260615 PS"}
{"ts_recv":"2026-04-07T02:16:21.987528978Z","hd":{"ts_event":"2026-04-07T02:16:21.987505569Z","rtype":160,"publisher_id":101,"instrument_id":436},"action":"C","side":"A","price":"1.156440000","size":30,"channel_id":23,"order_id":"1775528180575482793","flags":0,"ts_in_delta":908,"sequence":154734,"symbol":"FCEU SI 20260615 PS"}
{"ts_recv":"2026-04-07T02:16:21.987528978Z","hd":{"ts_event":"2026-04-07T02:16:21.987505569Z","rtype":160,"publisher_id":101,"instrument_id":436},"action":"A","side":"A","price":"1.156430000","size":30,"channel_id":23,"order_id":"1775528181987512230","flags":128,"ts_in_delta":908,"sequence":154734,"symbol":"FCEU SI 20260615 PS"}
{"ts_recv":"2026-04-07T02:16:30.878763622Z","hd":{"ts_event":"2026-04-07T02:16:30.878732695Z","rtype":160,"publisher_id":101,"instrument_id":436},"action":"C","side":"B","price":"1.156340000","size":30,"channel_id":23,"order_id":"10998900211955279016","flags":0,"ts_in_delta":1294,"sequence":154809,"symbol":"FCEU SI 20260615 PS"}
{"ts_recv":"2026-04-07T02:16:30.878763622Z","hd":{"ts_event":"2026-04-07T02:16:30.878732695Z","rtype":160,"publisher_id":101,"instrument_id":436},"action":"A","side":"B","price":"1.156320000","size":30,"channel_id":23,"order_id":"10998900227733517256","flags":0,"ts_in_delta":1294,"sequence":154809,"symbol":"FCEU SI 20260615 PS"}
{"ts_recv":"2026-04-07T02:16:30.878763622Z","hd":{"ts_event":"2026-04-07T02:16:30.878732695Z","rtype":160,"publisher_id":101,"instrument_id":436},"action":"C","side":"A","price":"1.156440000","size":30,"channel_id":23,"order_id":"1775528175100503208","flags":0,"ts_in_delta":1294,"sequence":154809,"symbol":"FCEU SI 20260615 PS"}
{"ts_recv":"2026-04-07T02:16:30.878763622Z","hd":{"ts_event":"2026-04-07T02:16:30.878732695Z","rtype":160,"publisher_id":101,"instrument_id":436},"action":"A","side":"A","price":"1.156420000","size":30,"channel_id":23,"order_id":"1775528190878741448","flags":128,"ts_in_delta":1294,"sequence":154809,"symbol":"FCEU SI 20260615 PS"}
{"ts_recv":"2026-04-07T02:16:30.878880352Z","hd":{"ts_event":"2026-04-07T02:16:30.878863717Z","rtype":160,"publisher_id":101,"instrument_id":436},"action":"C","side":"B","price":"1.156330000","size":30,"channel_id":23,"order_id":"10998900218842288038","flags":0,"ts_in_delta":910,"sequence":154810,"symbol":"FCEU SI 20260615 PS"}
{"ts_recv":"2026-04-07T02:16:30.878880352Z","hd":{"ts_event":"2026-04-07T02:16:30.878863717Z","rtype":160,"publisher_id":101,"instrument_id":436},"action":"A","side":"B","price":"1.156320000","size":30,"channel_id":23,"order_id":"10998900227733645507","flags":0,"ts_in_delta":910,"sequence":154810,"symbol":"FCEU SI 20260615 PS"}
{"ts_recv":"2026-04-07T02:16:30.878880352Z","hd":{"ts_event":"2026-04-07T02:16:30.878863717Z","rtype":160,"publisher_id":101,"instrument_id":436},"action":"C","side":"A","price":"1.156430000","size":30,"channel_id":23,"order_id":"1775528181987512230","flags":0,"ts_in_delta":910,"sequence":154810,"symbol":"FCEU SI 20260615 PS"}
{"ts_recv":"2026-04-07T02:16:30.878880352Z","hd":{"ts_event":"2026-04-07T02:16:30.878863717Z","rtype":160,"publisher_id":101,"instrument_id":436},"action":"A","side":"A","price":"1.156420000","size":30,"channel_id":23,"order_id":"1775528190878869699","flags":128,"ts_in_delta":910,"sequence":154810,"symbol":"FCEU SI 20260615 PS"}
{"ts_recv":"2026-04-07T02:16:30.894421832Z","hd":{"ts_event":"2026-04-07T02:16:30.894404363Z","rtype":160,"publisher_id":101,"instrument_id":436},"action":"C","side":"B","price":"1.156320000","size":30,"channel_id":23,"order_id":"10998900227733645507","flags":0,"ts_in_delta":902,"sequence":154824,"symbol":"FCEU SI 20260615 PS"}
{"ts_recv":"2026-04-07T02:16:30.894421832Z","hd":{"ts_event":"2026-04-07T02:16:30.894404363Z","rtype":160,"publisher_id":101,"instrument_id":436},"action":"A","side":"B","price":"1.156310000","size":30,"channel_id":23,"order_id":"10998900227749185667","flags":0,"ts_in_delta":902,"sequence":154824,"symbol":"FCEU SI 20260615 PS"}
{"ts_recv":"2026-04-07T02:16:30.894421832Z","hd":{"ts_event":"2026-04-07T02:16:30.894404363Z","rtype":160,"publisher_id":101,"instrument_id":436},"action":"C","side":"A","price":"1.156420000","size":30,"channel_id":23,"order_id":"1775528190878869699","flags":0,"ts_in_delta":902,"sequence":154824,"symbol":"FCEU SI 20260615 PS"}
{"ts_recv":"2026-04-07T02:16:30.894421832Z","hd":{"ts_event":"2026-04-07T02:16:30.894404363Z","rtype":160,"publisher_id":101,"instrument_id":436},"action":"A","side":"A","price":"1.156410000","size":30,"channel_id":23,"order_id":"1775528190894409859","flags":128,"ts_in_delta":902,"sequence":154824,"symbol":"FCEU SI 20260615 PS"}
{"ts_recv":"2026-04-07T02:16:30.894473531Z","hd":{"ts_event":"2026-04-07T02:16:30.894455237Z","rtype":160,"publisher_id":101,"instrument_id":436},"action":"C","side":"B","price":"1.156320000","size":30,"channel_id":23,"order_id":"10998900227733517256","flags":0,"ts_in_delta":719,"sequence":154825,"symbol":"FCEU SI 20260615 PS"}
{"ts_recv":"2026-04-07T02:16:30.894473531Z","hd":{"ts_event":"2026-04-07T02:16:30.894455237Z","rtype":160,"publisher_id":101,"instrument_id":436},"action":"A","side":"B","price":"1.156300000","size":30,"channel_id":23,"order_id":"10998900227749237113","flags":0,"ts_in_delta":719,"sequence":154825,"symbol":"FCEU SI 20260615 PS"}
{"ts_recv":"2026-04-07T02:16:30.894473531Z","hd":{"ts_event":"2026-04-07T02:16:30.894455237Z","rtype":160,"publisher_id":101,"instrument_id":436},"action":"C","side":"A","price":"1.156420000","size":30,"channel_id":23,"order_id":"1775528190878741448","flags":0,"ts_in_delta":719,"sequence":154825,"symbol":"FCEU SI 20260615 PS"}
{"ts_recv":"2026-04-07T02:16:30.894473531Z","hd":{"ts_event":"2026-04-07T02:16:30.894455237Z","rtype":160,"publisher_id":101,"instrument_id":436},"action":"A","side":"A","price":"1.156400000","size":30,"channel_id":23,"order_id":"1775528190894461305","flags":128,"ts_in_delta":719,"sequence":154825,"symbol":"FCEU SI 20260615 PS"}
{"ts_recv":"2026-04-07T02:16:30.894483914Z","hd":{"ts_event":"2026-04-07T02:16:30.894463975Z","rtype":160,"publisher_id":101,"instrument_id":436},"action":"C","side":"B","price":"1.156310000","size":30,"channel_id":23,"order_id":"10998900227749185667","flags":0,"ts_in_delta":714,"sequence":154826,"symbol":"FCEU SI 20260615 PS"}
{"ts_recv":"2026-04-07T02:16:30.894483914Z","hd":{"ts_event":"2026-04-07T02:16:30.894463975Z","rtype":160,"publisher_id":101,"instrument_id":436},"action":"A","side":"B","price":"1.156300000","size":30,"channel_id":23,"order_id":"10998900227749246519","flags":0,"ts_in_delta":714,"sequence":154826,"symbol":"FCEU SI 20260615 PS"}
{"ts_recv":"2026-04-07T02:16:30.894483914Z","hd":{"ts_event":"2026-04-07T02:16:30.894463975Z","rtype":160,"publisher_id":101,"instrument_id":436},"action":"C","side":"A","price":"1.156410000","size":30,"channel_id":23,"order_id":"1775528190894409859","flags":0,"ts_in_delta":714,"sequence":154826,"symbol":"FCEU SI 20260615 PS"}
{"ts_recv":"2026-04-07T02:16:30.894483914Z","hd":{"ts_event":"2026-04-07T02:16:30.894463975Z","rtype":160,"publisher_id":101,"instrument_id":436},"action":"A","side":"A","price":"1.156400000","size":30,"channel_id":23,"order_id":"1775528190894470711","flags":128,"ts_in_delta":714,"sequence":154826,"symbol":"FCEU SI 20260615 PS"}
{"ts_recv":"2026-04-07T02:16:39.503213616Z","hd":{"ts_event":"2026-04-07T02:16:39.503192175Z","rtype":160,"publisher_id":101,"instrument_id":436},"action":"C","side":"B","price":"1.156300000","size":30,"channel_id":23,"order_id":"10998900227749246519","flags":0,"ts_in_delta":931,"sequence":154904,"symbol":"FCEU SI 20260615 PS"}
{"ts_recv":"2026-04-07T02:16:39.503213616Z","hd":{"ts_event":"2026-04-07T02:16:39.503192175Z","rtype":160,"publisher_id":101,"instrument_id":436},"action":"A","side":"B","price":"1.156310000","size":30,"channel_id":23,"order_id":"10998900236357974003","flags":0,"ts_in_delta":931,"sequence":154904,"symbol":"FCEU SI 20260615 PS"}
{"ts_recv":"2026-04-07T02:16:39.503213616Z","hd":{"ts_event":"2026-04-07T02:16:39.503192175Z","rtype":160,"publisher_id":101,"instrument_id":436},"action":"C","side":"A","price":"1.156400000","size":30,"channel_id":23,"order_id":"1775528190894470711","flags":0,"ts_in_delta":931,"sequence":154904,"symbol":"FCEU SI 20260615 PS"}
{"ts_recv":"2026-04-07T02:16:39.503213616Z","hd":{"ts_event":"2026-04-07T02:16:39.503192175Z","rtype":160,"publisher_id":101,"instrument_id":436},"action":"A","side":"A","price":"1.156410000","size":30,"channel_id":23,"order_id":"1775528199503198195","flags":128,"ts_in_delta":931,"sequence":154904,"symbol":"FCEU SI 20260615 PS"}
{"ts_recv":"2026-04-07T02:16:39.504246890Z","hd":{"ts_event":"2026-04-07T02:16:39.504226025Z","rtype":160,"publisher_id":101,"instrument_id":436},"action":"C","side":"B","price":"1.156300000","size":30,"channel_id":23,"order_id":"10998900227749237113","flags":0,"ts_in_delta":967,"sequence":154907,"symbol":"FCEU SI 20260615 PS"}
{"ts_recv":"2026-04-07T02:16:39.504246890Z","hd":{"ts_event":"2026-04-07T02:16:39.504226025Z","rtype":160,"publisher_id":101,"instrument_id":436},"action":"A","side":"B","price":"1.156320000","size":30,"channel_id":23,"order_id":"10998900236359007600","flags":0,"ts_in_delta":967,"sequence":154907,"symbol":"FCEU SI 20260615 PS"}
{"ts_recv":"2026-04-07T02:16:39.504246890Z","hd":{"ts_event":"2026-04-07T02:16:39.504226025Z","rtype":160,"publisher_id":101,"instrument_id":436},"action":"C","side":"A","price":"1.156400000","size":30,"channel_id":23,"order_id":"1775528190894461305","flags":0,"ts_in_delta":967,"sequence":154907,"symbol":"FCEU SI 20260615 PS"}
{"ts_recv":"2026-04-07T02:16:39.504246890Z","hd":{"ts_event":"2026-04-07T02:16:39.504226025Z","rtype":160,"publisher_id":101,"instrument_id":436},"action":"A","side":"A","price":"1.156420000","size":30,"channel_id":23,"order_id":"1775528199504231792","flags":128,"ts_in_delta":967,"sequence":154907,"symbol":"FCEU SI 20260615 PS"}
{"ts_recv":"2026-04-07T02:16:39.504306208Z","hd":{"ts_event":"2026-04-07T02:16:39.504289097Z","rtype":160,"publisher_id":101,"instrument_id":436},"action":"C","side":"B","price":"1.156310000","size":30,"channel_id":23,"order_id":"10998900236357974003","flags":0,"ts_in_delta":912,"sequence":154908,"symbol":"FCEU SI 20260615 PS"}
{"ts_recv":"2026-04-07T02:16:39.504306208Z","hd":{"ts_event":"2026-04-07T02:16:39.504289097Z","rtype":160,"publisher_id":101,"instrument_id":436},"action":"A","side":"B","price":"1.156320000","size":30,"channel_id":23,"order_id":"10998900236359070737","flags":0,"ts_in_delta":912,"sequence":154908,"symbol":"FCEU SI 20260615 PS"}
{"ts_recv":"2026-04-07T02:16:39.504306208Z","hd":{"ts_event":"2026-04-07T02:16:39.504289097Z","rtype":160,"publisher_id":101,"instrument_id":436},"action":"C","side":"A","price":"1.156410000","size":30,"channel_id":23,"order_id":"1775528199503198195","flags":0,"ts_in_delta":912,"sequence":154908,"symbol":"FCEU SI 20260615 PS"}
{"ts_recv":"2026-04-07T02:16:39.504306208Z","hd":{"ts_event":"2026-04-07T02:16:39.504289097Z","rtype":160,"publisher_id":101,"instrument_id":436},"action":"A","side":"A","price":"1.156420000","size":30,"channel_id":23,"order_id":"1775528199504294929","flags":128,"ts_in_delta":912,"sequence":154908,"symbol":"FCEU SI 20260615 PS"}
{"ts_recv":"2026-04-07T02:16:39.513271321Z","hd":{"ts_event":"2026-04-07T02:16:39.513251609Z","rtype":160,"publisher_id":101,"instrument_id":436},"action":"C","side":"B","price":"1.156320000","size":30,"channel_id":23,"order_id":"10998900236359070737","flags":0,"ts_in_delta":923,"sequence":154913,"symbol":"FCEU SI 20260615 PS"}
{"ts_recv":"2026-04-07T02:16:39.513271321Z","hd":{"ts_event":"2026-04-07T02:16:39.513251609Z","rtype":160,"publisher_id":101,"instrument_id":436},"action":"A","side":"B","price":"1.156330000","size":30,"channel_id":23,"order_id":"10998900236368033518","flags":0,"ts_in_delta":923,"sequence":154913,"symbol":"FCEU SI 20260615 PS"}
{"ts_recv":"2026-04-07T02:16:39.513271321Z","hd":{"ts_event":"2026-04-07T02:16:39.513251609Z","rtype":160,"publisher_id":101,"instrument_id":436},"action":"C","side":"A","price":"1.156420000","size":30,"channel_id":23,"order_id":"1775528199504294929","flags":0,"ts_in_delta":923,"sequence":154913,"symbol":"FCEU SI 20260615 PS"}
{"ts_recv":"2026-04-07T02:16:39.513271321Z","hd":{"ts_event":"2026-04-07T02:16:39.513251609Z","rtype":160,"publisher_id":101,"instrument_id":436},"action":"A","side":"A","price":"1.156430000","size":30,"channel_id":23,"order_id":"1775528199513257710","flags":128,"ts_in_delta":923,"sequence":154913,"symbol":"FCEU SI 20260615 PS"}
{"ts_recv":"2026-04-07T02:16:39.784816678Z","hd":{"ts_event":"2026-04-07T02:16:39.784795481Z","rtype":160,"publisher_id":101,"instrument_id":436},"action":"C","side":"B","price":"1.156320000","size":30,"channel_id":23,"order_id":"10998900236359007600","flags":0,"ts_in_delta":910,"sequence":154946,"symbol":"FCEU SI 20260615 PS"}
{"ts_recv":"2026-04-07T02:16:39.784816678Z","hd":{"ts_event":"2026-04-07T02:16:39.784795481Z","rtype":160,"publisher_id":101,"instrument_id":436},"action":"A","side":"B","price":"1.156340000","size":30,"channel_id":23,"order_id":"10998900236639576992","flags":0,"ts_in_delta":910,"sequence":154946,"symbol":"FCEU SI 20260615 PS"}
{"ts_recv":"2026-04-07T02:16:39.784816678Z","hd":{"ts_event":"2026-04-07T02:16:39.784795481Z","rtype":160,"publisher_id":101,"instrument_id":436},"action":"C","side":"A","price":"1.156420000","size":30,"channel_id":23,"order_id":"1775528199504231792","flags":0,"ts_in_delta":910,"sequence":154946,"symbol":"FCEU SI 20260615 PS"}
{"ts_recv":"2026-04-07T02:16:39.784816678Z","hd":{"ts_event":"2026-04-07T02:16:39.784795481Z","rtype":160,"publisher_id":101,"instrument_id":436},"action":"A","side":"A","price":"1.156440000","size":30,"channel_id":23,"order_id":"1775528199784801184","flags":128,"ts_in_delta":910,"sequence":154946,"symbol":"FCEU SI 20260615 PS"}
{"ts_recv":"2026-04-07T02:16:39.784878952Z","hd":{"ts_event":"2026-04-07T02:16:39.784859151Z","rtype":160,"publisher_id":101,"instrument_id":436},"action":"C","side":"B","price":"1.156330000","size":30,"channel_id":23,"order_id":"10998900236368033518","flags":0,"ts_in_delta":1078,"sequence":154947,"symbol":"FCEU SI 20260615 PS"}
{"ts_recv":"2026-04-07T02:16:39.784878952Z","hd":{"ts_event":"2026-04-07T02:16:39.784859151Z","rtype":160,"publisher_id":101,"instrument_id":436},"action":"A","side":"B","price":"1.156340000","size":30,"channel_id":23,"order_id":"10998900236639640783","flags":0,"ts_in_delta":1078,"sequence":154947,"symbol":"FCEU SI 20260615 PS"}
{"ts_recv":"2026-04-07T02:16:39.784878952Z","hd":{"ts_event":"2026-04-07T02:16:39.784859151Z","rtype":160,"publisher_id":101,"instrument_id":436},"action":"C","side":"A","price":"1.156430000","size":30,"channel_id":23,"order_id":"1775528199513257710","flags":0,"ts_in_delta":1078,"sequence":154947,"symbol":"FCEU SI 20260615 PS"}
{"ts_recv":"2026-04-07T02:16:39.784878952Z","hd":{"ts_event":"2026-04-07T02:16:39.784859151Z","rtype":160,"publisher_id":101,"instrument_id":436},"action":"A","side":"A","price":"1.156440000","size":30,"channel_id":23,"order_id":"1775528199784864975","flags":128,"ts_in_delta":1078,"sequence":154947,"symbol":"FCEU SI 20260615 PS"}
{"ts_recv":"2026-04-07T02:16:42.648810892Z","hd":{"ts_event":"2026-04-07T02:16:42.648790661Z","rtype":160,"publisher_id":101,"instrument_id":436},"action":"C","side":"B","price":"1.156340000","size":30,"channel_id":23,"order_id":"10998900236639640783","flags":0,"ts_in_delta":1038,"sequence":154999,"symbol":"FCEU SI 20260615 PS"}
{"ts_recv":"2026-04-07T02:16:42.648810892Z","hd":{"ts_event":"2026-04-07T02:16:42.648790661Z","rtype":160,"publisher_id":101,"instrument_id":436},"action":"A","side":"B","price":"1.156330000","size":30,"channel_id":23,"order_id":"10998900239503572421","flags":0,"ts_in_delta":1038,"sequence":154999,"symbol":"FCEU SI 20260615 PS"}
{"ts_recv":"2026-04-07T02:16:42.648810892Z","hd":{"ts_event":"2026-04-07T02:16:42.648790661Z","rtype":160,"publisher_id":101,"instrument_id":436},"action":"C","side":"A","price":"1.156440000","size":30,"channel_id":23,"order_id":"1775528199784864975","flags":0,"ts_in_delta":1038,"sequence":154999,"symbol":"FCEU SI 20260615 PS"}
{"ts_recv":"2026-04-07T02:16:42.648810892Z","hd":{"ts_event":"2026-04-07T02:16:42.648790661Z","rtype":160,"publisher_id":101,"instrument_id":436},"action":"A","side":"A","price":"1.156430000","size":30,"channel_id":23,"order_id":"1775528202648796613","flags":128,"ts_in_delta":1038,"sequence":154999,"symbol":"FCEU SI 20260615 PS"}
{"ts_recv":"2026-04-07T02:16:42.651383183Z","hd":{"ts_event":"2026-04-07T02:16:42.651364075Z","rtype":160,"publisher_id":101,"instrument_id":436},"action":"C","side":"B","price":"1.156340000","size":30,"channel_id":23,"order_id":"10998900236639576992","flags":0,"ts_in_delta":1197,"sequence":155000,"symbol":"FCEU SI 20260615 PS"}
{"ts_recv":"2026-04-07T02:16:42.651383183Z","hd":{"ts_event":"2026-04-07T02:16:42.651364075Z","rtype":160,"publisher_id":101,"instrument_id":436},"action":"A","side":"B","price":"1.156320000","size":30,"channel_id":23,"order_id":"10998900239506145999","flags":0,"ts_in_delta":1197,"sequence":155000,"symbol":"FCEU SI 20260615 PS"}
{"ts_recv":"2026-04-07T02:16:42.651383183Z","hd":{"ts_event":"2026-04-07T02:16:42.651364075Z","rtype":160,"publisher_id":101,"instrument_id":436},"action":"C","side":"A","price":"1.156440000","size":30,"channel_id":23,"order_id":"1775528199784801184","flags":0,"ts_in_delta":1197,"sequence":155000,"symbol":"FCEU SI 20260615 PS"}
{"ts_recv":"2026-04-07T02:16:42.651383183Z","hd":{"ts_event":"2026-04-07T02:16:42.651364075Z","rtype":160,"publisher_id":101,"instrument_id":436},"action":"A","side":"A","price":"1.156420000","size":30,"channel_id":23,"order_id":"1775528202651370191","flags":128,"ts_in_delta":1197,"sequence":155000,"symbol":"FCEU SI 20260615 PS"}
{"ts_recv":"2026-04-07T02:16:42.651450034Z","hd":{"ts_event":"2026-04-07T02:16:42.651430987Z","rtype":160,"publisher_id":101,"instrument_id":436},"action":"C","side":"B","price":"1.156330000","size":30,"channel_id":23,"order_id":"10998900239503572421","flags":0,"ts_in_delta":928,"sequence":155001,"symbol":"FCEU SI 20260615 PS"}
{"ts_recv":"2026-04-07T02:16:42.651450034Z","hd":{"ts_event":"2026-04-07T02:16:42.651430987Z","rtype":160,"publisher_id":101,"instrument_id":436},"action":"A","side":"B","price":"1.156320000","size":30,"channel_id":23,"order_id":"10998900239506212773","flags":0,"ts_in_delta":928,"sequence":155001,"symbol":"FCEU SI 20260615 PS"}
{"ts_recv":"2026-04-07T02:16:42.651450034Z","hd":{"ts_event":"2026-04-07T02:16:42.651430987Z","rtype":160,"publisher_id":101,"instrument_id":436},"action":"C","side":"A","price":"1.156430000","size":30,"channel_id":23,"order_id":"1775528202648796613","flags":0,"ts_in_delta":928,"sequence":155001,"symbol":"FCEU SI 20260615 PS"}
{"ts_recv":"2026-04-07T02:16:42.651450034Z","hd":{"ts_event":"2026-04-07T02:16:42.651430987Z","rtype":160,"publisher_id":101,"instrument_id":436},"action":"A","side":"A","price":"1.156420000","size":30,"channel_id":23,"order_id":"1775528202651436965","flags":128,"ts_in_delta":928,"sequence":155001,"symbol":"FCEU SI 20260615 PS"}
{"ts_recv":"2026-04-07T02:16:42.654242308Z","hd":{"ts_event":"2026-04-07T02:16:42.654220815Z","rtype":160,"publisher_id":101,"instrument_id":436},"action":"C","side":"B","price":"1.156320000","size":30,"channel_id":23,"order_id":"10998900239506212773","flags":0,"ts_in_delta":964,"sequence":155002,"symbol":"FCEU SI 20260615 PS"}
{"ts_recv":"2026-04-07T02:16:42.654242308Z","hd":{"ts_event":"2026-04-07T02:16:42.654220815Z","rtype":160,"publisher_id":101,"instrument_id":436},"action":"A","side":"B","price":"1.156310000","size":30,"channel_id":23,"order_id":"10998900239509002659","flags":0,"ts_in_delta":964,"sequence":155002,"symbol":"FCEU SI 20260615 PS"}
{"ts_recv":"2026-04-07T02:16:42.654242308Z","hd":{"ts_event":"2026-04-07T02:16:42.654220815Z","rtype":160,"publisher_id":101,"instrument_id":436},"action":"C","side":"A","price":"1.156420000","size":30,"channel_id":23,"order_id":"1775528202651436965","flags":0,"ts_in_delta":964,"sequence":155002,"symbol":"FCEU SI 20260615 PS"}
{"ts_recv":"2026-04-07T02:16:42.654242308Z","hd":{"ts_event":"2026-04-07T02:16:42.654220815Z","rtype":160,"publisher_id":101,"instrument_id":436},"action":"A","side":"A","price":"1.156410000","size":30,"channel_id":23,"order_id":"1775528202654226851","flags":128,"ts_in_delta":964,"sequence":155002,"symbol":"FCEU SI 20260615 PS"}
{"ts_recv":"2026-04-07T02:16:42.659060673Z","hd":{"ts_event":"2026-04-07T02:16:42.659039997Z","rtype":160,"publisher_id":101,"instrument_id":436},"action":"C","side":"B","price":"1.156310000","size":30,"channel_id":23,"order_id":"10998900239509002659","flags":0,"ts_in_delta":968,"sequence":155004,"symbol":"FCEU SI 20260615 PS"}
{"ts_recv":"2026-04-07T02:16:42.659060673Z","hd":{"ts_event":"2026-04-07T02:16:42.659039997Z","rtype":160,"publisher_id":101,"instrument_id":436},"action":"A","side":"B","price":"1.156300000","size":30,"channel_id":23,"order_id":"10998900239513821938","flags":0,"ts_in_delta":968,"sequence":155004,"symbol":"FCEU SI 20260615 PS"}
{"ts_recv":"2026-04-07T02:16:42.659060673Z","hd":{"ts_event":"2026-04-07T02:16:42.659039997Z","rtype":160,"publisher_id":101,"instrument_id":436},"action":"C","side":"A","price":"1.156410000","size":30,"channel_id":23,"order_id":"1775528202654226851","flags":0,"ts_in_delta":968,"sequence":155004,"symbol":"FCEU SI 20260615 PS"}
{"ts_recv":"2026-04-07T02:16:42.659060673Z","hd":{"ts_event":"2026-04-07T02:16:42.659039997Z","rtype":160,"publisher_id":101,"instrument_id":436},"action":"A","side":"A","price":"1.156400000","size":30,"channel_id":23,"order_id":"1775528202659046130","flags":128,"ts_in_delta":968,"sequence":155004,"symbol":"FCEU SI 20260615 PS"}
{"ts_recv":"2026-04-07T02:16:42.659110184Z","hd":{"ts_event":"2026-04-07T02:16:42.659092369Z","rtype":160,"publisher_id":101,"instrument_id":436},"action":"C","side":"B","price":"1.156320000","size":30,"channel_id":23,"order_id":"10998900239506145999","flags":0,"ts_in_delta":943,"sequence":155005,"symbol":"FCEU SI 20260615 PS"}
{"ts_recv":"2026-04-07T02:16:42.659110184Z","hd":{"ts_event":"2026-04-07T02:16:42.659092369Z","rtype":160,"publisher_id":101,"instrument_id":436},"action":"A","side":"B","price":"1.156300000","size":30,"channel_id":23,"order_id":"10998900239513874449","flags":0,"ts_in_delta":943,"sequence":155005,"symbol":"FCEU SI 20260615 PS"}
{"ts_recv":"2026-04-07T02:16:42.659110184Z","hd":{"ts_event":"2026-04-07T02:16:42.659092369Z","rtype":160,"publisher_id":101,"instrument_id":436},"action":"C","side":"A","price":"1.156420000","size":30,"channel_id":23,"order_id":"1775528202651370191","flags":0,"ts_in_delta":943,"sequence":155005,"symbol":"FCEU SI 20260615 PS"}
{"ts_recv":"2026-04-07T02:16:42.659110184Z","hd":{"ts_event":"2026-04-07T02:16:42.659092369Z","rtype":160,"publisher_id":101,"instrument_id":436},"action":"A","side":"A","price":"1.156400000","size":30,"channel_id":23,"order_id":"1775528202659098641","flags":128,"ts_in_delta":943,"sequence":155005,"symbol":"FCEU SI 20260615 PS"}
{"ts_recv":"2026-04-07T02:16:42.659140449Z","hd":{"ts_event":"2026-04-07T02:16:42.659122989Z","rtype":160,"publisher_id":101,"instrument_id":436},"action":"C","side":"B","price":"1.156300000","size":30,"channel_id":23,"order_id":"10998900239513821938","flags":0,"ts_in_delta":931,"sequence":155006,"symbol":"FCEU SI 20260615 PS"}
{"ts_recv":"2026-04-07T02:16:42.659140449Z","hd":{"ts_event":"2026-04-07T02:16:42.659122989Z","rtype":160,"publisher_id":101,"instrument_id":436},"action":"A","side":"B","price":"1.156310000","size":30,"channel_id":23,"order_id":"10998900239513904652","flags":0,"ts_in_delta":931,"sequence":155006,"symbol":"FCEU SI 20260615 PS"}
{"ts_recv":"2026-04-07T02:16:42.659140449Z","hd":{"ts_event":"2026-04-07T02:16:42.659122989Z","rtype":160,"publisher_id":101,"instrument_id":436},"action":"C","side":"A","price":"1.156400000","size":30,"channel_id":23,"order_id":"1775528202659046130","flags":0,"ts_in_delta":931,"sequence":155006,"symbol":"FCEU SI 20260615 PS"}
{"ts_recv":"2026-04-07T02:16:42.659140449Z","hd":{"ts_event":"2026-04-07T02:16:42.659122989Z","rtype":160,"publisher_id":101,"instrument_id":436},"action":"A","side":"A","price":"1.156410000","size":30,"channel_id":23,"order_id":"1775528202659128844","flags":128,"ts_in_delta":931,"sequence":155006,"symbol":"FCEU SI 20260615 PS"}
{"ts_recv":"2026-04-07T02:16:42.659197478Z","hd":{"ts_event":"2026-04-07T02:16:42.659179673Z","rtype":160,"publisher_id":101,"instrument_id":436},"action":"C","side":"B","price":"1.156310000","size":30,"channel_id":23,"order_id":"10998900239513904652","flags":0,"ts_in_delta":915,"sequence":155007,"symbol":"FCEU SI 20260615 PS"}
{"ts_recv":"2026-04-07T02:16:42.659197478Z","hd":{"ts_event":"2026-04-07T02:16:42.659179673Z","rtype":160,"publisher_id":101,"instrument_id":436},"action":"A","side":"B","price":"1.156300000","size":30,"channel_id":23,"order_id":"10998900239513961289","flags":0,"ts_in_delta":915,"sequence":155007,"symbol":"FCEU SI 20260615 PS"}
{"ts_recv":"2026-04-07T02:16:42.659197478Z","hd":{"ts_event":"2026-04-07T02:16:42.659179673Z","rtype":160,"publisher_id":101,"instrument_id":436},"action":"C","side":"A","price":"1.156410000","size":30,"channel_id":23,"order_id":"1775528202659128844","flags":0,"ts_in_delta":915,"sequence":155007,"symbol":"FCEU SI 20260615 PS"}
{"ts_recv":"2026-04-07T02:16:42.659197478Z","hd":{"ts_event":"2026-04-07T02:16:42.659179673Z","rtype":160,"publisher_id":101,"instrument_id":436},"action":"A","side":"A","price":"1.156400000","size":30,"channel_id":23,"order_id":"1775528202659185481","flags":128,"ts_in_delta":915,"sequence":155007,"symbol":"FCEU SI 20260615 PS"}
{"ts_recv":"2026-04-07T02:16:42.664446241Z","hd":{"ts_event":"2026-04-07T02:16:42.664427723Z","rtype":160,"publisher_id":101,"instrument_id":436},"action":"C","side":"B","price":"1.156300000","size":30,"channel_id":23,"order_id":"10998900239513961289","flags":0,"ts_in_delta":785,"sequence":155011,"symbol":"FCEU SI 20260615 PS"}
{"ts_recv":"2026-04-07T02:16:42.664446241Z","hd":{"ts_event":"2026-04-07T02:16:42.664427723Z","rtype":160,"publisher_id":101,"instrument_id":436},"action":"A","side":"B","price":"1.156290000","size":30,"channel_id":23,"order_id":"10998900239519209167","flags":0,"ts_in_delta":785,"sequence":155011,"symbol":"FCEU SI 20260615 PS"}
{"ts_recv":"2026-04-07T02:16:42.664446241Z","hd":{"ts_event":"2026-04-07T02:16:42.664427723Z","rtype":160,"publisher_id":101,"instrument_id":436},"action":"C","side":"A","price":"1.156400000","size":30,"channel_id":23,"order_id":"1775528202659185481","flags":0,"ts_in_delta":785,"sequence":155011,"symbol":"FCEU SI 20260615 PS"}
{"ts_recv":"2026-04-07T02:16:42.664446241Z","hd":{"ts_event":"2026-04-07T02:16:42.664427723Z","rtype":160,"publisher_id":101,"instrument_id":436},"action":"A","side":"A","price":"1.156390000","size":30,"channel_id":23,"order_id":"1775528202664433359","flags":128,"ts_in_delta":785,"sequence":155011,"symbol":"FCEU SI 20260615 PS"}
{"ts_recv":"2026-04-07T02:16:42.664505228Z","hd":{"ts_event":"2026-04-07T02:16:42.664486337Z","rtype":160,"publisher_id":101,"instrument_id":436},"action":"C","side":"B","price":"1.156290000","size":30,"channel_id":23,"order_id":"10998900239519209167","flags":0,"ts_in_delta":725,"sequence":155012,"symbol":"FCEU SI 20260615 PS"}
{"ts_recv":"2026-04-07T02:16:42.664505228Z","hd":{"ts_event":"2026-04-07T02:16:42.664486337Z","rtype":160,"publisher_id":101,"instrument_id":436},"action":"A","side":"B","price":"1.156280000","size":30,"channel_id":23,"order_id":"10998900239519268095","flags":0,"ts_in_delta":725,"sequence":155012,"symbol":"FCEU SI 20260615 PS"}
{"ts_recv":"2026-04-07T02:16:42.664505228Z","hd":{"ts_event":"2026-04-07T02:16:42.664486337Z","rtype":160,"publisher_id":101,"instrument_id":436},"action":"C","side":"A","price":"1.156390000","size":30,"channel_id":23,"order_id":"1775528202664433359","flags":0,"ts_in_delta":725,"sequence":155012,"symbol":"FCEU SI 20260615 PS"}
{"ts_recv":"2026-04-07T02:16:42.664505228Z","hd":{"ts_event":"2026-04-07T02:16:42.664486337Z","rtype":160,"publisher_id":101,"instrument_id":436},"action":"A","side":"A","price":"1.156380000","size":30,"channel_id":23,"order_id":"1775528202664492287","flags":128,"ts_in_delta":725,"sequence":155012,"symbol":"FCEU SI 20260615 PS"}
{"ts_recv":"2026-04-07T02:16:42.664558532Z","hd":{"ts_event":"2026-04-07T02:16:42.664541939Z","rtype":160,"publisher_id":101,"instrument_id":436},"action":"C","side":"B","price":"1.156280000","size":30,"channel_id":23,"order_id":"10998900239519268095","flags":0,"ts_in_delta":781,"sequence":155013,"symbol":"FCEU SI 20260615 PS"}
{"ts_recv":"2026-04-07T02:16:42.664558532Z","hd":{"ts_event":"2026-04-07T02:16:42.664541939Z","rtype":160,"publisher_id":101,"instrument_id":436},"action":"A","side":"B","price":"1.156290000","size":30,"channel_id":23,"order_id":"10998900239519323577","flags":0,"ts_in_delta":781,"sequence":155013,"symbol":"FCEU SI 20260615 PS"}
{"ts_recv":"2026-04-07T02:16:42.664558532Z","hd":{"ts_event":"2026-04-07T02:16:42.664541939Z","rtype":160,"publisher_id":101,"instrument_id":436},"action":"C","side":"A","price":"1.156380000","size":30,"channel_id":23,"order_id":"1775528202664492287","flags":0,"ts_in_delta":781,"sequence":155013,"symbol":"FCEU SI 20260615 PS"}
{"ts_recv":"2026-04-07T02:16:42.664558532Z","hd":{"ts_event":"2026-04-07T02:16:42.664541939Z","rtype":160,"publisher_id":101,"instrument_id":436},"action":"A","side":"A","price":"1.156390000","size":30,"channel_id":23,"order_id":"1775528202664547769","flags":128,"ts_in_delta":781,"sequence":155013,"symbol":"FCEU SI 20260615 PS"}
{"ts_recv":"2026-04-07T02:16:42.762027425Z","hd":{"ts_event":"2026-04-07T02:16:42.762009603Z","rtype":160,"publisher_id":101,"instrument_id":436},"action":"C","side":"B","price":"1.156290000","size":30,"channel_id":23,"order_id":"10998900239519323577","flags":0,"ts_in_delta":1049,"sequence":155045,"symbol":"FCEU SI 20260615 PS"}
{"ts_recv":"2026-04-07T02:16:42.762027425Z","hd":{"ts_event":"2026-04-07T02:16:42.762009603Z","rtype":160,"publisher_id":101,"instrument_id":436},"action":"A","side":"B","price":"1.156280000","size":30,"channel_id":23,"order_id":"10998900239616791455","flags":0,"ts_in_delta":1049,"sequence":155045,"symbol":"FCEU SI 20260615 PS"}
{"ts_recv":"2026-04-07T02:16:42.762027425Z","hd":{"ts_event":"2026-04-07T02:16:42.762009603Z","rtype":160,"publisher_id":101,"instrument_id":436},"action":"C","side":"A","price":"1.156390000","size":30,"channel_id":23,"order_id":"1775528202664547769","flags":0,"ts_in_delta":1049,"sequence":155045,"symbol":"FCEU SI 20260615 PS"}
{"ts_recv":"2026-04-07T02:16:42.762027425Z","hd":{"ts_event":"2026-04-07T02:16:42.762009603Z","rtype":160,"publisher_id":101,"instrument_id":436},"action":"A","side":"A","price":"1.156380000","size":30,"channel_id":23,"order_id":"1775528202762015647","flags":128,"ts_in_delta":1049,"sequence":155045,"symbol":"FCEU SI 20260615 PS"}
{"ts_recv":"2026-04-07T02:16:42.762089738Z","hd":{"ts_event":"2026-04-07T02:16:42.762069507Z","rtype":160,"publisher_id":101,"instrument_id":436},"action":"C","side":"B","price":"1.156280000","size":30,"channel_id":23,"order_id":"10998900239616791455","flags":0,"ts_in_delta":909,"sequence":155046,"symbol":"FCEU SI 20260615 PS"}
{"ts_recv":"2026-04-07T02:16:42.762089738Z","hd":{"ts_event":"2026-04-07T02:16:42.762069507Z","rtype":160,"publisher_id":101,"instrument_id":436},"action":"A","side":"B","price":"1.156270000","size":30,"channel_id":23,"order_id":"10998900239616851392","flags":0,"ts_in_delta":909,"sequence":155046,"symbol":"FCEU SI 20260615 PS"}
{"ts_recv":"2026-04-07T02:16:42.762089738Z","hd":{"ts_event":"2026-04-07T02:16:42.762069507Z","rtype":160,"publisher_id":101,"instrument_id":436},"action":"C","side":"A","price":"1.156380000","size":30,"channel_id":23,"order_id":"1775528202762015647","flags":0,"ts_in_delta":909,"sequence":155046,"symbol":"FCEU SI 20260615 PS"}
{"ts_recv":"2026-04-07T02:16:42.762089738Z","hd":{"ts_event":"2026-04-07T02:16:42.762069507Z","rtype":160,"publisher_id":101,"instrument_id":436},"action":"A","side":"A","price":"1.156370000","size":30,"channel_id":23,"order_id":"1775528202762075584","flags":128,"ts_in_delta":909,"sequence":155046,"symbol":"FCEU SI 20260615 PS"}
{"ts_recv":"2026-04-07T02:16:42.762137919Z","hd":{"ts_event":"2026-04-07T02:16:42.762120023Z","rtype":160,"publisher_id":101,"instrument_id":436},"action":"C","side":"B","price":"1.156300000","size":30,"channel_id":23,"order_id":"10998900239513874449","flags":0,"ts_in_delta":912,"sequence":155047,"symbol":"FCEU SI 20260615 PS"}
{"ts_recv":"2026-04-07T02:16:42.762137919Z","hd":{"ts_event":"2026-04-07T02:16:42.762120023Z","rtype":160,"publisher_id":101,"instrument_id":436},"action":"A","side":"B","price":"1.156270000","size":30,"channel_id":23,"order_id":"10998900239616901860","flags":0,"ts_in_delta":912,"sequence":155047,"symbol":"FCEU SI 20260615 PS"}
{"ts_recv":"2026-04-07T02:16:42.762137919Z","hd":{"ts_event":"2026-04-07T02:16:42.762120023Z","rtype":160,"publisher_id":101,"instrument_id":436},"action":"C","side":"A","price":"1.156400000","size":30,"channel_id":23,"order_id":"1775528202659098641","flags":0,"ts_in_delta":912,"sequence":155047,"symbol":"FCEU SI 20260615 PS"}
{"ts_recv":"2026-04-07T02:16:42.762137919Z","hd":{"ts_event":"2026-04-07T02:16:42.762120023Z","rtype":160,"publisher_id":101,"instrument_id":436},"action":"A","side":"A","price":"1.156370000","size":30,"channel_id":23,"order_id":"1775528202762126052","flags":128,"ts_in_delta":912,"sequence":155047,"symbol":"FCEU SI 20260615 PS"}
{"ts_recv":"2026-04-07T02:16:42.762153724Z","hd":{"ts_event":"2026-04-07T02:16:42.762125861Z","rtype":160,"publisher_id":101,"instrument_id":436},"action":"C","side":"B","price":"1.156270000","size":30,"channel_id":23,"order_id":"10998900239616851392","flags":0,"ts_in_delta":6761,"sequence":155048,"symbol":"FCEU SI 20260615 PS"}
{"ts_recv":"2026-04-07T02:16:42.762153724Z","hd":{"ts_event":"2026-04-07T02:16:42.762125861Z","rtype":160,"publisher_id":101,"instrument_id":436},"action":"A","side":"B","price":"1.156280000","size":30,"channel_id":23,"order_id":"10998900239616910542","flags":0,"ts_in_delta":6761,"sequence":155048,"symbol":"FCEU SI 20260615 PS"}
{"ts_recv":"2026-04-07T02:16:42.762153724Z","hd":{"ts_event":"2026-04-07T02:16:42.762125861Z","rtype":160,"publisher_id":101,"instrument_id":436},"action":"C","side":"A","price":"1.156370000","size":30,"channel_id":23,"order_id":"1775528202762075584","flags":0,"ts_in_delta":6761,"sequence":155048,"symbol":"FCEU SI 20260615 PS"}
{"ts_recv":"2026-04-07T02:16:42.762153724Z","hd":{"ts_event":"2026-04-07T02:16:42.762125861Z","rtype":160,"publisher_id":101,"instrument_id":436},"action":"A","side":"A","price":"1.156380000","size":30,"channel_id":23,"order_id":"1775528202762134734","flags":128,"ts_in_delta":6761,"sequence":155048,"symbol":"FCEU SI 20260615 PS"}
{"ts_recv":"2026-04-07T02:16:42.762201324Z","hd":{"ts_event":"2026-04-07T02:16:42.762184189Z","rtype":160,"publisher_id":101,"instrument_id":436},"action":"C","side":"B","price":"1.156280000","size":30,"channel_id":23,"order_id":"10998900239616910542","flags":0,"ts_in_delta":1061,"sequence":155049,"symbol":"FCEU SI 20260615 PS"}
{"ts_recv":"2026-04-07T02:16:42.762201324Z","hd":{"ts_event":"2026-04-07T02:16:42.762184189Z","rtype":160,"publisher_id":101,"instrument_id":436},"action":"A","side":"B","price":"1.156260000","size":30,"channel_id":23,"order_id":"10998900239616965611","flags":0,"ts_in_delta":1061,"sequence":155049,"symbol":"FCEU SI 20260615 PS"}
{"ts_recv":"2026-04-07T02:16:42.762201324Z","hd":{"ts_event":"2026-04-07T02:16:42.762184189Z","rtype":160,"publisher_id":101,"instrument_id":436},"action":"C","side":"A","price":"1.156380000","size":30,"channel_id":23,"order_id":"1775528202762134734","flags":0,"ts_in_delta":1061,"sequence":155049,"symbol":"FCEU SI 20260615 PS"}
{"ts_recv":"2026-04-07T02:16:42.762201324Z","hd":{"ts_event":"2026-04-07T02:16:42.762184189Z","rtype":160,"publisher_id":101,"instrument_id":436},"action":"A","side":"A","price":"1.156360000","size":30,"channel_id":23,"order_id":"1775528202762189803","flags":128,"ts_in_delta":1061,"sequence":155049,"symbol":"FCEU SI 20260615 PS"}
{"ts_recv":"2026-04-07T02:16:42.821593608Z","hd":{"ts_event":"2026-04-07T02:16:42.821575911Z","rtype":160,"publisher_id":101,"instrument_id":436},"action":"C","side":"B","price":"1.156260000","size":30,"channel_id":23,"order_id":"10998900239616965611","flags":0,"ts_in_delta":934,"sequence":155053,"symbol":"FCEU SI 20260615 PS"}
{"ts_recv":"2026-04-07T02:16:42.821593608Z","hd":{"ts_event":"2026-04-07T02:16:42.821575911Z","rtype":160,"publisher_id":101,"instrument_id":436},"action":"A","side":"B","price":"1.156270000","size":30,"channel_id":23,"order_id":"10998900239676357561","flags":0,"ts_in_delta":934,"sequence":155053,"symbol":"FCEU SI 20260615 PS"}
{"ts_recv":"2026-04-07T02:16:42.821593608Z","hd":{"ts_event":"2026-04-07T02:16:42.821575911Z","rtype":160,"publisher_id":101,"instrument_id":436},"action":"C","side":"A","price":"1.156360000","size":30,"channel_id":23,"order_id":"1775528202762189803","flags":0,"ts_in_delta":934,"sequence":155053,"symbol":"FCEU SI 20260615 PS"}
{"ts_recv":"2026-04-07T02:16:42.821593608Z","hd":{"ts_event":"2026-04-07T02:16:42.821575911Z","rtype":160,"publisher_id":101,"instrument_id":436},"action":"A","side":"A","price":"1.156370000","size":30,"channel_id":23,"order_id":"1775528202821581753","flags":128,"ts_in_delta":934,"sequence":155053,"symbol":"FCEU SI 20260615 PS"}
{"ts_recv":"2026-04-07T02:16:46.562361269Z","hd":{"ts_event":"2026-04-07T02:16:46.562341867Z","rtype":160,"publisher_id":101,"instrument_id":436},"action":"C","side":"B","price":"1.156270000","size":30,"channel_id":23,"order_id":"10998900239676357561","flags":0,"ts_in_delta":1196,"sequence":155095,"symbol":"FCEU SI 20260615 PS"}
{"ts_recv":"2026-04-07T02:16:46.562361269Z","hd":{"ts_event":"2026-04-07T02:16:46.562341867Z","rtype":160,"publisher_id":101,"instrument_id":436},"action":"A","side":"B","price":"1.156260000","size":30,"channel_id":23,"order_id":"10998900243417123717","flags":0,"ts_in_delta":1196,"sequence":155095,"symbol":"FCEU SI 20260615 PS"}
{"ts_recv":"2026-04-07T02:16:46.562361269Z","hd":{"ts_event":"2026-04-07T02:16:46.562341867Z","rtype":160,"publisher_id":101,"instrument_id":436},"action":"C","side":"A","price":"1.156370000","size":30,"channel_id":23,"order_id":"1775528202821581753","flags":0,"ts_in_delta":1196,"sequence":155095,"symbol":"FCEU SI 20260615 PS"}
{"ts_recv":"2026-04-07T02:16:46.562361269Z","hd":{"ts_event":"2026-04-07T02:16:46.562341867Z","rtype":160,"publisher_id":101,"instrument_id":436},"action":"A","side":"A","price":"1.156360000","size":30,"channel_id":23,"order_id":"1775528206562347909","flags":128,"ts_in_delta":1196,"sequence":155095,"symbol":"FCEU SI 20260615 PS"}
{"ts_recv":"2026-04-07T02:16:46.577235380Z","hd":{"ts_event":"2026-04-07T02:16:46.577216863Z","rtype":160,"publisher_id":101,"instrument_id":436},"action":"C","side":"B","price":"1.156270000","size":30,"channel_id":23,"order_id":"10998900239616901860","flags":0,"ts_in_delta":1096,"sequence":155104,"symbol":"FCEU SI 20260615 PS"}
{"ts_recv":"2026-04-07T02:16:46.577235380Z","hd":{"ts_event":"2026-04-07T02:16:46.577216863Z","rtype":160,"publisher_id":101,"instrument_id":436},"action":"A","side":"B","price":"1.156250000","size":30,"channel_id":23,"order_id":"10998900243431998542","flags":0,"ts_in_delta":1096,"sequence":155104,"symbol":"FCEU SI 20260615 PS"}
{"ts_recv":"2026-04-07T02:16:46.577235380Z","hd":{"ts_event":"2026-04-07T02:16:46.577216863Z","rtype":160,"publisher_id":101,"instrument_id":436},"action":"C","side":"A","price":"1.156370000","size":30,"channel_id":23,"order_id":"1775528202762126052","flags":0,"ts_in_delta":1096,"sequence":155104,"symbol":"FCEU SI 20260615 PS"}
{"ts_recv":"2026-04-07T02:16:46.577235380Z","hd":{"ts_event":"2026-04-07T02:16:46.577216863Z","rtype":160,"publisher_id":101,"instrument_id":436},"action":"A","side":"A","price":"1.156350000","size":30,"channel_id":23,"order_id":"1775528206577222734","flags":128,"ts_in_delta":1096,"sequence":155104,"symbol":"FCEU SI 20260615 PS"}
{"ts_recv":"2026-04-07T02:16:46.577293515Z","hd":{"ts_event":"2026-04-07T02:16:46.577275423Z","rtype":160,"publisher_id":101,"instrument_id":436},"action":"C","side":"B","price":"1.156260000","size":30,"channel_id":23,"order_id":"10998900243417123717","flags":0,"ts_in_delta":906,"sequence":155105,"symbol":"FCEU SI 20260615 PS"}
{"ts_recv":"2026-04-07T02:16:46.577293515Z","hd":{"ts_event":"2026-04-07T02:16:46.577275423Z","rtype":160,"publisher_id":101,"instrument_id":436},"action":"A","side":"B","price":"1.156250000","size":30,"channel_id":23,"order_id":"10998900243432057182","flags":0,"ts_in_delta":906,"sequence":155105,"symbol":"FCEU SI 20260615 PS"}
{"ts_recv":"2026-04-07T02:16:46.577293515Z","hd":{"ts_event":"2026-04-07T02:16:46.577275423Z","rtype":160,"publisher_id":101,"instrument_id":436},"action":"C","side":"A","price":"1.156360000","size":30,"channel_id":23,"order_id":"1775528206562347909","flags":0,"ts_in_delta":906,"sequence":155105,"symbol":"FCEU SI 20260615 PS"}
{"ts_recv":"2026-04-07T02:16:46.577293515Z","hd":{"ts_event":"2026-04-07T02:16:46.577275423Z","rtype":160,"publisher_id":101,"instrument_id":436},"action":"A","side":"A","price":"1.156350000","size":30,"channel_id":23,"order_id":"1775528206577281374","flags":128,"ts_in_delta":906,"sequence":155105,"symbol":"FCEU SI 20260615 PS"}
{"ts_recv":"2026-04-07T02:16:46.631272025Z","hd":{"ts_event":"2026-04-07T02:16:46.631249301Z","rtype":160,"publisher_id":101,"instrument_id":436},"action":"A","side":"A","price":"1.156500000","size":20,"channel_id":23,"order_id":"1775528206631260239","flags":128,"ts_in_delta":1011,"sequence":155107,"symbol":"FCEU SI 20260615 PS"}
{"ts_recv":"2026-04-07T02:16:46.631288482Z","hd":{"ts_event":"2026-04-07T02:16:46.631273805Z","rtype":160,"publisher_id":101,"instrument_id":436},"action":"C","side":"A","price":"1.156600000","size":20,"channel_id":23,"order_id":"1775527962075583562","flags":128,"ts_in_delta":919,"sequence":155108,"symbol":"FCEU SI 20260615 PS"}
{"ts_recv":"2026-04-07T02:16:54.438164238Z","hd":{"ts_event":"2026-04-07T02:16:54.438137177Z","rtype":160,"publisher_id":101,"instrument_id":436},"action":"C","side":"B","price":"1.156250000","size":30,"channel_id":23,"order_id":"10998900243432057182","flags":0,"ts_in_delta":1630,"sequence":155167,"symbol":"FCEU SI 20260615 PS"}
{"ts_recv":"2026-04-07T02:16:54.438164238Z","hd":{"ts_event":"2026-04-07T02:16:54.438137177Z","rtype":160,"publisher_id":101,"instrument_id":436},"action":"A","side":"B","price":"1.156260000","size":30,"channel_id":23,"order_id":"10998900251292921739","flags":0,"ts_in_delta":1630,"sequence":155167,"symbol":"FCEU SI 20260615 PS"}
{"ts_recv":"2026-04-07T02:16:54.438164238Z","hd":{"ts_event":"2026-04-07T02:16:54.438137177Z","rtype":160,"publisher_id":101,"instrument_id":436},"action":"C","side":"A","price":"1.156350000","size":30,"channel_id":23,"order_id":"1775528206577281374","flags":0,"ts_in_delta":1630,"sequence":155167,"symbol":"FCEU SI 20260615 PS"}
{"ts_recv":"2026-04-07T02:16:54.438164238Z","hd":{"ts_event":"2026-04-07T02:16:54.438137177Z","rtype":160,"publisher_id":101,"instrument_id":436},"action":"A","side":"A","price":"1.156360000","size":30,"channel_id":23,"order_id":"1775528214438145931","flags":128,"ts_in_delta":1630,"sequence":155167,"symbol":"FCEU SI 20260615 PS"}
{"ts_recv":"2026-04-07T02:16:54.438224355Z","hd":{"ts_event":"2026-04-07T02:16:54.438205819Z","rtype":160,"publisher_id":101,"instrument_id":436},"action":"C","side":"B","price":"1.156250000","size":30,"channel_id":23,"order_id":"10998900243431998542","flags":0,"ts_in_delta":976,"sequence":155168,"symbol":"FCEU SI 20260615 PS"}
{"ts_recv":"2026-04-07T02:16:54.438224355Z","hd":{"ts_event":"2026-04-07T02:16:54.438205819Z","rtype":160,"publisher_id":101,"instrument_id":436},"action":"A","side":"B","price":"1.156270000","size":30,"channel_id":23,"order_id":"10998900251292987802","flags":0,"ts_in_delta":976,"sequence":155168,"symbol":"FCEU SI 20260615 PS"}
{"ts_recv":"2026-04-07T02:16:54.438224355Z","hd":{"ts_event":"2026-04-07T02:16:54.438205819Z","rtype":160,"publisher_id":101,"instrument_id":436},"action":"C","side":"A","price":"1.156350000","size":30,"channel_id":23,"order_id":"1775528206577222734","flags":0,"ts_in_delta":976,"sequence":155168,"symbol":"FCEU SI 20260615 PS"}
{"ts_recv":"2026-04-07T02:16:54.438224355Z","hd":{"ts_event":"2026-04-07T02:16:54.438205819Z","rtype":160,"publisher_id":101,"instrument_id":436},"action":"A","side":"A","price":"1.156370000","size":30,"channel_id":23,"order_id":"1775528214438211994","flags":128,"ts_in_delta":976,"sequence":155168,"symbol":"FCEU SI 20260615 PS"}
{"ts_recv":"2026-04-07T02:16:54.438283073Z","hd":{"ts_event":"2026-04-07T02:16:54.438264187Z","rtype":160,"publisher_id":101,"instrument_id":436},"action":"C","side":"B","price":"1.156260000","size":30,"channel_id":23,"order_id":"10998900251292921739","flags":0,"ts_in_delta":961,"sequence":155169,"symbol":"FCEU SI 20260615 PS"}
{"ts_recv":"2026-04-07T02:16:54.438283073Z","hd":{"ts_event":"2026-04-07T02:16:54.438264187Z","rtype":160,"publisher_id":101,"instrument_id":436},"action":"A","side":"B","price":"1.156270000","size":30,"channel_id":23,"order_id":"10998900251293046063","flags":0,"ts_in_delta":961,"sequence":155169,"symbol":"FCEU SI 20260615 PS"}
{"ts_recv":"2026-04-07T02:16:54.438283073Z","hd":{"ts_event":"2026-04-07T02:16:54.438264187Z","rtype":160,"publisher_id":101,"instrument_id":436},"action":"C","side":"A","price":"1.156360000","size":30,"channel_id":23,"order_id":"1775528214438145931","flags":0,"ts_in_delta":961,"sequence":155169,"symbol":"FCEU SI 20260615 PS"}
{"ts_recv":"2026-04-07T02:16:54.438283073Z","hd":{"ts_event":"2026-04-07T02:16:54.438264187Z","rtype":160,"publisher_id":101,"instrument_id":436},"action":"A","side":"A","price":"1.156370000","size":30,"channel_id":23,"order_id":"1775528214438270255","flags":128,"ts_in_delta":961,"sequence":155169,"symbol":"FCEU SI 20260615 PS"}
{"ts_recv":"2026-04-07T02:16:55.021858163Z","hd":{"ts_event":"2026-04-07T02:16:55.021835849Z","rtype":160,"publisher_id":101,"instrument_id":436},"action":"C","side":"B","price":"1.156270000","size":30,"channel_id":23,"order_id":"10998900251293046063","flags":0,"ts_in_delta":1143,"sequence":155190,"symbol":"FCEU SI 20260615 PS"}
{"ts_recv":"2026-04-07T02:16:55.021858163Z","hd":{"ts_event":"2026-04-07T02:16:55.021835849Z","rtype":160,"publisher_id":101,"instrument_id":436},"action":"A","side":"B","price":"1.156260000","size":30,"channel_id":23,"order_id":"10998900251876617679","flags":0,"ts_in_delta":1143,"sequence":155190,"symbol":"FCEU SI 20260615 PS"}
{"ts_recv":"2026-04-07T02:16:55.021858163Z","hd":{"ts_event":"2026-04-07T02:16:55.021835849Z","rtype":160,"publisher_id":101,"instrument_id":436},"action":"C","side":"A","price":"1.156370000","size":30,"channel_id":23,"order_id":"1775528214438270255","flags":0,"ts_in_delta":1143,"sequence":155190,"symbol":"FCEU SI 20260615 PS"}
{"ts_recv":"2026-04-07T02:16:55.021858163Z","hd":{"ts_event":"2026-04-07T02:16:55.021835849Z","rtype":160,"publisher_id":101,"instrument_id":436},"action":"A","side":"A","price":"1.156360000","size":30,"channel_id":23,"order_id":"1775528215021841871","flags":128,"ts_in_delta":1143,"sequence":155190,"symbol":"FCEU SI 20260615 PS"}
{"ts_recv":"2026-04-07T02:16:55.021940819Z","hd":{"ts_event":"2026-04-07T02:16:55.021920695Z","rtype":160,"publisher_id":101,"instrument_id":436},"action":"C","side":"B","price":"1.156260000","size":30,"channel_id":23,"order_id":"10998900251876617679","flags":0,"ts_in_delta":953,"sequence":155191,"symbol":"FCEU SI 20260615 PS"}
{"ts_recv":"2026-04-07T02:16:55.021940819Z","hd":{"ts_event":"2026-04-07T02:16:55.021920695Z","rtype":160,"publisher_id":101,"instrument_id":436},"action":"A","side":"B","price":"1.156250000","size":30,"channel_id":23,"order_id":"10998900251876702338","flags":0,"ts_in_delta":953,"sequence":155191,"symbol":"FCEU SI 20260615 PS"}
{"ts_recv":"2026-04-07T02:16:55.021940819Z","hd":{"ts_event":"2026-04-07T02:16:55.021920695Z","rtype":160,"publisher_id":101,"instrument_id":436},"action":"C","side":"A","price":"1.156360000","size":30,"channel_id":23,"order_id":"1775528215021841871","flags":0,"ts_in_delta":953,"sequence":155191,"symbol":"FCEU SI 20260615 PS"}
{"ts_recv":"2026-04-07T02:16:55.021940819Z","hd":{"ts_event":"2026-04-07T02:16:55.021920695Z","rtype":160,"publisher_id":101,"instrument_id":436},"action":"A","side":"A","price":"1.156350000","size":30,"channel_id":23,"order_id":"1775528215021926530","flags":128,"ts_in_delta":953,"sequence":155191,"symbol":"FCEU SI 20260615 PS"}
{"ts_recv":"2026-04-07T02:16:55.021989562Z","hd":{"ts_event":"2026-04-07T02:16:55.021973009Z","rtype":160,"publisher_id":101,"instrument_id":436},"action":"C","side":"B","price":"1.156270000","size":30,"channel_id":23,"order_id":"10998900251292987802","flags":0,"ts_in_delta":966,"sequence":155192,"symbol":"FCEU SI 20260615 PS"}
{"ts_recv":"2026-04-07T02:16:55.021989562Z","hd":{"ts_event":"2026-04-07T02:16:55.021973009Z","rtype":160,"publisher_id":101,"instrument_id":436},"action":"A","side":"B","price":"1.156250000","size":30,"channel_id":23,"order_id":"10998900251876754856","flags":0,"ts_in_delta":966,"sequence":155192,"symbol":"FCEU SI 20260615 PS"}
{"ts_recv":"2026-04-07T02:16:55.021989562Z","hd":{"ts_event":"2026-04-07T02:16:55.021973009Z","rtype":160,"publisher_id":101,"instrument_id":436},"action":"C","side":"A","price":"1.156370000","size":30,"channel_id":23,"order_id":"1775528214438211994","flags":0,"ts_in_delta":966,"sequence":155192,"symbol":"FCEU SI 20260615 PS"}
{"ts_recv":"2026-04-07T02:16:55.021989562Z","hd":{"ts_event":"2026-04-07T02:16:55.021973009Z","rtype":160,"publisher_id":101,"instrument_id":436},"action":"A","side":"A","price":"1.156350000","size":30,"channel_id":23,"order_id":"1775528215021979048","flags":128,"ts_in_delta":966,"sequence":155192,"symbol":"FCEU SI 20260615 PS"}
{"ts_recv":"2026-04-07T02:16:55.022000751Z","hd":{"ts_event":"2026-04-07T02:16:55.021981501Z","rtype":160,"publisher_id":101,"instrument_id":436},"action":"C","side":"B","price":"1.156250000","size":30,"channel_id":23,"order_id":"10998900251876702338","flags":0,"ts_in_delta":1130,"sequence":155193,"symbol":"FCEU SI 20260615 PS"}
{"ts_recv":"2026-04-07T02:16:55.022000751Z","hd":{"ts_event":"2026-04-07T02:16:55.021981501Z","rtype":160,"publisher_id":101,"instrument_id":436},"action":"A","side":"B","price":"1.156260000","size":30,"channel_id":23,"order_id":"10998900251876763214","flags":0,"ts_in_delta":1130,"sequence":155193,"symbol":"FCEU SI 20260615 PS"}
{"ts_recv":"2026-04-07T02:16:55.022000751Z","hd":{"ts_event":"2026-04-07T02:16:55.021981501Z","rtype":160,"publisher_id":101,"instrument_id":436},"action":"C","side":"A","price":"1.156350000","size":30,"channel_id":23,"order_id":"1775528215021926530","flags":0,"ts_in_delta":1130,"sequence":155193,"symbol":"FCEU SI 20260615 PS"}
{"ts_recv":"2026-04-07T02:16:55.022000751Z","hd":{"ts_event":"2026-04-07T02:16:55.021981501Z","rtype":160,"publisher_id":101,"instrument_id":436},"action":"A","side":"A","price":"1.156360000","size":30,"channel_id":23,"order_id":"1775528215021987406","flags":128,"ts_in_delta":1130,"sequence":155193,"symbol":"FCEU SI 20260615 PS"}
{"ts_recv":"2026-04-07T02:16:55.022055008Z","hd":{"ts_event":"2026-04-07T02:16:55.022037373Z","rtype":160,"publisher_id":101,"instrument_id":436},"action":"C","side":"B","price":"1.156260000","size":30,"channel_id":23,"order_id":"10998900251876763214","flags":0,"ts_in_delta":1108,"sequence":155194,"symbol":"FCEU SI 20260615 PS"}
{"ts_recv":"2026-04-07T02:16:55.022055008Z","hd":{"ts_event":"2026-04-07T02:16:55.022037373Z","rtype":160,"publisher_id":101,"instrument_id":436},"action":"A","side":"B","price":"1.156250000","size":30,"channel_id":23,"order_id":"10998900251876818992","flags":0,"ts_in_delta":1108,"sequence":155194,"symbol":"FCEU SI 20260615 PS"}
{"ts_recv":"2026-04-07T02:16:55.022055008Z","hd":{"ts_event":"2026-04-07T02:16:55.022037373Z","rtype":160,"publisher_id":101,"instrument_id":436},"action":"C","side":"A","price":"1.156360000","size":30,"channel_id":23,"order_id":"1775528215021987406","flags":0,"ts_in_delta":1108,"sequence":155194,"symbol":"FCEU SI 20260615 PS"}
{"ts_recv":"2026-04-07T02:16:55.022055008Z","hd":{"ts_event":"2026-04-07T02:16:55.022037373Z","rtype":160,"publisher_id":101,"instrument_id":436},"action":"A","side":"A","price":"1.156350000","size":30,"channel_id":23,"order_id":"1775528215022043184","flags":128,"ts_in_delta":1108,"sequence":155194,"symbol":"FCEU SI 20260615 PS"}
{"ts_recv":"2026-04-07T02:17:07.683333246Z","hd":{"ts_event":"2026-04-07T02:17:07.683311787Z","rtype":160,"publisher_id":101,"instrument_id":436},"action":"C","side":"B","price":"1.156250000","size":30,"channel_id":23,"order_id":"10998900251876818992","flags":0,"ts_in_delta":832,"sequence":155278,"symbol":"FCEU SI 20260615 PS"}
{"ts_recv":"2026-04-07T02:17:07.683333246Z","hd":{"ts_event":"2026-04-07T02:17:07.683311787Z","rtype":160,"publisher_id":101,"instrument_id":436},"action":"A","side":"B","price":"1.156260000","size":30,"channel_id":23,"order_id":"10998900264538093704","flags":0,"ts_in_delta":832,"sequence":155278,"symbol":"FCEU SI 20260615 PS"}
{"ts_recv":"2026-04-07T02:17:07.683333246Z","hd":{"ts_event":"2026-04-07T02:17:07.683311787Z","rtype":160,"publisher_id":101,"instrument_id":436},"action":"C","side":"A","price":"1.156350000","size":30,"channel_id":23,"order_id":"1775528215022043184","flags":0,"ts_in_delta":832,"sequence":155278,"symbol":"FCEU SI 20260615 PS"}
{"ts_recv":"2026-04-07T02:17:07.683333246Z","hd":{"ts_event":"2026-04-07T02:17:07.683311787Z","rtype":160,"publisher_id":101,"instrument_id":436},"action":"A","side":"A","price":"1.156360000","size":30,"channel_id":23,"order_id":"1775528227683317896","flags":128,"ts_in_delta":832,"sequence":155278,"symbol":"FCEU SI 20260615 PS"}
{"ts_recv":"2026-04-07T02:17:07.726212704Z","hd":{"ts_event":"2026-04-07T02:17:07.726190937Z","rtype":160,"publisher_id":101,"instrument_id":436},"action":"C","side":"B","price":"1.156250000","size":30,"channel_id":23,"order_id":"10998900251876754856","flags":0,"ts_in_delta":921,"sequence":155283,"symbol":"FCEU SI 20260615 PS"}
{"ts_recv":"2026-04-07T02:17:07.726212704Z","hd":{"ts_event":"2026-04-07T02:17:07.726190937Z","rtype":160,"publisher_id":101,"instrument_id":436},"action":"A","side":"B","price":"1.156270000","size":30,"channel_id":23,"order_id":"10998900264580972786","flags":0,"ts_in_delta":921,"sequence":155283,"symbol":"FCEU SI 20260615 PS"}
{"ts_recv":"2026-04-07T02:17:07.726212704Z","hd":{"ts_event":"2026-04-07T02:17:07.726190937Z","rtype":160,"publisher_id":101,"instrument_id":436},"action":"C","side":"A","price":"1.156350000","size":30,"channel_id":23,"order_id":"1775528215021979048","flags":0,"ts_in_delta":921,"sequence":155283,"symbol":"FCEU SI 20260615 PS"}
{"ts_recv":"2026-04-07T02:17:07.726212704Z","hd":{"ts_event":"2026-04-07T02:17:07.726190937Z","rtype":160,"publisher_id":101,"instrument_id":436},"action":"A","side":"A","price":"1.156370000","size":30,"channel_id":23,"order_id":"1775528227726196978","flags":128,"ts_in_delta":921,"sequence":155283,"symbol":"FCEU SI 20260615 PS"}
{"ts_recv":"2026-04-07T02:17:07.726274709Z","hd":{"ts_event":"2026-04-07T02:17:07.726255731Z","rtype":160,"publisher_id":101,"instrument_id":436},"action":"C","side":"B","price":"1.156260000","size":30,"channel_id":23,"order_id":"10998900264538093704","flags":0,"ts_in_delta":900,"sequence":155284,"symbol":"FCEU SI 20260615 PS"}
{"ts_recv":"2026-04-07T02:17:07.726274709Z","hd":{"ts_event":"2026-04-07T02:17:07.726255731Z","rtype":160,"publisher_id":101,"instrument_id":436},"action":"A","side":"B","price":"1.156270000","size":30,"channel_id":23,"order_id":"10998900264581037965","flags":0,"ts_in_delta":900,"sequence":155284,"symbol":"FCEU SI 20260615 PS"}
{"ts_recv":"2026-04-07T02:17:07.726274709Z","hd":{"ts_event":"2026-04-07T02:17:07.726255731Z","rtype":160,"publisher_id":101,"instrument_id":436},"action":"C","side":"A","price":"1.156360000","size":30,"channel_id":23,"order_id":"1775528227683317896","flags":0,"ts_in_delta":900,"sequence":155284,"symbol":"FCEU SI 20260615 PS"}
{"ts_recv":"2026-04-07T02:17:07.726274709Z","hd":{"ts_event":"2026-04-07T02:17:07.726255731Z","rtype":160,"publisher_id":101,"instrument_id":436},"action":"A","side":"A","price":"1.156370000","size":30,"channel_id":23,"order_id":"1775528227726262157","flags":128,"ts_in_delta":900,"sequence":155284,"symbol":"FCEU SI 20260615 PS"}
{"ts_recv":"2026-04-07T02:17:11.324355765Z","hd":{"ts_event":"2026-04-07T02:17:11.324335065Z","rtype":160,"publisher_id":101,"instrument_id":436},"action":"C","side":"B","price":"1.156270000","size":30,"channel_id":23,"order_id":"10998900264581037965","flags":0,"ts_in_delta":804,"sequence":155317,"symbol":"FCEU SI 20260615 PS"}
{"ts_recv":"2026-04-07T02:17:11.324355765Z","hd":{"ts_event":"2026-04-07T02:17:11.324335065Z","rtype":160,"publisher_id":101,"instrument_id":436},"action":"A","side":"B","price":"1.156280000","size":30,"channel_id":23,"order_id":"10998900268179117568","flags":0,"ts_in_delta":804,"sequence":155317,"symbol":"FCEU SI 20260615 PS"}
{"ts_recv":"2026-04-07T02:17:11.324355765Z","hd":{"ts_event":"2026-04-07T02:17:11.324335065Z","rtype":160,"publisher_id":101,"instrument_id":436},"action":"C","side":"A","price":"1.156370000","size":30,"channel_id":23,"order_id":"1775528227726262157","flags":0,"ts_in_delta":804,"sequence":155317,"symbol":"FCEU SI 20260615 PS"}
{"ts_recv":"2026-04-07T02:17:11.324355765Z","hd":{"ts_event":"2026-04-07T02:17:11.324335065Z","rtype":160,"publisher_id":101,"instrument_id":436},"action":"A","side":"A","price":"1.156380000","size":30,"channel_id":23,"order_id":"1775528231324341760","flags":128,"ts_in_delta":804,"sequence":155317,"symbol":"FCEU SI 20260615 PS"}
{"ts_recv":"2026-04-07T02:17:11.324415482Z","hd":{"ts_event":"2026-04-07T02:17:11.324395661Z","rtype":160,"publisher_id":101,"instrument_id":436},"action":"C","side":"B","price":"1.156270000","size":30,"channel_id":23,"order_id":"10998900264580972786","flags":0,"ts_in_delta":955,"sequence":155318,"symbol":"FCEU SI 20260615 PS"}
