{"ts_recv":"2026-04-07T02:10:05.035193157Z","hd":{"ts_event":"2026-04-07T02:10:05.035177239Z","rtype":160,"publisher_id":101,"instrument_id":436},"action":"A","side":"B","price":"1.156370000","size":30,"channel_id":23,"order_id":"10998899841889959184","flags":0,"ts_in_delta":948,"sequence":149842,"symbol":"FCEU SI 20260615 PS"}
{"ts_recv":"2026-04-07T02:10:05.035193157Z","hd":{"ts_event":"2026-04-07T02:10:05.035177239Z","rtype":160,"publisher_id":101,"instrument_id":436},"action":"C","side":"A","price":"1.156490000","size":30,"channel_id":23,"order_id":"1775527805035131618","flags":0,"ts_in_delta":948,"sequence":149842,"symbol":"FCEU SI 20260615 PS"}
{"ts_recv":"2026-04-07T02:10:05.035193157Z","hd":{"ts_event":"2026-04-07T02:10:05.035177239Z","rtype":160,"publisher_id":101,"instrument_id":436},"action":"A","side":"A","price":"1.156470000","size":30,"channel_id":23,"order_id":"1775527805035183376","flags":128,"ts_in_delta":948,"sequence":149842,"symbol":"FCEU SI 20260615 PS"}
{"ts_recv":"2026-04-07T02:10:05.035232024Z","hd":{"ts_event":"2026-04-07T02:10:05.035216215Z","rtype":160,"publisher_id":101,"instrument_id":436},"action":"C","side":"B","price":"1.156360000","size":30,"channel_id":23,"order_id":"10998899841889918853","flags":0,"ts_in_delta":953,"sequence":149843,"symbol":"FCEU SI 20260615 PS"}
{"ts_recv":"2026-04-07T02:10:05.035232024Z","hd":{"ts_event":"2026-04-07T02:10:05.035216215Z","rtype":160,"publisher_id":101,"instrument_id":436},"action":"A","side":"B","price":"1.156370000","size":30,"channel_id":23,"order_id":"10998899841889997864","flags":0,"ts_in_delta":953,"sequence":149843,"symbol":"FCEU SI 20260615 PS"}
{"ts_recv":"2026-04-07T02:10:05.035232024Z","hd":{"ts_event":"2026-04-07T02:10:05.035216215Z","rtype":160,"publisher_id":101,"instrument_id":436},"action":"C","side":"A","price":"1.156460000","size":30,"channel_id":23,"order_id":"1775527805035143045","flags":0,"ts_in_delta":953,"sequence":149843,"symbol":"FCEU SI 20260615 PS"}
{"ts_recv":"2026-04-07T02:10:05.035232024Z","hd":{"ts_event":"2026-04-07T02:10:05.035216215Z","rtype":160,"publisher_id":101,"instrument_id":436},"action":"A","side":"A","price":"1.156470000","size":30,"channel_id":23,"order_id":"1775527805035222056","flags":128,"ts_in_delta":953,"sequence":149843,"symbol":"FCEU SI 20260615 PS"}
{"ts_recv":"2026-04-07T02:10:05.035289490Z","hd":{"ts_event":"2026-04-07T02:10:05.035270993Z","rtype":160,"publisher_id":101,"instrument_id":436},"action":"C","side":"B","price":"1.156370000","size":30,"channel_id":23,"order_id":"10998899841889997864","flags":0,"ts_in_delta":948,"sequence":149844,"symbol":"FCEU SI 20260615 PS"}
{"ts_recv":"2026-04-07T02:10:05.035289490Z","hd":{"ts_event":"2026-04-07T02:10:05.035270993Z","rtype":160,"publisher_id":101,"instrument_id":436},"action":"A","side":"B","price":"1.156360000","size":30,"channel_id":23,"order_id":"10998899841890052350","flags":0,"ts_in_delta":948,"sequence":149844,"symbol":"FCEU SI 20260615 PS"}
{"ts_recv":"2026-04-07T02:10:05.035289490Z","hd":{"ts_event":"2026-04-07T02:10:05.035270993Z","rtype":160,"publisher_id":101,"instrument_id":436},"action":"C","side":"A","price":"1.156470000","size":30,"channel_id":23,"order_id":"1775527805035222056","flags":0,"ts_in_delta":948,"sequence":149844,"symbol":"FCEU SI 20260615 PS"}
{"ts_recv":"2026-04-07T02:10:05.035289490Z","hd":{"ts_event":"2026-04-07T02:10:05.035270993Z","rtype":160,"publisher_id":101,"instrument_id":436},"action":"A","side":"A","price":"1.156460000","size":30,"channel_id":23,"order_id":"1775527805035276542","flags":128,"ts_in_delta":948,"sequence":149844,"symbol":"FCEU SI 20260615 PS"}
{"ts_recv":"2026-04-07T02:10:05.036443081Z","hd":{"ts_event":"2026-04-07T02:10:05.036423763Z","rtype":160,"publisher_id":101,"instrument_id":436},"action":"C","side":"B","price":"1.156360000","size":30,"channel_id":23,"order_id":"10998899841890052350","flags":0,"ts_in_delta":773,"sequence":149846,"symbol":"FCEU SI 20260615 PS"}
{"ts_recv":"2026-04-07T02:10:05.036443081Z","hd":{"ts_event":"2026-04-07T02:10:05.036423763Z","rtype":160,"publisher_id":101,"instrument_id":436},"action":"A","side":"B","price":"1.156370000","size":30,"channel_id":23,"order_id":"10998899841891205314","flags":0,"ts_in_delta":773,"sequence":149846,"symbol":"FCEU SI 20260615 PS"}
{"ts_recv":"2026-04-07T02:10:05.036443081Z","hd":{"ts_event":"2026-04-07T02:10:05.036423763Z","rtype":160,"publisher_id":101,"instrument_id":436},"action":"C","side":"A","price":"1.156460000","size":30,"channel_id":23,"order_id":"1775527805035276542","flags":0,"ts_in_delta":773,"sequence":149846,"symbol":"FCEU SI 20260615 PS"}
{"ts_recv":"2026-04-07T02:10:05.036443081Z","hd":{"ts_event":"2026-04-07T02:10:05.036423763Z","rtype":160,"publisher_id":101,"instrument_id":436},"action":"A","side":"A","price":"1.156470000","size":30,"channel_id":23,"order_id":"1775527805036429506","flags":128,"ts_in_delta":773,"sequence":149846,"symbol":"FCEU SI 20260615 PS"}
{"ts_recv":"2026-04-07T02:10:05.046259092Z","hd":{"ts_event":"2026-04-07T02:10:05.046240603Z","rtype":160,"publisher_id":101,"instrument_id":436},"action":"C","side":"B","price":"1.156370000","size":30,"channel_id":23,"order_id":"10998899841891205314","flags":0,"ts_in_delta":760,"sequence":149856,"symbol":"FCEU SI 20260615 PS"}
{"ts_recv":"2026-04-07T02:10:05.046259092Z","hd":{"ts_event":"2026-04-07T02:10:05.046240603Z","rtype":160,"publisher_id":101,"instrument_id":436},"action":"A","side":"B","price":"1.156380000","size":30,"channel_id":23,"order_id":"10998899841901022146","flags":0,"ts_in_delta":760,"sequence":149856,"symbol":"FCEU SI 20260615 PS"}
{"ts_recv":"2026-04-07T02:10:05.046259092Z","hd":{"ts_event":"2026-04-07T02:10:05.046240603Z","rtype":160,"publisher_id":101,"instrument_id":436},"action":"C","side":"A","price":"1.156470000","size":30,"channel_id":23,"order_id":"1775527805036429506","flags":0,"ts_in_delta":760,"sequence":149856,"symbol":"FCEU SI 20260615 PS"}
{"ts_recv":"2026-04-07T02:10:05.046259092Z","hd":{"ts_event":"2026-04-07T02:10:05.046240603Z","rtype":160,"publisher_id":101,"instrument_id":436},"action":"A","side":"A","price":"1.156480000","size":30,"channel_id":23,"order_id":"1775527805046246338","flags":128,"ts_in_delta":760,"sequence":149856,"symbol":"FCEU SI 20260615 PS"}
{"ts_recv":"2026-04-07T02:10:05.046320721Z","hd":{"ts_event":"2026-04-07T02:10:05.046300777Z","rtype":160,"publisher_id":101,"instrument_id":436},"action":"C","side":"B","price":"1.156380000","size":30,"channel_id":23,"order_id":"10998899841901022146","flags":0,"ts_in_delta":757,"sequence":149858,"symbol":"FCEU SI 20260615 PS"}
{"ts_recv":"2026-04-07T02:10:05.046320721Z","hd":{"ts_event":"2026-04-07T02:10:05.046300777Z","rtype":160,"publisher_id":101,"instrument_id":436},"action":"A","side":"B","price":"1.156400000","size":30,"channel_id":23,"order_id":"10998899841901082974","flags":0,"ts_in_delta":757,"sequence":149858,"symbol":"FCEU SI 20260615 PS"}
{"ts_recv":"2026-04-07T02:10:05.046320721Z","hd":{"ts_event":"2026-04-07T02:10:05.046300777Z","rtype":160,"publisher_id":101,"instrument_id":436},"action":"C","side":"A","price":"1.156480000","size":30,"channel_id":23,"order_id":"1775527805046246338","flags":0,"ts_in_delta":757,"sequence":149858,"symbol":"FCEU SI 20260615 PS"}
{"ts_recv":"2026-04-07T02:10:05.046320721Z","hd":{"ts_event":"2026-04-07T02:10:05.046300777Z","rtype":160,"publisher_id":101,"instrument_id":436},"action":"A","side":"A","price":"1.156500000","size":30,"channel_id":23,"order_id":"1775527805046307166","flags":128,"ts_in_delta":757,"sequence":149858,"symbol":"FCEU SI 20260615 PS"}
{"ts_recv":"2026-04-07T02:10:05.046370124Z","hd":{"ts_event":"2026-04-07T02:10:05.046353213Z","rtype":160,"publisher_id":101,"instrument_id":436},"action":"C","side":"B","price":"1.156370000","size":30,"channel_id":23,"order_id":"10998899841889959184","flags":0,"ts_in_delta":746,"sequence":149859,"symbol":"FCEU SI 20260615 PS"}
{"ts_recv":"2026-04-07T02:10:05.046370124Z","hd":{"ts_event":"2026-04-07T02:10:05.046353213Z","rtype":160,"publisher_id":101,"instrument_id":436},"action":"A","side":"B","price":"1.156390000","size":30,"channel_id":23,"order_id":"10998899841901134993","flags":0,"ts_in_delta":746,"sequence":149859,"symbol":"FCEU SI 20260615 PS"}
{"ts_recv":"2026-04-07T02:10:05.046370124Z","hd":{"ts_event":"2026-04-07T02:10:05.046353213Z","rtype":160,"publisher_id":101,"instrument_id":436},"action":"C","side":"A","price":"1.156470000","size":30,"channel_id":23,"order_id":"1775527805035183376","flags":0,"ts_in_delta":746,"sequence":149859,"symbol":"FCEU SI 20260615 PS"}
{"ts_recv":"2026-04-07T02:10:05.046370124Z","hd":{"ts_event":"2026-04-07T02:10:05.046353213Z","rtype":160,"publisher_id":101,"instrument_id":436},"action":"A","side":"A","price":"1.156490000","size":30,"channel_id":23,"order_id":"1775527805046359185","flags":128,"ts_in_delta":746,"sequence":149859,"symbol":"FCEU SI 20260615 PS"}
{"ts_recv":"2026-04-07T02:10:05.046380300Z","hd":{"ts_event":"2026-04-07T02:10:05.046358379Z","rtype":160,"publisher_id":101,"instrument_id":436},"action":"C","side":"B","price":"1.156400000","size":30,"channel_id":23,"order_id":"10998899841901082974","flags":0,"ts_in_delta":754,"sequence":149860,"symbol":"FCEU SI 20260615 PS"}
{"ts_recv":"2026-04-07T02:10:05.046380300Z","hd":{"ts_event":"2026-04-07T02:10:05.046358379Z","rtype":160,"publisher_id":101,"instrument_id":436},"action":"A","side":"B","price":"1.156380000","size":30,"channel_id":23,"order_id":"10998899841901143151","flags":0,"ts_in_delta":754,"sequence":149860,"symbol":"FCEU SI 20260615 PS"}
{"ts_recv":"2026-04-07T02:10:05.046380300Z","hd":{"ts_event":"2026-04-07T02:10:05.046358379Z","rtype":160,"publisher_id":101,"instrument_id":436},"action":"C","side":"A","price":"1.156500000","size":30,"channel_id":23,"order_id":"1775527805046307166","flags":0,"ts_in_delta":754,"sequence":149860,"symbol":"FCEU SI 20260615 PS"}
{"ts_recv":"2026-04-07T02:10:05.046380300Z","hd":{"ts_event":"2026-04-07T02:10:05.046358379Z","rtype":160,"publisher_id":101,"instrument_id":436},"action":"A","side":"A","price":"1.156480000","size":30,"channel_id":23,"order_id":"1775527805046367343","flags":128,"ts_in_delta":754,"sequence":149860,"symbol":"FCEU SI 20260615 PS"}
{"ts_recv":"2026-04-07T02:10:05.046431300Z","hd":{"ts_event":"2026-04-07T02:10:05.046415747Z","rtype":160,"publisher_id":101,"instrument_id":436},"action":"C","side":"B","price":"1.156380000","size":30,"channel_id":23,"order_id":"10998899841901143151","flags":0,"ts_in_delta":1024,"sequence":149861,"symbol":"FCEU SI 20260615 PS"}
{"ts_recv":"2026-04-07T02:10:05.046431300Z","hd":{"ts_event":"2026-04-07T02:10:05.046415747Z","rtype":160,"publisher_id":101,"instrument_id":436},"action":"A","side":"B","price":"1.156390000","size":30,"channel_id":23,"order_id":"10998899841901197397","flags":0,"ts_in_delta":1024,"sequence":149861,"symbol":"FCEU SI 20260615 PS"}
{"ts_recv":"2026-04-07T02:10:05.046431300Z","hd":{"ts_event":"2026-04-07T02:10:05.046415747Z","rtype":160,"publisher_id":101,"instrument_id":436},"action":"C","side":"A","price":"1.156480000","size":30,"channel_id":23,"order_id":"1775527805046367343","flags":0,"ts_in_delta":1024,"sequence":149861,"symbol":"FCEU SI 20260615 PS"}
{"ts_recv":"2026-04-07T02:10:05.046431300Z","hd":{"ts_event":"2026-04-07T02:10:05.046415747Z","rtype":160,"publisher_id":101,"instrument_id":436},"action":"A","side":"A","price":"1.156490000","size":30,"channel_id":23,"order_id":"1775527805046421589","flags":128,"ts_in_delta":1024,"sequence":149861,"symbol":"FCEU SI 20260615 PS"}
{"ts_recv":"2026-04-07T02:10:05.240487903Z","hd":{"ts_event":"2026-04-07T02:10:05.240470535Z","rtype":160,"publisher_id":101,"instrument_id":436},"action":"A","side":"B","price":"1.156300000","size":20,"channel_id":23,"order_id":"10998899842095252922","flags":128,"ts_in_delta":979,"sequence":149889,"symbol":"FCEU SI 20260615 PS"}
{"ts_recv":"2026-04-07T02:10:05.240716710Z","hd":{"ts_event":"2026-04-07T02:10:05.240702789Z","rtype":160,"publisher_id":101,"instrument_id":436},"action":"C","side":"B","price":"1.156200000","size":20,"channel_id":23,"order_id":"10998899757545354213","flags":128,"ts_in_delta":900,"sequence":149890,"symbol":"FCEU SI 20260615 PS"}
{"ts_recv":"2026-04-07T02:10:10.744638795Z","hd":{"ts_event":"2026-04-07T02:10:10.744616641Z","rtype":160,"publisher_id":101,"instrument_id":436},"action":"C","side":"B","price":"1.156390000","size":30,"channel_id":23,"order_id":"10998899841901197397","flags":0,"ts_in_delta":919,"sequence":149947,"symbol":"FCEU SI 20260615 PS"}
{"ts_recv":"2026-04-07T02:10:10.744638795Z","hd":{"ts_event":"2026-04-07T02:10:10.744616641Z","rtype":160,"publisher_id":101,"instrument_id":436},"action":"A","side":"B","price":"1.156400000","size":30,"channel_id":23,"order_id":"10998899847599398136","flags":0,"ts_in_delta":919,"sequence":149947,"symbol":"FCEU SI 20260615 PS"}
{"ts_recv":"2026-04-07T02:10:10.744638795Z","hd":{"ts_event":"2026-04-07T02:10:10.744616641Z","rtype":160,"publisher_id":101,"instrument_id":436},"action":"C","side":"A","price":"1.156490000","size":30,"channel_id":23,"order_id":"1775527805046421589","flags":0,"ts_in_delta":919,"sequence":149947,"symbol":"FCEU SI 20260615 PS"}
{"ts_recv":"2026-04-07T02:10:10.744638795Z","hd":{"ts_event":"2026-04-07T02:10:10.744616641Z","rtype":160,"publisher_id":101,"instrument_id":436},"action":"A","side":"A","price":"1.156500000","size":30,"channel_id":23,"order_id":"1775527810744622328","flags":128,"ts_in_delta":919,"sequence":149947,"symbol":"FCEU SI 20260615 PS"}
{"ts_recv":"2026-04-07T02:10:10.744695509Z","hd":{"ts_event":"2026-04-07T02:10:10.744673499Z","rtype":160,"publisher_id":101,"instrument_id":436},"action":"C","side":"B","price":"1.156390000","size":30,"channel_id":23,"order_id":"10998899841901134993","flags":0,"ts_in_delta":1083,"sequence":149948,"symbol":"FCEU SI 20260615 PS"}
{"ts_recv":"2026-04-07T02:10:10.744695509Z","hd":{"ts_event":"2026-04-07T02:10:10.744673499Z","rtype":160,"publisher_id":101,"instrument_id":436},"action":"A","side":"B","price":"1.156410000","size":30,"channel_id":23,"order_id":"10998899847599455121","flags":0,"ts_in_delta":1083,"sequence":149948,"symbol":"FCEU SI 20260615 PS"}
{"ts_recv":"2026-04-07T02:10:10.744695509Z","hd":{"ts_event":"2026-04-07T02:10:10.744673499Z","rtype":160,"publisher_id":101,"instrument_id":436},"action":"C","side":"A","price":"1.156490000","size":30,"channel_id":23,"order_id":"1775527805046359185","flags":0,"ts_in_delta":1083,"sequence":149948,"symbol":"FCEU SI 20260615 PS"}
{"ts_recv":"2026-04-07T02:10:10.744695509Z","hd":{"ts_event":"2026-04-07T02:10:10.744673499Z","rtype":160,"publisher_id":101,"instrument_id":436},"action":"A","side":"A","price":"1.156510000","size":30,"channel_id":23,"order_id":"1775527810744679313","flags":128,"ts_in_delta":1083,"sequence":149948,"symbol":"FCEU SI 20260615 PS"}
{"ts_recv":"2026-04-07T02:10:10.744719815Z","hd":{"ts_event":"2026-04-07T02:10:10.744701513Z","rtype":160,"publisher_id":101,"instrument_id":436},"action":"C","side":"B","price":"1.156400000","size":30,"channel_id":23,"order_id":"10998899847599398136","flags":0,"ts_in_delta":895,"sequence":149949,"symbol":"FCEU SI 20260615 PS"}
{"ts_recv":"2026-04-07T02:10:10.744719815Z","hd":{"ts_event":"2026-04-07T02:10:10.744701513Z","rtype":160,"publisher_id":101,"instrument_id":436},"action":"A","side":"B","price":"1.156410000","size":30,"channel_id":23,"order_id":"10998899847599483181","flags":0,"ts_in_delta":895,"sequence":149949,"symbol":"FCEU SI 20260615 PS"}
{"ts_recv":"2026-04-07T02:10:10.744719815Z","hd":{"ts_event":"2026-04-07T02:10:10.744701513Z","rtype":160,"publisher_id":101,"instrument_id":436},"action":"C","side":"A","price":"1.156500000","size":30,"channel_id":23,"order_id":"1775527810744622328","flags":0,"ts_in_delta":895,"sequence":149949,"symbol":"FCEU SI 20260615 PS"}
{"ts_recv":"2026-04-07T02:10:10.744719815Z","hd":{"ts_event":"2026-04-07T02:10:10.744701513Z","rtype":160,"publisher_id":101,"instrument_id":436},"action":"A","side":"A","price":"1.156510000","size":30,"channel_id":23,"order_id":"1775527810744707373","flags":128,"ts_in_delta":895,"sequence":149949,"symbol":"FCEU SI 20260615 PS"}
{"ts_recv":"2026-04-07T02:10:11.643718729Z","hd":{"ts_event":"2026-04-07T02:10:11.643689383Z","rtype":160,"publisher_id":101,"instrument_id":436},"action":"C","side":"B","price":"1.156410000","size":30,"channel_id":23,"order_id":"10998899847599483181","flags":0,"ts_in_delta":1214,"sequence":149986,"symbol":"FCEU SI 20260615 PS"}
{"ts_recv":"2026-04-07T02:10:11.643718729Z","hd":{"ts_event":"2026-04-07T02:10:11.643689383Z","rtype":160,"publisher_id":101,"instrument_id":436},"action":"A","side":"B","price":"1.156420000","size":30,"channel_id":23,"order_id":"10998899848498478371","flags":0,"ts_in_delta":1214,"sequence":149986,"symbol":"FCEU SI 20260615 PS"}
{"ts_recv":"2026-04-07T02:10:11.643718729Z","hd":{"ts_event":"2026-04-07T02:10:11.643689383Z","rtype":160,"publisher_id":101,"instrument_id":436},"action":"C","side":"A","price":"1.156510000","size":30,"channel_id":23,"order_id":"1775527810744707373","flags":0,"ts_in_delta":1214,"sequence":149986,"symbol":"FCEU SI 20260615 PS"}
{"ts_recv":"2026-04-07T02:10:11.643718729Z","hd":{"ts_event":"2026-04-07T02:10:11.643689383Z","rtype":160,"publisher_id":101,"instrument_id":436},"action":"A","side":"A","price":"1.156520000","size":30,"channel_id":23,"order_id":"1775527811643702563","flags":128,"ts_in_delta":1214,"sequence":149986,"symbol":"FCEU SI 20260615 PS"}
{"ts_recv":"2026-04-07T02:10:11.643779245Z","hd":{"ts_event":"2026-04-07T02:10:11.643760729Z","rtype":160,"publisher_id":101,"instrument_id":436},"action":"C","side":"B","price":"1.156410000","size":30,"channel_id":23,"order_id":"10998899847599455121","flags":0,"ts_in_delta":939,"sequence":149987,"symbol":"FCEU SI 20260615 PS"}
{"ts_recv":"2026-04-07T02:10:11.643779245Z","hd":{"ts_event":"2026-04-07T02:10:11.643760729Z","rtype":160,"publisher_id":101,"instrument_id":436},"action":"A","side":"B","price":"1.156430000","size":30,"channel_id":23,"order_id":"10998899848498542688","flags":0,"ts_in_delta":939,"sequence":149987,"symbol":"FCEU SI 20260615 PS"}
{"ts_recv":"2026-04-07T02:10:11.643779245Z","hd":{"ts_event":"2026-04-07T02:10:11.643760729Z","rtype":160,"publisher_id":101,"instrument_id":436},"action":"C","side":"A","price":"1.156510000","size":30,"channel_id":23,"order_id":"1775527810744679313","flags":0,"ts_in_delta":939,"sequence":149987,"symbol":"FCEU SI 20260615 PS"}
{"ts_recv":"2026-04-07T02:10:11.643779245Z","hd":{"ts_event":"2026-04-07T02:10:11.643760729Z","rtype":160,"publisher_id":101,"instrument_id":436},"action":"A","side":"A","price":"1.156530000","size":30,"channel_id":23,"order_id":"1775527811643766880","flags":128,"ts_in_delta":939,"sequence":149987,"symbol":"FCEU SI 20260615 PS"}
{"ts_recv":"2026-04-07T02:10:11.643838055Z","hd":{"ts_event":"2026-04-07T02:10:11.643820307Z","rtype":160,"publisher_id":101,"instrument_id":436},"action":"C","side":"B","price":"1.156420000","size":30,"channel_id":23,"order_id":"10998899848498478371","flags":0,"ts_in_delta":944,"sequence":149988,"symbol":"FCEU SI 20260615 PS"}
{"ts_recv":"2026-04-07T02:10:11.643838055Z","hd":{"ts_event":"2026-04-07T02:10:11.643820307Z","rtype":160,"publisher_id":101,"instrument_id":436},"action":"A","side":"B","price":"1.156430000","size":30,"channel_id":23,"order_id":"10998899848498601922","flags":0,"ts_in_delta":944,"sequence":149988,"symbol":"FCEU SI 20260615 PS"}
{"ts_recv":"2026-04-07T02:10:11.643838055Z","hd":{"ts_event":"2026-04-07T02:10:11.643820307Z","rtype":160,"publisher_id":101,"instrument_id":436},"action":"C","side":"A","price":"1.156520000","size":30,"channel_id":23,"order_id":"1775527811643702563","flags":0,"ts_in_delta":944,"sequence":149988,"symbol":"FCEU SI 20260615 PS"}
{"ts_recv":"2026-04-07T02:10:11.643838055Z","hd":{"ts_event":"2026-04-07T02:10:11.643820307Z","rtype":160,"publisher_id":101,"instrument_id":436},"action":"A","side":"A","price":"1.156530000","size":30,"channel_id":23,"order_id":"1775527811643826114","flags":128,"ts_in_delta":944,"sequence":149988,"symbol":"FCEU SI 20260615 PS"}
{"ts_recv":"2026-04-07T02:10:12.598770274Z","hd":{"ts_event":"2026-04-07T02:10:12.598748815Z","rtype":160,"publisher_id":101,"instrument_id":436},"action":"C","side":"B","price":"1.156430000","size":30,"channel_id":23,"order_id":"10998899848498601922","flags":0,"ts_in_delta":1048,"sequence":150013,"symbol":"FCEU SI 20260615 PS"}
{"ts_recv":"2026-04-07T02:10:12.598770274Z","hd":{"ts_event":"2026-04-07T02:10:12.598748815Z","rtype":160,"publisher_id":101,"instrument_id":436},"action":"A","side":"B","price":"1.156420000","size":30,"channel_id":23,"order_id":"10998899849453531489","flags":0,"ts_in_delta":1048,"sequence":150013,"symbol":"FCEU SI 20260615 PS"}
{"ts_recv":"2026-04-07T02:10:12.598770274Z","hd":{"ts_event":"2026-04-07T02:10:12.598748815Z","rtype":160,"publisher_id":101,"instrument_id":436},"action":"C","side":"A","price":"1.156530000","size":30,"channel_id":23,"order_id":"1775527811643826114","flags":0,"ts_in_delta":1048,"sequence":150013,"symbol":"FCEU SI 20260615 PS"}
{"ts_recv":"2026-04-07T02:10:12.598770274Z","hd":{"ts_event":"2026-04-07T02:10:12.598748815Z","rtype":160,"publisher_id":101,"instrument_id":436},"action":"A","side":"A","price":"1.156520000","size":30,"channel_id":23,"order_id":"1775527812598755681","flags":128,"ts_in_delta":1048,"sequence":150013,"symbol":"FCEU SI 20260615 PS"}
{"ts_recv":"2026-04-07T02:10:16.099779962Z","hd":{"ts_event":"2026-04-07T02:10:16.099761075Z","rtype":160,"publisher_id":101,"instrument_id":436},"action":"C","side":"B","price":"1.156420000","size":30,"channel_id":23,"order_id":"10998899849453531489","flags":0,"ts_in_delta":985,"sequence":150066,"symbol":"FCEU SI 20260615 PS"}
{"ts_recv":"2026-04-07T02:10:16.099779962Z","hd":{"ts_event":"2026-04-07T02:10:16.099761075Z","rtype":160,"publisher_id":101,"instrument_id":436},"action":"A","side":"B","price":"1.156430000","size":30,"channel_id":23,"order_id":"10998899852954542719","flags":0,"ts_in_delta":985,"sequence":150066,"symbol":"FCEU SI 20260615 PS"}
{"ts_recv":"2026-04-07T02:10:16.099779962Z","hd":{"ts_event":"2026-04-07T02:10:16.099761075Z","rtype":160,"publisher_id":101,"instrument_id":436},"action":"C","side":"A","price":"1.156520000","size":30,"channel_id":23,"order_id":"1775527812598755681","flags":0,"ts_in_delta":985,"sequence":150066,"symbol":"FCEU SI 20260615 PS"}
{"ts_recv":"2026-04-07T02:10:16.099779962Z","hd":{"ts_event":"2026-04-07T02:10:16.099761075Z","rtype":160,"publisher_id":101,"instrument_id":436},"action":"A","side":"A","price":"1.156530000","size":30,"channel_id":23,"order_id":"1775527816099766911","flags":128,"ts_in_delta":985,"sequence":150066,"symbol":"FCEU SI 20260615 PS"}
{"ts_recv":"2026-04-07T02:10:28.103841590Z","hd":{"ts_event":"2026-04-07T02:10:28.103814001Z","rtype":160,"publisher_id":101,"instrument_id":436},"action":"C","side":"B","price":"1.156430000","size":30,"channel_id":23,"order_id":"10998899852954542719","flags":0,"ts_in_delta":926,"sequence":150259,"symbol":"FCEU SI 20260615 PS"}
{"ts_recv":"2026-04-07T02:10:28.103841590Z","hd":{"ts_event":"2026-04-07T02:10:28.103814001Z","rtype":160,"publisher_id":101,"instrument_id":436},"action":"A","side":"B","price":"1.156420000","size":30,"channel_id":23,"order_id":"10998899864958602565","flags":0,"ts_in_delta":926,"sequence":150259,"symbol":"FCEU SI 20260615 PS"}
{"ts_recv":"2026-04-07T02:10:28.103841590Z","hd":{"ts_event":"2026-04-07T02:10:28.103814001Z","rtype":160,"publisher_id":101,"instrument_id":436},"action":"C","side":"A","price":"1.156530000","size":30,"channel_id":23,"order_id":"1775527816099766911","flags":0,"ts_in_delta":926,"sequence":150259,"symbol":"FCEU SI 20260615 PS"}
{"ts_recv":"2026-04-07T02:10:28.103841590Z","hd":{"ts_event":"2026-04-07T02:10:28.103814001Z","rtype":160,"publisher_id":101,"instrument_id":436},"action":"A","side":"A","price":"1.156520000","size":30,"channel_id":23,"order_id":"1775527828103826757","flags":128,"ts_in_delta":926,"sequence":150259,"symbol":"FCEU SI 20260615 PS"}
{"ts_recv":"2026-04-07T02:10:28.113159652Z","hd":{"ts_event":"2026-04-07T02:10:28.113142139Z","rtype":160,"publisher_id":101,"instrument_id":436},"action":"C","side":"B","price":"1.156430000","size":30,"channel_id":23,"order_id":"10998899848498542688","flags":0,"ts_in_delta":923,"sequence":150261,"symbol":"FCEU SI 20260615 PS"}
{"ts_recv":"2026-04-07T02:10:28.113159652Z","hd":{"ts_event":"2026-04-07T02:10:28.113142139Z","rtype":160,"publisher_id":101,"instrument_id":436},"action":"A","side":"B","price":"1.156410000","size":30,"channel_id":23,"order_id":"10998899864967923781","flags":0,"ts_in_delta":923,"sequence":150261,"symbol":"FCEU SI 20260615 PS"}
{"ts_recv":"2026-04-07T02:10:28.113159652Z","hd":{"ts_event":"2026-04-07T02:10:28.113142139Z","rtype":160,"publisher_id":101,"instrument_id":436},"action":"C","side":"A","price":"1.156530000","size":30,"channel_id":23,"order_id":"1775527811643766880","flags":0,"ts_in_delta":923,"sequence":150261,"symbol":"FCEU SI 20260615 PS"}
{"ts_recv":"2026-04-07T02:10:28.113159652Z","hd":{"ts_event":"2026-04-07T02:10:28.113142139Z","rtype":160,"publisher_id":101,"instrument_id":436},"action":"A","side":"A","price":"1.156510000","size":30,"channel_id":23,"order_id":"1775527828113147973","flags":128,"ts_in_delta":923,"sequence":150261,"symbol":"FCEU SI 20260615 PS"}
{"ts_recv":"2026-04-07T02:10:28.113228139Z","hd":{"ts_event":"2026-04-07T02:10:28.113212399Z","rtype":160,"publisher_id":101,"instrument_id":436},"action":"C","side":"B","price":"1.156420000","size":30,"channel_id":23,"order_id":"10998899864958602565","flags":0,"ts_in_delta":910,"sequence":150262,"symbol":"FCEU SI 20260615 PS"}
{"ts_recv":"2026-04-07T02:10:28.113228139Z","hd":{"ts_event":"2026-04-07T02:10:28.113212399Z","rtype":160,"publisher_id":101,"instrument_id":436},"action":"A","side":"B","price":"1.156410000","size":30,"channel_id":23,"order_id":"10998899864967994026","flags":0,"ts_in_delta":910,"sequence":150262,"symbol":"FCEU SI 20260615 PS"}
{"ts_recv":"2026-04-07T02:10:28.113228139Z","hd":{"ts_event":"2026-04-07T02:10:28.113212399Z","rtype":160,"publisher_id":101,"instrument_id":436},"action":"C","side":"A","price":"1.156520000","size":30,"channel_id":23,"order_id":"1775527828103826757","flags":0,"ts_in_delta":910,"sequence":150262,"symbol":"FCEU SI 20260615 PS"}
{"ts_recv":"2026-04-07T02:10:28.113228139Z","hd":{"ts_event":"2026-04-07T02:10:28.113212399Z","rtype":160,"publisher_id":101,"instrument_id":436},"action":"A","side":"A","price":"1.156510000","size":30,"channel_id":23,"order_id":"1775527828113218218","flags":128,"ts_in_delta":910,"sequence":150262,"symbol":"FCEU SI 20260615 PS"}
{"ts_recv":"2026-04-07T02:10:28.115478046Z","hd":{"ts_event":"2026-04-07T02:10:28.115456417Z","rtype":160,"publisher_id":101,"instrument_id":436},"action":"C","side":"B","price":"1.156410000","size":30,"channel_id":23,"order_id":"10998899864967994026","flags":0,"ts_in_delta":944,"sequence":150264,"symbol":"FCEU SI 20260615 PS"}
{"ts_recv":"2026-04-07T02:10:28.115478046Z","hd":{"ts_event":"2026-04-07T02:10:28.115456417Z","rtype":160,"publisher_id":101,"instrument_id":436},"action":"A","side":"B","price":"1.156400000","size":30,"channel_id":23,"order_id":"10998899864970238045","flags":0,"ts_in_delta":944,"sequence":150264,"symbol":"FCEU SI 20260615 PS"}
{"ts_recv":"2026-04-07T02:10:28.115478046Z","hd":{"ts_event":"2026-04-07T02:10:28.115456417Z","rtype":160,"publisher_id":101,"instrument_id":436},"action":"C","side":"A","price":"1.156510000","size":30,"channel_id":23,"order_id":"1775527828113218218","flags":0,"ts_in_delta":944,"sequence":150264,"symbol":"FCEU SI 20260615 PS"}
{"ts_recv":"2026-04-07T02:10:28.115478046Z","hd":{"ts_event":"2026-04-07T02:10:28.115456417Z","rtype":160,"publisher_id":101,"instrument_id":436},"action":"A","side":"A","price":"1.156500000","size":30,"channel_id":23,"order_id":"1775527828115462237","flags":128,"ts_in_delta":944,"sequence":150264,"symbol":"FCEU SI 20260615 PS"}
{"ts_recv":"2026-04-07T02:10:28.115557645Z","hd":{"ts_event":"2026-04-07T02:10:28.115540051Z","rtype":160,"publisher_id":101,"instrument_id":436},"action":"C","side":"B","price":"1.156400000","size":30,"channel_id":23,"order_id":"10998899864970238045","flags":0,"ts_in_delta":914,"sequence":150265,"symbol":"FCEU SI 20260615 PS"}
{"ts_recv":"2026-04-07T02:10:28.115557645Z","hd":{"ts_event":"2026-04-07T02:10:28.115540051Z","rtype":160,"publisher_id":101,"instrument_id":436},"action":"A","side":"B","price":"1.156380000","size":30,"channel_id":23,"order_id":"10998899864970321812","flags":0,"ts_in_delta":914,"sequence":150265,"symbol":"FCEU SI 20260615 PS"}
{"ts_recv":"2026-04-07T02:10:28.115557645Z","hd":{"ts_event":"2026-04-07T02:10:28.115540051Z","rtype":160,"publisher_id":101,"instrument_id":436},"action":"C","side":"A","price":"1.156500000","size":30,"channel_id":23,"order_id":"1775527828115462237","flags":0,"ts_in_delta":914,"sequence":150265,"symbol":"FCEU SI 20260615 PS"}
{"ts_recv":"2026-04-07T02:10:28.115557645Z","hd":{"ts_event":"2026-04-07T02:10:28.115540051Z","rtype":160,"publisher_id":101,"instrument_id":436},"action":"A","side":"A","price":"1.156480000","size":30,"channel_id":23,"order_id":"1775527828115546004","flags":128,"ts_in_delta":914,"sequence":150265,"symbol":"FCEU SI 20260615 PS"}
{"ts_recv":"2026-04-07T02:10:28.115605466Z","hd":{"ts_event":"2026-04-07T02:10:28.115586899Z","rtype":160,"publisher_id":101,"instrument_id":436},"action":"C","side":"B","price":"1.156410000","size":30,"channel_id":23,"order_id":"10998899864967923781","flags":0,"ts_in_delta":885,"sequence":150266,"symbol":"FCEU SI 20260615 PS"}
{"ts_recv":"2026-04-07T02:10:28.115605466Z","hd":{"ts_event":"2026-04-07T02:10:28.115586899Z","rtype":160,"publisher_id":101,"instrument_id":436},"action":"A","side":"B","price":"1.156390000","size":30,"channel_id":23,"order_id":"10998899864970368723","flags":0,"ts_in_delta":885,"sequence":150266,"symbol":"FCEU SI 20260615 PS"}
{"ts_recv":"2026-04-07T02:10:28.115605466Z","hd":{"ts_event":"2026-04-07T02:10:28.115586899Z","rtype":160,"publisher_id":101,"instrument_id":436},"action":"C","side":"A","price":"1.156510000","size":30,"channel_id":23,"order_id":"1775527828113147973","flags":0,"ts_in_delta":885,"sequence":150266,"symbol":"FCEU SI 20260615 PS"}
{"ts_recv":"2026-04-07T02:10:28.115605466Z","hd":{"ts_event":"2026-04-07T02:10:28.115586899Z","rtype":160,"publisher_id":101,"instrument_id":436},"action":"A","side":"A","price":"1.156490000","size":30,"channel_id":23,"order_id":"1775527828115592915","flags":128,"ts_in_delta":885,"sequence":150266,"symbol":"FCEU SI 20260615 PS"}
{"ts_recv":"2026-04-07T02:10:28.115616663Z","hd":{"ts_event":"2026-04-07T02:10:28.115596981Z","rtype":160,"publisher_id":101,"instrument_id":436},"action":"C","side":"B","price":"1.156380000","size":30,"channel_id":23,"order_id":"10998899864970321812","flags":0,"ts_in_delta":911,"sequence":150267,"symbol":"FCEU SI 20260615 PS"}
{"ts_recv":"2026-04-07T02:10:28.115616663Z","hd":{"ts_event":"2026-04-07T02:10:28.115596981Z","rtype":160,"publisher_id":101,"instrument_id":436},"action":"A","side":"B","price":"1.156400000","size":30,"channel_id":23,"order_id":"10998899864970378580","flags":0,"ts_in_delta":911,"sequence":150267,"symbol":"FCEU SI 20260615 PS"}
{"ts_recv":"2026-04-07T02:10:28.115616663Z","hd":{"ts_event":"2026-04-07T02:10:28.115596981Z","rtype":160,"publisher_id":101,"instrument_id":436},"action":"C","side":"A","price":"1.156480000","size":30,"channel_id":23,"order_id":"1775527828115546004","flags":0,"ts_in_delta":911,"sequence":150267,"symbol":"FCEU SI 20260615 PS"}
{"ts_recv":"2026-04-07T02:10:28.115616663Z","hd":{"ts_event":"2026-04-07T02:10:28.115596981Z","rtype":160,"publisher_id":101,"instrument_id":436},"action":"A","side":"A","price":"1.156500000","size":30,"channel_id":23,"order_id":"1775527828115602772","flags":128,"ts_in_delta":911,"sequence":150267,"symbol":"FCEU SI 20260615 PS"}
{"ts_recv":"2026-04-07T02:10:28.115670851Z","hd":{"ts_event":"2026-04-07T02:10:28.115651797Z","rtype":160,"publisher_id":101,"instrument_id":436},"action":"C","side":"B","price":"1.156400000","size":30,"channel_id":23,"order_id":"10998899864970378580","flags":0,"ts_in_delta":902,"sequence":150268,"symbol":"FCEU SI 20260615 PS"}
{"ts_recv":"2026-04-07T02:10:28.115670851Z","hd":{"ts_event":"2026-04-07T02:10:28.115651797Z","rtype":160,"publisher_id":101,"instrument_id":436},"action":"A","side":"B","price":"1.156390000","size":30,"channel_id":23,"order_id":"10998899864970433819","flags":0,"ts_in_delta":902,"sequence":150268,"symbol":"FCEU SI 20260615 PS"}
{"ts_recv":"2026-04-07T02:10:28.115670851Z","hd":{"ts_event":"2026-04-07T02:10:28.115651797Z","rtype":160,"publisher_id":101,"instrument_id":436},"action":"C","side":"A","price":"1.156500000","size":30,"channel_id":23,"order_id":"1775527828115602772","flags":0,"ts_in_delta":902,"sequence":150268,"symbol":"FCEU SI 20260615 PS"}
{"ts_recv":"2026-04-07T02:10:28.115670851Z","hd":{"ts_event":"2026-04-07T02:10:28.115651797Z","rtype":160,"publisher_id":101,"instrument_id":436},"action":"A","side":"A","price":"1.156490000","size":30,"channel_id":23,"order_id":"1775527828115658011","flags":128,"ts_in_delta":902,"sequence":150268,"symbol":"FCEU SI 20260615 PS"}
{"ts_recv":"2026-04-07T02:10:28.120158637Z","hd":{"ts_event":"2026-04-07T02:10:28.120140213Z","rtype":160,"publisher_id":101,"instrument_id":436},"action":"C","side":"B","price":"1.156390000","size":30,"channel_id":23,"order_id":"10998899864970433819","flags":0,"ts_in_delta":947,"sequence":150270,"symbol":"FCEU SI 20260615 PS"}
{"ts_recv":"2026-04-07T02:10:28.120158637Z","hd":{"ts_event":"2026-04-07T02:10:28.120140213Z","rtype":160,"publisher_id":101,"instrument_id":436},"action":"A","side":"B","price":"1.156380000","size":30,"channel_id":23,"order_id":"10998899864974922169","flags":0,"ts_in_delta":947,"sequence":150270,"symbol":"FCEU SI 20260615 PS"}
{"ts_recv":"2026-04-07T02:10:28.120158637Z","hd":{"ts_event":"2026-04-07T02:10:28.120140213Z","rtype":160,"publisher_id":101,"instrument_id":436},"action":"C","side":"A","price":"1.156490000","size":30,"channel_id":23,"order_id":"1775527828115658011","flags":0,"ts_in_delta":947,"sequence":150270,"symbol":"FCEU SI 20260615 PS"}
{"ts_recv":"2026-04-07T02:10:28.120158637Z","hd":{"ts_event":"2026-04-07T02:10:28.120140213Z","rtype":160,"publisher_id":101,"instrument_id":436},"action":"A","side":"A","price":"1.156480000","size":30,"channel_id":23,"order_id":"1775527828120146361","flags":128,"ts_in_delta":947,"sequence":150270,"symbol":"FCEU SI 20260615 PS"}
{"ts_recv":"2026-04-07T02:10:28.120218531Z","hd":{"ts_event":"2026-04-07T02:10:28.120199331Z","rtype":160,"publisher_id":101,"instrument_id":436},"action":"C","side":"B","price":"1.156380000","size":30,"channel_id":23,"order_id":"10998899864974922169","flags":0,"ts_in_delta":890,"sequence":150271,"symbol":"FCEU SI 20260615 PS"}
{"ts_recv":"2026-04-07T02:10:28.120218531Z","hd":{"ts_event":"2026-04-07T02:10:28.120199331Z","rtype":160,"publisher_id":101,"instrument_id":436},"action":"A","side":"B","price":"1.156360000","size":30,"channel_id":23,"order_id":"10998899864974981068","flags":0,"ts_in_delta":890,"sequence":150271,"symbol":"FCEU SI 20260615 PS"}
{"ts_recv":"2026-04-07T02:10:28.120218531Z","hd":{"ts_event":"2026-04-07T02:10:28.120199331Z","rtype":160,"publisher_id":101,"instrument_id":436},"action":"C","side":"A","price":"1.156480000","size":30,"channel_id":23,"order_id":"1775527828120146361","flags":0,"ts_in_delta":890,"sequence":150271,"symbol":"FCEU SI 20260615 PS"}
{"ts_recv":"2026-04-07T02:10:28.120218531Z","hd":{"ts_event":"2026-04-07T02:10:28.120199331Z","rtype":160,"publisher_id":101,"instrument_id":436},"action":"A","side":"A","price":"1.156460000","size":30,"channel_id":23,"order_id":"1775527828120205260","flags":128,"ts_in_delta":890,"sequence":150271,"symbol":"FCEU SI 20260615 PS"}
{"ts_recv":"2026-04-07T02:10:28.120274047Z","hd":{"ts_event":"2026-04-07T02:10:28.120257623Z","rtype":160,"publisher_id":101,"instrument_id":436},"action":"C","side":"B","price":"1.156360000","size":30,"channel_id":23,"order_id":"10998899864974981068","flags":0,"ts_in_delta":908,"sequence":150272,"symbol":"FCEU SI 20260615 PS"}
{"ts_recv":"2026-04-07T02:10:28.120274047Z","hd":{"ts_event":"2026-04-07T02:10:28.120257623Z","rtype":160,"publisher_id":101,"instrument_id":436},"action":"A","side":"B","price":"1.156380000","size":30,"channel_id":23,"order_id":"10998899864975039121","flags":0,"ts_in_delta":908,"sequence":150272,"symbol":"FCEU SI 20260615 PS"}
{"ts_recv":"2026-04-07T02:10:28.120274047Z","hd":{"ts_event":"2026-04-07T02:10:28.120257623Z","rtype":160,"publisher_id":101,"instrument_id":436},"action":"C","side":"A","price":"1.156460000","size":30,"channel_id":23,"order_id":"1775527828120205260","flags":0,"ts_in_delta":908,"sequence":150272,"symbol":"FCEU SI 20260615 PS"}
{"ts_recv":"2026-04-07T02:10:28.120274047Z","hd":{"ts_event":"2026-04-07T02:10:28.120257623Z","rtype":160,"publisher_id":101,"instrument_id":436},"action":"A","side":"A","price":"1.156480000","size":30,"channel_id":23,"order_id":"1775527828120263313","flags":128,"ts_in_delta":908,"sequence":150272,"symbol":"FCEU SI 20260615 PS"}
{"ts_recv":"2026-04-07T02:10:28.134902086Z","hd":{"ts_event":"2026-04-07T02:10:28.134885155Z","rtype":160,"publisher_id":101,"instrument_id":436},"action":"C","side":"B","price":"1.156380000","size":30,"channel_id":23,"order_id":"10998899864975039121","flags":0,"ts_in_delta":752,"sequence":150281,"symbol":"FCEU SI 20260615 PS"}
{"ts_recv":"2026-04-07T02:10:28.134902086Z","hd":{"ts_event":"2026-04-07T02:10:28.134885155Z","rtype":160,"publisher_id":101,"instrument_id":436},"action":"A","side":"B","price":"1.156370000","size":30,"channel_id":23,"order_id":"10998899864989666959","flags":0,"ts_in_delta":752,"sequence":150281,"symbol":"FCEU SI 20260615 PS"}
{"ts_recv":"2026-04-07T02:10:28.134902086Z","hd":{"ts_event":"2026-04-07T02:10:28.134885155Z","rtype":160,"publisher_id":101,"instrument_id":436},"action":"C","side":"A","price":"1.156480000","size":30,"channel_id":23,"order_id":"1775527828120263313","flags":0,"ts_in_delta":752,"sequence":150281,"symbol":"FCEU SI 20260615 PS"}
{"ts_recv":"2026-04-07T02:10:28.134902086Z","hd":{"ts_event":"2026-04-07T02:10:28.134885155Z","rtype":160,"publisher_id":101,"instrument_id":436},"action":"A","side":"A","price":"1.156470000","size":30,"channel_id":23,"order_id":"1775527828134891151","flags":128,"ts_in_delta":752,"sequence":150281,"symbol":"FCEU SI 20260615 PS"}
{"ts_recv":"2026-04-07T02:10:28.135156820Z","hd":{"ts_event":"2026-04-07T02:10:28.135142115Z","rtype":160,"publisher_id":101,"instrument_id":436},"action":"C","side":"B","price":"1.156370000","size":30,"channel_id":23,"order_id":"10998899864989666959","flags":0,"ts_in_delta":775,"sequence":150282,"symbol":"FCEU SI 20260615 PS"}
{"ts_recv":"2026-04-07T02:10:28.135156820Z","hd":{"ts_event":"2026-04-07T02:10:28.135142115Z","rtype":160,"publisher_id":101,"instrument_id":436},"action":"C","side":"A","price":"1.156470000","size":30,"channel_id":23,"order_id":"1775527828134891151","flags":128,"ts_in_delta":775,"sequence":150282,"symbol":"FCEU SI 20260615 PS"}
{"ts_recv":"2026-04-07T02:10:28.137523895Z","hd":{"ts_event":"2026-04-07T02:10:28.137505481Z","rtype":160,"publisher_id":101,"instrument_id":436},"action":"C","side":"B","price":"1.156390000","size":30,"channel_id":23,"order_id":"10998899864970368723","flags":0,"ts_in_delta":706,"sequence":150283,"symbol":"FCEU SI 20260615 PS"}
{"ts_recv":"2026-04-07T02:10:28.137523895Z","hd":{"ts_event":"2026-04-07T02:10:28.137505481Z","rtype":160,"publisher_id":101,"instrument_id":436},"action":"A","side":"B","price":"1.156370000","size":30,"channel_id":23,"order_id":"10998899864992287087","flags":0,"ts_in_delta":706,"sequence":150283,"symbol":"FCEU SI 20260615 PS"}
{"ts_recv":"2026-04-07T02:10:28.137523895Z","hd":{"ts_event":"2026-04-07T02:10:28.137505481Z","rtype":160,"publisher_id":101,"instrument_id":436},"action":"C","side":"A","price":"1.156490000","size":30,"channel_id":23,"order_id":"1775527828115592915","flags":0,"ts_in_delta":706,"sequence":150283,"symbol":"FCEU SI 20260615 PS"}
{"ts_recv":"2026-04-07T02:10:28.137523895Z","hd":{"ts_event":"2026-04-07T02:10:28.137505481Z","rtype":160,"publisher_id":101,"instrument_id":436},"action":"A","side":"A","price":"1.156470000","size":30,"channel_id":23,"order_id":"1775527828137511279","flags":128,"ts_in_delta":706,"sequence":150283,"symbol":"FCEU SI 20260615 PS"}
{"ts_recv":"2026-04-07T02:10:28.205659917Z","hd":{"ts_event":"2026-04-07T02:10:28.205639155Z","rtype":160,"publisher_id":101,"instrument_id":436},"action":"C","side":"B","price":"1.156370000","size":30,"channel_id":23,"order_id":"10998899864992287087","flags":0,"ts_in_delta":948,"sequence":150296,"symbol":"FCEU SI 20260615 PS"}
{"ts_recv":"2026-04-07T02:10:28.205659917Z","hd":{"ts_event":"2026-04-07T02:10:28.205639155Z","rtype":160,"publisher_id":101,"instrument_id":436},"action":"A","side":"B","price":"1.156390000","size":30,"channel_id":23,"order_id":"10998899865060421026","flags":0,"ts_in_delta":948,"sequence":150296,"symbol":"FCEU SI 20260615 PS"}
{"ts_recv":"2026-04-07T02:10:28.205659917Z","hd":{"ts_event":"2026-04-07T02:10:28.205639155Z","rtype":160,"publisher_id":101,"instrument_id":436},"action":"C","side":"A","price":"1.156470000","size":30,"channel_id":23,"order_id":"1775527828137511279","flags":0,"ts_in_delta":948,"sequence":150296,"symbol":"FCEU SI 20260615 PS"}
{"ts_recv":"2026-04-07T02:10:28.205659917Z","hd":{"ts_event":"2026-04-07T02:10:28.205639155Z","rtype":160,"publisher_id":101,"instrument_id":436},"action":"A","side":"A","price":"1.156490000","size":30,"channel_id":23,"order_id":"1775527828205645218","flags":128,"ts_in_delta":948,"sequence":150296,"symbol":"FCEU SI 20260615 PS"}
{"ts_recv":"2026-04-07T02:10:36.577308148Z","hd":{"ts_event":"2026-04-07T02:10:36.577279011Z","rtype":160,"publisher_id":101,"instrument_id":436},"action":"C","side":"B","price":"1.156390000","size":30,"channel_id":23,"order_id":"10998899865060421026","flags":0,"ts_in_delta":990,"sequence":150371,"symbol":"FCEU SI 20260615 PS"}
{"ts_recv":"2026-04-07T02:10:36.577308148Z","hd":{"ts_event":"2026-04-07T02:10:36.577279011Z","rtype":160,"publisher_id":101,"instrument_id":436},"action":"A","side":"B","price":"1.156370000","size":30,"channel_id":23,"order_id":"10998899873432067969","flags":0,"ts_in_delta":990,"sequence":150371,"symbol":"FCEU SI 20260615 PS"}
{"ts_recv":"2026-04-07T02:10:36.577308148Z","hd":{"ts_event":"2026-04-07T02:10:36.577279011Z","rtype":160,"publisher_id":101,"instrument_id":436},"action":"C","side":"A","price":"1.156490000","size":30,"channel_id":23,"order_id":"1775527828205645218","flags":0,"ts_in_delta":990,"sequence":150371,"symbol":"FCEU SI 20260615 PS"}
{"ts_recv":"2026-04-07T02:10:36.577308148Z","hd":{"ts_event":"2026-04-07T02:10:36.577279011Z","rtype":160,"publisher_id":101,"instrument_id":436},"action":"A","side":"A","price":"1.156470000","size":30,"channel_id":23,"order_id":"1775527836577292161","flags":128,"ts_in_delta":990,"sequence":150371,"symbol":"FCEU SI 20260615 PS"}
{"ts_recv":"2026-04-07T02:10:36.577417682Z","hd":{"ts_event":"2026-04-07T02:10:36.577400913Z","rtype":160,"publisher_id":101,"instrument_id":436},"action":"A","side":"B","price":"1.156370000","size":30,"channel_id":23,"order_id":"10998899873432183196","flags":0,"ts_in_delta":983,"sequence":150372,"symbol":"FCEU SI 20260615 PS"}
{"ts_recv":"2026-04-07T02:10:36.577417682Z","hd":{"ts_event":"2026-04-07T02:10:36.577400913Z","rtype":160,"publisher_id":101,"instrument_id":436},"action":"A","side":"A","price":"1.156470000","size":30,"channel_id":23,"order_id":"1775527836577407388","flags":128,"ts_in_delta":983,"sequence":150372,"symbol":"FCEU SI 20260615 PS"}
{"ts_recv":"2026-04-07T02:10:36.581998446Z","hd":{"ts_event":"2026-04-07T02:10:36.581980249Z","rtype":160,"publisher_id":101,"instrument_id":436},"action":"C","side":"B","price":"1.156370000","size":30,"channel_id":23,"order_id":"10998899873432183196","flags":0,"ts_in_delta":930,"sequence":150374,"symbol":"FCEU SI 20260615 PS"}
{"ts_recv":"2026-04-07T02:10:36.581998446Z","hd":{"ts_event":"2026-04-07T02:10:36.581980249Z","rtype":160,"publisher_id":101,"instrument_id":436},"action":"A","side":"B","price":"1.156360000","size":30,"channel_id":23,"order_id":"10998899873436762249","flags":0,"ts_in_delta":930,"sequence":150374,"symbol":"FCEU SI 20260615 PS"}
{"ts_recv":"2026-04-07T02:10:36.581998446Z","hd":{"ts_event":"2026-04-07T02:10:36.581980249Z","rtype":160,"publisher_id":101,"instrument_id":436},"action":"C","side":"A","price":"1.156470000","size":30,"channel_id":23,"order_id":"1775527836577407388","flags":0,"ts_in_delta":930,"sequence":150374,"symbol":"FCEU SI 20260615 PS"}
{"ts_recv":"2026-04-07T02:10:36.581998446Z","hd":{"ts_event":"2026-04-07T02:10:36.581980249Z","rtype":160,"publisher_id":101,"instrument_id":436},"action":"A","side":"A","price":"1.156460000","size":30,"channel_id":23,"order_id":"1775527836581986441","flags":128,"ts_in_delta":930,"sequence":150374,"symbol":"FCEU SI 20260615 PS"}
{"ts_recv":"2026-04-07T02:10:36.586491285Z","hd":{"ts_event":"2026-04-07T02:10:36.586474017Z","rtype":160,"publisher_id":101,"instrument_id":436},"action":"C","side":"B","price":"1.156360000","size":30,"channel_id":23,"order_id":"10998899873436762249","flags":0,"ts_in_delta":932,"sequence":150379,"symbol":"FCEU SI 20260615 PS"}
{"ts_recv":"2026-04-07T02:10:36.586491285Z","hd":{"ts_event":"2026-04-07T02:10:36.586474017Z","rtype":160,"publisher_id":101,"instrument_id":436},"action":"A","side":"B","price":"1.156350000","size":30,"channel_id":23,"order_id":"10998899873441255662","flags":0,"ts_in_delta":932,"sequence":150379,"symbol":"FCEU SI 20260615 PS"}
{"ts_recv":"2026-04-07T02:10:36.586491285Z","hd":{"ts_event":"2026-04-07T02:10:36.586474017Z","rtype":160,"publisher_id":101,"instrument_id":436},"action":"C","side":"A","price":"1.156460000","size":30,"channel_id":23,"order_id":"1775527836581986441","flags":0,"ts_in_delta":932,"sequence":150379,"symbol":"FCEU SI 20260615 PS"}
{"ts_recv":"2026-04-07T02:10:36.586491285Z","hd":{"ts_event":"2026-04-07T02:10:36.586474017Z","rtype":160,"publisher_id":101,"instrument_id":436},"action":"A","side":"A","price":"1.156450000","size":30,"channel_id":23,"order_id":"1775527836586479854","flags":128,"ts_in_delta":932,"sequence":150379,"symbol":"FCEU SI 20260615 PS"}
{"ts_recv":"2026-04-07T02:10:36.591253665Z","hd":{"ts_event":"2026-04-07T02:10:36.591234889Z","rtype":160,"publisher_id":101,"instrument_id":436},"action":"C","side":"B","price":"1.156350000","size":30,"channel_id":23,"order_id":"10998899873441255662","flags":0,"ts_in_delta":920,"sequence":150382,"symbol":"FCEU SI 20260615 PS"}
{"ts_recv":"2026-04-07T02:10:36.591253665Z","hd":{"ts_event":"2026-04-07T02:10:36.591234889Z","rtype":160,"publisher_id":101,"instrument_id":436},"action":"A","side":"B","price":"1.156360000","size":30,"channel_id":23,"order_id":"10998899873446016734","flags":0,"ts_in_delta":920,"sequence":150382,"symbol":"FCEU SI 20260615 PS"}
{"ts_recv":"2026-04-07T02:10:36.591253665Z","hd":{"ts_event":"2026-04-07T02:10:36.591234889Z","rtype":160,"publisher_id":101,"instrument_id":436},"action":"C","side":"A","price":"1.156450000","size":30,"channel_id":23,"order_id":"1775527836586479854","flags":0,"ts_in_delta":920,"sequence":150382,"symbol":"FCEU SI 20260615 PS"}
{"ts_recv":"2026-04-07T02:10:36.591253665Z","hd":{"ts_event":"2026-04-07T02:10:36.591234889Z","rtype":160,"publisher_id":101,"instrument_id":436},"action":"A","side":"A","price":"1.156460000","size":30,"channel_id":23,"order_id":"1775527836591240926","flags":128,"ts_in_delta":920,"sequence":150382,"symbol":"FCEU SI 20260615 PS"}
{"ts_recv":"2026-04-07T02:10:38.618488235Z","hd":{"ts_event":"2026-04-07T02:10:38.618468905Z","rtype":160,"publisher_id":101,"instrument_id":436},"action":"C","side":"B","price":"1.156360000","size":30,"channel_id":23,"order_id":"10998899873446016734","flags":0,"ts_in_delta":1174,"sequence":150421,"symbol":"FCEU SI 20260615 PS"}
{"ts_recv":"2026-04-07T02:10:38.618488235Z","hd":{"ts_event":"2026-04-07T02:10:38.618468905Z","rtype":160,"publisher_id":101,"instrument_id":436},"action":"A","side":"B","price":"1.156370000","size":30,"channel_id":23,"order_id":"10998899875473250711","flags":0,"ts_in_delta":1174,"sequence":150421,"symbol":"FCEU SI 20260615 PS"}
{"ts_recv":"2026-04-07T02:10:38.618488235Z","hd":{"ts_event":"2026-04-07T02:10:38.618468905Z","rtype":160,"publisher_id":101,"instrument_id":436},"action":"C","side":"A","price":"1.156460000","size":30,"channel_id":23,"order_id":"1775527836591240926","flags":0,"ts_in_delta":1174,"sequence":150421,"symbol":"FCEU SI 20260615 PS"}
{"ts_recv":"2026-04-07T02:10:38.618488235Z","hd":{"ts_event":"2026-04-07T02:10:38.618468905Z","rtype":160,"publisher_id":101,"instrument_id":436},"action":"A","side":"A","price":"1.156470000","size":30,"channel_id":23,"order_id":"1775527838618474903","flags":128,"ts_in_delta":1174,"sequence":150421,"symbol":"FCEU SI 20260615 PS"}
{"ts_recv":"2026-04-07T02:10:51.613473163Z","hd":{"ts_event":"2026-04-07T02:10:51.613442449Z","rtype":160,"publisher_id":101,"instrument_id":436},"action":"C","side":"B","price":"1.156370000","size":30,"channel_id":23,"order_id":"10998899875473250711","flags":0,"ts_in_delta":1420,"sequence":150670,"symbol":"FCEU SI 20260615 PS"}
{"ts_recv":"2026-04-07T02:10:51.613473163Z","hd":{"ts_event":"2026-04-07T02:10:51.613442449Z","rtype":160,"publisher_id":101,"instrument_id":436},"action":"A","side":"B","price":"1.156380000","size":30,"channel_id":23,"order_id":"10998899888468231101","flags":0,"ts_in_delta":1420,"sequence":150670,"symbol":"FCEU SI 20260615 PS"}
{"ts_recv":"2026-04-07T02:10:51.613473163Z","hd":{"ts_event":"2026-04-07T02:10:51.613442449Z","rtype":160,"publisher_id":101,"instrument_id":436},"action":"C","side":"A","price":"1.156470000","size":30,"channel_id":23,"order_id":"1775527838618474903","flags":0,"ts_in_delta":1420,"sequence":150670,"symbol":"FCEU SI 20260615 PS"}
{"ts_recv":"2026-04-07T02:10:51.613473163Z","hd":{"ts_event":"2026-04-07T02:10:51.613442449Z","rtype":160,"publisher_id":101,"instrument_id":436},"action":"A","side":"A","price":"1.156480000","size":30,"channel_id":23,"order_id":"1775527851613455293","flags":128,"ts_in_delta":1420,"sequence":150670,"symbol":"FCEU SI 20260615 PS"}
{"ts_recv":"2026-04-07T02:10:51.613534922Z","hd":{"ts_event":"2026-04-07T02:10:51.613515805Z","rtype":160,"publisher_id":101,"instrument_id":436},"action":"C","side":"B","price":"1.156370000","size":30,"channel_id":23,"order_id":"10998899873432067969","flags":0,"ts_in_delta":1012,"sequence":150671,"symbol":"FCEU SI 20260615 PS"}
{"ts_recv":"2026-04-07T02:10:51.613534922Z","hd":{"ts_event":"2026-04-07T02:10:51.613515805Z","rtype":160,"publisher_id":101,"instrument_id":436},"action":"A","side":"B","price":"1.156390000","size":30,"channel_id":23,"order_id":"10998899888468297861","flags":0,"ts_in_delta":1012,"sequence":150671,"symbol":"FCEU SI 20260615 PS"}
{"ts_recv":"2026-04-07T02:10:51.613534922Z","hd":{"ts_event":"2026-04-07T02:10:51.613515805Z","rtype":160,"publisher_id":101,"instrument_id":436},"action":"C","side":"A","price":"1.156470000","size":30,"channel_id":23,"order_id":"1775527836577292161","flags":0,"ts_in_delta":1012,"sequence":150671,"symbol":"FCEU SI 20260615 PS"}
{"ts_recv":"2026-04-07T02:10:51.613534922Z","hd":{"ts_event":"2026-04-07T02:10:51.613515805Z","rtype":160,"publisher_id":101,"instrument_id":436},"action":"A","side":"A","price":"1.156490000","size":30,"channel_id":23,"order_id":"1775527851613522053","flags":128,"ts_in_delta":1012,"sequence":150671,"symbol":"FCEU SI 20260615 PS"}
{"ts_recv":"2026-04-07T02:10:51.613596920Z","hd":{"ts_event":"2026-04-07T02:10:51.613577239Z","rtype":160,"publisher_id":101,"instrument_id":436},"action":"C","side":"B","price":"1.156380000","size":30,"channel_id":23,"order_id":"10998899888468231101","flags":0,"ts_in_delta":1042,"sequence":150672,"symbol":"FCEU SI 20260615 PS"}
{"ts_recv":"2026-04-07T02:10:51.613596920Z","hd":{"ts_event":"2026-04-07T02:10:51.613577239Z","rtype":160,"publisher_id":101,"instrument_id":436},"action":"A","side":"B","price":"1.156390000","size":30,"channel_id":23,"order_id":"10998899888468359051","flags":0,"ts_in_delta":1042,"sequence":150672,"symbol":"FCEU SI 20260615 PS"}
{"ts_recv":"2026-04-07T02:10:51.613596920Z","hd":{"ts_event":"2026-04-07T02:10:51.613577239Z","rtype":160,"publisher_id":101,"instrument_id":436},"action":"C","side":"A","price":"1.156480000","size":30,"channel_id":23,"order_id":"1775527851613455293","flags":0,"ts_in_delta":1042,"sequence":150672,"symbol":"FCEU SI 20260615 PS"}
{"ts_recv":"2026-04-07T02:10:51.613596920Z","hd":{"ts_event":"2026-04-07T02:10:51.613577239Z","rtype":160,"publisher_id":101,"instrument_id":436},"action":"A","side":"A","price":"1.156490000","size":30,"channel_id":23,"order_id":"1775527851613583243","flags":128,"ts_in_delta":1042,"sequence":150672,"symbol":"FCEU SI 20260615 PS"}
{"ts_recv":"2026-04-07T02:10:56.082804538Z","hd":{"ts_event":"2026-04-07T02:10:56.082782709Z","rtype":160,"publisher_id":101,"instrument_id":436},"action":"C","side":"B","price":"1.156390000","size":30,"channel_id":23,"order_id":"10998899888468297861","flags":0,"ts_in_delta":996,"sequence":150707,"symbol":"FCEU SI 20260615 PS"}
{"ts_recv":"2026-04-07T02:10:56.082804538Z","hd":{"ts_event":"2026-04-07T02:10:56.082782709Z","rtype":160,"publisher_id":101,"instrument_id":436},"action":"A","side":"B","price":"1.156410000","size":30,"channel_id":23,"order_id":"10998899892937564788","flags":0,"ts_in_delta":996,"sequence":150707,"symbol":"FCEU SI 20260615 PS"}
{"ts_recv":"2026-04-07T02:10:56.082804538Z","hd":{"ts_event":"2026-04-07T02:10:56.082782709Z","rtype":160,"publisher_id":101,"instrument_id":436},"action":"C","side":"A","price":"1.156490000","size":30,"channel_id":23,"order_id":"1775527851613522053","flags":0,"ts_in_delta":996,"sequence":150707,"symbol":"FCEU SI 20260615 PS"}
{"ts_recv":"2026-04-07T02:10:56.082804538Z","hd":{"ts_event":"2026-04-07T02:10:56.082782709Z","rtype":160,"publisher_id":101,"instrument_id":436},"action":"A","side":"A","price":"1.156510000","size":30,"channel_id":23,"order_id":"1775527856082788980","flags":128,"ts_in_delta":996,"sequence":150707,"symbol":"FCEU SI 20260615 PS"}
{"ts_recv":"2026-04-07T02:10:56.082920778Z","hd":{"ts_event":"2026-04-07T02:10:56.082903633Z","rtype":160,"publisher_id":101,"instrument_id":436},"action":"C","side":"B","price":"1.156390000","size":30,"channel_id":23,"order_id":"10998899888468359051","flags":0,"ts_in_delta":1030,"sequence":150708,"symbol":"FCEU SI 20260615 PS"}
{"ts_recv":"2026-04-07T02:10:56.082920778Z","hd":{"ts_event":"2026-04-07T02:10:56.082903633Z","rtype":160,"publisher_id":101,"instrument_id":436},"action":"A","side":"B","price":"1.156400000","size":30,"channel_id":23,"order_id":"10998899892937685662","flags":0,"ts_in_delta":1030,"sequence":150708,"symbol":"FCEU SI 20260615 PS"}
{"ts_recv":"2026-04-07T02:10:56.082920778Z","hd":{"ts_event":"2026-04-07T02:10:56.082903633Z","rtype":160,"publisher_id":101,"instrument_id":436},"action":"C","side":"A","price":"1.156490000","size":30,"channel_id":23,"order_id":"1775527851613583243","flags":0,"ts_in_delta":1030,"sequence":150708,"symbol":"FCEU SI 20260615 PS"}
{"ts_recv":"2026-04-07T02:10:56.082920778Z","hd":{"ts_event":"2026-04-07T02:10:56.082903633Z","rtype":160,"publisher_id":101,"instrument_id":436},"action":"A","side":"A","price":"1.156500000","size":30,"channel_id":23,"order_id":"1775527856082909854","flags":128,"ts_in_delta":1030,"sequence":150708,"symbol":"FCEU SI 20260615 PS"}
{"ts_recv":"2026-04-07T02:10:56.087762895Z","hd":{"ts_event":"2026-04-07T02:10:56.087744275Z","rtype":160,"publisher_id":101,"instrument_id":436},"action":"C","side":"B","price":"1.156400000","size":30,"channel_id":23,"order_id":"10998899892937685662","flags":0,"ts_in_delta":982,"sequence":150714,"symbol":"FCEU SI 20260615 PS"}
{"ts_recv":"2026-04-07T02:10:56.087762895Z","hd":{"ts_event":"2026-04-07T02:10:56.087744275Z","rtype":160,"publisher_id":101,"instrument_id":436},"action":"A","side":"B","price":"1.156410000","size":30,"channel_id":23,"order_id":"10998899892942526183","flags":0,"ts_in_delta":982,"sequence":150714,"symbol":"FCEU SI 20260615 PS"}
{"ts_recv":"2026-04-07T02:10:56.087762895Z","hd":{"ts_event":"2026-04-07T02:10:56.087744275Z","rtype":160,"publisher_id":101,"instrument_id":436},"action":"C","side":"A","price":"1.156500000","size":30,"channel_id":23,"order_id":"1775527856082909854","flags":0,"ts_in_delta":982,"sequence":150714,"symbol":"FCEU SI 20260615 PS"}
{"ts_recv":"2026-04-07T02:10:56.087762895Z","hd":{"ts_event":"2026-04-07T02:10:56.087744275Z","rtype":160,"publisher_id":101,"instrument_id":436},"action":"A","side":"A","price":"1.156510000","size":30,"channel_id":23,"order_id":"1775527856087750375","flags":128,"ts_in_delta":982,"sequence":150714,"symbol":"FCEU SI 20260615 PS"}
{"ts_recv":"2026-04-07T02:10:56.095366799Z","hd":{"ts_event":"2026-04-07T02:10:56.095347327Z","rtype":160,"publisher_id":101,"instrument_id":436},"action":"C","side":"B","price":"1.156410000","size":30,"channel_id":23,"order_id":"10998899892942526183","flags":0,"ts_in_delta":1227,"sequence":150718,"symbol":"FCEU SI 20260615 PS"}
{"ts_recv":"2026-04-07T02:10:56.095366799Z","hd":{"ts_event":"2026-04-07T02:10:56.095347327Z","rtype":160,"publisher_id":101,"instrument_id":436},"action":"A","side":"B","price":"1.156420000","size":30,"channel_id":23,"order_id":"10998899892950128884","flags":0,"ts_in_delta":1227,"sequence":150718,"symbol":"FCEU SI 20260615 PS"}
{"ts_recv":"2026-04-07T02:10:56.095366799Z","hd":{"ts_event":"2026-04-07T02:10:56.095347327Z","rtype":160,"publisher_id":101,"instrument_id":436},"action":"C","side":"A","price":"1.156510000","size":30,"channel_id":23,"order_id":"1775527856087750375","flags":0,"ts_in_delta":1227,"sequence":150718,"symbol":"FCEU SI 20260615 PS"}
{"ts_recv":"2026-04-07T02:10:56.095366799Z","hd":{"ts_event":"2026-04-07T02:10:56.095347327Z","rtype":160,"publisher_id":101,"instrument_id":436},"action":"A","side":"A","price":"1.156520000","size":30,"channel_id":23,"order_id":"1775527856095353076","flags":128,"ts_in_delta":1227,"sequence":150718,"symbol":"FCEU SI 20260615 PS"}
{"ts_recv":"2026-04-07T02:10:56.095417661Z","hd":{"ts_event":"2026-04-07T02:10:56.095398957Z","rtype":160,"publisher_id":101,"instrument_id":436},"action":"C","side":"B","price":"1.156410000","size":30,"channel_id":23,"order_id":"10998899892937564788","flags":0,"ts_in_delta":1078,"sequence":150719,"symbol":"FCEU SI 20260615 PS"}
{"ts_recv":"2026-04-07T02:10:56.095417661Z","hd":{"ts_event":"2026-04-07T02:10:56.095398957Z","rtype":160,"publisher_id":101,"instrument_id":436},"action":"A","side":"B","price":"1.156430000","size":30,"channel_id":23,"order_id":"10998899892950181099","flags":0,"ts_in_delta":1078,"sequence":150719,"symbol":"FCEU SI 20260615 PS"}
{"ts_recv":"2026-04-07T02:10:56.095417661Z","hd":{"ts_event":"2026-04-07T02:10:56.095398957Z","rtype":160,"publisher_id":101,"instrument_id":436},"action":"C","side":"A","price":"1.156510000","size":30,"channel_id":23,"order_id":"1775527856082788980","flags":0,"ts_in_delta":1078,"sequence":150719,"symbol":"FCEU SI 20260615 PS"}
{"ts_recv":"2026-04-07T02:10:56.095417661Z","hd":{"ts_event":"2026-04-07T02:10:56.095398957Z","rtype":160,"publisher_id":101,"instrument_id":436},"action":"A","side":"A","price":"1.156530000","size":30,"channel_id":23,"order_id":"1775527856095405291","flags":128,"ts_in_delta":1078,"sequence":150719,"symbol":"FCEU SI 20260615 PS"}
{"ts_recv":"2026-04-07T02:10:56.095472993Z","hd":{"ts_event":"2026-04-07T02:10:56.095453139Z","rtype":160,"publisher_id":101,"instrument_id":436},"action":"C","side":"B","price":"1.156420000","size":30,"channel_id":23,"order_id":"10998899892950128884","flags":0,"ts_in_delta":1117,"sequence":150720,"symbol":"FCEU SI 20260615 PS"}
{"ts_recv":"2026-04-07T02:10:56.095472993Z","hd":{"ts_event":"2026-04-07T02:10:56.095453139Z","rtype":160,"publisher_id":101,"instrument_id":436},"action":"A","side":"B","price":"1.156430000","size":30,"channel_id":23,"order_id":"10998899892950234911","flags":0,"ts_in_delta":1117,"sequence":150720,"symbol":"FCEU SI 20260615 PS"}
{"ts_recv":"2026-04-07T02:10:56.095472993Z","hd":{"ts_event":"2026-04-07T02:10:56.095453139Z","rtype":160,"publisher_id":101,"instrument_id":436},"action":"C","side":"A","price":"1.156520000","size":30,"channel_id":23,"order_id":"1775527856095353076","flags":0,"ts_in_delta":1117,"sequence":150720,"symbol":"FCEU SI 20260615 PS"}
{"ts_recv":"2026-04-07T02:10:56.095472993Z","hd":{"ts_event":"2026-04-07T02:10:56.095453139Z","rtype":160,"publisher_id":101,"instrument_id":436},"action":"A","side":"A","price":"1.156530000","size":30,"channel_id":23,"order_id":"1775527856095459103","flags":128,"ts_in_delta":1117,"sequence":150720,"symbol":"FCEU SI 20260615 PS"}
{"ts_recv":"2026-04-07T02:10:58.469565155Z","hd":{"ts_event":"2026-04-07T02:10:58.469544309Z","rtype":160,"publisher_id":101,"instrument_id":436},"action":"C","side":"B","price":"1.156430000","size":30,"channel_id":23,"order_id":"10998899892950234911","flags":0,"ts_in_delta":873,"sequence":150778,"symbol":"FCEU SI 20260615 PS"}
{"ts_recv":"2026-04-07T02:10:58.469565155Z","hd":{"ts_event":"2026-04-07T02:10:58.469544309Z","rtype":160,"publisher_id":101,"instrument_id":436},"action":"A","side":"B","price":"1.156420000","size":30,"channel_id":23,"order_id":"10998899895324326533","flags":0,"ts_in_delta":873,"sequence":150778,"symbol":"FCEU SI 20260615 PS"}
{"ts_recv":"2026-04-07T02:10:58.469565155Z","hd":{"ts_event":"2026-04-07T02:10:58.469544309Z","rtype":160,"publisher_id":101,"instrument_id":436},"action":"C","side":"A","price":"1.156530000","size":30,"channel_id":23,"order_id":"1775527856095459103","flags":0,"ts_in_delta":873,"sequence":150778,"symbol":"FCEU SI 20260615 PS"}
{"ts_recv":"2026-04-07T02:10:58.469565155Z","hd":{"ts_event":"2026-04-07T02:10:58.469544309Z","rtype":160,"publisher_id":101,"instrument_id":436},"action":"A","side":"A","price":"1.156520000","size":30,"channel_id":23,"order_id":"1775527858469550725","flags":128,"ts_in_delta":873,"sequence":150778,"symbol":"FCEU SI 20260615 PS"}
{"ts_recv":"2026-04-07T02:10:58.469650914Z","hd":{"ts_event":"2026-04-07T02:10:58.469631171Z","rtype":160,"publisher_id":101,"instrument_id":436},"action":"C","side":"B","price":"1.156420000","size":30,"channel_id":23,"order_id":"10998899895324326533","flags":0,"ts_in_delta":937,"sequence":150779,"symbol":"FCEU SI 20260615 PS"}
{"ts_recv":"2026-04-07T02:10:58.469650914Z","hd":{"ts_event":"2026-04-07T02:10:58.469631171Z","rtype":160,"publisher_id":101,"instrument_id":436},"action":"A","side":"B","price":"1.156400000","size":30,"channel_id":23,"order_id":"10998899895324412739","flags":0,"ts_in_delta":937,"sequence":150779,"symbol":"FCEU SI 20260615 PS"}
{"ts_recv":"2026-04-07T02:10:58.469650914Z","hd":{"ts_event":"2026-04-07T02:10:58.469631171Z","rtype":160,"publisher_id":101,"instrument_id":436},"action":"C","side":"A","price":"1.156520000","size":30,"channel_id":23,"order_id":"1775527858469550725","flags":0,"ts_in_delta":937,"sequence":150779,"symbol":"FCEU SI 20260615 PS"}
{"ts_recv":"2026-04-07T02:10:58.469650914Z","hd":{"ts_event":"2026-04-07T02:10:58.469631171Z","rtype":160,"publisher_id":101,"instrument_id":436},"action":"A","side":"A","price":"1.156500000","size":30,"channel_id":23,"order_id":"1775527858469636931","flags":128,"ts_in_delta":937,"sequence":150779,"symbol":"FCEU SI 20260615 PS"}
{"ts_recv":"2026-04-07T02:10:58.469702582Z","hd":{"ts_event":"2026-04-07T02:10:58.469684259Z","rtype":160,"publisher_id":101,"instrument_id":436},"action":"C","side":"B","price":"1.156430000","size":30,"channel_id":23,"order_id":"10998899892950181099","flags":0,"ts_in_delta":900,"sequence":150780,"symbol":"FCEU SI 20260615 PS"}
{"ts_recv":"2026-04-07T02:10:58.469702582Z","hd":{"ts_event":"2026-04-07T02:10:58.469684259Z","rtype":160,"publisher_id":101,"instrument_id":436},"action":"A","side":"B","price":"1.156410000","size":30,"channel_id":23,"order_id":"10998899895324466172","flags":0,"ts_in_delta":900,"sequence":150780,"symbol":"FCEU SI 20260615 PS"}
{"ts_recv":"2026-04-07T02:10:58.469702582Z","hd":{"ts_event":"2026-04-07T02:10:58.469684259Z","rtype":160,"publisher_id":101,"instrument_id":436},"action":"C","side":"A","price":"1.156530000","size":30,"channel_id":23,"order_id":"1775527856095405291","flags":0,"ts_in_delta":900,"sequence":150780,"symbol":"FCEU SI 20260615 PS"}
{"ts_recv":"2026-04-07T02:10:58.469702582Z","hd":{"ts_event":"2026-04-07T02:10:58.469684259Z","rtype":160,"publisher_id":101,"instrument_id":436},"action":"A","side":"A","price":"1.156510000","size":30,"channel_id":23,"order_id":"1775527858469690364","flags":128,"ts_in_delta":900,"sequence":150780,"symbol":"FCEU SI 20260615 PS"}
{"ts_recv":"2026-04-07T02:10:58.469712128Z","hd":{"ts_event":"2026-04-07T02:10:58.469690959Z","rtype":160,"publisher_id":101,"instrument_id":436},"action":"C","side":"B","price":"1.156400000","size":30,"channel_id":23,"order_id":"10998899895324412739","flags":0,"ts_in_delta":886,"sequence":150781,"symbol":"FCEU SI 20260615 PS"}
{"ts_recv":"2026-04-07T02:10:58.469712128Z","hd":{"ts_event":"2026-04-07T02:10:58.469690959Z","rtype":160,"publisher_id":101,"instrument_id":436},"action":"A","side":"B","price":"1.156420000","size":30,"channel_id":23,"order_id":"10998899895324475081","flags":0,"ts_in_delta":886,"sequence":150781,"symbol":"FCEU SI 20260615 PS"}
{"ts_recv":"2026-04-07T02:10:58.469712128Z","hd":{"ts_event":"2026-04-07T02:10:58.469690959Z","rtype":160,"publisher_id":101,"instrument_id":436},"action":"C","side":"A","price":"1.156500000","size":30,"channel_id":23,"order_id":"1775527858469636931","flags":0,"ts_in_delta":886,"sequence":150781,"symbol":"FCEU SI 20260615 PS"}
{"ts_recv":"2026-04-07T02:10:58.469712128Z","hd":{"ts_event":"2026-04-07T02:10:58.469690959Z","rtype":160,"publisher_id":101,"instrument_id":436},"action":"A","side":"A","price":"1.156520000","size":30,"channel_id":23,"order_id":"1775527858469699273","flags":128,"ts_in_delta":886,"sequence":150781,"symbol":"FCEU SI 20260615 PS"}
{"ts_recv":"2026-04-07T02:10:58.469767077Z","hd":{"ts_event":"2026-04-07T02:10:58.469749923Z","rtype":160,"publisher_id":101,"instrument_id":436},"action":"C","side":"B","price":"1.156420000","size":30,"channel_id":23,"order_id":"10998899895324475081","flags":0,"ts_in_delta":922,"sequence":150782,"symbol":"FCEU SI 20260615 PS"}
{"ts_recv":"2026-04-07T02:10:58.469767077Z","hd":{"ts_event":"2026-04-07T02:10:58.469749923Z","rtype":160,"publisher_id":101,"instrument_id":436},"action":"A","side":"B","price":"1.156410000","size":30,"channel_id":23,"order_id":"10998899895324531529","flags":0,"ts_in_delta":922,"sequence":150782,"symbol":"FCEU SI 20260615 PS"}
{"ts_recv":"2026-04-07T02:10:58.469767077Z","hd":{"ts_event":"2026-04-07T02:10:58.469749923Z","rtype":160,"publisher_id":101,"instrument_id":436},"action":"C","side":"A","price":"1.156520000","size":30,"channel_id":23,"order_id":"1775527858469699273","flags":0,"ts_in_delta":922,"sequence":150782,"symbol":"FCEU SI 20260615 PS"}
{"ts_recv":"2026-04-07T02:10:58.469767077Z","hd":{"ts_event":"2026-04-07T02:10:58.469749923Z","rtype":160,"publisher_id":101,"instrument_id":436},"action":"A","side":"A","price":"1.156510000","size":30,"channel_id":23,"order_id":"1775527858469755721","flags":128,"ts_in_delta":922,"sequence":150782,"symbol":"FCEU SI 20260615 PS"}
{"ts_recv":"2026-04-07T02:10:58.480340462Z","hd":{"ts_event":"2026-04-07T02:10:58.480322553Z","rtype":160,"publisher_id":101,"instrument_id":436},"action":"C","side":"B","price":"1.156410000","size":30,"channel_id":23,"order_id":"10998899895324531529","flags":0,"ts_in_delta":714,"sequence":150787,"symbol":"FCEU SI 20260615 PS"}
{"ts_recv":"2026-04-07T02:10:58.480340462Z","hd":{"ts_event":"2026-04-07T02:10:58.480322553Z","rtype":160,"publisher_id":101,"instrument_id":436},"action":"A","side":"B","price":"1.156400000","size":30,"channel_id":23,"order_id":"10998899895335103951","flags":0,"ts_in_delta":714,"sequence":150787,"symbol":"FCEU SI 20260615 PS"}
{"ts_recv":"2026-04-07T02:10:58.480340462Z","hd":{"ts_event":"2026-04-07T02:10:58.480322553Z","rtype":160,"publisher_id":101,"instrument_id":436},"action":"C","side":"A","price":"1.156510000","size":30,"channel_id":23,"order_id":"1775527858469755721","flags":0,"ts_in_delta":714,"sequence":150787,"symbol":"FCEU SI 20260615 PS"}
{"ts_recv":"2026-04-07T02:10:58.480340462Z","hd":{"ts_event":"2026-04-07T02:10:58.480322553Z","rtype":160,"publisher_id":101,"instrument_id":436},"action":"A","side":"A","price":"1.156500000","size":30,"channel_id":23,"order_id":"1775527858480328143","flags":128,"ts_in_delta":714,"sequence":150787,"symbol":"FCEU SI 20260615 PS"}
{"ts_recv":"2026-04-07T02:10:58.480399265Z","hd":{"ts_event":"2026-04-07T02:10:58.480379853Z","rtype":160,"publisher_id":101,"instrument_id":436},"action":"C","side":"B","price":"1.156400000","size":30,"channel_id":23,"order_id":"10998899895335103951","flags":0,"ts_in_delta":754,"sequence":150788,"symbol":"FCEU SI 20260615 PS"}
{"ts_recv":"2026-04-07T02:10:58.480399265Z","hd":{"ts_event":"2026-04-07T02:10:58.480379853Z","rtype":160,"publisher_id":101,"instrument_id":436},"action":"A","side":"B","price":"1.156390000","size":30,"channel_id":23,"order_id":"10998899895335161538","flags":0,"ts_in_delta":754,"sequence":150788,"symbol":"FCEU SI 20260615 PS"}
{"ts_recv":"2026-04-07T02:10:58.480399265Z","hd":{"ts_event":"2026-04-07T02:10:58.480379853Z","rtype":160,"publisher_id":101,"instrument_id":436},"action":"C","side":"A","price":"1.156500000","size":30,"channel_id":23,"order_id":"1775527858480328143","flags":0,"ts_in_delta":754,"sequence":150788,"symbol":"FCEU SI 20260615 PS"}
{"ts_recv":"2026-04-07T02:10:58.480399265Z","hd":{"ts_event":"2026-04-07T02:10:58.480379853Z","rtype":160,"publisher_id":101,"instrument_id":436},"action":"A","side":"A","price":"1.156490000","size":30,"channel_id":23,"order_id":"1775527858480385730","flags":128,"ts_in_delta":754,"sequence":150788,"symbol":"FCEU SI 20260615 PS"}
{"ts_recv":"2026-04-07T02:10:58.480449997Z","hd":{"ts_event":"2026-04-07T02:10:58.480435257Z","rtype":160,"publisher_id":101,"instrument_id":436},"action":"C","side":"B","price":"1.156390000","size":30,"channel_id":23,"order_id":"10998899895335161538","flags":0,"ts_in_delta":717,"sequence":150789,"symbol":"FCEU SI 20260615 PS"}
{"ts_recv":"2026-04-07T02:10:58.480449997Z","hd":{"ts_event":"2026-04-07T02:10:58.480435257Z","rtype":160,"publisher_id":101,"instrument_id":436},"action":"A","side":"B","price":"1.156400000","size":30,"channel_id":23,"order_id":"10998899895335216646","flags":0,"ts_in_delta":717,"sequence":150789,"symbol":"FCEU SI 20260615 PS"}
{"ts_recv":"2026-04-07T02:10:58.480449997Z","hd":{"ts_event":"2026-04-07T02:10:58.480435257Z","rtype":160,"publisher_id":101,"instrument_id":436},"action":"C","side":"A","price":"1.156490000","size":30,"channel_id":23,"order_id":"1775527858480385730","flags":0,"ts_in_delta":717,"sequence":150789,"symbol":"FCEU SI 20260615 PS"}
{"ts_recv":"2026-04-07T02:10:58.480449997Z","hd":{"ts_event":"2026-04-07T02:10:58.480435257Z","rtype":160,"publisher_id":101,"instrument_id":436},"action":"A","side":"A","price":"1.156500000","size":30,"channel_id":23,"order_id":"1775527858480440838","flags":128,"ts_in_delta":717,"sequence":150789,"symbol":"FCEU SI 20260615 PS"}
{"ts_recv":"2026-04-07T02:11:06.276518218Z","hd":{"ts_event":"2026-04-07T02:11:06.276496701Z","rtype":160,"publisher_id":101,"instrument_id":436},"action":"C","side":"B","price":"1.156410000","size":30,"channel_id":23,"order_id":"10998899895324466172","flags":0,"ts_in_delta":995,"sequence":150852,"symbol":"FCEU SI 20260615 PS"}
{"ts_recv":"2026-04-07T02:11:06.276518218Z","hd":{"ts_event":"2026-04-07T02:11:06.276496701Z","rtype":160,"publisher_id":101,"instrument_id":436},"action":"A","side":"B","price":"1.156390000","size":30,"channel_id":23,"order_id":"10998899903131278824","flags":0,"ts_in_delta":995,"sequence":150852,"symbol":"FCEU SI 20260615 PS"}
{"ts_recv":"2026-04-07T02:11:06.276518218Z","hd":{"ts_event":"2026-04-07T02:11:06.276496701Z","rtype":160,"publisher_id":101,"instrument_id":436},"action":"C","side":"A","price":"1.156510000","size":30,"channel_id":23,"order_id":"1775527858469690364","flags":0,"ts_in_delta":995,"sequence":150852,"symbol":"FCEU SI 20260615 PS"}
{"ts_recv":"2026-04-07T02:11:06.276518218Z","hd":{"ts_event":"2026-04-07T02:11:06.276496701Z","rtype":160,"publisher_id":101,"instrument_id":436},"action":"A","side":"A","price":"1.156490000","size":30,"channel_id":23,"order_id":"1775527866276503016","flags":128,"ts_in_delta":995,"sequence":150852,"symbol":"FCEU SI 20260615 PS"}
{"ts_recv":"2026-04-07T02:11:06.276605597Z","hd":{"ts_event":"2026-04-07T02:11:06.276586843Z","rtype":160,"publisher_id":101,"instrument_id":436},"action":"C","side":"B","price":"1.156400000","size":30,"channel_id":23,"order_id":"10998899895335216646","flags":0,"ts_in_delta":954,"sequence":150853,"symbol":"FCEU SI 20260615 PS"}
{"ts_recv":"2026-04-07T02:11:06.276605597Z","hd":{"ts_event":"2026-04-07T02:11:06.276586843Z","rtype":160,"publisher_id":101,"instrument_id":436},"action":"A","side":"B","price":"1.156390000","size":30,"channel_id":23,"order_id":"10998899903131368781","flags":0,"ts_in_delta":954,"sequence":150853,"symbol":"FCEU SI 20260615 PS"}
{"ts_recv":"2026-04-07T02:11:06.276605597Z","hd":{"ts_event":"2026-04-07T02:11:06.276586843Z","rtype":160,"publisher_id":101,"instrument_id":436},"action":"C","side":"A","price":"1.156500000","size":30,"channel_id":23,"order_id":"1775527858480440838","flags":0,"ts_in_delta":954,"sequence":150853,"symbol":"FCEU SI 20260615 PS"}
{"ts_recv":"2026-04-07T02:11:06.276605597Z","hd":{"ts_event":"2026-04-07T02:11:06.276586843Z","rtype":160,"publisher_id":101,"instrument_id":436},"action":"A","side":"A","price":"1.156490000","size":30,"channel_id":23,"order_id":"1775527866276592973","flags":128,"ts_in_delta":954,"sequence":150853,"symbol":"FCEU SI 20260615 PS"}
{"ts_recv":"2026-04-07T02:11:07.432114311Z","hd":{"ts_event":"2026-04-07T02:11:07.432094747Z","rtype":160,"publisher_id":101,"instrument_id":436},"action":"C","side":"B","price":"1.156390000","size":30,"channel_id":23,"order_id":"10998899903131368781","flags":0,"ts_in_delta":959,"sequence":150876,"symbol":"FCEU SI 20260615 PS"}
{"ts_recv":"2026-04-07T02:11:07.432114311Z","hd":{"ts_event":"2026-04-07T02:11:07.432094747Z","rtype":160,"publisher_id":101,"instrument_id":436},"action":"A","side":"B","price":"1.156400000","size":30,"channel_id":23,"order_id":"10998899904286877048","flags":0,"ts_in_delta":959,"sequence":150876,"symbol":"FCEU SI 20260615 PS"}
{"ts_recv":"2026-04-07T02:11:07.432114311Z","hd":{"ts_event":"2026-04-07T02:11:07.432094747Z","rtype":160,"publisher_id":101,"instrument_id":436},"action":"C","side":"A","price":"1.156490000","size":30,"channel_id":23,"order_id":"1775527866276592973","flags":0,"ts_in_delta":959,"sequence":150876,"symbol":"FCEU SI 20260615 PS"}
{"ts_recv":"2026-04-07T02:11:07.432114311Z","hd":{"ts_event":"2026-04-07T02:11:07.432094747Z","rtype":160,"publisher_id":101,"instrument_id":436},"action":"A","side":"A","price":"1.156500000","size":30,"channel_id":23,"order_id":"1775527867432101240","flags":128,"ts_in_delta":959,"sequence":150876,"symbol":"FCEU SI 20260615 PS"}
{"ts_recv":"2026-04-07T02:11:07.432166056Z","hd":{"ts_event":"2026-04-07T02:11:07.432145665Z","rtype":160,"publisher_id":101,"instrument_id":436},"action":"C","side":"B","price":"1.156390000","size":30,"channel_id":23,"order_id":"10998899903131278824","flags":0,"ts_in_delta":994,"sequence":150877,"symbol":"FCEU SI 20260615 PS"}
{"ts_recv":"2026-04-07T02:11:07.432166056Z","hd":{"ts_event":"2026-04-07T02:11:07.432145665Z","rtype":160,"publisher_id":101,"instrument_id":436},"action":"A","side":"B","price":"1.156410000","size":30,"channel_id":23,"order_id":"10998899904286927417","flags":0,"ts_in_delta":994,"sequence":150877,"symbol":"FCEU SI 20260615 PS"}
{"ts_recv":"2026-04-07T02:11:07.432166056Z","hd":{"ts_event":"2026-04-07T02:11:07.432145665Z","rtype":160,"publisher_id":101,"instrument_id":436},"action":"C","side":"A","price":"1.156490000","size":30,"channel_id":23,"order_id":"1775527866276503016","flags":0,"ts_in_delta":994,"sequence":150877,"symbol":"FCEU SI 20260615 PS"}
{"ts_recv":"2026-04-07T02:11:07.432166056Z","hd":{"ts_event":"2026-04-07T02:11:07.432145665Z","rtype":160,"publisher_id":101,"instrument_id":436},"action":"A","side":"A","price":"1.156510000","size":30,"channel_id":23,"order_id":"1775527867432151609","flags":128,"ts_in_delta":994,"sequence":150877,"symbol":"FCEU SI 20260615 PS"}
{"ts_recv":"2026-04-07T02:11:07.432221634Z","hd":{"ts_event":"2026-04-07T02:11:07.432205955Z","rtype":160,"publisher_id":101,"instrument_id":436},"action":"C","side":"B","price":"1.156400000","size":30,"channel_id":23,"order_id":"10998899904286877048","flags":0,"ts_in_delta":749,"sequence":150879,"symbol":"FCEU SI 20260615 PS"}
{"ts_recv":"2026-04-07T02:11:07.432221634Z","hd":{"ts_event":"2026-04-07T02:11:07.432205955Z","rtype":160,"publisher_id":101,"instrument_id":436},"action":"A","side":"B","price":"1.156410000","size":30,"channel_id":23,"order_id":"10998899904286987675","flags":0,"ts_in_delta":749,"sequence":150879,"symbol":"FCEU SI 20260615 PS"}
{"ts_recv":"2026-04-07T02:11:07.432221634Z","hd":{"ts_event":"2026-04-07T02:11:07.432205955Z","rtype":160,"publisher_id":101,"instrument_id":436},"action":"C","side":"A","price":"1.156500000","size":30,"channel_id":23,"order_id":"1775527867432101240","flags":0,"ts_in_delta":749,"sequence":150879,"symbol":"FCEU SI 20260615 PS"}
{"ts_recv":"2026-04-07T02:11:07.432221634Z","hd":{"ts_event":"2026-04-07T02:11:07.432205955Z","rtype":160,"publisher_id":101,"instrument_id":436},"action":"A","side":"A","price":"1.156510000","size":30,"channel_id":23,"order_id":"1775527867432211867","flags":128,"ts_in_delta":749,"sequence":150879,"symbol":"FCEU SI 20260615 PS"}
{"ts_recv":"2026-04-07T02:11:11.220861804Z","hd":{"ts_event":"2026-04-07T02:11:11.220840225Z","rtype":160,"publisher_id":101,"instrument_id":436},"action":"C","side":"B","price":"1.156410000","size":30,"channel_id":23,"order_id":"10998899904286927417","flags":0,"ts_in_delta":929,"sequence":150933,"symbol":"FCEU SI 20260615 PS"}
{"ts_recv":"2026-04-07T02:11:11.220861804Z","hd":{"ts_event":"2026-04-07T02:11:11.220840225Z","rtype":160,"publisher_id":101,"instrument_id":436},"action":"A","side":"B","price":"1.156430000","size":30,"channel_id":23,"order_id":"10998899908075622210","flags":0,"ts_in_delta":929,"sequence":150933,"symbol":"FCEU SI 20260615 PS"}
{"ts_recv":"2026-04-07T02:11:11.220861804Z","hd":{"ts_event":"2026-04-07T02:11:11.220840225Z","rtype":160,"publisher_id":101,"instrument_id":436},"action":"C","side":"A","price":"1.156510000","size":30,"channel_id":23,"order_id":"1775527867432151609","flags":0,"ts_in_delta":929,"sequence":150933,"symbol":"FCEU SI 20260615 PS"}
{"ts_recv":"2026-04-07T02:11:11.220861804Z","hd":{"ts_event":"2026-04-07T02:11:11.220840225Z","rtype":160,"publisher_id":101,"instrument_id":436},"action":"A","side":"A","price":"1.156530000","size":30,"channel_id":23,"order_id":"1775527871220846402","flags":128,"ts_in_delta":929,"sequence":150933,"symbol":"FCEU SI 20260615 PS"}
{"ts_recv":"2026-04-07T02:11:11.220961915Z","hd":{"ts_event":"2026-04-07T02:11:11.220943157Z","rtype":160,"publisher_id":101,"instrument_id":436},"action":"C","side":"B","price":"1.156410000","size":30,"channel_id":23,"order_id":"10998899904286987675","flags":0,"ts_in_delta":964,"sequence":150934,"symbol":"FCEU SI 20260615 PS"}
{"ts_recv":"2026-04-07T02:11:11.220961915Z","hd":{"ts_event":"2026-04-07T02:11:11.220943157Z","rtype":160,"publisher_id":101,"instrument_id":436},"action":"A","side":"B","price":"1.156420000","size":30,"channel_id":23,"order_id":"10998899908075725322","flags":0,"ts_in_delta":964,"sequence":150934,"symbol":"FCEU SI 20260615 PS"}
{"ts_recv":"2026-04-07T02:11:11.220961915Z","hd":{"ts_event":"2026-04-07T02:11:11.220943157Z","rtype":160,"publisher_id":101,"instrument_id":436},"action":"C","side":"A","price":"1.156510000","size":30,"channel_id":23,"order_id":"1775527867432211867","flags":0,"ts_in_delta":964,"sequence":150934,"symbol":"FCEU SI 20260615 PS"}
{"ts_recv":"2026-04-07T02:11:11.220961915Z","hd":{"ts_event":"2026-04-07T02:11:11.220943157Z","rtype":160,"publisher_id":101,"instrument_id":436},"action":"A","side":"A","price":"1.156520000","size":30,"channel_id":23,"order_id":"1775527871220949514","flags":128,"ts_in_delta":964,"sequence":150934,"symbol":"FCEU SI 20260615 PS"}
{"ts_recv":"2026-04-07T02:11:11.221862000Z","hd":{"ts_event":"2026-04-07T02:11:11.221843905Z","rtype":160,"publisher_id":101,"instrument_id":436},"action":"C","side":"B","price":"1.156420000","size":30,"channel_id":23,"order_id":"10998899908075725322","flags":0,"ts_in_delta":870,"sequence":150936,"symbol":"FCEU SI 20260615 PS"}
{"ts_recv":"2026-04-07T02:11:11.221862000Z","hd":{"ts_event":"2026-04-07T02:11:11.221843905Z","rtype":160,"publisher_id":101,"instrument_id":436},"action":"A","side":"B","price":"1.156430000","size":30,"channel_id":23,"order_id":"10998899908076625471","flags":0,"ts_in_delta":870,"sequence":150936,"symbol":"FCEU SI 20260615 PS"}
{"ts_recv":"2026-04-07T02:11:11.221862000Z","hd":{"ts_event":"2026-04-07T02:11:11.221843905Z","rtype":160,"publisher_id":101,"instrument_id":436},"action":"C","side":"A","price":"1.156520000","size":30,"channel_id":23,"order_id":"1775527871220949514","flags":0,"ts_in_delta":870,"sequence":150936,"symbol":"FCEU SI 20260615 PS"}
{"ts_recv":"2026-04-07T02:11:11.221862000Z","hd":{"ts_event":"2026-04-07T02:11:11.221843905Z","rtype":160,"publisher_id":101,"instrument_id":436},"action":"A","side":"A","price":"1.156530000","size":30,"channel_id":23,"order_id":"1775527871221849663","flags":128,"ts_in_delta":870,"sequence":150936,"symbol":"FCEU SI 20260615 PS"}
{"ts_recv":"2026-04-07T02:11:11.234878420Z","hd":{"ts_event":"2026-04-07T02:11:11.234858869Z","rtype":160,"publisher_id":101,"instrument_id":436},"action":"C","side":"B","price":"1.156430000","size":30,"channel_id":23,"order_id":"10998899908076625471","flags":0,"ts_in_delta":1147,"sequence":150955,"symbol":"FCEU SI 20260615 PS"}
{"ts_recv":"2026-04-07T02:11:11.234878420Z","hd":{"ts_event":"2026-04-07T02:11:11.234858869Z","rtype":160,"publisher_id":101,"instrument_id":436},"action":"A","side":"B","price":"1.156440000","size":30,"channel_id":23,"order_id":"10998899908089640423","flags":0,"ts_in_delta":1147,"sequence":150955,"symbol":"FCEU SI 20260615 PS"}
{"ts_recv":"2026-04-07T02:11:11.234878420Z","hd":{"ts_event":"2026-04-07T02:11:11.234858869Z","rtype":160,"publisher_id":101,"instrument_id":436},"action":"C","side":"A","price":"1.156530000","size":30,"channel_id":23,"order_id":"1775527871221849663","flags":0,"ts_in_delta":1147,"sequence":150955,"symbol":"FCEU SI 20260615 PS"}
{"ts_recv":"2026-04-07T02:11:11.234878420Z","hd":{"ts_event":"2026-04-07T02:11:11.234858869Z","rtype":160,"publisher_id":101,"instrument_id":436},"action":"A","side":"A","price":"1.156540000","size":30,"channel_id":23,"order_id":"1775527871234864615","flags":128,"ts_in_delta":1147,"sequence":150955,"symbol":"FCEU SI 20260615 PS"}
{"ts_recv":"2026-04-07T02:11:11.234929336Z","hd":{"ts_event":"2026-04-07T02:11:11.234910013Z","rtype":160,"publisher_id":101,"instrument_id":436},"action":"C","side":"B","price":"1.156430000","size":30,"channel_id":23,"order_id":"10998899908075622210","flags":0,"ts_in_delta":885,"sequence":150956,"symbol":"FCEU SI 20260615 PS"}
{"ts_recv":"2026-04-07T02:11:11.234929336Z","hd":{"ts_event":"2026-04-07T02:11:11.234910013Z","rtype":160,"publisher_id":101,"instrument_id":436},"action":"A","side":"B","price":"1.156450000","size":30,"channel_id":23,"order_id":"10998899908089691631","flags":0,"ts_in_delta":885,"sequence":150956,"symbol":"FCEU SI 20260615 PS"}
{"ts_recv":"2026-04-07T02:11:11.234929336Z","hd":{"ts_event":"2026-04-07T02:11:11.234910013Z","rtype":160,"publisher_id":101,"instrument_id":436},"action":"C","side":"A","price":"1.156530000","size":30,"channel_id":23,"order_id":"1775527871220846402","flags":0,"ts_in_delta":885,"sequence":150956,"symbol":"FCEU SI 20260615 PS"}
{"ts_recv":"2026-04-07T02:11:11.234929336Z","hd":{"ts_event":"2026-04-07T02:11:11.234910013Z","rtype":160,"publisher_id":101,"instrument_id":436},"action":"A","side":"A","price":"1.156550000","size":30,"channel_id":23,"order_id":"1775527871234915823","flags":128,"ts_in_delta":885,"sequence":150956,"symbol":"FCEU SI 20260615 PS"}
{"ts_recv":"2026-04-07T02:11:11.234937461Z","hd":{"ts_event":"2026-04-07T02:11:11.234921041Z","rtype":160,"publisher_id":101,"instrument_id":436},"action":"C","side":"B","price":"1.156440000","size":30,"channel_id":23,"order_id":"10998899908089640423","flags":0,"ts_in_delta":858,"sequence":150957,"symbol":"FCEU SI 20260615 PS"}
{"ts_recv":"2026-04-07T02:11:11.234937461Z","hd":{"ts_event":"2026-04-07T02:11:11.234921041Z","rtype":160,"publisher_id":101,"instrument_id":436},"action":"A","side":"B","price":"1.156450000","size":30,"channel_id":23,"order_id":"10998899908089702905","flags":0,"ts_in_delta":858,"sequence":150957,"symbol":"FCEU SI 20260615 PS"}
{"ts_recv":"2026-04-07T02:11:11.234937461Z","hd":{"ts_event":"2026-04-07T02:11:11.234921041Z","rtype":160,"publisher_id":101,"instrument_id":436},"action":"C","side":"A","price":"1.156540000","size":30,"channel_id":23,"order_id":"1775527871234864615","flags":0,"ts_in_delta":858,"sequence":150957,"symbol":"FCEU SI 20260615 PS"}
{"ts_recv":"2026-04-07T02:11:11.234937461Z","hd":{"ts_event":"2026-04-07T02:11:11.234921041Z","rtype":160,"publisher_id":101,"instrument_id":436},"action":"A","side":"A","price":"1.156550000","size":30,"channel_id":23,"order_id":"1775527871234927097","flags":128,"ts_in_delta":858,"sequence":150957,"symbol":"FCEU SI 20260615 PS"}
{"ts_recv":"2026-04-07T02:11:11.239974004Z","hd":{"ts_event":"2026-04-07T02:11:11.239952891Z","rtype":160,"publisher_id":101,"instrument_id":436},"action":"C","side":"B","price":"1.156450000","size":30,"channel_id":23,"order_id":"10998899908089702905","flags":0,"ts_in_delta":860,"sequence":150967,"symbol":"FCEU SI 20260615 PS"}
{"ts_recv":"2026-04-07T02:11:11.239974004Z","hd":{"ts_event":"2026-04-07T02:11:11.239952891Z","rtype":160,"publisher_id":101,"instrument_id":436},"action":"A","side":"B","price":"1.156460000","size":30,"channel_id":23,"order_id":"10998899908094734965","flags":0,"ts_in_delta":860,"sequence":150967,"symbol":"FCEU SI 20260615 PS"}
{"ts_recv":"2026-04-07T02:11:11.239974004Z","hd":{"ts_event":"2026-04-07T02:11:11.239952891Z","rtype":160,"publisher_id":101,"instrument_id":436},"action":"C","side":"A","price":"1.156550000","size":30,"channel_id":23,"order_id":"1775527871234927097","flags":0,"ts_in_delta":860,"sequence":150967,"symbol":"FCEU SI 20260615 PS"}
{"ts_recv":"2026-04-07T02:11:11.239974004Z","hd":{"ts_event":"2026-04-07T02:11:11.239952891Z","rtype":160,"publisher_id":101,"instrument_id":436},"action":"A","side":"A","price":"1.156560000","size":30,"channel_id":23,"order_id":"1775527871239959157","flags":128,"ts_in_delta":860,"sequence":150967,"symbol":"FCEU SI 20260615 PS"}
{"ts_recv":"2026-04-07T02:11:11.261313848Z","hd":{"ts_event":"2026-04-07T02:11:11.261298807Z","rtype":160,"publisher_id":101,"instrument_id":436},"action":"C","side":"A","price":"1.156600000","size":20,"channel_id":23,"order_id":"1775527726611328836","flags":128,"ts_in_delta":804,"sequence":150979,"symbol":"FCEU SI 20260615 PS"}
{"ts_recv":"2026-04-07T02:11:11.304144817Z","hd":{"ts_event":"2026-04-07T02:11:11.304131827Z","rtype":160,"publisher_id":101,"instrument_id":436},"action":"A","side":"A","price":"1.156800000","size":20,"channel_id":23,"order_id":"1775527871304137888","flags":128,"ts_in_delta":592,"sequence":150998,"symbol":"FCEU SI 20260615 PS"}
{"ts_recv":"2026-04-07T02:11:11.362292452Z","hd":{"ts_event":"2026-04-07T02:11:11.362271975Z","rtype":160,"publisher_id":101,"instrument_id":436},"action":"C","side":"B","price":"1.156450000","size":30,"channel_id":23,"order_id":"10998899908089691631","flags":0,"ts_in_delta":882,"sequence":151008,"symbol":"FCEU SI 20260615 PS"}
{"ts_recv":"2026-04-07T02:11:11.362292452Z","hd":{"ts_event":"2026-04-07T02:11:11.362271975Z","rtype":160,"publisher_id":101,"instrument_id":436},"action":"A","side":"B","price":"1.156480000","size":30,"channel_id":23,"order_id":"10998899908217053806","flags":0,"ts_in_delta":882,"sequence":151008,"symbol":"FCEU SI 20260615 PS"}
{"ts_recv":"2026-04-07T02:11:11.362292452Z","hd":{"ts_event":"2026-04-07T02:11:11.362271975Z","rtype":160,"publisher_id":101,"instrument_id":436},"action":"C","side":"A","price":"1.156550000","size":30,"channel_id":23,"order_id":"1775527871234915823","flags":0,"ts_in_delta":882,"sequence":151008,"symbol":"FCEU SI 20260615 PS"}
{"ts_recv":"2026-04-07T02:11:11.362292452Z","hd":{"ts_event":"2026-04-07T02:11:11.362271975Z","rtype":160,"publisher_id":101,"instrument_id":436},"action":"A","side":"A","price":"1.156580000","size":30,"channel_id":23,"order_id":"1775527871362277998","flags":128,"ts_in_delta":882,"sequence":151008,"symbol":"FCEU SI 20260615 PS"}
{"ts_recv":"2026-04-07T02:11:11.362353336Z","hd":{"ts_event":"2026-04-07T02:11:11.362334605Z","rtype":160,"publisher_id":101,"instrument_id":436},"action":"C","side":"B","price":"1.156460000","size":30,"channel_id":23,"order_id":"10998899908094734965","flags":0,"ts_in_delta":863,"sequence":151009,"symbol":"FCEU SI 20260615 PS"}
{"ts_recv":"2026-04-07T02:11:11.362353336Z","hd":{"ts_event":"2026-04-07T02:11:11.362334605Z","rtype":160,"publisher_id":101,"instrument_id":436},"action":"A","side":"B","price":"1.156480000","size":30,"channel_id":23,"order_id":"10998899908217116662","flags":0,"ts_in_delta":863,"sequence":151009,"symbol":"FCEU SI 20260615 PS"}
{"ts_recv":"2026-04-07T02:11:11.362353336Z","hd":{"ts_event":"2026-04-07T02:11:11.362334605Z","rtype":160,"publisher_id":101,"instrument_id":436},"action":"C","side":"A","price":"1.156560000","size":30,"channel_id":23,"order_id":"1775527871239959157","flags":0,"ts_in_delta":863,"sequence":151009,"symbol":"FCEU SI 20260615 PS"}
{"ts_recv":"2026-04-07T02:11:11.362353336Z","hd":{"ts_event":"2026-04-07T02:11:11.362334605Z","rtype":160,"publisher_id":101,"instrument_id":436},"action":"A","side":"A","price":"1.156580000","size":30,"channel_id":23,"order_id":"1775527871362340854","flags":128,"ts_in_delta":863,"sequence":151009,"symbol":"FCEU SI 20260615 PS"}
{"ts_recv":"2026-04-07T02:11:11.472760314Z","hd":{"ts_event":"2026-04-07T02:11:11.472741107Z","rtype":160,"publisher_id":101,"instrument_id":436},"action":"C","side":"B","price":"1.156480000","size":30,"channel_id":23,"order_id":"10998899908217053806","flags":0,"ts_in_delta":869,"sequence":151021,"symbol":"FCEU SI 20260615 PS"}
{"ts_recv":"2026-04-07T02:11:11.472760314Z","hd":{"ts_event":"2026-04-07T02:11:11.472741107Z","rtype":160,"publisher_id":101,"instrument_id":436},"action":"A","side":"B","price":"1.156500000","size":30,"channel_id":23,"order_id":"10998899908327522951","flags":0,"ts_in_delta":869,"sequence":151021,"symbol":"FCEU SI 20260615 PS"}
{"ts_recv":"2026-04-07T02:11:11.472760314Z","hd":{"ts_event":"2026-04-07T02:11:11.472741107Z","rtype":160,"publisher_id":101,"instrument_id":436},"action":"C","side":"A","price":"1.156580000","size":30,"channel_id":23,"order_id":"1775527871362277998","flags":0,"ts_in_delta":869,"sequence":151021,"symbol":"FCEU SI 20260615 PS"}
{"ts_recv":"2026-04-07T02:11:11.472760314Z","hd":{"ts_event":"2026-04-07T02:11:11.472741107Z","rtype":160,"publisher_id":101,"instrument_id":436},"action":"A","side":"A","price":"1.156600000","size":30,"channel_id":23,"order_id":"1775527871472747143","flags":128,"ts_in_delta":869,"sequence":151021,"symbol":"FCEU SI 20260615 PS"}
{"ts_recv":"2026-04-07T02:11:11.472818534Z","hd":{"ts_event":"2026-04-07T02:11:11.472803393Z","rtype":160,"publisher_id":101,"instrument_id":436},"action":"C","side":"B","price":"1.156480000","size":30,"channel_id":23,"order_id":"10998899908217116662","flags":0,"ts_in_delta":846,"sequence":151022,"symbol":"FCEU SI 20260615 PS"}
{"ts_recv":"2026-04-07T02:11:11.472818534Z","hd":{"ts_event":"2026-04-07T02:11:11.472803393Z","rtype":160,"publisher_id":101,"instrument_id":436},"action":"A","side":"B","price":"1.156490000","size":30,"channel_id":23,"order_id":"10998899908327585275","flags":0,"ts_in_delta":846,"sequence":151022,"symbol":"FCEU SI 20260615 PS"}
{"ts_recv":"2026-04-07T02:11:11.472818534Z","hd":{"ts_event":"2026-04-07T02:11:11.472803393Z","rtype":160,"publisher_id":101,"instrument_id":436},"action":"C","side":"A","price":"1.156580000","size":30,"channel_id":23,"order_id":"1775527871362340854","flags":0,"ts_in_delta":846,"sequence":151022,"symbol":"FCEU SI 20260615 PS"}
{"ts_recv":"2026-04-07T02:11:11.472818534Z","hd":{"ts_event":"2026-04-07T02:11:11.472803393Z","rtype":160,"publisher_id":101,"instrument_id":436},"action":"A","side":"A","price":"1.156590000","size":30,"channel_id":23,"order_id":"1775527871472809467","flags":128,"ts_in_delta":846,"sequence":151022,"symbol":"FCEU SI 20260615 PS"}
{"ts_recv":"2026-04-07T02:11:15.599774963Z","hd":{"ts_event":"2026-04-07T02:11:15.599746461Z","rtype":160,"publisher_id":101,"instrument_id":436},"action":"C","side":"B","price":"1.156500000","size":30,"channel_id":23,"order_id":"10998899908327522951","flags":0,"ts_in_delta":1219,"sequence":151092,"symbol":"FCEU SI 20260615 PS"}
{"ts_recv":"2026-04-07T02:11:15.599774963Z","hd":{"ts_event":"2026-04-07T02:11:15.599746461Z","rtype":160,"publisher_id":101,"instrument_id":436},"action":"A","side":"B","price":"1.156480000","size":30,"channel_id":23,"order_id":"10998899912454533108","flags":0,"ts_in_delta":1219,"sequence":151092,"symbol":"FCEU SI 20260615 PS"}
{"ts_recv":"2026-04-07T02:11:15.599774963Z","hd":{"ts_event":"2026-04-07T02:11:15.599746461Z","rtype":160,"publisher_id":101,"instrument_id":436},"action":"C","side":"A","price":"1.156600000","size":30,"channel_id":23,"order_id":"1775527871472747143","flags":0,"ts_in_delta":1219,"sequence":151092,"symbol":"FCEU SI 20260615 PS"}
{"ts_recv":"2026-04-07T02:11:15.599774963Z","hd":{"ts_event":"2026-04-07T02:11:15.599746461Z","rtype":160,"publisher_id":101,"instrument_id":436},"action":"A","side":"A","price":"1.156580000","size":30,"channel_id":23,"order_id":"1775527875599757300","flags":128,"ts_in_delta":1219,"sequence":151092,"symbol":"FCEU SI 20260615 PS"}
{"ts_recv":"2026-04-07T02:11:15.599853127Z","hd":{"ts_event":"2026-04-07T02:11:15.599831863Z","rtype":160,"publisher_id":101,"instrument_id":436},"action":"C","side":"B","price":"1.156490000","size":30,"channel_id":23,"order_id":"10998899908327585275","flags":0,"ts_in_delta":875,"sequence":151093,"symbol":"FCEU SI 20260615 PS"}
{"ts_recv":"2026-04-07T02:11:15.599853127Z","hd":{"ts_event":"2026-04-07T02:11:15.599831863Z","rtype":160,"publisher_id":101,"instrument_id":436},"action":"A","side":"B","price":"1.156480000","size":30,"channel_id":23,"order_id":"10998899912454614347","flags":0,"ts_in_delta":875,"sequence":151093,"symbol":"FCEU SI 20260615 PS"}
{"ts_recv":"2026-04-07T02:11:15.599853127Z","hd":{"ts_event":"2026-04-07T02:11:15.599831863Z","rtype":160,"publisher_id":101,"instrument_id":436},"action":"C","side":"A","price":"1.156590000","size":30,"channel_id":23,"order_id":"1775527871472809467","flags":0,"ts_in_delta":875,"sequence":151093,"symbol":"FCEU SI 20260615 PS"}
{"ts_recv":"2026-04-07T02:11:15.599853127Z","hd":{"ts_event":"2026-04-07T02:11:15.599831863Z","rtype":160,"publisher_id":101,"instrument_id":436},"action":"A","side":"A","price":"1.156580000","size":30,"channel_id":23,"order_id":"1775527875599838539","flags":128,"ts_in_delta":875,"sequence":151093,"symbol":"FCEU SI 20260615 PS"}
{"ts_recv":"2026-04-07T02:11:15.627876976Z","hd":{"ts_event":"2026-04-07T02:11:15.627855981Z","rtype":160,"publisher_id":101,"instrument_id":436},"action":"C","side":"B","price":"1.156480000","size":30,"channel_id":23,"order_id":"10998899912454614347","flags":0,"ts_in_delta":991,"sequence":151095,"symbol":"FCEU SI 20260615 PS"}
{"ts_recv":"2026-04-07T02:11:15.627876976Z","hd":{"ts_event":"2026-04-07T02:11:15.627855981Z","rtype":160,"publisher_id":101,"instrument_id":436},"action":"A","side":"B","price":"1.156470000","size":30,"channel_id":23,"order_id":"10998899912482637816","flags":0,"ts_in_delta":991,"sequence":151095,"symbol":"FCEU SI 20260615 PS"}
{"ts_recv":"2026-04-07T02:11:15.627876976Z","hd":{"ts_event":"2026-04-07T02:11:15.627855981Z","rtype":160,"publisher_id":101,"instrument_id":436},"action":"C","side":"A","price":"1.156580000","size":30,"channel_id":23,"order_id":"1775527875599838539","flags":0,"ts_in_delta":991,"sequence":151095,"symbol":"FCEU SI 20260615 PS"}
{"ts_recv":"2026-04-07T02:11:15.627876976Z","hd":{"ts_event":"2026-04-07T02:11:15.627855981Z","rtype":160,"publisher_id":101,"instrument_id":436},"action":"A","side":"A","price":"1.156570000","size":30,"channel_id":23,"order_id":"1775527875627862008","flags":128,"ts_in_delta":991,"sequence":151095,"symbol":"FCEU SI 20260615 PS"}
{"ts_recv":"2026-04-07T02:11:15.627953549Z","hd":{"ts_event":"2026-04-07T02:11:15.627936251Z","rtype":160,"publisher_id":101,"instrument_id":436},"action":"C","side":"B","price":"1.156470000","size":30,"channel_id":23,"order_id":"10998899912482637816","flags":0,"ts_in_delta":888,"sequence":151096,"symbol":"FCEU SI 20260615 PS"}
{"ts_recv":"2026-04-07T02:11:15.627953549Z","hd":{"ts_event":"2026-04-07T02:11:15.627936251Z","rtype":160,"publisher_id":101,"instrument_id":436},"action":"A","side":"B","price":"1.156460000","size":30,"channel_id":23,"order_id":"10998899912482717802","flags":0,"ts_in_delta":888,"sequence":151096,"symbol":"FCEU SI 20260615 PS"}
{"ts_recv":"2026-04-07T02:11:15.627953549Z","hd":{"ts_event":"2026-04-07T02:11:15.627936251Z","rtype":160,"publisher_id":101,"instrument_id":436},"action":"C","side":"A","price":"1.156570000","size":30,"channel_id":23,"order_id":"1775527875627862008","flags":0,"ts_in_delta":888,"sequence":151096,"symbol":"FCEU SI 20260615 PS"}
{"ts_recv":"2026-04-07T02:11:15.627953549Z","hd":{"ts_event":"2026-04-07T02:11:15.627936251Z","rtype":160,"publisher_id":101,"instrument_id":436},"action":"A","side":"A","price":"1.156560000","size":30,"channel_id":23,"order_id":"1775527875627941994","flags":128,"ts_in_delta":888,"sequence":151096,"symbol":"FCEU SI 20260615 PS"}
{"ts_recv":"2026-04-07T02:11:15.628006170Z","hd":{"ts_event":"2026-04-07T02:11:15.627991451Z","rtype":160,"publisher_id":101,"instrument_id":436},"action":"C","side":"B","price":"1.156460000","size":30,"channel_id":23,"order_id":"10998899912482717802","flags":0,"ts_in_delta":871,"sequence":151097,"symbol":"FCEU SI 20260615 PS"}
{"ts_recv":"2026-04-07T02:11:15.628006170Z","hd":{"ts_event":"2026-04-07T02:11:15.627991451Z","rtype":160,"publisher_id":101,"instrument_id":436},"action":"A","side":"B","price":"1.156470000","size":30,"channel_id":23,"order_id":"10998899912482772977","flags":0,"ts_in_delta":871,"sequence":151097,"symbol":"FCEU SI 20260615 PS"}
{"ts_recv":"2026-04-07T02:11:15.628006170Z","hd":{"ts_event":"2026-04-07T02:11:15.627991451Z","rtype":160,"publisher_id":101,"instrument_id":436},"action":"C","side":"A","price":"1.156560000","size":30,"channel_id":23,"order_id":"1775527875627941994","flags":0,"ts_in_delta":871,"sequence":151097,"symbol":"FCEU SI 20260615 PS"}
{"ts_recv":"2026-04-07T02:11:15.628006170Z","hd":{"ts_event":"2026-04-07T02:11:15.627991451Z","rtype":160,"publisher_id":101,"instrument_id":436},"action":"A","side":"A","price":"1.156570000","size":30,"channel_id":23,"order_id":"1775527875627997169","flags":128,"ts_in_delta":871,"sequence":151097,"symbol":"FCEU SI 20260615 PS"}
{"ts_recv":"2026-04-07T02:11:48.848774951Z","hd":{"ts_event":"2026-04-07T02:11:48.848749851Z","rtype":160,"publisher_id":101,"instrument_id":436},"action":"C","side":"B","price":"1.156480000","size":30,"channel_id":23,"order_id":"10998899912454533108","flags":0,"ts_in_delta":899,"sequence":151326,"symbol":"FCEU SI 20260615 PS"}
{"ts_recv":"2026-04-07T02:11:48.848774951Z","hd":{"ts_event":"2026-04-07T02:11:48.848749851Z","rtype":160,"publisher_id":101,"instrument_id":436},"action":"A","side":"B","price":"1.156460000","size":30,"channel_id":23,"order_id":"10998899945703532308","flags":0,"ts_in_delta":899,"sequence":151326,"symbol":"FCEU SI 20260615 PS"}
{"ts_recv":"2026-04-07T02:11:48.848774951Z","hd":{"ts_event":"2026-04-07T02:11:48.848749851Z","rtype":160,"publisher_id":101,"instrument_id":436},"action":"C","side":"A","price":"1.156580000","size":30,"channel_id":23,"order_id":"1775527875599757300","flags":0,"ts_in_delta":899,"sequence":151326,"symbol":"FCEU SI 20260615 PS"}
{"ts_recv":"2026-04-07T02:11:48.848774951Z","hd":{"ts_event":"2026-04-07T02:11:48.848749851Z","rtype":160,"publisher_id":101,"instrument_id":436},"action":"A","side":"A","price":"1.156560000","size":30,"channel_id":23,"order_id":"1775527908848756500","flags":128,"ts_in_delta":899,"sequence":151326,"symbol":"FCEU SI 20260615 PS"}
{"ts_recv":"2026-04-07T02:11:48.848854682Z","hd":{"ts_event":"2026-04-07T02:11:48.848837405Z","rtype":160,"publisher_id":101,"instrument_id":436},"action":"C","side":"B","price":"1.156470000","size":30,"channel_id":23,"order_id":"10998899912482772977","flags":0,"ts_in_delta":872,"sequence":151327,"symbol":"FCEU SI 20260615 PS"}
{"ts_recv":"2026-04-07T02:11:48.848854682Z","hd":{"ts_event":"2026-04-07T02:11:48.848837405Z","rtype":160,"publisher_id":101,"instrument_id":436},"action":"A","side":"B","price":"1.156460000","size":30,"channel_id":23,"order_id":"10998899945703619241","flags":0,"ts_in_delta":872,"sequence":151327,"symbol":"FCEU SI 20260615 PS"}
{"ts_recv":"2026-04-07T02:11:48.848854682Z","hd":{"ts_event":"2026-04-07T02:11:48.848837405Z","rtype":160,"publisher_id":101,"instrument_id":436},"action":"C","side":"A","price":"1.156570000","size":30,"channel_id":23,"order_id":"1775527875627997169","flags":0,"ts_in_delta":872,"sequence":151327,"symbol":"FCEU SI 20260615 PS"}
{"ts_recv":"2026-04-07T02:11:48.848854682Z","hd":{"ts_event":"2026-04-07T02:11:48.848837405Z","rtype":160,"publisher_id":101,"instrument_id":436},"action":"A","side":"A","price":"1.156560000","size":30,"channel_id":23,"order_id":"1775527908848843433","flags":128,"ts_in_delta":872,"sequence":151327,"symbol":"FCEU SI 20260615 PS"}
{"ts_recv":"2026-04-07T02:11:48.850601540Z","hd":{"ts_event":"2026-04-07T02:11:48.850579419Z","rtype":160,"publisher_id":101,"instrument_id":436},"action":"C","side":"B","price":"1.156460000","size":30,"channel_id":23,"order_id":"10998899945703619241","flags":0,"ts_in_delta":903,"sequence":151329,"symbol":"FCEU SI 20260615 PS"}
{"ts_recv":"2026-04-07T02:11:48.850601540Z","hd":{"ts_event":"2026-04-07T02:11:48.850579419Z","rtype":160,"publisher_id":101,"instrument_id":436},"action":"A","side":"B","price":"1.156450000","size":30,"channel_id":23,"order_id":"10998899945705361163","flags":0,"ts_in_delta":903,"sequence":151329,"symbol":"FCEU SI 20260615 PS"}
{"ts_recv":"2026-04-07T02:11:48.850601540Z","hd":{"ts_event":"2026-04-07T02:11:48.850579419Z","rtype":160,"publisher_id":101,"instrument_id":436},"action":"C","side":"A","price":"1.156560000","size":30,"channel_id":23,"order_id":"1775527908848843433","flags":0,"ts_in_delta":903,"sequence":151329,"symbol":"FCEU SI 20260615 PS"}
{"ts_recv":"2026-04-07T02:11:48.850601540Z","hd":{"ts_event":"2026-04-07T02:11:48.850579419Z","rtype":160,"publisher_id":101,"instrument_id":436},"action":"A","side":"A","price":"1.156550000","size":30,"channel_id":23,"order_id":"1775527908850585355","flags":128,"ts_in_delta":903,"sequence":151329,"symbol":"FCEU SI 20260615 PS"}
{"ts_recv":"2026-04-07T02:11:48.850688029Z","hd":{"ts_event":"2026-04-07T02:11:48.850664917Z","rtype":160,"publisher_id":101,"instrument_id":436},"action":"C","side":"B","price":"1.156450000","size":30,"channel_id":23,"order_id":"10998899945705361163","flags":0,"ts_in_delta":890,"sequence":151330,"symbol":"FCEU SI 20260615 PS"}
{"ts_recv":"2026-04-07T02:11:48.850688029Z","hd":{"ts_event":"2026-04-07T02:11:48.850664917Z","rtype":160,"publisher_id":101,"instrument_id":436},"action":"A","side":"B","price":"1.156440000","size":30,"channel_id":23,"order_id":"10998899945705446993","flags":0,"ts_in_delta":890,"sequence":151330,"symbol":"FCEU SI 20260615 PS"}
{"ts_recv":"2026-04-07T02:11:48.850688029Z","hd":{"ts_event":"2026-04-07T02:11:48.850664917Z","rtype":160,"publisher_id":101,"instrument_id":436},"action":"C","side":"A","price":"1.156550000","size":30,"channel_id":23,"order_id":"1775527908850585355","flags":0,"ts_in_delta":890,"sequence":151330,"symbol":"FCEU SI 20260615 PS"}
{"ts_recv":"2026-04-07T02:11:48.850688029Z","hd":{"ts_event":"2026-04-07T02:11:48.850664917Z","rtype":160,"publisher_id":101,"instrument_id":436},"action":"A","side":"A","price":"1.156540000","size":30,"channel_id":23,"order_id":"1775527908850671185","flags":128,"ts_in_delta":890,"sequence":151330,"symbol":"FCEU SI 20260615 PS"}
{"ts_recv":"2026-04-07T02:11:48.850745664Z","hd":{"ts_event":"2026-04-07T02:11:48.850728681Z","rtype":160,"publisher_id":101,"instrument_id":436},"action":"C","side":"B","price":"1.156440000","size":30,"channel_id":23,"order_id":"10998899945705446993","flags":0,"ts_in_delta":859,"sequence":151331,"symbol":"FCEU SI 20260615 PS"}
{"ts_recv":"2026-04-07T02:11:48.850745664Z","hd":{"ts_event":"2026-04-07T02:11:48.850728681Z","rtype":160,"publisher_id":101,"instrument_id":436},"action":"A","side":"B","price":"1.156450000","size":30,"channel_id":23,"order_id":"10998899945705510421","flags":0,"ts_in_delta":859,"sequence":151331,"symbol":"FCEU SI 20260615 PS"}
{"ts_recv":"2026-04-07T02:11:48.850745664Z","hd":{"ts_event":"2026-04-07T02:11:48.850728681Z","rtype":160,"publisher_id":101,"instrument_id":436},"action":"C","side":"A","price":"1.156540000","size":30,"channel_id":23,"order_id":"1775527908850671185","flags":0,"ts_in_delta":859,"sequence":151331,"symbol":"FCEU SI 20260615 PS"}
{"ts_recv":"2026-04-07T02:11:48.850745664Z","hd":{"ts_event":"2026-04-07T02:11:48.850728681Z","rtype":160,"publisher_id":101,"instrument_id":436},"action":"A","side":"A","price":"1.156550000","size":30,"channel_id":23,"order_id":"1775527908850734613","flags":128,"ts_in_delta":859,"sequence":151331,"symbol":"FCEU SI 20260615 PS"}
{"ts_recv":"2026-04-07T02:11:50.074523741Z","hd":{"ts_event":"2026-04-07T02:11:50.074504435Z","rtype":160,"publisher_id":101,"instrument_id":436},"action":"C","side":"B","price":"1.156450000","size":30,"channel_id":23,"order_id":"10998899945705510421","flags":0,"ts_in_delta":887,"sequence":151370,"symbol":"FCEU SI 20260615 PS"}
{"ts_recv":"2026-04-07T02:11:50.074523741Z","hd":{"ts_event":"2026-04-07T02:11:50.074504435Z","rtype":160,"publisher_id":101,"instrument_id":436},"action":"A","side":"B","price":"1.156460000","size":30,"channel_id":23,"order_id":"10998899946929286130","flags":0,"ts_in_delta":887,"sequence":151370,"symbol":"FCEU SI 20260615 PS"}
{"ts_recv":"2026-04-07T02:11:50.074523741Z","hd":{"ts_event":"2026-04-07T02:11:50.074504435Z","rtype":160,"publisher_id":101,"instrument_id":436},"action":"C","side":"A","price":"1.156550000","size":30,"channel_id":23,"order_id":"1775527908850734613","flags":0,"ts_in_delta":887,"sequence":151370,"symbol":"FCEU SI 20260615 PS"}
{"ts_recv":"2026-04-07T02:11:50.074523741Z","hd":{"ts_event":"2026-04-07T02:11:50.074504435Z","rtype":160,"publisher_id":101,"instrument_id":436},"action":"A","side":"A","price":"1.156560000","size":30,"channel_id":23,"order_id":"1775527910074510322","flags":128,"ts_in_delta":887,"sequence":151370,"symbol":"FCEU SI 20260615 PS"}
{"ts_recv":"2026-04-07T02:11:56.112439299Z","hd":{"ts_event":"2026-04-07T02:11:56.112417415Z","rtype":160,"publisher_id":101,"instrument_id":436},"action":"C","side":"B","price":"1.156460000","size":30,"channel_id":23,"order_id":"10998899946929286130","flags":0,"ts_in_delta":919,"sequence":151435,"symbol":"FCEU SI 20260615 PS"}
{"ts_recv":"2026-04-07T02:11:56.112439299Z","hd":{"ts_event":"2026-04-07T02:11:56.112417415Z","rtype":160,"publisher_id":101,"instrument_id":436},"action":"A","side":"B","price":"1.156450000","size":30,"channel_id":23,"order_id":"10998899952967201123","flags":0,"ts_in_delta":919,"sequence":151435,"symbol":"FCEU SI 20260615 PS"}
{"ts_recv":"2026-04-07T02:11:56.112439299Z","hd":{"ts_event":"2026-04-07T02:11:56.112417415Z","rtype":160,"publisher_id":101,"instrument_id":436},"action":"C","side":"A","price":"1.156560000","size":30,"channel_id":23,"order_id":"1775527910074510322","flags":0,"ts_in_delta":919,"sequence":151435,"symbol":"FCEU SI 20260615 PS"}
{"ts_recv":"2026-04-07T02:11:56.112439299Z","hd":{"ts_event":"2026-04-07T02:11:56.112417415Z","rtype":160,"publisher_id":101,"instrument_id":436},"action":"A","side":"A","price":"1.156550000","size":30,"channel_id":23,"order_id":"1775527916112425315","flags":128,"ts_in_delta":919,"sequence":151435,"symbol":"FCEU SI 20260615 PS"}
{"ts_recv":"2026-04-07T02:12:02.128908692Z","hd":{"ts_event":"2026-04-07T02:12:02.128886081Z","rtype":160,"publisher_id":101,"instrument_id":436},"action":"C","side":"B","price":"1.156460000","size":30,"channel_id":23,"order_id":"10998899945703532308","flags":0,"ts_in_delta":958,"sequence":151525,"symbol":"FCEU SI 20260615 PS"}
{"ts_recv":"2026-04-07T02:12:02.128908692Z","hd":{"ts_event":"2026-04-07T02:12:02.128886081Z","rtype":160,"publisher_id":101,"instrument_id":436},"action":"A","side":"B","price":"1.156440000","size":30,"channel_id":23,"order_id":"10998899958983668069","flags":0,"ts_in_delta":958,"sequence":151525,"symbol":"FCEU SI 20260615 PS"}
{"ts_recv":"2026-04-07T02:12:02.128908692Z","hd":{"ts_event":"2026-04-07T02:12:02.128886081Z","rtype":160,"publisher_id":101,"instrument_id":436},"action":"C","side":"A","price":"1.156560000","size":30,"channel_id":23,"order_id":"1775527908848756500","flags":0,"ts_in_delta":958,"sequence":151525,"symbol":"FCEU SI 20260615 PS"}
{"ts_recv":"2026-04-07T02:12:02.128908692Z","hd":{"ts_event":"2026-04-07T02:12:02.128886081Z","rtype":160,"publisher_id":101,"instrument_id":436},"action":"A","side":"A","price":"1.156540000","size":30,"channel_id":23,"order_id":"1775527922128892261","flags":128,"ts_in_delta":958,"sequence":151525,"symbol":"FCEU SI 20260615 PS"}
{"ts_recv":"2026-04-07T02:12:02.128991617Z","hd":{"ts_event":"2026-04-07T02:12:02.128972461Z","rtype":160,"publisher_id":101,"instrument_id":436},"action":"C","side":"B","price":"1.156450000","size":30,"channel_id":23,"order_id":"10998899952967201123","flags":0,"ts_in_delta":830,"sequence":151526,"symbol":"FCEU SI 20260615 PS"}
{"ts_recv":"2026-04-07T02:12:02.128991617Z","hd":{"ts_event":"2026-04-07T02:12:02.128972461Z","rtype":160,"publisher_id":101,"instrument_id":436},"action":"A","side":"B","price":"1.156440000","size":30,"channel_id":23,"order_id":"10998899958983754394","flags":0,"ts_in_delta":830,"sequence":151526,"symbol":"FCEU SI 20260615 PS"}
{"ts_recv":"2026-04-07T02:12:02.128991617Z","hd":{"ts_event":"2026-04-07T02:12:02.128972461Z","rtype":160,"publisher_id":101,"instrument_id":436},"action":"C","side":"A","price":"1.156550000","size":30,"channel_id":23,"order_id":"1775527916112425315","flags":0,"ts_in_delta":830,"sequence":151526,"symbol":"FCEU SI 20260615 PS"}
{"ts_recv":"2026-04-07T02:12:02.128991617Z","hd":{"ts_event":"2026-04-07T02:12:02.128972461Z","rtype":160,"publisher_id":101,"instrument_id":436},"action":"A","side":"A","price":"1.156540000","size":30,"channel_id":23,"order_id":"1775527922128978586","flags":128,"ts_in_delta":830,"sequence":151526,"symbol":"FCEU SI 20260615 PS"}
{"ts_recv":"2026-04-07T02:12:02.132460146Z","hd":{"ts_event":"2026-04-07T02:12:02.132440685Z","rtype":160,"publisher_id":101,"instrument_id":436},"action":"C","side":"B","price":"1.156440000","size":30,"channel_id":23,"order_id":"10998899958983754394","flags":0,"ts_in_delta":774,"sequence":151529,"symbol":"FCEU SI 20260615 PS"}
{"ts_recv":"2026-04-07T02:12:02.132460146Z","hd":{"ts_event":"2026-04-07T02:12:02.132440685Z","rtype":160,"publisher_id":101,"instrument_id":436},"action":"A","side":"B","price":"1.156430000","size":30,"channel_id":23,"order_id":"10998899958987222138","flags":0,"ts_in_delta":774,"sequence":151529,"symbol":"FCEU SI 20260615 PS"}
{"ts_recv":"2026-04-07T02:12:02.132460146Z","hd":{"ts_event":"2026-04-07T02:12:02.132440685Z","rtype":160,"publisher_id":101,"instrument_id":436},"action":"C","side":"A","price":"1.156540000","size":30,"channel_id":23,"order_id":"1775527922128978586","flags":0,"ts_in_delta":774,"sequence":151529,"symbol":"FCEU SI 20260615 PS"}
{"ts_recv":"2026-04-07T02:12:02.132460146Z","hd":{"ts_event":"2026-04-07T02:12:02.132440685Z","rtype":160,"publisher_id":101,"instrument_id":436},"action":"A","side":"A","price":"1.156530000","size":30,"channel_id":23,"order_id":"1775527922132446330","flags":128,"ts_in_delta":774,"sequence":151529,"symbol":"FCEU SI 20260615 PS"}
{"ts_recv":"2026-04-07T02:12:02.132541742Z","hd":{"ts_event":"2026-04-07T02:12:02.132522709Z","rtype":160,"publisher_id":101,"instrument_id":436},"action":"C","side":"B","price":"1.156430000","size":30,"channel_id":23,"order_id":"10998899958987222138","flags":0,"ts_in_delta":757,"sequence":151530,"symbol":"FCEU SI 20260615 PS"}
{"ts_recv":"2026-04-07T02:12:02.132541742Z","hd":{"ts_event":"2026-04-07T02:12:02.132522709Z","rtype":160,"publisher_id":101,"instrument_id":436},"action":"A","side":"B","price":"1.156420000","size":30,"channel_id":23,"order_id":"10998899958987304372","flags":0,"ts_in_delta":757,"sequence":151530,"symbol":"FCEU SI 20260615 PS"}
{"ts_recv":"2026-04-07T02:12:02.132541742Z","hd":{"ts_event":"2026-04-07T02:12:02.132522709Z","rtype":160,"publisher_id":101,"instrument_id":436},"action":"C","side":"A","price":"1.156530000","size":30,"channel_id":23,"order_id":"1775527922132446330","flags":0,"ts_in_delta":757,"sequence":151530,"symbol":"FCEU SI 20260615 PS"}
{"ts_recv":"2026-04-07T02:12:02.132541742Z","hd":{"ts_event":"2026-04-07T02:12:02.132522709Z","rtype":160,"publisher_id":101,"instrument_id":436},"action":"A","side":"A","price":"1.156520000","size":30,"channel_id":23,"order_id":"1775527922132528564","flags":128,"ts_in_delta":757,"sequence":151530,"symbol":"FCEU SI 20260615 PS"}
{"ts_recv":"2026-04-07T02:12:02.132599132Z","hd":{"ts_event":"2026-04-07T02:12:02.132582075Z","rtype":160,"publisher_id":101,"instrument_id":436},"action":"C","side":"B","price":"1.156420000","size":30,"channel_id":23,"order_id":"10998899958987304372","flags":0,"ts_in_delta":941,"sequence":151531,"symbol":"FCEU SI 20260615 PS"}
{"ts_recv":"2026-04-07T02:12:02.132599132Z","hd":{"ts_event":"2026-04-07T02:12:02.132582075Z","rtype":160,"publisher_id":101,"instrument_id":436},"action":"A","side":"B","price":"1.156430000","size":30,"channel_id":23,"order_id":"10998899958987363706","flags":0,"ts_in_delta":941,"sequence":151531,"symbol":"FCEU SI 20260615 PS"}
{"ts_recv":"2026-04-07T02:12:02.132599132Z","hd":{"ts_event":"2026-04-07T02:12:02.132582075Z","rtype":160,"publisher_id":101,"instrument_id":436},"action":"C","side":"A","price":"1.156520000","size":30,"channel_id":23,"order_id":"1775527922132528564","flags":0,"ts_in_delta":941,"sequence":151531,"symbol":"FCEU SI 20260615 PS"}
{"ts_recv":"2026-04-07T02:12:02.132599132Z","hd":{"ts_event":"2026-04-07T02:12:02.132582075Z","rtype":160,"publisher_id":101,"instrument_id":436},"action":"A","side":"A","price":"1.156530000","size":30,"channel_id":23,"order_id":"1775527922132587898","flags":128,"ts_in_delta":941,"sequence":151531,"symbol":"FCEU SI 20260615 PS"}
{"ts_recv":"2026-04-07T02:12:02.172179034Z","hd":{"ts_event":"2026-04-07T02:12:02.172163501Z","rtype":160,"publisher_id":101,"instrument_id":436},"action":"A","side":"A","price":"1.156700000","size":20,"channel_id":23,"order_id":"1775527922172169846","flags":128,"ts_in_delta":953,"sequence":151540,"symbol":"FCEU SI 20260615 PS"}
{"ts_recv":"2026-04-07T02:12:02.172199961Z","hd":{"ts_event":"2026-04-07T02:12:02.172184781Z","rtype":160,"publisher_id":101,"instrument_id":436},"action":"C","side":"A","price":"1.156800000","size":20,"channel_id":23,"order_id":"1775527871304137888","flags":128,"ts_in_delta":989,"sequence":151541,"symbol":"FCEU SI 20260615 PS"}
{"ts_recv":"2026-04-07T02:12:02.444603787Z","hd":{"ts_event":"2026-04-07T02:12:02.444584907Z","rtype":160,"publisher_id":101,"instrument_id":436},"action":"C","side":"B","price":"1.156430000","size":30,"channel_id":23,"order_id":"10998899958987363706","flags":0,"ts_in_delta":1026,"sequence":151561,"symbol":"FCEU SI 20260615 PS"}
{"ts_recv":"2026-04-07T02:12:02.444603787Z","hd":{"ts_event":"2026-04-07T02:12:02.444584907Z","rtype":160,"publisher_id":101,"instrument_id":436},"action":"A","side":"B","price":"1.156420000","size":30,"channel_id":23,"order_id":"10998899959299366531","flags":0,"ts_in_delta":1026,"sequence":151561,"symbol":"FCEU SI 20260615 PS"}
{"ts_recv":"2026-04-07T02:12:02.444603787Z","hd":{"ts_event":"2026-04-07T02:12:02.444584907Z","rtype":160,"publisher_id":101,"instrument_id":436},"action":"C","side":"A","price":"1.156530000","size":30,"channel_id":23,"order_id":"1775527922132587898","flags":0,"ts_in_delta":1026,"sequence":151561,"symbol":"FCEU SI 20260615 PS"}
{"ts_recv":"2026-04-07T02:12:02.444603787Z","hd":{"ts_event":"2026-04-07T02:12:02.444584907Z","rtype":160,"publisher_id":101,"instrument_id":436},"action":"A","side":"A","price":"1.156520000","size":30,"channel_id":23,"order_id":"1775527922444590723","flags":128,"ts_in_delta":1026,"sequence":151561,"symbol":"FCEU SI 20260615 PS"}
{"ts_recv":"2026-04-07T02:12:02.444658151Z","hd":{"ts_event":"2026-04-07T02:12:02.444637267Z","rtype":160,"publisher_id":101,"instrument_id":436},"action":"C","side":"B","price":"1.156440000","size":30,"channel_id":23,"order_id":"10998899958983668069","flags":0,"ts_in_delta":1158,"sequence":151562,"symbol":"FCEU SI 20260615 PS"}
{"ts_recv":"2026-04-07T02:12:02.444658151Z","hd":{"ts_event":"2026-04-07T02:12:02.444637267Z","rtype":160,"publisher_id":101,"instrument_id":436},"action":"A","side":"B","price":"1.156420000","size":30,"channel_id":23,"order_id":"10998899959299419352","flags":0,"ts_in_delta":1158,"sequence":151562,"symbol":"FCEU SI 20260615 PS"}
{"ts_recv":"2026-04-07T02:12:02.444658151Z","hd":{"ts_event":"2026-04-07T02:12:02.444637267Z","rtype":160,"publisher_id":101,"instrument_id":436},"action":"C","side":"A","price":"1.156540000","size":30,"channel_id":23,"order_id":"1775527922128892261","flags":0,"ts_in_delta":1158,"sequence":151562,"symbol":"FCEU SI 20260615 PS"}
{"ts_recv":"2026-04-07T02:12:02.444658151Z","hd":{"ts_event":"2026-04-07T02:12:02.444637267Z","rtype":160,"publisher_id":101,"instrument_id":436},"action":"A","side":"A","price":"1.156520000","size":30,"channel_id":23,"order_id":"1775527922444643544","flags":128,"ts_in_delta":1158,"sequence":151562,"symbol":"FCEU SI 20260615 PS"}
{"ts_recv":"2026-04-07T02:12:02.444717000Z","hd":{"ts_event":"2026-04-07T02:12:02.444697151Z","rtype":160,"publisher_id":101,"instrument_id":436},"action":"C","side":"B","price":"1.156420000","size":30,"channel_id":23,"order_id":"10998899959299366531","flags":0,"ts_in_delta":967,"sequence":151564,"symbol":"FCEU SI 20260615 PS"}
{"ts_recv":"2026-04-07T02:12:02.444717000Z","hd":{"ts_event":"2026-04-07T02:12:02.444697151Z","rtype":160,"publisher_id":101,"instrument_id":436},"action":"A","side":"B","price":"1.156410000","size":30,"channel_id":23,"order_id":"10998899959299478587","flags":0,"ts_in_delta":967,"sequence":151564,"symbol":"FCEU SI 20260615 PS"}
{"ts_recv":"2026-04-07T02:12:02.444717000Z","hd":{"ts_event":"2026-04-07T02:12:02.444697151Z","rtype":160,"publisher_id":101,"instrument_id":436},"action":"C","side":"A","price":"1.156520000","size":30,"channel_id":23,"order_id":"1775527922444590723","flags":0,"ts_in_delta":967,"sequence":151564,"symbol":"FCEU SI 20260615 PS"}
{"ts_recv":"2026-04-07T02:12:02.444717000Z","hd":{"ts_event":"2026-04-07T02:12:02.444697151Z","rtype":160,"publisher_id":101,"instrument_id":436},"action":"A","side":"A","price":"1.156510000","size":30,"channel_id":23,"order_id":"1775527922444702779","flags":128,"ts_in_delta":967,"sequence":151564,"symbol":"FCEU SI 20260615 PS"}
{"ts_recv":"2026-04-07T02:12:02.444781402Z","hd":{"ts_event":"2026-04-07T02:12:02.444762175Z","rtype":160,"publisher_id":101,"instrument_id":436},"action":"C","side":"B","price":"1.156410000","size":30,"channel_id":23,"order_id":"10998899959299478587","flags":0,"ts_in_delta":1003,"sequence":151565,"symbol":"FCEU SI 20260615 PS"}
{"ts_recv":"2026-04-07T02:12:02.444781402Z","hd":{"ts_event":"2026-04-07T02:12:02.444762175Z","rtype":160,"publisher_id":101,"instrument_id":436},"action":"A","side":"B","price":"1.156400000","size":30,"channel_id":23,"order_id":"10998899959299543824","flags":0,"ts_in_delta":1003,"sequence":151565,"symbol":"FCEU SI 20260615 PS"}
{"ts_recv":"2026-04-07T02:12:02.444781402Z","hd":{"ts_event":"2026-04-07T02:12:02.444762175Z","rtype":160,"publisher_id":101,"instrument_id":436},"action":"C","side":"A","price":"1.156510000","size":30,"channel_id":23,"order_id":"1775527922444702779","flags":0,"ts_in_delta":1003,"sequence":151565,"symbol":"FCEU SI 20260615 PS"}
{"ts_recv":"2026-04-07T02:12:02.444781402Z","hd":{"ts_event":"2026-04-07T02:12:02.444762175Z","rtype":160,"publisher_id":101,"instrument_id":436},"action":"A","side":"A","price":"1.156500000","size":30,"channel_id":23,"order_id":"1775527922444768016","flags":128,"ts_in_delta":1003,"sequence":151565,"symbol":"FCEU SI 20260615 PS"}
{"ts_recv":"2026-04-07T02:12:02.444834913Z","hd":{"ts_event":"2026-04-07T02:12:02.444817747Z","rtype":160,"publisher_id":101,"instrument_id":436},"action":"C","side":"B","price":"1.156400000","size":30,"channel_id":23,"order_id":"10998899959299543824","flags":0,"ts_in_delta":944,"sequence":151566,"symbol":"FCEU SI 20260615 PS"}
{"ts_recv":"2026-04-07T02:12:02.444834913Z","hd":{"ts_event":"2026-04-07T02:12:02.444817747Z","rtype":160,"publisher_id":101,"instrument_id":436},"action":"A","side":"B","price":"1.156410000","size":30,"channel_id":23,"order_id":"10998899959299599265","flags":0,"ts_in_delta":944,"sequence":151566,"symbol":"FCEU SI 20260615 PS"}
{"ts_recv":"2026-04-07T02:12:02.444834913Z","hd":{"ts_event":"2026-04-07T02:12:02.444817747Z","rtype":160,"publisher_id":101,"instrument_id":436},"action":"C","side":"A","price":"1.156500000","size":30,"channel_id":23,"order_id":"1775527922444768016","flags":0,"ts_in_delta":944,"sequence":151566,"symbol":"FCEU SI 20260615 PS"}
{"ts_recv":"2026-04-07T02:12:02.444834913Z","hd":{"ts_event":"2026-04-07T02:12:02.444817747Z","rtype":160,"publisher_id":101,"instrument_id":436},"action":"A","side":"A","price":"1.156510000","size":30,"channel_id":23,"order_id":"1775527922444823457","flags":128,"ts_in_delta":944,"sequence":151566,"symbol":"FCEU SI 20260615 PS"}
{"ts_recv":"2026-04-07T02:12:02.459330680Z","hd":{"ts_event":"2026-04-07T02:12:02.459312947Z","rtype":160,"publisher_id":101,"instrument_id":436},"action":"C","side":"B","price":"1.156410000","size":30,"channel_id":23,"order_id":"10998899959299599265","flags":0,"ts_in_delta":778,"sequence":151574,"symbol":"FCEU SI 20260615 PS"}
{"ts_recv":"2026-04-07T02:12:02.459330680Z","hd":{"ts_event":"2026-04-07T02:12:02.459312947Z","rtype":160,"publisher_id":101,"instrument_id":436},"action":"A","side":"B","price":"1.156400000","size":30,"channel_id":23,"order_id":"10998899959314094560","flags":0,"ts_in_delta":778,"sequence":151574,"symbol":"FCEU SI 20260615 PS"}
{"ts_recv":"2026-04-07T02:12:02.459330680Z","hd":{"ts_event":"2026-04-07T02:12:02.459312947Z","rtype":160,"publisher_id":101,"instrument_id":436},"action":"C","side":"A","price":"1.156510000","size":30,"channel_id":23,"order_id":"1775527922444823457","flags":0,"ts_in_delta":778,"sequence":151574,"symbol":"FCEU SI 20260615 PS"}
{"ts_recv":"2026-04-07T02:12:02.459330680Z","hd":{"ts_event":"2026-04-07T02:12:02.459312947Z","rtype":160,"publisher_id":101,"instrument_id":436},"action":"A","side":"A","price":"1.156500000","size":30,"channel_id":23,"order_id":"1775527922459318752","flags":128,"ts_in_delta":778,"sequence":151574,"symbol":"FCEU SI 20260615 PS"}
{"ts_recv":"2026-04-07T02:12:02.459380474Z","hd":{"ts_event":"2026-04-07T02:12:02.459363251Z","rtype":160,"publisher_id":101,"instrument_id":436},"action":"C","side":"B","price":"1.156420000","size":30,"channel_id":23,"order_id":"10998899959299419352","flags":0,"ts_in_delta":758,"sequence":151575,"symbol":"FCEU SI 20260615 PS"}
{"ts_recv":"2026-04-07T02:12:02.459380474Z","hd":{"ts_event":"2026-04-07T02:12:02.459363251Z","rtype":160,"publisher_id":101,"instrument_id":436},"action":"A","side":"B","price":"1.156400000","size":30,"channel_id":23,"order_id":"10998899959314144943","flags":0,"ts_in_delta":758,"sequence":151575,"symbol":"FCEU SI 20260615 PS"}
{"ts_recv":"2026-04-07T02:12:02.459380474Z","hd":{"ts_event":"2026-04-07T02:12:02.459363251Z","rtype":160,"publisher_id":101,"instrument_id":436},"action":"C","side":"A","price":"1.156520000","size":30,"channel_id":23,"order_id":"1775527922444643544","flags":0,"ts_in_delta":758,"sequence":151575,"symbol":"FCEU SI 20260615 PS"}
{"ts_recv":"2026-04-07T02:12:02.459380474Z","hd":{"ts_event":"2026-04-07T02:12:02.459363251Z","rtype":160,"publisher_id":101,"instrument_id":436},"action":"A","side":"A","price":"1.156500000","size":30,"channel_id":23,"order_id":"1775527922459369135","flags":128,"ts_in_delta":758,"sequence":151575,"symbol":"FCEU SI 20260615 PS"}
{"ts_recv":"2026-04-07T02:12:02.459434501Z","hd":{"ts_event":"2026-04-07T02:12:02.459415909Z","rtype":160,"publisher_id":101,"instrument_id":436},"action":"C","side":"B","price":"1.156400000","size":30,"channel_id":23,"order_id":"10998899959314094560","flags":0,"ts_in_delta":775,"sequence":151576,"symbol":"FCEU SI 20260615 PS"}
{"ts_recv":"2026-04-07T02:12:02.459434501Z","hd":{"ts_event":"2026-04-07T02:12:02.459415909Z","rtype":160,"publisher_id":101,"instrument_id":436},"action":"A","side":"B","price":"1.156390000","size":30,"channel_id":23,"order_id":"10998899959314197544","flags":0,"ts_in_delta":775,"sequence":151576,"symbol":"FCEU SI 20260615 PS"}
{"ts_recv":"2026-04-07T02:12:02.459434501Z","hd":{"ts_event":"2026-04-07T02:12:02.459415909Z","rtype":160,"publisher_id":101,"instrument_id":436},"action":"C","side":"A","price":"1.156500000","size":30,"channel_id":23,"order_id":"1775527922459318752","flags":0,"ts_in_delta":775,"sequence":151576,"symbol":"FCEU SI 20260615 PS"}
{"ts_recv":"2026-04-07T02:12:02.459434501Z","hd":{"ts_event":"2026-04-07T02:12:02.459415909Z","rtype":160,"publisher_id":101,"instrument_id":436},"action":"A","side":"A","price":"1.156490000","size":30,"channel_id":23,"order_id":"1775527922459421736","flags":128,"ts_in_delta":775,"sequence":151576,"symbol":"FCEU SI 20260615 PS"}
{"ts_recv":"2026-04-07T02:12:02.459489395Z","hd":{"ts_event":"2026-04-07T02:12:02.459472743Z","rtype":160,"publisher_id":101,"instrument_id":436},"action":"C","side":"B","price":"1.156390000","size":30,"channel_id":23,"order_id":"10998899959314197544","flags":0,"ts_in_delta":773,"sequence":151577,"symbol":"FCEU SI 20260615 PS"}
{"ts_recv":"2026-04-07T02:12:02.459489395Z","hd":{"ts_event":"2026-04-07T02:12:02.459472743Z","rtype":160,"publisher_id":101,"instrument_id":436},"action":"A","side":"B","price":"1.156380000","size":30,"channel_id":23,"order_id":"10998899959314254215","flags":0,"ts_in_delta":773,"sequence":151577,"symbol":"FCEU SI 20260615 PS"}
{"ts_recv":"2026-04-07T02:12:02.459489395Z","hd":{"ts_event":"2026-04-07T02:12:02.459472743Z","rtype":160,"publisher_id":101,"instrument_id":436},"action":"C","side":"A","price":"1.156490000","size":30,"channel_id":23,"order_id":"1775527922459421736","flags":0,"ts_in_delta":773,"sequence":151577,"symbol":"FCEU SI 20260615 PS"}
{"ts_recv":"2026-04-07T02:12:02.459489395Z","hd":{"ts_event":"2026-04-07T02:12:02.459472743Z","rtype":160,"publisher_id":101,"instrument_id":436},"action":"A","side":"A","price":"1.156480000","size":30,"channel_id":23,"order_id":"1775527922459478407","flags":128,"ts_in_delta":773,"sequence":151577,"symbol":"FCEU SI 20260615 PS"}
{"ts_recv":"2026-04-07T02:12:02.459542054Z","hd":{"ts_event":"2026-04-07T02:12:02.459525293Z","rtype":160,"publisher_id":101,"instrument_id":436},"action":"C","side":"B","price":"1.156380000","size":30,"channel_id":23,"order_id":"10998899959314254215","flags":0,"ts_in_delta":769,"sequence":151578,"symbol":"FCEU SI 20260615 PS"}
{"ts_recv":"2026-04-07T02:12:02.459542054Z","hd":{"ts_event":"2026-04-07T02:12:02.459525293Z","rtype":160,"publisher_id":101,"instrument_id":436},"action":"A","side":"B","price":"1.156390000","size":30,"channel_id":23,"order_id":"10998899959314307104","flags":0,"ts_in_delta":769,"sequence":151578,"symbol":"FCEU SI 20260615 PS"}
{"ts_recv":"2026-04-07T02:12:02.459542054Z","hd":{"ts_event":"2026-04-07T02:12:02.459525293Z","rtype":160,"publisher_id":101,"instrument_id":436},"action":"C","side":"A","price":"1.156480000","size":30,"channel_id":23,"order_id":"1775527922459478407","flags":0,"ts_in_delta":769,"sequence":151578,"symbol":"FCEU SI 20260615 PS"}
{"ts_recv":"2026-04-07T02:12:02.459542054Z","hd":{"ts_event":"2026-04-07T02:12:02.459525293Z","rtype":160,"publisher_id":101,"instrument_id":436},"action":"A","side":"A","price":"1.156490000","size":30,"channel_id":23,"order_id":"1775527922459531296","flags":128,"ts_in_delta":769,"sequence":151578,"symbol":"FCEU SI 20260615 PS"}
{"ts_recv":"2026-04-07T02:12:02.528811389Z","hd":{"ts_event":"2026-04-07T02:12:02.528794867Z","rtype":160,"publisher_id":101,"instrument_id":436},"action":"C","side":"B","price":"1.156390000","size":30,"channel_id":23,"order_id":"10998899959314307104","flags":0,"ts_in_delta":974,"sequence":151596,"symbol":"FCEU SI 20260615 PS"}
{"ts_recv":"2026-04-07T02:12:02.528811389Z","hd":{"ts_event":"2026-04-07T02:12:02.528794867Z","rtype":160,"publisher_id":101,"instrument_id":436},"action":"A","side":"B","price":"1.156400000","size":30,"channel_id":23,"order_id":"10998899959383576868","flags":0,"ts_in_delta":974,"sequence":151596,"symbol":"FCEU SI 20260615 PS"}
{"ts_recv":"2026-04-07T02:12:02.528811389Z","hd":{"ts_event":"2026-04-07T02:12:02.528794867Z","rtype":160,"publisher_id":101,"instrument_id":436},"action":"C","side":"A","price":"1.156490000","size":30,"channel_id":23,"order_id":"1775527922459531296","flags":0,"ts_in_delta":974,"sequence":151596,"symbol":"FCEU SI 20260615 PS"}
{"ts_recv":"2026-04-07T02:12:02.528811389Z","hd":{"ts_event":"2026-04-07T02:12:02.528794867Z","rtype":160,"publisher_id":101,"instrument_id":436},"action":"A","side":"A","price":"1.156500000","size":30,"channel_id":23,"order_id":"1775527922528801060","flags":128,"ts_in_delta":974,"sequence":151596,"symbol":"FCEU SI 20260615 PS"}
{"ts_recv":"2026-04-07T02:12:03.536632217Z","hd":{"ts_event":"2026-04-07T02:12:03.536601259Z","rtype":160,"publisher_id":101,"instrument_id":436},"action":"C","side":"B","price":"1.156400000","size":30,"channel_id":23,"order_id":"10998899959314144943","flags":0,"ts_in_delta":1358,"sequence":151615,"symbol":"FCEU SI 20260615 PS"}
{"ts_recv":"2026-04-07T02:12:03.536632217Z","hd":{"ts_event":"2026-04-07T02:12:03.536601259Z","rtype":160,"publisher_id":101,"instrument_id":436},"action":"A","side":"B","price":"1.156420000","size":30,"channel_id":23,"order_id":"10998899960391390105","flags":0,"ts_in_delta":1358,"sequence":151615,"symbol":"FCEU SI 20260615 PS"}
{"ts_recv":"2026-04-07T02:12:03.536632217Z","hd":{"ts_event":"2026-04-07T02:12:03.536601259Z","rtype":160,"publisher_id":101,"instrument_id":436},"action":"C","side":"A","price":"1.156500000","size":30,"channel_id":23,"order_id":"1775527922459369135","flags":0,"ts_in_delta":1358,"sequence":151615,"symbol":"FCEU SI 20260615 PS"}
{"ts_recv":"2026-04-07T02:12:03.536632217Z","hd":{"ts_event":"2026-04-07T02:12:03.536601259Z","rtype":160,"publisher_id":101,"instrument_id":436},"action":"A","side":"A","price":"1.156520000","size":30,"channel_id":23,"order_id":"1775527923536614297","flags":128,"ts_in_delta":1358,"sequence":151615,"symbol":"FCEU SI 20260615 PS"}
{"ts_recv":"2026-04-07T02:12:03.536741675Z","hd":{"ts_event":"2026-04-07T02:12:03.536725667Z","rtype":160,"publisher_id":101,"instrument_id":436},"action":"C","side":"B","price":"1.156400000","size":30,"channel_id":23,"order_id":"10998899959383576868","flags":0,"ts_in_delta":921,"sequence":151616,"symbol":"FCEU SI 20260615 PS"}
{"ts_recv":"2026-04-07T02:12:03.536741675Z","hd":{"ts_event":"2026-04-07T02:12:03.536725667Z","rtype":160,"publisher_id":101,"instrument_id":436},"action":"A","side":"B","price":"1.156410000","size":30,"channel_id":23,"order_id":"10998899960391507783","flags":0,"ts_in_delta":921,"sequence":151616,"symbol":"FCEU SI 20260615 PS"}
{"ts_recv":"2026-04-07T02:12:03.536741675Z","hd":{"ts_event":"2026-04-07T02:12:03.536725667Z","rtype":160,"publisher_id":101,"instrument_id":436},"action":"C","side":"A","price":"1.156500000","size":30,"channel_id":23,"order_id":"1775527922528801060","flags":0,"ts_in_delta":921,"sequence":151616,"symbol":"FCEU SI 20260615 PS"}
{"ts_recv":"2026-04-07T02:12:03.536741675Z","hd":{"ts_event":"2026-04-07T02:12:03.536725667Z","rtype":160,"publisher_id":101,"instrument_id":436},"action":"A","side":"A","price":"1.156510000","size":30,"channel_id":23,"order_id":"1775527923536731975","flags":128,"ts_in_delta":921,"sequence":151616,"symbol":"FCEU SI 20260615 PS"}
{"ts_recv":"2026-04-07T02:12:04.977395193Z","hd":{"ts_event":"2026-04-07T02:12:04.977375019Z","rtype":160,"publisher_id":101,"instrument_id":436},"action":"C","side":"B","price":"1.156410000","size":30,"channel_id":23,"order_id":"10998899960391507783","flags":0,"ts_in_delta":926,"sequence":151637,"symbol":"FCEU SI 20260615 PS"}
{"ts_recv":"2026-04-07T02:12:04.977395193Z","hd":{"ts_event":"2026-04-07T02:12:04.977375019Z","rtype":160,"publisher_id":101,"instrument_id":436},"action":"A","side":"B","price":"1.156420000","size":30,"channel_id":23,"order_id":"10998899961832157112","flags":0,"ts_in_delta":926,"sequence":151637,"symbol":"FCEU SI 20260615 PS"}
{"ts_recv":"2026-04-07T02:12:04.977395193Z","hd":{"ts_event":"2026-04-07T02:12:04.977375019Z","rtype":160,"publisher_id":101,"instrument_id":436},"action":"C","side":"A","price":"1.156510000","size":30,"channel_id":23,"order_id":"1775527923536731975","flags":0,"ts_in_delta":926,"sequence":151637,"symbol":"FCEU SI 20260615 PS"}
{"ts_recv":"2026-04-07T02:12:04.977395193Z","hd":{"ts_event":"2026-04-07T02:12:04.977375019Z","rtype":160,"publisher_id":101,"instrument_id":436},"action":"A","side":"A","price":"1.156520000","size":30,"channel_id":23,"order_id":"1775527924977381304","flags":128,"ts_in_delta":926,"sequence":151637,"symbol":"FCEU SI 20260615 PS"}
{"ts_recv":"2026-04-07T02:12:17.857189635Z","hd":{"ts_event":"2026-04-07T02:12:17.857161475Z","rtype":160,"publisher_id":101,"instrument_id":436},"action":"C","side":"B","price":"1.156420000","size":30,"channel_id":23,"order_id":"10998899961832157112","flags":0,"ts_in_delta":1006,"sequence":151726,"symbol":"FCEU SI 20260615 PS"}
{"ts_recv":"2026-04-07T02:12:17.857189635Z","hd":{"ts_event":"2026-04-07T02:12:17.857161475Z","rtype":160,"publisher_id":101,"instrument_id":436},"action":"A","side":"B","price":"1.156410000","size":30,"channel_id":23,"order_id":"10998899974711948278","flags":0,"ts_in_delta":1006,"sequence":151726,"symbol":"FCEU SI 20260615 PS"}
{"ts_recv":"2026-04-07T02:12:17.857189635Z","hd":{"ts_event":"2026-04-07T02:12:17.857161475Z","rtype":160,"publisher_id":101,"instrument_id":436},"action":"C","side":"A","price":"1.156520000","size":30,"channel_id":23,"order_id":"1775527924977381304","flags":0,"ts_in_delta":1006,"sequence":151726,"symbol":"FCEU SI 20260615 PS"}
{"ts_recv":"2026-04-07T02:12:17.857189635Z","hd":{"ts_event":"2026-04-07T02:12:17.857161475Z","rtype":160,"publisher_id":101,"instrument_id":436},"action":"A","side":"A","price":"1.156510000","size":30,"channel_id":23,"order_id":"1775527937857172470","flags":128,"ts_in_delta":1006,"sequence":151726,"symbol":"FCEU SI 20260615 PS"}
{"ts_recv":"2026-04-07T02:12:17.857273926Z","hd":{"ts_event":"2026-04-07T02:12:17.857253105Z","rtype":160,"publisher_id":101,"instrument_id":436},"action":"C","side":"B","price":"1.156410000","size":30,"channel_id":23,"order_id":"10998899974711948278","flags":0,"ts_in_delta":976,"sequence":151727,"symbol":"FCEU SI 20260615 PS"}
{"ts_recv":"2026-04-07T02:12:17.857273926Z","hd":{"ts_event":"2026-04-07T02:12:17.857253105Z","rtype":160,"publisher_id":101,"instrument_id":436},"action":"A","side":"B","price":"1.156400000","size":30,"channel_id":23,"order_id":"10998899974712034929","flags":0,"ts_in_delta":976,"sequence":151727,"symbol":"FCEU SI 20260615 PS"}
{"ts_recv":"2026-04-07T02:12:17.857273926Z","hd":{"ts_event":"2026-04-07T02:12:17.857253105Z","rtype":160,"publisher_id":101,"instrument_id":436},"action":"C","side":"A","price":"1.156510000","size":30,"channel_id":23,"order_id":"1775527937857172470","flags":0,"ts_in_delta":976,"sequence":151727,"symbol":"FCEU SI 20260615 PS"}
{"ts_recv":"2026-04-07T02:12:17.857273926Z","hd":{"ts_event":"2026-04-07T02:12:17.857253105Z","rtype":160,"publisher_id":101,"instrument_id":436},"action":"A","side":"A","price":"1.156500000","size":30,"channel_id":23,"order_id":"1775527937857259121","flags":128,"ts_in_delta":976,"sequence":151727,"symbol":"FCEU SI 20260615 PS"}
{"ts_recv":"2026-04-07T02:12:17.857331408Z","hd":{"ts_event":"2026-04-07T02:12:17.857313809Z","rtype":160,"publisher_id":101,"instrument_id":436},"action":"C","side":"B","price":"1.156400000","size":30,"channel_id":23,"order_id":"10998899974712034929","flags":0,"ts_in_delta":975,"sequence":151728,"symbol":"FCEU SI 20260615 PS"}
{"ts_recv":"2026-04-07T02:12:17.857331408Z","hd":{"ts_event":"2026-04-07T02:12:17.857313809Z","rtype":160,"publisher_id":101,"instrument_id":436},"action":"A","side":"B","price":"1.156410000","size":30,"channel_id":23,"order_id":"10998899974712095788","flags":0,"ts_in_delta":975,"sequence":151728,"symbol":"FCEU SI 20260615 PS"}
{"ts_recv":"2026-04-07T02:12:17.857331408Z","hd":{"ts_event":"2026-04-07T02:12:17.857313809Z","rtype":160,"publisher_id":101,"instrument_id":436},"action":"C","side":"A","price":"1.156500000","size":30,"channel_id":23,"order_id":"1775527937857259121","flags":0,"ts_in_delta":975,"sequence":151728,"symbol":"FCEU SI 20260615 PS"}
{"ts_recv":"2026-04-07T02:12:17.857331408Z","hd":{"ts_event":"2026-04-07T02:12:17.857313809Z","rtype":160,"publisher_id":101,"instrument_id":436},"action":"A","side":"A","price":"1.156510000","size":30,"channel_id":23,"order_id":"1775527937857319980","flags":128,"ts_in_delta":975,"sequence":151728,"symbol":"FCEU SI 20260615 PS"}
{"ts_recv":"2026-04-07T02:12:17.868859166Z","hd":{"ts_event":"2026-04-07T02:12:17.868840391Z","rtype":160,"publisher_id":101,"instrument_id":436},"action":"C","side":"B","price":"1.156410000","size":30,"channel_id":23,"order_id":"10998899974712095788","flags":0,"ts_in_delta":1122,"sequence":151742,"symbol":"FCEU SI 20260615 PS"}
{"ts_recv":"2026-04-07T02:12:17.868859166Z","hd":{"ts_event":"2026-04-07T02:12:17.868840391Z","rtype":160,"publisher_id":101,"instrument_id":436},"action":"A","side":"B","price":"1.156400000","size":30,"channel_id":23,"order_id":"10998899974723622232","flags":0,"ts_in_delta":1122,"sequence":151742,"symbol":"FCEU SI 20260615 PS"}
{"ts_recv":"2026-04-07T02:12:17.868859166Z","hd":{"ts_event":"2026-04-07T02:12:17.868840391Z","rtype":160,"publisher_id":101,"instrument_id":436},"action":"C","side":"A","price":"1.156510000","size":30,"channel_id":23,"order_id":"1775527937857319980","flags":0,"ts_in_delta":1122,"sequence":151742,"symbol":"FCEU SI 20260615 PS"}
{"ts_recv":"2026-04-07T02:12:17.868859166Z","hd":{"ts_event":"2026-04-07T02:12:17.868840391Z","rtype":160,"publisher_id":101,"instrument_id":436},"action":"A","side":"A","price":"1.156500000","size":30,"channel_id":23,"order_id":"1775527937868846424","flags":128,"ts_in_delta":1122,"sequence":151742,"symbol":"FCEU SI 20260615 PS"}
{"ts_recv":"2026-04-07T02:12:17.868917347Z","hd":{"ts_event":"2026-04-07T02:12:17.868900929Z","rtype":160,"publisher_id":101,"instrument_id":436},"action":"C","side":"B","price":"1.156420000","size":30,"channel_id":23,"order_id":"10998899960391390105","flags":0,"ts_in_delta":943,"sequence":151743,"symbol":"FCEU SI 20260615 PS"}
{"ts_recv":"2026-04-07T02:12:17.868917347Z","hd":{"ts_event":"2026-04-07T02:12:17.868900929Z","rtype":160,"publisher_id":101,"instrument_id":436},"action":"A","side":"B","price":"1.156400000","size":30,"channel_id":23,"order_id":"10998899974723682404","flags":0,"ts_in_delta":943,"sequence":151743,"symbol":"FCEU SI 20260615 PS"}
{"ts_recv":"2026-04-07T02:12:17.868917347Z","hd":{"ts_event":"2026-04-07T02:12:17.868900929Z","rtype":160,"publisher_id":101,"instrument_id":436},"action":"C","side":"A","price":"1.156520000","size":30,"channel_id":23,"order_id":"1775527923536614297","flags":0,"ts_in_delta":943,"sequence":151743,"symbol":"FCEU SI 20260615 PS"}
{"ts_recv":"2026-04-07T02:12:17.868917347Z","hd":{"ts_event":"2026-04-07T02:12:17.868900929Z","rtype":160,"publisher_id":101,"instrument_id":436},"action":"A","side":"A","price":"1.156500000","size":30,"channel_id":23,"order_id":"1775527937868906596","flags":128,"ts_in_delta":943,"sequence":151743,"symbol":"FCEU SI 20260615 PS"}
{"ts_recv":"2026-04-07T02:12:17.868973478Z","hd":{"ts_event":"2026-04-07T02:12:17.868954543Z","rtype":160,"publisher_id":101,"instrument_id":436},"action":"C","side":"B","price":"1.156400000","size":30,"channel_id":23,"order_id":"10998899974723622232","flags":0,"ts_in_delta":939,"sequence":151744,"symbol":"FCEU SI 20260615 PS"}
{"ts_recv":"2026-04-07T02:12:17.868973478Z","hd":{"ts_event":"2026-04-07T02:12:17.868954543Z","rtype":160,"publisher_id":101,"instrument_id":436},"action":"A","side":"B","price":"1.156390000","size":30,"channel_id":23,"order_id":"10998899974723736218","flags":0,"ts_in_delta":939,"sequence":151744,"symbol":"FCEU SI 20260615 PS"}
{"ts_recv":"2026-04-07T02:12:17.868973478Z","hd":{"ts_event":"2026-04-07T02:12:17.868954543Z","rtype":160,"publisher_id":101,"instrument_id":436},"action":"C","side":"A","price":"1.156500000","size":30,"channel_id":23,"order_id":"1775527937868846424","flags":0,"ts_in_delta":939,"sequence":151744,"symbol":"FCEU SI 20260615 PS"}
{"ts_recv":"2026-04-07T02:12:17.868973478Z","hd":{"ts_event":"2026-04-07T02:12:17.868954543Z","rtype":160,"publisher_id":101,"instrument_id":436},"action":"A","side":"A","price":"1.156490000","size":30,"channel_id":23,"order_id":"1775527937868960410","flags":128,"ts_in_delta":939,"sequence":151744,"symbol":"FCEU SI 20260615 PS"}
{"ts_recv":"2026-04-07T02:12:17.869034431Z","hd":{"ts_event":"2026-04-07T02:12:17.869013985Z","rtype":160,"publisher_id":101,"instrument_id":436},"action":"C","side":"B","price":"1.156390000","size":30,"channel_id":23,"order_id":"10998899974723736218","flags":0,"ts_in_delta":943,"sequence":151745,"symbol":"FCEU SI 20260615 PS"}
{"ts_recv":"2026-04-07T02:12:17.869034431Z","hd":{"ts_event":"2026-04-07T02:12:17.869013985Z","rtype":160,"publisher_id":101,"instrument_id":436},"action":"A","side":"B","price":"1.156370000","size":30,"channel_id":23,"order_id":"10998899974723795579","flags":0,"ts_in_delta":943,"sequence":151745,"symbol":"FCEU SI 20260615 PS"}
{"ts_recv":"2026-04-07T02:12:17.869034431Z","hd":{"ts_event":"2026-04-07T02:12:17.869013985Z","rtype":160,"publisher_id":101,"instrument_id":436},"action":"C","side":"A","price":"1.156490000","size":30,"channel_id":23,"order_id":"1775527937868960410","flags":0,"ts_in_delta":943,"sequence":151745,"symbol":"FCEU SI 20260615 PS"}
{"ts_recv":"2026-04-07T02:12:17.869034431Z","hd":{"ts_event":"2026-04-07T02:12:17.869013985Z","rtype":160,"publisher_id":101,"instrument_id":436},"action":"A","side":"A","price":"1.156470000","size":30,"channel_id":23,"order_id":"1775527937869019771","flags":128,"ts_in_delta":943,"sequence":151745,"symbol":"FCEU SI 20260615 PS"}
{"ts_recv":"2026-04-07T02:12:17.869086315Z","hd":{"ts_event":"2026-04-07T02:12:17.869070109Z","rtype":160,"publisher_id":101,"instrument_id":436},"action":"C","side":"B","price":"1.156370000","size":30,"channel_id":23,"order_id":"10998899974723795579","flags":0,"ts_in_delta":962,"sequence":151746,"symbol":"FCEU SI 20260615 PS"}
{"ts_recv":"2026-04-07T02:12:17.869086315Z","hd":{"ts_event":"2026-04-07T02:12:17.869070109Z","rtype":160,"publisher_id":101,"instrument_id":436},"action":"A","side":"B","price":"1.156390000","size":30,"channel_id":23,"order_id":"10998899974723851530","flags":0,"ts_in_delta":962,"sequence":151746,"symbol":"FCEU SI 20260615 PS"}
{"ts_recv":"2026-04-07T02:12:17.869086315Z","hd":{"ts_event":"2026-04-07T02:12:17.869070109Z","rtype":160,"publisher_id":101,"instrument_id":436},"action":"C","side":"A","price":"1.156470000","size":30,"channel_id":23,"order_id":"1775527937869019771","flags":0,"ts_in_delta":962,"sequence":151746,"symbol":"FCEU SI 20260615 PS"}
{"ts_recv":"2026-04-07T02:12:17.869086315Z","hd":{"ts_event":"2026-04-07T02:12:17.869070109Z","rtype":160,"publisher_id":101,"instrument_id":436},"action":"A","side":"A","price":"1.156490000","size":30,"channel_id":23,"order_id":"1775527937869075722","flags":128,"ts_in_delta":962,"sequence":151746,"symbol":"FCEU SI 20260615 PS"}
{"ts_recv":"2026-04-07T02:12:18.207157701Z","hd":{"ts_event":"2026-04-07T02:12:18.207139751Z","rtype":160,"publisher_id":101,"instrument_id":436},"action":"C","side":"B","price":"1.156400000","size":30,"channel_id":23,"order_id":"10998899974723682404","flags":0,"ts_in_delta":918,"sequence":151774,"symbol":"FCEU SI 20260615 PS"}
{"ts_recv":"2026-04-07T02:12:18.207157701Z","hd":{"ts_event":"2026-04-07T02:12:18.207139751Z","rtype":160,"publisher_id":101,"instrument_id":436},"action":"A","side":"B","price":"1.156380000","size":30,"channel_id":23,"order_id":"10998899975061921661","flags":0,"ts_in_delta":918,"sequence":151774,"symbol":"FCEU SI 20260615 PS"}
{"ts_recv":"2026-04-07T02:12:18.207157701Z","hd":{"ts_event":"2026-04-07T02:12:18.207139751Z","rtype":160,"publisher_id":101,"instrument_id":436},"action":"C","side":"A","price":"1.156500000","size":30,"channel_id":23,"order_id":"1775527937868906596","flags":0,"ts_in_delta":918,"sequence":151774,"symbol":"FCEU SI 20260615 PS"}
{"ts_recv":"2026-04-07T02:12:18.207157701Z","hd":{"ts_event":"2026-04-07T02:12:18.207139751Z","rtype":160,"publisher_id":101,"instrument_id":436},"action":"A","side":"A","price":"1.156480000","size":30,"channel_id":23,"order_id":"1775527938207145853","flags":128,"ts_in_delta":918,"sequence":151774,"symbol":"FCEU SI 20260615 PS"}
{"ts_recv":"2026-04-07T02:12:18.207229720Z","hd":{"ts_event":"2026-04-07T02:12:18.207213205Z","rtype":160,"publisher_id":101,"instrument_id":436},"action":"C","side":"B","price":"1.156390000","size":30,"channel_id":23,"order_id":"10998899974723851530","flags":0,"ts_in_delta":1135,"sequence":151775,"symbol":"FCEU SI 20260615 PS"}
{"ts_recv":"2026-04-07T02:12:18.207229720Z","hd":{"ts_event":"2026-04-07T02:12:18.207213205Z","rtype":160,"publisher_id":101,"instrument_id":436},"action":"A","side":"B","price":"1.156380000","size":30,"channel_id":23,"order_id":"10998899975061995252","flags":0,"ts_in_delta":1135,"sequence":151775,"symbol":"FCEU SI 20260615 PS"}
{"ts_recv":"2026-04-07T02:12:18.207229720Z","hd":{"ts_event":"2026-04-07T02:12:18.207213205Z","rtype":160,"publisher_id":101,"instrument_id":436},"action":"C","side":"A","price":"1.156490000","size":30,"channel_id":23,"order_id":"1775527937869075722","flags":0,"ts_in_delta":1135,"sequence":151775,"symbol":"FCEU SI 20260615 PS"}
{"ts_recv":"2026-04-07T02:12:18.207229720Z","hd":{"ts_event":"2026-04-07T02:12:18.207213205Z","rtype":160,"publisher_id":101,"instrument_id":436},"action":"A","side":"A","price":"1.156480000","size":30,"channel_id":23,"order_id":"1775527938207219444","flags":128,"ts_in_delta":1135,"sequence":151775,"symbol":"FCEU SI 20260615 PS"}
{"ts_recv":"2026-04-07T02:12:18.208184285Z","hd":{"ts_event":"2026-04-07T02:12:18.208164885Z","rtype":160,"publisher_id":101,"instrument_id":436},"action":"C","side":"B","price":"1.156380000","size":30,"channel_id":23,"order_id":"10998899975061995252","flags":0,"ts_in_delta":953,"sequence":151776,"symbol":"FCEU SI 20260615 PS"}
{"ts_recv":"2026-04-07T02:12:18.208184285Z","hd":{"ts_event":"2026-04-07T02:12:18.208164885Z","rtype":160,"publisher_id":101,"instrument_id":436},"action":"A","side":"B","price":"1.156370000","size":30,"channel_id":23,"order_id":"10998899975062946505","flags":0,"ts_in_delta":953,"sequence":151776,"symbol":"FCEU SI 20260615 PS"}
{"ts_recv":"2026-04-07T02:12:18.208184285Z","hd":{"ts_event":"2026-04-07T02:12:18.208164885Z","rtype":160,"publisher_id":101,"instrument_id":436},"action":"C","side":"A","price":"1.156480000","size":30,"channel_id":23,"order_id":"1775527938207219444","flags":0,"ts_in_delta":953,"sequence":151776,"symbol":"FCEU SI 20260615 PS"}
{"ts_recv":"2026-04-07T02:12:18.208184285Z","hd":{"ts_event":"2026-04-07T02:12:18.208164885Z","rtype":160,"publisher_id":101,"instrument_id":436},"action":"A","side":"A","price":"1.156470000","size":30,"channel_id":23,"order_id":"1775527938208170697","flags":128,"ts_in_delta":953,"sequence":151776,"symbol":"FCEU SI 20260615 PS"}
{"ts_recv":"2026-04-07T02:12:18.208263025Z","hd":{"ts_event":"2026-04-07T02:12:18.208243389Z","rtype":160,"publisher_id":101,"instrument_id":436},"action":"C","side":"B","price":"1.156370000","size":30,"channel_id":23,"order_id":"10998899975062946505","flags":0,"ts_in_delta":1132,"sequence":151777,"symbol":"FCEU SI 20260615 PS"}
{"ts_recv":"2026-04-07T02:12:18.208263025Z","hd":{"ts_event":"2026-04-07T02:12:18.208243389Z","rtype":160,"publisher_id":101,"instrument_id":436},"action":"A","side":"B","price":"1.156360000","size":30,"channel_id":23,"order_id":"10998899975063025167","flags":0,"ts_in_delta":1132,"sequence":151777,"symbol":"FCEU SI 20260615 PS"}
{"ts_recv":"2026-04-07T02:12:18.208263025Z","hd":{"ts_event":"2026-04-07T02:12:18.208243389Z","rtype":160,"publisher_id":101,"instrument_id":436},"action":"C","side":"A","price":"1.156470000","size":30,"channel_id":23,"order_id":"1775527938208170697","flags":0,"ts_in_delta":1132,"sequence":151777,"symbol":"FCEU SI 20260615 PS"}
{"ts_recv":"2026-04-07T02:12:18.208263025Z","hd":{"ts_event":"2026-04-07T02:12:18.208243389Z","rtype":160,"publisher_id":101,"instrument_id":436},"action":"A","side":"A","price":"1.156460000","size":30,"channel_id":23,"order_id":"1775527938208249359","flags":128,"ts_in_delta":1132,"sequence":151777,"symbol":"FCEU SI 20260615 PS"}
{"ts_recv":"2026-04-07T02:12:18.208318994Z","hd":{"ts_event":"2026-04-07T02:12:18.208303563Z","rtype":160,"publisher_id":101,"instrument_id":436},"action":"C","side":"B","price":"1.156360000","size":30,"channel_id":23,"order_id":"10998899975063025167","flags":0,"ts_in_delta":973,"sequence":151778,"symbol":"FCEU SI 20260615 PS"}
{"ts_recv":"2026-04-07T02:12:18.208318994Z","hd":{"ts_event":"2026-04-07T02:12:18.208303563Z","rtype":160,"publisher_id":101,"instrument_id":436},"action":"A","side":"B","price":"1.156370000","size":30,"channel_id":23,"order_id":"10998899975063085338","flags":0,"ts_in_delta":973,"sequence":151778,"symbol":"FCEU SI 20260615 PS"}
{"ts_recv":"2026-04-07T02:12:18.208318994Z","hd":{"ts_event":"2026-04-07T02:12:18.208303563Z","rtype":160,"publisher_id":101,"instrument_id":436},"action":"C","side":"A","price":"1.156460000","size":30,"channel_id":23,"order_id":"1775527938208249359","flags":0,"ts_in_delta":973,"sequence":151778,"symbol":"FCEU SI 20260615 PS"}
{"ts_recv":"2026-04-07T02:12:18.208318994Z","hd":{"ts_event":"2026-04-07T02:12:18.208303563Z","rtype":160,"publisher_id":101,"instrument_id":436},"action":"A","side":"A","price":"1.156470000","size":30,"channel_id":23,"order_id":"1775527938208309530","flags":128,"ts_in_delta":973,"sequence":151778,"symbol":"FCEU SI 20260615 PS"}
{"ts_recv":"2026-04-07T02:12:40.017967987Z","hd":{"ts_event":"2026-04-07T02:12:40.017944217Z","rtype":160,"publisher_id":101,"instrument_id":436},"action":"C","side":"B","price":"1.156370000","size":30,"channel_id":23,"order_id":"10998899975063085338","flags":0,"ts_in_delta":900,"sequence":151965,"symbol":"FCEU SI 20260615 PS"}
{"ts_recv":"2026-04-07T02:12:40.017967987Z","hd":{"ts_event":"2026-04-07T02:12:40.017944217Z","rtype":160,"publisher_id":101,"instrument_id":436},"action":"A","side":"B","price":"1.156360000","size":30,"channel_id":23,"order_id":"10998899996872726491","flags":0,"ts_in_delta":900,"sequence":151965,"symbol":"FCEU SI 20260615 PS"}
{"ts_recv":"2026-04-07T02:12:40.017967987Z","hd":{"ts_event":"2026-04-07T02:12:40.017944217Z","rtype":160,"publisher_id":101,"instrument_id":436},"action":"C","side":"A","price":"1.156470000","size":30,"channel_id":23,"order_id":"1775527938208309530","flags":0,"ts_in_delta":900,"sequence":151965,"symbol":"FCEU SI 20260615 PS"}
{"ts_recv":"2026-04-07T02:12:40.017967987Z","hd":{"ts_event":"2026-04-07T02:12:40.017944217Z","rtype":160,"publisher_id":101,"instrument_id":436},"action":"A","side":"A","price":"1.156460000","size":30,"channel_id":23,"order_id":"1775527960017950683","flags":128,"ts_in_delta":900,"sequence":151965,"symbol":"FCEU SI 20260615 PS"}
{"ts_recv":"2026-04-07T02:12:40.018021983Z","hd":{"ts_event":"2026-04-07T02:12:40.018004293Z","rtype":160,"publisher_id":101,"instrument_id":436},"action":"C","side":"B","price":"1.156380000","size":30,"channel_id":23,"order_id":"10998899975061921661","flags":0,"ts_in_delta":914,"sequence":151966,"symbol":"FCEU SI 20260615 PS"}
{"ts_recv":"2026-04-07T02:12:40.018021983Z","hd":{"ts_event":"2026-04-07T02:12:40.018004293Z","rtype":160,"publisher_id":101,"instrument_id":436},"action":"A","side":"B","price":"1.156360000","size":30,"channel_id":23,"order_id":"10998899996872785945","flags":0,"ts_in_delta":914,"sequence":151966,"symbol":"FCEU SI 20260615 PS"}
{"ts_recv":"2026-04-07T02:12:40.018021983Z","hd":{"ts_event":"2026-04-07T02:12:40.018004293Z","rtype":160,"publisher_id":101,"instrument_id":436},"action":"C","side":"A","price":"1.156480000","size":30,"channel_id":23,"order_id":"1775527938207145853","flags":0,"ts_in_delta":914,"sequence":151966,"symbol":"FCEU SI 20260615 PS"}
{"ts_recv":"2026-04-07T02:12:40.018021983Z","hd":{"ts_event":"2026-04-07T02:12:40.018004293Z","rtype":160,"publisher_id":101,"instrument_id":436},"action":"A","side":"A","price":"1.156460000","size":30,"channel_id":23,"order_id":"1775527960018010137","flags":128,"ts_in_delta":914,"sequence":151966,"symbol":"FCEU SI 20260615 PS"}
{"ts_recv":"2026-04-07T02:12:40.018076178Z","hd":{"ts_event":"2026-04-07T02:12:40.018059033Z","rtype":160,"publisher_id":101,"instrument_id":436},"action":"C","side":"B","price":"1.156360000","size":30,"channel_id":23,"order_id":"10998899996872726491","flags":0,"ts_in_delta":900,"sequence":151967,"symbol":"FCEU SI 20260615 PS"}
{"ts_recv":"2026-04-07T02:12:40.018076178Z","hd":{"ts_event":"2026-04-07T02:12:40.018059033Z","rtype":160,"publisher_id":101,"instrument_id":436},"action":"A","side":"B","price":"1.156350000","size":30,"channel_id":23,"order_id":"10998899996872840832","flags":0,"ts_in_delta":900,"sequence":151967,"symbol":"FCEU SI 20260615 PS"}
{"ts_recv":"2026-04-07T02:12:40.018076178Z","hd":{"ts_event":"2026-04-07T02:12:40.018059033Z","rtype":160,"publisher_id":101,"instrument_id":436},"action":"C","side":"A","price":"1.156460000","size":30,"channel_id":23,"order_id":"1775527960017950683","flags":0,"ts_in_delta":900,"sequence":151967,"symbol":"FCEU SI 20260615 PS"}
{"ts_recv":"2026-04-07T02:12:40.018076178Z","hd":{"ts_event":"2026-04-07T02:12:40.018059033Z","rtype":160,"publisher_id":101,"instrument_id":436},"action":"A","side":"A","price":"1.156450000","size":30,"channel_id":23,"order_id":"1775527960018065024","flags":128,"ts_in_delta":900,"sequence":151967,"symbol":"FCEU SI 20260615 PS"}
{"ts_recv":"2026-04-07T02:12:40.018161330Z","hd":{"ts_event":"2026-04-07T02:12:40.018139861Z","rtype":160,"publisher_id":101,"instrument_id":436},"action":"C","side":"B","price":"1.156350000","size":30,"channel_id":23,"order_id":"10998899996872840832","flags":0,"ts_in_delta":1015,"sequence":151968,"symbol":"FCEU SI 20260615 PS"}
{"ts_recv":"2026-04-07T02:12:40.018161330Z","hd":{"ts_event":"2026-04-07T02:12:40.018139861Z","rtype":160,"publisher_id":101,"instrument_id":436},"action":"A","side":"B","price":"1.156340000","size":30,"channel_id":23,"order_id":"10998899996872921483","flags":0,"ts_in_delta":1015,"sequence":151968,"symbol":"FCEU SI 20260615 PS"}
{"ts_recv":"2026-04-07T02:12:40.018161330Z","hd":{"ts_event":"2026-04-07T02:12:40.018139861Z","rtype":160,"publisher_id":101,"instrument_id":436},"action":"C","side":"A","price":"1.156450000","size":30,"channel_id":23,"order_id":"1775527960018065024","flags":0,"ts_in_delta":1015,"sequence":151968,"symbol":"FCEU SI 20260615 PS"}
{"ts_recv":"2026-04-07T02:12:40.018161330Z","hd":{"ts_event":"2026-04-07T02:12:40.018139861Z","rtype":160,"publisher_id":101,"instrument_id":436},"action":"A","side":"A","price":"1.156440000","size":30,"channel_id":23,"order_id":"1775527960018145675","flags":128,"ts_in_delta":1015,"sequence":151968,"symbol":"FCEU SI 20260615 PS"}
{"ts_recv":"2026-04-07T02:12:40.018215126Z","hd":{"ts_event":"2026-04-07T02:12:40.018199899Z","rtype":160,"publisher_id":101,"instrument_id":436},"action":"C","side":"B","price":"1.156340000","size":30,"channel_id":23,"order_id":"10998899996872921483","flags":0,"ts_in_delta":896,"sequence":151969,"symbol":"FCEU SI 20260615 PS"}
{"ts_recv":"2026-04-07T02:12:40.018215126Z","hd":{"ts_event":"2026-04-07T02:12:40.018199899Z","rtype":160,"publisher_id":101,"instrument_id":436},"action":"A","side":"B","price":"1.156350000","size":30,"channel_id":23,"order_id":"10998899996872981549","flags":0,"ts_in_delta":896,"sequence":151969,"symbol":"FCEU SI 20260615 PS"}
{"ts_recv":"2026-04-07T02:12:40.018215126Z","hd":{"ts_event":"2026-04-07T02:12:40.018199899Z","rtype":160,"publisher_id":101,"instrument_id":436},"action":"C","side":"A","price":"1.156440000","size":30,"channel_id":23,"order_id":"1775527960018145675","flags":0,"ts_in_delta":896,"sequence":151969,"symbol":"FCEU SI 20260615 PS"}
{"ts_recv":"2026-04-07T02:12:40.018215126Z","hd":{"ts_event":"2026-04-07T02:12:40.018199899Z","rtype":160,"publisher_id":101,"instrument_id":436},"action":"A","side":"A","price":"1.156450000","size":30,"channel_id":23,"order_id":"1775527960018205741","flags":128,"ts_in_delta":896,"sequence":151969,"symbol":"FCEU SI 20260615 PS"}
{"ts_recv":"2026-04-07T02:12:42.075597480Z","hd":{"ts_event":"2026-04-07T02:12:42.075574777Z","rtype":160,"publisher_id":101,"instrument_id":436},"action":"A","side":"A","price":"1.156600000","size":20,"channel_id":23,"order_id":"1775527962075583562","flags":128,"ts_in_delta":1347,"sequence":152016,"symbol":"FCEU SI 20260615 PS"}
{"ts_recv":"2026-04-07T02:12:42.075602395Z","hd":{"ts_event":"2026-04-07T02:12:42.075585069Z","rtype":160,"publisher_id":101,"instrument_id":436},"action":"C","side":"A","price":"1.156700000","size":20,"channel_id":23,"order_id":"1775527922172169846","flags":128,"ts_in_delta":776,"sequence":152017,"symbol":"FCEU SI 20260615 PS"}
{"ts_recv":"2026-04-07T02:12:43.823437652Z","hd":{"ts_event":"2026-04-07T02:12:43.823416737Z","rtype":160,"publisher_id":101,"instrument_id":436},"action":"C","side":"B","price":"1.156360000","size":30,"channel_id":23,"order_id":"10998899996872785945","flags":0,"ts_in_delta":1187,"sequence":152035,"symbol":"FCEU SI 20260615 PS"}
{"ts_recv":"2026-04-07T02:12:43.823437652Z","hd":{"ts_event":"2026-04-07T02:12:43.823416737Z","rtype":160,"publisher_id":101,"instrument_id":436},"action":"A","side":"B","price":"1.156340000","size":30,"channel_id":23,"order_id":"10998900000678198255","flags":0,"ts_in_delta":1187,"sequence":152035,"symbol":"FCEU SI 20260615 PS"}
{"ts_recv":"2026-04-07T02:12:43.823437652Z","hd":{"ts_event":"2026-04-07T02:12:43.823416737Z","rtype":160,"publisher_id":101,"instrument_id":436},"action":"C","side":"A","price":"1.156460000","size":30,"channel_id":23,"order_id":"1775527960018010137","flags":0,"ts_in_delta":1187,"sequence":152035,"symbol":"FCEU SI 20260615 PS"}
{"ts_recv":"2026-04-07T02:12:43.823437652Z","hd":{"ts_event":"2026-04-07T02:12:43.823416737Z","rtype":160,"publisher_id":101,"instrument_id":436},"action":"A","side":"A","price":"1.156440000","size":30,"channel_id":23,"order_id":"1775527963823422447","flags":128,"ts_in_delta":1187,"sequence":152035,"symbol":"FCEU SI 20260615 PS"}
{"ts_recv":"2026-04-07T02:12:43.823516253Z","hd":{"ts_event":"2026-04-07T02:12:43.823497435Z","rtype":160,"publisher_id":101,"instrument_id":436},"action":"C","side":"B","price":"1.156350000","size":30,"channel_id":23,"order_id":"10998899996872981549","flags":0,"ts_in_delta":935,"sequence":152036,"symbol":"FCEU SI 20260615 PS"}
{"ts_recv":"2026-04-07T02:12:43.823516253Z","hd":{"ts_event":"2026-04-07T02:12:43.823497435Z","rtype":160,"publisher_id":101,"instrument_id":436},"action":"A","side":"B","price":"1.156340000","size":30,"channel_id":23,"order_id":"10998900000678279451","flags":0,"ts_in_delta":935,"sequence":152036,"symbol":"FCEU SI 20260615 PS"}
{"ts_recv":"2026-04-07T02:12:43.823516253Z","hd":{"ts_event":"2026-04-07T02:12:43.823497435Z","rtype":160,"publisher_id":101,"instrument_id":436},"action":"C","side":"A","price":"1.156450000","size":30,"channel_id":23,"order_id":"1775527960018205741","flags":0,"ts_in_delta":935,"sequence":152036,"symbol":"FCEU SI 20260615 PS"}
{"ts_recv":"2026-04-07T02:12:43.823516253Z","hd":{"ts_event":"2026-04-07T02:12:43.823497435Z","rtype":160,"publisher_id":101,"instrument_id":436},"action":"A","side":"A","price":"1.156440000","size":30,"channel_id":23,"order_id":"1775527963823503643","flags":128,"ts_in_delta":935,"sequence":152036,"symbol":"FCEU SI 20260615 PS"}
{"ts_recv":"2026-04-07T02:12:43.827736135Z","hd":{"ts_event":"2026-04-07T02:12:43.827716071Z","rtype":160,"publisher_id":101,"instrument_id":436},"action":"C","side":"B","price":"1.156340000","size":30,"channel_id":23,"order_id":"10998900000678279451","flags":0,"ts_in_delta":900,"sequence":152039,"symbol":"FCEU SI 20260615 PS"}
{"ts_recv":"2026-04-07T02:12:43.827736135Z","hd":{"ts_event":"2026-04-07T02:12:43.827716071Z","rtype":160,"publisher_id":101,"instrument_id":436},"action":"A","side":"B","price":"1.156330000","size":30,"channel_id":23,"order_id":"10998900000682498209","flags":0,"ts_in_delta":900,"sequence":152039,"symbol":"FCEU SI 20260615 PS"}
{"ts_recv":"2026-04-07T02:12:43.827736135Z","hd":{"ts_event":"2026-04-07T02:12:43.827716071Z","rtype":160,"publisher_id":101,"instrument_id":436},"action":"C","side":"A","price":"1.156440000","size":30,"channel_id":23,"order_id":"1775527963823503643","flags":0,"ts_in_delta":900,"sequence":152039,"symbol":"FCEU SI 20260615 PS"}
{"ts_recv":"2026-04-07T02:12:43.827736135Z","hd":{"ts_event":"2026-04-07T02:12:43.827716071Z","rtype":160,"publisher_id":101,"instrument_id":436},"action":"A","side":"A","price":"1.156430000","size":30,"channel_id":23,"order_id":"1775527963827722401","flags":128,"ts_in_delta":900,"sequence":152039,"symbol":"FCEU SI 20260615 PS"}
{"ts_recv":"2026-04-07T02:12:56.539285354Z","hd":{"ts_event":"2026-04-07T02:12:56.539264999Z","rtype":160,"publisher_id":101,"instrument_id":436},"action":"C","side":"B","price":"1.156330000","size":30,"channel_id":23,"order_id":"10998900000682498209","flags":0,"ts_in_delta":1031,"sequence":152267,"symbol":"FCEU SI 20260615 PS"}
{"ts_recv":"2026-04-07T02:12:56.539285354Z","hd":{"ts_event":"2026-04-07T02:12:56.539264999Z","rtype":160,"publisher_id":101,"instrument_id":436},"action":"A","side":"B","price":"1.156340000","size":30,"channel_id":23,"order_id":"10998900013394046619","flags":0,"ts_in_delta":1031,"sequence":152267,"symbol":"FCEU SI 20260615 PS"}
{"ts_recv":"2026-04-07T02:12:56.539285354Z","hd":{"ts_event":"2026-04-07T02:12:56.539264999Z","rtype":160,"publisher_id":101,"instrument_id":436},"action":"C","side":"A","price":"1.156430000","size":30,"channel_id":23,"order_id":"1775527963827722401","flags":0,"ts_in_delta":1031,"sequence":152267,"symbol":"FCEU SI 20260615 PS"}
{"ts_recv":"2026-04-07T02:12:56.539285354Z","hd":{"ts_event":"2026-04-07T02:12:56.539264999Z","rtype":160,"publisher_id":101,"instrument_id":436},"action":"A","side":"A","price":"1.156440000","size":30,"channel_id":23,"order_id":"1775527976539270811","flags":128,"ts_in_delta":1031,"sequence":152267,"symbol":"FCEU SI 20260615 PS"}
{"ts_recv":"2026-04-07T02:13:05.169321712Z","hd":{"ts_event":"2026-04-07T02:13:05.169299067Z","rtype":160,"publisher_id":101,"instrument_id":436},"action":"C","side":"B","price":"1.156340000","size":30,"channel_id":23,"order_id":"10998900013394046619","flags":0,"ts_in_delta":962,"sequence":152430,"symbol":"FCEU SI 20260615 PS"}
{"ts_recv":"2026-04-07T02:13:05.169321712Z","hd":{"ts_event":"2026-04-07T02:13:05.169299067Z","rtype":160,"publisher_id":101,"instrument_id":436},"action":"A","side":"B","price":"1.156330000","size":30,"channel_id":23,"order_id":"10998900022024080977","flags":0,"ts_in_delta":962,"sequence":152430,"symbol":"FCEU SI 20260615 PS"}
{"ts_recv":"2026-04-07T02:13:05.169321712Z","hd":{"ts_event":"2026-04-07T02:13:05.169299067Z","rtype":160,"publisher_id":101,"instrument_id":436},"action":"C","side":"A","price":"1.156440000","size":30,"channel_id":23,"order_id":"1775527976539270811","flags":0,"ts_in_delta":962,"sequence":152430,"symbol":"FCEU SI 20260615 PS"}
{"ts_recv":"2026-04-07T02:13:05.169321712Z","hd":{"ts_event":"2026-04-07T02:13:05.169299067Z","rtype":160,"publisher_id":101,"instrument_id":436},"action":"A","side":"A","price":"1.156430000","size":30,"channel_id":23,"order_id":"1775527985169305169","flags":128,"ts_in_delta":962,"sequence":152430,"symbol":"FCEU SI 20260615 PS"}
{"ts_recv":"2026-04-07T02:13:05.169407186Z","hd":{"ts_event":"2026-04-07T02:13:05.169386389Z","rtype":160,"publisher_id":101,"instrument_id":436},"action":"C","side":"B","price":"1.156330000","size":30,"channel_id":23,"order_id":"10998900022024080977","flags":0,"ts_in_delta":933,"sequence":152431,"symbol":"FCEU SI 20260615 PS"}
{"ts_recv":"2026-04-07T02:13:05.169407186Z","hd":{"ts_event":"2026-04-07T02:13:05.169386389Z","rtype":160,"publisher_id":101,"instrument_id":436},"action":"A","side":"B","price":"1.156320000","size":30,"channel_id":23,"order_id":"10998900022024167952","flags":0,"ts_in_delta":933,"sequence":152431,"symbol":"FCEU SI 20260615 PS"}
{"ts_recv":"2026-04-07T02:13:05.169407186Z","hd":{"ts_event":"2026-04-07T02:13:05.169386389Z","rtype":160,"publisher_id":101,"instrument_id":436},"action":"C","side":"A","price":"1.156430000","size":30,"channel_id":23,"order_id":"1775527985169305169","flags":0,"ts_in_delta":933,"sequence":152431,"symbol":"FCEU SI 20260615 PS"}
{"ts_recv":"2026-04-07T02:13:05.169407186Z","hd":{"ts_event":"2026-04-07T02:13:05.169386389Z","rtype":160,"publisher_id":101,"instrument_id":436},"action":"A","side":"A","price":"1.156420000","size":30,"channel_id":23,"order_id":"1775527985169392144","flags":128,"ts_in_delta":933,"sequence":152431,"symbol":"FCEU SI 20260615 PS"}
{"ts_recv":"2026-04-07T02:13:05.169463670Z","hd":{"ts_event":"2026-04-07T02:13:05.169447189Z","rtype":160,"publisher_id":101,"instrument_id":436},"action":"C","side":"B","price":"1.156320000","size":30,"channel_id":23,"order_id":"10998900022024167952","flags":0,"ts_in_delta":1111,"sequence":152432,"symbol":"FCEU SI 20260615 PS"}
{"ts_recv":"2026-04-07T02:13:05.169463670Z","hd":{"ts_event":"2026-04-07T02:13:05.169447189Z","rtype":160,"publisher_id":101,"instrument_id":436},"action":"A","side":"B","price":"1.156330000","size":30,"channel_id":23,"order_id":"10998900022024228748","flags":0,"ts_in_delta":1111,"sequence":152432,"symbol":"FCEU SI 20260615 PS"}
{"ts_recv":"2026-04-07T02:13:05.169463670Z","hd":{"ts_event":"2026-04-07T02:13:05.169447189Z","rtype":160,"publisher_id":101,"instrument_id":436},"action":"C","side":"A","price":"1.156420000","size":30,"channel_id":23,"order_id":"1775527985169392144","flags":0,"ts_in_delta":1111,"sequence":152432,"symbol":"FCEU SI 20260615 PS"}
{"ts_recv":"2026-04-07T02:13:05.169463670Z","hd":{"ts_event":"2026-04-07T02:13:05.169447189Z","rtype":160,"publisher_id":101,"instrument_id":436},"action":"A","side":"A","price":"1.156430000","size":30,"channel_id":23,"order_id":"1775527985169452940","flags":128,"ts_in_delta":1111,"sequence":152432,"symbol":"FCEU SI 20260615 PS"}
{"ts_recv":"2026-04-07T02:13:06.348019104Z","hd":{"ts_event":"2026-04-07T02:13:06.347999901Z","rtype":160,"publisher_id":101,"instrument_id":436},"action":"C","side":"B","price":"1.156330000","size":30,"channel_id":23,"order_id":"10998900022024228748","flags":0,"ts_in_delta":959,"sequence":152460,"symbol":"FCEU SI 20260615 PS"}
{"ts_recv":"2026-04-07T02:13:06.348019104Z","hd":{"ts_event":"2026-04-07T02:13:06.347999901Z","rtype":160,"publisher_id":101,"instrument_id":436},"action":"A","side":"B","price":"1.156340000","size":30,"channel_id":23,"order_id":"10998900023202781887","flags":0,"ts_in_delta":959,"sequence":152460,"symbol":"FCEU SI 20260615 PS"}
{"ts_recv":"2026-04-07T02:13:06.348019104Z","hd":{"ts_event":"2026-04-07T02:13:06.347999901Z","rtype":160,"publisher_id":101,"instrument_id":436},"action":"C","side":"A","price":"1.156430000","size":30,"channel_id":23,"order_id":"1775527985169452940","flags":0,"ts_in_delta":959,"sequence":152460,"symbol":"FCEU SI 20260615 PS"}
{"ts_recv":"2026-04-07T02:13:06.348019104Z","hd":{"ts_event":"2026-04-07T02:13:06.347999901Z","rtype":160,"publisher_id":101,"instrument_id":436},"action":"A","side":"A","price":"1.156440000","size":30,"channel_id":23,"order_id":"1775527986348006079","flags":128,"ts_in_delta":959,"sequence":152460,"symbol":"FCEU SI 20260615 PS"}
{"ts_recv":"2026-04-07T02:13:06.371576037Z","hd":{"ts_event":"2026-04-07T02:13:06.371554093Z","rtype":160,"publisher_id":101,"instrument_id":436},"action":"C","side":"B","price":"1.156340000","size":30,"channel_id":23,"order_id":"10998900023202781887","flags":0,"ts_in_delta":915,"sequence":152463,"symbol":"FCEU SI 20260615 PS"}
{"ts_recv":"2026-04-07T02:13:06.371576037Z","hd":{"ts_event":"2026-04-07T02:13:06.371554093Z","rtype":160,"publisher_id":101,"instrument_id":436},"action":"A","side":"B","price":"1.156330000","size":30,"channel_id":23,"order_id":"10998900023226335773","flags":0,"ts_in_delta":915,"sequence":152463,"symbol":"FCEU SI 20260615 PS"}
{"ts_recv":"2026-04-07T02:13:06.371576037Z","hd":{"ts_event":"2026-04-07T02:13:06.371554093Z","rtype":160,"publisher_id":101,"instrument_id":436},"action":"C","side":"A","price":"1.156440000","size":30,"channel_id":23,"order_id":"1775527986348006079","flags":0,"ts_in_delta":915,"sequence":152463,"symbol":"FCEU SI 20260615 PS"}
{"ts_recv":"2026-04-07T02:13:06.371576037Z","hd":{"ts_event":"2026-04-07T02:13:06.371554093Z","rtype":160,"publisher_id":101,"instrument_id":436},"action":"A","side":"A","price":"1.156430000","size":30,"channel_id":23,"order_id":"1775527986371559965","flags":128,"ts_in_delta":915,"sequence":152463,"symbol":"FCEU SI 20260615 PS"}
{"ts_recv":"2026-04-07T02:13:06.371645815Z","hd":{"ts_event":"2026-04-07T02:13:06.371628115Z","rtype":160,"publisher_id":101,"instrument_id":436},"action":"C","side":"B","price":"1.156330000","size":30,"channel_id":23,"order_id":"10998900023226335773","flags":0,"ts_in_delta":930,"sequence":152464,"symbol":"FCEU SI 20260615 PS"}
{"ts_recv":"2026-04-07T02:13:06.371645815Z","hd":{"ts_event":"2026-04-07T02:13:06.371628115Z","rtype":160,"publisher_id":101,"instrument_id":436},"action":"A","side":"B","price":"1.156320000","size":30,"channel_id":23,"order_id":"10998900023226409854","flags":0,"ts_in_delta":930,"sequence":152464,"symbol":"FCEU SI 20260615 PS"}
{"ts_recv":"2026-04-07T02:13:06.371645815Z","hd":{"ts_event":"2026-04-07T02:13:06.371628115Z","rtype":160,"publisher_id":101,"instrument_id":436},"action":"C","side":"A","price":"1.156430000","size":30,"channel_id":23,"order_id":"1775527986371559965","flags":0,"ts_in_delta":930,"sequence":152464,"symbol":"FCEU SI 20260615 PS"}
{"ts_recv":"2026-04-07T02:13:06.371645815Z","hd":{"ts_event":"2026-04-07T02:13:06.371628115Z","rtype":160,"publisher_id":101,"instrument_id":436},"action":"A","side":"A","price":"1.156420000","size":30,"channel_id":23,"order_id":"1775527986371634046","flags":128,"ts_in_delta":930,"sequence":152464,"symbol":"FCEU SI 20260615 PS"}
{"ts_recv":"2026-04-07T02:13:06.371701768Z","hd":{"ts_event":"2026-04-07T02:13:06.371684199Z","rtype":160,"publisher_id":101,"instrument_id":436},"action":"C","side":"B","price":"1.156320000","size":30,"channel_id":23,"order_id":"10998900023226409854","flags":0,"ts_in_delta":1190,"sequence":152465,"symbol":"FCEU SI 20260615 PS"}
{"ts_recv":"2026-04-07T02:13:06.371701768Z","hd":{"ts_event":"2026-04-07T02:13:06.371684199Z","rtype":160,"publisher_id":101,"instrument_id":436},"action":"A","side":"B","price":"1.156330000","size":30,"channel_id":23,"order_id":"10998900023226465760","flags":0,"ts_in_delta":1190,"sequence":152465,"symbol":"FCEU SI 20260615 PS"}
{"ts_recv":"2026-04-07T02:13:06.371701768Z","hd":{"ts_event":"2026-04-07T02:13:06.371684199Z","rtype":160,"publisher_id":101,"instrument_id":436},"action":"C","side":"A","price":"1.156420000","size":30,"channel_id":23,"order_id":"1775527986371634046","flags":0,"ts_in_delta":1190,"sequence":152465,"symbol":"FCEU SI 20260615 PS"}
{"ts_recv":"2026-04-07T02:13:06.371701768Z","hd":{"ts_event":"2026-04-07T02:13:06.371684199Z","rtype":160,"publisher_id":101,"instrument_id":436},"action":"A","side":"A","price":"1.156430000","size":30,"channel_id":23,"order_id":"1775527986371689952","flags":128,"ts_in_delta":1190,"sequence":152465,"symbol":"FCEU SI 20260615 PS"}
{"ts_recv":"2026-04-07T02:13:31.501786282Z","hd":{"ts_event":"2026-04-07T02:13:31.501762719Z","rtype":160,"publisher_id":101,"instrument_id":436},"action":"C","side":"B","price":"1.156340000","size":30,"channel_id":23,"order_id":"10998900000678198255","flags":0,"ts_in_delta":914,"sequence":152668,"symbol":"FCEU SI 20260615 PS"}
{"ts_recv":"2026-04-07T02:13:31.501786282Z","hd":{"ts_event":"2026-04-07T02:13:31.501762719Z","rtype":160,"publisher_id":101,"instrument_id":436},"action":"A","side":"B","price":"1.156320000","size":30,"channel_id":23,"order_id":"10998900048356544910","flags":0,"ts_in_delta":914,"sequence":152668,"symbol":"FCEU SI 20260615 PS"}
{"ts_recv":"2026-04-07T02:13:31.501786282Z","hd":{"ts_event":"2026-04-07T02:13:31.501762719Z","rtype":160,"publisher_id":101,"instrument_id":436},"action":"C","side":"A","price":"1.156440000","size":30,"channel_id":23,"order_id":"1775527963823422447","flags":0,"ts_in_delta":914,"sequence":152668,"symbol":"FCEU SI 20260615 PS"}
{"ts_recv":"2026-04-07T02:13:31.501786282Z","hd":{"ts_event":"2026-04-07T02:13:31.501762719Z","rtype":160,"publisher_id":101,"instrument_id":436},"action":"A","side":"A","price":"1.156420000","size":30,"channel_id":23,"order_id":"1775528011501769102","flags":128,"ts_in_delta":914,"sequence":152668,"symbol":"FCEU SI 20260615 PS"}
{"ts_recv":"2026-04-07T02:13:31.501863754Z","hd":{"ts_event":"2026-04-07T02:13:31.501842709Z","rtype":160,"publisher_id":101,"instrument_id":436},"action":"C","side":"B","price":"1.156330000","size":30,"channel_id":23,"order_id":"10998900023226465760","flags":0,"ts_in_delta":896,"sequence":152669,"symbol":"FCEU SI 20260615 PS"}
{"ts_recv":"2026-04-07T02:13:31.501863754Z","hd":{"ts_event":"2026-04-07T02:13:31.501842709Z","rtype":160,"publisher_id":101,"instrument_id":436},"action":"A","side":"B","price":"1.156320000","size":30,"channel_id":23,"order_id":"10998900048356624684","flags":0,"ts_in_delta":896,"sequence":152669,"symbol":"FCEU SI 20260615 PS"}
{"ts_recv":"2026-04-07T02:13:31.501863754Z","hd":{"ts_event":"2026-04-07T02:13:31.501842709Z","rtype":160,"publisher_id":101,"instrument_id":436},"action":"C","side":"A","price":"1.156430000","size":30,"channel_id":23,"order_id":"1775527986371689952","flags":0,"ts_in_delta":896,"sequence":152669,"symbol":"FCEU SI 20260615 PS"}
{"ts_recv":"2026-04-07T02:13:31.501863754Z","hd":{"ts_event":"2026-04-07T02:13:31.501842709Z","rtype":160,"publisher_id":101,"instrument_id":436},"action":"A","side":"A","price":"1.156420000","size":30,"channel_id":23,"order_id":"1775528011501848876","flags":128,"ts_in_delta":896,"sequence":152669,"symbol":"FCEU SI 20260615 PS"}
{"ts_recv":"2026-04-07T02:13:31.506152899Z","hd":{"ts_event":"2026-04-07T02:13:31.506131091Z","rtype":160,"publisher_id":101,"instrument_id":436},"action":"C","side":"B","price":"1.156320000","size":30,"channel_id":23,"order_id":"10998900048356624684","flags":0,"ts_in_delta":909,"sequence":152672,"symbol":"FCEU SI 20260615 PS"}
{"ts_recv":"2026-04-07T02:13:31.506152899Z","hd":{"ts_event":"2026-04-07T02:13:31.506131091Z","rtype":160,"publisher_id":101,"instrument_id":436},"action":"A","side":"B","price":"1.156310000","size":30,"channel_id":23,"order_id":"10998900048360912822","flags":0,"ts_in_delta":909,"sequence":152672,"symbol":"FCEU SI 20260615 PS"}
{"ts_recv":"2026-04-07T02:13:31.506152899Z","hd":{"ts_event":"2026-04-07T02:13:31.506131091Z","rtype":160,"publisher_id":101,"instrument_id":436},"action":"C","side":"A","price":"1.156420000","size":30,"channel_id":23,"order_id":"1775528011501848876","flags":0,"ts_in_delta":909,"sequence":152672,"symbol":"FCEU SI 20260615 PS"}
{"ts_recv":"2026-04-07T02:13:31.506152899Z","hd":{"ts_event":"2026-04-07T02:13:31.506131091Z","rtype":160,"publisher_id":101,"instrument_id":436},"action":"A","side":"A","price":"1.156410000","size":30,"channel_id":23,"order_id":"1775528011506137014","flags":128,"ts_in_delta":909,"sequence":152672,"symbol":"FCEU SI 20260615 PS"}
{"ts_recv":"2026-04-07T02:13:31.506232460Z","hd":{"ts_event":"2026-04-07T02:13:31.506212735Z","rtype":160,"publisher_id":101,"instrument_id":436},"action":"C","side":"B","price":"1.156310000","size":30,"channel_id":23,"order_id":"10998900048360912822","flags":0,"ts_in_delta":880,"sequence":152673,"symbol":"FCEU SI 20260615 PS"}
{"ts_recv":"2026-04-07T02:13:31.506232460Z","hd":{"ts_event":"2026-04-07T02:13:31.506212735Z","rtype":160,"publisher_id":101,"instrument_id":436},"action":"A","side":"B","price":"1.156290000","size":30,"channel_id":23,"order_id":"10998900048360994529","flags":0,"ts_in_delta":880,"sequence":152673,"symbol":"FCEU SI 20260615 PS"}
{"ts_recv":"2026-04-07T02:13:31.506232460Z","hd":{"ts_event":"2026-04-07T02:13:31.506212735Z","rtype":160,"publisher_id":101,"instrument_id":436},"action":"C","side":"A","price":"1.156410000","size":30,"channel_id":23,"order_id":"1775528011506137014","flags":0,"ts_in_delta":880,"sequence":152673,"symbol":"FCEU SI 20260615 PS"}
{"ts_recv":"2026-04-07T02:13:31.506232460Z","hd":{"ts_event":"2026-04-07T02:13:31.506212735Z","rtype":160,"publisher_id":101,"instrument_id":436},"action":"A","side":"A","price":"1.156390000","size":30,"channel_id":23,"order_id":"1775528011506218721","flags":128,"ts_in_delta":880,"sequence":152673,"symbol":"FCEU SI 20260615 PS"}
{"ts_recv":"2026-04-07T02:13:31.506286587Z","hd":{"ts_event":"2026-04-07T02:13:31.506270893Z","rtype":160,"publisher_id":101,"instrument_id":436},"action":"C","side":"B","price":"1.156290000","size":30,"channel_id":23,"order_id":"10998900048360994529","flags":0,"ts_in_delta":905,"sequence":152674,"symbol":"FCEU SI 20260615 PS"}
{"ts_recv":"2026-04-07T02:13:31.506286587Z","hd":{"ts_event":"2026-04-07T02:13:31.506270893Z","rtype":160,"publisher_id":101,"instrument_id":436},"action":"A","side":"B","price":"1.156310000","size":30,"channel_id":23,"order_id":"10998900048361052791","flags":0,"ts_in_delta":905,"sequence":152674,"symbol":"FCEU SI 20260615 PS"}
{"ts_recv":"2026-04-07T02:13:31.506286587Z","hd":{"ts_event":"2026-04-07T02:13:31.506270893Z","rtype":160,"publisher_id":101,"instrument_id":436},"action":"C","side":"A","price":"1.156390000","size":30,"channel_id":23,"order_id":"1775528011506218721","flags":0,"ts_in_delta":905,"sequence":152674,"symbol":"FCEU SI 20260615 PS"}
{"ts_recv":"2026-04-07T02:13:31.506286587Z","hd":{"ts_event":"2026-04-07T02:13:31.506270893Z","rtype":160,"publisher_id":101,"instrument_id":436},"action":"A","side":"A","price":"1.156410000","size":30,"channel_id":23,"order_id":"1775528011506276983","flags":128,"ts_in_delta":905,"sequence":152674,"symbol":"FCEU SI 20260615 PS"}
{"ts_recv":"2026-04-07T02:13:31.509778661Z","hd":{"ts_event":"2026-04-07T02:13:31.509764341Z","rtype":160,"publisher_id":101,"instrument_id":436},"action":"C","side":"B","price":"1.156300000","size":20,"channel_id":23,"order_id":"10998899842095252922","flags":128,"ts_in_delta":806,"sequence":152676,"symbol":"FCEU SI 20260615 PS"}
{"ts_recv":"2026-04-07T02:13:31.536071040Z","hd":{"ts_event":"2026-04-07T02:13:31.536052049Z","rtype":160,"publisher_id":101,"instrument_id":436},"action":"C","side":"B","price":"1.156310000","size":30,"channel_id":23,"order_id":"10998900048361052791","flags":0,"ts_in_delta":925,"sequence":152678,"symbol":"FCEU SI 20260615 PS"}
{"ts_recv":"2026-04-07T02:13:31.536071040Z","hd":{"ts_event":"2026-04-07T02:13:31.536052049Z","rtype":160,"publisher_id":101,"instrument_id":436},"action":"A","side":"B","price":"1.156320000","size":30,"channel_id":23,"order_id":"10998900048390833785","flags":0,"ts_in_delta":925,"sequence":152678,"symbol":"FCEU SI 20260615 PS"}
{"ts_recv":"2026-04-07T02:13:31.536071040Z","hd":{"ts_event":"2026-04-07T02:13:31.536052049Z","rtype":160,"publisher_id":101,"instrument_id":436},"action":"C","side":"A","price":"1.156410000","size":30,"channel_id":23,"order_id":"1775528011506276983","flags":0,"ts_in_delta":925,"sequence":152678,"symbol":"FCEU SI 20260615 PS"}
{"ts_recv":"2026-04-07T02:13:31.536071040Z","hd":{"ts_event":"2026-04-07T02:13:31.536052049Z","rtype":160,"publisher_id":101,"instrument_id":436},"action":"A","side":"A","price":"1.156420000","size":30,"channel_id":23,"order_id":"1775528011536057977","flags":128,"ts_in_delta":925,"sequence":152678,"symbol":"FCEU SI 20260615 PS"}
{"ts_recv":"2026-04-07T02:13:31.562712851Z","hd":{"ts_event":"2026-04-07T02:13:31.562698305Z","rtype":160,"publisher_id":101,"instrument_id":436},"action":"A","side":"B","price":"1.156200000","size":20,"channel_id":23,"order_id":"10998900048417480289","flags":128,"ts_in_delta":750,"sequence":152680,"symbol":"FCEU SI 20260615 PS"}
{"ts_recv":"2026-04-07T02:13:32.146459235Z","hd":{"ts_event":"2026-04-07T02:13:32.146439053Z","rtype":160,"publisher_id":101,"instrument_id":436},"action":"C","side":"B","price":"1.156320000","size":30,"channel_id":23,"order_id":"10998900048356544910","flags":0,"ts_in_delta":831,"sequence":152688,"symbol":"FCEU SI 20260615 PS"}
{"ts_recv":"2026-04-07T02:13:32.146459235Z","hd":{"ts_event":"2026-04-07T02:13:32.146439053Z","rtype":160,"publisher_id":101,"instrument_id":436},"action":"A","side":"B","price":"1.156340000","size":30,"channel_id":23,"order_id":"10998900049001221432","flags":0,"ts_in_delta":831,"sequence":152688,"symbol":"FCEU SI 20260615 PS"}
{"ts_recv":"2026-04-07T02:13:32.146459235Z","hd":{"ts_event":"2026-04-07T02:13:32.146439053Z","rtype":160,"publisher_id":101,"instrument_id":436},"action":"C","side":"A","price":"1.156420000","size":30,"channel_id":23,"order_id":"1775528011501769102","flags":0,"ts_in_delta":831,"sequence":152688,"symbol":"FCEU SI 20260615 PS"}
{"ts_recv":"2026-04-07T02:13:32.146459235Z","hd":{"ts_event":"2026-04-07T02:13:32.146439053Z","rtype":160,"publisher_id":101,"instrument_id":436},"action":"A","side":"A","price":"1.156440000","size":30,"channel_id":23,"order_id":"1775528012146445624","flags":128,"ts_in_delta":831,"sequence":152688,"symbol":"FCEU SI 20260615 PS"}
{"ts_recv":"2026-04-07T02:13:32.146525111Z","hd":{"ts_event":"2026-04-07T02:13:32.146507519Z","rtype":160,"publisher_id":101,"instrument_id":436},"action":"C","side":"B","price":"1.156320000","size":30,"channel_id":23,"order_id":"10998900048390833785","flags":0,"ts_in_delta":899,"sequence":152689,"symbol":"FCEU SI 20260615 PS"}
{"ts_recv":"2026-04-07T02:13:32.146525111Z","hd":{"ts_event":"2026-04-07T02:13:32.146507519Z","rtype":160,"publisher_id":101,"instrument_id":436},"action":"A","side":"B","price":"1.156330000","size":30,"channel_id":23,"order_id":"10998900049001289417","flags":0,"ts_in_delta":899,"sequence":152689,"symbol":"FCEU SI 20260615 PS"}
{"ts_recv":"2026-04-07T02:13:32.146525111Z","hd":{"ts_event":"2026-04-07T02:13:32.146507519Z","rtype":160,"publisher_id":101,"instrument_id":436},"action":"C","side":"A","price":"1.156420000","size":30,"channel_id":23,"order_id":"1775528011536057977","flags":0,"ts_in_delta":899,"sequence":152689,"symbol":"FCEU SI 20260615 PS"}
{"ts_recv":"2026-04-07T02:13:32.146525111Z","hd":{"ts_event":"2026-04-07T02:13:32.146507519Z","rtype":160,"publisher_id":101,"instrument_id":436},"action":"A","side":"A","price":"1.156430000","size":30,"channel_id":23,"order_id":"1775528012146513609","flags":128,"ts_in_delta":899,"sequence":152689,"symbol":"FCEU SI 20260615 PS"}
{"ts_recv":"2026-04-07T02:13:40.724208782Z","hd":{"ts_event":"2026-04-07T02:13:40.724190483Z","rtype":160,"publisher_id":101,"instrument_id":436},"action":"C","side":"B","price":"1.156330000","size":30,"channel_id":23,"order_id":"10998900049001289417","flags":0,"ts_in_delta":932,"sequence":152805,"symbol":"FCEU SI 20260615 PS"}
{"ts_recv":"2026-04-07T02:13:40.724208782Z","hd":{"ts_event":"2026-04-07T02:13:40.724190483Z","rtype":160,"publisher_id":101,"instrument_id":436},"action":"A","side":"B","price":"1.156340000","size":30,"channel_id":23,"order_id":"10998900057578972362","flags":0,"ts_in_delta":932,"sequence":152805,"symbol":"FCEU SI 20260615 PS"}
{"ts_recv":"2026-04-07T02:13:40.724208782Z","hd":{"ts_event":"2026-04-07T02:13:40.724190483Z","rtype":160,"publisher_id":101,"instrument_id":436},"action":"C","side":"A","price":"1.156430000","size":30,"channel_id":23,"order_id":"1775528012146513609","flags":0,"ts_in_delta":932,"sequence":152805,"symbol":"FCEU SI 20260615 PS"}
{"ts_recv":"2026-04-07T02:13:40.724208782Z","hd":{"ts_event":"2026-04-07T02:13:40.724190483Z","rtype":160,"publisher_id":101,"instrument_id":436},"action":"A","side":"A","price":"1.156440000","size":30,"channel_id":23,"order_id":"1775528020724196554","flags":128,"ts_in_delta":932,"sequence":152805,"symbol":"FCEU SI 20260615 PS"}
{"ts_recv":"2026-04-07T02:13:44.628871428Z","hd":{"ts_event":"2026-04-07T02:13:44.628850003Z","rtype":160,"publisher_id":101,"instrument_id":436},"action":"C","side":"B","price":"1.156340000","size":30,"channel_id":23,"order_id":"10998900057578972362","flags":0,"ts_in_delta":897,"sequence":152872,"symbol":"FCEU SI 20260615 PS"}
{"ts_recv":"2026-04-07T02:13:44.628871428Z","hd":{"ts_event":"2026-04-07T02:13:44.628850003Z","rtype":160,"publisher_id":101,"instrument_id":436},"action":"A","side":"B","price":"1.156330000","size":30,"channel_id":23,"order_id":"10998900061483632133","flags":0,"ts_in_delta":897,"sequence":152872,"symbol":"FCEU SI 20260615 PS"}
{"ts_recv":"2026-04-07T02:13:44.628871428Z","hd":{"ts_event":"2026-04-07T02:13:44.628850003Z","rtype":160,"publisher_id":101,"instrument_id":436},"action":"C","side":"A","price":"1.156440000","size":30,"channel_id":23,"order_id":"1775528020724196554","flags":0,"ts_in_delta":897,"sequence":152872,"symbol":"FCEU SI 20260615 PS"}
{"ts_recv":"2026-04-07T02:13:44.628871428Z","hd":{"ts_event":"2026-04-07T02:13:44.628850003Z","rtype":160,"publisher_id":101,"instrument_id":436},"action":"A","side":"A","price":"1.156430000","size":30,"channel_id":23,"order_id":"1775528024628856325","flags":128,"ts_in_delta":897,"sequence":152872,"symbol":"FCEU SI 20260615 PS"}
{"ts_recv":"2026-04-07T02:13:47.493776246Z","hd":{"ts_event":"2026-04-07T02:13:47.493756733Z","rtype":160,"publisher_id":101,"instrument_id":436},"action":"C","side":"B","price":"1.156330000","size":30,"channel_id":23,"order_id":"10998900061483632133","flags":0,"ts_in_delta":892,"sequence":152901,"symbol":"FCEU SI 20260615 PS"}
{"ts_recv":"2026-04-07T02:13:47.493776246Z","hd":{"ts_event":"2026-04-07T02:13:47.493756733Z","rtype":160,"publisher_id":101,"instrument_id":436},"action":"A","side":"B","price":"1.156340000","size":30,"channel_id":23,"order_id":"10998900064348538648","flags":0,"ts_in_delta":892,"sequence":152901,"symbol":"FCEU SI 20260615 PS"}
{"ts_recv":"2026-04-07T02:13:47.493776246Z","hd":{"ts_event":"2026-04-07T02:13:47.493756733Z","rtype":160,"publisher_id":101,"instrument_id":436},"action":"C","side":"A","price":"1.156430000","size":30,"channel_id":23,"order_id":"1775528024628856325","flags":0,"ts_in_delta":892,"sequence":152901,"symbol":"FCEU SI 20260615 PS"}
{"ts_recv":"2026-04-07T02:13:47.493776246Z","hd":{"ts_event":"2026-04-07T02:13:47.493756733Z","rtype":160,"publisher_id":101,"instrument_id":436},"action":"A","side":"A","price":"1.156440000","size":30,"channel_id":23,"order_id":"1775528027493762840","flags":128,"ts_in_delta":892,"sequence":152901,"symbol":"FCEU SI 20260615 PS"}
{"ts_recv":"2026-04-07T02:13:47.515995939Z","hd":{"ts_event":"2026-04-07T02:13:47.515975437Z","rtype":160,"publisher_id":101,"instrument_id":436},"action":"C","side":"B","price":"1.156340000","size":30,"channel_id":23,"order_id":"10998900064348538648","flags":0,"ts_in_delta":915,"sequence":152907,"symbol":"FCEU SI 20260615 PS"}
{"ts_recv":"2026-04-07T02:13:47.515995939Z","hd":{"ts_event":"2026-04-07T02:13:47.515975437Z","rtype":160,"publisher_id":101,"instrument_id":436},"action":"A","side":"B","price":"1.156330000","size":30,"channel_id":23,"order_id":"10998900064370756907","flags":0,"ts_in_delta":915,"sequence":152907,"symbol":"FCEU SI 20260615 PS"}
{"ts_recv":"2026-04-07T02:13:47.515995939Z","hd":{"ts_event":"2026-04-07T02:13:47.515975437Z","rtype":160,"publisher_id":101,"instrument_id":436},"action":"C","side":"A","price":"1.156440000","size":30,"channel_id":23,"order_id":"1775528027493762840","flags":0,"ts_in_delta":915,"sequence":152907,"symbol":"FCEU SI 20260615 PS"}
{"ts_recv":"2026-04-07T02:13:47.515995939Z","hd":{"ts_event":"2026-04-07T02:13:47.515975437Z","rtype":160,"publisher_id":101,"instrument_id":436},"action":"A","side":"A","price":"1.156430000","size":30,"channel_id":23,"order_id":"1775528027515981099","flags":128,"ts_in_delta":915,"sequence":152907,"symbol":"FCEU SI 20260615 PS"}
{"ts_recv":"2026-04-07T02:13:47.516081882Z","hd":{"ts_event":"2026-04-07T02:13:47.516061289Z","rtype":160,"publisher_id":101,"instrument_id":436},"action":"C","side":"B","price":"1.156330000","size":30,"channel_id":23,"order_id":"10998900064370756907","flags":0,"ts_in_delta":902,"sequence":152908,"symbol":"FCEU SI 20260615 PS"}
{"ts_recv":"2026-04-07T02:13:47.516081882Z","hd":{"ts_event":"2026-04-07T02:13:47.516061289Z","rtype":160,"publisher_id":101,"instrument_id":436},"action":"A","side":"B","price":"1.156320000","size":30,"channel_id":23,"order_id":"10998900064370842998","flags":0,"ts_in_delta":902,"sequence":152908,"symbol":"FCEU SI 20260615 PS"}
{"ts_recv":"2026-04-07T02:13:47.516081882Z","hd":{"ts_event":"2026-04-07T02:13:47.516061289Z","rtype":160,"publisher_id":101,"instrument_id":436},"action":"C","side":"A","price":"1.156430000","size":30,"channel_id":23,"order_id":"1775528027515981099","flags":0,"ts_in_delta":902,"sequence":152908,"symbol":"FCEU SI 20260615 PS"}
{"ts_recv":"2026-04-07T02:13:47.516081882Z","hd":{"ts_event":"2026-04-07T02:13:47.516061289Z","rtype":160,"publisher_id":101,"instrument_id":436},"action":"A","side":"A","price":"1.156420000","size":30,"channel_id":23,"order_id":"1775528027516067190","flags":128,"ts_in_delta":902,"sequence":152908,"symbol":"FCEU SI 20260615 PS"}
{"ts_recv":"2026-04-07T02:13:47.516136745Z","hd":{"ts_event":"2026-04-07T02:13:47.516120501Z","rtype":160,"publisher_id":101,"instrument_id":436},"action":"C","side":"B","price":"1.156320000","size":30,"channel_id":23,"order_id":"10998900064370842998","flags":0,"ts_in_delta":928,"sequence":152909,"symbol":"FCEU SI 20260615 PS"}
{"ts_recv":"2026-04-07T02:13:47.516136745Z","hd":{"ts_event":"2026-04-07T02:13:47.516120501Z","rtype":160,"publisher_id":101,"instrument_id":436},"action":"A","side":"B","price":"1.156330000","size":30,"channel_id":23,"order_id":"10998900064370902143","flags":0,"ts_in_delta":928,"sequence":152909,"symbol":"FCEU SI 20260615 PS"}
{"ts_recv":"2026-04-07T02:13:47.516136745Z","hd":{"ts_event":"2026-04-07T02:13:47.516120501Z","rtype":160,"publisher_id":101,"instrument_id":436},"action":"C","side":"A","price":"1.156420000","size":30,"channel_id":23,"order_id":"1775528027516067190","flags":0,"ts_in_delta":928,"sequence":152909,"symbol":"FCEU SI 20260615 PS"}
{"ts_recv":"2026-04-07T02:13:47.516136745Z","hd":{"ts_event":"2026-04-07T02:13:47.516120501Z","rtype":160,"publisher_id":101,"instrument_id":436},"action":"A","side":"A","price":"1.156430000","size":30,"channel_id":23,"order_id":"1775528027516126335","flags":128,"ts_in_delta":928,"sequence":152909,"symbol":"FCEU SI 20260615 PS"}
{"ts_recv":"2026-04-07T02:14:05.930619722Z","hd":{"ts_event":"2026-04-07T02:14:05.930588205Z","rtype":160,"publisher_id":101,"instrument_id":436},"action":"C","side":"B","price":"1.156340000","size":30,"channel_id":23,"order_id":"10998900049001221432","flags":0,"ts_in_delta":1467,"sequence":153100,"symbol":"FCEU SI 20260615 PS"}
{"ts_recv":"2026-04-07T02:14:05.930619722Z","hd":{"ts_event":"2026-04-07T02:14:05.930588205Z","rtype":160,"publisher_id":101,"instrument_id":436},"action":"A","side":"B","price":"1.156320000","size":30,"channel_id":23,"order_id":"10998900082785373842","flags":0,"ts_in_delta":1467,"sequence":153100,"symbol":"FCEU SI 20260615 PS"}
{"ts_recv":"2026-04-07T02:14:05.930619722Z","hd":{"ts_event":"2026-04-07T02:14:05.930588205Z","rtype":160,"publisher_id":101,"instrument_id":436},"action":"C","side":"A","price":"1.156440000","size":30,"channel_id":23,"order_id":"1775528012146445624","flags":0,"ts_in_delta":1467,"sequence":153100,"symbol":"FCEU SI 20260615 PS"}
{"ts_recv":"2026-04-07T02:14:05.930619722Z","hd":{"ts_event":"2026-04-07T02:14:05.930588205Z","rtype":160,"publisher_id":101,"instrument_id":436},"action":"A","side":"A","price":"1.156420000","size":30,"channel_id":23,"order_id":"1775528045930598034","flags":128,"ts_in_delta":1467,"sequence":153100,"symbol":"FCEU SI 20260615 PS"}
{"ts_recv":"2026-04-07T02:14:05.930728619Z","hd":{"ts_event":"2026-04-07T02:14:05.930711143Z","rtype":160,"publisher_id":101,"instrument_id":436},"action":"C","side":"B","price":"1.156330000","size":30,"channel_id":23,"order_id":"10998900064370902143","flags":0,"ts_in_delta":948,"sequence":153101,"symbol":"FCEU SI 20260615 PS"}
{"ts_recv":"2026-04-07T02:14:05.930728619Z","hd":{"ts_event":"2026-04-07T02:14:05.930711143Z","rtype":160,"publisher_id":101,"instrument_id":436},"action":"A","side":"B","price":"1.156320000","size":30,"channel_id":23,"order_id":"10998900082785493167","flags":0,"ts_in_delta":948,"sequence":153101,"symbol":"FCEU SI 20260615 PS"}
{"ts_recv":"2026-04-07T02:14:05.930728619Z","hd":{"ts_event":"2026-04-07T02:14:05.930711143Z","rtype":160,"publisher_id":101,"instrument_id":436},"action":"C","side":"A","price":"1.156430000","size":30,"channel_id":23,"order_id":"1775528027516126335","flags":0,"ts_in_delta":948,"sequence":153101,"symbol":"FCEU SI 20260615 PS"}
{"ts_recv":"2026-04-07T02:14:05.930728619Z","hd":{"ts_event":"2026-04-07T02:14:05.930711143Z","rtype":160,"publisher_id":101,"instrument_id":436},"action":"A","side":"A","price":"1.156420000","size":30,"channel_id":23,"order_id":"1775528045930717359","flags":128,"ts_in_delta":948,"sequence":153101,"symbol":"FCEU SI 20260615 PS"}
{"ts_recv":"2026-04-07T02:14:05.934417247Z","hd":{"ts_event":"2026-04-07T02:14:05.934395617Z","rtype":160,"publisher_id":101,"instrument_id":436},"action":"C","side":"B","price":"1.156320000","size":30,"channel_id":23,"order_id":"10998900082785493167","flags":0,"ts_in_delta":945,"sequence":153103,"symbol":"FCEU SI 20260615 PS"}
{"ts_recv":"2026-04-07T02:14:05.934417247Z","hd":{"ts_event":"2026-04-07T02:14:05.934395617Z","rtype":160,"publisher_id":101,"instrument_id":436},"action":"A","side":"B","price":"1.156310000","size":30,"channel_id":23,"order_id":"10998900082789177530","flags":0,"ts_in_delta":945,"sequence":153103,"symbol":"FCEU SI 20260615 PS"}
{"ts_recv":"2026-04-07T02:14:05.934417247Z","hd":{"ts_event":"2026-04-07T02:14:05.934395617Z","rtype":160,"publisher_id":101,"instrument_id":436},"action":"C","side":"A","price":"1.156420000","size":30,"channel_id":23,"order_id":"1775528045930717359","flags":0,"ts_in_delta":945,"sequence":153103,"symbol":"FCEU SI 20260615 PS"}
{"ts_recv":"2026-04-07T02:14:05.934417247Z","hd":{"ts_event":"2026-04-07T02:14:05.934395617Z","rtype":160,"publisher_id":101,"instrument_id":436},"action":"A","side":"A","price":"1.156410000","size":30,"channel_id":23,"order_id":"1775528045934401722","flags":128,"ts_in_delta":945,"sequence":153103,"symbol":"FCEU SI 20260615 PS"}
{"ts_recv":"2026-04-07T02:14:06.459524342Z","hd":{"ts_event":"2026-04-07T02:14:06.459500659Z","rtype":160,"publisher_id":101,"instrument_id":436},"action":"C","side":"B","price":"1.156310000","size":30,"channel_id":23,"order_id":"10998900082789177530","flags":0,"ts_in_delta":1480,"sequence":153123,"symbol":"FCEU SI 20260615 PS"}
{"ts_recv":"2026-04-07T02:14:06.459524342Z","hd":{"ts_event":"2026-04-07T02:14:06.459500659Z","rtype":160,"publisher_id":101,"instrument_id":436},"action":"A","side":"B","price":"1.156320000","size":30,"channel_id":23,"order_id":"10998900083314287018","flags":0,"ts_in_delta":1480,"sequence":153123,"symbol":"FCEU SI 20260615 PS"}
{"ts_recv":"2026-04-07T02:14:06.459524342Z","hd":{"ts_event":"2026-04-07T02:14:06.459500659Z","rtype":160,"publisher_id":101,"instrument_id":436},"action":"C","side":"A","price":"1.156410000","size":30,"channel_id":23,"order_id":"1775528045934401722","flags":0,"ts_in_delta":1480,"sequence":153123,"symbol":"FCEU SI 20260615 PS"}
{"ts_recv":"2026-04-07T02:14:06.459524342Z","hd":{"ts_event":"2026-04-07T02:14:06.459500659Z","rtype":160,"publisher_id":101,"instrument_id":436},"action":"A","side":"A","price":"1.156420000","size":30,"channel_id":23,"order_id":"1775528046459511210","flags":128,"ts_in_delta":1480,"sequence":153123,"symbol":"FCEU SI 20260615 PS"}
{"ts_recv":"2026-04-07T02:14:20.580648874Z","hd":{"ts_event":"2026-04-07T02:14:20.580626571Z","rtype":160,"publisher_id":101,"instrument_id":436},"action":"C","side":"B","price":"1.156320000","size":30,"channel_id":23,"order_id":"10998900082785373842","flags":0,"ts_in_delta":911,"sequence":153306,"symbol":"FCEU SI 20260615 PS"}
{"ts_recv":"2026-04-07T02:14:20.580648874Z","hd":{"ts_event":"2026-04-07T02:14:20.580626571Z","rtype":160,"publisher_id":101,"instrument_id":436},"action":"A","side":"B","price":"1.156340000","size":30,"channel_id":23,"order_id":"10998900097435409304","flags":0,"ts_in_delta":911,"sequence":153306,"symbol":"FCEU SI 20260615 PS"}
{"ts_recv":"2026-04-07T02:14:20.580648874Z","hd":{"ts_event":"2026-04-07T02:14:20.580626571Z","rtype":160,"publisher_id":101,"instrument_id":436},"action":"C","side":"A","price":"1.156420000","size":30,"channel_id":23,"order_id":"1775528045930598034","flags":0,"ts_in_delta":911,"sequence":153306,"symbol":"FCEU SI 20260615 PS"}
{"ts_recv":"2026-04-07T02:14:20.580648874Z","hd":{"ts_event":"2026-04-07T02:14:20.580626571Z","rtype":160,"publisher_id":101,"instrument_id":436},"action":"A","side":"A","price":"1.156440000","size":30,"channel_id":23,"order_id":"1775528060580633496","flags":128,"ts_in_delta":911,"sequence":153306,"symbol":"FCEU SI 20260615 PS"}
