{"ts_recv":"2026-04-07T02:17:11.324415482Z","hd":{"ts_event":"2026-04-07T02:17:11.324395661Z","rtype":160,"publisher_id":101,"instrument_id":436},"action":"A","side":"B","price":"1.156290000","size":30,"channel_id":23,"order_id":"10998900268179177345","flags":0,"ts_in_delta":955,"sequence":155318,"symbol":"FCEU SI 20260615 PS"}
{"ts_recv":"2026-04-07T02:17:11.324415482Z","hd":{"ts_event":"2026-04-07T02:17:11.324395661Z","rtype":160,"publisher_id":101,"instrument_id":436},"action":"C","side":"A","price":"1.156370000","size":30,"channel_id":23,"order_id":"1775528227726196978","flags":0,"ts_in_delta":955,"sequence":155318,"symbol":"FCEU SI 20260615 PS"}
{"ts_recv":"2026-04-07T02:17:11.324415482Z","hd":{"ts_event":"2026-04-07T02:17:11.324395661Z","rtype":160,"publisher_id":101,"instrument_id":436},"action":"A","side":"A","price":"1.156390000","size":30,"channel_id":23,"order_id":"1775528231324401537","flags":128,"ts_in_delta":955,"sequence":155318,"symbol":"FCEU SI 20260615 PS"}
{"ts_recv":"2026-04-07T02:17:11.324472926Z","hd":{"ts_event":"2026-04-07T02:17:11.324456013Z","rtype":160,"publisher_id":101,"instrument_id":436},"action":"C","side":"B","price":"1.156280000","size":30,"channel_id":23,"order_id":"10998900268179117568","flags":0,"ts_in_delta":1034,"sequence":155319,"symbol":"FCEU SI 20260615 PS"}
{"ts_recv":"2026-04-07T02:17:11.324472926Z","hd":{"ts_event":"2026-04-07T02:17:11.324456013Z","rtype":160,"publisher_id":101,"instrument_id":436},"action":"A","side":"B","price":"1.156290000","size":30,"channel_id":23,"order_id":"10998900268179237874","flags":0,"ts_in_delta":1034,"sequence":155319,"symbol":"FCEU SI 20260615 PS"}
{"ts_recv":"2026-04-07T02:17:11.324472926Z","hd":{"ts_event":"2026-04-07T02:17:11.324456013Z","rtype":160,"publisher_id":101,"instrument_id":436},"action":"C","side":"A","price":"1.156380000","size":30,"channel_id":23,"order_id":"1775528231324341760","flags":0,"ts_in_delta":1034,"sequence":155319,"symbol":"FCEU SI 20260615 PS"}
{"ts_recv":"2026-04-07T02:17:11.324472926Z","hd":{"ts_event":"2026-04-07T02:17:11.324456013Z","rtype":160,"publisher_id":101,"instrument_id":436},"action":"A","side":"A","price":"1.156390000","size":30,"channel_id":23,"order_id":"1775528231324462066","flags":128,"ts_in_delta":1034,"sequence":155319,"symbol":"FCEU SI 20260615 PS"}
{"ts_recv":"2026-04-07T02:17:11.330264601Z","hd":{"ts_event":"2026-04-07T02:17:11.330244689Z","rtype":160,"publisher_id":101,"instrument_id":436},"action":"C","side":"B","price":"1.156290000","size":30,"channel_id":23,"order_id":"10998900268179237874","flags":0,"ts_in_delta":989,"sequence":155327,"symbol":"FCEU SI 20260615 PS"}
{"ts_recv":"2026-04-07T02:17:11.330264601Z","hd":{"ts_event":"2026-04-07T02:17:11.330244689Z","rtype":160,"publisher_id":101,"instrument_id":436},"action":"A","side":"B","price":"1.156300000","size":30,"channel_id":23,"order_id":"10998900268185026484","flags":0,"ts_in_delta":989,"sequence":155327,"symbol":"FCEU SI 20260615 PS"}
{"ts_recv":"2026-04-07T02:17:11.330264601Z","hd":{"ts_event":"2026-04-07T02:17:11.330244689Z","rtype":160,"publisher_id":101,"instrument_id":436},"action":"C","side":"A","price":"1.156390000","size":30,"channel_id":23,"order_id":"1775528231324462066","flags":0,"ts_in_delta":989,"sequence":155327,"symbol":"FCEU SI 20260615 PS"}
{"ts_recv":"2026-04-07T02:17:11.330264601Z","hd":{"ts_event":"2026-04-07T02:17:11.330244689Z","rtype":160,"publisher_id":101,"instrument_id":436},"action":"A","side":"A","price":"1.156400000","size":30,"channel_id":23,"order_id":"1775528231330250676","flags":128,"ts_in_delta":989,"sequence":155327,"symbol":"FCEU SI 20260615 PS"}
{"ts_recv":"2026-04-07T02:17:11.333754563Z","hd":{"ts_event":"2026-04-07T02:17:11.333733247Z","rtype":160,"publisher_id":101,"instrument_id":436},"action":"C","side":"B","price":"1.156290000","size":30,"channel_id":23,"order_id":"10998900268179177345","flags":0,"ts_in_delta":983,"sequence":155328,"symbol":"FCEU SI 20260615 PS"}
{"ts_recv":"2026-04-07T02:17:11.333754563Z","hd":{"ts_event":"2026-04-07T02:17:11.333733247Z","rtype":160,"publisher_id":101,"instrument_id":436},"action":"A","side":"B","price":"1.156310000","size":30,"channel_id":23,"order_id":"10998900268188514866","flags":0,"ts_in_delta":983,"sequence":155328,"symbol":"FCEU SI 20260615 PS"}
{"ts_recv":"2026-04-07T02:17:11.333754563Z","hd":{"ts_event":"2026-04-07T02:17:11.333733247Z","rtype":160,"publisher_id":101,"instrument_id":436},"action":"C","side":"A","price":"1.156390000","size":30,"channel_id":23,"order_id":"1775528231324401537","flags":0,"ts_in_delta":983,"sequence":155328,"symbol":"FCEU SI 20260615 PS"}
{"ts_recv":"2026-04-07T02:17:11.333754563Z","hd":{"ts_event":"2026-04-07T02:17:11.333733247Z","rtype":160,"publisher_id":101,"instrument_id":436},"action":"A","side":"A","price":"1.156410000","size":30,"channel_id":23,"order_id":"1775528231333739058","flags":128,"ts_in_delta":983,"sequence":155328,"symbol":"FCEU SI 20260615 PS"}
{"ts_recv":"2026-04-07T02:17:11.333811700Z","hd":{"ts_event":"2026-04-07T02:17:11.333794649Z","rtype":160,"publisher_id":101,"instrument_id":436},"action":"C","side":"B","price":"1.156300000","size":30,"channel_id":23,"order_id":"10998900268185026484","flags":0,"ts_in_delta":966,"sequence":155329,"symbol":"FCEU SI 20260615 PS"}
{"ts_recv":"2026-04-07T02:17:11.333811700Z","hd":{"ts_event":"2026-04-07T02:17:11.333794649Z","rtype":160,"publisher_id":101,"instrument_id":436},"action":"A","side":"B","price":"1.156310000","size":30,"channel_id":23,"order_id":"10998900268188576512","flags":0,"ts_in_delta":966,"sequence":155329,"symbol":"FCEU SI 20260615 PS"}
{"ts_recv":"2026-04-07T02:17:11.333811700Z","hd":{"ts_event":"2026-04-07T02:17:11.333794649Z","rtype":160,"publisher_id":101,"instrument_id":436},"action":"C","side":"A","price":"1.156400000","size":30,"channel_id":23,"order_id":"1775528231330250676","flags":0,"ts_in_delta":966,"sequence":155329,"symbol":"FCEU SI 20260615 PS"}
{"ts_recv":"2026-04-07T02:17:11.333811700Z","hd":{"ts_event":"2026-04-07T02:17:11.333794649Z","rtype":160,"publisher_id":101,"instrument_id":436},"action":"A","side":"A","price":"1.156410000","size":30,"channel_id":23,"order_id":"1775528231333800704","flags":128,"ts_in_delta":966,"sequence":155329,"symbol":"FCEU SI 20260615 PS"}
{"ts_recv":"2026-04-07T02:17:14.896436253Z","hd":{"ts_event":"2026-04-07T02:17:14.896403215Z","rtype":160,"publisher_id":101,"instrument_id":436},"action":"C","side":"B","price":"1.156310000","size":30,"channel_id":23,"order_id":"10998900268188576512","flags":0,"ts_in_delta":1577,"sequence":155378,"symbol":"FCEU SI 20260615 PS"}
{"ts_recv":"2026-04-07T02:17:14.896436253Z","hd":{"ts_event":"2026-04-07T02:17:14.896403215Z","rtype":160,"publisher_id":101,"instrument_id":436},"action":"A","side":"B","price":"1.156320000","size":30,"channel_id":23,"order_id":"10998900271751192423","flags":0,"ts_in_delta":1577,"sequence":155378,"symbol":"FCEU SI 20260615 PS"}
{"ts_recv":"2026-04-07T02:17:14.896436253Z","hd":{"ts_event":"2026-04-07T02:17:14.896403215Z","rtype":160,"publisher_id":101,"instrument_id":436},"action":"C","side":"A","price":"1.156410000","size":30,"channel_id":23,"order_id":"1775528231333800704","flags":0,"ts_in_delta":1577,"sequence":155378,"symbol":"FCEU SI 20260615 PS"}
{"ts_recv":"2026-04-07T02:17:14.896436253Z","hd":{"ts_event":"2026-04-07T02:17:14.896403215Z","rtype":160,"publisher_id":101,"instrument_id":436},"action":"A","side":"A","price":"1.156420000","size":30,"channel_id":23,"order_id":"1775528234896416615","flags":128,"ts_in_delta":1577,"sequence":155378,"symbol":"FCEU SI 20260615 PS"}
{"ts_recv":"2026-04-07T02:17:14.896502283Z","hd":{"ts_event":"2026-04-07T02:17:14.896483737Z","rtype":160,"publisher_id":101,"instrument_id":436},"action":"C","side":"B","price":"1.156310000","size":30,"channel_id":23,"order_id":"10998900268188514866","flags":0,"ts_in_delta":1034,"sequence":155379,"symbol":"FCEU SI 20260615 PS"}
{"ts_recv":"2026-04-07T02:17:14.896502283Z","hd":{"ts_event":"2026-04-07T02:17:14.896483737Z","rtype":160,"publisher_id":101,"instrument_id":436},"action":"A","side":"B","price":"1.156330000","size":30,"channel_id":23,"order_id":"10998900271751265486","flags":0,"ts_in_delta":1034,"sequence":155379,"symbol":"FCEU SI 20260615 PS"}
{"ts_recv":"2026-04-07T02:17:14.896502283Z","hd":{"ts_event":"2026-04-07T02:17:14.896483737Z","rtype":160,"publisher_id":101,"instrument_id":436},"action":"C","side":"A","price":"1.156410000","size":30,"channel_id":23,"order_id":"1775528231333739058","flags":0,"ts_in_delta":1034,"sequence":155379,"symbol":"FCEU SI 20260615 PS"}
{"ts_recv":"2026-04-07T02:17:14.896502283Z","hd":{"ts_event":"2026-04-07T02:17:14.896483737Z","rtype":160,"publisher_id":101,"instrument_id":436},"action":"A","side":"A","price":"1.156430000","size":30,"channel_id":23,"order_id":"1775528234896489678","flags":128,"ts_in_delta":1034,"sequence":155379,"symbol":"FCEU SI 20260615 PS"}
{"ts_recv":"2026-04-07T02:17:14.896564849Z","hd":{"ts_event":"2026-04-07T02:17:14.896544869Z","rtype":160,"publisher_id":101,"instrument_id":436},"action":"C","side":"B","price":"1.156320000","size":30,"channel_id":23,"order_id":"10998900271751192423","flags":0,"ts_in_delta":874,"sequence":155380,"symbol":"FCEU SI 20260615 PS"}
{"ts_recv":"2026-04-07T02:17:14.896564849Z","hd":{"ts_event":"2026-04-07T02:17:14.896544869Z","rtype":160,"publisher_id":101,"instrument_id":436},"action":"A","side":"B","price":"1.156330000","size":30,"channel_id":23,"order_id":"10998900271751327031","flags":0,"ts_in_delta":874,"sequence":155380,"symbol":"FCEU SI 20260615 PS"}
{"ts_recv":"2026-04-07T02:17:14.896564849Z","hd":{"ts_event":"2026-04-07T02:17:14.896544869Z","rtype":160,"publisher_id":101,"instrument_id":436},"action":"C","side":"A","price":"1.156420000","size":30,"channel_id":23,"order_id":"1775528234896416615","flags":0,"ts_in_delta":874,"sequence":155380,"symbol":"FCEU SI 20260615 PS"}
{"ts_recv":"2026-04-07T02:17:14.896564849Z","hd":{"ts_event":"2026-04-07T02:17:14.896544869Z","rtype":160,"publisher_id":101,"instrument_id":436},"action":"A","side":"A","price":"1.156430000","size":30,"channel_id":23,"order_id":"1775528234896551223","flags":128,"ts_in_delta":874,"sequence":155380,"symbol":"FCEU SI 20260615 PS"}
{"ts_recv":"2026-04-07T02:17:14.898681728Z","hd":{"ts_event":"2026-04-07T02:17:14.898668781Z","rtype":160,"publisher_id":101,"instrument_id":436},"action":"C","side":"A","price":"1.156500000","size":20,"channel_id":23,"order_id":"1775528206631260239","flags":128,"ts_in_delta":766,"sequence":155382,"symbol":"FCEU SI 20260615 PS"}
{"ts_recv":"2026-04-07T02:17:14.985724533Z","hd":{"ts_event":"2026-04-07T02:17:14.985710013Z","rtype":160,"publisher_id":101,"instrument_id":436},"action":"A","side":"A","price":"1.156600000","size":20,"channel_id":23,"order_id":"1775528234985716212","flags":128,"ts_in_delta":910,"sequence":155384,"symbol":"FCEU SI 20260615 PS"}
{"ts_recv":"2026-04-07T02:17:22.335222631Z","hd":{"ts_event":"2026-04-07T02:17:22.335199955Z","rtype":160,"publisher_id":101,"instrument_id":436},"action":"C","side":"B","price":"1.156330000","size":30,"channel_id":23,"order_id":"10998900271751327031","flags":0,"ts_in_delta":1240,"sequence":155437,"symbol":"FCEU SI 20260615 PS"}
{"ts_recv":"2026-04-07T02:17:22.335222631Z","hd":{"ts_event":"2026-04-07T02:17:22.335199955Z","rtype":160,"publisher_id":101,"instrument_id":436},"action":"A","side":"B","price":"1.156320000","size":30,"channel_id":23,"order_id":"10998900279189982023","flags":0,"ts_in_delta":1240,"sequence":155437,"symbol":"FCEU SI 20260615 PS"}
{"ts_recv":"2026-04-07T02:17:22.335222631Z","hd":{"ts_event":"2026-04-07T02:17:22.335199955Z","rtype":160,"publisher_id":101,"instrument_id":436},"action":"C","side":"A","price":"1.156430000","size":30,"channel_id":23,"order_id":"1775528234896551223","flags":0,"ts_in_delta":1240,"sequence":155437,"symbol":"FCEU SI 20260615 PS"}
{"ts_recv":"2026-04-07T02:17:22.335222631Z","hd":{"ts_event":"2026-04-07T02:17:22.335199955Z","rtype":160,"publisher_id":101,"instrument_id":436},"action":"A","side":"A","price":"1.156420000","size":30,"channel_id":23,"order_id":"1775528242335206215","flags":128,"ts_in_delta":1240,"sequence":155437,"symbol":"FCEU SI 20260615 PS"}
{"ts_recv":"2026-04-07T02:17:22.335307883Z","hd":{"ts_event":"2026-04-07T02:17:22.335290061Z","rtype":160,"publisher_id":101,"instrument_id":436},"action":"C","side":"B","price":"1.156320000","size":30,"channel_id":23,"order_id":"10998900279189982023","flags":0,"ts_in_delta":998,"sequence":155438,"symbol":"FCEU SI 20260615 PS"}
{"ts_recv":"2026-04-07T02:17:22.335307883Z","hd":{"ts_event":"2026-04-07T02:17:22.335290061Z","rtype":160,"publisher_id":101,"instrument_id":436},"action":"A","side":"B","price":"1.156310000","size":30,"channel_id":23,"order_id":"10998900279190071776","flags":0,"ts_in_delta":998,"sequence":155438,"symbol":"FCEU SI 20260615 PS"}
{"ts_recv":"2026-04-07T02:17:22.335307883Z","hd":{"ts_event":"2026-04-07T02:17:22.335290061Z","rtype":160,"publisher_id":101,"instrument_id":436},"action":"C","side":"A","price":"1.156420000","size":30,"channel_id":23,"order_id":"1775528242335206215","flags":0,"ts_in_delta":998,"sequence":155438,"symbol":"FCEU SI 20260615 PS"}
{"ts_recv":"2026-04-07T02:17:22.335307883Z","hd":{"ts_event":"2026-04-07T02:17:22.335290061Z","rtype":160,"publisher_id":101,"instrument_id":436},"action":"A","side":"A","price":"1.156410000","size":30,"channel_id":23,"order_id":"1775528242335295968","flags":128,"ts_in_delta":998,"sequence":155438,"symbol":"FCEU SI 20260615 PS"}
{"ts_recv":"2026-04-07T02:17:22.335364635Z","hd":{"ts_event":"2026-04-07T02:17:22.335348719Z","rtype":160,"publisher_id":101,"instrument_id":436},"action":"C","side":"B","price":"1.156310000","size":30,"channel_id":23,"order_id":"10998900279190071776","flags":0,"ts_in_delta":894,"sequence":155439,"symbol":"FCEU SI 20260615 PS"}
{"ts_recv":"2026-04-07T02:17:22.335364635Z","hd":{"ts_event":"2026-04-07T02:17:22.335348719Z","rtype":160,"publisher_id":101,"instrument_id":436},"action":"A","side":"B","price":"1.156320000","size":30,"channel_id":23,"order_id":"10998900279190130596","flags":0,"ts_in_delta":894,"sequence":155439,"symbol":"FCEU SI 20260615 PS"}
{"ts_recv":"2026-04-07T02:17:22.335364635Z","hd":{"ts_event":"2026-04-07T02:17:22.335348719Z","rtype":160,"publisher_id":101,"instrument_id":436},"action":"C","side":"A","price":"1.156410000","size":30,"channel_id":23,"order_id":"1775528242335295968","flags":0,"ts_in_delta":894,"sequence":155439,"symbol":"FCEU SI 20260615 PS"}
{"ts_recv":"2026-04-07T02:17:22.335364635Z","hd":{"ts_event":"2026-04-07T02:17:22.335348719Z","rtype":160,"publisher_id":101,"instrument_id":436},"action":"A","side":"A","price":"1.156420000","size":30,"channel_id":23,"order_id":"1775528242335354788","flags":128,"ts_in_delta":894,"sequence":155439,"symbol":"FCEU SI 20260615 PS"}
{"ts_recv":"2026-04-07T02:17:25.658707246Z","hd":{"ts_event":"2026-04-07T02:17:25.658676671Z","rtype":160,"publisher_id":101,"instrument_id":436},"action":"C","side":"B","price":"1.156320000","size":30,"channel_id":23,"order_id":"10998900279190130596","flags":0,"ts_in_delta":1641,"sequence":155460,"symbol":"FCEU SI 20260615 PS"}
{"ts_recv":"2026-04-07T02:17:25.658707246Z","hd":{"ts_event":"2026-04-07T02:17:25.658676671Z","rtype":160,"publisher_id":101,"instrument_id":436},"action":"A","side":"B","price":"1.156330000","size":30,"channel_id":23,"order_id":"10998900282513465943","flags":0,"ts_in_delta":1641,"sequence":155460,"symbol":"FCEU SI 20260615 PS"}
{"ts_recv":"2026-04-07T02:17:25.658707246Z","hd":{"ts_event":"2026-04-07T02:17:25.658676671Z","rtype":160,"publisher_id":101,"instrument_id":436},"action":"C","side":"A","price":"1.156420000","size":30,"channel_id":23,"order_id":"1775528242335354788","flags":0,"ts_in_delta":1641,"sequence":155460,"symbol":"FCEU SI 20260615 PS"}
{"ts_recv":"2026-04-07T02:17:25.658707246Z","hd":{"ts_event":"2026-04-07T02:17:25.658676671Z","rtype":160,"publisher_id":101,"instrument_id":436},"action":"A","side":"A","price":"1.156430000","size":30,"channel_id":23,"order_id":"1775528245658690135","flags":128,"ts_in_delta":1641,"sequence":155460,"symbol":"FCEU SI 20260615 PS"}
{"ts_recv":"2026-04-07T02:17:30.115184038Z","hd":{"ts_event":"2026-04-07T02:17:30.115164609Z","rtype":160,"publisher_id":101,"instrument_id":436},"action":"C","side":"B","price":"1.156330000","size":30,"channel_id":23,"order_id":"10998900282513465943","flags":0,"ts_in_delta":960,"sequence":155495,"symbol":"FCEU SI 20260615 PS"}
{"ts_recv":"2026-04-07T02:17:30.115184038Z","hd":{"ts_event":"2026-04-07T02:17:30.115164609Z","rtype":160,"publisher_id":101,"instrument_id":436},"action":"A","side":"B","price":"1.156320000","size":30,"channel_id":23,"order_id":"10998900286969946782","flags":0,"ts_in_delta":960,"sequence":155495,"symbol":"FCEU SI 20260615 PS"}
{"ts_recv":"2026-04-07T02:17:30.115184038Z","hd":{"ts_event":"2026-04-07T02:17:30.115164609Z","rtype":160,"publisher_id":101,"instrument_id":436},"action":"C","side":"A","price":"1.156430000","size":30,"channel_id":23,"order_id":"1775528245658690135","flags":0,"ts_in_delta":960,"sequence":155495,"symbol":"FCEU SI 20260615 PS"}
{"ts_recv":"2026-04-07T02:17:30.115184038Z","hd":{"ts_event":"2026-04-07T02:17:30.115164609Z","rtype":160,"publisher_id":101,"instrument_id":436},"action":"A","side":"A","price":"1.156420000","size":30,"channel_id":23,"order_id":"1775528250115170974","flags":128,"ts_in_delta":960,"sequence":155495,"symbol":"FCEU SI 20260615 PS"}
{"ts_recv":"2026-04-07T02:17:32.754427937Z","hd":{"ts_event":"2026-04-07T02:17:32.754404625Z","rtype":160,"publisher_id":101,"instrument_id":436},"action":"C","side":"B","price":"1.156320000","size":30,"channel_id":23,"order_id":"10998900286969946782","flags":0,"ts_in_delta":925,"sequence":155512,"symbol":"FCEU SI 20260615 PS"}
{"ts_recv":"2026-04-07T02:17:32.754427937Z","hd":{"ts_event":"2026-04-07T02:17:32.754404625Z","rtype":160,"publisher_id":101,"instrument_id":436},"action":"A","side":"B","price":"1.156310000","size":30,"channel_id":23,"order_id":"10998900289609186421","flags":0,"ts_in_delta":925,"sequence":155512,"symbol":"FCEU SI 20260615 PS"}
{"ts_recv":"2026-04-07T02:17:32.754427937Z","hd":{"ts_event":"2026-04-07T02:17:32.754404625Z","rtype":160,"publisher_id":101,"instrument_id":436},"action":"C","side":"A","price":"1.156420000","size":30,"channel_id":23,"order_id":"1775528250115170974","flags":0,"ts_in_delta":925,"sequence":155512,"symbol":"FCEU SI 20260615 PS"}
{"ts_recv":"2026-04-07T02:17:32.754427937Z","hd":{"ts_event":"2026-04-07T02:17:32.754404625Z","rtype":160,"publisher_id":101,"instrument_id":436},"action":"A","side":"A","price":"1.156410000","size":30,"channel_id":23,"order_id":"1775528252754410613","flags":128,"ts_in_delta":925,"sequence":155512,"symbol":"FCEU SI 20260615 PS"}
{"ts_recv":"2026-04-07T02:17:32.759179643Z","hd":{"ts_event":"2026-04-07T02:17:32.759163199Z","rtype":160,"publisher_id":101,"instrument_id":436},"action":"C","side":"B","price":"1.156310000","size":30,"channel_id":23,"order_id":"10998900289609186421","flags":0,"ts_in_delta":1044,"sequence":155514,"symbol":"FCEU SI 20260615 PS"}
{"ts_recv":"2026-04-07T02:17:32.759179643Z","hd":{"ts_event":"2026-04-07T02:17:32.759163199Z","rtype":160,"publisher_id":101,"instrument_id":436},"action":"A","side":"B","price":"1.156320000","size":30,"channel_id":23,"order_id":"10998900289613944847","flags":0,"ts_in_delta":1044,"sequence":155514,"symbol":"FCEU SI 20260615 PS"}
{"ts_recv":"2026-04-07T02:17:32.759179643Z","hd":{"ts_event":"2026-04-07T02:17:32.759163199Z","rtype":160,"publisher_id":101,"instrument_id":436},"action":"C","side":"A","price":"1.156410000","size":30,"channel_id":23,"order_id":"1775528252754410613","flags":0,"ts_in_delta":1044,"sequence":155514,"symbol":"FCEU SI 20260615 PS"}
{"ts_recv":"2026-04-07T02:17:32.759179643Z","hd":{"ts_event":"2026-04-07T02:17:32.759163199Z","rtype":160,"publisher_id":101,"instrument_id":436},"action":"A","side":"A","price":"1.156420000","size":30,"channel_id":23,"order_id":"1775528252759169039","flags":128,"ts_in_delta":1044,"sequence":155514,"symbol":"FCEU SI 20260615 PS"}
{"ts_recv":"2026-04-07T02:17:32.958323320Z","hd":{"ts_event":"2026-04-07T02:17:32.958304431Z","rtype":160,"publisher_id":101,"instrument_id":436},"action":"C","side":"B","price":"1.156320000","size":30,"channel_id":23,"order_id":"10998900289613944847","flags":0,"ts_in_delta":1205,"sequence":155519,"symbol":"FCEU SI 20260615 PS"}
{"ts_recv":"2026-04-07T02:17:32.958323320Z","hd":{"ts_event":"2026-04-07T02:17:32.958304431Z","rtype":160,"publisher_id":101,"instrument_id":436},"action":"A","side":"B","price":"1.156330000","size":30,"channel_id":23,"order_id":"10998900289813086104","flags":0,"ts_in_delta":1205,"sequence":155519,"symbol":"FCEU SI 20260615 PS"}
{"ts_recv":"2026-04-07T02:17:32.958323320Z","hd":{"ts_event":"2026-04-07T02:17:32.958304431Z","rtype":160,"publisher_id":101,"instrument_id":436},"action":"C","side":"A","price":"1.156420000","size":30,"channel_id":23,"order_id":"1775528252759169039","flags":0,"ts_in_delta":1205,"sequence":155519,"symbol":"FCEU SI 20260615 PS"}
{"ts_recv":"2026-04-07T02:17:32.958323320Z","hd":{"ts_event":"2026-04-07T02:17:32.958304431Z","rtype":160,"publisher_id":101,"instrument_id":436},"action":"A","side":"A","price":"1.156430000","size":30,"channel_id":23,"order_id":"1775528252958310296","flags":128,"ts_in_delta":1205,"sequence":155519,"symbol":"FCEU SI 20260615 PS"}
{"ts_recv":"2026-04-07T02:17:37.100659960Z","hd":{"ts_event":"2026-04-07T02:17:37.100638781Z","rtype":160,"publisher_id":101,"instrument_id":436},"action":"C","side":"B","price":"1.156330000","size":30,"channel_id":23,"order_id":"10998900289813086104","flags":0,"ts_in_delta":907,"sequence":155538,"symbol":"FCEU SI 20260615 PS"}
{"ts_recv":"2026-04-07T02:17:37.100659960Z","hd":{"ts_event":"2026-04-07T02:17:37.100638781Z","rtype":160,"publisher_id":101,"instrument_id":436},"action":"A","side":"B","price":"1.156320000","size":30,"channel_id":23,"order_id":"10998900293955421142","flags":0,"ts_in_delta":907,"sequence":155538,"symbol":"FCEU SI 20260615 PS"}
{"ts_recv":"2026-04-07T02:17:37.100659960Z","hd":{"ts_event":"2026-04-07T02:17:37.100638781Z","rtype":160,"publisher_id":101,"instrument_id":436},"action":"C","side":"A","price":"1.156430000","size":30,"channel_id":23,"order_id":"1775528252958310296","flags":0,"ts_in_delta":907,"sequence":155538,"symbol":"FCEU SI 20260615 PS"}
{"ts_recv":"2026-04-07T02:17:37.100659960Z","hd":{"ts_event":"2026-04-07T02:17:37.100638781Z","rtype":160,"publisher_id":101,"instrument_id":436},"action":"A","side":"A","price":"1.156420000","size":30,"channel_id":23,"order_id":"1775528257100645334","flags":128,"ts_in_delta":907,"sequence":155538,"symbol":"FCEU SI 20260615 PS"}
{"ts_recv":"2026-04-07T02:17:37.809322118Z","hd":{"ts_event":"2026-04-07T02:17:37.809301639Z","rtype":160,"publisher_id":101,"instrument_id":436},"action":"C","side":"B","price":"1.156320000","size":30,"channel_id":23,"order_id":"10998900293955421142","flags":0,"ts_in_delta":911,"sequence":155570,"symbol":"FCEU SI 20260615 PS"}
{"ts_recv":"2026-04-07T02:17:37.809322118Z","hd":{"ts_event":"2026-04-07T02:17:37.809301639Z","rtype":160,"publisher_id":101,"instrument_id":436},"action":"A","side":"B","price":"1.156310000","size":30,"channel_id":23,"order_id":"10998900294664083656","flags":0,"ts_in_delta":911,"sequence":155570,"symbol":"FCEU SI 20260615 PS"}
{"ts_recv":"2026-04-07T02:17:37.809322118Z","hd":{"ts_event":"2026-04-07T02:17:37.809301639Z","rtype":160,"publisher_id":101,"instrument_id":436},"action":"C","side":"A","price":"1.156420000","size":30,"channel_id":23,"order_id":"1775528257100645334","flags":0,"ts_in_delta":911,"sequence":155570,"symbol":"FCEU SI 20260615 PS"}
{"ts_recv":"2026-04-07T02:17:37.809322118Z","hd":{"ts_event":"2026-04-07T02:17:37.809301639Z","rtype":160,"publisher_id":101,"instrument_id":436},"action":"A","side":"A","price":"1.156410000","size":30,"channel_id":23,"order_id":"1775528257809307848","flags":128,"ts_in_delta":911,"sequence":155570,"symbol":"FCEU SI 20260615 PS"}
{"ts_recv":"2026-04-07T02:17:37.809375431Z","hd":{"ts_event":"2026-04-07T02:17:37.809357739Z","rtype":160,"publisher_id":101,"instrument_id":436},"action":"C","side":"B","price":"1.156330000","size":30,"channel_id":23,"order_id":"10998900271751265486","flags":0,"ts_in_delta":722,"sequence":155571,"symbol":"FCEU SI 20260615 PS"}
{"ts_recv":"2026-04-07T02:17:37.809375431Z","hd":{"ts_event":"2026-04-07T02:17:37.809357739Z","rtype":160,"publisher_id":101,"instrument_id":436},"action":"A","side":"B","price":"1.156310000","size":30,"channel_id":23,"order_id":"10998900294664139712","flags":0,"ts_in_delta":722,"sequence":155571,"symbol":"FCEU SI 20260615 PS"}
{"ts_recv":"2026-04-07T02:17:37.809375431Z","hd":{"ts_event":"2026-04-07T02:17:37.809357739Z","rtype":160,"publisher_id":101,"instrument_id":436},"action":"C","side":"A","price":"1.156430000","size":30,"channel_id":23,"order_id":"1775528234896489678","flags":0,"ts_in_delta":722,"sequence":155571,"symbol":"FCEU SI 20260615 PS"}
{"ts_recv":"2026-04-07T02:17:37.809375431Z","hd":{"ts_event":"2026-04-07T02:17:37.809357739Z","rtype":160,"publisher_id":101,"instrument_id":436},"action":"A","side":"A","price":"1.156410000","size":30,"channel_id":23,"order_id":"1775528257809363904","flags":128,"ts_in_delta":722,"sequence":155571,"symbol":"FCEU SI 20260615 PS"}
{"ts_recv":"2026-04-07T02:17:37.809428650Z","hd":{"ts_event":"2026-04-07T02:17:37.809410209Z","rtype":160,"publisher_id":101,"instrument_id":436},"action":"C","side":"B","price":"1.156310000","size":30,"channel_id":23,"order_id":"10998900294664083656","flags":0,"ts_in_delta":770,"sequence":155572,"symbol":"FCEU SI 20260615 PS"}
{"ts_recv":"2026-04-07T02:17:37.809428650Z","hd":{"ts_event":"2026-04-07T02:17:37.809410209Z","rtype":160,"publisher_id":101,"instrument_id":436},"action":"A","side":"B","price":"1.156300000","size":30,"channel_id":23,"order_id":"10998900294664191874","flags":0,"ts_in_delta":770,"sequence":155572,"symbol":"FCEU SI 20260615 PS"}
{"ts_recv":"2026-04-07T02:17:37.809428650Z","hd":{"ts_event":"2026-04-07T02:17:37.809410209Z","rtype":160,"publisher_id":101,"instrument_id":436},"action":"C","side":"A","price":"1.156410000","size":30,"channel_id":23,"order_id":"1775528257809307848","flags":0,"ts_in_delta":770,"sequence":155572,"symbol":"FCEU SI 20260615 PS"}
{"ts_recv":"2026-04-07T02:17:37.809428650Z","hd":{"ts_event":"2026-04-07T02:17:37.809410209Z","rtype":160,"publisher_id":101,"instrument_id":436},"action":"A","side":"A","price":"1.156400000","size":30,"channel_id":23,"order_id":"1775528257809416066","flags":128,"ts_in_delta":770,"sequence":155572,"symbol":"FCEU SI 20260615 PS"}
{"ts_recv":"2026-04-07T02:17:37.809510254Z","hd":{"ts_event":"2026-04-07T02:17:37.809491579Z","rtype":160,"publisher_id":101,"instrument_id":436},"action":"C","side":"B","price":"1.156300000","size":30,"channel_id":23,"order_id":"10998900294664191874","flags":0,"ts_in_delta":728,"sequence":155574,"symbol":"FCEU SI 20260615 PS"}
{"ts_recv":"2026-04-07T02:17:37.809510254Z","hd":{"ts_event":"2026-04-07T02:17:37.809491579Z","rtype":160,"publisher_id":101,"instrument_id":436},"action":"A","side":"B","price":"1.156290000","size":30,"channel_id":23,"order_id":"10998900294664273030","flags":0,"ts_in_delta":728,"sequence":155574,"symbol":"FCEU SI 20260615 PS"}
{"ts_recv":"2026-04-07T02:17:37.809510254Z","hd":{"ts_event":"2026-04-07T02:17:37.809491579Z","rtype":160,"publisher_id":101,"instrument_id":436},"action":"C","side":"A","price":"1.156400000","size":30,"channel_id":23,"order_id":"1775528257809416066","flags":0,"ts_in_delta":728,"sequence":155574,"symbol":"FCEU SI 20260615 PS"}
{"ts_recv":"2026-04-07T02:17:37.809510254Z","hd":{"ts_event":"2026-04-07T02:17:37.809491579Z","rtype":160,"publisher_id":101,"instrument_id":436},"action":"A","side":"A","price":"1.156390000","size":30,"channel_id":23,"order_id":"1775528257809497222","flags":128,"ts_in_delta":728,"sequence":155574,"symbol":"FCEU SI 20260615 PS"}
{"ts_recv":"2026-04-07T02:17:37.809567375Z","hd":{"ts_event":"2026-04-07T02:17:37.809551291Z","rtype":160,"publisher_id":101,"instrument_id":436},"action":"C","side":"B","price":"1.156290000","size":30,"channel_id":23,"order_id":"10998900294664273030","flags":0,"ts_in_delta":949,"sequence":155575,"symbol":"FCEU SI 20260615 PS"}
{"ts_recv":"2026-04-07T02:17:37.809567375Z","hd":{"ts_event":"2026-04-07T02:17:37.809551291Z","rtype":160,"publisher_id":101,"instrument_id":436},"action":"A","side":"B","price":"1.156300000","size":30,"channel_id":23,"order_id":"10998900294664333028","flags":0,"ts_in_delta":949,"sequence":155575,"symbol":"FCEU SI 20260615 PS"}
{"ts_recv":"2026-04-07T02:17:37.809567375Z","hd":{"ts_event":"2026-04-07T02:17:37.809551291Z","rtype":160,"publisher_id":101,"instrument_id":436},"action":"C","side":"A","price":"1.156390000","size":30,"channel_id":23,"order_id":"1775528257809497222","flags":0,"ts_in_delta":949,"sequence":155575,"symbol":"FCEU SI 20260615 PS"}
{"ts_recv":"2026-04-07T02:17:37.809567375Z","hd":{"ts_event":"2026-04-07T02:17:37.809551291Z","rtype":160,"publisher_id":101,"instrument_id":436},"action":"A","side":"A","price":"1.156400000","size":30,"channel_id":23,"order_id":"1775528257809557220","flags":128,"ts_in_delta":949,"sequence":155575,"symbol":"FCEU SI 20260615 PS"}
{"ts_recv":"2026-04-07T02:17:46.910760387Z","hd":{"ts_event":"2026-04-07T02:17:46.910737027Z","rtype":160,"publisher_id":101,"instrument_id":436},"action":"C","side":"B","price":"1.156310000","size":30,"channel_id":23,"order_id":"10998900294664139712","flags":0,"ts_in_delta":948,"sequence":155730,"symbol":"FCEU SI 20260615 PS"}
{"ts_recv":"2026-04-07T02:17:46.910760387Z","hd":{"ts_event":"2026-04-07T02:17:46.910737027Z","rtype":160,"publisher_id":101,"instrument_id":436},"action":"A","side":"B","price":"1.156290000","size":30,"channel_id":23,"order_id":"10998900303765519427","flags":0,"ts_in_delta":948,"sequence":155730,"symbol":"FCEU SI 20260615 PS"}
{"ts_recv":"2026-04-07T02:17:46.910760387Z","hd":{"ts_event":"2026-04-07T02:17:46.910737027Z","rtype":160,"publisher_id":101,"instrument_id":436},"action":"C","side":"A","price":"1.156410000","size":30,"channel_id":23,"order_id":"1775528257809363904","flags":0,"ts_in_delta":948,"sequence":155730,"symbol":"FCEU SI 20260615 PS"}
{"ts_recv":"2026-04-07T02:17:46.910760387Z","hd":{"ts_event":"2026-04-07T02:17:46.910737027Z","rtype":160,"publisher_id":101,"instrument_id":436},"action":"A","side":"A","price":"1.156390000","size":30,"channel_id":23,"order_id":"1775528266910743619","flags":128,"ts_in_delta":948,"sequence":155730,"symbol":"FCEU SI 20260615 PS"}
{"ts_recv":"2026-04-07T02:17:46.910851683Z","hd":{"ts_event":"2026-04-07T02:17:46.910835351Z","rtype":160,"publisher_id":101,"instrument_id":436},"action":"C","side":"B","price":"1.156300000","size":30,"channel_id":23,"order_id":"10998900294664333028","flags":0,"ts_in_delta":958,"sequence":155731,"symbol":"FCEU SI 20260615 PS"}
{"ts_recv":"2026-04-07T02:17:46.910851683Z","hd":{"ts_event":"2026-04-07T02:17:46.910835351Z","rtype":160,"publisher_id":101,"instrument_id":436},"action":"A","side":"B","price":"1.156290000","size":30,"channel_id":23,"order_id":"10998900303765617364","flags":0,"ts_in_delta":958,"sequence":155731,"symbol":"FCEU SI 20260615 PS"}
{"ts_recv":"2026-04-07T02:17:46.910851683Z","hd":{"ts_event":"2026-04-07T02:17:46.910835351Z","rtype":160,"publisher_id":101,"instrument_id":436},"action":"C","side":"A","price":"1.156400000","size":30,"channel_id":23,"order_id":"1775528257809557220","flags":0,"ts_in_delta":958,"sequence":155731,"symbol":"FCEU SI 20260615 PS"}
{"ts_recv":"2026-04-07T02:17:46.910851683Z","hd":{"ts_event":"2026-04-07T02:17:46.910835351Z","rtype":160,"publisher_id":101,"instrument_id":436},"action":"A","side":"A","price":"1.156390000","size":30,"channel_id":23,"order_id":"1775528266910841556","flags":128,"ts_in_delta":958,"sequence":155731,"symbol":"FCEU SI 20260615 PS"}
{"ts_recv":"2026-04-07T02:17:46.917672346Z","hd":{"ts_event":"2026-04-07T02:17:46.917651547Z","rtype":160,"publisher_id":101,"instrument_id":436},"action":"C","side":"B","price":"1.156290000","size":30,"channel_id":23,"order_id":"10998900303765617364","flags":0,"ts_in_delta":1073,"sequence":155738,"symbol":"FCEU SI 20260615 PS"}
{"ts_recv":"2026-04-07T02:17:46.917672346Z","hd":{"ts_event":"2026-04-07T02:17:46.917651547Z","rtype":160,"publisher_id":101,"instrument_id":436},"action":"A","side":"B","price":"1.156280000","size":30,"channel_id":23,"order_id":"10998900303772433150","flags":0,"ts_in_delta":1073,"sequence":155738,"symbol":"FCEU SI 20260615 PS"}
{"ts_recv":"2026-04-07T02:17:46.917672346Z","hd":{"ts_event":"2026-04-07T02:17:46.917651547Z","rtype":160,"publisher_id":101,"instrument_id":436},"action":"C","side":"A","price":"1.156390000","size":30,"channel_id":23,"order_id":"1775528266910841556","flags":0,"ts_in_delta":1073,"sequence":155738,"symbol":"FCEU SI 20260615 PS"}
{"ts_recv":"2026-04-07T02:17:46.917672346Z","hd":{"ts_event":"2026-04-07T02:17:46.917651547Z","rtype":160,"publisher_id":101,"instrument_id":436},"action":"A","side":"A","price":"1.156380000","size":30,"channel_id":23,"order_id":"1775528266917657342","flags":128,"ts_in_delta":1073,"sequence":155738,"symbol":"FCEU SI 20260615 PS"}
{"ts_recv":"2026-04-07T02:17:46.987144191Z","hd":{"ts_event":"2026-04-07T02:17:46.987124047Z","rtype":160,"publisher_id":101,"instrument_id":436},"action":"C","side":"B","price":"1.156280000","size":30,"channel_id":23,"order_id":"10998900303772433150","flags":0,"ts_in_delta":946,"sequence":155758,"symbol":"FCEU SI 20260615 PS"}
{"ts_recv":"2026-04-07T02:17:46.987144191Z","hd":{"ts_event":"2026-04-07T02:17:46.987124047Z","rtype":160,"publisher_id":101,"instrument_id":436},"action":"A","side":"B","price":"1.156270000","size":30,"channel_id":23,"order_id":"10998900303841905584","flags":0,"ts_in_delta":946,"sequence":155758,"symbol":"FCEU SI 20260615 PS"}
{"ts_recv":"2026-04-07T02:17:46.987144191Z","hd":{"ts_event":"2026-04-07T02:17:46.987124047Z","rtype":160,"publisher_id":101,"instrument_id":436},"action":"C","side":"A","price":"1.156380000","size":30,"channel_id":23,"order_id":"1775528266917657342","flags":0,"ts_in_delta":946,"sequence":155758,"symbol":"FCEU SI 20260615 PS"}
{"ts_recv":"2026-04-07T02:17:46.987144191Z","hd":{"ts_event":"2026-04-07T02:17:46.987124047Z","rtype":160,"publisher_id":101,"instrument_id":436},"action":"A","side":"A","price":"1.156370000","size":30,"channel_id":23,"order_id":"1775528266987129776","flags":128,"ts_in_delta":946,"sequence":155758,"symbol":"FCEU SI 20260615 PS"}
{"ts_recv":"2026-04-07T02:17:46.987199177Z","hd":{"ts_event":"2026-04-07T02:17:46.987181603Z","rtype":160,"publisher_id":101,"instrument_id":436},"action":"C","side":"B","price":"1.156290000","size":30,"channel_id":23,"order_id":"10998900303765519427","flags":0,"ts_in_delta":1137,"sequence":155759,"symbol":"FCEU SI 20260615 PS"}
{"ts_recv":"2026-04-07T02:17:46.987199177Z","hd":{"ts_event":"2026-04-07T02:17:46.987181603Z","rtype":160,"publisher_id":101,"instrument_id":436},"action":"A","side":"B","price":"1.156270000","size":30,"channel_id":23,"order_id":"10998900303841963443","flags":0,"ts_in_delta":1137,"sequence":155759,"symbol":"FCEU SI 20260615 PS"}
{"ts_recv":"2026-04-07T02:17:46.987199177Z","hd":{"ts_event":"2026-04-07T02:17:46.987181603Z","rtype":160,"publisher_id":101,"instrument_id":436},"action":"C","side":"A","price":"1.156390000","size":30,"channel_id":23,"order_id":"1775528266910743619","flags":0,"ts_in_delta":1137,"sequence":155759,"symbol":"FCEU SI 20260615 PS"}
{"ts_recv":"2026-04-07T02:17:46.987199177Z","hd":{"ts_event":"2026-04-07T02:17:46.987181603Z","rtype":160,"publisher_id":101,"instrument_id":436},"action":"A","side":"A","price":"1.156370000","size":30,"channel_id":23,"order_id":"1775528266987187635","flags":128,"ts_in_delta":1137,"sequence":155759,"symbol":"FCEU SI 20260615 PS"}
{"ts_recv":"2026-04-07T02:17:46.987257781Z","hd":{"ts_event":"2026-04-07T02:17:46.987236113Z","rtype":160,"publisher_id":101,"instrument_id":436},"action":"C","side":"B","price":"1.156270000","size":30,"channel_id":23,"order_id":"10998900303841905584","flags":0,"ts_in_delta":1125,"sequence":155760,"symbol":"FCEU SI 20260615 PS"}
{"ts_recv":"2026-04-07T02:17:46.987257781Z","hd":{"ts_event":"2026-04-07T02:17:46.987236113Z","rtype":160,"publisher_id":101,"instrument_id":436},"action":"A","side":"B","price":"1.156260000","size":30,"channel_id":23,"order_id":"10998900303842018106","flags":0,"ts_in_delta":1125,"sequence":155760,"symbol":"FCEU SI 20260615 PS"}
{"ts_recv":"2026-04-07T02:17:46.987257781Z","hd":{"ts_event":"2026-04-07T02:17:46.987236113Z","rtype":160,"publisher_id":101,"instrument_id":436},"action":"C","side":"A","price":"1.156370000","size":30,"channel_id":23,"order_id":"1775528266987129776","flags":0,"ts_in_delta":1125,"sequence":155760,"symbol":"FCEU SI 20260615 PS"}
{"ts_recv":"2026-04-07T02:17:46.987257781Z","hd":{"ts_event":"2026-04-07T02:17:46.987236113Z","rtype":160,"publisher_id":101,"instrument_id":436},"action":"A","side":"A","price":"1.156360000","size":30,"channel_id":23,"order_id":"1775528266987242298","flags":128,"ts_in_delta":1125,"sequence":155760,"symbol":"FCEU SI 20260615 PS"}
{"ts_recv":"2026-04-07T02:17:51.631193807Z","hd":{"ts_event":"2026-04-07T02:17:51.631176251Z","rtype":160,"publisher_id":101,"instrument_id":436},"action":"C","side":"B","price":"1.156260000","size":30,"channel_id":23,"order_id":"10998900303842018106","flags":0,"ts_in_delta":1009,"sequence":155835,"symbol":"FCEU SI 20260615 PS"}
{"ts_recv":"2026-04-07T02:17:51.631193807Z","hd":{"ts_event":"2026-04-07T02:17:51.631176251Z","rtype":160,"publisher_id":101,"instrument_id":436},"action":"A","side":"B","price":"1.156270000","size":30,"channel_id":23,"order_id":"10998900308485958074","flags":0,"ts_in_delta":1009,"sequence":155835,"symbol":"FCEU SI 20260615 PS"}
{"ts_recv":"2026-04-07T02:17:51.631193807Z","hd":{"ts_event":"2026-04-07T02:17:51.631176251Z","rtype":160,"publisher_id":101,"instrument_id":436},"action":"C","side":"A","price":"1.156360000","size":30,"channel_id":23,"order_id":"1775528266987242298","flags":0,"ts_in_delta":1009,"sequence":155835,"symbol":"FCEU SI 20260615 PS"}
{"ts_recv":"2026-04-07T02:17:51.631193807Z","hd":{"ts_event":"2026-04-07T02:17:51.631176251Z","rtype":160,"publisher_id":101,"instrument_id":436},"action":"A","side":"A","price":"1.156370000","size":30,"channel_id":23,"order_id":"1775528271631182266","flags":128,"ts_in_delta":1009,"sequence":155835,"symbol":"FCEU SI 20260615 PS"}
{"ts_recv":"2026-04-07T02:18:06.059841025Z","hd":{"ts_event":"2026-04-07T02:18:06.059818291Z","rtype":160,"publisher_id":101,"instrument_id":436},"action":"C","side":"B","price":"1.156270000","size":30,"channel_id":23,"order_id":"10998900303841963443","flags":0,"ts_in_delta":986,"sequence":155978,"symbol":"FCEU SI 20260615 PS"}
{"ts_recv":"2026-04-07T02:18:06.059841025Z","hd":{"ts_event":"2026-04-07T02:18:06.059818291Z","rtype":160,"publisher_id":101,"instrument_id":436},"action":"A","side":"B","price":"1.156290000","size":30,"channel_id":23,"order_id":"10998900322914600419","flags":0,"ts_in_delta":986,"sequence":155978,"symbol":"FCEU SI 20260615 PS"}
{"ts_recv":"2026-04-07T02:18:06.059841025Z","hd":{"ts_event":"2026-04-07T02:18:06.059818291Z","rtype":160,"publisher_id":101,"instrument_id":436},"action":"C","side":"A","price":"1.156370000","size":30,"channel_id":23,"order_id":"1775528266987187635","flags":0,"ts_in_delta":986,"sequence":155978,"symbol":"FCEU SI 20260615 PS"}
{"ts_recv":"2026-04-07T02:18:06.059841025Z","hd":{"ts_event":"2026-04-07T02:18:06.059818291Z","rtype":160,"publisher_id":101,"instrument_id":436},"action":"A","side":"A","price":"1.156390000","size":30,"channel_id":23,"order_id":"1775528286059824611","flags":128,"ts_in_delta":986,"sequence":155978,"symbol":"FCEU SI 20260615 PS"}
{"ts_recv":"2026-04-07T02:18:06.059912453Z","hd":{"ts_event":"2026-04-07T02:18:06.059893901Z","rtype":160,"publisher_id":101,"instrument_id":436},"action":"C","side":"B","price":"1.156270000","size":30,"channel_id":23,"order_id":"10998900308485958074","flags":0,"ts_in_delta":905,"sequence":155979,"symbol":"FCEU SI 20260615 PS"}
{"ts_recv":"2026-04-07T02:18:06.059912453Z","hd":{"ts_event":"2026-04-07T02:18:06.059893901Z","rtype":160,"publisher_id":101,"instrument_id":436},"action":"A","side":"B","price":"1.156280000","size":30,"channel_id":23,"order_id":"10998900322914675528","flags":0,"ts_in_delta":905,"sequence":155979,"symbol":"FCEU SI 20260615 PS"}
{"ts_recv":"2026-04-07T02:18:06.059912453Z","hd":{"ts_event":"2026-04-07T02:18:06.059893901Z","rtype":160,"publisher_id":101,"instrument_id":436},"action":"C","side":"A","price":"1.156370000","size":30,"channel_id":23,"order_id":"1775528271631182266","flags":0,"ts_in_delta":905,"sequence":155979,"symbol":"FCEU SI 20260615 PS"}
{"ts_recv":"2026-04-07T02:18:06.059912453Z","hd":{"ts_event":"2026-04-07T02:18:06.059893901Z","rtype":160,"publisher_id":101,"instrument_id":436},"action":"A","side":"A","price":"1.156380000","size":30,"channel_id":23,"order_id":"1775528286059899720","flags":128,"ts_in_delta":905,"sequence":155979,"symbol":"FCEU SI 20260615 PS"}
{"ts_recv":"2026-04-07T02:18:06.061430528Z","hd":{"ts_event":"2026-04-07T02:18:06.061411903Z","rtype":160,"publisher_id":101,"instrument_id":436},"action":"C","side":"B","price":"1.156280000","size":30,"channel_id":23,"order_id":"10998900322914675528","flags":0,"ts_in_delta":947,"sequence":155980,"symbol":"FCEU SI 20260615 PS"}
{"ts_recv":"2026-04-07T02:18:06.061430528Z","hd":{"ts_event":"2026-04-07T02:18:06.061411903Z","rtype":160,"publisher_id":101,"instrument_id":436},"action":"A","side":"B","price":"1.156290000","size":30,"channel_id":23,"order_id":"10998900322916193711","flags":0,"ts_in_delta":947,"sequence":155980,"symbol":"FCEU SI 20260615 PS"}
{"ts_recv":"2026-04-07T02:18:06.061430528Z","hd":{"ts_event":"2026-04-07T02:18:06.061411903Z","rtype":160,"publisher_id":101,"instrument_id":436},"action":"C","side":"A","price":"1.156380000","size":30,"channel_id":23,"order_id":"1775528286059899720","flags":0,"ts_in_delta":947,"sequence":155980,"symbol":"FCEU SI 20260615 PS"}
{"ts_recv":"2026-04-07T02:18:06.061430528Z","hd":{"ts_event":"2026-04-07T02:18:06.061411903Z","rtype":160,"publisher_id":101,"instrument_id":436},"action":"A","side":"A","price":"1.156390000","size":30,"channel_id":23,"order_id":"1775528286061417903","flags":128,"ts_in_delta":947,"sequence":155980,"symbol":"FCEU SI 20260615 PS"}
{"ts_recv":"2026-04-07T02:18:08.387933744Z","hd":{"ts_event":"2026-04-07T02:18:08.387914133Z","rtype":160,"publisher_id":101,"instrument_id":436},"action":"C","side":"B","price":"1.156290000","size":30,"channel_id":23,"order_id":"10998900322916193711","flags":0,"ts_in_delta":921,"sequence":156011,"symbol":"FCEU SI 20260615 PS"}
{"ts_recv":"2026-04-07T02:18:08.387933744Z","hd":{"ts_event":"2026-04-07T02:18:08.387914133Z","rtype":160,"publisher_id":101,"instrument_id":436},"action":"A","side":"B","price":"1.156300000","size":30,"channel_id":23,"order_id":"10998900325242695960","flags":0,"ts_in_delta":921,"sequence":156011,"symbol":"FCEU SI 20260615 PS"}
{"ts_recv":"2026-04-07T02:18:08.387933744Z","hd":{"ts_event":"2026-04-07T02:18:08.387914133Z","rtype":160,"publisher_id":101,"instrument_id":436},"action":"C","side":"A","price":"1.156390000","size":30,"channel_id":23,"order_id":"1775528286061417903","flags":0,"ts_in_delta":921,"sequence":156011,"symbol":"FCEU SI 20260615 PS"}
{"ts_recv":"2026-04-07T02:18:08.387933744Z","hd":{"ts_event":"2026-04-07T02:18:08.387914133Z","rtype":160,"publisher_id":101,"instrument_id":436},"action":"A","side":"A","price":"1.156400000","size":30,"channel_id":23,"order_id":"1775528288387920152","flags":128,"ts_in_delta":921,"sequence":156011,"symbol":"FCEU SI 20260615 PS"}
{"ts_recv":"2026-04-07T02:18:08.387995550Z","hd":{"ts_event":"2026-04-07T02:18:08.387977219Z","rtype":160,"publisher_id":101,"instrument_id":436},"action":"C","side":"B","price":"1.156290000","size":30,"channel_id":23,"order_id":"10998900322914600419","flags":0,"ts_in_delta":908,"sequence":156012,"symbol":"FCEU SI 20260615 PS"}
{"ts_recv":"2026-04-07T02:18:08.387995550Z","hd":{"ts_event":"2026-04-07T02:18:08.387977219Z","rtype":160,"publisher_id":101,"instrument_id":436},"action":"A","side":"B","price":"1.156310000","size":30,"channel_id":23,"order_id":"10998900325242759111","flags":0,"ts_in_delta":908,"sequence":156012,"symbol":"FCEU SI 20260615 PS"}
{"ts_recv":"2026-04-07T02:18:08.387995550Z","hd":{"ts_event":"2026-04-07T02:18:08.387977219Z","rtype":160,"publisher_id":101,"instrument_id":436},"action":"C","side":"A","price":"1.156390000","size":30,"channel_id":23,"order_id":"1775528286059824611","flags":0,"ts_in_delta":908,"sequence":156012,"symbol":"FCEU SI 20260615 PS"}
{"ts_recv":"2026-04-07T02:18:08.387995550Z","hd":{"ts_event":"2026-04-07T02:18:08.387977219Z","rtype":160,"publisher_id":101,"instrument_id":436},"action":"A","side":"A","price":"1.156410000","size":30,"channel_id":23,"order_id":"1775528288387983303","flags":128,"ts_in_delta":908,"sequence":156012,"symbol":"FCEU SI 20260615 PS"}
{"ts_recv":"2026-04-07T02:18:08.388048539Z","hd":{"ts_event":"2026-04-07T02:18:08.388030715Z","rtype":160,"publisher_id":101,"instrument_id":436},"action":"C","side":"B","price":"1.156300000","size":30,"channel_id":23,"order_id":"10998900325242695960","flags":0,"ts_in_delta":891,"sequence":156013,"symbol":"FCEU SI 20260615 PS"}
{"ts_recv":"2026-04-07T02:18:08.388048539Z","hd":{"ts_event":"2026-04-07T02:18:08.388030715Z","rtype":160,"publisher_id":101,"instrument_id":436},"action":"A","side":"B","price":"1.156310000","size":30,"channel_id":23,"order_id":"10998900325242812402","flags":0,"ts_in_delta":891,"sequence":156013,"symbol":"FCEU SI 20260615 PS"}
{"ts_recv":"2026-04-07T02:18:08.388048539Z","hd":{"ts_event":"2026-04-07T02:18:08.388030715Z","rtype":160,"publisher_id":101,"instrument_id":436},"action":"C","side":"A","price":"1.156400000","size":30,"channel_id":23,"order_id":"1775528288387920152","flags":0,"ts_in_delta":891,"sequence":156013,"symbol":"FCEU SI 20260615 PS"}
{"ts_recv":"2026-04-07T02:18:08.388048539Z","hd":{"ts_event":"2026-04-07T02:18:08.388030715Z","rtype":160,"publisher_id":101,"instrument_id":436},"action":"A","side":"A","price":"1.156410000","size":30,"channel_id":23,"order_id":"1775528288388036594","flags":128,"ts_in_delta":891,"sequence":156013,"symbol":"FCEU SI 20260615 PS"}
{"ts_recv":"2026-04-07T02:18:13.200316300Z","hd":{"ts_event":"2026-04-07T02:18:13.200288031Z","rtype":160,"publisher_id":101,"instrument_id":436},"action":"C","side":"B","price":"1.156310000","size":30,"channel_id":23,"order_id":"10998900325242759111","flags":0,"ts_in_delta":1370,"sequence":156069,"symbol":"FCEU SI 20260615 PS"}
{"ts_recv":"2026-04-07T02:18:13.200316300Z","hd":{"ts_event":"2026-04-07T02:18:13.200288031Z","rtype":160,"publisher_id":101,"instrument_id":436},"action":"A","side":"B","price":"1.156330000","size":30,"channel_id":23,"order_id":"10998900330055075006","flags":0,"ts_in_delta":1370,"sequence":156069,"symbol":"FCEU SI 20260615 PS"}
{"ts_recv":"2026-04-07T02:18:13.200316300Z","hd":{"ts_event":"2026-04-07T02:18:13.200288031Z","rtype":160,"publisher_id":101,"instrument_id":436},"action":"C","side":"A","price":"1.156410000","size":30,"channel_id":23,"order_id":"1775528288387983303","flags":0,"ts_in_delta":1370,"sequence":156069,"symbol":"FCEU SI 20260615 PS"}
{"ts_recv":"2026-04-07T02:18:13.200316300Z","hd":{"ts_event":"2026-04-07T02:18:13.200288031Z","rtype":160,"publisher_id":101,"instrument_id":436},"action":"A","side":"A","price":"1.156430000","size":30,"channel_id":23,"order_id":"1775528293200299198","flags":128,"ts_in_delta":1370,"sequence":156069,"symbol":"FCEU SI 20260615 PS"}
{"ts_recv":"2026-04-07T02:18:13.200426503Z","hd":{"ts_event":"2026-04-07T02:18:13.200410463Z","rtype":160,"publisher_id":101,"instrument_id":436},"action":"C","side":"B","price":"1.156310000","size":30,"channel_id":23,"order_id":"10998900325242812402","flags":0,"ts_in_delta":980,"sequence":156070,"symbol":"FCEU SI 20260615 PS"}
{"ts_recv":"2026-04-07T02:18:13.200426503Z","hd":{"ts_event":"2026-04-07T02:18:13.200410463Z","rtype":160,"publisher_id":101,"instrument_id":436},"action":"A","side":"B","price":"1.156320000","size":30,"channel_id":23,"order_id":"10998900330055192151","flags":0,"ts_in_delta":980,"sequence":156070,"symbol":"FCEU SI 20260615 PS"}
{"ts_recv":"2026-04-07T02:18:13.200426503Z","hd":{"ts_event":"2026-04-07T02:18:13.200410463Z","rtype":160,"publisher_id":101,"instrument_id":436},"action":"C","side":"A","price":"1.156410000","size":30,"channel_id":23,"order_id":"1775528288388036594","flags":0,"ts_in_delta":980,"sequence":156070,"symbol":"FCEU SI 20260615 PS"}
{"ts_recv":"2026-04-07T02:18:13.200426503Z","hd":{"ts_event":"2026-04-07T02:18:13.200410463Z","rtype":160,"publisher_id":101,"instrument_id":436},"action":"A","side":"A","price":"1.156420000","size":30,"channel_id":23,"order_id":"1775528293200416343","flags":128,"ts_in_delta":980,"sequence":156070,"symbol":"FCEU SI 20260615 PS"}
{"ts_recv":"2026-04-07T02:18:40.192450082Z","hd":{"ts_event":"2026-04-07T02:18:40.192427659Z","rtype":160,"publisher_id":101,"instrument_id":436},"action":"C","side":"B","price":"1.156320000","size":30,"channel_id":23,"order_id":"10998900330055192151","flags":0,"ts_in_delta":1121,"sequence":156246,"symbol":"FCEU SI 20260615 PS"}
{"ts_recv":"2026-04-07T02:18:40.192450082Z","hd":{"ts_event":"2026-04-07T02:18:40.192427659Z","rtype":160,"publisher_id":101,"instrument_id":436},"action":"A","side":"B","price":"1.156310000","size":30,"channel_id":23,"order_id":"10998900357047209195","flags":0,"ts_in_delta":1121,"sequence":156246,"symbol":"FCEU SI 20260615 PS"}
{"ts_recv":"2026-04-07T02:18:40.192450082Z","hd":{"ts_event":"2026-04-07T02:18:40.192427659Z","rtype":160,"publisher_id":101,"instrument_id":436},"action":"C","side":"A","price":"1.156420000","size":30,"channel_id":23,"order_id":"1775528293200416343","flags":0,"ts_in_delta":1121,"sequence":156246,"symbol":"FCEU SI 20260615 PS"}
{"ts_recv":"2026-04-07T02:18:40.192450082Z","hd":{"ts_event":"2026-04-07T02:18:40.192427659Z","rtype":160,"publisher_id":101,"instrument_id":436},"action":"A","side":"A","price":"1.156410000","size":30,"channel_id":23,"order_id":"1775528320192433387","flags":128,"ts_in_delta":1121,"sequence":156246,"symbol":"FCEU SI 20260615 PS"}
{"ts_recv":"2026-04-07T02:18:40.192502557Z","hd":{"ts_event":"2026-04-07T02:18:40.192485029Z","rtype":160,"publisher_id":101,"instrument_id":436},"action":"C","side":"B","price":"1.156330000","size":30,"channel_id":23,"order_id":"10998900330055075006","flags":0,"ts_in_delta":1142,"sequence":156247,"symbol":"FCEU SI 20260615 PS"}
{"ts_recv":"2026-04-07T02:18:40.192502557Z","hd":{"ts_event":"2026-04-07T02:18:40.192485029Z","rtype":160,"publisher_id":101,"instrument_id":436},"action":"A","side":"B","price":"1.156310000","size":30,"channel_id":23,"order_id":"10998900357047266906","flags":0,"ts_in_delta":1142,"sequence":156247,"symbol":"FCEU SI 20260615 PS"}
{"ts_recv":"2026-04-07T02:18:40.192502557Z","hd":{"ts_event":"2026-04-07T02:18:40.192485029Z","rtype":160,"publisher_id":101,"instrument_id":436},"action":"C","side":"A","price":"1.156430000","size":30,"channel_id":23,"order_id":"1775528293200299198","flags":0,"ts_in_delta":1142,"sequence":156247,"symbol":"FCEU SI 20260615 PS"}
{"ts_recv":"2026-04-07T02:18:40.192502557Z","hd":{"ts_event":"2026-04-07T02:18:40.192485029Z","rtype":160,"publisher_id":101,"instrument_id":436},"action":"A","side":"A","price":"1.156410000","size":30,"channel_id":23,"order_id":"1775528320192491098","flags":128,"ts_in_delta":1142,"sequence":156247,"symbol":"FCEU SI 20260615 PS"}
{"ts_recv":"2026-04-07T02:18:40.192562028Z","hd":{"ts_event":"2026-04-07T02:18:40.192540747Z","rtype":160,"publisher_id":101,"instrument_id":436},"action":"C","side":"B","price":"1.156310000","size":30,"channel_id":23,"order_id":"10998900357047209195","flags":0,"ts_in_delta":933,"sequence":156248,"symbol":"FCEU SI 20260615 PS"}
{"ts_recv":"2026-04-07T02:18:40.192562028Z","hd":{"ts_event":"2026-04-07T02:18:40.192540747Z","rtype":160,"publisher_id":101,"instrument_id":436},"action":"A","side":"B","price":"1.156300000","size":30,"channel_id":23,"order_id":"10998900357047322577","flags":0,"ts_in_delta":933,"sequence":156248,"symbol":"FCEU SI 20260615 PS"}
{"ts_recv":"2026-04-07T02:18:40.192562028Z","hd":{"ts_event":"2026-04-07T02:18:40.192540747Z","rtype":160,"publisher_id":101,"instrument_id":436},"action":"C","side":"A","price":"1.156410000","size":30,"channel_id":23,"order_id":"1775528320192433387","flags":0,"ts_in_delta":933,"sequence":156248,"symbol":"FCEU SI 20260615 PS"}
{"ts_recv":"2026-04-07T02:18:40.192562028Z","hd":{"ts_event":"2026-04-07T02:18:40.192540747Z","rtype":160,"publisher_id":101,"instrument_id":436},"action":"A","side":"A","price":"1.156400000","size":30,"channel_id":23,"order_id":"1775528320192546769","flags":128,"ts_in_delta":933,"sequence":156248,"symbol":"FCEU SI 20260615 PS"}
{"ts_recv":"2026-04-07T02:18:40.192646973Z","hd":{"ts_event":"2026-04-07T02:18:40.192626995Z","rtype":160,"publisher_id":101,"instrument_id":436},"action":"C","side":"B","price":"1.156300000","size":30,"channel_id":23,"order_id":"10998900357047322577","flags":0,"ts_in_delta":930,"sequence":156249,"symbol":"FCEU SI 20260615 PS"}
{"ts_recv":"2026-04-07T02:18:40.192646973Z","hd":{"ts_event":"2026-04-07T02:18:40.192626995Z","rtype":160,"publisher_id":101,"instrument_id":436},"action":"A","side":"B","price":"1.156290000","size":30,"channel_id":23,"order_id":"10998900357047409426","flags":0,"ts_in_delta":930,"sequence":156249,"symbol":"FCEU SI 20260615 PS"}
{"ts_recv":"2026-04-07T02:18:40.192646973Z","hd":{"ts_event":"2026-04-07T02:18:40.192626995Z","rtype":160,"publisher_id":101,"instrument_id":436},"action":"C","side":"A","price":"1.156400000","size":30,"channel_id":23,"order_id":"1775528320192546769","flags":0,"ts_in_delta":930,"sequence":156249,"symbol":"FCEU SI 20260615 PS"}
{"ts_recv":"2026-04-07T02:18:40.192646973Z","hd":{"ts_event":"2026-04-07T02:18:40.192626995Z","rtype":160,"publisher_id":101,"instrument_id":436},"action":"A","side":"A","price":"1.156390000","size":30,"channel_id":23,"order_id":"1775528320192633618","flags":128,"ts_in_delta":930,"sequence":156249,"symbol":"FCEU SI 20260615 PS"}
{"ts_recv":"2026-04-07T02:18:40.192704570Z","hd":{"ts_event":"2026-04-07T02:18:40.192687929Z","rtype":160,"publisher_id":101,"instrument_id":436},"action":"C","side":"B","price":"1.156290000","size":30,"channel_id":23,"order_id":"10998900357047409426","flags":0,"ts_in_delta":1225,"sequence":156250,"symbol":"FCEU SI 20260615 PS"}
{"ts_recv":"2026-04-07T02:18:40.192704570Z","hd":{"ts_event":"2026-04-07T02:18:40.192687929Z","rtype":160,"publisher_id":101,"instrument_id":436},"action":"A","side":"B","price":"1.156300000","size":30,"channel_id":23,"order_id":"10998900357047469317","flags":0,"ts_in_delta":1225,"sequence":156250,"symbol":"FCEU SI 20260615 PS"}
{"ts_recv":"2026-04-07T02:18:40.192704570Z","hd":{"ts_event":"2026-04-07T02:18:40.192687929Z","rtype":160,"publisher_id":101,"instrument_id":436},"action":"C","side":"A","price":"1.156390000","size":30,"channel_id":23,"order_id":"1775528320192633618","flags":0,"ts_in_delta":1225,"sequence":156250,"symbol":"FCEU SI 20260615 PS"}
{"ts_recv":"2026-04-07T02:18:40.192704570Z","hd":{"ts_event":"2026-04-07T02:18:40.192687929Z","rtype":160,"publisher_id":101,"instrument_id":436},"action":"A","side":"A","price":"1.156400000","size":30,"channel_id":23,"order_id":"1775528320192693509","flags":128,"ts_in_delta":1225,"sequence":156250,"symbol":"FCEU SI 20260615 PS"}
{"ts_recv":"2026-04-07T02:18:40.201936882Z","hd":{"ts_event":"2026-04-07T02:18:40.201916791Z","rtype":160,"publisher_id":101,"instrument_id":436},"action":"C","side":"B","price":"1.156300000","size":30,"channel_id":23,"order_id":"10998900357047469317","flags":0,"ts_in_delta":960,"sequence":156256,"symbol":"FCEU SI 20260615 PS"}
{"ts_recv":"2026-04-07T02:18:40.201936882Z","hd":{"ts_event":"2026-04-07T02:18:40.201916791Z","rtype":160,"publisher_id":101,"instrument_id":436},"action":"A","side":"B","price":"1.156290000","size":30,"channel_id":23,"order_id":"10998900357056698572","flags":0,"ts_in_delta":960,"sequence":156256,"symbol":"FCEU SI 20260615 PS"}
{"ts_recv":"2026-04-07T02:18:40.201936882Z","hd":{"ts_event":"2026-04-07T02:18:40.201916791Z","rtype":160,"publisher_id":101,"instrument_id":436},"action":"C","side":"A","price":"1.156400000","size":30,"channel_id":23,"order_id":"1775528320192693509","flags":0,"ts_in_delta":960,"sequence":156256,"symbol":"FCEU SI 20260615 PS"}
{"ts_recv":"2026-04-07T02:18:40.201936882Z","hd":{"ts_event":"2026-04-07T02:18:40.201916791Z","rtype":160,"publisher_id":101,"instrument_id":436},"action":"A","side":"A","price":"1.156390000","size":30,"channel_id":23,"order_id":"1775528320201922764","flags":128,"ts_in_delta":960,"sequence":156256,"symbol":"FCEU SI 20260615 PS"}
{"ts_recv":"2026-04-07T02:18:40.206836021Z","hd":{"ts_event":"2026-04-07T02:18:40.206817877Z","rtype":160,"publisher_id":101,"instrument_id":436},"action":"C","side":"B","price":"1.156290000","size":30,"channel_id":23,"order_id":"10998900357056698572","flags":0,"ts_in_delta":953,"sequence":156261,"symbol":"FCEU SI 20260615 PS"}
{"ts_recv":"2026-04-07T02:18:40.206836021Z","hd":{"ts_event":"2026-04-07T02:18:40.206817877Z","rtype":160,"publisher_id":101,"instrument_id":436},"action":"A","side":"B","price":"1.156300000","size":30,"channel_id":23,"order_id":"10998900357061599480","flags":0,"ts_in_delta":953,"sequence":156261,"symbol":"FCEU SI 20260615 PS"}
{"ts_recv":"2026-04-07T02:18:40.206836021Z","hd":{"ts_event":"2026-04-07T02:18:40.206817877Z","rtype":160,"publisher_id":101,"instrument_id":436},"action":"C","side":"A","price":"1.156390000","size":30,"channel_id":23,"order_id":"1775528320201922764","flags":0,"ts_in_delta":953,"sequence":156261,"symbol":"FCEU SI 20260615 PS"}
{"ts_recv":"2026-04-07T02:18:40.206836021Z","hd":{"ts_event":"2026-04-07T02:18:40.206817877Z","rtype":160,"publisher_id":101,"instrument_id":436},"action":"A","side":"A","price":"1.156400000","size":30,"channel_id":23,"order_id":"1775528320206823672","flags":128,"ts_in_delta":953,"sequence":156261,"symbol":"FCEU SI 20260615 PS"}
{"ts_recv":"2026-04-07T02:18:47.760529385Z","hd":{"ts_event":"2026-04-07T02:18:47.760502307Z","rtype":160,"publisher_id":101,"instrument_id":436},"action":"C","side":"B","price":"1.156300000","size":30,"channel_id":23,"order_id":"10998900357061599480","flags":0,"ts_in_delta":1236,"sequence":156296,"symbol":"FCEU SI 20260615 PS"}
{"ts_recv":"2026-04-07T02:18:47.760529385Z","hd":{"ts_event":"2026-04-07T02:18:47.760502307Z","rtype":160,"publisher_id":101,"instrument_id":436},"action":"A","side":"B","price":"1.156290000","size":30,"channel_id":23,"order_id":"10998900364615287218","flags":0,"ts_in_delta":1236,"sequence":156296,"symbol":"FCEU SI 20260615 PS"}
{"ts_recv":"2026-04-07T02:18:47.760529385Z","hd":{"ts_event":"2026-04-07T02:18:47.760502307Z","rtype":160,"publisher_id":101,"instrument_id":436},"action":"C","side":"A","price":"1.156400000","size":30,"channel_id":23,"order_id":"1775528320206823672","flags":0,"ts_in_delta":1236,"sequence":156296,"symbol":"FCEU SI 20260615 PS"}
{"ts_recv":"2026-04-07T02:18:47.760529385Z","hd":{"ts_event":"2026-04-07T02:18:47.760502307Z","rtype":160,"publisher_id":101,"instrument_id":436},"action":"A","side":"A","price":"1.156390000","size":30,"channel_id":23,"order_id":"1775528327760511410","flags":128,"ts_in_delta":1236,"sequence":156296,"symbol":"FCEU SI 20260615 PS"}
{"ts_recv":"2026-04-07T02:18:47.760602426Z","hd":{"ts_event":"2026-04-07T02:18:47.760584405Z","rtype":160,"publisher_id":101,"instrument_id":436},"action":"C","side":"B","price":"1.156310000","size":30,"channel_id":23,"order_id":"10998900357047266906","flags":0,"ts_in_delta":973,"sequence":156297,"symbol":"FCEU SI 20260615 PS"}
{"ts_recv":"2026-04-07T02:18:47.760602426Z","hd":{"ts_event":"2026-04-07T02:18:47.760584405Z","rtype":160,"publisher_id":101,"instrument_id":436},"action":"A","side":"B","price":"1.156290000","size":30,"channel_id":23,"order_id":"10998900364615366756","flags":0,"ts_in_delta":973,"sequence":156297,"symbol":"FCEU SI 20260615 PS"}
{"ts_recv":"2026-04-07T02:18:47.760602426Z","hd":{"ts_event":"2026-04-07T02:18:47.760584405Z","rtype":160,"publisher_id":101,"instrument_id":436},"action":"C","side":"A","price":"1.156410000","size":30,"channel_id":23,"order_id":"1775528320192491098","flags":0,"ts_in_delta":973,"sequence":156297,"symbol":"FCEU SI 20260615 PS"}
{"ts_recv":"2026-04-07T02:18:47.760602426Z","hd":{"ts_event":"2026-04-07T02:18:47.760584405Z","rtype":160,"publisher_id":101,"instrument_id":436},"action":"A","side":"A","price":"1.156390000","size":30,"channel_id":23,"order_id":"1775528327760590948","flags":128,"ts_in_delta":973,"sequence":156297,"symbol":"FCEU SI 20260615 PS"}
{"ts_recv":"2026-04-07T02:18:47.760670913Z","hd":{"ts_event":"2026-04-07T02:18:47.760651933Z","rtype":160,"publisher_id":101,"instrument_id":436},"action":"C","side":"B","price":"1.156290000","size":30,"channel_id":23,"order_id":"10998900364615287218","flags":0,"ts_in_delta":966,"sequence":156298,"symbol":"FCEU SI 20260615 PS"}
{"ts_recv":"2026-04-07T02:18:47.760670913Z","hd":{"ts_event":"2026-04-07T02:18:47.760651933Z","rtype":160,"publisher_id":101,"instrument_id":436},"action":"A","side":"B","price":"1.156280000","size":30,"channel_id":23,"order_id":"10998900364615433883","flags":0,"ts_in_delta":966,"sequence":156298,"symbol":"FCEU SI 20260615 PS"}
{"ts_recv":"2026-04-07T02:18:47.760670913Z","hd":{"ts_event":"2026-04-07T02:18:47.760651933Z","rtype":160,"publisher_id":101,"instrument_id":436},"action":"C","side":"A","price":"1.156390000","size":30,"channel_id":23,"order_id":"1775528327760511410","flags":0,"ts_in_delta":966,"sequence":156298,"symbol":"FCEU SI 20260615 PS"}
{"ts_recv":"2026-04-07T02:18:47.760670913Z","hd":{"ts_event":"2026-04-07T02:18:47.760651933Z","rtype":160,"publisher_id":101,"instrument_id":436},"action":"A","side":"A","price":"1.156380000","size":30,"channel_id":23,"order_id":"1775528327760658075","flags":128,"ts_in_delta":966,"sequence":156298,"symbol":"FCEU SI 20260615 PS"}
{"ts_recv":"2026-04-07T02:18:47.760752740Z","hd":{"ts_event":"2026-04-07T02:18:47.760735173Z","rtype":160,"publisher_id":101,"instrument_id":436},"action":"C","side":"B","price":"1.156280000","size":30,"channel_id":23,"order_id":"10998900364615433883","flags":0,"ts_in_delta":1063,"sequence":156299,"symbol":"FCEU SI 20260615 PS"}
{"ts_recv":"2026-04-07T02:18:47.760752740Z","hd":{"ts_event":"2026-04-07T02:18:47.760735173Z","rtype":160,"publisher_id":101,"instrument_id":436},"action":"A","side":"B","price":"1.156270000","size":30,"channel_id":23,"order_id":"10998900364615516971","flags":0,"ts_in_delta":1063,"sequence":156299,"symbol":"FCEU SI 20260615 PS"}
{"ts_recv":"2026-04-07T02:18:47.760752740Z","hd":{"ts_event":"2026-04-07T02:18:47.760735173Z","rtype":160,"publisher_id":101,"instrument_id":436},"action":"C","side":"A","price":"1.156380000","size":30,"channel_id":23,"order_id":"1775528327760658075","flags":0,"ts_in_delta":1063,"sequence":156299,"symbol":"FCEU SI 20260615 PS"}
{"ts_recv":"2026-04-07T02:18:47.760752740Z","hd":{"ts_event":"2026-04-07T02:18:47.760735173Z","rtype":160,"publisher_id":101,"instrument_id":436},"action":"A","side":"A","price":"1.156370000","size":30,"channel_id":23,"order_id":"1775528327760741163","flags":128,"ts_in_delta":1063,"sequence":156299,"symbol":"FCEU SI 20260615 PS"}
{"ts_recv":"2026-04-07T02:18:47.760806175Z","hd":{"ts_event":"2026-04-07T02:18:47.760791179Z","rtype":160,"publisher_id":101,"instrument_id":436},"action":"C","side":"B","price":"1.156270000","size":30,"channel_id":23,"order_id":"10998900364615516971","flags":0,"ts_in_delta":980,"sequence":156300,"symbol":"FCEU SI 20260615 PS"}
{"ts_recv":"2026-04-07T02:18:47.760806175Z","hd":{"ts_event":"2026-04-07T02:18:47.760791179Z","rtype":160,"publisher_id":101,"instrument_id":436},"action":"A","side":"B","price":"1.156280000","size":30,"channel_id":23,"order_id":"10998900364615572869","flags":0,"ts_in_delta":980,"sequence":156300,"symbol":"FCEU SI 20260615 PS"}
{"ts_recv":"2026-04-07T02:18:47.760806175Z","hd":{"ts_event":"2026-04-07T02:18:47.760791179Z","rtype":160,"publisher_id":101,"instrument_id":436},"action":"C","side":"A","price":"1.156370000","size":30,"channel_id":23,"order_id":"1775528327760741163","flags":0,"ts_in_delta":980,"sequence":156300,"symbol":"FCEU SI 20260615 PS"}
{"ts_recv":"2026-04-07T02:18:47.760806175Z","hd":{"ts_event":"2026-04-07T02:18:47.760791179Z","rtype":160,"publisher_id":101,"instrument_id":436},"action":"A","side":"A","price":"1.156380000","size":30,"channel_id":23,"order_id":"1775528327760797061","flags":128,"ts_in_delta":980,"sequence":156300,"symbol":"FCEU SI 20260615 PS"}
{"ts_recv":"2026-04-07T02:18:48.254712554Z","hd":{"ts_event":"2026-04-07T02:18:48.254694141Z","rtype":160,"publisher_id":101,"instrument_id":436},"action":"C","side":"B","price":"1.156280000","size":30,"channel_id":23,"order_id":"10998900364615572869","flags":0,"ts_in_delta":989,"sequence":156327,"symbol":"FCEU SI 20260615 PS"}
{"ts_recv":"2026-04-07T02:18:48.254712554Z","hd":{"ts_event":"2026-04-07T02:18:48.254694141Z","rtype":160,"publisher_id":101,"instrument_id":436},"action":"A","side":"B","price":"1.156290000","size":30,"channel_id":23,"order_id":"10998900365109476301","flags":0,"ts_in_delta":989,"sequence":156327,"symbol":"FCEU SI 20260615 PS"}
{"ts_recv":"2026-04-07T02:18:48.254712554Z","hd":{"ts_event":"2026-04-07T02:18:48.254694141Z","rtype":160,"publisher_id":101,"instrument_id":436},"action":"C","side":"A","price":"1.156380000","size":30,"channel_id":23,"order_id":"1775528327760797061","flags":0,"ts_in_delta":989,"sequence":156327,"symbol":"FCEU SI 20260615 PS"}
{"ts_recv":"2026-04-07T02:18:48.254712554Z","hd":{"ts_event":"2026-04-07T02:18:48.254694141Z","rtype":160,"publisher_id":101,"instrument_id":436},"action":"A","side":"A","price":"1.156390000","size":30,"channel_id":23,"order_id":"1775528328254700493","flags":128,"ts_in_delta":989,"sequence":156327,"symbol":"FCEU SI 20260615 PS"}
{"ts_recv":"2026-04-07T02:18:53.032556166Z","hd":{"ts_event":"2026-04-07T02:18:53.032529791Z","rtype":160,"publisher_id":101,"instrument_id":436},"action":"C","side":"B","price":"1.156290000","size":30,"channel_id":23,"order_id":"10998900364615366756","flags":0,"ts_in_delta":1270,"sequence":156359,"symbol":"FCEU SI 20260615 PS"}
{"ts_recv":"2026-04-07T02:18:53.032556166Z","hd":{"ts_event":"2026-04-07T02:18:53.032529791Z","rtype":160,"publisher_id":101,"instrument_id":436},"action":"A","side":"B","price":"1.156310000","size":30,"channel_id":23,"order_id":"10998900369887314288","flags":0,"ts_in_delta":1270,"sequence":156359,"symbol":"FCEU SI 20260615 PS"}
{"ts_recv":"2026-04-07T02:18:53.032556166Z","hd":{"ts_event":"2026-04-07T02:18:53.032529791Z","rtype":160,"publisher_id":101,"instrument_id":436},"action":"C","side":"A","price":"1.156390000","size":30,"channel_id":23,"order_id":"1775528327760590948","flags":0,"ts_in_delta":1270,"sequence":156359,"symbol":"FCEU SI 20260615 PS"}
{"ts_recv":"2026-04-07T02:18:53.032556166Z","hd":{"ts_event":"2026-04-07T02:18:53.032529791Z","rtype":160,"publisher_id":101,"instrument_id":436},"action":"A","side":"A","price":"1.156410000","size":30,"channel_id":23,"order_id":"1775528333032538480","flags":128,"ts_in_delta":1270,"sequence":156359,"symbol":"FCEU SI 20260615 PS"}
{"ts_recv":"2026-04-07T02:18:53.032670754Z","hd":{"ts_event":"2026-04-07T02:18:53.032652537Z","rtype":160,"publisher_id":101,"instrument_id":436},"action":"C","side":"B","price":"1.156290000","size":30,"channel_id":23,"order_id":"10998900365109476301","flags":0,"ts_in_delta":920,"sequence":156360,"symbol":"FCEU SI 20260615 PS"}
{"ts_recv":"2026-04-07T02:18:53.032670754Z","hd":{"ts_event":"2026-04-07T02:18:53.032652537Z","rtype":160,"publisher_id":101,"instrument_id":436},"action":"A","side":"B","price":"1.156300000","size":30,"channel_id":23,"order_id":"10998900369887436150","flags":0,"ts_in_delta":920,"sequence":156360,"symbol":"FCEU SI 20260615 PS"}
{"ts_recv":"2026-04-07T02:18:53.032670754Z","hd":{"ts_event":"2026-04-07T02:18:53.032652537Z","rtype":160,"publisher_id":101,"instrument_id":436},"action":"C","side":"A","price":"1.156390000","size":30,"channel_id":23,"order_id":"1775528328254700493","flags":0,"ts_in_delta":920,"sequence":156360,"symbol":"FCEU SI 20260615 PS"}
{"ts_recv":"2026-04-07T02:18:53.032670754Z","hd":{"ts_event":"2026-04-07T02:18:53.032652537Z","rtype":160,"publisher_id":101,"instrument_id":436},"action":"A","side":"A","price":"1.156400000","size":30,"channel_id":23,"order_id":"1775528333032660342","flags":128,"ts_in_delta":920,"sequence":156360,"symbol":"FCEU SI 20260615 PS"}
{"ts_recv":"2026-04-07T02:18:53.040985248Z","hd":{"ts_event":"2026-04-07T02:18:53.040969833Z","rtype":160,"publisher_id":101,"instrument_id":436},"action":"C","side":"B","price":"1.156300000","size":30,"channel_id":23,"order_id":"10998900369887436150","flags":0,"ts_in_delta":959,"sequence":156362,"symbol":"FCEU SI 20260615 PS"}
{"ts_recv":"2026-04-07T02:18:53.040985248Z","hd":{"ts_event":"2026-04-07T02:18:53.040969833Z","rtype":160,"publisher_id":101,"instrument_id":436},"action":"A","side":"B","price":"1.156310000","size":30,"channel_id":23,"order_id":"10998900369895751608","flags":0,"ts_in_delta":959,"sequence":156362,"symbol":"FCEU SI 20260615 PS"}
{"ts_recv":"2026-04-07T02:18:53.040985248Z","hd":{"ts_event":"2026-04-07T02:18:53.040969833Z","rtype":160,"publisher_id":101,"instrument_id":436},"action":"C","side":"A","price":"1.156400000","size":30,"channel_id":23,"order_id":"1775528333032660342","flags":0,"ts_in_delta":959,"sequence":156362,"symbol":"FCEU SI 20260615 PS"}
{"ts_recv":"2026-04-07T02:18:53.040985248Z","hd":{"ts_event":"2026-04-07T02:18:53.040969833Z","rtype":160,"publisher_id":101,"instrument_id":436},"action":"A","side":"A","price":"1.156410000","size":30,"channel_id":23,"order_id":"1775528333040975800","flags":128,"ts_in_delta":959,"sequence":156362,"symbol":"FCEU SI 20260615 PS"}
{"ts_recv":"2026-04-07T02:18:53.107750440Z","hd":{"ts_event":"2026-04-07T02:18:53.107728899Z","rtype":160,"publisher_id":101,"instrument_id":436},"action":"C","side":"B","price":"1.156310000","size":30,"channel_id":23,"order_id":"10998900369895751608","flags":0,"ts_in_delta":969,"sequence":156370,"symbol":"FCEU SI 20260615 PS"}
{"ts_recv":"2026-04-07T02:18:53.107750440Z","hd":{"ts_event":"2026-04-07T02:18:53.107728899Z","rtype":160,"publisher_id":101,"instrument_id":436},"action":"A","side":"B","price":"1.156300000","size":30,"channel_id":23,"order_id":"10998900369962510972","flags":0,"ts_in_delta":969,"sequence":156370,"symbol":"FCEU SI 20260615 PS"}
{"ts_recv":"2026-04-07T02:18:53.107750440Z","hd":{"ts_event":"2026-04-07T02:18:53.107728899Z","rtype":160,"publisher_id":101,"instrument_id":436},"action":"C","side":"A","price":"1.156410000","size":30,"channel_id":23,"order_id":"1775528333040975800","flags":0,"ts_in_delta":969,"sequence":156370,"symbol":"FCEU SI 20260615 PS"}
{"ts_recv":"2026-04-07T02:18:53.107750440Z","hd":{"ts_event":"2026-04-07T02:18:53.107728899Z","rtype":160,"publisher_id":101,"instrument_id":436},"action":"A","side":"A","price":"1.156400000","size":30,"channel_id":23,"order_id":"1775528333107735164","flags":128,"ts_in_delta":969,"sequence":156370,"symbol":"FCEU SI 20260615 PS"}
{"ts_recv":"2026-04-07T02:18:53.107831337Z","hd":{"ts_event":"2026-04-07T02:18:53.107811901Z","rtype":160,"publisher_id":101,"instrument_id":436},"action":"C","side":"B","price":"1.156300000","size":30,"channel_id":23,"order_id":"10998900369962510972","flags":0,"ts_in_delta":933,"sequence":156371,"symbol":"FCEU SI 20260615 PS"}
{"ts_recv":"2026-04-07T02:18:53.107831337Z","hd":{"ts_event":"2026-04-07T02:18:53.107811901Z","rtype":160,"publisher_id":101,"instrument_id":436},"action":"A","side":"B","price":"1.156290000","size":30,"channel_id":23,"order_id":"10998900369962593768","flags":0,"ts_in_delta":933,"sequence":156371,"symbol":"FCEU SI 20260615 PS"}
{"ts_recv":"2026-04-07T02:18:53.107831337Z","hd":{"ts_event":"2026-04-07T02:18:53.107811901Z","rtype":160,"publisher_id":101,"instrument_id":436},"action":"C","side":"A","price":"1.156400000","size":30,"channel_id":23,"order_id":"1775528333107735164","flags":0,"ts_in_delta":933,"sequence":156371,"symbol":"FCEU SI 20260615 PS"}
{"ts_recv":"2026-04-07T02:18:53.107831337Z","hd":{"ts_event":"2026-04-07T02:18:53.107811901Z","rtype":160,"publisher_id":101,"instrument_id":436},"action":"A","side":"A","price":"1.156390000","size":30,"channel_id":23,"order_id":"1775528333107817960","flags":128,"ts_in_delta":933,"sequence":156371,"symbol":"FCEU SI 20260615 PS"}
{"ts_recv":"2026-04-07T02:18:53.107886139Z","hd":{"ts_event":"2026-04-07T02:18:53.107867255Z","rtype":160,"publisher_id":101,"instrument_id":436},"action":"C","side":"B","price":"1.156310000","size":30,"channel_id":23,"order_id":"10998900369887314288","flags":0,"ts_in_delta":1051,"sequence":156372,"symbol":"FCEU SI 20260615 PS"}
{"ts_recv":"2026-04-07T02:18:53.107886139Z","hd":{"ts_event":"2026-04-07T02:18:53.107867255Z","rtype":160,"publisher_id":101,"instrument_id":436},"action":"A","side":"B","price":"1.156290000","size":30,"channel_id":23,"order_id":"10998900369962648964","flags":0,"ts_in_delta":1051,"sequence":156372,"symbol":"FCEU SI 20260615 PS"}
{"ts_recv":"2026-04-07T02:18:53.107886139Z","hd":{"ts_event":"2026-04-07T02:18:53.107867255Z","rtype":160,"publisher_id":101,"instrument_id":436},"action":"C","side":"A","price":"1.156410000","size":30,"channel_id":23,"order_id":"1775528333032538480","flags":0,"ts_in_delta":1051,"sequence":156372,"symbol":"FCEU SI 20260615 PS"}
{"ts_recv":"2026-04-07T02:18:53.107886139Z","hd":{"ts_event":"2026-04-07T02:18:53.107867255Z","rtype":160,"publisher_id":101,"instrument_id":436},"action":"A","side":"A","price":"1.156390000","size":30,"channel_id":23,"order_id":"1775528333107873156","flags":128,"ts_in_delta":1051,"sequence":156372,"symbol":"FCEU SI 20260615 PS"}
{"ts_recv":"2026-04-07T02:18:53.107896107Z","hd":{"ts_event":"2026-04-07T02:18:53.107871057Z","rtype":160,"publisher_id":101,"instrument_id":436},"action":"C","side":"B","price":"1.156290000","size":30,"channel_id":23,"order_id":"10998900369962593768","flags":0,"ts_in_delta":1012,"sequence":156373,"symbol":"FCEU SI 20260615 PS"}
{"ts_recv":"2026-04-07T02:18:53.107896107Z","hd":{"ts_event":"2026-04-07T02:18:53.107871057Z","rtype":160,"publisher_id":101,"instrument_id":436},"action":"A","side":"B","price":"1.156300000","size":30,"channel_id":23,"order_id":"10998900369962657163","flags":0,"ts_in_delta":1012,"sequence":156373,"symbol":"FCEU SI 20260615 PS"}
{"ts_recv":"2026-04-07T02:18:53.107896107Z","hd":{"ts_event":"2026-04-07T02:18:53.107871057Z","rtype":160,"publisher_id":101,"instrument_id":436},"action":"C","side":"A","price":"1.156390000","size":30,"channel_id":23,"order_id":"1775528333107817960","flags":0,"ts_in_delta":1012,"sequence":156373,"symbol":"FCEU SI 20260615 PS"}
{"ts_recv":"2026-04-07T02:18:53.107896107Z","hd":{"ts_event":"2026-04-07T02:18:53.107871057Z","rtype":160,"publisher_id":101,"instrument_id":436},"action":"A","side":"A","price":"1.156400000","size":30,"channel_id":23,"order_id":"1775528333107881355","flags":128,"ts_in_delta":1012,"sequence":156373,"symbol":"FCEU SI 20260615 PS"}
{"ts_recv":"2026-04-07T02:18:53.107949465Z","hd":{"ts_event":"2026-04-07T02:18:53.107933751Z","rtype":160,"publisher_id":101,"instrument_id":436},"action":"C","side":"B","price":"1.156300000","size":30,"channel_id":23,"order_id":"10998900369962657163","flags":0,"ts_in_delta":973,"sequence":156374,"symbol":"FCEU SI 20260615 PS"}
{"ts_recv":"2026-04-07T02:18:53.107949465Z","hd":{"ts_event":"2026-04-07T02:18:53.107933751Z","rtype":160,"publisher_id":101,"instrument_id":436},"action":"A","side":"B","price":"1.156290000","size":30,"channel_id":23,"order_id":"10998900369962715574","flags":0,"ts_in_delta":973,"sequence":156374,"symbol":"FCEU SI 20260615 PS"}
{"ts_recv":"2026-04-07T02:18:53.107949465Z","hd":{"ts_event":"2026-04-07T02:18:53.107933751Z","rtype":160,"publisher_id":101,"instrument_id":436},"action":"C","side":"A","price":"1.156400000","size":30,"channel_id":23,"order_id":"1775528333107881355","flags":0,"ts_in_delta":973,"sequence":156374,"symbol":"FCEU SI 20260615 PS"}
{"ts_recv":"2026-04-07T02:18:53.107949465Z","hd":{"ts_event":"2026-04-07T02:18:53.107933751Z","rtype":160,"publisher_id":101,"instrument_id":436},"action":"A","side":"A","price":"1.156390000","size":30,"channel_id":23,"order_id":"1775528333107939766","flags":128,"ts_in_delta":973,"sequence":156374,"symbol":"FCEU SI 20260615 PS"}
{"ts_recv":"2026-04-07T02:18:53.111470376Z","hd":{"ts_event":"2026-04-07T02:18:53.111452331Z","rtype":160,"publisher_id":101,"instrument_id":436},"action":"C","side":"B","price":"1.156290000","size":30,"channel_id":23,"order_id":"10998900369962715574","flags":0,"ts_in_delta":1085,"sequence":156376,"symbol":"FCEU SI 20260615 PS"}
{"ts_recv":"2026-04-07T02:18:53.111470376Z","hd":{"ts_event":"2026-04-07T02:18:53.111452331Z","rtype":160,"publisher_id":101,"instrument_id":436},"action":"A","side":"B","price":"1.156280000","size":30,"channel_id":23,"order_id":"10998900369966234370","flags":0,"ts_in_delta":1085,"sequence":156376,"symbol":"FCEU SI 20260615 PS"}
{"ts_recv":"2026-04-07T02:18:53.111470376Z","hd":{"ts_event":"2026-04-07T02:18:53.111452331Z","rtype":160,"publisher_id":101,"instrument_id":436},"action":"C","side":"A","price":"1.156390000","size":30,"channel_id":23,"order_id":"1775528333107939766","flags":0,"ts_in_delta":1085,"sequence":156376,"symbol":"FCEU SI 20260615 PS"}
{"ts_recv":"2026-04-07T02:18:53.111470376Z","hd":{"ts_event":"2026-04-07T02:18:53.111452331Z","rtype":160,"publisher_id":101,"instrument_id":436},"action":"A","side":"A","price":"1.156380000","size":30,"channel_id":23,"order_id":"1775528333111458562","flags":128,"ts_in_delta":1085,"sequence":156376,"symbol":"FCEU SI 20260615 PS"}
{"ts_recv":"2026-04-07T02:18:53.111528726Z","hd":{"ts_event":"2026-04-07T02:18:53.111510073Z","rtype":160,"publisher_id":101,"instrument_id":436},"action":"C","side":"B","price":"1.156280000","size":30,"channel_id":23,"order_id":"10998900369966234370","flags":0,"ts_in_delta":944,"sequence":156377,"symbol":"FCEU SI 20260615 PS"}
{"ts_recv":"2026-04-07T02:18:53.111528726Z","hd":{"ts_event":"2026-04-07T02:18:53.111510073Z","rtype":160,"publisher_id":101,"instrument_id":436},"action":"A","side":"B","price":"1.156260000","size":30,"channel_id":23,"order_id":"10998900369966291765","flags":0,"ts_in_delta":944,"sequence":156377,"symbol":"FCEU SI 20260615 PS"}
{"ts_recv":"2026-04-07T02:18:53.111528726Z","hd":{"ts_event":"2026-04-07T02:18:53.111510073Z","rtype":160,"publisher_id":101,"instrument_id":436},"action":"C","side":"A","price":"1.156380000","size":30,"channel_id":23,"order_id":"1775528333111458562","flags":0,"ts_in_delta":944,"sequence":156377,"symbol":"FCEU SI 20260615 PS"}
{"ts_recv":"2026-04-07T02:18:53.111528726Z","hd":{"ts_event":"2026-04-07T02:18:53.111510073Z","rtype":160,"publisher_id":101,"instrument_id":436},"action":"A","side":"A","price":"1.156360000","size":30,"channel_id":23,"order_id":"1775528333111515957","flags":128,"ts_in_delta":944,"sequence":156377,"symbol":"FCEU SI 20260615 PS"}
{"ts_recv":"2026-04-07T02:18:53.111574497Z","hd":{"ts_event":"2026-04-07T02:18:53.111559015Z","rtype":160,"publisher_id":101,"instrument_id":436},"action":"C","side":"B","price":"1.156290000","size":30,"channel_id":23,"order_id":"10998900369962648964","flags":0,"ts_in_delta":923,"sequence":156378,"symbol":"FCEU SI 20260615 PS"}
{"ts_recv":"2026-04-07T02:18:53.111574497Z","hd":{"ts_event":"2026-04-07T02:18:53.111559015Z","rtype":160,"publisher_id":101,"instrument_id":436},"action":"A","side":"B","price":"1.156270000","size":30,"channel_id":23,"order_id":"10998900369966340803","flags":0,"ts_in_delta":923,"sequence":156378,"symbol":"FCEU SI 20260615 PS"}
{"ts_recv":"2026-04-07T02:18:53.111574497Z","hd":{"ts_event":"2026-04-07T02:18:53.111559015Z","rtype":160,"publisher_id":101,"instrument_id":436},"action":"C","side":"A","price":"1.156390000","size":30,"channel_id":23,"order_id":"1775528333107873156","flags":0,"ts_in_delta":923,"sequence":156378,"symbol":"FCEU SI 20260615 PS"}
{"ts_recv":"2026-04-07T02:18:53.111574497Z","hd":{"ts_event":"2026-04-07T02:18:53.111559015Z","rtype":160,"publisher_id":101,"instrument_id":436},"action":"A","side":"A","price":"1.156370000","size":30,"channel_id":23,"order_id":"1775528333111564995","flags":128,"ts_in_delta":923,"sequence":156378,"symbol":"FCEU SI 20260615 PS"}
{"ts_recv":"2026-04-07T02:18:53.111584043Z","hd":{"ts_event":"2026-04-07T02:18:53.111563533Z","rtype":160,"publisher_id":101,"instrument_id":436},"action":"C","side":"B","price":"1.156260000","size":30,"channel_id":23,"order_id":"10998900369966291765","flags":0,"ts_in_delta":937,"sequence":156379,"symbol":"FCEU SI 20260615 PS"}
{"ts_recv":"2026-04-07T02:18:53.111584043Z","hd":{"ts_event":"2026-04-07T02:18:53.111563533Z","rtype":160,"publisher_id":101,"instrument_id":436},"action":"A","side":"B","price":"1.156280000","size":30,"channel_id":23,"order_id":"10998900369966347194","flags":0,"ts_in_delta":937,"sequence":156379,"symbol":"FCEU SI 20260615 PS"}
{"ts_recv":"2026-04-07T02:18:53.111584043Z","hd":{"ts_event":"2026-04-07T02:18:53.111563533Z","rtype":160,"publisher_id":101,"instrument_id":436},"action":"C","side":"A","price":"1.156360000","size":30,"channel_id":23,"order_id":"1775528333111515957","flags":0,"ts_in_delta":937,"sequence":156379,"symbol":"FCEU SI 20260615 PS"}
{"ts_recv":"2026-04-07T02:18:53.111584043Z","hd":{"ts_event":"2026-04-07T02:18:53.111563533Z","rtype":160,"publisher_id":101,"instrument_id":436},"action":"A","side":"A","price":"1.156380000","size":30,"channel_id":23,"order_id":"1775528333111571386","flags":128,"ts_in_delta":937,"sequence":156379,"symbol":"FCEU SI 20260615 PS"}
{"ts_recv":"2026-04-07T02:18:53.111637608Z","hd":{"ts_event":"2026-04-07T02:18:53.111620869Z","rtype":160,"publisher_id":101,"instrument_id":436},"action":"C","side":"B","price":"1.156280000","size":30,"channel_id":23,"order_id":"10998900369966347194","flags":0,"ts_in_delta":952,"sequence":156380,"symbol":"FCEU SI 20260615 PS"}
{"ts_recv":"2026-04-07T02:18:53.111637608Z","hd":{"ts_event":"2026-04-07T02:18:53.111620869Z","rtype":160,"publisher_id":101,"instrument_id":436},"action":"A","side":"B","price":"1.156270000","size":30,"channel_id":23,"order_id":"10998900369966403849","flags":0,"ts_in_delta":952,"sequence":156380,"symbol":"FCEU SI 20260615 PS"}
{"ts_recv":"2026-04-07T02:18:53.111637608Z","hd":{"ts_event":"2026-04-07T02:18:53.111620869Z","rtype":160,"publisher_id":101,"instrument_id":436},"action":"C","side":"A","price":"1.156380000","size":30,"channel_id":23,"order_id":"1775528333111571386","flags":0,"ts_in_delta":952,"sequence":156380,"symbol":"FCEU SI 20260615 PS"}
{"ts_recv":"2026-04-07T02:18:53.111637608Z","hd":{"ts_event":"2026-04-07T02:18:53.111620869Z","rtype":160,"publisher_id":101,"instrument_id":436},"action":"A","side":"A","price":"1.156370000","size":30,"channel_id":23,"order_id":"1775528333111628041","flags":128,"ts_in_delta":952,"sequence":156380,"symbol":"FCEU SI 20260615 PS"}
{"ts_recv":"2026-04-07T02:18:58.373450373Z","hd":{"ts_event":"2026-04-07T02:18:58.373430135Z","rtype":160,"publisher_id":101,"instrument_id":436},"action":"C","side":"B","price":"1.156270000","size":30,"channel_id":23,"order_id":"10998900369966403849","flags":0,"ts_in_delta":943,"sequence":156421,"symbol":"FCEU SI 20260615 PS"}
{"ts_recv":"2026-04-07T02:18:58.373450373Z","hd":{"ts_event":"2026-04-07T02:18:58.373430135Z","rtype":160,"publisher_id":101,"instrument_id":436},"action":"A","side":"B","price":"1.156260000","size":30,"channel_id":23,"order_id":"10998900375228212161","flags":0,"ts_in_delta":943,"sequence":156421,"symbol":"FCEU SI 20260615 PS"}
{"ts_recv":"2026-04-07T02:18:58.373450373Z","hd":{"ts_event":"2026-04-07T02:18:58.373430135Z","rtype":160,"publisher_id":101,"instrument_id":436},"action":"C","side":"A","price":"1.156370000","size":30,"channel_id":23,"order_id":"1775528333111628041","flags":0,"ts_in_delta":943,"sequence":156421,"symbol":"FCEU SI 20260615 PS"}
{"ts_recv":"2026-04-07T02:18:58.373450373Z","hd":{"ts_event":"2026-04-07T02:18:58.373430135Z","rtype":160,"publisher_id":101,"instrument_id":436},"action":"A","side":"A","price":"1.156360000","size":30,"channel_id":23,"order_id":"1775528338373436353","flags":128,"ts_in_delta":943,"sequence":156421,"symbol":"FCEU SI 20260615 PS"}
{"ts_recv":"2026-04-07T02:18:58.395956757Z","hd":{"ts_event":"2026-04-07T02:18:58.395939421Z","rtype":160,"publisher_id":101,"instrument_id":436},"action":"C","side":"B","price":"1.156260000","size":30,"channel_id":23,"order_id":"10998900375228212161","flags":0,"ts_in_delta":783,"sequence":156426,"symbol":"FCEU SI 20260615 PS"}
{"ts_recv":"2026-04-07T02:18:58.395956757Z","hd":{"ts_event":"2026-04-07T02:18:58.395939421Z","rtype":160,"publisher_id":101,"instrument_id":436},"action":"A","side":"B","price":"1.156270000","size":30,"channel_id":23,"order_id":"10998900375250720878","flags":0,"ts_in_delta":783,"sequence":156426,"symbol":"FCEU SI 20260615 PS"}
{"ts_recv":"2026-04-07T02:18:58.395956757Z","hd":{"ts_event":"2026-04-07T02:18:58.395939421Z","rtype":160,"publisher_id":101,"instrument_id":436},"action":"C","side":"A","price":"1.156360000","size":30,"channel_id":23,"order_id":"1775528338373436353","flags":0,"ts_in_delta":783,"sequence":156426,"symbol":"FCEU SI 20260615 PS"}
{"ts_recv":"2026-04-07T02:18:58.395956757Z","hd":{"ts_event":"2026-04-07T02:18:58.395939421Z","rtype":160,"publisher_id":101,"instrument_id":436},"action":"A","side":"A","price":"1.156370000","size":30,"channel_id":23,"order_id":"1775528338395945070","flags":128,"ts_in_delta":783,"sequence":156426,"symbol":"FCEU SI 20260615 PS"}
{"ts_recv":"2026-04-07T02:19:10.714433380Z","hd":{"ts_event":"2026-04-07T02:19:10.714411475Z","rtype":160,"publisher_id":101,"instrument_id":436},"action":"C","side":"B","price":"1.156270000","size":30,"channel_id":23,"order_id":"10998900369966340803","flags":0,"ts_in_delta":947,"sequence":156566,"symbol":"FCEU SI 20260615 PS"}
{"ts_recv":"2026-04-07T02:19:10.714433380Z","hd":{"ts_event":"2026-04-07T02:19:10.714411475Z","rtype":160,"publisher_id":101,"instrument_id":436},"action":"A","side":"B","price":"1.156290000","size":30,"channel_id":23,"order_id":"10998900387569193789","flags":0,"ts_in_delta":947,"sequence":156566,"symbol":"FCEU SI 20260615 PS"}
{"ts_recv":"2026-04-07T02:19:10.714433380Z","hd":{"ts_event":"2026-04-07T02:19:10.714411475Z","rtype":160,"publisher_id":101,"instrument_id":436},"action":"C","side":"A","price":"1.156370000","size":30,"channel_id":23,"order_id":"1775528333111564995","flags":0,"ts_in_delta":947,"sequence":156566,"symbol":"FCEU SI 20260615 PS"}
{"ts_recv":"2026-04-07T02:19:10.714433380Z","hd":{"ts_event":"2026-04-07T02:19:10.714411475Z","rtype":160,"publisher_id":101,"instrument_id":436},"action":"A","side":"A","price":"1.156390000","size":30,"channel_id":23,"order_id":"1775528350714417981","flags":128,"ts_in_delta":947,"sequence":156566,"symbol":"FCEU SI 20260615 PS"}
{"ts_recv":"2026-04-07T02:19:10.714507650Z","hd":{"ts_event":"2026-04-07T02:19:10.714488551Z","rtype":160,"publisher_id":101,"instrument_id":436},"action":"C","side":"B","price":"1.156270000","size":30,"channel_id":23,"order_id":"10998900375250720878","flags":0,"ts_in_delta":959,"sequence":156567,"symbol":"FCEU SI 20260615 PS"}
{"ts_recv":"2026-04-07T02:19:10.714507650Z","hd":{"ts_event":"2026-04-07T02:19:10.714488551Z","rtype":160,"publisher_id":101,"instrument_id":436},"action":"A","side":"B","price":"1.156280000","size":30,"channel_id":23,"order_id":"10998900387569270516","flags":0,"ts_in_delta":959,"sequence":156567,"symbol":"FCEU SI 20260615 PS"}
{"ts_recv":"2026-04-07T02:19:10.714507650Z","hd":{"ts_event":"2026-04-07T02:19:10.714488551Z","rtype":160,"publisher_id":101,"instrument_id":436},"action":"C","side":"A","price":"1.156370000","size":30,"channel_id":23,"order_id":"1775528338395945070","flags":0,"ts_in_delta":959,"sequence":156567,"symbol":"FCEU SI 20260615 PS"}
{"ts_recv":"2026-04-07T02:19:10.714507650Z","hd":{"ts_event":"2026-04-07T02:19:10.714488551Z","rtype":160,"publisher_id":101,"instrument_id":436},"action":"A","side":"A","price":"1.156380000","size":30,"channel_id":23,"order_id":"1775528350714494708","flags":128,"ts_in_delta":959,"sequence":156567,"symbol":"FCEU SI 20260615 PS"}
{"ts_recv":"2026-04-07T02:19:10.716842094Z","hd":{"ts_event":"2026-04-07T02:19:10.716826487Z","rtype":160,"publisher_id":101,"instrument_id":436},"action":"C","side":"B","price":"1.156280000","size":30,"channel_id":23,"order_id":"10998900387569270516","flags":0,"ts_in_delta":970,"sequence":156568,"symbol":"FCEU SI 20260615 PS"}
{"ts_recv":"2026-04-07T02:19:10.716842094Z","hd":{"ts_event":"2026-04-07T02:19:10.716826487Z","rtype":160,"publisher_id":101,"instrument_id":436},"action":"A","side":"B","price":"1.156290000","size":30,"channel_id":23,"order_id":"10998900387571608330","flags":0,"ts_in_delta":970,"sequence":156568,"symbol":"FCEU SI 20260615 PS"}
{"ts_recv":"2026-04-07T02:19:10.716842094Z","hd":{"ts_event":"2026-04-07T02:19:10.716826487Z","rtype":160,"publisher_id":101,"instrument_id":436},"action":"C","side":"A","price":"1.156380000","size":30,"channel_id":23,"order_id":"1775528350714494708","flags":0,"ts_in_delta":970,"sequence":156568,"symbol":"FCEU SI 20260615 PS"}
{"ts_recv":"2026-04-07T02:19:10.716842094Z","hd":{"ts_event":"2026-04-07T02:19:10.716826487Z","rtype":160,"publisher_id":101,"instrument_id":436},"action":"A","side":"A","price":"1.156390000","size":30,"channel_id":23,"order_id":"1775528350716832522","flags":128,"ts_in_delta":970,"sequence":156568,"symbol":"FCEU SI 20260615 PS"}
{"ts_recv":"2026-04-07T02:19:13.284906815Z","hd":{"ts_event":"2026-04-07T02:19:13.284885369Z","rtype":160,"publisher_id":101,"instrument_id":436},"action":"C","side":"B","price":"1.156290000","size":30,"channel_id":23,"order_id":"10998900387571608330","flags":0,"ts_in_delta":1052,"sequence":156586,"symbol":"FCEU SI 20260615 PS"}
{"ts_recv":"2026-04-07T02:19:13.284906815Z","hd":{"ts_event":"2026-04-07T02:19:13.284885369Z","rtype":160,"publisher_id":101,"instrument_id":436},"action":"A","side":"B","price":"1.156280000","size":30,"channel_id":23,"order_id":"10998900390139667284","flags":0,"ts_in_delta":1052,"sequence":156586,"symbol":"FCEU SI 20260615 PS"}
{"ts_recv":"2026-04-07T02:19:13.284906815Z","hd":{"ts_event":"2026-04-07T02:19:13.284885369Z","rtype":160,"publisher_id":101,"instrument_id":436},"action":"C","side":"A","price":"1.156390000","size":30,"channel_id":23,"order_id":"1775528350716832522","flags":0,"ts_in_delta":1052,"sequence":156586,"symbol":"FCEU SI 20260615 PS"}
{"ts_recv":"2026-04-07T02:19:13.284906815Z","hd":{"ts_event":"2026-04-07T02:19:13.284885369Z","rtype":160,"publisher_id":101,"instrument_id":436},"action":"A","side":"A","price":"1.156380000","size":30,"channel_id":23,"order_id":"1775528353284891476","flags":128,"ts_in_delta":1052,"sequence":156586,"symbol":"FCEU SI 20260615 PS"}
{"ts_recv":"2026-04-07T02:19:27.211886296Z","hd":{"ts_event":"2026-04-07T02:19:27.211864097Z","rtype":160,"publisher_id":101,"instrument_id":436},"action":"C","side":"B","price":"1.156280000","size":30,"channel_id":23,"order_id":"10998900390139667284","flags":0,"ts_in_delta":1356,"sequence":156681,"symbol":"FCEU SI 20260615 PS"}
{"ts_recv":"2026-04-07T02:19:27.211886296Z","hd":{"ts_event":"2026-04-07T02:19:27.211864097Z","rtype":160,"publisher_id":101,"instrument_id":436},"action":"A","side":"B","price":"1.156290000","size":30,"channel_id":23,"order_id":"10998900404066646069","flags":0,"ts_in_delta":1356,"sequence":156681,"symbol":"FCEU SI 20260615 PS"}
{"ts_recv":"2026-04-07T02:19:27.211886296Z","hd":{"ts_event":"2026-04-07T02:19:27.211864097Z","rtype":160,"publisher_id":101,"instrument_id":436},"action":"C","side":"A","price":"1.156380000","size":30,"channel_id":23,"order_id":"1775528353284891476","flags":0,"ts_in_delta":1356,"sequence":156681,"symbol":"FCEU SI 20260615 PS"}
{"ts_recv":"2026-04-07T02:19:27.211886296Z","hd":{"ts_event":"2026-04-07T02:19:27.211864097Z","rtype":160,"publisher_id":101,"instrument_id":436},"action":"A","side":"A","price":"1.156390000","size":30,"channel_id":23,"order_id":"1775528367211870261","flags":128,"ts_in_delta":1356,"sequence":156681,"symbol":"FCEU SI 20260615 PS"}
{"ts_recv":"2026-04-07T02:19:30.985939076Z","hd":{"ts_event":"2026-04-07T02:19:30.985916807Z","rtype":160,"publisher_id":101,"instrument_id":436},"action":"C","side":"B","price":"1.156290000","size":30,"channel_id":23,"order_id":"10998900387569193789","flags":0,"ts_in_delta":972,"sequence":156709,"symbol":"FCEU SI 20260615 PS"}
{"ts_recv":"2026-04-07T02:19:30.985939076Z","hd":{"ts_event":"2026-04-07T02:19:30.985916807Z","rtype":160,"publisher_id":101,"instrument_id":436},"action":"A","side":"B","price":"1.156310000","size":30,"channel_id":23,"order_id":"10998900407840698877","flags":0,"ts_in_delta":972,"sequence":156709,"symbol":"FCEU SI 20260615 PS"}
{"ts_recv":"2026-04-07T02:19:30.985939076Z","hd":{"ts_event":"2026-04-07T02:19:30.985916807Z","rtype":160,"publisher_id":101,"instrument_id":436},"action":"C","side":"A","price":"1.156390000","size":30,"channel_id":23,"order_id":"1775528350714417981","flags":0,"ts_in_delta":972,"sequence":156709,"symbol":"FCEU SI 20260615 PS"}
{"ts_recv":"2026-04-07T02:19:30.985939076Z","hd":{"ts_event":"2026-04-07T02:19:30.985916807Z","rtype":160,"publisher_id":101,"instrument_id":436},"action":"A","side":"A","price":"1.156410000","size":30,"channel_id":23,"order_id":"1775528370985923069","flags":128,"ts_in_delta":972,"sequence":156709,"symbol":"FCEU SI 20260615 PS"}
{"ts_recv":"2026-04-07T02:19:30.986013807Z","hd":{"ts_event":"2026-04-07T02:19:30.985996839Z","rtype":160,"publisher_id":101,"instrument_id":436},"action":"C","side":"B","price":"1.156290000","size":30,"channel_id":23,"order_id":"10998900404066646069","flags":0,"ts_in_delta":949,"sequence":156710,"symbol":"FCEU SI 20260615 PS"}
{"ts_recv":"2026-04-07T02:19:30.986013807Z","hd":{"ts_event":"2026-04-07T02:19:30.985996839Z","rtype":160,"publisher_id":101,"instrument_id":436},"action":"A","side":"B","price":"1.156300000","size":30,"channel_id":23,"order_id":"10998900407840778770","flags":0,"ts_in_delta":949,"sequence":156710,"symbol":"FCEU SI 20260615 PS"}
{"ts_recv":"2026-04-07T02:19:30.986013807Z","hd":{"ts_event":"2026-04-07T02:19:30.985996839Z","rtype":160,"publisher_id":101,"instrument_id":436},"action":"C","side":"A","price":"1.156390000","size":30,"channel_id":23,"order_id":"1775528367211870261","flags":0,"ts_in_delta":949,"sequence":156710,"symbol":"FCEU SI 20260615 PS"}
{"ts_recv":"2026-04-07T02:19:30.986013807Z","hd":{"ts_event":"2026-04-07T02:19:30.985996839Z","rtype":160,"publisher_id":101,"instrument_id":436},"action":"A","side":"A","price":"1.156400000","size":30,"channel_id":23,"order_id":"1775528370986002962","flags":128,"ts_in_delta":949,"sequence":156710,"symbol":"FCEU SI 20260615 PS"}
{"ts_recv":"2026-04-07T02:19:31.051180251Z","hd":{"ts_event":"2026-04-07T02:19:31.051162113Z","rtype":160,"publisher_id":101,"instrument_id":436},"action":"C","side":"B","price":"1.156300000","size":30,"channel_id":23,"order_id":"10998900407840778770","flags":0,"ts_in_delta":951,"sequence":156714,"symbol":"FCEU SI 20260615 PS"}
{"ts_recv":"2026-04-07T02:19:31.051180251Z","hd":{"ts_event":"2026-04-07T02:19:31.051162113Z","rtype":160,"publisher_id":101,"instrument_id":436},"action":"A","side":"B","price":"1.156310000","size":30,"channel_id":23,"order_id":"10998900407905943949","flags":0,"ts_in_delta":951,"sequence":156714,"symbol":"FCEU SI 20260615 PS"}
{"ts_recv":"2026-04-07T02:19:31.051180251Z","hd":{"ts_event":"2026-04-07T02:19:31.051162113Z","rtype":160,"publisher_id":101,"instrument_id":436},"action":"C","side":"A","price":"1.156400000","size":30,"channel_id":23,"order_id":"1775528370986002962","flags":0,"ts_in_delta":951,"sequence":156714,"symbol":"FCEU SI 20260615 PS"}
{"ts_recv":"2026-04-07T02:19:31.051180251Z","hd":{"ts_event":"2026-04-07T02:19:31.051162113Z","rtype":160,"publisher_id":101,"instrument_id":436},"action":"A","side":"A","price":"1.156410000","size":30,"channel_id":23,"order_id":"1775528371051168141","flags":128,"ts_in_delta":951,"sequence":156714,"symbol":"FCEU SI 20260615 PS"}
{"ts_recv":"2026-04-07T02:19:33.516790520Z","hd":{"ts_event":"2026-04-07T02:19:33.516760905Z","rtype":160,"publisher_id":101,"instrument_id":436},"action":"C","side":"B","price":"1.156310000","size":30,"channel_id":23,"order_id":"10998900407905943949","flags":0,"ts_in_delta":1494,"sequence":156726,"symbol":"FCEU SI 20260615 PS"}
{"ts_recv":"2026-04-07T02:19:33.516790520Z","hd":{"ts_event":"2026-04-07T02:19:33.516760905Z","rtype":160,"publisher_id":101,"instrument_id":436},"action":"A","side":"B","price":"1.156300000","size":30,"channel_id":23,"order_id":"10998900410371549777","flags":0,"ts_in_delta":1494,"sequence":156726,"symbol":"FCEU SI 20260615 PS"}
{"ts_recv":"2026-04-07T02:19:33.516790520Z","hd":{"ts_event":"2026-04-07T02:19:33.516760905Z","rtype":160,"publisher_id":101,"instrument_id":436},"action":"C","side":"A","price":"1.156410000","size":30,"channel_id":23,"order_id":"1775528371051168141","flags":0,"ts_in_delta":1494,"sequence":156726,"symbol":"FCEU SI 20260615 PS"}
{"ts_recv":"2026-04-07T02:19:33.516790520Z","hd":{"ts_event":"2026-04-07T02:19:33.516760905Z","rtype":160,"publisher_id":101,"instrument_id":436},"action":"A","side":"A","price":"1.156400000","size":30,"channel_id":23,"order_id":"1775528373516773969","flags":128,"ts_in_delta":1494,"sequence":156726,"symbol":"FCEU SI 20260615 PS"}
{"ts_recv":"2026-04-07T02:19:33.551667418Z","hd":{"ts_event":"2026-04-07T02:19:33.551645041Z","rtype":160,"publisher_id":101,"instrument_id":436},"action":"C","side":"B","price":"1.156300000","size":30,"channel_id":23,"order_id":"10998900410371549777","flags":0,"ts_in_delta":1616,"sequence":156731,"symbol":"FCEU SI 20260615 PS"}
{"ts_recv":"2026-04-07T02:19:33.551667418Z","hd":{"ts_event":"2026-04-07T02:19:33.551645041Z","rtype":160,"publisher_id":101,"instrument_id":436},"action":"A","side":"B","price":"1.156290000","size":30,"channel_id":23,"order_id":"10998900410406426945","flags":0,"ts_in_delta":1616,"sequence":156731,"symbol":"FCEU SI 20260615 PS"}
{"ts_recv":"2026-04-07T02:19:33.551667418Z","hd":{"ts_event":"2026-04-07T02:19:33.551645041Z","rtype":160,"publisher_id":101,"instrument_id":436},"action":"C","side":"A","price":"1.156400000","size":30,"channel_id":23,"order_id":"1775528373516773969","flags":0,"ts_in_delta":1616,"sequence":156731,"symbol":"FCEU SI 20260615 PS"}
{"ts_recv":"2026-04-07T02:19:33.551667418Z","hd":{"ts_event":"2026-04-07T02:19:33.551645041Z","rtype":160,"publisher_id":101,"instrument_id":436},"action":"A","side":"A","price":"1.156390000","size":30,"channel_id":23,"order_id":"1775528373551651137","flags":128,"ts_in_delta":1616,"sequence":156731,"symbol":"FCEU SI 20260615 PS"}
{"ts_recv":"2026-04-07T02:19:33.551721875Z","hd":{"ts_event":"2026-04-07T02:19:33.551701471Z","rtype":160,"publisher_id":101,"instrument_id":436},"action":"C","side":"B","price":"1.156310000","size":30,"channel_id":23,"order_id":"10998900407840698877","flags":0,"ts_in_delta":1073,"sequence":156732,"symbol":"FCEU SI 20260615 PS"}
{"ts_recv":"2026-04-07T02:19:33.551721875Z","hd":{"ts_event":"2026-04-07T02:19:33.551701471Z","rtype":160,"publisher_id":101,"instrument_id":436},"action":"A","side":"B","price":"1.156290000","size":30,"channel_id":23,"order_id":"10998900410406483494","flags":0,"ts_in_delta":1073,"sequence":156732,"symbol":"FCEU SI 20260615 PS"}
{"ts_recv":"2026-04-07T02:19:33.551721875Z","hd":{"ts_event":"2026-04-07T02:19:33.551701471Z","rtype":160,"publisher_id":101,"instrument_id":436},"action":"C","side":"A","price":"1.156410000","size":30,"channel_id":23,"order_id":"1775528370985923069","flags":0,"ts_in_delta":1073,"sequence":156732,"symbol":"FCEU SI 20260615 PS"}
{"ts_recv":"2026-04-07T02:19:33.551721875Z","hd":{"ts_event":"2026-04-07T02:19:33.551701471Z","rtype":160,"publisher_id":101,"instrument_id":436},"action":"A","side":"A","price":"1.156390000","size":30,"channel_id":23,"order_id":"1775528373551707686","flags":128,"ts_in_delta":1073,"sequence":156732,"symbol":"FCEU SI 20260615 PS"}
{"ts_recv":"2026-04-07T02:19:33.551779564Z","hd":{"ts_event":"2026-04-07T02:19:33.551758061Z","rtype":160,"publisher_id":101,"instrument_id":436},"action":"C","side":"B","price":"1.156290000","size":30,"channel_id":23,"order_id":"10998900410406426945","flags":0,"ts_in_delta":1272,"sequence":156733,"symbol":"FCEU SI 20260615 PS"}
{"ts_recv":"2026-04-07T02:19:33.551779564Z","hd":{"ts_event":"2026-04-07T02:19:33.551758061Z","rtype":160,"publisher_id":101,"instrument_id":436},"action":"A","side":"B","price":"1.156280000","size":30,"channel_id":23,"order_id":"10998900410406540245","flags":0,"ts_in_delta":1272,"sequence":156733,"symbol":"FCEU SI 20260615 PS"}
{"ts_recv":"2026-04-07T02:19:33.551779564Z","hd":{"ts_event":"2026-04-07T02:19:33.551758061Z","rtype":160,"publisher_id":101,"instrument_id":436},"action":"C","side":"A","price":"1.156390000","size":30,"channel_id":23,"order_id":"1775528373551651137","flags":0,"ts_in_delta":1272,"sequence":156733,"symbol":"FCEU SI 20260615 PS"}
{"ts_recv":"2026-04-07T02:19:33.551779564Z","hd":{"ts_event":"2026-04-07T02:19:33.551758061Z","rtype":160,"publisher_id":101,"instrument_id":436},"action":"A","side":"A","price":"1.156380000","size":30,"channel_id":23,"order_id":"1775528373551764437","flags":128,"ts_in_delta":1272,"sequence":156733,"symbol":"FCEU SI 20260615 PS"}
{"ts_recv":"2026-04-07T02:19:33.551862873Z","hd":{"ts_event":"2026-04-07T02:19:33.551843521Z","rtype":160,"publisher_id":101,"instrument_id":436},"action":"C","side":"B","price":"1.156280000","size":30,"channel_id":23,"order_id":"10998900410406540245","flags":0,"ts_in_delta":1037,"sequence":156734,"symbol":"FCEU SI 20260615 PS"}
{"ts_recv":"2026-04-07T02:19:33.551862873Z","hd":{"ts_event":"2026-04-07T02:19:33.551843521Z","rtype":160,"publisher_id":101,"instrument_id":436},"action":"A","side":"B","price":"1.156270000","size":30,"channel_id":23,"order_id":"10998900410406625388","flags":0,"ts_in_delta":1037,"sequence":156734,"symbol":"FCEU SI 20260615 PS"}
{"ts_recv":"2026-04-07T02:19:33.551862873Z","hd":{"ts_event":"2026-04-07T02:19:33.551843521Z","rtype":160,"publisher_id":101,"instrument_id":436},"action":"C","side":"A","price":"1.156380000","size":30,"channel_id":23,"order_id":"1775528373551764437","flags":0,"ts_in_delta":1037,"sequence":156734,"symbol":"FCEU SI 20260615 PS"}
{"ts_recv":"2026-04-07T02:19:33.551862873Z","hd":{"ts_event":"2026-04-07T02:19:33.551843521Z","rtype":160,"publisher_id":101,"instrument_id":436},"action":"A","side":"A","price":"1.156370000","size":30,"channel_id":23,"order_id":"1775528373551849580","flags":128,"ts_in_delta":1037,"sequence":156734,"symbol":"FCEU SI 20260615 PS"}
{"ts_recv":"2026-04-07T02:19:33.551919195Z","hd":{"ts_event":"2026-04-07T02:19:33.551902099Z","rtype":160,"publisher_id":101,"instrument_id":436},"action":"C","side":"B","price":"1.156270000","size":30,"channel_id":23,"order_id":"10998900410406625388","flags":0,"ts_in_delta":938,"sequence":156736,"symbol":"FCEU SI 20260615 PS"}
{"ts_recv":"2026-04-07T02:19:33.551919195Z","hd":{"ts_event":"2026-04-07T02:19:33.551902099Z","rtype":160,"publisher_id":101,"instrument_id":436},"action":"A","side":"B","price":"1.156280000","size":30,"channel_id":23,"order_id":"10998900410406683998","flags":0,"ts_in_delta":938,"sequence":156736,"symbol":"FCEU SI 20260615 PS"}
{"ts_recv":"2026-04-07T02:19:33.551919195Z","hd":{"ts_event":"2026-04-07T02:19:33.551902099Z","rtype":160,"publisher_id":101,"instrument_id":436},"action":"C","side":"A","price":"1.156370000","size":30,"channel_id":23,"order_id":"1775528373551849580","flags":0,"ts_in_delta":938,"sequence":156736,"symbol":"FCEU SI 20260615 PS"}
{"ts_recv":"2026-04-07T02:19:33.551919195Z","hd":{"ts_event":"2026-04-07T02:19:33.551902099Z","rtype":160,"publisher_id":101,"instrument_id":436},"action":"A","side":"A","price":"1.156380000","size":30,"channel_id":23,"order_id":"1775528373551908190","flags":128,"ts_in_delta":938,"sequence":156736,"symbol":"FCEU SI 20260615 PS"}
{"ts_recv":"2026-04-07T02:19:42.352024464Z","hd":{"ts_event":"2026-04-07T02:19:42.352006097Z","rtype":160,"publisher_id":101,"instrument_id":436},"action":"C","side":"B","price":"1.156280000","size":30,"channel_id":23,"order_id":"10998900410406683998","flags":0,"ts_in_delta":728,"sequence":156827,"symbol":"FCEU SI 20260615 PS"}
{"ts_recv":"2026-04-07T02:19:42.352024464Z","hd":{"ts_event":"2026-04-07T02:19:42.352006097Z","rtype":160,"publisher_id":101,"instrument_id":436},"action":"A","side":"B","price":"1.156290000","size":30,"channel_id":23,"order_id":"10998900419206787848","flags":0,"ts_in_delta":728,"sequence":156827,"symbol":"FCEU SI 20260615 PS"}
{"ts_recv":"2026-04-07T02:19:42.352024464Z","hd":{"ts_event":"2026-04-07T02:19:42.352006097Z","rtype":160,"publisher_id":101,"instrument_id":436},"action":"C","side":"A","price":"1.156380000","size":30,"channel_id":23,"order_id":"1775528373551908190","flags":0,"ts_in_delta":728,"sequence":156827,"symbol":"FCEU SI 20260615 PS"}
{"ts_recv":"2026-04-07T02:19:42.352024464Z","hd":{"ts_event":"2026-04-07T02:19:42.352006097Z","rtype":160,"publisher_id":101,"instrument_id":436},"action":"A","side":"A","price":"1.156390000","size":30,"channel_id":23,"order_id":"1775528382352012040","flags":128,"ts_in_delta":728,"sequence":156827,"symbol":"FCEU SI 20260615 PS"}
{"ts_recv":"2026-04-07T02:19:45.575588484Z","hd":{"ts_event":"2026-04-07T02:19:45.575561299Z","rtype":160,"publisher_id":101,"instrument_id":436},"action":"C","side":"B","price":"1.156290000","size":30,"channel_id":23,"order_id":"10998900419206787848","flags":0,"ts_in_delta":1738,"sequence":156860,"symbol":"FCEU SI 20260615 PS"}
{"ts_recv":"2026-04-07T02:19:45.575588484Z","hd":{"ts_event":"2026-04-07T02:19:45.575561299Z","rtype":160,"publisher_id":101,"instrument_id":436},"action":"A","side":"B","price":"1.156280000","size":30,"channel_id":23,"order_id":"10998900422430345487","flags":0,"ts_in_delta":1738,"sequence":156860,"symbol":"FCEU SI 20260615 PS"}
{"ts_recv":"2026-04-07T02:19:45.575588484Z","hd":{"ts_event":"2026-04-07T02:19:45.575561299Z","rtype":160,"publisher_id":101,"instrument_id":436},"action":"C","side":"A","price":"1.156390000","size":30,"channel_id":23,"order_id":"1775528382352012040","flags":0,"ts_in_delta":1738,"sequence":156860,"symbol":"FCEU SI 20260615 PS"}
{"ts_recv":"2026-04-07T02:19:45.575588484Z","hd":{"ts_event":"2026-04-07T02:19:45.575561299Z","rtype":160,"publisher_id":101,"instrument_id":436},"action":"A","side":"A","price":"1.156380000","size":30,"channel_id":23,"order_id":"1775528385575569679","flags":128,"ts_in_delta":1738,"sequence":156860,"symbol":"FCEU SI 20260615 PS"}
{"ts_recv":"2026-04-07T02:19:58.286224669Z","hd":{"ts_event":"2026-04-07T02:19:58.286197539Z","rtype":160,"publisher_id":101,"instrument_id":436},"action":"C","side":"B","price":"1.156280000","size":30,"channel_id":23,"order_id":"10998900422430345487","flags":0,"ts_in_delta":910,"sequence":156973,"symbol":"FCEU SI 20260615 PS"}
{"ts_recv":"2026-04-07T02:19:58.286224669Z","hd":{"ts_event":"2026-04-07T02:19:58.286197539Z","rtype":160,"publisher_id":101,"instrument_id":436},"action":"A","side":"B","price":"1.156290000","size":30,"channel_id":23,"order_id":"10998900435140982215","flags":0,"ts_in_delta":910,"sequence":156973,"symbol":"FCEU SI 20260615 PS"}
{"ts_recv":"2026-04-07T02:19:58.286224669Z","hd":{"ts_event":"2026-04-07T02:19:58.286197539Z","rtype":160,"publisher_id":101,"instrument_id":436},"action":"C","side":"A","price":"1.156380000","size":30,"channel_id":23,"order_id":"1775528385575569679","flags":0,"ts_in_delta":910,"sequence":156973,"symbol":"FCEU SI 20260615 PS"}
{"ts_recv":"2026-04-07T02:19:58.286224669Z","hd":{"ts_event":"2026-04-07T02:19:58.286197539Z","rtype":160,"publisher_id":101,"instrument_id":436},"action":"A","side":"A","price":"1.156390000","size":30,"channel_id":23,"order_id":"1775528398286206407","flags":128,"ts_in_delta":910,"sequence":156973,"symbol":"FCEU SI 20260615 PS"}
{"ts_recv":"2026-04-07T02:20:03.994341533Z","hd":{"ts_event":"2026-04-07T02:20:03.994307451Z","rtype":160,"publisher_id":101,"instrument_id":436},"action":"C","side":"B","price":"1.156290000","size":30,"channel_id":23,"order_id":"10998900435140982215","flags":0,"ts_in_delta":1580,"sequence":157004,"symbol":"FCEU SI 20260615 PS"}
{"ts_recv":"2026-04-07T02:20:03.994341533Z","hd":{"ts_event":"2026-04-07T02:20:03.994307451Z","rtype":160,"publisher_id":101,"instrument_id":436},"action":"A","side":"B","price":"1.156280000","size":30,"channel_id":23,"order_id":"10998900440849096772","flags":0,"ts_in_delta":1580,"sequence":157004,"symbol":"FCEU SI 20260615 PS"}
{"ts_recv":"2026-04-07T02:20:03.994341533Z","hd":{"ts_event":"2026-04-07T02:20:03.994307451Z","rtype":160,"publisher_id":101,"instrument_id":436},"action":"C","side":"A","price":"1.156390000","size":30,"channel_id":23,"order_id":"1775528398286206407","flags":0,"ts_in_delta":1580,"sequence":157004,"symbol":"FCEU SI 20260615 PS"}
{"ts_recv":"2026-04-07T02:20:03.994341533Z","hd":{"ts_event":"2026-04-07T02:20:03.994307451Z","rtype":160,"publisher_id":101,"instrument_id":436},"action":"A","side":"A","price":"1.156380000","size":30,"channel_id":23,"order_id":"1775528403994320964","flags":128,"ts_in_delta":1580,"sequence":157004,"symbol":"FCEU SI 20260615 PS"}
{"ts_recv":"2026-04-07T02:20:09.231494689Z","hd":{"ts_event":"2026-04-07T02:20:09.231473805Z","rtype":160,"publisher_id":101,"instrument_id":436},"action":"C","side":"B","price":"1.156280000","size":30,"channel_id":23,"order_id":"10998900440849096772","flags":0,"ts_in_delta":936,"sequence":157080,"symbol":"FCEU SI 20260615 PS"}
{"ts_recv":"2026-04-07T02:20:09.231494689Z","hd":{"ts_event":"2026-04-07T02:20:09.231473805Z","rtype":160,"publisher_id":101,"instrument_id":436},"action":"A","side":"B","price":"1.156260000","size":30,"channel_id":23,"order_id":"10998900446086255418","flags":0,"ts_in_delta":936,"sequence":157080,"symbol":"FCEU SI 20260615 PS"}
{"ts_recv":"2026-04-07T02:20:09.231494689Z","hd":{"ts_event":"2026-04-07T02:20:09.231473805Z","rtype":160,"publisher_id":101,"instrument_id":436},"action":"C","side":"A","price":"1.156380000","size":30,"channel_id":23,"order_id":"1775528403994320964","flags":0,"ts_in_delta":936,"sequence":157080,"symbol":"FCEU SI 20260615 PS"}
{"ts_recv":"2026-04-07T02:20:09.231494689Z","hd":{"ts_event":"2026-04-07T02:20:09.231473805Z","rtype":160,"publisher_id":101,"instrument_id":436},"action":"A","side":"A","price":"1.156360000","size":30,"channel_id":23,"order_id":"1775528409231479610","flags":128,"ts_in_delta":936,"sequence":157080,"symbol":"FCEU SI 20260615 PS"}
{"ts_recv":"2026-04-07T02:20:09.231559743Z","hd":{"ts_event":"2026-04-07T02:20:09.231540777Z","rtype":160,"publisher_id":101,"instrument_id":436},"action":"C","side":"B","price":"1.156290000","size":30,"channel_id":23,"order_id":"10998900410406483494","flags":0,"ts_in_delta":1047,"sequence":157081,"symbol":"FCEU SI 20260615 PS"}
{"ts_recv":"2026-04-07T02:20:09.231559743Z","hd":{"ts_event":"2026-04-07T02:20:09.231540777Z","rtype":160,"publisher_id":101,"instrument_id":436},"action":"A","side":"B","price":"1.156270000","size":30,"channel_id":23,"order_id":"10998900446086323057","flags":0,"ts_in_delta":1047,"sequence":157081,"symbol":"FCEU SI 20260615 PS"}
{"ts_recv":"2026-04-07T02:20:09.231559743Z","hd":{"ts_event":"2026-04-07T02:20:09.231540777Z","rtype":160,"publisher_id":101,"instrument_id":436},"action":"C","side":"A","price":"1.156390000","size":30,"channel_id":23,"order_id":"1775528373551707686","flags":0,"ts_in_delta":1047,"sequence":157081,"symbol":"FCEU SI 20260615 PS"}
{"ts_recv":"2026-04-07T02:20:09.231559743Z","hd":{"ts_event":"2026-04-07T02:20:09.231540777Z","rtype":160,"publisher_id":101,"instrument_id":436},"action":"A","side":"A","price":"1.156370000","size":30,"channel_id":23,"order_id":"1775528409231547249","flags":128,"ts_in_delta":1047,"sequence":157081,"symbol":"FCEU SI 20260615 PS"}
{"ts_recv":"2026-04-07T02:20:09.231574196Z","hd":{"ts_event":"2026-04-07T02:20:09.231555471Z","rtype":160,"publisher_id":101,"instrument_id":436},"action":"C","side":"B","price":"1.156260000","size":30,"channel_id":23,"order_id":"10998900446086255418","flags":0,"ts_in_delta":898,"sequence":157082,"symbol":"FCEU SI 20260615 PS"}
{"ts_recv":"2026-04-07T02:20:09.231574196Z","hd":{"ts_event":"2026-04-07T02:20:09.231555471Z","rtype":160,"publisher_id":101,"instrument_id":436},"action":"A","side":"B","price":"1.156280000","size":30,"channel_id":23,"order_id":"10998900446086337072","flags":0,"ts_in_delta":898,"sequence":157082,"symbol":"FCEU SI 20260615 PS"}
{"ts_recv":"2026-04-07T02:20:09.231574196Z","hd":{"ts_event":"2026-04-07T02:20:09.231555471Z","rtype":160,"publisher_id":101,"instrument_id":436},"action":"C","side":"A","price":"1.156360000","size":30,"channel_id":23,"order_id":"1775528409231479610","flags":0,"ts_in_delta":898,"sequence":157082,"symbol":"FCEU SI 20260615 PS"}
{"ts_recv":"2026-04-07T02:20:09.231574196Z","hd":{"ts_event":"2026-04-07T02:20:09.231555471Z","rtype":160,"publisher_id":101,"instrument_id":436},"action":"A","side":"A","price":"1.156380000","size":30,"channel_id":23,"order_id":"1775528409231561264","flags":128,"ts_in_delta":898,"sequence":157082,"symbol":"FCEU SI 20260615 PS"}
{"ts_recv":"2026-04-07T02:20:09.231635480Z","hd":{"ts_event":"2026-04-07T02:20:09.231613839Z","rtype":160,"publisher_id":101,"instrument_id":436},"action":"C","side":"B","price":"1.156280000","size":30,"channel_id":23,"order_id":"10998900446086337072","flags":0,"ts_in_delta":896,"sequence":157083,"symbol":"FCEU SI 20260615 PS"}
{"ts_recv":"2026-04-07T02:20:09.231635480Z","hd":{"ts_event":"2026-04-07T02:20:09.231613839Z","rtype":160,"publisher_id":101,"instrument_id":436},"action":"A","side":"B","price":"1.156270000","size":30,"channel_id":23,"order_id":"10998900446086396623","flags":0,"ts_in_delta":896,"sequence":157083,"symbol":"FCEU SI 20260615 PS"}
{"ts_recv":"2026-04-07T02:20:09.231635480Z","hd":{"ts_event":"2026-04-07T02:20:09.231613839Z","rtype":160,"publisher_id":101,"instrument_id":436},"action":"C","side":"A","price":"1.156380000","size":30,"channel_id":23,"order_id":"1775528409231561264","flags":0,"ts_in_delta":896,"sequence":157083,"symbol":"FCEU SI 20260615 PS"}
{"ts_recv":"2026-04-07T02:20:09.231635480Z","hd":{"ts_event":"2026-04-07T02:20:09.231613839Z","rtype":160,"publisher_id":101,"instrument_id":436},"action":"A","side":"A","price":"1.156370000","size":30,"channel_id":23,"order_id":"1775528409231620815","flags":128,"ts_in_delta":896,"sequence":157083,"symbol":"FCEU SI 20260615 PS"}
{"ts_recv":"2026-04-07T02:20:09.244222353Z","hd":{"ts_event":"2026-04-07T02:20:09.244203399Z","rtype":160,"publisher_id":101,"instrument_id":436},"action":"C","side":"B","price":"1.156270000","size":30,"channel_id":23,"order_id":"10998900446086396623","flags":0,"ts_in_delta":1001,"sequence":157089,"symbol":"FCEU SI 20260615 PS"}
{"ts_recv":"2026-04-07T02:20:09.244222353Z","hd":{"ts_event":"2026-04-07T02:20:09.244203399Z","rtype":160,"publisher_id":101,"instrument_id":436},"action":"A","side":"B","price":"1.156260000","size":30,"channel_id":23,"order_id":"10998900446098985246","flags":0,"ts_in_delta":1001,"sequence":157089,"symbol":"FCEU SI 20260615 PS"}
{"ts_recv":"2026-04-07T02:20:09.244222353Z","hd":{"ts_event":"2026-04-07T02:20:09.244203399Z","rtype":160,"publisher_id":101,"instrument_id":436},"action":"C","side":"A","price":"1.156370000","size":30,"channel_id":23,"order_id":"1775528409231620815","flags":0,"ts_in_delta":1001,"sequence":157089,"symbol":"FCEU SI 20260615 PS"}
{"ts_recv":"2026-04-07T02:20:09.244222353Z","hd":{"ts_event":"2026-04-07T02:20:09.244203399Z","rtype":160,"publisher_id":101,"instrument_id":436},"action":"A","side":"A","price":"1.156360000","size":30,"channel_id":23,"order_id":"1775528409244209438","flags":128,"ts_in_delta":1001,"sequence":157089,"symbol":"FCEU SI 20260615 PS"}
{"ts_recv":"2026-04-07T02:20:09.248151215Z","hd":{"ts_event":"2026-04-07T02:20:09.248132271Z","rtype":160,"publisher_id":101,"instrument_id":436},"action":"C","side":"B","price":"1.156260000","size":30,"channel_id":23,"order_id":"10998900446098985246","flags":0,"ts_in_delta":939,"sequence":157092,"symbol":"FCEU SI 20260615 PS"}
{"ts_recv":"2026-04-07T02:20:09.248151215Z","hd":{"ts_event":"2026-04-07T02:20:09.248132271Z","rtype":160,"publisher_id":101,"instrument_id":436},"action":"A","side":"B","price":"1.156250000","size":30,"channel_id":23,"order_id":"10998900446102913734","flags":0,"ts_in_delta":939,"sequence":157092,"symbol":"FCEU SI 20260615 PS"}
{"ts_recv":"2026-04-07T02:20:09.248151215Z","hd":{"ts_event":"2026-04-07T02:20:09.248132271Z","rtype":160,"publisher_id":101,"instrument_id":436},"action":"C","side":"A","price":"1.156360000","size":30,"channel_id":23,"order_id":"1775528409244209438","flags":0,"ts_in_delta":939,"sequence":157092,"symbol":"FCEU SI 20260615 PS"}
{"ts_recv":"2026-04-07T02:20:09.248151215Z","hd":{"ts_event":"2026-04-07T02:20:09.248132271Z","rtype":160,"publisher_id":101,"instrument_id":436},"action":"A","side":"A","price":"1.156350000","size":30,"channel_id":23,"order_id":"1775528409248137926","flags":128,"ts_in_delta":939,"sequence":157092,"symbol":"FCEU SI 20260615 PS"}
{"ts_recv":"2026-04-07T02:20:09.248204028Z","hd":{"ts_event":"2026-04-07T02:20:09.248187819Z","rtype":160,"publisher_id":101,"instrument_id":436},"action":"C","side":"B","price":"1.156270000","size":30,"channel_id":23,"order_id":"10998900446086323057","flags":0,"ts_in_delta":918,"sequence":157093,"symbol":"FCEU SI 20260615 PS"}
{"ts_recv":"2026-04-07T02:20:09.248204028Z","hd":{"ts_event":"2026-04-07T02:20:09.248187819Z","rtype":160,"publisher_id":101,"instrument_id":436},"action":"A","side":"B","price":"1.156250000","size":30,"channel_id":23,"order_id":"10998900446102969960","flags":0,"ts_in_delta":918,"sequence":157093,"symbol":"FCEU SI 20260615 PS"}
{"ts_recv":"2026-04-07T02:20:09.248204028Z","hd":{"ts_event":"2026-04-07T02:20:09.248187819Z","rtype":160,"publisher_id":101,"instrument_id":436},"action":"C","side":"A","price":"1.156370000","size":30,"channel_id":23,"order_id":"1775528409231547249","flags":0,"ts_in_delta":918,"sequence":157093,"symbol":"FCEU SI 20260615 PS"}
{"ts_recv":"2026-04-07T02:20:09.248204028Z","hd":{"ts_event":"2026-04-07T02:20:09.248187819Z","rtype":160,"publisher_id":101,"instrument_id":436},"action":"A","side":"A","price":"1.156350000","size":30,"channel_id":23,"order_id":"1775528409248194152","flags":128,"ts_in_delta":918,"sequence":157093,"symbol":"FCEU SI 20260615 PS"}
{"ts_recv":"2026-04-07T02:20:09.248258476Z","hd":{"ts_event":"2026-04-07T02:20:09.248238973Z","rtype":160,"publisher_id":101,"instrument_id":436},"action":"C","side":"B","price":"1.156250000","size":30,"channel_id":23,"order_id":"10998900446102913734","flags":0,"ts_in_delta":904,"sequence":157094,"symbol":"FCEU SI 20260615 PS"}
{"ts_recv":"2026-04-07T02:20:09.248258476Z","hd":{"ts_event":"2026-04-07T02:20:09.248238973Z","rtype":160,"publisher_id":101,"instrument_id":436},"action":"A","side":"B","price":"1.156240000","size":30,"channel_id":23,"order_id":"10998900446103020354","flags":0,"ts_in_delta":904,"sequence":157094,"symbol":"FCEU SI 20260615 PS"}
{"ts_recv":"2026-04-07T02:20:09.248258476Z","hd":{"ts_event":"2026-04-07T02:20:09.248238973Z","rtype":160,"publisher_id":101,"instrument_id":436},"action":"C","side":"A","price":"1.156350000","size":30,"channel_id":23,"order_id":"1775528409248137926","flags":0,"ts_in_delta":904,"sequence":157094,"symbol":"FCEU SI 20260615 PS"}
{"ts_recv":"2026-04-07T02:20:09.248258476Z","hd":{"ts_event":"2026-04-07T02:20:09.248238973Z","rtype":160,"publisher_id":101,"instrument_id":436},"action":"A","side":"A","price":"1.156340000","size":30,"channel_id":23,"order_id":"1775528409248244546","flags":128,"ts_in_delta":904,"sequence":157094,"symbol":"FCEU SI 20260615 PS"}
{"ts_recv":"2026-04-07T02:20:09.279385525Z","hd":{"ts_event":"2026-04-07T02:20:09.279367205Z","rtype":160,"publisher_id":101,"instrument_id":436},"action":"C","side":"B","price":"1.156240000","size":30,"channel_id":23,"order_id":"10998900446103020354","flags":0,"ts_in_delta":1007,"sequence":157107,"symbol":"FCEU SI 20260615 PS"}
{"ts_recv":"2026-04-07T02:20:09.279385525Z","hd":{"ts_event":"2026-04-07T02:20:09.279367205Z","rtype":160,"publisher_id":101,"instrument_id":436},"action":"A","side":"B","price":"1.156230000","size":30,"channel_id":23,"order_id":"10998900446134148651","flags":0,"ts_in_delta":1007,"sequence":157107,"symbol":"FCEU SI 20260615 PS"}
{"ts_recv":"2026-04-07T02:20:09.279385525Z","hd":{"ts_event":"2026-04-07T02:20:09.279367205Z","rtype":160,"publisher_id":101,"instrument_id":436},"action":"C","side":"A","price":"1.156340000","size":30,"channel_id":23,"order_id":"1775528409248244546","flags":0,"ts_in_delta":1007,"sequence":157107,"symbol":"FCEU SI 20260615 PS"}
{"ts_recv":"2026-04-07T02:20:09.279385525Z","hd":{"ts_event":"2026-04-07T02:20:09.279367205Z","rtype":160,"publisher_id":101,"instrument_id":436},"action":"A","side":"A","price":"1.156330000","size":30,"channel_id":23,"order_id":"1775528409279372843","flags":128,"ts_in_delta":1007,"sequence":157107,"symbol":"FCEU SI 20260615 PS"}
{"ts_recv":"2026-04-07T02:20:09.384744815Z","hd":{"ts_event":"2026-04-07T02:20:09.384726701Z","rtype":160,"publisher_id":101,"instrument_id":436},"action":"C","side":"B","price":"1.156250000","size":30,"channel_id":23,"order_id":"10998900446102969960","flags":0,"ts_in_delta":1309,"sequence":157124,"symbol":"FCEU SI 20260615 PS"}
{"ts_recv":"2026-04-07T02:20:09.384744815Z","hd":{"ts_event":"2026-04-07T02:20:09.384726701Z","rtype":160,"publisher_id":101,"instrument_id":436},"action":"A","side":"B","price":"1.156230000","size":30,"channel_id":23,"order_id":"10998900446239508492","flags":0,"ts_in_delta":1309,"sequence":157124,"symbol":"FCEU SI 20260615 PS"}
{"ts_recv":"2026-04-07T02:20:09.384744815Z","hd":{"ts_event":"2026-04-07T02:20:09.384726701Z","rtype":160,"publisher_id":101,"instrument_id":436},"action":"C","side":"A","price":"1.156350000","size":30,"channel_id":23,"order_id":"1775528409248194152","flags":0,"ts_in_delta":1309,"sequence":157124,"symbol":"FCEU SI 20260615 PS"}
{"ts_recv":"2026-04-07T02:20:09.384744815Z","hd":{"ts_event":"2026-04-07T02:20:09.384726701Z","rtype":160,"publisher_id":101,"instrument_id":436},"action":"A","side":"A","price":"1.156330000","size":30,"channel_id":23,"order_id":"1775528409384732684","flags":128,"ts_in_delta":1309,"sequence":157124,"symbol":"FCEU SI 20260615 PS"}
{"ts_recv":"2026-04-07T02:20:09.598460792Z","hd":{"ts_event":"2026-04-07T02:20:09.598439805Z","rtype":160,"publisher_id":101,"instrument_id":436},"action":"A","side":"A","price":"1.156500000","size":20,"channel_id":23,"order_id":"1775528409598450385","flags":128,"ts_in_delta":985,"sequence":157134,"symbol":"FCEU SI 20260615 PS"}
{"ts_recv":"2026-04-07T02:20:09.598467573Z","hd":{"ts_event":"2026-04-07T02:20:09.598456437Z","rtype":160,"publisher_id":101,"instrument_id":436},"action":"C","side":"A","price":"1.156600000","size":20,"channel_id":23,"order_id":"1775528234985716212","flags":128,"ts_in_delta":684,"sequence":157135,"symbol":"FCEU SI 20260615 PS"}
{"ts_recv":"2026-04-07T02:20:09.824566182Z","hd":{"ts_event":"2026-04-07T02:20:09.824546809Z","rtype":160,"publisher_id":101,"instrument_id":436},"action":"C","side":"B","price":"1.156230000","size":30,"channel_id":23,"order_id":"10998900446239508492","flags":0,"ts_in_delta":972,"sequence":157148,"symbol":"FCEU SI 20260615 PS"}
{"ts_recv":"2026-04-07T02:20:09.824566182Z","hd":{"ts_event":"2026-04-07T02:20:09.824546809Z","rtype":160,"publisher_id":101,"instrument_id":436},"action":"A","side":"B","price":"1.156250000","size":30,"channel_id":23,"order_id":"10998900446679328582","flags":0,"ts_in_delta":972,"sequence":157148,"symbol":"FCEU SI 20260615 PS"}
{"ts_recv":"2026-04-07T02:20:09.824566182Z","hd":{"ts_event":"2026-04-07T02:20:09.824546809Z","rtype":160,"publisher_id":101,"instrument_id":436},"action":"C","side":"A","price":"1.156330000","size":30,"channel_id":23,"order_id":"1775528409384732684","flags":0,"ts_in_delta":972,"sequence":157148,"symbol":"FCEU SI 20260615 PS"}
{"ts_recv":"2026-04-07T02:20:09.824566182Z","hd":{"ts_event":"2026-04-07T02:20:09.824546809Z","rtype":160,"publisher_id":101,"instrument_id":436},"action":"A","side":"A","price":"1.156350000","size":30,"channel_id":23,"order_id":"1775528409824552774","flags":128,"ts_in_delta":972,"sequence":157148,"symbol":"FCEU SI 20260615 PS"}
{"ts_recv":"2026-04-07T02:20:09.824626744Z","hd":{"ts_event":"2026-04-07T02:20:09.824610855Z","rtype":160,"publisher_id":101,"instrument_id":436},"action":"C","side":"B","price":"1.156230000","size":30,"channel_id":23,"order_id":"10998900446134148651","flags":0,"ts_in_delta":928,"sequence":157149,"symbol":"FCEU SI 20260615 PS"}
{"ts_recv":"2026-04-07T02:20:09.824626744Z","hd":{"ts_event":"2026-04-07T02:20:09.824610855Z","rtype":160,"publisher_id":101,"instrument_id":436},"action":"A","side":"B","price":"1.156240000","size":30,"channel_id":23,"order_id":"10998900446679392673","flags":0,"ts_in_delta":928,"sequence":157149,"symbol":"FCEU SI 20260615 PS"}
{"ts_recv":"2026-04-07T02:20:09.824626744Z","hd":{"ts_event":"2026-04-07T02:20:09.824610855Z","rtype":160,"publisher_id":101,"instrument_id":436},"action":"C","side":"A","price":"1.156330000","size":30,"channel_id":23,"order_id":"1775528409279372843","flags":0,"ts_in_delta":928,"sequence":157149,"symbol":"FCEU SI 20260615 PS"}
{"ts_recv":"2026-04-07T02:20:09.824626744Z","hd":{"ts_event":"2026-04-07T02:20:09.824610855Z","rtype":160,"publisher_id":101,"instrument_id":436},"action":"A","side":"A","price":"1.156340000","size":30,"channel_id":23,"order_id":"1775528409824616865","flags":128,"ts_in_delta":928,"sequence":157149,"symbol":"FCEU SI 20260615 PS"}
{"ts_recv":"2026-04-07T02:20:09.824636228Z","hd":{"ts_event":"2026-04-07T02:20:09.824615361Z","rtype":160,"publisher_id":101,"instrument_id":436},"action":"C","side":"B","price":"1.156250000","size":30,"channel_id":23,"order_id":"10998900446679328582","flags":0,"ts_in_delta":836,"sequence":157150,"symbol":"FCEU SI 20260615 PS"}
{"ts_recv":"2026-04-07T02:20:09.824636228Z","hd":{"ts_event":"2026-04-07T02:20:09.824615361Z","rtype":160,"publisher_id":101,"instrument_id":436},"action":"A","side":"B","price":"1.156270000","size":30,"channel_id":23,"order_id":"10998900446679399496","flags":0,"ts_in_delta":836,"sequence":157150,"symbol":"FCEU SI 20260615 PS"}
{"ts_recv":"2026-04-07T02:20:09.824636228Z","hd":{"ts_event":"2026-04-07T02:20:09.824615361Z","rtype":160,"publisher_id":101,"instrument_id":436},"action":"C","side":"A","price":"1.156350000","size":30,"channel_id":23,"order_id":"1775528409824552774","flags":0,"ts_in_delta":836,"sequence":157150,"symbol":"FCEU SI 20260615 PS"}
{"ts_recv":"2026-04-07T02:20:09.824636228Z","hd":{"ts_event":"2026-04-07T02:20:09.824615361Z","rtype":160,"publisher_id":101,"instrument_id":436},"action":"A","side":"A","price":"1.156370000","size":30,"channel_id":23,"order_id":"1775528409824623688","flags":128,"ts_in_delta":836,"sequence":157150,"symbol":"FCEU SI 20260615 PS"}
{"ts_recv":"2026-04-07T02:20:09.824687119Z","hd":{"ts_event":"2026-04-07T02:20:09.824669251Z","rtype":160,"publisher_id":101,"instrument_id":436},"action":"C","side":"B","price":"1.156270000","size":30,"channel_id":23,"order_id":"10998900446679399496","flags":0,"ts_in_delta":2203,"sequence":157151,"symbol":"FCEU SI 20260615 PS"}
{"ts_recv":"2026-04-07T02:20:09.824687119Z","hd":{"ts_event":"2026-04-07T02:20:09.824669251Z","rtype":160,"publisher_id":101,"instrument_id":436},"action":"A","side":"B","price":"1.156250000","size":30,"channel_id":23,"order_id":"10998900446679450876","flags":0,"ts_in_delta":2203,"sequence":157151,"symbol":"FCEU SI 20260615 PS"}
{"ts_recv":"2026-04-07T02:20:09.824687119Z","hd":{"ts_event":"2026-04-07T02:20:09.824669251Z","rtype":160,"publisher_id":101,"instrument_id":436},"action":"C","side":"A","price":"1.156370000","size":30,"channel_id":23,"order_id":"1775528409824623688","flags":0,"ts_in_delta":2203,"sequence":157151,"symbol":"FCEU SI 20260615 PS"}
{"ts_recv":"2026-04-07T02:20:09.824687119Z","hd":{"ts_event":"2026-04-07T02:20:09.824669251Z","rtype":160,"publisher_id":101,"instrument_id":436},"action":"A","side":"A","price":"1.156350000","size":30,"channel_id":23,"order_id":"1775528409824675068","flags":128,"ts_in_delta":2203,"sequence":157151,"symbol":"FCEU SI 20260615 PS"}
{"ts_recv":"2026-04-07T02:20:09.824698111Z","hd":{"ts_event":"2026-04-07T02:20:09.824679955Z","rtype":160,"publisher_id":101,"instrument_id":436},"action":"C","side":"B","price":"1.156240000","size":30,"channel_id":23,"order_id":"10998900446679392673","flags":0,"ts_in_delta":919,"sequence":157152,"symbol":"FCEU SI 20260615 PS"}
{"ts_recv":"2026-04-07T02:20:09.824698111Z","hd":{"ts_event":"2026-04-07T02:20:09.824679955Z","rtype":160,"publisher_id":101,"instrument_id":436},"action":"A","side":"B","price":"1.156250000","size":30,"channel_id":23,"order_id":"10998900446679461609","flags":0,"ts_in_delta":919,"sequence":157152,"symbol":"FCEU SI 20260615 PS"}
{"ts_recv":"2026-04-07T02:20:09.824698111Z","hd":{"ts_event":"2026-04-07T02:20:09.824679955Z","rtype":160,"publisher_id":101,"instrument_id":436},"action":"C","side":"A","price":"1.156340000","size":30,"channel_id":23,"order_id":"1775528409824616865","flags":0,"ts_in_delta":919,"sequence":157152,"symbol":"FCEU SI 20260615 PS"}
{"ts_recv":"2026-04-07T02:20:09.824698111Z","hd":{"ts_event":"2026-04-07T02:20:09.824679955Z","rtype":160,"publisher_id":101,"instrument_id":436},"action":"A","side":"A","price":"1.156350000","size":30,"channel_id":23,"order_id":"1775528409824685801","flags":128,"ts_in_delta":919,"sequence":157152,"symbol":"FCEU SI 20260615 PS"}
{"ts_recv":"2026-04-07T02:20:09.824754733Z","hd":{"ts_event":"2026-04-07T02:20:09.824735811Z","rtype":160,"publisher_id":101,"instrument_id":436},"action":"C","side":"B","price":"1.156250000","size":30,"channel_id":23,"order_id":"10998900446679461609","flags":0,"ts_in_delta":841,"sequence":157153,"symbol":"FCEU SI 20260615 PS"}
{"ts_recv":"2026-04-07T02:20:09.824754733Z","hd":{"ts_event":"2026-04-07T02:20:09.824735811Z","rtype":160,"publisher_id":101,"instrument_id":436},"action":"A","side":"B","price":"1.156260000","size":30,"channel_id":23,"order_id":"10998900446679517466","flags":0,"ts_in_delta":841,"sequence":157153,"symbol":"FCEU SI 20260615 PS"}
{"ts_recv":"2026-04-07T02:20:09.824754733Z","hd":{"ts_event":"2026-04-07T02:20:09.824735811Z","rtype":160,"publisher_id":101,"instrument_id":436},"action":"C","side":"A","price":"1.156350000","size":30,"channel_id":23,"order_id":"1775528409824685801","flags":0,"ts_in_delta":841,"sequence":157153,"symbol":"FCEU SI 20260615 PS"}
{"ts_recv":"2026-04-07T02:20:09.824754733Z","hd":{"ts_event":"2026-04-07T02:20:09.824735811Z","rtype":160,"publisher_id":101,"instrument_id":436},"action":"A","side":"A","price":"1.156360000","size":30,"channel_id":23,"order_id":"1775528409824741658","flags":128,"ts_in_delta":841,"sequence":157153,"symbol":"FCEU SI 20260615 PS"}
{"ts_recv":"2026-04-07T02:20:09.824809489Z","hd":{"ts_event":"2026-04-07T02:20:09.824793063Z","rtype":160,"publisher_id":101,"instrument_id":436},"action":"C","side":"B","price":"1.156260000","size":30,"channel_id":23,"order_id":"10998900446679517466","flags":0,"ts_in_delta":826,"sequence":157154,"symbol":"FCEU SI 20260615 PS"}
{"ts_recv":"2026-04-07T02:20:09.824809489Z","hd":{"ts_event":"2026-04-07T02:20:09.824793063Z","rtype":160,"publisher_id":101,"instrument_id":436},"action":"A","side":"B","price":"1.156250000","size":30,"channel_id":23,"order_id":"10998900446679574573","flags":0,"ts_in_delta":826,"sequence":157154,"symbol":"FCEU SI 20260615 PS"}
{"ts_recv":"2026-04-07T02:20:09.824809489Z","hd":{"ts_event":"2026-04-07T02:20:09.824793063Z","rtype":160,"publisher_id":101,"instrument_id":436},"action":"C","side":"A","price":"1.156360000","size":30,"channel_id":23,"order_id":"1775528409824741658","flags":0,"ts_in_delta":826,"sequence":157154,"symbol":"FCEU SI 20260615 PS"}
{"ts_recv":"2026-04-07T02:20:09.824809489Z","hd":{"ts_event":"2026-04-07T02:20:09.824793063Z","rtype":160,"publisher_id":101,"instrument_id":436},"action":"A","side":"A","price":"1.156350000","size":30,"channel_id":23,"order_id":"1775528409824798765","flags":128,"ts_in_delta":826,"sequence":157154,"symbol":"FCEU SI 20260615 PS"}
{"ts_recv":"2026-04-07T02:20:09.917861243Z","hd":{"ts_event":"2026-04-07T02:20:09.917842621Z","rtype":160,"publisher_id":101,"instrument_id":436},"action":"C","side":"B","price":"1.156250000","size":30,"channel_id":23,"order_id":"10998900446679574573","flags":0,"ts_in_delta":901,"sequence":157169,"symbol":"FCEU SI 20260615 PS"}
{"ts_recv":"2026-04-07T02:20:09.917861243Z","hd":{"ts_event":"2026-04-07T02:20:09.917842621Z","rtype":160,"publisher_id":101,"instrument_id":436},"action":"A","side":"B","price":"1.156240000","size":30,"channel_id":23,"order_id":"10998900446772624071","flags":0,"ts_in_delta":901,"sequence":157169,"symbol":"FCEU SI 20260615 PS"}
{"ts_recv":"2026-04-07T02:20:09.917861243Z","hd":{"ts_event":"2026-04-07T02:20:09.917842621Z","rtype":160,"publisher_id":101,"instrument_id":436},"action":"C","side":"A","price":"1.156350000","size":30,"channel_id":23,"order_id":"1775528409824798765","flags":0,"ts_in_delta":901,"sequence":157169,"symbol":"FCEU SI 20260615 PS"}
{"ts_recv":"2026-04-07T02:20:09.917861243Z","hd":{"ts_event":"2026-04-07T02:20:09.917842621Z","rtype":160,"publisher_id":101,"instrument_id":436},"action":"A","side":"A","price":"1.156340000","size":30,"channel_id":23,"order_id":"1775528409917848263","flags":128,"ts_in_delta":901,"sequence":157169,"symbol":"FCEU SI 20260615 PS"}
{"ts_recv":"2026-04-07T02:20:14.111228240Z","hd":{"ts_event":"2026-04-07T02:20:14.111210585Z","rtype":160,"publisher_id":101,"instrument_id":436},"action":"C","side":"B","price":"1.156240000","size":30,"channel_id":23,"order_id":"10998900446772624071","flags":0,"ts_in_delta":967,"sequence":157188,"symbol":"FCEU SI 20260615 PS"}
{"ts_recv":"2026-04-07T02:20:14.111228240Z","hd":{"ts_event":"2026-04-07T02:20:14.111210585Z","rtype":160,"publisher_id":101,"instrument_id":436},"action":"A","side":"B","price":"1.156250000","size":30,"channel_id":23,"order_id":"10998900450965992819","flags":0,"ts_in_delta":967,"sequence":157188,"symbol":"FCEU SI 20260615 PS"}
{"ts_recv":"2026-04-07T02:20:14.111228240Z","hd":{"ts_event":"2026-04-07T02:20:14.111210585Z","rtype":160,"publisher_id":101,"instrument_id":436},"action":"C","side":"A","price":"1.156340000","size":30,"channel_id":23,"order_id":"1775528409917848263","flags":0,"ts_in_delta":967,"sequence":157188,"symbol":"FCEU SI 20260615 PS"}
{"ts_recv":"2026-04-07T02:20:14.111228240Z","hd":{"ts_event":"2026-04-07T02:20:14.111210585Z","rtype":160,"publisher_id":101,"instrument_id":436},"action":"A","side":"A","price":"1.156350000","size":30,"channel_id":23,"order_id":"1775528414111217011","flags":128,"ts_in_delta":967,"sequence":157188,"symbol":"FCEU SI 20260615 PS"}
{"ts_recv":"2026-04-07T02:20:14.120611472Z","hd":{"ts_event":"2026-04-07T02:20:14.120590889Z","rtype":160,"publisher_id":101,"instrument_id":436},"action":"C","side":"B","price":"1.156250000","size":30,"channel_id":23,"order_id":"10998900450965992819","flags":0,"ts_in_delta":888,"sequence":157190,"symbol":"FCEU SI 20260615 PS"}
{"ts_recv":"2026-04-07T02:20:14.120611472Z","hd":{"ts_event":"2026-04-07T02:20:14.120590889Z","rtype":160,"publisher_id":101,"instrument_id":436},"action":"A","side":"B","price":"1.156260000","size":30,"channel_id":23,"order_id":"10998900450975372461","flags":0,"ts_in_delta":888,"sequence":157190,"symbol":"FCEU SI 20260615 PS"}
{"ts_recv":"2026-04-07T02:20:14.120611472Z","hd":{"ts_event":"2026-04-07T02:20:14.120590889Z","rtype":160,"publisher_id":101,"instrument_id":436},"action":"C","side":"A","price":"1.156350000","size":30,"channel_id":23,"order_id":"1775528414111217011","flags":0,"ts_in_delta":888,"sequence":157190,"symbol":"FCEU SI 20260615 PS"}
{"ts_recv":"2026-04-07T02:20:14.120611472Z","hd":{"ts_event":"2026-04-07T02:20:14.120590889Z","rtype":160,"publisher_id":101,"instrument_id":436},"action":"A","side":"A","price":"1.156360000","size":30,"channel_id":23,"order_id":"1775528414120596653","flags":128,"ts_in_delta":888,"sequence":157190,"symbol":"FCEU SI 20260615 PS"}
{"ts_recv":"2026-04-07T02:20:14.134019292Z","hd":{"ts_event":"2026-04-07T02:20:14.133998791Z","rtype":160,"publisher_id":101,"instrument_id":436},"action":"C","side":"B","price":"1.156250000","size":30,"channel_id":23,"order_id":"10998900446679450876","flags":0,"ts_in_delta":919,"sequence":157191,"symbol":"FCEU SI 20260615 PS"}
{"ts_recv":"2026-04-07T02:20:14.134019292Z","hd":{"ts_event":"2026-04-07T02:20:14.133998791Z","rtype":160,"publisher_id":101,"instrument_id":436},"action":"A","side":"B","price":"1.156270000","size":30,"channel_id":23,"order_id":"10998900450988780568","flags":0,"ts_in_delta":919,"sequence":157191,"symbol":"FCEU SI 20260615 PS"}
{"ts_recv":"2026-04-07T02:20:14.134019292Z","hd":{"ts_event":"2026-04-07T02:20:14.133998791Z","rtype":160,"publisher_id":101,"instrument_id":436},"action":"C","side":"A","price":"1.156350000","size":30,"channel_id":23,"order_id":"1775528409824675068","flags":0,"ts_in_delta":919,"sequence":157191,"symbol":"FCEU SI 20260615 PS"}
{"ts_recv":"2026-04-07T02:20:14.134019292Z","hd":{"ts_event":"2026-04-07T02:20:14.133998791Z","rtype":160,"publisher_id":101,"instrument_id":436},"action":"A","side":"A","price":"1.156370000","size":30,"channel_id":23,"order_id":"1775528414134004760","flags":128,"ts_in_delta":919,"sequence":157191,"symbol":"FCEU SI 20260615 PS"}
{"ts_recv":"2026-04-07T02:20:14.134079915Z","hd":{"ts_event":"2026-04-07T02:20:14.134062523Z","rtype":160,"publisher_id":101,"instrument_id":436},"action":"C","side":"B","price":"1.156260000","size":30,"channel_id":23,"order_id":"10998900450975372461","flags":0,"ts_in_delta":938,"sequence":157192,"symbol":"FCEU SI 20260615 PS"}
{"ts_recv":"2026-04-07T02:20:14.134079915Z","hd":{"ts_event":"2026-04-07T02:20:14.134062523Z","rtype":160,"publisher_id":101,"instrument_id":436},"action":"A","side":"B","price":"1.156270000","size":30,"channel_id":23,"order_id":"10998900450988844498","flags":0,"ts_in_delta":938,"sequence":157192,"symbol":"FCEU SI 20260615 PS"}
{"ts_recv":"2026-04-07T02:20:14.134079915Z","hd":{"ts_event":"2026-04-07T02:20:14.134062523Z","rtype":160,"publisher_id":101,"instrument_id":436},"action":"C","side":"A","price":"1.156360000","size":30,"channel_id":23,"order_id":"1775528414120596653","flags":0,"ts_in_delta":938,"sequence":157192,"symbol":"FCEU SI 20260615 PS"}
{"ts_recv":"2026-04-07T02:20:14.134079915Z","hd":{"ts_event":"2026-04-07T02:20:14.134062523Z","rtype":160,"publisher_id":101,"instrument_id":436},"action":"A","side":"A","price":"1.156370000","size":30,"channel_id":23,"order_id":"1775528414134068690","flags":128,"ts_in_delta":938,"sequence":157192,"symbol":"FCEU SI 20260615 PS"}
{"ts_recv":"2026-04-07T02:20:22.951298533Z","hd":{"ts_event":"2026-04-07T02:20:22.951276753Z","rtype":160,"publisher_id":101,"instrument_id":436},"action":"C","side":"B","price":"1.156270000","size":30,"channel_id":23,"order_id":"10998900450988844498","flags":0,"ts_in_delta":932,"sequence":157312,"symbol":"FCEU SI 20260615 PS"}
{"ts_recv":"2026-04-07T02:20:22.951298533Z","hd":{"ts_event":"2026-04-07T02:20:22.951276753Z","rtype":160,"publisher_id":101,"instrument_id":436},"action":"A","side":"B","price":"1.156280000","size":30,"channel_id":23,"order_id":"10998900459806059001","flags":0,"ts_in_delta":932,"sequence":157312,"symbol":"FCEU SI 20260615 PS"}
{"ts_recv":"2026-04-07T02:20:22.951298533Z","hd":{"ts_event":"2026-04-07T02:20:22.951276753Z","rtype":160,"publisher_id":101,"instrument_id":436},"action":"C","side":"A","price":"1.156370000","size":30,"channel_id":23,"order_id":"1775528414134068690","flags":0,"ts_in_delta":932,"sequence":157312,"symbol":"FCEU SI 20260615 PS"}
{"ts_recv":"2026-04-07T02:20:22.951298533Z","hd":{"ts_event":"2026-04-07T02:20:22.951276753Z","rtype":160,"publisher_id":101,"instrument_id":436},"action":"A","side":"A","price":"1.156380000","size":30,"channel_id":23,"order_id":"1775528422951283193","flags":128,"ts_in_delta":932,"sequence":157312,"symbol":"FCEU SI 20260615 PS"}
{"ts_recv":"2026-04-07T02:20:23.994882979Z","hd":{"ts_event":"2026-04-07T02:20:23.994853945Z","rtype":160,"publisher_id":101,"instrument_id":436},"action":"C","side":"B","price":"1.156270000","size":30,"channel_id":23,"order_id":"10998900450988780568","flags":0,"ts_in_delta":1291,"sequence":157321,"symbol":"FCEU SI 20260615 PS"}
{"ts_recv":"2026-04-07T02:20:23.994882979Z","hd":{"ts_event":"2026-04-07T02:20:23.994853945Z","rtype":160,"publisher_id":101,"instrument_id":436},"action":"A","side":"B","price":"1.156290000","size":30,"channel_id":23,"order_id":"10998900460849642979","flags":0,"ts_in_delta":1291,"sequence":157321,"symbol":"FCEU SI 20260615 PS"}
{"ts_recv":"2026-04-07T02:20:23.994882979Z","hd":{"ts_event":"2026-04-07T02:20:23.994853945Z","rtype":160,"publisher_id":101,"instrument_id":436},"action":"C","side":"A","price":"1.156370000","size":30,"channel_id":23,"order_id":"1775528414134004760","flags":0,"ts_in_delta":1291,"sequence":157321,"symbol":"FCEU SI 20260615 PS"}
{"ts_recv":"2026-04-07T02:20:23.994882979Z","hd":{"ts_event":"2026-04-07T02:20:23.994853945Z","rtype":160,"publisher_id":101,"instrument_id":436},"action":"A","side":"A","price":"1.156390000","size":30,"channel_id":23,"order_id":"1775528423994867171","flags":128,"ts_in_delta":1291,"sequence":157321,"symbol":"FCEU SI 20260615 PS"}
{"ts_recv":"2026-04-07T02:20:23.994996123Z","hd":{"ts_event":"2026-04-07T02:20:23.994980525Z","rtype":160,"publisher_id":101,"instrument_id":436},"action":"C","side":"B","price":"1.156280000","size":30,"channel_id":23,"order_id":"10998900459806059001","flags":0,"ts_in_delta":963,"sequence":157322,"symbol":"FCEU SI 20260615 PS"}
{"ts_recv":"2026-04-07T02:20:23.994996123Z","hd":{"ts_event":"2026-04-07T02:20:23.994980525Z","rtype":160,"publisher_id":101,"instrument_id":436},"action":"A","side":"B","price":"1.156290000","size":30,"channel_id":23,"order_id":"10998900460849762288","flags":0,"ts_in_delta":963,"sequence":157322,"symbol":"FCEU SI 20260615 PS"}
{"ts_recv":"2026-04-07T02:20:23.994996123Z","hd":{"ts_event":"2026-04-07T02:20:23.994980525Z","rtype":160,"publisher_id":101,"instrument_id":436},"action":"C","side":"A","price":"1.156380000","size":30,"channel_id":23,"order_id":"1775528422951283193","flags":0,"ts_in_delta":963,"sequence":157322,"symbol":"FCEU SI 20260615 PS"}
{"ts_recv":"2026-04-07T02:20:23.994996123Z","hd":{"ts_event":"2026-04-07T02:20:23.994980525Z","rtype":160,"publisher_id":101,"instrument_id":436},"action":"A","side":"A","price":"1.156390000","size":30,"channel_id":23,"order_id":"1775528423994986480","flags":128,"ts_in_delta":963,"sequence":157322,"symbol":"FCEU SI 20260615 PS"}
{"ts_recv":"2026-04-07T02:20:24.980387568Z","hd":{"ts_event":"2026-04-07T02:20:24.980366557Z","rtype":160,"publisher_id":101,"instrument_id":436},"action":"C","side":"B","price":"1.156290000","size":30,"channel_id":23,"order_id":"10998900460849762288","flags":0,"ts_in_delta":869,"sequence":157327,"symbol":"FCEU SI 20260615 PS"}
{"ts_recv":"2026-04-07T02:20:24.980387568Z","hd":{"ts_event":"2026-04-07T02:20:24.980366557Z","rtype":160,"publisher_id":101,"instrument_id":436},"action":"A","side":"B","price":"1.156300000","size":30,"channel_id":23,"order_id":"10998900461835148554","flags":0,"ts_in_delta":869,"sequence":157327,"symbol":"FCEU SI 20260615 PS"}
{"ts_recv":"2026-04-07T02:20:24.980387568Z","hd":{"ts_event":"2026-04-07T02:20:24.980366557Z","rtype":160,"publisher_id":101,"instrument_id":436},"action":"C","side":"A","price":"1.156390000","size":30,"channel_id":23,"order_id":"1775528423994986480","flags":0,"ts_in_delta":869,"sequence":157327,"symbol":"FCEU SI 20260615 PS"}
{"ts_recv":"2026-04-07T02:20:24.980387568Z","hd":{"ts_event":"2026-04-07T02:20:24.980366557Z","rtype":160,"publisher_id":101,"instrument_id":436},"action":"A","side":"A","price":"1.156400000","size":30,"channel_id":23,"order_id":"1775528424980372746","flags":128,"ts_in_delta":869,"sequence":157327,"symbol":"FCEU SI 20260615 PS"}
{"ts_recv":"2026-04-07T02:20:25.000312828Z","hd":{"ts_event":"2026-04-07T02:20:25.000292265Z","rtype":160,"publisher_id":101,"instrument_id":436},"action":"C","side":"B","price":"1.156290000","size":30,"channel_id":23,"order_id":"10998900460849642979","flags":0,"ts_in_delta":892,"sequence":157331,"symbol":"FCEU SI 20260615 PS"}
{"ts_recv":"2026-04-07T02:20:25.000312828Z","hd":{"ts_event":"2026-04-07T02:20:25.000292265Z","rtype":160,"publisher_id":101,"instrument_id":436},"action":"A","side":"B","price":"1.156310000","size":30,"channel_id":23,"order_id":"10998900461855073777","flags":0,"ts_in_delta":892,"sequence":157331,"symbol":"FCEU SI 20260615 PS"}
{"ts_recv":"2026-04-07T02:20:25.000312828Z","hd":{"ts_event":"2026-04-07T02:20:25.000292265Z","rtype":160,"publisher_id":101,"instrument_id":436},"action":"C","side":"A","price":"1.156390000","size":30,"channel_id":23,"order_id":"1775528423994867171","flags":0,"ts_in_delta":892,"sequence":157331,"symbol":"FCEU SI 20260615 PS"}
{"ts_recv":"2026-04-07T02:20:25.000312828Z","hd":{"ts_event":"2026-04-07T02:20:25.000292265Z","rtype":160,"publisher_id":101,"instrument_id":436},"action":"A","side":"A","price":"1.156410000","size":30,"channel_id":23,"order_id":"1775528425000297969","flags":128,"ts_in_delta":892,"sequence":157331,"symbol":"FCEU SI 20260615 PS"}
{"ts_recv":"2026-04-07T02:20:25.000387843Z","hd":{"ts_event":"2026-04-07T02:20:25.000371077Z","rtype":160,"publisher_id":101,"instrument_id":436},"action":"C","side":"B","price":"1.156300000","size":30,"channel_id":23,"order_id":"10998900461835148554","flags":0,"ts_in_delta":881,"sequence":157332,"symbol":"FCEU SI 20260615 PS"}
{"ts_recv":"2026-04-07T02:20:25.000387843Z","hd":{"ts_event":"2026-04-07T02:20:25.000371077Z","rtype":160,"publisher_id":101,"instrument_id":436},"action":"A","side":"B","price":"1.156310000","size":30,"channel_id":23,"order_id":"10998900461855153087","flags":0,"ts_in_delta":881,"sequence":157332,"symbol":"FCEU SI 20260615 PS"}
{"ts_recv":"2026-04-07T02:20:25.000387843Z","hd":{"ts_event":"2026-04-07T02:20:25.000371077Z","rtype":160,"publisher_id":101,"instrument_id":436},"action":"C","side":"A","price":"1.156400000","size":30,"channel_id":23,"order_id":"1775528424980372746","flags":0,"ts_in_delta":881,"sequence":157332,"symbol":"FCEU SI 20260615 PS"}
{"ts_recv":"2026-04-07T02:20:25.000387843Z","hd":{"ts_event":"2026-04-07T02:20:25.000371077Z","rtype":160,"publisher_id":101,"instrument_id":436},"action":"A","side":"A","price":"1.156410000","size":30,"channel_id":23,"order_id":"1775528425000377279","flags":128,"ts_in_delta":881,"sequence":157332,"symbol":"FCEU SI 20260615 PS"}
{"ts_recv":"2026-04-07T02:20:29.281684144Z","hd":{"ts_event":"2026-04-07T02:20:29.281655099Z","rtype":160,"publisher_id":101,"instrument_id":436},"action":"C","side":"B","price":"1.156310000","size":30,"channel_id":23,"order_id":"10998900461855153087","flags":0,"ts_in_delta":1161,"sequence":157364,"symbol":"FCEU SI 20260615 PS"}
{"ts_recv":"2026-04-07T02:20:29.281684144Z","hd":{"ts_event":"2026-04-07T02:20:29.281655099Z","rtype":160,"publisher_id":101,"instrument_id":436},"action":"A","side":"B","price":"1.156300000","size":30,"channel_id":23,"order_id":"10998900466136441755","flags":0,"ts_in_delta":1161,"sequence":157364,"symbol":"FCEU SI 20260615 PS"}
{"ts_recv":"2026-04-07T02:20:29.281684144Z","hd":{"ts_event":"2026-04-07T02:20:29.281655099Z","rtype":160,"publisher_id":101,"instrument_id":436},"action":"C","side":"A","price":"1.156410000","size":30,"channel_id":23,"order_id":"1775528425000377279","flags":0,"ts_in_delta":1161,"sequence":157364,"symbol":"FCEU SI 20260615 PS"}
{"ts_recv":"2026-04-07T02:20:29.281684144Z","hd":{"ts_event":"2026-04-07T02:20:29.281655099Z","rtype":160,"publisher_id":101,"instrument_id":436},"action":"A","side":"A","price":"1.156400000","size":30,"channel_id":23,"order_id":"1775528429281665947","flags":128,"ts_in_delta":1161,"sequence":157364,"symbol":"FCEU SI 20260615 PS"}
{"ts_recv":"2026-04-07T02:20:30.648319431Z","hd":{"ts_event":"2026-04-07T02:20:30.648300699Z","rtype":160,"publisher_id":101,"instrument_id":436},"action":"C","side":"B","price":"1.156300000","size":30,"channel_id":23,"order_id":"10998900466136441755","flags":0,"ts_in_delta":912,"sequence":157398,"symbol":"FCEU SI 20260615 PS"}
{"ts_recv":"2026-04-07T02:20:30.648319431Z","hd":{"ts_event":"2026-04-07T02:20:30.648300699Z","rtype":160,"publisher_id":101,"instrument_id":436},"action":"A","side":"B","price":"1.156310000","size":30,"channel_id":23,"order_id":"10998900467503082277","flags":0,"ts_in_delta":912,"sequence":157398,"symbol":"FCEU SI 20260615 PS"}
{"ts_recv":"2026-04-07T02:20:30.648319431Z","hd":{"ts_event":"2026-04-07T02:20:30.648300699Z","rtype":160,"publisher_id":101,"instrument_id":436},"action":"C","side":"A","price":"1.156400000","size":30,"channel_id":23,"order_id":"1775528429281665947","flags":0,"ts_in_delta":912,"sequence":157398,"symbol":"FCEU SI 20260615 PS"}
{"ts_recv":"2026-04-07T02:20:30.648319431Z","hd":{"ts_event":"2026-04-07T02:20:30.648300699Z","rtype":160,"publisher_id":101,"instrument_id":436},"action":"A","side":"A","price":"1.156410000","size":30,"channel_id":23,"order_id":"1775528430648306469","flags":128,"ts_in_delta":912,"sequence":157398,"symbol":"FCEU SI 20260615 PS"}
{"ts_recv":"2026-04-07T02:20:32.734269789Z","hd":{"ts_event":"2026-04-07T02:20:32.734249975Z","rtype":160,"publisher_id":101,"instrument_id":436},"action":"C","side":"B","price":"1.156310000","size":30,"channel_id":23,"order_id":"10998900461855073777","flags":0,"ts_in_delta":948,"sequence":157410,"symbol":"FCEU SI 20260615 PS"}
{"ts_recv":"2026-04-07T02:20:32.734269789Z","hd":{"ts_event":"2026-04-07T02:20:32.734249975Z","rtype":160,"publisher_id":101,"instrument_id":436},"action":"A","side":"B","price":"1.156330000","size":30,"channel_id":23,"order_id":"10998900469589031683","flags":0,"ts_in_delta":948,"sequence":157410,"symbol":"FCEU SI 20260615 PS"}
{"ts_recv":"2026-04-07T02:20:32.734269789Z","hd":{"ts_event":"2026-04-07T02:20:32.734249975Z","rtype":160,"publisher_id":101,"instrument_id":436},"action":"C","side":"A","price":"1.156410000","size":30,"channel_id":23,"order_id":"1775528425000297969","flags":0,"ts_in_delta":948,"sequence":157410,"symbol":"FCEU SI 20260615 PS"}
{"ts_recv":"2026-04-07T02:20:32.734269789Z","hd":{"ts_event":"2026-04-07T02:20:32.734249975Z","rtype":160,"publisher_id":101,"instrument_id":436},"action":"A","side":"A","price":"1.156430000","size":30,"channel_id":23,"order_id":"1775528432734255875","flags":128,"ts_in_delta":948,"sequence":157410,"symbol":"FCEU SI 20260615 PS"}
{"ts_recv":"2026-04-07T02:20:32.734382089Z","hd":{"ts_event":"2026-04-07T02:20:32.734361739Z","rtype":160,"publisher_id":101,"instrument_id":436},"action":"C","side":"B","price":"1.156310000","size":30,"channel_id":23,"order_id":"10998900467503082277","flags":0,"ts_in_delta":965,"sequence":157411,"symbol":"FCEU SI 20260615 PS"}
{"ts_recv":"2026-04-07T02:20:32.734382089Z","hd":{"ts_event":"2026-04-07T02:20:32.734361739Z","rtype":160,"publisher_id":101,"instrument_id":436},"action":"A","side":"B","price":"1.156320000","size":30,"channel_id":23,"order_id":"10998900469589144664","flags":0,"ts_in_delta":965,"sequence":157411,"symbol":"FCEU SI 20260615 PS"}
{"ts_recv":"2026-04-07T02:20:32.734382089Z","hd":{"ts_event":"2026-04-07T02:20:32.734361739Z","rtype":160,"publisher_id":101,"instrument_id":436},"action":"C","side":"A","price":"1.156410000","size":30,"channel_id":23,"order_id":"1775528430648306469","flags":0,"ts_in_delta":965,"sequence":157411,"symbol":"FCEU SI 20260615 PS"}
{"ts_recv":"2026-04-07T02:20:32.734382089Z","hd":{"ts_event":"2026-04-07T02:20:32.734361739Z","rtype":160,"publisher_id":101,"instrument_id":436},"action":"A","side":"A","price":"1.156420000","size":30,"channel_id":23,"order_id":"1775528432734368856","flags":128,"ts_in_delta":965,"sequence":157411,"symbol":"FCEU SI 20260615 PS"}
{"ts_recv":"2026-04-07T02:20:32.738091558Z","hd":{"ts_event":"2026-04-07T02:20:32.738073477Z","rtype":160,"publisher_id":101,"instrument_id":436},"action":"C","side":"B","price":"1.156320000","size":30,"channel_id":23,"order_id":"10998900469589144664","flags":0,"ts_in_delta":909,"sequence":157419,"symbol":"FCEU SI 20260615 PS"}
{"ts_recv":"2026-04-07T02:20:32.738091558Z","hd":{"ts_event":"2026-04-07T02:20:32.738073477Z","rtype":160,"publisher_id":101,"instrument_id":436},"action":"A","side":"B","price":"1.156330000","size":30,"channel_id":23,"order_id":"10998900469592855430","flags":0,"ts_in_delta":909,"sequence":157419,"symbol":"FCEU SI 20260615 PS"}
{"ts_recv":"2026-04-07T02:20:32.738091558Z","hd":{"ts_event":"2026-04-07T02:20:32.738073477Z","rtype":160,"publisher_id":101,"instrument_id":436},"action":"C","side":"A","price":"1.156420000","size":30,"channel_id":23,"order_id":"1775528432734368856","flags":0,"ts_in_delta":909,"sequence":157419,"symbol":"FCEU SI 20260615 PS"}
{"ts_recv":"2026-04-07T02:20:32.738091558Z","hd":{"ts_event":"2026-04-07T02:20:32.738073477Z","rtype":160,"publisher_id":101,"instrument_id":436},"action":"A","side":"A","price":"1.156430000","size":30,"channel_id":23,"order_id":"1775528432738079622","flags":128,"ts_in_delta":909,"sequence":157419,"symbol":"FCEU SI 20260615 PS"}
{"ts_recv":"2026-04-07T02:20:32.742270008Z","hd":{"ts_event":"2026-04-07T02:20:32.742250541Z","rtype":160,"publisher_id":101,"instrument_id":436},"action":"C","side":"B","price":"1.156330000","size":30,"channel_id":23,"order_id":"10998900469592855430","flags":0,"ts_in_delta":907,"sequence":157426,"symbol":"FCEU SI 20260615 PS"}
{"ts_recv":"2026-04-07T02:20:32.742270008Z","hd":{"ts_event":"2026-04-07T02:20:32.742250541Z","rtype":160,"publisher_id":101,"instrument_id":436},"action":"A","side":"B","price":"1.156340000","size":30,"channel_id":23,"order_id":"10998900469597032162","flags":0,"ts_in_delta":907,"sequence":157426,"symbol":"FCEU SI 20260615 PS"}
{"ts_recv":"2026-04-07T02:20:32.742270008Z","hd":{"ts_event":"2026-04-07T02:20:32.742250541Z","rtype":160,"publisher_id":101,"instrument_id":436},"action":"C","side":"A","price":"1.156430000","size":30,"channel_id":23,"order_id":"1775528432738079622","flags":0,"ts_in_delta":907,"sequence":157426,"symbol":"FCEU SI 20260615 PS"}
{"ts_recv":"2026-04-07T02:20:32.742270008Z","hd":{"ts_event":"2026-04-07T02:20:32.742250541Z","rtype":160,"publisher_id":101,"instrument_id":436},"action":"A","side":"A","price":"1.156440000","size":30,"channel_id":23,"order_id":"1775528432742256354","flags":128,"ts_in_delta":907,"sequence":157426,"symbol":"FCEU SI 20260615 PS"}
{"ts_recv":"2026-04-07T02:20:32.742320510Z","hd":{"ts_event":"2026-04-07T02:20:32.742301209Z","rtype":160,"publisher_id":101,"instrument_id":436},"action":"C","side":"B","price":"1.156330000","size":30,"channel_id":23,"order_id":"10998900469589031683","flags":0,"ts_in_delta":913,"sequence":157427,"symbol":"FCEU SI 20260615 PS"}
{"ts_recv":"2026-04-07T02:20:32.742320510Z","hd":{"ts_event":"2026-04-07T02:20:32.742301209Z","rtype":160,"publisher_id":101,"instrument_id":436},"action":"A","side":"B","price":"1.156350000","size":30,"channel_id":23,"order_id":"10998900469597083057","flags":0,"ts_in_delta":913,"sequence":157427,"symbol":"FCEU SI 20260615 PS"}
{"ts_recv":"2026-04-07T02:20:32.742320510Z","hd":{"ts_event":"2026-04-07T02:20:32.742301209Z","rtype":160,"publisher_id":101,"instrument_id":436},"action":"C","side":"A","price":"1.156430000","size":30,"channel_id":23,"order_id":"1775528432734255875","flags":0,"ts_in_delta":913,"sequence":157427,"symbol":"FCEU SI 20260615 PS"}
{"ts_recv":"2026-04-07T02:20:32.742320510Z","hd":{"ts_event":"2026-04-07T02:20:32.742301209Z","rtype":160,"publisher_id":101,"instrument_id":436},"action":"A","side":"A","price":"1.156450000","size":30,"channel_id":23,"order_id":"1775528432742307249","flags":128,"ts_in_delta":913,"sequence":157427,"symbol":"FCEU SI 20260615 PS"}
{"ts_recv":"2026-04-07T02:20:32.742351252Z","hd":{"ts_event":"2026-04-07T02:20:32.742335289Z","rtype":160,"publisher_id":101,"instrument_id":436},"action":"C","side":"B","price":"1.156340000","size":30,"channel_id":23,"order_id":"10998900469597032162","flags":0,"ts_in_delta":1013,"sequence":157429,"symbol":"FCEU SI 20260615 PS"}
{"ts_recv":"2026-04-07T02:20:32.742351252Z","hd":{"ts_event":"2026-04-07T02:20:32.742335289Z","rtype":160,"publisher_id":101,"instrument_id":436},"action":"A","side":"B","price":"1.156350000","size":30,"channel_id":23,"order_id":"10998900469597116712","flags":0,"ts_in_delta":1013,"sequence":157429,"symbol":"FCEU SI 20260615 PS"}
{"ts_recv":"2026-04-07T02:20:32.742351252Z","hd":{"ts_event":"2026-04-07T02:20:32.742335289Z","rtype":160,"publisher_id":101,"instrument_id":436},"action":"C","side":"A","price":"1.156440000","size":30,"channel_id":23,"order_id":"1775528432742256354","flags":0,"ts_in_delta":1013,"sequence":157429,"symbol":"FCEU SI 20260615 PS"}
{"ts_recv":"2026-04-07T02:20:32.742351252Z","hd":{"ts_event":"2026-04-07T02:20:32.742335289Z","rtype":160,"publisher_id":101,"instrument_id":436},"action":"A","side":"A","price":"1.156450000","size":30,"channel_id":23,"order_id":"1775528432742340904","flags":128,"ts_in_delta":1013,"sequence":157429,"symbol":"FCEU SI 20260615 PS"}
{"ts_recv":"2026-04-07T02:20:32.742519183Z","hd":{"ts_event":"2026-04-07T02:20:32.742505037Z","rtype":160,"publisher_id":101,"instrument_id":436},"action":"C","side":"A","price":"1.156500000","size":20,"channel_id":23,"order_id":"1775528409598450385","flags":128,"ts_in_delta":786,"sequence":157431,"symbol":"FCEU SI 20260615 PS"}
{"ts_recv":"2026-04-07T02:20:32.746977679Z","hd":{"ts_event":"2026-04-07T02:20:32.746957523Z","rtype":160,"publisher_id":101,"instrument_id":436},"action":"C","side":"B","price":"1.156350000","size":30,"channel_id":23,"order_id":"10998900469597116712","flags":0,"ts_in_delta":955,"sequence":157440,"symbol":"FCEU SI 20260615 PS"}
{"ts_recv":"2026-04-07T02:20:32.746977679Z","hd":{"ts_event":"2026-04-07T02:20:32.746957523Z","rtype":160,"publisher_id":101,"instrument_id":436},"action":"A","side":"B","price":"1.156360000","size":30,"channel_id":23,"order_id":"10998900469601738999","flags":0,"ts_in_delta":955,"sequence":157440,"symbol":"FCEU SI 20260615 PS"}
{"ts_recv":"2026-04-07T02:20:32.746977679Z","hd":{"ts_event":"2026-04-07T02:20:32.746957523Z","rtype":160,"publisher_id":101,"instrument_id":436},"action":"C","side":"A","price":"1.156450000","size":30,"channel_id":23,"order_id":"1775528432742340904","flags":0,"ts_in_delta":955,"sequence":157440,"symbol":"FCEU SI 20260615 PS"}
{"ts_recv":"2026-04-07T02:20:32.746977679Z","hd":{"ts_event":"2026-04-07T02:20:32.746957523Z","rtype":160,"publisher_id":101,"instrument_id":436},"action":"A","side":"A","price":"1.156460000","size":30,"channel_id":23,"order_id":"1775528432746963191","flags":128,"ts_in_delta":955,"sequence":157440,"symbol":"FCEU SI 20260615 PS"}
{"ts_recv":"2026-04-07T02:20:32.779372486Z","hd":{"ts_event":"2026-04-07T02:20:32.779352795Z","rtype":160,"publisher_id":101,"instrument_id":436},"action":"C","side":"B","price":"1.156350000","size":30,"channel_id":23,"order_id":"10998900469597083057","flags":0,"ts_in_delta":861,"sequence":157451,"symbol":"FCEU SI 20260615 PS"}
{"ts_recv":"2026-04-07T02:20:32.779372486Z","hd":{"ts_event":"2026-04-07T02:20:32.779352795Z","rtype":160,"publisher_id":101,"instrument_id":436},"action":"A","side":"B","price":"1.156370000","size":30,"channel_id":23,"order_id":"10998900469634135084","flags":0,"ts_in_delta":861,"sequence":157451,"symbol":"FCEU SI 20260615 PS"}
{"ts_recv":"2026-04-07T02:20:32.779372486Z","hd":{"ts_event":"2026-04-07T02:20:32.779352795Z","rtype":160,"publisher_id":101,"instrument_id":436},"action":"C","side":"A","price":"1.156450000","size":30,"channel_id":23,"order_id":"1775528432742307249","flags":0,"ts_in_delta":861,"sequence":157451,"symbol":"FCEU SI 20260615 PS"}
{"ts_recv":"2026-04-07T02:20:32.779372486Z","hd":{"ts_event":"2026-04-07T02:20:32.779352795Z","rtype":160,"publisher_id":101,"instrument_id":436},"action":"A","side":"A","price":"1.156470000","size":30,"channel_id":23,"order_id":"1775528432779359276","flags":128,"ts_in_delta":861,"sequence":157451,"symbol":"FCEU SI 20260615 PS"}
{"ts_recv":"2026-04-07T02:20:32.779435251Z","hd":{"ts_event":"2026-04-07T02:20:32.779417539Z","rtype":160,"publisher_id":101,"instrument_id":436},"action":"C","side":"B","price":"1.156360000","size":30,"channel_id":23,"order_id":"10998900469601738999","flags":0,"ts_in_delta":926,"sequence":157452,"symbol":"FCEU SI 20260615 PS"}
{"ts_recv":"2026-04-07T02:20:32.779435251Z","hd":{"ts_event":"2026-04-07T02:20:32.779417539Z","rtype":160,"publisher_id":101,"instrument_id":436},"action":"A","side":"B","price":"1.156370000","size":30,"channel_id":23,"order_id":"10998900469634199303","flags":0,"ts_in_delta":926,"sequence":157452,"symbol":"FCEU SI 20260615 PS"}
{"ts_recv":"2026-04-07T02:20:32.779435251Z","hd":{"ts_event":"2026-04-07T02:20:32.779417539Z","rtype":160,"publisher_id":101,"instrument_id":436},"action":"C","side":"A","price":"1.156460000","size":30,"channel_id":23,"order_id":"1775528432746963191","flags":0,"ts_in_delta":926,"sequence":157452,"symbol":"FCEU SI 20260615 PS"}
{"ts_recv":"2026-04-07T02:20:32.779435251Z","hd":{"ts_event":"2026-04-07T02:20:32.779417539Z","rtype":160,"publisher_id":101,"instrument_id":436},"action":"A","side":"A","price":"1.156470000","size":30,"channel_id":23,"order_id":"1775528432779423495","flags":128,"ts_in_delta":926,"sequence":157452,"symbol":"FCEU SI 20260615 PS"}
{"ts_recv":"2026-04-07T02:20:32.785903244Z","hd":{"ts_event":"2026-04-07T02:20:32.785889811Z","rtype":160,"publisher_id":101,"instrument_id":436},"action":"A","side":"A","price":"1.156700000","size":20,"channel_id":23,"order_id":"1775528432785896201","flags":128,"ts_in_delta":835,"sequence":157454,"symbol":"FCEU SI 20260615 PS"}
{"ts_recv":"2026-04-07T02:20:33.150606547Z","hd":{"ts_event":"2026-04-07T02:20:33.150586703Z","rtype":160,"publisher_id":101,"instrument_id":436},"action":"C","side":"B","price":"1.156370000","size":30,"channel_id":23,"order_id":"10998900469634199303","flags":0,"ts_in_delta":914,"sequence":157491,"symbol":"FCEU SI 20260615 PS"}
{"ts_recv":"2026-04-07T02:20:33.150606547Z","hd":{"ts_event":"2026-04-07T02:20:33.150586703Z","rtype":160,"publisher_id":101,"instrument_id":436},"action":"A","side":"B","price":"1.156380000","size":30,"channel_id":23,"order_id":"10998900470005368432","flags":0,"ts_in_delta":914,"sequence":157491,"symbol":"FCEU SI 20260615 PS"}
{"ts_recv":"2026-04-07T02:20:33.150606547Z","hd":{"ts_event":"2026-04-07T02:20:33.150586703Z","rtype":160,"publisher_id":101,"instrument_id":436},"action":"C","side":"A","price":"1.156470000","size":30,"channel_id":23,"order_id":"1775528432779423495","flags":0,"ts_in_delta":914,"sequence":157491,"symbol":"FCEU SI 20260615 PS"}
{"ts_recv":"2026-04-07T02:20:33.150606547Z","hd":{"ts_event":"2026-04-07T02:20:33.150586703Z","rtype":160,"publisher_id":101,"instrument_id":436},"action":"A","side":"A","price":"1.156480000","size":30,"channel_id":23,"order_id":"1775528433150592624","flags":128,"ts_in_delta":914,"sequence":157491,"symbol":"FCEU SI 20260615 PS"}
{"ts_recv":"2026-04-07T02:20:33.278990249Z","hd":{"ts_event":"2026-04-07T02:20:33.278961231Z","rtype":160,"publisher_id":101,"instrument_id":436},"action":"C","side":"B","price":"1.156370000","size":30,"channel_id":23,"order_id":"10998900469634135084","flags":0,"ts_in_delta":1295,"sequence":157502,"symbol":"FCEU SI 20260615 PS"}
{"ts_recv":"2026-04-07T02:20:33.278990249Z","hd":{"ts_event":"2026-04-07T02:20:33.278961231Z","rtype":160,"publisher_id":101,"instrument_id":436},"action":"A","side":"B","price":"1.156390000","size":30,"channel_id":23,"order_id":"10998900470133748623","flags":0,"ts_in_delta":1295,"sequence":157502,"symbol":"FCEU SI 20260615 PS"}
{"ts_recv":"2026-04-07T02:20:33.278990249Z","hd":{"ts_event":"2026-04-07T02:20:33.278961231Z","rtype":160,"publisher_id":101,"instrument_id":436},"action":"C","side":"A","price":"1.156470000","size":30,"channel_id":23,"order_id":"1775528432779359276","flags":0,"ts_in_delta":1295,"sequence":157502,"symbol":"FCEU SI 20260615 PS"}
{"ts_recv":"2026-04-07T02:20:33.278990249Z","hd":{"ts_event":"2026-04-07T02:20:33.278961231Z","rtype":160,"publisher_id":101,"instrument_id":436},"action":"A","side":"A","price":"1.156490000","size":30,"channel_id":23,"order_id":"1775528433278972815","flags":128,"ts_in_delta":1295,"sequence":157502,"symbol":"FCEU SI 20260615 PS"}
{"ts_recv":"2026-04-07T02:20:33.279072222Z","hd":{"ts_event":"2026-04-07T02:20:33.279056201Z","rtype":160,"publisher_id":101,"instrument_id":436},"action":"C","side":"B","price":"1.156380000","size":30,"channel_id":23,"order_id":"10998900470005368432","flags":0,"ts_in_delta":1147,"sequence":157503,"symbol":"FCEU SI 20260615 PS"}
{"ts_recv":"2026-04-07T02:20:33.279072222Z","hd":{"ts_event":"2026-04-07T02:20:33.279056201Z","rtype":160,"publisher_id":101,"instrument_id":436},"action":"A","side":"B","price":"1.156390000","size":30,"channel_id":23,"order_id":"10998900470133837830","flags":0,"ts_in_delta":1147,"sequence":157503,"symbol":"FCEU SI 20260615 PS"}
{"ts_recv":"2026-04-07T02:20:33.279072222Z","hd":{"ts_event":"2026-04-07T02:20:33.279056201Z","rtype":160,"publisher_id":101,"instrument_id":436},"action":"C","side":"A","price":"1.156480000","size":30,"channel_id":23,"order_id":"1775528433150592624","flags":0,"ts_in_delta":1147,"sequence":157503,"symbol":"FCEU SI 20260615 PS"}
{"ts_recv":"2026-04-07T02:20:33.279072222Z","hd":{"ts_event":"2026-04-07T02:20:33.279056201Z","rtype":160,"publisher_id":101,"instrument_id":436},"action":"A","side":"A","price":"1.156490000","size":30,"channel_id":23,"order_id":"1775528433279062022","flags":128,"ts_in_delta":1147,"sequence":157503,"symbol":"FCEU SI 20260615 PS"}
{"ts_recv":"2026-04-07T02:20:33.955992056Z","hd":{"ts_event":"2026-04-07T02:20:33.955973637Z","rtype":160,"publisher_id":101,"instrument_id":436},"action":"C","side":"B","price":"1.156390000","size":30,"channel_id":23,"order_id":"10998900470133837830","flags":0,"ts_in_delta":1086,"sequence":157528,"symbol":"FCEU SI 20260615 PS"}
{"ts_recv":"2026-04-07T02:20:33.955992056Z","hd":{"ts_event":"2026-04-07T02:20:33.955973637Z","rtype":160,"publisher_id":101,"instrument_id":436},"action":"A","side":"B","price":"1.156400000","size":30,"channel_id":23,"order_id":"10998900470810755232","flags":0,"ts_in_delta":1086,"sequence":157528,"symbol":"FCEU SI 20260615 PS"}
{"ts_recv":"2026-04-07T02:20:33.955992056Z","hd":{"ts_event":"2026-04-07T02:20:33.955973637Z","rtype":160,"publisher_id":101,"instrument_id":436},"action":"C","side":"A","price":"1.156490000","size":30,"channel_id":23,"order_id":"1775528433279062022","flags":0,"ts_in_delta":1086,"sequence":157528,"symbol":"FCEU SI 20260615 PS"}
{"ts_recv":"2026-04-07T02:20:33.955992056Z","hd":{"ts_event":"2026-04-07T02:20:33.955973637Z","rtype":160,"publisher_id":101,"instrument_id":436},"action":"A","side":"A","price":"1.156500000","size":30,"channel_id":23,"order_id":"1775528433955979424","flags":128,"ts_in_delta":1086,"sequence":157528,"symbol":"FCEU SI 20260615 PS"}
{"ts_recv":"2026-04-07T02:20:33.956045338Z","hd":{"ts_event":"2026-04-07T02:20:33.956026891Z","rtype":160,"publisher_id":101,"instrument_id":436},"action":"C","side":"B","price":"1.156390000","size":30,"channel_id":23,"order_id":"10998900470133748623","flags":0,"ts_in_delta":1072,"sequence":157529,"symbol":"FCEU SI 20260615 PS"}
{"ts_recv":"2026-04-07T02:20:33.956045338Z","hd":{"ts_event":"2026-04-07T02:20:33.956026891Z","rtype":160,"publisher_id":101,"instrument_id":436},"action":"A","side":"B","price":"1.156410000","size":30,"channel_id":23,"order_id":"10998900470810808693","flags":0,"ts_in_delta":1072,"sequence":157529,"symbol":"FCEU SI 20260615 PS"}
{"ts_recv":"2026-04-07T02:20:33.956045338Z","hd":{"ts_event":"2026-04-07T02:20:33.956026891Z","rtype":160,"publisher_id":101,"instrument_id":436},"action":"C","side":"A","price":"1.156490000","size":30,"channel_id":23,"order_id":"1775528433278972815","flags":0,"ts_in_delta":1072,"sequence":157529,"symbol":"FCEU SI 20260615 PS"}
{"ts_recv":"2026-04-07T02:20:33.956045338Z","hd":{"ts_event":"2026-04-07T02:20:33.956026891Z","rtype":160,"publisher_id":101,"instrument_id":436},"action":"A","side":"A","price":"1.156510000","size":30,"channel_id":23,"order_id":"1775528433956032885","flags":128,"ts_in_delta":1072,"sequence":157529,"symbol":"FCEU SI 20260615 PS"}
{"ts_recv":"2026-04-07T02:20:33.956068991Z","hd":{"ts_event":"2026-04-07T02:20:33.956053549Z","rtype":160,"publisher_id":101,"instrument_id":436},"action":"C","side":"B","price":"1.156400000","size":30,"channel_id":23,"order_id":"10998900470810755232","flags":0,"ts_in_delta":888,"sequence":157530,"symbol":"FCEU SI 20260615 PS"}
{"ts_recv":"2026-04-07T02:20:33.956068991Z","hd":{"ts_event":"2026-04-07T02:20:33.956053549Z","rtype":160,"publisher_id":101,"instrument_id":436},"action":"A","side":"B","price":"1.156410000","size":30,"channel_id":23,"order_id":"10998900470810835303","flags":0,"ts_in_delta":888,"sequence":157530,"symbol":"FCEU SI 20260615 PS"}
{"ts_recv":"2026-04-07T02:20:33.956068991Z","hd":{"ts_event":"2026-04-07T02:20:33.956053549Z","rtype":160,"publisher_id":101,"instrument_id":436},"action":"C","side":"A","price":"1.156500000","size":30,"channel_id":23,"order_id":"1775528433955979424","flags":0,"ts_in_delta":888,"sequence":157530,"symbol":"FCEU SI 20260615 PS"}
{"ts_recv":"2026-04-07T02:20:33.956068991Z","hd":{"ts_event":"2026-04-07T02:20:33.956053549Z","rtype":160,"publisher_id":101,"instrument_id":436},"action":"A","side":"A","price":"1.156510000","size":30,"channel_id":23,"order_id":"1775528433956059495","flags":128,"ts_in_delta":888,"sequence":157530,"symbol":"FCEU SI 20260615 PS"}
{"ts_recv":"2026-04-07T02:20:33.980716228Z","hd":{"ts_event":"2026-04-07T02:20:33.980695745Z","rtype":160,"publisher_id":101,"instrument_id":436},"action":"C","side":"B","price":"1.156410000","size":30,"channel_id":23,"order_id":"10998900470810835303","flags":0,"ts_in_delta":909,"sequence":157535,"symbol":"FCEU SI 20260615 PS"}
{"ts_recv":"2026-04-07T02:20:33.980716228Z","hd":{"ts_event":"2026-04-07T02:20:33.980695745Z","rtype":160,"publisher_id":101,"instrument_id":436},"action":"A","side":"B","price":"1.156420000","size":30,"channel_id":23,"order_id":"10998900470835477471","flags":0,"ts_in_delta":909,"sequence":157535,"symbol":"FCEU SI 20260615 PS"}
{"ts_recv":"2026-04-07T02:20:33.980716228Z","hd":{"ts_event":"2026-04-07T02:20:33.980695745Z","rtype":160,"publisher_id":101,"instrument_id":436},"action":"C","side":"A","price":"1.156510000","size":30,"channel_id":23,"order_id":"1775528433956059495","flags":0,"ts_in_delta":909,"sequence":157535,"symbol":"FCEU SI 20260615 PS"}
{"ts_recv":"2026-04-07T02:20:33.980716228Z","hd":{"ts_event":"2026-04-07T02:20:33.980695745Z","rtype":160,"publisher_id":101,"instrument_id":436},"action":"A","side":"A","price":"1.156520000","size":30,"channel_id":23,"order_id":"1775528433980701663","flags":128,"ts_in_delta":909,"sequence":157535,"symbol":"FCEU SI 20260615 PS"}
{"ts_recv":"2026-04-07T02:20:33.980766936Z","hd":{"ts_event":"2026-04-07T02:20:33.980747613Z","rtype":160,"publisher_id":101,"instrument_id":436},"action":"C","side":"B","price":"1.156410000","size":30,"channel_id":23,"order_id":"10998900470810808693","flags":0,"ts_in_delta":912,"sequence":157536,"symbol":"FCEU SI 20260615 PS"}
{"ts_recv":"2026-04-07T02:20:33.980766936Z","hd":{"ts_event":"2026-04-07T02:20:33.980747613Z","rtype":160,"publisher_id":101,"instrument_id":436},"action":"A","side":"B","price":"1.156430000","size":30,"channel_id":23,"order_id":"10998900470835529425","flags":0,"ts_in_delta":912,"sequence":157536,"symbol":"FCEU SI 20260615 PS"}
{"ts_recv":"2026-04-07T02:20:33.980766936Z","hd":{"ts_event":"2026-04-07T02:20:33.980747613Z","rtype":160,"publisher_id":101,"instrument_id":436},"action":"C","side":"A","price":"1.156510000","size":30,"channel_id":23,"order_id":"1775528433956032885","flags":0,"ts_in_delta":912,"sequence":157536,"symbol":"FCEU SI 20260615 PS"}
{"ts_recv":"2026-04-07T02:20:33.980766936Z","hd":{"ts_event":"2026-04-07T02:20:33.980747613Z","rtype":160,"publisher_id":101,"instrument_id":436},"action":"A","side":"A","price":"1.156530000","size":30,"channel_id":23,"order_id":"1775528433980753617","flags":128,"ts_in_delta":912,"sequence":157536,"symbol":"FCEU SI 20260615 PS"}
{"ts_recv":"2026-04-07T02:20:33.980780168Z","hd":{"ts_event":"2026-04-07T02:20:33.980762005Z","rtype":160,"publisher_id":101,"instrument_id":436},"action":"C","side":"B","price":"1.156420000","size":30,"channel_id":23,"order_id":"10998900470835477471","flags":0,"ts_in_delta":916,"sequence":157537,"symbol":"FCEU SI 20260615 PS"}
{"ts_recv":"2026-04-07T02:20:33.980780168Z","hd":{"ts_event":"2026-04-07T02:20:33.980762005Z","rtype":160,"publisher_id":101,"instrument_id":436},"action":"A","side":"B","price":"1.156430000","size":30,"channel_id":23,"order_id":"10998900470835543362","flags":0,"ts_in_delta":916,"sequence":157537,"symbol":"FCEU SI 20260615 PS"}
{"ts_recv":"2026-04-07T02:20:33.980780168Z","hd":{"ts_event":"2026-04-07T02:20:33.980762005Z","rtype":160,"publisher_id":101,"instrument_id":436},"action":"C","side":"A","price":"1.156520000","size":30,"channel_id":23,"order_id":"1775528433980701663","flags":0,"ts_in_delta":916,"sequence":157537,"symbol":"FCEU SI 20260615 PS"}
{"ts_recv":"2026-04-07T02:20:33.980780168Z","hd":{"ts_event":"2026-04-07T02:20:33.980762005Z","rtype":160,"publisher_id":101,"instrument_id":436},"action":"A","side":"A","price":"1.156530000","size":30,"channel_id":23,"order_id":"1775528433980767554","flags":128,"ts_in_delta":916,"sequence":157537,"symbol":"FCEU SI 20260615 PS"}
{"ts_recv":"2026-04-07T02:20:33.997575273Z","hd":{"ts_event":"2026-04-07T02:20:33.997563033Z","rtype":160,"publisher_id":101,"instrument_id":436},"action":"A","side":"B","price":"1.156300000","size":20,"channel_id":23,"order_id":"10998900470852344791","flags":128,"ts_in_delta":835,"sequence":157543,"symbol":"FCEU SI 20260615 PS"}
{"ts_recv":"2026-04-07T02:20:33.997869250Z","hd":{"ts_event":"2026-04-07T02:20:33.997855655Z","rtype":160,"publisher_id":101,"instrument_id":436},"action":"C","side":"B","price":"1.156200000","size":20,"channel_id":23,"order_id":"10998900048417480289","flags":128,"ts_in_delta":660,"sequence":157544,"symbol":"FCEU SI 20260615 PS"}
{"ts_recv":"2026-04-07T02:20:34.374175082Z","hd":{"ts_event":"2026-04-07T02:20:34.374155893Z","rtype":160,"publisher_id":101,"instrument_id":436},"action":"C","side":"B","price":"1.156430000","size":30,"channel_id":23,"order_id":"10998900470835543362","flags":0,"ts_in_delta":1090,"sequence":157577,"symbol":"FCEU SI 20260615 PS"}
{"ts_recv":"2026-04-07T02:20:34.374175082Z","hd":{"ts_event":"2026-04-07T02:20:34.374155893Z","rtype":160,"publisher_id":101,"instrument_id":436},"action":"A","side":"B","price":"1.156440000","size":30,"channel_id":23,"order_id":"10998900471228937637","flags":0,"ts_in_delta":1090,"sequence":157577,"symbol":"FCEU SI 20260615 PS"}
{"ts_recv":"2026-04-07T02:20:34.374175082Z","hd":{"ts_event":"2026-04-07T02:20:34.374155893Z","rtype":160,"publisher_id":101,"instrument_id":436},"action":"C","side":"A","price":"1.156530000","size":30,"channel_id":23,"order_id":"1775528433980767554","flags":0,"ts_in_delta":1090,"sequence":157577,"symbol":"FCEU SI 20260615 PS"}
{"ts_recv":"2026-04-07T02:20:34.374175082Z","hd":{"ts_event":"2026-04-07T02:20:34.374155893Z","rtype":160,"publisher_id":101,"instrument_id":436},"action":"A","side":"A","price":"1.156540000","size":30,"channel_id":23,"order_id":"1775528434374161829","flags":128,"ts_in_delta":1090,"sequence":157577,"symbol":"FCEU SI 20260615 PS"}
{"ts_recv":"2026-04-07T02:20:34.510889980Z","hd":{"ts_event":"2026-04-07T02:20:34.510869105Z","rtype":160,"publisher_id":101,"instrument_id":436},"action":"C","side":"B","price":"1.156430000","size":30,"channel_id":23,"order_id":"10998900470835529425","flags":0,"ts_in_delta":1474,"sequence":157597,"symbol":"FCEU SI 20260615 PS"}
{"ts_recv":"2026-04-07T02:20:34.510889980Z","hd":{"ts_event":"2026-04-07T02:20:34.510869105Z","rtype":160,"publisher_id":101,"instrument_id":436},"action":"A","side":"B","price":"1.156450000","size":30,"channel_id":23,"order_id":"10998900471365650609","flags":0,"ts_in_delta":1474,"sequence":157597,"symbol":"FCEU SI 20260615 PS"}
{"ts_recv":"2026-04-07T02:20:34.510889980Z","hd":{"ts_event":"2026-04-07T02:20:34.510869105Z","rtype":160,"publisher_id":101,"instrument_id":436},"action":"C","side":"A","price":"1.156530000","size":30,"channel_id":23,"order_id":"1775528433980753617","flags":0,"ts_in_delta":1474,"sequence":157597,"symbol":"FCEU SI 20260615 PS"}
{"ts_recv":"2026-04-07T02:20:34.510889980Z","hd":{"ts_event":"2026-04-07T02:20:34.510869105Z","rtype":160,"publisher_id":101,"instrument_id":436},"action":"A","side":"A","price":"1.156550000","size":30,"channel_id":23,"order_id":"1775528434510874801","flags":128,"ts_in_delta":1474,"sequence":157597,"symbol":"FCEU SI 20260615 PS"}
{"ts_recv":"2026-04-07T02:20:34.510954320Z","hd":{"ts_event":"2026-04-07T02:20:34.510937133Z","rtype":160,"publisher_id":101,"instrument_id":436},"action":"C","side":"B","price":"1.156440000","size":30,"channel_id":23,"order_id":"10998900471228937637","flags":0,"ts_in_delta":882,"sequence":157598,"symbol":"FCEU SI 20260615 PS"}
{"ts_recv":"2026-04-07T02:20:34.510954320Z","hd":{"ts_event":"2026-04-07T02:20:34.510937133Z","rtype":160,"publisher_id":101,"instrument_id":436},"action":"A","side":"B","price":"1.156450000","size":30,"channel_id":23,"order_id":"10998900471365718982","flags":0,"ts_in_delta":882,"sequence":157598,"symbol":"FCEU SI 20260615 PS"}
{"ts_recv":"2026-04-07T02:20:34.510954320Z","hd":{"ts_event":"2026-04-07T02:20:34.510937133Z","rtype":160,"publisher_id":101,"instrument_id":436},"action":"C","side":"A","price":"1.156540000","size":30,"channel_id":23,"order_id":"1775528434374161829","flags":0,"ts_in_delta":882,"sequence":157598,"symbol":"FCEU SI 20260615 PS"}
{"ts_recv":"2026-04-07T02:20:34.510954320Z","hd":{"ts_event":"2026-04-07T02:20:34.510937133Z","rtype":160,"publisher_id":101,"instrument_id":436},"action":"A","side":"A","price":"1.156550000","size":30,"channel_id":23,"order_id":"1775528434510943174","flags":128,"ts_in_delta":882,"sequence":157598,"symbol":"FCEU SI 20260615 PS"}
{"ts_recv":"2026-04-07T02:20:35.239865174Z","hd":{"ts_event":"2026-04-07T02:20:35.239840673Z","rtype":160,"publisher_id":101,"instrument_id":436},"action":"C","side":"B","price":"1.156450000","size":30,"channel_id":23,"order_id":"10998900471365718982","flags":0,"ts_in_delta":1167,"sequence":157622,"symbol":"FCEU SI 20260615 PS"}
{"ts_recv":"2026-04-07T02:20:35.239865174Z","hd":{"ts_event":"2026-04-07T02:20:35.239840673Z","rtype":160,"publisher_id":101,"instrument_id":436},"action":"A","side":"B","price":"1.156460000","size":30,"channel_id":23,"order_id":"10998900472094624771","flags":0,"ts_in_delta":1167,"sequence":157622,"symbol":"FCEU SI 20260615 PS"}
{"ts_recv":"2026-04-07T02:20:35.239865174Z","hd":{"ts_event":"2026-04-07T02:20:35.239840673Z","rtype":160,"publisher_id":101,"instrument_id":436},"action":"C","side":"A","price":"1.156550000","size":30,"channel_id":23,"order_id":"1775528434510943174","flags":0,"ts_in_delta":1167,"sequence":157622,"symbol":"FCEU SI 20260615 PS"}
{"ts_recv":"2026-04-07T02:20:35.239865174Z","hd":{"ts_event":"2026-04-07T02:20:35.239840673Z","rtype":160,"publisher_id":101,"instrument_id":436},"action":"A","side":"A","price":"1.156560000","size":30,"channel_id":23,"order_id":"1775528435239848963","flags":128,"ts_in_delta":1167,"sequence":157622,"symbol":"FCEU SI 20260615 PS"}
{"ts_recv":"2026-04-07T02:20:40.863601517Z","hd":{"ts_event":"2026-04-07T02:20:40.863572717Z","rtype":160,"publisher_id":101,"instrument_id":436},"action":"C","side":"B","price":"1.156460000","size":30,"channel_id":23,"order_id":"10998900472094624771","flags":0,"ts_in_delta":1187,"sequence":157657,"symbol":"FCEU SI 20260615 PS"}
{"ts_recv":"2026-04-07T02:20:40.863601517Z","hd":{"ts_event":"2026-04-07T02:20:40.863572717Z","rtype":160,"publisher_id":101,"instrument_id":436},"action":"A","side":"B","price":"1.156450000","size":30,"channel_id":23,"order_id":"10998900477718361740","flags":0,"ts_in_delta":1187,"sequence":157657,"symbol":"FCEU SI 20260615 PS"}
{"ts_recv":"2026-04-07T02:20:40.863601517Z","hd":{"ts_event":"2026-04-07T02:20:40.863572717Z","rtype":160,"publisher_id":101,"instrument_id":436},"action":"C","side":"A","price":"1.156560000","size":30,"channel_id":23,"order_id":"1775528435239848963","flags":0,"ts_in_delta":1187,"sequence":157657,"symbol":"FCEU SI 20260615 PS"}
{"ts_recv":"2026-04-07T02:20:40.863601517Z","hd":{"ts_event":"2026-04-07T02:20:40.863572717Z","rtype":160,"publisher_id":101,"instrument_id":436},"action":"A","side":"A","price":"1.156550000","size":30,"channel_id":23,"order_id":"1775528440863585932","flags":128,"ts_in_delta":1187,"sequence":157657,"symbol":"FCEU SI 20260615 PS"}
{"ts_recv":"2026-04-07T02:20:43.228188178Z","hd":{"ts_event":"2026-04-07T02:20:43.228167565Z","rtype":160,"publisher_id":101,"instrument_id":436},"action":"C","side":"B","price":"1.156450000","size":30,"channel_id":23,"order_id":"10998900477718361740","flags":0,"ts_in_delta":920,"sequence":157712,"symbol":"FCEU SI 20260615 PS"}
{"ts_recv":"2026-04-07T02:20:43.228188178Z","hd":{"ts_event":"2026-04-07T02:20:43.228167565Z","rtype":160,"publisher_id":101,"instrument_id":436},"action":"A","side":"B","price":"1.156460000","size":30,"channel_id":23,"order_id":"10998900480082949159","flags":0,"ts_in_delta":920,"sequence":157712,"symbol":"FCEU SI 20260615 PS"}
{"ts_recv":"2026-04-07T02:20:43.228188178Z","hd":{"ts_event":"2026-04-07T02:20:43.228167565Z","rtype":160,"publisher_id":101,"instrument_id":436},"action":"C","side":"A","price":"1.156550000","size":30,"channel_id":23,"order_id":"1775528440863585932","flags":0,"ts_in_delta":920,"sequence":157712,"symbol":"FCEU SI 20260615 PS"}
{"ts_recv":"2026-04-07T02:20:43.228188178Z","hd":{"ts_event":"2026-04-07T02:20:43.228167565Z","rtype":160,"publisher_id":101,"instrument_id":436},"action":"A","side":"A","price":"1.156560000","size":30,"channel_id":23,"order_id":"1775528443228173351","flags":128,"ts_in_delta":920,"sequence":157712,"symbol":"FCEU SI 20260615 PS"}
{"ts_recv":"2026-04-07T02:20:44.090660612Z","hd":{"ts_event":"2026-04-07T02:20:44.090639021Z","rtype":160,"publisher_id":101,"instrument_id":436},"action":"C","side":"B","price":"1.156460000","size":30,"channel_id":23,"order_id":"10998900480082949159","flags":0,"ts_in_delta":960,"sequence":157742,"symbol":"FCEU SI 20260615 PS"}
{"ts_recv":"2026-04-07T02:20:44.090660612Z","hd":{"ts_event":"2026-04-07T02:20:44.090639021Z","rtype":160,"publisher_id":101,"instrument_id":436},"action":"A","side":"B","price":"1.156470000","size":30,"channel_id":23,"order_id":"10998900480945420797","flags":0,"ts_in_delta":960,"sequence":157742,"symbol":"FCEU SI 20260615 PS"}
{"ts_recv":"2026-04-07T02:20:44.090660612Z","hd":{"ts_event":"2026-04-07T02:20:44.090639021Z","rtype":160,"publisher_id":101,"instrument_id":436},"action":"C","side":"A","price":"1.156560000","size":30,"channel_id":23,"order_id":"1775528443228173351","flags":0,"ts_in_delta":960,"sequence":157742,"symbol":"FCEU SI 20260615 PS"}
{"ts_recv":"2026-04-07T02:20:44.090660612Z","hd":{"ts_event":"2026-04-07T02:20:44.090639021Z","rtype":160,"publisher_id":101,"instrument_id":436},"action":"A","side":"A","price":"1.156570000","size":30,"channel_id":23,"order_id":"1775528444090644989","flags":128,"ts_in_delta":960,"sequence":157742,"symbol":"FCEU SI 20260615 PS"}
{"ts_recv":"2026-04-07T02:20:44.090754911Z","hd":{"ts_event":"2026-04-07T02:20:44.090736233Z","rtype":160,"publisher_id":101,"instrument_id":436},"action":"C","side":"B","price":"1.156470000","size":30,"channel_id":23,"order_id":"10998900480945420797","flags":0,"ts_in_delta":931,"sequence":157743,"symbol":"FCEU SI 20260615 PS"}
{"ts_recv":"2026-04-07T02:20:44.090754911Z","hd":{"ts_event":"2026-04-07T02:20:44.090736233Z","rtype":160,"publisher_id":101,"instrument_id":436},"action":"A","side":"B","price":"1.156460000","size":30,"channel_id":23,"order_id":"10998900480945517692","flags":0,"ts_in_delta":931,"sequence":157743,"symbol":"FCEU SI 20260615 PS"}
{"ts_recv":"2026-04-07T02:20:44.090754911Z","hd":{"ts_event":"2026-04-07T02:20:44.090736233Z","rtype":160,"publisher_id":101,"instrument_id":436},"action":"C","side":"A","price":"1.156570000","size":30,"channel_id":23,"order_id":"1775528444090644989","flags":0,"ts_in_delta":931,"sequence":157743,"symbol":"FCEU SI 20260615 PS"}
{"ts_recv":"2026-04-07T02:20:44.090754911Z","hd":{"ts_event":"2026-04-07T02:20:44.090736233Z","rtype":160,"publisher_id":101,"instrument_id":436},"action":"A","side":"A","price":"1.156560000","size":30,"channel_id":23,"order_id":"1775528444090741884","flags":128,"ts_in_delta":931,"sequence":157743,"symbol":"FCEU SI 20260615 PS"}
{"ts_recv":"2026-04-07T02:20:45.012758600Z","hd":{"ts_event":"2026-04-07T02:20:45.012729453Z","rtype":160,"publisher_id":101,"instrument_id":436},"action":"C","side":"B","price":"1.156450000","size":30,"channel_id":23,"order_id":"10998900471365650609","flags":0,"ts_in_delta":1457,"sequence":157754,"symbol":"FCEU SI 20260615 PS"}
{"ts_recv":"2026-04-07T02:20:45.012758600Z","hd":{"ts_event":"2026-04-07T02:20:45.012729453Z","rtype":160,"publisher_id":101,"instrument_id":436},"action":"A","side":"B","price":"1.156480000","size":30,"channel_id":23,"order_id":"10998900481867516718","flags":0,"ts_in_delta":1457,"sequence":157754,"symbol":"FCEU SI 20260615 PS"}
{"ts_recv":"2026-04-07T02:20:45.012758600Z","hd":{"ts_event":"2026-04-07T02:20:45.012729453Z","rtype":160,"publisher_id":101,"instrument_id":436},"action":"C","side":"A","price":"1.156550000","size":30,"channel_id":23,"order_id":"1775528434510874801","flags":0,"ts_in_delta":1457,"sequence":157754,"symbol":"FCEU SI 20260615 PS"}
{"ts_recv":"2026-04-07T02:20:45.012758600Z","hd":{"ts_event":"2026-04-07T02:20:45.012729453Z","rtype":160,"publisher_id":101,"instrument_id":436},"action":"A","side":"A","price":"1.156580000","size":30,"channel_id":23,"order_id":"1775528445012740910","flags":128,"ts_in_delta":1457,"sequence":157754,"symbol":"FCEU SI 20260615 PS"}
{"ts_recv":"2026-04-07T02:20:45.012858713Z","hd":{"ts_event":"2026-04-07T02:20:45.012841755Z","rtype":160,"publisher_id":101,"instrument_id":436},"action":"C","side":"B","price":"1.156460000","size":30,"channel_id":23,"order_id":"10998900480945517692","flags":0,"ts_in_delta":974,"sequence":157755,"symbol":"FCEU SI 20260615 PS"}
{"ts_recv":"2026-04-07T02:20:45.012858713Z","hd":{"ts_event":"2026-04-07T02:20:45.012841755Z","rtype":160,"publisher_id":101,"instrument_id":436},"action":"A","side":"B","price":"1.156480000","size":30,"channel_id":23,"order_id":"10998900481867623932","flags":0,"ts_in_delta":974,"sequence":157755,"symbol":"FCEU SI 20260615 PS"}
{"ts_recv":"2026-04-07T02:20:45.012858713Z","hd":{"ts_event":"2026-04-07T02:20:45.012841755Z","rtype":160,"publisher_id":101,"instrument_id":436},"action":"C","side":"A","price":"1.156560000","size":30,"channel_id":23,"order_id":"1775528444090741884","flags":0,"ts_in_delta":974,"sequence":157755,"symbol":"FCEU SI 20260615 PS"}
{"ts_recv":"2026-04-07T02:20:45.012858713Z","hd":{"ts_event":"2026-04-07T02:20:45.012841755Z","rtype":160,"publisher_id":101,"instrument_id":436},"action":"A","side":"A","price":"1.156580000","size":30,"channel_id":23,"order_id":"1775528445012848124","flags":128,"ts_in_delta":974,"sequence":157755,"symbol":"FCEU SI 20260615 PS"}
{"ts_recv":"2026-04-07T02:20:45.014400218Z","hd":{"ts_event":"2026-04-07T02:20:45.014382021Z","rtype":160,"publisher_id":101,"instrument_id":436},"action":"C","side":"B","price":"1.156480000","size":30,"channel_id":23,"order_id":"10998900481867623932","flags":0,"ts_in_delta":918,"sequence":157758,"symbol":"FCEU SI 20260615 PS"}
{"ts_recv":"2026-04-07T02:20:45.014400218Z","hd":{"ts_event":"2026-04-07T02:20:45.014382021Z","rtype":160,"publisher_id":101,"instrument_id":436},"action":"A","side":"B","price":"1.156490000","size":30,"channel_id":23,"order_id":"10998900481869164036","flags":0,"ts_in_delta":918,"sequence":157758,"symbol":"FCEU SI 20260615 PS"}
{"ts_recv":"2026-04-07T02:20:45.014400218Z","hd":{"ts_event":"2026-04-07T02:20:45.014382021Z","rtype":160,"publisher_id":101,"instrument_id":436},"action":"C","side":"A","price":"1.156580000","size":30,"channel_id":23,"order_id":"1775528445012848124","flags":0,"ts_in_delta":918,"sequence":157758,"symbol":"FCEU SI 20260615 PS"}
{"ts_recv":"2026-04-07T02:20:45.014400218Z","hd":{"ts_event":"2026-04-07T02:20:45.014382021Z","rtype":160,"publisher_id":101,"instrument_id":436},"action":"A","side":"A","price":"1.156590000","size":30,"channel_id":23,"order_id":"1775528445014388228","flags":128,"ts_in_delta":918,"sequence":157758,"symbol":"FCEU SI 20260615 PS"}
{"ts_recv":"2026-04-07T02:20:45.019857298Z","hd":{"ts_event":"2026-04-07T02:20:45.019836521Z","rtype":160,"publisher_id":101,"instrument_id":436},"action":"C","side":"B","price":"1.156480000","size":30,"channel_id":23,"order_id":"10998900481867516718","flags":0,"ts_in_delta":954,"sequence":157760,"symbol":"FCEU SI 20260615 PS"}
{"ts_recv":"2026-04-07T02:20:45.019857298Z","hd":{"ts_event":"2026-04-07T02:20:45.019836521Z","rtype":160,"publisher_id":101,"instrument_id":436},"action":"A","side":"B","price":"1.156500000","size":30,"channel_id":23,"order_id":"10998900481874618164","flags":0,"ts_in_delta":954,"sequence":157760,"symbol":"FCEU SI 20260615 PS"}
{"ts_recv":"2026-04-07T02:20:45.019857298Z","hd":{"ts_event":"2026-04-07T02:20:45.019836521Z","rtype":160,"publisher_id":101,"instrument_id":436},"action":"C","side":"A","price":"1.156580000","size":30,"channel_id":23,"order_id":"1775528445012740910","flags":0,"ts_in_delta":954,"sequence":157760,"symbol":"FCEU SI 20260615 PS"}
{"ts_recv":"2026-04-07T02:20:45.019857298Z","hd":{"ts_event":"2026-04-07T02:20:45.019836521Z","rtype":160,"publisher_id":101,"instrument_id":436},"action":"A","side":"A","price":"1.156600000","size":30,"channel_id":23,"order_id":"1775528445019842356","flags":128,"ts_in_delta":954,"sequence":157760,"symbol":"FCEU SI 20260615 PS"}
{"ts_recv":"2026-04-07T02:20:45.019916339Z","hd":{"ts_event":"2026-04-07T02:20:45.019899023Z","rtype":160,"publisher_id":101,"instrument_id":436},"action":"C","side":"B","price":"1.156490000","size":30,"channel_id":23,"order_id":"10998900481869164036","flags":0,"ts_in_delta":1066,"sequence":157761,"symbol":"FCEU SI 20260615 PS"}
{"ts_recv":"2026-04-07T02:20:45.019916339Z","hd":{"ts_event":"2026-04-07T02:20:45.019899023Z","rtype":160,"publisher_id":101,"instrument_id":436},"action":"A","side":"B","price":"1.156500000","size":30,"channel_id":23,"order_id":"10998900481874680744","flags":0,"ts_in_delta":1066,"sequence":157761,"symbol":"FCEU SI 20260615 PS"}
{"ts_recv":"2026-04-07T02:20:45.019916339Z","hd":{"ts_event":"2026-04-07T02:20:45.019899023Z","rtype":160,"publisher_id":101,"instrument_id":436},"action":"C","side":"A","price":"1.156590000","size":30,"channel_id":23,"order_id":"1775528445014388228","flags":0,"ts_in_delta":1066,"sequence":157761,"symbol":"FCEU SI 20260615 PS"}
{"ts_recv":"2026-04-07T02:20:45.019916339Z","hd":{"ts_event":"2026-04-07T02:20:45.019899023Z","rtype":160,"publisher_id":101,"instrument_id":436},"action":"A","side":"A","price":"1.156600000","size":30,"channel_id":23,"order_id":"1775528445019904936","flags":128,"ts_in_delta":1066,"sequence":157761,"symbol":"FCEU SI 20260615 PS"}
{"ts_recv":"2026-04-07T02:20:45.083518510Z","hd":{"ts_event":"2026-04-07T02:20:45.083498013Z","rtype":160,"publisher_id":101,"instrument_id":436},"action":"C","side":"B","price":"1.156500000","size":30,"channel_id":23,"order_id":"10998900481874680744","flags":0,"ts_in_delta":949,"sequence":157777,"symbol":"FCEU SI 20260615 PS"}
{"ts_recv":"2026-04-07T02:20:45.083518510Z","hd":{"ts_event":"2026-04-07T02:20:45.083498013Z","rtype":160,"publisher_id":101,"instrument_id":436},"action":"A","side":"B","price":"1.156510000","size":30,"channel_id":23,"order_id":"10998900481938279827","flags":0,"ts_in_delta":949,"sequence":157777,"symbol":"FCEU SI 20260615 PS"}
{"ts_recv":"2026-04-07T02:20:45.083518510Z","hd":{"ts_event":"2026-04-07T02:20:45.083498013Z","rtype":160,"publisher_id":101,"instrument_id":436},"action":"C","side":"A","price":"1.156600000","size":30,"channel_id":23,"order_id":"1775528445019904936","flags":0,"ts_in_delta":949,"sequence":157777,"symbol":"FCEU SI 20260615 PS"}
{"ts_recv":"2026-04-07T02:20:45.083518510Z","hd":{"ts_event":"2026-04-07T02:20:45.083498013Z","rtype":160,"publisher_id":101,"instrument_id":436},"action":"A","side":"A","price":"1.156610000","size":30,"channel_id":23,"order_id":"1775528445083504019","flags":128,"ts_in_delta":949,"sequence":157777,"symbol":"FCEU SI 20260615 PS"}
{"ts_recv":"2026-04-07T02:20:45.083571169Z","hd":{"ts_event":"2026-04-07T02:20:45.083551793Z","rtype":160,"publisher_id":101,"instrument_id":436},"action":"C","side":"B","price":"1.156500000","size":30,"channel_id":23,"order_id":"10998900481874618164","flags":0,"ts_in_delta":1042,"sequence":157778,"symbol":"FCEU SI 20260615 PS"}
{"ts_recv":"2026-04-07T02:20:45.083571169Z","hd":{"ts_event":"2026-04-07T02:20:45.083551793Z","rtype":160,"publisher_id":101,"instrument_id":436},"action":"A","side":"B","price":"1.156520000","size":30,"channel_id":23,"order_id":"10998900481938333241","flags":0,"ts_in_delta":1042,"sequence":157778,"symbol":"FCEU SI 20260615 PS"}
{"ts_recv":"2026-04-07T02:20:45.083571169Z","hd":{"ts_event":"2026-04-07T02:20:45.083551793Z","rtype":160,"publisher_id":101,"instrument_id":436},"action":"C","side":"A","price":"1.156600000","size":30,"channel_id":23,"order_id":"1775528445019842356","flags":0,"ts_in_delta":1042,"sequence":157778,"symbol":"FCEU SI 20260615 PS"}
{"ts_recv":"2026-04-07T02:20:45.083571169Z","hd":{"ts_event":"2026-04-07T02:20:45.083551793Z","rtype":160,"publisher_id":101,"instrument_id":436},"action":"A","side":"A","price":"1.156620000","size":30,"channel_id":23,"order_id":"1775528445083557433","flags":128,"ts_in_delta":1042,"sequence":157778,"symbol":"FCEU SI 20260615 PS"}
{"ts_recv":"2026-04-07T02:20:45.083625349Z","hd":{"ts_event":"2026-04-07T02:20:45.083608433Z","rtype":160,"publisher_id":101,"instrument_id":436},"action":"C","side":"B","price":"1.156510000","size":30,"channel_id":23,"order_id":"10998900481938279827","flags":0,"ts_in_delta":959,"sequence":157779,"symbol":"FCEU SI 20260615 PS"}
{"ts_recv":"2026-04-07T02:20:45.083625349Z","hd":{"ts_event":"2026-04-07T02:20:45.083608433Z","rtype":160,"publisher_id":101,"instrument_id":436},"action":"A","side":"B","price":"1.156520000","size":30,"channel_id":23,"order_id":"10998900481938389940","flags":0,"ts_in_delta":959,"sequence":157779,"symbol":"FCEU SI 20260615 PS"}
{"ts_recv":"2026-04-07T02:20:45.083625349Z","hd":{"ts_event":"2026-04-07T02:20:45.083608433Z","rtype":160,"publisher_id":101,"instrument_id":436},"action":"C","side":"A","price":"1.156610000","size":30,"channel_id":23,"order_id":"1775528445083504019","flags":0,"ts_in_delta":959,"sequence":157779,"symbol":"FCEU SI 20260615 PS"}
{"ts_recv":"2026-04-07T02:20:45.083625349Z","hd":{"ts_event":"2026-04-07T02:20:45.083608433Z","rtype":160,"publisher_id":101,"instrument_id":436},"action":"A","side":"A","price":"1.156620000","size":30,"channel_id":23,"order_id":"1775528445083614132","flags":128,"ts_in_delta":959,"sequence":157779,"symbol":"FCEU SI 20260615 PS"}
{"ts_recv":"2026-04-07T02:20:45.094275493Z","hd":{"ts_event":"2026-04-07T02:20:45.094256473Z","rtype":160,"publisher_id":101,"instrument_id":436},"action":"C","side":"B","price":"1.156520000","size":30,"channel_id":23,"order_id":"10998900481938389940","flags":0,"ts_in_delta":960,"sequence":157787,"symbol":"FCEU SI 20260615 PS"}
{"ts_recv":"2026-04-07T02:20:45.094275493Z","hd":{"ts_event":"2026-04-07T02:20:45.094256473Z","rtype":160,"publisher_id":101,"instrument_id":436},"action":"A","side":"B","price":"1.156530000","size":30,"channel_id":23,"order_id":"10998900481949037972","flags":0,"ts_in_delta":960,"sequence":157787,"symbol":"FCEU SI 20260615 PS"}
{"ts_recv":"2026-04-07T02:20:45.094275493Z","hd":{"ts_event":"2026-04-07T02:20:45.094256473Z","rtype":160,"publisher_id":101,"instrument_id":436},"action":"C","side":"A","price":"1.156620000","size":30,"channel_id":23,"order_id":"1775528445083614132","flags":0,"ts_in_delta":960,"sequence":157787,"symbol":"FCEU SI 20260615 PS"}
{"ts_recv":"2026-04-07T02:20:45.094275493Z","hd":{"ts_event":"2026-04-07T02:20:45.094256473Z","rtype":160,"publisher_id":101,"instrument_id":436},"action":"A","side":"A","price":"1.156630000","size":30,"channel_id":23,"order_id":"1775528445094262164","flags":128,"ts_in_delta":960,"sequence":157787,"symbol":"FCEU SI 20260615 PS"}
{"ts_recv":"2026-04-07T02:20:45.121426289Z","hd":{"ts_event":"2026-04-07T02:20:45.121411259Z","rtype":160,"publisher_id":101,"instrument_id":436},"action":"A","side":"B","price":"1.156400000","size":20,"channel_id":23,"order_id":"10998900481976193329","flags":128,"ts_in_delta":612,"sequence":157794,"symbol":"FCEU SI 20260615 PS"}
{"ts_recv":"2026-04-07T02:20:45.121447708Z","hd":{"ts_event":"2026-04-07T02:20:45.121436483Z","rtype":160,"publisher_id":101,"instrument_id":436},"action":"C","side":"B","price":"1.156300000","size":20,"channel_id":23,"order_id":"10998900470852344791","flags":128,"ts_in_delta":766,"sequence":157795,"symbol":"FCEU SI 20260615 PS"}
{"ts_recv":"2026-04-07T02:20:45.683826611Z","hd":{"ts_event":"2026-04-07T02:20:45.683797691Z","rtype":160,"publisher_id":101,"instrument_id":436},"action":"C","side":"B","price":"1.156520000","size":30,"channel_id":23,"order_id":"10998900481938333241","flags":0,"ts_in_delta":1647,"sequence":157816,"symbol":"FCEU SI 20260615 PS"}
{"ts_recv":"2026-04-07T02:20:45.683826611Z","hd":{"ts_event":"2026-04-07T02:20:45.683797691Z","rtype":160,"publisher_id":101,"instrument_id":436},"action":"A","side":"B","price":"1.156540000","size":30,"channel_id":23,"order_id":"10998900482538586690","flags":0,"ts_in_delta":1647,"sequence":157816,"symbol":"FCEU SI 20260615 PS"}
{"ts_recv":"2026-04-07T02:20:45.683826611Z","hd":{"ts_event":"2026-04-07T02:20:45.683797691Z","rtype":160,"publisher_id":101,"instrument_id":436},"action":"C","side":"A","price":"1.156620000","size":30,"channel_id":23,"order_id":"1775528445083557433","flags":0,"ts_in_delta":1647,"sequence":157816,"symbol":"FCEU SI 20260615 PS"}
{"ts_recv":"2026-04-07T02:20:45.683826611Z","hd":{"ts_event":"2026-04-07T02:20:45.683797691Z","rtype":160,"publisher_id":101,"instrument_id":436},"action":"A","side":"A","price":"1.156640000","size":30,"channel_id":23,"order_id":"1775528445683810882","flags":128,"ts_in_delta":1647,"sequence":157816,"symbol":"FCEU SI 20260615 PS"}
