{"ts_recv":"2026-04-07T02:20:45.683896066Z","hd":{"ts_event":"2026-04-07T02:20:45.683879695Z","rtype":160,"publisher_id":101,"instrument_id":436},"action":"C","side":"B","price":"1.156530000","size":30,"channel_id":23,"order_id":"10998900481949037972","flags":0,"ts_in_delta":1126,"sequence":157817,"symbol":"FCEU SI 20260615 PS"}
{"ts_recv":"2026-04-07T02:20:45.683896066Z","hd":{"ts_event":"2026-04-07T02:20:45.683879695Z","rtype":160,"publisher_id":101,"instrument_id":436},"action":"A","side":"B","price":"1.156540000","size":30,"channel_id":23,"order_id":"10998900482538661681","flags":0,"ts_in_delta":1126,"sequence":157817,"symbol":"FCEU SI 20260615 PS"}
{"ts_recv":"2026-04-07T02:20:45.683896066Z","hd":{"ts_event":"2026-04-07T02:20:45.683879695Z","rtype":160,"publisher_id":101,"instrument_id":436},"action":"C","side":"A","price":"1.156630000","size":30,"channel_id":23,"order_id":"1775528445094262164","flags":0,"ts_in_delta":1126,"sequence":157817,"symbol":"FCEU SI 20260615 PS"}
{"ts_recv":"2026-04-07T02:20:45.683896066Z","hd":{"ts_event":"2026-04-07T02:20:45.683879695Z","rtype":160,"publisher_id":101,"instrument_id":436},"action":"A","side":"A","price":"1.156640000","size":30,"channel_id":23,"order_id":"1775528445683885873","flags":128,"ts_in_delta":1126,"sequence":157817,"symbol":"FCEU SI 20260615 PS"}
{"ts_recv":"2026-04-07T02:20:50.256330186Z","hd":{"ts_event":"2026-04-07T02:20:50.256316719Z","rtype":160,"publisher_id":101,"instrument_id":436},"action":"C","side":"A","price":"1.156700000","size":20,"channel_id":23,"order_id":"1775528432785896201","flags":128,"ts_in_delta":862,"sequence":157846,"symbol":"FCEU SI 20260615 PS"}
{"ts_recv":"2026-04-07T02:20:50.259969027Z","hd":{"ts_event":"2026-04-07T02:20:50.259943261Z","rtype":160,"publisher_id":101,"instrument_id":436},"action":"C","side":"B","price":"1.156540000","size":30,"channel_id":23,"order_id":"10998900482538661681","flags":0,"ts_in_delta":1035,"sequence":157848,"symbol":"FCEU SI 20260615 PS"}
{"ts_recv":"2026-04-07T02:20:50.259969027Z","hd":{"ts_event":"2026-04-07T02:20:50.259943261Z","rtype":160,"publisher_id":101,"instrument_id":436},"action":"A","side":"B","price":"1.156550000","size":30,"channel_id":23,"order_id":"10998900487114725578","flags":0,"ts_in_delta":1035,"sequence":157848,"symbol":"FCEU SI 20260615 PS"}
{"ts_recv":"2026-04-07T02:20:50.259969027Z","hd":{"ts_event":"2026-04-07T02:20:50.259943261Z","rtype":160,"publisher_id":101,"instrument_id":436},"action":"C","side":"A","price":"1.156640000","size":30,"channel_id":23,"order_id":"1775528445683885873","flags":0,"ts_in_delta":1035,"sequence":157848,"symbol":"FCEU SI 20260615 PS"}
{"ts_recv":"2026-04-07T02:20:50.259969027Z","hd":{"ts_event":"2026-04-07T02:20:50.259943261Z","rtype":160,"publisher_id":101,"instrument_id":436},"action":"A","side":"A","price":"1.156650000","size":30,"channel_id":23,"order_id":"1775528450259949770","flags":128,"ts_in_delta":1035,"sequence":157848,"symbol":"FCEU SI 20260615 PS"}
{"ts_recv":"2026-04-07T02:20:50.299507585Z","hd":{"ts_event":"2026-04-07T02:20:50.299492641Z","rtype":160,"publisher_id":101,"instrument_id":436},"action":"A","side":"A","price":"1.156900000","size":20,"channel_id":23,"order_id":"1775528450299498599","flags":128,"ts_in_delta":844,"sequence":157858,"symbol":"FCEU SI 20260615 PS"}
{"ts_recv":"2026-04-07T02:20:51.273329237Z","hd":{"ts_event":"2026-04-07T02:20:51.273309585Z","rtype":160,"publisher_id":101,"instrument_id":436},"action":"C","side":"B","price":"1.156550000","size":30,"channel_id":23,"order_id":"10998900487114725578","flags":0,"ts_in_delta":1788,"sequence":157878,"symbol":"FCEU SI 20260615 PS"}
{"ts_recv":"2026-04-07T02:20:51.273329237Z","hd":{"ts_event":"2026-04-07T02:20:51.273309585Z","rtype":160,"publisher_id":101,"instrument_id":436},"action":"A","side":"B","price":"1.156540000","size":30,"channel_id":23,"order_id":"10998900488128091534","flags":0,"ts_in_delta":1788,"sequence":157878,"symbol":"FCEU SI 20260615 PS"}
{"ts_recv":"2026-04-07T02:20:51.273329237Z","hd":{"ts_event":"2026-04-07T02:20:51.273309585Z","rtype":160,"publisher_id":101,"instrument_id":436},"action":"C","side":"A","price":"1.156650000","size":30,"channel_id":23,"order_id":"1775528450259949770","flags":0,"ts_in_delta":1788,"sequence":157878,"symbol":"FCEU SI 20260615 PS"}
{"ts_recv":"2026-04-07T02:20:51.273329237Z","hd":{"ts_event":"2026-04-07T02:20:51.273309585Z","rtype":160,"publisher_id":101,"instrument_id":436},"action":"A","side":"A","price":"1.156640000","size":30,"channel_id":23,"order_id":"1775528451273315726","flags":128,"ts_in_delta":1788,"sequence":157878,"symbol":"FCEU SI 20260615 PS"}
{"ts_recv":"2026-04-07T02:20:51.313683918Z","hd":{"ts_event":"2026-04-07T02:20:51.313669383Z","rtype":160,"publisher_id":101,"instrument_id":436},"action":"A","side":"A","price":"1.156800000","size":20,"channel_id":23,"order_id":"1775528451313675253","flags":128,"ts_in_delta":1029,"sequence":157883,"symbol":"FCEU SI 20260615 PS"}
{"ts_recv":"2026-04-07T02:20:51.313746223Z","hd":{"ts_event":"2026-04-07T02:20:51.313734863Z","rtype":160,"publisher_id":101,"instrument_id":436},"action":"C","side":"A","price":"1.156900000","size":20,"channel_id":23,"order_id":"1775528450299498599","flags":128,"ts_in_delta":968,"sequence":157886,"symbol":"FCEU SI 20260615 PS"}
{"ts_recv":"2026-04-07T02:20:58.005168087Z","hd":{"ts_event":"2026-04-07T02:20:58.005144939Z","rtype":160,"publisher_id":101,"instrument_id":436},"action":"C","side":"B","price":"1.156540000","size":30,"channel_id":23,"order_id":"10998900488128091534","flags":0,"ts_in_delta":875,"sequence":157919,"symbol":"FCEU SI 20260615 PS"}
{"ts_recv":"2026-04-07T02:20:58.005168087Z","hd":{"ts_event":"2026-04-07T02:20:58.005144939Z","rtype":160,"publisher_id":101,"instrument_id":436},"action":"A","side":"B","price":"1.156550000","size":30,"channel_id":23,"order_id":"10998900494859926744","flags":0,"ts_in_delta":875,"sequence":157919,"symbol":"FCEU SI 20260615 PS"}
{"ts_recv":"2026-04-07T02:20:58.005168087Z","hd":{"ts_event":"2026-04-07T02:20:58.005144939Z","rtype":160,"publisher_id":101,"instrument_id":436},"action":"C","side":"A","price":"1.156640000","size":30,"channel_id":23,"order_id":"1775528451273315726","flags":0,"ts_in_delta":875,"sequence":157919,"symbol":"FCEU SI 20260615 PS"}
{"ts_recv":"2026-04-07T02:20:58.005168087Z","hd":{"ts_event":"2026-04-07T02:20:58.005144939Z","rtype":160,"publisher_id":101,"instrument_id":436},"action":"A","side":"A","price":"1.156650000","size":30,"channel_id":23,"order_id":"1775528458005150936","flags":128,"ts_in_delta":875,"sequence":157919,"symbol":"FCEU SI 20260615 PS"}
{"ts_recv":"2026-04-07T02:21:01.454397133Z","hd":{"ts_event":"2026-04-07T02:21:01.454373433Z","rtype":160,"publisher_id":101,"instrument_id":436},"action":"C","side":"B","price":"1.156550000","size":30,"channel_id":23,"order_id":"10998900494859926744","flags":0,"ts_in_delta":1205,"sequence":157986,"symbol":"FCEU SI 20260615 PS"}
{"ts_recv":"2026-04-07T02:21:01.454397133Z","hd":{"ts_event":"2026-04-07T02:21:01.454373433Z","rtype":160,"publisher_id":101,"instrument_id":436},"action":"A","side":"B","price":"1.156560000","size":30,"channel_id":23,"order_id":"10998900498309155521","flags":0,"ts_in_delta":1205,"sequence":157986,"symbol":"FCEU SI 20260615 PS"}
{"ts_recv":"2026-04-07T02:21:01.454397133Z","hd":{"ts_event":"2026-04-07T02:21:01.454373433Z","rtype":160,"publisher_id":101,"instrument_id":436},"action":"C","side":"A","price":"1.156650000","size":30,"channel_id":23,"order_id":"1775528458005150936","flags":0,"ts_in_delta":1205,"sequence":157986,"symbol":"FCEU SI 20260615 PS"}
{"ts_recv":"2026-04-07T02:21:01.454397133Z","hd":{"ts_event":"2026-04-07T02:21:01.454373433Z","rtype":160,"publisher_id":101,"instrument_id":436},"action":"A","side":"A","price":"1.156660000","size":30,"channel_id":23,"order_id":"1775528461454379713","flags":128,"ts_in_delta":1205,"sequence":157986,"symbol":"FCEU SI 20260615 PS"}
{"ts_recv":"2026-04-07T02:21:01.454465397Z","hd":{"ts_event":"2026-04-07T02:21:01.454441483Z","rtype":160,"publisher_id":101,"instrument_id":436},"action":"C","side":"B","price":"1.156540000","size":30,"channel_id":23,"order_id":"10998900482538586690","flags":0,"ts_in_delta":971,"sequence":157987,"symbol":"FCEU SI 20260615 PS"}
{"ts_recv":"2026-04-07T02:21:01.454465397Z","hd":{"ts_event":"2026-04-07T02:21:01.454441483Z","rtype":160,"publisher_id":101,"instrument_id":436},"action":"A","side":"B","price":"1.156570000","size":30,"channel_id":23,"order_id":"10998900498309223482","flags":0,"ts_in_delta":971,"sequence":157987,"symbol":"FCEU SI 20260615 PS"}
{"ts_recv":"2026-04-07T02:21:01.454465397Z","hd":{"ts_event":"2026-04-07T02:21:01.454441483Z","rtype":160,"publisher_id":101,"instrument_id":436},"action":"C","side":"A","price":"1.156640000","size":30,"channel_id":23,"order_id":"1775528445683810882","flags":0,"ts_in_delta":971,"sequence":157987,"symbol":"FCEU SI 20260615 PS"}
{"ts_recv":"2026-04-07T02:21:01.454465397Z","hd":{"ts_event":"2026-04-07T02:21:01.454441483Z","rtype":160,"publisher_id":101,"instrument_id":436},"action":"A","side":"A","price":"1.156670000","size":30,"channel_id":23,"order_id":"1775528461454447674","flags":128,"ts_in_delta":971,"sequence":157987,"symbol":"FCEU SI 20260615 PS"}
{"ts_recv":"2026-04-07T02:21:01.454529269Z","hd":{"ts_event":"2026-04-07T02:21:01.454509067Z","rtype":160,"publisher_id":101,"instrument_id":436},"action":"C","side":"B","price":"1.156560000","size":30,"channel_id":23,"order_id":"10998900498309155521","flags":0,"ts_in_delta":997,"sequence":157988,"symbol":"FCEU SI 20260615 PS"}
{"ts_recv":"2026-04-07T02:21:01.454529269Z","hd":{"ts_event":"2026-04-07T02:21:01.454509067Z","rtype":160,"publisher_id":101,"instrument_id":436},"action":"A","side":"B","price":"1.156580000","size":30,"channel_id":23,"order_id":"10998900498309290656","flags":0,"ts_in_delta":997,"sequence":157988,"symbol":"FCEU SI 20260615 PS"}
{"ts_recv":"2026-04-07T02:21:01.454529269Z","hd":{"ts_event":"2026-04-07T02:21:01.454509067Z","rtype":160,"publisher_id":101,"instrument_id":436},"action":"C","side":"A","price":"1.156660000","size":30,"channel_id":23,"order_id":"1775528461454379713","flags":0,"ts_in_delta":997,"sequence":157988,"symbol":"FCEU SI 20260615 PS"}
{"ts_recv":"2026-04-07T02:21:01.454529269Z","hd":{"ts_event":"2026-04-07T02:21:01.454509067Z","rtype":160,"publisher_id":101,"instrument_id":436},"action":"A","side":"A","price":"1.156680000","size":30,"channel_id":23,"order_id":"1775528461454514848","flags":128,"ts_in_delta":997,"sequence":157988,"symbol":"FCEU SI 20260615 PS"}
{"ts_recv":"2026-04-07T02:21:01.463559430Z","hd":{"ts_event":"2026-04-07T02:21:01.463537661Z","rtype":160,"publisher_id":101,"instrument_id":436},"action":"C","side":"B","price":"1.156570000","size":30,"channel_id":23,"order_id":"10998900498309223482","flags":0,"ts_in_delta":1203,"sequence":157990,"symbol":"FCEU SI 20260615 PS"}
{"ts_recv":"2026-04-07T02:21:01.463559430Z","hd":{"ts_event":"2026-04-07T02:21:01.463537661Z","rtype":160,"publisher_id":101,"instrument_id":436},"action":"A","side":"B","price":"1.156590000","size":30,"channel_id":23,"order_id":"10998900498318319456","flags":0,"ts_in_delta":1203,"sequence":157990,"symbol":"FCEU SI 20260615 PS"}
{"ts_recv":"2026-04-07T02:21:01.463559430Z","hd":{"ts_event":"2026-04-07T02:21:01.463537661Z","rtype":160,"publisher_id":101,"instrument_id":436},"action":"C","side":"A","price":"1.156670000","size":30,"channel_id":23,"order_id":"1775528461454447674","flags":0,"ts_in_delta":1203,"sequence":157990,"symbol":"FCEU SI 20260615 PS"}
{"ts_recv":"2026-04-07T02:21:01.463559430Z","hd":{"ts_event":"2026-04-07T02:21:01.463537661Z","rtype":160,"publisher_id":101,"instrument_id":436},"action":"A","side":"A","price":"1.156690000","size":30,"channel_id":23,"order_id":"1775528461463543648","flags":128,"ts_in_delta":1203,"sequence":157990,"symbol":"FCEU SI 20260615 PS"}
{"ts_recv":"2026-04-07T02:21:01.463620437Z","hd":{"ts_event":"2026-04-07T02:21:01.463604029Z","rtype":160,"publisher_id":101,"instrument_id":436},"action":"C","side":"B","price":"1.156580000","size":30,"channel_id":23,"order_id":"10998900498309290656","flags":0,"ts_in_delta":973,"sequence":157991,"symbol":"FCEU SI 20260615 PS"}
{"ts_recv":"2026-04-07T02:21:01.463620437Z","hd":{"ts_event":"2026-04-07T02:21:01.463604029Z","rtype":160,"publisher_id":101,"instrument_id":436},"action":"A","side":"B","price":"1.156590000","size":30,"channel_id":23,"order_id":"10998900498318385975","flags":0,"ts_in_delta":973,"sequence":157991,"symbol":"FCEU SI 20260615 PS"}
{"ts_recv":"2026-04-07T02:21:01.463620437Z","hd":{"ts_event":"2026-04-07T02:21:01.463604029Z","rtype":160,"publisher_id":101,"instrument_id":436},"action":"C","side":"A","price":"1.156680000","size":30,"channel_id":23,"order_id":"1775528461454514848","flags":0,"ts_in_delta":973,"sequence":157991,"symbol":"FCEU SI 20260615 PS"}
{"ts_recv":"2026-04-07T02:21:01.463620437Z","hd":{"ts_event":"2026-04-07T02:21:01.463604029Z","rtype":160,"publisher_id":101,"instrument_id":436},"action":"A","side":"A","price":"1.156690000","size":30,"channel_id":23,"order_id":"1775528461463610167","flags":128,"ts_in_delta":973,"sequence":157991,"symbol":"FCEU SI 20260615 PS"}
{"ts_recv":"2026-04-07T02:21:03.695145281Z","hd":{"ts_event":"2026-04-07T02:21:03.695124899Z","rtype":160,"publisher_id":101,"instrument_id":436},"action":"C","side":"B","price":"1.156590000","size":30,"channel_id":23,"order_id":"10998900498318319456","flags":0,"ts_in_delta":1000,"sequence":158015,"symbol":"FCEU SI 20260615 PS"}
{"ts_recv":"2026-04-07T02:21:03.695145281Z","hd":{"ts_event":"2026-04-07T02:21:03.695124899Z","rtype":160,"publisher_id":101,"instrument_id":436},"action":"A","side":"B","price":"1.156570000","size":30,"channel_id":23,"order_id":"10998900500549907926","flags":0,"ts_in_delta":1000,"sequence":158015,"symbol":"FCEU SI 20260615 PS"}
{"ts_recv":"2026-04-07T02:21:03.695145281Z","hd":{"ts_event":"2026-04-07T02:21:03.695124899Z","rtype":160,"publisher_id":101,"instrument_id":436},"action":"C","side":"A","price":"1.156690000","size":30,"channel_id":23,"order_id":"1775528461463543648","flags":0,"ts_in_delta":1000,"sequence":158015,"symbol":"FCEU SI 20260615 PS"}
{"ts_recv":"2026-04-07T02:21:03.695145281Z","hd":{"ts_event":"2026-04-07T02:21:03.695124899Z","rtype":160,"publisher_id":101,"instrument_id":436},"action":"A","side":"A","price":"1.156670000","size":30,"channel_id":23,"order_id":"1775528463695132118","flags":128,"ts_in_delta":1000,"sequence":158015,"symbol":"FCEU SI 20260615 PS"}
{"ts_recv":"2026-04-07T02:21:03.695228812Z","hd":{"ts_event":"2026-04-07T02:21:03.695209617Z","rtype":160,"publisher_id":101,"instrument_id":436},"action":"C","side":"B","price":"1.156590000","size":30,"channel_id":23,"order_id":"10998900498318385975","flags":0,"ts_in_delta":1002,"sequence":158016,"symbol":"FCEU SI 20260615 PS"}
{"ts_recv":"2026-04-07T02:21:03.695228812Z","hd":{"ts_event":"2026-04-07T02:21:03.695209617Z","rtype":160,"publisher_id":101,"instrument_id":436},"action":"A","side":"B","price":"1.156580000","size":30,"channel_id":23,"order_id":"10998900500549991321","flags":0,"ts_in_delta":1002,"sequence":158016,"symbol":"FCEU SI 20260615 PS"}
{"ts_recv":"2026-04-07T02:21:03.695228812Z","hd":{"ts_event":"2026-04-07T02:21:03.695209617Z","rtype":160,"publisher_id":101,"instrument_id":436},"action":"C","side":"A","price":"1.156690000","size":30,"channel_id":23,"order_id":"1775528461463610167","flags":0,"ts_in_delta":1002,"sequence":158016,"symbol":"FCEU SI 20260615 PS"}
{"ts_recv":"2026-04-07T02:21:03.695228812Z","hd":{"ts_event":"2026-04-07T02:21:03.695209617Z","rtype":160,"publisher_id":101,"instrument_id":436},"action":"A","side":"A","price":"1.156680000","size":30,"channel_id":23,"order_id":"1775528463695215513","flags":128,"ts_in_delta":1002,"sequence":158016,"symbol":"FCEU SI 20260615 PS"}
{"ts_recv":"2026-04-07T02:21:03.698724319Z","hd":{"ts_event":"2026-04-07T02:21:03.698706819Z","rtype":160,"publisher_id":101,"instrument_id":436},"action":"C","side":"B","price":"1.156580000","size":30,"channel_id":23,"order_id":"10998900500549991321","flags":0,"ts_in_delta":969,"sequence":158019,"symbol":"FCEU SI 20260615 PS"}
{"ts_recv":"2026-04-07T02:21:03.698724319Z","hd":{"ts_event":"2026-04-07T02:21:03.698706819Z","rtype":160,"publisher_id":101,"instrument_id":436},"action":"A","side":"B","price":"1.156570000","size":30,"channel_id":23,"order_id":"10998900500553488770","flags":0,"ts_in_delta":969,"sequence":158019,"symbol":"FCEU SI 20260615 PS"}
{"ts_recv":"2026-04-07T02:21:03.698724319Z","hd":{"ts_event":"2026-04-07T02:21:03.698706819Z","rtype":160,"publisher_id":101,"instrument_id":436},"action":"C","side":"A","price":"1.156680000","size":30,"channel_id":23,"order_id":"1775528463695215513","flags":0,"ts_in_delta":969,"sequence":158019,"symbol":"FCEU SI 20260615 PS"}
{"ts_recv":"2026-04-07T02:21:03.698724319Z","hd":{"ts_event":"2026-04-07T02:21:03.698706819Z","rtype":160,"publisher_id":101,"instrument_id":436},"action":"A","side":"A","price":"1.156670000","size":30,"channel_id":23,"order_id":"1775528463698712962","flags":128,"ts_in_delta":969,"sequence":158019,"symbol":"FCEU SI 20260615 PS"}
{"ts_recv":"2026-04-07T02:21:03.703580083Z","hd":{"ts_event":"2026-04-07T02:21:03.703562081Z","rtype":160,"publisher_id":101,"instrument_id":436},"action":"C","side":"B","price":"1.156570000","size":30,"channel_id":23,"order_id":"10998900500553488770","flags":0,"ts_in_delta":852,"sequence":158021,"symbol":"FCEU SI 20260615 PS"}
{"ts_recv":"2026-04-07T02:21:03.703580083Z","hd":{"ts_event":"2026-04-07T02:21:03.703562081Z","rtype":160,"publisher_id":101,"instrument_id":436},"action":"A","side":"B","price":"1.156560000","size":30,"channel_id":23,"order_id":"10998900500558343941","flags":0,"ts_in_delta":852,"sequence":158021,"symbol":"FCEU SI 20260615 PS"}
{"ts_recv":"2026-04-07T02:21:03.703580083Z","hd":{"ts_event":"2026-04-07T02:21:03.703562081Z","rtype":160,"publisher_id":101,"instrument_id":436},"action":"C","side":"A","price":"1.156670000","size":30,"channel_id":23,"order_id":"1775528463698712962","flags":0,"ts_in_delta":852,"sequence":158021,"symbol":"FCEU SI 20260615 PS"}
{"ts_recv":"2026-04-07T02:21:03.703580083Z","hd":{"ts_event":"2026-04-07T02:21:03.703562081Z","rtype":160,"publisher_id":101,"instrument_id":436},"action":"A","side":"A","price":"1.156660000","size":30,"channel_id":23,"order_id":"1775528463703568133","flags":128,"ts_in_delta":852,"sequence":158021,"symbol":"FCEU SI 20260615 PS"}
{"ts_recv":"2026-04-07T02:21:03.734925926Z","hd":{"ts_event":"2026-04-07T02:21:03.734910193Z","rtype":160,"publisher_id":101,"instrument_id":436},"action":"C","side":"B","price":"1.156560000","size":30,"channel_id":23,"order_id":"10998900500558343941","flags":0,"ts_in_delta":788,"sequence":158025,"symbol":"FCEU SI 20260615 PS"}
{"ts_recv":"2026-04-07T02:21:03.734925926Z","hd":{"ts_event":"2026-04-07T02:21:03.734910193Z","rtype":160,"publisher_id":101,"instrument_id":436},"action":"A","side":"B","price":"1.156570000","size":30,"channel_id":23,"order_id":"10998900500589691749","flags":0,"ts_in_delta":788,"sequence":158025,"symbol":"FCEU SI 20260615 PS"}
{"ts_recv":"2026-04-07T02:21:03.734925926Z","hd":{"ts_event":"2026-04-07T02:21:03.734910193Z","rtype":160,"publisher_id":101,"instrument_id":436},"action":"C","side":"A","price":"1.156660000","size":30,"channel_id":23,"order_id":"1775528463703568133","flags":0,"ts_in_delta":788,"sequence":158025,"symbol":"FCEU SI 20260615 PS"}
{"ts_recv":"2026-04-07T02:21:03.734925926Z","hd":{"ts_event":"2026-04-07T02:21:03.734910193Z","rtype":160,"publisher_id":101,"instrument_id":436},"action":"A","side":"A","price":"1.156670000","size":30,"channel_id":23,"order_id":"1775528463734915941","flags":128,"ts_in_delta":788,"sequence":158025,"symbol":"FCEU SI 20260615 PS"}
{"ts_recv":"2026-04-07T02:21:10.695823786Z","hd":{"ts_event":"2026-04-07T02:21:10.695792173Z","rtype":160,"publisher_id":101,"instrument_id":436},"action":"C","side":"B","price":"1.156570000","size":30,"channel_id":23,"order_id":"10998900500589691749","flags":0,"ts_in_delta":1642,"sequence":158075,"symbol":"FCEU SI 20260615 PS"}
{"ts_recv":"2026-04-07T02:21:10.695823786Z","hd":{"ts_event":"2026-04-07T02:21:10.695792173Z","rtype":160,"publisher_id":101,"instrument_id":436},"action":"A","side":"B","price":"1.156560000","size":30,"channel_id":23,"order_id":"10998900507550581908","flags":0,"ts_in_delta":1642,"sequence":158075,"symbol":"FCEU SI 20260615 PS"}
{"ts_recv":"2026-04-07T02:21:10.695823786Z","hd":{"ts_event":"2026-04-07T02:21:10.695792173Z","rtype":160,"publisher_id":101,"instrument_id":436},"action":"C","side":"A","price":"1.156670000","size":30,"channel_id":23,"order_id":"1775528463734915941","flags":0,"ts_in_delta":1642,"sequence":158075,"symbol":"FCEU SI 20260615 PS"}
{"ts_recv":"2026-04-07T02:21:10.695823786Z","hd":{"ts_event":"2026-04-07T02:21:10.695792173Z","rtype":160,"publisher_id":101,"instrument_id":436},"action":"A","side":"A","price":"1.156660000","size":30,"channel_id":23,"order_id":"1775528470695806100","flags":128,"ts_in_delta":1642,"sequence":158075,"symbol":"FCEU SI 20260615 PS"}
{"ts_recv":"2026-04-07T02:21:10.695898509Z","hd":{"ts_event":"2026-04-07T02:21:10.695879739Z","rtype":160,"publisher_id":101,"instrument_id":436},"action":"C","side":"B","price":"1.156570000","size":30,"channel_id":23,"order_id":"10998900500549907926","flags":0,"ts_in_delta":923,"sequence":158076,"symbol":"FCEU SI 20260615 PS"}
{"ts_recv":"2026-04-07T02:21:10.695898509Z","hd":{"ts_event":"2026-04-07T02:21:10.695879739Z","rtype":160,"publisher_id":101,"instrument_id":436},"action":"A","side":"B","price":"1.156550000","size":30,"channel_id":23,"order_id":"10998900507550662005","flags":0,"ts_in_delta":923,"sequence":158076,"symbol":"FCEU SI 20260615 PS"}
{"ts_recv":"2026-04-07T02:21:10.695898509Z","hd":{"ts_event":"2026-04-07T02:21:10.695879739Z","rtype":160,"publisher_id":101,"instrument_id":436},"action":"C","side":"A","price":"1.156670000","size":30,"channel_id":23,"order_id":"1775528463695132118","flags":0,"ts_in_delta":923,"sequence":158076,"symbol":"FCEU SI 20260615 PS"}
{"ts_recv":"2026-04-07T02:21:10.695898509Z","hd":{"ts_event":"2026-04-07T02:21:10.695879739Z","rtype":160,"publisher_id":101,"instrument_id":436},"action":"A","side":"A","price":"1.156650000","size":30,"channel_id":23,"order_id":"1775528470695886197","flags":128,"ts_in_delta":923,"sequence":158076,"symbol":"FCEU SI 20260615 PS"}
{"ts_recv":"2026-04-07T02:21:10.695956437Z","hd":{"ts_event":"2026-04-07T02:21:10.695940797Z","rtype":160,"publisher_id":101,"instrument_id":436},"action":"C","side":"B","price":"1.156560000","size":30,"channel_id":23,"order_id":"10998900507550581908","flags":0,"ts_in_delta":729,"sequence":158077,"symbol":"FCEU SI 20260615 PS"}
{"ts_recv":"2026-04-07T02:21:10.695956437Z","hd":{"ts_event":"2026-04-07T02:21:10.695940797Z","rtype":160,"publisher_id":101,"instrument_id":436},"action":"A","side":"B","price":"1.156550000","size":30,"channel_id":23,"order_id":"10998900507550722557","flags":0,"ts_in_delta":729,"sequence":158077,"symbol":"FCEU SI 20260615 PS"}
{"ts_recv":"2026-04-07T02:21:10.695956437Z","hd":{"ts_event":"2026-04-07T02:21:10.695940797Z","rtype":160,"publisher_id":101,"instrument_id":436},"action":"C","side":"A","price":"1.156660000","size":30,"channel_id":23,"order_id":"1775528470695806100","flags":0,"ts_in_delta":729,"sequence":158077,"symbol":"FCEU SI 20260615 PS"}
{"ts_recv":"2026-04-07T02:21:10.695956437Z","hd":{"ts_event":"2026-04-07T02:21:10.695940797Z","rtype":160,"publisher_id":101,"instrument_id":436},"action":"A","side":"A","price":"1.156650000","size":30,"channel_id":23,"order_id":"1775528470695946749","flags":128,"ts_in_delta":729,"sequence":158077,"symbol":"FCEU SI 20260615 PS"}
{"ts_recv":"2026-04-07T02:21:14.080541400Z","hd":{"ts_event":"2026-04-07T02:21:14.080509991Z","rtype":160,"publisher_id":101,"instrument_id":436},"action":"C","side":"B","price":"1.156550000","size":30,"channel_id":23,"order_id":"10998900507550722557","flags":0,"ts_in_delta":1686,"sequence":158092,"symbol":"FCEU SI 20260615 PS"}
{"ts_recv":"2026-04-07T02:21:14.080541400Z","hd":{"ts_event":"2026-04-07T02:21:14.080509991Z","rtype":160,"publisher_id":101,"instrument_id":436},"action":"A","side":"B","price":"1.156560000","size":30,"channel_id":23,"order_id":"10998900510935299715","flags":0,"ts_in_delta":1686,"sequence":158092,"symbol":"FCEU SI 20260615 PS"}
{"ts_recv":"2026-04-07T02:21:14.080541400Z","hd":{"ts_event":"2026-04-07T02:21:14.080509991Z","rtype":160,"publisher_id":101,"instrument_id":436},"action":"C","side":"A","price":"1.156650000","size":30,"channel_id":23,"order_id":"1775528470695946749","flags":0,"ts_in_delta":1686,"sequence":158092,"symbol":"FCEU SI 20260615 PS"}
{"ts_recv":"2026-04-07T02:21:14.080541400Z","hd":{"ts_event":"2026-04-07T02:21:14.080509991Z","rtype":160,"publisher_id":101,"instrument_id":436},"action":"A","side":"A","price":"1.156660000","size":30,"channel_id":23,"order_id":"1775528474080523907","flags":128,"ts_in_delta":1686,"sequence":158092,"symbol":"FCEU SI 20260615 PS"}
{"ts_recv":"2026-04-07T02:21:14.084899338Z","hd":{"ts_event":"2026-04-07T02:21:14.084881711Z","rtype":160,"publisher_id":101,"instrument_id":436},"action":"C","side":"B","price":"1.156560000","size":30,"channel_id":23,"order_id":"10998900510935299715","flags":0,"ts_in_delta":985,"sequence":158093,"symbol":"FCEU SI 20260615 PS"}
{"ts_recv":"2026-04-07T02:21:14.084899338Z","hd":{"ts_event":"2026-04-07T02:21:14.084881711Z","rtype":160,"publisher_id":101,"instrument_id":436},"action":"A","side":"B","price":"1.156570000","size":30,"channel_id":23,"order_id":"10998900510939663583","flags":0,"ts_in_delta":985,"sequence":158093,"symbol":"FCEU SI 20260615 PS"}
{"ts_recv":"2026-04-07T02:21:14.084899338Z","hd":{"ts_event":"2026-04-07T02:21:14.084881711Z","rtype":160,"publisher_id":101,"instrument_id":436},"action":"C","side":"A","price":"1.156660000","size":30,"channel_id":23,"order_id":"1775528474080523907","flags":0,"ts_in_delta":985,"sequence":158093,"symbol":"FCEU SI 20260615 PS"}
{"ts_recv":"2026-04-07T02:21:14.084899338Z","hd":{"ts_event":"2026-04-07T02:21:14.084881711Z","rtype":160,"publisher_id":101,"instrument_id":436},"action":"A","side":"A","price":"1.156670000","size":30,"channel_id":23,"order_id":"1775528474084887775","flags":128,"ts_in_delta":985,"sequence":158093,"symbol":"FCEU SI 20260615 PS"}
{"ts_recv":"2026-04-07T02:21:14.084976288Z","hd":{"ts_event":"2026-04-07T02:21:14.084956777Z","rtype":160,"publisher_id":101,"instrument_id":436},"action":"C","side":"B","price":"1.156550000","size":30,"channel_id":23,"order_id":"10998900507550662005","flags":0,"ts_in_delta":962,"sequence":158094,"symbol":"FCEU SI 20260615 PS"}
{"ts_recv":"2026-04-07T02:21:14.084976288Z","hd":{"ts_event":"2026-04-07T02:21:14.084956777Z","rtype":160,"publisher_id":101,"instrument_id":436},"action":"A","side":"B","price":"1.156570000","size":30,"channel_id":23,"order_id":"10998900510939738683","flags":0,"ts_in_delta":962,"sequence":158094,"symbol":"FCEU SI 20260615 PS"}
{"ts_recv":"2026-04-07T02:21:14.084976288Z","hd":{"ts_event":"2026-04-07T02:21:14.084956777Z","rtype":160,"publisher_id":101,"instrument_id":436},"action":"C","side":"A","price":"1.156650000","size":30,"channel_id":23,"order_id":"1775528470695886197","flags":0,"ts_in_delta":962,"sequence":158094,"symbol":"FCEU SI 20260615 PS"}
{"ts_recv":"2026-04-07T02:21:14.084976288Z","hd":{"ts_event":"2026-04-07T02:21:14.084956777Z","rtype":160,"publisher_id":101,"instrument_id":436},"action":"A","side":"A","price":"1.156670000","size":30,"channel_id":23,"order_id":"1775528474084962875","flags":128,"ts_in_delta":962,"sequence":158094,"symbol":"FCEU SI 20260615 PS"}
{"ts_recv":"2026-04-07T02:21:14.085034347Z","hd":{"ts_event":"2026-04-07T02:21:14.085013365Z","rtype":160,"publisher_id":101,"instrument_id":436},"action":"C","side":"B","price":"1.156570000","size":30,"channel_id":23,"order_id":"10998900510939663583","flags":0,"ts_in_delta":1092,"sequence":158095,"symbol":"FCEU SI 20260615 PS"}
{"ts_recv":"2026-04-07T02:21:14.085034347Z","hd":{"ts_event":"2026-04-07T02:21:14.085013365Z","rtype":160,"publisher_id":101,"instrument_id":436},"action":"A","side":"B","price":"1.156580000","size":30,"channel_id":23,"order_id":"10998900510939795269","flags":0,"ts_in_delta":1092,"sequence":158095,"symbol":"FCEU SI 20260615 PS"}
{"ts_recv":"2026-04-07T02:21:14.085034347Z","hd":{"ts_event":"2026-04-07T02:21:14.085013365Z","rtype":160,"publisher_id":101,"instrument_id":436},"action":"C","side":"A","price":"1.156670000","size":30,"channel_id":23,"order_id":"1775528474084887775","flags":0,"ts_in_delta":1092,"sequence":158095,"symbol":"FCEU SI 20260615 PS"}
{"ts_recv":"2026-04-07T02:21:14.085034347Z","hd":{"ts_event":"2026-04-07T02:21:14.085013365Z","rtype":160,"publisher_id":101,"instrument_id":436},"action":"A","side":"A","price":"1.156680000","size":30,"channel_id":23,"order_id":"1775528474085019461","flags":128,"ts_in_delta":1092,"sequence":158095,"symbol":"FCEU SI 20260615 PS"}
{"ts_recv":"2026-04-07T02:21:14.085119215Z","hd":{"ts_event":"2026-04-07T02:21:14.085099627Z","rtype":160,"publisher_id":101,"instrument_id":436},"action":"C","side":"B","price":"1.156580000","size":30,"channel_id":23,"order_id":"10998900510939795269","flags":0,"ts_in_delta":961,"sequence":158096,"symbol":"FCEU SI 20260615 PS"}
{"ts_recv":"2026-04-07T02:21:14.085119215Z","hd":{"ts_event":"2026-04-07T02:21:14.085099627Z","rtype":160,"publisher_id":101,"instrument_id":436},"action":"A","side":"B","price":"1.156590000","size":30,"channel_id":23,"order_id":"10998900510939881200","flags":0,"ts_in_delta":961,"sequence":158096,"symbol":"FCEU SI 20260615 PS"}
{"ts_recv":"2026-04-07T02:21:14.085119215Z","hd":{"ts_event":"2026-04-07T02:21:14.085099627Z","rtype":160,"publisher_id":101,"instrument_id":436},"action":"C","side":"A","price":"1.156680000","size":30,"channel_id":23,"order_id":"1775528474085019461","flags":0,"ts_in_delta":961,"sequence":158096,"symbol":"FCEU SI 20260615 PS"}
{"ts_recv":"2026-04-07T02:21:14.085119215Z","hd":{"ts_event":"2026-04-07T02:21:14.085099627Z","rtype":160,"publisher_id":101,"instrument_id":436},"action":"A","side":"A","price":"1.156690000","size":30,"channel_id":23,"order_id":"1775528474085105392","flags":128,"ts_in_delta":961,"sequence":158096,"symbol":"FCEU SI 20260615 PS"}
{"ts_recv":"2026-04-07T02:21:14.085177411Z","hd":{"ts_event":"2026-04-07T02:21:14.085159691Z","rtype":160,"publisher_id":101,"instrument_id":436},"action":"C","side":"B","price":"1.156590000","size":30,"channel_id":23,"order_id":"10998900510939881200","flags":0,"ts_in_delta":779,"sequence":158097,"symbol":"FCEU SI 20260615 PS"}
{"ts_recv":"2026-04-07T02:21:14.085177411Z","hd":{"ts_event":"2026-04-07T02:21:14.085159691Z","rtype":160,"publisher_id":101,"instrument_id":436},"action":"A","side":"B","price":"1.156580000","size":30,"channel_id":23,"order_id":"10998900510939941540","flags":0,"ts_in_delta":779,"sequence":158097,"symbol":"FCEU SI 20260615 PS"}
{"ts_recv":"2026-04-07T02:21:14.085177411Z","hd":{"ts_event":"2026-04-07T02:21:14.085159691Z","rtype":160,"publisher_id":101,"instrument_id":436},"action":"C","side":"A","price":"1.156690000","size":30,"channel_id":23,"order_id":"1775528474085105392","flags":0,"ts_in_delta":779,"sequence":158097,"symbol":"FCEU SI 20260615 PS"}
{"ts_recv":"2026-04-07T02:21:14.085177411Z","hd":{"ts_event":"2026-04-07T02:21:14.085159691Z","rtype":160,"publisher_id":101,"instrument_id":436},"action":"A","side":"A","price":"1.156680000","size":30,"channel_id":23,"order_id":"1775528474085165732","flags":128,"ts_in_delta":779,"sequence":158097,"symbol":"FCEU SI 20260615 PS"}
{"ts_recv":"2026-04-07T02:21:14.099368453Z","hd":{"ts_event":"2026-04-07T02:21:14.099352651Z","rtype":160,"publisher_id":101,"instrument_id":436},"action":"C","side":"B","price":"1.156580000","size":30,"channel_id":23,"order_id":"10998900510939941540","flags":0,"ts_in_delta":992,"sequence":158102,"symbol":"FCEU SI 20260615 PS"}
{"ts_recv":"2026-04-07T02:21:14.099368453Z","hd":{"ts_event":"2026-04-07T02:21:14.099352651Z","rtype":160,"publisher_id":101,"instrument_id":436},"action":"A","side":"B","price":"1.156570000","size":30,"channel_id":23,"order_id":"10998900510954134503","flags":0,"ts_in_delta":992,"sequence":158102,"symbol":"FCEU SI 20260615 PS"}
{"ts_recv":"2026-04-07T02:21:14.099368453Z","hd":{"ts_event":"2026-04-07T02:21:14.099352651Z","rtype":160,"publisher_id":101,"instrument_id":436},"action":"C","side":"A","price":"1.156680000","size":30,"channel_id":23,"order_id":"1775528474085165732","flags":0,"ts_in_delta":992,"sequence":158102,"symbol":"FCEU SI 20260615 PS"}
{"ts_recv":"2026-04-07T02:21:14.099368453Z","hd":{"ts_event":"2026-04-07T02:21:14.099352651Z","rtype":160,"publisher_id":101,"instrument_id":436},"action":"A","side":"A","price":"1.156670000","size":30,"channel_id":23,"order_id":"1775528474099358695","flags":128,"ts_in_delta":992,"sequence":158102,"symbol":"FCEU SI 20260615 PS"}
{"ts_recv":"2026-04-07T02:21:24.120613631Z","hd":{"ts_event":"2026-04-07T02:21:24.120592361Z","rtype":160,"publisher_id":101,"instrument_id":436},"action":"C","side":"B","price":"1.156570000","size":30,"channel_id":23,"order_id":"10998900510939738683","flags":0,"ts_in_delta":885,"sequence":158186,"symbol":"FCEU SI 20260615 PS"}
{"ts_recv":"2026-04-07T02:21:24.120613631Z","hd":{"ts_event":"2026-04-07T02:21:24.120592361Z","rtype":160,"publisher_id":101,"instrument_id":436},"action":"A","side":"B","price":"1.156550000","size":30,"channel_id":23,"order_id":"10998900520975374447","flags":0,"ts_in_delta":885,"sequence":158186,"symbol":"FCEU SI 20260615 PS"}
{"ts_recv":"2026-04-07T02:21:24.120613631Z","hd":{"ts_event":"2026-04-07T02:21:24.120592361Z","rtype":160,"publisher_id":101,"instrument_id":436},"action":"C","side":"A","price":"1.156670000","size":30,"channel_id":23,"order_id":"1775528474084962875","flags":0,"ts_in_delta":885,"sequence":158186,"symbol":"FCEU SI 20260615 PS"}
{"ts_recv":"2026-04-07T02:21:24.120613631Z","hd":{"ts_event":"2026-04-07T02:21:24.120592361Z","rtype":160,"publisher_id":101,"instrument_id":436},"action":"A","side":"A","price":"1.156650000","size":30,"channel_id":23,"order_id":"1775528484120598639","flags":128,"ts_in_delta":885,"sequence":158186,"symbol":"FCEU SI 20260615 PS"}
{"ts_recv":"2026-04-07T02:21:24.120720524Z","hd":{"ts_event":"2026-04-07T02:21:24.120704521Z","rtype":160,"publisher_id":101,"instrument_id":436},"action":"C","side":"B","price":"1.156570000","size":30,"channel_id":23,"order_id":"10998900510954134503","flags":0,"ts_in_delta":1193,"sequence":158187,"symbol":"FCEU SI 20260615 PS"}
{"ts_recv":"2026-04-07T02:21:24.120720524Z","hd":{"ts_event":"2026-04-07T02:21:24.120704521Z","rtype":160,"publisher_id":101,"instrument_id":436},"action":"A","side":"B","price":"1.156560000","size":30,"channel_id":23,"order_id":"10998900520975486322","flags":0,"ts_in_delta":1193,"sequence":158187,"symbol":"FCEU SI 20260615 PS"}
{"ts_recv":"2026-04-07T02:21:24.120720524Z","hd":{"ts_event":"2026-04-07T02:21:24.120704521Z","rtype":160,"publisher_id":101,"instrument_id":436},"action":"C","side":"A","price":"1.156670000","size":30,"channel_id":23,"order_id":"1775528474099358695","flags":0,"ts_in_delta":1193,"sequence":158187,"symbol":"FCEU SI 20260615 PS"}
{"ts_recv":"2026-04-07T02:21:24.120720524Z","hd":{"ts_event":"2026-04-07T02:21:24.120704521Z","rtype":160,"publisher_id":101,"instrument_id":436},"action":"A","side":"A","price":"1.156660000","size":30,"channel_id":23,"order_id":"1775528484120710514","flags":128,"ts_in_delta":1193,"sequence":158187,"symbol":"FCEU SI 20260615 PS"}
{"ts_recv":"2026-04-07T02:21:24.122076121Z","hd":{"ts_event":"2026-04-07T02:21:24.122058131Z","rtype":160,"publisher_id":101,"instrument_id":436},"action":"C","side":"B","price":"1.156560000","size":30,"channel_id":23,"order_id":"10998900520975486322","flags":0,"ts_in_delta":940,"sequence":158190,"symbol":"FCEU SI 20260615 PS"}
{"ts_recv":"2026-04-07T02:21:24.122076121Z","hd":{"ts_event":"2026-04-07T02:21:24.122058131Z","rtype":160,"publisher_id":101,"instrument_id":436},"action":"A","side":"B","price":"1.156550000","size":30,"channel_id":23,"order_id":"10998900520976840204","flags":0,"ts_in_delta":940,"sequence":158190,"symbol":"FCEU SI 20260615 PS"}
{"ts_recv":"2026-04-07T02:21:24.122076121Z","hd":{"ts_event":"2026-04-07T02:21:24.122058131Z","rtype":160,"publisher_id":101,"instrument_id":436},"action":"C","side":"A","price":"1.156660000","size":30,"channel_id":23,"order_id":"1775528484120710514","flags":0,"ts_in_delta":940,"sequence":158190,"symbol":"FCEU SI 20260615 PS"}
{"ts_recv":"2026-04-07T02:21:24.122076121Z","hd":{"ts_event":"2026-04-07T02:21:24.122058131Z","rtype":160,"publisher_id":101,"instrument_id":436},"action":"A","side":"A","price":"1.156650000","size":30,"channel_id":23,"order_id":"1775528484122064396","flags":128,"ts_in_delta":940,"sequence":158190,"symbol":"FCEU SI 20260615 PS"}
{"ts_recv":"2026-04-07T02:21:29.770789839Z","hd":{"ts_event":"2026-04-07T02:21:29.770761373Z","rtype":160,"publisher_id":101,"instrument_id":436},"action":"C","side":"B","price":"1.156550000","size":30,"channel_id":23,"order_id":"10998900520976840204","flags":0,"ts_in_delta":915,"sequence":158255,"symbol":"FCEU SI 20260615 PS"}
{"ts_recv":"2026-04-07T02:21:29.770789839Z","hd":{"ts_event":"2026-04-07T02:21:29.770761373Z","rtype":160,"publisher_id":101,"instrument_id":436},"action":"A","side":"B","price":"1.156540000","size":30,"channel_id":23,"order_id":"10998900526625548348","flags":0,"ts_in_delta":915,"sequence":158255,"symbol":"FCEU SI 20260615 PS"}
{"ts_recv":"2026-04-07T02:21:29.770789839Z","hd":{"ts_event":"2026-04-07T02:21:29.770761373Z","rtype":160,"publisher_id":101,"instrument_id":436},"action":"C","side":"A","price":"1.156650000","size":30,"channel_id":23,"order_id":"1775528484122064396","flags":0,"ts_in_delta":915,"sequence":158255,"symbol":"FCEU SI 20260615 PS"}
{"ts_recv":"2026-04-07T02:21:29.770789839Z","hd":{"ts_event":"2026-04-07T02:21:29.770761373Z","rtype":160,"publisher_id":101,"instrument_id":436},"action":"A","side":"A","price":"1.156640000","size":30,"channel_id":23,"order_id":"1775528489770772540","flags":128,"ts_in_delta":915,"sequence":158255,"symbol":"FCEU SI 20260615 PS"}
{"ts_recv":"2026-04-07T02:21:29.770843774Z","hd":{"ts_event":"2026-04-07T02:21:29.770825291Z","rtype":160,"publisher_id":101,"instrument_id":436},"action":"C","side":"B","price":"1.156550000","size":30,"channel_id":23,"order_id":"10998900520975374447","flags":0,"ts_in_delta":948,"sequence":158256,"symbol":"FCEU SI 20260615 PS"}
{"ts_recv":"2026-04-07T02:21:29.770843774Z","hd":{"ts_event":"2026-04-07T02:21:29.770825291Z","rtype":160,"publisher_id":101,"instrument_id":436},"action":"A","side":"B","price":"1.156530000","size":30,"channel_id":23,"order_id":"10998900526625607225","flags":0,"ts_in_delta":948,"sequence":158256,"symbol":"FCEU SI 20260615 PS"}
{"ts_recv":"2026-04-07T02:21:29.770843774Z","hd":{"ts_event":"2026-04-07T02:21:29.770825291Z","rtype":160,"publisher_id":101,"instrument_id":436},"action":"C","side":"A","price":"1.156650000","size":30,"channel_id":23,"order_id":"1775528484120598639","flags":0,"ts_in_delta":948,"sequence":158256,"symbol":"FCEU SI 20260615 PS"}
{"ts_recv":"2026-04-07T02:21:29.770843774Z","hd":{"ts_event":"2026-04-07T02:21:29.770825291Z","rtype":160,"publisher_id":101,"instrument_id":436},"action":"A","side":"A","price":"1.156630000","size":30,"channel_id":23,"order_id":"1775528489770831417","flags":128,"ts_in_delta":948,"sequence":158256,"symbol":"FCEU SI 20260615 PS"}
{"ts_recv":"2026-04-07T02:21:29.770901117Z","hd":{"ts_event":"2026-04-07T02:21:29.770885899Z","rtype":160,"publisher_id":101,"instrument_id":436},"action":"C","side":"B","price":"1.156540000","size":30,"channel_id":23,"order_id":"10998900526625548348","flags":0,"ts_in_delta":731,"sequence":158257,"symbol":"FCEU SI 20260615 PS"}
{"ts_recv":"2026-04-07T02:21:29.770901117Z","hd":{"ts_event":"2026-04-07T02:21:29.770885899Z","rtype":160,"publisher_id":101,"instrument_id":436},"action":"A","side":"B","price":"1.156530000","size":30,"channel_id":23,"order_id":"10998900526625667552","flags":0,"ts_in_delta":731,"sequence":158257,"symbol":"FCEU SI 20260615 PS"}
{"ts_recv":"2026-04-07T02:21:29.770901117Z","hd":{"ts_event":"2026-04-07T02:21:29.770885899Z","rtype":160,"publisher_id":101,"instrument_id":436},"action":"C","side":"A","price":"1.156640000","size":30,"channel_id":23,"order_id":"1775528489770772540","flags":0,"ts_in_delta":731,"sequence":158257,"symbol":"FCEU SI 20260615 PS"}
{"ts_recv":"2026-04-07T02:21:29.770901117Z","hd":{"ts_event":"2026-04-07T02:21:29.770885899Z","rtype":160,"publisher_id":101,"instrument_id":436},"action":"A","side":"A","price":"1.156630000","size":30,"channel_id":23,"order_id":"1775528489770891744","flags":128,"ts_in_delta":731,"sequence":158257,"symbol":"FCEU SI 20260615 PS"}
{"ts_recv":"2026-04-07T02:21:40.975312335Z","hd":{"ts_event":"2026-04-07T02:21:40.975289295Z","rtype":160,"publisher_id":101,"instrument_id":436},"action":"C","side":"B","price":"1.156530000","size":30,"channel_id":23,"order_id":"10998900526625667552","flags":0,"ts_in_delta":1041,"sequence":158329,"symbol":"FCEU SI 20260615 PS"}
{"ts_recv":"2026-04-07T02:21:40.975312335Z","hd":{"ts_event":"2026-04-07T02:21:40.975289295Z","rtype":160,"publisher_id":101,"instrument_id":436},"action":"A","side":"B","price":"1.156520000","size":30,"channel_id":23,"order_id":"10998900537830071402","flags":0,"ts_in_delta":1041,"sequence":158329,"symbol":"FCEU SI 20260615 PS"}
{"ts_recv":"2026-04-07T02:21:40.975312335Z","hd":{"ts_event":"2026-04-07T02:21:40.975289295Z","rtype":160,"publisher_id":101,"instrument_id":436},"action":"C","side":"A","price":"1.156630000","size":30,"channel_id":23,"order_id":"1775528489770891744","flags":0,"ts_in_delta":1041,"sequence":158329,"symbol":"FCEU SI 20260615 PS"}
{"ts_recv":"2026-04-07T02:21:40.975312335Z","hd":{"ts_event":"2026-04-07T02:21:40.975289295Z","rtype":160,"publisher_id":101,"instrument_id":436},"action":"A","side":"A","price":"1.156620000","size":30,"channel_id":23,"order_id":"1775528500975295594","flags":128,"ts_in_delta":1041,"sequence":158329,"symbol":"FCEU SI 20260615 PS"}
{"ts_recv":"2026-04-07T02:21:40.975403945Z","hd":{"ts_event":"2026-04-07T02:21:40.975381629Z","rtype":160,"publisher_id":101,"instrument_id":436},"action":"C","side":"B","price":"1.156520000","size":30,"channel_id":23,"order_id":"10998900537830071402","flags":0,"ts_in_delta":949,"sequence":158330,"symbol":"FCEU SI 20260615 PS"}
{"ts_recv":"2026-04-07T02:21:40.975403945Z","hd":{"ts_event":"2026-04-07T02:21:40.975381629Z","rtype":160,"publisher_id":101,"instrument_id":436},"action":"A","side":"B","price":"1.156510000","size":30,"channel_id":23,"order_id":"10998900537830163649","flags":0,"ts_in_delta":949,"sequence":158330,"symbol":"FCEU SI 20260615 PS"}
{"ts_recv":"2026-04-07T02:21:40.975403945Z","hd":{"ts_event":"2026-04-07T02:21:40.975381629Z","rtype":160,"publisher_id":101,"instrument_id":436},"action":"C","side":"A","price":"1.156620000","size":30,"channel_id":23,"order_id":"1775528500975295594","flags":0,"ts_in_delta":949,"sequence":158330,"symbol":"FCEU SI 20260615 PS"}
{"ts_recv":"2026-04-07T02:21:40.975403945Z","hd":{"ts_event":"2026-04-07T02:21:40.975381629Z","rtype":160,"publisher_id":101,"instrument_id":436},"action":"A","side":"A","price":"1.156610000","size":30,"channel_id":23,"order_id":"1775528500975387841","flags":128,"ts_in_delta":949,"sequence":158330,"symbol":"FCEU SI 20260615 PS"}
{"ts_recv":"2026-04-07T02:21:40.975463754Z","hd":{"ts_event":"2026-04-07T02:21:40.975443759Z","rtype":160,"publisher_id":101,"instrument_id":436},"action":"C","side":"B","price":"1.156510000","size":30,"channel_id":23,"order_id":"10998900537830163649","flags":0,"ts_in_delta":902,"sequence":158331,"symbol":"FCEU SI 20260615 PS"}
{"ts_recv":"2026-04-07T02:21:40.975463754Z","hd":{"ts_event":"2026-04-07T02:21:40.975443759Z","rtype":160,"publisher_id":101,"instrument_id":436},"action":"A","side":"B","price":"1.156520000","size":30,"channel_id":23,"order_id":"10998900537830225806","flags":0,"ts_in_delta":902,"sequence":158331,"symbol":"FCEU SI 20260615 PS"}
{"ts_recv":"2026-04-07T02:21:40.975463754Z","hd":{"ts_event":"2026-04-07T02:21:40.975443759Z","rtype":160,"publisher_id":101,"instrument_id":436},"action":"C","side":"A","price":"1.156610000","size":30,"channel_id":23,"order_id":"1775528500975387841","flags":0,"ts_in_delta":902,"sequence":158331,"symbol":"FCEU SI 20260615 PS"}
{"ts_recv":"2026-04-07T02:21:40.975463754Z","hd":{"ts_event":"2026-04-07T02:21:40.975443759Z","rtype":160,"publisher_id":101,"instrument_id":436},"action":"A","side":"A","price":"1.156620000","size":30,"channel_id":23,"order_id":"1775528500975449998","flags":128,"ts_in_delta":902,"sequence":158331,"symbol":"FCEU SI 20260615 PS"}
{"ts_recv":"2026-04-07T02:21:40.975475635Z","hd":{"ts_event":"2026-04-07T02:21:40.975450865Z","rtype":160,"publisher_id":101,"instrument_id":436},"action":"C","side":"B","price":"1.156530000","size":30,"channel_id":23,"order_id":"10998900526625607225","flags":0,"ts_in_delta":918,"sequence":158332,"symbol":"FCEU SI 20260615 PS"}
{"ts_recv":"2026-04-07T02:21:40.975475635Z","hd":{"ts_event":"2026-04-07T02:21:40.975450865Z","rtype":160,"publisher_id":101,"instrument_id":436},"action":"A","side":"B","price":"1.156510000","size":30,"channel_id":23,"order_id":"10998900537830236193","flags":0,"ts_in_delta":918,"sequence":158332,"symbol":"FCEU SI 20260615 PS"}
{"ts_recv":"2026-04-07T02:21:40.975475635Z","hd":{"ts_event":"2026-04-07T02:21:40.975450865Z","rtype":160,"publisher_id":101,"instrument_id":436},"action":"C","side":"A","price":"1.156630000","size":30,"channel_id":23,"order_id":"1775528489770831417","flags":0,"ts_in_delta":918,"sequence":158332,"symbol":"FCEU SI 20260615 PS"}
{"ts_recv":"2026-04-07T02:21:40.975475635Z","hd":{"ts_event":"2026-04-07T02:21:40.975450865Z","rtype":160,"publisher_id":101,"instrument_id":436},"action":"A","side":"A","price":"1.156610000","size":30,"channel_id":23,"order_id":"1775528500975460385","flags":128,"ts_in_delta":918,"sequence":158332,"symbol":"FCEU SI 20260615 PS"}
{"ts_recv":"2026-04-07T02:21:40.975540006Z","hd":{"ts_event":"2026-04-07T02:21:40.975519811Z","rtype":160,"publisher_id":101,"instrument_id":436},"action":"C","side":"B","price":"1.156520000","size":30,"channel_id":23,"order_id":"10998900537830225806","flags":0,"ts_in_delta":897,"sequence":158333,"symbol":"FCEU SI 20260615 PS"}
{"ts_recv":"2026-04-07T02:21:40.975540006Z","hd":{"ts_event":"2026-04-07T02:21:40.975519811Z","rtype":160,"publisher_id":101,"instrument_id":436},"action":"A","side":"B","price":"1.156510000","size":30,"channel_id":23,"order_id":"10998900537830301171","flags":0,"ts_in_delta":897,"sequence":158333,"symbol":"FCEU SI 20260615 PS"}
{"ts_recv":"2026-04-07T02:21:40.975540006Z","hd":{"ts_event":"2026-04-07T02:21:40.975519811Z","rtype":160,"publisher_id":101,"instrument_id":436},"action":"C","side":"A","price":"1.156620000","size":30,"channel_id":23,"order_id":"1775528500975449998","flags":0,"ts_in_delta":897,"sequence":158333,"symbol":"FCEU SI 20260615 PS"}
{"ts_recv":"2026-04-07T02:21:40.975540006Z","hd":{"ts_event":"2026-04-07T02:21:40.975519811Z","rtype":160,"publisher_id":101,"instrument_id":436},"action":"A","side":"A","price":"1.156610000","size":30,"channel_id":23,"order_id":"1775528500975525363","flags":128,"ts_in_delta":897,"sequence":158333,"symbol":"FCEU SI 20260615 PS"}
{"ts_recv":"2026-04-07T02:21:42.938193361Z","hd":{"ts_event":"2026-04-07T02:21:42.938173355Z","rtype":160,"publisher_id":101,"instrument_id":436},"action":"C","side":"B","price":"1.156510000","size":30,"channel_id":23,"order_id":"10998900537830301171","flags":0,"ts_in_delta":1090,"sequence":158378,"symbol":"FCEU SI 20260615 PS"}
{"ts_recv":"2026-04-07T02:21:42.938193361Z","hd":{"ts_event":"2026-04-07T02:21:42.938173355Z","rtype":160,"publisher_id":101,"instrument_id":436},"action":"A","side":"B","price":"1.156500000","size":30,"channel_id":23,"order_id":"10998900539792955025","flags":0,"ts_in_delta":1090,"sequence":158378,"symbol":"FCEU SI 20260615 PS"}
{"ts_recv":"2026-04-07T02:21:42.938193361Z","hd":{"ts_event":"2026-04-07T02:21:42.938173355Z","rtype":160,"publisher_id":101,"instrument_id":436},"action":"C","side":"A","price":"1.156610000","size":30,"channel_id":23,"order_id":"1775528500975525363","flags":0,"ts_in_delta":1090,"sequence":158378,"symbol":"FCEU SI 20260615 PS"}
{"ts_recv":"2026-04-07T02:21:42.938193361Z","hd":{"ts_event":"2026-04-07T02:21:42.938173355Z","rtype":160,"publisher_id":101,"instrument_id":436},"action":"A","side":"A","price":"1.156600000","size":30,"channel_id":23,"order_id":"1775528502938179217","flags":128,"ts_in_delta":1090,"sequence":158378,"symbol":"FCEU SI 20260615 PS"}
{"ts_recv":"2026-04-07T02:21:42.938255750Z","hd":{"ts_event":"2026-04-07T02:21:42.938238117Z","rtype":160,"publisher_id":101,"instrument_id":436},"action":"C","side":"B","price":"1.156500000","size":30,"channel_id":23,"order_id":"10998900539792955025","flags":0,"ts_in_delta":927,"sequence":158379,"symbol":"FCEU SI 20260615 PS"}
{"ts_recv":"2026-04-07T02:21:42.938255750Z","hd":{"ts_event":"2026-04-07T02:21:42.938238117Z","rtype":160,"publisher_id":101,"instrument_id":436},"action":"A","side":"B","price":"1.156490000","size":30,"channel_id":23,"order_id":"10998900539793019804","flags":0,"ts_in_delta":927,"sequence":158379,"symbol":"FCEU SI 20260615 PS"}
{"ts_recv":"2026-04-07T02:21:42.938255750Z","hd":{"ts_event":"2026-04-07T02:21:42.938238117Z","rtype":160,"publisher_id":101,"instrument_id":436},"action":"C","side":"A","price":"1.156600000","size":30,"channel_id":23,"order_id":"1775528502938179217","flags":0,"ts_in_delta":927,"sequence":158379,"symbol":"FCEU SI 20260615 PS"}
{"ts_recv":"2026-04-07T02:21:42.938255750Z","hd":{"ts_event":"2026-04-07T02:21:42.938238117Z","rtype":160,"publisher_id":101,"instrument_id":436},"action":"A","side":"A","price":"1.156590000","size":30,"channel_id":23,"order_id":"1775528502938243996","flags":128,"ts_in_delta":927,"sequence":158379,"symbol":"FCEU SI 20260615 PS"}
{"ts_recv":"2026-04-07T02:21:42.938305683Z","hd":{"ts_event":"2026-04-07T02:21:42.938286637Z","rtype":160,"publisher_id":101,"instrument_id":436},"action":"C","side":"B","price":"1.156510000","size":30,"channel_id":23,"order_id":"10998900537830236193","flags":0,"ts_in_delta":928,"sequence":158380,"symbol":"FCEU SI 20260615 PS"}
{"ts_recv":"2026-04-07T02:21:42.938305683Z","hd":{"ts_event":"2026-04-07T02:21:42.938286637Z","rtype":160,"publisher_id":101,"instrument_id":436},"action":"A","side":"B","price":"1.156490000","size":30,"channel_id":23,"order_id":"10998900539793068273","flags":0,"ts_in_delta":928,"sequence":158380,"symbol":"FCEU SI 20260615 PS"}
{"ts_recv":"2026-04-07T02:21:42.938305683Z","hd":{"ts_event":"2026-04-07T02:21:42.938286637Z","rtype":160,"publisher_id":101,"instrument_id":436},"action":"C","side":"A","price":"1.156610000","size":30,"channel_id":23,"order_id":"1775528500975460385","flags":0,"ts_in_delta":928,"sequence":158380,"symbol":"FCEU SI 20260615 PS"}
{"ts_recv":"2026-04-07T02:21:42.938305683Z","hd":{"ts_event":"2026-04-07T02:21:42.938286637Z","rtype":160,"publisher_id":101,"instrument_id":436},"action":"A","side":"A","price":"1.156590000","size":30,"channel_id":23,"order_id":"1775528502938292465","flags":128,"ts_in_delta":928,"sequence":158380,"symbol":"FCEU SI 20260615 PS"}
{"ts_recv":"2026-04-07T02:21:42.938316028Z","hd":{"ts_event":"2026-04-07T02:21:42.938295135Z","rtype":160,"publisher_id":101,"instrument_id":436},"action":"C","side":"B","price":"1.156490000","size":30,"channel_id":23,"order_id":"10998900539793019804","flags":0,"ts_in_delta":1040,"sequence":158381,"symbol":"FCEU SI 20260615 PS"}
{"ts_recv":"2026-04-07T02:21:42.938316028Z","hd":{"ts_event":"2026-04-07T02:21:42.938295135Z","rtype":160,"publisher_id":101,"instrument_id":436},"action":"A","side":"B","price":"1.156500000","size":30,"channel_id":23,"order_id":"10998900539793078066","flags":0,"ts_in_delta":1040,"sequence":158381,"symbol":"FCEU SI 20260615 PS"}
{"ts_recv":"2026-04-07T02:21:42.938316028Z","hd":{"ts_event":"2026-04-07T02:21:42.938295135Z","rtype":160,"publisher_id":101,"instrument_id":436},"action":"C","side":"A","price":"1.156590000","size":30,"channel_id":23,"order_id":"1775528502938243996","flags":0,"ts_in_delta":1040,"sequence":158381,"symbol":"FCEU SI 20260615 PS"}
{"ts_recv":"2026-04-07T02:21:42.938316028Z","hd":{"ts_event":"2026-04-07T02:21:42.938295135Z","rtype":160,"publisher_id":101,"instrument_id":436},"action":"A","side":"A","price":"1.156600000","size":30,"channel_id":23,"order_id":"1775528502938302258","flags":128,"ts_in_delta":1040,"sequence":158381,"symbol":"FCEU SI 20260615 PS"}
{"ts_recv":"2026-04-07T02:21:42.938368526Z","hd":{"ts_event":"2026-04-07T02:21:42.938353165Z","rtype":160,"publisher_id":101,"instrument_id":436},"action":"C","side":"B","price":"1.156500000","size":30,"channel_id":23,"order_id":"10998900539793078066","flags":0,"ts_in_delta":1079,"sequence":158382,"symbol":"FCEU SI 20260615 PS"}
{"ts_recv":"2026-04-07T02:21:42.938368526Z","hd":{"ts_event":"2026-04-07T02:21:42.938353165Z","rtype":160,"publisher_id":101,"instrument_id":436},"action":"A","side":"B","price":"1.156490000","size":30,"channel_id":23,"order_id":"10998900539793134823","flags":0,"ts_in_delta":1079,"sequence":158382,"symbol":"FCEU SI 20260615 PS"}
{"ts_recv":"2026-04-07T02:21:42.938368526Z","hd":{"ts_event":"2026-04-07T02:21:42.938353165Z","rtype":160,"publisher_id":101,"instrument_id":436},"action":"C","side":"A","price":"1.156600000","size":30,"channel_id":23,"order_id":"1775528502938302258","flags":0,"ts_in_delta":1079,"sequence":158382,"symbol":"FCEU SI 20260615 PS"}
{"ts_recv":"2026-04-07T02:21:42.938368526Z","hd":{"ts_event":"2026-04-07T02:21:42.938353165Z","rtype":160,"publisher_id":101,"instrument_id":436},"action":"A","side":"A","price":"1.156590000","size":30,"channel_id":23,"order_id":"1775528502938359015","flags":128,"ts_in_delta":1079,"sequence":158382,"symbol":"FCEU SI 20260615 PS"}
{"ts_recv":"2026-04-07T02:21:43.883449010Z","hd":{"ts_event":"2026-04-07T02:21:43.883428669Z","rtype":160,"publisher_id":101,"instrument_id":436},"action":"C","side":"B","price":"1.156490000","size":30,"channel_id":23,"order_id":"10998900539793134823","flags":0,"ts_in_delta":951,"sequence":158410,"symbol":"FCEU SI 20260615 PS"}
{"ts_recv":"2026-04-07T02:21:43.883449010Z","hd":{"ts_event":"2026-04-07T02:21:43.883428669Z","rtype":160,"publisher_id":101,"instrument_id":436},"action":"A","side":"B","price":"1.156500000","size":30,"channel_id":23,"order_id":"10998900540738210776","flags":0,"ts_in_delta":951,"sequence":158410,"symbol":"FCEU SI 20260615 PS"}
{"ts_recv":"2026-04-07T02:21:43.883449010Z","hd":{"ts_event":"2026-04-07T02:21:43.883428669Z","rtype":160,"publisher_id":101,"instrument_id":436},"action":"C","side":"A","price":"1.156590000","size":30,"channel_id":23,"order_id":"1775528502938359015","flags":0,"ts_in_delta":951,"sequence":158410,"symbol":"FCEU SI 20260615 PS"}
{"ts_recv":"2026-04-07T02:21:43.883449010Z","hd":{"ts_event":"2026-04-07T02:21:43.883428669Z","rtype":160,"publisher_id":101,"instrument_id":436},"action":"A","side":"A","price":"1.156600000","size":30,"channel_id":23,"order_id":"1775528503883434968","flags":128,"ts_in_delta":951,"sequence":158410,"symbol":"FCEU SI 20260615 PS"}
{"ts_recv":"2026-04-07T02:21:43.883502391Z","hd":{"ts_event":"2026-04-07T02:21:43.883484087Z","rtype":160,"publisher_id":101,"instrument_id":436},"action":"C","side":"B","price":"1.156490000","size":30,"channel_id":23,"order_id":"10998900539793068273","flags":0,"ts_in_delta":960,"sequence":158411,"symbol":"FCEU SI 20260615 PS"}
{"ts_recv":"2026-04-07T02:21:43.883502391Z","hd":{"ts_event":"2026-04-07T02:21:43.883484087Z","rtype":160,"publisher_id":101,"instrument_id":436},"action":"A","side":"B","price":"1.156510000","size":30,"channel_id":23,"order_id":"10998900540738266002","flags":0,"ts_in_delta":960,"sequence":158411,"symbol":"FCEU SI 20260615 PS"}
{"ts_recv":"2026-04-07T02:21:43.883502391Z","hd":{"ts_event":"2026-04-07T02:21:43.883484087Z","rtype":160,"publisher_id":101,"instrument_id":436},"action":"C","side":"A","price":"1.156590000","size":30,"channel_id":23,"order_id":"1775528502938292465","flags":0,"ts_in_delta":960,"sequence":158411,"symbol":"FCEU SI 20260615 PS"}
{"ts_recv":"2026-04-07T02:21:43.883502391Z","hd":{"ts_event":"2026-04-07T02:21:43.883484087Z","rtype":160,"publisher_id":101,"instrument_id":436},"action":"A","side":"A","price":"1.156610000","size":30,"channel_id":23,"order_id":"1775528503883490194","flags":128,"ts_in_delta":960,"sequence":158411,"symbol":"FCEU SI 20260615 PS"}
{"ts_recv":"2026-04-07T02:21:43.883557585Z","hd":{"ts_event":"2026-04-07T02:21:43.883540067Z","rtype":160,"publisher_id":101,"instrument_id":436},"action":"C","side":"B","price":"1.156500000","size":30,"channel_id":23,"order_id":"10998900540738210776","flags":0,"ts_in_delta":1082,"sequence":158412,"symbol":"FCEU SI 20260615 PS"}
{"ts_recv":"2026-04-07T02:21:43.883557585Z","hd":{"ts_event":"2026-04-07T02:21:43.883540067Z","rtype":160,"publisher_id":101,"instrument_id":436},"action":"A","side":"B","price":"1.156510000","size":30,"channel_id":23,"order_id":"10998900540738321613","flags":0,"ts_in_delta":1082,"sequence":158412,"symbol":"FCEU SI 20260615 PS"}
{"ts_recv":"2026-04-07T02:21:43.883557585Z","hd":{"ts_event":"2026-04-07T02:21:43.883540067Z","rtype":160,"publisher_id":101,"instrument_id":436},"action":"C","side":"A","price":"1.156600000","size":30,"channel_id":23,"order_id":"1775528503883434968","flags":0,"ts_in_delta":1082,"sequence":158412,"symbol":"FCEU SI 20260615 PS"}
{"ts_recv":"2026-04-07T02:21:43.883557585Z","hd":{"ts_event":"2026-04-07T02:21:43.883540067Z","rtype":160,"publisher_id":101,"instrument_id":436},"action":"A","side":"A","price":"1.156610000","size":30,"channel_id":23,"order_id":"1775528503883545805","flags":128,"ts_in_delta":1082,"sequence":158412,"symbol":"FCEU SI 20260615 PS"}
{"ts_recv":"2026-04-07T02:21:43.888939728Z","hd":{"ts_event":"2026-04-07T02:21:43.888920081Z","rtype":160,"publisher_id":101,"instrument_id":436},"action":"C","side":"B","price":"1.156510000","size":30,"channel_id":23,"order_id":"10998900540738321613","flags":0,"ts_in_delta":927,"sequence":158415,"symbol":"FCEU SI 20260615 PS"}
{"ts_recv":"2026-04-07T02:21:43.888939728Z","hd":{"ts_event":"2026-04-07T02:21:43.888920081Z","rtype":160,"publisher_id":101,"instrument_id":436},"action":"A","side":"B","price":"1.156520000","size":30,"channel_id":23,"order_id":"10998900540743701954","flags":0,"ts_in_delta":927,"sequence":158415,"symbol":"FCEU SI 20260615 PS"}
{"ts_recv":"2026-04-07T02:21:43.888939728Z","hd":{"ts_event":"2026-04-07T02:21:43.888920081Z","rtype":160,"publisher_id":101,"instrument_id":436},"action":"C","side":"A","price":"1.156610000","size":30,"channel_id":23,"order_id":"1775528503883545805","flags":0,"ts_in_delta":927,"sequence":158415,"symbol":"FCEU SI 20260615 PS"}
{"ts_recv":"2026-04-07T02:21:43.888939728Z","hd":{"ts_event":"2026-04-07T02:21:43.888920081Z","rtype":160,"publisher_id":101,"instrument_id":436},"action":"A","side":"A","price":"1.156620000","size":30,"channel_id":23,"order_id":"1775528503888926146","flags":128,"ts_in_delta":927,"sequence":158415,"symbol":"FCEU SI 20260615 PS"}
{"ts_recv":"2026-04-07T02:21:43.977605041Z","hd":{"ts_event":"2026-04-07T02:21:43.977584523Z","rtype":160,"publisher_id":101,"instrument_id":436},"action":"C","side":"B","price":"1.156510000","size":30,"channel_id":23,"order_id":"10998900540738266002","flags":0,"ts_in_delta":947,"sequence":158428,"symbol":"FCEU SI 20260615 PS"}
{"ts_recv":"2026-04-07T02:21:43.977605041Z","hd":{"ts_event":"2026-04-07T02:21:43.977584523Z","rtype":160,"publisher_id":101,"instrument_id":436},"action":"A","side":"B","price":"1.156530000","size":30,"channel_id":23,"order_id":"10998900540832366631","flags":0,"ts_in_delta":947,"sequence":158428,"symbol":"FCEU SI 20260615 PS"}
{"ts_recv":"2026-04-07T02:21:43.977605041Z","hd":{"ts_event":"2026-04-07T02:21:43.977584523Z","rtype":160,"publisher_id":101,"instrument_id":436},"action":"C","side":"A","price":"1.156610000","size":30,"channel_id":23,"order_id":"1775528503883490194","flags":0,"ts_in_delta":947,"sequence":158428,"symbol":"FCEU SI 20260615 PS"}
{"ts_recv":"2026-04-07T02:21:43.977605041Z","hd":{"ts_event":"2026-04-07T02:21:43.977584523Z","rtype":160,"publisher_id":101,"instrument_id":436},"action":"A","side":"A","price":"1.156630000","size":30,"channel_id":23,"order_id":"1775528503977590823","flags":128,"ts_in_delta":947,"sequence":158428,"symbol":"FCEU SI 20260615 PS"}
{"ts_recv":"2026-04-07T02:21:43.977670502Z","hd":{"ts_event":"2026-04-07T02:21:43.977651621Z","rtype":160,"publisher_id":101,"instrument_id":436},"action":"C","side":"B","price":"1.156520000","size":30,"channel_id":23,"order_id":"10998900540743701954","flags":0,"ts_in_delta":1117,"sequence":158429,"symbol":"FCEU SI 20260615 PS"}
{"ts_recv":"2026-04-07T02:21:43.977670502Z","hd":{"ts_event":"2026-04-07T02:21:43.977651621Z","rtype":160,"publisher_id":101,"instrument_id":436},"action":"A","side":"B","price":"1.156530000","size":30,"channel_id":23,"order_id":"10998900540832433469","flags":0,"ts_in_delta":1117,"sequence":158429,"symbol":"FCEU SI 20260615 PS"}
{"ts_recv":"2026-04-07T02:21:43.977670502Z","hd":{"ts_event":"2026-04-07T02:21:43.977651621Z","rtype":160,"publisher_id":101,"instrument_id":436},"action":"C","side":"A","price":"1.156620000","size":30,"channel_id":23,"order_id":"1775528503888926146","flags":0,"ts_in_delta":1117,"sequence":158429,"symbol":"FCEU SI 20260615 PS"}
{"ts_recv":"2026-04-07T02:21:43.977670502Z","hd":{"ts_event":"2026-04-07T02:21:43.977651621Z","rtype":160,"publisher_id":101,"instrument_id":436},"action":"A","side":"A","price":"1.156630000","size":30,"channel_id":23,"order_id":"1775528503977657661","flags":128,"ts_in_delta":1117,"sequence":158429,"symbol":"FCEU SI 20260615 PS"}
{"ts_recv":"2026-04-07T02:21:53.203499877Z","hd":{"ts_event":"2026-04-07T02:21:53.203479131Z","rtype":160,"publisher_id":101,"instrument_id":436},"action":"C","side":"B","price":"1.156530000","size":30,"channel_id":23,"order_id":"10998900540832433469","flags":0,"ts_in_delta":904,"sequence":158472,"symbol":"FCEU SI 20260615 PS"}
{"ts_recv":"2026-04-07T02:21:53.203499877Z","hd":{"ts_event":"2026-04-07T02:21:53.203479131Z","rtype":160,"publisher_id":101,"instrument_id":436},"action":"A","side":"B","price":"1.156520000","size":30,"channel_id":23,"order_id":"10998900550058260885","flags":0,"ts_in_delta":904,"sequence":158472,"symbol":"FCEU SI 20260615 PS"}
{"ts_recv":"2026-04-07T02:21:53.203499877Z","hd":{"ts_event":"2026-04-07T02:21:53.203479131Z","rtype":160,"publisher_id":101,"instrument_id":436},"action":"C","side":"A","price":"1.156630000","size":30,"channel_id":23,"order_id":"1775528503977657661","flags":0,"ts_in_delta":904,"sequence":158472,"symbol":"FCEU SI 20260615 PS"}
{"ts_recv":"2026-04-07T02:21:53.203499877Z","hd":{"ts_event":"2026-04-07T02:21:53.203479131Z","rtype":160,"publisher_id":101,"instrument_id":436},"action":"A","side":"A","price":"1.156620000","size":30,"channel_id":23,"order_id":"1775528513203485077","flags":128,"ts_in_delta":904,"sequence":158472,"symbol":"FCEU SI 20260615 PS"}
{"ts_recv":"2026-04-07T02:21:56.169006340Z","hd":{"ts_event":"2026-04-07T02:21:56.168985431Z","rtype":160,"publisher_id":101,"instrument_id":436},"action":"C","side":"B","price":"1.156530000","size":30,"channel_id":23,"order_id":"10998900540832366631","flags":0,"ts_in_delta":989,"sequence":158485,"symbol":"FCEU SI 20260615 PS"}
{"ts_recv":"2026-04-07T02:21:56.169006340Z","hd":{"ts_event":"2026-04-07T02:21:56.168985431Z","rtype":160,"publisher_id":101,"instrument_id":436},"action":"A","side":"B","price":"1.156510000","size":30,"channel_id":23,"order_id":"10998900553023767439","flags":0,"ts_in_delta":989,"sequence":158485,"symbol":"FCEU SI 20260615 PS"}
{"ts_recv":"2026-04-07T02:21:56.169006340Z","hd":{"ts_event":"2026-04-07T02:21:56.168985431Z","rtype":160,"publisher_id":101,"instrument_id":436},"action":"C","side":"A","price":"1.156630000","size":30,"channel_id":23,"order_id":"1775528503977590823","flags":0,"ts_in_delta":989,"sequence":158485,"symbol":"FCEU SI 20260615 PS"}
{"ts_recv":"2026-04-07T02:21:56.169006340Z","hd":{"ts_event":"2026-04-07T02:21:56.168985431Z","rtype":160,"publisher_id":101,"instrument_id":436},"action":"A","side":"A","price":"1.156610000","size":30,"channel_id":23,"order_id":"1775528516168991631","flags":128,"ts_in_delta":989,"sequence":158485,"symbol":"FCEU SI 20260615 PS"}
{"ts_recv":"2026-04-07T02:21:56.169083351Z","hd":{"ts_event":"2026-04-07T02:21:56.169066957Z","rtype":160,"publisher_id":101,"instrument_id":436},"action":"C","side":"B","price":"1.156520000","size":30,"channel_id":23,"order_id":"10998900550058260885","flags":0,"ts_in_delta":960,"sequence":158486,"symbol":"FCEU SI 20260615 PS"}
{"ts_recv":"2026-04-07T02:21:56.169083351Z","hd":{"ts_event":"2026-04-07T02:21:56.169066957Z","rtype":160,"publisher_id":101,"instrument_id":436},"action":"A","side":"B","price":"1.156510000","size":30,"channel_id":23,"order_id":"10998900553023848871","flags":0,"ts_in_delta":960,"sequence":158486,"symbol":"FCEU SI 20260615 PS"}
{"ts_recv":"2026-04-07T02:21:56.169083351Z","hd":{"ts_event":"2026-04-07T02:21:56.169066957Z","rtype":160,"publisher_id":101,"instrument_id":436},"action":"C","side":"A","price":"1.156620000","size":30,"channel_id":23,"order_id":"1775528513203485077","flags":0,"ts_in_delta":960,"sequence":158486,"symbol":"FCEU SI 20260615 PS"}
{"ts_recv":"2026-04-07T02:21:56.169083351Z","hd":{"ts_event":"2026-04-07T02:21:56.169066957Z","rtype":160,"publisher_id":101,"instrument_id":436},"action":"A","side":"A","price":"1.156610000","size":30,"channel_id":23,"order_id":"1775528516169073063","flags":128,"ts_in_delta":960,"sequence":158486,"symbol":"FCEU SI 20260615 PS"}
{"ts_recv":"2026-04-07T02:22:00.818096879Z","hd":{"ts_event":"2026-04-07T02:22:00.818062767Z","rtype":160,"publisher_id":101,"instrument_id":436},"action":"C","side":"B","price":"1.156510000","size":30,"channel_id":23,"order_id":"10998900553023848871","flags":0,"ts_in_delta":1293,"sequence":158504,"symbol":"FCEU SI 20260615 PS"}
{"ts_recv":"2026-04-07T02:22:00.818096879Z","hd":{"ts_event":"2026-04-07T02:22:00.818062767Z","rtype":160,"publisher_id":101,"instrument_id":436},"action":"A","side":"B","price":"1.156500000","size":30,"channel_id":23,"order_id":"10998900557672851680","flags":0,"ts_in_delta":1293,"sequence":158504,"symbol":"FCEU SI 20260615 PS"}
{"ts_recv":"2026-04-07T02:22:00.818096879Z","hd":{"ts_event":"2026-04-07T02:22:00.818062767Z","rtype":160,"publisher_id":101,"instrument_id":436},"action":"C","side":"A","price":"1.156610000","size":30,"channel_id":23,"order_id":"1775528516169073063","flags":0,"ts_in_delta":1293,"sequence":158504,"symbol":"FCEU SI 20260615 PS"}
{"ts_recv":"2026-04-07T02:22:00.818096879Z","hd":{"ts_event":"2026-04-07T02:22:00.818062767Z","rtype":160,"publisher_id":101,"instrument_id":436},"action":"A","side":"A","price":"1.156600000","size":30,"channel_id":23,"order_id":"1775528520818075872","flags":128,"ts_in_delta":1293,"sequence":158504,"symbol":"FCEU SI 20260615 PS"}
{"ts_recv":"2026-04-07T02:22:00.827891809Z","hd":{"ts_event":"2026-04-07T02:22:00.827867925Z","rtype":160,"publisher_id":101,"instrument_id":436},"action":"C","side":"B","price":"1.156510000","size":30,"channel_id":23,"order_id":"10998900553023767439","flags":0,"ts_in_delta":908,"sequence":158507,"symbol":"FCEU SI 20260615 PS"}
{"ts_recv":"2026-04-07T02:22:00.827891809Z","hd":{"ts_event":"2026-04-07T02:22:00.827867925Z","rtype":160,"publisher_id":101,"instrument_id":436},"action":"A","side":"B","price":"1.156490000","size":30,"channel_id":23,"order_id":"10998900557682650100","flags":0,"ts_in_delta":908,"sequence":158507,"symbol":"FCEU SI 20260615 PS"}
{"ts_recv":"2026-04-07T02:22:00.827891809Z","hd":{"ts_event":"2026-04-07T02:22:00.827867925Z","rtype":160,"publisher_id":101,"instrument_id":436},"action":"C","side":"A","price":"1.156610000","size":30,"channel_id":23,"order_id":"1775528516168991631","flags":0,"ts_in_delta":908,"sequence":158507,"symbol":"FCEU SI 20260615 PS"}
{"ts_recv":"2026-04-07T02:22:00.827891809Z","hd":{"ts_event":"2026-04-07T02:22:00.827867925Z","rtype":160,"publisher_id":101,"instrument_id":436},"action":"A","side":"A","price":"1.156590000","size":30,"channel_id":23,"order_id":"1775528520827874292","flags":128,"ts_in_delta":908,"sequence":158507,"symbol":"FCEU SI 20260615 PS"}
{"ts_recv":"2026-04-07T02:22:00.827963253Z","hd":{"ts_event":"2026-04-07T02:22:00.827944055Z","rtype":160,"publisher_id":101,"instrument_id":436},"action":"C","side":"B","price":"1.156500000","size":30,"channel_id":23,"order_id":"10998900557672851680","flags":0,"ts_in_delta":880,"sequence":158508,"symbol":"FCEU SI 20260615 PS"}
{"ts_recv":"2026-04-07T02:22:00.827963253Z","hd":{"ts_event":"2026-04-07T02:22:00.827944055Z","rtype":160,"publisher_id":101,"instrument_id":436},"action":"A","side":"B","price":"1.156490000","size":30,"channel_id":23,"order_id":"10998900557682725951","flags":0,"ts_in_delta":880,"sequence":158508,"symbol":"FCEU SI 20260615 PS"}
{"ts_recv":"2026-04-07T02:22:00.827963253Z","hd":{"ts_event":"2026-04-07T02:22:00.827944055Z","rtype":160,"publisher_id":101,"instrument_id":436},"action":"C","side":"A","price":"1.156600000","size":30,"channel_id":23,"order_id":"1775528520818075872","flags":0,"ts_in_delta":880,"sequence":158508,"symbol":"FCEU SI 20260615 PS"}
{"ts_recv":"2026-04-07T02:22:00.827963253Z","hd":{"ts_event":"2026-04-07T02:22:00.827944055Z","rtype":160,"publisher_id":101,"instrument_id":436},"action":"A","side":"A","price":"1.156590000","size":30,"channel_id":23,"order_id":"1775528520827950143","flags":128,"ts_in_delta":880,"sequence":158508,"symbol":"FCEU SI 20260615 PS"}
{"ts_recv":"2026-04-07T02:22:14.741870794Z","hd":{"ts_event":"2026-04-07T02:22:14.741847291Z","rtype":160,"publisher_id":101,"instrument_id":436},"action":"C","side":"B","price":"1.156490000","size":30,"channel_id":23,"order_id":"10998900557682650100","flags":0,"ts_in_delta":958,"sequence":158655,"symbol":"FCEU SI 20260615 PS"}
{"ts_recv":"2026-04-07T02:22:14.741870794Z","hd":{"ts_event":"2026-04-07T02:22:14.741847291Z","rtype":160,"publisher_id":101,"instrument_id":436},"action":"A","side":"B","price":"1.156470000","size":30,"channel_id":23,"order_id":"10998900571596629752","flags":0,"ts_in_delta":958,"sequence":158655,"symbol":"FCEU SI 20260615 PS"}
{"ts_recv":"2026-04-07T02:22:14.741870794Z","hd":{"ts_event":"2026-04-07T02:22:14.741847291Z","rtype":160,"publisher_id":101,"instrument_id":436},"action":"C","side":"A","price":"1.156590000","size":30,"channel_id":23,"order_id":"1775528520827874292","flags":0,"ts_in_delta":958,"sequence":158655,"symbol":"FCEU SI 20260615 PS"}
{"ts_recv":"2026-04-07T02:22:14.741870794Z","hd":{"ts_event":"2026-04-07T02:22:14.741847291Z","rtype":160,"publisher_id":101,"instrument_id":436},"action":"A","side":"A","price":"1.156570000","size":30,"channel_id":23,"order_id":"1775528534741853944","flags":128,"ts_in_delta":958,"sequence":158655,"symbol":"FCEU SI 20260615 PS"}
{"ts_recv":"2026-04-07T02:22:14.741939089Z","hd":{"ts_event":"2026-04-07T02:22:14.741922639Z","rtype":160,"publisher_id":101,"instrument_id":436},"action":"C","side":"B","price":"1.156490000","size":30,"channel_id":23,"order_id":"10998900557682725951","flags":0,"ts_in_delta":934,"sequence":158656,"symbol":"FCEU SI 20260615 PS"}
{"ts_recv":"2026-04-07T02:22:14.741939089Z","hd":{"ts_event":"2026-04-07T02:22:14.741922639Z","rtype":160,"publisher_id":101,"instrument_id":436},"action":"A","side":"B","price":"1.156480000","size":30,"channel_id":23,"order_id":"10998900571596704467","flags":0,"ts_in_delta":934,"sequence":158656,"symbol":"FCEU SI 20260615 PS"}
{"ts_recv":"2026-04-07T02:22:14.741939089Z","hd":{"ts_event":"2026-04-07T02:22:14.741922639Z","rtype":160,"publisher_id":101,"instrument_id":436},"action":"C","side":"A","price":"1.156590000","size":30,"channel_id":23,"order_id":"1775528520827950143","flags":0,"ts_in_delta":934,"sequence":158656,"symbol":"FCEU SI 20260615 PS"}
{"ts_recv":"2026-04-07T02:22:14.741939089Z","hd":{"ts_event":"2026-04-07T02:22:14.741922639Z","rtype":160,"publisher_id":101,"instrument_id":436},"action":"A","side":"A","price":"1.156580000","size":30,"channel_id":23,"order_id":"1775528534741928659","flags":128,"ts_in_delta":934,"sequence":158656,"symbol":"FCEU SI 20260615 PS"}
{"ts_recv":"2026-04-07T02:22:14.745383933Z","hd":{"ts_event":"2026-04-07T02:22:14.745363897Z","rtype":160,"publisher_id":101,"instrument_id":436},"action":"C","side":"B","price":"1.156480000","size":30,"channel_id":23,"order_id":"10998900571596704467","flags":0,"ts_in_delta":917,"sequence":158659,"symbol":"FCEU SI 20260615 PS"}
{"ts_recv":"2026-04-07T02:22:14.745383933Z","hd":{"ts_event":"2026-04-07T02:22:14.745363897Z","rtype":160,"publisher_id":101,"instrument_id":436},"action":"A","side":"B","price":"1.156470000","size":30,"channel_id":23,"order_id":"10998900571600145610","flags":0,"ts_in_delta":917,"sequence":158659,"symbol":"FCEU SI 20260615 PS"}
{"ts_recv":"2026-04-07T02:22:14.745383933Z","hd":{"ts_event":"2026-04-07T02:22:14.745363897Z","rtype":160,"publisher_id":101,"instrument_id":436},"action":"C","side":"A","price":"1.156580000","size":30,"channel_id":23,"order_id":"1775528534741928659","flags":0,"ts_in_delta":917,"sequence":158659,"symbol":"FCEU SI 20260615 PS"}
{"ts_recv":"2026-04-07T02:22:14.745383933Z","hd":{"ts_event":"2026-04-07T02:22:14.745363897Z","rtype":160,"publisher_id":101,"instrument_id":436},"action":"A","side":"A","price":"1.156570000","size":30,"channel_id":23,"order_id":"1775528534745369802","flags":128,"ts_in_delta":917,"sequence":158659,"symbol":"FCEU SI 20260615 PS"}
{"ts_recv":"2026-04-07T02:22:14.773297681Z","hd":{"ts_event":"2026-04-07T02:22:14.773277903Z","rtype":160,"publisher_id":101,"instrument_id":436},"action":"C","side":"B","price":"1.156470000","size":30,"channel_id":23,"order_id":"10998900571600145610","flags":0,"ts_in_delta":800,"sequence":158674,"symbol":"FCEU SI 20260615 PS"}
{"ts_recv":"2026-04-07T02:22:14.773297681Z","hd":{"ts_event":"2026-04-07T02:22:14.773277903Z","rtype":160,"publisher_id":101,"instrument_id":436},"action":"A","side":"B","price":"1.156460000","size":30,"channel_id":23,"order_id":"10998900571628059551","flags":0,"ts_in_delta":800,"sequence":158674,"symbol":"FCEU SI 20260615 PS"}
{"ts_recv":"2026-04-07T02:22:14.773297681Z","hd":{"ts_event":"2026-04-07T02:22:14.773277903Z","rtype":160,"publisher_id":101,"instrument_id":436},"action":"C","side":"A","price":"1.156570000","size":30,"channel_id":23,"order_id":"1775528534745369802","flags":0,"ts_in_delta":800,"sequence":158674,"symbol":"FCEU SI 20260615 PS"}
{"ts_recv":"2026-04-07T02:22:14.773297681Z","hd":{"ts_event":"2026-04-07T02:22:14.773277903Z","rtype":160,"publisher_id":101,"instrument_id":436},"action":"A","side":"A","price":"1.156560000","size":30,"channel_id":23,"order_id":"1775528534773283743","flags":128,"ts_in_delta":800,"sequence":158674,"symbol":"FCEU SI 20260615 PS"}
{"ts_recv":"2026-04-07T02:22:14.773384200Z","hd":{"ts_event":"2026-04-07T02:22:14.773365711Z","rtype":160,"publisher_id":101,"instrument_id":436},"action":"C","side":"B","price":"1.156460000","size":30,"channel_id":23,"order_id":"10998900571628059551","flags":0,"ts_in_delta":737,"sequence":158675,"symbol":"FCEU SI 20260615 PS"}
{"ts_recv":"2026-04-07T02:22:14.773384200Z","hd":{"ts_event":"2026-04-07T02:22:14.773365711Z","rtype":160,"publisher_id":101,"instrument_id":436},"action":"A","side":"B","price":"1.156450000","size":30,"channel_id":23,"order_id":"10998900571628147264","flags":0,"ts_in_delta":737,"sequence":158675,"symbol":"FCEU SI 20260615 PS"}
{"ts_recv":"2026-04-07T02:22:14.773384200Z","hd":{"ts_event":"2026-04-07T02:22:14.773365711Z","rtype":160,"publisher_id":101,"instrument_id":436},"action":"C","side":"A","price":"1.156560000","size":30,"channel_id":23,"order_id":"1775528534773283743","flags":0,"ts_in_delta":737,"sequence":158675,"symbol":"FCEU SI 20260615 PS"}
{"ts_recv":"2026-04-07T02:22:14.773384200Z","hd":{"ts_event":"2026-04-07T02:22:14.773365711Z","rtype":160,"publisher_id":101,"instrument_id":436},"action":"A","side":"A","price":"1.156550000","size":30,"channel_id":23,"order_id":"1775528534773371456","flags":128,"ts_in_delta":737,"sequence":158675,"symbol":"FCEU SI 20260615 PS"}
{"ts_recv":"2026-04-07T02:22:14.773446497Z","hd":{"ts_event":"2026-04-07T02:22:14.773428067Z","rtype":160,"publisher_id":101,"instrument_id":436},"action":"C","side":"B","price":"1.156450000","size":30,"channel_id":23,"order_id":"10998900571628147264","flags":0,"ts_in_delta":762,"sequence":158676,"symbol":"FCEU SI 20260615 PS"}
{"ts_recv":"2026-04-07T02:22:14.773446497Z","hd":{"ts_event":"2026-04-07T02:22:14.773428067Z","rtype":160,"publisher_id":101,"instrument_id":436},"action":"A","side":"B","price":"1.156460000","size":30,"channel_id":23,"order_id":"10998900571628210137","flags":0,"ts_in_delta":762,"sequence":158676,"symbol":"FCEU SI 20260615 PS"}
{"ts_recv":"2026-04-07T02:22:14.773446497Z","hd":{"ts_event":"2026-04-07T02:22:14.773428067Z","rtype":160,"publisher_id":101,"instrument_id":436},"action":"C","side":"A","price":"1.156550000","size":30,"channel_id":23,"order_id":"1775528534773371456","flags":0,"ts_in_delta":762,"sequence":158676,"symbol":"FCEU SI 20260615 PS"}
{"ts_recv":"2026-04-07T02:22:14.773446497Z","hd":{"ts_event":"2026-04-07T02:22:14.773428067Z","rtype":160,"publisher_id":101,"instrument_id":436},"action":"A","side":"A","price":"1.156560000","size":30,"channel_id":23,"order_id":"1775528534773434329","flags":128,"ts_in_delta":762,"sequence":158676,"symbol":"FCEU SI 20260615 PS"}
{"ts_recv":"2026-04-07T02:22:15.401398518Z","hd":{"ts_event":"2026-04-07T02:22:15.401382667Z","rtype":160,"publisher_id":101,"instrument_id":436},"action":"A","side":"A","price":"1.156700000","size":20,"channel_id":23,"order_id":"1775528535401389357","flags":128,"ts_in_delta":1506,"sequence":158724,"symbol":"FCEU SI 20260615 PS"}
{"ts_recv":"2026-04-07T02:22:15.401419138Z","hd":{"ts_event":"2026-04-07T02:22:15.401405457Z","rtype":160,"publisher_id":101,"instrument_id":436},"action":"C","side":"A","price":"1.156800000","size":20,"channel_id":23,"order_id":"1775528451313675253","flags":128,"ts_in_delta":885,"sequence":158725,"symbol":"FCEU SI 20260615 PS"}
{"ts_recv":"2026-04-07T02:22:22.769959067Z","hd":{"ts_event":"2026-04-07T02:22:22.769930331Z","rtype":160,"publisher_id":101,"instrument_id":436},"action":"C","side":"B","price":"1.156460000","size":30,"channel_id":23,"order_id":"10998900571628210137","flags":0,"ts_in_delta":1253,"sequence":158802,"symbol":"FCEU SI 20260615 PS"}
{"ts_recv":"2026-04-07T02:22:22.769959067Z","hd":{"ts_event":"2026-04-07T02:22:22.769930331Z","rtype":160,"publisher_id":101,"instrument_id":436},"action":"A","side":"B","price":"1.156470000","size":30,"channel_id":23,"order_id":"10998900579624717113","flags":0,"ts_in_delta":1253,"sequence":158802,"symbol":"FCEU SI 20260615 PS"}
{"ts_recv":"2026-04-07T02:22:22.769959067Z","hd":{"ts_event":"2026-04-07T02:22:22.769930331Z","rtype":160,"publisher_id":101,"instrument_id":436},"action":"C","side":"A","price":"1.156560000","size":30,"channel_id":23,"order_id":"1775528534773434329","flags":0,"ts_in_delta":1253,"sequence":158802,"symbol":"FCEU SI 20260615 PS"}
{"ts_recv":"2026-04-07T02:22:22.769959067Z","hd":{"ts_event":"2026-04-07T02:22:22.769930331Z","rtype":160,"publisher_id":101,"instrument_id":436},"action":"A","side":"A","price":"1.156570000","size":30,"channel_id":23,"order_id":"1775528542769941305","flags":128,"ts_in_delta":1253,"sequence":158802,"symbol":"FCEU SI 20260615 PS"}
{"ts_recv":"2026-04-07T02:22:31.691579447Z","hd":{"ts_event":"2026-04-07T02:22:31.691556969Z","rtype":160,"publisher_id":101,"instrument_id":436},"action":"C","side":"B","price":"1.156470000","size":30,"channel_id":23,"order_id":"10998900579624717113","flags":0,"ts_in_delta":1130,"sequence":158872,"symbol":"FCEU SI 20260615 PS"}
{"ts_recv":"2026-04-07T02:22:31.691579447Z","hd":{"ts_event":"2026-04-07T02:22:31.691556969Z","rtype":160,"publisher_id":101,"instrument_id":436},"action":"A","side":"B","price":"1.156460000","size":30,"channel_id":23,"order_id":"10998900588546339187","flags":0,"ts_in_delta":1130,"sequence":158872,"symbol":"FCEU SI 20260615 PS"}
{"ts_recv":"2026-04-07T02:22:31.691579447Z","hd":{"ts_event":"2026-04-07T02:22:31.691556969Z","rtype":160,"publisher_id":101,"instrument_id":436},"action":"C","side":"A","price":"1.156570000","size":30,"channel_id":23,"order_id":"1775528542769941305","flags":0,"ts_in_delta":1130,"sequence":158872,"symbol":"FCEU SI 20260615 PS"}
{"ts_recv":"2026-04-07T02:22:31.691579447Z","hd":{"ts_event":"2026-04-07T02:22:31.691556969Z","rtype":160,"publisher_id":101,"instrument_id":436},"action":"A","side":"A","price":"1.156560000","size":30,"channel_id":23,"order_id":"1775528551691563379","flags":128,"ts_in_delta":1130,"sequence":158872,"symbol":"FCEU SI 20260615 PS"}
{"ts_recv":"2026-04-07T02:22:31.769280619Z","hd":{"ts_event":"2026-04-07T02:22:31.769266925Z","rtype":160,"publisher_id":101,"instrument_id":436},"action":"C","side":"B","price":"1.156400000","size":20,"channel_id":23,"order_id":"10998900481976193329","flags":128,"ts_in_delta":788,"sequence":158884,"symbol":"FCEU SI 20260615 PS"}
{"ts_recv":"2026-04-07T02:22:31.816637924Z","hd":{"ts_event":"2026-04-07T02:22:31.816615393Z","rtype":160,"publisher_id":101,"instrument_id":436},"action":"A","side":"B","price":"1.156300000","size":20,"channel_id":23,"order_id":"10998900588671402332","flags":128,"ts_in_delta":3030,"sequence":158886,"symbol":"FCEU SI 20260615 PS"}
{"ts_recv":"2026-04-07T02:22:39.213403551Z","hd":{"ts_event":"2026-04-07T02:22:39.213374513Z","rtype":160,"publisher_id":101,"instrument_id":436},"action":"C","side":"B","price":"1.156470000","size":30,"channel_id":23,"order_id":"10998900571596629752","flags":0,"ts_in_delta":1036,"sequence":158918,"symbol":"FCEU SI 20260615 PS"}
{"ts_recv":"2026-04-07T02:22:39.213403551Z","hd":{"ts_event":"2026-04-07T02:22:39.213374513Z","rtype":160,"publisher_id":101,"instrument_id":436},"action":"A","side":"B","price":"1.156440000","size":30,"channel_id":23,"order_id":"10998900596068161104","flags":0,"ts_in_delta":1036,"sequence":158918,"symbol":"FCEU SI 20260615 PS"}
{"ts_recv":"2026-04-07T02:22:39.213403551Z","hd":{"ts_event":"2026-04-07T02:22:39.213374513Z","rtype":160,"publisher_id":101,"instrument_id":436},"action":"C","side":"A","price":"1.156570000","size":30,"channel_id":23,"order_id":"1775528534741853944","flags":0,"ts_in_delta":1036,"sequence":158918,"symbol":"FCEU SI 20260615 PS"}
{"ts_recv":"2026-04-07T02:22:39.213403551Z","hd":{"ts_event":"2026-04-07T02:22:39.213374513Z","rtype":160,"publisher_id":101,"instrument_id":436},"action":"A","side":"A","price":"1.156540000","size":30,"channel_id":23,"order_id":"1775528559213385296","flags":128,"ts_in_delta":1036,"sequence":158918,"symbol":"FCEU SI 20260615 PS"}
{"ts_recv":"2026-04-07T02:22:39.213522155Z","hd":{"ts_event":"2026-04-07T02:22:39.213501733Z","rtype":160,"publisher_id":101,"instrument_id":436},"action":"C","side":"B","price":"1.156460000","size":30,"channel_id":23,"order_id":"10998900588546339187","flags":0,"ts_in_delta":944,"sequence":158919,"symbol":"FCEU SI 20260615 PS"}
{"ts_recv":"2026-04-07T02:22:39.213522155Z","hd":{"ts_event":"2026-04-07T02:22:39.213501733Z","rtype":160,"publisher_id":101,"instrument_id":436},"action":"A","side":"B","price":"1.156440000","size":30,"channel_id":23,"order_id":"10998900596068283784","flags":0,"ts_in_delta":944,"sequence":158919,"symbol":"FCEU SI 20260615 PS"}
{"ts_recv":"2026-04-07T02:22:39.213522155Z","hd":{"ts_event":"2026-04-07T02:22:39.213501733Z","rtype":160,"publisher_id":101,"instrument_id":436},"action":"C","side":"A","price":"1.156560000","size":30,"channel_id":23,"order_id":"1775528551691563379","flags":0,"ts_in_delta":944,"sequence":158919,"symbol":"FCEU SI 20260615 PS"}
{"ts_recv":"2026-04-07T02:22:39.213522155Z","hd":{"ts_event":"2026-04-07T02:22:39.213501733Z","rtype":160,"publisher_id":101,"instrument_id":436},"action":"A","side":"A","price":"1.156540000","size":30,"channel_id":23,"order_id":"1775528559213507976","flags":128,"ts_in_delta":944,"sequence":158919,"symbol":"FCEU SI 20260615 PS"}
{"ts_recv":"2026-04-07T02:22:41.465388666Z","hd":{"ts_event":"2026-04-07T02:22:41.465358205Z","rtype":160,"publisher_id":101,"instrument_id":436},"action":"C","side":"B","price":"1.156440000","size":30,"channel_id":23,"order_id":"10998900596068283784","flags":0,"ts_in_delta":1389,"sequence":158937,"symbol":"FCEU SI 20260615 PS"}
{"ts_recv":"2026-04-07T02:22:41.465388666Z","hd":{"ts_event":"2026-04-07T02:22:41.465358205Z","rtype":160,"publisher_id":101,"instrument_id":436},"action":"A","side":"B","price":"1.156430000","size":30,"channel_id":23,"order_id":"10998900598320143189","flags":0,"ts_in_delta":1389,"sequence":158937,"symbol":"FCEU SI 20260615 PS"}
{"ts_recv":"2026-04-07T02:22:41.465388666Z","hd":{"ts_event":"2026-04-07T02:22:41.465358205Z","rtype":160,"publisher_id":101,"instrument_id":436},"action":"C","side":"A","price":"1.156540000","size":30,"channel_id":23,"order_id":"1775528559213507976","flags":0,"ts_in_delta":1389,"sequence":158937,"symbol":"FCEU SI 20260615 PS"}
{"ts_recv":"2026-04-07T02:22:41.465388666Z","hd":{"ts_event":"2026-04-07T02:22:41.465358205Z","rtype":160,"publisher_id":101,"instrument_id":436},"action":"A","side":"A","price":"1.156530000","size":30,"channel_id":23,"order_id":"1775528561465367381","flags":128,"ts_in_delta":1389,"sequence":158937,"symbol":"FCEU SI 20260615 PS"}
{"ts_recv":"2026-04-07T02:22:41.507169282Z","hd":{"ts_event":"2026-04-07T02:22:41.507142339Z","rtype":160,"publisher_id":101,"instrument_id":436},"action":"C","side":"B","price":"1.156440000","size":30,"channel_id":23,"order_id":"10998900596068161104","flags":0,"ts_in_delta":1011,"sequence":158941,"symbol":"FCEU SI 20260615 PS"}
{"ts_recv":"2026-04-07T02:22:41.507169282Z","hd":{"ts_event":"2026-04-07T02:22:41.507142339Z","rtype":160,"publisher_id":101,"instrument_id":436},"action":"A","side":"B","price":"1.156420000","size":30,"channel_id":23,"order_id":"10998900598361929335","flags":0,"ts_in_delta":1011,"sequence":158941,"symbol":"FCEU SI 20260615 PS"}
{"ts_recv":"2026-04-07T02:22:41.507169282Z","hd":{"ts_event":"2026-04-07T02:22:41.507142339Z","rtype":160,"publisher_id":101,"instrument_id":436},"action":"C","side":"A","price":"1.156540000","size":30,"channel_id":23,"order_id":"1775528559213385296","flags":0,"ts_in_delta":1011,"sequence":158941,"symbol":"FCEU SI 20260615 PS"}
{"ts_recv":"2026-04-07T02:22:41.507169282Z","hd":{"ts_event":"2026-04-07T02:22:41.507142339Z","rtype":160,"publisher_id":101,"instrument_id":436},"action":"A","side":"A","price":"1.156520000","size":30,"channel_id":23,"order_id":"1775528561507153527","flags":128,"ts_in_delta":1011,"sequence":158941,"symbol":"FCEU SI 20260615 PS"}
{"ts_recv":"2026-04-07T02:22:41.507233038Z","hd":{"ts_event":"2026-04-07T02:22:41.507214211Z","rtype":160,"publisher_id":101,"instrument_id":436},"action":"C","side":"B","price":"1.156430000","size":30,"channel_id":23,"order_id":"10998900598320143189","flags":0,"ts_in_delta":997,"sequence":158942,"symbol":"FCEU SI 20260615 PS"}
{"ts_recv":"2026-04-07T02:22:41.507233038Z","hd":{"ts_event":"2026-04-07T02:22:41.507214211Z","rtype":160,"publisher_id":101,"instrument_id":436},"action":"A","side":"B","price":"1.156420000","size":30,"channel_id":23,"order_id":"10998900598361996273","flags":0,"ts_in_delta":997,"sequence":158942,"symbol":"FCEU SI 20260615 PS"}
{"ts_recv":"2026-04-07T02:22:41.507233038Z","hd":{"ts_event":"2026-04-07T02:22:41.507214211Z","rtype":160,"publisher_id":101,"instrument_id":436},"action":"C","side":"A","price":"1.156530000","size":30,"channel_id":23,"order_id":"1775528561465367381","flags":0,"ts_in_delta":997,"sequence":158942,"symbol":"FCEU SI 20260615 PS"}
{"ts_recv":"2026-04-07T02:22:41.507233038Z","hd":{"ts_event":"2026-04-07T02:22:41.507214211Z","rtype":160,"publisher_id":101,"instrument_id":436},"action":"A","side":"A","price":"1.156520000","size":30,"channel_id":23,"order_id":"1775528561507220465","flags":128,"ts_in_delta":997,"sequence":158942,"symbol":"FCEU SI 20260615 PS"}
{"ts_recv":"2026-04-07T02:22:44.135556235Z","hd":{"ts_event":"2026-04-07T02:22:44.135530539Z","rtype":160,"publisher_id":101,"instrument_id":436},"action":"C","side":"B","price":"1.156420000","size":30,"channel_id":23,"order_id":"10998900598361996273","flags":0,"ts_in_delta":1423,"sequence":158984,"symbol":"FCEU SI 20260615 PS"}
{"ts_recv":"2026-04-07T02:22:44.135556235Z","hd":{"ts_event":"2026-04-07T02:22:44.135530539Z","rtype":160,"publisher_id":101,"instrument_id":436},"action":"A","side":"B","price":"1.156430000","size":30,"channel_id":23,"order_id":"10998900600990312664","flags":0,"ts_in_delta":1423,"sequence":158984,"symbol":"FCEU SI 20260615 PS"}
{"ts_recv":"2026-04-07T02:22:44.135556235Z","hd":{"ts_event":"2026-04-07T02:22:44.135530539Z","rtype":160,"publisher_id":101,"instrument_id":436},"action":"C","side":"A","price":"1.156520000","size":30,"channel_id":23,"order_id":"1775528561507220465","flags":0,"ts_in_delta":1423,"sequence":158984,"symbol":"FCEU SI 20260615 PS"}
{"ts_recv":"2026-04-07T02:22:44.135556235Z","hd":{"ts_event":"2026-04-07T02:22:44.135530539Z","rtype":160,"publisher_id":101,"instrument_id":436},"action":"A","side":"A","price":"1.156530000","size":30,"channel_id":23,"order_id":"1775528564135536856","flags":128,"ts_in_delta":1423,"sequence":158984,"symbol":"FCEU SI 20260615 PS"}
{"ts_recv":"2026-04-07T02:22:44.135641072Z","hd":{"ts_event":"2026-04-07T02:22:44.135622969Z","rtype":160,"publisher_id":101,"instrument_id":436},"action":"C","side":"B","price":"1.156430000","size":30,"channel_id":23,"order_id":"10998900600990312664","flags":0,"ts_in_delta":1089,"sequence":158985,"symbol":"FCEU SI 20260615 PS"}
{"ts_recv":"2026-04-07T02:22:44.135641072Z","hd":{"ts_event":"2026-04-07T02:22:44.135622969Z","rtype":160,"publisher_id":101,"instrument_id":436},"action":"A","side":"B","price":"1.156440000","size":30,"channel_id":23,"order_id":"10998900600990404401","flags":0,"ts_in_delta":1089,"sequence":158985,"symbol":"FCEU SI 20260615 PS"}
{"ts_recv":"2026-04-07T02:22:44.135641072Z","hd":{"ts_event":"2026-04-07T02:22:44.135622969Z","rtype":160,"publisher_id":101,"instrument_id":436},"action":"C","side":"A","price":"1.156530000","size":30,"channel_id":23,"order_id":"1775528564135536856","flags":0,"ts_in_delta":1089,"sequence":158985,"symbol":"FCEU SI 20260615 PS"}
{"ts_recv":"2026-04-07T02:22:44.135641072Z","hd":{"ts_event":"2026-04-07T02:22:44.135622969Z","rtype":160,"publisher_id":101,"instrument_id":436},"action":"A","side":"A","price":"1.156540000","size":30,"channel_id":23,"order_id":"1775528564135628593","flags":128,"ts_in_delta":1089,"sequence":158985,"symbol":"FCEU SI 20260615 PS"}
{"ts_recv":"2026-04-07T02:22:44.135694814Z","hd":{"ts_event":"2026-04-07T02:22:44.135675923Z","rtype":160,"publisher_id":101,"instrument_id":436},"action":"C","side":"B","price":"1.156420000","size":30,"channel_id":23,"order_id":"10998900598361929335","flags":0,"ts_in_delta":965,"sequence":158986,"symbol":"FCEU SI 20260615 PS"}
{"ts_recv":"2026-04-07T02:22:44.135694814Z","hd":{"ts_event":"2026-04-07T02:22:44.135675923Z","rtype":160,"publisher_id":101,"instrument_id":436},"action":"A","side":"B","price":"1.156440000","size":30,"channel_id":23,"order_id":"10998900600990458000","flags":0,"ts_in_delta":965,"sequence":158986,"symbol":"FCEU SI 20260615 PS"}
{"ts_recv":"2026-04-07T02:22:44.135694814Z","hd":{"ts_event":"2026-04-07T02:22:44.135675923Z","rtype":160,"publisher_id":101,"instrument_id":436},"action":"C","side":"A","price":"1.156520000","size":30,"channel_id":23,"order_id":"1775528561507153527","flags":0,"ts_in_delta":965,"sequence":158986,"symbol":"FCEU SI 20260615 PS"}
{"ts_recv":"2026-04-07T02:22:44.135694814Z","hd":{"ts_event":"2026-04-07T02:22:44.135675923Z","rtype":160,"publisher_id":101,"instrument_id":436},"action":"A","side":"A","price":"1.156540000","size":30,"channel_id":23,"order_id":"1775528564135682192","flags":128,"ts_in_delta":965,"sequence":158986,"symbol":"FCEU SI 20260615 PS"}
{"ts_recv":"2026-04-07T02:22:44.135704099Z","hd":{"ts_event":"2026-04-07T02:22:44.135681549Z","rtype":160,"publisher_id":101,"instrument_id":436},"action":"C","side":"B","price":"1.156440000","size":30,"channel_id":23,"order_id":"10998900600990404401","flags":0,"ts_in_delta":936,"sequence":158987,"symbol":"FCEU SI 20260615 PS"}
{"ts_recv":"2026-04-07T02:22:44.135704099Z","hd":{"ts_event":"2026-04-07T02:22:44.135681549Z","rtype":160,"publisher_id":101,"instrument_id":436},"action":"A","side":"B","price":"1.156430000","size":30,"channel_id":23,"order_id":"10998900600990466952","flags":0,"ts_in_delta":936,"sequence":158987,"symbol":"FCEU SI 20260615 PS"}
{"ts_recv":"2026-04-07T02:22:44.135704099Z","hd":{"ts_event":"2026-04-07T02:22:44.135681549Z","rtype":160,"publisher_id":101,"instrument_id":436},"action":"C","side":"A","price":"1.156540000","size":30,"channel_id":23,"order_id":"1775528564135628593","flags":0,"ts_in_delta":936,"sequence":158987,"symbol":"FCEU SI 20260615 PS"}
{"ts_recv":"2026-04-07T02:22:44.135704099Z","hd":{"ts_event":"2026-04-07T02:22:44.135681549Z","rtype":160,"publisher_id":101,"instrument_id":436},"action":"A","side":"A","price":"1.156530000","size":30,"channel_id":23,"order_id":"1775528564135691144","flags":128,"ts_in_delta":936,"sequence":158987,"symbol":"FCEU SI 20260615 PS"}
{"ts_recv":"2026-04-07T02:22:44.135759814Z","hd":{"ts_event":"2026-04-07T02:22:44.135741569Z","rtype":160,"publisher_id":101,"instrument_id":436},"action":"C","side":"B","price":"1.156430000","size":30,"channel_id":23,"order_id":"10998900600990466952","flags":0,"ts_in_delta":929,"sequence":158988,"symbol":"FCEU SI 20260615 PS"}
{"ts_recv":"2026-04-07T02:22:44.135759814Z","hd":{"ts_event":"2026-04-07T02:22:44.135741569Z","rtype":160,"publisher_id":101,"instrument_id":436},"action":"A","side":"B","price":"1.156440000","size":30,"channel_id":23,"order_id":"10998900600990523359","flags":0,"ts_in_delta":929,"sequence":158988,"symbol":"FCEU SI 20260615 PS"}
{"ts_recv":"2026-04-07T02:22:44.135759814Z","hd":{"ts_event":"2026-04-07T02:22:44.135741569Z","rtype":160,"publisher_id":101,"instrument_id":436},"action":"C","side":"A","price":"1.156530000","size":30,"channel_id":23,"order_id":"1775528564135691144","flags":0,"ts_in_delta":929,"sequence":158988,"symbol":"FCEU SI 20260615 PS"}
{"ts_recv":"2026-04-07T02:22:44.135759814Z","hd":{"ts_event":"2026-04-07T02:22:44.135741569Z","rtype":160,"publisher_id":101,"instrument_id":436},"action":"A","side":"A","price":"1.156540000","size":30,"channel_id":23,"order_id":"1775528564135747551","flags":128,"ts_in_delta":929,"sequence":158988,"symbol":"FCEU SI 20260615 PS"}
{"ts_recv":"2026-04-07T02:23:32.301415317Z","hd":{"ts_event":"2026-04-07T02:23:32.301390843Z","rtype":160,"publisher_id":101,"instrument_id":436},"action":"C","side":"B","price":"1.156440000","size":30,"channel_id":23,"order_id":"10998900600990523359","flags":0,"ts_in_delta":1092,"sequence":159308,"symbol":"FCEU SI 20260615 PS"}
{"ts_recv":"2026-04-07T02:23:32.301415317Z","hd":{"ts_event":"2026-04-07T02:23:32.301390843Z","rtype":160,"publisher_id":101,"instrument_id":436},"action":"A","side":"B","price":"1.156450000","size":30,"channel_id":23,"order_id":"10998900649156172885","flags":0,"ts_in_delta":1092,"sequence":159308,"symbol":"FCEU SI 20260615 PS"}
{"ts_recv":"2026-04-07T02:23:32.301415317Z","hd":{"ts_event":"2026-04-07T02:23:32.301390843Z","rtype":160,"publisher_id":101,"instrument_id":436},"action":"C","side":"A","price":"1.156540000","size":30,"channel_id":23,"order_id":"1775528564135747551","flags":0,"ts_in_delta":1092,"sequence":159308,"symbol":"FCEU SI 20260615 PS"}
{"ts_recv":"2026-04-07T02:23:32.301415317Z","hd":{"ts_event":"2026-04-07T02:23:32.301390843Z","rtype":160,"publisher_id":101,"instrument_id":436},"action":"A","side":"A","price":"1.156550000","size":30,"channel_id":23,"order_id":"1775528612301397077","flags":128,"ts_in_delta":1092,"sequence":159308,"symbol":"FCEU SI 20260615 PS"}
{"ts_recv":"2026-04-07T02:23:38.212222543Z","hd":{"ts_event":"2026-04-07T02:23:38.212191649Z","rtype":160,"publisher_id":101,"instrument_id":436},"action":"C","side":"B","price":"1.156450000","size":30,"channel_id":23,"order_id":"10998900649156172885","flags":0,"ts_in_delta":1262,"sequence":159351,"symbol":"FCEU SI 20260615 PS"}
{"ts_recv":"2026-04-07T02:23:38.212222543Z","hd":{"ts_event":"2026-04-07T02:23:38.212191649Z","rtype":160,"publisher_id":101,"instrument_id":436},"action":"A","side":"B","price":"1.156440000","size":30,"channel_id":23,"order_id":"10998900655066980756","flags":0,"ts_in_delta":1262,"sequence":159351,"symbol":"FCEU SI 20260615 PS"}
{"ts_recv":"2026-04-07T02:23:38.212222543Z","hd":{"ts_event":"2026-04-07T02:23:38.212191649Z","rtype":160,"publisher_id":101,"instrument_id":436},"action":"C","side":"A","price":"1.156550000","size":30,"channel_id":23,"order_id":"1775528612301397077","flags":0,"ts_in_delta":1262,"sequence":159351,"symbol":"FCEU SI 20260615 PS"}
{"ts_recv":"2026-04-07T02:23:38.212222543Z","hd":{"ts_event":"2026-04-07T02:23:38.212191649Z","rtype":160,"publisher_id":101,"instrument_id":436},"action":"A","side":"A","price":"1.156540000","size":30,"channel_id":23,"order_id":"1775528618212204948","flags":128,"ts_in_delta":1262,"sequence":159351,"symbol":"FCEU SI 20260615 PS"}
{"ts_recv":"2026-04-07T02:24:02.017891304Z","hd":{"ts_event":"2026-04-07T02:24:02.017866237Z","rtype":160,"publisher_id":101,"instrument_id":436},"action":"C","side":"B","price":"1.156440000","size":30,"channel_id":23,"order_id":"10998900655066980756","flags":0,"ts_in_delta":867,"sequence":159578,"symbol":"FCEU SI 20260615 PS"}
{"ts_recv":"2026-04-07T02:24:02.017891304Z","hd":{"ts_event":"2026-04-07T02:24:02.017866237Z","rtype":160,"publisher_id":101,"instrument_id":436},"action":"A","side":"B","price":"1.156430000","size":30,"channel_id":23,"order_id":"10998900678872648061","flags":0,"ts_in_delta":867,"sequence":159578,"symbol":"FCEU SI 20260615 PS"}
{"ts_recv":"2026-04-07T02:24:02.017891304Z","hd":{"ts_event":"2026-04-07T02:24:02.017866237Z","rtype":160,"publisher_id":101,"instrument_id":436},"action":"C","side":"A","price":"1.156540000","size":30,"channel_id":23,"order_id":"1775528618212204948","flags":0,"ts_in_delta":867,"sequence":159578,"symbol":"FCEU SI 20260615 PS"}
{"ts_recv":"2026-04-07T02:24:02.017891304Z","hd":{"ts_event":"2026-04-07T02:24:02.017866237Z","rtype":160,"publisher_id":101,"instrument_id":436},"action":"A","side":"A","price":"1.156530000","size":30,"channel_id":23,"order_id":"1775528642017872253","flags":128,"ts_in_delta":867,"sequence":159578,"symbol":"FCEU SI 20260615 PS"}
{"ts_recv":"2026-04-07T02:24:02.017955982Z","hd":{"ts_event":"2026-04-07T02:24:02.017932503Z","rtype":160,"publisher_id":101,"instrument_id":436},"action":"C","side":"B","price":"1.156440000","size":30,"channel_id":23,"order_id":"10998900600990458000","flags":0,"ts_in_delta":749,"sequence":159579,"symbol":"FCEU SI 20260615 PS"}
{"ts_recv":"2026-04-07T02:24:02.017955982Z","hd":{"ts_event":"2026-04-07T02:24:02.017932503Z","rtype":160,"publisher_id":101,"instrument_id":436},"action":"A","side":"B","price":"1.156420000","size":30,"channel_id":23,"order_id":"10998900678872714880","flags":0,"ts_in_delta":749,"sequence":159579,"symbol":"FCEU SI 20260615 PS"}
{"ts_recv":"2026-04-07T02:24:02.017955982Z","hd":{"ts_event":"2026-04-07T02:24:02.017932503Z","rtype":160,"publisher_id":101,"instrument_id":436},"action":"C","side":"A","price":"1.156540000","size":30,"channel_id":23,"order_id":"1775528564135682192","flags":0,"ts_in_delta":749,"sequence":159579,"symbol":"FCEU SI 20260615 PS"}
{"ts_recv":"2026-04-07T02:24:02.017955982Z","hd":{"ts_event":"2026-04-07T02:24:02.017932503Z","rtype":160,"publisher_id":101,"instrument_id":436},"action":"A","side":"A","price":"1.156520000","size":30,"channel_id":23,"order_id":"1775528642017939072","flags":128,"ts_in_delta":749,"sequence":159579,"symbol":"FCEU SI 20260615 PS"}
{"ts_recv":"2026-04-07T02:24:02.018014669Z","hd":{"ts_event":"2026-04-07T02:24:02.017994421Z","rtype":160,"publisher_id":101,"instrument_id":436},"action":"C","side":"B","price":"1.156430000","size":30,"channel_id":23,"order_id":"10998900678872648061","flags":0,"ts_in_delta":957,"sequence":159580,"symbol":"FCEU SI 20260615 PS"}
{"ts_recv":"2026-04-07T02:24:02.018014669Z","hd":{"ts_event":"2026-04-07T02:24:02.017994421Z","rtype":160,"publisher_id":101,"instrument_id":436},"action":"A","side":"B","price":"1.156420000","size":30,"channel_id":23,"order_id":"10998900678872776150","flags":0,"ts_in_delta":957,"sequence":159580,"symbol":"FCEU SI 20260615 PS"}
{"ts_recv":"2026-04-07T02:24:02.018014669Z","hd":{"ts_event":"2026-04-07T02:24:02.017994421Z","rtype":160,"publisher_id":101,"instrument_id":436},"action":"C","side":"A","price":"1.156530000","size":30,"channel_id":23,"order_id":"1775528642017872253","flags":0,"ts_in_delta":957,"sequence":159580,"symbol":"FCEU SI 20260615 PS"}
{"ts_recv":"2026-04-07T02:24:02.018014669Z","hd":{"ts_event":"2026-04-07T02:24:02.017994421Z","rtype":160,"publisher_id":101,"instrument_id":436},"action":"A","side":"A","price":"1.156520000","size":30,"channel_id":23,"order_id":"1775528642018000342","flags":128,"ts_in_delta":957,"sequence":159580,"symbol":"FCEU SI 20260615 PS"}
{"ts_recv":"2026-04-07T02:24:03.065519116Z","hd":{"ts_event":"2026-04-07T02:24:03.065499825Z","rtype":160,"publisher_id":101,"instrument_id":436},"action":"C","side":"B","price":"1.156420000","size":30,"channel_id":23,"order_id":"10998900678872776150","flags":0,"ts_in_delta":938,"sequence":159629,"symbol":"FCEU SI 20260615 PS"}
{"ts_recv":"2026-04-07T02:24:03.065519116Z","hd":{"ts_event":"2026-04-07T02:24:03.065499825Z","rtype":160,"publisher_id":101,"instrument_id":436},"action":"A","side":"B","price":"1.156430000","size":30,"channel_id":23,"order_id":"10998900679920281499","flags":0,"ts_in_delta":938,"sequence":159629,"symbol":"FCEU SI 20260615 PS"}
{"ts_recv":"2026-04-07T02:24:03.065519116Z","hd":{"ts_event":"2026-04-07T02:24:03.065499825Z","rtype":160,"publisher_id":101,"instrument_id":436},"action":"C","side":"A","price":"1.156520000","size":30,"channel_id":23,"order_id":"1775528642018000342","flags":0,"ts_in_delta":938,"sequence":159629,"symbol":"FCEU SI 20260615 PS"}
{"ts_recv":"2026-04-07T02:24:03.065519116Z","hd":{"ts_event":"2026-04-07T02:24:03.065499825Z","rtype":160,"publisher_id":101,"instrument_id":436},"action":"A","side":"A","price":"1.156530000","size":30,"channel_id":23,"order_id":"1775528643065505691","flags":128,"ts_in_delta":938,"sequence":159629,"symbol":"FCEU SI 20260615 PS"}
{"ts_recv":"2026-04-07T02:24:05.095541394Z","hd":{"ts_event":"2026-04-07T02:24:05.095521009Z","rtype":160,"publisher_id":101,"instrument_id":436},"action":"C","side":"B","price":"1.156420000","size":30,"channel_id":23,"order_id":"10998900678872714880","flags":0,"ts_in_delta":942,"sequence":159680,"symbol":"FCEU SI 20260615 PS"}
{"ts_recv":"2026-04-07T02:24:05.095541394Z","hd":{"ts_event":"2026-04-07T02:24:05.095521009Z","rtype":160,"publisher_id":101,"instrument_id":436},"action":"A","side":"B","price":"1.156440000","size":30,"channel_id":23,"order_id":"10998900681950302691","flags":0,"ts_in_delta":942,"sequence":159680,"symbol":"FCEU SI 20260615 PS"}
{"ts_recv":"2026-04-07T02:24:05.095541394Z","hd":{"ts_event":"2026-04-07T02:24:05.095521009Z","rtype":160,"publisher_id":101,"instrument_id":436},"action":"C","side":"A","price":"1.156520000","size":30,"channel_id":23,"order_id":"1775528642017939072","flags":0,"ts_in_delta":942,"sequence":159680,"symbol":"FCEU SI 20260615 PS"}
{"ts_recv":"2026-04-07T02:24:05.095541394Z","hd":{"ts_event":"2026-04-07T02:24:05.095521009Z","rtype":160,"publisher_id":101,"instrument_id":436},"action":"A","side":"A","price":"1.156540000","size":30,"channel_id":23,"order_id":"1775528645095526883","flags":128,"ts_in_delta":942,"sequence":159680,"symbol":"FCEU SI 20260615 PS"}
{"ts_recv":"2026-04-07T02:24:05.095603399Z","hd":{"ts_event":"2026-04-07T02:24:05.095584639Z","rtype":160,"publisher_id":101,"instrument_id":436},"action":"C","side":"B","price":"1.156430000","size":30,"channel_id":23,"order_id":"10998900679920281499","flags":0,"ts_in_delta":897,"sequence":159681,"symbol":"FCEU SI 20260615 PS"}
{"ts_recv":"2026-04-07T02:24:05.095603399Z","hd":{"ts_event":"2026-04-07T02:24:05.095584639Z","rtype":160,"publisher_id":101,"instrument_id":436},"action":"A","side":"B","price":"1.156440000","size":30,"channel_id":23,"order_id":"10998900681950366335","flags":0,"ts_in_delta":897,"sequence":159681,"symbol":"FCEU SI 20260615 PS"}
{"ts_recv":"2026-04-07T02:24:05.095603399Z","hd":{"ts_event":"2026-04-07T02:24:05.095584639Z","rtype":160,"publisher_id":101,"instrument_id":436},"action":"C","side":"A","price":"1.156530000","size":30,"channel_id":23,"order_id":"1775528643065505691","flags":0,"ts_in_delta":897,"sequence":159681,"symbol":"FCEU SI 20260615 PS"}
{"ts_recv":"2026-04-07T02:24:05.095603399Z","hd":{"ts_event":"2026-04-07T02:24:05.095584639Z","rtype":160,"publisher_id":101,"instrument_id":436},"action":"A","side":"A","price":"1.156540000","size":30,"channel_id":23,"order_id":"1775528645095590527","flags":128,"ts_in_delta":897,"sequence":159681,"symbol":"FCEU SI 20260615 PS"}
{"ts_recv":"2026-04-07T02:24:16.554477969Z","hd":{"ts_event":"2026-04-07T02:24:16.554456557Z","rtype":160,"publisher_id":101,"instrument_id":436},"action":"C","side":"B","price":"1.156440000","size":30,"channel_id":23,"order_id":"10998900681950366335","flags":0,"ts_in_delta":988,"sequence":159756,"symbol":"FCEU SI 20260615 PS"}
{"ts_recv":"2026-04-07T02:24:16.554477969Z","hd":{"ts_event":"2026-04-07T02:24:16.554456557Z","rtype":160,"publisher_id":101,"instrument_id":436},"action":"A","side":"B","price":"1.156450000","size":30,"channel_id":23,"order_id":"10998900693409238285","flags":0,"ts_in_delta":988,"sequence":159756,"symbol":"FCEU SI 20260615 PS"}
{"ts_recv":"2026-04-07T02:24:16.554477969Z","hd":{"ts_event":"2026-04-07T02:24:16.554456557Z","rtype":160,"publisher_id":101,"instrument_id":436},"action":"C","side":"A","price":"1.156540000","size":30,"channel_id":23,"order_id":"1775528645095590527","flags":0,"ts_in_delta":988,"sequence":159756,"symbol":"FCEU SI 20260615 PS"}
{"ts_recv":"2026-04-07T02:24:16.554477969Z","hd":{"ts_event":"2026-04-07T02:24:16.554456557Z","rtype":160,"publisher_id":101,"instrument_id":436},"action":"A","side":"A","price":"1.156550000","size":30,"channel_id":23,"order_id":"1775528656554462477","flags":128,"ts_in_delta":988,"sequence":159756,"symbol":"FCEU SI 20260615 PS"}
{"ts_recv":"2026-04-07T02:24:21.277345869Z","hd":{"ts_event":"2026-04-07T02:24:21.277324881Z","rtype":160,"publisher_id":101,"instrument_id":436},"action":"C","side":"B","price":"1.156440000","size":30,"channel_id":23,"order_id":"10998900681950302691","flags":0,"ts_in_delta":898,"sequence":159789,"symbol":"FCEU SI 20260615 PS"}
{"ts_recv":"2026-04-07T02:24:21.277345869Z","hd":{"ts_event":"2026-04-07T02:24:21.277324881Z","rtype":160,"publisher_id":101,"instrument_id":436},"action":"A","side":"B","price":"1.156460000","size":30,"channel_id":23,"order_id":"10998900698132106808","flags":0,"ts_in_delta":898,"sequence":159789,"symbol":"FCEU SI 20260615 PS"}
{"ts_recv":"2026-04-07T02:24:21.277345869Z","hd":{"ts_event":"2026-04-07T02:24:21.277324881Z","rtype":160,"publisher_id":101,"instrument_id":436},"action":"C","side":"A","price":"1.156540000","size":30,"channel_id":23,"order_id":"1775528645095526883","flags":0,"ts_in_delta":898,"sequence":159789,"symbol":"FCEU SI 20260615 PS"}
{"ts_recv":"2026-04-07T02:24:21.277345869Z","hd":{"ts_event":"2026-04-07T02:24:21.277324881Z","rtype":160,"publisher_id":101,"instrument_id":436},"action":"A","side":"A","price":"1.156560000","size":30,"channel_id":23,"order_id":"1775528661277331000","flags":128,"ts_in_delta":898,"sequence":159789,"symbol":"FCEU SI 20260615 PS"}
{"ts_recv":"2026-04-07T02:24:21.277425722Z","hd":{"ts_event":"2026-04-07T02:24:21.277405739Z","rtype":160,"publisher_id":101,"instrument_id":436},"action":"C","side":"B","price":"1.156450000","size":30,"channel_id":23,"order_id":"10998900693409238285","flags":0,"ts_in_delta":928,"sequence":159790,"symbol":"FCEU SI 20260615 PS"}
{"ts_recv":"2026-04-07T02:24:21.277425722Z","hd":{"ts_event":"2026-04-07T02:24:21.277405739Z","rtype":160,"publisher_id":101,"instrument_id":436},"action":"A","side":"B","price":"1.156460000","size":30,"channel_id":23,"order_id":"10998900698132187733","flags":0,"ts_in_delta":928,"sequence":159790,"symbol":"FCEU SI 20260615 PS"}
{"ts_recv":"2026-04-07T02:24:21.277425722Z","hd":{"ts_event":"2026-04-07T02:24:21.277405739Z","rtype":160,"publisher_id":101,"instrument_id":436},"action":"C","side":"A","price":"1.156550000","size":30,"channel_id":23,"order_id":"1775528656554462477","flags":0,"ts_in_delta":928,"sequence":159790,"symbol":"FCEU SI 20260615 PS"}
{"ts_recv":"2026-04-07T02:24:21.277425722Z","hd":{"ts_event":"2026-04-07T02:24:21.277405739Z","rtype":160,"publisher_id":101,"instrument_id":436},"action":"A","side":"A","price":"1.156560000","size":30,"channel_id":23,"order_id":"1775528661277411925","flags":128,"ts_in_delta":928,"sequence":159790,"symbol":"FCEU SI 20260615 PS"}
{"ts_recv":"2026-04-07T02:24:22.471936677Z","hd":{"ts_event":"2026-04-07T02:24:22.471916945Z","rtype":160,"publisher_id":101,"instrument_id":436},"action":"C","side":"B","price":"1.156460000","size":30,"channel_id":23,"order_id":"10998900698132187733","flags":0,"ts_in_delta":887,"sequence":159809,"symbol":"FCEU SI 20260615 PS"}
{"ts_recv":"2026-04-07T02:24:22.471936677Z","hd":{"ts_event":"2026-04-07T02:24:22.471916945Z","rtype":160,"publisher_id":101,"instrument_id":436},"action":"A","side":"B","price":"1.156450000","size":30,"channel_id":23,"order_id":"10998900699326698641","flags":0,"ts_in_delta":887,"sequence":159809,"symbol":"FCEU SI 20260615 PS"}
{"ts_recv":"2026-04-07T02:24:22.471936677Z","hd":{"ts_event":"2026-04-07T02:24:22.471916945Z","rtype":160,"publisher_id":101,"instrument_id":436},"action":"C","side":"A","price":"1.156560000","size":30,"channel_id":23,"order_id":"1775528661277411925","flags":0,"ts_in_delta":887,"sequence":159809,"symbol":"FCEU SI 20260615 PS"}
{"ts_recv":"2026-04-07T02:24:22.471936677Z","hd":{"ts_event":"2026-04-07T02:24:22.471916945Z","rtype":160,"publisher_id":101,"instrument_id":436},"action":"A","side":"A","price":"1.156550000","size":30,"channel_id":23,"order_id":"1775528662471922833","flags":128,"ts_in_delta":887,"sequence":159809,"symbol":"FCEU SI 20260615 PS"}
{"ts_recv":"2026-04-07T02:24:22.471994812Z","hd":{"ts_event":"2026-04-07T02:24:22.471974281Z","rtype":160,"publisher_id":101,"instrument_id":436},"action":"C","side":"B","price":"1.156460000","size":30,"channel_id":23,"order_id":"10998900698132106808","flags":0,"ts_in_delta":904,"sequence":159810,"symbol":"FCEU SI 20260615 PS"}
{"ts_recv":"2026-04-07T02:24:22.471994812Z","hd":{"ts_event":"2026-04-07T02:24:22.471974281Z","rtype":160,"publisher_id":101,"instrument_id":436},"action":"A","side":"B","price":"1.156440000","size":30,"channel_id":23,"order_id":"10998900699326756371","flags":0,"ts_in_delta":904,"sequence":159810,"symbol":"FCEU SI 20260615 PS"}
{"ts_recv":"2026-04-07T02:24:22.471994812Z","hd":{"ts_event":"2026-04-07T02:24:22.471974281Z","rtype":160,"publisher_id":101,"instrument_id":436},"action":"C","side":"A","price":"1.156560000","size":30,"channel_id":23,"order_id":"1775528661277331000","flags":0,"ts_in_delta":904,"sequence":159810,"symbol":"FCEU SI 20260615 PS"}
{"ts_recv":"2026-04-07T02:24:22.471994812Z","hd":{"ts_event":"2026-04-07T02:24:22.471974281Z","rtype":160,"publisher_id":101,"instrument_id":436},"action":"A","side":"A","price":"1.156540000","size":30,"channel_id":23,"order_id":"1775528662471980563","flags":128,"ts_in_delta":904,"sequence":159810,"symbol":"FCEU SI 20260615 PS"}
{"ts_recv":"2026-04-07T02:24:22.472055035Z","hd":{"ts_event":"2026-04-07T02:24:22.472037987Z","rtype":160,"publisher_id":101,"instrument_id":436},"action":"C","side":"B","price":"1.156450000","size":30,"channel_id":23,"order_id":"10998900699326698641","flags":0,"ts_in_delta":883,"sequence":159811,"symbol":"FCEU SI 20260615 PS"}
{"ts_recv":"2026-04-07T02:24:22.472055035Z","hd":{"ts_event":"2026-04-07T02:24:22.472037987Z","rtype":160,"publisher_id":101,"instrument_id":436},"action":"A","side":"B","price":"1.156440000","size":30,"channel_id":23,"order_id":"10998900699326820044","flags":0,"ts_in_delta":883,"sequence":159811,"symbol":"FCEU SI 20260615 PS"}
{"ts_recv":"2026-04-07T02:24:22.472055035Z","hd":{"ts_event":"2026-04-07T02:24:22.472037987Z","rtype":160,"publisher_id":101,"instrument_id":436},"action":"C","side":"A","price":"1.156550000","size":30,"channel_id":23,"order_id":"1775528662471922833","flags":0,"ts_in_delta":883,"sequence":159811,"symbol":"FCEU SI 20260615 PS"}
{"ts_recv":"2026-04-07T02:24:22.472055035Z","hd":{"ts_event":"2026-04-07T02:24:22.472037987Z","rtype":160,"publisher_id":101,"instrument_id":436},"action":"A","side":"A","price":"1.156540000","size":30,"channel_id":23,"order_id":"1775528662472044236","flags":128,"ts_in_delta":883,"sequence":159811,"symbol":"FCEU SI 20260615 PS"}
{"ts_recv":"2026-04-07T02:24:22.998513428Z","hd":{"ts_event":"2026-04-07T02:24:22.998490989Z","rtype":160,"publisher_id":101,"instrument_id":436},"action":"C","side":"B","price":"1.156440000","size":30,"channel_id":23,"order_id":"10998900699326820044","flags":0,"ts_in_delta":993,"sequence":159820,"symbol":"FCEU SI 20260615 PS"}
{"ts_recv":"2026-04-07T02:24:22.998513428Z","hd":{"ts_event":"2026-04-07T02:24:22.998490989Z","rtype":160,"publisher_id":101,"instrument_id":436},"action":"A","side":"B","price":"1.156450000","size":30,"channel_id":23,"order_id":"10998900699853273074","flags":0,"ts_in_delta":993,"sequence":159820,"symbol":"FCEU SI 20260615 PS"}
{"ts_recv":"2026-04-07T02:24:22.998513428Z","hd":{"ts_event":"2026-04-07T02:24:22.998490989Z","rtype":160,"publisher_id":101,"instrument_id":436},"action":"C","side":"A","price":"1.156540000","size":30,"channel_id":23,"order_id":"1775528662472044236","flags":0,"ts_in_delta":993,"sequence":159820,"symbol":"FCEU SI 20260615 PS"}
{"ts_recv":"2026-04-07T02:24:22.998513428Z","hd":{"ts_event":"2026-04-07T02:24:22.998490989Z","rtype":160,"publisher_id":101,"instrument_id":436},"action":"A","side":"A","price":"1.156550000","size":30,"channel_id":23,"order_id":"1775528662998497266","flags":128,"ts_in_delta":993,"sequence":159820,"symbol":"FCEU SI 20260615 PS"}
{"ts_recv":"2026-04-07T02:24:23.031890353Z","hd":{"ts_event":"2026-04-07T02:24:23.031871613Z","rtype":160,"publisher_id":101,"instrument_id":436},"action":"C","side":"B","price":"1.156440000","size":30,"channel_id":23,"order_id":"10998900699326756371","flags":0,"ts_in_delta":1432,"sequence":159827,"symbol":"FCEU SI 20260615 PS"}
{"ts_recv":"2026-04-07T02:24:23.031890353Z","hd":{"ts_event":"2026-04-07T02:24:23.031871613Z","rtype":160,"publisher_id":101,"instrument_id":436},"action":"A","side":"B","price":"1.156460000","size":30,"channel_id":23,"order_id":"10998900699886653393","flags":0,"ts_in_delta":1432,"sequence":159827,"symbol":"FCEU SI 20260615 PS"}
{"ts_recv":"2026-04-07T02:24:23.031890353Z","hd":{"ts_event":"2026-04-07T02:24:23.031871613Z","rtype":160,"publisher_id":101,"instrument_id":436},"action":"C","side":"A","price":"1.156540000","size":30,"channel_id":23,"order_id":"1775528662471980563","flags":0,"ts_in_delta":1432,"sequence":159827,"symbol":"FCEU SI 20260615 PS"}
{"ts_recv":"2026-04-07T02:24:23.031890353Z","hd":{"ts_event":"2026-04-07T02:24:23.031871613Z","rtype":160,"publisher_id":101,"instrument_id":436},"action":"A","side":"A","price":"1.156560000","size":30,"channel_id":23,"order_id":"1775528663031877585","flags":128,"ts_in_delta":1432,"sequence":159827,"symbol":"FCEU SI 20260615 PS"}
{"ts_recv":"2026-04-07T02:24:23.031950055Z","hd":{"ts_event":"2026-04-07T02:24:23.031932899Z","rtype":160,"publisher_id":101,"instrument_id":436},"action":"C","side":"B","price":"1.156450000","size":30,"channel_id":23,"order_id":"10998900699853273074","flags":0,"ts_in_delta":920,"sequence":159828,"symbol":"FCEU SI 20260615 PS"}
{"ts_recv":"2026-04-07T02:24:23.031950055Z","hd":{"ts_event":"2026-04-07T02:24:23.031932899Z","rtype":160,"publisher_id":101,"instrument_id":436},"action":"A","side":"B","price":"1.156460000","size":30,"channel_id":23,"order_id":"10998900699886714808","flags":0,"ts_in_delta":920,"sequence":159828,"symbol":"FCEU SI 20260615 PS"}
{"ts_recv":"2026-04-07T02:24:23.031950055Z","hd":{"ts_event":"2026-04-07T02:24:23.031932899Z","rtype":160,"publisher_id":101,"instrument_id":436},"action":"C","side":"A","price":"1.156550000","size":30,"channel_id":23,"order_id":"1775528662998497266","flags":0,"ts_in_delta":920,"sequence":159828,"symbol":"FCEU SI 20260615 PS"}
{"ts_recv":"2026-04-07T02:24:23.031950055Z","hd":{"ts_event":"2026-04-07T02:24:23.031932899Z","rtype":160,"publisher_id":101,"instrument_id":436},"action":"A","side":"A","price":"1.156560000","size":30,"channel_id":23,"order_id":"1775528663031939000","flags":128,"ts_in_delta":920,"sequence":159828,"symbol":"FCEU SI 20260615 PS"}
{"ts_recv":"2026-04-07T02:24:23.380436760Z","hd":{"ts_event":"2026-04-07T02:24:23.380414193Z","rtype":160,"publisher_id":101,"instrument_id":436},"action":"C","side":"B","price":"1.156460000","size":30,"channel_id":23,"order_id":"10998900699886714808","flags":0,"ts_in_delta":949,"sequence":159838,"symbol":"FCEU SI 20260615 PS"}
{"ts_recv":"2026-04-07T02:24:23.380436760Z","hd":{"ts_event":"2026-04-07T02:24:23.380414193Z","rtype":160,"publisher_id":101,"instrument_id":436},"action":"A","side":"B","price":"1.156470000","size":30,"channel_id":23,"order_id":"10998900700235196203","flags":0,"ts_in_delta":949,"sequence":159838,"symbol":"FCEU SI 20260615 PS"}
{"ts_recv":"2026-04-07T02:24:23.380436760Z","hd":{"ts_event":"2026-04-07T02:24:23.380414193Z","rtype":160,"publisher_id":101,"instrument_id":436},"action":"C","side":"A","price":"1.156560000","size":30,"channel_id":23,"order_id":"1775528663031939000","flags":0,"ts_in_delta":949,"sequence":159838,"symbol":"FCEU SI 20260615 PS"}
{"ts_recv":"2026-04-07T02:24:23.380436760Z","hd":{"ts_event":"2026-04-07T02:24:23.380414193Z","rtype":160,"publisher_id":101,"instrument_id":436},"action":"A","side":"A","price":"1.156570000","size":30,"channel_id":23,"order_id":"1775528663380420395","flags":128,"ts_in_delta":949,"sequence":159838,"symbol":"FCEU SI 20260615 PS"}
{"ts_recv":"2026-04-07T02:24:23.380518902Z","hd":{"ts_event":"2026-04-07T02:24:23.380498271Z","rtype":160,"publisher_id":101,"instrument_id":436},"action":"C","side":"B","price":"1.156470000","size":30,"channel_id":23,"order_id":"10998900700235196203","flags":0,"ts_in_delta":1101,"sequence":159839,"symbol":"FCEU SI 20260615 PS"}
{"ts_recv":"2026-04-07T02:24:23.380518902Z","hd":{"ts_event":"2026-04-07T02:24:23.380498271Z","rtype":160,"publisher_id":101,"instrument_id":436},"action":"A","side":"B","price":"1.156480000","size":30,"channel_id":23,"order_id":"10998900700235279993","flags":0,"ts_in_delta":1101,"sequence":159839,"symbol":"FCEU SI 20260615 PS"}
{"ts_recv":"2026-04-07T02:24:23.380518902Z","hd":{"ts_event":"2026-04-07T02:24:23.380498271Z","rtype":160,"publisher_id":101,"instrument_id":436},"action":"C","side":"A","price":"1.156570000","size":30,"channel_id":23,"order_id":"1775528663380420395","flags":0,"ts_in_delta":1101,"sequence":159839,"symbol":"FCEU SI 20260615 PS"}
{"ts_recv":"2026-04-07T02:24:23.380518902Z","hd":{"ts_event":"2026-04-07T02:24:23.380498271Z","rtype":160,"publisher_id":101,"instrument_id":436},"action":"A","side":"A","price":"1.156580000","size":30,"channel_id":23,"order_id":"1775528663380504185","flags":128,"ts_in_delta":1101,"sequence":159839,"symbol":"FCEU SI 20260615 PS"}
{"ts_recv":"2026-04-07T02:24:23.380569956Z","hd":{"ts_event":"2026-04-07T02:24:23.380551723Z","rtype":160,"publisher_id":101,"instrument_id":436},"action":"C","side":"B","price":"1.156460000","size":30,"channel_id":23,"order_id":"10998900699886653393","flags":0,"ts_in_delta":961,"sequence":159840,"symbol":"FCEU SI 20260615 PS"}
{"ts_recv":"2026-04-07T02:24:23.380569956Z","hd":{"ts_event":"2026-04-07T02:24:23.380551723Z","rtype":160,"publisher_id":101,"instrument_id":436},"action":"A","side":"B","price":"1.156480000","size":30,"channel_id":23,"order_id":"10998900700235333751","flags":0,"ts_in_delta":961,"sequence":159840,"symbol":"FCEU SI 20260615 PS"}
{"ts_recv":"2026-04-07T02:24:23.380569956Z","hd":{"ts_event":"2026-04-07T02:24:23.380551723Z","rtype":160,"publisher_id":101,"instrument_id":436},"action":"C","side":"A","price":"1.156560000","size":30,"channel_id":23,"order_id":"1775528663031877585","flags":0,"ts_in_delta":961,"sequence":159840,"symbol":"FCEU SI 20260615 PS"}
{"ts_recv":"2026-04-07T02:24:23.380569956Z","hd":{"ts_event":"2026-04-07T02:24:23.380551723Z","rtype":160,"publisher_id":101,"instrument_id":436},"action":"A","side":"A","price":"1.156580000","size":30,"channel_id":23,"order_id":"1775528663380557943","flags":128,"ts_in_delta":961,"sequence":159840,"symbol":"FCEU SI 20260615 PS"}
{"ts_recv":"2026-04-07T02:24:23.380579840Z","hd":{"ts_event":"2026-04-07T02:24:23.380558387Z","rtype":160,"publisher_id":101,"instrument_id":436},"action":"C","side":"B","price":"1.156480000","size":30,"channel_id":23,"order_id":"10998900700235279993","flags":0,"ts_in_delta":1090,"sequence":159841,"symbol":"FCEU SI 20260615 PS"}
{"ts_recv":"2026-04-07T02:24:23.380579840Z","hd":{"ts_event":"2026-04-07T02:24:23.380558387Z","rtype":160,"publisher_id":101,"instrument_id":436},"action":"A","side":"B","price":"1.156470000","size":30,"channel_id":23,"order_id":"10998900700235342475","flags":0,"ts_in_delta":1090,"sequence":159841,"symbol":"FCEU SI 20260615 PS"}
{"ts_recv":"2026-04-07T02:24:23.380579840Z","hd":{"ts_event":"2026-04-07T02:24:23.380558387Z","rtype":160,"publisher_id":101,"instrument_id":436},"action":"C","side":"A","price":"1.156580000","size":30,"channel_id":23,"order_id":"1775528663380504185","flags":0,"ts_in_delta":1090,"sequence":159841,"symbol":"FCEU SI 20260615 PS"}
{"ts_recv":"2026-04-07T02:24:23.380579840Z","hd":{"ts_event":"2026-04-07T02:24:23.380558387Z","rtype":160,"publisher_id":101,"instrument_id":436},"action":"A","side":"A","price":"1.156570000","size":30,"channel_id":23,"order_id":"1775528663380566667","flags":128,"ts_in_delta":1090,"sequence":159841,"symbol":"FCEU SI 20260615 PS"}
{"ts_recv":"2026-04-07T02:24:23.380634642Z","hd":{"ts_event":"2026-04-07T02:24:23.380617695Z","rtype":160,"publisher_id":101,"instrument_id":436},"action":"C","side":"B","price":"1.156470000","size":30,"channel_id":23,"order_id":"10998900700235342475","flags":0,"ts_in_delta":1113,"sequence":159842,"symbol":"FCEU SI 20260615 PS"}
{"ts_recv":"2026-04-07T02:24:23.380634642Z","hd":{"ts_event":"2026-04-07T02:24:23.380617695Z","rtype":160,"publisher_id":101,"instrument_id":436},"action":"A","side":"B","price":"1.156480000","size":30,"channel_id":23,"order_id":"10998900700235399291","flags":0,"ts_in_delta":1113,"sequence":159842,"symbol":"FCEU SI 20260615 PS"}
{"ts_recv":"2026-04-07T02:24:23.380634642Z","hd":{"ts_event":"2026-04-07T02:24:23.380617695Z","rtype":160,"publisher_id":101,"instrument_id":436},"action":"C","side":"A","price":"1.156570000","size":30,"channel_id":23,"order_id":"1775528663380566667","flags":0,"ts_in_delta":1113,"sequence":159842,"symbol":"FCEU SI 20260615 PS"}
{"ts_recv":"2026-04-07T02:24:23.380634642Z","hd":{"ts_event":"2026-04-07T02:24:23.380617695Z","rtype":160,"publisher_id":101,"instrument_id":436},"action":"A","side":"A","price":"1.156580000","size":30,"channel_id":23,"order_id":"1775528663380623483","flags":128,"ts_in_delta":1113,"sequence":159842,"symbol":"FCEU SI 20260615 PS"}
{"ts_recv":"2026-04-07T02:24:28.040867768Z","hd":{"ts_event":"2026-04-07T02:24:28.040849389Z","rtype":160,"publisher_id":101,"instrument_id":436},"action":"C","side":"B","price":"1.156480000","size":30,"channel_id":23,"order_id":"10998900700235399291","flags":0,"ts_in_delta":972,"sequence":159896,"symbol":"FCEU SI 20260615 PS"}
{"ts_recv":"2026-04-07T02:24:28.040867768Z","hd":{"ts_event":"2026-04-07T02:24:28.040849389Z","rtype":160,"publisher_id":101,"instrument_id":436},"action":"A","side":"B","price":"1.156490000","size":30,"channel_id":23,"order_id":"10998900704895631041","flags":0,"ts_in_delta":972,"sequence":159896,"symbol":"FCEU SI 20260615 PS"}
{"ts_recv":"2026-04-07T02:24:28.040867768Z","hd":{"ts_event":"2026-04-07T02:24:28.040849389Z","rtype":160,"publisher_id":101,"instrument_id":436},"action":"C","side":"A","price":"1.156580000","size":30,"channel_id":23,"order_id":"1775528663380623483","flags":0,"ts_in_delta":972,"sequence":159896,"symbol":"FCEU SI 20260615 PS"}
{"ts_recv":"2026-04-07T02:24:28.040867768Z","hd":{"ts_event":"2026-04-07T02:24:28.040849389Z","rtype":160,"publisher_id":101,"instrument_id":436},"action":"A","side":"A","price":"1.156590000","size":30,"channel_id":23,"order_id":"1775528668040855233","flags":128,"ts_in_delta":972,"sequence":159896,"symbol":"FCEU SI 20260615 PS"}
{"ts_recv":"2026-04-07T02:25:02.323795759Z","hd":{"ts_event":"2026-04-07T02:25:02.323767985Z","rtype":160,"publisher_id":101,"instrument_id":436},"action":"C","side":"B","price":"1.156490000","size":30,"channel_id":23,"order_id":"10998900704895631041","flags":0,"ts_in_delta":1584,"sequence":160190,"symbol":"FCEU SI 20260615 PS"}
{"ts_recv":"2026-04-07T02:25:02.323795759Z","hd":{"ts_event":"2026-04-07T02:25:02.323767985Z","rtype":160,"publisher_id":101,"instrument_id":436},"action":"A","side":"B","price":"1.156480000","size":30,"channel_id":23,"order_id":"10998900739178551933","flags":0,"ts_in_delta":1584,"sequence":160190,"symbol":"FCEU SI 20260615 PS"}
{"ts_recv":"2026-04-07T02:25:02.323795759Z","hd":{"ts_event":"2026-04-07T02:25:02.323767985Z","rtype":160,"publisher_id":101,"instrument_id":436},"action":"C","side":"A","price":"1.156590000","size":30,"channel_id":23,"order_id":"1775528668040855233","flags":0,"ts_in_delta":1584,"sequence":160190,"symbol":"FCEU SI 20260615 PS"}
{"ts_recv":"2026-04-07T02:25:02.323795759Z","hd":{"ts_event":"2026-04-07T02:25:02.323767985Z","rtype":160,"publisher_id":101,"instrument_id":436},"action":"A","side":"A","price":"1.156580000","size":30,"channel_id":23,"order_id":"1775528702323776125","flags":128,"ts_in_delta":1584,"sequence":160190,"symbol":"FCEU SI 20260615 PS"}
{"ts_recv":"2026-04-07T02:25:02.331049815Z","hd":{"ts_event":"2026-04-07T02:25:02.331029843Z","rtype":160,"publisher_id":101,"instrument_id":436},"action":"C","side":"B","price":"1.156480000","size":30,"channel_id":23,"order_id":"10998900700235333751","flags":0,"ts_in_delta":896,"sequence":160193,"symbol":"FCEU SI 20260615 PS"}
{"ts_recv":"2026-04-07T02:25:02.331049815Z","hd":{"ts_event":"2026-04-07T02:25:02.331029843Z","rtype":160,"publisher_id":101,"instrument_id":436},"action":"A","side":"B","price":"1.156460000","size":30,"channel_id":23,"order_id":"10998900739185811856","flags":0,"ts_in_delta":896,"sequence":160193,"symbol":"FCEU SI 20260615 PS"}
{"ts_recv":"2026-04-07T02:25:02.331049815Z","hd":{"ts_event":"2026-04-07T02:25:02.331029843Z","rtype":160,"publisher_id":101,"instrument_id":436},"action":"C","side":"A","price":"1.156580000","size":30,"channel_id":23,"order_id":"1775528663380557943","flags":0,"ts_in_delta":896,"sequence":160193,"symbol":"FCEU SI 20260615 PS"}
{"ts_recv":"2026-04-07T02:25:02.331049815Z","hd":{"ts_event":"2026-04-07T02:25:02.331029843Z","rtype":160,"publisher_id":101,"instrument_id":436},"action":"A","side":"A","price":"1.156560000","size":30,"channel_id":23,"order_id":"1775528702331036048","flags":128,"ts_in_delta":896,"sequence":160193,"symbol":"FCEU SI 20260615 PS"}
{"ts_recv":"2026-04-07T02:25:02.331118425Z","hd":{"ts_event":"2026-04-07T02:25:02.331097915Z","rtype":160,"publisher_id":101,"instrument_id":436},"action":"C","side":"B","price":"1.156480000","size":30,"channel_id":23,"order_id":"10998900739178551933","flags":0,"ts_in_delta":918,"sequence":160194,"symbol":"FCEU SI 20260615 PS"}
{"ts_recv":"2026-04-07T02:25:02.331118425Z","hd":{"ts_event":"2026-04-07T02:25:02.331097915Z","rtype":160,"publisher_id":101,"instrument_id":436},"action":"A","side":"B","price":"1.156470000","size":30,"channel_id":23,"order_id":"10998900739185880263","flags":0,"ts_in_delta":918,"sequence":160194,"symbol":"FCEU SI 20260615 PS"}
{"ts_recv":"2026-04-07T02:25:02.331118425Z","hd":{"ts_event":"2026-04-07T02:25:02.331097915Z","rtype":160,"publisher_id":101,"instrument_id":436},"action":"C","side":"A","price":"1.156580000","size":30,"channel_id":23,"order_id":"1775528702323776125","flags":0,"ts_in_delta":918,"sequence":160194,"symbol":"FCEU SI 20260615 PS"}
{"ts_recv":"2026-04-07T02:25:02.331118425Z","hd":{"ts_event":"2026-04-07T02:25:02.331097915Z","rtype":160,"publisher_id":101,"instrument_id":436},"action":"A","side":"A","price":"1.156570000","size":30,"channel_id":23,"order_id":"1775528702331104455","flags":128,"ts_in_delta":918,"sequence":160194,"symbol":"FCEU SI 20260615 PS"}
{"ts_recv":"2026-04-07T02:25:02.333188720Z","hd":{"ts_event":"2026-04-07T02:25:02.333167913Z","rtype":160,"publisher_id":101,"instrument_id":436},"action":"C","side":"B","price":"1.156470000","size":30,"channel_id":23,"order_id":"10998900739185880263","flags":0,"ts_in_delta":907,"sequence":160195,"symbol":"FCEU SI 20260615 PS"}
{"ts_recv":"2026-04-07T02:25:02.333188720Z","hd":{"ts_event":"2026-04-07T02:25:02.333167913Z","rtype":160,"publisher_id":101,"instrument_id":436},"action":"A","side":"B","price":"1.156450000","size":30,"channel_id":23,"order_id":"10998900739187949644","flags":0,"ts_in_delta":907,"sequence":160195,"symbol":"FCEU SI 20260615 PS"}
{"ts_recv":"2026-04-07T02:25:02.333188720Z","hd":{"ts_event":"2026-04-07T02:25:02.333167913Z","rtype":160,"publisher_id":101,"instrument_id":436},"action":"C","side":"A","price":"1.156570000","size":30,"channel_id":23,"order_id":"1775528702331104455","flags":0,"ts_in_delta":907,"sequence":160195,"symbol":"FCEU SI 20260615 PS"}