{"ts_recv":"2026-04-07T02:30:11.711700311Z","hd":{"ts_event":"2026-04-07T02:30:11.711679507Z","rtype":160,"publisher_id":101,"instrument_id":436},"action":"C","side":"B","price":"1.156550000","size":30,"channel_id":23,"order_id":"10998901045018587257","flags":0,"ts_in_delta":914,"sequence":163017,"symbol":"FCEU SI 20260615 PS"}
{"ts_recv":"2026-04-07T02:30:11.711700311Z","hd":{"ts_event":"2026-04-07T02:30:11.711679507Z","rtype":160,"publisher_id":101,"instrument_id":436},"action":"A","side":"B","price":"1.156570000","size":30,"channel_id":23,"order_id":"10998901048566461537","flags":0,"ts_in_delta":914,"sequence":163017,"symbol":"FCEU SI 20260615 PS"}
{"ts_recv":"2026-04-07T02:30:11.711700311Z","hd":{"ts_event":"2026-04-07T02:30:11.711679507Z","rtype":160,"publisher_id":101,"instrument_id":436},"action":"C","side":"A","price":"1.156650000","size":30,"channel_id":23,"order_id":"1775529008163811449","flags":0,"ts_in_delta":914,"sequence":163017,"symbol":"FCEU SI 20260615 PS"}
{"ts_recv":"2026-04-07T02:30:11.711700311Z","hd":{"ts_event":"2026-04-07T02:30:11.711679507Z","rtype":160,"publisher_id":101,"instrument_id":436},"action":"A","side":"A","price":"1.156670000","size":30,"channel_id":23,"order_id":"1775529011711685729","flags":128,"ts_in_delta":914,"sequence":163017,"symbol":"FCEU SI 20260615 PS"}
{"ts_recv":"2026-04-07T02:30:11.711757854Z","hd":{"ts_event":"2026-04-07T02:30:11.711741851Z","rtype":160,"publisher_id":101,"instrument_id":436},"action":"C","side":"B","price":"1.156560000","size":30,"channel_id":23,"order_id":"10998901048566408772","flags":0,"ts_in_delta":878,"sequence":163018,"symbol":"FCEU SI 20260615 PS"}
{"ts_recv":"2026-04-07T02:30:11.711757854Z","hd":{"ts_event":"2026-04-07T02:30:11.711741851Z","rtype":160,"publisher_id":101,"instrument_id":436},"action":"A","side":"B","price":"1.156570000","size":30,"channel_id":23,"order_id":"10998901048566523363","flags":0,"ts_in_delta":878,"sequence":163018,"symbol":"FCEU SI 20260615 PS"}
{"ts_recv":"2026-04-07T02:30:11.711757854Z","hd":{"ts_event":"2026-04-07T02:30:11.711741851Z","rtype":160,"publisher_id":101,"instrument_id":436},"action":"C","side":"A","price":"1.156660000","size":30,"channel_id":23,"order_id":"1775529011711632964","flags":0,"ts_in_delta":878,"sequence":163018,"symbol":"FCEU SI 20260615 PS"}
{"ts_recv":"2026-04-07T02:30:11.711757854Z","hd":{"ts_event":"2026-04-07T02:30:11.711741851Z","rtype":160,"publisher_id":101,"instrument_id":436},"action":"A","side":"A","price":"1.156670000","size":30,"channel_id":23,"order_id":"1775529011711747555","flags":128,"ts_in_delta":878,"sequence":163018,"symbol":"FCEU SI 20260615 PS"}
{"ts_recv":"2026-04-07T02:30:11.781111055Z","hd":{"ts_event":"2026-04-07T02:30:11.781092299Z","rtype":160,"publisher_id":101,"instrument_id":436},"action":"C","side":"B","price":"1.156570000","size":30,"channel_id":23,"order_id":"10998901048566523363","flags":0,"ts_in_delta":900,"sequence":163036,"symbol":"FCEU SI 20260615 PS"}
{"ts_recv":"2026-04-07T02:30:11.781111055Z","hd":{"ts_event":"2026-04-07T02:30:11.781092299Z","rtype":160,"publisher_id":101,"instrument_id":436},"action":"A","side":"B","price":"1.156580000","size":30,"channel_id":23,"order_id":"10998901048635873883","flags":0,"ts_in_delta":900,"sequence":163036,"symbol":"FCEU SI 20260615 PS"}
{"ts_recv":"2026-04-07T02:30:11.781111055Z","hd":{"ts_event":"2026-04-07T02:30:11.781092299Z","rtype":160,"publisher_id":101,"instrument_id":436},"action":"C","side":"A","price":"1.156670000","size":30,"channel_id":23,"order_id":"1775529011711747555","flags":0,"ts_in_delta":900,"sequence":163036,"symbol":"FCEU SI 20260615 PS"}
{"ts_recv":"2026-04-07T02:30:11.781111055Z","hd":{"ts_event":"2026-04-07T02:30:11.781092299Z","rtype":160,"publisher_id":101,"instrument_id":436},"action":"A","side":"A","price":"1.156680000","size":30,"channel_id":23,"order_id":"1775529011781098075","flags":128,"ts_in_delta":900,"sequence":163036,"symbol":"FCEU SI 20260615 PS"}
{"ts_recv":"2026-04-07T02:30:11.781192698Z","hd":{"ts_event":"2026-04-07T02:30:11.781171713Z","rtype":160,"publisher_id":101,"instrument_id":436},"action":"C","side":"B","price":"1.156580000","size":30,"channel_id":23,"order_id":"10998901048635873883","flags":0,"ts_in_delta":928,"sequence":163037,"symbol":"FCEU SI 20260615 PS"}
{"ts_recv":"2026-04-07T02:30:11.781192698Z","hd":{"ts_event":"2026-04-07T02:30:11.781171713Z","rtype":160,"publisher_id":101,"instrument_id":436},"action":"A","side":"B","price":"1.156590000","size":30,"channel_id":23,"order_id":"10998901048635953309","flags":0,"ts_in_delta":928,"sequence":163037,"symbol":"FCEU SI 20260615 PS"}
{"ts_recv":"2026-04-07T02:30:11.781192698Z","hd":{"ts_event":"2026-04-07T02:30:11.781171713Z","rtype":160,"publisher_id":101,"instrument_id":436},"action":"C","side":"A","price":"1.156680000","size":30,"channel_id":23,"order_id":"1775529011781098075","flags":0,"ts_in_delta":928,"sequence":163037,"symbol":"FCEU SI 20260615 PS"}
{"ts_recv":"2026-04-07T02:30:11.781192698Z","hd":{"ts_event":"2026-04-07T02:30:11.781171713Z","rtype":160,"publisher_id":101,"instrument_id":436},"action":"A","side":"A","price":"1.156690000","size":30,"channel_id":23,"order_id":"1775529011781177501","flags":128,"ts_in_delta":928,"sequence":163037,"symbol":"FCEU SI 20260615 PS"}
{"ts_recv":"2026-04-07T02:30:11.781245203Z","hd":{"ts_event":"2026-04-07T02:30:11.781227067Z","rtype":160,"publisher_id":101,"instrument_id":436},"action":"C","side":"B","price":"1.156570000","size":30,"channel_id":23,"order_id":"10998901048566461537","flags":0,"ts_in_delta":916,"sequence":163038,"symbol":"FCEU SI 20260615 PS"}
{"ts_recv":"2026-04-07T02:30:11.781245203Z","hd":{"ts_event":"2026-04-07T02:30:11.781227067Z","rtype":160,"publisher_id":101,"instrument_id":436},"action":"A","side":"B","price":"1.156590000","size":30,"channel_id":23,"order_id":"10998901048636010584","flags":0,"ts_in_delta":916,"sequence":163038,"symbol":"FCEU SI 20260615 PS"}
{"ts_recv":"2026-04-07T02:30:11.781245203Z","hd":{"ts_event":"2026-04-07T02:30:11.781227067Z","rtype":160,"publisher_id":101,"instrument_id":436},"action":"C","side":"A","price":"1.156670000","size":30,"channel_id":23,"order_id":"1775529011711685729","flags":0,"ts_in_delta":916,"sequence":163038,"symbol":"FCEU SI 20260615 PS"}
{"ts_recv":"2026-04-07T02:30:11.781245203Z","hd":{"ts_event":"2026-04-07T02:30:11.781227067Z","rtype":160,"publisher_id":101,"instrument_id":436},"action":"A","side":"A","price":"1.156690000","size":30,"channel_id":23,"order_id":"1775529011781234776","flags":128,"ts_in_delta":916,"sequence":163038,"symbol":"FCEU SI 20260615 PS"}
{"ts_recv":"2026-04-07T02:30:11.781255371Z","hd":{"ts_event":"2026-04-07T02:30:11.781233325Z","rtype":160,"publisher_id":101,"instrument_id":436},"action":"C","side":"B","price":"1.156590000","size":30,"channel_id":23,"order_id":"10998901048635953309","flags":0,"ts_in_delta":915,"sequence":163039,"symbol":"FCEU SI 20260615 PS"}
{"ts_recv":"2026-04-07T02:30:11.781255371Z","hd":{"ts_event":"2026-04-07T02:30:11.781233325Z","rtype":160,"publisher_id":101,"instrument_id":436},"action":"A","side":"B","price":"1.156580000","size":30,"channel_id":23,"order_id":"10998901048636018011","flags":0,"ts_in_delta":915,"sequence":163039,"symbol":"FCEU SI 20260615 PS"}
{"ts_recv":"2026-04-07T02:30:11.781255371Z","hd":{"ts_event":"2026-04-07T02:30:11.781233325Z","rtype":160,"publisher_id":101,"instrument_id":436},"action":"C","side":"A","price":"1.156690000","size":30,"channel_id":23,"order_id":"1775529011781177501","flags":0,"ts_in_delta":915,"sequence":163039,"symbol":"FCEU SI 20260615 PS"}
{"ts_recv":"2026-04-07T02:30:11.781255371Z","hd":{"ts_event":"2026-04-07T02:30:11.781233325Z","rtype":160,"publisher_id":101,"instrument_id":436},"action":"A","side":"A","price":"1.156680000","size":30,"channel_id":23,"order_id":"1775529011781242203","flags":128,"ts_in_delta":915,"sequence":163039,"symbol":"FCEU SI 20260615 PS"}
{"ts_recv":"2026-04-07T02:30:11.781311102Z","hd":{"ts_event":"2026-04-07T02:30:11.781293555Z","rtype":160,"publisher_id":101,"instrument_id":436},"action":"C","side":"B","price":"1.156580000","size":30,"channel_id":23,"order_id":"10998901048636018011","flags":0,"ts_in_delta":919,"sequence":163040,"symbol":"FCEU SI 20260615 PS"}
{"ts_recv":"2026-04-07T02:30:11.781311102Z","hd":{"ts_event":"2026-04-07T02:30:11.781293555Z","rtype":160,"publisher_id":101,"instrument_id":436},"action":"A","side":"B","price":"1.156590000","size":30,"channel_id":23,"order_id":"10998901048636075492","flags":0,"ts_in_delta":919,"sequence":163040,"symbol":"FCEU SI 20260615 PS"}
{"ts_recv":"2026-04-07T02:30:11.781311102Z","hd":{"ts_event":"2026-04-07T02:30:11.781293555Z","rtype":160,"publisher_id":101,"instrument_id":436},"action":"C","side":"A","price":"1.156680000","size":30,"channel_id":23,"order_id":"1775529011781242203","flags":0,"ts_in_delta":919,"sequence":163040,"symbol":"FCEU SI 20260615 PS"}
{"ts_recv":"2026-04-07T02:30:11.781311102Z","hd":{"ts_event":"2026-04-07T02:30:11.781293555Z","rtype":160,"publisher_id":101,"instrument_id":436},"action":"A","side":"A","price":"1.156690000","size":30,"channel_id":23,"order_id":"1775529011781299684","flags":128,"ts_in_delta":919,"sequence":163040,"symbol":"FCEU SI 20260615 PS"}
{"ts_recv":"2026-04-07T02:30:29.368102321Z","hd":{"ts_event":"2026-04-07T02:30:29.368071381Z","rtype":160,"publisher_id":101,"instrument_id":436},"action":"C","side":"B","price":"1.156590000","size":30,"channel_id":23,"order_id":"10998901048636075492","flags":0,"ts_in_delta":1322,"sequence":163148,"symbol":"FCEU SI 20260615 PS"}
{"ts_recv":"2026-04-07T02:30:29.368102321Z","hd":{"ts_event":"2026-04-07T02:30:29.368071381Z","rtype":160,"publisher_id":101,"instrument_id":436},"action":"A","side":"B","price":"1.156580000","size":30,"channel_id":23,"order_id":"10998901066222857932","flags":0,"ts_in_delta":1322,"sequence":163148,"symbol":"FCEU SI 20260615 PS"}
{"ts_recv":"2026-04-07T02:30:29.368102321Z","hd":{"ts_event":"2026-04-07T02:30:29.368071381Z","rtype":160,"publisher_id":101,"instrument_id":436},"action":"C","side":"A","price":"1.156690000","size":30,"channel_id":23,"order_id":"1775529011781299684","flags":0,"ts_in_delta":1322,"sequence":163148,"symbol":"FCEU SI 20260615 PS"}
{"ts_recv":"2026-04-07T02:30:29.368102321Z","hd":{"ts_event":"2026-04-07T02:30:29.368071381Z","rtype":160,"publisher_id":101,"instrument_id":436},"action":"A","side":"A","price":"1.156680000","size":30,"channel_id":23,"order_id":"1775529029368082124","flags":128,"ts_in_delta":1322,"sequence":163148,"symbol":"FCEU SI 20260615 PS"}
{"ts_recv":"2026-04-07T02:30:29.368167452Z","hd":{"ts_event":"2026-04-07T02:30:29.368145377Z","rtype":160,"publisher_id":101,"instrument_id":436},"action":"C","side":"B","price":"1.156590000","size":30,"channel_id":23,"order_id":"10998901048636010584","flags":0,"ts_in_delta":873,"sequence":163149,"symbol":"FCEU SI 20260615 PS"}
{"ts_recv":"2026-04-07T02:30:29.368167452Z","hd":{"ts_event":"2026-04-07T02:30:29.368145377Z","rtype":160,"publisher_id":101,"instrument_id":436},"action":"A","side":"B","price":"1.156570000","size":30,"channel_id":23,"order_id":"10998901066222927245","flags":0,"ts_in_delta":873,"sequence":163149,"symbol":"FCEU SI 20260615 PS"}
{"ts_recv":"2026-04-07T02:30:29.368167452Z","hd":{"ts_event":"2026-04-07T02:30:29.368145377Z","rtype":160,"publisher_id":101,"instrument_id":436},"action":"C","side":"A","price":"1.156690000","size":30,"channel_id":23,"order_id":"1775529011781234776","flags":0,"ts_in_delta":873,"sequence":163149,"symbol":"FCEU SI 20260615 PS"}
{"ts_recv":"2026-04-07T02:30:29.368167452Z","hd":{"ts_event":"2026-04-07T02:30:29.368145377Z","rtype":160,"publisher_id":101,"instrument_id":436},"action":"A","side":"A","price":"1.156670000","size":30,"channel_id":23,"order_id":"1775529029368151437","flags":128,"ts_in_delta":873,"sequence":163149,"symbol":"FCEU SI 20260615 PS"}
{"ts_recv":"2026-04-07T02:30:29.368231078Z","hd":{"ts_event":"2026-04-07T02:30:29.368210691Z","rtype":160,"publisher_id":101,"instrument_id":436},"action":"C","side":"B","price":"1.156580000","size":30,"channel_id":23,"order_id":"10998901066222857932","flags":0,"ts_in_delta":889,"sequence":163150,"symbol":"FCEU SI 20260615 PS"}
{"ts_recv":"2026-04-07T02:30:29.368231078Z","hd":{"ts_event":"2026-04-07T02:30:29.368210691Z","rtype":160,"publisher_id":101,"instrument_id":436},"action":"A","side":"B","price":"1.156570000","size":30,"channel_id":23,"order_id":"10998901066222992566","flags":0,"ts_in_delta":889,"sequence":163150,"symbol":"FCEU SI 20260615 PS"}
{"ts_recv":"2026-04-07T02:30:29.368231078Z","hd":{"ts_event":"2026-04-07T02:30:29.368210691Z","rtype":160,"publisher_id":101,"instrument_id":436},"action":"C","side":"A","price":"1.156680000","size":30,"channel_id":23,"order_id":"1775529029368082124","flags":0,"ts_in_delta":889,"sequence":163150,"symbol":"FCEU SI 20260615 PS"}
{"ts_recv":"2026-04-07T02:30:29.368231078Z","hd":{"ts_event":"2026-04-07T02:30:29.368210691Z","rtype":160,"publisher_id":101,"instrument_id":436},"action":"A","side":"A","price":"1.156670000","size":30,"channel_id":23,"order_id":"1775529029368216758","flags":128,"ts_in_delta":889,"sequence":163150,"symbol":"FCEU SI 20260615 PS"}
{"ts_recv":"2026-04-07T02:30:29.372007284Z","hd":{"ts_event":"2026-04-07T02:30:29.371989667Z","rtype":160,"publisher_id":101,"instrument_id":436},"action":"C","side":"B","price":"1.156570000","size":30,"channel_id":23,"order_id":"10998901066222992566","flags":0,"ts_in_delta":912,"sequence":163156,"symbol":"FCEU SI 20260615 PS"}
{"ts_recv":"2026-04-07T02:30:29.372007284Z","hd":{"ts_event":"2026-04-07T02:30:29.371989667Z","rtype":160,"publisher_id":101,"instrument_id":436},"action":"A","side":"B","price":"1.156560000","size":30,"channel_id":23,"order_id":"10998901066226771340","flags":0,"ts_in_delta":912,"sequence":163156,"symbol":"FCEU SI 20260615 PS"}
{"ts_recv":"2026-04-07T02:30:29.372007284Z","hd":{"ts_event":"2026-04-07T02:30:29.371989667Z","rtype":160,"publisher_id":101,"instrument_id":436},"action":"C","side":"A","price":"1.156670000","size":30,"channel_id":23,"order_id":"1775529029368216758","flags":0,"ts_in_delta":912,"sequence":163156,"symbol":"FCEU SI 20260615 PS"}
{"ts_recv":"2026-04-07T02:30:29.372007284Z","hd":{"ts_event":"2026-04-07T02:30:29.371989667Z","rtype":160,"publisher_id":101,"instrument_id":436},"action":"A","side":"A","price":"1.156660000","size":30,"channel_id":23,"order_id":"1775529029371995532","flags":128,"ts_in_delta":912,"sequence":163156,"symbol":"FCEU SI 20260615 PS"}
{"ts_recv":"2026-04-07T02:30:29.372088749Z","hd":{"ts_event":"2026-04-07T02:30:29.372069003Z","rtype":160,"publisher_id":101,"instrument_id":436},"action":"C","side":"B","price":"1.156560000","size":30,"channel_id":23,"order_id":"10998901066226771340","flags":0,"ts_in_delta":985,"sequence":163157,"symbol":"FCEU SI 20260615 PS"}
{"ts_recv":"2026-04-07T02:30:29.372088749Z","hd":{"ts_event":"2026-04-07T02:30:29.372069003Z","rtype":160,"publisher_id":101,"instrument_id":436},"action":"A","side":"B","price":"1.156550000","size":30,"channel_id":23,"order_id":"10998901066226850796","flags":0,"ts_in_delta":985,"sequence":163157,"symbol":"FCEU SI 20260615 PS"}
{"ts_recv":"2026-04-07T02:30:29.372088749Z","hd":{"ts_event":"2026-04-07T02:30:29.372069003Z","rtype":160,"publisher_id":101,"instrument_id":436},"action":"C","side":"A","price":"1.156660000","size":30,"channel_id":23,"order_id":"1775529029371995532","flags":0,"ts_in_delta":985,"sequence":163157,"symbol":"FCEU SI 20260615 PS"}
{"ts_recv":"2026-04-07T02:30:29.372088749Z","hd":{"ts_event":"2026-04-07T02:30:29.372069003Z","rtype":160,"publisher_id":101,"instrument_id":436},"action":"A","side":"A","price":"1.156650000","size":30,"channel_id":23,"order_id":"1775529029372074988","flags":128,"ts_in_delta":985,"sequence":163157,"symbol":"FCEU SI 20260615 PS"}
{"ts_recv":"2026-04-07T02:30:29.372151730Z","hd":{"ts_event":"2026-04-07T02:30:29.372133727Z","rtype":160,"publisher_id":101,"instrument_id":436},"action":"C","side":"B","price":"1.156550000","size":30,"channel_id":23,"order_id":"10998901066226850796","flags":0,"ts_in_delta":893,"sequence":163158,"symbol":"FCEU SI 20260615 PS"}
{"ts_recv":"2026-04-07T02:30:29.372151730Z","hd":{"ts_event":"2026-04-07T02:30:29.372133727Z","rtype":160,"publisher_id":101,"instrument_id":436},"action":"A","side":"B","price":"1.156560000","size":30,"channel_id":23,"order_id":"10998901066226915411","flags":0,"ts_in_delta":893,"sequence":163158,"symbol":"FCEU SI 20260615 PS"}
{"ts_recv":"2026-04-07T02:30:29.372151730Z","hd":{"ts_event":"2026-04-07T02:30:29.372133727Z","rtype":160,"publisher_id":101,"instrument_id":436},"action":"C","side":"A","price":"1.156650000","size":30,"channel_id":23,"order_id":"1775529029372074988","flags":0,"ts_in_delta":893,"sequence":163158,"symbol":"FCEU SI 20260615 PS"}
{"ts_recv":"2026-04-07T02:30:29.372151730Z","hd":{"ts_event":"2026-04-07T02:30:29.372133727Z","rtype":160,"publisher_id":101,"instrument_id":436},"action":"A","side":"A","price":"1.156660000","size":30,"channel_id":23,"order_id":"1775529029372139603","flags":128,"ts_in_delta":893,"sequence":163158,"symbol":"FCEU SI 20260615 PS"}
{"ts_recv":"2026-04-07T02:30:29.377043873Z","hd":{"ts_event":"2026-04-07T02:30:29.377025397Z","rtype":160,"publisher_id":101,"instrument_id":436},"action":"C","side":"B","price":"1.156560000","size":30,"channel_id":23,"order_id":"10998901066226915411","flags":0,"ts_in_delta":863,"sequence":163163,"symbol":"FCEU SI 20260615 PS"}
{"ts_recv":"2026-04-07T02:30:29.377043873Z","hd":{"ts_event":"2026-04-07T02:30:29.377025397Z","rtype":160,"publisher_id":101,"instrument_id":436},"action":"A","side":"B","price":"1.156550000","size":30,"channel_id":23,"order_id":"10998901066231807357","flags":0,"ts_in_delta":863,"sequence":163163,"symbol":"FCEU SI 20260615 PS"}
{"ts_recv":"2026-04-07T02:30:29.377043873Z","hd":{"ts_event":"2026-04-07T02:30:29.377025397Z","rtype":160,"publisher_id":101,"instrument_id":436},"action":"C","side":"A","price":"1.156660000","size":30,"channel_id":23,"order_id":"1775529029372139603","flags":0,"ts_in_delta":863,"sequence":163163,"symbol":"FCEU SI 20260615 PS"}
{"ts_recv":"2026-04-07T02:30:29.377043873Z","hd":{"ts_event":"2026-04-07T02:30:29.377025397Z","rtype":160,"publisher_id":101,"instrument_id":436},"action":"A","side":"A","price":"1.156650000","size":30,"channel_id":23,"order_id":"1775529029377031549","flags":128,"ts_in_delta":863,"sequence":163163,"symbol":"FCEU SI 20260615 PS"}
{"ts_recv":"2026-04-07T02:30:29.377094122Z","hd":{"ts_event":"2026-04-07T02:30:29.377077527Z","rtype":160,"publisher_id":101,"instrument_id":436},"action":"C","side":"B","price":"1.156570000","size":30,"channel_id":23,"order_id":"10998901066222927245","flags":0,"ts_in_delta":871,"sequence":163164,"symbol":"FCEU SI 20260615 PS"}
{"ts_recv":"2026-04-07T02:30:29.377094122Z","hd":{"ts_event":"2026-04-07T02:30:29.377077527Z","rtype":160,"publisher_id":101,"instrument_id":436},"action":"A","side":"B","price":"1.156550000","size":30,"channel_id":23,"order_id":"10998901066231859126","flags":0,"ts_in_delta":871,"sequence":163164,"symbol":"FCEU SI 20260615 PS"}
{"ts_recv":"2026-04-07T02:30:29.377094122Z","hd":{"ts_event":"2026-04-07T02:30:29.377077527Z","rtype":160,"publisher_id":101,"instrument_id":436},"action":"C","side":"A","price":"1.156670000","size":30,"channel_id":23,"order_id":"1775529029368151437","flags":0,"ts_in_delta":871,"sequence":163164,"symbol":"FCEU SI 20260615 PS"}
{"ts_recv":"2026-04-07T02:30:29.377094122Z","hd":{"ts_event":"2026-04-07T02:30:29.377077527Z","rtype":160,"publisher_id":101,"instrument_id":436},"action":"A","side":"A","price":"1.156650000","size":30,"channel_id":23,"order_id":"1775529029377083318","flags":128,"ts_in_delta":871,"sequence":163164,"symbol":"FCEU SI 20260615 PS"}
{"ts_recv":"2026-04-07T02:30:29.377149392Z","hd":{"ts_event":"2026-04-07T02:30:29.377129943Z","rtype":160,"publisher_id":101,"instrument_id":436},"action":"C","side":"B","price":"1.156550000","size":30,"channel_id":23,"order_id":"10998901066231807357","flags":0,"ts_in_delta":1059,"sequence":163165,"symbol":"FCEU SI 20260615 PS"}
{"ts_recv":"2026-04-07T02:30:29.377149392Z","hd":{"ts_event":"2026-04-07T02:30:29.377129943Z","rtype":160,"publisher_id":101,"instrument_id":436},"action":"A","side":"B","price":"1.156540000","size":30,"channel_id":23,"order_id":"10998901066231911525","flags":0,"ts_in_delta":1059,"sequence":163165,"symbol":"FCEU SI 20260615 PS"}
{"ts_recv":"2026-04-07T02:30:29.377149392Z","hd":{"ts_event":"2026-04-07T02:30:29.377129943Z","rtype":160,"publisher_id":101,"instrument_id":436},"action":"C","side":"A","price":"1.156650000","size":30,"channel_id":23,"order_id":"1775529029377031549","flags":0,"ts_in_delta":1059,"sequence":163165,"symbol":"FCEU SI 20260615 PS"}
{"ts_recv":"2026-04-07T02:30:29.377149392Z","hd":{"ts_event":"2026-04-07T02:30:29.377129943Z","rtype":160,"publisher_id":101,"instrument_id":436},"action":"A","side":"A","price":"1.156640000","size":30,"channel_id":23,"order_id":"1775529029377135717","flags":128,"ts_in_delta":1059,"sequence":163165,"symbol":"FCEU SI 20260615 PS"}
{"ts_recv":"2026-04-07T02:30:42.462027969Z","hd":{"ts_event":"2026-04-07T02:30:42.462006933Z","rtype":160,"publisher_id":101,"instrument_id":436},"action":"C","side":"B","price":"1.156540000","size":30,"channel_id":23,"order_id":"10998901066231911525","flags":0,"ts_in_delta":958,"sequence":163241,"symbol":"FCEU SI 20260615 PS"}
{"ts_recv":"2026-04-07T02:30:42.462027969Z","hd":{"ts_event":"2026-04-07T02:30:42.462006933Z","rtype":160,"publisher_id":101,"instrument_id":436},"action":"A","side":"B","price":"1.156550000","size":30,"channel_id":23,"order_id":"10998901079316789082","flags":0,"ts_in_delta":958,"sequence":163241,"symbol":"FCEU SI 20260615 PS"}
{"ts_recv":"2026-04-07T02:30:42.462027969Z","hd":{"ts_event":"2026-04-07T02:30:42.462006933Z","rtype":160,"publisher_id":101,"instrument_id":436},"action":"C","side":"A","price":"1.156640000","size":30,"channel_id":23,"order_id":"1775529029377135717","flags":0,"ts_in_delta":958,"sequence":163241,"symbol":"FCEU SI 20260615 PS"}
{"ts_recv":"2026-04-07T02:30:42.462027969Z","hd":{"ts_event":"2026-04-07T02:30:42.462006933Z","rtype":160,"publisher_id":101,"instrument_id":436},"action":"A","side":"A","price":"1.156650000","size":30,"channel_id":23,"order_id":"1775529042462013274","flags":128,"ts_in_delta":958,"sequence":163241,"symbol":"FCEU SI 20260615 PS"}
{"ts_recv":"2026-04-07T02:30:42.470750750Z","hd":{"ts_event":"2026-04-07T02:30:42.470729287Z","rtype":160,"publisher_id":101,"instrument_id":436},"action":"C","side":"B","price":"1.156550000","size":30,"channel_id":23,"order_id":"10998901079316789082","flags":0,"ts_in_delta":798,"sequence":163246,"symbol":"FCEU SI 20260615 PS"}
{"ts_recv":"2026-04-07T02:30:42.470750750Z","hd":{"ts_event":"2026-04-07T02:30:42.470729287Z","rtype":160,"publisher_id":101,"instrument_id":436},"action":"A","side":"B","price":"1.156560000","size":30,"channel_id":23,"order_id":"10998901079325511277","flags":0,"ts_in_delta":798,"sequence":163246,"symbol":"FCEU SI 20260615 PS"}
{"ts_recv":"2026-04-07T02:30:42.470750750Z","hd":{"ts_event":"2026-04-07T02:30:42.470729287Z","rtype":160,"publisher_id":101,"instrument_id":436},"action":"C","side":"A","price":"1.156650000","size":30,"channel_id":23,"order_id":"1775529042462013274","flags":0,"ts_in_delta":798,"sequence":163246,"symbol":"FCEU SI 20260615 PS"}
{"ts_recv":"2026-04-07T02:30:42.470750750Z","hd":{"ts_event":"2026-04-07T02:30:42.470729287Z","rtype":160,"publisher_id":101,"instrument_id":436},"action":"A","side":"A","price":"1.156660000","size":30,"channel_id":23,"order_id":"1775529042470735469","flags":128,"ts_in_delta":798,"sequence":163246,"symbol":"FCEU SI 20260615 PS"}
{"ts_recv":"2026-04-07T02:30:42.470805652Z","hd":{"ts_event":"2026-04-07T02:30:42.470787195Z","rtype":160,"publisher_id":101,"instrument_id":436},"action":"C","side":"B","price":"1.156550000","size":30,"channel_id":23,"order_id":"10998901066231859126","flags":0,"ts_in_delta":876,"sequence":163247,"symbol":"FCEU SI 20260615 PS"}
{"ts_recv":"2026-04-07T02:30:42.470805652Z","hd":{"ts_event":"2026-04-07T02:30:42.470787195Z","rtype":160,"publisher_id":101,"instrument_id":436},"action":"A","side":"B","price":"1.156570000","size":30,"channel_id":23,"order_id":"10998901079325568878","flags":0,"ts_in_delta":876,"sequence":163247,"symbol":"FCEU SI 20260615 PS"}
{"ts_recv":"2026-04-07T02:30:42.470805652Z","hd":{"ts_event":"2026-04-07T02:30:42.470787195Z","rtype":160,"publisher_id":101,"instrument_id":436},"action":"C","side":"A","price":"1.156650000","size":30,"channel_id":23,"order_id":"1775529029377083318","flags":0,"ts_in_delta":876,"sequence":163247,"symbol":"FCEU SI 20260615 PS"}
{"ts_recv":"2026-04-07T02:30:42.470805652Z","hd":{"ts_event":"2026-04-07T02:30:42.470787195Z","rtype":160,"publisher_id":101,"instrument_id":436},"action":"A","side":"A","price":"1.156670000","size":30,"channel_id":23,"order_id":"1775529042470793070","flags":128,"ts_in_delta":876,"sequence":163247,"symbol":"FCEU SI 20260615 PS"}
{"ts_recv":"2026-04-07T02:30:42.470859218Z","hd":{"ts_event":"2026-04-07T02:30:42.470842299Z","rtype":160,"publisher_id":101,"instrument_id":436},"action":"C","side":"B","price":"1.156560000","size":30,"channel_id":23,"order_id":"10998901079325511277","flags":0,"ts_in_delta":935,"sequence":163248,"symbol":"FCEU SI 20260615 PS"}
{"ts_recv":"2026-04-07T02:30:42.470859218Z","hd":{"ts_event":"2026-04-07T02:30:42.470842299Z","rtype":160,"publisher_id":101,"instrument_id":436},"action":"A","side":"B","price":"1.156570000","size":30,"channel_id":23,"order_id":"10998901079325624171","flags":0,"ts_in_delta":935,"sequence":163248,"symbol":"FCEU SI 20260615 PS"}
{"ts_recv":"2026-04-07T02:30:42.470859218Z","hd":{"ts_event":"2026-04-07T02:30:42.470842299Z","rtype":160,"publisher_id":101,"instrument_id":436},"action":"C","side":"A","price":"1.156660000","size":30,"channel_id":23,"order_id":"1775529042470735469","flags":0,"ts_in_delta":935,"sequence":163248,"symbol":"FCEU SI 20260615 PS"}
{"ts_recv":"2026-04-07T02:30:42.470859218Z","hd":{"ts_event":"2026-04-07T02:30:42.470842299Z","rtype":160,"publisher_id":101,"instrument_id":436},"action":"A","side":"A","price":"1.156670000","size":30,"channel_id":23,"order_id":"1775529042470848363","flags":128,"ts_in_delta":935,"sequence":163248,"symbol":"FCEU SI 20260615 PS"}
{"ts_recv":"2026-04-07T02:30:42.475560276Z","hd":{"ts_event":"2026-04-07T02:30:42.475539281Z","rtype":160,"publisher_id":101,"instrument_id":436},"action":"C","side":"B","price":"1.156570000","size":30,"channel_id":23,"order_id":"10998901079325624171","flags":0,"ts_in_delta":1047,"sequence":163255,"symbol":"FCEU SI 20260615 PS"}
{"ts_recv":"2026-04-07T02:30:42.475560276Z","hd":{"ts_event":"2026-04-07T02:30:42.475539281Z","rtype":160,"publisher_id":101,"instrument_id":436},"action":"A","side":"B","price":"1.156580000","size":30,"channel_id":23,"order_id":"10998901079330320869","flags":0,"ts_in_delta":1047,"sequence":163255,"symbol":"FCEU SI 20260615 PS"}
{"ts_recv":"2026-04-07T02:30:42.475560276Z","hd":{"ts_event":"2026-04-07T02:30:42.475539281Z","rtype":160,"publisher_id":101,"instrument_id":436},"action":"C","side":"A","price":"1.156670000","size":30,"channel_id":23,"order_id":"1775529042470848363","flags":0,"ts_in_delta":1047,"sequence":163255,"symbol":"FCEU SI 20260615 PS"}
{"ts_recv":"2026-04-07T02:30:42.475560276Z","hd":{"ts_event":"2026-04-07T02:30:42.475539281Z","rtype":160,"publisher_id":101,"instrument_id":436},"action":"A","side":"A","price":"1.156680000","size":30,"channel_id":23,"order_id":"1775529042475545061","flags":128,"ts_in_delta":1047,"sequence":163255,"symbol":"FCEU SI 20260615 PS"}
{"ts_recv":"2026-04-07T02:30:42.483939661Z","hd":{"ts_event":"2026-04-07T02:30:42.483919489Z","rtype":160,"publisher_id":101,"instrument_id":436},"action":"C","side":"B","price":"1.156580000","size":30,"channel_id":23,"order_id":"10998901079330320869","flags":0,"ts_in_delta":957,"sequence":163259,"symbol":"FCEU SI 20260615 PS"}
{"ts_recv":"2026-04-07T02:30:42.483939661Z","hd":{"ts_event":"2026-04-07T02:30:42.483919489Z","rtype":160,"publisher_id":101,"instrument_id":436},"action":"A","side":"B","price":"1.156590000","size":30,"channel_id":23,"order_id":"10998901079338701396","flags":0,"ts_in_delta":957,"sequence":163259,"symbol":"FCEU SI 20260615 PS"}
{"ts_recv":"2026-04-07T02:30:42.483939661Z","hd":{"ts_event":"2026-04-07T02:30:42.483919489Z","rtype":160,"publisher_id":101,"instrument_id":436},"action":"C","side":"A","price":"1.156680000","size":30,"channel_id":23,"order_id":"1775529042475545061","flags":0,"ts_in_delta":957,"sequence":163259,"symbol":"FCEU SI 20260615 PS"}
{"ts_recv":"2026-04-07T02:30:42.483939661Z","hd":{"ts_event":"2026-04-07T02:30:42.483919489Z","rtype":160,"publisher_id":101,"instrument_id":436},"action":"A","side":"A","price":"1.156690000","size":30,"channel_id":23,"order_id":"1775529042483925588","flags":128,"ts_in_delta":957,"sequence":163259,"symbol":"FCEU SI 20260615 PS"}
{"ts_recv":"2026-04-07T02:30:42.484018746Z","hd":{"ts_event":"2026-04-07T02:30:42.484001271Z","rtype":160,"publisher_id":101,"instrument_id":436},"action":"C","side":"B","price":"1.156590000","size":30,"channel_id":23,"order_id":"10998901079338701396","flags":0,"ts_in_delta":979,"sequence":163260,"symbol":"FCEU SI 20260615 PS"}
{"ts_recv":"2026-04-07T02:30:42.484018746Z","hd":{"ts_event":"2026-04-07T02:30:42.484001271Z","rtype":160,"publisher_id":101,"instrument_id":436},"action":"A","side":"B","price":"1.156580000","size":30,"channel_id":23,"order_id":"10998901079338782825","flags":0,"ts_in_delta":979,"sequence":163260,"symbol":"FCEU SI 20260615 PS"}
{"ts_recv":"2026-04-07T02:30:42.484018746Z","hd":{"ts_event":"2026-04-07T02:30:42.484001271Z","rtype":160,"publisher_id":101,"instrument_id":436},"action":"C","side":"A","price":"1.156690000","size":30,"channel_id":23,"order_id":"1775529042483925588","flags":0,"ts_in_delta":979,"sequence":163260,"symbol":"FCEU SI 20260615 PS"}
{"ts_recv":"2026-04-07T02:30:42.484018746Z","hd":{"ts_event":"2026-04-07T02:30:42.484001271Z","rtype":160,"publisher_id":101,"instrument_id":436},"action":"A","side":"A","price":"1.156680000","size":30,"channel_id":23,"order_id":"1775529042484007017","flags":128,"ts_in_delta":979,"sequence":163260,"symbol":"FCEU SI 20260615 PS"}
{"ts_recv":"2026-04-07T02:30:48.361161351Z","hd":{"ts_event":"2026-04-07T02:30:48.361137647Z","rtype":160,"publisher_id":101,"instrument_id":436},"action":"C","side":"B","price":"1.156570000","size":30,"channel_id":23,"order_id":"10998901079325568878","flags":0,"ts_in_delta":869,"sequence":163344,"symbol":"FCEU SI 20260615 PS"}
{"ts_recv":"2026-04-07T02:30:48.361161351Z","hd":{"ts_event":"2026-04-07T02:30:48.361137647Z","rtype":160,"publisher_id":101,"instrument_id":436},"action":"A","side":"B","price":"1.156590000","size":30,"channel_id":23,"order_id":"10998901085215919755","flags":0,"ts_in_delta":869,"sequence":163344,"symbol":"FCEU SI 20260615 PS"}
{"ts_recv":"2026-04-07T02:30:48.361161351Z","hd":{"ts_event":"2026-04-07T02:30:48.361137647Z","rtype":160,"publisher_id":101,"instrument_id":436},"action":"C","side":"A","price":"1.156670000","size":30,"channel_id":23,"order_id":"1775529042470793070","flags":0,"ts_in_delta":869,"sequence":163344,"symbol":"FCEU SI 20260615 PS"}
{"ts_recv":"2026-04-07T02:30:48.361161351Z","hd":{"ts_event":"2026-04-07T02:30:48.361137647Z","rtype":160,"publisher_id":101,"instrument_id":436},"action":"A","side":"A","price":"1.156690000","size":30,"channel_id":23,"order_id":"1775529048361143947","flags":128,"ts_in_delta":869,"sequence":163344,"symbol":"FCEU SI 20260615 PS"}
{"ts_recv":"2026-04-07T02:30:48.361292297Z","hd":{"ts_event":"2026-04-07T02:30:48.361272221Z","rtype":160,"publisher_id":101,"instrument_id":436},"action":"C","side":"B","price":"1.156580000","size":30,"channel_id":23,"order_id":"10998901079338782825","flags":0,"ts_in_delta":909,"sequence":163345,"symbol":"FCEU SI 20260615 PS"}
{"ts_recv":"2026-04-07T02:30:48.361292297Z","hd":{"ts_event":"2026-04-07T02:30:48.361272221Z","rtype":160,"publisher_id":101,"instrument_id":436},"action":"A","side":"B","price":"1.156590000","size":30,"channel_id":23,"order_id":"10998901085216054512","flags":0,"ts_in_delta":909,"sequence":163345,"symbol":"FCEU SI 20260615 PS"}
{"ts_recv":"2026-04-07T02:30:48.361292297Z","hd":{"ts_event":"2026-04-07T02:30:48.361272221Z","rtype":160,"publisher_id":101,"instrument_id":436},"action":"C","side":"A","price":"1.156680000","size":30,"channel_id":23,"order_id":"1775529042484007017","flags":0,"ts_in_delta":909,"sequence":163345,"symbol":"FCEU SI 20260615 PS"}
{"ts_recv":"2026-04-07T02:30:48.361292297Z","hd":{"ts_event":"2026-04-07T02:30:48.361272221Z","rtype":160,"publisher_id":101,"instrument_id":436},"action":"A","side":"A","price":"1.156690000","size":30,"channel_id":23,"order_id":"1775529048361278704","flags":128,"ts_in_delta":909,"sequence":163345,"symbol":"FCEU SI 20260615 PS"}
{"ts_recv":"2026-04-07T02:30:49.664567996Z","hd":{"ts_event":"2026-04-07T02:30:49.664539637Z","rtype":160,"publisher_id":101,"instrument_id":436},"action":"C","side":"B","price":"1.156590000","size":30,"channel_id":23,"order_id":"10998901085216054512","flags":0,"ts_in_delta":1430,"sequence":163352,"symbol":"FCEU SI 20260615 PS"}
{"ts_recv":"2026-04-07T02:30:49.664567996Z","hd":{"ts_event":"2026-04-07T02:30:49.664539637Z","rtype":160,"publisher_id":101,"instrument_id":436},"action":"A","side":"B","price":"1.156580000","size":30,"channel_id":23,"order_id":"10998901086519322810","flags":0,"ts_in_delta":1430,"sequence":163352,"symbol":"FCEU SI 20260615 PS"}
{"ts_recv":"2026-04-07T02:30:49.664567996Z","hd":{"ts_event":"2026-04-07T02:30:49.664539637Z","rtype":160,"publisher_id":101,"instrument_id":436},"action":"C","side":"A","price":"1.156690000","size":30,"channel_id":23,"order_id":"1775529048361278704","flags":0,"ts_in_delta":1430,"sequence":163352,"symbol":"FCEU SI 20260615 PS"}
{"ts_recv":"2026-04-07T02:30:49.664567996Z","hd":{"ts_event":"2026-04-07T02:30:49.664539637Z","rtype":160,"publisher_id":101,"instrument_id":436},"action":"A","side":"A","price":"1.156680000","size":30,"channel_id":23,"order_id":"1775529049664547002","flags":128,"ts_in_delta":1430,"sequence":163352,"symbol":"FCEU SI 20260615 PS"}
{"ts_recv":"2026-04-07T02:30:49.664635815Z","hd":{"ts_event":"2026-04-07T02:30:49.664616303Z","rtype":160,"publisher_id":101,"instrument_id":436},"action":"C","side":"B","price":"1.156590000","size":30,"channel_id":23,"order_id":"10998901085215919755","flags":0,"ts_in_delta":968,"sequence":163353,"symbol":"FCEU SI 20260615 PS"}
{"ts_recv":"2026-04-07T02:30:49.664635815Z","hd":{"ts_event":"2026-04-07T02:30:49.664616303Z","rtype":160,"publisher_id":101,"instrument_id":436},"action":"A","side":"B","price":"1.156570000","size":30,"channel_id":23,"order_id":"10998901086519398401","flags":0,"ts_in_delta":968,"sequence":163353,"symbol":"FCEU SI 20260615 PS"}
{"ts_recv":"2026-04-07T02:30:49.664635815Z","hd":{"ts_event":"2026-04-07T02:30:49.664616303Z","rtype":160,"publisher_id":101,"instrument_id":436},"action":"C","side":"A","price":"1.156690000","size":30,"channel_id":23,"order_id":"1775529048361143947","flags":0,"ts_in_delta":968,"sequence":163353,"symbol":"FCEU SI 20260615 PS"}
{"ts_recv":"2026-04-07T02:30:49.664635815Z","hd":{"ts_event":"2026-04-07T02:30:49.664616303Z","rtype":160,"publisher_id":101,"instrument_id":436},"action":"A","side":"A","price":"1.156670000","size":30,"channel_id":23,"order_id":"1775529049664622593","flags":128,"ts_in_delta":968,"sequence":163353,"symbol":"FCEU SI 20260615 PS"}
{"ts_recv":"2026-04-07T02:30:49.664692706Z","hd":{"ts_event":"2026-04-07T02:30:49.664673423Z","rtype":160,"publisher_id":101,"instrument_id":436},"action":"C","side":"B","price":"1.156580000","size":30,"channel_id":23,"order_id":"10998901086519322810","flags":0,"ts_in_delta":978,"sequence":163354,"symbol":"FCEU SI 20260615 PS"}
{"ts_recv":"2026-04-07T02:30:49.664692706Z","hd":{"ts_event":"2026-04-07T02:30:49.664673423Z","rtype":160,"publisher_id":101,"instrument_id":436},"action":"A","side":"B","price":"1.156570000","size":30,"channel_id":23,"order_id":"10998901086519455581","flags":0,"ts_in_delta":978,"sequence":163354,"symbol":"FCEU SI 20260615 PS"}
{"ts_recv":"2026-04-07T02:30:49.664692706Z","hd":{"ts_event":"2026-04-07T02:30:49.664673423Z","rtype":160,"publisher_id":101,"instrument_id":436},"action":"C","side":"A","price":"1.156680000","size":30,"channel_id":23,"order_id":"1775529049664547002","flags":0,"ts_in_delta":978,"sequence":163354,"symbol":"FCEU SI 20260615 PS"}
{"ts_recv":"2026-04-07T02:30:49.664692706Z","hd":{"ts_event":"2026-04-07T02:30:49.664673423Z","rtype":160,"publisher_id":101,"instrument_id":436},"action":"A","side":"A","price":"1.156670000","size":30,"channel_id":23,"order_id":"1775529049664679773","flags":128,"ts_in_delta":978,"sequence":163354,"symbol":"FCEU SI 20260615 PS"}
{"ts_recv":"2026-04-07T02:30:51.776315004Z","hd":{"ts_event":"2026-04-07T02:30:51.776295197Z","rtype":160,"publisher_id":101,"instrument_id":436},"action":"C","side":"B","price":"1.156570000","size":30,"channel_id":23,"order_id":"10998901086519455581","flags":0,"ts_in_delta":1037,"sequence":163382,"symbol":"FCEU SI 20260615 PS"}
{"ts_recv":"2026-04-07T02:30:51.776315004Z","hd":{"ts_event":"2026-04-07T02:30:51.776295197Z","rtype":160,"publisher_id":101,"instrument_id":436},"action":"A","side":"B","price":"1.156560000","size":30,"channel_id":23,"order_id":"10998901088631077478","flags":0,"ts_in_delta":1037,"sequence":163382,"symbol":"FCEU SI 20260615 PS"}
{"ts_recv":"2026-04-07T02:30:51.776315004Z","hd":{"ts_event":"2026-04-07T02:30:51.776295197Z","rtype":160,"publisher_id":101,"instrument_id":436},"action":"C","side":"A","price":"1.156670000","size":30,"channel_id":23,"order_id":"1775529049664679773","flags":0,"ts_in_delta":1037,"sequence":163382,"symbol":"FCEU SI 20260615 PS"}
{"ts_recv":"2026-04-07T02:30:51.776315004Z","hd":{"ts_event":"2026-04-07T02:30:51.776295197Z","rtype":160,"publisher_id":101,"instrument_id":436},"action":"A","side":"A","price":"1.156660000","size":30,"channel_id":23,"order_id":"1775529051776301670","flags":128,"ts_in_delta":1037,"sequence":163382,"symbol":"FCEU SI 20260615 PS"}
{"ts_recv":"2026-04-07T02:30:51.781674876Z","hd":{"ts_event":"2026-04-07T02:30:51.781650761Z","rtype":160,"publisher_id":101,"instrument_id":436},"action":"C","side":"B","price":"1.156570000","size":30,"channel_id":23,"order_id":"10998901086519398401","flags":0,"ts_in_delta":831,"sequence":163383,"symbol":"FCEU SI 20260615 PS"}
{"ts_recv":"2026-04-07T02:30:51.781674876Z","hd":{"ts_event":"2026-04-07T02:30:51.781650761Z","rtype":160,"publisher_id":101,"instrument_id":436},"action":"A","side":"B","price":"1.156550000","size":30,"channel_id":23,"order_id":"10998901088636432584","flags":0,"ts_in_delta":831,"sequence":163383,"symbol":"FCEU SI 20260615 PS"}
{"ts_recv":"2026-04-07T02:30:51.781674876Z","hd":{"ts_event":"2026-04-07T02:30:51.781650761Z","rtype":160,"publisher_id":101,"instrument_id":436},"action":"C","side":"A","price":"1.156670000","size":30,"channel_id":23,"order_id":"1775529049664622593","flags":0,"ts_in_delta":831,"sequence":163383,"symbol":"FCEU SI 20260615 PS"}
{"ts_recv":"2026-04-07T02:30:51.781674876Z","hd":{"ts_event":"2026-04-07T02:30:51.781650761Z","rtype":160,"publisher_id":101,"instrument_id":436},"action":"A","side":"A","price":"1.156650000","size":30,"channel_id":23,"order_id":"1775529051781656776","flags":128,"ts_in_delta":831,"sequence":163383,"symbol":"FCEU SI 20260615 PS"}
{"ts_recv":"2026-04-07T02:30:51.781732888Z","hd":{"ts_event":"2026-04-07T02:30:51.781715273Z","rtype":160,"publisher_id":101,"instrument_id":436},"action":"C","side":"B","price":"1.156560000","size":30,"channel_id":23,"order_id":"10998901088631077478","flags":0,"ts_in_delta":849,"sequence":163384,"symbol":"FCEU SI 20260615 PS"}
{"ts_recv":"2026-04-07T02:30:51.781732888Z","hd":{"ts_event":"2026-04-07T02:30:51.781715273Z","rtype":160,"publisher_id":101,"instrument_id":436},"action":"A","side":"B","price":"1.156550000","size":30,"channel_id":23,"order_id":"10998901088636497002","flags":0,"ts_in_delta":849,"sequence":163384,"symbol":"FCEU SI 20260615 PS"}
{"ts_recv":"2026-04-07T02:30:51.781732888Z","hd":{"ts_event":"2026-04-07T02:30:51.781715273Z","rtype":160,"publisher_id":101,"instrument_id":436},"action":"C","side":"A","price":"1.156660000","size":30,"channel_id":23,"order_id":"1775529051776301670","flags":0,"ts_in_delta":849,"sequence":163384,"symbol":"FCEU SI 20260615 PS"}
{"ts_recv":"2026-04-07T02:30:51.781732888Z","hd":{"ts_event":"2026-04-07T02:30:51.781715273Z","rtype":160,"publisher_id":101,"instrument_id":436},"action":"A","side":"A","price":"1.156650000","size":30,"channel_id":23,"order_id":"1775529051781721194","flags":128,"ts_in_delta":849,"sequence":163384,"symbol":"FCEU SI 20260615 PS"}
{"ts_recv":"2026-04-07T02:31:03.795073207Z","hd":{"ts_event":"2026-04-07T02:31:03.795038925Z","rtype":160,"publisher_id":101,"instrument_id":436},"action":"C","side":"B","price":"1.156550000","size":30,"channel_id":23,"order_id":"10998901088636497002","flags":0,"ts_in_delta":1292,"sequence":163457,"symbol":"FCEU SI 20260615 PS"}
{"ts_recv":"2026-04-07T02:31:03.795073207Z","hd":{"ts_event":"2026-04-07T02:31:03.795038925Z","rtype":160,"publisher_id":101,"instrument_id":436},"action":"A","side":"B","price":"1.156540000","size":30,"channel_id":23,"order_id":"10998901100649828690","flags":0,"ts_in_delta":1292,"sequence":163457,"symbol":"FCEU SI 20260615 PS"}
{"ts_recv":"2026-04-07T02:31:03.795073207Z","hd":{"ts_event":"2026-04-07T02:31:03.795038925Z","rtype":160,"publisher_id":101,"instrument_id":436},"action":"C","side":"A","price":"1.156650000","size":30,"channel_id":23,"order_id":"1775529051781721194","flags":0,"ts_in_delta":1292,"sequence":163457,"symbol":"FCEU SI 20260615 PS"}
{"ts_recv":"2026-04-07T02:31:03.795073207Z","hd":{"ts_event":"2026-04-07T02:31:03.795038925Z","rtype":160,"publisher_id":101,"instrument_id":436},"action":"A","side":"A","price":"1.156640000","size":30,"channel_id":23,"order_id":"1775529063795052882","flags":128,"ts_in_delta":1292,"sequence":163457,"symbol":"FCEU SI 20260615 PS"}
{"ts_recv":"2026-04-07T02:31:03.795131642Z","hd":{"ts_event":"2026-04-07T02:31:03.795111519Z","rtype":160,"publisher_id":101,"instrument_id":436},"action":"C","side":"B","price":"1.156550000","size":30,"channel_id":23,"order_id":"10998901088636432584","flags":0,"ts_in_delta":1067,"sequence":163458,"symbol":"FCEU SI 20260615 PS"}
{"ts_recv":"2026-04-07T02:31:03.795131642Z","hd":{"ts_event":"2026-04-07T02:31:03.795111519Z","rtype":160,"publisher_id":101,"instrument_id":436},"action":"A","side":"B","price":"1.156530000","size":30,"channel_id":23,"order_id":"10998901100649893868","flags":0,"ts_in_delta":1067,"sequence":163458,"symbol":"FCEU SI 20260615 PS"}
{"ts_recv":"2026-04-07T02:31:03.795131642Z","hd":{"ts_event":"2026-04-07T02:31:03.795111519Z","rtype":160,"publisher_id":101,"instrument_id":436},"action":"C","side":"A","price":"1.156650000","size":30,"channel_id":23,"order_id":"1775529051781656776","flags":0,"ts_in_delta":1067,"sequence":163458,"symbol":"FCEU SI 20260615 PS"}
{"ts_recv":"2026-04-07T02:31:03.795131642Z","hd":{"ts_event":"2026-04-07T02:31:03.795111519Z","rtype":160,"publisher_id":101,"instrument_id":436},"action":"A","side":"A","price":"1.156630000","size":30,"channel_id":23,"order_id":"1775529063795118060","flags":128,"ts_in_delta":1067,"sequence":163458,"symbol":"FCEU SI 20260615 PS"}
{"ts_recv":"2026-04-07T02:31:03.795157238Z","hd":{"ts_event":"2026-04-07T02:31:03.795137837Z","rtype":160,"publisher_id":101,"instrument_id":436},"action":"C","side":"B","price":"1.156540000","size":30,"channel_id":23,"order_id":"10998901100649828690","flags":0,"ts_in_delta":1002,"sequence":163459,"symbol":"FCEU SI 20260615 PS"}
{"ts_recv":"2026-04-07T02:31:03.795157238Z","hd":{"ts_event":"2026-04-07T02:31:03.795137837Z","rtype":160,"publisher_id":101,"instrument_id":436},"action":"A","side":"B","price":"1.156530000","size":30,"channel_id":23,"order_id":"10998901100649919913","flags":0,"ts_in_delta":1002,"sequence":163459,"symbol":"FCEU SI 20260615 PS"}
{"ts_recv":"2026-04-07T02:31:03.795157238Z","hd":{"ts_event":"2026-04-07T02:31:03.795137837Z","rtype":160,"publisher_id":101,"instrument_id":436},"action":"C","side":"A","price":"1.156640000","size":30,"channel_id":23,"order_id":"1775529063795052882","flags":0,"ts_in_delta":1002,"sequence":163459,"symbol":"FCEU SI 20260615 PS"}
{"ts_recv":"2026-04-07T02:31:03.795157238Z","hd":{"ts_event":"2026-04-07T02:31:03.795137837Z","rtype":160,"publisher_id":101,"instrument_id":436},"action":"A","side":"A","price":"1.156630000","size":30,"channel_id":23,"order_id":"1775529063795144105","flags":128,"ts_in_delta":1002,"sequence":163459,"symbol":"FCEU SI 20260615 PS"}
{"ts_recv":"2026-04-07T02:31:04.155137172Z","hd":{"ts_event":"2026-04-07T02:31:04.155113169Z","rtype":160,"publisher_id":101,"instrument_id":436},"action":"C","side":"B","price":"1.156500000","size":20,"channel_id":23,"order_id":"10998901014868479363","flags":128,"ts_in_delta":1911,"sequence":163482,"symbol":"FCEU SI 20260615 PS"}
{"ts_recv":"2026-04-07T02:31:04.240345134Z","hd":{"ts_event":"2026-04-07T02:31:04.240325639Z","rtype":160,"publisher_id":101,"instrument_id":436},"action":"A","side":"B","price":"1.156400000","size":20,"channel_id":23,"order_id":"10998901101095112539","flags":128,"ts_in_delta":1134,"sequence":163483,"symbol":"FCEU SI 20260615 PS"}
{"ts_recv":"2026-04-07T02:31:05.091734571Z","hd":{"ts_event":"2026-04-07T02:31:05.091711369Z","rtype":160,"publisher_id":101,"instrument_id":436},"action":"C","side":"B","price":"1.156530000","size":30,"channel_id":23,"order_id":"10998901100649919913","flags":0,"ts_in_delta":1086,"sequence":163499,"symbol":"FCEU SI 20260615 PS"}
{"ts_recv":"2026-04-07T02:31:05.091734571Z","hd":{"ts_event":"2026-04-07T02:31:05.091711369Z","rtype":160,"publisher_id":101,"instrument_id":436},"action":"A","side":"B","price":"1.156520000","size":30,"channel_id":23,"order_id":"10998901101946493397","flags":0,"ts_in_delta":1086,"sequence":163499,"symbol":"FCEU SI 20260615 PS"}
{"ts_recv":"2026-04-07T02:31:05.091734571Z","hd":{"ts_event":"2026-04-07T02:31:05.091711369Z","rtype":160,"publisher_id":101,"instrument_id":436},"action":"C","side":"A","price":"1.156630000","size":30,"channel_id":23,"order_id":"1775529063795144105","flags":0,"ts_in_delta":1086,"sequence":163499,"symbol":"FCEU SI 20260615 PS"}
{"ts_recv":"2026-04-07T02:31:05.091734571Z","hd":{"ts_event":"2026-04-07T02:31:05.091711369Z","rtype":160,"publisher_id":101,"instrument_id":436},"action":"A","side":"A","price":"1.156620000","size":30,"channel_id":23,"order_id":"1775529065091717589","flags":128,"ts_in_delta":1086,"sequence":163499,"symbol":"FCEU SI 20260615 PS"}
{"ts_recv":"2026-04-07T02:31:05.091789097Z","hd":{"ts_event":"2026-04-07T02:31:05.091768411Z","rtype":160,"publisher_id":101,"instrument_id":436},"action":"C","side":"B","price":"1.156530000","size":30,"channel_id":23,"order_id":"10998901100649893868","flags":0,"ts_in_delta":1072,"sequence":163500,"symbol":"FCEU SI 20260615 PS"}
{"ts_recv":"2026-04-07T02:31:05.091789097Z","hd":{"ts_event":"2026-04-07T02:31:05.091768411Z","rtype":160,"publisher_id":101,"instrument_id":436},"action":"A","side":"B","price":"1.156510000","size":30,"channel_id":23,"order_id":"10998901101946550412","flags":0,"ts_in_delta":1072,"sequence":163500,"symbol":"FCEU SI 20260615 PS"}
{"ts_recv":"2026-04-07T02:31:05.091789097Z","hd":{"ts_event":"2026-04-07T02:31:05.091768411Z","rtype":160,"publisher_id":101,"instrument_id":436},"action":"C","side":"A","price":"1.156630000","size":30,"channel_id":23,"order_id":"1775529063795118060","flags":0,"ts_in_delta":1072,"sequence":163500,"symbol":"FCEU SI 20260615 PS"}
{"ts_recv":"2026-04-07T02:31:05.091789097Z","hd":{"ts_event":"2026-04-07T02:31:05.091768411Z","rtype":160,"publisher_id":101,"instrument_id":436},"action":"A","side":"A","price":"1.156610000","size":30,"channel_id":23,"order_id":"1775529065091774604","flags":128,"ts_in_delta":1072,"sequence":163500,"symbol":"FCEU SI 20260615 PS"}
{"ts_recv":"2026-04-07T02:31:05.091843530Z","hd":{"ts_event":"2026-04-07T02:31:05.091825679Z","rtype":160,"publisher_id":101,"instrument_id":436},"action":"C","side":"B","price":"1.156520000","size":30,"channel_id":23,"order_id":"10998901101946493397","flags":0,"ts_in_delta":1024,"sequence":163501,"symbol":"FCEU SI 20260615 PS"}
{"ts_recv":"2026-04-07T02:31:05.091843530Z","hd":{"ts_event":"2026-04-07T02:31:05.091825679Z","rtype":160,"publisher_id":101,"instrument_id":436},"action":"A","side":"B","price":"1.156510000","size":30,"channel_id":23,"order_id":"10998901101946607433","flags":0,"ts_in_delta":1024,"sequence":163501,"symbol":"FCEU SI 20260615 PS"}
{"ts_recv":"2026-04-07T02:31:05.091843530Z","hd":{"ts_event":"2026-04-07T02:31:05.091825679Z","rtype":160,"publisher_id":101,"instrument_id":436},"action":"C","side":"A","price":"1.156620000","size":30,"channel_id":23,"order_id":"1775529065091717589","flags":0,"ts_in_delta":1024,"sequence":163501,"symbol":"FCEU SI 20260615 PS"}
{"ts_recv":"2026-04-07T02:31:05.091843530Z","hd":{"ts_event":"2026-04-07T02:31:05.091825679Z","rtype":160,"publisher_id":101,"instrument_id":436},"action":"A","side":"A","price":"1.156610000","size":30,"channel_id":23,"order_id":"1775529065091831625","flags":128,"ts_in_delta":1024,"sequence":163501,"symbol":"FCEU SI 20260615 PS"}
{"ts_recv":"2026-04-07T02:31:06.141338082Z","hd":{"ts_event":"2026-04-07T02:31:06.141318739Z","rtype":160,"publisher_id":101,"instrument_id":436},"action":"C","side":"B","price":"1.156510000","size":30,"channel_id":23,"order_id":"10998901101946607433","flags":0,"ts_in_delta":940,"sequence":163521,"symbol":"FCEU SI 20260615 PS"}
{"ts_recv":"2026-04-07T02:31:06.141338082Z","hd":{"ts_event":"2026-04-07T02:31:06.141318739Z","rtype":160,"publisher_id":101,"instrument_id":436},"action":"A","side":"B","price":"1.156500000","size":30,"channel_id":23,"order_id":"10998901102996100733","flags":0,"ts_in_delta":940,"sequence":163521,"symbol":"FCEU SI 20260615 PS"}
{"ts_recv":"2026-04-07T02:31:06.141338082Z","hd":{"ts_event":"2026-04-07T02:31:06.141318739Z","rtype":160,"publisher_id":101,"instrument_id":436},"action":"C","side":"A","price":"1.156610000","size":30,"channel_id":23,"order_id":"1775529065091831625","flags":0,"ts_in_delta":940,"sequence":163521,"symbol":"FCEU SI 20260615 PS"}
{"ts_recv":"2026-04-07T02:31:06.141338082Z","hd":{"ts_event":"2026-04-07T02:31:06.141318739Z","rtype":160,"publisher_id":101,"instrument_id":436},"action":"A","side":"A","price":"1.156600000","size":30,"channel_id":23,"order_id":"1775529066141324925","flags":128,"ts_in_delta":940,"sequence":163521,"symbol":"FCEU SI 20260615 PS"}
{"ts_recv":"2026-04-07T02:31:06.145807829Z","hd":{"ts_event":"2026-04-07T02:31:06.145786407Z","rtype":160,"publisher_id":101,"instrument_id":436},"action":"C","side":"B","price":"1.156510000","size":30,"channel_id":23,"order_id":"10998901101946550412","flags":0,"ts_in_delta":1121,"sequence":163525,"symbol":"FCEU SI 20260615 PS"}
{"ts_recv":"2026-04-07T02:31:06.145807829Z","hd":{"ts_event":"2026-04-07T02:31:06.145786407Z","rtype":160,"publisher_id":101,"instrument_id":436},"action":"A","side":"B","price":"1.156490000","size":30,"channel_id":23,"order_id":"10998901103000568210","flags":0,"ts_in_delta":1121,"sequence":163525,"symbol":"FCEU SI 20260615 PS"}
{"ts_recv":"2026-04-07T02:31:06.145807829Z","hd":{"ts_event":"2026-04-07T02:31:06.145786407Z","rtype":160,"publisher_id":101,"instrument_id":436},"action":"C","side":"A","price":"1.156610000","size":30,"channel_id":23,"order_id":"1775529065091774604","flags":0,"ts_in_delta":1121,"sequence":163525,"symbol":"FCEU SI 20260615 PS"}
{"ts_recv":"2026-04-07T02:31:06.145807829Z","hd":{"ts_event":"2026-04-07T02:31:06.145786407Z","rtype":160,"publisher_id":101,"instrument_id":436},"action":"A","side":"A","price":"1.156590000","size":30,"channel_id":23,"order_id":"1775529066145792402","flags":128,"ts_in_delta":1121,"sequence":163525,"symbol":"FCEU SI 20260615 PS"}
{"ts_recv":"2026-04-07T02:31:06.145865104Z","hd":{"ts_event":"2026-04-07T02:31:06.145848521Z","rtype":160,"publisher_id":101,"instrument_id":436},"action":"C","side":"B","price":"1.156500000","size":30,"channel_id":23,"order_id":"10998901102996100733","flags":0,"ts_in_delta":952,"sequence":163526,"symbol":"FCEU SI 20260615 PS"}
{"ts_recv":"2026-04-07T02:31:06.145865104Z","hd":{"ts_event":"2026-04-07T02:31:06.145848521Z","rtype":160,"publisher_id":101,"instrument_id":436},"action":"A","side":"B","price":"1.156490000","size":30,"channel_id":23,"order_id":"10998901103000630287","flags":0,"ts_in_delta":952,"sequence":163526,"symbol":"FCEU SI 20260615 PS"}
{"ts_recv":"2026-04-07T02:31:06.145865104Z","hd":{"ts_event":"2026-04-07T02:31:06.145848521Z","rtype":160,"publisher_id":101,"instrument_id":436},"action":"C","side":"A","price":"1.156600000","size":30,"channel_id":23,"order_id":"1775529066141324925","flags":0,"ts_in_delta":952,"sequence":163526,"symbol":"FCEU SI 20260615 PS"}
{"ts_recv":"2026-04-07T02:31:06.145865104Z","hd":{"ts_event":"2026-04-07T02:31:06.145848521Z","rtype":160,"publisher_id":101,"instrument_id":436},"action":"A","side":"A","price":"1.156590000","size":30,"channel_id":23,"order_id":"1775529066145854479","flags":128,"ts_in_delta":952,"sequence":163526,"symbol":"FCEU SI 20260615 PS"}
{"ts_recv":"2026-04-07T02:31:07.235228020Z","hd":{"ts_event":"2026-04-07T02:31:07.235202323Z","rtype":160,"publisher_id":101,"instrument_id":436},"action":"C","side":"B","price":"1.156490000","size":30,"channel_id":23,"order_id":"10998901103000630287","flags":0,"ts_in_delta":1199,"sequence":163544,"symbol":"FCEU SI 20260615 PS"}
{"ts_recv":"2026-04-07T02:31:07.235228020Z","hd":{"ts_event":"2026-04-07T02:31:07.235202323Z","rtype":160,"publisher_id":101,"instrument_id":436},"action":"A","side":"B","price":"1.156500000","size":30,"channel_id":23,"order_id":"10998901104089989298","flags":0,"ts_in_delta":1199,"sequence":163544,"symbol":"FCEU SI 20260615 PS"}
{"ts_recv":"2026-04-07T02:31:07.235228020Z","hd":{"ts_event":"2026-04-07T02:31:07.235202323Z","rtype":160,"publisher_id":101,"instrument_id":436},"action":"C","side":"A","price":"1.156590000","size":30,"channel_id":23,"order_id":"1775529066145854479","flags":0,"ts_in_delta":1199,"sequence":163544,"symbol":"FCEU SI 20260615 PS"}
{"ts_recv":"2026-04-07T02:31:07.235228020Z","hd":{"ts_event":"2026-04-07T02:31:07.235202323Z","rtype":160,"publisher_id":101,"instrument_id":436},"action":"A","side":"A","price":"1.156600000","size":30,"channel_id":23,"order_id":"1775529067235213490","flags":128,"ts_in_delta":1199,"sequence":163544,"symbol":"FCEU SI 20260615 PS"}
{"ts_recv":"2026-04-07T02:31:07.239017865Z","hd":{"ts_event":"2026-04-07T02:31:07.238997543Z","rtype":160,"publisher_id":101,"instrument_id":436},"action":"C","side":"B","price":"1.156490000","size":30,"channel_id":23,"order_id":"10998901103000568210","flags":0,"ts_in_delta":935,"sequence":163545,"symbol":"FCEU SI 20260615 PS"}
{"ts_recv":"2026-04-07T02:31:07.239017865Z","hd":{"ts_event":"2026-04-07T02:31:07.238997543Z","rtype":160,"publisher_id":101,"instrument_id":436},"action":"A","side":"B","price":"1.156510000","size":30,"channel_id":23,"order_id":"10998901104093779604","flags":0,"ts_in_delta":935,"sequence":163545,"symbol":"FCEU SI 20260615 PS"}
{"ts_recv":"2026-04-07T02:31:07.239017865Z","hd":{"ts_event":"2026-04-07T02:31:07.238997543Z","rtype":160,"publisher_id":101,"instrument_id":436},"action":"C","side":"A","price":"1.156590000","size":30,"channel_id":23,"order_id":"1775529066145792402","flags":0,"ts_in_delta":935,"sequence":163545,"symbol":"FCEU SI 20260615 PS"}
{"ts_recv":"2026-04-07T02:31:07.239017865Z","hd":{"ts_event":"2026-04-07T02:31:07.238997543Z","rtype":160,"publisher_id":101,"instrument_id":436},"action":"A","side":"A","price":"1.156610000","size":30,"channel_id":23,"order_id":"1775529067239003796","flags":128,"ts_in_delta":935,"sequence":163545,"symbol":"FCEU SI 20260615 PS"}
{"ts_recv":"2026-04-07T02:31:07.239081076Z","hd":{"ts_event":"2026-04-07T02:31:07.239062747Z","rtype":160,"publisher_id":101,"instrument_id":436},"action":"C","side":"B","price":"1.156500000","size":30,"channel_id":23,"order_id":"10998901104089989298","flags":0,"ts_in_delta":1008,"sequence":163546,"symbol":"FCEU SI 20260615 PS"}
{"ts_recv":"2026-04-07T02:31:07.239081076Z","hd":{"ts_event":"2026-04-07T02:31:07.239062747Z","rtype":160,"publisher_id":101,"instrument_id":436},"action":"A","side":"B","price":"1.156510000","size":30,"channel_id":23,"order_id":"10998901104093844500","flags":0,"ts_in_delta":1008,"sequence":163546,"symbol":"FCEU SI 20260615 PS"}
{"ts_recv":"2026-04-07T02:31:07.239081076Z","hd":{"ts_event":"2026-04-07T02:31:07.239062747Z","rtype":160,"publisher_id":101,"instrument_id":436},"action":"C","side":"A","price":"1.156600000","size":30,"channel_id":23,"order_id":"1775529067235213490","flags":0,"ts_in_delta":1008,"sequence":163546,"symbol":"FCEU SI 20260615 PS"}
{"ts_recv":"2026-04-07T02:31:07.239081076Z","hd":{"ts_event":"2026-04-07T02:31:07.239062747Z","rtype":160,"publisher_id":101,"instrument_id":436},"action":"A","side":"A","price":"1.156610000","size":30,"channel_id":23,"order_id":"1775529067239068692","flags":128,"ts_in_delta":1008,"sequence":163546,"symbol":"FCEU SI 20260615 PS"}
{"ts_recv":"2026-04-07T02:31:08.755411400Z","hd":{"ts_event":"2026-04-07T02:31:08.755381203Z","rtype":160,"publisher_id":101,"instrument_id":436},"action":"C","side":"B","price":"1.156510000","size":30,"channel_id":23,"order_id":"10998901104093844500","flags":0,"ts_in_delta":1384,"sequence":163549,"symbol":"FCEU SI 20260615 PS"}
{"ts_recv":"2026-04-07T02:31:08.755411400Z","hd":{"ts_event":"2026-04-07T02:31:08.755381203Z","rtype":160,"publisher_id":101,"instrument_id":436},"action":"A","side":"B","price":"1.156500000","size":30,"channel_id":23,"order_id":"10998901105610170107","flags":0,"ts_in_delta":1384,"sequence":163549,"symbol":"FCEU SI 20260615 PS"}
{"ts_recv":"2026-04-07T02:31:08.755411400Z","hd":{"ts_event":"2026-04-07T02:31:08.755381203Z","rtype":160,"publisher_id":101,"instrument_id":436},"action":"C","side":"A","price":"1.156610000","size":30,"channel_id":23,"order_id":"1775529067239068692","flags":0,"ts_in_delta":1384,"sequence":163549,"symbol":"FCEU SI 20260615 PS"}
{"ts_recv":"2026-04-07T02:31:08.755411400Z","hd":{"ts_event":"2026-04-07T02:31:08.755381203Z","rtype":160,"publisher_id":101,"instrument_id":436},"action":"A","side":"A","price":"1.156600000","size":30,"channel_id":23,"order_id":"1775529068755394299","flags":128,"ts_in_delta":1384,"sequence":163549,"symbol":"FCEU SI 20260615 PS"}
{"ts_recv":"2026-04-07T02:31:09.413336976Z","hd":{"ts_event":"2026-04-07T02:31:09.413311823Z","rtype":160,"publisher_id":101,"instrument_id":436},"action":"C","side":"B","price":"1.156500000","size":30,"channel_id":23,"order_id":"10998901105610170107","flags":0,"ts_in_delta":1353,"sequence":163558,"symbol":"FCEU SI 20260615 PS"}
{"ts_recv":"2026-04-07T02:31:09.413336976Z","hd":{"ts_event":"2026-04-07T02:31:09.413311823Z","rtype":160,"publisher_id":101,"instrument_id":436},"action":"A","side":"B","price":"1.156510000","size":30,"channel_id":23,"order_id":"10998901106268099064","flags":0,"ts_in_delta":1353,"sequence":163558,"symbol":"FCEU SI 20260615 PS"}
{"ts_recv":"2026-04-07T02:31:09.413336976Z","hd":{"ts_event":"2026-04-07T02:31:09.413311823Z","rtype":160,"publisher_id":101,"instrument_id":436},"action":"C","side":"A","price":"1.156600000","size":30,"channel_id":23,"order_id":"1775529068755394299","flags":0,"ts_in_delta":1353,"sequence":163558,"symbol":"FCEU SI 20260615 PS"}
{"ts_recv":"2026-04-07T02:31:09.413336976Z","hd":{"ts_event":"2026-04-07T02:31:09.413311823Z","rtype":160,"publisher_id":101,"instrument_id":436},"action":"A","side":"A","price":"1.156610000","size":30,"channel_id":23,"order_id":"1775529069413323256","flags":128,"ts_in_delta":1353,"sequence":163558,"symbol":"FCEU SI 20260615 PS"}
{"ts_recv":"2026-04-07T02:31:09.774899070Z","hd":{"ts_event":"2026-04-07T02:31:09.774878495Z","rtype":160,"publisher_id":101,"instrument_id":436},"action":"C","side":"B","price":"1.156510000","size":30,"channel_id":23,"order_id":"10998901106268099064","flags":0,"ts_in_delta":1254,"sequence":163586,"symbol":"FCEU SI 20260615 PS"}
{"ts_recv":"2026-04-07T02:31:09.774899070Z","hd":{"ts_event":"2026-04-07T02:31:09.774878495Z","rtype":160,"publisher_id":101,"instrument_id":436},"action":"A","side":"B","price":"1.156520000","size":30,"channel_id":23,"order_id":"10998901106629660522","flags":0,"ts_in_delta":1254,"sequence":163586,"symbol":"FCEU SI 20260615 PS"}
{"ts_recv":"2026-04-07T02:31:09.774899070Z","hd":{"ts_event":"2026-04-07T02:31:09.774878495Z","rtype":160,"publisher_id":101,"instrument_id":436},"action":"C","side":"A","price":"1.156610000","size":30,"channel_id":23,"order_id":"1775529069413323256","flags":0,"ts_in_delta":1254,"sequence":163586,"symbol":"FCEU SI 20260615 PS"}
{"ts_recv":"2026-04-07T02:31:09.774899070Z","hd":{"ts_event":"2026-04-07T02:31:09.774878495Z","rtype":160,"publisher_id":101,"instrument_id":436},"action":"A","side":"A","price":"1.156620000","size":30,"channel_id":23,"order_id":"1775529069774884714","flags":128,"ts_in_delta":1254,"sequence":163586,"symbol":"FCEU SI 20260615 PS"}
{"ts_recv":"2026-04-07T02:31:09.818039592Z","hd":{"ts_event":"2026-04-07T02:31:09.818019165Z","rtype":160,"publisher_id":101,"instrument_id":436},"action":"C","side":"B","price":"1.156520000","size":30,"channel_id":23,"order_id":"10998901106629660522","flags":0,"ts_in_delta":1386,"sequence":163590,"symbol":"FCEU SI 20260615 PS"}
{"ts_recv":"2026-04-07T02:31:09.818039592Z","hd":{"ts_event":"2026-04-07T02:31:09.818019165Z","rtype":160,"publisher_id":101,"instrument_id":436},"action":"A","side":"B","price":"1.156530000","size":30,"channel_id":23,"order_id":"10998901106672800883","flags":0,"ts_in_delta":1386,"sequence":163590,"symbol":"FCEU SI 20260615 PS"}
{"ts_recv":"2026-04-07T02:31:09.818039592Z","hd":{"ts_event":"2026-04-07T02:31:09.818019165Z","rtype":160,"publisher_id":101,"instrument_id":436},"action":"C","side":"A","price":"1.156620000","size":30,"channel_id":23,"order_id":"1775529069774884714","flags":0,"ts_in_delta":1386,"sequence":163590,"symbol":"FCEU SI 20260615 PS"}
{"ts_recv":"2026-04-07T02:31:09.818039592Z","hd":{"ts_event":"2026-04-07T02:31:09.818019165Z","rtype":160,"publisher_id":101,"instrument_id":436},"action":"A","side":"A","price":"1.156630000","size":30,"channel_id":23,"order_id":"1775529069818025075","flags":128,"ts_in_delta":1386,"sequence":163590,"symbol":"FCEU SI 20260615 PS"}
{"ts_recv":"2026-04-07T02:31:09.818089948Z","hd":{"ts_event":"2026-04-07T02:31:09.818073745Z","rtype":160,"publisher_id":101,"instrument_id":436},"action":"C","side":"B","price":"1.156510000","size":30,"channel_id":23,"order_id":"10998901104093779604","flags":0,"ts_in_delta":1139,"sequence":163591,"symbol":"FCEU SI 20260615 PS"}
{"ts_recv":"2026-04-07T02:31:09.818089948Z","hd":{"ts_event":"2026-04-07T02:31:09.818073745Z","rtype":160,"publisher_id":101,"instrument_id":436},"action":"A","side":"B","price":"1.156530000","size":30,"channel_id":23,"order_id":"10998901106672855676","flags":0,"ts_in_delta":1139,"sequence":163591,"symbol":"FCEU SI 20260615 PS"}
{"ts_recv":"2026-04-07T02:31:09.818089948Z","hd":{"ts_event":"2026-04-07T02:31:09.818073745Z","rtype":160,"publisher_id":101,"instrument_id":436},"action":"C","side":"A","price":"1.156610000","size":30,"channel_id":23,"order_id":"1775529067239003796","flags":0,"ts_in_delta":1139,"sequence":163591,"symbol":"FCEU SI 20260615 PS"}
{"ts_recv":"2026-04-07T02:31:09.818089948Z","hd":{"ts_event":"2026-04-07T02:31:09.818073745Z","rtype":160,"publisher_id":101,"instrument_id":436},"action":"A","side":"A","price":"1.156630000","size":30,"channel_id":23,"order_id":"1775529069818079868","flags":128,"ts_in_delta":1139,"sequence":163591,"symbol":"FCEU SI 20260615 PS"}
{"ts_recv":"2026-04-07T02:31:09.818122417Z","hd":{"ts_event":"2026-04-07T02:31:09.818102047Z","rtype":160,"publisher_id":101,"instrument_id":436},"action":"C","side":"B","price":"1.156530000","size":30,"channel_id":23,"order_id":"10998901106672800883","flags":0,"ts_in_delta":918,"sequence":163592,"symbol":"FCEU SI 20260615 PS"}
{"ts_recv":"2026-04-07T02:31:09.818122417Z","hd":{"ts_event":"2026-04-07T02:31:09.818102047Z","rtype":160,"publisher_id":101,"instrument_id":436},"action":"A","side":"B","price":"1.156520000","size":30,"channel_id":23,"order_id":"10998901106672884375","flags":0,"ts_in_delta":918,"sequence":163592,"symbol":"FCEU SI 20260615 PS"}
{"ts_recv":"2026-04-07T02:31:09.818122417Z","hd":{"ts_event":"2026-04-07T02:31:09.818102047Z","rtype":160,"publisher_id":101,"instrument_id":436},"action":"C","side":"A","price":"1.156630000","size":30,"channel_id":23,"order_id":"1775529069818025075","flags":0,"ts_in_delta":918,"sequence":163592,"symbol":"FCEU SI 20260615 PS"}
{"ts_recv":"2026-04-07T02:31:09.818122417Z","hd":{"ts_event":"2026-04-07T02:31:09.818102047Z","rtype":160,"publisher_id":101,"instrument_id":436},"action":"A","side":"A","price":"1.156620000","size":30,"channel_id":23,"order_id":"1775529069818108567","flags":128,"ts_in_delta":918,"sequence":163592,"symbol":"FCEU SI 20260615 PS"}
{"ts_recv":"2026-04-07T02:31:09.818179654Z","hd":{"ts_event":"2026-04-07T02:31:09.818162257Z","rtype":160,"publisher_id":101,"instrument_id":436},"action":"C","side":"B","price":"1.156520000","size":30,"channel_id":23,"order_id":"10998901106672884375","flags":0,"ts_in_delta":937,"sequence":163593,"symbol":"FCEU SI 20260615 PS"}
{"ts_recv":"2026-04-07T02:31:09.818179654Z","hd":{"ts_event":"2026-04-07T02:31:09.818162257Z","rtype":160,"publisher_id":101,"instrument_id":436},"action":"A","side":"B","price":"1.156530000","size":30,"channel_id":23,"order_id":"10998901106672943940","flags":0,"ts_in_delta":937,"sequence":163593,"symbol":"FCEU SI 20260615 PS"}
{"ts_recv":"2026-04-07T02:31:09.818179654Z","hd":{"ts_event":"2026-04-07T02:31:09.818162257Z","rtype":160,"publisher_id":101,"instrument_id":436},"action":"C","side":"A","price":"1.156620000","size":30,"channel_id":23,"order_id":"1775529069818108567","flags":0,"ts_in_delta":937,"sequence":163593,"symbol":"FCEU SI 20260615 PS"}
{"ts_recv":"2026-04-07T02:31:09.818179654Z","hd":{"ts_event":"2026-04-07T02:31:09.818162257Z","rtype":160,"publisher_id":101,"instrument_id":436},"action":"A","side":"A","price":"1.156630000","size":30,"channel_id":23,"order_id":"1775529069818168132","flags":128,"ts_in_delta":937,"sequence":163593,"symbol":"FCEU SI 20260615 PS"}
{"ts_recv":"2026-04-07T02:31:15.493014565Z","hd":{"ts_event":"2026-04-07T02:31:15.492993249Z","rtype":160,"publisher_id":101,"instrument_id":436},"action":"C","side":"B","price":"1.156530000","size":30,"channel_id":23,"order_id":"10998901106672943940","flags":0,"ts_in_delta":1002,"sequence":163635,"symbol":"FCEU SI 20260615 PS"}
{"ts_recv":"2026-04-07T02:31:15.493014565Z","hd":{"ts_event":"2026-04-07T02:31:15.492993249Z","rtype":160,"publisher_id":101,"instrument_id":436},"action":"A","side":"B","price":"1.156520000","size":30,"channel_id":23,"order_id":"10998901112347776063","flags":0,"ts_in_delta":1002,"sequence":163635,"symbol":"FCEU SI 20260615 PS"}
{"ts_recv":"2026-04-07T02:31:15.493014565Z","hd":{"ts_event":"2026-04-07T02:31:15.492993249Z","rtype":160,"publisher_id":101,"instrument_id":436},"action":"C","side":"A","price":"1.156630000","size":30,"channel_id":23,"order_id":"1775529069818168132","flags":0,"ts_in_delta":1002,"sequence":163635,"symbol":"FCEU SI 20260615 PS"}
{"ts_recv":"2026-04-07T02:31:15.493014565Z","hd":{"ts_event":"2026-04-07T02:31:15.492993249Z","rtype":160,"publisher_id":101,"instrument_id":436},"action":"A","side":"A","price":"1.156620000","size":30,"channel_id":23,"order_id":"1775529075493000255","flags":128,"ts_in_delta":1002,"sequence":163635,"symbol":"FCEU SI 20260615 PS"}
{"ts_recv":"2026-04-07T02:31:15.493080095Z","hd":{"ts_event":"2026-04-07T02:31:15.493059379Z","rtype":160,"publisher_id":101,"instrument_id":436},"action":"C","side":"B","price":"1.156530000","size":30,"channel_id":23,"order_id":"10998901106672855676","flags":0,"ts_in_delta":920,"sequence":163636,"symbol":"FCEU SI 20260615 PS"}
{"ts_recv":"2026-04-07T02:31:15.493080095Z","hd":{"ts_event":"2026-04-07T02:31:15.493059379Z","rtype":160,"publisher_id":101,"instrument_id":436},"action":"A","side":"B","price":"1.156510000","size":30,"channel_id":23,"order_id":"10998901112347841327","flags":0,"ts_in_delta":920,"sequence":163636,"symbol":"FCEU SI 20260615 PS"}
{"ts_recv":"2026-04-07T02:31:15.493080095Z","hd":{"ts_event":"2026-04-07T02:31:15.493059379Z","rtype":160,"publisher_id":101,"instrument_id":436},"action":"C","side":"A","price":"1.156630000","size":30,"channel_id":23,"order_id":"1775529069818079868","flags":0,"ts_in_delta":920,"sequence":163636,"symbol":"FCEU SI 20260615 PS"}
{"ts_recv":"2026-04-07T02:31:15.493080095Z","hd":{"ts_event":"2026-04-07T02:31:15.493059379Z","rtype":160,"publisher_id":101,"instrument_id":436},"action":"A","side":"A","price":"1.156610000","size":30,"channel_id":23,"order_id":"1775529075493065519","flags":128,"ts_in_delta":920,"sequence":163636,"symbol":"FCEU SI 20260615 PS"}
{"ts_recv":"2026-04-07T02:31:15.493137708Z","hd":{"ts_event":"2026-04-07T02:31:15.493121907Z","rtype":160,"publisher_id":101,"instrument_id":436},"action":"C","side":"B","price":"1.156520000","size":30,"channel_id":23,"order_id":"10998901112347776063","flags":0,"ts_in_delta":930,"sequence":163637,"symbol":"FCEU SI 20260615 PS"}
{"ts_recv":"2026-04-07T02:31:15.493137708Z","hd":{"ts_event":"2026-04-07T02:31:15.493121907Z","rtype":160,"publisher_id":101,"instrument_id":436},"action":"A","side":"B","price":"1.156510000","size":30,"channel_id":23,"order_id":"10998901112347903464","flags":0,"ts_in_delta":930,"sequence":163637,"symbol":"FCEU SI 20260615 PS"}
{"ts_recv":"2026-04-07T02:31:15.493137708Z","hd":{"ts_event":"2026-04-07T02:31:15.493121907Z","rtype":160,"publisher_id":101,"instrument_id":436},"action":"C","side":"A","price":"1.156620000","size":30,"channel_id":23,"order_id":"1775529075493000255","flags":0,"ts_in_delta":930,"sequence":163637,"symbol":"FCEU SI 20260615 PS"}
{"ts_recv":"2026-04-07T02:31:15.493137708Z","hd":{"ts_event":"2026-04-07T02:31:15.493121907Z","rtype":160,"publisher_id":101,"instrument_id":436},"action":"A","side":"A","price":"1.156610000","size":30,"channel_id":23,"order_id":"1775529075493127656","flags":128,"ts_in_delta":930,"sequence":163637,"symbol":"FCEU SI 20260615 PS"}
{"ts_recv":"2026-04-07T02:31:22.818322894Z","hd":{"ts_event":"2026-04-07T02:31:22.818301549Z","rtype":160,"publisher_id":101,"instrument_id":436},"action":"C","side":"B","price":"1.156510000","size":30,"channel_id":23,"order_id":"10998901112347903464","flags":0,"ts_in_delta":904,"sequence":163694,"symbol":"FCEU SI 20260615 PS"}
{"ts_recv":"2026-04-07T02:31:22.818322894Z","hd":{"ts_event":"2026-04-07T02:31:22.818301549Z","rtype":160,"publisher_id":101,"instrument_id":436},"action":"A","side":"B","price":"1.156520000","size":30,"channel_id":23,"order_id":"10998901119673083575","flags":0,"ts_in_delta":904,"sequence":163694,"symbol":"FCEU SI 20260615 PS"}
{"ts_recv":"2026-04-07T02:31:22.818322894Z","hd":{"ts_event":"2026-04-07T02:31:22.818301549Z","rtype":160,"publisher_id":101,"instrument_id":436},"action":"C","side":"A","price":"1.156610000","size":30,"channel_id":23,"order_id":"1775529075493127656","flags":0,"ts_in_delta":904,"sequence":163694,"symbol":"FCEU SI 20260615 PS"}
{"ts_recv":"2026-04-07T02:31:22.818322894Z","hd":{"ts_event":"2026-04-07T02:31:22.818301549Z","rtype":160,"publisher_id":101,"instrument_id":436},"action":"A","side":"A","price":"1.156620000","size":30,"channel_id":23,"order_id":"1775529082818307767","flags":128,"ts_in_delta":904,"sequence":163694,"symbol":"FCEU SI 20260615 PS"}
{"ts_recv":"2026-04-07T02:31:22.818376145Z","hd":{"ts_event":"2026-04-07T02:31:22.818357883Z","rtype":160,"publisher_id":101,"instrument_id":436},"action":"C","side":"B","price":"1.156510000","size":30,"channel_id":23,"order_id":"10998901112347841327","flags":0,"ts_in_delta":908,"sequence":163695,"symbol":"FCEU SI 20260615 PS"}
{"ts_recv":"2026-04-07T02:31:22.818376145Z","hd":{"ts_event":"2026-04-07T02:31:22.818357883Z","rtype":160,"publisher_id":101,"instrument_id":436},"action":"A","side":"B","price":"1.156530000","size":30,"channel_id":23,"order_id":"10998901119673139662","flags":0,"ts_in_delta":908,"sequence":163695,"symbol":"FCEU SI 20260615 PS"}
{"ts_recv":"2026-04-07T02:31:22.818376145Z","hd":{"ts_event":"2026-04-07T02:31:22.818357883Z","rtype":160,"publisher_id":101,"instrument_id":436},"action":"C","side":"A","price":"1.156610000","size":30,"channel_id":23,"order_id":"1775529075493065519","flags":0,"ts_in_delta":908,"sequence":163695,"symbol":"FCEU SI 20260615 PS"}
{"ts_recv":"2026-04-07T02:31:22.818376145Z","hd":{"ts_event":"2026-04-07T02:31:22.818357883Z","rtype":160,"publisher_id":101,"instrument_id":436},"action":"A","side":"A","price":"1.156630000","size":30,"channel_id":23,"order_id":"1775529082818363854","flags":128,"ts_in_delta":908,"sequence":163695,"symbol":"FCEU SI 20260615 PS"}
{"ts_recv":"2026-04-07T02:31:22.818406495Z","hd":{"ts_event":"2026-04-07T02:31:22.818388047Z","rtype":160,"publisher_id":101,"instrument_id":436},"action":"C","side":"B","price":"1.156520000","size":30,"channel_id":23,"order_id":"10998901119673083575","flags":0,"ts_in_delta":873,"sequence":163696,"symbol":"FCEU SI 20260615 PS"}
{"ts_recv":"2026-04-07T02:31:22.818406495Z","hd":{"ts_event":"2026-04-07T02:31:22.818388047Z","rtype":160,"publisher_id":101,"instrument_id":436},"action":"A","side":"B","price":"1.156530000","size":30,"channel_id":23,"order_id":"10998901119673169763","flags":0,"ts_in_delta":873,"sequence":163696,"symbol":"FCEU SI 20260615 PS"}
{"ts_recv":"2026-04-07T02:31:22.818406495Z","hd":{"ts_event":"2026-04-07T02:31:22.818388047Z","rtype":160,"publisher_id":101,"instrument_id":436},"action":"C","side":"A","price":"1.156620000","size":30,"channel_id":23,"order_id":"1775529082818307767","flags":0,"ts_in_delta":873,"sequence":163696,"symbol":"FCEU SI 20260615 PS"}
{"ts_recv":"2026-04-07T02:31:22.818406495Z","hd":{"ts_event":"2026-04-07T02:31:22.818388047Z","rtype":160,"publisher_id":101,"instrument_id":436},"action":"A","side":"A","price":"1.156630000","size":30,"channel_id":23,"order_id":"1775529082818393955","flags":128,"ts_in_delta":873,"sequence":163696,"symbol":"FCEU SI 20260615 PS"}
{"ts_recv":"2026-04-07T02:31:25.240398705Z","hd":{"ts_event":"2026-04-07T02:31:25.240376479Z","rtype":160,"publisher_id":101,"instrument_id":436},"action":"C","side":"B","price":"1.156530000","size":30,"channel_id":23,"order_id":"10998901119673169763","flags":0,"ts_in_delta":896,"sequence":163737,"symbol":"FCEU SI 20260615 PS"}
{"ts_recv":"2026-04-07T02:31:25.240398705Z","hd":{"ts_event":"2026-04-07T02:31:25.240376479Z","rtype":160,"publisher_id":101,"instrument_id":436},"action":"A","side":"B","price":"1.156540000","size":30,"channel_id":23,"order_id":"10998901122095158556","flags":0,"ts_in_delta":896,"sequence":163737,"symbol":"FCEU SI 20260615 PS"}
{"ts_recv":"2026-04-07T02:31:25.240398705Z","hd":{"ts_event":"2026-04-07T02:31:25.240376479Z","rtype":160,"publisher_id":101,"instrument_id":436},"action":"C","side":"A","price":"1.156630000","size":30,"channel_id":23,"order_id":"1775529082818393955","flags":0,"ts_in_delta":896,"sequence":163737,"symbol":"FCEU SI 20260615 PS"}
{"ts_recv":"2026-04-07T02:31:25.240398705Z","hd":{"ts_event":"2026-04-07T02:31:25.240376479Z","rtype":160,"publisher_id":101,"instrument_id":436},"action":"A","side":"A","price":"1.156640000","size":30,"channel_id":23,"order_id":"1775529085240382748","flags":128,"ts_in_delta":896,"sequence":163737,"symbol":"FCEU SI 20260615 PS"}
{"ts_recv":"2026-04-07T02:31:27.927954619Z","hd":{"ts_event":"2026-04-07T02:31:27.927934553Z","rtype":160,"publisher_id":101,"instrument_id":436},"action":"C","side":"B","price":"1.156530000","size":30,"channel_id":23,"order_id":"10998901119673139662","flags":0,"ts_in_delta":736,"sequence":163782,"symbol":"FCEU SI 20260615 PS"}
{"ts_recv":"2026-04-07T02:31:27.927954619Z","hd":{"ts_event":"2026-04-07T02:31:27.927934553Z","rtype":160,"publisher_id":101,"instrument_id":436},"action":"A","side":"B","price":"1.156550000","size":30,"channel_id":23,"order_id":"10998901124782716656","flags":0,"ts_in_delta":736,"sequence":163782,"symbol":"FCEU SI 20260615 PS"}
{"ts_recv":"2026-04-07T02:31:27.927954619Z","hd":{"ts_event":"2026-04-07T02:31:27.927934553Z","rtype":160,"publisher_id":101,"instrument_id":436},"action":"C","side":"A","price":"1.156630000","size":30,"channel_id":23,"order_id":"1775529082818363854","flags":0,"ts_in_delta":736,"sequence":163782,"symbol":"FCEU SI 20260615 PS"}
{"ts_recv":"2026-04-07T02:31:27.927954619Z","hd":{"ts_event":"2026-04-07T02:31:27.927934553Z","rtype":160,"publisher_id":101,"instrument_id":436},"action":"A","side":"A","price":"1.156650000","size":30,"channel_id":23,"order_id":"1775529087927940848","flags":128,"ts_in_delta":736,"sequence":163782,"symbol":"FCEU SI 20260615 PS"}
{"ts_recv":"2026-04-07T02:31:27.928014858Z","hd":{"ts_event":"2026-04-07T02:31:27.927998643Z","rtype":160,"publisher_id":101,"instrument_id":436},"action":"C","side":"B","price":"1.156540000","size":30,"channel_id":23,"order_id":"10998901122095158556","flags":0,"ts_in_delta":733,"sequence":163783,"symbol":"FCEU SI 20260615 PS"}
{"ts_recv":"2026-04-07T02:31:27.928014858Z","hd":{"ts_event":"2026-04-07T02:31:27.927998643Z","rtype":160,"publisher_id":101,"instrument_id":436},"action":"A","side":"B","price":"1.156550000","size":30,"channel_id":23,"order_id":"10998901124782780213","flags":0,"ts_in_delta":733,"sequence":163783,"symbol":"FCEU SI 20260615 PS"}
{"ts_recv":"2026-04-07T02:31:27.928014858Z","hd":{"ts_event":"2026-04-07T02:31:27.927998643Z","rtype":160,"publisher_id":101,"instrument_id":436},"action":"C","side":"A","price":"1.156640000","size":30,"channel_id":23,"order_id":"1775529085240382748","flags":0,"ts_in_delta":733,"sequence":163783,"symbol":"FCEU SI 20260615 PS"}
{"ts_recv":"2026-04-07T02:31:27.928014858Z","hd":{"ts_event":"2026-04-07T02:31:27.927998643Z","rtype":160,"publisher_id":101,"instrument_id":436},"action":"A","side":"A","price":"1.156650000","size":30,"channel_id":23,"order_id":"1775529087928004405","flags":128,"ts_in_delta":733,"sequence":163783,"symbol":"FCEU SI 20260615 PS"}
{"ts_recv":"2026-04-07T02:31:30.619461409Z","hd":{"ts_event":"2026-04-07T02:31:30.619441133Z","rtype":160,"publisher_id":101,"instrument_id":436},"action":"C","side":"B","price":"1.156550000","size":30,"channel_id":23,"order_id":"10998901124782780213","flags":0,"ts_in_delta":1236,"sequence":163820,"symbol":"FCEU SI 20260615 PS"}
{"ts_recv":"2026-04-07T02:31:30.619461409Z","hd":{"ts_event":"2026-04-07T02:31:30.619441133Z","rtype":160,"publisher_id":101,"instrument_id":436},"action":"A","side":"B","price":"1.156560000","size":30,"channel_id":23,"order_id":"10998901127474222909","flags":0,"ts_in_delta":1236,"sequence":163820,"symbol":"FCEU SI 20260615 PS"}
{"ts_recv":"2026-04-07T02:31:30.619461409Z","hd":{"ts_event":"2026-04-07T02:31:30.619441133Z","rtype":160,"publisher_id":101,"instrument_id":436},"action":"C","side":"A","price":"1.156650000","size":30,"channel_id":23,"order_id":"1775529087928004405","flags":0,"ts_in_delta":1236,"sequence":163820,"symbol":"FCEU SI 20260615 PS"}
{"ts_recv":"2026-04-07T02:31:30.619461409Z","hd":{"ts_event":"2026-04-07T02:31:30.619441133Z","rtype":160,"publisher_id":101,"instrument_id":436},"action":"A","side":"A","price":"1.156660000","size":30,"channel_id":23,"order_id":"1775529090619447101","flags":128,"ts_in_delta":1236,"sequence":163820,"symbol":"FCEU SI 20260615 PS"}
{"ts_recv":"2026-04-07T02:31:38.225736267Z","hd":{"ts_event":"2026-04-07T02:31:38.225712077Z","rtype":160,"publisher_id":101,"instrument_id":436},"action":"C","side":"B","price":"1.156550000","size":30,"channel_id":23,"order_id":"10998901124782716656","flags":0,"ts_in_delta":952,"sequence":163864,"symbol":"FCEU SI 20260615 PS"}
{"ts_recv":"2026-04-07T02:31:38.225736267Z","hd":{"ts_event":"2026-04-07T02:31:38.225712077Z","rtype":160,"publisher_id":101,"instrument_id":436},"action":"A","side":"B","price":"1.156570000","size":30,"channel_id":23,"order_id":"10998901135080494508","flags":0,"ts_in_delta":952,"sequence":163864,"symbol":"FCEU SI 20260615 PS"}
{"ts_recv":"2026-04-07T02:31:38.225736267Z","hd":{"ts_event":"2026-04-07T02:31:38.225712077Z","rtype":160,"publisher_id":101,"instrument_id":436},"action":"C","side":"A","price":"1.156650000","size":30,"channel_id":23,"order_id":"1775529087927940848","flags":0,"ts_in_delta":952,"sequence":163864,"symbol":"FCEU SI 20260615 PS"}
{"ts_recv":"2026-04-07T02:31:38.225736267Z","hd":{"ts_event":"2026-04-07T02:31:38.225712077Z","rtype":160,"publisher_id":101,"instrument_id":436},"action":"A","side":"A","price":"1.156670000","size":30,"channel_id":23,"order_id":"1775529098225718700","flags":128,"ts_in_delta":952,"sequence":163864,"symbol":"FCEU SI 20260615 PS"}
{"ts_recv":"2026-04-07T02:31:38.225849119Z","hd":{"ts_event":"2026-04-07T02:31:38.225832315Z","rtype":160,"publisher_id":101,"instrument_id":436},"action":"C","side":"B","price":"1.156560000","size":30,"channel_id":23,"order_id":"10998901127474222909","flags":0,"ts_in_delta":938,"sequence":163865,"symbol":"FCEU SI 20260615 PS"}
{"ts_recv":"2026-04-07T02:31:38.225849119Z","hd":{"ts_event":"2026-04-07T02:31:38.225832315Z","rtype":160,"publisher_id":101,"instrument_id":436},"action":"A","side":"B","price":"1.156570000","size":30,"channel_id":23,"order_id":"10998901135080614118","flags":0,"ts_in_delta":938,"sequence":163865,"symbol":"FCEU SI 20260615 PS"}
{"ts_recv":"2026-04-07T02:31:38.225849119Z","hd":{"ts_event":"2026-04-07T02:31:38.225832315Z","rtype":160,"publisher_id":101,"instrument_id":436},"action":"C","side":"A","price":"1.156660000","size":30,"channel_id":23,"order_id":"1775529090619447101","flags":0,"ts_in_delta":938,"sequence":163865,"symbol":"FCEU SI 20260615 PS"}
{"ts_recv":"2026-04-07T02:31:38.225849119Z","hd":{"ts_event":"2026-04-07T02:31:38.225832315Z","rtype":160,"publisher_id":101,"instrument_id":436},"action":"A","side":"A","price":"1.156670000","size":30,"channel_id":23,"order_id":"1775529098225838310","flags":128,"ts_in_delta":938,"sequence":163865,"symbol":"FCEU SI 20260615 PS"}
{"ts_recv":"2026-04-07T02:31:53.227955769Z","hd":{"ts_event":"2026-04-07T02:31:53.227933809Z","rtype":160,"publisher_id":101,"instrument_id":436},"action":"C","side":"B","price":"1.156570000","size":30,"channel_id":23,"order_id":"10998901135080614118","flags":0,"ts_in_delta":934,"sequence":163990,"symbol":"FCEU SI 20260615 PS"}
{"ts_recv":"2026-04-07T02:31:53.227955769Z","hd":{"ts_event":"2026-04-07T02:31:53.227933809Z","rtype":160,"publisher_id":101,"instrument_id":436},"action":"A","side":"B","price":"1.156580000","size":30,"channel_id":23,"order_id":"10998901150082715679","flags":0,"ts_in_delta":934,"sequence":163990,"symbol":"FCEU SI 20260615 PS"}
{"ts_recv":"2026-04-07T02:31:53.227955769Z","hd":{"ts_event":"2026-04-07T02:31:53.227933809Z","rtype":160,"publisher_id":101,"instrument_id":436},"action":"C","side":"A","price":"1.156670000","size":30,"channel_id":23,"order_id":"1775529098225838310","flags":0,"ts_in_delta":934,"sequence":163990,"symbol":"FCEU SI 20260615 PS"}
{"ts_recv":"2026-04-07T02:31:53.227955769Z","hd":{"ts_event":"2026-04-07T02:31:53.227933809Z","rtype":160,"publisher_id":101,"instrument_id":436},"action":"A","side":"A","price":"1.156680000","size":30,"channel_id":23,"order_id":"1775529113227939871","flags":128,"ts_in_delta":934,"sequence":163990,"symbol":"FCEU SI 20260615 PS"}
{"ts_recv":"2026-04-07T02:31:56.324882981Z","hd":{"ts_event":"2026-04-07T02:31:56.324854991Z","rtype":160,"publisher_id":101,"instrument_id":436},"action":"C","side":"B","price":"1.156580000","size":30,"channel_id":23,"order_id":"10998901150082715679","flags":0,"ts_in_delta":1430,"sequence":164036,"symbol":"FCEU SI 20260615 PS"}
{"ts_recv":"2026-04-07T02:31:56.324882981Z","hd":{"ts_event":"2026-04-07T02:31:56.324854991Z","rtype":160,"publisher_id":101,"instrument_id":436},"action":"A","side":"B","price":"1.156590000","size":30,"channel_id":23,"order_id":"10998901153179641651","flags":0,"ts_in_delta":1430,"sequence":164036,"symbol":"FCEU SI 20260615 PS"}
{"ts_recv":"2026-04-07T02:31:56.324882981Z","hd":{"ts_event":"2026-04-07T02:31:56.324854991Z","rtype":160,"publisher_id":101,"instrument_id":436},"action":"C","side":"A","price":"1.156680000","size":30,"channel_id":23,"order_id":"1775529113227939871","flags":0,"ts_in_delta":1430,"sequence":164036,"symbol":"FCEU SI 20260615 PS"}
{"ts_recv":"2026-04-07T02:31:56.324882981Z","hd":{"ts_event":"2026-04-07T02:31:56.324854991Z","rtype":160,"publisher_id":101,"instrument_id":436},"action":"A","side":"A","price":"1.156690000","size":30,"channel_id":23,"order_id":"1775529116324865843","flags":128,"ts_in_delta":1430,"sequence":164036,"symbol":"FCEU SI 20260615 PS"}
{"ts_recv":"2026-04-07T02:31:56.324954448Z","hd":{"ts_event":"2026-04-07T02:31:56.324937379Z","rtype":160,"publisher_id":101,"instrument_id":436},"action":"C","side":"B","price":"1.156570000","size":30,"channel_id":23,"order_id":"10998901135080494508","flags":0,"ts_in_delta":959,"sequence":164037,"symbol":"FCEU SI 20260615 PS"}
{"ts_recv":"2026-04-07T02:31:56.324954448Z","hd":{"ts_event":"2026-04-07T02:31:56.324937379Z","rtype":160,"publisher_id":101,"instrument_id":436},"action":"A","side":"B","price":"1.156590000","size":30,"channel_id":23,"order_id":"10998901153179719379","flags":0,"ts_in_delta":959,"sequence":164037,"symbol":"FCEU SI 20260615 PS"}
{"ts_recv":"2026-04-07T02:31:56.324954448Z","hd":{"ts_event":"2026-04-07T02:31:56.324937379Z","rtype":160,"publisher_id":101,"instrument_id":436},"action":"C","side":"A","price":"1.156670000","size":30,"channel_id":23,"order_id":"1775529098225718700","flags":0,"ts_in_delta":959,"sequence":164037,"symbol":"FCEU SI 20260615 PS"}
{"ts_recv":"2026-04-07T02:31:56.324954448Z","hd":{"ts_event":"2026-04-07T02:31:56.324937379Z","rtype":160,"publisher_id":101,"instrument_id":436},"action":"A","side":"A","price":"1.156690000","size":30,"channel_id":23,"order_id":"1775529116324943571","flags":128,"ts_in_delta":959,"sequence":164037,"symbol":"FCEU SI 20260615 PS"}
{"ts_recv":"2026-04-07T02:31:56.324979883Z","hd":{"ts_event":"2026-04-07T02:31:56.324958479Z","rtype":160,"publisher_id":101,"instrument_id":436},"action":"C","side":"B","price":"1.156590000","size":30,"channel_id":23,"order_id":"10998901153179641651","flags":0,"ts_in_delta":920,"sequence":164038,"symbol":"FCEU SI 20260615 PS"}
{"ts_recv":"2026-04-07T02:31:56.324979883Z","hd":{"ts_event":"2026-04-07T02:31:56.324958479Z","rtype":160,"publisher_id":101,"instrument_id":436},"action":"A","side":"B","price":"1.156580000","size":30,"channel_id":23,"order_id":"10998901153179740310","flags":0,"ts_in_delta":920,"sequence":164038,"symbol":"FCEU SI 20260615 PS"}
{"ts_recv":"2026-04-07T02:31:56.324979883Z","hd":{"ts_event":"2026-04-07T02:31:56.324958479Z","rtype":160,"publisher_id":101,"instrument_id":436},"action":"C","side":"A","price":"1.156690000","size":30,"channel_id":23,"order_id":"1775529116324865843","flags":0,"ts_in_delta":920,"sequence":164038,"symbol":"FCEU SI 20260615 PS"}
{"ts_recv":"2026-04-07T02:31:56.324979883Z","hd":{"ts_event":"2026-04-07T02:31:56.324958479Z","rtype":160,"publisher_id":101,"instrument_id":436},"action":"A","side":"A","price":"1.156680000","size":30,"channel_id":23,"order_id":"1775529116324964502","flags":128,"ts_in_delta":920,"sequence":164038,"symbol":"FCEU SI 20260615 PS"}
{"ts_recv":"2026-04-07T02:31:56.325039822Z","hd":{"ts_event":"2026-04-07T02:31:56.325023877Z","rtype":160,"publisher_id":101,"instrument_id":436},"action":"C","side":"B","price":"1.156580000","size":30,"channel_id":23,"order_id":"10998901153179740310","flags":0,"ts_in_delta":1026,"sequence":164039,"symbol":"FCEU SI 20260615 PS"}
{"ts_recv":"2026-04-07T02:31:56.325039822Z","hd":{"ts_event":"2026-04-07T02:31:56.325023877Z","rtype":160,"publisher_id":101,"instrument_id":436},"action":"A","side":"B","price":"1.156590000","size":30,"channel_id":23,"order_id":"10998901153179805465","flags":0,"ts_in_delta":1026,"sequence":164039,"symbol":"FCEU SI 20260615 PS"}
{"ts_recv":"2026-04-07T02:31:56.325039822Z","hd":{"ts_event":"2026-04-07T02:31:56.325023877Z","rtype":160,"publisher_id":101,"instrument_id":436},"action":"C","side":"A","price":"1.156680000","size":30,"channel_id":23,"order_id":"1775529116324964502","flags":0,"ts_in_delta":1026,"sequence":164039,"symbol":"FCEU SI 20260615 PS"}
{"ts_recv":"2026-04-07T02:31:56.325039822Z","hd":{"ts_event":"2026-04-07T02:31:56.325023877Z","rtype":160,"publisher_id":101,"instrument_id":436},"action":"A","side":"A","price":"1.156690000","size":30,"channel_id":23,"order_id":"1775529116325029657","flags":128,"ts_in_delta":1026,"sequence":164039,"symbol":"FCEU SI 20260615 PS"}
{"ts_recv":"2026-04-07T02:32:04.543766689Z","hd":{"ts_event":"2026-04-07T02:32:04.543744809Z","rtype":160,"publisher_id":101,"instrument_id":436},"action":"C","side":"B","price":"1.156590000","size":30,"channel_id":23,"order_id":"10998901153179805465","flags":0,"ts_in_delta":940,"sequence":164119,"symbol":"FCEU SI 20260615 PS"}
{"ts_recv":"2026-04-07T02:32:04.543766689Z","hd":{"ts_event":"2026-04-07T02:32:04.543744809Z","rtype":160,"publisher_id":101,"instrument_id":436},"action":"A","side":"B","price":"1.156580000","size":30,"channel_id":23,"order_id":"10998901161398526665","flags":0,"ts_in_delta":940,"sequence":164119,"symbol":"FCEU SI 20260615 PS"}
{"ts_recv":"2026-04-07T02:32:04.543766689Z","hd":{"ts_event":"2026-04-07T02:32:04.543744809Z","rtype":160,"publisher_id":101,"instrument_id":436},"action":"C","side":"A","price":"1.156690000","size":30,"channel_id":23,"order_id":"1775529116325029657","flags":0,"ts_in_delta":940,"sequence":164119,"symbol":"FCEU SI 20260615 PS"}
{"ts_recv":"2026-04-07T02:32:04.543766689Z","hd":{"ts_event":"2026-04-07T02:32:04.543744809Z","rtype":160,"publisher_id":101,"instrument_id":436},"action":"A","side":"A","price":"1.156680000","size":30,"channel_id":23,"order_id":"1775529124543750857","flags":128,"ts_in_delta":940,"sequence":164119,"symbol":"FCEU SI 20260615 PS"}
{"ts_recv":"2026-04-07T02:32:04.543819188Z","hd":{"ts_event":"2026-04-07T02:32:04.543797915Z","rtype":160,"publisher_id":101,"instrument_id":436},"action":"C","side":"B","price":"1.156590000","size":30,"channel_id":23,"order_id":"10998901153179719379","flags":0,"ts_in_delta":911,"sequence":164120,"symbol":"FCEU SI 20260615 PS"}
{"ts_recv":"2026-04-07T02:32:04.543819188Z","hd":{"ts_event":"2026-04-07T02:32:04.543797915Z","rtype":160,"publisher_id":101,"instrument_id":436},"action":"A","side":"B","price":"1.156570000","size":30,"channel_id":23,"order_id":"10998901161398579750","flags":0,"ts_in_delta":911,"sequence":164120,"symbol":"FCEU SI 20260615 PS"}
{"ts_recv":"2026-04-07T02:32:04.543819188Z","hd":{"ts_event":"2026-04-07T02:32:04.543797915Z","rtype":160,"publisher_id":101,"instrument_id":436},"action":"C","side":"A","price":"1.156690000","size":30,"channel_id":23,"order_id":"1775529116324943571","flags":0,"ts_in_delta":911,"sequence":164120,"symbol":"FCEU SI 20260615 PS"}
{"ts_recv":"2026-04-07T02:32:04.543819188Z","hd":{"ts_event":"2026-04-07T02:32:04.543797915Z","rtype":160,"publisher_id":101,"instrument_id":436},"action":"A","side":"A","price":"1.156670000","size":30,"channel_id":23,"order_id":"1775529124543803942","flags":128,"ts_in_delta":911,"sequence":164120,"symbol":"FCEU SI 20260615 PS"}
{"ts_recv":"2026-04-07T02:32:04.543871432Z","hd":{"ts_event":"2026-04-07T02:32:04.543854805Z","rtype":160,"publisher_id":101,"instrument_id":436},"action":"C","side":"B","price":"1.156580000","size":30,"channel_id":23,"order_id":"10998901161398526665","flags":0,"ts_in_delta":850,"sequence":164121,"symbol":"FCEU SI 20260615 PS"}
{"ts_recv":"2026-04-07T02:32:04.543871432Z","hd":{"ts_event":"2026-04-07T02:32:04.543854805Z","rtype":160,"publisher_id":101,"instrument_id":436},"action":"A","side":"B","price":"1.156570000","size":30,"channel_id":23,"order_id":"10998901161398636363","flags":0,"ts_in_delta":850,"sequence":164121,"symbol":"FCEU SI 20260615 PS"}
{"ts_recv":"2026-04-07T02:32:04.543871432Z","hd":{"ts_event":"2026-04-07T02:32:04.543854805Z","rtype":160,"publisher_id":101,"instrument_id":436},"action":"C","side":"A","price":"1.156680000","size":30,"channel_id":23,"order_id":"1775529124543750857","flags":0,"ts_in_delta":850,"sequence":164121,"symbol":"FCEU SI 20260615 PS"}
{"ts_recv":"2026-04-07T02:32:04.543871432Z","hd":{"ts_event":"2026-04-07T02:32:04.543854805Z","rtype":160,"publisher_id":101,"instrument_id":436},"action":"A","side":"A","price":"1.156670000","size":30,"channel_id":23,"order_id":"1775529124543860555","flags":128,"ts_in_delta":850,"sequence":164121,"symbol":"FCEU SI 20260615 PS"}
{"ts_recv":"2026-04-07T02:32:10.612190284Z","hd":{"ts_event":"2026-04-07T02:32:10.612168001Z","rtype":160,"publisher_id":101,"instrument_id":436},"action":"C","side":"B","price":"1.156570000","size":30,"channel_id":23,"order_id":"10998901161398636363","flags":0,"ts_in_delta":949,"sequence":164192,"symbol":"FCEU SI 20260615 PS"}
{"ts_recv":"2026-04-07T02:32:10.612190284Z","hd":{"ts_event":"2026-04-07T02:32:10.612168001Z","rtype":160,"publisher_id":101,"instrument_id":436},"action":"A","side":"B","price":"1.156580000","size":30,"channel_id":23,"order_id":"10998901167466949765","flags":0,"ts_in_delta":949,"sequence":164192,"symbol":"FCEU SI 20260615 PS"}
{"ts_recv":"2026-04-07T02:32:10.612190284Z","hd":{"ts_event":"2026-04-07T02:32:10.612168001Z","rtype":160,"publisher_id":101,"instrument_id":436},"action":"C","side":"A","price":"1.156670000","size":30,"channel_id":23,"order_id":"1775529124543860555","flags":0,"ts_in_delta":949,"sequence":164192,"symbol":"FCEU SI 20260615 PS"}
{"ts_recv":"2026-04-07T02:32:10.612190284Z","hd":{"ts_event":"2026-04-07T02:32:10.612168001Z","rtype":160,"publisher_id":101,"instrument_id":436},"action":"A","side":"A","price":"1.156680000","size":30,"channel_id":23,"order_id":"1775529130612173957","flags":128,"ts_in_delta":949,"sequence":164192,"symbol":"FCEU SI 20260615 PS"}
{"ts_recv":"2026-04-07T02:32:16.227129572Z","hd":{"ts_event":"2026-04-07T02:32:16.227111517Z","rtype":160,"publisher_id":101,"instrument_id":436},"action":"C","side":"B","price":"1.156580000","size":30,"channel_id":23,"order_id":"10998901167466949765","flags":0,"ts_in_delta":973,"sequence":164250,"symbol":"FCEU SI 20260615 PS"}
{"ts_recv":"2026-04-07T02:32:16.227129572Z","hd":{"ts_event":"2026-04-07T02:32:16.227111517Z","rtype":160,"publisher_id":101,"instrument_id":436},"action":"A","side":"B","price":"1.156570000","size":30,"channel_id":23,"order_id":"10998901173081893647","flags":0,"ts_in_delta":973,"sequence":164250,"symbol":"FCEU SI 20260615 PS"}
{"ts_recv":"2026-04-07T02:32:16.227129572Z","hd":{"ts_event":"2026-04-07T02:32:16.227111517Z","rtype":160,"publisher_id":101,"instrument_id":436},"action":"C","side":"A","price":"1.156680000","size":30,"channel_id":23,"order_id":"1775529130612173957","flags":0,"ts_in_delta":973,"sequence":164250,"symbol":"FCEU SI 20260615 PS"}
{"ts_recv":"2026-04-07T02:32:16.227129572Z","hd":{"ts_event":"2026-04-07T02:32:16.227111517Z","rtype":160,"publisher_id":101,"instrument_id":436},"action":"A","side":"A","price":"1.156670000","size":30,"channel_id":23,"order_id":"1775529136227117839","flags":128,"ts_in_delta":973,"sequence":164250,"symbol":"FCEU SI 20260615 PS"}
{"ts_recv":"2026-04-07T02:32:27.618942970Z","hd":{"ts_event":"2026-04-07T02:32:27.618920797Z","rtype":160,"publisher_id":101,"instrument_id":436},"action":"C","side":"B","price":"1.156570000","size":30,"channel_id":23,"order_id":"10998901173081893647","flags":0,"ts_in_delta":1149,"sequence":164342,"symbol":"FCEU SI 20260615 PS"}
{"ts_recv":"2026-04-07T02:32:27.618942970Z","hd":{"ts_event":"2026-04-07T02:32:27.618920797Z","rtype":160,"publisher_id":101,"instrument_id":436},"action":"A","side":"B","price":"1.156580000","size":30,"channel_id":23,"order_id":"10998901184473702900","flags":0,"ts_in_delta":1149,"sequence":164342,"symbol":"FCEU SI 20260615 PS"}
{"ts_recv":"2026-04-07T02:32:27.618942970Z","hd":{"ts_event":"2026-04-07T02:32:27.618920797Z","rtype":160,"publisher_id":101,"instrument_id":436},"action":"C","side":"A","price":"1.156670000","size":30,"channel_id":23,"order_id":"1775529136227117839","flags":0,"ts_in_delta":1149,"sequence":164342,"symbol":"FCEU SI 20260615 PS"}
{"ts_recv":"2026-04-07T02:32:27.618942970Z","hd":{"ts_event":"2026-04-07T02:32:27.618920797Z","rtype":160,"publisher_id":101,"instrument_id":436},"action":"A","side":"A","price":"1.156680000","size":30,"channel_id":23,"order_id":"1775529147618927092","flags":128,"ts_in_delta":1149,"sequence":164342,"symbol":"FCEU SI 20260615 PS"}
{"ts_recv":"2026-04-07T02:32:27.677821513Z","hd":{"ts_event":"2026-04-07T02:32:27.677801373Z","rtype":160,"publisher_id":101,"instrument_id":436},"action":"C","side":"B","price":"1.156580000","size":30,"channel_id":23,"order_id":"10998901184473702900","flags":0,"ts_in_delta":917,"sequence":164349,"symbol":"FCEU SI 20260615 PS"}
{"ts_recv":"2026-04-07T02:32:27.677821513Z","hd":{"ts_event":"2026-04-07T02:32:27.677801373Z","rtype":160,"publisher_id":101,"instrument_id":436},"action":"A","side":"B","price":"1.156570000","size":30,"channel_id":23,"order_id":"10998901184532583256","flags":0,"ts_in_delta":917,"sequence":164349,"symbol":"FCEU SI 20260615 PS"}
{"ts_recv":"2026-04-07T02:32:27.677821513Z","hd":{"ts_event":"2026-04-07T02:32:27.677801373Z","rtype":160,"publisher_id":101,"instrument_id":436},"action":"C","side":"A","price":"1.156680000","size":30,"channel_id":23,"order_id":"1775529147618927092","flags":0,"ts_in_delta":917,"sequence":164349,"symbol":"FCEU SI 20260615 PS"}
{"ts_recv":"2026-04-07T02:32:27.677821513Z","hd":{"ts_event":"2026-04-07T02:32:27.677801373Z","rtype":160,"publisher_id":101,"instrument_id":436},"action":"A","side":"A","price":"1.156670000","size":30,"channel_id":23,"order_id":"1775529147677807448","flags":128,"ts_in_delta":917,"sequence":164349,"symbol":"FCEU SI 20260615 PS"}
{"ts_recv":"2026-04-07T02:32:27.766899640Z","hd":{"ts_event":"2026-04-07T02:32:27.766869263Z","rtype":160,"publisher_id":101,"instrument_id":436},"action":"C","side":"B","price":"1.156570000","size":30,"channel_id":23,"order_id":"10998901184532583256","flags":0,"ts_in_delta":1441,"sequence":164354,"symbol":"FCEU SI 20260615 PS"}
{"ts_recv":"2026-04-07T02:32:27.766899640Z","hd":{"ts_event":"2026-04-07T02:32:27.766869263Z","rtype":160,"publisher_id":101,"instrument_id":436},"action":"A","side":"B","price":"1.156580000","size":30,"channel_id":23,"order_id":"10998901184621655937","flags":0,"ts_in_delta":1441,"sequence":164354,"symbol":"FCEU SI 20260615 PS"}
{"ts_recv":"2026-04-07T02:32:27.766899640Z","hd":{"ts_event":"2026-04-07T02:32:27.766869263Z","rtype":160,"publisher_id":101,"instrument_id":436},"action":"C","side":"A","price":"1.156670000","size":30,"channel_id":23,"order_id":"1775529147677807448","flags":0,"ts_in_delta":1441,"sequence":164354,"symbol":"FCEU SI 20260615 PS"}
{"ts_recv":"2026-04-07T02:32:27.766899640Z","hd":{"ts_event":"2026-04-07T02:32:27.766869263Z","rtype":160,"publisher_id":101,"instrument_id":436},"action":"A","side":"A","price":"1.156680000","size":30,"channel_id":23,"order_id":"1775529147766880129","flags":128,"ts_in_delta":1441,"sequence":164354,"symbol":"FCEU SI 20260615 PS"}
{"ts_recv":"2026-04-07T02:32:27.779248766Z","hd":{"ts_event":"2026-04-07T02:32:27.779229301Z","rtype":160,"publisher_id":101,"instrument_id":436},"action":"C","side":"B","price":"1.156580000","size":30,"channel_id":23,"order_id":"10998901184621655937","flags":0,"ts_in_delta":741,"sequence":164356,"symbol":"FCEU SI 20260615 PS"}
{"ts_recv":"2026-04-07T02:32:27.779248766Z","hd":{"ts_event":"2026-04-07T02:32:27.779229301Z","rtype":160,"publisher_id":101,"instrument_id":436},"action":"A","side":"B","price":"1.156590000","size":30,"channel_id":23,"order_id":"10998901184634012784","flags":0,"ts_in_delta":741,"sequence":164356,"symbol":"FCEU SI 20260615 PS"}
{"ts_recv":"2026-04-07T02:32:27.779248766Z","hd":{"ts_event":"2026-04-07T02:32:27.779229301Z","rtype":160,"publisher_id":101,"instrument_id":436},"action":"C","side":"A","price":"1.156680000","size":30,"channel_id":23,"order_id":"1775529147766880129","flags":0,"ts_in_delta":741,"sequence":164356,"symbol":"FCEU SI 20260615 PS"}
{"ts_recv":"2026-04-07T02:32:27.779248766Z","hd":{"ts_event":"2026-04-07T02:32:27.779229301Z","rtype":160,"publisher_id":101,"instrument_id":436},"action":"A","side":"A","price":"1.156690000","size":30,"channel_id":23,"order_id":"1775529147779236976","flags":128,"ts_in_delta":741,"sequence":164356,"symbol":"FCEU SI 20260615 PS"}
{"ts_recv":"2026-04-07T02:32:27.779316285Z","hd":{"ts_event":"2026-04-07T02:32:27.779298519Z","rtype":160,"publisher_id":101,"instrument_id":436},"action":"C","side":"B","price":"1.156570000","size":30,"channel_id":23,"order_id":"10998901161398579750","flags":0,"ts_in_delta":745,"sequence":164357,"symbol":"FCEU SI 20260615 PS"}
{"ts_recv":"2026-04-07T02:32:27.779316285Z","hd":{"ts_event":"2026-04-07T02:32:27.779298519Z","rtype":160,"publisher_id":101,"instrument_id":436},"action":"A","side":"B","price":"1.156590000","size":30,"channel_id":23,"order_id":"10998901184634080874","flags":0,"ts_in_delta":745,"sequence":164357,"symbol":"FCEU SI 20260615 PS"}
{"ts_recv":"2026-04-07T02:32:27.779316285Z","hd":{"ts_event":"2026-04-07T02:32:27.779298519Z","rtype":160,"publisher_id":101,"instrument_id":436},"action":"C","side":"A","price":"1.156670000","size":30,"channel_id":23,"order_id":"1775529124543803942","flags":0,"ts_in_delta":745,"sequence":164357,"symbol":"FCEU SI 20260615 PS"}
{"ts_recv":"2026-04-07T02:32:27.779316285Z","hd":{"ts_event":"2026-04-07T02:32:27.779298519Z","rtype":160,"publisher_id":101,"instrument_id":436},"action":"A","side":"A","price":"1.156690000","size":30,"channel_id":23,"order_id":"1775529147779305066","flags":128,"ts_in_delta":745,"sequence":164357,"symbol":"FCEU SI 20260615 PS"}
{"ts_recv":"2026-04-07T02:32:27.779330063Z","hd":{"ts_event":"2026-04-07T02:32:27.779312939Z","rtype":160,"publisher_id":101,"instrument_id":436},"action":"C","side":"B","price":"1.156590000","size":30,"channel_id":23,"order_id":"10998901184634012784","flags":0,"ts_in_delta":757,"sequence":164358,"symbol":"FCEU SI 20260615 PS"}
{"ts_recv":"2026-04-07T02:32:27.779330063Z","hd":{"ts_event":"2026-04-07T02:32:27.779312939Z","rtype":160,"publisher_id":101,"instrument_id":436},"action":"A","side":"B","price":"1.156580000","size":30,"channel_id":23,"order_id":"10998901184634094392","flags":0,"ts_in_delta":757,"sequence":164358,"symbol":"FCEU SI 20260615 PS"}
{"ts_recv":"2026-04-07T02:32:27.779330063Z","hd":{"ts_event":"2026-04-07T02:32:27.779312939Z","rtype":160,"publisher_id":101,"instrument_id":436},"action":"C","side":"A","price":"1.156690000","size":30,"channel_id":23,"order_id":"1775529147779236976","flags":0,"ts_in_delta":757,"sequence":164358,"symbol":"FCEU SI 20260615 PS"}
{"ts_recv":"2026-04-07T02:32:27.779330063Z","hd":{"ts_event":"2026-04-07T02:32:27.779312939Z","rtype":160,"publisher_id":101,"instrument_id":436},"action":"A","side":"A","price":"1.156680000","size":30,"channel_id":23,"order_id":"1775529147779318584","flags":128,"ts_in_delta":757,"sequence":164358,"symbol":"FCEU SI 20260615 PS"}
{"ts_recv":"2026-04-07T02:32:27.779391884Z","hd":{"ts_event":"2026-04-07T02:32:27.779372555Z","rtype":160,"publisher_id":101,"instrument_id":436},"action":"C","side":"B","price":"1.156580000","size":30,"channel_id":23,"order_id":"10998901184634094392","flags":0,"ts_in_delta":734,"sequence":164359,"symbol":"FCEU SI 20260615 PS"}
{"ts_recv":"2026-04-07T02:32:27.779391884Z","hd":{"ts_event":"2026-04-07T02:32:27.779372555Z","rtype":160,"publisher_id":101,"instrument_id":436},"action":"A","side":"B","price":"1.156590000","size":30,"channel_id":23,"order_id":"10998901184634154167","flags":0,"ts_in_delta":734,"sequence":164359,"symbol":"FCEU SI 20260615 PS"}
{"ts_recv":"2026-04-07T02:32:27.779391884Z","hd":{"ts_event":"2026-04-07T02:32:27.779372555Z","rtype":160,"publisher_id":101,"instrument_id":436},"action":"C","side":"A","price":"1.156680000","size":30,"channel_id":23,"order_id":"1775529147779318584","flags":0,"ts_in_delta":734,"sequence":164359,"symbol":"FCEU SI 20260615 PS"}
{"ts_recv":"2026-04-07T02:32:27.779391884Z","hd":{"ts_event":"2026-04-07T02:32:27.779372555Z","rtype":160,"publisher_id":101,"instrument_id":436},"action":"A","side":"A","price":"1.156690000","size":30,"channel_id":23,"order_id":"1775529147779378359","flags":128,"ts_in_delta":734,"sequence":164359,"symbol":"FCEU SI 20260615 PS"}
{"ts_recv":"2026-04-07T02:32:28.435139487Z","hd":{"ts_event":"2026-04-07T02:32:28.435120275Z","rtype":160,"publisher_id":101,"instrument_id":436},"action":"C","side":"B","price":"1.156590000","size":30,"channel_id":23,"order_id":"10998901184634154167","flags":0,"ts_in_delta":910,"sequence":164369,"symbol":"FCEU SI 20260615 PS"}
{"ts_recv":"2026-04-07T02:32:28.435139487Z","hd":{"ts_event":"2026-04-07T02:32:28.435120275Z","rtype":160,"publisher_id":101,"instrument_id":436},"action":"A","side":"B","price":"1.156580000","size":30,"channel_id":23,"order_id":"10998901185289902224","flags":0,"ts_in_delta":910,"sequence":164369,"symbol":"FCEU SI 20260615 PS"}
{"ts_recv":"2026-04-07T02:32:28.435139487Z","hd":{"ts_event":"2026-04-07T02:32:28.435120275Z","rtype":160,"publisher_id":101,"instrument_id":436},"action":"C","side":"A","price":"1.156690000","size":30,"channel_id":23,"order_id":"1775529147779378359","flags":0,"ts_in_delta":910,"sequence":164369,"symbol":"FCEU SI 20260615 PS"}
{"ts_recv":"2026-04-07T02:32:28.435139487Z","hd":{"ts_event":"2026-04-07T02:32:28.435120275Z","rtype":160,"publisher_id":101,"instrument_id":436},"action":"A","side":"A","price":"1.156680000","size":30,"channel_id":23,"order_id":"1775529148435126416","flags":128,"ts_in_delta":910,"sequence":164369,"symbol":"FCEU SI 20260615 PS"}
{"ts_recv":"2026-04-07T02:32:28.442321908Z","hd":{"ts_event":"2026-04-07T02:32:28.442301959Z","rtype":160,"publisher_id":101,"instrument_id":436},"action":"C","side":"B","price":"1.156590000","size":30,"channel_id":23,"order_id":"10998901184634080874","flags":0,"ts_in_delta":957,"sequence":164370,"symbol":"FCEU SI 20260615 PS"}
{"ts_recv":"2026-04-07T02:32:28.442321908Z","hd":{"ts_event":"2026-04-07T02:32:28.442301959Z","rtype":160,"publisher_id":101,"instrument_id":436},"action":"A","side":"B","price":"1.156570000","size":30,"channel_id":23,"order_id":"10998901185297083854","flags":0,"ts_in_delta":957,"sequence":164370,"symbol":"FCEU SI 20260615 PS"}
{"ts_recv":"2026-04-07T02:32:28.442321908Z","hd":{"ts_event":"2026-04-07T02:32:28.442301959Z","rtype":160,"publisher_id":101,"instrument_id":436},"action":"C","side":"A","price":"1.156690000","size":30,"channel_id":23,"order_id":"1775529147779305066","flags":0,"ts_in_delta":957,"sequence":164370,"symbol":"FCEU SI 20260615 PS"}
{"ts_recv":"2026-04-07T02:32:28.442321908Z","hd":{"ts_event":"2026-04-07T02:32:28.442301959Z","rtype":160,"publisher_id":101,"instrument_id":436},"action":"A","side":"A","price":"1.156670000","size":30,"channel_id":23,"order_id":"1775529148442308046","flags":128,"ts_in_delta":957,"sequence":164370,"symbol":"FCEU SI 20260615 PS"}
{"ts_recv":"2026-04-07T02:32:28.442383269Z","hd":{"ts_event":"2026-04-07T02:32:28.442365569Z","rtype":160,"publisher_id":101,"instrument_id":436},"action":"C","side":"B","price":"1.156580000","size":30,"channel_id":23,"order_id":"10998901185289902224","flags":0,"ts_in_delta":892,"sequence":164371,"symbol":"FCEU SI 20260615 PS"}
{"ts_recv":"2026-04-07T02:32:28.442383269Z","hd":{"ts_event":"2026-04-07T02:32:28.442365569Z","rtype":160,"publisher_id":101,"instrument_id":436},"action":"A","side":"B","price":"1.156570000","size":30,"channel_id":23,"order_id":"10998901185297147230","flags":0,"ts_in_delta":892,"sequence":164371,"symbol":"FCEU SI 20260615 PS"}
{"ts_recv":"2026-04-07T02:32:28.442383269Z","hd":{"ts_event":"2026-04-07T02:32:28.442365569Z","rtype":160,"publisher_id":101,"instrument_id":436},"action":"C","side":"A","price":"1.156680000","size":30,"channel_id":23,"order_id":"1775529148435126416","flags":0,"ts_in_delta":892,"sequence":164371,"symbol":"FCEU SI 20260615 PS"}
{"ts_recv":"2026-04-07T02:32:28.442383269Z","hd":{"ts_event":"2026-04-07T02:32:28.442365569Z","rtype":160,"publisher_id":101,"instrument_id":436},"action":"A","side":"A","price":"1.156670000","size":30,"channel_id":23,"order_id":"1775529148442371422","flags":128,"ts_in_delta":892,"sequence":164371,"symbol":"FCEU SI 20260615 PS"}
{"ts_recv":"2026-04-07T02:32:30.148549774Z","hd":{"ts_event":"2026-04-07T02:32:30.148527533Z","rtype":160,"publisher_id":101,"instrument_id":436},"action":"C","side":"B","price":"1.156570000","size":30,"channel_id":23,"order_id":"10998901185297147230","flags":0,"ts_in_delta":1392,"sequence":164387,"symbol":"FCEU SI 20260615 PS"}
{"ts_recv":"2026-04-07T02:32:30.148549774Z","hd":{"ts_event":"2026-04-07T02:32:30.148527533Z","rtype":160,"publisher_id":101,"instrument_id":436},"action":"A","side":"B","price":"1.156580000","size":30,"channel_id":23,"order_id":"10998901187003309288","flags":0,"ts_in_delta":1392,"sequence":164387,"symbol":"FCEU SI 20260615 PS"}
{"ts_recv":"2026-04-07T02:32:30.148549774Z","hd":{"ts_event":"2026-04-07T02:32:30.148527533Z","rtype":160,"publisher_id":101,"instrument_id":436},"action":"C","side":"A","price":"1.156670000","size":30,"channel_id":23,"order_id":"1775529148442371422","flags":0,"ts_in_delta":1392,"sequence":164387,"symbol":"FCEU SI 20260615 PS"}
{"ts_recv":"2026-04-07T02:32:30.148549774Z","hd":{"ts_event":"2026-04-07T02:32:30.148527533Z","rtype":160,"publisher_id":101,"instrument_id":436},"action":"A","side":"A","price":"1.156680000","size":30,"channel_id":23,"order_id":"1775529150148533480","flags":128,"ts_in_delta":1392,"sequence":164387,"symbol":"FCEU SI 20260615 PS"}
{"ts_recv":"2026-04-07T02:32:41.283701302Z","hd":{"ts_event":"2026-04-07T02:32:41.283673171Z","rtype":160,"publisher_id":101,"instrument_id":436},"action":"C","side":"B","price":"1.156570000","size":30,"channel_id":23,"order_id":"10998901185297083854","flags":0,"ts_in_delta":1334,"sequence":164451,"symbol":"FCEU SI 20260615 PS"}
{"ts_recv":"2026-04-07T02:32:41.283701302Z","hd":{"ts_event":"2026-04-07T02:32:41.283673171Z","rtype":160,"publisher_id":101,"instrument_id":436},"action":"A","side":"B","price":"1.156590000","size":30,"channel_id":23,"order_id":"10998901198138459699","flags":0,"ts_in_delta":1334,"sequence":164451,"symbol":"FCEU SI 20260615 PS"}
{"ts_recv":"2026-04-07T02:32:41.283701302Z","hd":{"ts_event":"2026-04-07T02:32:41.283673171Z","rtype":160,"publisher_id":101,"instrument_id":436},"action":"C","side":"A","price":"1.156670000","size":30,"channel_id":23,"order_id":"1775529148442308046","flags":0,"ts_in_delta":1334,"sequence":164451,"symbol":"FCEU SI 20260615 PS"}
{"ts_recv":"2026-04-07T02:32:41.283701302Z","hd":{"ts_event":"2026-04-07T02:32:41.283673171Z","rtype":160,"publisher_id":101,"instrument_id":436},"action":"A","side":"A","price":"1.156690000","size":30,"channel_id":23,"order_id":"1775529161283683891","flags":128,"ts_in_delta":1334,"sequence":164451,"symbol":"FCEU SI 20260615 PS"}
{"ts_recv":"2026-04-07T02:32:41.283773476Z","hd":{"ts_event":"2026-04-07T02:32:41.283753717Z","rtype":160,"publisher_id":101,"instrument_id":436},"action":"C","side":"B","price":"1.156580000","size":30,"channel_id":23,"order_id":"10998901187003309288","flags":0,"ts_in_delta":1312,"sequence":164452,"symbol":"FCEU SI 20260615 PS"}
{"ts_recv":"2026-04-07T02:32:41.283773476Z","hd":{"ts_event":"2026-04-07T02:32:41.283753717Z","rtype":160,"publisher_id":101,"instrument_id":436},"action":"A","side":"B","price":"1.156590000","size":30,"channel_id":23,"order_id":"10998901198138535683","flags":0,"ts_in_delta":1312,"sequence":164452,"symbol":"FCEU SI 20260615 PS"}
{"ts_recv":"2026-04-07T02:32:41.283773476Z","hd":{"ts_event":"2026-04-07T02:32:41.283753717Z","rtype":160,"publisher_id":101,"instrument_id":436},"action":"C","side":"A","price":"1.156680000","size":30,"channel_id":23,"order_id":"1775529150148533480","flags":0,"ts_in_delta":1312,"sequence":164452,"symbol":"FCEU SI 20260615 PS"}
{"ts_recv":"2026-04-07T02:32:41.283773476Z","hd":{"ts_event":"2026-04-07T02:32:41.283753717Z","rtype":160,"publisher_id":101,"instrument_id":436},"action":"A","side":"A","price":"1.156690000","size":30,"channel_id":23,"order_id":"1775529161283759875","flags":128,"ts_in_delta":1312,"sequence":164452,"symbol":"FCEU SI 20260615 PS"}
{"ts_recv":"2026-04-07T02:32:49.409594434Z","hd":{"ts_event":"2026-04-07T02:32:49.409574051Z","rtype":160,"publisher_id":101,"instrument_id":436},"action":"C","side":"B","price":"1.156590000","size":30,"channel_id":23,"order_id":"10998901198138535683","flags":0,"ts_in_delta":1117,"sequence":164550,"symbol":"FCEU SI 20260615 PS"}
{"ts_recv":"2026-04-07T02:32:49.409594434Z","hd":{"ts_event":"2026-04-07T02:32:49.409574051Z","rtype":160,"publisher_id":101,"instrument_id":436},"action":"A","side":"B","price":"1.156580000","size":30,"channel_id":23,"order_id":"10998901206264355746","flags":0,"ts_in_delta":1117,"sequence":164550,"symbol":"FCEU SI 20260615 PS"}
{"ts_recv":"2026-04-07T02:32:49.409594434Z","hd":{"ts_event":"2026-04-07T02:32:49.409574051Z","rtype":160,"publisher_id":101,"instrument_id":436},"action":"C","side":"A","price":"1.156690000","size":30,"channel_id":23,"order_id":"1775529161283759875","flags":0,"ts_in_delta":1117,"sequence":164550,"symbol":"FCEU SI 20260615 PS"}
{"ts_recv":"2026-04-07T02:32:49.409594434Z","hd":{"ts_event":"2026-04-07T02:32:49.409574051Z","rtype":160,"publisher_id":101,"instrument_id":436},"action":"A","side":"A","price":"1.156680000","size":30,"channel_id":23,"order_id":"1775529169409579938","flags":128,"ts_in_delta":1117,"sequence":164550,"symbol":"FCEU SI 20260615 PS"}
{"ts_recv":"2026-04-07T02:32:49.409653713Z","hd":{"ts_event":"2026-04-07T02:32:49.409631631Z","rtype":160,"publisher_id":101,"instrument_id":436},"action":"C","side":"B","price":"1.156590000","size":30,"channel_id":23,"order_id":"10998901198138459699","flags":0,"ts_in_delta":1094,"sequence":164551,"symbol":"FCEU SI 20260615 PS"}
{"ts_recv":"2026-04-07T02:32:49.409653713Z","hd":{"ts_event":"2026-04-07T02:32:49.409631631Z","rtype":160,"publisher_id":101,"instrument_id":436},"action":"A","side":"B","price":"1.156570000","size":30,"channel_id":23,"order_id":"10998901206264414043","flags":0,"ts_in_delta":1094,"sequence":164551,"symbol":"FCEU SI 20260615 PS"}
{"ts_recv":"2026-04-07T02:32:49.409653713Z","hd":{"ts_event":"2026-04-07T02:32:49.409631631Z","rtype":160,"publisher_id":101,"instrument_id":436},"action":"C","side":"A","price":"1.156690000","size":30,"channel_id":23,"order_id":"1775529161283683891","flags":0,"ts_in_delta":1094,"sequence":164551,"symbol":"FCEU SI 20260615 PS"}
{"ts_recv":"2026-04-07T02:32:49.409653713Z","hd":{"ts_event":"2026-04-07T02:32:49.409631631Z","rtype":160,"publisher_id":101,"instrument_id":436},"action":"A","side":"A","price":"1.156670000","size":30,"channel_id":23,"order_id":"1775529169409638235","flags":128,"ts_in_delta":1094,"sequence":164551,"symbol":"FCEU SI 20260615 PS"}
{"ts_recv":"2026-04-07T02:32:49.409710934Z","hd":{"ts_event":"2026-04-07T02:32:49.409691901Z","rtype":160,"publisher_id":101,"instrument_id":436},"action":"C","side":"B","price":"1.156580000","size":30,"channel_id":23,"order_id":"10998901206264355746","flags":0,"ts_in_delta":1084,"sequence":164552,"symbol":"FCEU SI 20260615 PS"}
{"ts_recv":"2026-04-07T02:32:49.409710934Z","hd":{"ts_event":"2026-04-07T02:32:49.409691901Z","rtype":160,"publisher_id":101,"instrument_id":436},"action":"A","side":"B","price":"1.156570000","size":30,"channel_id":23,"order_id":"10998901206264474027","flags":0,"ts_in_delta":1084,"sequence":164552,"symbol":"FCEU SI 20260615 PS"}
{"ts_recv":"2026-04-07T02:32:49.409710934Z","hd":{"ts_event":"2026-04-07T02:32:49.409691901Z","rtype":160,"publisher_id":101,"instrument_id":436},"action":"C","side":"A","price":"1.156680000","size":30,"channel_id":23,"order_id":"1775529169409579938","flags":0,"ts_in_delta":1084,"sequence":164552,"symbol":"FCEU SI 20260615 PS"}
{"ts_recv":"2026-04-07T02:32:49.409710934Z","hd":{"ts_event":"2026-04-07T02:32:49.409691901Z","rtype":160,"publisher_id":101,"instrument_id":436},"action":"A","side":"A","price":"1.156670000","size":30,"channel_id":23,"order_id":"1775529169409698219","flags":128,"ts_in_delta":1084,"sequence":164552,"symbol":"FCEU SI 20260615 PS"}
{"ts_recv":"2026-04-07T02:33:04.116215717Z","hd":{"ts_event":"2026-04-07T02:33:04.116193179Z","rtype":160,"publisher_id":101,"instrument_id":436},"action":"C","side":"B","price":"1.156570000","size":30,"channel_id":23,"order_id":"10998901206264474027","flags":0,"ts_in_delta":963,"sequence":164611,"symbol":"FCEU SI 20260615 PS"}
{"ts_recv":"2026-04-07T02:33:04.116215717Z","hd":{"ts_event":"2026-04-07T02:33:04.116193179Z","rtype":160,"publisher_id":101,"instrument_id":436},"action":"A","side":"B","price":"1.156580000","size":30,"channel_id":23,"order_id":"10998901220970975307","flags":0,"ts_in_delta":963,"sequence":164611,"symbol":"FCEU SI 20260615 PS"}
{"ts_recv":"2026-04-07T02:33:04.116215717Z","hd":{"ts_event":"2026-04-07T02:33:04.116193179Z","rtype":160,"publisher_id":101,"instrument_id":436},"action":"C","side":"A","price":"1.156670000","size":30,"channel_id":23,"order_id":"1775529169409698219","flags":0,"ts_in_delta":963,"sequence":164611,"symbol":"FCEU SI 20260615 PS"}
{"ts_recv":"2026-04-07T02:33:04.116215717Z","hd":{"ts_event":"2026-04-07T02:33:04.116193179Z","rtype":160,"publisher_id":101,"instrument_id":436},"action":"A","side":"A","price":"1.156680000","size":30,"channel_id":23,"order_id":"1775529184116199499","flags":128,"ts_in_delta":963,"sequence":164611,"symbol":"FCEU SI 20260615 PS"}
{"ts_recv":"2026-04-07T02:33:07.862447456Z","hd":{"ts_event":"2026-04-07T02:33:07.862419739Z","rtype":160,"publisher_id":101,"instrument_id":436},"action":"C","side":"B","price":"1.156580000","size":30,"channel_id":23,"order_id":"10998901220970975307","flags":0,"ts_in_delta":1028,"sequence":164650,"symbol":"FCEU SI 20260615 PS"}
{"ts_recv":"2026-04-07T02:33:07.862447456Z","hd":{"ts_event":"2026-04-07T02:33:07.862419739Z","rtype":160,"publisher_id":101,"instrument_id":436},"action":"A","side":"B","price":"1.156570000","size":30,"channel_id":23,"order_id":"10998901224717207290","flags":0,"ts_in_delta":1028,"sequence":164650,"symbol":"FCEU SI 20260615 PS"}
{"ts_recv":"2026-04-07T02:33:07.862447456Z","hd":{"ts_event":"2026-04-07T02:33:07.862419739Z","rtype":160,"publisher_id":101,"instrument_id":436},"action":"C","side":"A","price":"1.156680000","size":30,"channel_id":23,"order_id":"1775529184116199499","flags":0,"ts_in_delta":1028,"sequence":164650,"symbol":"FCEU SI 20260615 PS"}
{"ts_recv":"2026-04-07T02:33:07.862447456Z","hd":{"ts_event":"2026-04-07T02:33:07.862419739Z","rtype":160,"publisher_id":101,"instrument_id":436},"action":"A","side":"A","price":"1.156670000","size":30,"channel_id":23,"order_id":"1775529187862431482","flags":128,"ts_in_delta":1028,"sequence":164650,"symbol":"FCEU SI 20260615 PS"}
{"ts_recv":"2026-04-07T02:33:11.715994203Z","hd":{"ts_event":"2026-04-07T02:33:11.715974753Z","rtype":160,"publisher_id":101,"instrument_id":436},"action":"C","side":"B","price":"1.156570000","size":30,"channel_id":23,"order_id":"10998901224717207290","flags":0,"ts_in_delta":912,"sequence":164702,"symbol":"FCEU SI 20260615 PS"}
{"ts_recv":"2026-04-07T02:33:11.715994203Z","hd":{"ts_event":"2026-04-07T02:33:11.715974753Z","rtype":160,"publisher_id":101,"instrument_id":436},"action":"A","side":"B","price":"1.156560000","size":30,"channel_id":23,"order_id":"10998901228570756406","flags":0,"ts_in_delta":912,"sequence":164702,"symbol":"FCEU SI 20260615 PS"}
{"ts_recv":"2026-04-07T02:33:11.715994203Z","hd":{"ts_event":"2026-04-07T02:33:11.715974753Z","rtype":160,"publisher_id":101,"instrument_id":436},"action":"C","side":"A","price":"1.156670000","size":30,"channel_id":23,"order_id":"1775529187862431482","flags":0,"ts_in_delta":912,"sequence":164702,"symbol":"FCEU SI 20260615 PS"}
{"ts_recv":"2026-04-07T02:33:11.715994203Z","hd":{"ts_event":"2026-04-07T02:33:11.715974753Z","rtype":160,"publisher_id":101,"instrument_id":436},"action":"A","side":"A","price":"1.156660000","size":30,"channel_id":23,"order_id":"1775529191715980598","flags":128,"ts_in_delta":912,"sequence":164702,"symbol":"FCEU SI 20260615 PS"}
{"ts_recv":"2026-04-07T02:33:11.716047231Z","hd":{"ts_event":"2026-04-07T02:33:11.716026095Z","rtype":160,"publisher_id":101,"instrument_id":436},"action":"C","side":"B","price":"1.156570000","size":30,"channel_id":23,"order_id":"10998901206264414043","flags":0,"ts_in_delta":916,"sequence":164703,"symbol":"FCEU SI 20260615 PS"}
{"ts_recv":"2026-04-07T02:33:11.716047231Z","hd":{"ts_event":"2026-04-07T02:33:11.716026095Z","rtype":160,"publisher_id":101,"instrument_id":436},"action":"A","side":"B","price":"1.156550000","size":30,"channel_id":23,"order_id":"10998901228570807910","flags":0,"ts_in_delta":916,"sequence":164703,"symbol":"FCEU SI 20260615 PS"}
{"ts_recv":"2026-04-07T02:33:11.716047231Z","hd":{"ts_event":"2026-04-07T02:33:11.716026095Z","rtype":160,"publisher_id":101,"instrument_id":436},"action":"C","side":"A","price":"1.156670000","size":30,"channel_id":23,"order_id":"1775529169409638235","flags":0,"ts_in_delta":916,"sequence":164703,"symbol":"FCEU SI 20260615 PS"}
{"ts_recv":"2026-04-07T02:33:11.716047231Z","hd":{"ts_event":"2026-04-07T02:33:11.716026095Z","rtype":160,"publisher_id":101,"instrument_id":436},"action":"A","side":"A","price":"1.156650000","size":30,"channel_id":23,"order_id":"1775529191716032102","flags":128,"ts_in_delta":916,"sequence":164703,"symbol":"FCEU SI 20260615 PS"}
{"ts_recv":"2026-04-07T02:33:11.716100566Z","hd":{"ts_event":"2026-04-07T02:33:11.716083139Z","rtype":160,"publisher_id":101,"instrument_id":436},"action":"C","side":"B","price":"1.156560000","size":30,"channel_id":23,"order_id":"10998901228570756406","flags":0,"ts_in_delta":934,"sequence":164704,"symbol":"FCEU SI 20260615 PS"}
{"ts_recv":"2026-04-07T02:33:11.716100566Z","hd":{"ts_event":"2026-04-07T02:33:11.716083139Z","rtype":160,"publisher_id":101,"instrument_id":436},"action":"A","side":"B","price":"1.156550000","size":30,"channel_id":23,"order_id":"10998901228570865053","flags":0,"ts_in_delta":934,"sequence":164704,"symbol":"FCEU SI 20260615 PS"}
{"ts_recv":"2026-04-07T02:33:11.716100566Z","hd":{"ts_event":"2026-04-07T02:33:11.716083139Z","rtype":160,"publisher_id":101,"instrument_id":436},"action":"C","side":"A","price":"1.156660000","size":30,"channel_id":23,"order_id":"1775529191715980598","flags":0,"ts_in_delta":934,"sequence":164704,"symbol":"FCEU SI 20260615 PS"}
{"ts_recv":"2026-04-07T02:33:11.716100566Z","hd":{"ts_event":"2026-04-07T02:33:11.716083139Z","rtype":160,"publisher_id":101,"instrument_id":436},"action":"A","side":"A","price":"1.156650000","size":30,"channel_id":23,"order_id":"1775529191716089245","flags":128,"ts_in_delta":934,"sequence":164704,"symbol":"FCEU SI 20260615 PS"}
{"ts_recv":"2026-04-07T02:33:11.722222821Z","hd":{"ts_event":"2026-04-07T02:33:11.722203119Z","rtype":160,"publisher_id":101,"instrument_id":436},"action":"C","side":"B","price":"1.156550000","size":30,"channel_id":23,"order_id":"10998901228570865053","flags":0,"ts_in_delta":1101,"sequence":164711,"symbol":"FCEU SI 20260615 PS"}
{"ts_recv":"2026-04-07T02:33:11.722222821Z","hd":{"ts_event":"2026-04-07T02:33:11.722203119Z","rtype":160,"publisher_id":101,"instrument_id":436},"action":"A","side":"B","price":"1.156540000","size":30,"channel_id":23,"order_id":"10998901228576984812","flags":0,"ts_in_delta":1101,"sequence":164711,"symbol":"FCEU SI 20260615 PS"}
{"ts_recv":"2026-04-07T02:33:11.722222821Z","hd":{"ts_event":"2026-04-07T02:33:11.722203119Z","rtype":160,"publisher_id":101,"instrument_id":436},"action":"C","side":"A","price":"1.156650000","size":30,"channel_id":23,"order_id":"1775529191716089245","flags":0,"ts_in_delta":1101,"sequence":164711,"symbol":"FCEU SI 20260615 PS"}
{"ts_recv":"2026-04-07T02:33:11.722222821Z","hd":{"ts_event":"2026-04-07T02:33:11.722203119Z","rtype":160,"publisher_id":101,"instrument_id":436},"action":"A","side":"A","price":"1.156640000","size":30,"channel_id":23,"order_id":"1775529191722209004","flags":128,"ts_in_delta":1101,"sequence":164711,"symbol":"FCEU SI 20260615 PS"}
{"ts_recv":"2026-04-07T02:33:11.728510156Z","hd":{"ts_event":"2026-04-07T02:33:11.728492255Z","rtype":160,"publisher_id":101,"instrument_id":436},"action":"C","side":"B","price":"1.156550000","size":30,"channel_id":23,"order_id":"10998901228570807910","flags":0,"ts_in_delta":920,"sequence":164717,"symbol":"FCEU SI 20260615 PS"}
{"ts_recv":"2026-04-07T02:33:11.728510156Z","hd":{"ts_event":"2026-04-07T02:33:11.728492255Z","rtype":160,"publisher_id":101,"instrument_id":436},"action":"A","side":"B","price":"1.156530000","size":30,"channel_id":23,"order_id":"10998901228583273728","flags":0,"ts_in_delta":920,"sequence":164717,"symbol":"FCEU SI 20260615 PS"}
{"ts_recv":"2026-04-07T02:33:11.728510156Z","hd":{"ts_event":"2026-04-07T02:33:11.728492255Z","rtype":160,"publisher_id":101,"instrument_id":436},"action":"C","side":"A","price":"1.156650000","size":30,"channel_id":23,"order_id":"1775529191716032102","flags":0,"ts_in_delta":920,"sequence":164717,"symbol":"FCEU SI 20260615 PS"}
{"ts_recv":"2026-04-07T02:33:11.728510156Z","hd":{"ts_event":"2026-04-07T02:33:11.728492255Z","rtype":160,"publisher_id":101,"instrument_id":436},"action":"A","side":"A","price":"1.156630000","size":30,"channel_id":23,"order_id":"1775529191728497920","flags":128,"ts_in_delta":920,"sequence":164717,"symbol":"FCEU SI 20260615 PS"}
{"ts_recv":"2026-04-07T02:33:11.728567784Z","hd":{"ts_event":"2026-04-07T02:33:11.728549181Z","rtype":160,"publisher_id":101,"instrument_id":436},"action":"C","side":"B","price":"1.156540000","size":30,"channel_id":23,"order_id":"10998901228576984812","flags":0,"ts_in_delta":920,"sequence":164718,"symbol":"FCEU SI 20260615 PS"}
{"ts_recv":"2026-04-07T02:33:11.728567784Z","hd":{"ts_event":"2026-04-07T02:33:11.728549181Z","rtype":160,"publisher_id":101,"instrument_id":436},"action":"A","side":"B","price":"1.156530000","size":30,"channel_id":23,"order_id":"10998901228583330752","flags":0,"ts_in_delta":920,"sequence":164718,"symbol":"FCEU SI 20260615 PS"}
{"ts_recv":"2026-04-07T02:33:11.728567784Z","hd":{"ts_event":"2026-04-07T02:33:11.728549181Z","rtype":160,"publisher_id":101,"instrument_id":436},"action":"C","side":"A","price":"1.156640000","size":30,"channel_id":23,"order_id":"1775529191722209004","flags":0,"ts_in_delta":920,"sequence":164718,"symbol":"FCEU SI 20260615 PS"}
{"ts_recv":"2026-04-07T02:33:11.728567784Z","hd":{"ts_event":"2026-04-07T02:33:11.728549181Z","rtype":160,"publisher_id":101,"instrument_id":436},"action":"A","side":"A","price":"1.156630000","size":30,"channel_id":23,"order_id":"1775529191728554944","flags":128,"ts_in_delta":920,"sequence":164718,"symbol":"FCEU SI 20260615 PS"}
{"ts_recv":"2026-04-07T02:33:18.959832742Z","hd":{"ts_event":"2026-04-07T02:33:18.959809463Z","rtype":160,"publisher_id":101,"instrument_id":436},"action":"C","side":"B","price":"1.156530000","size":30,"channel_id":23,"order_id":"10998901228583330752","flags":0,"ts_in_delta":995,"sequence":164819,"symbol":"FCEU SI 20260615 PS"}
{"ts_recv":"2026-04-07T02:33:18.959832742Z","hd":{"ts_event":"2026-04-07T02:33:18.959809463Z","rtype":160,"publisher_id":101,"instrument_id":436},"action":"A","side":"B","price":"1.156520000","size":30,"channel_id":23,"order_id":"10998901235814591425","flags":0,"ts_in_delta":995,"sequence":164819,"symbol":"FCEU SI 20260615 PS"}
{"ts_recv":"2026-04-07T02:33:18.959832742Z","hd":{"ts_event":"2026-04-07T02:33:18.959809463Z","rtype":160,"publisher_id":101,"instrument_id":436},"action":"C","side":"A","price":"1.156630000","size":30,"channel_id":23,"order_id":"1775529191728554944","flags":0,"ts_in_delta":995,"sequence":164819,"symbol":"FCEU SI 20260615 PS"}
{"ts_recv":"2026-04-07T02:33:18.959832742Z","hd":{"ts_event":"2026-04-07T02:33:18.959809463Z","rtype":160,"publisher_id":101,"instrument_id":436},"action":"A","side":"A","price":"1.156620000","size":30,"channel_id":23,"order_id":"1775529198959815617","flags":128,"ts_in_delta":995,"sequence":164819,"symbol":"FCEU SI 20260615 PS"}
{"ts_recv":"2026-04-07T02:33:18.959920705Z","hd":{"ts_event":"2026-04-07T02:33:18.959899647Z","rtype":160,"publisher_id":101,"instrument_id":436},"action":"C","side":"B","price":"1.156520000","size":30,"channel_id":23,"order_id":"10998901235814591425","flags":0,"ts_in_delta":968,"sequence":164820,"symbol":"FCEU SI 20260615 PS"}
{"ts_recv":"2026-04-07T02:33:18.959920705Z","hd":{"ts_event":"2026-04-07T02:33:18.959899647Z","rtype":160,"publisher_id":101,"instrument_id":436},"action":"A","side":"B","price":"1.156510000","size":30,"channel_id":23,"order_id":"10998901235814681307","flags":0,"ts_in_delta":968,"sequence":164820,"symbol":"FCEU SI 20260615 PS"}
{"ts_recv":"2026-04-07T02:33:18.959920705Z","hd":{"ts_event":"2026-04-07T02:33:18.959899647Z","rtype":160,"publisher_id":101,"instrument_id":436},"action":"C","side":"A","price":"1.156620000","size":30,"channel_id":23,"order_id":"1775529198959815617","flags":0,"ts_in_delta":968,"sequence":164820,"symbol":"FCEU SI 20260615 PS"}
{"ts_recv":"2026-04-07T02:33:18.959920705Z","hd":{"ts_event":"2026-04-07T02:33:18.959899647Z","rtype":160,"publisher_id":101,"instrument_id":436},"action":"A","side":"A","price":"1.156610000","size":30,"channel_id":23,"order_id":"1775529198959905499","flags":128,"ts_in_delta":968,"sequence":164820,"symbol":"FCEU SI 20260615 PS"}
{"ts_recv":"2026-04-07T02:33:18.959977419Z","hd":{"ts_event":"2026-04-07T02:33:18.959959813Z","rtype":160,"publisher_id":101,"instrument_id":436},"action":"C","side":"B","price":"1.156510000","size":30,"channel_id":23,"order_id":"10998901235814681307","flags":0,"ts_in_delta":971,"sequence":164821,"symbol":"FCEU SI 20260615 PS"}