{"ts_recv":"2026-04-07T02:25:02.333188720Z","hd":{"ts_event":"2026-04-07T02:25:02.333167913Z","rtype":160,"publisher_id":101,"instrument_id":436},"action":"A","side":"A","price":"1.156550000","size":30,"channel_id":23,"order_id":"1775528702333173836","flags":128,"ts_in_delta":907,"sequence":160195,"symbol":"FCEU SI 20260615 PS"}
{"ts_recv":"2026-04-07T02:25:02.338099939Z","hd":{"ts_event":"2026-04-07T02:25:02.338082337Z","rtype":160,"publisher_id":101,"instrument_id":436},"action":"C","side":"B","price":"1.156450000","size":30,"channel_id":23,"order_id":"10998900739187949644","flags":0,"ts_in_delta":937,"sequence":160198,"symbol":"FCEU SI 20260615 PS"}
{"ts_recv":"2026-04-07T02:25:02.338099939Z","hd":{"ts_event":"2026-04-07T02:25:02.338082337Z","rtype":160,"publisher_id":101,"instrument_id":436},"action":"A","side":"B","price":"1.156460000","size":30,"channel_id":23,"order_id":"10998900739192864040","flags":0,"ts_in_delta":937,"sequence":160198,"symbol":"FCEU SI 20260615 PS"}
{"ts_recv":"2026-04-07T02:25:02.338099939Z","hd":{"ts_event":"2026-04-07T02:25:02.338082337Z","rtype":160,"publisher_id":101,"instrument_id":436},"action":"C","side":"A","price":"1.156550000","size":30,"channel_id":23,"order_id":"1775528702333173836","flags":0,"ts_in_delta":937,"sequence":160198,"symbol":"FCEU SI 20260615 PS"}
{"ts_recv":"2026-04-07T02:25:02.338099939Z","hd":{"ts_event":"2026-04-07T02:25:02.338082337Z","rtype":160,"publisher_id":101,"instrument_id":436},"action":"A","side":"A","price":"1.156560000","size":30,"channel_id":23,"order_id":"1775528702338088232","flags":128,"ts_in_delta":937,"sequence":160198,"symbol":"FCEU SI 20260615 PS"}
{"ts_recv":"2026-04-07T02:25:08.030710321Z","hd":{"ts_event":"2026-04-07T02:25:08.030676405Z","rtype":160,"publisher_id":101,"instrument_id":436},"action":"C","side":"B","price":"1.156460000","size":30,"channel_id":23,"order_id":"10998900739192864040","flags":0,"ts_in_delta":1153,"sequence":160241,"symbol":"FCEU SI 20260615 PS"}
{"ts_recv":"2026-04-07T02:25:08.030710321Z","hd":{"ts_event":"2026-04-07T02:25:08.030676405Z","rtype":160,"publisher_id":101,"instrument_id":436},"action":"A","side":"B","price":"1.156450000","size":30,"channel_id":23,"order_id":"10998900744885466198","flags":0,"ts_in_delta":1153,"sequence":160241,"symbol":"FCEU SI 20260615 PS"}
{"ts_recv":"2026-04-07T02:25:08.030710321Z","hd":{"ts_event":"2026-04-07T02:25:08.030676405Z","rtype":160,"publisher_id":101,"instrument_id":436},"action":"C","side":"A","price":"1.156560000","size":30,"channel_id":23,"order_id":"1775528702338088232","flags":0,"ts_in_delta":1153,"sequence":160241,"symbol":"FCEU SI 20260615 PS"}
{"ts_recv":"2026-04-07T02:25:08.030710321Z","hd":{"ts_event":"2026-04-07T02:25:08.030676405Z","rtype":160,"publisher_id":101,"instrument_id":436},"action":"A","side":"A","price":"1.156550000","size":30,"channel_id":23,"order_id":"1775528708030690390","flags":128,"ts_in_delta":1153,"sequence":160241,"symbol":"FCEU SI 20260615 PS"}
{"ts_recv":"2026-04-07T02:25:08.032542600Z","hd":{"ts_event":"2026-04-07T02:25:08.032521485Z","rtype":160,"publisher_id":101,"instrument_id":436},"action":"C","side":"B","price":"1.156460000","size":30,"channel_id":23,"order_id":"10998900739185811856","flags":0,"ts_in_delta":925,"sequence":160243,"symbol":"FCEU SI 20260615 PS"}
{"ts_recv":"2026-04-07T02:25:08.032542600Z","hd":{"ts_event":"2026-04-07T02:25:08.032521485Z","rtype":160,"publisher_id":101,"instrument_id":436},"action":"A","side":"B","price":"1.156440000","size":30,"channel_id":23,"order_id":"10998900744887303342","flags":0,"ts_in_delta":925,"sequence":160243,"symbol":"FCEU SI 20260615 PS"}
{"ts_recv":"2026-04-07T02:25:08.032542600Z","hd":{"ts_event":"2026-04-07T02:25:08.032521485Z","rtype":160,"publisher_id":101,"instrument_id":436},"action":"C","side":"A","price":"1.156560000","size":30,"channel_id":23,"order_id":"1775528702331036048","flags":0,"ts_in_delta":925,"sequence":160243,"symbol":"FCEU SI 20260615 PS"}
{"ts_recv":"2026-04-07T02:25:08.032542600Z","hd":{"ts_event":"2026-04-07T02:25:08.032521485Z","rtype":160,"publisher_id":101,"instrument_id":436},"action":"A","side":"A","price":"1.156540000","size":30,"channel_id":23,"order_id":"1775528708032527534","flags":128,"ts_in_delta":925,"sequence":160243,"symbol":"FCEU SI 20260615 PS"}
{"ts_recv":"2026-04-07T02:25:08.032608645Z","hd":{"ts_event":"2026-04-07T02:25:08.032592853Z","rtype":160,"publisher_id":101,"instrument_id":436},"action":"C","side":"B","price":"1.156450000","size":30,"channel_id":23,"order_id":"10998900744885466198","flags":0,"ts_in_delta":885,"sequence":160244,"symbol":"FCEU SI 20260615 PS"}
{"ts_recv":"2026-04-07T02:25:08.032608645Z","hd":{"ts_event":"2026-04-07T02:25:08.032592853Z","rtype":160,"publisher_id":101,"instrument_id":436},"action":"A","side":"B","price":"1.156440000","size":30,"channel_id":23,"order_id":"10998900744887374724","flags":0,"ts_in_delta":885,"sequence":160244,"symbol":"FCEU SI 20260615 PS"}
{"ts_recv":"2026-04-07T02:25:08.032608645Z","hd":{"ts_event":"2026-04-07T02:25:08.032592853Z","rtype":160,"publisher_id":101,"instrument_id":436},"action":"C","side":"A","price":"1.156550000","size":30,"channel_id":23,"order_id":"1775528708030690390","flags":0,"ts_in_delta":885,"sequence":160244,"symbol":"FCEU SI 20260615 PS"}
{"ts_recv":"2026-04-07T02:25:08.032608645Z","hd":{"ts_event":"2026-04-07T02:25:08.032592853Z","rtype":160,"publisher_id":101,"instrument_id":436},"action":"A","side":"A","price":"1.156540000","size":30,"channel_id":23,"order_id":"1775528708032598916","flags":128,"ts_in_delta":885,"sequence":160244,"symbol":"FCEU SI 20260615 PS"}
{"ts_recv":"2026-04-07T02:25:12.336500940Z","hd":{"ts_event":"2026-04-07T02:25:12.336480401Z","rtype":160,"publisher_id":101,"instrument_id":436},"action":"C","side":"B","price":"1.156440000","size":30,"channel_id":23,"order_id":"10998900744887374724","flags":0,"ts_in_delta":1071,"sequence":160295,"symbol":"FCEU SI 20260615 PS"}
{"ts_recv":"2026-04-07T02:25:12.336500940Z","hd":{"ts_event":"2026-04-07T02:25:12.336480401Z","rtype":160,"publisher_id":101,"instrument_id":436},"action":"A","side":"B","price":"1.156450000","size":30,"channel_id":23,"order_id":"10998900749191262520","flags":0,"ts_in_delta":1071,"sequence":160295,"symbol":"FCEU SI 20260615 PS"}
{"ts_recv":"2026-04-07T02:25:12.336500940Z","hd":{"ts_event":"2026-04-07T02:25:12.336480401Z","rtype":160,"publisher_id":101,"instrument_id":436},"action":"C","side":"A","price":"1.156540000","size":30,"channel_id":23,"order_id":"1775528708032598916","flags":0,"ts_in_delta":1071,"sequence":160295,"symbol":"FCEU SI 20260615 PS"}
{"ts_recv":"2026-04-07T02:25:12.336500940Z","hd":{"ts_event":"2026-04-07T02:25:12.336480401Z","rtype":160,"publisher_id":101,"instrument_id":436},"action":"A","side":"A","price":"1.156550000","size":30,"channel_id":23,"order_id":"1775528712336486712","flags":128,"ts_in_delta":1071,"sequence":160295,"symbol":"FCEU SI 20260615 PS"}
{"ts_recv":"2026-04-07T02:25:12.407899325Z","hd":{"ts_event":"2026-04-07T02:25:12.407878125Z","rtype":160,"publisher_id":101,"instrument_id":436},"action":"C","side":"B","price":"1.156440000","size":30,"channel_id":23,"order_id":"10998900744887303342","flags":0,"ts_in_delta":1000,"sequence":160297,"symbol":"FCEU SI 20260615 PS"}
{"ts_recv":"2026-04-07T02:25:12.407899325Z","hd":{"ts_event":"2026-04-07T02:25:12.407878125Z","rtype":160,"publisher_id":101,"instrument_id":436},"action":"A","side":"B","price":"1.156460000","size":30,"channel_id":23,"order_id":"10998900749262660178","flags":0,"ts_in_delta":1000,"sequence":160297,"symbol":"FCEU SI 20260615 PS"}
{"ts_recv":"2026-04-07T02:25:12.407899325Z","hd":{"ts_event":"2026-04-07T02:25:12.407878125Z","rtype":160,"publisher_id":101,"instrument_id":436},"action":"C","side":"A","price":"1.156540000","size":30,"channel_id":23,"order_id":"1775528708032527534","flags":0,"ts_in_delta":1000,"sequence":160297,"symbol":"FCEU SI 20260615 PS"}
{"ts_recv":"2026-04-07T02:25:12.407899325Z","hd":{"ts_event":"2026-04-07T02:25:12.407878125Z","rtype":160,"publisher_id":101,"instrument_id":436},"action":"A","side":"A","price":"1.156560000","size":30,"channel_id":23,"order_id":"1775528712407884370","flags":128,"ts_in_delta":1000,"sequence":160297,"symbol":"FCEU SI 20260615 PS"}
{"ts_recv":"2026-04-07T02:25:12.407963066Z","hd":{"ts_event":"2026-04-07T02:25:12.407945671Z","rtype":160,"publisher_id":101,"instrument_id":436},"action":"C","side":"B","price":"1.156450000","size":30,"channel_id":23,"order_id":"10998900749191262520","flags":0,"ts_in_delta":1074,"sequence":160298,"symbol":"FCEU SI 20260615 PS"}
{"ts_recv":"2026-04-07T02:25:12.407963066Z","hd":{"ts_event":"2026-04-07T02:25:12.407945671Z","rtype":160,"publisher_id":101,"instrument_id":436},"action":"A","side":"B","price":"1.156460000","size":30,"channel_id":23,"order_id":"10998900749262727223","flags":0,"ts_in_delta":1074,"sequence":160298,"symbol":"FCEU SI 20260615 PS"}
{"ts_recv":"2026-04-07T02:25:12.407963066Z","hd":{"ts_event":"2026-04-07T02:25:12.407945671Z","rtype":160,"publisher_id":101,"instrument_id":436},"action":"C","side":"A","price":"1.156550000","size":30,"channel_id":23,"order_id":"1775528712336486712","flags":0,"ts_in_delta":1074,"sequence":160298,"symbol":"FCEU SI 20260615 PS"}
{"ts_recv":"2026-04-07T02:25:12.407963066Z","hd":{"ts_event":"2026-04-07T02:25:12.407945671Z","rtype":160,"publisher_id":101,"instrument_id":436},"action":"A","side":"A","price":"1.156560000","size":30,"channel_id":23,"order_id":"1775528712407951415","flags":128,"ts_in_delta":1074,"sequence":160298,"symbol":"FCEU SI 20260615 PS"}
{"ts_recv":"2026-04-07T02:25:14.315492507Z","hd":{"ts_event":"2026-04-07T02:25:14.315471987Z","rtype":160,"publisher_id":101,"instrument_id":436},"action":"C","side":"B","price":"1.156460000","size":30,"channel_id":23,"order_id":"10998900749262727223","flags":0,"ts_in_delta":911,"sequence":160335,"symbol":"FCEU SI 20260615 PS"}
{"ts_recv":"2026-04-07T02:25:14.315492507Z","hd":{"ts_event":"2026-04-07T02:25:14.315471987Z","rtype":160,"publisher_id":101,"instrument_id":436},"action":"A","side":"B","price":"1.156470000","size":30,"channel_id":23,"order_id":"10998900751170253621","flags":0,"ts_in_delta":911,"sequence":160335,"symbol":"FCEU SI 20260615 PS"}
{"ts_recv":"2026-04-07T02:25:14.315492507Z","hd":{"ts_event":"2026-04-07T02:25:14.315471987Z","rtype":160,"publisher_id":101,"instrument_id":436},"action":"C","side":"A","price":"1.156560000","size":30,"channel_id":23,"order_id":"1775528712407951415","flags":0,"ts_in_delta":911,"sequence":160335,"symbol":"FCEU SI 20260615 PS"}
{"ts_recv":"2026-04-07T02:25:14.315492507Z","hd":{"ts_event":"2026-04-07T02:25:14.315471987Z","rtype":160,"publisher_id":101,"instrument_id":436},"action":"A","side":"A","price":"1.156570000","size":30,"channel_id":23,"order_id":"1775528714315477813","flags":128,"ts_in_delta":911,"sequence":160335,"symbol":"FCEU SI 20260615 PS"}
{"ts_recv":"2026-04-07T02:25:14.324557886Z","hd":{"ts_event":"2026-04-07T02:25:14.324542287Z","rtype":160,"publisher_id":101,"instrument_id":436},"action":"C","side":"B","price":"1.156470000","size":30,"channel_id":23,"order_id":"10998900751170253621","flags":0,"ts_in_delta":902,"sequence":160340,"symbol":"FCEU SI 20260615 PS"}
{"ts_recv":"2026-04-07T02:25:14.324557886Z","hd":{"ts_event":"2026-04-07T02:25:14.324542287Z","rtype":160,"publisher_id":101,"instrument_id":436},"action":"A","side":"B","price":"1.156460000","size":30,"channel_id":23,"order_id":"10998900751179323786","flags":0,"ts_in_delta":902,"sequence":160340,"symbol":"FCEU SI 20260615 PS"}
{"ts_recv":"2026-04-07T02:25:14.324557886Z","hd":{"ts_event":"2026-04-07T02:25:14.324542287Z","rtype":160,"publisher_id":101,"instrument_id":436},"action":"C","side":"A","price":"1.156570000","size":30,"channel_id":23,"order_id":"1775528714315477813","flags":0,"ts_in_delta":902,"sequence":160340,"symbol":"FCEU SI 20260615 PS"}
{"ts_recv":"2026-04-07T02:25:14.324557886Z","hd":{"ts_event":"2026-04-07T02:25:14.324542287Z","rtype":160,"publisher_id":101,"instrument_id":436},"action":"A","side":"A","price":"1.156560000","size":30,"channel_id":23,"order_id":"1775528714324547978","flags":128,"ts_in_delta":902,"sequence":160340,"symbol":"FCEU SI 20260615 PS"}
{"ts_recv":"2026-04-07T02:25:14.385277293Z","hd":{"ts_event":"2026-04-07T02:25:14.385256483Z","rtype":160,"publisher_id":101,"instrument_id":436},"action":"C","side":"B","price":"1.156460000","size":30,"channel_id":23,"order_id":"10998900751179323786","flags":0,"ts_in_delta":1026,"sequence":160362,"symbol":"FCEU SI 20260615 PS"}
{"ts_recv":"2026-04-07T02:25:14.385277293Z","hd":{"ts_event":"2026-04-07T02:25:14.385256483Z","rtype":160,"publisher_id":101,"instrument_id":436},"action":"A","side":"B","price":"1.156470000","size":30,"channel_id":23,"order_id":"10998900751240038358","flags":0,"ts_in_delta":1026,"sequence":160362,"symbol":"FCEU SI 20260615 PS"}
{"ts_recv":"2026-04-07T02:25:14.385277293Z","hd":{"ts_event":"2026-04-07T02:25:14.385256483Z","rtype":160,"publisher_id":101,"instrument_id":436},"action":"C","side":"A","price":"1.156560000","size":30,"channel_id":23,"order_id":"1775528714324547978","flags":0,"ts_in_delta":1026,"sequence":160362,"symbol":"FCEU SI 20260615 PS"}
{"ts_recv":"2026-04-07T02:25:14.385277293Z","hd":{"ts_event":"2026-04-07T02:25:14.385256483Z","rtype":160,"publisher_id":101,"instrument_id":436},"action":"A","side":"A","price":"1.156570000","size":30,"channel_id":23,"order_id":"1775528714385262550","flags":128,"ts_in_delta":1026,"sequence":160362,"symbol":"FCEU SI 20260615 PS"}
{"ts_recv":"2026-04-07T02:25:14.394052127Z","hd":{"ts_event":"2026-04-07T02:25:14.394033387Z","rtype":160,"publisher_id":101,"instrument_id":436},"action":"C","side":"B","price":"1.156460000","size":30,"channel_id":23,"order_id":"10998900749262660178","flags":0,"ts_in_delta":1194,"sequence":160366,"symbol":"FCEU SI 20260615 PS"}
{"ts_recv":"2026-04-07T02:25:14.394052127Z","hd":{"ts_event":"2026-04-07T02:25:14.394033387Z","rtype":160,"publisher_id":101,"instrument_id":436},"action":"A","side":"B","price":"1.156480000","size":30,"channel_id":23,"order_id":"10998900751248815320","flags":0,"ts_in_delta":1194,"sequence":160366,"symbol":"FCEU SI 20260615 PS"}
{"ts_recv":"2026-04-07T02:25:14.394052127Z","hd":{"ts_event":"2026-04-07T02:25:14.394033387Z","rtype":160,"publisher_id":101,"instrument_id":436},"action":"C","side":"A","price":"1.156560000","size":30,"channel_id":23,"order_id":"1775528712407884370","flags":0,"ts_in_delta":1194,"sequence":160366,"symbol":"FCEU SI 20260615 PS"}
{"ts_recv":"2026-04-07T02:25:14.394052127Z","hd":{"ts_event":"2026-04-07T02:25:14.394033387Z","rtype":160,"publisher_id":101,"instrument_id":436},"action":"A","side":"A","price":"1.156580000","size":30,"channel_id":23,"order_id":"1775528714394039512","flags":128,"ts_in_delta":1194,"sequence":160366,"symbol":"FCEU SI 20260615 PS"}
{"ts_recv":"2026-04-07T02:25:14.394107981Z","hd":{"ts_event":"2026-04-07T02:25:14.394089707Z","rtype":160,"publisher_id":101,"instrument_id":436},"action":"C","side":"B","price":"1.156470000","size":30,"channel_id":23,"order_id":"10998900751240038358","flags":0,"ts_in_delta":924,"sequence":160367,"symbol":"FCEU SI 20260615 PS"}
{"ts_recv":"2026-04-07T02:25:14.394107981Z","hd":{"ts_event":"2026-04-07T02:25:14.394089707Z","rtype":160,"publisher_id":101,"instrument_id":436},"action":"A","side":"B","price":"1.156480000","size":30,"channel_id":23,"order_id":"10998900751248871486","flags":0,"ts_in_delta":924,"sequence":160367,"symbol":"FCEU SI 20260615 PS"}
{"ts_recv":"2026-04-07T02:25:14.394107981Z","hd":{"ts_event":"2026-04-07T02:25:14.394089707Z","rtype":160,"publisher_id":101,"instrument_id":436},"action":"C","side":"A","price":"1.156570000","size":30,"channel_id":23,"order_id":"1775528714385262550","flags":0,"ts_in_delta":924,"sequence":160367,"symbol":"FCEU SI 20260615 PS"}
{"ts_recv":"2026-04-07T02:25:14.394107981Z","hd":{"ts_event":"2026-04-07T02:25:14.394089707Z","rtype":160,"publisher_id":101,"instrument_id":436},"action":"A","side":"A","price":"1.156580000","size":30,"channel_id":23,"order_id":"1775528714394095678","flags":128,"ts_in_delta":924,"sequence":160367,"symbol":"FCEU SI 20260615 PS"}
{"ts_recv":"2026-04-07T02:25:31.258900286Z","hd":{"ts_event":"2026-04-07T02:25:31.258876499Z","rtype":160,"publisher_id":101,"instrument_id":436},"action":"C","side":"B","price":"1.156480000","size":30,"channel_id":23,"order_id":"10998900751248871486","flags":0,"ts_in_delta":972,"sequence":160532,"symbol":"FCEU SI 20260615 PS"}
{"ts_recv":"2026-04-07T02:25:31.258900286Z","hd":{"ts_event":"2026-04-07T02:25:31.258876499Z","rtype":160,"publisher_id":101,"instrument_id":436},"action":"A","side":"B","price":"1.156470000","size":30,"channel_id":23,"order_id":"10998900768113658293","flags":0,"ts_in_delta":972,"sequence":160532,"symbol":"FCEU SI 20260615 PS"}
{"ts_recv":"2026-04-07T02:25:31.258900286Z","hd":{"ts_event":"2026-04-07T02:25:31.258876499Z","rtype":160,"publisher_id":101,"instrument_id":436},"action":"C","side":"A","price":"1.156580000","size":30,"channel_id":23,"order_id":"1775528714394095678","flags":0,"ts_in_delta":972,"sequence":160532,"symbol":"FCEU SI 20260615 PS"}
{"ts_recv":"2026-04-07T02:25:31.258900286Z","hd":{"ts_event":"2026-04-07T02:25:31.258876499Z","rtype":160,"publisher_id":101,"instrument_id":436},"action":"A","side":"A","price":"1.156570000","size":30,"channel_id":23,"order_id":"1775528731258882485","flags":128,"ts_in_delta":972,"sequence":160532,"symbol":"FCEU SI 20260615 PS"}
{"ts_recv":"2026-04-07T02:25:31.258963067Z","hd":{"ts_event":"2026-04-07T02:25:31.258940333Z","rtype":160,"publisher_id":101,"instrument_id":436},"action":"C","side":"B","price":"1.156480000","size":30,"channel_id":23,"order_id":"10998900751248815320","flags":0,"ts_in_delta":1073,"sequence":160533,"symbol":"FCEU SI 20260615 PS"}
{"ts_recv":"2026-04-07T02:25:31.258963067Z","hd":{"ts_event":"2026-04-07T02:25:31.258940333Z","rtype":160,"publisher_id":101,"instrument_id":436},"action":"A","side":"B","price":"1.156460000","size":30,"channel_id":23,"order_id":"10998900768113722597","flags":0,"ts_in_delta":1073,"sequence":160533,"symbol":"FCEU SI 20260615 PS"}
{"ts_recv":"2026-04-07T02:25:31.258963067Z","hd":{"ts_event":"2026-04-07T02:25:31.258940333Z","rtype":160,"publisher_id":101,"instrument_id":436},"action":"C","side":"A","price":"1.156580000","size":30,"channel_id":23,"order_id":"1775528714394039512","flags":0,"ts_in_delta":1073,"sequence":160533,"symbol":"FCEU SI 20260615 PS"}
{"ts_recv":"2026-04-07T02:25:31.258963067Z","hd":{"ts_event":"2026-04-07T02:25:31.258940333Z","rtype":160,"publisher_id":101,"instrument_id":436},"action":"A","side":"A","price":"1.156560000","size":30,"channel_id":23,"order_id":"1775528731258946789","flags":128,"ts_in_delta":1073,"sequence":160533,"symbol":"FCEU SI 20260615 PS"}
{"ts_recv":"2026-04-07T02:25:31.258985553Z","hd":{"ts_event":"2026-04-07T02:25:31.258965357Z","rtype":160,"publisher_id":101,"instrument_id":436},"action":"C","side":"B","price":"1.156470000","size":30,"channel_id":23,"order_id":"10998900768113658293","flags":0,"ts_in_delta":1110,"sequence":160534,"symbol":"FCEU SI 20260615 PS"}
{"ts_recv":"2026-04-07T02:25:31.258985553Z","hd":{"ts_event":"2026-04-07T02:25:31.258965357Z","rtype":160,"publisher_id":101,"instrument_id":436},"action":"A","side":"B","price":"1.156460000","size":30,"channel_id":23,"order_id":"10998900768113747880","flags":0,"ts_in_delta":1110,"sequence":160534,"symbol":"FCEU SI 20260615 PS"}
{"ts_recv":"2026-04-07T02:25:31.258985553Z","hd":{"ts_event":"2026-04-07T02:25:31.258965357Z","rtype":160,"publisher_id":101,"instrument_id":436},"action":"C","side":"A","price":"1.156570000","size":30,"channel_id":23,"order_id":"1775528731258882485","flags":0,"ts_in_delta":1110,"sequence":160534,"symbol":"FCEU SI 20260615 PS"}
{"ts_recv":"2026-04-07T02:25:31.258985553Z","hd":{"ts_event":"2026-04-07T02:25:31.258965357Z","rtype":160,"publisher_id":101,"instrument_id":436},"action":"A","side":"A","price":"1.156560000","size":30,"channel_id":23,"order_id":"1775528731258972072","flags":128,"ts_in_delta":1110,"sequence":160534,"symbol":"FCEU SI 20260615 PS"}
{"ts_recv":"2026-04-07T02:25:31.270578175Z","hd":{"ts_event":"2026-04-07T02:25:31.270558275Z","rtype":160,"publisher_id":101,"instrument_id":436},"action":"C","side":"B","price":"1.156460000","size":30,"channel_id":23,"order_id":"10998900768113747880","flags":0,"ts_in_delta":935,"sequence":160549,"symbol":"FCEU SI 20260615 PS"}
{"ts_recv":"2026-04-07T02:25:31.270578175Z","hd":{"ts_event":"2026-04-07T02:25:31.270558275Z","rtype":160,"publisher_id":101,"instrument_id":436},"action":"A","side":"B","price":"1.156450000","size":30,"channel_id":23,"order_id":"10998900768125339990","flags":0,"ts_in_delta":935,"sequence":160549,"symbol":"FCEU SI 20260615 PS"}
{"ts_recv":"2026-04-07T02:25:31.270578175Z","hd":{"ts_event":"2026-04-07T02:25:31.270558275Z","rtype":160,"publisher_id":101,"instrument_id":436},"action":"C","side":"A","price":"1.156560000","size":30,"channel_id":23,"order_id":"1775528731258972072","flags":0,"ts_in_delta":935,"sequence":160549,"symbol":"FCEU SI 20260615 PS"}
{"ts_recv":"2026-04-07T02:25:31.270578175Z","hd":{"ts_event":"2026-04-07T02:25:31.270558275Z","rtype":160,"publisher_id":101,"instrument_id":436},"action":"A","side":"A","price":"1.156550000","size":30,"channel_id":23,"order_id":"1775528731270564182","flags":128,"ts_in_delta":935,"sequence":160549,"symbol":"FCEU SI 20260615 PS"}
{"ts_recv":"2026-04-07T02:25:31.270640979Z","hd":{"ts_event":"2026-04-07T02:25:31.270621053Z","rtype":160,"publisher_id":101,"instrument_id":436},"action":"C","side":"B","price":"1.156450000","size":30,"channel_id":23,"order_id":"10998900768125339990","flags":0,"ts_in_delta":944,"sequence":160550,"symbol":"FCEU SI 20260615 PS"}
{"ts_recv":"2026-04-07T02:25:31.270640979Z","hd":{"ts_event":"2026-04-07T02:25:31.270621053Z","rtype":160,"publisher_id":101,"instrument_id":436},"action":"A","side":"B","price":"1.156440000","size":30,"channel_id":23,"order_id":"10998900768125403619","flags":0,"ts_in_delta":944,"sequence":160550,"symbol":"FCEU SI 20260615 PS"}
{"ts_recv":"2026-04-07T02:25:31.270640979Z","hd":{"ts_event":"2026-04-07T02:25:31.270621053Z","rtype":160,"publisher_id":101,"instrument_id":436},"action":"C","side":"A","price":"1.156550000","size":30,"channel_id":23,"order_id":"1775528731270564182","flags":0,"ts_in_delta":944,"sequence":160550,"symbol":"FCEU SI 20260615 PS"}
{"ts_recv":"2026-04-07T02:25:31.270640979Z","hd":{"ts_event":"2026-04-07T02:25:31.270621053Z","rtype":160,"publisher_id":101,"instrument_id":436},"action":"A","side":"A","price":"1.156540000","size":30,"channel_id":23,"order_id":"1775528731270627811","flags":128,"ts_in_delta":944,"sequence":160550,"symbol":"FCEU SI 20260615 PS"}
{"ts_recv":"2026-04-07T02:25:31.270690397Z","hd":{"ts_event":"2026-04-07T02:25:31.270672683Z","rtype":160,"publisher_id":101,"instrument_id":436},"action":"C","side":"B","price":"1.156460000","size":30,"channel_id":23,"order_id":"10998900768113722597","flags":0,"ts_in_delta":931,"sequence":160551,"symbol":"FCEU SI 20260615 PS"}
{"ts_recv":"2026-04-07T02:25:31.270690397Z","hd":{"ts_event":"2026-04-07T02:25:31.270672683Z","rtype":160,"publisher_id":101,"instrument_id":436},"action":"A","side":"B","price":"1.156440000","size":30,"channel_id":23,"order_id":"10998900768125454393","flags":0,"ts_in_delta":931,"sequence":160551,"symbol":"FCEU SI 20260615 PS"}
{"ts_recv":"2026-04-07T02:25:31.270690397Z","hd":{"ts_event":"2026-04-07T02:25:31.270672683Z","rtype":160,"publisher_id":101,"instrument_id":436},"action":"C","side":"A","price":"1.156560000","size":30,"channel_id":23,"order_id":"1775528731258946789","flags":0,"ts_in_delta":931,"sequence":160551,"symbol":"FCEU SI 20260615 PS"}
{"ts_recv":"2026-04-07T02:25:31.270690397Z","hd":{"ts_event":"2026-04-07T02:25:31.270672683Z","rtype":160,"publisher_id":101,"instrument_id":436},"action":"A","side":"A","price":"1.156540000","size":30,"channel_id":23,"order_id":"1775528731270678585","flags":128,"ts_in_delta":931,"sequence":160551,"symbol":"FCEU SI 20260615 PS"}
{"ts_recv":"2026-04-07T02:25:31.270700112Z","hd":{"ts_event":"2026-04-07T02:25:31.270678929Z","rtype":160,"publisher_id":101,"instrument_id":436},"action":"C","side":"B","price":"1.156440000","size":30,"channel_id":23,"order_id":"10998900768125403619","flags":0,"ts_in_delta":946,"sequence":160552,"symbol":"FCEU SI 20260615 PS"}
{"ts_recv":"2026-04-07T02:25:31.270700112Z","hd":{"ts_event":"2026-04-07T02:25:31.270678929Z","rtype":160,"publisher_id":101,"instrument_id":436},"action":"A","side":"B","price":"1.156450000","size":30,"channel_id":23,"order_id":"10998900768125462847","flags":0,"ts_in_delta":946,"sequence":160552,"symbol":"FCEU SI 20260615 PS"}
{"ts_recv":"2026-04-07T02:25:31.270700112Z","hd":{"ts_event":"2026-04-07T02:25:31.270678929Z","rtype":160,"publisher_id":101,"instrument_id":436},"action":"C","side":"A","price":"1.156540000","size":30,"channel_id":23,"order_id":"1775528731270627811","flags":0,"ts_in_delta":946,"sequence":160552,"symbol":"FCEU SI 20260615 PS"}
{"ts_recv":"2026-04-07T02:25:31.270700112Z","hd":{"ts_event":"2026-04-07T02:25:31.270678929Z","rtype":160,"publisher_id":101,"instrument_id":436},"action":"A","side":"A","price":"1.156550000","size":30,"channel_id":23,"order_id":"1775528731270687039","flags":128,"ts_in_delta":946,"sequence":160552,"symbol":"FCEU SI 20260615 PS"}
{"ts_recv":"2026-04-07T02:25:31.270756135Z","hd":{"ts_event":"2026-04-07T02:25:31.270736715Z","rtype":160,"publisher_id":101,"instrument_id":436},"action":"C","side":"B","price":"1.156450000","size":30,"channel_id":23,"order_id":"10998900768125462847","flags":0,"ts_in_delta":959,"sequence":160553,"symbol":"FCEU SI 20260615 PS"}
{"ts_recv":"2026-04-07T02:25:31.270756135Z","hd":{"ts_event":"2026-04-07T02:25:31.270736715Z","rtype":160,"publisher_id":101,"instrument_id":436},"action":"A","side":"B","price":"1.156440000","size":30,"channel_id":23,"order_id":"10998900768125518506","flags":0,"ts_in_delta":959,"sequence":160553,"symbol":"FCEU SI 20260615 PS"}
{"ts_recv":"2026-04-07T02:25:31.270756135Z","hd":{"ts_event":"2026-04-07T02:25:31.270736715Z","rtype":160,"publisher_id":101,"instrument_id":436},"action":"C","side":"A","price":"1.156550000","size":30,"channel_id":23,"order_id":"1775528731270687039","flags":0,"ts_in_delta":959,"sequence":160553,"symbol":"FCEU SI 20260615 PS"}
{"ts_recv":"2026-04-07T02:25:31.270756135Z","hd":{"ts_event":"2026-04-07T02:25:31.270736715Z","rtype":160,"publisher_id":101,"instrument_id":436},"action":"A","side":"A","price":"1.156540000","size":30,"channel_id":23,"order_id":"1775528731270742698","flags":128,"ts_in_delta":959,"sequence":160553,"symbol":"FCEU SI 20260615 PS"}
{"ts_recv":"2026-04-07T02:25:42.669855514Z","hd":{"ts_event":"2026-04-07T02:25:42.669833307Z","rtype":160,"publisher_id":101,"instrument_id":436},"action":"C","side":"B","price":"1.156440000","size":30,"channel_id":23,"order_id":"10998900768125518506","flags":0,"ts_in_delta":1005,"sequence":160635,"symbol":"FCEU SI 20260615 PS"}
{"ts_recv":"2026-04-07T02:25:42.669855514Z","hd":{"ts_event":"2026-04-07T02:25:42.669833307Z","rtype":160,"publisher_id":101,"instrument_id":436},"action":"A","side":"B","price":"1.156450000","size":30,"channel_id":23,"order_id":"10998900779524615526","flags":0,"ts_in_delta":1005,"sequence":160635,"symbol":"FCEU SI 20260615 PS"}
{"ts_recv":"2026-04-07T02:25:42.669855514Z","hd":{"ts_event":"2026-04-07T02:25:42.669833307Z","rtype":160,"publisher_id":101,"instrument_id":436},"action":"C","side":"A","price":"1.156540000","size":30,"channel_id":23,"order_id":"1775528731270742698","flags":0,"ts_in_delta":1005,"sequence":160635,"symbol":"FCEU SI 20260615 PS"}
{"ts_recv":"2026-04-07T02:25:42.669855514Z","hd":{"ts_event":"2026-04-07T02:25:42.669833307Z","rtype":160,"publisher_id":101,"instrument_id":436},"action":"A","side":"A","price":"1.156550000","size":30,"channel_id":23,"order_id":"1775528742669839718","flags":128,"ts_in_delta":1005,"sequence":160635,"symbol":"FCEU SI 20260615 PS"}
{"ts_recv":"2026-04-07T02:25:42.669918602Z","hd":{"ts_event":"2026-04-07T02:25:42.669898935Z","rtype":160,"publisher_id":101,"instrument_id":436},"action":"C","side":"B","price":"1.156440000","size":30,"channel_id":23,"order_id":"10998900768125454393","flags":0,"ts_in_delta":1005,"sequence":160636,"symbol":"FCEU SI 20260615 PS"}
{"ts_recv":"2026-04-07T02:25:42.669918602Z","hd":{"ts_event":"2026-04-07T02:25:42.669898935Z","rtype":160,"publisher_id":101,"instrument_id":436},"action":"A","side":"B","price":"1.156460000","size":30,"channel_id":23,"order_id":"10998900779524681140","flags":0,"ts_in_delta":1005,"sequence":160636,"symbol":"FCEU SI 20260615 PS"}
{"ts_recv":"2026-04-07T02:25:42.669918602Z","hd":{"ts_event":"2026-04-07T02:25:42.669898935Z","rtype":160,"publisher_id":101,"instrument_id":436},"action":"C","side":"A","price":"1.156540000","size":30,"channel_id":23,"order_id":"1775528731270678585","flags":0,"ts_in_delta":1005,"sequence":160636,"symbol":"FCEU SI 20260615 PS"}
{"ts_recv":"2026-04-07T02:25:42.669918602Z","hd":{"ts_event":"2026-04-07T02:25:42.669898935Z","rtype":160,"publisher_id":101,"instrument_id":436},"action":"A","side":"A","price":"1.156560000","size":30,"channel_id":23,"order_id":"1775528742669905332","flags":128,"ts_in_delta":1005,"sequence":160636,"symbol":"FCEU SI 20260615 PS"}
{"ts_recv":"2026-04-07T02:25:42.669983587Z","hd":{"ts_event":"2026-04-07T02:25:42.669964061Z","rtype":160,"publisher_id":101,"instrument_id":436},"action":"C","side":"B","price":"1.156450000","size":30,"channel_id":23,"order_id":"10998900779524615526","flags":0,"ts_in_delta":1016,"sequence":160637,"symbol":"FCEU SI 20260615 PS"}
{"ts_recv":"2026-04-07T02:25:42.669983587Z","hd":{"ts_event":"2026-04-07T02:25:42.669964061Z","rtype":160,"publisher_id":101,"instrument_id":436},"action":"A","side":"B","price":"1.156460000","size":30,"channel_id":23,"order_id":"10998900779524746184","flags":0,"ts_in_delta":1016,"sequence":160637,"symbol":"FCEU SI 20260615 PS"}
{"ts_recv":"2026-04-07T02:25:42.669983587Z","hd":{"ts_event":"2026-04-07T02:25:42.669964061Z","rtype":160,"publisher_id":101,"instrument_id":436},"action":"C","side":"A","price":"1.156550000","size":30,"channel_id":23,"order_id":"1775528742669839718","flags":0,"ts_in_delta":1016,"sequence":160637,"symbol":"FCEU SI 20260615 PS"}
{"ts_recv":"2026-04-07T02:25:42.669983587Z","hd":{"ts_event":"2026-04-07T02:25:42.669964061Z","rtype":160,"publisher_id":101,"instrument_id":436},"action":"A","side":"A","price":"1.156560000","size":30,"channel_id":23,"order_id":"1775528742669970376","flags":128,"ts_in_delta":1016,"sequence":160637,"symbol":"FCEU SI 20260615 PS"}
{"ts_recv":"2026-04-07T02:25:42.674504328Z","hd":{"ts_event":"2026-04-07T02:25:42.674482961Z","rtype":160,"publisher_id":101,"instrument_id":436},"action":"C","side":"B","price":"1.156460000","size":30,"channel_id":23,"order_id":"10998900779524746184","flags":0,"ts_in_delta":1010,"sequence":160642,"symbol":"FCEU SI 20260615 PS"}
{"ts_recv":"2026-04-07T02:25:42.674504328Z","hd":{"ts_event":"2026-04-07T02:25:42.674482961Z","rtype":160,"publisher_id":101,"instrument_id":436},"action":"A","side":"B","price":"1.156470000","size":30,"channel_id":23,"order_id":"10998900779529264798","flags":0,"ts_in_delta":1010,"sequence":160642,"symbol":"FCEU SI 20260615 PS"}
{"ts_recv":"2026-04-07T02:25:42.674504328Z","hd":{"ts_event":"2026-04-07T02:25:42.674482961Z","rtype":160,"publisher_id":101,"instrument_id":436},"action":"C","side":"A","price":"1.156560000","size":30,"channel_id":23,"order_id":"1775528742669970376","flags":0,"ts_in_delta":1010,"sequence":160642,"symbol":"FCEU SI 20260615 PS"}
{"ts_recv":"2026-04-07T02:25:42.674504328Z","hd":{"ts_event":"2026-04-07T02:25:42.674482961Z","rtype":160,"publisher_id":101,"instrument_id":436},"action":"A","side":"A","price":"1.156570000","size":30,"channel_id":23,"order_id":"1775528742674488990","flags":128,"ts_in_delta":1010,"sequence":160642,"symbol":"FCEU SI 20260615 PS"}
{"ts_recv":"2026-04-07T02:25:42.679265686Z","hd":{"ts_event":"2026-04-07T02:25:42.679247181Z","rtype":160,"publisher_id":101,"instrument_id":436},"action":"C","side":"B","price":"1.156470000","size":30,"channel_id":23,"order_id":"10998900779529264798","flags":0,"ts_in_delta":991,"sequence":160645,"symbol":"FCEU SI 20260615 PS"}
{"ts_recv":"2026-04-07T02:25:42.679265686Z","hd":{"ts_event":"2026-04-07T02:25:42.679247181Z","rtype":160,"publisher_id":101,"instrument_id":436},"action":"A","side":"B","price":"1.156480000","size":30,"channel_id":23,"order_id":"10998900779534029184","flags":0,"ts_in_delta":991,"sequence":160645,"symbol":"FCEU SI 20260615 PS"}
{"ts_recv":"2026-04-07T02:25:42.679265686Z","hd":{"ts_event":"2026-04-07T02:25:42.679247181Z","rtype":160,"publisher_id":101,"instrument_id":436},"action":"C","side":"A","price":"1.156570000","size":30,"channel_id":23,"order_id":"1775528742674488990","flags":0,"ts_in_delta":991,"sequence":160645,"symbol":"FCEU SI 20260615 PS"}
{"ts_recv":"2026-04-07T02:25:42.679265686Z","hd":{"ts_event":"2026-04-07T02:25:42.679247181Z","rtype":160,"publisher_id":101,"instrument_id":436},"action":"A","side":"A","price":"1.156580000","size":30,"channel_id":23,"order_id":"1775528742679253376","flags":128,"ts_in_delta":991,"sequence":160645,"symbol":"FCEU SI 20260615 PS"}
{"ts_recv":"2026-04-07T02:25:42.679317401Z","hd":{"ts_event":"2026-04-07T02:25:42.679299727Z","rtype":160,"publisher_id":101,"instrument_id":436},"action":"C","side":"B","price":"1.156460000","size":30,"channel_id":23,"order_id":"10998900779524681140","flags":0,"ts_in_delta":1011,"sequence":160646,"symbol":"FCEU SI 20260615 PS"}
{"ts_recv":"2026-04-07T02:25:42.679317401Z","hd":{"ts_event":"2026-04-07T02:25:42.679299727Z","rtype":160,"publisher_id":101,"instrument_id":436},"action":"A","side":"B","price":"1.156480000","size":30,"channel_id":23,"order_id":"10998900779534081756","flags":0,"ts_in_delta":1011,"sequence":160646,"symbol":"FCEU SI 20260615 PS"}
{"ts_recv":"2026-04-07T02:25:42.679317401Z","hd":{"ts_event":"2026-04-07T02:25:42.679299727Z","rtype":160,"publisher_id":101,"instrument_id":436},"action":"C","side":"A","price":"1.156560000","size":30,"channel_id":23,"order_id":"1775528742669905332","flags":0,"ts_in_delta":1011,"sequence":160646,"symbol":"FCEU SI 20260615 PS"}
{"ts_recv":"2026-04-07T02:25:42.679317401Z","hd":{"ts_event":"2026-04-07T02:25:42.679299727Z","rtype":160,"publisher_id":101,"instrument_id":436},"action":"A","side":"A","price":"1.156580000","size":30,"channel_id":23,"order_id":"1775528742679305948","flags":128,"ts_in_delta":1011,"sequence":160646,"symbol":"FCEU SI 20260615 PS"}
{"ts_recv":"2026-04-07T02:25:42.679347636Z","hd":{"ts_event":"2026-04-07T02:25:42.679329135Z","rtype":160,"publisher_id":101,"instrument_id":436},"action":"C","side":"B","price":"1.156480000","size":30,"channel_id":23,"order_id":"10998900779534029184","flags":0,"ts_in_delta":991,"sequence":160647,"symbol":"FCEU SI 20260615 PS"}
{"ts_recv":"2026-04-07T02:25:42.679347636Z","hd":{"ts_event":"2026-04-07T02:25:42.679329135Z","rtype":160,"publisher_id":101,"instrument_id":436},"action":"A","side":"B","price":"1.156470000","size":30,"channel_id":23,"order_id":"10998900779534111104","flags":0,"ts_in_delta":991,"sequence":160647,"symbol":"FCEU SI 20260615 PS"}
{"ts_recv":"2026-04-07T02:25:42.679347636Z","hd":{"ts_event":"2026-04-07T02:25:42.679329135Z","rtype":160,"publisher_id":101,"instrument_id":436},"action":"C","side":"A","price":"1.156580000","size":30,"channel_id":23,"order_id":"1775528742679253376","flags":0,"ts_in_delta":991,"sequence":160647,"symbol":"FCEU SI 20260615 PS"}
{"ts_recv":"2026-04-07T02:25:42.679347636Z","hd":{"ts_event":"2026-04-07T02:25:42.679329135Z","rtype":160,"publisher_id":101,"instrument_id":436},"action":"A","side":"A","price":"1.156570000","size":30,"channel_id":23,"order_id":"1775528742679335296","flags":128,"ts_in_delta":991,"sequence":160647,"symbol":"FCEU SI 20260615 PS"}
{"ts_recv":"2026-04-07T02:25:42.679408228Z","hd":{"ts_event":"2026-04-07T02:25:42.679390639Z","rtype":160,"publisher_id":101,"instrument_id":436},"action":"C","side":"B","price":"1.156470000","size":30,"channel_id":23,"order_id":"10998900779534111104","flags":0,"ts_in_delta":972,"sequence":160648,"symbol":"FCEU SI 20260615 PS"}
{"ts_recv":"2026-04-07T02:25:42.679408228Z","hd":{"ts_event":"2026-04-07T02:25:42.679390639Z","rtype":160,"publisher_id":101,"instrument_id":436},"action":"A","side":"B","price":"1.156480000","size":30,"channel_id":23,"order_id":"10998900779534172676","flags":0,"ts_in_delta":972,"sequence":160648,"symbol":"FCEU SI 20260615 PS"}
{"ts_recv":"2026-04-07T02:25:42.679408228Z","hd":{"ts_event":"2026-04-07T02:25:42.679390639Z","rtype":160,"publisher_id":101,"instrument_id":436},"action":"C","side":"A","price":"1.156570000","size":30,"channel_id":23,"order_id":"1775528742679335296","flags":0,"ts_in_delta":972,"sequence":160648,"symbol":"FCEU SI 20260615 PS"}
{"ts_recv":"2026-04-07T02:25:42.679408228Z","hd":{"ts_event":"2026-04-07T02:25:42.679390639Z","rtype":160,"publisher_id":101,"instrument_id":436},"action":"A","side":"A","price":"1.156580000","size":30,"channel_id":23,"order_id":"1775528742679396868","flags":128,"ts_in_delta":972,"sequence":160648,"symbol":"FCEU SI 20260615 PS"}
{"ts_recv":"2026-04-07T02:25:43.201364684Z","hd":{"ts_event":"2026-04-07T02:25:43.201337777Z","rtype":160,"publisher_id":101,"instrument_id":436},"action":"C","side":"B","price":"1.156480000","size":30,"channel_id":23,"order_id":"10998900779534172676","flags":0,"ts_in_delta":1409,"sequence":160693,"symbol":"FCEU SI 20260615 PS"}
{"ts_recv":"2026-04-07T02:25:43.201364684Z","hd":{"ts_event":"2026-04-07T02:25:43.201337777Z","rtype":160,"publisher_id":101,"instrument_id":436},"action":"A","side":"B","price":"1.156490000","size":30,"channel_id":23,"order_id":"10998900780056124188","flags":0,"ts_in_delta":1409,"sequence":160693,"symbol":"FCEU SI 20260615 PS"}
{"ts_recv":"2026-04-07T02:25:43.201364684Z","hd":{"ts_event":"2026-04-07T02:25:43.201337777Z","rtype":160,"publisher_id":101,"instrument_id":436},"action":"C","side":"A","price":"1.156580000","size":30,"channel_id":23,"order_id":"1775528742679396868","flags":0,"ts_in_delta":1409,"sequence":160693,"symbol":"FCEU SI 20260615 PS"}
{"ts_recv":"2026-04-07T02:25:43.201364684Z","hd":{"ts_event":"2026-04-07T02:25:43.201337777Z","rtype":160,"publisher_id":101,"instrument_id":436},"action":"A","side":"A","price":"1.156590000","size":30,"channel_id":23,"order_id":"1775528743201348380","flags":128,"ts_in_delta":1409,"sequence":160693,"symbol":"FCEU SI 20260615 PS"}
{"ts_recv":"2026-04-07T02:25:48.296406517Z","hd":{"ts_event":"2026-04-07T02:25:48.296387355Z","rtype":160,"publisher_id":101,"instrument_id":436},"action":"C","side":"B","price":"1.156490000","size":30,"channel_id":23,"order_id":"10998900780056124188","flags":0,"ts_in_delta":935,"sequence":160724,"symbol":"FCEU SI 20260615 PS"}
{"ts_recv":"2026-04-07T02:25:48.296406517Z","hd":{"ts_event":"2026-04-07T02:25:48.296387355Z","rtype":160,"publisher_id":101,"instrument_id":436},"action":"A","side":"B","price":"1.156480000","size":30,"channel_id":23,"order_id":"10998900785151169409","flags":0,"ts_in_delta":935,"sequence":160724,"symbol":"FCEU SI 20260615 PS"}
{"ts_recv":"2026-04-07T02:25:48.296406517Z","hd":{"ts_event":"2026-04-07T02:25:48.296387355Z","rtype":160,"publisher_id":101,"instrument_id":436},"action":"C","side":"A","price":"1.156590000","size":30,"channel_id":23,"order_id":"1775528743201348380","flags":0,"ts_in_delta":935,"sequence":160724,"symbol":"FCEU SI 20260615 PS"}
{"ts_recv":"2026-04-07T02:25:48.296406517Z","hd":{"ts_event":"2026-04-07T02:25:48.296387355Z","rtype":160,"publisher_id":101,"instrument_id":436},"action":"A","side":"A","price":"1.156580000","size":30,"channel_id":23,"order_id":"1775528748296393601","flags":128,"ts_in_delta":935,"sequence":160724,"symbol":"FCEU SI 20260615 PS"}
{"ts_recv":"2026-04-07T02:26:02.921554954Z","hd":{"ts_event":"2026-04-07T02:26:02.921529495Z","rtype":160,"publisher_id":101,"instrument_id":436},"action":"C","side":"B","price":"1.156480000","size":30,"channel_id":23,"order_id":"10998900785151169409","flags":0,"ts_in_delta":965,"sequence":160800,"symbol":"FCEU SI 20260615 PS"}
{"ts_recv":"2026-04-07T02:26:02.921554954Z","hd":{"ts_event":"2026-04-07T02:26:02.921529495Z","rtype":160,"publisher_id":101,"instrument_id":436},"action":"A","side":"B","price":"1.156490000","size":30,"channel_id":23,"order_id":"10998900799776311510","flags":0,"ts_in_delta":965,"sequence":160800,"symbol":"FCEU SI 20260615 PS"}
{"ts_recv":"2026-04-07T02:26:02.921554954Z","hd":{"ts_event":"2026-04-07T02:26:02.921529495Z","rtype":160,"publisher_id":101,"instrument_id":436},"action":"C","side":"A","price":"1.156580000","size":30,"channel_id":23,"order_id":"1775528748296393601","flags":0,"ts_in_delta":965,"sequence":160800,"symbol":"FCEU SI 20260615 PS"}
{"ts_recv":"2026-04-07T02:26:02.921554954Z","hd":{"ts_event":"2026-04-07T02:26:02.921529495Z","rtype":160,"publisher_id":101,"instrument_id":436},"action":"A","side":"A","price":"1.156590000","size":30,"channel_id":23,"order_id":"1775528762921535702","flags":128,"ts_in_delta":965,"sequence":160800,"symbol":"FCEU SI 20260615 PS"}
{"ts_recv":"2026-04-07T02:26:03.356787564Z","hd":{"ts_event":"2026-04-07T02:26:03.356771083Z","rtype":160,"publisher_id":101,"instrument_id":436},"action":"C","side":"B","price":"1.156490000","size":30,"channel_id":23,"order_id":"10998900799776311510","flags":0,"ts_in_delta":951,"sequence":160805,"symbol":"FCEU SI 20260615 PS"}
{"ts_recv":"2026-04-07T02:26:03.356787564Z","hd":{"ts_event":"2026-04-07T02:26:03.356771083Z","rtype":160,"publisher_id":101,"instrument_id":436},"action":"A","side":"B","price":"1.156480000","size":30,"channel_id":23,"order_id":"10998900800211552928","flags":0,"ts_in_delta":951,"sequence":160805,"symbol":"FCEU SI 20260615 PS"}
{"ts_recv":"2026-04-07T02:26:03.356787564Z","hd":{"ts_event":"2026-04-07T02:26:03.356771083Z","rtype":160,"publisher_id":101,"instrument_id":436},"action":"C","side":"A","price":"1.156590000","size":30,"channel_id":23,"order_id":"1775528762921535702","flags":0,"ts_in_delta":951,"sequence":160805,"symbol":"FCEU SI 20260615 PS"}
{"ts_recv":"2026-04-07T02:26:03.356787564Z","hd":{"ts_event":"2026-04-07T02:26:03.356771083Z","rtype":160,"publisher_id":101,"instrument_id":436},"action":"A","side":"A","price":"1.156580000","size":30,"channel_id":23,"order_id":"1775528763356777120","flags":128,"ts_in_delta":951,"sequence":160805,"symbol":"FCEU SI 20260615 PS"}
{"ts_recv":"2026-04-07T02:26:19.070346010Z","hd":{"ts_event":"2026-04-07T02:26:19.070311953Z","rtype":160,"publisher_id":101,"instrument_id":436},"action":"C","side":"B","price":"1.156480000","size":30,"channel_id":23,"order_id":"10998900800211552928","flags":0,"ts_in_delta":1159,"sequence":160890,"symbol":"FCEU SI 20260615 PS"}
{"ts_recv":"2026-04-07T02:26:19.070346010Z","hd":{"ts_event":"2026-04-07T02:26:19.070311953Z","rtype":160,"publisher_id":101,"instrument_id":436},"action":"A","side":"B","price":"1.156490000","size":30,"channel_id":23,"order_id":"10998900815925099866","flags":0,"ts_in_delta":1159,"sequence":160890,"symbol":"FCEU SI 20260615 PS"}
{"ts_recv":"2026-04-07T02:26:19.070346010Z","hd":{"ts_event":"2026-04-07T02:26:19.070311953Z","rtype":160,"publisher_id":101,"instrument_id":436},"action":"C","side":"A","price":"1.156580000","size":30,"channel_id":23,"order_id":"1775528763356777120","flags":0,"ts_in_delta":1159,"sequence":160890,"symbol":"FCEU SI 20260615 PS"}
{"ts_recv":"2026-04-07T02:26:19.070346010Z","hd":{"ts_event":"2026-04-07T02:26:19.070311953Z","rtype":160,"publisher_id":101,"instrument_id":436},"action":"A","side":"A","price":"1.156590000","size":30,"channel_id":23,"order_id":"1775528779070324058","flags":128,"ts_in_delta":1159,"sequence":160890,"symbol":"FCEU SI 20260615 PS"}
{"ts_recv":"2026-04-07T02:26:58.006575726Z","hd":{"ts_event":"2026-04-07T02:26:58.006550105Z","rtype":160,"publisher_id":101,"instrument_id":436},"action":"C","side":"B","price":"1.156490000","size":30,"channel_id":23,"order_id":"10998900815925099866","flags":0,"ts_in_delta":1133,"sequence":161129,"symbol":"FCEU SI 20260615 PS"}
{"ts_recv":"2026-04-07T02:26:58.006575726Z","hd":{"ts_event":"2026-04-07T02:26:58.006550105Z","rtype":160,"publisher_id":101,"instrument_id":436},"action":"A","side":"B","price":"1.156480000","size":30,"channel_id":23,"order_id":"10998900854861332048","flags":0,"ts_in_delta":1133,"sequence":161129,"symbol":"FCEU SI 20260615 PS"}
{"ts_recv":"2026-04-07T02:26:58.006575726Z","hd":{"ts_event":"2026-04-07T02:26:58.006550105Z","rtype":160,"publisher_id":101,"instrument_id":436},"action":"C","side":"A","price":"1.156590000","size":30,"channel_id":23,"order_id":"1775528779070324058","flags":0,"ts_in_delta":1133,"sequence":161129,"symbol":"FCEU SI 20260615 PS"}
{"ts_recv":"2026-04-07T02:26:58.006575726Z","hd":{"ts_event":"2026-04-07T02:26:58.006550105Z","rtype":160,"publisher_id":101,"instrument_id":436},"action":"A","side":"A","price":"1.156580000","size":30,"channel_id":23,"order_id":"1775528818006556240","flags":128,"ts_in_delta":1133,"sequence":161129,"symbol":"FCEU SI 20260615 PS"}
{"ts_recv":"2026-04-07T02:27:03.909323953Z","hd":{"ts_event":"2026-04-07T02:27:03.909302201Z","rtype":160,"publisher_id":101,"instrument_id":436},"action":"C","side":"B","price":"1.156480000","size":30,"channel_id":23,"order_id":"10998900854861332048","flags":0,"ts_in_delta":939,"sequence":161158,"symbol":"FCEU SI 20260615 PS"}
{"ts_recv":"2026-04-07T02:27:03.909323953Z","hd":{"ts_event":"2026-04-07T02:27:03.909302201Z","rtype":160,"publisher_id":101,"instrument_id":436},"action":"A","side":"B","price":"1.156470000","size":30,"channel_id":23,"order_id":"10998900860764084648","flags":0,"ts_in_delta":939,"sequence":161158,"symbol":"FCEU SI 20260615 PS"}
{"ts_recv":"2026-04-07T02:27:03.909323953Z","hd":{"ts_event":"2026-04-07T02:27:03.909302201Z","rtype":160,"publisher_id":101,"instrument_id":436},"action":"C","side":"A","price":"1.156580000","size":30,"channel_id":23,"order_id":"1775528818006556240","flags":0,"ts_in_delta":939,"sequence":161158,"symbol":"FCEU SI 20260615 PS"}
{"ts_recv":"2026-04-07T02:27:03.909323953Z","hd":{"ts_event":"2026-04-07T02:27:03.909302201Z","rtype":160,"publisher_id":101,"instrument_id":436},"action":"A","side":"A","price":"1.156570000","size":30,"channel_id":23,"order_id":"1775528823909308840","flags":128,"ts_in_delta":939,"sequence":161158,"symbol":"FCEU SI 20260615 PS"}
{"ts_recv":"2026-04-07T02:27:03.948592676Z","hd":{"ts_event":"2026-04-07T02:27:03.948571323Z","rtype":160,"publisher_id":101,"instrument_id":436},"action":"C","side":"B","price":"1.156470000","size":30,"channel_id":23,"order_id":"10998900860764084648","flags":0,"ts_in_delta":867,"sequence":161170,"symbol":"FCEU SI 20260615 PS"}
{"ts_recv":"2026-04-07T02:27:03.948592676Z","hd":{"ts_event":"2026-04-07T02:27:03.948571323Z","rtype":160,"publisher_id":101,"instrument_id":436},"action":"A","side":"B","price":"1.156480000","size":30,"channel_id":23,"order_id":"10998900860803353435","flags":0,"ts_in_delta":867,"sequence":161170,"symbol":"FCEU SI 20260615 PS"}
{"ts_recv":"2026-04-07T02:27:03.948592676Z","hd":{"ts_event":"2026-04-07T02:27:03.948571323Z","rtype":160,"publisher_id":101,"instrument_id":436},"action":"C","side":"A","price":"1.156570000","size":30,"channel_id":23,"order_id":"1775528823909308840","flags":0,"ts_in_delta":867,"sequence":161170,"symbol":"FCEU SI 20260615 PS"}
{"ts_recv":"2026-04-07T02:27:03.948592676Z","hd":{"ts_event":"2026-04-07T02:27:03.948571323Z","rtype":160,"publisher_id":101,"instrument_id":436},"action":"A","side":"A","price":"1.156580000","size":30,"channel_id":23,"order_id":"1775528823948577627","flags":128,"ts_in_delta":867,"sequence":161170,"symbol":"FCEU SI 20260615 PS"}
{"ts_recv":"2026-04-07T02:27:06.232674455Z","hd":{"ts_event":"2026-04-07T02:27:06.232651973Z","rtype":160,"publisher_id":101,"instrument_id":436},"action":"C","side":"B","price":"1.156480000","size":30,"channel_id":23,"order_id":"10998900860803353435","flags":0,"ts_in_delta":1196,"sequence":161228,"symbol":"FCEU SI 20260615 PS"}
{"ts_recv":"2026-04-07T02:27:06.232674455Z","hd":{"ts_event":"2026-04-07T02:27:06.232651973Z","rtype":160,"publisher_id":101,"instrument_id":436},"action":"A","side":"B","price":"1.156500000","size":30,"channel_id":23,"order_id":"10998900863087433928","flags":0,"ts_in_delta":1196,"sequence":161228,"symbol":"FCEU SI 20260615 PS"}
{"ts_recv":"2026-04-07T02:27:06.232674455Z","hd":{"ts_event":"2026-04-07T02:27:06.232651973Z","rtype":160,"publisher_id":101,"instrument_id":436},"action":"C","side":"A","price":"1.156580000","size":30,"channel_id":23,"order_id":"1775528823948577627","flags":0,"ts_in_delta":1196,"sequence":161228,"symbol":"FCEU SI 20260615 PS"}
{"ts_recv":"2026-04-07T02:27:06.232674455Z","hd":{"ts_event":"2026-04-07T02:27:06.232651973Z","rtype":160,"publisher_id":101,"instrument_id":436},"action":"A","side":"A","price":"1.156600000","size":30,"channel_id":23,"order_id":"1775528826232658120","flags":128,"ts_in_delta":1196,"sequence":161228,"symbol":"FCEU SI 20260615 PS"}
{"ts_recv":"2026-04-07T02:27:06.232752388Z","hd":{"ts_event":"2026-04-07T02:27:06.232731057Z","rtype":160,"publisher_id":101,"instrument_id":436},"action":"C","side":"B","price":"1.156480000","size":30,"channel_id":23,"order_id":"10998900779534081756","flags":0,"ts_in_delta":971,"sequence":161229,"symbol":"FCEU SI 20260615 PS"}
{"ts_recv":"2026-04-07T02:27:06.232752388Z","hd":{"ts_event":"2026-04-07T02:27:06.232731057Z","rtype":160,"publisher_id":101,"instrument_id":436},"action":"A","side":"B","price":"1.156500000","size":30,"channel_id":23,"order_id":"10998900863087513855","flags":0,"ts_in_delta":971,"sequence":161229,"symbol":"FCEU SI 20260615 PS"}
{"ts_recv":"2026-04-07T02:27:06.232752388Z","hd":{"ts_event":"2026-04-07T02:27:06.232731057Z","rtype":160,"publisher_id":101,"instrument_id":436},"action":"C","side":"A","price":"1.156580000","size":30,"channel_id":23,"order_id":"1775528742679305948","flags":0,"ts_in_delta":971,"sequence":161229,"symbol":"FCEU SI 20260615 PS"}
{"ts_recv":"2026-04-07T02:27:06.232752388Z","hd":{"ts_event":"2026-04-07T02:27:06.232731057Z","rtype":160,"publisher_id":101,"instrument_id":436},"action":"A","side":"A","price":"1.156600000","size":30,"channel_id":23,"order_id":"1775528826232738047","flags":128,"ts_in_delta":971,"sequence":161229,"symbol":"FCEU SI 20260615 PS"}
{"ts_recv":"2026-04-07T02:27:06.232813718Z","hd":{"ts_event":"2026-04-07T02:27:06.232793547Z","rtype":160,"publisher_id":101,"instrument_id":436},"action":"C","side":"B","price":"1.156500000","size":30,"channel_id":23,"order_id":"10998900863087433928","flags":0,"ts_in_delta":937,"sequence":161230,"symbol":"FCEU SI 20260615 PS"}
{"ts_recv":"2026-04-07T02:27:06.232813718Z","hd":{"ts_event":"2026-04-07T02:27:06.232793547Z","rtype":160,"publisher_id":101,"instrument_id":436},"action":"A","side":"B","price":"1.156510000","size":30,"channel_id":23,"order_id":"10998900863087575271","flags":0,"ts_in_delta":937,"sequence":161230,"symbol":"FCEU SI 20260615 PS"}
{"ts_recv":"2026-04-07T02:27:06.232813718Z","hd":{"ts_event":"2026-04-07T02:27:06.232793547Z","rtype":160,"publisher_id":101,"instrument_id":436},"action":"C","side":"A","price":"1.156600000","size":30,"channel_id":23,"order_id":"1775528826232658120","flags":0,"ts_in_delta":937,"sequence":161230,"symbol":"FCEU SI 20260615 PS"}
{"ts_recv":"2026-04-07T02:27:06.232813718Z","hd":{"ts_event":"2026-04-07T02:27:06.232793547Z","rtype":160,"publisher_id":101,"instrument_id":436},"action":"A","side":"A","price":"1.156610000","size":30,"channel_id":23,"order_id":"1775528826232799463","flags":128,"ts_in_delta":937,"sequence":161230,"symbol":"FCEU SI 20260615 PS"}
{"ts_recv":"2026-04-07T02:27:06.239175278Z","hd":{"ts_event":"2026-04-07T02:27:06.239157491Z","rtype":160,"publisher_id":101,"instrument_id":436},"action":"C","side":"B","price":"1.156510000","size":30,"channel_id":23,"order_id":"10998900863087575271","flags":0,"ts_in_delta":801,"sequence":161234,"symbol":"FCEU SI 20260615 PS"}
{"ts_recv":"2026-04-07T02:27:06.239175278Z","hd":{"ts_event":"2026-04-07T02:27:06.239157491Z","rtype":160,"publisher_id":101,"instrument_id":436},"action":"A","side":"B","price":"1.156520000","size":30,"channel_id":23,"order_id":"10998900863093939231","flags":0,"ts_in_delta":801,"sequence":161234,"symbol":"FCEU SI 20260615 PS"}
{"ts_recv":"2026-04-07T02:27:06.239175278Z","hd":{"ts_event":"2026-04-07T02:27:06.239157491Z","rtype":160,"publisher_id":101,"instrument_id":436},"action":"C","side":"A","price":"1.156610000","size":30,"channel_id":23,"order_id":"1775528826232799463","flags":0,"ts_in_delta":801,"sequence":161234,"symbol":"FCEU SI 20260615 PS"}
{"ts_recv":"2026-04-07T02:27:06.239175278Z","hd":{"ts_event":"2026-04-07T02:27:06.239157491Z","rtype":160,"publisher_id":101,"instrument_id":436},"action":"A","side":"A","price":"1.156620000","size":30,"channel_id":23,"order_id":"1775528826239163423","flags":128,"ts_in_delta":801,"sequence":161234,"symbol":"FCEU SI 20260615 PS"}
{"ts_recv":"2026-04-07T02:27:06.239229934Z","hd":{"ts_event":"2026-04-07T02:27:06.239213499Z","rtype":160,"publisher_id":101,"instrument_id":436},"action":"C","side":"B","price":"1.156500000","size":30,"channel_id":23,"order_id":"10998900863087513855","flags":0,"ts_in_delta":780,"sequence":161235,"symbol":"FCEU SI 20260615 PS"}
{"ts_recv":"2026-04-07T02:27:06.239229934Z","hd":{"ts_event":"2026-04-07T02:27:06.239213499Z","rtype":160,"publisher_id":101,"instrument_id":436},"action":"A","side":"B","price":"1.156520000","size":30,"channel_id":23,"order_id":"10998900863093995515","flags":0,"ts_in_delta":780,"sequence":161235,"symbol":"FCEU SI 20260615 PS"}
{"ts_recv":"2026-04-07T02:27:06.239229934Z","hd":{"ts_event":"2026-04-07T02:27:06.239213499Z","rtype":160,"publisher_id":101,"instrument_id":436},"action":"C","side":"A","price":"1.156600000","size":30,"channel_id":23,"order_id":"1775528826232738047","flags":0,"ts_in_delta":780,"sequence":161235,"symbol":"FCEU SI 20260615 PS"}
{"ts_recv":"2026-04-07T02:27:06.239229934Z","hd":{"ts_event":"2026-04-07T02:27:06.239213499Z","rtype":160,"publisher_id":101,"instrument_id":436},"action":"A","side":"A","price":"1.156620000","size":30,"channel_id":23,"order_id":"1775528826239219707","flags":128,"ts_in_delta":780,"sequence":161235,"symbol":"FCEU SI 20260615 PS"}
{"ts_recv":"2026-04-07T02:27:06.239255507Z","hd":{"ts_event":"2026-04-07T02:27:06.239237921Z","rtype":160,"publisher_id":101,"instrument_id":436},"action":"C","side":"B","price":"1.156520000","size":30,"channel_id":23,"order_id":"10998900863093939231","flags":0,"ts_in_delta":812,"sequence":161236,"symbol":"FCEU SI 20260615 PS"}
{"ts_recv":"2026-04-07T02:27:06.239255507Z","hd":{"ts_event":"2026-04-07T02:27:06.239237921Z","rtype":160,"publisher_id":101,"instrument_id":436},"action":"A","side":"B","price":"1.156510000","size":30,"channel_id":23,"order_id":"10998900863094019828","flags":0,"ts_in_delta":812,"sequence":161236,"symbol":"FCEU SI 20260615 PS"}
{"ts_recv":"2026-04-07T02:27:06.239255507Z","hd":{"ts_event":"2026-04-07T02:27:06.239237921Z","rtype":160,"publisher_id":101,"instrument_id":436},"action":"C","side":"A","price":"1.156620000","size":30,"channel_id":23,"order_id":"1775528826239163423","flags":0,"ts_in_delta":812,"sequence":161236,"symbol":"FCEU SI 20260615 PS"}
{"ts_recv":"2026-04-07T02:27:06.239255507Z","hd":{"ts_event":"2026-04-07T02:27:06.239237921Z","rtype":160,"publisher_id":101,"instrument_id":436},"action":"A","side":"A","price":"1.156610000","size":30,"channel_id":23,"order_id":"1775528826239244020","flags":128,"ts_in_delta":812,"sequence":161236,"symbol":"FCEU SI 20260615 PS"}
{"ts_recv":"2026-04-07T02:27:06.239315462Z","hd":{"ts_event":"2026-04-07T02:27:06.239297845Z","rtype":160,"publisher_id":101,"instrument_id":436},"action":"C","side":"B","price":"1.156510000","size":30,"channel_id":23,"order_id":"10998900863094019828","flags":0,"ts_in_delta":948,"sequence":161237,"symbol":"FCEU SI 20260615 PS"}
{"ts_recv":"2026-04-07T02:27:06.239315462Z","hd":{"ts_event":"2026-04-07T02:27:06.239297845Z","rtype":160,"publisher_id":101,"instrument_id":436},"action":"A","side":"B","price":"1.156520000","size":30,"channel_id":23,"order_id":"10998900863094079589","flags":0,"ts_in_delta":948,"sequence":161237,"symbol":"FCEU SI 20260615 PS"}
{"ts_recv":"2026-04-07T02:27:06.239315462Z","hd":{"ts_event":"2026-04-07T02:27:06.239297845Z","rtype":160,"publisher_id":101,"instrument_id":436},"action":"C","side":"A","price":"1.156610000","size":30,"channel_id":23,"order_id":"1775528826239244020","flags":0,"ts_in_delta":948,"sequence":161237,"symbol":"FCEU SI 20260615 PS"}
{"ts_recv":"2026-04-07T02:27:06.239315462Z","hd":{"ts_event":"2026-04-07T02:27:06.239297845Z","rtype":160,"publisher_id":101,"instrument_id":436},"action":"A","side":"A","price":"1.156620000","size":30,"channel_id":23,"order_id":"1775528826239303781","flags":128,"ts_in_delta":948,"sequence":161237,"symbol":"FCEU SI 20260615 PS"}
{"ts_recv":"2026-04-07T02:27:06.392240243Z","hd":{"ts_event":"2026-04-07T02:27:06.392217813Z","rtype":160,"publisher_id":101,"instrument_id":436},"action":"A","side":"B","price":"1.156400000","size":20,"channel_id":23,"order_id":"10998900863247004555","flags":128,"ts_in_delta":1168,"sequence":161257,"symbol":"FCEU SI 20260615 PS"}
{"ts_recv":"2026-04-07T02:27:06.392254359Z","hd":{"ts_event":"2026-04-07T02:27:06.392240509Z","rtype":160,"publisher_id":101,"instrument_id":436},"action":"C","side":"B","price":"1.156300000","size":20,"channel_id":23,"order_id":"10998900588671402332","flags":128,"ts_in_delta":873,"sequence":161258,"symbol":"FCEU SI 20260615 PS"}
{"ts_recv":"2026-04-07T02:27:11.824977218Z","hd":{"ts_event":"2026-04-07T02:27:11.824953617Z","rtype":160,"publisher_id":101,"instrument_id":436},"action":"C","side":"B","price":"1.156520000","size":30,"channel_id":23,"order_id":"10998900863094079589","flags":0,"ts_in_delta":994,"sequence":161297,"symbol":"FCEU SI 20260615 PS"}
{"ts_recv":"2026-04-07T02:27:11.824977218Z","hd":{"ts_event":"2026-04-07T02:27:11.824953617Z","rtype":160,"publisher_id":101,"instrument_id":436},"action":"A","side":"B","price":"1.156530000","size":30,"channel_id":23,"order_id":"10998900868679735798","flags":0,"ts_in_delta":994,"sequence":161297,"symbol":"FCEU SI 20260615 PS"}
{"ts_recv":"2026-04-07T02:27:11.824977218Z","hd":{"ts_event":"2026-04-07T02:27:11.824953617Z","rtype":160,"publisher_id":101,"instrument_id":436},"action":"C","side":"A","price":"1.156620000","size":30,"channel_id":23,"order_id":"1775528826239303781","flags":0,"ts_in_delta":994,"sequence":161297,"symbol":"FCEU SI 20260615 PS"}
{"ts_recv":"2026-04-07T02:27:11.824977218Z","hd":{"ts_event":"2026-04-07T02:27:11.824953617Z","rtype":160,"publisher_id":101,"instrument_id":436},"action":"A","side":"A","price":"1.156630000","size":30,"channel_id":23,"order_id":"1775528831824959990","flags":128,"ts_in_delta":994,"sequence":161297,"symbol":"FCEU SI 20260615 PS"}
{"ts_recv":"2026-04-07T02:27:16.155422259Z","hd":{"ts_event":"2026-04-07T02:27:16.155407457Z","rtype":160,"publisher_id":101,"instrument_id":436},"action":"C","side":"A","price":"1.156700000","size":20,"channel_id":23,"order_id":"1775528535401389357","flags":128,"ts_in_delta":806,"sequence":161319,"symbol":"FCEU SI 20260615 PS"}
{"ts_recv":"2026-04-07T02:27:16.176366195Z","hd":{"ts_event":"2026-04-07T02:27:16.176344457Z","rtype":160,"publisher_id":101,"instrument_id":436},"action":"C","side":"B","price":"1.156520000","size":30,"channel_id":23,"order_id":"10998900863093995515","flags":0,"ts_in_delta":1034,"sequence":161320,"symbol":"FCEU SI 20260615 PS"}
{"ts_recv":"2026-04-07T02:27:16.176366195Z","hd":{"ts_event":"2026-04-07T02:27:16.176344457Z","rtype":160,"publisher_id":101,"instrument_id":436},"action":"A","side":"B","price":"1.156540000","size":30,"channel_id":23,"order_id":"10998900873031126177","flags":0,"ts_in_delta":1034,"sequence":161320,"symbol":"FCEU SI 20260615 PS"}
{"ts_recv":"2026-04-07T02:27:16.176366195Z","hd":{"ts_event":"2026-04-07T02:27:16.176344457Z","rtype":160,"publisher_id":101,"instrument_id":436},"action":"C","side":"A","price":"1.156620000","size":30,"channel_id":23,"order_id":"1775528826239219707","flags":0,"ts_in_delta":1034,"sequence":161320,"symbol":"FCEU SI 20260615 PS"}
{"ts_recv":"2026-04-07T02:27:16.176366195Z","hd":{"ts_event":"2026-04-07T02:27:16.176344457Z","rtype":160,"publisher_id":101,"instrument_id":436},"action":"A","side":"A","price":"1.156640000","size":30,"channel_id":23,"order_id":"1775528836176350369","flags":128,"ts_in_delta":1034,"sequence":161320,"symbol":"FCEU SI 20260615 PS"}
{"ts_recv":"2026-04-07T02:27:16.176440042Z","hd":{"ts_event":"2026-04-07T02:27:16.176421163Z","rtype":160,"publisher_id":101,"instrument_id":436},"action":"C","side":"B","price":"1.156530000","size":30,"channel_id":23,"order_id":"10998900868679735798","flags":0,"ts_in_delta":888,"sequence":161321,"symbol":"FCEU SI 20260615 PS"}
{"ts_recv":"2026-04-07T02:27:16.176440042Z","hd":{"ts_event":"2026-04-07T02:27:16.176421163Z","rtype":160,"publisher_id":101,"instrument_id":436},"action":"A","side":"B","price":"1.156540000","size":30,"channel_id":23,"order_id":"10998900873031202875","flags":0,"ts_in_delta":888,"sequence":161321,"symbol":"FCEU SI 20260615 PS"}
{"ts_recv":"2026-04-07T02:27:16.176440042Z","hd":{"ts_event":"2026-04-07T02:27:16.176421163Z","rtype":160,"publisher_id":101,"instrument_id":436},"action":"C","side":"A","price":"1.156630000","size":30,"channel_id":23,"order_id":"1775528831824959990","flags":0,"ts_in_delta":888,"sequence":161321,"symbol":"FCEU SI 20260615 PS"}
{"ts_recv":"2026-04-07T02:27:16.176440042Z","hd":{"ts_event":"2026-04-07T02:27:16.176421163Z","rtype":160,"publisher_id":101,"instrument_id":436},"action":"A","side":"A","price":"1.156640000","size":30,"channel_id":23,"order_id":"1775528836176427067","flags":128,"ts_in_delta":888,"sequence":161321,"symbol":"FCEU SI 20260615 PS"}
{"ts_recv":"2026-04-07T02:27:16.199269738Z","hd":{"ts_event":"2026-04-07T02:27:16.199254757Z","rtype":160,"publisher_id":101,"instrument_id":436},"action":"A","side":"A","price":"1.156900000","size":20,"channel_id":23,"order_id":"1775528836199261096","flags":128,"ts_in_delta":778,"sequence":161322,"symbol":"FCEU SI 20260615 PS"}
{"ts_recv":"2026-04-07T02:27:19.896298001Z","hd":{"ts_event":"2026-04-07T02:27:19.896272647Z","rtype":160,"publisher_id":101,"instrument_id":436},"action":"A","side":"A","price":"1.156800000","size":20,"channel_id":23,"order_id":"1775528839896286926","flags":128,"ts_in_delta":1107,"sequence":161343,"symbol":"FCEU SI 20260615 PS"}
{"ts_recv":"2026-04-07T02:27:19.896307117Z","hd":{"ts_event":"2026-04-07T02:27:19.896292103Z","rtype":160,"publisher_id":101,"instrument_id":436},"action":"C","side":"A","price":"1.156900000","size":20,"channel_id":23,"order_id":"1775528836199261096","flags":128,"ts_in_delta":771,"sequence":161344,"symbol":"FCEU SI 20260615 PS"}
{"ts_recv":"2026-04-07T02:27:57.129147896Z","hd":{"ts_event":"2026-04-07T02:27:57.129122207Z","rtype":160,"publisher_id":101,"instrument_id":436},"action":"C","side":"B","price":"1.156540000","size":30,"channel_id":23,"order_id":"10998900873031202875","flags":0,"ts_in_delta":1093,"sequence":161550,"symbol":"FCEU SI 20260615 PS"}
{"ts_recv":"2026-04-07T02:27:57.129147896Z","hd":{"ts_event":"2026-04-07T02:27:57.129122207Z","rtype":160,"publisher_id":101,"instrument_id":436},"action":"A","side":"B","price":"1.156530000","size":30,"channel_id":23,"order_id":"10998900913983904324","flags":0,"ts_in_delta":1093,"sequence":161550,"symbol":"FCEU SI 20260615 PS"}
{"ts_recv":"2026-04-07T02:27:57.129147896Z","hd":{"ts_event":"2026-04-07T02:27:57.129122207Z","rtype":160,"publisher_id":101,"instrument_id":436},"action":"C","side":"A","price":"1.156640000","size":30,"channel_id":23,"order_id":"1775528836176427067","flags":0,"ts_in_delta":1093,"sequence":161550,"symbol":"FCEU SI 20260615 PS"}
{"ts_recv":"2026-04-07T02:27:57.129147896Z","hd":{"ts_event":"2026-04-07T02:27:57.129122207Z","rtype":160,"publisher_id":101,"instrument_id":436},"action":"A","side":"A","price":"1.156630000","size":30,"channel_id":23,"order_id":"1775528877129128516","flags":128,"ts_in_delta":1093,"sequence":161550,"symbol":"FCEU SI 20260615 PS"}
{"ts_recv":"2026-04-07T02:27:57.129257992Z","hd":{"ts_event":"2026-04-07T02:27:57.129234431Z","rtype":160,"publisher_id":101,"instrument_id":436},"action":"C","side":"B","price":"1.156540000","size":30,"channel_id":23,"order_id":"10998900873031126177","flags":0,"ts_in_delta":991,"sequence":161551,"symbol":"FCEU SI 20260615 PS"}
{"ts_recv":"2026-04-07T02:27:57.129257992Z","hd":{"ts_event":"2026-04-07T02:27:57.129234431Z","rtype":160,"publisher_id":101,"instrument_id":436},"action":"A","side":"B","price":"1.156520000","size":30,"channel_id":23,"order_id":"10998900913984016665","flags":0,"ts_in_delta":991,"sequence":161551,"symbol":"FCEU SI 20260615 PS"}
{"ts_recv":"2026-04-07T02:27:57.129257992Z","hd":{"ts_event":"2026-04-07T02:27:57.129234431Z","rtype":160,"publisher_id":101,"instrument_id":436},"action":"C","side":"A","price":"1.156640000","size":30,"channel_id":23,"order_id":"1775528836176350369","flags":0,"ts_in_delta":991,"sequence":161551,"symbol":"FCEU SI 20260615 PS"}
{"ts_recv":"2026-04-07T02:27:57.129257992Z","hd":{"ts_event":"2026-04-07T02:27:57.129234431Z","rtype":160,"publisher_id":101,"instrument_id":436},"action":"A","side":"A","price":"1.156620000","size":30,"channel_id":23,"order_id":"1775528877129240857","flags":128,"ts_in_delta":991,"sequence":161551,"symbol":"FCEU SI 20260615 PS"}
{"ts_recv":"2026-04-07T02:27:57.129319959Z","hd":{"ts_event":"2026-04-07T02:27:57.129299347Z","rtype":160,"publisher_id":101,"instrument_id":436},"action":"C","side":"B","price":"1.156530000","size":30,"channel_id":23,"order_id":"10998900913983904324","flags":0,"ts_in_delta":989,"sequence":161552,"symbol":"FCEU SI 20260615 PS"}
{"ts_recv":"2026-04-07T02:27:57.129319959Z","hd":{"ts_event":"2026-04-07T02:27:57.129299347Z","rtype":160,"publisher_id":101,"instrument_id":436},"action":"A","side":"B","price":"1.156520000","size":30,"channel_id":23,"order_id":"10998900913984081384","flags":0,"ts_in_delta":989,"sequence":161552,"symbol":"FCEU SI 20260615 PS"}
{"ts_recv":"2026-04-07T02:27:57.129319959Z","hd":{"ts_event":"2026-04-07T02:27:57.129299347Z","rtype":160,"publisher_id":101,"instrument_id":436},"action":"C","side":"A","price":"1.156630000","size":30,"channel_id":23,"order_id":"1775528877129128516","flags":0,"ts_in_delta":989,"sequence":161552,"symbol":"FCEU SI 20260615 PS"}
{"ts_recv":"2026-04-07T02:27:57.129319959Z","hd":{"ts_event":"2026-04-07T02:27:57.129299347Z","rtype":160,"publisher_id":101,"instrument_id":436},"action":"A","side":"A","price":"1.156620000","size":30,"channel_id":23,"order_id":"1775528877129305576","flags":128,"ts_in_delta":989,"sequence":161552,"symbol":"FCEU SI 20260615 PS"}
{"ts_recv":"2026-04-07T02:27:57.144294389Z","hd":{"ts_event":"2026-04-07T02:27:57.144276041Z","rtype":160,"publisher_id":101,"instrument_id":436},"action":"C","side":"B","price":"1.156520000","size":30,"channel_id":23,"order_id":"10998900913984081384","flags":0,"ts_in_delta":805,"sequence":161563,"symbol":"FCEU SI 20260615 PS"}
{"ts_recv":"2026-04-07T02:27:57.144294389Z","hd":{"ts_event":"2026-04-07T02:27:57.144276041Z","rtype":160,"publisher_id":101,"instrument_id":436},"action":"A","side":"B","price":"1.156530000","size":30,"channel_id":23,"order_id":"10998900913999058000","flags":0,"ts_in_delta":805,"sequence":161563,"symbol":"FCEU SI 20260615 PS"}
{"ts_recv":"2026-04-07T02:27:57.144294389Z","hd":{"ts_event":"2026-04-07T02:27:57.144276041Z","rtype":160,"publisher_id":101,"instrument_id":436},"action":"C","side":"A","price":"1.156620000","size":30,"channel_id":23,"order_id":"1775528877129305576","flags":0,"ts_in_delta":805,"sequence":161563,"symbol":"FCEU SI 20260615 PS"}
{"ts_recv":"2026-04-07T02:27:57.144294389Z","hd":{"ts_event":"2026-04-07T02:27:57.144276041Z","rtype":160,"publisher_id":101,"instrument_id":436},"action":"A","side":"A","price":"1.156630000","size":30,"channel_id":23,"order_id":"1775528877144282192","flags":128,"ts_in_delta":805,"sequence":161563,"symbol":"FCEU SI 20260615 PS"}
{"ts_recv":"2026-04-07T02:27:57.144376262Z","hd":{"ts_event":"2026-04-07T02:27:57.144356001Z","rtype":160,"publisher_id":101,"instrument_id":436},"action":"C","side":"B","price":"1.156530000","size":30,"channel_id":23,"order_id":"10998900913999058000","flags":0,"ts_in_delta":847,"sequence":161564,"symbol":"FCEU SI 20260615 PS"}
{"ts_recv":"2026-04-07T02:27:57.144376262Z","hd":{"ts_event":"2026-04-07T02:27:57.144356001Z","rtype":160,"publisher_id":101,"instrument_id":436},"action":"A","side":"B","price":"1.156540000","size":30,"channel_id":23,"order_id":"10998900913999137553","flags":0,"ts_in_delta":847,"sequence":161564,"symbol":"FCEU SI 20260615 PS"}
{"ts_recv":"2026-04-07T02:27:57.144376262Z","hd":{"ts_event":"2026-04-07T02:27:57.144356001Z","rtype":160,"publisher_id":101,"instrument_id":436},"action":"C","side":"A","price":"1.156630000","size":30,"channel_id":23,"order_id":"1775528877144282192","flags":0,"ts_in_delta":847,"sequence":161564,"symbol":"FCEU SI 20260615 PS"}
{"ts_recv":"2026-04-07T02:27:57.144376262Z","hd":{"ts_event":"2026-04-07T02:27:57.144356001Z","rtype":160,"publisher_id":101,"instrument_id":436},"action":"A","side":"A","price":"1.156640000","size":30,"channel_id":23,"order_id":"1775528877144361745","flags":128,"ts_in_delta":847,"sequence":161564,"symbol":"FCEU SI 20260615 PS"}
{"ts_recv":"2026-04-07T02:27:57.144430135Z","hd":{"ts_event":"2026-04-07T02:27:57.144411215Z","rtype":160,"publisher_id":101,"instrument_id":436},"action":"C","side":"B","price":"1.156520000","size":30,"channel_id":23,"order_id":"10998900913984016665","flags":0,"ts_in_delta":817,"sequence":161565,"symbol":"FCEU SI 20260615 PS"}
{"ts_recv":"2026-04-07T02:27:57.144430135Z","hd":{"ts_event":"2026-04-07T02:27:57.144411215Z","rtype":160,"publisher_id":101,"instrument_id":436},"action":"A","side":"B","price":"1.156540000","size":30,"channel_id":23,"order_id":"10998900913999193155","flags":0,"ts_in_delta":817,"sequence":161565,"symbol":"FCEU SI 20260615 PS"}
{"ts_recv":"2026-04-07T02:27:57.144430135Z","hd":{"ts_event":"2026-04-07T02:27:57.144411215Z","rtype":160,"publisher_id":101,"instrument_id":436},"action":"C","side":"A","price":"1.156620000","size":30,"channel_id":23,"order_id":"1775528877129240857","flags":0,"ts_in_delta":817,"sequence":161565,"symbol":"FCEU SI 20260615 PS"}
{"ts_recv":"2026-04-07T02:27:57.144430135Z","hd":{"ts_event":"2026-04-07T02:27:57.144411215Z","rtype":160,"publisher_id":101,"instrument_id":436},"action":"A","side":"A","price":"1.156640000","size":30,"channel_id":23,"order_id":"1775528877144417347","flags":128,"ts_in_delta":817,"sequence":161565,"symbol":"FCEU SI 20260615 PS"}
{"ts_recv":"2026-04-07T02:27:57.144441078Z","hd":{"ts_event":"2026-04-07T02:27:57.144415689Z","rtype":160,"publisher_id":101,"instrument_id":436},"action":"C","side":"B","price":"1.156540000","size":30,"channel_id":23,"order_id":"10998900913999137553","flags":0,"ts_in_delta":812,"sequence":161566,"symbol":"FCEU SI 20260615 PS"}
{"ts_recv":"2026-04-07T02:27:57.144441078Z","hd":{"ts_event":"2026-04-07T02:27:57.144415689Z","rtype":160,"publisher_id":101,"instrument_id":436},"action":"A","side":"B","price":"1.156530000","size":30,"channel_id":23,"order_id":"10998900913999202849","flags":0,"ts_in_delta":812,"sequence":161566,"symbol":"FCEU SI 20260615 PS"}
{"ts_recv":"2026-04-07T02:27:57.144441078Z","hd":{"ts_event":"2026-04-07T02:27:57.144415689Z","rtype":160,"publisher_id":101,"instrument_id":436},"action":"C","side":"A","price":"1.156640000","size":30,"channel_id":23,"order_id":"1775528877144361745","flags":0,"ts_in_delta":812,"sequence":161566,"symbol":"FCEU SI 20260615 PS"}
{"ts_recv":"2026-04-07T02:27:57.144441078Z","hd":{"ts_event":"2026-04-07T02:27:57.144415689Z","rtype":160,"publisher_id":101,"instrument_id":436},"action":"A","side":"A","price":"1.156630000","size":30,"channel_id":23,"order_id":"1775528877144427041","flags":128,"ts_in_delta":812,"sequence":161566,"symbol":"FCEU SI 20260615 PS"}
{"ts_recv":"2026-04-07T02:27:57.144495089Z","hd":{"ts_event":"2026-04-07T02:27:57.144478415Z","rtype":160,"publisher_id":101,"instrument_id":436},"action":"C","side":"B","price":"1.156530000","size":30,"channel_id":23,"order_id":"10998900913999202849","flags":0,"ts_in_delta":827,"sequence":161567,"symbol":"FCEU SI 20260615 PS"}
{"ts_recv":"2026-04-07T02:27:57.144495089Z","hd":{"ts_event":"2026-04-07T02:27:57.144478415Z","rtype":160,"publisher_id":101,"instrument_id":436},"action":"A","side":"B","price":"1.156540000","size":30,"channel_id":23,"order_id":"10998900913999260246","flags":0,"ts_in_delta":827,"sequence":161567,"symbol":"FCEU SI 20260615 PS"}
{"ts_recv":"2026-04-07T02:27:57.144495089Z","hd":{"ts_event":"2026-04-07T02:27:57.144478415Z","rtype":160,"publisher_id":101,"instrument_id":436},"action":"C","side":"A","price":"1.156630000","size":30,"channel_id":23,"order_id":"1775528877144427041","flags":0,"ts_in_delta":827,"sequence":161567,"symbol":"FCEU SI 20260615 PS"}
{"ts_recv":"2026-04-07T02:27:57.144495089Z","hd":{"ts_event":"2026-04-07T02:27:57.144478415Z","rtype":160,"publisher_id":101,"instrument_id":436},"action":"A","side":"A","price":"1.156640000","size":30,"channel_id":23,"order_id":"1775528877144484438","flags":128,"ts_in_delta":827,"sequence":161567,"symbol":"FCEU SI 20260615 PS"}
{"ts_recv":"2026-04-07T02:27:57.260025616Z","hd":{"ts_event":"2026-04-07T02:27:57.260005099Z","rtype":160,"publisher_id":101,"instrument_id":436},"action":"C","side":"B","price":"1.156540000","size":30,"channel_id":23,"order_id":"10998900913999260246","flags":0,"ts_in_delta":1075,"sequence":161581,"symbol":"FCEU SI 20260615 PS"}
{"ts_recv":"2026-04-07T02:27:57.260025616Z","hd":{"ts_event":"2026-04-07T02:27:57.260005099Z","rtype":160,"publisher_id":101,"instrument_id":436},"action":"A","side":"B","price":"1.156550000","size":30,"channel_id":23,"order_id":"10998900914114787303","flags":0,"ts_in_delta":1075,"sequence":161581,"symbol":"FCEU SI 20260615 PS"}
{"ts_recv":"2026-04-07T02:27:57.260025616Z","hd":{"ts_event":"2026-04-07T02:27:57.260005099Z","rtype":160,"publisher_id":101,"instrument_id":436},"action":"C","side":"A","price":"1.156640000","size":30,"channel_id":23,"order_id":"1775528877144484438","flags":0,"ts_in_delta":1075,"sequence":161581,"symbol":"FCEU SI 20260615 PS"}
{"ts_recv":"2026-04-07T02:27:57.260025616Z","hd":{"ts_event":"2026-04-07T02:27:57.260005099Z","rtype":160,"publisher_id":101,"instrument_id":436},"action":"A","side":"A","price":"1.156650000","size":30,"channel_id":23,"order_id":"1775528877260011495","flags":128,"ts_in_delta":1075,"sequence":161581,"symbol":"FCEU SI 20260615 PS"}
{"ts_recv":"2026-04-07T02:27:57.267682040Z","hd":{"ts_event":"2026-04-07T02:27:57.267663031Z","rtype":160,"publisher_id":101,"instrument_id":436},"action":"C","side":"B","price":"1.156550000","size":30,"channel_id":23,"order_id":"10998900914114787303","flags":0,"ts_in_delta":973,"sequence":161586,"symbol":"FCEU SI 20260615 PS"}
{"ts_recv":"2026-04-07T02:27:57.267682040Z","hd":{"ts_event":"2026-04-07T02:27:57.267663031Z","rtype":160,"publisher_id":101,"instrument_id":436},"action":"A","side":"B","price":"1.156560000","size":30,"channel_id":23,"order_id":"10998900914122444653","flags":0,"ts_in_delta":973,"sequence":161586,"symbol":"FCEU SI 20260615 PS"}
{"ts_recv":"2026-04-07T02:27:57.267682040Z","hd":{"ts_event":"2026-04-07T02:27:57.267663031Z","rtype":160,"publisher_id":101,"instrument_id":436},"action":"C","side":"A","price":"1.156650000","size":30,"channel_id":23,"order_id":"1775528877260011495","flags":0,"ts_in_delta":973,"sequence":161586,"symbol":"FCEU SI 20260615 PS"}
{"ts_recv":"2026-04-07T02:27:57.267682040Z","hd":{"ts_event":"2026-04-07T02:27:57.267663031Z","rtype":160,"publisher_id":101,"instrument_id":436},"action":"A","side":"A","price":"1.156660000","size":30,"channel_id":23,"order_id":"1775528877267668845","flags":128,"ts_in_delta":973,"sequence":161586,"symbol":"FCEU SI 20260615 PS"}
{"ts_recv":"2026-04-07T02:27:57.267741742Z","hd":{"ts_event":"2026-04-07T02:27:57.267725881Z","rtype":160,"publisher_id":101,"instrument_id":436},"action":"C","side":"B","price":"1.156560000","size":30,"channel_id":23,"order_id":"10998900914122444653","flags":0,"ts_in_delta":1082,"sequence":161587,"symbol":"FCEU SI 20260615 PS"}
{"ts_recv":"2026-04-07T02:27:57.267741742Z","hd":{"ts_event":"2026-04-07T02:27:57.267725881Z","rtype":160,"publisher_id":101,"instrument_id":436},"action":"A","side":"B","price":"1.156550000","size":30,"channel_id":23,"order_id":"10998900914122507607","flags":0,"ts_in_delta":1082,"sequence":161587,"symbol":"FCEU SI 20260615 PS"}
{"ts_recv":"2026-04-07T02:27:57.267741742Z","hd":{"ts_event":"2026-04-07T02:27:57.267725881Z","rtype":160,"publisher_id":101,"instrument_id":436},"action":"C","side":"A","price":"1.156660000","size":30,"channel_id":23,"order_id":"1775528877267668845","flags":0,"ts_in_delta":1082,"sequence":161587,"symbol":"FCEU SI 20260615 PS"}
{"ts_recv":"2026-04-07T02:27:57.267741742Z","hd":{"ts_event":"2026-04-07T02:27:57.267725881Z","rtype":160,"publisher_id":101,"instrument_id":436},"action":"A","side":"A","price":"1.156650000","size":30,"channel_id":23,"order_id":"1775528877267731799","flags":128,"ts_in_delta":1082,"sequence":161587,"symbol":"FCEU SI 20260615 PS"}
{"ts_recv":"2026-04-07T02:28:00.460114382Z","hd":{"ts_event":"2026-04-07T02:28:00.460093719Z","rtype":160,"publisher_id":101,"instrument_id":436},"action":"C","side":"B","price":"1.156550000","size":30,"channel_id":23,"order_id":"10998900914122507607","flags":0,"ts_in_delta":913,"sequence":161635,"symbol":"FCEU SI 20260615 PS"}
{"ts_recv":"2026-04-07T02:28:00.460114382Z","hd":{"ts_event":"2026-04-07T02:28:00.460093719Z","rtype":160,"publisher_id":101,"instrument_id":436},"action":"A","side":"B","price":"1.156560000","size":30,"channel_id":23,"order_id":"10998900917314875561","flags":0,"ts_in_delta":913,"sequence":161635,"symbol":"FCEU SI 20260615 PS"}
{"ts_recv":"2026-04-07T02:28:00.460114382Z","hd":{"ts_event":"2026-04-07T02:28:00.460093719Z","rtype":160,"publisher_id":101,"instrument_id":436},"action":"C","side":"A","price":"1.156650000","size":30,"channel_id":23,"order_id":"1775528877267731799","flags":0,"ts_in_delta":913,"sequence":161635,"symbol":"FCEU SI 20260615 PS"}
{"ts_recv":"2026-04-07T02:28:00.460114382Z","hd":{"ts_event":"2026-04-07T02:28:00.460093719Z","rtype":160,"publisher_id":101,"instrument_id":436},"action":"A","side":"A","price":"1.156660000","size":30,"channel_id":23,"order_id":"1775528880460099753","flags":128,"ts_in_delta":913,"sequence":161635,"symbol":"FCEU SI 20260615 PS"}
{"ts_recv":"2026-04-07T02:28:00.460175405Z","hd":{"ts_event":"2026-04-07T02:28:00.460154831Z","rtype":160,"publisher_id":101,"instrument_id":436},"action":"C","side":"B","price":"1.156540000","size":30,"channel_id":23,"order_id":"10998900913999193155","flags":0,"ts_in_delta":914,"sequence":161636,"symbol":"FCEU SI 20260615 PS"}
{"ts_recv":"2026-04-07T02:28:00.460175405Z","hd":{"ts_event":"2026-04-07T02:28:00.460154831Z","rtype":160,"publisher_id":101,"instrument_id":436},"action":"A","side":"B","price":"1.156570000","size":30,"channel_id":23,"order_id":"10998900917314936528","flags":0,"ts_in_delta":914,"sequence":161636,"symbol":"FCEU SI 20260615 PS"}
{"ts_recv":"2026-04-07T02:28:00.460175405Z","hd":{"ts_event":"2026-04-07T02:28:00.460154831Z","rtype":160,"publisher_id":101,"instrument_id":436},"action":"C","side":"A","price":"1.156640000","size":30,"channel_id":23,"order_id":"1775528877144417347","flags":0,"ts_in_delta":914,"sequence":161636,"symbol":"FCEU SI 20260615 PS"}
{"ts_recv":"2026-04-07T02:28:00.460175405Z","hd":{"ts_event":"2026-04-07T02:28:00.460154831Z","rtype":160,"publisher_id":101,"instrument_id":436},"action":"A","side":"A","price":"1.156670000","size":30,"channel_id":23,"order_id":"1775528880460160720","flags":128,"ts_in_delta":914,"sequence":161636,"symbol":"FCEU SI 20260615 PS"}
{"ts_recv":"2026-04-07T02:28:00.460229830Z","hd":{"ts_event":"2026-04-07T02:28:00.460212969Z","rtype":160,"publisher_id":101,"instrument_id":436},"action":"C","side":"B","price":"1.156560000","size":30,"channel_id":23,"order_id":"10998900917314875561","flags":0,"ts_in_delta":908,"sequence":161637,"symbol":"FCEU SI 20260615 PS"}
{"ts_recv":"2026-04-07T02:28:00.460229830Z","hd":{"ts_event":"2026-04-07T02:28:00.460212969Z","rtype":160,"publisher_id":101,"instrument_id":436},"action":"A","side":"B","price":"1.156570000","size":30,"channel_id":23,"order_id":"10998900917314994642","flags":0,"ts_in_delta":908,"sequence":161637,"symbol":"FCEU SI 20260615 PS"}
{"ts_recv":"2026-04-07T02:28:00.460229830Z","hd":{"ts_event":"2026-04-07T02:28:00.460212969Z","rtype":160,"publisher_id":101,"instrument_id":436},"action":"C","side":"A","price":"1.156660000","size":30,"channel_id":23,"order_id":"1775528880460099753","flags":0,"ts_in_delta":908,"sequence":161637,"symbol":"FCEU SI 20260615 PS"}
{"ts_recv":"2026-04-07T02:28:00.460229830Z","hd":{"ts_event":"2026-04-07T02:28:00.460212969Z","rtype":160,"publisher_id":101,"instrument_id":436},"action":"A","side":"A","price":"1.156670000","size":30,"channel_id":23,"order_id":"1775528880460218834","flags":128,"ts_in_delta":908,"sequence":161637,"symbol":"FCEU SI 20260615 PS"}
{"ts_recv":"2026-04-07T02:28:00.465398394Z","hd":{"ts_event":"2026-04-07T02:28:00.465376151Z","rtype":160,"publisher_id":101,"instrument_id":436},"action":"C","side":"B","price":"1.156570000","size":30,"channel_id":23,"order_id":"10998900917314994642","flags":0,"ts_in_delta":915,"sequence":161650,"symbol":"FCEU SI 20260615 PS"}
{"ts_recv":"2026-04-07T02:28:00.465398394Z","hd":{"ts_event":"2026-04-07T02:28:00.465376151Z","rtype":160,"publisher_id":101,"instrument_id":436},"action":"A","side":"B","price":"1.156580000","size":30,"channel_id":23,"order_id":"10998900917320159310","flags":0,"ts_in_delta":915,"sequence":161650,"symbol":"FCEU SI 20260615 PS"}
{"ts_recv":"2026-04-07T02:28:00.465398394Z","hd":{"ts_event":"2026-04-07T02:28:00.465376151Z","rtype":160,"publisher_id":101,"instrument_id":436},"action":"C","side":"A","price":"1.156670000","size":30,"channel_id":23,"order_id":"1775528880460218834","flags":0,"ts_in_delta":915,"sequence":161650,"symbol":"FCEU SI 20260615 PS"}
{"ts_recv":"2026-04-07T02:28:00.465398394Z","hd":{"ts_event":"2026-04-07T02:28:00.465376151Z","rtype":160,"publisher_id":101,"instrument_id":436},"action":"A","side":"A","price":"1.156680000","size":30,"channel_id":23,"order_id":"1775528880465383502","flags":128,"ts_in_delta":915,"sequence":161650,"symbol":"FCEU SI 20260615 PS"}
{"ts_recv":"2026-04-07T02:28:00.465481012Z","hd":{"ts_event":"2026-04-07T02:28:00.465460479Z","rtype":160,"publisher_id":101,"instrument_id":436},"action":"C","side":"B","price":"1.156580000","size":30,"channel_id":23,"order_id":"10998900917320159310","flags":0,"ts_in_delta":931,"sequence":161651,"symbol":"FCEU SI 20260615 PS"}
{"ts_recv":"2026-04-07T02:28:00.465481012Z","hd":{"ts_event":"2026-04-07T02:28:00.465460479Z","rtype":160,"publisher_id":101,"instrument_id":436},"action":"A","side":"B","price":"1.156590000","size":30,"channel_id":23,"order_id":"10998900917320242334","flags":0,"ts_in_delta":931,"sequence":161651,"symbol":"FCEU SI 20260615 PS"}
{"ts_recv":"2026-04-07T02:28:00.465481012Z","hd":{"ts_event":"2026-04-07T02:28:00.465460479Z","rtype":160,"publisher_id":101,"instrument_id":436},"action":"C","side":"A","price":"1.156680000","size":30,"channel_id":23,"order_id":"1775528880465383502","flags":0,"ts_in_delta":931,"sequence":161651,"symbol":"FCEU SI 20260615 PS"}
{"ts_recv":"2026-04-07T02:28:00.465481012Z","hd":{"ts_event":"2026-04-07T02:28:00.465460479Z","rtype":160,"publisher_id":101,"instrument_id":436},"action":"A","side":"A","price":"1.156690000","size":30,"channel_id":23,"order_id":"1775528880465466526","flags":128,"ts_in_delta":931,"sequence":161651,"symbol":"FCEU SI 20260615 PS"}
{"ts_recv":"2026-04-07T02:28:00.465536136Z","hd":{"ts_event":"2026-04-07T02:28:00.465520497Z","rtype":160,"publisher_id":101,"instrument_id":436},"action":"C","side":"B","price":"1.156590000","size":30,"channel_id":23,"order_id":"10998900917320242334","flags":0,"ts_in_delta":907,"sequence":161652,"symbol":"FCEU SI 20260615 PS"}
{"ts_recv":"2026-04-07T02:28:00.465536136Z","hd":{"ts_event":"2026-04-07T02:28:00.465520497Z","rtype":160,"publisher_id":101,"instrument_id":436},"action":"A","side":"B","price":"1.156580000","size":30,"channel_id":23,"order_id":"10998900917320302354","flags":0,"ts_in_delta":907,"sequence":161652,"symbol":"FCEU SI 20260615 PS"}
{"ts_recv":"2026-04-07T02:28:00.465536136Z","hd":{"ts_event":"2026-04-07T02:28:00.465520497Z","rtype":160,"publisher_id":101,"instrument_id":436},"action":"C","side":"A","price":"1.156690000","size":30,"channel_id":23,"order_id":"1775528880465466526","flags":0,"ts_in_delta":907,"sequence":161652,"symbol":"FCEU SI 20260615 PS"}
{"ts_recv":"2026-04-07T02:28:00.465536136Z","hd":{"ts_event":"2026-04-07T02:28:00.465520497Z","rtype":160,"publisher_id":101,"instrument_id":436},"action":"A","side":"A","price":"1.156680000","size":30,"channel_id":23,"order_id":"1775528880465526546","flags":128,"ts_in_delta":907,"sequence":161652,"symbol":"FCEU SI 20260615 PS"}
{"ts_recv":"2026-04-07T02:28:03.730199078Z","hd":{"ts_event":"2026-04-07T02:28:03.730177997Z","rtype":160,"publisher_id":101,"instrument_id":436},"action":"C","side":"B","price":"1.156580000","size":30,"channel_id":23,"order_id":"10998900917320302354","flags":0,"ts_in_delta":1853,"sequence":161709,"symbol":"FCEU SI 20260615 PS"}
{"ts_recv":"2026-04-07T02:28:03.730199078Z","hd":{"ts_event":"2026-04-07T02:28:03.730177997Z","rtype":160,"publisher_id":101,"instrument_id":436},"action":"A","side":"B","price":"1.156570000","size":30,"channel_id":23,"order_id":"10998900920584960523","flags":0,"ts_in_delta":1853,"sequence":161709,"symbol":"FCEU SI 20260615 PS"}
{"ts_recv":"2026-04-07T02:28:03.730199078Z","hd":{"ts_event":"2026-04-07T02:28:03.730177997Z","rtype":160,"publisher_id":101,"instrument_id":436},"action":"C","side":"A","price":"1.156680000","size":30,"channel_id":23,"order_id":"1775528880465526546","flags":0,"ts_in_delta":1853,"sequence":161709,"symbol":"FCEU SI 20260615 PS"}
{"ts_recv":"2026-04-07T02:28:03.730199078Z","hd":{"ts_event":"2026-04-07T02:28:03.730177997Z","rtype":160,"publisher_id":101,"instrument_id":436},"action":"A","side":"A","price":"1.156670000","size":30,"channel_id":23,"order_id":"1775528883730184715","flags":128,"ts_in_delta":1853,"sequence":161709,"symbol":"FCEU SI 20260615 PS"}
{"ts_recv":"2026-04-07T02:28:07.101550235Z","hd":{"ts_event":"2026-04-07T02:28:07.101520707Z","rtype":160,"publisher_id":101,"instrument_id":436},"action":"C","side":"B","price":"1.156570000","size":30,"channel_id":23,"order_id":"10998900920584960523","flags":0,"ts_in_delta":1743,"sequence":161743,"symbol":"FCEU SI 20260615 PS"}
{"ts_recv":"2026-04-07T02:28:07.101550235Z","hd":{"ts_event":"2026-04-07T02:28:07.101520707Z","rtype":160,"publisher_id":101,"instrument_id":436},"action":"A","side":"B","price":"1.156560000","size":30,"channel_id":23,"order_id":"10998900923956305428","flags":0,"ts_in_delta":1743,"sequence":161743,"symbol":"FCEU SI 20260615 PS"}
{"ts_recv":"2026-04-07T02:28:07.101550235Z","hd":{"ts_event":"2026-04-07T02:28:07.101520707Z","rtype":160,"publisher_id":101,"instrument_id":436},"action":"C","side":"A","price":"1.156670000","size":30,"channel_id":23,"order_id":"1775528883730184715","flags":0,"ts_in_delta":1743,"sequence":161743,"symbol":"FCEU SI 20260615 PS"}
{"ts_recv":"2026-04-07T02:28:07.101550235Z","hd":{"ts_event":"2026-04-07T02:28:07.101520707Z","rtype":160,"publisher_id":101,"instrument_id":436},"action":"A","side":"A","price":"1.156660000","size":30,"channel_id":23,"order_id":"1775528887101529620","flags":128,"ts_in_delta":1743,"sequence":161743,"symbol":"FCEU SI 20260615 PS"}
{"ts_recv":"2026-04-07T02:28:07.101646139Z","hd":{"ts_event":"2026-04-07T02:28:07.101627269Z","rtype":160,"publisher_id":101,"instrument_id":436},"action":"C","side":"B","price":"1.156570000","size":30,"channel_id":23,"order_id":"10998900917314936528","flags":0,"ts_in_delta":906,"sequence":161744,"symbol":"FCEU SI 20260615 PS"}
{"ts_recv":"2026-04-07T02:28:07.101646139Z","hd":{"ts_event":"2026-04-07T02:28:07.101627269Z","rtype":160,"publisher_id":101,"instrument_id":436},"action":"A","side":"B","price":"1.156550000","size":30,"channel_id":23,"order_id":"10998900923956409617","flags":0,"ts_in_delta":906,"sequence":161744,"symbol":"FCEU SI 20260615 PS"}
{"ts_recv":"2026-04-07T02:28:07.101646139Z","hd":{"ts_event":"2026-04-07T02:28:07.101627269Z","rtype":160,"publisher_id":101,"instrument_id":436},"action":"C","side":"A","price":"1.156670000","size":30,"channel_id":23,"order_id":"1775528880460160720","flags":0,"ts_in_delta":906,"sequence":161744,"symbol":"FCEU SI 20260615 PS"}
{"ts_recv":"2026-04-07T02:28:07.101646139Z","hd":{"ts_event":"2026-04-07T02:28:07.101627269Z","rtype":160,"publisher_id":101,"instrument_id":436},"action":"A","side":"A","price":"1.156650000","size":30,"channel_id":23,"order_id":"1775528887101633809","flags":128,"ts_in_delta":906,"sequence":161744,"symbol":"FCEU SI 20260615 PS"}
{"ts_recv":"2026-04-07T02:28:07.101708029Z","hd":{"ts_event":"2026-04-07T02:28:07.101691781Z","rtype":160,"publisher_id":101,"instrument_id":436},"action":"C","side":"B","price":"1.156560000","size":30,"channel_id":23,"order_id":"10998900923956305428","flags":0,"ts_in_delta":737,"sequence":161745,"symbol":"FCEU SI 20260615 PS"}
{"ts_recv":"2026-04-07T02:28:07.101708029Z","hd":{"ts_event":"2026-04-07T02:28:07.101691781Z","rtype":160,"publisher_id":101,"instrument_id":436},"action":"A","side":"B","price":"1.156550000","size":30,"channel_id":23,"order_id":"10998900923956473496","flags":0,"ts_in_delta":737,"sequence":161745,"symbol":"FCEU SI 20260615 PS"}
{"ts_recv":"2026-04-07T02:28:07.101708029Z","hd":{"ts_event":"2026-04-07T02:28:07.101691781Z","rtype":160,"publisher_id":101,"instrument_id":436},"action":"C","side":"A","price":"1.156660000","size":30,"channel_id":23,"order_id":"1775528887101529620","flags":0,"ts_in_delta":737,"sequence":161745,"symbol":"FCEU SI 20260615 PS"}
{"ts_recv":"2026-04-07T02:28:07.101708029Z","hd":{"ts_event":"2026-04-07T02:28:07.101691781Z","rtype":160,"publisher_id":101,"instrument_id":436},"action":"A","side":"A","price":"1.156650000","size":30,"channel_id":23,"order_id":"1775528887101697688","flags":128,"ts_in_delta":737,"sequence":161745,"symbol":"FCEU SI 20260615 PS"}
{"ts_recv":"2026-04-07T02:28:11.712733165Z","hd":{"ts_event":"2026-04-07T02:28:11.712713271Z","rtype":160,"publisher_id":101,"instrument_id":436},"action":"C","side":"B","price":"1.156550000","size":30,"channel_id":23,"order_id":"10998900923956473496","flags":0,"ts_in_delta":1043,"sequence":161821,"symbol":"FCEU SI 20260615 PS"}
{"ts_recv":"2026-04-07T02:28:11.712733165Z","hd":{"ts_event":"2026-04-07T02:28:11.712713271Z","rtype":160,"publisher_id":101,"instrument_id":436},"action":"A","side":"B","price":"1.156560000","size":30,"channel_id":23,"order_id":"10998900928567495022","flags":0,"ts_in_delta":1043,"sequence":161821,"symbol":"FCEU SI 20260615 PS"}
{"ts_recv":"2026-04-07T02:28:11.712733165Z","hd":{"ts_event":"2026-04-07T02:28:11.712713271Z","rtype":160,"publisher_id":101,"instrument_id":436},"action":"C","side":"A","price":"1.156650000","size":30,"channel_id":23,"order_id":"1775528887101697688","flags":0,"ts_in_delta":1043,"sequence":161821,"symbol":"FCEU SI 20260615 PS"}
{"ts_recv":"2026-04-07T02:28:11.712733165Z","hd":{"ts_event":"2026-04-07T02:28:11.712713271Z","rtype":160,"publisher_id":101,"instrument_id":436},"action":"A","side":"A","price":"1.156660000","size":30,"channel_id":23,"order_id":"1775528891712719214","flags":128,"ts_in_delta":1043,"sequence":161821,"symbol":"FCEU SI 20260615 PS"}
{"ts_recv":"2026-04-07T02:28:11.712817533Z","hd":{"ts_event":"2026-04-07T02:28:11.712796503Z","rtype":160,"publisher_id":101,"instrument_id":436},"action":"C","side":"B","price":"1.156560000","size":30,"channel_id":23,"order_id":"10998900928567495022","flags":0,"ts_in_delta":872,"sequence":161822,"symbol":"FCEU SI 20260615 PS"}
{"ts_recv":"2026-04-07T02:28:11.712817533Z","hd":{"ts_event":"2026-04-07T02:28:11.712796503Z","rtype":160,"publisher_id":101,"instrument_id":436},"action":"A","side":"B","price":"1.156570000","size":30,"channel_id":23,"order_id":"10998900928567578172","flags":0,"ts_in_delta":872,"sequence":161822,"symbol":"FCEU SI 20260615 PS"}
{"ts_recv":"2026-04-07T02:28:11.712817533Z","hd":{"ts_event":"2026-04-07T02:28:11.712796503Z","rtype":160,"publisher_id":101,"instrument_id":436},"action":"C","side":"A","price":"1.156660000","size":30,"channel_id":23,"order_id":"1775528891712719214","flags":0,"ts_in_delta":872,"sequence":161822,"symbol":"FCEU SI 20260615 PS"}
{"ts_recv":"2026-04-07T02:28:11.712817533Z","hd":{"ts_event":"2026-04-07T02:28:11.712796503Z","rtype":160,"publisher_id":101,"instrument_id":436},"action":"A","side":"A","price":"1.156670000","size":30,"channel_id":23,"order_id":"1775528891712802364","flags":128,"ts_in_delta":872,"sequence":161822,"symbol":"FCEU SI 20260615 PS"}
{"ts_recv":"2026-04-07T02:28:11.712871713Z","hd":{"ts_event":"2026-04-07T02:28:11.712854787Z","rtype":160,"publisher_id":101,"instrument_id":436},"action":"C","side":"B","price":"1.156550000","size":30,"channel_id":23,"order_id":"10998900923956409617","flags":0,"ts_in_delta":846,"sequence":161823,"symbol":"FCEU SI 20260615 PS"}
{"ts_recv":"2026-04-07T02:28:11.712871713Z","hd":{"ts_event":"2026-04-07T02:28:11.712854787Z","rtype":160,"publisher_id":101,"instrument_id":436},"action":"A","side":"B","price":"1.156570000","size":30,"channel_id":23,"order_id":"10998900928567636523","flags":0,"ts_in_delta":846,"sequence":161823,"symbol":"FCEU SI 20260615 PS"}
{"ts_recv":"2026-04-07T02:28:11.712871713Z","hd":{"ts_event":"2026-04-07T02:28:11.712854787Z","rtype":160,"publisher_id":101,"instrument_id":436},"action":"C","side":"A","price":"1.156650000","size":30,"channel_id":23,"order_id":"1775528887101633809","flags":0,"ts_in_delta":846,"sequence":161823,"symbol":"FCEU SI 20260615 PS"}
{"ts_recv":"2026-04-07T02:28:11.712871713Z","hd":{"ts_event":"2026-04-07T02:28:11.712854787Z","rtype":160,"publisher_id":101,"instrument_id":436},"action":"A","side":"A","price":"1.156670000","size":30,"channel_id":23,"order_id":"1775528891712860715","flags":128,"ts_in_delta":846,"sequence":161823,"symbol":"FCEU SI 20260615 PS"}
{"ts_recv":"2026-04-07T02:28:11.712883525Z","hd":{"ts_event":"2026-04-07T02:28:11.712856215Z","rtype":160,"publisher_id":101,"instrument_id":436},"action":"C","side":"B","price":"1.156570000","size":30,"channel_id":23,"order_id":"10998900928567578172","flags":0,"ts_in_delta":862,"sequence":161824,"symbol":"FCEU SI 20260615 PS"}
{"ts_recv":"2026-04-07T02:28:11.712883525Z","hd":{"ts_event":"2026-04-07T02:28:11.712856215Z","rtype":160,"publisher_id":101,"instrument_id":436},"action":"A","side":"B","price":"1.156560000","size":30,"channel_id":23,"order_id":"10998900928567644371","flags":0,"ts_in_delta":862,"sequence":161824,"symbol":"FCEU SI 20260615 PS"}
{"ts_recv":"2026-04-07T02:28:11.712883525Z","hd":{"ts_event":"2026-04-07T02:28:11.712856215Z","rtype":160,"publisher_id":101,"instrument_id":436},"action":"C","side":"A","price":"1.156670000","size":30,"channel_id":23,"order_id":"1775528891712802364","flags":0,"ts_in_delta":862,"sequence":161824,"symbol":"FCEU SI 20260615 PS"}
{"ts_recv":"2026-04-07T02:28:11.712883525Z","hd":{"ts_event":"2026-04-07T02:28:11.712856215Z","rtype":160,"publisher_id":101,"instrument_id":436},"action":"A","side":"A","price":"1.156660000","size":30,"channel_id":23,"order_id":"1775528891712868563","flags":128,"ts_in_delta":862,"sequence":161824,"symbol":"FCEU SI 20260615 PS"}
{"ts_recv":"2026-04-07T02:28:11.712939394Z","hd":{"ts_event":"2026-04-07T02:28:11.712920395Z","rtype":160,"publisher_id":101,"instrument_id":436},"action":"C","side":"B","price":"1.156560000","size":30,"channel_id":23,"order_id":"10998900928567644371","flags":0,"ts_in_delta":1128,"sequence":161825,"symbol":"FCEU SI 20260615 PS"}
{"ts_recv":"2026-04-07T02:28:11.712939394Z","hd":{"ts_event":"2026-04-07T02:28:11.712920395Z","rtype":160,"publisher_id":101,"instrument_id":436},"action":"A","side":"B","price":"1.156570000","size":30,"channel_id":23,"order_id":"10998900928567702014","flags":0,"ts_in_delta":1128,"sequence":161825,"symbol":"FCEU SI 20260615 PS"}
{"ts_recv":"2026-04-07T02:28:11.712939394Z","hd":{"ts_event":"2026-04-07T02:28:11.712920395Z","rtype":160,"publisher_id":101,"instrument_id":436},"action":"C","side":"A","price":"1.156660000","size":30,"channel_id":23,"order_id":"1775528891712868563","flags":0,"ts_in_delta":1128,"sequence":161825,"symbol":"FCEU SI 20260615 PS"}
{"ts_recv":"2026-04-07T02:28:11.712939394Z","hd":{"ts_event":"2026-04-07T02:28:11.712920395Z","rtype":160,"publisher_id":101,"instrument_id":436},"action":"A","side":"A","price":"1.156670000","size":30,"channel_id":23,"order_id":"1775528891712926206","flags":128,"ts_in_delta":1128,"sequence":161825,"symbol":"FCEU SI 20260615 PS"}
{"ts_recv":"2026-04-07T02:28:17.535328328Z","hd":{"ts_event":"2026-04-07T02:28:17.535306639Z","rtype":160,"publisher_id":101,"instrument_id":436},"action":"C","side":"B","price":"1.156570000","size":30,"channel_id":23,"order_id":"10998900928567702014","flags":0,"ts_in_delta":929,"sequence":161885,"symbol":"FCEU SI 20260615 PS"}
{"ts_recv":"2026-04-07T02:28:17.535328328Z","hd":{"ts_event":"2026-04-07T02:28:17.535306639Z","rtype":160,"publisher_id":101,"instrument_id":436},"action":"A","side":"B","price":"1.156580000","size":30,"channel_id":23,"order_id":"10998900934390089082","flags":0,"ts_in_delta":929,"sequence":161885,"symbol":"FCEU SI 20260615 PS"}
{"ts_recv":"2026-04-07T02:28:17.535328328Z","hd":{"ts_event":"2026-04-07T02:28:17.535306639Z","rtype":160,"publisher_id":101,"instrument_id":436},"action":"C","side":"A","price":"1.156670000","size":30,"channel_id":23,"order_id":"1775528891712926206","flags":0,"ts_in_delta":929,"sequence":161885,"symbol":"FCEU SI 20260615 PS"}
{"ts_recv":"2026-04-07T02:28:17.535328328Z","hd":{"ts_event":"2026-04-07T02:28:17.535306639Z","rtype":160,"publisher_id":101,"instrument_id":436},"action":"A","side":"A","price":"1.156680000","size":30,"channel_id":23,"order_id":"1775528897535313274","flags":128,"ts_in_delta":929,"sequence":161885,"symbol":"FCEU SI 20260615 PS"}
{"ts_recv":"2026-04-07T02:28:18.099349689Z","hd":{"ts_event":"2026-04-07T02:28:18.099325871Z","rtype":160,"publisher_id":101,"instrument_id":436},"action":"C","side":"B","price":"1.156580000","size":30,"channel_id":23,"order_id":"10998900934390089082","flags":0,"ts_in_delta":932,"sequence":161897,"symbol":"FCEU SI 20260615 PS"}
{"ts_recv":"2026-04-07T02:28:18.099349689Z","hd":{"ts_event":"2026-04-07T02:28:18.099325871Z","rtype":160,"publisher_id":101,"instrument_id":436},"action":"A","side":"B","price":"1.156570000","size":30,"channel_id":23,"order_id":"10998900934954110064","flags":0,"ts_in_delta":932,"sequence":161897,"symbol":"FCEU SI 20260615 PS"}
{"ts_recv":"2026-04-07T02:28:18.099349689Z","hd":{"ts_event":"2026-04-07T02:28:18.099325871Z","rtype":160,"publisher_id":101,"instrument_id":436},"action":"C","side":"A","price":"1.156680000","size":30,"channel_id":23,"order_id":"1775528897535313274","flags":0,"ts_in_delta":932,"sequence":161897,"symbol":"FCEU SI 20260615 PS"}
{"ts_recv":"2026-04-07T02:28:18.099349689Z","hd":{"ts_event":"2026-04-07T02:28:18.099325871Z","rtype":160,"publisher_id":101,"instrument_id":436},"action":"A","side":"A","price":"1.156670000","size":30,"channel_id":23,"order_id":"1775528898099334256","flags":128,"ts_in_delta":932,"sequence":161897,"symbol":"FCEU SI 20260615 PS"}
{"ts_recv":"2026-04-07T02:28:18.256534467Z","hd":{"ts_event":"2026-04-07T02:28:18.256515511Z","rtype":160,"publisher_id":101,"instrument_id":436},"action":"C","side":"B","price":"1.156570000","size":30,"channel_id":23,"order_id":"10998900934954110064","flags":0,"ts_in_delta":866,"sequence":161905,"symbol":"FCEU SI 20260615 PS"}
{"ts_recv":"2026-04-07T02:28:18.256534467Z","hd":{"ts_event":"2026-04-07T02:28:18.256515511Z","rtype":160,"publisher_id":101,"instrument_id":436},"action":"A","side":"B","price":"1.156560000","size":30,"channel_id":23,"order_id":"10998900935111297773","flags":0,"ts_in_delta":866,"sequence":161905,"symbol":"FCEU SI 20260615 PS"}
{"ts_recv":"2026-04-07T02:28:18.256534467Z","hd":{"ts_event":"2026-04-07T02:28:18.256515511Z","rtype":160,"publisher_id":101,"instrument_id":436},"action":"C","side":"A","price":"1.156670000","size":30,"channel_id":23,"order_id":"1775528898099334256","flags":0,"ts_in_delta":866,"sequence":161905,"symbol":"FCEU SI 20260615 PS"}
{"ts_recv":"2026-04-07T02:28:18.256534467Z","hd":{"ts_event":"2026-04-07T02:28:18.256515511Z","rtype":160,"publisher_id":101,"instrument_id":436},"action":"A","side":"A","price":"1.156660000","size":30,"channel_id":23,"order_id":"1775528898256521965","flags":128,"ts_in_delta":866,"sequence":161905,"symbol":"FCEU SI 20260615 PS"}
{"ts_recv":"2026-04-07T02:28:18.256616194Z","hd":{"ts_event":"2026-04-07T02:28:18.256595787Z","rtype":160,"publisher_id":101,"instrument_id":436},"action":"C","side":"B","price":"1.156560000","size":30,"channel_id":23,"order_id":"10998900935111297773","flags":0,"ts_in_delta":852,"sequence":161906,"symbol":"FCEU SI 20260615 PS"}
{"ts_recv":"2026-04-07T02:28:18.256616194Z","hd":{"ts_event":"2026-04-07T02:28:18.256595787Z","rtype":160,"publisher_id":101,"instrument_id":436},"action":"A","side":"B","price":"1.156550000","size":30,"channel_id":23,"order_id":"10998900935111378120","flags":0,"ts_in_delta":852,"sequence":161906,"symbol":"FCEU SI 20260615 PS"}
{"ts_recv":"2026-04-07T02:28:18.256616194Z","hd":{"ts_event":"2026-04-07T02:28:18.256595787Z","rtype":160,"publisher_id":101,"instrument_id":436},"action":"C","side":"A","price":"1.156660000","size":30,"channel_id":23,"order_id":"1775528898256521965","flags":0,"ts_in_delta":852,"sequence":161906,"symbol":"FCEU SI 20260615 PS"}
{"ts_recv":"2026-04-07T02:28:18.256616194Z","hd":{"ts_event":"2026-04-07T02:28:18.256595787Z","rtype":160,"publisher_id":101,"instrument_id":436},"action":"A","side":"A","price":"1.156650000","size":30,"channel_id":23,"order_id":"1775528898256602312","flags":128,"ts_in_delta":852,"sequence":161906,"symbol":"FCEU SI 20260615 PS"}
{"ts_recv":"2026-04-07T02:28:18.256671472Z","hd":{"ts_event":"2026-04-07T02:28:18.256651685Z","rtype":160,"publisher_id":101,"instrument_id":436},"action":"C","side":"B","price":"1.156570000","size":30,"channel_id":23,"order_id":"10998900928567636523","flags":0,"ts_in_delta":850,"sequence":161907,"symbol":"FCEU SI 20260615 PS"}
{"ts_recv":"2026-04-07T02:28:18.256671472Z","hd":{"ts_event":"2026-04-07T02:28:18.256651685Z","rtype":160,"publisher_id":101,"instrument_id":436},"action":"A","side":"B","price":"1.156550000","size":30,"channel_id":23,"order_id":"10998900935111433636","flags":0,"ts_in_delta":850,"sequence":161907,"symbol":"FCEU SI 20260615 PS"}
{"ts_recv":"2026-04-07T02:28:18.256671472Z","hd":{"ts_event":"2026-04-07T02:28:18.256651685Z","rtype":160,"publisher_id":101,"instrument_id":436},"action":"C","side":"A","price":"1.156670000","size":30,"channel_id":23,"order_id":"1775528891712860715","flags":0,"ts_in_delta":850,"sequence":161907,"symbol":"FCEU SI 20260615 PS"}
{"ts_recv":"2026-04-07T02:28:18.256671472Z","hd":{"ts_event":"2026-04-07T02:28:18.256651685Z","rtype":160,"publisher_id":101,"instrument_id":436},"action":"A","side":"A","price":"1.156650000","size":30,"channel_id":23,"order_id":"1775528898256657828","flags":128,"ts_in_delta":850,"sequence":161907,"symbol":"FCEU SI 20260615 PS"}
{"ts_recv":"2026-04-07T02:28:18.256681456Z","hd":{"ts_event":"2026-04-07T02:28:18.256655373Z","rtype":160,"publisher_id":101,"instrument_id":436},"action":"C","side":"B","price":"1.156550000","size":30,"channel_id":23,"order_id":"10998900935111378120","flags":0,"ts_in_delta":1036,"sequence":161908,"symbol":"FCEU SI 20260615 PS"}
{"ts_recv":"2026-04-07T02:28:18.256681456Z","hd":{"ts_event":"2026-04-07T02:28:18.256655373Z","rtype":160,"publisher_id":101,"instrument_id":436},"action":"A","side":"B","price":"1.156560000","size":30,"channel_id":23,"order_id":"10998900935111444068","flags":0,"ts_in_delta":1036,"sequence":161908,"symbol":"FCEU SI 20260615 PS"}
{"ts_recv":"2026-04-07T02:28:18.256681456Z","hd":{"ts_event":"2026-04-07T02:28:18.256655373Z","rtype":160,"publisher_id":101,"instrument_id":436},"action":"C","side":"A","price":"1.156650000","size":30,"channel_id":23,"order_id":"1775528898256602312","flags":0,"ts_in_delta":1036,"sequence":161908,"symbol":"FCEU SI 20260615 PS"}
{"ts_recv":"2026-04-07T02:28:18.256681456Z","hd":{"ts_event":"2026-04-07T02:28:18.256655373Z","rtype":160,"publisher_id":101,"instrument_id":436},"action":"A","side":"A","price":"1.156660000","size":30,"channel_id":23,"order_id":"1775528898256668260","flags":128,"ts_in_delta":1036,"sequence":161908,"symbol":"FCEU SI 20260615 PS"}
{"ts_recv":"2026-04-07T02:28:18.256739422Z","hd":{"ts_event":"2026-04-07T02:28:18.256721669Z","rtype":160,"publisher_id":101,"instrument_id":436},"action":"C","side":"B","price":"1.156560000","size":30,"channel_id":23,"order_id":"10998900935111444068","flags":0,"ts_in_delta":1036,"sequence":161909,"symbol":"FCEU SI 20260615 PS"}
{"ts_recv":"2026-04-07T02:28:18.256739422Z","hd":{"ts_event":"2026-04-07T02:28:18.256721669Z","rtype":160,"publisher_id":101,"instrument_id":436},"action":"A","side":"B","price":"1.156550000","size":30,"channel_id":23,"order_id":"10998900935111503402","flags":0,"ts_in_delta":1036,"sequence":161909,"symbol":"FCEU SI 20260615 PS"}
{"ts_recv":"2026-04-07T02:28:18.256739422Z","hd":{"ts_event":"2026-04-07T02:28:18.256721669Z","rtype":160,"publisher_id":101,"instrument_id":436},"action":"C","side":"A","price":"1.156660000","size":30,"channel_id":23,"order_id":"1775528898256668260","flags":0,"ts_in_delta":1036,"sequence":161909,"symbol":"FCEU SI 20260615 PS"}
{"ts_recv":"2026-04-07T02:28:18.256739422Z","hd":{"ts_event":"2026-04-07T02:28:18.256721669Z","rtype":160,"publisher_id":101,"instrument_id":436},"action":"A","side":"A","price":"1.156650000","size":30,"channel_id":23,"order_id":"1775528898256727594","flags":128,"ts_in_delta":1036,"sequence":161909,"symbol":"FCEU SI 20260615 PS"}
{"ts_recv":"2026-04-07T02:28:18.554061652Z","hd":{"ts_event":"2026-04-07T02:28:18.554042131Z","rtype":160,"publisher_id":101,"instrument_id":436},"action":"C","side":"B","price":"1.156550000","size":30,"channel_id":23,"order_id":"10998900935111503402","flags":0,"ts_in_delta":1132,"sequence":161928,"symbol":"FCEU SI 20260615 PS"}
{"ts_recv":"2026-04-07T02:28:18.554061652Z","hd":{"ts_event":"2026-04-07T02:28:18.554042131Z","rtype":160,"publisher_id":101,"instrument_id":436},"action":"A","side":"B","price":"1.156560000","size":30,"channel_id":23,"order_id":"10998900935408823751","flags":0,"ts_in_delta":1132,"sequence":161928,"symbol":"FCEU SI 20260615 PS"}
{"ts_recv":"2026-04-07T02:28:18.554061652Z","hd":{"ts_event":"2026-04-07T02:28:18.554042131Z","rtype":160,"publisher_id":101,"instrument_id":436},"action":"C","side":"A","price":"1.156650000","size":30,"channel_id":23,"order_id":"1775528898256727594","flags":0,"ts_in_delta":1132,"sequence":161928,"symbol":"FCEU SI 20260615 PS"}
{"ts_recv":"2026-04-07T02:28:18.554061652Z","hd":{"ts_event":"2026-04-07T02:28:18.554042131Z","rtype":160,"publisher_id":101,"instrument_id":436},"action":"A","side":"A","price":"1.156660000","size":30,"channel_id":23,"order_id":"1775528898554047943","flags":128,"ts_in_delta":1132,"sequence":161928,"symbol":"FCEU SI 20260615 PS"}
{"ts_recv":"2026-04-07T02:28:18.554113205Z","hd":{"ts_event":"2026-04-07T02:28:18.554093529Z","rtype":160,"publisher_id":101,"instrument_id":436},"action":"C","side":"B","price":"1.156550000","size":30,"channel_id":23,"order_id":"10998900935111433636","flags":0,"ts_in_delta":847,"sequence":161929,"symbol":"FCEU SI 20260615 PS"}
{"ts_recv":"2026-04-07T02:28:18.554113205Z","hd":{"ts_event":"2026-04-07T02:28:18.554093529Z","rtype":160,"publisher_id":101,"instrument_id":436},"action":"A","side":"B","price":"1.156570000","size":30,"channel_id":23,"order_id":"10998900935408875172","flags":0,"ts_in_delta":847,"sequence":161929,"symbol":"FCEU SI 20260615 PS"}
{"ts_recv":"2026-04-07T02:28:18.554113205Z","hd":{"ts_event":"2026-04-07T02:28:18.554093529Z","rtype":160,"publisher_id":101,"instrument_id":436},"action":"C","side":"A","price":"1.156650000","size":30,"channel_id":23,"order_id":"1775528898256657828","flags":0,"ts_in_delta":847,"sequence":161929,"symbol":"FCEU SI 20260615 PS"}
{"ts_recv":"2026-04-07T02:28:18.554113205Z","hd":{"ts_event":"2026-04-07T02:28:18.554093529Z","rtype":160,"publisher_id":101,"instrument_id":436},"action":"A","side":"A","price":"1.156670000","size":30,"channel_id":23,"order_id":"1775528898554099364","flags":128,"ts_in_delta":847,"sequence":161929,"symbol":"FCEU SI 20260615 PS"}
{"ts_recv":"2026-04-07T02:28:18.554169905Z","hd":{"ts_event":"2026-04-07T02:28:18.554152245Z","rtype":160,"publisher_id":101,"instrument_id":436},"action":"C","side":"B","price":"1.156560000","size":30,"channel_id":23,"order_id":"10998900935408823751","flags":0,"ts_in_delta":842,"sequence":161930,"symbol":"FCEU SI 20260615 PS"}
{"ts_recv":"2026-04-07T02:28:18.554169905Z","hd":{"ts_event":"2026-04-07T02:28:18.554152245Z","rtype":160,"publisher_id":101,"instrument_id":436},"action":"A","side":"B","price":"1.156570000","size":30,"channel_id":23,"order_id":"10998900935408933714","flags":0,"ts_in_delta":842,"sequence":161930,"symbol":"FCEU SI 20260615 PS"}
{"ts_recv":"2026-04-07T02:28:18.554169905Z","hd":{"ts_event":"2026-04-07T02:28:18.554152245Z","rtype":160,"publisher_id":101,"instrument_id":436},"action":"C","side":"A","price":"1.156660000","size":30,"channel_id":23,"order_id":"1775528898554047943","flags":0,"ts_in_delta":842,"sequence":161930,"symbol":"FCEU SI 20260615 PS"}
{"ts_recv":"2026-04-07T02:28:18.554169905Z","hd":{"ts_event":"2026-04-07T02:28:18.554152245Z","rtype":160,"publisher_id":101,"instrument_id":436},"action":"A","side":"A","price":"1.156670000","size":30,"channel_id":23,"order_id":"1775528898554157906","flags":128,"ts_in_delta":842,"sequence":161930,"symbol":"FCEU SI 20260615 PS"}
{"ts_recv":"2026-04-07T02:28:29.648515633Z","hd":{"ts_event":"2026-04-07T02:28:29.648495153Z","rtype":160,"publisher_id":101,"instrument_id":436},"action":"C","side":"B","price":"1.156570000","size":30,"channel_id":23,"order_id":"10998900935408933714","flags":0,"ts_in_delta":829,"sequence":161996,"symbol":"FCEU SI 20260615 PS"}
{"ts_recv":"2026-04-07T02:28:29.648515633Z","hd":{"ts_event":"2026-04-07T02:28:29.648495153Z","rtype":160,"publisher_id":101,"instrument_id":436},"action":"A","side":"B","price":"1.156580000","size":30,"channel_id":23,"order_id":"10998900946503276967","flags":0,"ts_in_delta":829,"sequence":161996,"symbol":"FCEU SI 20260615 PS"}
{"ts_recv":"2026-04-07T02:28:29.648515633Z","hd":{"ts_event":"2026-04-07T02:28:29.648495153Z","rtype":160,"publisher_id":101,"instrument_id":436},"action":"C","side":"A","price":"1.156670000","size":30,"channel_id":23,"order_id":"1775528898554157906","flags":0,"ts_in_delta":829,"sequence":161996,"symbol":"FCEU SI 20260615 PS"}
{"ts_recv":"2026-04-07T02:28:29.648515633Z","hd":{"ts_event":"2026-04-07T02:28:29.648495153Z","rtype":160,"publisher_id":101,"instrument_id":436},"action":"A","side":"A","price":"1.156680000","size":30,"channel_id":23,"order_id":"1775528909648501159","flags":128,"ts_in_delta":829,"sequence":161996,"symbol":"FCEU SI 20260615 PS"}
{"ts_recv":"2026-04-07T02:28:29.648572424Z","hd":{"ts_event":"2026-04-07T02:28:29.648552223Z","rtype":160,"publisher_id":101,"instrument_id":436},"action":"C","side":"B","price":"1.156570000","size":30,"channel_id":23,"order_id":"10998900935408875172","flags":0,"ts_in_delta":938,"sequence":161997,"symbol":"FCEU SI 20260615 PS"}
{"ts_recv":"2026-04-07T02:28:29.648572424Z","hd":{"ts_event":"2026-04-07T02:28:29.648552223Z","rtype":160,"publisher_id":101,"instrument_id":436},"action":"A","side":"B","price":"1.156590000","size":30,"channel_id":23,"order_id":"10998900946503334147","flags":0,"ts_in_delta":938,"sequence":161997,"symbol":"FCEU SI 20260615 PS"}
{"ts_recv":"2026-04-07T02:28:29.648572424Z","hd":{"ts_event":"2026-04-07T02:28:29.648552223Z","rtype":160,"publisher_id":101,"instrument_id":436},"action":"C","side":"A","price":"1.156670000","size":30,"channel_id":23,"order_id":"1775528898554099364","flags":0,"ts_in_delta":938,"sequence":161997,"symbol":"FCEU SI 20260615 PS"}
{"ts_recv":"2026-04-07T02:28:29.648572424Z","hd":{"ts_event":"2026-04-07T02:28:29.648552223Z","rtype":160,"publisher_id":101,"instrument_id":436},"action":"A","side":"A","price":"1.156690000","size":30,"channel_id":23,"order_id":"1775528909648558339","flags":128,"ts_in_delta":938,"sequence":161997,"symbol":"FCEU SI 20260615 PS"}
{"ts_recv":"2026-04-07T02:28:29.648628317Z","hd":{"ts_event":"2026-04-07T02:28:29.648611713Z","rtype":160,"publisher_id":101,"instrument_id":436},"action":"C","side":"B","price":"1.156580000","size":30,"channel_id":23,"order_id":"10998900946503276967","flags":0,"ts_in_delta":858,"sequence":161998,"symbol":"FCEU SI 20260615 PS"}
{"ts_recv":"2026-04-07T02:28:29.648628317Z","hd":{"ts_event":"2026-04-07T02:28:29.648611713Z","rtype":160,"publisher_id":101,"instrument_id":436},"action":"A","side":"B","price":"1.156590000","size":30,"channel_id":23,"order_id":"10998900946503393321","flags":0,"ts_in_delta":858,"sequence":161998,"symbol":"FCEU SI 20260615 PS"}
{"ts_recv":"2026-04-07T02:28:29.648628317Z","hd":{"ts_event":"2026-04-07T02:28:29.648611713Z","rtype":160,"publisher_id":101,"instrument_id":436},"action":"C","side":"A","price":"1.156680000","size":30,"channel_id":23,"order_id":"1775528909648501159","flags":0,"ts_in_delta":858,"sequence":161998,"symbol":"FCEU SI 20260615 PS"}
{"ts_recv":"2026-04-07T02:28:29.648628317Z","hd":{"ts_event":"2026-04-07T02:28:29.648611713Z","rtype":160,"publisher_id":101,"instrument_id":436},"action":"A","side":"A","price":"1.156690000","size":30,"channel_id":23,"order_id":"1775528909648617513","flags":128,"ts_in_delta":858,"sequence":161998,"symbol":"FCEU SI 20260615 PS"}
{"ts_recv":"2026-04-07T02:28:29.834996826Z","hd":{"ts_event":"2026-04-07T02:28:29.834965741Z","rtype":160,"publisher_id":101,"instrument_id":436},"action":"C","side":"B","price":"1.156590000","size":30,"channel_id":23,"order_id":"10998900946503393321","flags":0,"ts_in_delta":1527,"sequence":162007,"symbol":"FCEU SI 20260615 PS"}
{"ts_recv":"2026-04-07T02:28:29.834996826Z","hd":{"ts_event":"2026-04-07T02:28:29.834965741Z","rtype":160,"publisher_id":101,"instrument_id":436},"action":"A","side":"B","price":"1.156580000","size":30,"channel_id":23,"order_id":"10998900946689754636","flags":0,"ts_in_delta":1527,"sequence":162007,"symbol":"FCEU SI 20260615 PS"}
{"ts_recv":"2026-04-07T02:28:29.834996826Z","hd":{"ts_event":"2026-04-07T02:28:29.834965741Z","rtype":160,"publisher_id":101,"instrument_id":436},"action":"C","side":"A","price":"1.156690000","size":30,"channel_id":23,"order_id":"1775528909648617513","flags":0,"ts_in_delta":1527,"sequence":162007,"symbol":"FCEU SI 20260615 PS"}
{"ts_recv":"2026-04-07T02:28:29.834996826Z","hd":{"ts_event":"2026-04-07T02:28:29.834965741Z","rtype":160,"publisher_id":101,"instrument_id":436},"action":"A","side":"A","price":"1.156680000","size":30,"channel_id":23,"order_id":"1775528909834978828","flags":128,"ts_in_delta":1527,"sequence":162007,"symbol":"FCEU SI 20260615 PS"}
{"ts_recv":"2026-04-07T02:28:29.835052212Z","hd":{"ts_event":"2026-04-07T02:28:29.835031675Z","rtype":160,"publisher_id":101,"instrument_id":436},"action":"C","side":"B","price":"1.156590000","size":30,"channel_id":23,"order_id":"10998900946503334147","flags":0,"ts_in_delta":1053,"sequence":162008,"symbol":"FCEU SI 20260615 PS"}
{"ts_recv":"2026-04-07T02:28:29.835052212Z","hd":{"ts_event":"2026-04-07T02:28:29.835031675Z","rtype":160,"publisher_id":101,"instrument_id":436},"action":"A","side":"B","price":"1.156570000","size":30,"channel_id":23,"order_id":"10998900946689813764","flags":0,"ts_in_delta":1053,"sequence":162008,"symbol":"FCEU SI 20260615 PS"}
{"ts_recv":"2026-04-07T02:28:29.835052212Z","hd":{"ts_event":"2026-04-07T02:28:29.835031675Z","rtype":160,"publisher_id":101,"instrument_id":436},"action":"C","side":"A","price":"1.156690000","size":30,"channel_id":23,"order_id":"1775528909648558339","flags":0,"ts_in_delta":1053,"sequence":162008,"symbol":"FCEU SI 20260615 PS"}
{"ts_recv":"2026-04-07T02:28:29.835052212Z","hd":{"ts_event":"2026-04-07T02:28:29.835031675Z","rtype":160,"publisher_id":101,"instrument_id":436},"action":"A","side":"A","price":"1.156670000","size":30,"channel_id":23,"order_id":"1775528909835037956","flags":128,"ts_in_delta":1053,"sequence":162008,"symbol":"FCEU SI 20260615 PS"}
{"ts_recv":"2026-04-07T02:28:29.835105977Z","hd":{"ts_event":"2026-04-07T02:28:29.835090311Z","rtype":160,"publisher_id":101,"instrument_id":436},"action":"C","side":"B","price":"1.156580000","size":30,"channel_id":23,"order_id":"10998900946689754636","flags":0,"ts_in_delta":886,"sequence":162009,"symbol":"FCEU SI 20260615 PS"}
{"ts_recv":"2026-04-07T02:28:29.835105977Z","hd":{"ts_event":"2026-04-07T02:28:29.835090311Z","rtype":160,"publisher_id":101,"instrument_id":436},"action":"A","side":"B","price":"1.156570000","size":30,"channel_id":23,"order_id":"10998900946689872129","flags":0,"ts_in_delta":886,"sequence":162009,"symbol":"FCEU SI 20260615 PS"}
{"ts_recv":"2026-04-07T02:28:29.835105977Z","hd":{"ts_event":"2026-04-07T02:28:29.835090311Z","rtype":160,"publisher_id":101,"instrument_id":436},"action":"C","side":"A","price":"1.156680000","size":30,"channel_id":23,"order_id":"1775528909834978828","flags":0,"ts_in_delta":886,"sequence":162009,"symbol":"FCEU SI 20260615 PS"}
{"ts_recv":"2026-04-07T02:28:29.835105977Z","hd":{"ts_event":"2026-04-07T02:28:29.835090311Z","rtype":160,"publisher_id":101,"instrument_id":436},"action":"A","side":"A","price":"1.156670000","size":30,"channel_id":23,"order_id":"1775528909835096321","flags":128,"ts_in_delta":886,"sequence":162009,"symbol":"FCEU SI 20260615 PS"}
{"ts_recv":"2026-04-07T02:28:29.847350362Z","hd":{"ts_event":"2026-04-07T02:28:29.847330145Z","rtype":160,"publisher_id":101,"instrument_id":436},"action":"C","side":"B","price":"1.156570000","size":30,"channel_id":23,"order_id":"10998900946689872129","flags":0,"ts_in_delta":1028,"sequence":162019,"symbol":"FCEU SI 20260615 PS"}
{"ts_recv":"2026-04-07T02:28:29.847350362Z","hd":{"ts_event":"2026-04-07T02:28:29.847330145Z","rtype":160,"publisher_id":101,"instrument_id":436},"action":"A","side":"B","price":"1.156560000","size":30,"channel_id":23,"order_id":"10998900946702111908","flags":0,"ts_in_delta":1028,"sequence":162019,"symbol":"FCEU SI 20260615 PS"}
{"ts_recv":"2026-04-07T02:28:29.847350362Z","hd":{"ts_event":"2026-04-07T02:28:29.847330145Z","rtype":160,"publisher_id":101,"instrument_id":436},"action":"C","side":"A","price":"1.156670000","size":30,"channel_id":23,"order_id":"1775528909835096321","flags":0,"ts_in_delta":1028,"sequence":162019,"symbol":"FCEU SI 20260615 PS"}
{"ts_recv":"2026-04-07T02:28:29.847350362Z","hd":{"ts_event":"2026-04-07T02:28:29.847330145Z","rtype":160,"publisher_id":101,"instrument_id":436},"action":"A","side":"A","price":"1.156660000","size":30,"channel_id":23,"order_id":"1775528909847336100","flags":128,"ts_in_delta":1028,"sequence":162019,"symbol":"FCEU SI 20260615 PS"}
{"ts_recv":"2026-04-07T02:28:29.847432865Z","hd":{"ts_event":"2026-04-07T02:28:29.847413103Z","rtype":160,"publisher_id":101,"instrument_id":436},"action":"C","side":"B","price":"1.156560000","size":30,"channel_id":23,"order_id":"10998900946702111908","flags":0,"ts_in_delta":867,"sequence":162020,"symbol":"FCEU SI 20260615 PS"}
{"ts_recv":"2026-04-07T02:28:29.847432865Z","hd":{"ts_event":"2026-04-07T02:28:29.847413103Z","rtype":160,"publisher_id":101,"instrument_id":436},"action":"A","side":"B","price":"1.156550000","size":30,"channel_id":23,"order_id":"10998900946702195279","flags":0,"ts_in_delta":867,"sequence":162020,"symbol":"FCEU SI 20260615 PS"}
{"ts_recv":"2026-04-07T02:28:29.847432865Z","hd":{"ts_event":"2026-04-07T02:28:29.847413103Z","rtype":160,"publisher_id":101,"instrument_id":436},"action":"C","side":"A","price":"1.156660000","size":30,"channel_id":23,"order_id":"1775528909847336100","flags":0,"ts_in_delta":867,"sequence":162020,"symbol":"FCEU SI 20260615 PS"}
{"ts_recv":"2026-04-07T02:28:29.847432865Z","hd":{"ts_event":"2026-04-07T02:28:29.847413103Z","rtype":160,"publisher_id":101,"instrument_id":436},"action":"A","side":"A","price":"1.156650000","size":30,"channel_id":23,"order_id":"1775528909847419471","flags":128,"ts_in_delta":867,"sequence":162020,"symbol":"FCEU SI 20260615 PS"}
{"ts_recv":"2026-04-07T02:28:29.847478743Z","hd":{"ts_event":"2026-04-07T02:28:29.847462255Z","rtype":160,"publisher_id":101,"instrument_id":436},"action":"C","side":"B","price":"1.156570000","size":30,"channel_id":23,"order_id":"10998900946689813764","flags":0,"ts_in_delta":1033,"sequence":162021,"symbol":"FCEU SI 20260615 PS"}
{"ts_recv":"2026-04-07T02:28:29.847478743Z","hd":{"ts_event":"2026-04-07T02:28:29.847462255Z","rtype":160,"publisher_id":101,"instrument_id":436},"action":"A","side":"B","price":"1.156550000","size":30,"channel_id":23,"order_id":"10998900946702244162","flags":0,"ts_in_delta":1033,"sequence":162021,"symbol":"FCEU SI 20260615 PS"}
{"ts_recv":"2026-04-07T02:28:29.847478743Z","hd":{"ts_event":"2026-04-07T02:28:29.847462255Z","rtype":160,"publisher_id":101,"instrument_id":436},"action":"C","side":"A","price":"1.156670000","size":30,"channel_id":23,"order_id":"1775528909835037956","flags":0,"ts_in_delta":1033,"sequence":162021,"symbol":"FCEU SI 20260615 PS"}
{"ts_recv":"2026-04-07T02:28:29.847478743Z","hd":{"ts_event":"2026-04-07T02:28:29.847462255Z","rtype":160,"publisher_id":101,"instrument_id":436},"action":"A","side":"A","price":"1.156650000","size":30,"channel_id":23,"order_id":"1775528909847468354","flags":128,"ts_in_delta":1033,"sequence":162021,"symbol":"FCEU SI 20260615 PS"}
{"ts_recv":"2026-04-07T02:28:29.847490792Z","hd":{"ts_event":"2026-04-07T02:28:29.847472009Z","rtype":160,"publisher_id":101,"instrument_id":436},"action":"C","side":"B","price":"1.156550000","size":30,"channel_id":23,"order_id":"10998900946702195279","flags":0,"ts_in_delta":1035,"sequence":162022,"symbol":"FCEU SI 20260615 PS"}
{"ts_recv":"2026-04-07T02:28:29.847490792Z","hd":{"ts_event":"2026-04-07T02:28:29.847472009Z","rtype":160,"publisher_id":101,"instrument_id":436},"action":"A","side":"B","price":"1.156560000","size":30,"channel_id":23,"order_id":"10998900946702253802","flags":0,"ts_in_delta":1035,"sequence":162022,"symbol":"FCEU SI 20260615 PS"}
{"ts_recv":"2026-04-07T02:28:29.847490792Z","hd":{"ts_event":"2026-04-07T02:28:29.847472009Z","rtype":160,"publisher_id":101,"instrument_id":436},"action":"C","side":"A","price":"1.156650000","size":30,"channel_id":23,"order_id":"1775528909847419471","flags":0,"ts_in_delta":1035,"sequence":162022,"symbol":"FCEU SI 20260615 PS"}
{"ts_recv":"2026-04-07T02:28:29.847490792Z","hd":{"ts_event":"2026-04-07T02:28:29.847472009Z","rtype":160,"publisher_id":101,"instrument_id":436},"action":"A","side":"A","price":"1.156660000","size":30,"channel_id":23,"order_id":"1775528909847477994","flags":128,"ts_in_delta":1035,"sequence":162022,"symbol":"FCEU SI 20260615 PS"}
{"ts_recv":"2026-04-07T02:28:29.847544627Z","hd":{"ts_event":"2026-04-07T02:28:29.847527997Z","rtype":160,"publisher_id":101,"instrument_id":436},"action":"C","side":"B","price":"1.156560000","size":30,"channel_id":23,"order_id":"10998900946702253802","flags":0,"ts_in_delta":1057,"sequence":162023,"symbol":"FCEU SI 20260615 PS"}
{"ts_recv":"2026-04-07T02:28:29.847544627Z","hd":{"ts_event":"2026-04-07T02:28:29.847527997Z","rtype":160,"publisher_id":101,"instrument_id":436},"action":"A","side":"B","price":"1.156550000","size":30,"channel_id":23,"order_id":"10998900946702309225","flags":0,"ts_in_delta":1057,"sequence":162023,"symbol":"FCEU SI 20260615 PS"}
{"ts_recv":"2026-04-07T02:28:29.847544627Z","hd":{"ts_event":"2026-04-07T02:28:29.847527997Z","rtype":160,"publisher_id":101,"instrument_id":436},"action":"C","side":"A","price":"1.156660000","size":30,"channel_id":23,"order_id":"1775528909847477994","flags":0,"ts_in_delta":1057,"sequence":162023,"symbol":"FCEU SI 20260615 PS"}
{"ts_recv":"2026-04-07T02:28:29.847544627Z","hd":{"ts_event":"2026-04-07T02:28:29.847527997Z","rtype":160,"publisher_id":101,"instrument_id":436},"action":"A","side":"A","price":"1.156650000","size":30,"channel_id":23,"order_id":"1775528909847533417","flags":128,"ts_in_delta":1057,"sequence":162023,"symbol":"FCEU SI 20260615 PS"}
{"ts_recv":"2026-04-07T02:28:40.728168827Z","hd":{"ts_event":"2026-04-07T02:28:40.728138751Z","rtype":160,"publisher_id":101,"instrument_id":436},"action":"C","side":"B","price":"1.156550000","size":30,"channel_id":23,"order_id":"10998900946702309225","flags":0,"ts_in_delta":1342,"sequence":162139,"symbol":"FCEU SI 20260615 PS"}
{"ts_recv":"2026-04-07T02:28:40.728168827Z","hd":{"ts_event":"2026-04-07T02:28:40.728138751Z","rtype":160,"publisher_id":101,"instrument_id":436},"action":"A","side":"B","price":"1.156540000","size":30,"channel_id":23,"order_id":"10998900957582927619","flags":0,"ts_in_delta":1342,"sequence":162139,"symbol":"FCEU SI 20260615 PS"}
{"ts_recv":"2026-04-07T02:28:40.728168827Z","hd":{"ts_event":"2026-04-07T02:28:40.728138751Z","rtype":160,"publisher_id":101,"instrument_id":436},"action":"C","side":"A","price":"1.156650000","size":30,"channel_id":23,"order_id":"1775528909847533417","flags":0,"ts_in_delta":1342,"sequence":162139,"symbol":"FCEU SI 20260615 PS"}
{"ts_recv":"2026-04-07T02:28:40.728168827Z","hd":{"ts_event":"2026-04-07T02:28:40.728138751Z","rtype":160,"publisher_id":101,"instrument_id":436},"action":"A","side":"A","price":"1.156640000","size":30,"channel_id":23,"order_id":"1775528920728151811","flags":128,"ts_in_delta":1342,"sequence":162139,"symbol":"FCEU SI 20260615 PS"}
{"ts_recv":"2026-04-07T02:28:40.728226693Z","hd":{"ts_event":"2026-04-07T02:28:40.728207989Z","rtype":160,"publisher_id":101,"instrument_id":436},"action":"C","side":"B","price":"1.156550000","size":30,"channel_id":23,"order_id":"10998900946702244162","flags":0,"ts_in_delta":937,"sequence":162140,"symbol":"FCEU SI 20260615 PS"}
{"ts_recv":"2026-04-07T02:28:40.728226693Z","hd":{"ts_event":"2026-04-07T02:28:40.728207989Z","rtype":160,"publisher_id":101,"instrument_id":436},"action":"A","side":"B","price":"1.156530000","size":30,"channel_id":23,"order_id":"10998900957582990209","flags":0,"ts_in_delta":937,"sequence":162140,"symbol":"FCEU SI 20260615 PS"}
{"ts_recv":"2026-04-07T02:28:40.728226693Z","hd":{"ts_event":"2026-04-07T02:28:40.728207989Z","rtype":160,"publisher_id":101,"instrument_id":436},"action":"C","side":"A","price":"1.156650000","size":30,"channel_id":23,"order_id":"1775528909847468354","flags":0,"ts_in_delta":937,"sequence":162140,"symbol":"FCEU SI 20260615 PS"}
{"ts_recv":"2026-04-07T02:28:40.728226693Z","hd":{"ts_event":"2026-04-07T02:28:40.728207989Z","rtype":160,"publisher_id":101,"instrument_id":436},"action":"A","side":"A","price":"1.156630000","size":30,"channel_id":23,"order_id":"1775528920728214401","flags":128,"ts_in_delta":937,"sequence":162140,"symbol":"FCEU SI 20260615 PS"}
{"ts_recv":"2026-04-07T02:28:40.728251813Z","hd":{"ts_event":"2026-04-07T02:28:40.728236077Z","rtype":160,"publisher_id":101,"instrument_id":436},"action":"C","side":"B","price":"1.156540000","size":30,"channel_id":23,"order_id":"10998900957582927619","flags":0,"ts_in_delta":981,"sequence":162141,"symbol":"FCEU SI 20260615 PS"}
{"ts_recv":"2026-04-07T02:28:40.728251813Z","hd":{"ts_event":"2026-04-07T02:28:40.728236077Z","rtype":160,"publisher_id":101,"instrument_id":436},"action":"A","side":"B","price":"1.156530000","size":30,"channel_id":23,"order_id":"10998900957583018017","flags":0,"ts_in_delta":981,"sequence":162141,"symbol":"FCEU SI 20260615 PS"}
{"ts_recv":"2026-04-07T02:28:40.728251813Z","hd":{"ts_event":"2026-04-07T02:28:40.728236077Z","rtype":160,"publisher_id":101,"instrument_id":436},"action":"C","side":"A","price":"1.156640000","size":30,"channel_id":23,"order_id":"1775528920728151811","flags":0,"ts_in_delta":981,"sequence":162141,"symbol":"FCEU SI 20260615 PS"}
{"ts_recv":"2026-04-07T02:28:40.728251813Z","hd":{"ts_event":"2026-04-07T02:28:40.728236077Z","rtype":160,"publisher_id":101,"instrument_id":436},"action":"A","side":"A","price":"1.156630000","size":30,"channel_id":23,"order_id":"1775528920728242209","flags":128,"ts_in_delta":981,"sequence":162141,"symbol":"FCEU SI 20260615 PS"}
{"ts_recv":"2026-04-07T02:28:48.340669505Z","hd":{"ts_event":"2026-04-07T02:28:48.340649107Z","rtype":160,"publisher_id":101,"instrument_id":436},"action":"C","side":"B","price":"1.156530000","size":30,"channel_id":23,"order_id":"10998900957583018017","flags":0,"ts_in_delta":961,"sequence":162204,"symbol":"FCEU SI 20260615 PS"}
{"ts_recv":"2026-04-07T02:28:48.340669505Z","hd":{"ts_event":"2026-04-07T02:28:48.340649107Z","rtype":160,"publisher_id":101,"instrument_id":436},"action":"A","side":"B","price":"1.156540000","size":30,"channel_id":23,"order_id":"10998900965195430792","flags":0,"ts_in_delta":961,"sequence":162204,"symbol":"FCEU SI 20260615 PS"}
{"ts_recv":"2026-04-07T02:28:48.340669505Z","hd":{"ts_event":"2026-04-07T02:28:48.340649107Z","rtype":160,"publisher_id":101,"instrument_id":436},"action":"C","side":"A","price":"1.156630000","size":30,"channel_id":23,"order_id":"1775528920728242209","flags":0,"ts_in_delta":961,"sequence":162204,"symbol":"FCEU SI 20260615 PS"}
{"ts_recv":"2026-04-07T02:28:48.340669505Z","hd":{"ts_event":"2026-04-07T02:28:48.340649107Z","rtype":160,"publisher_id":101,"instrument_id":436},"action":"A","side":"A","price":"1.156640000","size":30,"channel_id":23,"order_id":"1775528928340654984","flags":128,"ts_in_delta":961,"sequence":162204,"symbol":"FCEU SI 20260615 PS"}
{"ts_recv":"2026-04-07T02:28:49.387832152Z","hd":{"ts_event":"2026-04-07T02:28:49.387802421Z","rtype":160,"publisher_id":101,"instrument_id":436},"action":"C","side":"B","price":"1.156530000","size":30,"channel_id":23,"order_id":"10998900957582990209","flags":0,"ts_in_delta":1174,"sequence":162230,"symbol":"FCEU SI 20260615 PS"}
{"ts_recv":"2026-04-07T02:28:49.387832152Z","hd":{"ts_event":"2026-04-07T02:28:49.387802421Z","rtype":160,"publisher_id":101,"instrument_id":436},"action":"A","side":"B","price":"1.156550000","size":30,"channel_id":23,"order_id":"10998900966242589202","flags":0,"ts_in_delta":1174,"sequence":162230,"symbol":"FCEU SI 20260615 PS"}
{"ts_recv":"2026-04-07T02:28:49.387832152Z","hd":{"ts_event":"2026-04-07T02:28:49.387802421Z","rtype":160,"publisher_id":101,"instrument_id":436},"action":"C","side":"A","price":"1.156630000","size":30,"channel_id":23,"order_id":"1775528920728214401","flags":0,"ts_in_delta":1174,"sequence":162230,"symbol":"FCEU SI 20260615 PS"}
{"ts_recv":"2026-04-07T02:28:49.387832152Z","hd":{"ts_event":"2026-04-07T02:28:49.387802421Z","rtype":160,"publisher_id":101,"instrument_id":436},"action":"A","side":"A","price":"1.156650000","size":30,"channel_id":23,"order_id":"1775528929387813394","flags":128,"ts_in_delta":1174,"sequence":162230,"symbol":"FCEU SI 20260615 PS"}
{"ts_recv":"2026-04-07T02:28:49.387901222Z","hd":{"ts_event":"2026-04-07T02:28:49.387884905Z","rtype":160,"publisher_id":101,"instrument_id":436},"action":"C","side":"B","price":"1.156540000","size":30,"channel_id":23,"order_id":"10998900965195430792","flags":0,"ts_in_delta":932,"sequence":162231,"symbol":"FCEU SI 20260615 PS"}
{"ts_recv":"2026-04-07T02:28:49.387901222Z","hd":{"ts_event":"2026-04-07T02:28:49.387884905Z","rtype":160,"publisher_id":101,"instrument_id":436},"action":"A","side":"B","price":"1.156550000","size":30,"channel_id":23,"order_id":"10998900966242666723","flags":0,"ts_in_delta":932,"sequence":162231,"symbol":"FCEU SI 20260615 PS"}
{"ts_recv":"2026-04-07T02:28:49.387901222Z","hd":{"ts_event":"2026-04-07T02:28:49.387884905Z","rtype":160,"publisher_id":101,"instrument_id":436},"action":"C","side":"A","price":"1.156640000","size":30,"channel_id":23,"order_id":"1775528928340654984","flags":0,"ts_in_delta":932,"sequence":162231,"symbol":"FCEU SI 20260615 PS"}
{"ts_recv":"2026-04-07T02:28:49.387901222Z","hd":{"ts_event":"2026-04-07T02:28:49.387884905Z","rtype":160,"publisher_id":101,"instrument_id":436},"action":"A","side":"A","price":"1.156650000","size":30,"channel_id":23,"order_id":"1775528929387890915","flags":128,"ts_in_delta":932,"sequence":162231,"symbol":"FCEU SI 20260615 PS"}
{"ts_recv":"2026-04-07T02:29:01.893283018Z","hd":{"ts_event":"2026-04-07T02:29:01.893259941Z","rtype":160,"publisher_id":101,"instrument_id":436},"action":"C","side":"B","price":"1.156550000","size":30,"channel_id":23,"order_id":"10998900966242666723","flags":0,"ts_in_delta":891,"sequence":162318,"symbol":"FCEU SI 20260615 PS"}
{"ts_recv":"2026-04-07T02:29:01.893283018Z","hd":{"ts_event":"2026-04-07T02:29:01.893259941Z","rtype":160,"publisher_id":101,"instrument_id":436},"action":"A","side":"B","price":"1.156540000","size":30,"channel_id":23,"order_id":"10998900978748042077","flags":0,"ts_in_delta":891,"sequence":162318,"symbol":"FCEU SI 20260615 PS"}
{"ts_recv":"2026-04-07T02:29:01.893283018Z","hd":{"ts_event":"2026-04-07T02:29:01.893259941Z","rtype":160,"publisher_id":101,"instrument_id":436},"action":"C","side":"A","price":"1.156650000","size":30,"channel_id":23,"order_id":"1775528929387890915","flags":0,"ts_in_delta":891,"sequence":162318,"symbol":"FCEU SI 20260615 PS"}
{"ts_recv":"2026-04-07T02:29:01.893283018Z","hd":{"ts_event":"2026-04-07T02:29:01.893259941Z","rtype":160,"publisher_id":101,"instrument_id":436},"action":"A","side":"A","price":"1.156640000","size":30,"channel_id":23,"order_id":"1775528941893266269","flags":128,"ts_in_delta":891,"sequence":162318,"symbol":"FCEU SI 20260615 PS"}
{"ts_recv":"2026-04-07T02:29:01.893337005Z","hd":{"ts_event":"2026-04-07T02:29:01.893318303Z","rtype":160,"publisher_id":101,"instrument_id":436},"action":"C","side":"B","price":"1.156550000","size":30,"channel_id":23,"order_id":"10998900966242589202","flags":0,"ts_in_delta":846,"sequence":162319,"symbol":"FCEU SI 20260615 PS"}
{"ts_recv":"2026-04-07T02:29:01.893337005Z","hd":{"ts_event":"2026-04-07T02:29:01.893318303Z","rtype":160,"publisher_id":101,"instrument_id":436},"action":"A","side":"B","price":"1.156530000","size":30,"channel_id":23,"order_id":"10998900978748100172","flags":0,"ts_in_delta":846,"sequence":162319,"symbol":"FCEU SI 20260615 PS"}
{"ts_recv":"2026-04-07T02:29:01.893337005Z","hd":{"ts_event":"2026-04-07T02:29:01.893318303Z","rtype":160,"publisher_id":101,"instrument_id":436},"action":"C","side":"A","price":"1.156650000","size":30,"channel_id":23,"order_id":"1775528929387813394","flags":0,"ts_in_delta":846,"sequence":162319,"symbol":"FCEU SI 20260615 PS"}
{"ts_recv":"2026-04-07T02:29:01.893337005Z","hd":{"ts_event":"2026-04-07T02:29:01.893318303Z","rtype":160,"publisher_id":101,"instrument_id":436},"action":"A","side":"A","price":"1.156630000","size":30,"channel_id":23,"order_id":"1775528941893324364","flags":128,"ts_in_delta":846,"sequence":162319,"symbol":"FCEU SI 20260615 PS"}
{"ts_recv":"2026-04-07T02:29:01.893392898Z","hd":{"ts_event":"2026-04-07T02:29:01.893373703Z","rtype":160,"publisher_id":101,"instrument_id":436},"action":"C","side":"B","price":"1.156540000","size":30,"channel_id":23,"order_id":"10998900978748042077","flags":0,"ts_in_delta":900,"sequence":162320,"symbol":"FCEU SI 20260615 PS"}
{"ts_recv":"2026-04-07T02:29:01.893392898Z","hd":{"ts_event":"2026-04-07T02:29:01.893373703Z","rtype":160,"publisher_id":101,"instrument_id":436},"action":"A","side":"B","price":"1.156530000","size":30,"channel_id":23,"order_id":"10998900978748155665","flags":0,"ts_in_delta":900,"sequence":162320,"symbol":"FCEU SI 20260615 PS"}
{"ts_recv":"2026-04-07T02:29:01.893392898Z","hd":{"ts_event":"2026-04-07T02:29:01.893373703Z","rtype":160,"publisher_id":101,"instrument_id":436},"action":"C","side":"A","price":"1.156640000","size":30,"channel_id":23,"order_id":"1775528941893266269","flags":0,"ts_in_delta":900,"sequence":162320,"symbol":"FCEU SI 20260615 PS"}
{"ts_recv":"2026-04-07T02:29:01.893392898Z","hd":{"ts_event":"2026-04-07T02:29:01.893373703Z","rtype":160,"publisher_id":101,"instrument_id":436},"action":"A","side":"A","price":"1.156630000","size":30,"channel_id":23,"order_id":"1775528941893379857","flags":128,"ts_in_delta":900,"sequence":162320,"symbol":"FCEU SI 20260615 PS"}
{"ts_recv":"2026-04-07T02:29:06.976850542Z","hd":{"ts_event":"2026-04-07T02:29:06.976818655Z","rtype":160,"publisher_id":101,"instrument_id":436},"action":"C","side":"B","price":"1.156530000","size":30,"channel_id":23,"order_id":"10998900978748155665","flags":0,"ts_in_delta":883,"sequence":162340,"symbol":"FCEU SI 20260615 PS"}
{"ts_recv":"2026-04-07T02:29:06.976850542Z","hd":{"ts_event":"2026-04-07T02:29:06.976818655Z","rtype":160,"publisher_id":101,"instrument_id":436},"action":"A","side":"B","price":"1.156540000","size":30,"channel_id":23,"order_id":"10998900983831609248","flags":0,"ts_in_delta":883,"sequence":162340,"symbol":"FCEU SI 20260615 PS"}
{"ts_recv":"2026-04-07T02:29:06.976850542Z","hd":{"ts_event":"2026-04-07T02:29:06.976818655Z","rtype":160,"publisher_id":101,"instrument_id":436},"action":"C","side":"A","price":"1.156630000","size":30,"channel_id":23,"order_id":"1775528941893379857","flags":0,"ts_in_delta":883,"sequence":162340,"symbol":"FCEU SI 20260615 PS"}
{"ts_recv":"2026-04-07T02:29:06.976850542Z","hd":{"ts_event":"2026-04-07T02:29:06.976818655Z","rtype":160,"publisher_id":101,"instrument_id":436},"action":"A","side":"A","price":"1.156640000","size":30,"channel_id":23,"order_id":"1775528946976833440","flags":128,"ts_in_delta":883,"sequence":162340,"symbol":"FCEU SI 20260615 PS"}
{"ts_recv":"2026-04-07T02:29:06.976920449Z","hd":{"ts_event":"2026-04-07T02:29:06.976901275Z","rtype":160,"publisher_id":101,"instrument_id":436},"action":"C","side":"B","price":"1.156530000","size":30,"channel_id":23,"order_id":"10998900978748100172","flags":0,"ts_in_delta":940,"sequence":162341,"symbol":"FCEU SI 20260615 PS"}
{"ts_recv":"2026-04-07T02:29:06.976920449Z","hd":{"ts_event":"2026-04-07T02:29:06.976901275Z","rtype":160,"publisher_id":101,"instrument_id":436},"action":"A","side":"B","price":"1.156550000","size":30,"channel_id":23,"order_id":"10998900983831683370","flags":0,"ts_in_delta":940,"sequence":162341,"symbol":"FCEU SI 20260615 PS"}
{"ts_recv":"2026-04-07T02:29:06.976920449Z","hd":{"ts_event":"2026-04-07T02:29:06.976901275Z","rtype":160,"publisher_id":101,"instrument_id":436},"action":"C","side":"A","price":"1.156630000","size":30,"channel_id":23,"order_id":"1775528941893324364","flags":0,"ts_in_delta":940,"sequence":162341,"symbol":"FCEU SI 20260615 PS"}
{"ts_recv":"2026-04-07T02:29:06.976920449Z","hd":{"ts_event":"2026-04-07T02:29:06.976901275Z","rtype":160,"publisher_id":101,"instrument_id":436},"action":"A","side":"A","price":"1.156650000","size":30,"channel_id":23,"order_id":"1775528946976907562","flags":128,"ts_in_delta":940,"sequence":162341,"symbol":"FCEU SI 20260615 PS"}
{"ts_recv":"2026-04-07T02:29:06.976993168Z","hd":{"ts_event":"2026-04-07T02:29:06.976974121Z","rtype":160,"publisher_id":101,"instrument_id":436},"action":"C","side":"B","price":"1.156540000","size":30,"channel_id":23,"order_id":"10998900983831609248","flags":0,"ts_in_delta":965,"sequence":162342,"symbol":"FCEU SI 20260615 PS"}
{"ts_recv":"2026-04-07T02:29:06.976993168Z","hd":{"ts_event":"2026-04-07T02:29:06.976974121Z","rtype":160,"publisher_id":101,"instrument_id":436},"action":"A","side":"B","price":"1.156550000","size":30,"channel_id":23,"order_id":"10998900983831755934","flags":0,"ts_in_delta":965,"sequence":162342,"symbol":"FCEU SI 20260615 PS"}
{"ts_recv":"2026-04-07T02:29:06.976993168Z","hd":{"ts_event":"2026-04-07T02:29:06.976974121Z","rtype":160,"publisher_id":101,"instrument_id":436},"action":"C","side":"A","price":"1.156640000","size":30,"channel_id":23,"order_id":"1775528946976833440","flags":0,"ts_in_delta":965,"sequence":162342,"symbol":"FCEU SI 20260615 PS"}
{"ts_recv":"2026-04-07T02:29:06.976993168Z","hd":{"ts_event":"2026-04-07T02:29:06.976974121Z","rtype":160,"publisher_id":101,"instrument_id":436},"action":"A","side":"A","price":"1.156650000","size":30,"channel_id":23,"order_id":"1775528946976980126","flags":128,"ts_in_delta":965,"sequence":162342,"symbol":"FCEU SI 20260615 PS"}
{"ts_recv":"2026-04-07T02:29:07.035674618Z","hd":{"ts_event":"2026-04-07T02:29:07.035652921Z","rtype":160,"publisher_id":101,"instrument_id":436},"action":"C","side":"B","price":"1.156550000","size":30,"channel_id":23,"order_id":"10998900983831683370","flags":0,"ts_in_delta":940,"sequence":162350,"symbol":"FCEU SI 20260615 PS"}
{"ts_recv":"2026-04-07T02:29:07.035674618Z","hd":{"ts_event":"2026-04-07T02:29:07.035652921Z","rtype":160,"publisher_id":101,"instrument_id":436},"action":"A","side":"B","price":"1.156570000","size":30,"channel_id":23,"order_id":"10998900983890435003","flags":0,"ts_in_delta":940,"sequence":162350,"symbol":"FCEU SI 20260615 PS"}
{"ts_recv":"2026-04-07T02:29:07.035674618Z","hd":{"ts_event":"2026-04-07T02:29:07.035652921Z","rtype":160,"publisher_id":101,"instrument_id":436},"action":"C","side":"A","price":"1.156650000","size":30,"channel_id":23,"order_id":"1775528946976907562","flags":0,"ts_in_delta":940,"sequence":162350,"symbol":"FCEU SI 20260615 PS"}
{"ts_recv":"2026-04-07T02:29:07.035674618Z","hd":{"ts_event":"2026-04-07T02:29:07.035652921Z","rtype":160,"publisher_id":101,"instrument_id":436},"action":"A","side":"A","price":"1.156670000","size":30,"channel_id":23,"order_id":"1775528947035659195","flags":128,"ts_in_delta":940,"sequence":162350,"symbol":"FCEU SI 20260615 PS"}
{"ts_recv":"2026-04-07T02:29:07.035737068Z","hd":{"ts_event":"2026-04-07T02:29:07.035718951Z","rtype":160,"publisher_id":101,"instrument_id":436},"action":"C","side":"B","price":"1.156550000","size":30,"channel_id":23,"order_id":"10998900983831755934","flags":0,"ts_in_delta":1071,"sequence":162351,"symbol":"FCEU SI 20260615 PS"}
{"ts_recv":"2026-04-07T02:29:07.035737068Z","hd":{"ts_event":"2026-04-07T02:29:07.035718951Z","rtype":160,"publisher_id":101,"instrument_id":436},"action":"A","side":"B","price":"1.156560000","size":30,"channel_id":23,"order_id":"10998900983890501126","flags":0,"ts_in_delta":1071,"sequence":162351,"symbol":"FCEU SI 20260615 PS"}
{"ts_recv":"2026-04-07T02:29:07.035737068Z","hd":{"ts_event":"2026-04-07T02:29:07.035718951Z","rtype":160,"publisher_id":101,"instrument_id":436},"action":"C","side":"A","price":"1.156650000","size":30,"channel_id":23,"order_id":"1775528946976980126","flags":0,"ts_in_delta":1071,"sequence":162351,"symbol":"FCEU SI 20260615 PS"}
{"ts_recv":"2026-04-07T02:29:07.035737068Z","hd":{"ts_event":"2026-04-07T02:29:07.035718951Z","rtype":160,"publisher_id":101,"instrument_id":436},"action":"A","side":"A","price":"1.156660000","size":30,"channel_id":23,"order_id":"1775528947035725318","flags":128,"ts_in_delta":1071,"sequence":162351,"symbol":"FCEU SI 20260615 PS"}
{"ts_recv":"2026-04-07T02:29:07.039513397Z","hd":{"ts_event":"2026-04-07T02:29:07.039495617Z","rtype":160,"publisher_id":101,"instrument_id":436},"action":"C","side":"B","price":"1.156560000","size":30,"channel_id":23,"order_id":"10998900983890501126","flags":0,"ts_in_delta":960,"sequence":162354,"symbol":"FCEU SI 20260615 PS"}
{"ts_recv":"2026-04-07T02:29:07.039513397Z","hd":{"ts_event":"2026-04-07T02:29:07.039495617Z","rtype":160,"publisher_id":101,"instrument_id":436},"action":"A","side":"B","price":"1.156580000","size":30,"channel_id":23,"order_id":"10998900983894277649","flags":0,"ts_in_delta":960,"sequence":162354,"symbol":"FCEU SI 20260615 PS"}
{"ts_recv":"2026-04-07T02:29:07.039513397Z","hd":{"ts_event":"2026-04-07T02:29:07.039495617Z","rtype":160,"publisher_id":101,"instrument_id":436},"action":"C","side":"A","price":"1.156660000","size":30,"channel_id":23,"order_id":"1775528947035725318","flags":0,"ts_in_delta":960,"sequence":162354,"symbol":"FCEU SI 20260615 PS"}
{"ts_recv":"2026-04-07T02:29:07.039513397Z","hd":{"ts_event":"2026-04-07T02:29:07.039495617Z","rtype":160,"publisher_id":101,"instrument_id":436},"action":"A","side":"A","price":"1.156680000","size":30,"channel_id":23,"order_id":"1775528947039501841","flags":128,"ts_in_delta":960,"sequence":162354,"symbol":"FCEU SI 20260615 PS"}
{"ts_recv":"2026-04-07T02:29:07.041015636Z","hd":{"ts_event":"2026-04-07T02:29:07.040997025Z","rtype":160,"publisher_id":101,"instrument_id":436},"action":"C","side":"B","price":"1.156570000","size":30,"channel_id":23,"order_id":"10998900983890435003","flags":0,"ts_in_delta":936,"sequence":162360,"symbol":"FCEU SI 20260615 PS"}
{"ts_recv":"2026-04-07T02:29:07.041015636Z","hd":{"ts_event":"2026-04-07T02:29:07.040997025Z","rtype":160,"publisher_id":101,"instrument_id":436},"action":"A","side":"B","price":"1.156590000","size":30,"channel_id":23,"order_id":"10998900983895778938","flags":0,"ts_in_delta":936,"sequence":162360,"symbol":"FCEU SI 20260615 PS"}
{"ts_recv":"2026-04-07T02:29:07.041015636Z","hd":{"ts_event":"2026-04-07T02:29:07.040997025Z","rtype":160,"publisher_id":101,"instrument_id":436},"action":"C","side":"A","price":"1.156670000","size":30,"channel_id":23,"order_id":"1775528947035659195","flags":0,"ts_in_delta":936,"sequence":162360,"symbol":"FCEU SI 20260615 PS"}
{"ts_recv":"2026-04-07T02:29:07.041015636Z","hd":{"ts_event":"2026-04-07T02:29:07.040997025Z","rtype":160,"publisher_id":101,"instrument_id":436},"action":"A","side":"A","price":"1.156690000","size":30,"channel_id":23,"order_id":"1775528947041003130","flags":128,"ts_in_delta":936,"sequence":162360,"symbol":"FCEU SI 20260615 PS"}
{"ts_recv":"2026-04-07T02:29:07.041074869Z","hd":{"ts_event":"2026-04-07T02:29:07.041056757Z","rtype":160,"publisher_id":101,"instrument_id":436},"action":"C","side":"B","price":"1.156580000","size":30,"channel_id":23,"order_id":"10998900983894277649","flags":0,"ts_in_delta":947,"sequence":162361,"symbol":"FCEU SI 20260615 PS"}
{"ts_recv":"2026-04-07T02:29:07.041074869Z","hd":{"ts_event":"2026-04-07T02:29:07.041056757Z","rtype":160,"publisher_id":101,"instrument_id":436},"action":"A","side":"B","price":"1.156590000","size":30,"channel_id":23,"order_id":"10998900983895838540","flags":0,"ts_in_delta":947,"sequence":162361,"symbol":"FCEU SI 20260615 PS"}
{"ts_recv":"2026-04-07T02:29:07.041074869Z","hd":{"ts_event":"2026-04-07T02:29:07.041056757Z","rtype":160,"publisher_id":101,"instrument_id":436},"action":"C","side":"A","price":"1.156680000","size":30,"channel_id":23,"order_id":"1775528947039501841","flags":0,"ts_in_delta":947,"sequence":162361,"symbol":"FCEU SI 20260615 PS"}
{"ts_recv":"2026-04-07T02:29:07.041074869Z","hd":{"ts_event":"2026-04-07T02:29:07.041056757Z","rtype":160,"publisher_id":101,"instrument_id":436},"action":"A","side":"A","price":"1.156690000","size":30,"channel_id":23,"order_id":"1775528947041062732","flags":128,"ts_in_delta":947,"sequence":162361,"symbol":"FCEU SI 20260615 PS"}
{"ts_recv":"2026-04-07T02:29:12.750018482Z","hd":{"ts_event":"2026-04-07T02:29:12.749988603Z","rtype":160,"publisher_id":101,"instrument_id":436},"action":"C","side":"B","price":"1.156590000","size":30,"channel_id":23,"order_id":"10998900983895838540","flags":0,"ts_in_delta":1313,"sequence":162409,"symbol":"FCEU SI 20260615 PS"}
{"ts_recv":"2026-04-07T02:29:12.750018482Z","hd":{"ts_event":"2026-04-07T02:29:12.749988603Z","rtype":160,"publisher_id":101,"instrument_id":436},"action":"A","side":"B","price":"1.156580000","size":30,"channel_id":23,"order_id":"10998900989604777872","flags":0,"ts_in_delta":1313,"sequence":162409,"symbol":"FCEU SI 20260615 PS"}
{"ts_recv":"2026-04-07T02:29:12.750018482Z","hd":{"ts_event":"2026-04-07T02:29:12.749988603Z","rtype":160,"publisher_id":101,"instrument_id":436},"action":"C","side":"A","price":"1.156690000","size":30,"channel_id":23,"order_id":"1775528947041062732","flags":0,"ts_in_delta":1313,"sequence":162409,"symbol":"FCEU SI 20260615 PS"}
{"ts_recv":"2026-04-07T02:29:12.750018482Z","hd":{"ts_event":"2026-04-07T02:29:12.749988603Z","rtype":160,"publisher_id":101,"instrument_id":436},"action":"A","side":"A","price":"1.156680000","size":30,"channel_id":23,"order_id":"1775528952750002064","flags":128,"ts_in_delta":1313,"sequence":162409,"symbol":"FCEU SI 20260615 PS"}
{"ts_recv":"2026-04-07T02:29:12.750081532Z","hd":{"ts_event":"2026-04-07T02:29:12.750062561Z","rtype":160,"publisher_id":101,"instrument_id":436},"action":"C","side":"B","price":"1.156590000","size":30,"channel_id":23,"order_id":"10998900983895778938","flags":0,"ts_in_delta":1009,"sequence":162410,"symbol":"FCEU SI 20260615 PS"}
{"ts_recv":"2026-04-07T02:29:12.750081532Z","hd":{"ts_event":"2026-04-07T02:29:12.750062561Z","rtype":160,"publisher_id":101,"instrument_id":436},"action":"A","side":"B","price":"1.156570000","size":30,"channel_id":23,"order_id":"10998900989604844459","flags":0,"ts_in_delta":1009,"sequence":162410,"symbol":"FCEU SI 20260615 PS"}
{"ts_recv":"2026-04-07T02:29:12.750081532Z","hd":{"ts_event":"2026-04-07T02:29:12.750062561Z","rtype":160,"publisher_id":101,"instrument_id":436},"action":"C","side":"A","price":"1.156690000","size":30,"channel_id":23,"order_id":"1775528947041003130","flags":0,"ts_in_delta":1009,"sequence":162410,"symbol":"FCEU SI 20260615 PS"}
{"ts_recv":"2026-04-07T02:29:12.750081532Z","hd":{"ts_event":"2026-04-07T02:29:12.750062561Z","rtype":160,"publisher_id":101,"instrument_id":436},"action":"A","side":"A","price":"1.156670000","size":30,"channel_id":23,"order_id":"1775528952750068651","flags":128,"ts_in_delta":1009,"sequence":162410,"symbol":"FCEU SI 20260615 PS"}
{"ts_recv":"2026-04-07T02:29:12.750142531Z","hd":{"ts_event":"2026-04-07T02:29:12.750126191Z","rtype":160,"publisher_id":101,"instrument_id":436},"action":"C","side":"B","price":"1.156580000","size":30,"channel_id":23,"order_id":"10998900989604777872","flags":0,"ts_in_delta":1039,"sequence":162411,"symbol":"FCEU SI 20260615 PS"}
{"ts_recv":"2026-04-07T02:29:12.750142531Z","hd":{"ts_event":"2026-04-07T02:29:12.750126191Z","rtype":160,"publisher_id":101,"instrument_id":436},"action":"A","side":"B","price":"1.156570000","size":30,"channel_id":23,"order_id":"10998900989604908115","flags":0,"ts_in_delta":1039,"sequence":162411,"symbol":"FCEU SI 20260615 PS"}
{"ts_recv":"2026-04-07T02:29:12.750142531Z","hd":{"ts_event":"2026-04-07T02:29:12.750126191Z","rtype":160,"publisher_id":101,"instrument_id":436},"action":"C","side":"A","price":"1.156680000","size":30,"channel_id":23,"order_id":"1775528952750002064","flags":0,"ts_in_delta":1039,"sequence":162411,"symbol":"FCEU SI 20260615 PS"}
{"ts_recv":"2026-04-07T02:29:12.750142531Z","hd":{"ts_event":"2026-04-07T02:29:12.750126191Z","rtype":160,"publisher_id":101,"instrument_id":436},"action":"A","side":"A","price":"1.156670000","size":30,"channel_id":23,"order_id":"1775528952750132307","flags":128,"ts_in_delta":1039,"sequence":162411,"symbol":"FCEU SI 20260615 PS"}
{"ts_recv":"2026-04-07T02:29:14.481691505Z","hd":{"ts_event":"2026-04-07T02:29:14.481655433Z","rtype":160,"publisher_id":101,"instrument_id":436},"action":"C","side":"B","price":"1.156570000","size":30,"channel_id":23,"order_id":"10998900989604908115","flags":0,"ts_in_delta":1552,"sequence":162421,"symbol":"FCEU SI 20260615 PS"}
{"ts_recv":"2026-04-07T02:29:14.481691505Z","hd":{"ts_event":"2026-04-07T02:29:14.481655433Z","rtype":160,"publisher_id":101,"instrument_id":436},"action":"A","side":"B","price":"1.156560000","size":30,"channel_id":23,"order_id":"10998900991336448274","flags":0,"ts_in_delta":1552,"sequence":162421,"symbol":"FCEU SI 20260615 PS"}
{"ts_recv":"2026-04-07T02:29:14.481691505Z","hd":{"ts_event":"2026-04-07T02:29:14.481655433Z","rtype":160,"publisher_id":101,"instrument_id":436},"action":"C","side":"A","price":"1.156670000","size":30,"channel_id":23,"order_id":"1775528952750132307","flags":0,"ts_in_delta":1552,"sequence":162421,"symbol":"FCEU SI 20260615 PS"}
{"ts_recv":"2026-04-07T02:29:14.481691505Z","hd":{"ts_event":"2026-04-07T02:29:14.481655433Z","rtype":160,"publisher_id":101,"instrument_id":436},"action":"A","side":"A","price":"1.156660000","size":30,"channel_id":23,"order_id":"1775528954481672466","flags":128,"ts_in_delta":1552,"sequence":162421,"symbol":"FCEU SI 20260615 PS"}
{"ts_recv":"2026-04-07T02:29:14.481755423Z","hd":{"ts_event":"2026-04-07T02:29:14.481736829Z","rtype":160,"publisher_id":101,"instrument_id":436},"action":"C","side":"B","price":"1.156570000","size":30,"channel_id":23,"order_id":"10998900989604844459","flags":0,"ts_in_delta":917,"sequence":162422,"symbol":"FCEU SI 20260615 PS"}
{"ts_recv":"2026-04-07T02:29:14.481755423Z","hd":{"ts_event":"2026-04-07T02:29:14.481736829Z","rtype":160,"publisher_id":101,"instrument_id":436},"action":"A","side":"B","price":"1.156550000","size":30,"channel_id":23,"order_id":"10998900991336519166","flags":0,"ts_in_delta":917,"sequence":162422,"symbol":"FCEU SI 20260615 PS"}
{"ts_recv":"2026-04-07T02:29:14.481755423Z","hd":{"ts_event":"2026-04-07T02:29:14.481736829Z","rtype":160,"publisher_id":101,"instrument_id":436},"action":"C","side":"A","price":"1.156670000","size":30,"channel_id":23,"order_id":"1775528952750068651","flags":0,"ts_in_delta":917,"sequence":162422,"symbol":"FCEU SI 20260615 PS"}
{"ts_recv":"2026-04-07T02:29:14.481755423Z","hd":{"ts_event":"2026-04-07T02:29:14.481736829Z","rtype":160,"publisher_id":101,"instrument_id":436},"action":"A","side":"A","price":"1.156650000","size":30,"channel_id":23,"order_id":"1775528954481743358","flags":128,"ts_in_delta":917,"sequence":162422,"symbol":"FCEU SI 20260615 PS"}
{"ts_recv":"2026-04-07T02:29:14.481777586Z","hd":{"ts_event":"2026-04-07T02:29:14.481758979Z","rtype":160,"publisher_id":101,"instrument_id":436},"action":"C","side":"B","price":"1.156560000","size":30,"channel_id":23,"order_id":"10998900991336448274","flags":0,"ts_in_delta":913,"sequence":162423,"symbol":"FCEU SI 20260615 PS"}
{"ts_recv":"2026-04-07T02:29:14.481777586Z","hd":{"ts_event":"2026-04-07T02:29:14.481758979Z","rtype":160,"publisher_id":101,"instrument_id":436},"action":"A","side":"B","price":"1.156550000","size":30,"channel_id":23,"order_id":"10998900991336541191","flags":0,"ts_in_delta":913,"sequence":162423,"symbol":"FCEU SI 20260615 PS"}
{"ts_recv":"2026-04-07T02:29:14.481777586Z","hd":{"ts_event":"2026-04-07T02:29:14.481758979Z","rtype":160,"publisher_id":101,"instrument_id":436},"action":"C","side":"A","price":"1.156660000","size":30,"channel_id":23,"order_id":"1775528954481672466","flags":0,"ts_in_delta":913,"sequence":162423,"symbol":"FCEU SI 20260615 PS"}
{"ts_recv":"2026-04-07T02:29:14.481777586Z","hd":{"ts_event":"2026-04-07T02:29:14.481758979Z","rtype":160,"publisher_id":101,"instrument_id":436},"action":"A","side":"A","price":"1.156650000","size":30,"channel_id":23,"order_id":"1775528954481765383","flags":128,"ts_in_delta":913,"sequence":162423,"symbol":"FCEU SI 20260615 PS"}
{"ts_recv":"2026-04-07T02:29:26.096556629Z","hd":{"ts_event":"2026-04-07T02:29:26.096536485Z","rtype":160,"publisher_id":101,"instrument_id":436},"action":"C","side":"B","price":"1.156550000","size":30,"channel_id":23,"order_id":"10998900991336541191","flags":0,"ts_in_delta":916,"sequence":162522,"symbol":"FCEU SI 20260615 PS"}
{"ts_recv":"2026-04-07T02:29:26.096556629Z","hd":{"ts_event":"2026-04-07T02:29:26.096536485Z","rtype":160,"publisher_id":101,"instrument_id":436},"action":"A","side":"B","price":"1.156560000","size":30,"channel_id":23,"order_id":"10998901002951317922","flags":0,"ts_in_delta":916,"sequence":162522,"symbol":"FCEU SI 20260615 PS"}
{"ts_recv":"2026-04-07T02:29:26.096556629Z","hd":{"ts_event":"2026-04-07T02:29:26.096536485Z","rtype":160,"publisher_id":101,"instrument_id":436},"action":"C","side":"A","price":"1.156650000","size":30,"channel_id":23,"order_id":"1775528954481765383","flags":0,"ts_in_delta":916,"sequence":162522,"symbol":"FCEU SI 20260615 PS"}
{"ts_recv":"2026-04-07T02:29:26.096556629Z","hd":{"ts_event":"2026-04-07T02:29:26.096536485Z","rtype":160,"publisher_id":101,"instrument_id":436},"action":"A","side":"A","price":"1.156660000","size":30,"channel_id":23,"order_id":"1775528966096542114","flags":128,"ts_in_delta":916,"sequence":162522,"symbol":"FCEU SI 20260615 PS"}
{"ts_recv":"2026-04-07T02:29:26.101322372Z","hd":{"ts_event":"2026-04-07T02:29:26.101302895Z","rtype":160,"publisher_id":101,"instrument_id":436},"action":"C","side":"B","price":"1.156560000","size":30,"channel_id":23,"order_id":"10998901002951317922","flags":0,"ts_in_delta":958,"sequence":162530,"symbol":"FCEU SI 20260615 PS"}
{"ts_recv":"2026-04-07T02:29:26.101322372Z","hd":{"ts_event":"2026-04-07T02:29:26.101302895Z","rtype":160,"publisher_id":101,"instrument_id":436},"action":"A","side":"B","price":"1.156570000","size":30,"channel_id":23,"order_id":"10998901002956084376","flags":0,"ts_in_delta":958,"sequence":162530,"symbol":"FCEU SI 20260615 PS"}
{"ts_recv":"2026-04-07T02:29:26.101322372Z","hd":{"ts_event":"2026-04-07T02:29:26.101302895Z","rtype":160,"publisher_id":101,"instrument_id":436},"action":"C","side":"A","price":"1.156660000","size":30,"channel_id":23,"order_id":"1775528966096542114","flags":0,"ts_in_delta":958,"sequence":162530,"symbol":"FCEU SI 20260615 PS"}
{"ts_recv":"2026-04-07T02:29:26.101322372Z","hd":{"ts_event":"2026-04-07T02:29:26.101302895Z","rtype":160,"publisher_id":101,"instrument_id":436},"action":"A","side":"A","price":"1.156670000","size":30,"channel_id":23,"order_id":"1775528966101308568","flags":128,"ts_in_delta":958,"sequence":162530,"symbol":"FCEU SI 20260615 PS"}
{"ts_recv":"2026-04-07T02:29:26.101380223Z","hd":{"ts_event":"2026-04-07T02:29:26.101363797Z","rtype":160,"publisher_id":101,"instrument_id":436},"action":"C","side":"B","price":"1.156550000","size":30,"channel_id":23,"order_id":"10998900991336519166","flags":0,"ts_in_delta":916,"sequence":162531,"symbol":"FCEU SI 20260615 PS"}
{"ts_recv":"2026-04-07T02:29:26.101380223Z","hd":{"ts_event":"2026-04-07T02:29:26.101363797Z","rtype":160,"publisher_id":101,"instrument_id":436},"action":"A","side":"B","price":"1.156570000","size":30,"channel_id":23,"order_id":"10998901002956145601","flags":0,"ts_in_delta":916,"sequence":162531,"symbol":"FCEU SI 20260615 PS"}
{"ts_recv":"2026-04-07T02:29:26.101380223Z","hd":{"ts_event":"2026-04-07T02:29:26.101363797Z","rtype":160,"publisher_id":101,"instrument_id":436},"action":"C","side":"A","price":"1.156650000","size":30,"channel_id":23,"order_id":"1775528954481743358","flags":0,"ts_in_delta":916,"sequence":162531,"symbol":"FCEU SI 20260615 PS"}
{"ts_recv":"2026-04-07T02:29:26.101380223Z","hd":{"ts_event":"2026-04-07T02:29:26.101363797Z","rtype":160,"publisher_id":101,"instrument_id":436},"action":"A","side":"A","price":"1.156670000","size":30,"channel_id":23,"order_id":"1775528966101369793","flags":128,"ts_in_delta":916,"sequence":162531,"symbol":"FCEU SI 20260615 PS"}
{"ts_recv":"2026-04-07T02:29:26.101434695Z","hd":{"ts_event":"2026-04-07T02:29:26.101414735Z","rtype":160,"publisher_id":101,"instrument_id":436},"action":"C","side":"B","price":"1.156570000","size":30,"channel_id":23,"order_id":"10998901002956084376","flags":0,"ts_in_delta":908,"sequence":162532,"symbol":"FCEU SI 20260615 PS"}
{"ts_recv":"2026-04-07T02:29:26.101434695Z","hd":{"ts_event":"2026-04-07T02:29:26.101414735Z","rtype":160,"publisher_id":101,"instrument_id":436},"action":"A","side":"B","price":"1.156580000","size":30,"channel_id":23,"order_id":"10998901002956195993","flags":0,"ts_in_delta":908,"sequence":162532,"symbol":"FCEU SI 20260615 PS"}
{"ts_recv":"2026-04-07T02:29:26.101434695Z","hd":{"ts_event":"2026-04-07T02:29:26.101414735Z","rtype":160,"publisher_id":101,"instrument_id":436},"action":"C","side":"A","price":"1.156670000","size":30,"channel_id":23,"order_id":"1775528966101308568","flags":0,"ts_in_delta":908,"sequence":162532,"symbol":"FCEU SI 20260615 PS"}
{"ts_recv":"2026-04-07T02:29:26.101434695Z","hd":{"ts_event":"2026-04-07T02:29:26.101414735Z","rtype":160,"publisher_id":101,"instrument_id":436},"action":"A","side":"A","price":"1.156680000","size":30,"channel_id":23,"order_id":"1775528966101420185","flags":128,"ts_in_delta":908,"sequence":162532,"symbol":"FCEU SI 20260615 PS"}
{"ts_recv":"2026-04-07T02:29:26.106813458Z","hd":{"ts_event":"2026-04-07T02:29:26.106793015Z","rtype":160,"publisher_id":101,"instrument_id":436},"action":"C","side":"B","price":"1.156580000","size":30,"channel_id":23,"order_id":"10998901002956195993","flags":0,"ts_in_delta":968,"sequence":162535,"symbol":"FCEU SI 20260615 PS"}
{"ts_recv":"2026-04-07T02:29:26.106813458Z","hd":{"ts_event":"2026-04-07T02:29:26.106793015Z","rtype":160,"publisher_id":101,"instrument_id":436},"action":"A","side":"B","price":"1.156590000","size":30,"channel_id":23,"order_id":"10998901002961574639","flags":0,"ts_in_delta":968,"sequence":162535,"symbol":"FCEU SI 20260615 PS"}
{"ts_recv":"2026-04-07T02:29:26.106813458Z","hd":{"ts_event":"2026-04-07T02:29:26.106793015Z","rtype":160,"publisher_id":101,"instrument_id":436},"action":"C","side":"A","price":"1.156680000","size":30,"channel_id":23,"order_id":"1775528966101420185","flags":0,"ts_in_delta":968,"sequence":162535,"symbol":"FCEU SI 20260615 PS"}
{"ts_recv":"2026-04-07T02:29:26.106813458Z","hd":{"ts_event":"2026-04-07T02:29:26.106793015Z","rtype":160,"publisher_id":101,"instrument_id":436},"action":"A","side":"A","price":"1.156690000","size":30,"channel_id":23,"order_id":"1775528966106798831","flags":128,"ts_in_delta":968,"sequence":162535,"symbol":"FCEU SI 20260615 PS"}
{"ts_recv":"2026-04-07T02:29:26.106905376Z","hd":{"ts_event":"2026-04-07T02:29:26.106888207Z","rtype":160,"publisher_id":101,"instrument_id":436},"action":"C","side":"B","price":"1.156590000","size":30,"channel_id":23,"order_id":"10998901002961574639","flags":0,"ts_in_delta":895,"sequence":162537,"symbol":"FCEU SI 20260615 PS"}
{"ts_recv":"2026-04-07T02:29:26.106905376Z","hd":{"ts_event":"2026-04-07T02:29:26.106888207Z","rtype":160,"publisher_id":101,"instrument_id":436},"action":"A","side":"B","price":"1.156580000","size":30,"channel_id":23,"order_id":"10998901002961670147","flags":0,"ts_in_delta":895,"sequence":162537,"symbol":"FCEU SI 20260615 PS"}
{"ts_recv":"2026-04-07T02:29:26.106905376Z","hd":{"ts_event":"2026-04-07T02:29:26.106888207Z","rtype":160,"publisher_id":101,"instrument_id":436},"action":"C","side":"A","price":"1.156690000","size":30,"channel_id":23,"order_id":"1775528966106798831","flags":0,"ts_in_delta":895,"sequence":162537,"symbol":"FCEU SI 20260615 PS"}
{"ts_recv":"2026-04-07T02:29:26.106905376Z","hd":{"ts_event":"2026-04-07T02:29:26.106888207Z","rtype":160,"publisher_id":101,"instrument_id":436},"action":"A","side":"A","price":"1.156680000","size":30,"channel_id":23,"order_id":"1775528966106894339","flags":128,"ts_in_delta":895,"sequence":162537,"symbol":"FCEU SI 20260615 PS"}
{"ts_recv":"2026-04-07T02:29:37.089340685Z","hd":{"ts_event":"2026-04-07T02:29:37.089307507Z","rtype":160,"publisher_id":101,"instrument_id":436},"action":"C","side":"B","price":"1.156570000","size":30,"channel_id":23,"order_id":"10998901002956145601","flags":0,"ts_in_delta":1146,"sequence":162625,"symbol":"FCEU SI 20260615 PS"}
{"ts_recv":"2026-04-07T02:29:37.089340685Z","hd":{"ts_event":"2026-04-07T02:29:37.089307507Z","rtype":160,"publisher_id":101,"instrument_id":436},"action":"A","side":"B","price":"1.156590000","size":30,"channel_id":23,"order_id":"10998901013944097494","flags":0,"ts_in_delta":1146,"sequence":162625,"symbol":"FCEU SI 20260615 PS"}
{"ts_recv":"2026-04-07T02:29:37.089340685Z","hd":{"ts_event":"2026-04-07T02:29:37.089307507Z","rtype":160,"publisher_id":101,"instrument_id":436},"action":"C","side":"A","price":"1.156670000","size":30,"channel_id":23,"order_id":"1775528966101369793","flags":0,"ts_in_delta":1146,"sequence":162625,"symbol":"FCEU SI 20260615 PS"}
{"ts_recv":"2026-04-07T02:29:37.089340685Z","hd":{"ts_event":"2026-04-07T02:29:37.089307507Z","rtype":160,"publisher_id":101,"instrument_id":436},"action":"A","side":"A","price":"1.156690000","size":30,"channel_id":23,"order_id":"1775528977089321686","flags":128,"ts_in_delta":1146,"sequence":162625,"symbol":"FCEU SI 20260615 PS"}
{"ts_recv":"2026-04-07T02:29:37.089460587Z","hd":{"ts_event":"2026-04-07T02:29:37.089443937Z","rtype":160,"publisher_id":101,"instrument_id":436},"action":"C","side":"B","price":"1.156580000","size":30,"channel_id":23,"order_id":"10998901002961670147","flags":0,"ts_in_delta":924,"sequence":162626,"symbol":"FCEU SI 20260615 PS"}
{"ts_recv":"2026-04-07T02:29:37.089460587Z","hd":{"ts_event":"2026-04-07T02:29:37.089443937Z","rtype":160,"publisher_id":101,"instrument_id":436},"action":"A","side":"B","price":"1.156590000","size":30,"channel_id":23,"order_id":"10998901013944225977","flags":0,"ts_in_delta":924,"sequence":162626,"symbol":"FCEU SI 20260615 PS"}
{"ts_recv":"2026-04-07T02:29:37.089460587Z","hd":{"ts_event":"2026-04-07T02:29:37.089443937Z","rtype":160,"publisher_id":101,"instrument_id":436},"action":"C","side":"A","price":"1.156680000","size":30,"channel_id":23,"order_id":"1775528966106894339","flags":0,"ts_in_delta":924,"sequence":162626,"symbol":"FCEU SI 20260615 PS"}
{"ts_recv":"2026-04-07T02:29:37.089460587Z","hd":{"ts_event":"2026-04-07T02:29:37.089443937Z","rtype":160,"publisher_id":101,"instrument_id":436},"action":"A","side":"A","price":"1.156690000","size":30,"channel_id":23,"order_id":"1775528977089450169","flags":128,"ts_in_delta":924,"sequence":162626,"symbol":"FCEU SI 20260615 PS"}
{"ts_recv":"2026-04-07T02:29:37.168325774Z","hd":{"ts_event":"2026-04-07T02:29:37.168304831Z","rtype":160,"publisher_id":101,"instrument_id":436},"action":"C","side":"B","price":"1.156590000","size":30,"channel_id":23,"order_id":"10998901013944225977","flags":0,"ts_in_delta":953,"sequence":162636,"symbol":"FCEU SI 20260615 PS"}
{"ts_recv":"2026-04-07T02:29:37.168325774Z","hd":{"ts_event":"2026-04-07T02:29:37.168304831Z","rtype":160,"publisher_id":101,"instrument_id":436},"action":"A","side":"B","price":"1.156600000","size":30,"channel_id":23,"order_id":"10998901014023086446","flags":0,"ts_in_delta":953,"sequence":162636,"symbol":"FCEU SI 20260615 PS"}
{"ts_recv":"2026-04-07T02:29:37.168325774Z","hd":{"ts_event":"2026-04-07T02:29:37.168304831Z","rtype":160,"publisher_id":101,"instrument_id":436},"action":"C","side":"A","price":"1.156690000","size":30,"channel_id":23,"order_id":"1775528977089450169","flags":0,"ts_in_delta":953,"sequence":162636,"symbol":"FCEU SI 20260615 PS"}
{"ts_recv":"2026-04-07T02:29:37.168325774Z","hd":{"ts_event":"2026-04-07T02:29:37.168304831Z","rtype":160,"publisher_id":101,"instrument_id":436},"action":"A","side":"A","price":"1.156700000","size":30,"channel_id":23,"order_id":"1775528977168310638","flags":128,"ts_in_delta":953,"sequence":162636,"symbol":"FCEU SI 20260615 PS"}
{"ts_recv":"2026-04-07T02:29:37.168409398Z","hd":{"ts_event":"2026-04-07T02:29:37.168388947Z","rtype":160,"publisher_id":101,"instrument_id":436},"action":"C","side":"B","price":"1.156600000","size":30,"channel_id":23,"order_id":"10998901014023086446","flags":0,"ts_in_delta":915,"sequence":162637,"symbol":"FCEU SI 20260615 PS"}
{"ts_recv":"2026-04-07T02:29:37.168409398Z","hd":{"ts_event":"2026-04-07T02:29:37.168388947Z","rtype":160,"publisher_id":101,"instrument_id":436},"action":"A","side":"B","price":"1.156610000","size":30,"channel_id":23,"order_id":"10998901014023170966","flags":0,"ts_in_delta":915,"sequence":162637,"symbol":"FCEU SI 20260615 PS"}
{"ts_recv":"2026-04-07T02:29:37.168409398Z","hd":{"ts_event":"2026-04-07T02:29:37.168388947Z","rtype":160,"publisher_id":101,"instrument_id":436},"action":"C","side":"A","price":"1.156700000","size":30,"channel_id":23,"order_id":"1775528977168310638","flags":0,"ts_in_delta":915,"sequence":162637,"symbol":"FCEU SI 20260615 PS"}
{"ts_recv":"2026-04-07T02:29:37.168409398Z","hd":{"ts_event":"2026-04-07T02:29:37.168388947Z","rtype":160,"publisher_id":101,"instrument_id":436},"action":"A","side":"A","price":"1.156710000","size":30,"channel_id":23,"order_id":"1775528977168395158","flags":128,"ts_in_delta":915,"sequence":162637,"symbol":"FCEU SI 20260615 PS"}
{"ts_recv":"2026-04-07T02:29:37.168455122Z","hd":{"ts_event":"2026-04-07T02:29:37.168438191Z","rtype":160,"publisher_id":101,"instrument_id":436},"action":"C","side":"B","price":"1.156590000","size":30,"channel_id":23,"order_id":"10998901013944097494","flags":0,"ts_in_delta":924,"sequence":162638,"symbol":"FCEU SI 20260615 PS"}
{"ts_recv":"2026-04-07T02:29:37.168455122Z","hd":{"ts_event":"2026-04-07T02:29:37.168438191Z","rtype":160,"publisher_id":101,"instrument_id":436},"action":"A","side":"B","price":"1.156610000","size":30,"channel_id":23,"order_id":"10998901014023219964","flags":0,"ts_in_delta":924,"sequence":162638,"symbol":"FCEU SI 20260615 PS"}
{"ts_recv":"2026-04-07T02:29:37.168455122Z","hd":{"ts_event":"2026-04-07T02:29:37.168438191Z","rtype":160,"publisher_id":101,"instrument_id":436},"action":"C","side":"A","price":"1.156690000","size":30,"channel_id":23,"order_id":"1775528977089321686","flags":0,"ts_in_delta":924,"sequence":162638,"symbol":"FCEU SI 20260615 PS"}
{"ts_recv":"2026-04-07T02:29:37.168455122Z","hd":{"ts_event":"2026-04-07T02:29:37.168438191Z","rtype":160,"publisher_id":101,"instrument_id":436},"action":"A","side":"A","price":"1.156710000","size":30,"channel_id":23,"order_id":"1775528977168444156","flags":128,"ts_in_delta":924,"sequence":162638,"symbol":"FCEU SI 20260615 PS"}
{"ts_recv":"2026-04-07T02:29:37.168476963Z","hd":{"ts_event":"2026-04-07T02:29:37.168455649Z","rtype":160,"publisher_id":101,"instrument_id":436},"action":"C","side":"B","price":"1.156610000","size":30,"channel_id":23,"order_id":"10998901014023170966","flags":0,"ts_in_delta":929,"sequence":162639,"symbol":"FCEU SI 20260615 PS"}
{"ts_recv":"2026-04-07T02:29:37.168476963Z","hd":{"ts_event":"2026-04-07T02:29:37.168455649Z","rtype":160,"publisher_id":101,"instrument_id":436},"action":"A","side":"B","price":"1.156600000","size":30,"channel_id":23,"order_id":"10998901014023240766","flags":0,"ts_in_delta":929,"sequence":162639,"symbol":"FCEU SI 20260615 PS"}
{"ts_recv":"2026-04-07T02:29:37.168476963Z","hd":{"ts_event":"2026-04-07T02:29:37.168455649Z","rtype":160,"publisher_id":101,"instrument_id":436},"action":"C","side":"A","price":"1.156710000","size":30,"channel_id":23,"order_id":"1775528977168395158","flags":0,"ts_in_delta":929,"sequence":162639,"symbol":"FCEU SI 20260615 PS"}
{"ts_recv":"2026-04-07T02:29:37.168476963Z","hd":{"ts_event":"2026-04-07T02:29:37.168455649Z","rtype":160,"publisher_id":101,"instrument_id":436},"action":"A","side":"A","price":"1.156700000","size":30,"channel_id":23,"order_id":"1775528977168464958","flags":128,"ts_in_delta":929,"sequence":162639,"symbol":"FCEU SI 20260615 PS"}
{"ts_recv":"2026-04-07T02:29:37.168530429Z","hd":{"ts_event":"2026-04-07T02:29:37.168515509Z","rtype":160,"publisher_id":101,"instrument_id":436},"action":"C","side":"B","price":"1.156600000","size":30,"channel_id":23,"order_id":"10998901014023240766","flags":0,"ts_in_delta":936,"sequence":162640,"symbol":"FCEU SI 20260615 PS"}
{"ts_recv":"2026-04-07T02:29:37.168530429Z","hd":{"ts_event":"2026-04-07T02:29:37.168515509Z","rtype":160,"publisher_id":101,"instrument_id":436},"action":"A","side":"B","price":"1.156610000","size":30,"channel_id":23,"order_id":"10998901014023297019","flags":0,"ts_in_delta":936,"sequence":162640,"symbol":"FCEU SI 20260615 PS"}
{"ts_recv":"2026-04-07T02:29:37.168530429Z","hd":{"ts_event":"2026-04-07T02:29:37.168515509Z","rtype":160,"publisher_id":101,"instrument_id":436},"action":"C","side":"A","price":"1.156700000","size":30,"channel_id":23,"order_id":"1775528977168464958","flags":0,"ts_in_delta":936,"sequence":162640,"symbol":"FCEU SI 20260615 PS"}
{"ts_recv":"2026-04-07T02:29:37.168530429Z","hd":{"ts_event":"2026-04-07T02:29:37.168515509Z","rtype":160,"publisher_id":101,"instrument_id":436},"action":"A","side":"A","price":"1.156710000","size":30,"channel_id":23,"order_id":"1775528977168521211","flags":128,"ts_in_delta":936,"sequence":162640,"symbol":"FCEU SI 20260615 PS"}
{"ts_recv":"2026-04-07T02:29:38.013716478Z","hd":{"ts_event":"2026-04-07T02:29:38.013689079Z","rtype":160,"publisher_id":101,"instrument_id":436},"action":"A","side":"B","price":"1.156500000","size":20,"channel_id":23,"order_id":"10998901014868479363","flags":128,"ts_in_delta":1177,"sequence":162662,"symbol":"FCEU SI 20260615 PS"}
{"ts_recv":"2026-04-07T02:29:38.013719588Z","hd":{"ts_event":"2026-04-07T02:29:38.013695203Z","rtype":160,"publisher_id":101,"instrument_id":436},"action":"C","side":"B","price":"1.156400000","size":20,"channel_id":23,"order_id":"10998900863247004555","flags":128,"ts_in_delta":747,"sequence":162663,"symbol":"FCEU SI 20260615 PS"}
{"ts_recv":"2026-04-07T02:29:40.266301872Z","hd":{"ts_event":"2026-04-07T02:29:40.266274467Z","rtype":160,"publisher_id":101,"instrument_id":436},"action":"C","side":"B","price":"1.156610000","size":30,"channel_id":23,"order_id":"10998901014023297019","flags":0,"ts_in_delta":929,"sequence":162680,"symbol":"FCEU SI 20260615 PS"}
{"ts_recv":"2026-04-07T02:29:40.266301872Z","hd":{"ts_event":"2026-04-07T02:29:40.266274467Z","rtype":160,"publisher_id":101,"instrument_id":436},"action":"A","side":"B","price":"1.156620000","size":30,"channel_id":23,"order_id":"10998901017121061582","flags":0,"ts_in_delta":929,"sequence":162680,"symbol":"FCEU SI 20260615 PS"}
{"ts_recv":"2026-04-07T02:29:40.266301872Z","hd":{"ts_event":"2026-04-07T02:29:40.266274467Z","rtype":160,"publisher_id":101,"instrument_id":436},"action":"C","side":"A","price":"1.156710000","size":30,"channel_id":23,"order_id":"1775528977168521211","flags":0,"ts_in_delta":929,"sequence":162680,"symbol":"FCEU SI 20260615 PS"}
{"ts_recv":"2026-04-07T02:29:40.266301872Z","hd":{"ts_event":"2026-04-07T02:29:40.266274467Z","rtype":160,"publisher_id":101,"instrument_id":436},"action":"A","side":"A","price":"1.156720000","size":30,"channel_id":23,"order_id":"1775528980266285774","flags":128,"ts_in_delta":929,"sequence":162680,"symbol":"FCEU SI 20260615 PS"}
{"ts_recv":"2026-04-07T02:29:42.137428864Z","hd":{"ts_event":"2026-04-07T02:29:42.137402985Z","rtype":160,"publisher_id":101,"instrument_id":436},"action":"C","side":"B","price":"1.156620000","size":30,"channel_id":23,"order_id":"10998901017121061582","flags":0,"ts_in_delta":1292,"sequence":162691,"symbol":"FCEU SI 20260615 PS"}
{"ts_recv":"2026-04-07T02:29:42.137428864Z","hd":{"ts_event":"2026-04-07T02:29:42.137402985Z","rtype":160,"publisher_id":101,"instrument_id":436},"action":"A","side":"B","price":"1.156610000","size":30,"channel_id":23,"order_id":"10998901018992188232","flags":0,"ts_in_delta":1292,"sequence":162691,"symbol":"FCEU SI 20260615 PS"}
{"ts_recv":"2026-04-07T02:29:42.137428864Z","hd":{"ts_event":"2026-04-07T02:29:42.137402985Z","rtype":160,"publisher_id":101,"instrument_id":436},"action":"C","side":"A","price":"1.156720000","size":30,"channel_id":23,"order_id":"1775528980266285774","flags":0,"ts_in_delta":1292,"sequence":162691,"symbol":"FCEU SI 20260615 PS"}
{"ts_recv":"2026-04-07T02:29:42.137428864Z","hd":{"ts_event":"2026-04-07T02:29:42.137402985Z","rtype":160,"publisher_id":101,"instrument_id":436},"action":"A","side":"A","price":"1.156710000","size":30,"channel_id":23,"order_id":"1775528982137412424","flags":128,"ts_in_delta":1292,"sequence":162691,"symbol":"FCEU SI 20260615 PS"}
{"ts_recv":"2026-04-07T02:29:42.148036584Z","hd":{"ts_event":"2026-04-07T02:29:42.148018231Z","rtype":160,"publisher_id":101,"instrument_id":436},"action":"C","side":"B","price":"1.156610000","size":30,"channel_id":23,"order_id":"10998901018992188232","flags":0,"ts_in_delta":892,"sequence":162695,"symbol":"FCEU SI 20260615 PS"}
{"ts_recv":"2026-04-07T02:29:42.148036584Z","hd":{"ts_event":"2026-04-07T02:29:42.148018231Z","rtype":160,"publisher_id":101,"instrument_id":436},"action":"A","side":"B","price":"1.156600000","size":30,"channel_id":23,"order_id":"10998901019002800274","flags":0,"ts_in_delta":892,"sequence":162695,"symbol":"FCEU SI 20260615 PS"}
{"ts_recv":"2026-04-07T02:29:42.148036584Z","hd":{"ts_event":"2026-04-07T02:29:42.148018231Z","rtype":160,"publisher_id":101,"instrument_id":436},"action":"C","side":"A","price":"1.156710000","size":30,"channel_id":23,"order_id":"1775528982137412424","flags":0,"ts_in_delta":892,"sequence":162695,"symbol":"FCEU SI 20260615 PS"}
{"ts_recv":"2026-04-07T02:29:42.148036584Z","hd":{"ts_event":"2026-04-07T02:29:42.148018231Z","rtype":160,"publisher_id":101,"instrument_id":436},"action":"A","side":"A","price":"1.156700000","size":30,"channel_id":23,"order_id":"1775528982148024466","flags":128,"ts_in_delta":892,"sequence":162695,"symbol":"FCEU SI 20260615 PS"}
{"ts_recv":"2026-04-07T02:29:42.152272554Z","hd":{"ts_event":"2026-04-07T02:29:42.152252425Z","rtype":160,"publisher_id":101,"instrument_id":436},"action":"C","side":"B","price":"1.156610000","size":30,"channel_id":23,"order_id":"10998901014023219964","flags":0,"ts_in_delta":906,"sequence":162696,"symbol":"FCEU SI 20260615 PS"}
{"ts_recv":"2026-04-07T02:29:42.152272554Z","hd":{"ts_event":"2026-04-07T02:29:42.152252425Z","rtype":160,"publisher_id":101,"instrument_id":436},"action":"A","side":"B","price":"1.156590000","size":30,"channel_id":23,"order_id":"10998901019007034144","flags":0,"ts_in_delta":906,"sequence":162696,"symbol":"FCEU SI 20260615 PS"}
{"ts_recv":"2026-04-07T02:29:42.152272554Z","hd":{"ts_event":"2026-04-07T02:29:42.152252425Z","rtype":160,"publisher_id":101,"instrument_id":436},"action":"C","side":"A","price":"1.156710000","size":30,"channel_id":23,"order_id":"1775528977168444156","flags":0,"ts_in_delta":906,"sequence":162696,"symbol":"FCEU SI 20260615 PS"}
{"ts_recv":"2026-04-07T02:29:42.152272554Z","hd":{"ts_event":"2026-04-07T02:29:42.152252425Z","rtype":160,"publisher_id":101,"instrument_id":436},"action":"A","side":"A","price":"1.156690000","size":30,"channel_id":23,"order_id":"1775528982152258336","flags":128,"ts_in_delta":906,"sequence":162696,"symbol":"FCEU SI 20260615 PS"}
{"ts_recv":"2026-04-07T02:29:42.152326995Z","hd":{"ts_event":"2026-04-07T02:29:42.152311029Z","rtype":160,"publisher_id":101,"instrument_id":436},"action":"C","side":"B","price":"1.156600000","size":30,"channel_id":23,"order_id":"10998901019002800274","flags":0,"ts_in_delta":917,"sequence":162697,"symbol":"FCEU SI 20260615 PS"}
{"ts_recv":"2026-04-07T02:29:42.152326995Z","hd":{"ts_event":"2026-04-07T02:29:42.152311029Z","rtype":160,"publisher_id":101,"instrument_id":436},"action":"A","side":"B","price":"1.156590000","size":30,"channel_id":23,"order_id":"10998901019007092696","flags":0,"ts_in_delta":917,"sequence":162697,"symbol":"FCEU SI 20260615 PS"}
{"ts_recv":"2026-04-07T02:29:42.152326995Z","hd":{"ts_event":"2026-04-07T02:29:42.152311029Z","rtype":160,"publisher_id":101,"instrument_id":436},"action":"C","side":"A","price":"1.156700000","size":30,"channel_id":23,"order_id":"1775528982148024466","flags":0,"ts_in_delta":917,"sequence":162697,"symbol":"FCEU SI 20260615 PS"}
{"ts_recv":"2026-04-07T02:29:42.152326995Z","hd":{"ts_event":"2026-04-07T02:29:42.152311029Z","rtype":160,"publisher_id":101,"instrument_id":436},"action":"A","side":"A","price":"1.156690000","size":30,"channel_id":23,"order_id":"1775528982152316888","flags":128,"ts_in_delta":917,"sequence":162697,"symbol":"FCEU SI 20260615 PS"}
{"ts_recv":"2026-04-07T02:30:02.079439127Z","hd":{"ts_event":"2026-04-07T02:30:02.079415859Z","rtype":160,"publisher_id":101,"instrument_id":436},"action":"C","side":"B","price":"1.156590000","size":30,"channel_id":23,"order_id":"10998901019007092696","flags":0,"ts_in_delta":1072,"sequence":162841,"symbol":"FCEU SI 20260615 PS"}
{"ts_recv":"2026-04-07T02:30:02.079439127Z","hd":{"ts_event":"2026-04-07T02:30:02.079415859Z","rtype":160,"publisher_id":101,"instrument_id":436},"action":"A","side":"B","price":"1.156600000","size":30,"channel_id":23,"order_id":"10998901038934197720","flags":0,"ts_in_delta":1072,"sequence":162841,"symbol":"FCEU SI 20260615 PS"}
{"ts_recv":"2026-04-07T02:30:02.079439127Z","hd":{"ts_event":"2026-04-07T02:30:02.079415859Z","rtype":160,"publisher_id":101,"instrument_id":436},"action":"C","side":"A","price":"1.156690000","size":30,"channel_id":23,"order_id":"1775528982152316888","flags":0,"ts_in_delta":1072,"sequence":162841,"symbol":"FCEU SI 20260615 PS"}
{"ts_recv":"2026-04-07T02:30:02.079439127Z","hd":{"ts_event":"2026-04-07T02:30:02.079415859Z","rtype":160,"publisher_id":101,"instrument_id":436},"action":"A","side":"A","price":"1.156700000","size":30,"channel_id":23,"order_id":"1775529002079421912","flags":128,"ts_in_delta":1072,"sequence":162841,"symbol":"FCEU SI 20260615 PS"}
{"ts_recv":"2026-04-07T02:30:02.079526160Z","hd":{"ts_event":"2026-04-07T02:30:02.079504621Z","rtype":160,"publisher_id":101,"instrument_id":436},"action":"C","side":"B","price":"1.156600000","size":30,"channel_id":23,"order_id":"10998901038934197720","flags":0,"ts_in_delta":879,"sequence":162842,"symbol":"FCEU SI 20260615 PS"}
{"ts_recv":"2026-04-07T02:30:02.079526160Z","hd":{"ts_event":"2026-04-07T02:30:02.079504621Z","rtype":160,"publisher_id":101,"instrument_id":436},"action":"A","side":"B","price":"1.156610000","size":30,"channel_id":23,"order_id":"10998901038934286365","flags":0,"ts_in_delta":879,"sequence":162842,"symbol":"FCEU SI 20260615 PS"}
{"ts_recv":"2026-04-07T02:30:02.079526160Z","hd":{"ts_event":"2026-04-07T02:30:02.079504621Z","rtype":160,"publisher_id":101,"instrument_id":436},"action":"C","side":"A","price":"1.156700000","size":30,"channel_id":23,"order_id":"1775529002079421912","flags":0,"ts_in_delta":879,"sequence":162842,"symbol":"FCEU SI 20260615 PS"}
{"ts_recv":"2026-04-07T02:30:02.079526160Z","hd":{"ts_event":"2026-04-07T02:30:02.079504621Z","rtype":160,"publisher_id":101,"instrument_id":436},"action":"A","side":"A","price":"1.156710000","size":30,"channel_id":23,"order_id":"1775529002079510557","flags":128,"ts_in_delta":879,"sequence":162842,"symbol":"FCEU SI 20260615 PS"}
{"ts_recv":"2026-04-07T02:30:02.079580694Z","hd":{"ts_event":"2026-04-07T02:30:02.079563239Z","rtype":160,"publisher_id":101,"instrument_id":436},"action":"C","side":"B","price":"1.156590000","size":30,"channel_id":23,"order_id":"10998901019007034144","flags":0,"ts_in_delta":889,"sequence":162843,"symbol":"FCEU SI 20260615 PS"}
{"ts_recv":"2026-04-07T02:30:02.079580694Z","hd":{"ts_event":"2026-04-07T02:30:02.079563239Z","rtype":160,"publisher_id":101,"instrument_id":436},"action":"A","side":"B","price":"1.156610000","size":30,"channel_id":23,"order_id":"10998901038934345385","flags":0,"ts_in_delta":889,"sequence":162843,"symbol":"FCEU SI 20260615 PS"}
{"ts_recv":"2026-04-07T02:30:02.079580694Z","hd":{"ts_event":"2026-04-07T02:30:02.079563239Z","rtype":160,"publisher_id":101,"instrument_id":436},"action":"C","side":"A","price":"1.156690000","size":30,"channel_id":23,"order_id":"1775528982152258336","flags":0,"ts_in_delta":889,"sequence":162843,"symbol":"FCEU SI 20260615 PS"}
{"ts_recv":"2026-04-07T02:30:02.079580694Z","hd":{"ts_event":"2026-04-07T02:30:02.079563239Z","rtype":160,"publisher_id":101,"instrument_id":436},"action":"A","side":"A","price":"1.156710000","size":30,"channel_id":23,"order_id":"1775529002079569577","flags":128,"ts_in_delta":889,"sequence":162843,"symbol":"FCEU SI 20260615 PS"}
{"ts_recv":"2026-04-07T02:30:02.079594041Z","hd":{"ts_event":"2026-04-07T02:30:02.079572723Z","rtype":160,"publisher_id":101,"instrument_id":436},"action":"C","side":"B","price":"1.156610000","size":30,"channel_id":23,"order_id":"10998901038934286365","flags":0,"ts_in_delta":977,"sequence":162844,"symbol":"FCEU SI 20260615 PS"}
{"ts_recv":"2026-04-07T02:30:02.079594041Z","hd":{"ts_event":"2026-04-07T02:30:02.079572723Z","rtype":160,"publisher_id":101,"instrument_id":436},"action":"A","side":"B","price":"1.156600000","size":30,"channel_id":23,"order_id":"10998901038934354364","flags":0,"ts_in_delta":977,"sequence":162844,"symbol":"FCEU SI 20260615 PS"}
{"ts_recv":"2026-04-07T02:30:02.079594041Z","hd":{"ts_event":"2026-04-07T02:30:02.079572723Z","rtype":160,"publisher_id":101,"instrument_id":436},"action":"C","side":"A","price":"1.156710000","size":30,"channel_id":23,"order_id":"1775529002079510557","flags":0,"ts_in_delta":977,"sequence":162844,"symbol":"FCEU SI 20260615 PS"}
{"ts_recv":"2026-04-07T02:30:02.079594041Z","hd":{"ts_event":"2026-04-07T02:30:02.079572723Z","rtype":160,"publisher_id":101,"instrument_id":436},"action":"A","side":"A","price":"1.156700000","size":30,"channel_id":23,"order_id":"1775529002079578556","flags":128,"ts_in_delta":977,"sequence":162844,"symbol":"FCEU SI 20260615 PS"}
{"ts_recv":"2026-04-07T02:30:02.079649611Z","hd":{"ts_event":"2026-04-07T02:30:02.079632149Z","rtype":160,"publisher_id":101,"instrument_id":436},"action":"C","side":"B","price":"1.156600000","size":30,"channel_id":23,"order_id":"10998901038934354364","flags":0,"ts_in_delta":918,"sequence":162845,"symbol":"FCEU SI 20260615 PS"}
{"ts_recv":"2026-04-07T02:30:02.079649611Z","hd":{"ts_event":"2026-04-07T02:30:02.079632149Z","rtype":160,"publisher_id":101,"instrument_id":436},"action":"A","side":"B","price":"1.156610000","size":30,"channel_id":23,"order_id":"10998901038934413876","flags":0,"ts_in_delta":918,"sequence":162845,"symbol":"FCEU SI 20260615 PS"}
{"ts_recv":"2026-04-07T02:30:02.079649611Z","hd":{"ts_event":"2026-04-07T02:30:02.079632149Z","rtype":160,"publisher_id":101,"instrument_id":436},"action":"C","side":"A","price":"1.156700000","size":30,"channel_id":23,"order_id":"1775529002079578556","flags":0,"ts_in_delta":918,"sequence":162845,"symbol":"FCEU SI 20260615 PS"}
{"ts_recv":"2026-04-07T02:30:02.079649611Z","hd":{"ts_event":"2026-04-07T02:30:02.079632149Z","rtype":160,"publisher_id":101,"instrument_id":436},"action":"A","side":"A","price":"1.156710000","size":30,"channel_id":23,"order_id":"1775529002079638068","flags":128,"ts_in_delta":918,"sequence":162845,"symbol":"FCEU SI 20260615 PS"}
{"ts_recv":"2026-04-07T02:30:02.673574086Z","hd":{"ts_event":"2026-04-07T02:30:02.673554215Z","rtype":160,"publisher_id":101,"instrument_id":436},"action":"C","side":"B","price":"1.156610000","size":30,"channel_id":23,"order_id":"10998901038934413876","flags":0,"ts_in_delta":1050,"sequence":162906,"symbol":"FCEU SI 20260615 PS"}
{"ts_recv":"2026-04-07T02:30:02.673574086Z","hd":{"ts_event":"2026-04-07T02:30:02.673554215Z","rtype":160,"publisher_id":101,"instrument_id":436},"action":"A","side":"B","price":"1.156600000","size":30,"channel_id":23,"order_id":"10998901039528336122","flags":0,"ts_in_delta":1050,"sequence":162906,"symbol":"FCEU SI 20260615 PS"}
{"ts_recv":"2026-04-07T02:30:02.673574086Z","hd":{"ts_event":"2026-04-07T02:30:02.673554215Z","rtype":160,"publisher_id":101,"instrument_id":436},"action":"C","side":"A","price":"1.156710000","size":30,"channel_id":23,"order_id":"1775529002079638068","flags":0,"ts_in_delta":1050,"sequence":162906,"symbol":"FCEU SI 20260615 PS"}
{"ts_recv":"2026-04-07T02:30:02.673574086Z","hd":{"ts_event":"2026-04-07T02:30:02.673554215Z","rtype":160,"publisher_id":101,"instrument_id":436},"action":"A","side":"A","price":"1.156700000","size":30,"channel_id":23,"order_id":"1775529002673560314","flags":128,"ts_in_delta":1050,"sequence":162906,"symbol":"FCEU SI 20260615 PS"}
{"ts_recv":"2026-04-07T02:30:02.673627529Z","hd":{"ts_event":"2026-04-07T02:30:02.673605663Z","rtype":160,"publisher_id":101,"instrument_id":436},"action":"C","side":"B","price":"1.156610000","size":30,"channel_id":23,"order_id":"10998901038934345385","flags":0,"ts_in_delta":985,"sequence":162907,"symbol":"FCEU SI 20260615 PS"}
{"ts_recv":"2026-04-07T02:30:02.673627529Z","hd":{"ts_event":"2026-04-07T02:30:02.673605663Z","rtype":160,"publisher_id":101,"instrument_id":436},"action":"A","side":"B","price":"1.156590000","size":30,"channel_id":23,"order_id":"10998901039528387313","flags":0,"ts_in_delta":985,"sequence":162907,"symbol":"FCEU SI 20260615 PS"}
{"ts_recv":"2026-04-07T02:30:02.673627529Z","hd":{"ts_event":"2026-04-07T02:30:02.673605663Z","rtype":160,"publisher_id":101,"instrument_id":436},"action":"C","side":"A","price":"1.156710000","size":30,"channel_id":23,"order_id":"1775529002079569577","flags":0,"ts_in_delta":985,"sequence":162907,"symbol":"FCEU SI 20260615 PS"}
{"ts_recv":"2026-04-07T02:30:02.673627529Z","hd":{"ts_event":"2026-04-07T02:30:02.673605663Z","rtype":160,"publisher_id":101,"instrument_id":436},"action":"A","side":"A","price":"1.156690000","size":30,"channel_id":23,"order_id":"1775529002673611505","flags":128,"ts_in_delta":985,"sequence":162907,"symbol":"FCEU SI 20260615 PS"}
{"ts_recv":"2026-04-07T02:30:02.673679505Z","hd":{"ts_event":"2026-04-07T02:30:02.673662631Z","rtype":160,"publisher_id":101,"instrument_id":436},"action":"C","side":"B","price":"1.156600000","size":30,"channel_id":23,"order_id":"10998901039528336122","flags":0,"ts_in_delta":931,"sequence":162908,"symbol":"FCEU SI 20260615 PS"}
{"ts_recv":"2026-04-07T02:30:02.673679505Z","hd":{"ts_event":"2026-04-07T02:30:02.673662631Z","rtype":160,"publisher_id":101,"instrument_id":436},"action":"A","side":"B","price":"1.156590000","size":30,"channel_id":23,"order_id":"10998901039528444400","flags":0,"ts_in_delta":931,"sequence":162908,"symbol":"FCEU SI 20260615 PS"}
{"ts_recv":"2026-04-07T02:30:02.673679505Z","hd":{"ts_event":"2026-04-07T02:30:02.673662631Z","rtype":160,"publisher_id":101,"instrument_id":436},"action":"C","side":"A","price":"1.156700000","size":30,"channel_id":23,"order_id":"1775529002673560314","flags":0,"ts_in_delta":931,"sequence":162908,"symbol":"FCEU SI 20260615 PS"}
{"ts_recv":"2026-04-07T02:30:02.673679505Z","hd":{"ts_event":"2026-04-07T02:30:02.673662631Z","rtype":160,"publisher_id":101,"instrument_id":436},"action":"A","side":"A","price":"1.156690000","size":30,"channel_id":23,"order_id":"1775529002673668592","flags":128,"ts_in_delta":931,"sequence":162908,"symbol":"FCEU SI 20260615 PS"}
{"ts_recv":"2026-04-07T02:30:08.151932714Z","hd":{"ts_event":"2026-04-07T02:30:08.151908347Z","rtype":160,"publisher_id":101,"instrument_id":436},"action":"C","side":"B","price":"1.156590000","size":30,"channel_id":23,"order_id":"10998901039528444400","flags":0,"ts_in_delta":1485,"sequence":162963,"symbol":"FCEU SI 20260615 PS"}
{"ts_recv":"2026-04-07T02:30:08.151932714Z","hd":{"ts_event":"2026-04-07T02:30:08.151908347Z","rtype":160,"publisher_id":101,"instrument_id":436},"action":"A","side":"B","price":"1.156580000","size":30,"channel_id":23,"order_id":"10998901045006692710","flags":0,"ts_in_delta":1485,"sequence":162963,"symbol":"FCEU SI 20260615 PS"}
{"ts_recv":"2026-04-07T02:30:08.151932714Z","hd":{"ts_event":"2026-04-07T02:30:08.151908347Z","rtype":160,"publisher_id":101,"instrument_id":436},"action":"C","side":"A","price":"1.156690000","size":30,"channel_id":23,"order_id":"1775529002673668592","flags":0,"ts_in_delta":1485,"sequence":162963,"symbol":"FCEU SI 20260615 PS"}
{"ts_recv":"2026-04-07T02:30:08.151932714Z","hd":{"ts_event":"2026-04-07T02:30:08.151908347Z","rtype":160,"publisher_id":101,"instrument_id":436},"action":"A","side":"A","price":"1.156680000","size":30,"channel_id":23,"order_id":"1775529008151916902","flags":128,"ts_in_delta":1485,"sequence":162963,"symbol":"FCEU SI 20260615 PS"}
{"ts_recv":"2026-04-07T02:30:08.151994673Z","hd":{"ts_event":"2026-04-07T02:30:08.151976545Z","rtype":160,"publisher_id":101,"instrument_id":436},"action":"C","side":"B","price":"1.156590000","size":30,"channel_id":23,"order_id":"10998901039528387313","flags":0,"ts_in_delta":941,"sequence":162964,"symbol":"FCEU SI 20260615 PS"}
{"ts_recv":"2026-04-07T02:30:08.151994673Z","hd":{"ts_event":"2026-04-07T02:30:08.151976545Z","rtype":160,"publisher_id":101,"instrument_id":436},"action":"A","side":"B","price":"1.156570000","size":30,"channel_id":23,"order_id":"10998901045006758305","flags":0,"ts_in_delta":941,"sequence":162964,"symbol":"FCEU SI 20260615 PS"}
{"ts_recv":"2026-04-07T02:30:08.151994673Z","hd":{"ts_event":"2026-04-07T02:30:08.151976545Z","rtype":160,"publisher_id":101,"instrument_id":436},"action":"C","side":"A","price":"1.156690000","size":30,"channel_id":23,"order_id":"1775529002673611505","flags":0,"ts_in_delta":941,"sequence":162964,"symbol":"FCEU SI 20260615 PS"}
{"ts_recv":"2026-04-07T02:30:08.151994673Z","hd":{"ts_event":"2026-04-07T02:30:08.151976545Z","rtype":160,"publisher_id":101,"instrument_id":436},"action":"A","side":"A","price":"1.156670000","size":30,"channel_id":23,"order_id":"1775529008151982497","flags":128,"ts_in_delta":941,"sequence":162964,"symbol":"FCEU SI 20260615 PS"}
{"ts_recv":"2026-04-07T02:30:08.152021321Z","hd":{"ts_event":"2026-04-07T02:30:08.152000929Z","rtype":160,"publisher_id":101,"instrument_id":436},"action":"C","side":"B","price":"1.156580000","size":30,"channel_id":23,"order_id":"10998901045006692710","flags":0,"ts_in_delta":887,"sequence":162965,"symbol":"FCEU SI 20260615 PS"}
{"ts_recv":"2026-04-07T02:30:08.152021321Z","hd":{"ts_event":"2026-04-07T02:30:08.152000929Z","rtype":160,"publisher_id":101,"instrument_id":436},"action":"A","side":"B","price":"1.156570000","size":30,"channel_id":23,"order_id":"10998901045006782862","flags":0,"ts_in_delta":887,"sequence":162965,"symbol":"FCEU SI 20260615 PS"}
{"ts_recv":"2026-04-07T02:30:08.152021321Z","hd":{"ts_event":"2026-04-07T02:30:08.152000929Z","rtype":160,"publisher_id":101,"instrument_id":436},"action":"C","side":"A","price":"1.156680000","size":30,"channel_id":23,"order_id":"1775529008151916902","flags":0,"ts_in_delta":887,"sequence":162965,"symbol":"FCEU SI 20260615 PS"}
{"ts_recv":"2026-04-07T02:30:08.152021321Z","hd":{"ts_event":"2026-04-07T02:30:08.152000929Z","rtype":160,"publisher_id":101,"instrument_id":436},"action":"A","side":"A","price":"1.156670000","size":30,"channel_id":23,"order_id":"1775529008152007054","flags":128,"ts_in_delta":887,"sequence":162965,"symbol":"FCEU SI 20260615 PS"}
{"ts_recv":"2026-04-07T02:30:08.163304391Z","hd":{"ts_event":"2026-04-07T02:30:08.163283283Z","rtype":160,"publisher_id":101,"instrument_id":436},"action":"C","side":"B","price":"1.156570000","size":30,"channel_id":23,"order_id":"10998901045006782862","flags":0,"ts_in_delta":874,"sequence":162969,"symbol":"FCEU SI 20260615 PS"}
{"ts_recv":"2026-04-07T02:30:08.163304391Z","hd":{"ts_event":"2026-04-07T02:30:08.163283283Z","rtype":160,"publisher_id":101,"instrument_id":436},"action":"A","side":"B","price":"1.156560000","size":30,"channel_id":23,"order_id":"10998901045018065226","flags":0,"ts_in_delta":874,"sequence":162969,"symbol":"FCEU SI 20260615 PS"}
{"ts_recv":"2026-04-07T02:30:08.163304391Z","hd":{"ts_event":"2026-04-07T02:30:08.163283283Z","rtype":160,"publisher_id":101,"instrument_id":436},"action":"C","side":"A","price":"1.156670000","size":30,"channel_id":23,"order_id":"1775529008152007054","flags":0,"ts_in_delta":874,"sequence":162969,"symbol":"FCEU SI 20260615 PS"}
{"ts_recv":"2026-04-07T02:30:08.163304391Z","hd":{"ts_event":"2026-04-07T02:30:08.163283283Z","rtype":160,"publisher_id":101,"instrument_id":436},"action":"A","side":"A","price":"1.156660000","size":30,"channel_id":23,"order_id":"1775529008163289418","flags":128,"ts_in_delta":874,"sequence":162969,"symbol":"FCEU SI 20260615 PS"}
{"ts_recv":"2026-04-07T02:30:08.163824373Z","hd":{"ts_event":"2026-04-07T02:30:08.163805253Z","rtype":160,"publisher_id":101,"instrument_id":436},"action":"C","side":"B","price":"1.156570000","size":30,"channel_id":23,"order_id":"10998901045006758305","flags":0,"ts_in_delta":1210,"sequence":162970,"symbol":"FCEU SI 20260615 PS"}
{"ts_recv":"2026-04-07T02:30:08.163824373Z","hd":{"ts_event":"2026-04-07T02:30:08.163805253Z","rtype":160,"publisher_id":101,"instrument_id":436},"action":"A","side":"B","price":"1.156550000","size":30,"channel_id":23,"order_id":"10998901045018587257","flags":0,"ts_in_delta":1210,"sequence":162970,"symbol":"FCEU SI 20260615 PS"}
{"ts_recv":"2026-04-07T02:30:08.163824373Z","hd":{"ts_event":"2026-04-07T02:30:08.163805253Z","rtype":160,"publisher_id":101,"instrument_id":436},"action":"C","side":"A","price":"1.156670000","size":30,"channel_id":23,"order_id":"1775529008151982497","flags":0,"ts_in_delta":1210,"sequence":162970,"symbol":"FCEU SI 20260615 PS"}
{"ts_recv":"2026-04-07T02:30:08.163824373Z","hd":{"ts_event":"2026-04-07T02:30:08.163805253Z","rtype":160,"publisher_id":101,"instrument_id":436},"action":"A","side":"A","price":"1.156650000","size":30,"channel_id":23,"order_id":"1775529008163811449","flags":128,"ts_in_delta":1210,"sequence":162970,"symbol":"FCEU SI 20260615 PS"}
{"ts_recv":"2026-04-07T02:30:08.163880611Z","hd":{"ts_event":"2026-04-07T02:30:08.163863315Z","rtype":160,"publisher_id":101,"instrument_id":436},"action":"C","side":"B","price":"1.156560000","size":30,"channel_id":23,"order_id":"10998901045018065226","flags":0,"ts_in_delta":1057,"sequence":162971,"symbol":"FCEU SI 20260615 PS"}
{"ts_recv":"2026-04-07T02:30:08.163880611Z","hd":{"ts_event":"2026-04-07T02:30:08.163863315Z","rtype":160,"publisher_id":101,"instrument_id":436},"action":"A","side":"B","price":"1.156550000","size":30,"channel_id":23,"order_id":"10998901045018645083","flags":0,"ts_in_delta":1057,"sequence":162971,"symbol":"FCEU SI 20260615 PS"}
{"ts_recv":"2026-04-07T02:30:08.163880611Z","hd":{"ts_event":"2026-04-07T02:30:08.163863315Z","rtype":160,"publisher_id":101,"instrument_id":436},"action":"C","side":"A","price":"1.156660000","size":30,"channel_id":23,"order_id":"1775529008163289418","flags":0,"ts_in_delta":1057,"sequence":162971,"symbol":"FCEU SI 20260615 PS"}
{"ts_recv":"2026-04-07T02:30:08.163880611Z","hd":{"ts_event":"2026-04-07T02:30:08.163863315Z","rtype":160,"publisher_id":101,"instrument_id":436},"action":"A","side":"A","price":"1.156650000","size":30,"channel_id":23,"order_id":"1775529008163869275","flags":128,"ts_in_delta":1057,"sequence":162971,"symbol":"FCEU SI 20260615 PS"}
{"ts_recv":"2026-04-07T02:30:11.711646906Z","hd":{"ts_event":"2026-04-07T02:30:11.711625433Z","rtype":160,"publisher_id":101,"instrument_id":436},"action":"C","side":"B","price":"1.156550000","size":30,"channel_id":23,"order_id":"10998901045018645083","flags":0,"ts_in_delta":899,"sequence":163016,"symbol":"FCEU SI 20260615 PS"}
{"ts_recv":"2026-04-07T02:30:11.711646906Z","hd":{"ts_event":"2026-04-07T02:30:11.711625433Z","rtype":160,"publisher_id":101,"instrument_id":436},"action":"A","side":"B","price":"1.156560000","size":30,"channel_id":23,"order_id":"10998901048566408772","flags":0,"ts_in_delta":899,"sequence":163016,"symbol":"FCEU SI 20260615 PS"}
{"ts_recv":"2026-04-07T02:30:11.711646906Z","hd":{"ts_event":"2026-04-07T02:30:11.711625433Z","rtype":160,"publisher_id":101,"instrument_id":436},"action":"C","side":"A","price":"1.156650000","size":30,"channel_id":23,"order_id":"1775529008163869275","flags":0,"ts_in_delta":899,"sequence":163016,"symbol":"FCEU SI 20260615 PS"}
{"ts_recv":"2026-04-07T02:30:11.711646906Z","hd":{"ts_event":"2026-04-07T02:30:11.711625433Z","rtype":160,"publisher_id":101,"instrument_id":436},"action":"A","side":"A","price":"1.156660000","size":30,"channel_id":23,"order_id":"1775529011711632964","flags":128,"ts_in_delta":899,"sequence":163016,"symbol":"FCEU SI 20260615 PS"}
