{"ts_recv":"2026-04-07T02:33:18.959977419Z","hd":{"ts_event":"2026-04-07T02:33:18.959959813Z","rtype":160,"publisher_id":101,"instrument_id":436},"action":"A","side":"B","price":"1.156520000","size":30,"channel_id":23,"order_id":"10998901235814741841","flags":0,"ts_in_delta":971,"sequence":164821,"symbol":"FCEU SI 20260615 PS"}
{"ts_recv":"2026-04-07T02:33:18.959977419Z","hd":{"ts_event":"2026-04-07T02:33:18.959959813Z","rtype":160,"publisher_id":101,"instrument_id":436},"action":"C","side":"A","price":"1.156610000","size":30,"channel_id":23,"order_id":"1775529198959905499","flags":0,"ts_in_delta":971,"sequence":164821,"symbol":"FCEU SI 20260615 PS"}
{"ts_recv":"2026-04-07T02:33:18.959977419Z","hd":{"ts_event":"2026-04-07T02:33:18.959959813Z","rtype":160,"publisher_id":101,"instrument_id":436},"action":"A","side":"A","price":"1.156620000","size":30,"channel_id":23,"order_id":"1775529198959966033","flags":128,"ts_in_delta":971,"sequence":164821,"symbol":"FCEU SI 20260615 PS"}
{"ts_recv":"2026-04-07T02:33:18.959990275Z","hd":{"ts_event":"2026-04-07T02:33:18.959960119Z","rtype":160,"publisher_id":101,"instrument_id":436},"action":"C","side":"B","price":"1.156530000","size":30,"channel_id":23,"order_id":"10998901228583273728","flags":0,"ts_in_delta":976,"sequence":164822,"symbol":"FCEU SI 20260615 PS"}
{"ts_recv":"2026-04-07T02:33:18.959990275Z","hd":{"ts_event":"2026-04-07T02:33:18.959960119Z","rtype":160,"publisher_id":101,"instrument_id":436},"action":"A","side":"B","price":"1.156510000","size":30,"channel_id":23,"order_id":"10998901235814749620","flags":0,"ts_in_delta":976,"sequence":164822,"symbol":"FCEU SI 20260615 PS"}
{"ts_recv":"2026-04-07T02:33:18.959990275Z","hd":{"ts_event":"2026-04-07T02:33:18.959960119Z","rtype":160,"publisher_id":101,"instrument_id":436},"action":"C","side":"A","price":"1.156630000","size":30,"channel_id":23,"order_id":"1775529191728497920","flags":0,"ts_in_delta":976,"sequence":164822,"symbol":"FCEU SI 20260615 PS"}
{"ts_recv":"2026-04-07T02:33:18.959990275Z","hd":{"ts_event":"2026-04-07T02:33:18.959960119Z","rtype":160,"publisher_id":101,"instrument_id":436},"action":"A","side":"A","price":"1.156610000","size":30,"channel_id":23,"order_id":"1775529198959973812","flags":128,"ts_in_delta":976,"sequence":164822,"symbol":"FCEU SI 20260615 PS"}
{"ts_recv":"2026-04-07T02:33:18.960055536Z","hd":{"ts_event":"2026-04-07T02:33:18.960035583Z","rtype":160,"publisher_id":101,"instrument_id":436},"action":"C","side":"B","price":"1.156520000","size":30,"channel_id":23,"order_id":"10998901235814741841","flags":0,"ts_in_delta":999,"sequence":164823,"symbol":"FCEU SI 20260615 PS"}
{"ts_recv":"2026-04-07T02:33:18.960055536Z","hd":{"ts_event":"2026-04-07T02:33:18.960035583Z","rtype":160,"publisher_id":101,"instrument_id":436},"action":"A","side":"B","price":"1.156510000","size":30,"channel_id":23,"order_id":"10998901235814817431","flags":0,"ts_in_delta":999,"sequence":164823,"symbol":"FCEU SI 20260615 PS"}
{"ts_recv":"2026-04-07T02:33:18.960055536Z","hd":{"ts_event":"2026-04-07T02:33:18.960035583Z","rtype":160,"publisher_id":101,"instrument_id":436},"action":"C","side":"A","price":"1.156620000","size":30,"channel_id":23,"order_id":"1775529198959966033","flags":0,"ts_in_delta":999,"sequence":164823,"symbol":"FCEU SI 20260615 PS"}
{"ts_recv":"2026-04-07T02:33:18.960055536Z","hd":{"ts_event":"2026-04-07T02:33:18.960035583Z","rtype":160,"publisher_id":101,"instrument_id":436},"action":"A","side":"A","price":"1.156610000","size":30,"channel_id":23,"order_id":"1775529198960041623","flags":128,"ts_in_delta":999,"sequence":164823,"symbol":"FCEU SI 20260615 PS"}
{"ts_recv":"2026-04-07T02:33:20.239130814Z","hd":{"ts_event":"2026-04-07T02:33:20.239111669Z","rtype":160,"publisher_id":101,"instrument_id":436},"action":"C","side":"B","price":"1.156510000","size":30,"channel_id":23,"order_id":"10998901235814817431","flags":0,"ts_in_delta":940,"sequence":164838,"symbol":"FCEU SI 20260615 PS"}
{"ts_recv":"2026-04-07T02:33:20.239130814Z","hd":{"ts_event":"2026-04-07T02:33:20.239111669Z","rtype":160,"publisher_id":101,"instrument_id":436},"action":"A","side":"B","price":"1.156520000","size":30,"channel_id":23,"order_id":"10998901237093894253","flags":0,"ts_in_delta":940,"sequence":164838,"symbol":"FCEU SI 20260615 PS"}
{"ts_recv":"2026-04-07T02:33:20.239130814Z","hd":{"ts_event":"2026-04-07T02:33:20.239111669Z","rtype":160,"publisher_id":101,"instrument_id":436},"action":"C","side":"A","price":"1.156610000","size":30,"channel_id":23,"order_id":"1775529198960041623","flags":0,"ts_in_delta":940,"sequence":164838,"symbol":"FCEU SI 20260615 PS"}
{"ts_recv":"2026-04-07T02:33:20.239130814Z","hd":{"ts_event":"2026-04-07T02:33:20.239111669Z","rtype":160,"publisher_id":101,"instrument_id":436},"action":"A","side":"A","price":"1.156620000","size":30,"channel_id":23,"order_id":"1775529200239118445","flags":128,"ts_in_delta":940,"sequence":164838,"symbol":"FCEU SI 20260615 PS"}
{"ts_recv":"2026-04-07T02:33:20.243721723Z","hd":{"ts_event":"2026-04-07T02:33:20.243700383Z","rtype":160,"publisher_id":101,"instrument_id":436},"action":"C","side":"B","price":"1.156520000","size":30,"channel_id":23,"order_id":"10998901237093894253","flags":0,"ts_in_delta":949,"sequence":164843,"symbol":"FCEU SI 20260615 PS"}
{"ts_recv":"2026-04-07T02:33:20.243721723Z","hd":{"ts_event":"2026-04-07T02:33:20.243700383Z","rtype":160,"publisher_id":101,"instrument_id":436},"action":"A","side":"B","price":"1.156530000","size":30,"channel_id":23,"order_id":"10998901237098482346","flags":0,"ts_in_delta":949,"sequence":164843,"symbol":"FCEU SI 20260615 PS"}
{"ts_recv":"2026-04-07T02:33:20.243721723Z","hd":{"ts_event":"2026-04-07T02:33:20.243700383Z","rtype":160,"publisher_id":101,"instrument_id":436},"action":"C","side":"A","price":"1.156620000","size":30,"channel_id":23,"order_id":"1775529200239118445","flags":0,"ts_in_delta":949,"sequence":164843,"symbol":"FCEU SI 20260615 PS"}
{"ts_recv":"2026-04-07T02:33:20.243721723Z","hd":{"ts_event":"2026-04-07T02:33:20.243700383Z","rtype":160,"publisher_id":101,"instrument_id":436},"action":"A","side":"A","price":"1.156630000","size":30,"channel_id":23,"order_id":"1775529200243706538","flags":128,"ts_in_delta":949,"sequence":164843,"symbol":"FCEU SI 20260615 PS"}
{"ts_recv":"2026-04-07T02:33:20.243769129Z","hd":{"ts_event":"2026-04-07T02:33:20.243753219Z","rtype":160,"publisher_id":101,"instrument_id":436},"action":"C","side":"B","price":"1.156510000","size":30,"channel_id":23,"order_id":"10998901235814749620","flags":0,"ts_in_delta":938,"sequence":164844,"symbol":"FCEU SI 20260615 PS"}
{"ts_recv":"2026-04-07T02:33:20.243769129Z","hd":{"ts_event":"2026-04-07T02:33:20.243753219Z","rtype":160,"publisher_id":101,"instrument_id":436},"action":"A","side":"B","price":"1.156530000","size":30,"channel_id":23,"order_id":"10998901237098534887","flags":0,"ts_in_delta":938,"sequence":164844,"symbol":"FCEU SI 20260615 PS"}
{"ts_recv":"2026-04-07T02:33:20.243769129Z","hd":{"ts_event":"2026-04-07T02:33:20.243753219Z","rtype":160,"publisher_id":101,"instrument_id":436},"action":"C","side":"A","price":"1.156610000","size":30,"channel_id":23,"order_id":"1775529198959973812","flags":0,"ts_in_delta":938,"sequence":164844,"symbol":"FCEU SI 20260615 PS"}
{"ts_recv":"2026-04-07T02:33:20.243769129Z","hd":{"ts_event":"2026-04-07T02:33:20.243753219Z","rtype":160,"publisher_id":101,"instrument_id":436},"action":"A","side":"A","price":"1.156630000","size":30,"channel_id":23,"order_id":"1775529200243759079","flags":128,"ts_in_delta":938,"sequence":164844,"symbol":"FCEU SI 20260615 PS"}
{"ts_recv":"2026-04-07T02:33:20.243824300Z","hd":{"ts_event":"2026-04-07T02:33:20.243806923Z","rtype":160,"publisher_id":101,"instrument_id":436},"action":"C","side":"B","price":"1.156530000","size":30,"channel_id":23,"order_id":"10998901237098482346","flags":0,"ts_in_delta":930,"sequence":164845,"symbol":"FCEU SI 20260615 PS"}
{"ts_recv":"2026-04-07T02:33:20.243824300Z","hd":{"ts_event":"2026-04-07T02:33:20.243806923Z","rtype":160,"publisher_id":101,"instrument_id":436},"action":"A","side":"B","price":"1.156540000","size":30,"channel_id":23,"order_id":"10998901237098588802","flags":0,"ts_in_delta":930,"sequence":164845,"symbol":"FCEU SI 20260615 PS"}
{"ts_recv":"2026-04-07T02:33:20.243824300Z","hd":{"ts_event":"2026-04-07T02:33:20.243806923Z","rtype":160,"publisher_id":101,"instrument_id":436},"action":"C","side":"A","price":"1.156630000","size":30,"channel_id":23,"order_id":"1775529200243706538","flags":0,"ts_in_delta":930,"sequence":164845,"symbol":"FCEU SI 20260615 PS"}
{"ts_recv":"2026-04-07T02:33:20.243824300Z","hd":{"ts_event":"2026-04-07T02:33:20.243806923Z","rtype":160,"publisher_id":101,"instrument_id":436},"action":"A","side":"A","price":"1.156640000","size":30,"channel_id":23,"order_id":"1775529200243812994","flags":128,"ts_in_delta":930,"sequence":164845,"symbol":"FCEU SI 20260615 PS"}
{"ts_recv":"2026-04-07T02:33:22.841860459Z","hd":{"ts_event":"2026-04-07T02:33:22.841831677Z","rtype":160,"publisher_id":101,"instrument_id":436},"action":"C","side":"B","price":"1.156540000","size":30,"channel_id":23,"order_id":"10998901237098588802","flags":0,"ts_in_delta":1575,"sequence":164883,"symbol":"FCEU SI 20260615 PS"}
{"ts_recv":"2026-04-07T02:33:22.841860459Z","hd":{"ts_event":"2026-04-07T02:33:22.841831677Z","rtype":160,"publisher_id":101,"instrument_id":436},"action":"A","side":"B","price":"1.156550000","size":30,"channel_id":23,"order_id":"10998901239696618614","flags":0,"ts_in_delta":1575,"sequence":164883,"symbol":"FCEU SI 20260615 PS"}
{"ts_recv":"2026-04-07T02:33:22.841860459Z","hd":{"ts_event":"2026-04-07T02:33:22.841831677Z","rtype":160,"publisher_id":101,"instrument_id":436},"action":"C","side":"A","price":"1.156640000","size":30,"channel_id":23,"order_id":"1775529200243812994","flags":0,"ts_in_delta":1575,"sequence":164883,"symbol":"FCEU SI 20260615 PS"}
{"ts_recv":"2026-04-07T02:33:22.841860459Z","hd":{"ts_event":"2026-04-07T02:33:22.841831677Z","rtype":160,"publisher_id":101,"instrument_id":436},"action":"A","side":"A","price":"1.156650000","size":30,"channel_id":23,"order_id":"1775529202841842806","flags":128,"ts_in_delta":1575,"sequence":164883,"symbol":"FCEU SI 20260615 PS"}
{"ts_recv":"2026-04-07T02:33:22.841915753Z","hd":{"ts_event":"2026-04-07T02:33:22.841897175Z","rtype":160,"publisher_id":101,"instrument_id":436},"action":"C","side":"B","price":"1.156530000","size":30,"channel_id":23,"order_id":"10998901237098534887","flags":0,"ts_in_delta":960,"sequence":164884,"symbol":"FCEU SI 20260615 PS"}
{"ts_recv":"2026-04-07T02:33:22.841915753Z","hd":{"ts_event":"2026-04-07T02:33:22.841897175Z","rtype":160,"publisher_id":101,"instrument_id":436},"action":"A","side":"B","price":"1.156550000","size":30,"channel_id":23,"order_id":"10998901239696679336","flags":0,"ts_in_delta":960,"sequence":164884,"symbol":"FCEU SI 20260615 PS"}
{"ts_recv":"2026-04-07T02:33:22.841915753Z","hd":{"ts_event":"2026-04-07T02:33:22.841897175Z","rtype":160,"publisher_id":101,"instrument_id":436},"action":"C","side":"A","price":"1.156630000","size":30,"channel_id":23,"order_id":"1775529200243759079","flags":0,"ts_in_delta":960,"sequence":164884,"symbol":"FCEU SI 20260615 PS"}
{"ts_recv":"2026-04-07T02:33:22.841915753Z","hd":{"ts_event":"2026-04-07T02:33:22.841897175Z","rtype":160,"publisher_id":101,"instrument_id":436},"action":"A","side":"A","price":"1.156650000","size":30,"channel_id":23,"order_id":"1775529202841903528","flags":128,"ts_in_delta":960,"sequence":164884,"symbol":"FCEU SI 20260615 PS"}
{"ts_recv":"2026-04-07T02:33:22.841953053Z","hd":{"ts_event":"2026-04-07T02:33:22.841932977Z","rtype":160,"publisher_id":101,"instrument_id":436},"action":"C","side":"B","price":"1.156550000","size":30,"channel_id":23,"order_id":"10998901239696618614","flags":0,"ts_in_delta":942,"sequence":164885,"symbol":"FCEU SI 20260615 PS"}
{"ts_recv":"2026-04-07T02:33:22.841953053Z","hd":{"ts_event":"2026-04-07T02:33:22.841932977Z","rtype":160,"publisher_id":101,"instrument_id":436},"action":"A","side":"B","price":"1.156540000","size":30,"channel_id":23,"order_id":"10998901239696714752","flags":0,"ts_in_delta":942,"sequence":164885,"symbol":"FCEU SI 20260615 PS"}
{"ts_recv":"2026-04-07T02:33:22.841953053Z","hd":{"ts_event":"2026-04-07T02:33:22.841932977Z","rtype":160,"publisher_id":101,"instrument_id":436},"action":"C","side":"A","price":"1.156650000","size":30,"channel_id":23,"order_id":"1775529202841842806","flags":0,"ts_in_delta":942,"sequence":164885,"symbol":"FCEU SI 20260615 PS"}
{"ts_recv":"2026-04-07T02:33:22.841953053Z","hd":{"ts_event":"2026-04-07T02:33:22.841932977Z","rtype":160,"publisher_id":101,"instrument_id":436},"action":"A","side":"A","price":"1.156640000","size":30,"channel_id":23,"order_id":"1775529202841938944","flags":128,"ts_in_delta":942,"sequence":164885,"symbol":"FCEU SI 20260615 PS"}
{"ts_recv":"2026-04-07T02:33:22.842033543Z","hd":{"ts_event":"2026-04-07T02:33:22.842015135Z","rtype":160,"publisher_id":101,"instrument_id":436},"action":"C","side":"B","price":"1.156540000","size":30,"channel_id":23,"order_id":"10998901239696714752","flags":0,"ts_in_delta":933,"sequence":164886,"symbol":"FCEU SI 20260615 PS"}
{"ts_recv":"2026-04-07T02:33:22.842033543Z","hd":{"ts_event":"2026-04-07T02:33:22.842015135Z","rtype":160,"publisher_id":101,"instrument_id":436},"action":"A","side":"B","price":"1.156550000","size":30,"channel_id":23,"order_id":"10998901239696796975","flags":0,"ts_in_delta":933,"sequence":164886,"symbol":"FCEU SI 20260615 PS"}
{"ts_recv":"2026-04-07T02:33:22.842033543Z","hd":{"ts_event":"2026-04-07T02:33:22.842015135Z","rtype":160,"publisher_id":101,"instrument_id":436},"action":"C","side":"A","price":"1.156640000","size":30,"channel_id":23,"order_id":"1775529202841938944","flags":0,"ts_in_delta":933,"sequence":164886,"symbol":"FCEU SI 20260615 PS"}
{"ts_recv":"2026-04-07T02:33:22.842033543Z","hd":{"ts_event":"2026-04-07T02:33:22.842015135Z","rtype":160,"publisher_id":101,"instrument_id":436},"action":"A","side":"A","price":"1.156650000","size":30,"channel_id":23,"order_id":"1775529202842021167","flags":128,"ts_in_delta":933,"sequence":164886,"symbol":"FCEU SI 20260615 PS"}
{"ts_recv":"2026-04-07T02:33:26.415411866Z","hd":{"ts_event":"2026-04-07T02:33:26.415391555Z","rtype":160,"publisher_id":101,"instrument_id":436},"action":"C","side":"B","price":"1.156550000","size":30,"channel_id":23,"order_id":"10998901239696796975","flags":0,"ts_in_delta":1390,"sequence":164914,"symbol":"FCEU SI 20260615 PS"}
{"ts_recv":"2026-04-07T02:33:26.415411866Z","hd":{"ts_event":"2026-04-07T02:33:26.415391555Z","rtype":160,"publisher_id":101,"instrument_id":436},"action":"A","side":"B","price":"1.156560000","size":30,"channel_id":23,"order_id":"10998901243270173516","flags":0,"ts_in_delta":1390,"sequence":164914,"symbol":"FCEU SI 20260615 PS"}
{"ts_recv":"2026-04-07T02:33:26.415411866Z","hd":{"ts_event":"2026-04-07T02:33:26.415391555Z","rtype":160,"publisher_id":101,"instrument_id":436},"action":"C","side":"A","price":"1.156650000","size":30,"channel_id":23,"order_id":"1775529202842021167","flags":0,"ts_in_delta":1390,"sequence":164914,"symbol":"FCEU SI 20260615 PS"}
{"ts_recv":"2026-04-07T02:33:26.415411866Z","hd":{"ts_event":"2026-04-07T02:33:26.415391555Z","rtype":160,"publisher_id":101,"instrument_id":436},"action":"A","side":"A","price":"1.156660000","size":30,"channel_id":23,"order_id":"1775529206415397708","flags":128,"ts_in_delta":1390,"sequence":164914,"symbol":"FCEU SI 20260615 PS"}
{"ts_recv":"2026-04-07T02:33:26.428470262Z","hd":{"ts_event":"2026-04-07T02:33:26.428449727Z","rtype":160,"publisher_id":101,"instrument_id":436},"action":"C","side":"B","price":"1.156550000","size":30,"channel_id":23,"order_id":"10998901239696679336","flags":0,"ts_in_delta":952,"sequence":164924,"symbol":"FCEU SI 20260615 PS"}
{"ts_recv":"2026-04-07T02:33:26.428470262Z","hd":{"ts_event":"2026-04-07T02:33:26.428449727Z","rtype":160,"publisher_id":101,"instrument_id":436},"action":"A","side":"B","price":"1.156570000","size":30,"channel_id":23,"order_id":"10998901243283231542","flags":0,"ts_in_delta":952,"sequence":164924,"symbol":"FCEU SI 20260615 PS"}
{"ts_recv":"2026-04-07T02:33:26.428470262Z","hd":{"ts_event":"2026-04-07T02:33:26.428449727Z","rtype":160,"publisher_id":101,"instrument_id":436},"action":"C","side":"A","price":"1.156650000","size":30,"channel_id":23,"order_id":"1775529202841903528","flags":0,"ts_in_delta":952,"sequence":164924,"symbol":"FCEU SI 20260615 PS"}
{"ts_recv":"2026-04-07T02:33:26.428470262Z","hd":{"ts_event":"2026-04-07T02:33:26.428449727Z","rtype":160,"publisher_id":101,"instrument_id":436},"action":"A","side":"A","price":"1.156670000","size":30,"channel_id":23,"order_id":"1775529206428455734","flags":128,"ts_in_delta":952,"sequence":164924,"symbol":"FCEU SI 20260615 PS"}
{"ts_recv":"2026-04-07T02:33:26.428527314Z","hd":{"ts_event":"2026-04-07T02:33:26.428510465Z","rtype":160,"publisher_id":101,"instrument_id":436},"action":"C","side":"B","price":"1.156560000","size":30,"channel_id":23,"order_id":"10998901243270173516","flags":0,"ts_in_delta":957,"sequence":164925,"symbol":"FCEU SI 20260615 PS"}
{"ts_recv":"2026-04-07T02:33:26.428527314Z","hd":{"ts_event":"2026-04-07T02:33:26.428510465Z","rtype":160,"publisher_id":101,"instrument_id":436},"action":"A","side":"B","price":"1.156570000","size":30,"channel_id":23,"order_id":"10998901243283292257","flags":0,"ts_in_delta":957,"sequence":164925,"symbol":"FCEU SI 20260615 PS"}
{"ts_recv":"2026-04-07T02:33:26.428527314Z","hd":{"ts_event":"2026-04-07T02:33:26.428510465Z","rtype":160,"publisher_id":101,"instrument_id":436},"action":"C","side":"A","price":"1.156660000","size":30,"channel_id":23,"order_id":"1775529206415397708","flags":0,"ts_in_delta":957,"sequence":164925,"symbol":"FCEU SI 20260615 PS"}
{"ts_recv":"2026-04-07T02:33:26.428527314Z","hd":{"ts_event":"2026-04-07T02:33:26.428510465Z","rtype":160,"publisher_id":101,"instrument_id":436},"action":"A","side":"A","price":"1.156670000","size":30,"channel_id":23,"order_id":"1775529206428516449","flags":128,"ts_in_delta":957,"sequence":164925,"symbol":"FCEU SI 20260615 PS"}
{"ts_recv":"2026-04-07T02:33:27.408194835Z","hd":{"ts_event":"2026-04-07T02:33:27.408175109Z","rtype":160,"publisher_id":101,"instrument_id":436},"action":"C","side":"B","price":"1.156570000","size":30,"channel_id":23,"order_id":"10998901243283292257","flags":0,"ts_in_delta":746,"sequence":164979,"symbol":"FCEU SI 20260615 PS"}
{"ts_recv":"2026-04-07T02:33:27.408194835Z","hd":{"ts_event":"2026-04-07T02:33:27.408175109Z","rtype":160,"publisher_id":101,"instrument_id":436},"action":"A","side":"B","price":"1.156580000","size":30,"channel_id":23,"order_id":"10998901244262956658","flags":0,"ts_in_delta":746,"sequence":164979,"symbol":"FCEU SI 20260615 PS"}
{"ts_recv":"2026-04-07T02:33:27.408194835Z","hd":{"ts_event":"2026-04-07T02:33:27.408175109Z","rtype":160,"publisher_id":101,"instrument_id":436},"action":"C","side":"A","price":"1.156670000","size":30,"channel_id":23,"order_id":"1775529206428516449","flags":0,"ts_in_delta":746,"sequence":164979,"symbol":"FCEU SI 20260615 PS"}
{"ts_recv":"2026-04-07T02:33:27.408194835Z","hd":{"ts_event":"2026-04-07T02:33:27.408175109Z","rtype":160,"publisher_id":101,"instrument_id":436},"action":"A","side":"A","price":"1.156680000","size":30,"channel_id":23,"order_id":"1775529207408180850","flags":128,"ts_in_delta":746,"sequence":164979,"symbol":"FCEU SI 20260615 PS"}
{"ts_recv":"2026-04-07T02:33:31.914926754Z","hd":{"ts_event":"2026-04-07T02:33:31.914909623Z","rtype":160,"publisher_id":101,"instrument_id":436},"action":"C","side":"B","price":"1.156580000","size":30,"channel_id":23,"order_id":"10998901244262956658","flags":0,"ts_in_delta":1138,"sequence":165024,"symbol":"FCEU SI 20260615 PS"}
{"ts_recv":"2026-04-07T02:33:31.914926754Z","hd":{"ts_event":"2026-04-07T02:33:31.914909623Z","rtype":160,"publisher_id":101,"instrument_id":436},"action":"A","side":"B","price":"1.156570000","size":30,"channel_id":23,"order_id":"10998901248769691432","flags":0,"ts_in_delta":1138,"sequence":165024,"symbol":"FCEU SI 20260615 PS"}
{"ts_recv":"2026-04-07T02:33:31.914926754Z","hd":{"ts_event":"2026-04-07T02:33:31.914909623Z","rtype":160,"publisher_id":101,"instrument_id":436},"action":"C","side":"A","price":"1.156680000","size":30,"channel_id":23,"order_id":"1775529207408180850","flags":0,"ts_in_delta":1138,"sequence":165024,"symbol":"FCEU SI 20260615 PS"}
{"ts_recv":"2026-04-07T02:33:31.914926754Z","hd":{"ts_event":"2026-04-07T02:33:31.914909623Z","rtype":160,"publisher_id":101,"instrument_id":436},"action":"A","side":"A","price":"1.156670000","size":30,"channel_id":23,"order_id":"1775529211914915624","flags":128,"ts_in_delta":1138,"sequence":165024,"symbol":"FCEU SI 20260615 PS"}
{"ts_recv":"2026-04-07T02:33:32.168991108Z","hd":{"ts_event":"2026-04-07T02:33:32.168959993Z","rtype":160,"publisher_id":101,"instrument_id":436},"action":"C","side":"B","price":"1.156570000","size":30,"channel_id":23,"order_id":"10998901248769691432","flags":0,"ts_in_delta":1604,"sequence":165037,"symbol":"FCEU SI 20260615 PS"}
{"ts_recv":"2026-04-07T02:33:32.168991108Z","hd":{"ts_event":"2026-04-07T02:33:32.168959993Z","rtype":160,"publisher_id":101,"instrument_id":436},"action":"A","side":"B","price":"1.156580000","size":30,"channel_id":23,"order_id":"10998901249023749158","flags":0,"ts_in_delta":1604,"sequence":165037,"symbol":"FCEU SI 20260615 PS"}
{"ts_recv":"2026-04-07T02:33:32.168991108Z","hd":{"ts_event":"2026-04-07T02:33:32.168959993Z","rtype":160,"publisher_id":101,"instrument_id":436},"action":"C","side":"A","price":"1.156670000","size":30,"channel_id":23,"order_id":"1775529211914915624","flags":0,"ts_in_delta":1604,"sequence":165037,"symbol":"FCEU SI 20260615 PS"}
{"ts_recv":"2026-04-07T02:33:32.168991108Z","hd":{"ts_event":"2026-04-07T02:33:32.168959993Z","rtype":160,"publisher_id":101,"instrument_id":436},"action":"A","side":"A","price":"1.156680000","size":30,"channel_id":23,"order_id":"1775529212168973350","flags":128,"ts_in_delta":1604,"sequence":165037,"symbol":"FCEU SI 20260615 PS"}
{"ts_recv":"2026-04-07T02:33:33.749476656Z","hd":{"ts_event":"2026-04-07T02:33:33.749459275Z","rtype":160,"publisher_id":101,"instrument_id":436},"action":"C","side":"B","price":"1.156580000","size":30,"channel_id":23,"order_id":"10998901249023749158","flags":0,"ts_in_delta":927,"sequence":165049,"symbol":"FCEU SI 20260615 PS"}
{"ts_recv":"2026-04-07T02:33:33.749476656Z","hd":{"ts_event":"2026-04-07T02:33:33.749459275Z","rtype":160,"publisher_id":101,"instrument_id":436},"action":"A","side":"B","price":"1.156570000","size":30,"channel_id":23,"order_id":"10998901250604241248","flags":0,"ts_in_delta":927,"sequence":165049,"symbol":"FCEU SI 20260615 PS"}
{"ts_recv":"2026-04-07T02:33:33.749476656Z","hd":{"ts_event":"2026-04-07T02:33:33.749459275Z","rtype":160,"publisher_id":101,"instrument_id":436},"action":"C","side":"A","price":"1.156680000","size":30,"channel_id":23,"order_id":"1775529212168973350","flags":0,"ts_in_delta":927,"sequence":165049,"symbol":"FCEU SI 20260615 PS"}
{"ts_recv":"2026-04-07T02:33:33.749476656Z","hd":{"ts_event":"2026-04-07T02:33:33.749459275Z","rtype":160,"publisher_id":101,"instrument_id":436},"action":"A","side":"A","price":"1.156670000","size":30,"channel_id":23,"order_id":"1775529213749465440","flags":128,"ts_in_delta":927,"sequence":165049,"symbol":"FCEU SI 20260615 PS"}
{"ts_recv":"2026-04-07T02:33:45.858792091Z","hd":{"ts_event":"2026-04-07T02:33:45.858760013Z","rtype":160,"publisher_id":101,"instrument_id":436},"action":"C","side":"B","price":"1.156570000","size":30,"channel_id":23,"order_id":"10998901250604241248","flags":0,"ts_in_delta":1389,"sequence":165140,"symbol":"FCEU SI 20260615 PS"}
{"ts_recv":"2026-04-07T02:33:45.858792091Z","hd":{"ts_event":"2026-04-07T02:33:45.858760013Z","rtype":160,"publisher_id":101,"instrument_id":436},"action":"A","side":"B","price":"1.156580000","size":30,"channel_id":23,"order_id":"10998901262713548983","flags":0,"ts_in_delta":1389,"sequence":165140,"symbol":"FCEU SI 20260615 PS"}
{"ts_recv":"2026-04-07T02:33:45.858792091Z","hd":{"ts_event":"2026-04-07T02:33:45.858760013Z","rtype":160,"publisher_id":101,"instrument_id":436},"action":"C","side":"A","price":"1.156670000","size":30,"channel_id":23,"order_id":"1775529213749465440","flags":0,"ts_in_delta":1389,"sequence":165140,"symbol":"FCEU SI 20260615 PS"}
{"ts_recv":"2026-04-07T02:33:45.858792091Z","hd":{"ts_event":"2026-04-07T02:33:45.858760013Z","rtype":160,"publisher_id":101,"instrument_id":436},"action":"A","side":"A","price":"1.156680000","size":30,"channel_id":23,"order_id":"1775529225858773175","flags":128,"ts_in_delta":1389,"sequence":165140,"symbol":"FCEU SI 20260615 PS"}
{"ts_recv":"2026-04-07T02:34:19.012495056Z","hd":{"ts_event":"2026-04-07T02:34:19.012472205Z","rtype":160,"publisher_id":101,"instrument_id":436},"action":"C","side":"B","price":"1.156580000","size":30,"channel_id":23,"order_id":"10998901262713548983","flags":0,"ts_in_delta":936,"sequence":165329,"symbol":"FCEU SI 20260615 PS"}
{"ts_recv":"2026-04-07T02:34:19.012495056Z","hd":{"ts_event":"2026-04-07T02:34:19.012472205Z","rtype":160,"publisher_id":101,"instrument_id":436},"action":"A","side":"B","price":"1.156570000","size":30,"channel_id":23,"order_id":"10998901295867254305","flags":0,"ts_in_delta":936,"sequence":165329,"symbol":"FCEU SI 20260615 PS"}
{"ts_recv":"2026-04-07T02:34:19.012495056Z","hd":{"ts_event":"2026-04-07T02:34:19.012472205Z","rtype":160,"publisher_id":101,"instrument_id":436},"action":"C","side":"A","price":"1.156680000","size":30,"channel_id":23,"order_id":"1775529225858773175","flags":0,"ts_in_delta":936,"sequence":165329,"symbol":"FCEU SI 20260615 PS"}
{"ts_recv":"2026-04-07T02:34:19.012495056Z","hd":{"ts_event":"2026-04-07T02:34:19.012472205Z","rtype":160,"publisher_id":101,"instrument_id":436},"action":"A","side":"A","price":"1.156670000","size":30,"channel_id":23,"order_id":"1775529259012478497","flags":128,"ts_in_delta":936,"sequence":165329,"symbol":"FCEU SI 20260615 PS"}
{"ts_recv":"2026-04-07T02:34:19.016834519Z","hd":{"ts_event":"2026-04-07T02:34:19.016811917Z","rtype":160,"publisher_id":101,"instrument_id":436},"action":"C","side":"B","price":"1.156570000","size":30,"channel_id":23,"order_id":"10998901295867254305","flags":0,"ts_in_delta":977,"sequence":165337,"symbol":"FCEU SI 20260615 PS"}
{"ts_recv":"2026-04-07T02:34:19.016834519Z","hd":{"ts_event":"2026-04-07T02:34:19.016811917Z","rtype":160,"publisher_id":101,"instrument_id":436},"action":"A","side":"B","price":"1.156560000","size":30,"channel_id":23,"order_id":"10998901295871593338","flags":0,"ts_in_delta":977,"sequence":165337,"symbol":"FCEU SI 20260615 PS"}
{"ts_recv":"2026-04-07T02:34:19.016834519Z","hd":{"ts_event":"2026-04-07T02:34:19.016811917Z","rtype":160,"publisher_id":101,"instrument_id":436},"action":"C","side":"A","price":"1.156670000","size":30,"channel_id":23,"order_id":"1775529259012478497","flags":0,"ts_in_delta":977,"sequence":165337,"symbol":"FCEU SI 20260615 PS"}
{"ts_recv":"2026-04-07T02:34:19.016834519Z","hd":{"ts_event":"2026-04-07T02:34:19.016811917Z","rtype":160,"publisher_id":101,"instrument_id":436},"action":"A","side":"A","price":"1.156660000","size":30,"channel_id":23,"order_id":"1775529259016817530","flags":128,"ts_in_delta":977,"sequence":165337,"symbol":"FCEU SI 20260615 PS"}
{"ts_recv":"2026-04-07T02:34:19.016916422Z","hd":{"ts_event":"2026-04-07T02:34:19.016898727Z","rtype":160,"publisher_id":101,"instrument_id":436},"action":"C","side":"B","price":"1.156560000","size":30,"channel_id":23,"order_id":"10998901295871593338","flags":0,"ts_in_delta":933,"sequence":165338,"symbol":"FCEU SI 20260615 PS"}
{"ts_recv":"2026-04-07T02:34:19.016916422Z","hd":{"ts_event":"2026-04-07T02:34:19.016898727Z","rtype":160,"publisher_id":101,"instrument_id":436},"action":"A","side":"B","price":"1.156550000","size":30,"channel_id":23,"order_id":"10998901295871680605","flags":0,"ts_in_delta":933,"sequence":165338,"symbol":"FCEU SI 20260615 PS"}
{"ts_recv":"2026-04-07T02:34:19.016916422Z","hd":{"ts_event":"2026-04-07T02:34:19.016898727Z","rtype":160,"publisher_id":101,"instrument_id":436},"action":"C","side":"A","price":"1.156660000","size":30,"channel_id":23,"order_id":"1775529259016817530","flags":0,"ts_in_delta":933,"sequence":165338,"symbol":"FCEU SI 20260615 PS"}
{"ts_recv":"2026-04-07T02:34:19.016916422Z","hd":{"ts_event":"2026-04-07T02:34:19.016898727Z","rtype":160,"publisher_id":101,"instrument_id":436},"action":"A","side":"A","price":"1.156650000","size":30,"channel_id":23,"order_id":"1775529259016904797","flags":128,"ts_in_delta":933,"sequence":165338,"symbol":"FCEU SI 20260615 PS"}
{"ts_recv":"2026-04-07T02:34:19.016972222Z","hd":{"ts_event":"2026-04-07T02:34:19.016957305Z","rtype":160,"publisher_id":101,"instrument_id":436},"action":"C","side":"B","price":"1.156550000","size":30,"channel_id":23,"order_id":"10998901295871680605","flags":0,"ts_in_delta":940,"sequence":165339,"symbol":"FCEU SI 20260615 PS"}
{"ts_recv":"2026-04-07T02:34:19.016972222Z","hd":{"ts_event":"2026-04-07T02:34:19.016957305Z","rtype":160,"publisher_id":101,"instrument_id":436},"action":"A","side":"B","price":"1.156560000","size":30,"channel_id":23,"order_id":"10998901295871738940","flags":0,"ts_in_delta":940,"sequence":165339,"symbol":"FCEU SI 20260615 PS"}
{"ts_recv":"2026-04-07T02:34:19.016972222Z","hd":{"ts_event":"2026-04-07T02:34:19.016957305Z","rtype":160,"publisher_id":101,"instrument_id":436},"action":"C","side":"A","price":"1.156650000","size":30,"channel_id":23,"order_id":"1775529259016904797","flags":0,"ts_in_delta":940,"sequence":165339,"symbol":"FCEU SI 20260615 PS"}
{"ts_recv":"2026-04-07T02:34:19.016972222Z","hd":{"ts_event":"2026-04-07T02:34:19.016957305Z","rtype":160,"publisher_id":101,"instrument_id":436},"action":"A","side":"A","price":"1.156660000","size":30,"channel_id":23,"order_id":"1775529259016963132","flags":128,"ts_in_delta":940,"sequence":165339,"symbol":"FCEU SI 20260615 PS"}
{"ts_recv":"2026-04-07T02:34:19.016985485Z","hd":{"ts_event":"2026-04-07T02:34:19.016957721Z","rtype":160,"publisher_id":101,"instrument_id":436},"action":"C","side":"B","price":"1.156570000","size":30,"channel_id":23,"order_id":"10998901243283231542","flags":0,"ts_in_delta":939,"sequence":165340,"symbol":"FCEU SI 20260615 PS"}
{"ts_recv":"2026-04-07T02:34:19.016985485Z","hd":{"ts_event":"2026-04-07T02:34:19.016957721Z","rtype":160,"publisher_id":101,"instrument_id":436},"action":"A","side":"B","price":"1.156550000","size":30,"channel_id":23,"order_id":"10998901295871744971","flags":0,"ts_in_delta":939,"sequence":165340,"symbol":"FCEU SI 20260615 PS"}
{"ts_recv":"2026-04-07T02:34:19.016985485Z","hd":{"ts_event":"2026-04-07T02:34:19.016957721Z","rtype":160,"publisher_id":101,"instrument_id":436},"action":"C","side":"A","price":"1.156670000","size":30,"channel_id":23,"order_id":"1775529206428455734","flags":0,"ts_in_delta":939,"sequence":165340,"symbol":"FCEU SI 20260615 PS"}
{"ts_recv":"2026-04-07T02:34:19.016985485Z","hd":{"ts_event":"2026-04-07T02:34:19.016957721Z","rtype":160,"publisher_id":101,"instrument_id":436},"action":"A","side":"A","price":"1.156650000","size":30,"channel_id":23,"order_id":"1775529259016969163","flags":128,"ts_in_delta":939,"sequence":165340,"symbol":"FCEU SI 20260615 PS"}
{"ts_recv":"2026-04-07T02:34:19.017042762Z","hd":{"ts_event":"2026-04-07T02:34:19.017025255Z","rtype":160,"publisher_id":101,"instrument_id":436},"action":"C","side":"B","price":"1.156560000","size":30,"channel_id":23,"order_id":"10998901295871738940","flags":0,"ts_in_delta":1025,"sequence":165341,"symbol":"FCEU SI 20260615 PS"}
{"ts_recv":"2026-04-07T02:34:19.017042762Z","hd":{"ts_event":"2026-04-07T02:34:19.017025255Z","rtype":160,"publisher_id":101,"instrument_id":436},"action":"A","side":"B","price":"1.156550000","size":30,"channel_id":23,"order_id":"10998901295871807254","flags":0,"ts_in_delta":1025,"sequence":165341,"symbol":"FCEU SI 20260615 PS"}
{"ts_recv":"2026-04-07T02:34:19.017042762Z","hd":{"ts_event":"2026-04-07T02:34:19.017025255Z","rtype":160,"publisher_id":101,"instrument_id":436},"action":"C","side":"A","price":"1.156660000","size":30,"channel_id":23,"order_id":"1775529259016963132","flags":0,"ts_in_delta":1025,"sequence":165341,"symbol":"FCEU SI 20260615 PS"}
{"ts_recv":"2026-04-07T02:34:19.017042762Z","hd":{"ts_event":"2026-04-07T02:34:19.017025255Z","rtype":160,"publisher_id":101,"instrument_id":436},"action":"A","side":"A","price":"1.156650000","size":30,"channel_id":23,"order_id":"1775529259017031446","flags":128,"ts_in_delta":1025,"sequence":165341,"symbol":"FCEU SI 20260615 PS"}
{"ts_recv":"2026-04-07T02:34:21.335363092Z","hd":{"ts_event":"2026-04-07T02:34:21.335341503Z","rtype":160,"publisher_id":101,"instrument_id":436},"action":"C","side":"B","price":"1.156550000","size":30,"channel_id":23,"order_id":"10998901295871807254","flags":0,"ts_in_delta":946,"sequence":165381,"symbol":"FCEU SI 20260615 PS"}
{"ts_recv":"2026-04-07T02:34:21.335363092Z","hd":{"ts_event":"2026-04-07T02:34:21.335341503Z","rtype":160,"publisher_id":101,"instrument_id":436},"action":"A","side":"B","price":"1.156560000","size":30,"channel_id":23,"order_id":"10998901298190123827","flags":0,"ts_in_delta":946,"sequence":165381,"symbol":"FCEU SI 20260615 PS"}
{"ts_recv":"2026-04-07T02:34:21.335363092Z","hd":{"ts_event":"2026-04-07T02:34:21.335341503Z","rtype":160,"publisher_id":101,"instrument_id":436},"action":"C","side":"A","price":"1.156650000","size":30,"channel_id":23,"order_id":"1775529259017031446","flags":0,"ts_in_delta":946,"sequence":165381,"symbol":"FCEU SI 20260615 PS"}
{"ts_recv":"2026-04-07T02:34:21.335363092Z","hd":{"ts_event":"2026-04-07T02:34:21.335341503Z","rtype":160,"publisher_id":101,"instrument_id":436},"action":"A","side":"A","price":"1.156660000","size":30,"channel_id":23,"order_id":"1775529261335348019","flags":128,"ts_in_delta":946,"sequence":165381,"symbol":"FCEU SI 20260615 PS"}
{"ts_recv":"2026-04-07T02:34:21.335429422Z","hd":{"ts_event":"2026-04-07T02:34:21.335408185Z","rtype":160,"publisher_id":101,"instrument_id":436},"action":"C","side":"B","price":"1.156550000","size":30,"channel_id":23,"order_id":"10998901295871744971","flags":0,"ts_in_delta":881,"sequence":165382,"symbol":"FCEU SI 20260615 PS"}
{"ts_recv":"2026-04-07T02:34:21.335429422Z","hd":{"ts_event":"2026-04-07T02:34:21.335408185Z","rtype":160,"publisher_id":101,"instrument_id":436},"action":"A","side":"B","price":"1.156570000","size":30,"channel_id":23,"order_id":"10998901298190190133","flags":0,"ts_in_delta":881,"sequence":165382,"symbol":"FCEU SI 20260615 PS"}
{"ts_recv":"2026-04-07T02:34:21.335429422Z","hd":{"ts_event":"2026-04-07T02:34:21.335408185Z","rtype":160,"publisher_id":101,"instrument_id":436},"action":"C","side":"A","price":"1.156650000","size":30,"channel_id":23,"order_id":"1775529259016969163","flags":0,"ts_in_delta":881,"sequence":165382,"symbol":"FCEU SI 20260615 PS"}
{"ts_recv":"2026-04-07T02:34:21.335429422Z","hd":{"ts_event":"2026-04-07T02:34:21.335408185Z","rtype":160,"publisher_id":101,"instrument_id":436},"action":"A","side":"A","price":"1.156670000","size":30,"channel_id":23,"order_id":"1775529261335414325","flags":128,"ts_in_delta":881,"sequence":165382,"symbol":"FCEU SI 20260615 PS"}
{"ts_recv":"2026-04-07T02:34:21.335484838Z","hd":{"ts_event":"2026-04-07T02:34:21.335468147Z","rtype":160,"publisher_id":101,"instrument_id":436},"action":"C","side":"B","price":"1.156560000","size":30,"channel_id":23,"order_id":"10998901298190123827","flags":0,"ts_in_delta":871,"sequence":165383,"symbol":"FCEU SI 20260615 PS"}
{"ts_recv":"2026-04-07T02:34:21.335484838Z","hd":{"ts_event":"2026-04-07T02:34:21.335468147Z","rtype":160,"publisher_id":101,"instrument_id":436},"action":"A","side":"B","price":"1.156570000","size":30,"channel_id":23,"order_id":"10998901298190250013","flags":0,"ts_in_delta":871,"sequence":165383,"symbol":"FCEU SI 20260615 PS"}
{"ts_recv":"2026-04-07T02:34:21.335484838Z","hd":{"ts_event":"2026-04-07T02:34:21.335468147Z","rtype":160,"publisher_id":101,"instrument_id":436},"action":"C","side":"A","price":"1.156660000","size":30,"channel_id":23,"order_id":"1775529261335348019","flags":0,"ts_in_delta":871,"sequence":165383,"symbol":"FCEU SI 20260615 PS"}
{"ts_recv":"2026-04-07T02:34:21.335484838Z","hd":{"ts_event":"2026-04-07T02:34:21.335468147Z","rtype":160,"publisher_id":101,"instrument_id":436},"action":"A","side":"A","price":"1.156670000","size":30,"channel_id":23,"order_id":"1775529261335474205","flags":128,"ts_in_delta":871,"sequence":165383,"symbol":"FCEU SI 20260615 PS"}
{"ts_recv":"2026-04-07T02:34:21.340103240Z","hd":{"ts_event":"2026-04-07T02:34:21.340082875Z","rtype":160,"publisher_id":101,"instrument_id":436},"action":"C","side":"B","price":"1.156570000","size":30,"channel_id":23,"order_id":"10998901298190250013","flags":0,"ts_in_delta":713,"sequence":165387,"symbol":"FCEU SI 20260615 PS"}
{"ts_recv":"2026-04-07T02:34:21.340103240Z","hd":{"ts_event":"2026-04-07T02:34:21.340082875Z","rtype":160,"publisher_id":101,"instrument_id":436},"action":"A","side":"B","price":"1.156580000","size":30,"channel_id":23,"order_id":"10998901298194864525","flags":0,"ts_in_delta":713,"sequence":165387,"symbol":"FCEU SI 20260615 PS"}
{"ts_recv":"2026-04-07T02:34:21.340103240Z","hd":{"ts_event":"2026-04-07T02:34:21.340082875Z","rtype":160,"publisher_id":101,"instrument_id":436},"action":"C","side":"A","price":"1.156670000","size":30,"channel_id":23,"order_id":"1775529261335474205","flags":0,"ts_in_delta":713,"sequence":165387,"symbol":"FCEU SI 20260615 PS"}
{"ts_recv":"2026-04-07T02:34:21.340103240Z","hd":{"ts_event":"2026-04-07T02:34:21.340082875Z","rtype":160,"publisher_id":101,"instrument_id":436},"action":"A","side":"A","price":"1.156680000","size":30,"channel_id":23,"order_id":"1775529261340088717","flags":128,"ts_in_delta":713,"sequence":165387,"symbol":"FCEU SI 20260615 PS"}
{"ts_recv":"2026-04-07T02:34:30.569889774Z","hd":{"ts_event":"2026-04-07T02:34:30.569858917Z","rtype":160,"publisher_id":101,"instrument_id":436},"action":"C","side":"B","price":"1.156570000","size":30,"channel_id":23,"order_id":"10998901298190190133","flags":0,"ts_in_delta":1349,"sequence":165492,"symbol":"FCEU SI 20260615 PS"}
{"ts_recv":"2026-04-07T02:34:30.569889774Z","hd":{"ts_event":"2026-04-07T02:34:30.569858917Z","rtype":160,"publisher_id":101,"instrument_id":436},"action":"A","side":"B","price":"1.156590000","size":30,"channel_id":23,"order_id":"10998901307424647667","flags":0,"ts_in_delta":1349,"sequence":165492,"symbol":"FCEU SI 20260615 PS"}
{"ts_recv":"2026-04-07T02:34:30.569889774Z","hd":{"ts_event":"2026-04-07T02:34:30.569858917Z","rtype":160,"publisher_id":101,"instrument_id":436},"action":"C","side":"A","price":"1.156670000","size":30,"channel_id":23,"order_id":"1775529261335414325","flags":0,"ts_in_delta":1349,"sequence":165492,"symbol":"FCEU SI 20260615 PS"}
{"ts_recv":"2026-04-07T02:34:30.569889774Z","hd":{"ts_event":"2026-04-07T02:34:30.569858917Z","rtype":160,"publisher_id":101,"instrument_id":436},"action":"A","side":"A","price":"1.156690000","size":30,"channel_id":23,"order_id":"1775529270569871859","flags":128,"ts_in_delta":1349,"sequence":165492,"symbol":"FCEU SI 20260615 PS"}
{"ts_recv":"2026-04-07T02:34:30.570007327Z","hd":{"ts_event":"2026-04-07T02:34:30.569989479Z","rtype":160,"publisher_id":101,"instrument_id":436},"action":"C","side":"B","price":"1.156580000","size":30,"channel_id":23,"order_id":"10998901298194864525","flags":0,"ts_in_delta":910,"sequence":165493,"symbol":"FCEU SI 20260615 PS"}
{"ts_recv":"2026-04-07T02:34:30.570007327Z","hd":{"ts_event":"2026-04-07T02:34:30.569989479Z","rtype":160,"publisher_id":101,"instrument_id":436},"action":"A","side":"B","price":"1.156590000","size":30,"channel_id":23,"order_id":"10998901307424771280","flags":0,"ts_in_delta":910,"sequence":165493,"symbol":"FCEU SI 20260615 PS"}
{"ts_recv":"2026-04-07T02:34:30.570007327Z","hd":{"ts_event":"2026-04-07T02:34:30.569989479Z","rtype":160,"publisher_id":101,"instrument_id":436},"action":"C","side":"A","price":"1.156680000","size":30,"channel_id":23,"order_id":"1775529261340088717","flags":0,"ts_in_delta":910,"sequence":165493,"symbol":"FCEU SI 20260615 PS"}
{"ts_recv":"2026-04-07T02:34:30.570007327Z","hd":{"ts_event":"2026-04-07T02:34:30.569989479Z","rtype":160,"publisher_id":101,"instrument_id":436},"action":"A","side":"A","price":"1.156690000","size":30,"channel_id":23,"order_id":"1775529270569995472","flags":128,"ts_in_delta":910,"sequence":165493,"symbol":"FCEU SI 20260615 PS"}
{"ts_recv":"2026-04-07T02:34:54.777055423Z","hd":{"ts_event":"2026-04-07T02:34:54.777031919Z","rtype":160,"publisher_id":101,"instrument_id":436},"action":"C","side":"B","price":"1.156590000","size":30,"channel_id":23,"order_id":"10998901307424771280","flags":0,"ts_in_delta":1091,"sequence":165676,"symbol":"FCEU SI 20260615 PS"}
{"ts_recv":"2026-04-07T02:34:54.777055423Z","hd":{"ts_event":"2026-04-07T02:34:54.777031919Z","rtype":160,"publisher_id":101,"instrument_id":436},"action":"A","side":"B","price":"1.156600000","size":30,"channel_id":23,"order_id":"10998901331631813766","flags":0,"ts_in_delta":1091,"sequence":165676,"symbol":"FCEU SI 20260615 PS"}
{"ts_recv":"2026-04-07T02:34:54.777055423Z","hd":{"ts_event":"2026-04-07T02:34:54.777031919Z","rtype":160,"publisher_id":101,"instrument_id":436},"action":"C","side":"A","price":"1.156690000","size":30,"channel_id":23,"order_id":"1775529270569995472","flags":0,"ts_in_delta":1091,"sequence":165676,"symbol":"FCEU SI 20260615 PS"}
{"ts_recv":"2026-04-07T02:34:54.777055423Z","hd":{"ts_event":"2026-04-07T02:34:54.777031919Z","rtype":160,"publisher_id":101,"instrument_id":436},"action":"A","side":"A","price":"1.156700000","size":30,"channel_id":23,"order_id":"1775529294777037958","flags":128,"ts_in_delta":1091,"sequence":165676,"symbol":"FCEU SI 20260615 PS"}
{"ts_recv":"2026-04-07T02:34:54.777473211Z","hd":{"ts_event":"2026-04-07T02:34:54.777450167Z","rtype":160,"publisher_id":101,"instrument_id":436},"action":"C","side":"B","price":"1.156590000","size":30,"channel_id":23,"order_id":"10998901307424647667","flags":0,"ts_in_delta":979,"sequence":165677,"symbol":"FCEU SI 20260615 PS"}
{"ts_recv":"2026-04-07T02:34:54.777473211Z","hd":{"ts_event":"2026-04-07T02:34:54.777450167Z","rtype":160,"publisher_id":101,"instrument_id":436},"action":"A","side":"B","price":"1.156610000","size":30,"channel_id":23,"order_id":"10998901331632231958","flags":0,"ts_in_delta":979,"sequence":165677,"symbol":"FCEU SI 20260615 PS"}
{"ts_recv":"2026-04-07T02:34:54.777473211Z","hd":{"ts_event":"2026-04-07T02:34:54.777450167Z","rtype":160,"publisher_id":101,"instrument_id":436},"action":"C","side":"A","price":"1.156690000","size":30,"channel_id":23,"order_id":"1775529270569871859","flags":0,"ts_in_delta":979,"sequence":165677,"symbol":"FCEU SI 20260615 PS"}
{"ts_recv":"2026-04-07T02:34:54.777473211Z","hd":{"ts_event":"2026-04-07T02:34:54.777450167Z","rtype":160,"publisher_id":101,"instrument_id":436},"action":"A","side":"A","price":"1.156710000","size":30,"channel_id":23,"order_id":"1775529294777456150","flags":128,"ts_in_delta":979,"sequence":165677,"symbol":"FCEU SI 20260615 PS"}
{"ts_recv":"2026-04-07T02:34:54.777527744Z","hd":{"ts_event":"2026-04-07T02:34:54.777510973Z","rtype":160,"publisher_id":101,"instrument_id":436},"action":"C","side":"B","price":"1.156600000","size":30,"channel_id":23,"order_id":"10998901331631813766","flags":0,"ts_in_delta":961,"sequence":165678,"symbol":"FCEU SI 20260615 PS"}
{"ts_recv":"2026-04-07T02:34:54.777527744Z","hd":{"ts_event":"2026-04-07T02:34:54.777510973Z","rtype":160,"publisher_id":101,"instrument_id":436},"action":"A","side":"B","price":"1.156610000","size":30,"channel_id":23,"order_id":"10998901331632292687","flags":0,"ts_in_delta":961,"sequence":165678,"symbol":"FCEU SI 20260615 PS"}
{"ts_recv":"2026-04-07T02:34:54.777527744Z","hd":{"ts_event":"2026-04-07T02:34:54.777510973Z","rtype":160,"publisher_id":101,"instrument_id":436},"action":"C","side":"A","price":"1.156700000","size":30,"channel_id":23,"order_id":"1775529294777037958","flags":0,"ts_in_delta":961,"sequence":165678,"symbol":"FCEU SI 20260615 PS"}
{"ts_recv":"2026-04-07T02:34:54.777527744Z","hd":{"ts_event":"2026-04-07T02:34:54.777510973Z","rtype":160,"publisher_id":101,"instrument_id":436},"action":"A","side":"A","price":"1.156710000","size":30,"channel_id":23,"order_id":"1775529294777516879","flags":128,"ts_in_delta":961,"sequence":165678,"symbol":"FCEU SI 20260615 PS"}
{"ts_recv":"2026-04-07T02:34:55.152458376Z","hd":{"ts_event":"2026-04-07T02:34:55.152443227Z","rtype":160,"publisher_id":101,"instrument_id":436},"action":"A","side":"B","price":"1.156500000","size":20,"channel_id":23,"order_id":"10998901332007225116","flags":128,"ts_in_delta":665,"sequence":165738,"symbol":"FCEU SI 20260615 PS"}
{"ts_recv":"2026-04-07T02:34:55.152711835Z","hd":{"ts_event":"2026-04-07T02:34:55.152698097Z","rtype":160,"publisher_id":101,"instrument_id":436},"action":"C","side":"B","price":"1.156400000","size":20,"channel_id":23,"order_id":"10998901101095112539","flags":128,"ts_in_delta":695,"sequence":165741,"symbol":"FCEU SI 20260615 PS"}
{"ts_recv":"2026-04-07T02:35:07.376471681Z","hd":{"ts_event":"2026-04-07T02:35:07.376448707Z","rtype":160,"publisher_id":101,"instrument_id":436},"action":"C","side":"B","price":"1.156610000","size":30,"channel_id":23,"order_id":"10998901331632292687","flags":0,"ts_in_delta":974,"sequence":165825,"symbol":"FCEU SI 20260615 PS"}
{"ts_recv":"2026-04-07T02:35:07.376471681Z","hd":{"ts_event":"2026-04-07T02:35:07.376448707Z","rtype":160,"publisher_id":101,"instrument_id":436},"action":"A","side":"B","price":"1.156600000","size":30,"channel_id":23,"order_id":"10998901344231230485","flags":0,"ts_in_delta":974,"sequence":165825,"symbol":"FCEU SI 20260615 PS"}
{"ts_recv":"2026-04-07T02:35:07.376471681Z","hd":{"ts_event":"2026-04-07T02:35:07.376448707Z","rtype":160,"publisher_id":101,"instrument_id":436},"action":"C","side":"A","price":"1.156710000","size":30,"channel_id":23,"order_id":"1775529294777516879","flags":0,"ts_in_delta":974,"sequence":165825,"symbol":"FCEU SI 20260615 PS"}
{"ts_recv":"2026-04-07T02:35:07.376471681Z","hd":{"ts_event":"2026-04-07T02:35:07.376448707Z","rtype":160,"publisher_id":101,"instrument_id":436},"action":"A","side":"A","price":"1.156700000","size":30,"channel_id":23,"order_id":"1775529307376454677","flags":128,"ts_in_delta":974,"sequence":165825,"symbol":"FCEU SI 20260615 PS"}
{"ts_recv":"2026-04-07T02:35:07.376533464Z","hd":{"ts_event":"2026-04-07T02:35:07.376510937Z","rtype":160,"publisher_id":101,"instrument_id":436},"action":"C","side":"B","price":"1.156610000","size":30,"channel_id":23,"order_id":"10998901331632231958","flags":0,"ts_in_delta":961,"sequence":165826,"symbol":"FCEU SI 20260615 PS"}
{"ts_recv":"2026-04-07T02:35:07.376533464Z","hd":{"ts_event":"2026-04-07T02:35:07.376510937Z","rtype":160,"publisher_id":101,"instrument_id":436},"action":"A","side":"B","price":"1.156590000","size":30,"channel_id":23,"order_id":"10998901344231293119","flags":0,"ts_in_delta":961,"sequence":165826,"symbol":"FCEU SI 20260615 PS"}
{"ts_recv":"2026-04-07T02:35:07.376533464Z","hd":{"ts_event":"2026-04-07T02:35:07.376510937Z","rtype":160,"publisher_id":101,"instrument_id":436},"action":"C","side":"A","price":"1.156710000","size":30,"channel_id":23,"order_id":"1775529294777456150","flags":0,"ts_in_delta":961,"sequence":165826,"symbol":"FCEU SI 20260615 PS"}
{"ts_recv":"2026-04-07T02:35:07.376533464Z","hd":{"ts_event":"2026-04-07T02:35:07.376510937Z","rtype":160,"publisher_id":101,"instrument_id":436},"action":"A","side":"A","price":"1.156690000","size":30,"channel_id":23,"order_id":"1775529307376517311","flags":128,"ts_in_delta":961,"sequence":165826,"symbol":"FCEU SI 20260615 PS"}
{"ts_recv":"2026-04-07T02:35:07.376591492Z","hd":{"ts_event":"2026-04-07T02:35:07.376572531Z","rtype":160,"publisher_id":101,"instrument_id":436},"action":"C","side":"B","price":"1.156600000","size":30,"channel_id":23,"order_id":"10998901344231230485","flags":0,"ts_in_delta":960,"sequence":165827,"symbol":"FCEU SI 20260615 PS"}
{"ts_recv":"2026-04-07T02:35:07.376591492Z","hd":{"ts_event":"2026-04-07T02:35:07.376572531Z","rtype":160,"publisher_id":101,"instrument_id":436},"action":"A","side":"B","price":"1.156590000","size":30,"channel_id":23,"order_id":"10998901344231354296","flags":0,"ts_in_delta":960,"sequence":165827,"symbol":"FCEU SI 20260615 PS"}
{"ts_recv":"2026-04-07T02:35:07.376591492Z","hd":{"ts_event":"2026-04-07T02:35:07.376572531Z","rtype":160,"publisher_id":101,"instrument_id":436},"action":"C","side":"A","price":"1.156700000","size":30,"channel_id":23,"order_id":"1775529307376454677","flags":0,"ts_in_delta":960,"sequence":165827,"symbol":"FCEU SI 20260615 PS"}
{"ts_recv":"2026-04-07T02:35:07.376591492Z","hd":{"ts_event":"2026-04-07T02:35:07.376572531Z","rtype":160,"publisher_id":101,"instrument_id":436},"action":"A","side":"A","price":"1.156690000","size":30,"channel_id":23,"order_id":"1775529307376578488","flags":128,"ts_in_delta":960,"sequence":165827,"symbol":"FCEU SI 20260615 PS"}
{"ts_recv":"2026-04-07T02:35:35.353292024Z","hd":{"ts_event":"2026-04-07T02:35:35.353268523Z","rtype":160,"publisher_id":101,"instrument_id":436},"action":"C","side":"B","price":"1.156590000","size":30,"channel_id":23,"order_id":"10998901344231354296","flags":0,"ts_in_delta":931,"sequence":166019,"symbol":"FCEU SI 20260615 PS"}
{"ts_recv":"2026-04-07T02:35:35.353292024Z","hd":{"ts_event":"2026-04-07T02:35:35.353268523Z","rtype":160,"publisher_id":101,"instrument_id":436},"action":"A","side":"B","price":"1.156580000","size":30,"channel_id":23,"order_id":"10998901372208050317","flags":0,"ts_in_delta":931,"sequence":166019,"symbol":"FCEU SI 20260615 PS"}
{"ts_recv":"2026-04-07T02:35:35.353292024Z","hd":{"ts_event":"2026-04-07T02:35:35.353268523Z","rtype":160,"publisher_id":101,"instrument_id":436},"action":"C","side":"A","price":"1.156690000","size":30,"channel_id":23,"order_id":"1775529307376578488","flags":0,"ts_in_delta":931,"sequence":166019,"symbol":"FCEU SI 20260615 PS"}
{"ts_recv":"2026-04-07T02:35:35.353292024Z","hd":{"ts_event":"2026-04-07T02:35:35.353268523Z","rtype":160,"publisher_id":101,"instrument_id":436},"action":"A","side":"A","price":"1.156680000","size":30,"channel_id":23,"order_id":"1775529335353274509","flags":128,"ts_in_delta":931,"sequence":166019,"symbol":"FCEU SI 20260615 PS"}
{"ts_recv":"2026-04-07T02:35:35.368810419Z","hd":{"ts_event":"2026-04-07T02:35:35.368787331Z","rtype":160,"publisher_id":101,"instrument_id":436},"action":"C","side":"B","price":"1.156590000","size":30,"channel_id":23,"order_id":"10998901344231293119","flags":0,"ts_in_delta":1110,"sequence":166027,"symbol":"FCEU SI 20260615 PS"}
{"ts_recv":"2026-04-07T02:35:35.368810419Z","hd":{"ts_event":"2026-04-07T02:35:35.368787331Z","rtype":160,"publisher_id":101,"instrument_id":436},"action":"A","side":"B","price":"1.156570000","size":30,"channel_id":23,"order_id":"10998901372223569450","flags":0,"ts_in_delta":1110,"sequence":166027,"symbol":"FCEU SI 20260615 PS"}
{"ts_recv":"2026-04-07T02:35:35.368810419Z","hd":{"ts_event":"2026-04-07T02:35:35.368787331Z","rtype":160,"publisher_id":101,"instrument_id":436},"action":"C","side":"A","price":"1.156690000","size":30,"channel_id":23,"order_id":"1775529307376517311","flags":0,"ts_in_delta":1110,"sequence":166027,"symbol":"FCEU SI 20260615 PS"}
{"ts_recv":"2026-04-07T02:35:35.368810419Z","hd":{"ts_event":"2026-04-07T02:35:35.368787331Z","rtype":160,"publisher_id":101,"instrument_id":436},"action":"A","side":"A","price":"1.156670000","size":30,"channel_id":23,"order_id":"1775529335368793642","flags":128,"ts_in_delta":1110,"sequence":166027,"symbol":"FCEU SI 20260615 PS"}
{"ts_recv":"2026-04-07T02:35:35.368877930Z","hd":{"ts_event":"2026-04-07T02:35:35.368861175Z","rtype":160,"publisher_id":101,"instrument_id":436},"action":"C","side":"B","price":"1.156580000","size":30,"channel_id":23,"order_id":"10998901372208050317","flags":0,"ts_in_delta":979,"sequence":166028,"symbol":"FCEU SI 20260615 PS"}
{"ts_recv":"2026-04-07T02:35:35.368877930Z","hd":{"ts_event":"2026-04-07T02:35:35.368861175Z","rtype":160,"publisher_id":101,"instrument_id":436},"action":"A","side":"B","price":"1.156570000","size":30,"channel_id":23,"order_id":"10998901372223642954","flags":0,"ts_in_delta":979,"sequence":166028,"symbol":"FCEU SI 20260615 PS"}
{"ts_recv":"2026-04-07T02:35:35.368877930Z","hd":{"ts_event":"2026-04-07T02:35:35.368861175Z","rtype":160,"publisher_id":101,"instrument_id":436},"action":"C","side":"A","price":"1.156680000","size":30,"channel_id":23,"order_id":"1775529335353274509","flags":0,"ts_in_delta":979,"sequence":166028,"symbol":"FCEU SI 20260615 PS"}
{"ts_recv":"2026-04-07T02:35:35.368877930Z","hd":{"ts_event":"2026-04-07T02:35:35.368861175Z","rtype":160,"publisher_id":101,"instrument_id":436},"action":"A","side":"A","price":"1.156670000","size":30,"channel_id":23,"order_id":"1775529335368867146","flags":128,"ts_in_delta":979,"sequence":166028,"symbol":"FCEU SI 20260615 PS"}
{"ts_recv":"2026-04-07T02:35:36.490669624Z","hd":{"ts_event":"2026-04-07T02:35:36.490642103Z","rtype":160,"publisher_id":101,"instrument_id":436},"action":"C","side":"B","price":"1.156570000","size":30,"channel_id":23,"order_id":"10998901372223642954","flags":0,"ts_in_delta":879,"sequence":166073,"symbol":"FCEU SI 20260615 PS"}
{"ts_recv":"2026-04-07T02:35:36.490669624Z","hd":{"ts_event":"2026-04-07T02:35:36.490642103Z","rtype":160,"publisher_id":101,"instrument_id":436},"action":"A","side":"B","price":"1.156580000","size":30,"channel_id":23,"order_id":"10998901373345428396","flags":0,"ts_in_delta":879,"sequence":166073,"symbol":"FCEU SI 20260615 PS"}
{"ts_recv":"2026-04-07T02:35:36.490669624Z","hd":{"ts_event":"2026-04-07T02:35:36.490642103Z","rtype":160,"publisher_id":101,"instrument_id":436},"action":"C","side":"A","price":"1.156670000","size":30,"channel_id":23,"order_id":"1775529335368867146","flags":0,"ts_in_delta":879,"sequence":166073,"symbol":"FCEU SI 20260615 PS"}
{"ts_recv":"2026-04-07T02:35:36.490669624Z","hd":{"ts_event":"2026-04-07T02:35:36.490642103Z","rtype":160,"publisher_id":101,"instrument_id":436},"action":"A","side":"A","price":"1.156680000","size":30,"channel_id":23,"order_id":"1775529336490652588","flags":128,"ts_in_delta":879,"sequence":166073,"symbol":"FCEU SI 20260615 PS"}
{"ts_recv":"2026-04-07T02:35:36.504249037Z","hd":{"ts_event":"2026-04-07T02:35:36.504228271Z","rtype":160,"publisher_id":101,"instrument_id":436},"action":"C","side":"B","price":"1.156580000","size":30,"channel_id":23,"order_id":"10998901373345428396","flags":0,"ts_in_delta":1149,"sequence":166075,"symbol":"FCEU SI 20260615 PS"}
{"ts_recv":"2026-04-07T02:35:36.504249037Z","hd":{"ts_event":"2026-04-07T02:35:36.504228271Z","rtype":160,"publisher_id":101,"instrument_id":436},"action":"A","side":"B","price":"1.156590000","size":30,"channel_id":23,"order_id":"10998901373359010586","flags":0,"ts_in_delta":1149,"sequence":166075,"symbol":"FCEU SI 20260615 PS"}
{"ts_recv":"2026-04-07T02:35:36.504249037Z","hd":{"ts_event":"2026-04-07T02:35:36.504228271Z","rtype":160,"publisher_id":101,"instrument_id":436},"action":"C","side":"A","price":"1.156680000","size":30,"channel_id":23,"order_id":"1775529336490652588","flags":0,"ts_in_delta":1149,"sequence":166075,"symbol":"FCEU SI 20260615 PS"}
{"ts_recv":"2026-04-07T02:35:36.504249037Z","hd":{"ts_event":"2026-04-07T02:35:36.504228271Z","rtype":160,"publisher_id":101,"instrument_id":436},"action":"A","side":"A","price":"1.156690000","size":30,"channel_id":23,"order_id":"1775529336504234778","flags":128,"ts_in_delta":1149,"sequence":166075,"symbol":"FCEU SI 20260615 PS"}
{"ts_recv":"2026-04-07T02:35:36.504302572Z","hd":{"ts_event":"2026-04-07T02:35:36.504283857Z","rtype":160,"publisher_id":101,"instrument_id":436},"action":"C","side":"B","price":"1.156570000","size":30,"channel_id":23,"order_id":"10998901372223569450","flags":0,"ts_in_delta":886,"sequence":166076,"symbol":"FCEU SI 20260615 PS"}
{"ts_recv":"2026-04-07T02:35:36.504302572Z","hd":{"ts_event":"2026-04-07T02:35:36.504283857Z","rtype":160,"publisher_id":101,"instrument_id":436},"action":"A","side":"B","price":"1.156590000","size":30,"channel_id":23,"order_id":"10998901373359065642","flags":0,"ts_in_delta":886,"sequence":166076,"symbol":"FCEU SI 20260615 PS"}
{"ts_recv":"2026-04-07T02:35:36.504302572Z","hd":{"ts_event":"2026-04-07T02:35:36.504283857Z","rtype":160,"publisher_id":101,"instrument_id":436},"action":"C","side":"A","price":"1.156670000","size":30,"channel_id":23,"order_id":"1775529335368793642","flags":0,"ts_in_delta":886,"sequence":166076,"symbol":"FCEU SI 20260615 PS"}
{"ts_recv":"2026-04-07T02:35:36.504302572Z","hd":{"ts_event":"2026-04-07T02:35:36.504283857Z","rtype":160,"publisher_id":101,"instrument_id":436},"action":"A","side":"A","price":"1.156690000","size":30,"channel_id":23,"order_id":"1775529336504289834","flags":128,"ts_in_delta":886,"sequence":166076,"symbol":"FCEU SI 20260615 PS"}
{"ts_recv":"2026-04-07T02:35:36.504331463Z","hd":{"ts_event":"2026-04-07T02:35:36.504312235Z","rtype":160,"publisher_id":101,"instrument_id":436},"action":"C","side":"B","price":"1.156590000","size":30,"channel_id":23,"order_id":"10998901373359010586","flags":0,"ts_in_delta":888,"sequence":166077,"symbol":"FCEU SI 20260615 PS"}
{"ts_recv":"2026-04-07T02:35:36.504331463Z","hd":{"ts_event":"2026-04-07T02:35:36.504312235Z","rtype":160,"publisher_id":101,"instrument_id":436},"action":"A","side":"B","price":"1.156580000","size":30,"channel_id":23,"order_id":"10998901373359094120","flags":0,"ts_in_delta":888,"sequence":166077,"symbol":"FCEU SI 20260615 PS"}
{"ts_recv":"2026-04-07T02:35:36.504331463Z","hd":{"ts_event":"2026-04-07T02:35:36.504312235Z","rtype":160,"publisher_id":101,"instrument_id":436},"action":"C","side":"A","price":"1.156690000","size":30,"channel_id":23,"order_id":"1775529336504234778","flags":0,"ts_in_delta":888,"sequence":166077,"symbol":"FCEU SI 20260615 PS"}
{"ts_recv":"2026-04-07T02:35:36.504331463Z","hd":{"ts_event":"2026-04-07T02:35:36.504312235Z","rtype":160,"publisher_id":101,"instrument_id":436},"action":"A","side":"A","price":"1.156680000","size":30,"channel_id":23,"order_id":"1775529336504318312","flags":128,"ts_in_delta":888,"sequence":166077,"symbol":"FCEU SI 20260615 PS"}
{"ts_recv":"2026-04-07T02:35:36.504387794Z","hd":{"ts_event":"2026-04-07T02:35:36.504370615Z","rtype":160,"publisher_id":101,"instrument_id":436},"action":"C","side":"B","price":"1.156580000","size":30,"channel_id":23,"order_id":"10998901373359094120","flags":0,"ts_in_delta":894,"sequence":166078,"symbol":"FCEU SI 20260615 PS"}
{"ts_recv":"2026-04-07T02:35:36.504387794Z","hd":{"ts_event":"2026-04-07T02:35:36.504370615Z","rtype":160,"publisher_id":101,"instrument_id":436},"action":"A","side":"B","price":"1.156590000","size":30,"channel_id":23,"order_id":"10998901373359152408","flags":0,"ts_in_delta":894,"sequence":166078,"symbol":"FCEU SI 20260615 PS"}
{"ts_recv":"2026-04-07T02:35:36.504387794Z","hd":{"ts_event":"2026-04-07T02:35:36.504370615Z","rtype":160,"publisher_id":101,"instrument_id":436},"action":"C","side":"A","price":"1.156680000","size":30,"channel_id":23,"order_id":"1775529336504318312","flags":0,"ts_in_delta":894,"sequence":166078,"symbol":"FCEU SI 20260615 PS"}
{"ts_recv":"2026-04-07T02:35:36.504387794Z","hd":{"ts_event":"2026-04-07T02:35:36.504370615Z","rtype":160,"publisher_id":101,"instrument_id":436},"action":"A","side":"A","price":"1.156690000","size":30,"channel_id":23,"order_id":"1775529336504376600","flags":128,"ts_in_delta":894,"sequence":166078,"symbol":"FCEU SI 20260615 PS"}
{"ts_recv":"2026-04-07T02:35:53.142616918Z","hd":{"ts_event":"2026-04-07T02:35:53.142594479Z","rtype":160,"publisher_id":101,"instrument_id":436},"action":"C","side":"B","price":"1.156590000","size":30,"channel_id":23,"order_id":"10998901373359152408","flags":0,"ts_in_delta":965,"sequence":166161,"symbol":"FCEU SI 20260615 PS"}
{"ts_recv":"2026-04-07T02:35:53.142616918Z","hd":{"ts_event":"2026-04-07T02:35:53.142594479Z","rtype":160,"publisher_id":101,"instrument_id":436},"action":"A","side":"B","price":"1.156580000","size":30,"channel_id":23,"order_id":"10998901389997376490","flags":0,"ts_in_delta":965,"sequence":166161,"symbol":"FCEU SI 20260615 PS"}
{"ts_recv":"2026-04-07T02:35:53.142616918Z","hd":{"ts_event":"2026-04-07T02:35:53.142594479Z","rtype":160,"publisher_id":101,"instrument_id":436},"action":"C","side":"A","price":"1.156690000","size":30,"channel_id":23,"order_id":"1775529336504376600","flags":0,"ts_in_delta":965,"sequence":166161,"symbol":"FCEU SI 20260615 PS"}
{"ts_recv":"2026-04-07T02:35:53.142616918Z","hd":{"ts_event":"2026-04-07T02:35:53.142594479Z","rtype":160,"publisher_id":101,"instrument_id":436},"action":"A","side":"A","price":"1.156680000","size":30,"channel_id":23,"order_id":"1775529353142600682","flags":128,"ts_in_delta":965,"sequence":166161,"symbol":"FCEU SI 20260615 PS"}
{"ts_recv":"2026-04-07T02:35:53.142687064Z","hd":{"ts_event":"2026-04-07T02:35:53.142663503Z","rtype":160,"publisher_id":101,"instrument_id":436},"action":"C","side":"B","price":"1.156590000","size":30,"channel_id":23,"order_id":"10998901373359065642","flags":0,"ts_in_delta":1926,"sequence":166162,"symbol":"FCEU SI 20260615 PS"}
{"ts_recv":"2026-04-07T02:35:53.142687064Z","hd":{"ts_event":"2026-04-07T02:35:53.142663503Z","rtype":160,"publisher_id":101,"instrument_id":436},"action":"A","side":"B","price":"1.156570000","size":30,"channel_id":23,"order_id":"10998901389997446455","flags":0,"ts_in_delta":1926,"sequence":166162,"symbol":"FCEU SI 20260615 PS"}
{"ts_recv":"2026-04-07T02:35:53.142687064Z","hd":{"ts_event":"2026-04-07T02:35:53.142663503Z","rtype":160,"publisher_id":101,"instrument_id":436},"action":"C","side":"A","price":"1.156690000","size":30,"channel_id":23,"order_id":"1775529336504289834","flags":0,"ts_in_delta":1926,"sequence":166162,"symbol":"FCEU SI 20260615 PS"}
{"ts_recv":"2026-04-07T02:35:53.142687064Z","hd":{"ts_event":"2026-04-07T02:35:53.142663503Z","rtype":160,"publisher_id":101,"instrument_id":436},"action":"A","side":"A","price":"1.156670000","size":30,"channel_id":23,"order_id":"1775529353142670647","flags":128,"ts_in_delta":1926,"sequence":166162,"symbol":"FCEU SI 20260615 PS"}
{"ts_recv":"2026-04-07T02:35:53.142747442Z","hd":{"ts_event":"2026-04-07T02:35:53.142729791Z","rtype":160,"publisher_id":101,"instrument_id":436},"action":"C","side":"B","price":"1.156580000","size":30,"channel_id":23,"order_id":"10998901389997376490","flags":0,"ts_in_delta":946,"sequence":166163,"symbol":"FCEU SI 20260615 PS"}
{"ts_recv":"2026-04-07T02:35:53.142747442Z","hd":{"ts_event":"2026-04-07T02:35:53.142729791Z","rtype":160,"publisher_id":101,"instrument_id":436},"action":"A","side":"B","price":"1.156570000","size":30,"channel_id":23,"order_id":"10998901389997511880","flags":0,"ts_in_delta":946,"sequence":166163,"symbol":"FCEU SI 20260615 PS"}
{"ts_recv":"2026-04-07T02:35:53.142747442Z","hd":{"ts_event":"2026-04-07T02:35:53.142729791Z","rtype":160,"publisher_id":101,"instrument_id":436},"action":"C","side":"A","price":"1.156680000","size":30,"channel_id":23,"order_id":"1775529353142600682","flags":0,"ts_in_delta":946,"sequence":166163,"symbol":"FCEU SI 20260615 PS"}
{"ts_recv":"2026-04-07T02:35:53.142747442Z","hd":{"ts_event":"2026-04-07T02:35:53.142729791Z","rtype":160,"publisher_id":101,"instrument_id":436},"action":"A","side":"A","price":"1.156670000","size":30,"channel_id":23,"order_id":"1775529353142736072","flags":128,"ts_in_delta":946,"sequence":166163,"symbol":"FCEU SI 20260615 PS"}
{"ts_recv":"2026-04-07T02:36:25.392576127Z","hd":{"ts_event":"2026-04-07T02:36:25.392551053Z","rtype":160,"publisher_id":101,"instrument_id":436},"action":"C","side":"B","price":"1.156570000","size":30,"channel_id":23,"order_id":"10998901389997511880","flags":0,"ts_in_delta":1144,"sequence":166494,"symbol":"FCEU SI 20260615 PS"}
{"ts_recv":"2026-04-07T02:36:25.392576127Z","hd":{"ts_event":"2026-04-07T02:36:25.392551053Z","rtype":160,"publisher_id":101,"instrument_id":436},"action":"A","side":"B","price":"1.156580000","size":30,"channel_id":23,"order_id":"10998901422247333395","flags":0,"ts_in_delta":1144,"sequence":166494,"symbol":"FCEU SI 20260615 PS"}
{"ts_recv":"2026-04-07T02:36:25.392576127Z","hd":{"ts_event":"2026-04-07T02:36:25.392551053Z","rtype":160,"publisher_id":101,"instrument_id":436},"action":"C","side":"A","price":"1.156670000","size":30,"channel_id":23,"order_id":"1775529353142736072","flags":0,"ts_in_delta":1144,"sequence":166494,"symbol":"FCEU SI 20260615 PS"}
{"ts_recv":"2026-04-07T02:36:25.392576127Z","hd":{"ts_event":"2026-04-07T02:36:25.392551053Z","rtype":160,"publisher_id":101,"instrument_id":436},"action":"A","side":"A","price":"1.156680000","size":30,"channel_id":23,"order_id":"1775529385392557587","flags":128,"ts_in_delta":1144,"sequence":166494,"symbol":"FCEU SI 20260615 PS"}
{"ts_recv":"2026-04-07T02:36:26.348715791Z","hd":{"ts_event":"2026-04-07T02:36:26.348690487Z","rtype":160,"publisher_id":101,"instrument_id":436},"action":"C","side":"B","price":"1.156580000","size":30,"channel_id":23,"order_id":"10998901422247333395","flags":0,"ts_in_delta":1297,"sequence":166515,"symbol":"FCEU SI 20260615 PS"}
{"ts_recv":"2026-04-07T02:36:26.348715791Z","hd":{"ts_event":"2026-04-07T02:36:26.348690487Z","rtype":160,"publisher_id":101,"instrument_id":436},"action":"A","side":"B","price":"1.156570000","size":30,"channel_id":23,"order_id":"10998901423203479117","flags":0,"ts_in_delta":1297,"sequence":166515,"symbol":"FCEU SI 20260615 PS"}
{"ts_recv":"2026-04-07T02:36:26.348715791Z","hd":{"ts_event":"2026-04-07T02:36:26.348690487Z","rtype":160,"publisher_id":101,"instrument_id":436},"action":"C","side":"A","price":"1.156680000","size":30,"channel_id":23,"order_id":"1775529385392557587","flags":0,"ts_in_delta":1297,"sequence":166515,"symbol":"FCEU SI 20260615 PS"}
{"ts_recv":"2026-04-07T02:36:26.348715791Z","hd":{"ts_event":"2026-04-07T02:36:26.348690487Z","rtype":160,"publisher_id":101,"instrument_id":436},"action":"A","side":"A","price":"1.156670000","size":30,"channel_id":23,"order_id":"1775529386348703309","flags":128,"ts_in_delta":1297,"sequence":166515,"symbol":"FCEU SI 20260615 PS"}
{"ts_recv":"2026-04-07T02:36:30.626126329Z","hd":{"ts_event":"2026-04-07T02:36:30.626104039Z","rtype":160,"publisher_id":101,"instrument_id":436},"action":"C","side":"B","price":"1.156570000","size":30,"channel_id":23,"order_id":"10998901423203479117","flags":0,"ts_in_delta":935,"sequence":166561,"symbol":"FCEU SI 20260615 PS"}
{"ts_recv":"2026-04-07T02:36:30.626126329Z","hd":{"ts_event":"2026-04-07T02:36:30.626104039Z","rtype":160,"publisher_id":101,"instrument_id":436},"action":"A","side":"B","price":"1.156580000","size":30,"channel_id":23,"order_id":"10998901427480886135","flags":0,"ts_in_delta":935,"sequence":166561,"symbol":"FCEU SI 20260615 PS"}
{"ts_recv":"2026-04-07T02:36:30.626126329Z","hd":{"ts_event":"2026-04-07T02:36:30.626104039Z","rtype":160,"publisher_id":101,"instrument_id":436},"action":"C","side":"A","price":"1.156670000","size":30,"channel_id":23,"order_id":"1775529386348703309","flags":0,"ts_in_delta":935,"sequence":166561,"symbol":"FCEU SI 20260615 PS"}
{"ts_recv":"2026-04-07T02:36:30.626126329Z","hd":{"ts_event":"2026-04-07T02:36:30.626104039Z","rtype":160,"publisher_id":101,"instrument_id":436},"action":"A","side":"A","price":"1.156680000","size":30,"channel_id":23,"order_id":"1775529390626110327","flags":128,"ts_in_delta":935,"sequence":166561,"symbol":"FCEU SI 20260615 PS"}
{"ts_recv":"2026-04-07T02:36:33.790470870Z","hd":{"ts_event":"2026-04-07T02:36:33.790433419Z","rtype":160,"publisher_id":101,"instrument_id":436},"action":"C","side":"B","price":"1.156570000","size":30,"channel_id":23,"order_id":"10998901389997446455","flags":0,"ts_in_delta":1405,"sequence":166589,"symbol":"FCEU SI 20260615 PS"}
{"ts_recv":"2026-04-07T02:36:33.790470870Z","hd":{"ts_event":"2026-04-07T02:36:33.790433419Z","rtype":160,"publisher_id":101,"instrument_id":436},"action":"A","side":"B","price":"1.156590000","size":30,"channel_id":23,"order_id":"10998901430645223704","flags":0,"ts_in_delta":1405,"sequence":166589,"symbol":"FCEU SI 20260615 PS"}
{"ts_recv":"2026-04-07T02:36:33.790470870Z","hd":{"ts_event":"2026-04-07T02:36:33.790433419Z","rtype":160,"publisher_id":101,"instrument_id":436},"action":"C","side":"A","price":"1.156670000","size":30,"channel_id":23,"order_id":"1775529353142670647","flags":0,"ts_in_delta":1405,"sequence":166589,"symbol":"FCEU SI 20260615 PS"}
{"ts_recv":"2026-04-07T02:36:33.790470870Z","hd":{"ts_event":"2026-04-07T02:36:33.790433419Z","rtype":160,"publisher_id":101,"instrument_id":436},"action":"A","side":"A","price":"1.156690000","size":30,"channel_id":23,"order_id":"1775529393790447896","flags":128,"ts_in_delta":1405,"sequence":166589,"symbol":"FCEU SI 20260615 PS"}
{"ts_recv":"2026-04-07T02:36:33.790605071Z","hd":{"ts_event":"2026-04-07T02:36:33.790586943Z","rtype":160,"publisher_id":101,"instrument_id":436},"action":"C","side":"B","price":"1.156580000","size":30,"channel_id":23,"order_id":"10998901427480886135","flags":0,"ts_in_delta":742,"sequence":166594,"symbol":"FCEU SI 20260615 PS"}
{"ts_recv":"2026-04-07T02:36:33.790605071Z","hd":{"ts_event":"2026-04-07T02:36:33.790586943Z","rtype":160,"publisher_id":101,"instrument_id":436},"action":"A","side":"B","price":"1.156590000","size":30,"channel_id":23,"order_id":"10998901430645368328","flags":0,"ts_in_delta":742,"sequence":166594,"symbol":"FCEU SI 20260615 PS"}
{"ts_recv":"2026-04-07T02:36:33.790605071Z","hd":{"ts_event":"2026-04-07T02:36:33.790586943Z","rtype":160,"publisher_id":101,"instrument_id":436},"action":"C","side":"A","price":"1.156680000","size":30,"channel_id":23,"order_id":"1775529390626110327","flags":0,"ts_in_delta":742,"sequence":166594,"symbol":"FCEU SI 20260615 PS"}
{"ts_recv":"2026-04-07T02:36:33.790605071Z","hd":{"ts_event":"2026-04-07T02:36:33.790586943Z","rtype":160,"publisher_id":101,"instrument_id":436},"action":"A","side":"A","price":"1.156690000","size":30,"channel_id":23,"order_id":"1775529393790592520","flags":128,"ts_in_delta":742,"sequence":166594,"symbol":"FCEU SI 20260615 PS"}
{"ts_recv":"2026-04-07T02:36:54.777523282Z","hd":{"ts_event":"2026-04-07T02:36:54.777497075Z","rtype":160,"publisher_id":101,"instrument_id":436},"action":"C","side":"B","price":"1.156590000","size":30,"channel_id":23,"order_id":"10998901430645368328","flags":0,"ts_in_delta":915,"sequence":166723,"symbol":"FCEU SI 20260615 PS"}
{"ts_recv":"2026-04-07T02:36:54.777523282Z","hd":{"ts_event":"2026-04-07T02:36:54.777497075Z","rtype":160,"publisher_id":101,"instrument_id":436},"action":"A","side":"B","price":"1.156600000","size":30,"channel_id":23,"order_id":"10998901451632279636","flags":0,"ts_in_delta":915,"sequence":166723,"symbol":"FCEU SI 20260615 PS"}
{"ts_recv":"2026-04-07T02:36:54.777523282Z","hd":{"ts_event":"2026-04-07T02:36:54.777497075Z","rtype":160,"publisher_id":101,"instrument_id":436},"action":"C","side":"A","price":"1.156690000","size":30,"channel_id":23,"order_id":"1775529393790592520","flags":0,"ts_in_delta":915,"sequence":166723,"symbol":"FCEU SI 20260615 PS"}
{"ts_recv":"2026-04-07T02:36:54.777523282Z","hd":{"ts_event":"2026-04-07T02:36:54.777497075Z","rtype":160,"publisher_id":101,"instrument_id":436},"action":"A","side":"A","price":"1.156700000","size":30,"channel_id":23,"order_id":"1775529414777503828","flags":128,"ts_in_delta":915,"sequence":166723,"symbol":"FCEU SI 20260615 PS"}
{"ts_recv":"2026-04-07T02:36:54.777592076Z","hd":{"ts_event":"2026-04-07T02:36:54.777568833Z","rtype":160,"publisher_id":101,"instrument_id":436},"action":"C","side":"B","price":"1.156590000","size":30,"channel_id":23,"order_id":"10998901430645223704","flags":0,"ts_in_delta":910,"sequence":166724,"symbol":"FCEU SI 20260615 PS"}
{"ts_recv":"2026-04-07T02:36:54.777592076Z","hd":{"ts_event":"2026-04-07T02:36:54.777568833Z","rtype":160,"publisher_id":101,"instrument_id":436},"action":"A","side":"B","price":"1.156610000","size":30,"channel_id":23,"order_id":"10998901451632350892","flags":0,"ts_in_delta":910,"sequence":166724,"symbol":"FCEU SI 20260615 PS"}
{"ts_recv":"2026-04-07T02:36:54.777592076Z","hd":{"ts_event":"2026-04-07T02:36:54.777568833Z","rtype":160,"publisher_id":101,"instrument_id":436},"action":"C","side":"A","price":"1.156690000","size":30,"channel_id":23,"order_id":"1775529393790447896","flags":0,"ts_in_delta":910,"sequence":166724,"symbol":"FCEU SI 20260615 PS"}
{"ts_recv":"2026-04-07T02:36:54.777592076Z","hd":{"ts_event":"2026-04-07T02:36:54.777568833Z","rtype":160,"publisher_id":101,"instrument_id":436},"action":"A","side":"A","price":"1.156710000","size":30,"channel_id":23,"order_id":"1775529414777575084","flags":128,"ts_in_delta":910,"sequence":166724,"symbol":"FCEU SI 20260615 PS"}
{"ts_recv":"2026-04-07T02:36:54.777657753Z","hd":{"ts_event":"2026-04-07T02:36:54.777639431Z","rtype":160,"publisher_id":101,"instrument_id":436},"action":"C","side":"B","price":"1.156600000","size":30,"channel_id":23,"order_id":"10998901451632279636","flags":0,"ts_in_delta":950,"sequence":166725,"symbol":"FCEU SI 20260615 PS"}
{"ts_recv":"2026-04-07T02:36:54.777657753Z","hd":{"ts_event":"2026-04-07T02:36:54.777639431Z","rtype":160,"publisher_id":101,"instrument_id":436},"action":"A","side":"B","price":"1.156610000","size":30,"channel_id":23,"order_id":"10998901451632421591","flags":0,"ts_in_delta":950,"sequence":166725,"symbol":"FCEU SI 20260615 PS"}
{"ts_recv":"2026-04-07T02:36:54.777657753Z","hd":{"ts_event":"2026-04-07T02:36:54.777639431Z","rtype":160,"publisher_id":101,"instrument_id":436},"action":"C","side":"A","price":"1.156700000","size":30,"channel_id":23,"order_id":"1775529414777503828","flags":0,"ts_in_delta":950,"sequence":166725,"symbol":"FCEU SI 20260615 PS"}
{"ts_recv":"2026-04-07T02:36:54.777657753Z","hd":{"ts_event":"2026-04-07T02:36:54.777639431Z","rtype":160,"publisher_id":101,"instrument_id":436},"action":"A","side":"A","price":"1.156710000","size":30,"channel_id":23,"order_id":"1775529414777645783","flags":128,"ts_in_delta":950,"sequence":166725,"symbol":"FCEU SI 20260615 PS"}
{"ts_recv":"2026-04-07T02:36:54.781794364Z","hd":{"ts_event":"2026-04-07T02:36:54.781771091Z","rtype":160,"publisher_id":101,"instrument_id":436},"action":"C","side":"B","price":"1.156610000","size":30,"channel_id":23,"order_id":"10998901451632421591","flags":0,"ts_in_delta":941,"sequence":166728,"symbol":"FCEU SI 20260615 PS"}
{"ts_recv":"2026-04-07T02:36:54.781794364Z","hd":{"ts_event":"2026-04-07T02:36:54.781771091Z","rtype":160,"publisher_id":101,"instrument_id":436},"action":"A","side":"B","price":"1.156620000","size":30,"channel_id":23,"order_id":"10998901451636552902","flags":0,"ts_in_delta":941,"sequence":166728,"symbol":"FCEU SI 20260615 PS"}
{"ts_recv":"2026-04-07T02:36:54.781794364Z","hd":{"ts_event":"2026-04-07T02:36:54.781771091Z","rtype":160,"publisher_id":101,"instrument_id":436},"action":"C","side":"A","price":"1.156710000","size":30,"channel_id":23,"order_id":"1775529414777645783","flags":0,"ts_in_delta":941,"sequence":166728,"symbol":"FCEU SI 20260615 PS"}
{"ts_recv":"2026-04-07T02:36:54.781794364Z","hd":{"ts_event":"2026-04-07T02:36:54.781771091Z","rtype":160,"publisher_id":101,"instrument_id":436},"action":"A","side":"A","price":"1.156720000","size":30,"channel_id":23,"order_id":"1775529414781777094","flags":128,"ts_in_delta":941,"sequence":166728,"symbol":"FCEU SI 20260615 PS"}
{"ts_recv":"2026-04-07T02:36:54.781879017Z","hd":{"ts_event":"2026-04-07T02:36:54.781858491Z","rtype":160,"publisher_id":101,"instrument_id":436},"action":"C","side":"B","price":"1.156620000","size":30,"channel_id":23,"order_id":"10998901451636552902","flags":0,"ts_in_delta":919,"sequence":166729,"symbol":"FCEU SI 20260615 PS"}
{"ts_recv":"2026-04-07T02:36:54.781879017Z","hd":{"ts_event":"2026-04-07T02:36:54.781858491Z","rtype":160,"publisher_id":101,"instrument_id":436},"action":"A","side":"B","price":"1.156630000","size":30,"channel_id":23,"order_id":"10998901451636640371","flags":0,"ts_in_delta":919,"sequence":166729,"symbol":"FCEU SI 20260615 PS"}
{"ts_recv":"2026-04-07T02:36:54.781879017Z","hd":{"ts_event":"2026-04-07T02:36:54.781858491Z","rtype":160,"publisher_id":101,"instrument_id":436},"action":"C","side":"A","price":"1.156720000","size":30,"channel_id":23,"order_id":"1775529414781777094","flags":0,"ts_in_delta":919,"sequence":166729,"symbol":"FCEU SI 20260615 PS"}
{"ts_recv":"2026-04-07T02:36:54.781879017Z","hd":{"ts_event":"2026-04-07T02:36:54.781858491Z","rtype":160,"publisher_id":101,"instrument_id":436},"action":"A","side":"A","price":"1.156730000","size":30,"channel_id":23,"order_id":"1775529414781864563","flags":128,"ts_in_delta":919,"sequence":166729,"symbol":"FCEU SI 20260615 PS"}
{"ts_recv":"2026-04-07T02:36:54.781937237Z","hd":{"ts_event":"2026-04-07T02:36:54.781918701Z","rtype":160,"publisher_id":101,"instrument_id":436},"action":"C","side":"B","price":"1.156630000","size":30,"channel_id":23,"order_id":"10998901451636640371","flags":0,"ts_in_delta":944,"sequence":166730,"symbol":"FCEU SI 20260615 PS"}
{"ts_recv":"2026-04-07T02:36:54.781937237Z","hd":{"ts_event":"2026-04-07T02:36:54.781918701Z","rtype":160,"publisher_id":101,"instrument_id":436},"action":"A","side":"B","price":"1.156620000","size":30,"channel_id":23,"order_id":"10998901451636700576","flags":0,"ts_in_delta":944,"sequence":166730,"symbol":"FCEU SI 20260615 PS"}
{"ts_recv":"2026-04-07T02:36:54.781937237Z","hd":{"ts_event":"2026-04-07T02:36:54.781918701Z","rtype":160,"publisher_id":101,"instrument_id":436},"action":"C","side":"A","price":"1.156730000","size":30,"channel_id":23,"order_id":"1775529414781864563","flags":0,"ts_in_delta":944,"sequence":166730,"symbol":"FCEU SI 20260615 PS"}
{"ts_recv":"2026-04-07T02:36:54.781937237Z","hd":{"ts_event":"2026-04-07T02:36:54.781918701Z","rtype":160,"publisher_id":101,"instrument_id":436},"action":"A","side":"A","price":"1.156720000","size":30,"channel_id":23,"order_id":"1775529414781924768","flags":128,"ts_in_delta":944,"sequence":166730,"symbol":"FCEU SI 20260615 PS"}
{"ts_recv":"2026-04-07T02:36:54.782287213Z","hd":{"ts_event":"2026-04-07T02:36:54.782268261Z","rtype":160,"publisher_id":101,"instrument_id":436},"action":"C","side":"B","price":"1.156610000","size":30,"channel_id":23,"order_id":"10998901451632350892","flags":0,"ts_in_delta":919,"sequence":166731,"symbol":"FCEU SI 20260615 PS"}
{"ts_recv":"2026-04-07T02:36:54.782287213Z","hd":{"ts_event":"2026-04-07T02:36:54.782268261Z","rtype":160,"publisher_id":101,"instrument_id":436},"action":"A","side":"B","price":"1.156630000","size":30,"channel_id":23,"order_id":"10998901451637050271","flags":0,"ts_in_delta":919,"sequence":166731,"symbol":"FCEU SI 20260615 PS"}
{"ts_recv":"2026-04-07T02:36:54.782287213Z","hd":{"ts_event":"2026-04-07T02:36:54.782268261Z","rtype":160,"publisher_id":101,"instrument_id":436},"action":"C","side":"A","price":"1.156710000","size":30,"channel_id":23,"order_id":"1775529414777575084","flags":0,"ts_in_delta":919,"sequence":166731,"symbol":"FCEU SI 20260615 PS"}
{"ts_recv":"2026-04-07T02:36:54.782287213Z","hd":{"ts_event":"2026-04-07T02:36:54.782268261Z","rtype":160,"publisher_id":101,"instrument_id":436},"action":"A","side":"A","price":"1.156730000","size":30,"channel_id":23,"order_id":"1775529414782274463","flags":128,"ts_in_delta":919,"sequence":166731,"symbol":"FCEU SI 20260615 PS"}
{"ts_recv":"2026-04-07T02:36:54.782342914Z","hd":{"ts_event":"2026-04-07T02:36:54.782326071Z","rtype":160,"publisher_id":101,"instrument_id":436},"action":"C","side":"B","price":"1.156620000","size":30,"channel_id":23,"order_id":"10998901451636700576","flags":0,"ts_in_delta":942,"sequence":166732,"symbol":"FCEU SI 20260615 PS"}
{"ts_recv":"2026-04-07T02:36:54.782342914Z","hd":{"ts_event":"2026-04-07T02:36:54.782326071Z","rtype":160,"publisher_id":101,"instrument_id":436},"action":"A","side":"B","price":"1.156630000","size":30,"channel_id":23,"order_id":"10998901451637107467","flags":0,"ts_in_delta":942,"sequence":166732,"symbol":"FCEU SI 20260615 PS"}
{"ts_recv":"2026-04-07T02:36:54.782342914Z","hd":{"ts_event":"2026-04-07T02:36:54.782326071Z","rtype":160,"publisher_id":101,"instrument_id":436},"action":"C","side":"A","price":"1.156720000","size":30,"channel_id":23,"order_id":"1775529414781924768","flags":0,"ts_in_delta":942,"sequence":166732,"symbol":"FCEU SI 20260615 PS"}
{"ts_recv":"2026-04-07T02:36:54.782342914Z","hd":{"ts_event":"2026-04-07T02:36:54.782326071Z","rtype":160,"publisher_id":101,"instrument_id":436},"action":"A","side":"A","price":"1.156730000","size":30,"channel_id":23,"order_id":"1775529414782331659","flags":128,"ts_in_delta":942,"sequence":166732,"symbol":"FCEU SI 20260615 PS"}
{"ts_recv":"2026-04-07T02:36:56.361784284Z","hd":{"ts_event":"2026-04-07T02:36:56.361764093Z","rtype":160,"publisher_id":101,"instrument_id":436},"action":"C","side":"B","price":"1.156630000","size":30,"channel_id":23,"order_id":"10998901451637107467","flags":0,"ts_in_delta":1826,"sequence":166809,"symbol":"FCEU SI 20260615 PS"}
{"ts_recv":"2026-04-07T02:36:56.361784284Z","hd":{"ts_event":"2026-04-07T02:36:56.361764093Z","rtype":160,"publisher_id":101,"instrument_id":436},"action":"A","side":"B","price":"1.156640000","size":30,"channel_id":23,"order_id":"10998901453216546346","flags":0,"ts_in_delta":1826,"sequence":166809,"symbol":"FCEU SI 20260615 PS"}
{"ts_recv":"2026-04-07T02:36:56.361784284Z","hd":{"ts_event":"2026-04-07T02:36:56.361764093Z","rtype":160,"publisher_id":101,"instrument_id":436},"action":"C","side":"A","price":"1.156730000","size":30,"channel_id":23,"order_id":"1775529414782331659","flags":0,"ts_in_delta":1826,"sequence":166809,"symbol":"FCEU SI 20260615 PS"}
{"ts_recv":"2026-04-07T02:36:56.361784284Z","hd":{"ts_event":"2026-04-07T02:36:56.361764093Z","rtype":160,"publisher_id":101,"instrument_id":436},"action":"A","side":"A","price":"1.156740000","size":30,"channel_id":23,"order_id":"1775529416361770538","flags":128,"ts_in_delta":1826,"sequence":166809,"symbol":"FCEU SI 20260615 PS"}
{"ts_recv":"2026-04-07T02:36:56.362328894Z","hd":{"ts_event":"2026-04-07T02:36:56.362312803Z","rtype":160,"publisher_id":101,"instrument_id":436},"action":"C","side":"A","price":"1.156800000","size":20,"channel_id":23,"order_id":"1775528839896286926","flags":128,"ts_in_delta":868,"sequence":166810,"symbol":"FCEU SI 20260615 PS"}
{"ts_recv":"2026-04-07T02:36:56.405916850Z","hd":{"ts_event":"2026-04-07T02:36:56.405897155Z","rtype":160,"publisher_id":101,"instrument_id":436},"action":"A","side":"A","price":"1.157000000","size":20,"channel_id":23,"order_id":"1775529416405908075","flags":128,"ts_in_delta":885,"sequence":166814,"symbol":"FCEU SI 20260615 PS"}
{"ts_recv":"2026-04-07T02:37:06.663697826Z","hd":{"ts_event":"2026-04-07T02:37:06.663683279Z","rtype":160,"publisher_id":101,"instrument_id":436},"action":"A","side":"A","price":"1.156900000","size":20,"channel_id":23,"order_id":"1775529426663689821","flags":128,"ts_in_delta":958,"sequence":166961,"symbol":"FCEU SI 20260615 PS"}
{"ts_recv":"2026-04-07T02:37:06.663721756Z","hd":{"ts_event":"2026-04-07T02:37:06.663707619Z","rtype":160,"publisher_id":101,"instrument_id":436},"action":"C","side":"A","price":"1.157000000","size":20,"channel_id":23,"order_id":"1775529416405908075","flags":128,"ts_in_delta":858,"sequence":166962,"symbol":"FCEU SI 20260615 PS"}
{"ts_recv":"2026-04-07T02:37:08.063016485Z","hd":{"ts_event":"2026-04-07T02:37:08.062994983Z","rtype":160,"publisher_id":101,"instrument_id":436},"action":"C","side":"B","price":"1.156630000","size":30,"channel_id":23,"order_id":"10998901451637050271","flags":0,"ts_in_delta":935,"sequence":167000,"symbol":"FCEU SI 20260615 PS"}
{"ts_recv":"2026-04-07T02:37:08.063016485Z","hd":{"ts_event":"2026-04-07T02:37:08.062994983Z","rtype":160,"publisher_id":101,"instrument_id":436},"action":"A","side":"B","price":"1.156660000","size":30,"channel_id":23,"order_id":"10998901464917776854","flags":0,"ts_in_delta":935,"sequence":167000,"symbol":"FCEU SI 20260615 PS"}
{"ts_recv":"2026-04-07T02:37:08.063016485Z","hd":{"ts_event":"2026-04-07T02:37:08.062994983Z","rtype":160,"publisher_id":101,"instrument_id":436},"action":"C","side":"A","price":"1.156730000","size":30,"channel_id":23,"order_id":"1775529414782274463","flags":0,"ts_in_delta":935,"sequence":167000,"symbol":"FCEU SI 20260615 PS"}
{"ts_recv":"2026-04-07T02:37:08.063016485Z","hd":{"ts_event":"2026-04-07T02:37:08.062994983Z","rtype":160,"publisher_id":101,"instrument_id":436},"action":"A","side":"A","price":"1.156760000","size":30,"channel_id":23,"order_id":"1775529428063001046","flags":128,"ts_in_delta":935,"sequence":167000,"symbol":"FCEU SI 20260615 PS"}
{"ts_recv":"2026-04-07T02:37:08.063093496Z","hd":{"ts_event":"2026-04-07T02:37:08.063073049Z","rtype":160,"publisher_id":101,"instrument_id":436},"action":"C","side":"B","price":"1.156640000","size":30,"channel_id":23,"order_id":"10998901453216546346","flags":0,"ts_in_delta":942,"sequence":167001,"symbol":"FCEU SI 20260615 PS"}
{"ts_recv":"2026-04-07T02:37:08.063093496Z","hd":{"ts_event":"2026-04-07T02:37:08.063073049Z","rtype":160,"publisher_id":101,"instrument_id":436},"action":"A","side":"B","price":"1.156660000","size":30,"channel_id":23,"order_id":"10998901464917855146","flags":0,"ts_in_delta":942,"sequence":167001,"symbol":"FCEU SI 20260615 PS"}
{"ts_recv":"2026-04-07T02:37:08.063093496Z","hd":{"ts_event":"2026-04-07T02:37:08.063073049Z","rtype":160,"publisher_id":101,"instrument_id":436},"action":"C","side":"A","price":"1.156740000","size":30,"channel_id":23,"order_id":"1775529416361770538","flags":0,"ts_in_delta":942,"sequence":167001,"symbol":"FCEU SI 20260615 PS"}
{"ts_recv":"2026-04-07T02:37:08.063093496Z","hd":{"ts_event":"2026-04-07T02:37:08.063073049Z","rtype":160,"publisher_id":101,"instrument_id":436},"action":"A","side":"A","price":"1.156760000","size":30,"channel_id":23,"order_id":"1775529428063079338","flags":128,"ts_in_delta":942,"sequence":167001,"symbol":"FCEU SI 20260615 PS"}
{"ts_recv":"2026-04-07T02:37:08.070688229Z","hd":{"ts_event":"2026-04-07T02:37:08.070667173Z","rtype":160,"publisher_id":101,"instrument_id":436},"action":"C","side":"B","price":"1.156660000","size":30,"channel_id":23,"order_id":"10998901464917855146","flags":0,"ts_in_delta":749,"sequence":167005,"symbol":"FCEU SI 20260615 PS"}
{"ts_recv":"2026-04-07T02:37:08.070688229Z","hd":{"ts_event":"2026-04-07T02:37:08.070667173Z","rtype":160,"publisher_id":101,"instrument_id":436},"action":"A","side":"B","price":"1.156670000","size":30,"channel_id":23,"order_id":"10998901464925449245","flags":0,"ts_in_delta":749,"sequence":167005,"symbol":"FCEU SI 20260615 PS"}
{"ts_recv":"2026-04-07T02:37:08.070688229Z","hd":{"ts_event":"2026-04-07T02:37:08.070667173Z","rtype":160,"publisher_id":101,"instrument_id":436},"action":"C","side":"A","price":"1.156760000","size":30,"channel_id":23,"order_id":"1775529428063079338","flags":0,"ts_in_delta":749,"sequence":167005,"symbol":"FCEU SI 20260615 PS"}
{"ts_recv":"2026-04-07T02:37:08.070688229Z","hd":{"ts_event":"2026-04-07T02:37:08.070667173Z","rtype":160,"publisher_id":101,"instrument_id":436},"action":"A","side":"A","price":"1.156770000","size":30,"channel_id":23,"order_id":"1775529428070673437","flags":128,"ts_in_delta":749,"sequence":167005,"symbol":"FCEU SI 20260615 PS"}
{"ts_recv":"2026-04-07T02:37:16.929984616Z","hd":{"ts_event":"2026-04-07T02:37:16.929966203Z","rtype":160,"publisher_id":101,"instrument_id":436},"action":"C","side":"B","price":"1.156670000","size":30,"channel_id":23,"order_id":"10998901464925449245","flags":0,"ts_in_delta":1000,"sequence":167100,"symbol":"FCEU SI 20260615 PS"}
{"ts_recv":"2026-04-07T02:37:16.929984616Z","hd":{"ts_event":"2026-04-07T02:37:16.929966203Z","rtype":160,"publisher_id":101,"instrument_id":436},"action":"A","side":"B","price":"1.156660000","size":30,"channel_id":23,"order_id":"10998901473784747717","flags":0,"ts_in_delta":1000,"sequence":167100,"symbol":"FCEU SI 20260615 PS"}
{"ts_recv":"2026-04-07T02:37:16.929984616Z","hd":{"ts_event":"2026-04-07T02:37:16.929966203Z","rtype":160,"publisher_id":101,"instrument_id":436},"action":"C","side":"A","price":"1.156770000","size":30,"channel_id":23,"order_id":"1775529428070673437","flags":0,"ts_in_delta":1000,"sequence":167100,"symbol":"FCEU SI 20260615 PS"}
{"ts_recv":"2026-04-07T02:37:16.929984616Z","hd":{"ts_event":"2026-04-07T02:37:16.929966203Z","rtype":160,"publisher_id":101,"instrument_id":436},"action":"A","side":"A","price":"1.156760000","size":30,"channel_id":23,"order_id":"1775529436929971909","flags":128,"ts_in_delta":1000,"sequence":167100,"symbol":"FCEU SI 20260615 PS"}
{"ts_recv":"2026-04-07T02:37:16.933496442Z","hd":{"ts_event":"2026-04-07T02:37:16.933474837Z","rtype":160,"publisher_id":101,"instrument_id":436},"action":"C","side":"B","price":"1.156660000","size":30,"channel_id":23,"order_id":"10998901473784747717","flags":0,"ts_in_delta":972,"sequence":167101,"symbol":"FCEU SI 20260615 PS"}
{"ts_recv":"2026-04-07T02:37:16.933496442Z","hd":{"ts_event":"2026-04-07T02:37:16.933474837Z","rtype":160,"publisher_id":101,"instrument_id":436},"action":"A","side":"B","price":"1.156650000","size":30,"channel_id":23,"order_id":"10998901473788256796","flags":0,"ts_in_delta":972,"sequence":167101,"symbol":"FCEU SI 20260615 PS"}
{"ts_recv":"2026-04-07T02:37:16.933496442Z","hd":{"ts_event":"2026-04-07T02:37:16.933474837Z","rtype":160,"publisher_id":101,"instrument_id":436},"action":"C","side":"A","price":"1.156760000","size":30,"channel_id":23,"order_id":"1775529436929971909","flags":0,"ts_in_delta":972,"sequence":167101,"symbol":"FCEU SI 20260615 PS"}
{"ts_recv":"2026-04-07T02:37:16.933496442Z","hd":{"ts_event":"2026-04-07T02:37:16.933474837Z","rtype":160,"publisher_id":101,"instrument_id":436},"action":"A","side":"A","price":"1.156750000","size":30,"channel_id":23,"order_id":"1775529436933480988","flags":128,"ts_in_delta":972,"sequence":167101,"symbol":"FCEU SI 20260615 PS"}
{"ts_recv":"2026-04-07T02:37:16.933581095Z","hd":{"ts_event":"2026-04-07T02:37:16.933560999Z","rtype":160,"publisher_id":101,"instrument_id":436},"action":"C","side":"B","price":"1.156650000","size":30,"channel_id":23,"order_id":"10998901473788256796","flags":0,"ts_in_delta":954,"sequence":167102,"symbol":"FCEU SI 20260615 PS"}
{"ts_recv":"2026-04-07T02:37:16.933581095Z","hd":{"ts_event":"2026-04-07T02:37:16.933560999Z","rtype":160,"publisher_id":101,"instrument_id":436},"action":"A","side":"B","price":"1.156640000","size":30,"channel_id":23,"order_id":"10998901473788342660","flags":0,"ts_in_delta":954,"sequence":167102,"symbol":"FCEU SI 20260615 PS"}
{"ts_recv":"2026-04-07T02:37:16.933581095Z","hd":{"ts_event":"2026-04-07T02:37:16.933560999Z","rtype":160,"publisher_id":101,"instrument_id":436},"action":"C","side":"A","price":"1.156750000","size":30,"channel_id":23,"order_id":"1775529436933480988","flags":0,"ts_in_delta":954,"sequence":167102,"symbol":"FCEU SI 20260615 PS"}
{"ts_recv":"2026-04-07T02:37:16.933581095Z","hd":{"ts_event":"2026-04-07T02:37:16.933560999Z","rtype":160,"publisher_id":101,"instrument_id":436},"action":"A","side":"A","price":"1.156740000","size":30,"channel_id":23,"order_id":"1775529436933566852","flags":128,"ts_in_delta":954,"sequence":167102,"symbol":"FCEU SI 20260615 PS"}
{"ts_recv":"2026-04-07T02:37:16.933639215Z","hd":{"ts_event":"2026-04-07T02:37:16.933619875Z","rtype":160,"publisher_id":101,"instrument_id":436},"action":"C","side":"B","price":"1.156640000","size":30,"channel_id":23,"order_id":"10998901473788342660","flags":0,"ts_in_delta":964,"sequence":167103,"symbol":"FCEU SI 20260615 PS"}
{"ts_recv":"2026-04-07T02:37:16.933639215Z","hd":{"ts_event":"2026-04-07T02:37:16.933619875Z","rtype":160,"publisher_id":101,"instrument_id":436},"action":"A","side":"B","price":"1.156650000","size":30,"channel_id":23,"order_id":"10998901473788403000","flags":0,"ts_in_delta":964,"sequence":167103,"symbol":"FCEU SI 20260615 PS"}
{"ts_recv":"2026-04-07T02:37:16.933639215Z","hd":{"ts_event":"2026-04-07T02:37:16.933619875Z","rtype":160,"publisher_id":101,"instrument_id":436},"action":"C","side":"A","price":"1.156740000","size":30,"channel_id":23,"order_id":"1775529436933566852","flags":0,"ts_in_delta":964,"sequence":167103,"symbol":"FCEU SI 20260615 PS"}
{"ts_recv":"2026-04-07T02:37:16.933639215Z","hd":{"ts_event":"2026-04-07T02:37:16.933619875Z","rtype":160,"publisher_id":101,"instrument_id":436},"action":"A","side":"A","price":"1.156750000","size":30,"channel_id":23,"order_id":"1775529436933627192","flags":128,"ts_in_delta":964,"sequence":167103,"symbol":"FCEU SI 20260615 PS"}
{"ts_recv":"2026-04-07T02:37:16.946426405Z","hd":{"ts_event":"2026-04-07T02:37:16.946406829Z","rtype":160,"publisher_id":101,"instrument_id":436},"action":"C","side":"B","price":"1.156660000","size":30,"channel_id":23,"order_id":"10998901464917776854","flags":0,"ts_in_delta":986,"sequence":167105,"symbol":"FCEU SI 20260615 PS"}
{"ts_recv":"2026-04-07T02:37:16.946426405Z","hd":{"ts_event":"2026-04-07T02:37:16.946406829Z","rtype":160,"publisher_id":101,"instrument_id":436},"action":"A","side":"B","price":"1.156640000","size":30,"channel_id":23,"order_id":"10998901473801188689","flags":0,"ts_in_delta":986,"sequence":167105,"symbol":"FCEU SI 20260615 PS"}
{"ts_recv":"2026-04-07T02:37:16.946426405Z","hd":{"ts_event":"2026-04-07T02:37:16.946406829Z","rtype":160,"publisher_id":101,"instrument_id":436},"action":"C","side":"A","price":"1.156760000","size":30,"channel_id":23,"order_id":"1775529428063001046","flags":0,"ts_in_delta":986,"sequence":167105,"symbol":"FCEU SI 20260615 PS"}
{"ts_recv":"2026-04-07T02:37:16.946426405Z","hd":{"ts_event":"2026-04-07T02:37:16.946406829Z","rtype":160,"publisher_id":101,"instrument_id":436},"action":"A","side":"A","price":"1.156740000","size":30,"channel_id":23,"order_id":"1775529436946412881","flags":128,"ts_in_delta":986,"sequence":167105,"symbol":"FCEU SI 20260615 PS"}
{"ts_recv":"2026-04-07T02:37:16.946484325Z","hd":{"ts_event":"2026-04-07T02:37:16.946468193Z","rtype":160,"publisher_id":101,"instrument_id":436},"action":"C","side":"B","price":"1.156650000","size":30,"channel_id":23,"order_id":"10998901473788403000","flags":0,"ts_in_delta":1088,"sequence":167106,"symbol":"FCEU SI 20260615 PS"}
{"ts_recv":"2026-04-07T02:37:16.946484325Z","hd":{"ts_event":"2026-04-07T02:37:16.946468193Z","rtype":160,"publisher_id":101,"instrument_id":436},"action":"A","side":"B","price":"1.156640000","size":30,"channel_id":23,"order_id":"10998901473801249842","flags":0,"ts_in_delta":1088,"sequence":167106,"symbol":"FCEU SI 20260615 PS"}
{"ts_recv":"2026-04-07T02:37:16.946484325Z","hd":{"ts_event":"2026-04-07T02:37:16.946468193Z","rtype":160,"publisher_id":101,"instrument_id":436},"action":"C","side":"A","price":"1.156750000","size":30,"channel_id":23,"order_id":"1775529436933627192","flags":0,"ts_in_delta":1088,"sequence":167106,"symbol":"FCEU SI 20260615 PS"}
{"ts_recv":"2026-04-07T02:37:16.946484325Z","hd":{"ts_event":"2026-04-07T02:37:16.946468193Z","rtype":160,"publisher_id":101,"instrument_id":436},"action":"A","side":"A","price":"1.156740000","size":30,"channel_id":23,"order_id":"1775529436946474034","flags":128,"ts_in_delta":1088,"sequence":167106,"symbol":"FCEU SI 20260615 PS"}
{"ts_recv":"2026-04-07T02:37:52.690856197Z","hd":{"ts_event":"2026-04-07T02:37:52.690829645Z","rtype":160,"publisher_id":101,"instrument_id":436},"action":"C","side":"B","price":"1.156640000","size":30,"channel_id":23,"order_id":"10998901473801249842","flags":0,"ts_in_delta":916,"sequence":167293,"symbol":"FCEU SI 20260615 PS"}
{"ts_recv":"2026-04-07T02:37:52.690856197Z","hd":{"ts_event":"2026-04-07T02:37:52.690829645Z","rtype":160,"publisher_id":101,"instrument_id":436},"action":"A","side":"B","price":"1.156630000","size":30,"channel_id":23,"order_id":"10998901509545611905","flags":0,"ts_in_delta":916,"sequence":167293,"symbol":"FCEU SI 20260615 PS"}
{"ts_recv":"2026-04-07T02:37:52.690856197Z","hd":{"ts_event":"2026-04-07T02:37:52.690829645Z","rtype":160,"publisher_id":101,"instrument_id":436},"action":"C","side":"A","price":"1.156740000","size":30,"channel_id":23,"order_id":"1775529436946474034","flags":0,"ts_in_delta":916,"sequence":167293,"symbol":"FCEU SI 20260615 PS"}
{"ts_recv":"2026-04-07T02:37:52.690856197Z","hd":{"ts_event":"2026-04-07T02:37:52.690829645Z","rtype":160,"publisher_id":101,"instrument_id":436},"action":"A","side":"A","price":"1.156730000","size":30,"channel_id":23,"order_id":"1775529472690836097","flags":128,"ts_in_delta":916,"sequence":167293,"symbol":"FCEU SI 20260615 PS"}
{"ts_recv":"2026-04-07T02:37:52.691906911Z","hd":{"ts_event":"2026-04-07T02:37:52.691884763Z","rtype":160,"publisher_id":101,"instrument_id":436},"action":"C","side":"B","price":"1.156640000","size":30,"channel_id":23,"order_id":"10998901473801188689","flags":0,"ts_in_delta":912,"sequence":167295,"symbol":"FCEU SI 20260615 PS"}
{"ts_recv":"2026-04-07T02:37:52.691906911Z","hd":{"ts_event":"2026-04-07T02:37:52.691884763Z","rtype":160,"publisher_id":101,"instrument_id":436},"action":"A","side":"B","price":"1.156620000","size":30,"channel_id":23,"order_id":"10998901509546666627","flags":0,"ts_in_delta":912,"sequence":167295,"symbol":"FCEU SI 20260615 PS"}
{"ts_recv":"2026-04-07T02:37:52.691906911Z","hd":{"ts_event":"2026-04-07T02:37:52.691884763Z","rtype":160,"publisher_id":101,"instrument_id":436},"action":"C","side":"A","price":"1.156740000","size":30,"channel_id":23,"order_id":"1775529436946412881","flags":0,"ts_in_delta":912,"sequence":167295,"symbol":"FCEU SI 20260615 PS"}
{"ts_recv":"2026-04-07T02:37:52.691906911Z","hd":{"ts_event":"2026-04-07T02:37:52.691884763Z","rtype":160,"publisher_id":101,"instrument_id":436},"action":"A","side":"A","price":"1.156720000","size":30,"channel_id":23,"order_id":"1775529472691890819","flags":128,"ts_in_delta":912,"sequence":167295,"symbol":"FCEU SI 20260615 PS"}
{"ts_recv":"2026-04-07T02:37:52.691974768Z","hd":{"ts_event":"2026-04-07T02:37:52.691954817Z","rtype":160,"publisher_id":101,"instrument_id":436},"action":"C","side":"B","price":"1.156630000","size":30,"channel_id":23,"order_id":"10998901509545611905","flags":0,"ts_in_delta":890,"sequence":167296,"symbol":"FCEU SI 20260615 PS"}
{"ts_recv":"2026-04-07T02:37:52.691974768Z","hd":{"ts_event":"2026-04-07T02:37:52.691954817Z","rtype":160,"publisher_id":101,"instrument_id":436},"action":"A","side":"B","price":"1.156620000","size":30,"channel_id":23,"order_id":"10998901509546736865","flags":0,"ts_in_delta":890,"sequence":167296,"symbol":"FCEU SI 20260615 PS"}
{"ts_recv":"2026-04-07T02:37:52.691974768Z","hd":{"ts_event":"2026-04-07T02:37:52.691954817Z","rtype":160,"publisher_id":101,"instrument_id":436},"action":"C","side":"A","price":"1.156730000","size":30,"channel_id":23,"order_id":"1775529472690836097","flags":0,"ts_in_delta":890,"sequence":167296,"symbol":"FCEU SI 20260615 PS"}
{"ts_recv":"2026-04-07T02:37:52.691974768Z","hd":{"ts_event":"2026-04-07T02:37:52.691954817Z","rtype":160,"publisher_id":101,"instrument_id":436},"action":"A","side":"A","price":"1.156720000","size":30,"channel_id":23,"order_id":"1775529472691961057","flags":128,"ts_in_delta":890,"sequence":167296,"symbol":"FCEU SI 20260615 PS"}
{"ts_recv":"2026-04-07T02:37:52.700476017Z","hd":{"ts_event":"2026-04-07T02:37:52.700452501Z","rtype":160,"publisher_id":101,"instrument_id":436},"action":"C","side":"B","price":"1.156620000","size":30,"channel_id":23,"order_id":"10998901509546736865","flags":0,"ts_in_delta":900,"sequence":167301,"symbol":"FCEU SI 20260615 PS"}
{"ts_recv":"2026-04-07T02:37:52.700476017Z","hd":{"ts_event":"2026-04-07T02:37:52.700452501Z","rtype":160,"publisher_id":101,"instrument_id":436},"action":"A","side":"B","price":"1.156610000","size":30,"channel_id":23,"order_id":"10998901509555236007","flags":0,"ts_in_delta":900,"sequence":167301,"symbol":"FCEU SI 20260615 PS"}
{"ts_recv":"2026-04-07T02:37:52.700476017Z","hd":{"ts_event":"2026-04-07T02:37:52.700452501Z","rtype":160,"publisher_id":101,"instrument_id":436},"action":"C","side":"A","price":"1.156720000","size":30,"channel_id":23,"order_id":"1775529472691961057","flags":0,"ts_in_delta":900,"sequence":167301,"symbol":"FCEU SI 20260615 PS"}
{"ts_recv":"2026-04-07T02:37:52.700476017Z","hd":{"ts_event":"2026-04-07T02:37:52.700452501Z","rtype":160,"publisher_id":101,"instrument_id":436},"action":"A","side":"A","price":"1.156710000","size":30,"channel_id":23,"order_id":"1775529472700460199","flags":128,"ts_in_delta":900,"sequence":167301,"symbol":"FCEU SI 20260615 PS"}
{"ts_recv":"2026-04-07T02:37:52.700560555Z","hd":{"ts_event":"2026-04-07T02:37:52.700540181Z","rtype":160,"publisher_id":101,"instrument_id":436},"action":"C","side":"B","price":"1.156610000","size":30,"channel_id":23,"order_id":"10998901509555236007","flags":0,"ts_in_delta":897,"sequence":167302,"symbol":"FCEU SI 20260615 PS"}
{"ts_recv":"2026-04-07T02:37:52.700560555Z","hd":{"ts_event":"2026-04-07T02:37:52.700540181Z","rtype":160,"publisher_id":101,"instrument_id":436},"action":"A","side":"B","price":"1.156600000","size":30,"channel_id":23,"order_id":"10998901509555322533","flags":0,"ts_in_delta":897,"sequence":167302,"symbol":"FCEU SI 20260615 PS"}
{"ts_recv":"2026-04-07T02:37:52.700560555Z","hd":{"ts_event":"2026-04-07T02:37:52.700540181Z","rtype":160,"publisher_id":101,"instrument_id":436},"action":"C","side":"A","price":"1.156710000","size":30,"channel_id":23,"order_id":"1775529472700460199","flags":0,"ts_in_delta":897,"sequence":167302,"symbol":"FCEU SI 20260615 PS"}
{"ts_recv":"2026-04-07T02:37:52.700560555Z","hd":{"ts_event":"2026-04-07T02:37:52.700540181Z","rtype":160,"publisher_id":101,"instrument_id":436},"action":"A","side":"A","price":"1.156700000","size":30,"channel_id":23,"order_id":"1775529472700546725","flags":128,"ts_in_delta":897,"sequence":167302,"symbol":"FCEU SI 20260615 PS"}
{"ts_recv":"2026-04-07T02:37:52.700615188Z","hd":{"ts_event":"2026-04-07T02:37:52.700599957Z","rtype":160,"publisher_id":101,"instrument_id":436},"action":"C","side":"B","price":"1.156600000","size":30,"channel_id":23,"order_id":"10998901509555322533","flags":0,"ts_in_delta":932,"sequence":167303,"symbol":"FCEU SI 20260615 PS"}
{"ts_recv":"2026-04-07T02:37:52.700615188Z","hd":{"ts_event":"2026-04-07T02:37:52.700599957Z","rtype":160,"publisher_id":101,"instrument_id":436},"action":"A","side":"B","price":"1.156610000","size":30,"channel_id":23,"order_id":"10998901509555381790","flags":0,"ts_in_delta":932,"sequence":167303,"symbol":"FCEU SI 20260615 PS"}
{"ts_recv":"2026-04-07T02:37:52.700615188Z","hd":{"ts_event":"2026-04-07T02:37:52.700599957Z","rtype":160,"publisher_id":101,"instrument_id":436},"action":"C","side":"A","price":"1.156700000","size":30,"channel_id":23,"order_id":"1775529472700546725","flags":0,"ts_in_delta":932,"sequence":167303,"symbol":"FCEU SI 20260615 PS"}
{"ts_recv":"2026-04-07T02:37:52.700615188Z","hd":{"ts_event":"2026-04-07T02:37:52.700599957Z","rtype":160,"publisher_id":101,"instrument_id":436},"action":"A","side":"A","price":"1.156710000","size":30,"channel_id":23,"order_id":"1775529472700605982","flags":128,"ts_in_delta":932,"sequence":167303,"symbol":"FCEU SI 20260615 PS"}
{"ts_recv":"2026-04-07T02:37:52.728576407Z","hd":{"ts_event":"2026-04-07T02:37:52.728556955Z","rtype":160,"publisher_id":101,"instrument_id":436},"action":"C","side":"B","price":"1.156620000","size":30,"channel_id":23,"order_id":"10998901509546666627","flags":0,"ts_in_delta":826,"sequence":167311,"symbol":"FCEU SI 20260615 PS"}
{"ts_recv":"2026-04-07T02:37:52.728576407Z","hd":{"ts_event":"2026-04-07T02:37:52.728556955Z","rtype":160,"publisher_id":101,"instrument_id":436},"action":"A","side":"B","price":"1.156600000","size":30,"channel_id":23,"order_id":"10998901509583338822","flags":0,"ts_in_delta":826,"sequence":167311,"symbol":"FCEU SI 20260615 PS"}
{"ts_recv":"2026-04-07T02:37:52.728576407Z","hd":{"ts_event":"2026-04-07T02:37:52.728556955Z","rtype":160,"publisher_id":101,"instrument_id":436},"action":"C","side":"A","price":"1.156720000","size":30,"channel_id":23,"order_id":"1775529472691890819","flags":0,"ts_in_delta":826,"sequence":167311,"symbol":"FCEU SI 20260615 PS"}
{"ts_recv":"2026-04-07T02:37:52.728576407Z","hd":{"ts_event":"2026-04-07T02:37:52.728556955Z","rtype":160,"publisher_id":101,"instrument_id":436},"action":"A","side":"A","price":"1.156700000","size":30,"channel_id":23,"order_id":"1775529472728563014","flags":128,"ts_in_delta":826,"sequence":167311,"symbol":"FCEU SI 20260615 PS"}
{"ts_recv":"2026-04-07T02:37:52.728634742Z","hd":{"ts_event":"2026-04-07T02:37:52.728617091Z","rtype":160,"publisher_id":101,"instrument_id":436},"action":"C","side":"B","price":"1.156610000","size":30,"channel_id":23,"order_id":"10998901509555381790","flags":0,"ts_in_delta":934,"sequence":167312,"symbol":"FCEU SI 20260615 PS"}
{"ts_recv":"2026-04-07T02:37:52.728634742Z","hd":{"ts_event":"2026-04-07T02:37:52.728617091Z","rtype":160,"publisher_id":101,"instrument_id":436},"action":"A","side":"B","price":"1.156600000","size":30,"channel_id":23,"order_id":"10998901509583398749","flags":0,"ts_in_delta":934,"sequence":167312,"symbol":"FCEU SI 20260615 PS"}
{"ts_recv":"2026-04-07T02:37:52.728634742Z","hd":{"ts_event":"2026-04-07T02:37:52.728617091Z","rtype":160,"publisher_id":101,"instrument_id":436},"action":"C","side":"A","price":"1.156710000","size":30,"channel_id":23,"order_id":"1775529472700605982","flags":0,"ts_in_delta":934,"sequence":167312,"symbol":"FCEU SI 20260615 PS"}
{"ts_recv":"2026-04-07T02:37:52.728634742Z","hd":{"ts_event":"2026-04-07T02:37:52.728617091Z","rtype":160,"publisher_id":101,"instrument_id":436},"action":"A","side":"A","price":"1.156700000","size":30,"channel_id":23,"order_id":"1775529472728622941","flags":128,"ts_in_delta":934,"sequence":167312,"symbol":"FCEU SI 20260615 PS"}
{"ts_recv":"2026-04-07T02:37:52.856507125Z","hd":{"ts_event":"2026-04-07T02:37:52.856487255Z","rtype":160,"publisher_id":101,"instrument_id":436},"action":"C","side":"B","price":"1.156600000","size":30,"channel_id":23,"order_id":"10998901509583398749","flags":0,"ts_in_delta":922,"sequence":167338,"symbol":"FCEU SI 20260615 PS"}
{"ts_recv":"2026-04-07T02:37:52.856507125Z","hd":{"ts_event":"2026-04-07T02:37:52.856487255Z","rtype":160,"publisher_id":101,"instrument_id":436},"action":"A","side":"B","price":"1.156590000","size":30,"channel_id":23,"order_id":"10998901509711269269","flags":0,"ts_in_delta":922,"sequence":167338,"symbol":"FCEU SI 20260615 PS"}
{"ts_recv":"2026-04-07T02:37:52.856507125Z","hd":{"ts_event":"2026-04-07T02:37:52.856487255Z","rtype":160,"publisher_id":101,"instrument_id":436},"action":"C","side":"A","price":"1.156700000","size":30,"channel_id":23,"order_id":"1775529472728622941","flags":0,"ts_in_delta":922,"sequence":167338,"symbol":"FCEU SI 20260615 PS"}
{"ts_recv":"2026-04-07T02:37:52.856507125Z","hd":{"ts_event":"2026-04-07T02:37:52.856487255Z","rtype":160,"publisher_id":101,"instrument_id":436},"action":"A","side":"A","price":"1.156690000","size":30,"channel_id":23,"order_id":"1775529472856493461","flags":128,"ts_in_delta":922,"sequence":167338,"symbol":"FCEU SI 20260615 PS"}
{"ts_recv":"2026-04-07T02:37:52.856567993Z","hd":{"ts_event":"2026-04-07T02:37:52.856550827Z","rtype":160,"publisher_id":101,"instrument_id":436},"action":"C","side":"B","price":"1.156590000","size":30,"channel_id":23,"order_id":"10998901509711269269","flags":0,"ts_in_delta":912,"sequence":167339,"symbol":"FCEU SI 20260615 PS"}
{"ts_recv":"2026-04-07T02:37:52.856567993Z","hd":{"ts_event":"2026-04-07T02:37:52.856550827Z","rtype":160,"publisher_id":101,"instrument_id":436},"action":"A","side":"B","price":"1.156580000","size":30,"channel_id":23,"order_id":"10998901509711332431","flags":0,"ts_in_delta":912,"sequence":167339,"symbol":"FCEU SI 20260615 PS"}
{"ts_recv":"2026-04-07T02:37:52.856567993Z","hd":{"ts_event":"2026-04-07T02:37:52.856550827Z","rtype":160,"publisher_id":101,"instrument_id":436},"action":"C","side":"A","price":"1.156690000","size":30,"channel_id":23,"order_id":"1775529472856493461","flags":0,"ts_in_delta":912,"sequence":167339,"symbol":"FCEU SI 20260615 PS"}
{"ts_recv":"2026-04-07T02:37:52.856567993Z","hd":{"ts_event":"2026-04-07T02:37:52.856550827Z","rtype":160,"publisher_id":101,"instrument_id":436},"action":"A","side":"A","price":"1.156680000","size":30,"channel_id":23,"order_id":"1775529472856556623","flags":128,"ts_in_delta":912,"sequence":167339,"symbol":"FCEU SI 20260615 PS"}
{"ts_recv":"2026-04-07T02:37:52.856616045Z","hd":{"ts_event":"2026-04-07T02:37:52.856598425Z","rtype":160,"publisher_id":101,"instrument_id":436},"action":"C","side":"B","price":"1.156600000","size":30,"channel_id":23,"order_id":"10998901509583338822","flags":0,"ts_in_delta":890,"sequence":167340,"symbol":"FCEU SI 20260615 PS"}
{"ts_recv":"2026-04-07T02:37:52.856616045Z","hd":{"ts_event":"2026-04-07T02:37:52.856598425Z","rtype":160,"publisher_id":101,"instrument_id":436},"action":"A","side":"B","price":"1.156580000","size":30,"channel_id":23,"order_id":"10998901509711380220","flags":0,"ts_in_delta":890,"sequence":167340,"symbol":"FCEU SI 20260615 PS"}
{"ts_recv":"2026-04-07T02:37:52.856616045Z","hd":{"ts_event":"2026-04-07T02:37:52.856598425Z","rtype":160,"publisher_id":101,"instrument_id":436},"action":"C","side":"A","price":"1.156700000","size":30,"channel_id":23,"order_id":"1775529472728563014","flags":0,"ts_in_delta":890,"sequence":167340,"symbol":"FCEU SI 20260615 PS"}
{"ts_recv":"2026-04-07T02:37:52.856616045Z","hd":{"ts_event":"2026-04-07T02:37:52.856598425Z","rtype":160,"publisher_id":101,"instrument_id":436},"action":"A","side":"A","price":"1.156680000","size":30,"channel_id":23,"order_id":"1775529472856604412","flags":128,"ts_in_delta":890,"sequence":167340,"symbol":"FCEU SI 20260615 PS"}
{"ts_recv":"2026-04-07T02:37:52.856626627Z","hd":{"ts_event":"2026-04-07T02:37:52.856604901Z","rtype":160,"publisher_id":101,"instrument_id":436},"action":"C","side":"B","price":"1.156580000","size":30,"channel_id":23,"order_id":"10998901509711332431","flags":0,"ts_in_delta":1115,"sequence":167341,"symbol":"FCEU SI 20260615 PS"}
{"ts_recv":"2026-04-07T02:37:52.856626627Z","hd":{"ts_event":"2026-04-07T02:37:52.856604901Z","rtype":160,"publisher_id":101,"instrument_id":436},"action":"A","side":"B","price":"1.156590000","size":30,"channel_id":23,"order_id":"10998901509711388583","flags":0,"ts_in_delta":1115,"sequence":167341,"symbol":"FCEU SI 20260615 PS"}
{"ts_recv":"2026-04-07T02:37:52.856626627Z","hd":{"ts_event":"2026-04-07T02:37:52.856604901Z","rtype":160,"publisher_id":101,"instrument_id":436},"action":"C","side":"A","price":"1.156680000","size":30,"channel_id":23,"order_id":"1775529472856556623","flags":0,"ts_in_delta":1115,"sequence":167341,"symbol":"FCEU SI 20260615 PS"}
{"ts_recv":"2026-04-07T02:37:52.856626627Z","hd":{"ts_event":"2026-04-07T02:37:52.856604901Z","rtype":160,"publisher_id":101,"instrument_id":436},"action":"A","side":"A","price":"1.156690000","size":30,"channel_id":23,"order_id":"1775529472856612775","flags":128,"ts_in_delta":1115,"sequence":167341,"symbol":"FCEU SI 20260615 PS"}
{"ts_recv":"2026-04-07T02:37:52.856680930Z","hd":{"ts_event":"2026-04-07T02:37:52.856663359Z","rtype":160,"publisher_id":101,"instrument_id":436},"action":"C","side":"B","price":"1.156590000","size":30,"channel_id":23,"order_id":"10998901509711388583","flags":0,"ts_in_delta":732,"sequence":167342,"symbol":"FCEU SI 20260615 PS"}
{"ts_recv":"2026-04-07T02:37:52.856680930Z","hd":{"ts_event":"2026-04-07T02:37:52.856663359Z","rtype":160,"publisher_id":101,"instrument_id":436},"action":"A","side":"B","price":"1.156580000","size":30,"channel_id":23,"order_id":"10998901509711445135","flags":0,"ts_in_delta":732,"sequence":167342,"symbol":"FCEU SI 20260615 PS"}
{"ts_recv":"2026-04-07T02:37:52.856680930Z","hd":{"ts_event":"2026-04-07T02:37:52.856663359Z","rtype":160,"publisher_id":101,"instrument_id":436},"action":"C","side":"A","price":"1.156690000","size":30,"channel_id":23,"order_id":"1775529472856612775","flags":0,"ts_in_delta":732,"sequence":167342,"symbol":"FCEU SI 20260615 PS"}
{"ts_recv":"2026-04-07T02:37:52.856680930Z","hd":{"ts_event":"2026-04-07T02:37:52.856663359Z","rtype":160,"publisher_id":101,"instrument_id":436},"action":"A","side":"A","price":"1.156680000","size":30,"channel_id":23,"order_id":"1775529472856669327","flags":128,"ts_in_delta":732,"sequence":167342,"symbol":"FCEU SI 20260615 PS"}
{"ts_recv":"2026-04-07T02:38:01.996009168Z","hd":{"ts_event":"2026-04-07T02:38:01.995986225Z","rtype":160,"publisher_id":101,"instrument_id":436},"action":"C","side":"B","price":"1.156580000","size":30,"channel_id":23,"order_id":"10998901509711445135","flags":0,"ts_in_delta":923,"sequence":167436,"symbol":"FCEU SI 20260615 PS"}
{"ts_recv":"2026-04-07T02:38:01.996009168Z","hd":{"ts_event":"2026-04-07T02:38:01.995986225Z","rtype":160,"publisher_id":101,"instrument_id":436},"action":"A","side":"B","price":"1.156590000","size":30,"channel_id":23,"order_id":"10998901518850768095","flags":0,"ts_in_delta":923,"sequence":167436,"symbol":"FCEU SI 20260615 PS"}
{"ts_recv":"2026-04-07T02:38:01.996009168Z","hd":{"ts_event":"2026-04-07T02:38:01.995986225Z","rtype":160,"publisher_id":101,"instrument_id":436},"action":"C","side":"A","price":"1.156680000","size":30,"channel_id":23,"order_id":"1775529472856669327","flags":0,"ts_in_delta":923,"sequence":167436,"symbol":"FCEU SI 20260615 PS"}
{"ts_recv":"2026-04-07T02:38:01.996009168Z","hd":{"ts_event":"2026-04-07T02:38:01.995986225Z","rtype":160,"publisher_id":101,"instrument_id":436},"action":"A","side":"A","price":"1.156690000","size":30,"channel_id":23,"order_id":"1775529481995992287","flags":128,"ts_in_delta":923,"sequence":167436,"symbol":"FCEU SI 20260615 PS"}
{"ts_recv":"2026-04-07T02:38:01.996083220Z","hd":{"ts_event":"2026-04-07T02:38:01.996061151Z","rtype":160,"publisher_id":101,"instrument_id":436},"action":"C","side":"B","price":"1.156580000","size":30,"channel_id":23,"order_id":"10998901509711380220","flags":0,"ts_in_delta":917,"sequence":167437,"symbol":"FCEU SI 20260615 PS"}
{"ts_recv":"2026-04-07T02:38:01.996083220Z","hd":{"ts_event":"2026-04-07T02:38:01.996061151Z","rtype":160,"publisher_id":101,"instrument_id":436},"action":"A","side":"B","price":"1.156600000","size":30,"channel_id":23,"order_id":"10998901518850843400","flags":0,"ts_in_delta":917,"sequence":167437,"symbol":"FCEU SI 20260615 PS"}
{"ts_recv":"2026-04-07T02:38:01.996083220Z","hd":{"ts_event":"2026-04-07T02:38:01.996061151Z","rtype":160,"publisher_id":101,"instrument_id":436},"action":"C","side":"A","price":"1.156680000","size":30,"channel_id":23,"order_id":"1775529472856604412","flags":0,"ts_in_delta":917,"sequence":167437,"symbol":"FCEU SI 20260615 PS"}
{"ts_recv":"2026-04-07T02:38:01.996083220Z","hd":{"ts_event":"2026-04-07T02:38:01.996061151Z","rtype":160,"publisher_id":101,"instrument_id":436},"action":"A","side":"A","price":"1.156700000","size":30,"channel_id":23,"order_id":"1775529481996067592","flags":128,"ts_in_delta":917,"sequence":167437,"symbol":"FCEU SI 20260615 PS"}
{"ts_recv":"2026-04-07T02:38:01.996147906Z","hd":{"ts_event":"2026-04-07T02:38:01.996131473Z","rtype":160,"publisher_id":101,"instrument_id":436},"action":"C","side":"B","price":"1.156590000","size":30,"channel_id":23,"order_id":"10998901518850768095","flags":0,"ts_in_delta":924,"sequence":167438,"symbol":"FCEU SI 20260615 PS"}
{"ts_recv":"2026-04-07T02:38:01.996147906Z","hd":{"ts_event":"2026-04-07T02:38:01.996131473Z","rtype":160,"publisher_id":101,"instrument_id":436},"action":"A","side":"B","price":"1.156600000","size":30,"channel_id":23,"order_id":"10998901518850912967","flags":0,"ts_in_delta":924,"sequence":167438,"symbol":"FCEU SI 20260615 PS"}
{"ts_recv":"2026-04-07T02:38:01.996147906Z","hd":{"ts_event":"2026-04-07T02:38:01.996131473Z","rtype":160,"publisher_id":101,"instrument_id":436},"action":"C","side":"A","price":"1.156690000","size":30,"channel_id":23,"order_id":"1775529481995992287","flags":0,"ts_in_delta":924,"sequence":167438,"symbol":"FCEU SI 20260615 PS"}
{"ts_recv":"2026-04-07T02:38:01.996147906Z","hd":{"ts_event":"2026-04-07T02:38:01.996131473Z","rtype":160,"publisher_id":101,"instrument_id":436},"action":"A","side":"A","price":"1.156700000","size":30,"channel_id":23,"order_id":"1775529481996137159","flags":128,"ts_in_delta":924,"sequence":167438,"symbol":"FCEU SI 20260615 PS"}
{"ts_recv":"2026-04-07T02:38:10.174269511Z","hd":{"ts_event":"2026-04-07T02:38:10.174244955Z","rtype":160,"publisher_id":101,"instrument_id":436},"action":"C","side":"B","price":"1.156600000","size":30,"channel_id":23,"order_id":"10998901518850912967","flags":0,"ts_in_delta":960,"sequence":167510,"symbol":"FCEU SI 20260615 PS"}
{"ts_recv":"2026-04-07T02:38:10.174269511Z","hd":{"ts_event":"2026-04-07T02:38:10.174244955Z","rtype":160,"publisher_id":101,"instrument_id":436},"action":"A","side":"B","price":"1.156610000","size":30,"channel_id":23,"order_id":"10998901527029026763","flags":0,"ts_in_delta":960,"sequence":167510,"symbol":"FCEU SI 20260615 PS"}
{"ts_recv":"2026-04-07T02:38:10.174269511Z","hd":{"ts_event":"2026-04-07T02:38:10.174244955Z","rtype":160,"publisher_id":101,"instrument_id":436},"action":"C","side":"A","price":"1.156700000","size":30,"channel_id":23,"order_id":"1775529481996137159","flags":0,"ts_in_delta":960,"sequence":167510,"symbol":"FCEU SI 20260615 PS"}
{"ts_recv":"2026-04-07T02:38:10.174269511Z","hd":{"ts_event":"2026-04-07T02:38:10.174244955Z","rtype":160,"publisher_id":101,"instrument_id":436},"action":"A","side":"A","price":"1.156710000","size":30,"channel_id":23,"order_id":"1775529490174250955","flags":128,"ts_in_delta":960,"sequence":167510,"symbol":"FCEU SI 20260615 PS"}
{"ts_recv":"2026-04-07T02:38:10.174331209Z","hd":{"ts_event":"2026-04-07T02:38:10.174312539Z","rtype":160,"publisher_id":101,"instrument_id":436},"action":"C","side":"B","price":"1.156600000","size":30,"channel_id":23,"order_id":"10998901518850843400","flags":0,"ts_in_delta":895,"sequence":167511,"symbol":"FCEU SI 20260615 PS"}
{"ts_recv":"2026-04-07T02:38:10.174331209Z","hd":{"ts_event":"2026-04-07T02:38:10.174312539Z","rtype":160,"publisher_id":101,"instrument_id":436},"action":"A","side":"B","price":"1.156620000","size":30,"channel_id":23,"order_id":"10998901527029094466","flags":0,"ts_in_delta":895,"sequence":167511,"symbol":"FCEU SI 20260615 PS"}
{"ts_recv":"2026-04-07T02:38:10.174331209Z","hd":{"ts_event":"2026-04-07T02:38:10.174312539Z","rtype":160,"publisher_id":101,"instrument_id":436},"action":"C","side":"A","price":"1.156700000","size":30,"channel_id":23,"order_id":"1775529481996067592","flags":0,"ts_in_delta":895,"sequence":167511,"symbol":"FCEU SI 20260615 PS"}
{"ts_recv":"2026-04-07T02:38:10.174331209Z","hd":{"ts_event":"2026-04-07T02:38:10.174312539Z","rtype":160,"publisher_id":101,"instrument_id":436},"action":"A","side":"A","price":"1.156720000","size":30,"channel_id":23,"order_id":"1775529490174318658","flags":128,"ts_in_delta":895,"sequence":167511,"symbol":"FCEU SI 20260615 PS"}
{"ts_recv":"2026-04-07T02:38:10.174389513Z","hd":{"ts_event":"2026-04-07T02:38:10.174370371Z","rtype":160,"publisher_id":101,"instrument_id":436},"action":"C","side":"B","price":"1.156610000","size":30,"channel_id":23,"order_id":"10998901527029026763","flags":0,"ts_in_delta":883,"sequence":167512,"symbol":"FCEU SI 20260615 PS"}
{"ts_recv":"2026-04-07T02:38:10.174389513Z","hd":{"ts_event":"2026-04-07T02:38:10.174370371Z","rtype":160,"publisher_id":101,"instrument_id":436},"action":"A","side":"B","price":"1.156620000","size":30,"channel_id":23,"order_id":"10998901527029152137","flags":0,"ts_in_delta":883,"sequence":167512,"symbol":"FCEU SI 20260615 PS"}
{"ts_recv":"2026-04-07T02:38:10.174389513Z","hd":{"ts_event":"2026-04-07T02:38:10.174370371Z","rtype":160,"publisher_id":101,"instrument_id":436},"action":"C","side":"A","price":"1.156710000","size":30,"channel_id":23,"order_id":"1775529490174250955","flags":0,"ts_in_delta":883,"sequence":167512,"symbol":"FCEU SI 20260615 PS"}
{"ts_recv":"2026-04-07T02:38:10.174389513Z","hd":{"ts_event":"2026-04-07T02:38:10.174370371Z","rtype":160,"publisher_id":101,"instrument_id":436},"action":"A","side":"A","price":"1.156720000","size":30,"channel_id":23,"order_id":"1775529490174376329","flags":128,"ts_in_delta":883,"sequence":167512,"symbol":"FCEU SI 20260615 PS"}
{"ts_recv":"2026-04-07T02:38:10.187597952Z","hd":{"ts_event":"2026-04-07T02:38:10.187578161Z","rtype":160,"publisher_id":101,"instrument_id":436},"action":"C","side":"B","price":"1.156620000","size":30,"channel_id":23,"order_id":"10998901527029152137","flags":0,"ts_in_delta":1102,"sequence":167522,"symbol":"FCEU SI 20260615 PS"}
{"ts_recv":"2026-04-07T02:38:10.187597952Z","hd":{"ts_event":"2026-04-07T02:38:10.187578161Z","rtype":160,"publisher_id":101,"instrument_id":436},"action":"A","side":"B","price":"1.156630000","size":30,"channel_id":23,"order_id":"10998901527042359807","flags":0,"ts_in_delta":1102,"sequence":167522,"symbol":"FCEU SI 20260615 PS"}
{"ts_recv":"2026-04-07T02:38:10.187597952Z","hd":{"ts_event":"2026-04-07T02:38:10.187578161Z","rtype":160,"publisher_id":101,"instrument_id":436},"action":"C","side":"A","price":"1.156720000","size":30,"channel_id":23,"order_id":"1775529490174376329","flags":0,"ts_in_delta":1102,"sequence":167522,"symbol":"FCEU SI 20260615 PS"}
{"ts_recv":"2026-04-07T02:38:10.187597952Z","hd":{"ts_event":"2026-04-07T02:38:10.187578161Z","rtype":160,"publisher_id":101,"instrument_id":436},"action":"A","side":"A","price":"1.156730000","size":30,"channel_id":23,"order_id":"1775529490187583999","flags":128,"ts_in_delta":1102,"sequence":167522,"symbol":"FCEU SI 20260615 PS"}
{"ts_recv":"2026-04-07T02:38:10.193334341Z","hd":{"ts_event":"2026-04-07T02:38:10.193312315Z","rtype":160,"publisher_id":101,"instrument_id":436},"action":"C","side":"B","price":"1.156620000","size":30,"channel_id":23,"order_id":"10998901527029094466","flags":0,"ts_in_delta":920,"sequence":167523,"symbol":"FCEU SI 20260615 PS"}
{"ts_recv":"2026-04-07T02:38:10.193334341Z","hd":{"ts_event":"2026-04-07T02:38:10.193312315Z","rtype":160,"publisher_id":101,"instrument_id":436},"action":"A","side":"B","price":"1.156640000","size":30,"channel_id":23,"order_id":"10998901527048094111","flags":0,"ts_in_delta":920,"sequence":167523,"symbol":"FCEU SI 20260615 PS"}
{"ts_recv":"2026-04-07T02:38:10.193334341Z","hd":{"ts_event":"2026-04-07T02:38:10.193312315Z","rtype":160,"publisher_id":101,"instrument_id":436},"action":"C","side":"A","price":"1.156720000","size":30,"channel_id":23,"order_id":"1775529490174318658","flags":0,"ts_in_delta":920,"sequence":167523,"symbol":"FCEU SI 20260615 PS"}
{"ts_recv":"2026-04-07T02:38:10.193334341Z","hd":{"ts_event":"2026-04-07T02:38:10.193312315Z","rtype":160,"publisher_id":101,"instrument_id":436},"action":"A","side":"A","price":"1.156740000","size":30,"channel_id":23,"order_id":"1775529490193318303","flags":128,"ts_in_delta":920,"sequence":167523,"symbol":"FCEU SI 20260615 PS"}
{"ts_recv":"2026-04-07T02:38:10.193391938Z","hd":{"ts_event":"2026-04-07T02:38:10.193372333Z","rtype":160,"publisher_id":101,"instrument_id":436},"action":"C","side":"B","price":"1.156630000","size":30,"channel_id":23,"order_id":"10998901527042359807","flags":0,"ts_in_delta":883,"sequence":167524,"symbol":"FCEU SI 20260615 PS"}
{"ts_recv":"2026-04-07T02:38:10.193391938Z","hd":{"ts_event":"2026-04-07T02:38:10.193372333Z","rtype":160,"publisher_id":101,"instrument_id":436},"action":"A","side":"B","price":"1.156640000","size":30,"channel_id":23,"order_id":"10998901527048154255","flags":0,"ts_in_delta":883,"sequence":167524,"symbol":"FCEU SI 20260615 PS"}
{"ts_recv":"2026-04-07T02:38:10.193391938Z","hd":{"ts_event":"2026-04-07T02:38:10.193372333Z","rtype":160,"publisher_id":101,"instrument_id":436},"action":"C","side":"A","price":"1.156730000","size":30,"channel_id":23,"order_id":"1775529490187583999","flags":0,"ts_in_delta":883,"sequence":167524,"symbol":"FCEU SI 20260615 PS"}
{"ts_recv":"2026-04-07T02:38:10.193391938Z","hd":{"ts_event":"2026-04-07T02:38:10.193372333Z","rtype":160,"publisher_id":101,"instrument_id":436},"action":"A","side":"A","price":"1.156740000","size":30,"channel_id":23,"order_id":"1775529490193378447","flags":128,"ts_in_delta":883,"sequence":167524,"symbol":"FCEU SI 20260615 PS"}
{"ts_recv":"2026-04-07T02:38:37.750874498Z","hd":{"ts_event":"2026-04-07T02:38:37.750845027Z","rtype":160,"publisher_id":101,"instrument_id":436},"action":"C","side":"B","price":"1.156640000","size":30,"channel_id":23,"order_id":"10998901527048154255","flags":0,"ts_in_delta":1099,"sequence":167682,"symbol":"FCEU SI 20260615 PS"}
{"ts_recv":"2026-04-07T02:38:37.750874498Z","hd":{"ts_event":"2026-04-07T02:38:37.750845027Z","rtype":160,"publisher_id":101,"instrument_id":436},"action":"A","side":"B","price":"1.156650000","size":30,"channel_id":23,"order_id":"10998901554605629766","flags":0,"ts_in_delta":1099,"sequence":167682,"symbol":"FCEU SI 20260615 PS"}
{"ts_recv":"2026-04-07T02:38:37.750874498Z","hd":{"ts_event":"2026-04-07T02:38:37.750845027Z","rtype":160,"publisher_id":101,"instrument_id":436},"action":"C","side":"A","price":"1.156740000","size":30,"channel_id":23,"order_id":"1775529490193378447","flags":0,"ts_in_delta":1099,"sequence":167682,"symbol":"FCEU SI 20260615 PS"}
{"ts_recv":"2026-04-07T02:38:37.750874498Z","hd":{"ts_event":"2026-04-07T02:38:37.750845027Z","rtype":160,"publisher_id":101,"instrument_id":436},"action":"A","side":"A","price":"1.156750000","size":30,"channel_id":23,"order_id":"1775529517750853958","flags":128,"ts_in_delta":1099,"sequence":167682,"symbol":"FCEU SI 20260615 PS"}
{"ts_recv":"2026-04-07T02:38:39.626398763Z","hd":{"ts_event":"2026-04-07T02:38:39.626378795Z","rtype":160,"publisher_id":101,"instrument_id":436},"action":"C","side":"B","price":"1.156650000","size":30,"channel_id":23,"order_id":"10998901554605629766","flags":0,"ts_in_delta":1390,"sequence":167708,"symbol":"FCEU SI 20260615 PS"}
{"ts_recv":"2026-04-07T02:38:39.626398763Z","hd":{"ts_event":"2026-04-07T02:38:39.626378795Z","rtype":160,"publisher_id":101,"instrument_id":436},"action":"A","side":"B","price":"1.156640000","size":30,"channel_id":23,"order_id":"10998901556481160894","flags":0,"ts_in_delta":1390,"sequence":167708,"symbol":"FCEU SI 20260615 PS"}
{"ts_recv":"2026-04-07T02:38:39.626398763Z","hd":{"ts_event":"2026-04-07T02:38:39.626378795Z","rtype":160,"publisher_id":101,"instrument_id":436},"action":"C","side":"A","price":"1.156750000","size":30,"channel_id":23,"order_id":"1775529517750853958","flags":0,"ts_in_delta":1390,"sequence":167708,"symbol":"FCEU SI 20260615 PS"}
{"ts_recv":"2026-04-07T02:38:39.626398763Z","hd":{"ts_event":"2026-04-07T02:38:39.626378795Z","rtype":160,"publisher_id":101,"instrument_id":436},"action":"A","side":"A","price":"1.156740000","size":30,"channel_id":23,"order_id":"1775529519626385086","flags":128,"ts_in_delta":1390,"sequence":167708,"symbol":"FCEU SI 20260615 PS"}
{"ts_recv":"2026-04-07T02:38:44.700281742Z","hd":{"ts_event":"2026-04-07T02:38:44.700260183Z","rtype":160,"publisher_id":101,"instrument_id":436},"action":"C","side":"B","price":"1.156640000","size":30,"channel_id":23,"order_id":"10998901556481160894","flags":0,"ts_in_delta":716,"sequence":167751,"symbol":"FCEU SI 20260615 PS"}
{"ts_recv":"2026-04-07T02:38:44.700281742Z","hd":{"ts_event":"2026-04-07T02:38:44.700260183Z","rtype":160,"publisher_id":101,"instrument_id":436},"action":"A","side":"B","price":"1.156650000","size":30,"channel_id":23,"order_id":"10998901561555041800","flags":0,"ts_in_delta":716,"sequence":167751,"symbol":"FCEU SI 20260615 PS"}
{"ts_recv":"2026-04-07T02:38:44.700281742Z","hd":{"ts_event":"2026-04-07T02:38:44.700260183Z","rtype":160,"publisher_id":101,"instrument_id":436},"action":"C","side":"A","price":"1.156740000","size":30,"channel_id":23,"order_id":"1775529519626385086","flags":0,"ts_in_delta":716,"sequence":167751,"symbol":"FCEU SI 20260615 PS"}
{"ts_recv":"2026-04-07T02:38:44.700281742Z","hd":{"ts_event":"2026-04-07T02:38:44.700260183Z","rtype":160,"publisher_id":101,"instrument_id":436},"action":"A","side":"A","price":"1.156750000","size":30,"channel_id":23,"order_id":"1775529524700265992","flags":128,"ts_in_delta":716,"sequence":167751,"symbol":"FCEU SI 20260615 PS"}
{"ts_recv":"2026-04-07T02:38:44.704957020Z","hd":{"ts_event":"2026-04-07T02:38:44.704938857Z","rtype":160,"publisher_id":101,"instrument_id":436},"action":"C","side":"B","price":"1.156650000","size":30,"channel_id":23,"order_id":"10998901561555041800","flags":0,"ts_in_delta":993,"sequence":167756,"symbol":"FCEU SI 20260615 PS"}
{"ts_recv":"2026-04-07T02:38:44.704957020Z","hd":{"ts_event":"2026-04-07T02:38:44.704938857Z","rtype":160,"publisher_id":101,"instrument_id":436},"action":"A","side":"B","price":"1.156660000","size":30,"channel_id":23,"order_id":"10998901561559720571","flags":0,"ts_in_delta":993,"sequence":167756,"symbol":"FCEU SI 20260615 PS"}
{"ts_recv":"2026-04-07T02:38:44.704957020Z","hd":{"ts_event":"2026-04-07T02:38:44.704938857Z","rtype":160,"publisher_id":101,"instrument_id":436},"action":"C","side":"A","price":"1.156750000","size":30,"channel_id":23,"order_id":"1775529524700265992","flags":0,"ts_in_delta":993,"sequence":167756,"symbol":"FCEU SI 20260615 PS"}
{"ts_recv":"2026-04-07T02:38:44.704957020Z","hd":{"ts_event":"2026-04-07T02:38:44.704938857Z","rtype":160,"publisher_id":101,"instrument_id":436},"action":"A","side":"A","price":"1.156760000","size":30,"channel_id":23,"order_id":"1775529524704944763","flags":128,"ts_in_delta":993,"sequence":167756,"symbol":"FCEU SI 20260615 PS"}
{"ts_recv":"2026-04-07T02:38:44.705011053Z","hd":{"ts_event":"2026-04-07T02:38:44.704994075Z","rtype":160,"publisher_id":101,"instrument_id":436},"action":"C","side":"B","price":"1.156640000","size":30,"channel_id":23,"order_id":"10998901527048094111","flags":0,"ts_in_delta":912,"sequence":167757,"symbol":"FCEU SI 20260615 PS"}
{"ts_recv":"2026-04-07T02:38:44.705011053Z","hd":{"ts_event":"2026-04-07T02:38:44.704994075Z","rtype":160,"publisher_id":101,"instrument_id":436},"action":"A","side":"B","price":"1.156660000","size":30,"channel_id":23,"order_id":"10998901561559775881","flags":0,"ts_in_delta":912,"sequence":167757,"symbol":"FCEU SI 20260615 PS"}
{"ts_recv":"2026-04-07T02:38:44.705011053Z","hd":{"ts_event":"2026-04-07T02:38:44.704994075Z","rtype":160,"publisher_id":101,"instrument_id":436},"action":"C","side":"A","price":"1.156740000","size":30,"channel_id":23,"order_id":"1775529490193318303","flags":0,"ts_in_delta":912,"sequence":167757,"symbol":"FCEU SI 20260615 PS"}
{"ts_recv":"2026-04-07T02:38:44.705011053Z","hd":{"ts_event":"2026-04-07T02:38:44.704994075Z","rtype":160,"publisher_id":101,"instrument_id":436},"action":"A","side":"A","price":"1.156760000","size":30,"channel_id":23,"order_id":"1775529524705000073","flags":128,"ts_in_delta":912,"sequence":167757,"symbol":"FCEU SI 20260615 PS"}
{"ts_recv":"2026-04-07T02:38:44.705039760Z","hd":{"ts_event":"2026-04-07T02:38:44.705022203Z","rtype":160,"publisher_id":101,"instrument_id":436},"action":"C","side":"B","price":"1.156660000","size":30,"channel_id":23,"order_id":"10998901561559720571","flags":0,"ts_in_delta":930,"sequence":167758,"symbol":"FCEU SI 20260615 PS"}
{"ts_recv":"2026-04-07T02:38:44.705039760Z","hd":{"ts_event":"2026-04-07T02:38:44.705022203Z","rtype":160,"publisher_id":101,"instrument_id":436},"action":"A","side":"B","price":"1.156650000","size":30,"channel_id":23,"order_id":"10998901561559804086","flags":0,"ts_in_delta":930,"sequence":167758,"symbol":"FCEU SI 20260615 PS"}
{"ts_recv":"2026-04-07T02:38:44.705039760Z","hd":{"ts_event":"2026-04-07T02:38:44.705022203Z","rtype":160,"publisher_id":101,"instrument_id":436},"action":"C","side":"A","price":"1.156760000","size":30,"channel_id":23,"order_id":"1775529524704944763","flags":0,"ts_in_delta":930,"sequence":167758,"symbol":"FCEU SI 20260615 PS"}
{"ts_recv":"2026-04-07T02:38:44.705039760Z","hd":{"ts_event":"2026-04-07T02:38:44.705022203Z","rtype":160,"publisher_id":101,"instrument_id":436},"action":"A","side":"A","price":"1.156750000","size":30,"channel_id":23,"order_id":"1775529524705028278","flags":128,"ts_in_delta":930,"sequence":167758,"symbol":"FCEU SI 20260615 PS"}
{"ts_recv":"2026-04-07T02:38:44.705094861Z","hd":{"ts_event":"2026-04-07T02:38:44.705079465Z","rtype":160,"publisher_id":101,"instrument_id":436},"action":"C","side":"B","price":"1.156650000","size":30,"channel_id":23,"order_id":"10998901561559804086","flags":0,"ts_in_delta":885,"sequence":167759,"symbol":"FCEU SI 20260615 PS"}
{"ts_recv":"2026-04-07T02:38:44.705094861Z","hd":{"ts_event":"2026-04-07T02:38:44.705079465Z","rtype":160,"publisher_id":101,"instrument_id":436},"action":"A","side":"B","price":"1.156660000","size":30,"channel_id":23,"order_id":"10998901561559861003","flags":0,"ts_in_delta":885,"sequence":167759,"symbol":"FCEU SI 20260615 PS"}
{"ts_recv":"2026-04-07T02:38:44.705094861Z","hd":{"ts_event":"2026-04-07T02:38:44.705079465Z","rtype":160,"publisher_id":101,"instrument_id":436},"action":"C","side":"A","price":"1.156750000","size":30,"channel_id":23,"order_id":"1775529524705028278","flags":0,"ts_in_delta":885,"sequence":167759,"symbol":"FCEU SI 20260615 PS"}
{"ts_recv":"2026-04-07T02:38:44.705094861Z","hd":{"ts_event":"2026-04-07T02:38:44.705079465Z","rtype":160,"publisher_id":101,"instrument_id":436},"action":"A","side":"A","price":"1.156760000","size":30,"channel_id":23,"order_id":"1775529524705085195","flags":128,"ts_in_delta":885,"sequence":167759,"symbol":"FCEU SI 20260615 PS"}
{"ts_recv":"2026-04-07T02:38:44.709841399Z","hd":{"ts_event":"2026-04-07T02:38:44.709821305Z","rtype":160,"publisher_id":101,"instrument_id":436},"action":"C","side":"B","price":"1.156660000","size":30,"channel_id":23,"order_id":"10998901561559861003","flags":0,"ts_in_delta":917,"sequence":167763,"symbol":"FCEU SI 20260615 PS"}
{"ts_recv":"2026-04-07T02:38:44.709841399Z","hd":{"ts_event":"2026-04-07T02:38:44.709821305Z","rtype":160,"publisher_id":101,"instrument_id":436},"action":"A","side":"B","price":"1.156670000","size":30,"channel_id":23,"order_id":"10998901561564602690","flags":0,"ts_in_delta":917,"sequence":167763,"symbol":"FCEU SI 20260615 PS"}
{"ts_recv":"2026-04-07T02:38:44.709841399Z","hd":{"ts_event":"2026-04-07T02:38:44.709821305Z","rtype":160,"publisher_id":101,"instrument_id":436},"action":"C","side":"A","price":"1.156760000","size":30,"channel_id":23,"order_id":"1775529524705085195","flags":0,"ts_in_delta":917,"sequence":167763,"symbol":"FCEU SI 20260615 PS"}
{"ts_recv":"2026-04-07T02:38:44.709841399Z","hd":{"ts_event":"2026-04-07T02:38:44.709821305Z","rtype":160,"publisher_id":101,"instrument_id":436},"action":"A","side":"A","price":"1.156770000","size":30,"channel_id":23,"order_id":"1775529524709826882","flags":128,"ts_in_delta":917,"sequence":167763,"symbol":"FCEU SI 20260615 PS"}
{"ts_recv":"2026-04-07T02:38:44.995285392Z","hd":{"ts_event":"2026-04-07T02:38:44.995267441Z","rtype":160,"publisher_id":101,"instrument_id":436},"action":"C","side":"B","price":"1.156670000","size":30,"channel_id":23,"order_id":"10998901561564602690","flags":0,"ts_in_delta":872,"sequence":167786,"symbol":"FCEU SI 20260615 PS"}
{"ts_recv":"2026-04-07T02:38:44.995285392Z","hd":{"ts_event":"2026-04-07T02:38:44.995267441Z","rtype":160,"publisher_id":101,"instrument_id":436},"action":"A","side":"B","price":"1.156660000","size":30,"channel_id":23,"order_id":"10998901561850048963","flags":0,"ts_in_delta":872,"sequence":167786,"symbol":"FCEU SI 20260615 PS"}
{"ts_recv":"2026-04-07T02:38:44.995285392Z","hd":{"ts_event":"2026-04-07T02:38:44.995267441Z","rtype":160,"publisher_id":101,"instrument_id":436},"action":"C","side":"A","price":"1.156770000","size":30,"channel_id":23,"order_id":"1775529524709826882","flags":0,"ts_in_delta":872,"sequence":167786,"symbol":"FCEU SI 20260615 PS"}
{"ts_recv":"2026-04-07T02:38:44.995285392Z","hd":{"ts_event":"2026-04-07T02:38:44.995267441Z","rtype":160,"publisher_id":101,"instrument_id":436},"action":"A","side":"A","price":"1.156760000","size":30,"channel_id":23,"order_id":"1775529524995273155","flags":128,"ts_in_delta":872,"sequence":167786,"symbol":"FCEU SI 20260615 PS"}
{"ts_recv":"2026-04-07T02:39:07.616028574Z","hd":{"ts_event":"2026-04-07T02:39:07.615991853Z","rtype":160,"publisher_id":101,"instrument_id":436},"action":"C","side":"B","price":"1.156660000","size":30,"channel_id":23,"order_id":"10998901561850048963","flags":0,"ts_in_delta":1196,"sequence":167886,"symbol":"FCEU SI 20260615 PS"}
{"ts_recv":"2026-04-07T02:39:07.616028574Z","hd":{"ts_event":"2026-04-07T02:39:07.615991853Z","rtype":160,"publisher_id":101,"instrument_id":436},"action":"A","side":"B","price":"1.156670000","size":30,"channel_id":23,"order_id":"10998901584470781618","flags":0,"ts_in_delta":1196,"sequence":167886,"symbol":"FCEU SI 20260615 PS"}
{"ts_recv":"2026-04-07T02:39:07.616028574Z","hd":{"ts_event":"2026-04-07T02:39:07.615991853Z","rtype":160,"publisher_id":101,"instrument_id":436},"action":"C","side":"A","price":"1.156760000","size":30,"channel_id":23,"order_id":"1775529524995273155","flags":0,"ts_in_delta":1196,"sequence":167886,"symbol":"FCEU SI 20260615 PS"}
{"ts_recv":"2026-04-07T02:39:07.616028574Z","hd":{"ts_event":"2026-04-07T02:39:07.615991853Z","rtype":160,"publisher_id":101,"instrument_id":436},"action":"A","side":"A","price":"1.156770000","size":30,"channel_id":23,"order_id":"1775529547616005810","flags":128,"ts_in_delta":1196,"sequence":167886,"symbol":"FCEU SI 20260615 PS"}
{"ts_recv":"2026-04-07T02:39:21.748162965Z","hd":{"ts_event":"2026-04-07T02:39:21.748139799Z","rtype":160,"publisher_id":101,"instrument_id":436},"action":"C","side":"B","price":"1.156660000","size":30,"channel_id":23,"order_id":"10998901561559775881","flags":0,"ts_in_delta":951,"sequence":167948,"symbol":"FCEU SI 20260615 PS"}
{"ts_recv":"2026-04-07T02:39:21.748162965Z","hd":{"ts_event":"2026-04-07T02:39:21.748139799Z","rtype":160,"publisher_id":101,"instrument_id":436},"action":"A","side":"B","price":"1.156680000","size":30,"channel_id":23,"order_id":"10998901598602922096","flags":0,"ts_in_delta":951,"sequence":167948,"symbol":"FCEU SI 20260615 PS"}
{"ts_recv":"2026-04-07T02:39:21.748162965Z","hd":{"ts_event":"2026-04-07T02:39:21.748139799Z","rtype":160,"publisher_id":101,"instrument_id":436},"action":"C","side":"A","price":"1.156760000","size":30,"channel_id":23,"order_id":"1775529524705000073","flags":0,"ts_in_delta":951,"sequence":167948,"symbol":"FCEU SI 20260615 PS"}
{"ts_recv":"2026-04-07T02:39:21.748162965Z","hd":{"ts_event":"2026-04-07T02:39:21.748139799Z","rtype":160,"publisher_id":101,"instrument_id":436},"action":"A","side":"A","price":"1.156780000","size":30,"channel_id":23,"order_id":"1775529561748146288","flags":128,"ts_in_delta":951,"sequence":167948,"symbol":"FCEU SI 20260615 PS"}
{"ts_recv":"2026-04-07T02:39:21.748261963Z","hd":{"ts_event":"2026-04-07T02:39:21.748240727Z","rtype":160,"publisher_id":101,"instrument_id":436},"action":"C","side":"B","price":"1.156670000","size":30,"channel_id":23,"order_id":"10998901584470781618","flags":0,"ts_in_delta":728,"sequence":167949,"symbol":"FCEU SI 20260615 PS"}
{"ts_recv":"2026-04-07T02:39:21.748261963Z","hd":{"ts_event":"2026-04-07T02:39:21.748240727Z","rtype":160,"publisher_id":101,"instrument_id":436},"action":"A","side":"B","price":"1.156680000","size":30,"channel_id":23,"order_id":"10998901598603023136","flags":0,"ts_in_delta":728,"sequence":167949,"symbol":"FCEU SI 20260615 PS"}
{"ts_recv":"2026-04-07T02:39:21.748261963Z","hd":{"ts_event":"2026-04-07T02:39:21.748240727Z","rtype":160,"publisher_id":101,"instrument_id":436},"action":"C","side":"A","price":"1.156770000","size":30,"channel_id":23,"order_id":"1775529547616005810","flags":0,"ts_in_delta":728,"sequence":167949,"symbol":"FCEU SI 20260615 PS"}
{"ts_recv":"2026-04-07T02:39:21.748261963Z","hd":{"ts_event":"2026-04-07T02:39:21.748240727Z","rtype":160,"publisher_id":101,"instrument_id":436},"action":"A","side":"A","price":"1.156780000","size":30,"channel_id":23,"order_id":"1775529561748247328","flags":128,"ts_in_delta":728,"sequence":167949,"symbol":"FCEU SI 20260615 PS"}
{"ts_recv":"2026-04-07T02:40:24.212570921Z","hd":{"ts_event":"2026-04-07T02:40:24.212544593Z","rtype":160,"publisher_id":101,"instrument_id":436},"action":"C","side":"B","price":"1.156680000","size":30,"channel_id":23,"order_id":"10998901598603023136","flags":0,"ts_in_delta":901,"sequence":168277,"symbol":"FCEU SI 20260615 PS"}
{"ts_recv":"2026-04-07T02:40:24.212570921Z","hd":{"ts_event":"2026-04-07T02:40:24.212544593Z","rtype":160,"publisher_id":101,"instrument_id":436},"action":"A","side":"B","price":"1.156690000","size":30,"channel_id":23,"order_id":"10998901661067326400","flags":0,"ts_in_delta":901,"sequence":168277,"symbol":"FCEU SI 20260615 PS"}
{"ts_recv":"2026-04-07T02:40:24.212570921Z","hd":{"ts_event":"2026-04-07T02:40:24.212544593Z","rtype":160,"publisher_id":101,"instrument_id":436},"action":"C","side":"A","price":"1.156780000","size":30,"channel_id":23,"order_id":"1775529561748247328","flags":0,"ts_in_delta":901,"sequence":168277,"symbol":"FCEU SI 20260615 PS"}
{"ts_recv":"2026-04-07T02:40:24.212570921Z","hd":{"ts_event":"2026-04-07T02:40:24.212544593Z","rtype":160,"publisher_id":101,"instrument_id":436},"action":"A","side":"A","price":"1.156790000","size":30,"channel_id":23,"order_id":"1775529624212550592","flags":128,"ts_in_delta":901,"sequence":168277,"symbol":"FCEU SI 20260615 PS"}
{"ts_recv":"2026-04-07T02:40:24.212626199Z","hd":{"ts_event":"2026-04-07T02:40:24.212606727Z","rtype":160,"publisher_id":101,"instrument_id":436},"action":"C","side":"B","price":"1.156680000","size":30,"channel_id":23,"order_id":"10998901598602922096","flags":0,"ts_in_delta":888,"sequence":168278,"symbol":"FCEU SI 20260615 PS"}
{"ts_recv":"2026-04-07T02:40:24.212626199Z","hd":{"ts_event":"2026-04-07T02:40:24.212606727Z","rtype":160,"publisher_id":101,"instrument_id":436},"action":"A","side":"B","price":"1.156700000","size":30,"channel_id":23,"order_id":"10998901661067388688","flags":0,"ts_in_delta":888,"sequence":168278,"symbol":"FCEU SI 20260615 PS"}
{"ts_recv":"2026-04-07T02:40:24.212626199Z","hd":{"ts_event":"2026-04-07T02:40:24.212606727Z","rtype":160,"publisher_id":101,"instrument_id":436},"action":"C","side":"A","price":"1.156780000","size":30,"channel_id":23,"order_id":"1775529561748146288","flags":0,"ts_in_delta":888,"sequence":168278,"symbol":"FCEU SI 20260615 PS"}
{"ts_recv":"2026-04-07T02:40:24.212626199Z","hd":{"ts_event":"2026-04-07T02:40:24.212606727Z","rtype":160,"publisher_id":101,"instrument_id":436},"action":"A","side":"A","price":"1.156800000","size":30,"channel_id":23,"order_id":"1775529624212612880","flags":128,"ts_in_delta":888,"sequence":168278,"symbol":"FCEU SI 20260615 PS"}
{"ts_recv":"2026-04-07T02:40:24.212685209Z","hd":{"ts_event":"2026-04-07T02:40:24.212663801Z","rtype":160,"publisher_id":101,"instrument_id":436},"action":"C","side":"B","price":"1.156690000","size":30,"channel_id":23,"order_id":"10998901661067326400","flags":0,"ts_in_delta":884,"sequence":168279,"symbol":"FCEU SI 20260615 PS"}
{"ts_recv":"2026-04-07T02:40:24.212685209Z","hd":{"ts_event":"2026-04-07T02:40:24.212663801Z","rtype":160,"publisher_id":101,"instrument_id":436},"action":"A","side":"B","price":"1.156700000","size":30,"channel_id":23,"order_id":"10998901661067446102","flags":0,"ts_in_delta":884,"sequence":168279,"symbol":"FCEU SI 20260615 PS"}
{"ts_recv":"2026-04-07T02:40:24.212685209Z","hd":{"ts_event":"2026-04-07T02:40:24.212663801Z","rtype":160,"publisher_id":101,"instrument_id":436},"action":"C","side":"A","price":"1.156790000","size":30,"channel_id":23,"order_id":"1775529624212550592","flags":0,"ts_in_delta":884,"sequence":168279,"symbol":"FCEU SI 20260615 PS"}
{"ts_recv":"2026-04-07T02:40:24.212685209Z","hd":{"ts_event":"2026-04-07T02:40:24.212663801Z","rtype":160,"publisher_id":101,"instrument_id":436},"action":"A","side":"A","price":"1.156800000","size":30,"channel_id":23,"order_id":"1775529624212670294","flags":128,"ts_in_delta":884,"sequence":168279,"symbol":"FCEU SI 20260615 PS"}
{"ts_recv":"2026-04-07T02:40:24.217469253Z","hd":{"ts_event":"2026-04-07T02:40:24.217447733Z","rtype":160,"publisher_id":101,"instrument_id":436},"action":"C","side":"B","price":"1.156700000","size":30,"channel_id":23,"order_id":"10998901661067446102","flags":0,"ts_in_delta":898,"sequence":168284,"symbol":"FCEU SI 20260615 PS"}
{"ts_recv":"2026-04-07T02:40:24.217469253Z","hd":{"ts_event":"2026-04-07T02:40:24.217447733Z","rtype":160,"publisher_id":101,"instrument_id":436},"action":"A","side":"B","price":"1.156710000","size":30,"channel_id":23,"order_id":"10998901661072229647","flags":0,"ts_in_delta":898,"sequence":168284,"symbol":"FCEU SI 20260615 PS"}
{"ts_recv":"2026-04-07T02:40:24.217469253Z","hd":{"ts_event":"2026-04-07T02:40:24.217447733Z","rtype":160,"publisher_id":101,"instrument_id":436},"action":"C","side":"A","price":"1.156800000","size":30,"channel_id":23,"order_id":"1775529624212670294","flags":0,"ts_in_delta":898,"sequence":168284,"symbol":"FCEU SI 20260615 PS"}
{"ts_recv":"2026-04-07T02:40:24.217469253Z","hd":{"ts_event":"2026-04-07T02:40:24.217447733Z","rtype":160,"publisher_id":101,"instrument_id":436},"action":"A","side":"A","price":"1.156810000","size":30,"channel_id":23,"order_id":"1775529624217453839","flags":128,"ts_in_delta":898,"sequence":168284,"symbol":"FCEU SI 20260615 PS"}
{"ts_recv":"2026-04-07T02:40:24.217556886Z","hd":{"ts_event":"2026-04-07T02:40:24.217535729Z","rtype":160,"publisher_id":101,"instrument_id":436},"action":"C","side":"B","price":"1.156710000","size":30,"channel_id":23,"order_id":"10998901661072229647","flags":0,"ts_in_delta":909,"sequence":168285,"symbol":"FCEU SI 20260615 PS"}
{"ts_recv":"2026-04-07T02:40:24.217556886Z","hd":{"ts_event":"2026-04-07T02:40:24.217535729Z","rtype":160,"publisher_id":101,"instrument_id":436},"action":"A","side":"B","price":"1.156720000","size":30,"channel_id":23,"order_id":"10998901661072317354","flags":0,"ts_in_delta":909,"sequence":168285,"symbol":"FCEU SI 20260615 PS"}
{"ts_recv":"2026-04-07T02:40:24.217556886Z","hd":{"ts_event":"2026-04-07T02:40:24.217535729Z","rtype":160,"publisher_id":101,"instrument_id":436},"action":"C","side":"A","price":"1.156810000","size":30,"channel_id":23,"order_id":"1775529624217453839","flags":0,"ts_in_delta":909,"sequence":168285,"symbol":"FCEU SI 20260615 PS"}
{"ts_recv":"2026-04-07T02:40:24.217556886Z","hd":{"ts_event":"2026-04-07T02:40:24.217535729Z","rtype":160,"publisher_id":101,"instrument_id":436},"action":"A","side":"A","price":"1.156820000","size":30,"channel_id":23,"order_id":"1775529624217541546","flags":128,"ts_in_delta":909,"sequence":168285,"symbol":"FCEU SI 20260615 PS"}
{"ts_recv":"2026-04-07T02:40:24.217603578Z","hd":{"ts_event":"2026-04-07T02:40:24.217586417Z","rtype":160,"publisher_id":101,"instrument_id":436},"action":"C","side":"B","price":"1.156700000","size":30,"channel_id":23,"order_id":"10998901661067388688","flags":0,"ts_in_delta":905,"sequence":168286,"symbol":"FCEU SI 20260615 PS"}
{"ts_recv":"2026-04-07T02:40:24.217603578Z","hd":{"ts_event":"2026-04-07T02:40:24.217586417Z","rtype":160,"publisher_id":101,"instrument_id":436},"action":"A","side":"B","price":"1.156720000","size":30,"channel_id":23,"order_id":"10998901661072368246","flags":0,"ts_in_delta":905,"sequence":168286,"symbol":"FCEU SI 20260615 PS"}
{"ts_recv":"2026-04-07T02:40:24.217603578Z","hd":{"ts_event":"2026-04-07T02:40:24.217586417Z","rtype":160,"publisher_id":101,"instrument_id":436},"action":"C","side":"A","price":"1.156800000","size":30,"channel_id":23,"order_id":"1775529624212612880","flags":0,"ts_in_delta":905,"sequence":168286,"symbol":"FCEU SI 20260615 PS"}
{"ts_recv":"2026-04-07T02:40:24.217603578Z","hd":{"ts_event":"2026-04-07T02:40:24.217586417Z","rtype":160,"publisher_id":101,"instrument_id":436},"action":"A","side":"A","price":"1.156820000","size":30,"channel_id":23,"order_id":"1775529624217592438","flags":128,"ts_in_delta":905,"sequence":168286,"symbol":"FCEU SI 20260615 PS"}
{"ts_recv":"2026-04-07T02:40:24.217616365Z","hd":{"ts_event":"2026-04-07T02:40:24.217596671Z","rtype":160,"publisher_id":101,"instrument_id":436},"action":"C","side":"B","price":"1.156720000","size":30,"channel_id":23,"order_id":"10998901661072317354","flags":0,"ts_in_delta":958,"sequence":168287,"symbol":"FCEU SI 20260615 PS"}
{"ts_recv":"2026-04-07T02:40:24.217616365Z","hd":{"ts_event":"2026-04-07T02:40:24.217596671Z","rtype":160,"publisher_id":101,"instrument_id":436},"action":"A","side":"B","price":"1.156710000","size":30,"channel_id":23,"order_id":"10998901661072378481","flags":0,"ts_in_delta":958,"sequence":168287,"symbol":"FCEU SI 20260615 PS"}
{"ts_recv":"2026-04-07T02:40:24.217616365Z","hd":{"ts_event":"2026-04-07T02:40:24.217596671Z","rtype":160,"publisher_id":101,"instrument_id":436},"action":"C","side":"A","price":"1.156820000","size":30,"channel_id":23,"order_id":"1775529624217541546","flags":0,"ts_in_delta":958,"sequence":168287,"symbol":"FCEU SI 20260615 PS"}
{"ts_recv":"2026-04-07T02:40:24.217616365Z","hd":{"ts_event":"2026-04-07T02:40:24.217596671Z","rtype":160,"publisher_id":101,"instrument_id":436},"action":"A","side":"A","price":"1.156810000","size":30,"channel_id":23,"order_id":"1775529624217602673","flags":128,"ts_in_delta":958,"sequence":168287,"symbol":"FCEU SI 20260615 PS"}
{"ts_recv":"2026-04-07T02:40:24.217671236Z","hd":{"ts_event":"2026-04-07T02:40:24.217653751Z","rtype":160,"publisher_id":101,"instrument_id":436},"action":"C","side":"B","price":"1.156710000","size":30,"channel_id":23,"order_id":"10998901661072378481","flags":0,"ts_in_delta":899,"sequence":168288,"symbol":"FCEU SI 20260615 PS"}
{"ts_recv":"2026-04-07T02:40:24.217671236Z","hd":{"ts_event":"2026-04-07T02:40:24.217653751Z","rtype":160,"publisher_id":101,"instrument_id":436},"action":"A","side":"B","price":"1.156720000","size":30,"channel_id":23,"order_id":"10998901661072435775","flags":0,"ts_in_delta":899,"sequence":168288,"symbol":"FCEU SI 20260615 PS"}
{"ts_recv":"2026-04-07T02:40:24.217671236Z","hd":{"ts_event":"2026-04-07T02:40:24.217653751Z","rtype":160,"publisher_id":101,"instrument_id":436},"action":"C","side":"A","price":"1.156810000","size":30,"channel_id":23,"order_id":"1775529624217602673","flags":0,"ts_in_delta":899,"sequence":168288,"symbol":"FCEU SI 20260615 PS"}
{"ts_recv":"2026-04-07T02:40:24.217671236Z","hd":{"ts_event":"2026-04-07T02:40:24.217653751Z","rtype":160,"publisher_id":101,"instrument_id":436},"action":"A","side":"A","price":"1.156820000","size":30,"channel_id":23,"order_id":"1775529624217659967","flags":128,"ts_in_delta":899,"sequence":168288,"symbol":"FCEU SI 20260615 PS"}
{"ts_recv":"2026-04-07T02:40:24.238190955Z","hd":{"ts_event":"2026-04-07T02:40:24.238172321Z","rtype":160,"publisher_id":101,"instrument_id":436},"action":"C","side":"B","price":"1.156720000","size":30,"channel_id":23,"order_id":"10998901661072435775","flags":0,"ts_in_delta":969,"sequence":168295,"symbol":"FCEU SI 20260615 PS"}
{"ts_recv":"2026-04-07T02:40:24.238190955Z","hd":{"ts_event":"2026-04-07T02:40:24.238172321Z","rtype":160,"publisher_id":101,"instrument_id":436},"action":"A","side":"B","price":"1.156710000","size":30,"channel_id":23,"order_id":"10998901661092954139","flags":0,"ts_in_delta":969,"sequence":168295,"symbol":"FCEU SI 20260615 PS"}
{"ts_recv":"2026-04-07T02:40:24.238190955Z","hd":{"ts_event":"2026-04-07T02:40:24.238172321Z","rtype":160,"publisher_id":101,"instrument_id":436},"action":"C","side":"A","price":"1.156820000","size":30,"channel_id":23,"order_id":"1775529624217659967","flags":0,"ts_in_delta":969,"sequence":168295,"symbol":"FCEU SI 20260615 PS"}
{"ts_recv":"2026-04-07T02:40:24.238190955Z","hd":{"ts_event":"2026-04-07T02:40:24.238172321Z","rtype":160,"publisher_id":101,"instrument_id":436},"action":"A","side":"A","price":"1.156810000","size":30,"channel_id":23,"order_id":"1775529624238178331","flags":128,"ts_in_delta":969,"sequence":168295,"symbol":"FCEU SI 20260615 PS"}
{"ts_recv":"2026-04-07T02:40:24.238251178Z","hd":{"ts_event":"2026-04-07T02:40:24.238233277Z","rtype":160,"publisher_id":101,"instrument_id":436},"action":"C","side":"B","price":"1.156710000","size":30,"channel_id":23,"order_id":"10998901661092954139","flags":0,"ts_in_delta":902,"sequence":168296,"symbol":"FCEU SI 20260615 PS"}
{"ts_recv":"2026-04-07T02:40:24.238251178Z","hd":{"ts_event":"2026-04-07T02:40:24.238233277Z","rtype":160,"publisher_id":101,"instrument_id":436},"action":"A","side":"B","price":"1.156700000","size":30,"channel_id":23,"order_id":"10998901661093015808","flags":0,"ts_in_delta":902,"sequence":168296,"symbol":"FCEU SI 20260615 PS"}
{"ts_recv":"2026-04-07T02:40:24.238251178Z","hd":{"ts_event":"2026-04-07T02:40:24.238233277Z","rtype":160,"publisher_id":101,"instrument_id":436},"action":"C","side":"A","price":"1.156810000","size":30,"channel_id":23,"order_id":"1775529624238178331","flags":0,"ts_in_delta":902,"sequence":168296,"symbol":"FCEU SI 20260615 PS"}
{"ts_recv":"2026-04-07T02:40:24.238251178Z","hd":{"ts_event":"2026-04-07T02:40:24.238233277Z","rtype":160,"publisher_id":101,"instrument_id":436},"action":"A","side":"A","price":"1.156800000","size":30,"channel_id":23,"order_id":"1775529624238240000","flags":128,"ts_in_delta":902,"sequence":168296,"symbol":"FCEU SI 20260615 PS"}
{"ts_recv":"2026-04-07T02:40:24.238303669Z","hd":{"ts_event":"2026-04-07T02:40:24.238286819Z","rtype":160,"publisher_id":101,"instrument_id":436},"action":"C","side":"B","price":"1.156700000","size":30,"channel_id":23,"order_id":"10998901661093015808","flags":0,"ts_in_delta":904,"sequence":168297,"symbol":"FCEU SI 20260615 PS"}
{"ts_recv":"2026-04-07T02:40:24.238303669Z","hd":{"ts_event":"2026-04-07T02:40:24.238286819Z","rtype":160,"publisher_id":101,"instrument_id":436},"action":"A","side":"B","price":"1.156710000","size":30,"channel_id":23,"order_id":"10998901661093068720","flags":0,"ts_in_delta":904,"sequence":168297,"symbol":"FCEU SI 20260615 PS"}
{"ts_recv":"2026-04-07T02:40:24.238303669Z","hd":{"ts_event":"2026-04-07T02:40:24.238286819Z","rtype":160,"publisher_id":101,"instrument_id":436},"action":"C","side":"A","price":"1.156800000","size":30,"channel_id":23,"order_id":"1775529624238240000","flags":0,"ts_in_delta":904,"sequence":168297,"symbol":"FCEU SI 20260615 PS"}
{"ts_recv":"2026-04-07T02:40:24.238303669Z","hd":{"ts_event":"2026-04-07T02:40:24.238286819Z","rtype":160,"publisher_id":101,"instrument_id":436},"action":"A","side":"A","price":"1.156810000","size":30,"channel_id":23,"order_id":"1775529624238292912","flags":128,"ts_in_delta":904,"sequence":168297,"symbol":"FCEU SI 20260615 PS"}
{"ts_recv":"2026-04-07T02:40:24.252936362Z","hd":{"ts_event":"2026-04-07T02:40:24.252917193Z","rtype":160,"publisher_id":101,"instrument_id":436},"action":"C","side":"B","price":"1.156720000","size":30,"channel_id":23,"order_id":"10998901661072368246","flags":0,"ts_in_delta":864,"sequence":168301,"symbol":"FCEU SI 20260615 PS"}
{"ts_recv":"2026-04-07T02:40:24.252936362Z","hd":{"ts_event":"2026-04-07T02:40:24.252917193Z","rtype":160,"publisher_id":101,"instrument_id":436},"action":"A","side":"B","price":"1.156700000","size":30,"channel_id":23,"order_id":"10998901661107699144","flags":0,"ts_in_delta":864,"sequence":168301,"symbol":"FCEU SI 20260615 PS"}
{"ts_recv":"2026-04-07T02:40:24.252936362Z","hd":{"ts_event":"2026-04-07T02:40:24.252917193Z","rtype":160,"publisher_id":101,"instrument_id":436},"action":"C","side":"A","price":"1.156820000","size":30,"channel_id":23,"order_id":"1775529624217592438","flags":0,"ts_in_delta":864,"sequence":168301,"symbol":"FCEU SI 20260615 PS"}
{"ts_recv":"2026-04-07T02:40:24.252936362Z","hd":{"ts_event":"2026-04-07T02:40:24.252917193Z","rtype":160,"publisher_id":101,"instrument_id":436},"action":"A","side":"A","price":"1.156800000","size":30,"channel_id":23,"order_id":"1775529624252923336","flags":128,"ts_in_delta":864,"sequence":168301,"symbol":"FCEU SI 20260615 PS"}
{"ts_recv":"2026-04-07T02:40:24.252993691Z","hd":{"ts_event":"2026-04-07T02:40:24.252978363Z","rtype":160,"publisher_id":101,"instrument_id":436},"action":"C","side":"B","price":"1.156710000","size":30,"channel_id":23,"order_id":"10998901661093068720","flags":0,"ts_in_delta":897,"sequence":168302,"symbol":"FCEU SI 20260615 PS"}
{"ts_recv":"2026-04-07T02:40:24.252993691Z","hd":{"ts_event":"2026-04-07T02:40:24.252978363Z","rtype":160,"publisher_id":101,"instrument_id":436},"action":"A","side":"B","price":"1.156700000","size":30,"channel_id":23,"order_id":"10998901661107759913","flags":0,"ts_in_delta":897,"sequence":168302,"symbol":"FCEU SI 20260615 PS"}
{"ts_recv":"2026-04-07T02:40:24.252993691Z","hd":{"ts_event":"2026-04-07T02:40:24.252978363Z","rtype":160,"publisher_id":101,"instrument_id":436},"action":"C","side":"A","price":"1.156810000","size":30,"channel_id":23,"order_id":"1775529624238292912","flags":0,"ts_in_delta":897,"sequence":168302,"symbol":"FCEU SI 20260615 PS"}
{"ts_recv":"2026-04-07T02:40:24.252993691Z","hd":{"ts_event":"2026-04-07T02:40:24.252978363Z","rtype":160,"publisher_id":101,"instrument_id":436},"action":"A","side":"A","price":"1.156800000","size":30,"channel_id":23,"order_id":"1775529624252984105","flags":128,"ts_in_delta":897,"sequence":168302,"symbol":"FCEU SI 20260615 PS"}
{"ts_recv":"2026-04-07T02:40:50.047675459Z","hd":{"ts_event":"2026-04-07T02:40:50.047639809Z","rtype":160,"publisher_id":101,"instrument_id":436},"action":"C","side":"B","price":"1.156700000","size":30,"channel_id":23,"order_id":"10998901661107759913","flags":0,"ts_in_delta":1752,"sequence":168432,"symbol":"FCEU SI 20260615 PS"}
{"ts_recv":"2026-04-07T02:40:50.047675459Z","hd":{"ts_event":"2026-04-07T02:40:50.047639809Z","rtype":160,"publisher_id":101,"instrument_id":436},"action":"A","side":"B","price":"1.156690000","size":30,"channel_id":23,"order_id":"10998901686902429098","flags":0,"ts_in_delta":1752,"sequence":168432,"symbol":"FCEU SI 20260615 PS"}
{"ts_recv":"2026-04-07T02:40:50.047675459Z","hd":{"ts_event":"2026-04-07T02:40:50.047639809Z","rtype":160,"publisher_id":101,"instrument_id":436},"action":"C","side":"A","price":"1.156800000","size":30,"channel_id":23,"order_id":"1775529624252984105","flags":0,"ts_in_delta":1752,"sequence":168432,"symbol":"FCEU SI 20260615 PS"}
{"ts_recv":"2026-04-07T02:40:50.047675459Z","hd":{"ts_event":"2026-04-07T02:40:50.047639809Z","rtype":160,"publisher_id":101,"instrument_id":436},"action":"A","side":"A","price":"1.156790000","size":30,"channel_id":23,"order_id":"1775529650047653290","flags":128,"ts_in_delta":1752,"sequence":168432,"symbol":"FCEU SI 20260615 PS"}
{"ts_recv":"2026-04-07T02:40:50.047753124Z","hd":{"ts_event":"2026-04-07T02:40:50.047733513Z","rtype":160,"publisher_id":101,"instrument_id":436},"action":"C","side":"B","price":"1.156700000","size":30,"channel_id":23,"order_id":"10998901661107699144","flags":0,"ts_in_delta":975,"sequence":168433,"symbol":"FCEU SI 20260615 PS"}
{"ts_recv":"2026-04-07T02:40:50.047753124Z","hd":{"ts_event":"2026-04-07T02:40:50.047733513Z","rtype":160,"publisher_id":101,"instrument_id":436},"action":"A","side":"B","price":"1.156680000","size":30,"channel_id":23,"order_id":"10998901686902515798","flags":0,"ts_in_delta":975,"sequence":168433,"symbol":"FCEU SI 20260615 PS"}
{"ts_recv":"2026-04-07T02:40:50.047753124Z","hd":{"ts_event":"2026-04-07T02:40:50.047733513Z","rtype":160,"publisher_id":101,"instrument_id":436},"action":"C","side":"A","price":"1.156800000","size":30,"channel_id":23,"order_id":"1775529624252923336","flags":0,"ts_in_delta":975,"sequence":168433,"symbol":"FCEU SI 20260615 PS"}
{"ts_recv":"2026-04-07T02:40:50.047753124Z","hd":{"ts_event":"2026-04-07T02:40:50.047733513Z","rtype":160,"publisher_id":101,"instrument_id":436},"action":"A","side":"A","price":"1.156780000","size":30,"channel_id":23,"order_id":"1775529650047739990","flags":128,"ts_in_delta":975,"sequence":168433,"symbol":"FCEU SI 20260615 PS"}
{"ts_recv":"2026-04-07T02:40:50.047820843Z","hd":{"ts_event":"2026-04-07T02:40:50.047800707Z","rtype":160,"publisher_id":101,"instrument_id":436},"action":"C","side":"B","price":"1.156690000","size":30,"channel_id":23,"order_id":"10998901686902429098","flags":0,"ts_in_delta":722,"sequence":168434,"symbol":"FCEU SI 20260615 PS"}
{"ts_recv":"2026-04-07T02:40:50.047820843Z","hd":{"ts_event":"2026-04-07T02:40:50.047800707Z","rtype":160,"publisher_id":101,"instrument_id":436},"action":"A","side":"B","price":"1.156680000","size":30,"channel_id":23,"order_id":"10998901686902582910","flags":0,"ts_in_delta":722,"sequence":168434,"symbol":"FCEU SI 20260615 PS"}
{"ts_recv":"2026-04-07T02:40:50.047820843Z","hd":{"ts_event":"2026-04-07T02:40:50.047800707Z","rtype":160,"publisher_id":101,"instrument_id":436},"action":"C","side":"A","price":"1.156790000","size":30,"channel_id":23,"order_id":"1775529650047653290","flags":0,"ts_in_delta":722,"sequence":168434,"symbol":"FCEU SI 20260615 PS"}
{"ts_recv":"2026-04-07T02:40:50.047820843Z","hd":{"ts_event":"2026-04-07T02:40:50.047800707Z","rtype":160,"publisher_id":101,"instrument_id":436},"action":"A","side":"A","price":"1.156780000","size":30,"channel_id":23,"order_id":"1775529650047807102","flags":128,"ts_in_delta":722,"sequence":168434,"symbol":"FCEU SI 20260615 PS"}
{"ts_recv":"2026-04-07T02:41:29.716738168Z","hd":{"ts_event":"2026-04-07T02:41:29.716713457Z","rtype":160,"publisher_id":101,"instrument_id":436},"action":"C","side":"B","price":"1.156680000","size":30,"channel_id":23,"order_id":"10998901686902515798","flags":0,"ts_in_delta":979,"sequence":168656,"symbol":"FCEU SI 20260615 PS"}
{"ts_recv":"2026-04-07T02:41:29.716738168Z","hd":{"ts_event":"2026-04-07T02:41:29.716713457Z","rtype":160,"publisher_id":101,"instrument_id":436},"action":"A","side":"B","price":"1.156700000","size":30,"channel_id":23,"order_id":"10998901726571495538","flags":0,"ts_in_delta":979,"sequence":168656,"symbol":"FCEU SI 20260615 PS"}
{"ts_recv":"2026-04-07T02:41:29.716738168Z","hd":{"ts_event":"2026-04-07T02:41:29.716713457Z","rtype":160,"publisher_id":101,"instrument_id":436},"action":"C","side":"A","price":"1.156780000","size":30,"channel_id":23,"order_id":"1775529650047739990","flags":0,"ts_in_delta":979,"sequence":168656,"symbol":"FCEU SI 20260615 PS"}
{"ts_recv":"2026-04-07T02:41:29.716738168Z","hd":{"ts_event":"2026-04-07T02:41:29.716713457Z","rtype":160,"publisher_id":101,"instrument_id":436},"action":"A","side":"A","price":"1.156800000","size":30,"channel_id":23,"order_id":"1775529689716719730","flags":128,"ts_in_delta":979,"sequence":168656,"symbol":"FCEU SI 20260615 PS"}
{"ts_recv":"2026-04-07T02:41:29.716805788Z","hd":{"ts_event":"2026-04-07T02:41:29.716786149Z","rtype":160,"publisher_id":101,"instrument_id":436},"action":"C","side":"B","price":"1.156680000","size":30,"channel_id":23,"order_id":"10998901686902582910","flags":0,"ts_in_delta":916,"sequence":168657,"symbol":"FCEU SI 20260615 PS"}
{"ts_recv":"2026-04-07T02:41:29.716805788Z","hd":{"ts_event":"2026-04-07T02:41:29.716786149Z","rtype":160,"publisher_id":101,"instrument_id":436},"action":"A","side":"B","price":"1.156690000","size":30,"channel_id":23,"order_id":"10998901726571567621","flags":0,"ts_in_delta":916,"sequence":168657,"symbol":"FCEU SI 20260615 PS"}
{"ts_recv":"2026-04-07T02:41:29.716805788Z","hd":{"ts_event":"2026-04-07T02:41:29.716786149Z","rtype":160,"publisher_id":101,"instrument_id":436},"action":"C","side":"A","price":"1.156780000","size":30,"channel_id":23,"order_id":"1775529650047807102","flags":0,"ts_in_delta":916,"sequence":168657,"symbol":"FCEU SI 20260615 PS"}
{"ts_recv":"2026-04-07T02:41:29.716805788Z","hd":{"ts_event":"2026-04-07T02:41:29.716786149Z","rtype":160,"publisher_id":101,"instrument_id":436},"action":"A","side":"A","price":"1.156790000","size":30,"channel_id":23,"order_id":"1775529689716791813","flags":128,"ts_in_delta":916,"sequence":168657,"symbol":"FCEU SI 20260615 PS"}
{"ts_recv":"2026-04-07T02:41:29.725875720Z","hd":{"ts_event":"2026-04-07T02:41:29.725856929Z","rtype":160,"publisher_id":101,"instrument_id":436},"action":"C","side":"B","price":"1.156690000","size":30,"channel_id":23,"order_id":"10998901726571567621","flags":0,"ts_in_delta":961,"sequence":168678,"symbol":"FCEU SI 20260615 PS"}
{"ts_recv":"2026-04-07T02:41:29.725875720Z","hd":{"ts_event":"2026-04-07T02:41:29.725856929Z","rtype":160,"publisher_id":101,"instrument_id":436},"action":"A","side":"B","price":"1.156700000","size":30,"channel_id":23,"order_id":"10998901726580638357","flags":0,"ts_in_delta":961,"sequence":168678,"symbol":"FCEU SI 20260615 PS"}
{"ts_recv":"2026-04-07T02:41:29.725875720Z","hd":{"ts_event":"2026-04-07T02:41:29.725856929Z","rtype":160,"publisher_id":101,"instrument_id":436},"action":"C","side":"A","price":"1.156790000","size":30,"channel_id":23,"order_id":"1775529689716791813","flags":0,"ts_in_delta":961,"sequence":168678,"symbol":"FCEU SI 20260615 PS"}
{"ts_recv":"2026-04-07T02:41:29.725875720Z","hd":{"ts_event":"2026-04-07T02:41:29.725856929Z","rtype":160,"publisher_id":101,"instrument_id":436},"action":"A","side":"A","price":"1.156800000","size":30,"channel_id":23,"order_id":"1775529689725862549","flags":128,"ts_in_delta":961,"sequence":168678,"symbol":"FCEU SI 20260615 PS"}
{"ts_recv":"2026-04-07T02:41:29.768294576Z","hd":{"ts_event":"2026-04-07T02:41:29.768279053Z","rtype":160,"publisher_id":101,"instrument_id":436},"action":"A","side":"B","price":"1.156600000","size":20,"channel_id":23,"order_id":"10998901726623061222","flags":128,"ts_in_delta":713,"sequence":168709,"symbol":"FCEU SI 20260615 PS"}
{"ts_recv":"2026-04-07T02:41:29.768410577Z","hd":{"ts_event":"2026-04-07T02:41:29.768398381Z","rtype":160,"publisher_id":101,"instrument_id":436},"action":"C","side":"B","price":"1.156500000","size":20,"channel_id":23,"order_id":"10998901332007225116","flags":128,"ts_in_delta":672,"sequence":168710,"symbol":"FCEU SI 20260615 PS"}
{"ts_recv":"2026-04-07T02:41:55.301615887Z","hd":{"ts_event":"2026-04-07T02:41:55.301589991Z","rtype":160,"publisher_id":101,"instrument_id":436},"action":"C","side":"B","price":"1.156700000","size":30,"channel_id":23,"order_id":"10998901726580638357","flags":0,"ts_in_delta":1000,"sequence":168866,"symbol":"FCEU SI 20260615 PS"}
{"ts_recv":"2026-04-07T02:41:55.301615887Z","hd":{"ts_event":"2026-04-07T02:41:55.301589991Z","rtype":160,"publisher_id":101,"instrument_id":436},"action":"A","side":"B","price":"1.156690000","size":30,"channel_id":23,"order_id":"10998901752156372090","flags":0,"ts_in_delta":1000,"sequence":168866,"symbol":"FCEU SI 20260615 PS"}
{"ts_recv":"2026-04-07T02:41:55.301615887Z","hd":{"ts_event":"2026-04-07T02:41:55.301589991Z","rtype":160,"publisher_id":101,"instrument_id":436},"action":"C","side":"A","price":"1.156800000","size":30,"channel_id":23,"order_id":"1775529689725862549","flags":0,"ts_in_delta":1000,"sequence":168866,"symbol":"FCEU SI 20260615 PS"}
{"ts_recv":"2026-04-07T02:41:55.301615887Z","hd":{"ts_event":"2026-04-07T02:41:55.301589991Z","rtype":160,"publisher_id":101,"instrument_id":436},"action":"A","side":"A","price":"1.156790000","size":30,"channel_id":23,"order_id":"1775529715301596282","flags":128,"ts_in_delta":1000,"sequence":168866,"symbol":"FCEU SI 20260615 PS"}
{"ts_recv":"2026-04-07T02:41:55.301704365Z","hd":{"ts_event":"2026-04-07T02:41:55.301682331Z","rtype":160,"publisher_id":101,"instrument_id":436},"action":"C","side":"B","price":"1.156690000","size":30,"channel_id":23,"order_id":"10998901752156372090","flags":0,"ts_in_delta":971,"sequence":168867,"symbol":"FCEU SI 20260615 PS"}
{"ts_recv":"2026-04-07T02:41:55.301704365Z","hd":{"ts_event":"2026-04-07T02:41:55.301682331Z","rtype":160,"publisher_id":101,"instrument_id":436},"action":"A","side":"B","price":"1.156680000","size":30,"channel_id":23,"order_id":"10998901752156464162","flags":0,"ts_in_delta":971,"sequence":168867,"symbol":"FCEU SI 20260615 PS"}
{"ts_recv":"2026-04-07T02:41:55.301704365Z","hd":{"ts_event":"2026-04-07T02:41:55.301682331Z","rtype":160,"publisher_id":101,"instrument_id":436},"action":"C","side":"A","price":"1.156790000","size":30,"channel_id":23,"order_id":"1775529715301596282","flags":0,"ts_in_delta":971,"sequence":168867,"symbol":"FCEU SI 20260615 PS"}
{"ts_recv":"2026-04-07T02:41:55.301704365Z","hd":{"ts_event":"2026-04-07T02:41:55.301682331Z","rtype":160,"publisher_id":101,"instrument_id":436},"action":"A","side":"A","price":"1.156780000","size":30,"channel_id":23,"order_id":"1775529715301688354","flags":128,"ts_in_delta":971,"sequence":168867,"symbol":"FCEU SI 20260615 PS"}
{"ts_recv":"2026-04-07T02:41:55.301757800Z","hd":{"ts_event":"2026-04-07T02:41:55.301737225Z","rtype":160,"publisher_id":101,"instrument_id":436},"action":"C","side":"B","price":"1.156700000","size":30,"channel_id":23,"order_id":"10998901726571495538","flags":0,"ts_in_delta":986,"sequence":168868,"symbol":"FCEU SI 20260615 PS"}
{"ts_recv":"2026-04-07T02:41:55.301757800Z","hd":{"ts_event":"2026-04-07T02:41:55.301737225Z","rtype":160,"publisher_id":101,"instrument_id":436},"action":"A","side":"B","price":"1.156680000","size":30,"channel_id":23,"order_id":"10998901752156519017","flags":0,"ts_in_delta":986,"sequence":168868,"symbol":"FCEU SI 20260615 PS"}
{"ts_recv":"2026-04-07T02:41:55.301757800Z","hd":{"ts_event":"2026-04-07T02:41:55.301737225Z","rtype":160,"publisher_id":101,"instrument_id":436},"action":"C","side":"A","price":"1.156800000","size":30,"channel_id":23,"order_id":"1775529689716719730","flags":0,"ts_in_delta":986,"sequence":168868,"symbol":"FCEU SI 20260615 PS"}
{"ts_recv":"2026-04-07T02:41:55.301757800Z","hd":{"ts_event":"2026-04-07T02:41:55.301737225Z","rtype":160,"publisher_id":101,"instrument_id":436},"action":"A","side":"A","price":"1.156780000","size":30,"channel_id":23,"order_id":"1775529715301743209","flags":128,"ts_in_delta":986,"sequence":168868,"symbol":"FCEU SI 20260615 PS"}
{"ts_recv":"2026-04-07T02:41:55.301767668Z","hd":{"ts_event":"2026-04-07T02:41:55.301747497Z","rtype":160,"publisher_id":101,"instrument_id":436},"action":"C","side":"B","price":"1.156680000","size":30,"channel_id":23,"order_id":"10998901752156464162","flags":0,"ts_in_delta":1004,"sequence":168869,"symbol":"FCEU SI 20260615 PS"}
{"ts_recv":"2026-04-07T02:41:55.301767668Z","hd":{"ts_event":"2026-04-07T02:41:55.301747497Z","rtype":160,"publisher_id":101,"instrument_id":436},"action":"A","side":"B","price":"1.156690000","size":30,"channel_id":23,"order_id":"10998901752156530257","flags":0,"ts_in_delta":1004,"sequence":168869,"symbol":"FCEU SI 20260615 PS"}
{"ts_recv":"2026-04-07T02:41:55.301767668Z","hd":{"ts_event":"2026-04-07T02:41:55.301747497Z","rtype":160,"publisher_id":101,"instrument_id":436},"action":"C","side":"A","price":"1.156780000","size":30,"channel_id":23,"order_id":"1775529715301688354","flags":0,"ts_in_delta":1004,"sequence":168869,"symbol":"FCEU SI 20260615 PS"}
{"ts_recv":"2026-04-07T02:41:55.301767668Z","hd":{"ts_event":"2026-04-07T02:41:55.301747497Z","rtype":160,"publisher_id":101,"instrument_id":436},"action":"A","side":"A","price":"1.156790000","size":30,"channel_id":23,"order_id":"1775529715301754449","flags":128,"ts_in_delta":1004,"sequence":168869,"symbol":"FCEU SI 20260615 PS"}
{"ts_recv":"2026-04-07T02:41:55.301823653Z","hd":{"ts_event":"2026-04-07T02:41:55.301807689Z","rtype":160,"publisher_id":101,"instrument_id":436},"action":"C","side":"B","price":"1.156690000","size":30,"channel_id":23,"order_id":"10998901752156530257","flags":0,"ts_in_delta":977,"sequence":168870,"symbol":"FCEU SI 20260615 PS"}
{"ts_recv":"2026-04-07T02:41:55.301823653Z","hd":{"ts_event":"2026-04-07T02:41:55.301807689Z","rtype":160,"publisher_id":101,"instrument_id":436},"action":"A","side":"B","price":"1.156680000","size":30,"channel_id":23,"order_id":"10998901752156589776","flags":0,"ts_in_delta":977,"sequence":168870,"symbol":"FCEU SI 20260615 PS"}
{"ts_recv":"2026-04-07T02:41:55.301823653Z","hd":{"ts_event":"2026-04-07T02:41:55.301807689Z","rtype":160,"publisher_id":101,"instrument_id":436},"action":"C","side":"A","price":"1.156790000","size":30,"channel_id":23,"order_id":"1775529715301754449","flags":0,"ts_in_delta":977,"sequence":168870,"symbol":"FCEU SI 20260615 PS"}
{"ts_recv":"2026-04-07T02:41:55.301823653Z","hd":{"ts_event":"2026-04-07T02:41:55.301807689Z","rtype":160,"publisher_id":101,"instrument_id":436},"action":"A","side":"A","price":"1.156780000","size":30,"channel_id":23,"order_id":"1775529715301813968","flags":128,"ts_in_delta":977,"sequence":168870,"symbol":"FCEU SI 20260615 PS"}
{"ts_recv":"2026-04-07T02:42:15.048230107Z","hd":{"ts_event":"2026-04-07T02:42:15.048206457Z","rtype":160,"publisher_id":101,"instrument_id":436},"action":"C","side":"B","price":"1.156680000","size":30,"channel_id":23,"order_id":"10998901752156519017","flags":0,"ts_in_delta":927,"sequence":169088,"symbol":"FCEU SI 20260615 PS"}
{"ts_recv":"2026-04-07T02:42:15.048230107Z","hd":{"ts_event":"2026-04-07T02:42:15.048206457Z","rtype":160,"publisher_id":101,"instrument_id":436},"action":"A","side":"B","price":"1.156660000","size":30,"channel_id":23,"order_id":"10998901771902988537","flags":0,"ts_in_delta":927,"sequence":169088,"symbol":"FCEU SI 20260615 PS"}
{"ts_recv":"2026-04-07T02:42:15.048230107Z","hd":{"ts_event":"2026-04-07T02:42:15.048206457Z","rtype":160,"publisher_id":101,"instrument_id":436},"action":"C","side":"A","price":"1.156780000","size":30,"channel_id":23,"order_id":"1775529715301743209","flags":0,"ts_in_delta":927,"sequence":169088,"symbol":"FCEU SI 20260615 PS"}
{"ts_recv":"2026-04-07T02:42:15.048230107Z","hd":{"ts_event":"2026-04-07T02:42:15.048206457Z","rtype":160,"publisher_id":101,"instrument_id":436},"action":"A","side":"A","price":"1.156760000","size":30,"channel_id":23,"order_id":"1775529735048212729","flags":128,"ts_in_delta":927,"sequence":169088,"symbol":"FCEU SI 20260615 PS"}
{"ts_recv":"2026-04-07T02:42:15.048303702Z","hd":{"ts_event":"2026-04-07T02:42:15.048284327Z","rtype":160,"publisher_id":101,"instrument_id":436},"action":"C","side":"B","price":"1.156680000","size":30,"channel_id":23,"order_id":"10998901752156589776","flags":0,"ts_in_delta":921,"sequence":169089,"symbol":"FCEU SI 20260615 PS"}
{"ts_recv":"2026-04-07T02:42:15.048303702Z","hd":{"ts_event":"2026-04-07T02:42:15.048284327Z","rtype":160,"publisher_id":101,"instrument_id":436},"action":"A","side":"B","price":"1.156670000","size":30,"channel_id":23,"order_id":"10998901771903066333","flags":0,"ts_in_delta":921,"sequence":169089,"symbol":"FCEU SI 20260615 PS"}
{"ts_recv":"2026-04-07T02:42:15.048303702Z","hd":{"ts_event":"2026-04-07T02:42:15.048284327Z","rtype":160,"publisher_id":101,"instrument_id":436},"action":"C","side":"A","price":"1.156780000","size":30,"channel_id":23,"order_id":"1775529715301813968","flags":0,"ts_in_delta":921,"sequence":169089,"symbol":"FCEU SI 20260615 PS"}
{"ts_recv":"2026-04-07T02:42:15.048303702Z","hd":{"ts_event":"2026-04-07T02:42:15.048284327Z","rtype":160,"publisher_id":101,"instrument_id":436},"action":"A","side":"A","price":"1.156770000","size":30,"channel_id":23,"order_id":"1775529735048290525","flags":128,"ts_in_delta":921,"sequence":169089,"symbol":"FCEU SI 20260615 PS"}
{"ts_recv":"2026-04-07T02:42:15.048382019Z","hd":{"ts_event":"2026-04-07T02:42:15.048363411Z","rtype":160,"publisher_id":101,"instrument_id":436},"action":"C","side":"B","price":"1.156670000","size":30,"channel_id":23,"order_id":"10998901771903066333","flags":0,"ts_in_delta":1110,"sequence":169090,"symbol":"FCEU SI 20260615 PS"}
{"ts_recv":"2026-04-07T02:42:15.048382019Z","hd":{"ts_event":"2026-04-07T02:42:15.048363411Z","rtype":160,"publisher_id":101,"instrument_id":436},"action":"A","side":"B","price":"1.156660000","size":30,"channel_id":23,"order_id":"10998901771903144970","flags":0,"ts_in_delta":1110,"sequence":169090,"symbol":"FCEU SI 20260615 PS"}
{"ts_recv":"2026-04-07T02:42:15.048382019Z","hd":{"ts_event":"2026-04-07T02:42:15.048363411Z","rtype":160,"publisher_id":101,"instrument_id":436},"action":"C","side":"A","price":"1.156770000","size":30,"channel_id":23,"order_id":"1775529735048290525","flags":0,"ts_in_delta":1110,"sequence":169090,"symbol":"FCEU SI 20260615 PS"}
{"ts_recv":"2026-04-07T02:42:15.048382019Z","hd":{"ts_event":"2026-04-07T02:42:15.048363411Z","rtype":160,"publisher_id":101,"instrument_id":436},"action":"A","side":"A","price":"1.156760000","size":30,"channel_id":23,"order_id":"1775529735048369162","flags":128,"ts_in_delta":1110,"sequence":169090,"symbol":"FCEU SI 20260615 PS"}
{"ts_recv":"2026-04-07T02:42:15.052907989Z","hd":{"ts_event":"2026-04-07T02:42:15.052886101Z","rtype":160,"publisher_id":101,"instrument_id":436},"action":"C","side":"B","price":"1.156660000","size":30,"channel_id":23,"order_id":"10998901771903144970","flags":0,"ts_in_delta":1002,"sequence":169092,"symbol":"FCEU SI 20260615 PS"}
{"ts_recv":"2026-04-07T02:42:15.052907989Z","hd":{"ts_event":"2026-04-07T02:42:15.052886101Z","rtype":160,"publisher_id":101,"instrument_id":436},"action":"A","side":"B","price":"1.156650000","size":30,"channel_id":23,"order_id":"10998901771907667975","flags":0,"ts_in_delta":1002,"sequence":169092,"symbol":"FCEU SI 20260615 PS"}
{"ts_recv":"2026-04-07T02:42:15.052907989Z","hd":{"ts_event":"2026-04-07T02:42:15.052886101Z","rtype":160,"publisher_id":101,"instrument_id":436},"action":"C","side":"A","price":"1.156760000","size":30,"channel_id":23,"order_id":"1775529735048369162","flags":0,"ts_in_delta":1002,"sequence":169092,"symbol":"FCEU SI 20260615 PS"}
{"ts_recv":"2026-04-07T02:42:15.052907989Z","hd":{"ts_event":"2026-04-07T02:42:15.052886101Z","rtype":160,"publisher_id":101,"instrument_id":436},"action":"A","side":"A","price":"1.156750000","size":30,"channel_id":23,"order_id":"1775529735052892167","flags":128,"ts_in_delta":1002,"sequence":169092,"symbol":"FCEU SI 20260615 PS"}
{"ts_recv":"2026-04-07T02:42:15.057709827Z","hd":{"ts_event":"2026-04-07T02:42:15.057690723Z","rtype":160,"publisher_id":101,"instrument_id":436},"action":"C","side":"B","price":"1.156660000","size":30,"channel_id":23,"order_id":"10998901771902988537","flags":0,"ts_in_delta":927,"sequence":169096,"symbol":"FCEU SI 20260615 PS"}
{"ts_recv":"2026-04-07T02:42:15.057709827Z","hd":{"ts_event":"2026-04-07T02:42:15.057690723Z","rtype":160,"publisher_id":101,"instrument_id":436},"action":"A","side":"B","price":"1.156640000","size":30,"channel_id":23,"order_id":"10998901771912472332","flags":0,"ts_in_delta":927,"sequence":169096,"symbol":"FCEU SI 20260615 PS"}
{"ts_recv":"2026-04-07T02:42:15.057709827Z","hd":{"ts_event":"2026-04-07T02:42:15.057690723Z","rtype":160,"publisher_id":101,"instrument_id":436},"action":"C","side":"A","price":"1.156760000","size":30,"channel_id":23,"order_id":"1775529735048212729","flags":0,"ts_in_delta":927,"sequence":169096,"symbol":"FCEU SI 20260615 PS"}
{"ts_recv":"2026-04-07T02:42:15.057709827Z","hd":{"ts_event":"2026-04-07T02:42:15.057690723Z","rtype":160,"publisher_id":101,"instrument_id":436},"action":"A","side":"A","price":"1.156740000","size":30,"channel_id":23,"order_id":"1775529735057696524","flags":128,"ts_in_delta":927,"sequence":169096,"symbol":"FCEU SI 20260615 PS"}
{"ts_recv":"2026-04-07T02:42:15.057766027Z","hd":{"ts_event":"2026-04-07T02:42:15.057749707Z","rtype":160,"publisher_id":101,"instrument_id":436},"action":"C","side":"B","price":"1.156650000","size":30,"channel_id":23,"order_id":"10998901771907667975","flags":0,"ts_in_delta":942,"sequence":169097,"symbol":"FCEU SI 20260615 PS"}
{"ts_recv":"2026-04-07T02:42:15.057766027Z","hd":{"ts_event":"2026-04-07T02:42:15.057749707Z","rtype":160,"publisher_id":101,"instrument_id":436},"action":"A","side":"B","price":"1.156640000","size":30,"channel_id":23,"order_id":"10998901771912531255","flags":0,"ts_in_delta":942,"sequence":169097,"symbol":"FCEU SI 20260615 PS"}
{"ts_recv":"2026-04-07T02:42:15.057766027Z","hd":{"ts_event":"2026-04-07T02:42:15.057749707Z","rtype":160,"publisher_id":101,"instrument_id":436},"action":"C","side":"A","price":"1.156750000","size":30,"channel_id":23,"order_id":"1775529735052892167","flags":0,"ts_in_delta":942,"sequence":169097,"symbol":"FCEU SI 20260615 PS"}
{"ts_recv":"2026-04-07T02:42:15.057766027Z","hd":{"ts_event":"2026-04-07T02:42:15.057749707Z","rtype":160,"publisher_id":101,"instrument_id":436},"action":"A","side":"A","price":"1.156740000","size":30,"channel_id":23,"order_id":"1775529735057755447","flags":128,"ts_in_delta":942,"sequence":169097,"symbol":"FCEU SI 20260615 PS"}
{"ts_recv":"2026-04-07T02:42:24.598139646Z","hd":{"ts_event":"2026-04-07T02:42:24.598109209Z","rtype":160,"publisher_id":101,"instrument_id":436},"action":"C","side":"B","price":"1.156640000","size":30,"channel_id":23,"order_id":"10998901771912531255","flags":0,"ts_in_delta":1310,"sequence":169150,"symbol":"FCEU SI 20260615 PS"}
{"ts_recv":"2026-04-07T02:42:24.598139646Z","hd":{"ts_event":"2026-04-07T02:42:24.598109209Z","rtype":160,"publisher_id":101,"instrument_id":436},"action":"A","side":"B","price":"1.156650000","size":30,"channel_id":23,"order_id":"10998901781452898067","flags":0,"ts_in_delta":1310,"sequence":169150,"symbol":"FCEU SI 20260615 PS"}
{"ts_recv":"2026-04-07T02:42:24.598139646Z","hd":{"ts_event":"2026-04-07T02:42:24.598109209Z","rtype":160,"publisher_id":101,"instrument_id":436},"action":"C","side":"A","price":"1.156740000","size":30,"channel_id":23,"order_id":"1775529735057755447","flags":0,"ts_in_delta":1310,"sequence":169150,"symbol":"FCEU SI 20260615 PS"}
{"ts_recv":"2026-04-07T02:42:24.598139646Z","hd":{"ts_event":"2026-04-07T02:42:24.598109209Z","rtype":160,"publisher_id":101,"instrument_id":436},"action":"A","side":"A","price":"1.156750000","size":30,"channel_id":23,"order_id":"1775529744598122259","flags":128,"ts_in_delta":1310,"sequence":169150,"symbol":"FCEU SI 20260615 PS"}
{"ts_recv":"2026-04-07T02:42:28.031251283Z","hd":{"ts_event":"2026-04-07T02:42:28.031218141Z","rtype":160,"publisher_id":101,"instrument_id":436},"action":"C","side":"B","price":"1.156640000","size":30,"channel_id":23,"order_id":"10998901771912472332","flags":0,"ts_in_delta":917,"sequence":169179,"symbol":"FCEU SI 20260615 PS"}
{"ts_recv":"2026-04-07T02:42:28.031251283Z","hd":{"ts_event":"2026-04-07T02:42:28.031218141Z","rtype":160,"publisher_id":101,"instrument_id":436},"action":"A","side":"B","price":"1.156660000","size":30,"channel_id":23,"order_id":"10998901784886008218","flags":0,"ts_in_delta":917,"sequence":169179,"symbol":"FCEU SI 20260615 PS"}
{"ts_recv":"2026-04-07T02:42:28.031251283Z","hd":{"ts_event":"2026-04-07T02:42:28.031218141Z","rtype":160,"publisher_id":101,"instrument_id":436},"action":"C","side":"A","price":"1.156740000","size":30,"channel_id":23,"order_id":"1775529735057696524","flags":0,"ts_in_delta":917,"sequence":169179,"symbol":"FCEU SI 20260615 PS"}
{"ts_recv":"2026-04-07T02:42:28.031251283Z","hd":{"ts_event":"2026-04-07T02:42:28.031218141Z","rtype":160,"publisher_id":101,"instrument_id":436},"action":"A","side":"A","price":"1.156760000","size":30,"channel_id":23,"order_id":"1775529748031232410","flags":128,"ts_in_delta":917,"sequence":169179,"symbol":"FCEU SI 20260615 PS"}
{"ts_recv":"2026-04-07T02:42:28.031364973Z","hd":{"ts_event":"2026-04-07T02:42:28.031347941Z","rtype":160,"publisher_id":101,"instrument_id":436},"action":"C","side":"B","price":"1.156650000","size":30,"channel_id":23,"order_id":"10998901781452898067","flags":0,"ts_in_delta":920,"sequence":169180,"symbol":"FCEU SI 20260615 PS"}
{"ts_recv":"2026-04-07T02:42:28.031364973Z","hd":{"ts_event":"2026-04-07T02:42:28.031347941Z","rtype":160,"publisher_id":101,"instrument_id":436},"action":"A","side":"B","price":"1.156660000","size":30,"channel_id":23,"order_id":"10998901784886130127","flags":0,"ts_in_delta":920,"sequence":169180,"symbol":"FCEU SI 20260615 PS"}
{"ts_recv":"2026-04-07T02:42:28.031364973Z","hd":{"ts_event":"2026-04-07T02:42:28.031347941Z","rtype":160,"publisher_id":101,"instrument_id":436},"action":"C","side":"A","price":"1.156750000","size":30,"channel_id":23,"order_id":"1775529744598122259","flags":0,"ts_in_delta":920,"sequence":169180,"symbol":"FCEU SI 20260615 PS"}
{"ts_recv":"2026-04-07T02:42:28.031364973Z","hd":{"ts_event":"2026-04-07T02:42:28.031347941Z","rtype":160,"publisher_id":101,"instrument_id":436},"action":"A","side":"A","price":"1.156760000","size":30,"channel_id":23,"order_id":"1775529748031354319","flags":128,"ts_in_delta":920,"sequence":169180,"symbol":"FCEU SI 20260615 PS"}
{"ts_recv":"2026-04-07T02:42:28.046311119Z","hd":{"ts_event":"2026-04-07T02:42:28.046291259Z","rtype":160,"publisher_id":101,"instrument_id":436},"action":"C","side":"B","price":"1.156660000","size":30,"channel_id":23,"order_id":"10998901784886130127","flags":0,"ts_in_delta":929,"sequence":169194,"symbol":"FCEU SI 20260615 PS"}
{"ts_recv":"2026-04-07T02:42:28.046311119Z","hd":{"ts_event":"2026-04-07T02:42:28.046291259Z","rtype":160,"publisher_id":101,"instrument_id":436},"action":"A","side":"B","price":"1.156670000","size":30,"channel_id":23,"order_id":"10998901784901073160","flags":0,"ts_in_delta":929,"sequence":169194,"symbol":"FCEU SI 20260615 PS"}
{"ts_recv":"2026-04-07T02:42:28.046311119Z","hd":{"ts_event":"2026-04-07T02:42:28.046291259Z","rtype":160,"publisher_id":101,"instrument_id":436},"action":"C","side":"A","price":"1.156760000","size":30,"channel_id":23,"order_id":"1775529748031354319","flags":0,"ts_in_delta":929,"sequence":169194,"symbol":"FCEU SI 20260615 PS"}
{"ts_recv":"2026-04-07T02:42:28.046311119Z","hd":{"ts_event":"2026-04-07T02:42:28.046291259Z","rtype":160,"publisher_id":101,"instrument_id":436},"action":"A","side":"A","price":"1.156770000","size":30,"channel_id":23,"order_id":"1775529748046297352","flags":128,"ts_in_delta":929,"sequence":169194,"symbol":"FCEU SI 20260615 PS"}
{"ts_recv":"2026-04-07T02:42:28.046360154Z","hd":{"ts_event":"2026-04-07T02:42:28.046342247Z","rtype":160,"publisher_id":101,"instrument_id":436},"action":"C","side":"B","price":"1.156660000","size":30,"channel_id":23,"order_id":"10998901784886008218","flags":0,"ts_in_delta":942,"sequence":169195,"symbol":"FCEU SI 20260615 PS"}
{"ts_recv":"2026-04-07T02:42:28.046360154Z","hd":{"ts_event":"2026-04-07T02:42:28.046342247Z","rtype":160,"publisher_id":101,"instrument_id":436},"action":"A","side":"B","price":"1.156680000","size":30,"channel_id":23,"order_id":"10998901784901123961","flags":0,"ts_in_delta":942,"sequence":169195,"symbol":"FCEU SI 20260615 PS"}
{"ts_recv":"2026-04-07T02:42:28.046360154Z","hd":{"ts_event":"2026-04-07T02:42:28.046342247Z","rtype":160,"publisher_id":101,"instrument_id":436},"action":"C","side":"A","price":"1.156760000","size":30,"channel_id":23,"order_id":"1775529748031232410","flags":0,"ts_in_delta":942,"sequence":169195,"symbol":"FCEU SI 20260615 PS"}
{"ts_recv":"2026-04-07T02:42:28.046360154Z","hd":{"ts_event":"2026-04-07T02:42:28.046342247Z","rtype":160,"publisher_id":101,"instrument_id":436},"action":"A","side":"A","price":"1.156780000","size":30,"channel_id":23,"order_id":"1775529748046348153","flags":128,"ts_in_delta":942,"sequence":169195,"symbol":"FCEU SI 20260615 PS"}
{"ts_recv":"2026-04-07T02:42:28.046413512Z","hd":{"ts_event":"2026-04-07T02:42:28.046396245Z","rtype":160,"publisher_id":101,"instrument_id":436},"action":"C","side":"B","price":"1.156670000","size":30,"channel_id":23,"order_id":"10998901784901073160","flags":0,"ts_in_delta":993,"sequence":169196,"symbol":"FCEU SI 20260615 PS"}
{"ts_recv":"2026-04-07T02:42:28.046413512Z","hd":{"ts_event":"2026-04-07T02:42:28.046396245Z","rtype":160,"publisher_id":101,"instrument_id":436},"action":"A","side":"B","price":"1.156680000","size":30,"channel_id":23,"order_id":"10998901784901177779","flags":0,"ts_in_delta":993,"sequence":169196,"symbol":"FCEU SI 20260615 PS"}
{"ts_recv":"2026-04-07T02:42:28.046413512Z","hd":{"ts_event":"2026-04-07T02:42:28.046396245Z","rtype":160,"publisher_id":101,"instrument_id":436},"action":"C","side":"A","price":"1.156770000","size":30,"channel_id":23,"order_id":"1775529748046297352","flags":0,"ts_in_delta":993,"sequence":169196,"symbol":"FCEU SI 20260615 PS"}
{"ts_recv":"2026-04-07T02:42:28.046413512Z","hd":{"ts_event":"2026-04-07T02:42:28.046396245Z","rtype":160,"publisher_id":101,"instrument_id":436},"action":"A","side":"A","price":"1.156780000","size":30,"channel_id":23,"order_id":"1775529748046401971","flags":128,"ts_in_delta":993,"sequence":169196,"symbol":"FCEU SI 20260615 PS"}
{"ts_recv":"2026-04-07T02:42:45.113602645Z","hd":{"ts_event":"2026-04-07T02:42:45.113570245Z","rtype":160,"publisher_id":101,"instrument_id":436},"action":"C","side":"B","price":"1.156680000","size":30,"channel_id":23,"order_id":"10998901784901177779","flags":0,"ts_in_delta":1409,"sequence":169361,"symbol":"FCEU SI 20260615 PS"}
{"ts_recv":"2026-04-07T02:42:45.113602645Z","hd":{"ts_event":"2026-04-07T02:42:45.113570245Z","rtype":160,"publisher_id":101,"instrument_id":436},"action":"A","side":"B","price":"1.156690000","size":30,"channel_id":23,"order_id":"10998901801968359455","flags":0,"ts_in_delta":1409,"sequence":169361,"symbol":"FCEU SI 20260615 PS"}
{"ts_recv":"2026-04-07T02:42:45.113602645Z","hd":{"ts_event":"2026-04-07T02:42:45.113570245Z","rtype":160,"publisher_id":101,"instrument_id":436},"action":"C","side":"A","price":"1.156780000","size":30,"channel_id":23,"order_id":"1775529748046401971","flags":0,"ts_in_delta":1409,"sequence":169361,"symbol":"FCEU SI 20260615 PS"}
{"ts_recv":"2026-04-07T02:42:45.113602645Z","hd":{"ts_event":"2026-04-07T02:42:45.113570245Z","rtype":160,"publisher_id":101,"instrument_id":436},"action":"A","side":"A","price":"1.156790000","size":30,"channel_id":23,"order_id":"1775529765113583647","flags":128,"ts_in_delta":1409,"sequence":169361,"symbol":"FCEU SI 20260615 PS"}
{"ts_recv":"2026-04-07T02:42:55.610290383Z","hd":{"ts_event":"2026-04-07T02:42:55.610269927Z","rtype":160,"publisher_id":101,"instrument_id":436},"action":"C","side":"B","price":"1.156690000","size":30,"channel_id":23,"order_id":"10998901801968359455","flags":0,"ts_in_delta":894,"sequence":169439,"symbol":"FCEU SI 20260615 PS"}
{"ts_recv":"2026-04-07T02:42:55.610290383Z","hd":{"ts_event":"2026-04-07T02:42:55.610269927Z","rtype":160,"publisher_id":101,"instrument_id":436},"action":"A","side":"B","price":"1.156680000","size":30,"channel_id":23,"order_id":"10998901812465052001","flags":0,"ts_in_delta":894,"sequence":169439,"symbol":"FCEU SI 20260615 PS"}
{"ts_recv":"2026-04-07T02:42:55.610290383Z","hd":{"ts_event":"2026-04-07T02:42:55.610269927Z","rtype":160,"publisher_id":101,"instrument_id":436},"action":"C","side":"A","price":"1.156790000","size":30,"channel_id":23,"order_id":"1775529765113583647","flags":0,"ts_in_delta":894,"sequence":169439,"symbol":"FCEU SI 20260615 PS"}
{"ts_recv":"2026-04-07T02:42:55.610290383Z","hd":{"ts_event":"2026-04-07T02:42:55.610269927Z","rtype":160,"publisher_id":101,"instrument_id":436},"action":"A","side":"A","price":"1.156780000","size":30,"channel_id":23,"order_id":"1775529775610276193","flags":128,"ts_in_delta":894,"sequence":169439,"symbol":"FCEU SI 20260615 PS"}
{"ts_recv":"2026-04-07T02:43:03.152923061Z","hd":{"ts_event":"2026-04-07T02:43:03.152900679Z","rtype":160,"publisher_id":101,"instrument_id":436},"action":"C","side":"B","price":"1.156680000","size":30,"channel_id":23,"order_id":"10998901812465052001","flags":0,"ts_in_delta":1103,"sequence":169531,"symbol":"FCEU SI 20260615 PS"}
{"ts_recv":"2026-04-07T02:43:03.152923061Z","hd":{"ts_event":"2026-04-07T02:43:03.152900679Z","rtype":160,"publisher_id":101,"instrument_id":436},"action":"A","side":"B","price":"1.156690000","size":30,"channel_id":23,"order_id":"10998901820007682384","flags":0,"ts_in_delta":1103,"sequence":169531,"symbol":"FCEU SI 20260615 PS"}
{"ts_recv":"2026-04-07T02:43:03.152923061Z","hd":{"ts_event":"2026-04-07T02:43:03.152900679Z","rtype":160,"publisher_id":101,"instrument_id":436},"action":"C","side":"A","price":"1.156780000","size":30,"channel_id":23,"order_id":"1775529775610276193","flags":0,"ts_in_delta":1103,"sequence":169531,"symbol":"FCEU SI 20260615 PS"}
{"ts_recv":"2026-04-07T02:43:03.152923061Z","hd":{"ts_event":"2026-04-07T02:43:03.152900679Z","rtype":160,"publisher_id":101,"instrument_id":436},"action":"A","side":"A","price":"1.156790000","size":30,"channel_id":23,"order_id":"1775529783152906576","flags":128,"ts_in_delta":1103,"sequence":169531,"symbol":"FCEU SI 20260615 PS"}
{"ts_recv":"2026-04-07T02:43:30.535434215Z","hd":{"ts_event":"2026-04-07T02:43:30.535411901Z","rtype":160,"publisher_id":101,"instrument_id":436},"action":"C","side":"B","price":"1.156690000","size":30,"channel_id":23,"order_id":"10998901820007682384","flags":0,"ts_in_delta":954,"sequence":169877,"symbol":"FCEU SI 20260615 PS"}
{"ts_recv":"2026-04-07T02:43:30.535434215Z","hd":{"ts_event":"2026-04-07T02:43:30.535411901Z","rtype":160,"publisher_id":101,"instrument_id":436},"action":"A","side":"B","price":"1.156680000","size":30,"channel_id":23,"order_id":"10998901847390194197","flags":0,"ts_in_delta":954,"sequence":169877,"symbol":"FCEU SI 20260615 PS"}
{"ts_recv":"2026-04-07T02:43:30.535434215Z","hd":{"ts_event":"2026-04-07T02:43:30.535411901Z","rtype":160,"publisher_id":101,"instrument_id":436},"action":"C","side":"A","price":"1.156790000","size":30,"channel_id":23,"order_id":"1775529783152906576","flags":0,"ts_in_delta":954,"sequence":169877,"symbol":"FCEU SI 20260615 PS"}
{"ts_recv":"2026-04-07T02:43:30.535434215Z","hd":{"ts_event":"2026-04-07T02:43:30.535411901Z","rtype":160,"publisher_id":101,"instrument_id":436},"action":"A","side":"A","price":"1.156780000","size":30,"channel_id":23,"order_id":"1775529810535418389","flags":128,"ts_in_delta":954,"sequence":169877,"symbol":"FCEU SI 20260615 PS"}
{"ts_recv":"2026-04-07T02:43:43.812268387Z","hd":{"ts_event":"2026-04-07T02:43:43.812239639Z","rtype":160,"publisher_id":101,"instrument_id":436},"action":"C","side":"B","price":"1.156680000","size":30,"channel_id":23,"order_id":"10998901847390194197","flags":0,"ts_in_delta":1196,"sequence":169958,"symbol":"FCEU SI 20260615 PS"}
{"ts_recv":"2026-04-07T02:43:43.812268387Z","hd":{"ts_event":"2026-04-07T02:43:43.812239639Z","rtype":160,"publisher_id":101,"instrument_id":436},"action":"A","side":"B","price":"1.156690000","size":30,"channel_id":23,"order_id":"10998901860667026414","flags":0,"ts_in_delta":1196,"sequence":169958,"symbol":"FCEU SI 20260615 PS"}
{"ts_recv":"2026-04-07T02:43:43.812268387Z","hd":{"ts_event":"2026-04-07T02:43:43.812239639Z","rtype":160,"publisher_id":101,"instrument_id":436},"action":"C","side":"A","price":"1.156780000","size":30,"channel_id":23,"order_id":"1775529810535418389","flags":0,"ts_in_delta":1196,"sequence":169958,"symbol":"FCEU SI 20260615 PS"}
{"ts_recv":"2026-04-07T02:43:43.812268387Z","hd":{"ts_event":"2026-04-07T02:43:43.812239639Z","rtype":160,"publisher_id":101,"instrument_id":436},"action":"A","side":"A","price":"1.156790000","size":30,"channel_id":23,"order_id":"1775529823812250606","flags":128,"ts_in_delta":1196,"sequence":169958,"symbol":"FCEU SI 20260615 PS"}
{"ts_recv":"2026-04-07T02:44:00.927741932Z","hd":{"ts_event":"2026-04-07T02:44:00.927719311Z","rtype":160,"publisher_id":101,"instrument_id":436},"action":"C","side":"B","price":"1.156680000","size":30,"channel_id":23,"order_id":"10998901784901123961","flags":0,"ts_in_delta":987,"sequence":170089,"symbol":"FCEU SI 20260615 PS"}
{"ts_recv":"2026-04-07T02:44:00.927741932Z","hd":{"ts_event":"2026-04-07T02:44:00.927719311Z","rtype":160,"publisher_id":101,"instrument_id":436},"action":"A","side":"B","price":"1.156700000","size":30,"channel_id":23,"order_id":"10998901877782501302","flags":0,"ts_in_delta":987,"sequence":170089,"symbol":"FCEU SI 20260615 PS"}
{"ts_recv":"2026-04-07T02:44:00.927741932Z","hd":{"ts_event":"2026-04-07T02:44:00.927719311Z","rtype":160,"publisher_id":101,"instrument_id":436},"action":"C","side":"A","price":"1.156780000","size":30,"channel_id":23,"order_id":"1775529748046348153","flags":0,"ts_in_delta":987,"sequence":170089,"symbol":"FCEU SI 20260615 PS"}
{"ts_recv":"2026-04-07T02:44:00.927741932Z","hd":{"ts_event":"2026-04-07T02:44:00.927719311Z","rtype":160,"publisher_id":101,"instrument_id":436},"action":"A","side":"A","price":"1.156800000","size":30,"channel_id":23,"order_id":"1775529840927725494","flags":128,"ts_in_delta":987,"sequence":170089,"symbol":"FCEU SI 20260615 PS"}
{"ts_recv":"2026-04-07T02:44:00.927828335Z","hd":{"ts_event":"2026-04-07T02:44:00.927806479Z","rtype":160,"publisher_id":101,"instrument_id":436},"action":"C","side":"B","price":"1.156690000","size":30,"channel_id":23,"order_id":"10998901860667026414","flags":0,"ts_in_delta":994,"sequence":170090,"symbol":"FCEU SI 20260615 PS"}
{"ts_recv":"2026-04-07T02:44:00.927828335Z","hd":{"ts_event":"2026-04-07T02:44:00.927806479Z","rtype":160,"publisher_id":101,"instrument_id":436},"action":"A","side":"B","price":"1.156700000","size":30,"channel_id":23,"order_id":"10998901877782588286","flags":0,"ts_in_delta":994,"sequence":170090,"symbol":"FCEU SI 20260615 PS"}
{"ts_recv":"2026-04-07T02:44:00.927828335Z","hd":{"ts_event":"2026-04-07T02:44:00.927806479Z","rtype":160,"publisher_id":101,"instrument_id":436},"action":"C","side":"A","price":"1.156790000","size":30,"channel_id":23,"order_id":"1775529823812250606","flags":0,"ts_in_delta":994,"sequence":170090,"symbol":"FCEU SI 20260615 PS"}
{"ts_recv":"2026-04-07T02:44:00.927828335Z","hd":{"ts_event":"2026-04-07T02:44:00.927806479Z","rtype":160,"publisher_id":101,"instrument_id":436},"action":"A","side":"A","price":"1.156800000","size":30,"channel_id":23,"order_id":"1775529840927812478","flags":128,"ts_in_delta":994,"sequence":170090,"symbol":"FCEU SI 20260615 PS"}
{"ts_recv":"2026-04-07T02:44:27.203739262Z","hd":{"ts_event":"2026-04-07T02:44:27.203703091Z","rtype":160,"publisher_id":101,"instrument_id":436},"action":"C","side":"B","price":"1.156700000","size":30,"channel_id":23,"order_id":"10998901877782588286","flags":0,"ts_in_delta":1457,"sequence":170308,"symbol":"FCEU SI 20260615 PS"}
{"ts_recv":"2026-04-07T02:44:27.203739262Z","hd":{"ts_event":"2026-04-07T02:44:27.203703091Z","rtype":160,"publisher_id":101,"instrument_id":436},"action":"A","side":"B","price":"1.156710000","size":30,"channel_id":23,"order_id":"10998901904058492750","flags":0,"ts_in_delta":1457,"sequence":170308,"symbol":"FCEU SI 20260615 PS"}
{"ts_recv":"2026-04-07T02:44:27.203739262Z","hd":{"ts_event":"2026-04-07T02:44:27.203703091Z","rtype":160,"publisher_id":101,"instrument_id":436},"action":"C","side":"A","price":"1.156800000","size":30,"channel_id":23,"order_id":"1775529840927812478","flags":0,"ts_in_delta":1457,"sequence":170308,"symbol":"FCEU SI 20260615 PS"}
{"ts_recv":"2026-04-07T02:44:27.203739262Z","hd":{"ts_event":"2026-04-07T02:44:27.203703091Z","rtype":160,"publisher_id":101,"instrument_id":436},"action":"A","side":"A","price":"1.156810000","size":30,"channel_id":23,"order_id":"1775529867203716942","flags":128,"ts_in_delta":1457,"sequence":170308,"symbol":"FCEU SI 20260615 PS"}
{"ts_recv":"2026-04-07T02:44:27.440287138Z","hd":{"ts_event":"2026-04-07T02:44:27.440256695Z","rtype":160,"publisher_id":101,"instrument_id":436},"action":"C","side":"B","price":"1.156700000","size":30,"channel_id":23,"order_id":"10998901877782501302","flags":0,"ts_in_delta":843,"sequence":170310,"symbol":"FCEU SI 20260615 PS"}
{"ts_recv":"2026-04-07T02:44:27.440287138Z","hd":{"ts_event":"2026-04-07T02:44:27.440256695Z","rtype":160,"publisher_id":101,"instrument_id":436},"action":"A","side":"B","price":"1.156720000","size":30,"channel_id":23,"order_id":"10998901904295043611","flags":0,"ts_in_delta":843,"sequence":170310,"symbol":"FCEU SI 20260615 PS"}
