{"ts_recv":"2026-04-07T02:44:27.440287138Z","hd":{"ts_event":"2026-04-07T02:44:27.440256695Z","rtype":160,"publisher_id":101,"instrument_id":436},"action":"C","side":"A","price":"1.156800000","size":30,"channel_id":23,"order_id":"1775529840927725494","flags":0,"ts_in_delta":843,"sequence":170310,"symbol":"FCEU SI 20260615 PS"}
{"ts_recv":"2026-04-07T02:44:27.440287138Z","hd":{"ts_event":"2026-04-07T02:44:27.440256695Z","rtype":160,"publisher_id":101,"instrument_id":436},"action":"A","side":"A","price":"1.156820000","size":30,"channel_id":23,"order_id":"1775529867440267803","flags":128,"ts_in_delta":843,"sequence":170310,"symbol":"FCEU SI 20260615 PS"}
{"ts_recv":"2026-04-07T02:44:27.440382696Z","hd":{"ts_event":"2026-04-07T02:44:27.440363153Z","rtype":160,"publisher_id":101,"instrument_id":436},"action":"C","side":"B","price":"1.156710000","size":30,"channel_id":23,"order_id":"10998901904058492750","flags":0,"ts_in_delta":955,"sequence":170311,"symbol":"FCEU SI 20260615 PS"}
{"ts_recv":"2026-04-07T02:44:27.440382696Z","hd":{"ts_event":"2026-04-07T02:44:27.440363153Z","rtype":160,"publisher_id":101,"instrument_id":436},"action":"A","side":"B","price":"1.156720000","size":30,"channel_id":23,"order_id":"10998901904295145086","flags":0,"ts_in_delta":955,"sequence":170311,"symbol":"FCEU SI 20260615 PS"}
{"ts_recv":"2026-04-07T02:44:27.440382696Z","hd":{"ts_event":"2026-04-07T02:44:27.440363153Z","rtype":160,"publisher_id":101,"instrument_id":436},"action":"C","side":"A","price":"1.156810000","size":30,"channel_id":23,"order_id":"1775529867203716942","flags":0,"ts_in_delta":955,"sequence":170311,"symbol":"FCEU SI 20260615 PS"}
{"ts_recv":"2026-04-07T02:44:27.440382696Z","hd":{"ts_event":"2026-04-07T02:44:27.440363153Z","rtype":160,"publisher_id":101,"instrument_id":436},"action":"A","side":"A","price":"1.156820000","size":30,"channel_id":23,"order_id":"1775529867440369278","flags":128,"ts_in_delta":955,"sequence":170311,"symbol":"FCEU SI 20260615 PS"}
{"ts_recv":"2026-04-07T02:44:36.254085146Z","hd":{"ts_event":"2026-04-07T02:44:36.254063605Z","rtype":160,"publisher_id":101,"instrument_id":436},"action":"C","side":"B","price":"1.156720000","size":30,"channel_id":23,"order_id":"10998901904295145086","flags":0,"ts_in_delta":987,"sequence":170386,"symbol":"FCEU SI 20260615 PS"}
{"ts_recv":"2026-04-07T02:44:36.254085146Z","hd":{"ts_event":"2026-04-07T02:44:36.254063605Z","rtype":160,"publisher_id":101,"instrument_id":436},"action":"A","side":"B","price":"1.156710000","size":30,"channel_id":23,"order_id":"10998901913108845693","flags":0,"ts_in_delta":987,"sequence":170386,"symbol":"FCEU SI 20260615 PS"}
{"ts_recv":"2026-04-07T02:44:36.254085146Z","hd":{"ts_event":"2026-04-07T02:44:36.254063605Z","rtype":160,"publisher_id":101,"instrument_id":436},"action":"C","side":"A","price":"1.156820000","size":30,"channel_id":23,"order_id":"1775529867440369278","flags":0,"ts_in_delta":987,"sequence":170386,"symbol":"FCEU SI 20260615 PS"}
{"ts_recv":"2026-04-07T02:44:36.254085146Z","hd":{"ts_event":"2026-04-07T02:44:36.254063605Z","rtype":160,"publisher_id":101,"instrument_id":436},"action":"A","side":"A","price":"1.156810000","size":30,"channel_id":23,"order_id":"1775529876254069885","flags":128,"ts_in_delta":987,"sequence":170386,"symbol":"FCEU SI 20260615 PS"}
{"ts_recv":"2026-04-07T02:44:36.267847829Z","hd":{"ts_event":"2026-04-07T02:44:36.267826067Z","rtype":160,"publisher_id":101,"instrument_id":436},"action":"C","side":"B","price":"1.156720000","size":30,"channel_id":23,"order_id":"10998901904295043611","flags":0,"ts_in_delta":1016,"sequence":170388,"symbol":"FCEU SI 20260615 PS"}
{"ts_recv":"2026-04-07T02:44:36.267847829Z","hd":{"ts_event":"2026-04-07T02:44:36.267826067Z","rtype":160,"publisher_id":101,"instrument_id":436},"action":"A","side":"B","price":"1.156700000","size":30,"channel_id":23,"order_id":"10998901913122608061","flags":0,"ts_in_delta":1016,"sequence":170388,"symbol":"FCEU SI 20260615 PS"}
{"ts_recv":"2026-04-07T02:44:36.267847829Z","hd":{"ts_event":"2026-04-07T02:44:36.267826067Z","rtype":160,"publisher_id":101,"instrument_id":436},"action":"C","side":"A","price":"1.156820000","size":30,"channel_id":23,"order_id":"1775529867440267803","flags":0,"ts_in_delta":1016,"sequence":170388,"symbol":"FCEU SI 20260615 PS"}
{"ts_recv":"2026-04-07T02:44:36.267847829Z","hd":{"ts_event":"2026-04-07T02:44:36.267826067Z","rtype":160,"publisher_id":101,"instrument_id":436},"action":"A","side":"A","price":"1.156800000","size":30,"channel_id":23,"order_id":"1775529876267832253","flags":128,"ts_in_delta":1016,"sequence":170388,"symbol":"FCEU SI 20260615 PS"}
{"ts_recv":"2026-04-07T02:44:36.267915564Z","hd":{"ts_event":"2026-04-07T02:44:36.267895731Z","rtype":160,"publisher_id":101,"instrument_id":436},"action":"C","side":"B","price":"1.156710000","size":30,"channel_id":23,"order_id":"10998901913108845693","flags":0,"ts_in_delta":983,"sequence":170389,"symbol":"FCEU SI 20260615 PS"}
{"ts_recv":"2026-04-07T02:44:36.267915564Z","hd":{"ts_event":"2026-04-07T02:44:36.267895731Z","rtype":160,"publisher_id":101,"instrument_id":436},"action":"A","side":"B","price":"1.156700000","size":30,"channel_id":23,"order_id":"10998901913122677709","flags":0,"ts_in_delta":983,"sequence":170389,"symbol":"FCEU SI 20260615 PS"}
{"ts_recv":"2026-04-07T02:44:36.267915564Z","hd":{"ts_event":"2026-04-07T02:44:36.267895731Z","rtype":160,"publisher_id":101,"instrument_id":436},"action":"C","side":"A","price":"1.156810000","size":30,"channel_id":23,"order_id":"1775529876254069885","flags":0,"ts_in_delta":983,"sequence":170389,"symbol":"FCEU SI 20260615 PS"}
{"ts_recv":"2026-04-07T02:44:36.267915564Z","hd":{"ts_event":"2026-04-07T02:44:36.267895731Z","rtype":160,"publisher_id":101,"instrument_id":436},"action":"A","side":"A","price":"1.156800000","size":30,"channel_id":23,"order_id":"1775529876267901901","flags":128,"ts_in_delta":983,"sequence":170389,"symbol":"FCEU SI 20260615 PS"}
{"ts_recv":"2026-04-07T02:45:01.573311345Z","hd":{"ts_event":"2026-04-07T02:45:01.573288969Z","rtype":160,"publisher_id":101,"instrument_id":436},"action":"C","side":"B","price":"1.156700000","size":30,"channel_id":23,"order_id":"10998901913122677709","flags":0,"ts_in_delta":884,"sequence":170538,"symbol":"FCEU SI 20260615 PS"}
{"ts_recv":"2026-04-07T02:45:01.573311345Z","hd":{"ts_event":"2026-04-07T02:45:01.573288969Z","rtype":160,"publisher_id":101,"instrument_id":436},"action":"A","side":"B","price":"1.156690000","size":30,"channel_id":23,"order_id":"10998901938428071134","flags":0,"ts_in_delta":884,"sequence":170538,"symbol":"FCEU SI 20260615 PS"}
{"ts_recv":"2026-04-07T02:45:01.573311345Z","hd":{"ts_event":"2026-04-07T02:45:01.573288969Z","rtype":160,"publisher_id":101,"instrument_id":436},"action":"C","side":"A","price":"1.156800000","size":30,"channel_id":23,"order_id":"1775529876267901901","flags":0,"ts_in_delta":884,"sequence":170538,"symbol":"FCEU SI 20260615 PS"}
{"ts_recv":"2026-04-07T02:45:01.573311345Z","hd":{"ts_event":"2026-04-07T02:45:01.573288969Z","rtype":160,"publisher_id":101,"instrument_id":436},"action":"A","side":"A","price":"1.156790000","size":30,"channel_id":23,"order_id":"1775529901573295326","flags":128,"ts_in_delta":884,"sequence":170538,"symbol":"FCEU SI 20260615 PS"}
{"ts_recv":"2026-04-07T02:45:01.573369280Z","hd":{"ts_event":"2026-04-07T02:45:01.573347889Z","rtype":160,"publisher_id":101,"instrument_id":436},"action":"C","side":"B","price":"1.156700000","size":30,"channel_id":23,"order_id":"10998901913122608061","flags":0,"ts_in_delta":913,"sequence":170539,"symbol":"FCEU SI 20260615 PS"}
{"ts_recv":"2026-04-07T02:45:01.573369280Z","hd":{"ts_event":"2026-04-07T02:45:01.573347889Z","rtype":160,"publisher_id":101,"instrument_id":436},"action":"A","side":"B","price":"1.156680000","size":30,"channel_id":23,"order_id":"10998901938428129879","flags":0,"ts_in_delta":913,"sequence":170539,"symbol":"FCEU SI 20260615 PS"}
{"ts_recv":"2026-04-07T02:45:01.573369280Z","hd":{"ts_event":"2026-04-07T02:45:01.573347889Z","rtype":160,"publisher_id":101,"instrument_id":436},"action":"C","side":"A","price":"1.156800000","size":30,"channel_id":23,"order_id":"1775529876267832253","flags":0,"ts_in_delta":913,"sequence":170539,"symbol":"FCEU SI 20260615 PS"}
{"ts_recv":"2026-04-07T02:45:01.573369280Z","hd":{"ts_event":"2026-04-07T02:45:01.573347889Z","rtype":160,"publisher_id":101,"instrument_id":436},"action":"A","side":"A","price":"1.156780000","size":30,"channel_id":23,"order_id":"1775529901573354071","flags":128,"ts_in_delta":913,"sequence":170539,"symbol":"FCEU SI 20260615 PS"}
{"ts_recv":"2026-04-07T02:45:01.573425894Z","hd":{"ts_event":"2026-04-07T02:45:01.573406373Z","rtype":160,"publisher_id":101,"instrument_id":436},"action":"C","side":"B","price":"1.156690000","size":30,"channel_id":23,"order_id":"10998901938428071134","flags":0,"ts_in_delta":931,"sequence":170540,"symbol":"FCEU SI 20260615 PS"}
{"ts_recv":"2026-04-07T02:45:01.573425894Z","hd":{"ts_event":"2026-04-07T02:45:01.573406373Z","rtype":160,"publisher_id":101,"instrument_id":436},"action":"A","side":"B","price":"1.156680000","size":30,"channel_id":23,"order_id":"10998901938428188141","flags":0,"ts_in_delta":931,"sequence":170540,"symbol":"FCEU SI 20260615 PS"}
{"ts_recv":"2026-04-07T02:45:01.573425894Z","hd":{"ts_event":"2026-04-07T02:45:01.573406373Z","rtype":160,"publisher_id":101,"instrument_id":436},"action":"C","side":"A","price":"1.156790000","size":30,"channel_id":23,"order_id":"1775529901573295326","flags":0,"ts_in_delta":931,"sequence":170540,"symbol":"FCEU SI 20260615 PS"}
{"ts_recv":"2026-04-07T02:45:01.573425894Z","hd":{"ts_event":"2026-04-07T02:45:01.573406373Z","rtype":160,"publisher_id":101,"instrument_id":436},"action":"A","side":"A","price":"1.156780000","size":30,"channel_id":23,"order_id":"1775529901573412333","flags":128,"ts_in_delta":931,"sequence":170540,"symbol":"FCEU SI 20260615 PS"}
{"ts_recv":"2026-04-07T02:45:01.584069449Z","hd":{"ts_event":"2026-04-07T02:45:01.584050451Z","rtype":160,"publisher_id":101,"instrument_id":436},"action":"C","side":"B","price":"1.156680000","size":30,"channel_id":23,"order_id":"10998901938428188141","flags":0,"ts_in_delta":1652,"sequence":170545,"symbol":"FCEU SI 20260615 PS"}
{"ts_recv":"2026-04-07T02:45:01.584069449Z","hd":{"ts_event":"2026-04-07T02:45:01.584050451Z","rtype":160,"publisher_id":101,"instrument_id":436},"action":"A","side":"B","price":"1.156670000","size":30,"channel_id":23,"order_id":"10998901938438832306","flags":0,"ts_in_delta":1652,"sequence":170545,"symbol":"FCEU SI 20260615 PS"}
{"ts_recv":"2026-04-07T02:45:01.584069449Z","hd":{"ts_event":"2026-04-07T02:45:01.584050451Z","rtype":160,"publisher_id":101,"instrument_id":436},"action":"C","side":"A","price":"1.156780000","size":30,"channel_id":23,"order_id":"1775529901573412333","flags":0,"ts_in_delta":1652,"sequence":170545,"symbol":"FCEU SI 20260615 PS"}
{"ts_recv":"2026-04-07T02:45:01.584069449Z","hd":{"ts_event":"2026-04-07T02:45:01.584050451Z","rtype":160,"publisher_id":101,"instrument_id":436},"action":"A","side":"A","price":"1.156770000","size":30,"channel_id":23,"order_id":"1775529901584056498","flags":128,"ts_in_delta":1652,"sequence":170545,"symbol":"FCEU SI 20260615 PS"}
{"ts_recv":"2026-04-07T02:45:01.584303724Z","hd":{"ts_event":"2026-04-07T02:45:01.584284329Z","rtype":160,"publisher_id":101,"instrument_id":436},"action":"C","side":"B","price":"1.156680000","size":30,"channel_id":23,"order_id":"10998901938428129879","flags":0,"ts_in_delta":1048,"sequence":170546,"symbol":"FCEU SI 20260615 PS"}
{"ts_recv":"2026-04-07T02:45:01.584303724Z","hd":{"ts_event":"2026-04-07T02:45:01.584284329Z","rtype":160,"publisher_id":101,"instrument_id":436},"action":"A","side":"B","price":"1.156660000","size":30,"channel_id":23,"order_id":"10998901938439066155","flags":0,"ts_in_delta":1048,"sequence":170546,"symbol":"FCEU SI 20260615 PS"}
{"ts_recv":"2026-04-07T02:45:01.584303724Z","hd":{"ts_event":"2026-04-07T02:45:01.584284329Z","rtype":160,"publisher_id":101,"instrument_id":436},"action":"C","side":"A","price":"1.156780000","size":30,"channel_id":23,"order_id":"1775529901573354071","flags":0,"ts_in_delta":1048,"sequence":170546,"symbol":"FCEU SI 20260615 PS"}
{"ts_recv":"2026-04-07T02:45:01.584303724Z","hd":{"ts_event":"2026-04-07T02:45:01.584284329Z","rtype":160,"publisher_id":101,"instrument_id":436},"action":"A","side":"A","price":"1.156760000","size":30,"channel_id":23,"order_id":"1775529901584290347","flags":128,"ts_in_delta":1048,"sequence":170546,"symbol":"FCEU SI 20260615 PS"}
{"ts_recv":"2026-04-07T02:45:01.584360231Z","hd":{"ts_event":"2026-04-07T02:45:01.584341373Z","rtype":160,"publisher_id":101,"instrument_id":436},"action":"C","side":"B","price":"1.156670000","size":30,"channel_id":23,"order_id":"10998901938438832306","flags":0,"ts_in_delta":901,"sequence":170547,"symbol":"FCEU SI 20260615 PS"}
{"ts_recv":"2026-04-07T02:45:01.584360231Z","hd":{"ts_event":"2026-04-07T02:45:01.584341373Z","rtype":160,"publisher_id":101,"instrument_id":436},"action":"A","side":"B","price":"1.156660000","size":30,"channel_id":23,"order_id":"10998901938439123204","flags":0,"ts_in_delta":901,"sequence":170547,"symbol":"FCEU SI 20260615 PS"}
{"ts_recv":"2026-04-07T02:45:01.584360231Z","hd":{"ts_event":"2026-04-07T02:45:01.584341373Z","rtype":160,"publisher_id":101,"instrument_id":436},"action":"C","side":"A","price":"1.156770000","size":30,"channel_id":23,"order_id":"1775529901584056498","flags":0,"ts_in_delta":901,"sequence":170547,"symbol":"FCEU SI 20260615 PS"}
{"ts_recv":"2026-04-07T02:45:01.584360231Z","hd":{"ts_event":"2026-04-07T02:45:01.584341373Z","rtype":160,"publisher_id":101,"instrument_id":436},"action":"A","side":"A","price":"1.156760000","size":30,"channel_id":23,"order_id":"1775529901584347396","flags":128,"ts_in_delta":901,"sequence":170547,"symbol":"FCEU SI 20260615 PS"}
{"ts_recv":"2026-04-07T02:45:04.910533057Z","hd":{"ts_event":"2026-04-07T02:45:04.910511777Z","rtype":160,"publisher_id":101,"instrument_id":436},"action":"C","side":"B","price":"1.156660000","size":30,"channel_id":23,"order_id":"10998901938439123204","flags":0,"ts_in_delta":934,"sequence":170605,"symbol":"FCEU SI 20260615 PS"}
{"ts_recv":"2026-04-07T02:45:04.910533057Z","hd":{"ts_event":"2026-04-07T02:45:04.910511777Z","rtype":160,"publisher_id":101,"instrument_id":436},"action":"A","side":"B","price":"1.156670000","size":30,"channel_id":23,"order_id":"10998901941765293326","flags":0,"ts_in_delta":934,"sequence":170605,"symbol":"FCEU SI 20260615 PS"}
{"ts_recv":"2026-04-07T02:45:04.910533057Z","hd":{"ts_event":"2026-04-07T02:45:04.910511777Z","rtype":160,"publisher_id":101,"instrument_id":436},"action":"C","side":"A","price":"1.156760000","size":30,"channel_id":23,"order_id":"1775529901584347396","flags":0,"ts_in_delta":934,"sequence":170605,"symbol":"FCEU SI 20260615 PS"}
{"ts_recv":"2026-04-07T02:45:04.910533057Z","hd":{"ts_event":"2026-04-07T02:45:04.910511777Z","rtype":160,"publisher_id":101,"instrument_id":436},"action":"A","side":"A","price":"1.156770000","size":30,"channel_id":23,"order_id":"1775529904910517518","flags":128,"ts_in_delta":934,"sequence":170605,"symbol":"FCEU SI 20260615 PS"}
{"ts_recv":"2026-04-07T02:45:05.076414020Z","hd":{"ts_event":"2026-04-07T02:45:05.076392885Z","rtype":160,"publisher_id":101,"instrument_id":436},"action":"C","side":"B","price":"1.156660000","size":30,"channel_id":23,"order_id":"10998901938439066155","flags":0,"ts_in_delta":934,"sequence":170619,"symbol":"FCEU SI 20260615 PS"}
{"ts_recv":"2026-04-07T02:45:05.076414020Z","hd":{"ts_event":"2026-04-07T02:45:05.076392885Z","rtype":160,"publisher_id":101,"instrument_id":436},"action":"A","side":"B","price":"1.156680000","size":30,"channel_id":23,"order_id":"10998901941931174820","flags":0,"ts_in_delta":934,"sequence":170619,"symbol":"FCEU SI 20260615 PS"}
{"ts_recv":"2026-04-07T02:45:05.076414020Z","hd":{"ts_event":"2026-04-07T02:45:05.076392885Z","rtype":160,"publisher_id":101,"instrument_id":436},"action":"C","side":"A","price":"1.156760000","size":30,"channel_id":23,"order_id":"1775529901584290347","flags":0,"ts_in_delta":934,"sequence":170619,"symbol":"FCEU SI 20260615 PS"}
{"ts_recv":"2026-04-07T02:45:05.076414020Z","hd":{"ts_event":"2026-04-07T02:45:05.076392885Z","rtype":160,"publisher_id":101,"instrument_id":436},"action":"A","side":"A","price":"1.156780000","size":30,"channel_id":23,"order_id":"1775529905076399012","flags":128,"ts_in_delta":934,"sequence":170619,"symbol":"FCEU SI 20260615 PS"}
{"ts_recv":"2026-04-07T02:45:05.076470473Z","hd":{"ts_event":"2026-04-07T02:45:05.076453923Z","rtype":160,"publisher_id":101,"instrument_id":436},"action":"C","side":"B","price":"1.156670000","size":30,"channel_id":23,"order_id":"10998901941765293326","flags":0,"ts_in_delta":916,"sequence":170620,"symbol":"FCEU SI 20260615 PS"}
{"ts_recv":"2026-04-07T02:45:05.076470473Z","hd":{"ts_event":"2026-04-07T02:45:05.076453923Z","rtype":160,"publisher_id":101,"instrument_id":436},"action":"A","side":"B","price":"1.156680000","size":30,"channel_id":23,"order_id":"10998901941931235413","flags":0,"ts_in_delta":916,"sequence":170620,"symbol":"FCEU SI 20260615 PS"}
{"ts_recv":"2026-04-07T02:45:05.076470473Z","hd":{"ts_event":"2026-04-07T02:45:05.076453923Z","rtype":160,"publisher_id":101,"instrument_id":436},"action":"C","side":"A","price":"1.156770000","size":30,"channel_id":23,"order_id":"1775529904910517518","flags":0,"ts_in_delta":916,"sequence":170620,"symbol":"FCEU SI 20260615 PS"}
{"ts_recv":"2026-04-07T02:45:05.076470473Z","hd":{"ts_event":"2026-04-07T02:45:05.076453923Z","rtype":160,"publisher_id":101,"instrument_id":436},"action":"A","side":"A","price":"1.156780000","size":30,"channel_id":23,"order_id":"1775529905076459605","flags":128,"ts_in_delta":916,"sequence":170620,"symbol":"FCEU SI 20260615 PS"}
{"ts_recv":"2026-04-07T02:45:19.403338224Z","hd":{"ts_event":"2026-04-07T02:45:19.403315533Z","rtype":160,"publisher_id":101,"instrument_id":436},"action":"C","side":"B","price":"1.156680000","size":30,"channel_id":23,"order_id":"10998901941931235413","flags":0,"ts_in_delta":949,"sequence":170705,"symbol":"FCEU SI 20260615 PS"}
{"ts_recv":"2026-04-07T02:45:19.403338224Z","hd":{"ts_event":"2026-04-07T02:45:19.403315533Z","rtype":160,"publisher_id":101,"instrument_id":436},"action":"A","side":"B","price":"1.156690000","size":30,"channel_id":23,"order_id":"10998901956258097686","flags":0,"ts_in_delta":949,"sequence":170705,"symbol":"FCEU SI 20260615 PS"}
{"ts_recv":"2026-04-07T02:45:19.403338224Z","hd":{"ts_event":"2026-04-07T02:45:19.403315533Z","rtype":160,"publisher_id":101,"instrument_id":436},"action":"C","side":"A","price":"1.156780000","size":30,"channel_id":23,"order_id":"1775529905076459605","flags":0,"ts_in_delta":949,"sequence":170705,"symbol":"FCEU SI 20260615 PS"}
{"ts_recv":"2026-04-07T02:45:19.403338224Z","hd":{"ts_event":"2026-04-07T02:45:19.403315533Z","rtype":160,"publisher_id":101,"instrument_id":436},"action":"A","side":"A","price":"1.156790000","size":30,"channel_id":23,"order_id":"1775529919403321878","flags":128,"ts_in_delta":949,"sequence":170705,"symbol":"FCEU SI 20260615 PS"}
{"ts_recv":"2026-04-07T02:45:29.823199355Z","hd":{"ts_event":"2026-04-07T02:45:29.823176355Z","rtype":160,"publisher_id":101,"instrument_id":436},"action":"C","side":"B","price":"1.156680000","size":30,"channel_id":23,"order_id":"10998901941931174820","flags":0,"ts_in_delta":742,"sequence":170791,"symbol":"FCEU SI 20260615 PS"}
{"ts_recv":"2026-04-07T02:45:29.823199355Z","hd":{"ts_event":"2026-04-07T02:45:29.823176355Z","rtype":160,"publisher_id":101,"instrument_id":436},"action":"A","side":"B","price":"1.156700000","size":30,"channel_id":23,"order_id":"10998901966677957996","flags":0,"ts_in_delta":742,"sequence":170791,"symbol":"FCEU SI 20260615 PS"}
{"ts_recv":"2026-04-07T02:45:29.823199355Z","hd":{"ts_event":"2026-04-07T02:45:29.823176355Z","rtype":160,"publisher_id":101,"instrument_id":436},"action":"C","side":"A","price":"1.156780000","size":30,"channel_id":23,"order_id":"1775529905076399012","flags":0,"ts_in_delta":742,"sequence":170791,"symbol":"FCEU SI 20260615 PS"}
{"ts_recv":"2026-04-07T02:45:29.823199355Z","hd":{"ts_event":"2026-04-07T02:45:29.823176355Z","rtype":160,"publisher_id":101,"instrument_id":436},"action":"A","side":"A","price":"1.156800000","size":30,"channel_id":23,"order_id":"1775529929823182188","flags":128,"ts_in_delta":742,"sequence":170791,"symbol":"FCEU SI 20260615 PS"}
{"ts_recv":"2026-04-07T02:45:29.823272903Z","hd":{"ts_event":"2026-04-07T02:45:29.823253731Z","rtype":160,"publisher_id":101,"instrument_id":436},"action":"C","side":"B","price":"1.156690000","size":30,"channel_id":23,"order_id":"10998901956258097686","flags":0,"ts_in_delta":908,"sequence":170792,"symbol":"FCEU SI 20260615 PS"}
{"ts_recv":"2026-04-07T02:45:29.823272903Z","hd":{"ts_event":"2026-04-07T02:45:29.823253731Z","rtype":160,"publisher_id":101,"instrument_id":436},"action":"A","side":"B","price":"1.156700000","size":30,"channel_id":23,"order_id":"10998901966678035470","flags":0,"ts_in_delta":908,"sequence":170792,"symbol":"FCEU SI 20260615 PS"}
{"ts_recv":"2026-04-07T02:45:29.823272903Z","hd":{"ts_event":"2026-04-07T02:45:29.823253731Z","rtype":160,"publisher_id":101,"instrument_id":436},"action":"C","side":"A","price":"1.156790000","size":30,"channel_id":23,"order_id":"1775529919403321878","flags":0,"ts_in_delta":908,"sequence":170792,"symbol":"FCEU SI 20260615 PS"}
{"ts_recv":"2026-04-07T02:45:29.823272903Z","hd":{"ts_event":"2026-04-07T02:45:29.823253731Z","rtype":160,"publisher_id":101,"instrument_id":436},"action":"A","side":"A","price":"1.156800000","size":30,"channel_id":23,"order_id":"1775529929823259662","flags":128,"ts_in_delta":908,"sequence":170792,"symbol":"FCEU SI 20260615 PS"}
{"ts_recv":"2026-04-07T02:45:55.047553711Z","hd":{"ts_event":"2026-04-07T02:45:55.047529545Z","rtype":160,"publisher_id":101,"instrument_id":436},"action":"C","side":"B","price":"1.156700000","size":30,"channel_id":23,"order_id":"10998901966678035470","flags":0,"ts_in_delta":974,"sequence":171000,"symbol":"FCEU SI 20260615 PS"}
{"ts_recv":"2026-04-07T02:45:55.047553711Z","hd":{"ts_event":"2026-04-07T02:45:55.047529545Z","rtype":160,"publisher_id":101,"instrument_id":436},"action":"A","side":"B","price":"1.156710000","size":30,"channel_id":23,"order_id":"10998901991902311795","flags":0,"ts_in_delta":974,"sequence":171000,"symbol":"FCEU SI 20260615 PS"}
{"ts_recv":"2026-04-07T02:45:55.047553711Z","hd":{"ts_event":"2026-04-07T02:45:55.047529545Z","rtype":160,"publisher_id":101,"instrument_id":436},"action":"C","side":"A","price":"1.156800000","size":30,"channel_id":23,"order_id":"1775529929823259662","flags":0,"ts_in_delta":974,"sequence":171000,"symbol":"FCEU SI 20260615 PS"}
{"ts_recv":"2026-04-07T02:45:55.047553711Z","hd":{"ts_event":"2026-04-07T02:45:55.047529545Z","rtype":160,"publisher_id":101,"instrument_id":436},"action":"A","side":"A","price":"1.156810000","size":30,"channel_id":23,"order_id":"1775529955047535987","flags":128,"ts_in_delta":974,"sequence":171000,"symbol":"FCEU SI 20260615 PS"}
{"ts_recv":"2026-04-07T02:46:15.163397596Z","hd":{"ts_event":"2026-04-07T02:46:15.163367611Z","rtype":160,"publisher_id":101,"instrument_id":436},"action":"C","side":"B","price":"1.156710000","size":30,"channel_id":23,"order_id":"10998901991902311795","flags":0,"ts_in_delta":1234,"sequence":171131,"symbol":"FCEU SI 20260615 PS"}
{"ts_recv":"2026-04-07T02:46:15.163397596Z","hd":{"ts_event":"2026-04-07T02:46:15.163367611Z","rtype":160,"publisher_id":101,"instrument_id":436},"action":"A","side":"B","price":"1.156700000","size":30,"channel_id":23,"order_id":"10998902012018157293","flags":0,"ts_in_delta":1234,"sequence":171131,"symbol":"FCEU SI 20260615 PS"}
{"ts_recv":"2026-04-07T02:46:15.163397596Z","hd":{"ts_event":"2026-04-07T02:46:15.163367611Z","rtype":160,"publisher_id":101,"instrument_id":436},"action":"C","side":"A","price":"1.156810000","size":30,"channel_id":23,"order_id":"1775529955047535987","flags":0,"ts_in_delta":1234,"sequence":171131,"symbol":"FCEU SI 20260615 PS"}
{"ts_recv":"2026-04-07T02:46:15.163397596Z","hd":{"ts_event":"2026-04-07T02:46:15.163367611Z","rtype":160,"publisher_id":101,"instrument_id":436},"action":"A","side":"A","price":"1.156800000","size":30,"channel_id":23,"order_id":"1775529975163381485","flags":128,"ts_in_delta":1234,"sequence":171131,"symbol":"FCEU SI 20260615 PS"}
{"ts_recv":"2026-04-07T02:47:02.977390046Z","hd":{"ts_event":"2026-04-07T02:47:02.977364373Z","rtype":160,"publisher_id":101,"instrument_id":436},"action":"C","side":"B","price":"1.156700000","size":30,"channel_id":23,"order_id":"10998902012018157293","flags":0,"ts_in_delta":1323,"sequence":171390,"symbol":"FCEU SI 20260615 PS"}
{"ts_recv":"2026-04-07T02:47:02.977390046Z","hd":{"ts_event":"2026-04-07T02:47:02.977364373Z","rtype":160,"publisher_id":101,"instrument_id":436},"action":"A","side":"B","price":"1.156690000","size":30,"channel_id":23,"order_id":"10998902059832146799","flags":0,"ts_in_delta":1323,"sequence":171390,"symbol":"FCEU SI 20260615 PS"}
{"ts_recv":"2026-04-07T02:47:02.977390046Z","hd":{"ts_event":"2026-04-07T02:47:02.977364373Z","rtype":160,"publisher_id":101,"instrument_id":436},"action":"C","side":"A","price":"1.156800000","size":30,"channel_id":23,"order_id":"1775529975163381485","flags":0,"ts_in_delta":1323,"sequence":171390,"symbol":"FCEU SI 20260615 PS"}
{"ts_recv":"2026-04-07T02:47:02.977390046Z","hd":{"ts_event":"2026-04-07T02:47:02.977364373Z","rtype":160,"publisher_id":101,"instrument_id":436},"action":"A","side":"A","price":"1.156790000","size":30,"channel_id":23,"order_id":"1775530022977370991","flags":128,"ts_in_delta":1323,"sequence":171390,"symbol":"FCEU SI 20260615 PS"}
{"ts_recv":"2026-04-07T02:47:02.991806672Z","hd":{"ts_event":"2026-04-07T02:47:02.991787187Z","rtype":160,"publisher_id":101,"instrument_id":436},"action":"C","side":"B","price":"1.156700000","size":30,"channel_id":23,"order_id":"10998901966677957996","flags":0,"ts_in_delta":982,"sequence":171391,"symbol":"FCEU SI 20260615 PS"}
{"ts_recv":"2026-04-07T02:47:02.991806672Z","hd":{"ts_event":"2026-04-07T02:47:02.991787187Z","rtype":160,"publisher_id":101,"instrument_id":436},"action":"A","side":"B","price":"1.156680000","size":30,"channel_id":23,"order_id":"10998902059846569373","flags":0,"ts_in_delta":982,"sequence":171391,"symbol":"FCEU SI 20260615 PS"}
{"ts_recv":"2026-04-07T02:47:02.991806672Z","hd":{"ts_event":"2026-04-07T02:47:02.991787187Z","rtype":160,"publisher_id":101,"instrument_id":436},"action":"C","side":"A","price":"1.156800000","size":30,"channel_id":23,"order_id":"1775529929823182188","flags":0,"ts_in_delta":982,"sequence":171391,"symbol":"FCEU SI 20260615 PS"}
{"ts_recv":"2026-04-07T02:47:02.991806672Z","hd":{"ts_event":"2026-04-07T02:47:02.991787187Z","rtype":160,"publisher_id":101,"instrument_id":436},"action":"A","side":"A","price":"1.156780000","size":30,"channel_id":23,"order_id":"1775530022991793565","flags":128,"ts_in_delta":982,"sequence":171391,"symbol":"FCEU SI 20260615 PS"}
{"ts_recv":"2026-04-07T02:47:02.991868593Z","hd":{"ts_event":"2026-04-07T02:47:02.991852735Z","rtype":160,"publisher_id":101,"instrument_id":436},"action":"C","side":"B","price":"1.156690000","size":30,"channel_id":23,"order_id":"10998902059832146799","flags":0,"ts_in_delta":967,"sequence":171392,"symbol":"FCEU SI 20260615 PS"}
{"ts_recv":"2026-04-07T02:47:02.991868593Z","hd":{"ts_event":"2026-04-07T02:47:02.991852735Z","rtype":160,"publisher_id":101,"instrument_id":436},"action":"A","side":"B","price":"1.156680000","size":30,"channel_id":23,"order_id":"10998902059846634695","flags":0,"ts_in_delta":967,"sequence":171392,"symbol":"FCEU SI 20260615 PS"}
{"ts_recv":"2026-04-07T02:47:02.991868593Z","hd":{"ts_event":"2026-04-07T02:47:02.991852735Z","rtype":160,"publisher_id":101,"instrument_id":436},"action":"C","side":"A","price":"1.156790000","size":30,"channel_id":23,"order_id":"1775530022977370991","flags":0,"ts_in_delta":967,"sequence":171392,"symbol":"FCEU SI 20260615 PS"}
{"ts_recv":"2026-04-07T02:47:02.991868593Z","hd":{"ts_event":"2026-04-07T02:47:02.991852735Z","rtype":160,"publisher_id":101,"instrument_id":436},"action":"A","side":"A","price":"1.156780000","size":30,"channel_id":23,"order_id":"1775530022991858887","flags":128,"ts_in_delta":967,"sequence":171392,"symbol":"FCEU SI 20260615 PS"}
{"ts_recv":"2026-04-07T02:47:07.496350719Z","hd":{"ts_event":"2026-04-07T02:47:07.496320579Z","rtype":160,"publisher_id":101,"instrument_id":436},"action":"C","side":"B","price":"1.156680000","size":30,"channel_id":23,"order_id":"10998902059846634695","flags":0,"ts_in_delta":1342,"sequence":171450,"symbol":"FCEU SI 20260615 PS"}
{"ts_recv":"2026-04-07T02:47:07.496350719Z","hd":{"ts_event":"2026-04-07T02:47:07.496320579Z","rtype":160,"publisher_id":101,"instrument_id":436},"action":"A","side":"B","price":"1.156670000","size":30,"channel_id":23,"order_id":"10998902064351106971","flags":0,"ts_in_delta":1342,"sequence":171450,"symbol":"FCEU SI 20260615 PS"}
{"ts_recv":"2026-04-07T02:47:07.496350719Z","hd":{"ts_event":"2026-04-07T02:47:07.496320579Z","rtype":160,"publisher_id":101,"instrument_id":436},"action":"C","side":"A","price":"1.156780000","size":30,"channel_id":23,"order_id":"1775530022991858887","flags":0,"ts_in_delta":1342,"sequence":171450,"symbol":"FCEU SI 20260615 PS"}
{"ts_recv":"2026-04-07T02:47:07.496350719Z","hd":{"ts_event":"2026-04-07T02:47:07.496320579Z","rtype":160,"publisher_id":101,"instrument_id":436},"action":"A","side":"A","price":"1.156770000","size":30,"channel_id":23,"order_id":"1775530027496331163","flags":128,"ts_in_delta":1342,"sequence":171450,"symbol":"FCEU SI 20260615 PS"}
{"ts_recv":"2026-04-07T02:47:07.496439296Z","hd":{"ts_event":"2026-04-07T02:47:07.496417811Z","rtype":160,"publisher_id":101,"instrument_id":436},"action":"C","side":"B","price":"1.156670000","size":30,"channel_id":23,"order_id":"10998902064351106971","flags":0,"ts_in_delta":956,"sequence":171451,"symbol":"FCEU SI 20260615 PS"}
{"ts_recv":"2026-04-07T02:47:07.496439296Z","hd":{"ts_event":"2026-04-07T02:47:07.496417811Z","rtype":160,"publisher_id":101,"instrument_id":436},"action":"A","side":"B","price":"1.156660000","size":30,"channel_id":23,"order_id":"10998902064351199475","flags":0,"ts_in_delta":956,"sequence":171451,"symbol":"FCEU SI 20260615 PS"}
{"ts_recv":"2026-04-07T02:47:07.496439296Z","hd":{"ts_event":"2026-04-07T02:47:07.496417811Z","rtype":160,"publisher_id":101,"instrument_id":436},"action":"C","side":"A","price":"1.156770000","size":30,"channel_id":23,"order_id":"1775530027496331163","flags":0,"ts_in_delta":956,"sequence":171451,"symbol":"FCEU SI 20260615 PS"}
{"ts_recv":"2026-04-07T02:47:07.496439296Z","hd":{"ts_event":"2026-04-07T02:47:07.496417811Z","rtype":160,"publisher_id":101,"instrument_id":436},"action":"A","side":"A","price":"1.156760000","size":30,"channel_id":23,"order_id":"1775530027496423667","flags":128,"ts_in_delta":956,"sequence":171451,"symbol":"FCEU SI 20260615 PS"}
{"ts_recv":"2026-04-07T02:47:07.496495795Z","hd":{"ts_event":"2026-04-07T02:47:07.496480595Z","rtype":160,"publisher_id":101,"instrument_id":436},"action":"C","side":"B","price":"1.156660000","size":30,"channel_id":23,"order_id":"10998902064351199475","flags":0,"ts_in_delta":919,"sequence":171452,"symbol":"FCEU SI 20260615 PS"}
{"ts_recv":"2026-04-07T02:47:07.496495795Z","hd":{"ts_event":"2026-04-07T02:47:07.496480595Z","rtype":160,"publisher_id":101,"instrument_id":436},"action":"A","side":"B","price":"1.156670000","size":30,"channel_id":23,"order_id":"10998902064351262183","flags":0,"ts_in_delta":919,"sequence":171452,"symbol":"FCEU SI 20260615 PS"}
{"ts_recv":"2026-04-07T02:47:07.496495795Z","hd":{"ts_event":"2026-04-07T02:47:07.496480595Z","rtype":160,"publisher_id":101,"instrument_id":436},"action":"C","side":"A","price":"1.156760000","size":30,"channel_id":23,"order_id":"1775530027496423667","flags":0,"ts_in_delta":919,"sequence":171452,"symbol":"FCEU SI 20260615 PS"}
{"ts_recv":"2026-04-07T02:47:07.496495795Z","hd":{"ts_event":"2026-04-07T02:47:07.496480595Z","rtype":160,"publisher_id":101,"instrument_id":436},"action":"A","side":"A","price":"1.156770000","size":30,"channel_id":23,"order_id":"1775530027496486375","flags":128,"ts_in_delta":919,"sequence":171452,"symbol":"FCEU SI 20260615 PS"}
{"ts_recv":"2026-04-07T02:47:07.496507553Z","hd":{"ts_event":"2026-04-07T02:47:07.496486897Z","rtype":160,"publisher_id":101,"instrument_id":436},"action":"C","side":"B","price":"1.156680000","size":30,"channel_id":23,"order_id":"10998902059846569373","flags":0,"ts_in_delta":1062,"sequence":171453,"symbol":"FCEU SI 20260615 PS"}
{"ts_recv":"2026-04-07T02:47:07.496507553Z","hd":{"ts_event":"2026-04-07T02:47:07.496486897Z","rtype":160,"publisher_id":101,"instrument_id":436},"action":"A","side":"B","price":"1.156660000","size":30,"channel_id":23,"order_id":"10998902064351268881","flags":0,"ts_in_delta":1062,"sequence":171453,"symbol":"FCEU SI 20260615 PS"}
{"ts_recv":"2026-04-07T02:47:07.496507553Z","hd":{"ts_event":"2026-04-07T02:47:07.496486897Z","rtype":160,"publisher_id":101,"instrument_id":436},"action":"C","side":"A","price":"1.156780000","size":30,"channel_id":23,"order_id":"1775530022991793565","flags":0,"ts_in_delta":1062,"sequence":171453,"symbol":"FCEU SI 20260615 PS"}
{"ts_recv":"2026-04-07T02:47:07.496507553Z","hd":{"ts_event":"2026-04-07T02:47:07.496486897Z","rtype":160,"publisher_id":101,"instrument_id":436},"action":"A","side":"A","price":"1.156760000","size":30,"channel_id":23,"order_id":"1775530027496493073","flags":128,"ts_in_delta":1062,"sequence":171453,"symbol":"FCEU SI 20260615 PS"}
{"ts_recv":"2026-04-07T02:47:07.496569873Z","hd":{"ts_event":"2026-04-07T02:47:07.496552631Z","rtype":160,"publisher_id":101,"instrument_id":436},"action":"C","side":"B","price":"1.156670000","size":30,"channel_id":23,"order_id":"10998902064351262183","flags":0,"ts_in_delta":900,"sequence":171454,"symbol":"FCEU SI 20260615 PS"}
{"ts_recv":"2026-04-07T02:47:07.496569873Z","hd":{"ts_event":"2026-04-07T02:47:07.496552631Z","rtype":160,"publisher_id":101,"instrument_id":436},"action":"A","side":"B","price":"1.156660000","size":30,"channel_id":23,"order_id":"10998902064351334647","flags":0,"ts_in_delta":900,"sequence":171454,"symbol":"FCEU SI 20260615 PS"}
{"ts_recv":"2026-04-07T02:47:07.496569873Z","hd":{"ts_event":"2026-04-07T02:47:07.496552631Z","rtype":160,"publisher_id":101,"instrument_id":436},"action":"C","side":"A","price":"1.156770000","size":30,"channel_id":23,"order_id":"1775530027496486375","flags":0,"ts_in_delta":900,"sequence":171454,"symbol":"FCEU SI 20260615 PS"}
{"ts_recv":"2026-04-07T02:47:07.496569873Z","hd":{"ts_event":"2026-04-07T02:47:07.496552631Z","rtype":160,"publisher_id":101,"instrument_id":436},"action":"A","side":"A","price":"1.156760000","size":30,"channel_id":23,"order_id":"1775530027496558839","flags":128,"ts_in_delta":900,"sequence":171454,"symbol":"FCEU SI 20260615 PS"}
{"ts_recv":"2026-04-07T02:47:28.273262467Z","hd":{"ts_event":"2026-04-07T02:47:28.273228341Z","rtype":160,"publisher_id":101,"instrument_id":436},"action":"C","side":"B","price":"1.156660000","size":30,"channel_id":23,"order_id":"10998902064351334647","flags":0,"ts_in_delta":888,"sequence":171564,"symbol":"FCEU SI 20260615 PS"}
{"ts_recv":"2026-04-07T02:47:28.273262467Z","hd":{"ts_event":"2026-04-07T02:47:28.273228341Z","rtype":160,"publisher_id":101,"instrument_id":436},"action":"A","side":"B","price":"1.156670000","size":30,"channel_id":23,"order_id":"10998902085128018825","flags":0,"ts_in_delta":888,"sequence":171564,"symbol":"FCEU SI 20260615 PS"}
{"ts_recv":"2026-04-07T02:47:28.273262467Z","hd":{"ts_event":"2026-04-07T02:47:28.273228341Z","rtype":160,"publisher_id":101,"instrument_id":436},"action":"C","side":"A","price":"1.156760000","size":30,"channel_id":23,"order_id":"1775530027496558839","flags":0,"ts_in_delta":888,"sequence":171564,"symbol":"FCEU SI 20260615 PS"}
{"ts_recv":"2026-04-07T02:47:28.273262467Z","hd":{"ts_event":"2026-04-07T02:47:28.273228341Z","rtype":160,"publisher_id":101,"instrument_id":436},"action":"A","side":"A","price":"1.156770000","size":30,"channel_id":23,"order_id":"1775530048273243017","flags":128,"ts_in_delta":888,"sequence":171564,"symbol":"FCEU SI 20260615 PS"}
{"ts_recv":"2026-04-07T02:47:28.281140502Z","hd":{"ts_event":"2026-04-07T02:47:28.281117845Z","rtype":160,"publisher_id":101,"instrument_id":436},"action":"C","side":"B","price":"1.156660000","size":30,"channel_id":23,"order_id":"10998902064351268881","flags":0,"ts_in_delta":958,"sequence":171570,"symbol":"FCEU SI 20260615 PS"}
{"ts_recv":"2026-04-07T02:47:28.281140502Z","hd":{"ts_event":"2026-04-07T02:47:28.281117845Z","rtype":160,"publisher_id":101,"instrument_id":436},"action":"A","side":"B","price":"1.156680000","size":30,"channel_id":23,"order_id":"10998902085135900005","flags":0,"ts_in_delta":958,"sequence":171570,"symbol":"FCEU SI 20260615 PS"}
{"ts_recv":"2026-04-07T02:47:28.281140502Z","hd":{"ts_event":"2026-04-07T02:47:28.281117845Z","rtype":160,"publisher_id":101,"instrument_id":436},"action":"C","side":"A","price":"1.156760000","size":30,"channel_id":23,"order_id":"1775530027496493073","flags":0,"ts_in_delta":958,"sequence":171570,"symbol":"FCEU SI 20260615 PS"}
{"ts_recv":"2026-04-07T02:47:28.281140502Z","hd":{"ts_event":"2026-04-07T02:47:28.281117845Z","rtype":160,"publisher_id":101,"instrument_id":436},"action":"A","side":"A","price":"1.156780000","size":30,"channel_id":23,"order_id":"1775530048281124197","flags":128,"ts_in_delta":958,"sequence":171570,"symbol":"FCEU SI 20260615 PS"}
{"ts_recv":"2026-04-07T02:47:28.281198776Z","hd":{"ts_event":"2026-04-07T02:47:28.281180911Z","rtype":160,"publisher_id":101,"instrument_id":436},"action":"C","side":"B","price":"1.156670000","size":30,"channel_id":23,"order_id":"10998902085128018825","flags":0,"ts_in_delta":901,"sequence":171571,"symbol":"FCEU SI 20260615 PS"}
{"ts_recv":"2026-04-07T02:47:28.281198776Z","hd":{"ts_event":"2026-04-07T02:47:28.281180911Z","rtype":160,"publisher_id":101,"instrument_id":436},"action":"A","side":"B","price":"1.156680000","size":30,"channel_id":23,"order_id":"10998902085135962988","flags":0,"ts_in_delta":901,"sequence":171571,"symbol":"FCEU SI 20260615 PS"}
{"ts_recv":"2026-04-07T02:47:28.281198776Z","hd":{"ts_event":"2026-04-07T02:47:28.281180911Z","rtype":160,"publisher_id":101,"instrument_id":436},"action":"C","side":"A","price":"1.156770000","size":30,"channel_id":23,"order_id":"1775530048273243017","flags":0,"ts_in_delta":901,"sequence":171571,"symbol":"FCEU SI 20260615 PS"}
{"ts_recv":"2026-04-07T02:47:28.281198776Z","hd":{"ts_event":"2026-04-07T02:47:28.281180911Z","rtype":160,"publisher_id":101,"instrument_id":436},"action":"A","side":"A","price":"1.156780000","size":30,"channel_id":23,"order_id":"1775530048281187180","flags":128,"ts_in_delta":901,"sequence":171571,"symbol":"FCEU SI 20260615 PS"}
{"ts_recv":"2026-04-07T02:47:48.436649745Z","hd":{"ts_event":"2026-04-07T02:47:48.436625643Z","rtype":160,"publisher_id":101,"instrument_id":436},"action":"C","side":"B","price":"1.156680000","size":30,"channel_id":23,"order_id":"10998902085135962988","flags":0,"ts_in_delta":875,"sequence":171683,"symbol":"FCEU SI 20260615 PS"}
{"ts_recv":"2026-04-07T02:47:48.436649745Z","hd":{"ts_event":"2026-04-07T02:47:48.436625643Z","rtype":160,"publisher_id":101,"instrument_id":436},"action":"A","side":"B","price":"1.156670000","size":30,"channel_id":23,"order_id":"10998902105291408399","flags":0,"ts_in_delta":875,"sequence":171683,"symbol":"FCEU SI 20260615 PS"}
{"ts_recv":"2026-04-07T02:47:48.436649745Z","hd":{"ts_event":"2026-04-07T02:47:48.436625643Z","rtype":160,"publisher_id":101,"instrument_id":436},"action":"C","side":"A","price":"1.156780000","size":30,"channel_id":23,"order_id":"1775530048281187180","flags":0,"ts_in_delta":875,"sequence":171683,"symbol":"FCEU SI 20260615 PS"}
{"ts_recv":"2026-04-07T02:47:48.436649745Z","hd":{"ts_event":"2026-04-07T02:47:48.436625643Z","rtype":160,"publisher_id":101,"instrument_id":436},"action":"A","side":"A","price":"1.156770000","size":30,"channel_id":23,"order_id":"1775530068436632591","flags":128,"ts_in_delta":875,"sequence":171683,"symbol":"FCEU SI 20260615 PS"}
{"ts_recv":"2026-04-07T02:47:48.436737446Z","hd":{"ts_event":"2026-04-07T02:47:48.436716051Z","rtype":160,"publisher_id":101,"instrument_id":436},"action":"C","side":"B","price":"1.156670000","size":30,"channel_id":23,"order_id":"10998902105291408399","flags":0,"ts_in_delta":913,"sequence":171684,"symbol":"FCEU SI 20260615 PS"}
{"ts_recv":"2026-04-07T02:47:48.436737446Z","hd":{"ts_event":"2026-04-07T02:47:48.436716051Z","rtype":160,"publisher_id":101,"instrument_id":436},"action":"A","side":"B","price":"1.156660000","size":30,"channel_id":23,"order_id":"10998902105291497947","flags":0,"ts_in_delta":913,"sequence":171684,"symbol":"FCEU SI 20260615 PS"}
{"ts_recv":"2026-04-07T02:47:48.436737446Z","hd":{"ts_event":"2026-04-07T02:47:48.436716051Z","rtype":160,"publisher_id":101,"instrument_id":436},"action":"C","side":"A","price":"1.156770000","size":30,"channel_id":23,"order_id":"1775530068436632591","flags":0,"ts_in_delta":913,"sequence":171684,"symbol":"FCEU SI 20260615 PS"}
{"ts_recv":"2026-04-07T02:47:48.436737446Z","hd":{"ts_event":"2026-04-07T02:47:48.436716051Z","rtype":160,"publisher_id":101,"instrument_id":436},"action":"A","side":"A","price":"1.156760000","size":30,"channel_id":23,"order_id":"1775530068436722139","flags":128,"ts_in_delta":913,"sequence":171684,"symbol":"FCEU SI 20260615 PS"}
{"ts_recv":"2026-04-07T02:47:48.436791173Z","hd":{"ts_event":"2026-04-07T02:47:48.436773825Z","rtype":160,"publisher_id":101,"instrument_id":436},"action":"C","side":"B","price":"1.156680000","size":30,"channel_id":23,"order_id":"10998902085135900005","flags":0,"ts_in_delta":929,"sequence":171685,"symbol":"FCEU SI 20260615 PS"}
{"ts_recv":"2026-04-07T02:47:48.436791173Z","hd":{"ts_event":"2026-04-07T02:47:48.436773825Z","rtype":160,"publisher_id":101,"instrument_id":436},"action":"A","side":"B","price":"1.156660000","size":30,"channel_id":23,"order_id":"10998902105291555401","flags":0,"ts_in_delta":929,"sequence":171685,"symbol":"FCEU SI 20260615 PS"}
{"ts_recv":"2026-04-07T02:47:48.436791173Z","hd":{"ts_event":"2026-04-07T02:47:48.436773825Z","rtype":160,"publisher_id":101,"instrument_id":436},"action":"C","side":"A","price":"1.156780000","size":30,"channel_id":23,"order_id":"1775530048281124197","flags":0,"ts_in_delta":929,"sequence":171685,"symbol":"FCEU SI 20260615 PS"}
{"ts_recv":"2026-04-07T02:47:48.436791173Z","hd":{"ts_event":"2026-04-07T02:47:48.436773825Z","rtype":160,"publisher_id":101,"instrument_id":436},"action":"A","side":"A","price":"1.156760000","size":30,"channel_id":23,"order_id":"1775530068436779593","flags":128,"ts_in_delta":929,"sequence":171685,"symbol":"FCEU SI 20260615 PS"}
{"ts_recv":"2026-04-07T02:47:48.436803438Z","hd":{"ts_event":"2026-04-07T02:47:48.436777587Z","rtype":160,"publisher_id":101,"instrument_id":436},"action":"C","side":"B","price":"1.156660000","size":30,"channel_id":23,"order_id":"10998902105291497947","flags":0,"ts_in_delta":920,"sequence":171686,"symbol":"FCEU SI 20260615 PS"}
{"ts_recv":"2026-04-07T02:47:48.436803438Z","hd":{"ts_event":"2026-04-07T02:47:48.436777587Z","rtype":160,"publisher_id":101,"instrument_id":436},"action":"A","side":"B","price":"1.156670000","size":30,"channel_id":23,"order_id":"10998902105291563834","flags":0,"ts_in_delta":920,"sequence":171686,"symbol":"FCEU SI 20260615 PS"}
{"ts_recv":"2026-04-07T02:47:48.436803438Z","hd":{"ts_event":"2026-04-07T02:47:48.436777587Z","rtype":160,"publisher_id":101,"instrument_id":436},"action":"C","side":"A","price":"1.156760000","size":30,"channel_id":23,"order_id":"1775530068436722139","flags":0,"ts_in_delta":920,"sequence":171686,"symbol":"FCEU SI 20260615 PS"}
{"ts_recv":"2026-04-07T02:47:48.436803438Z","hd":{"ts_event":"2026-04-07T02:47:48.436777587Z","rtype":160,"publisher_id":101,"instrument_id":436},"action":"A","side":"A","price":"1.156770000","size":30,"channel_id":23,"order_id":"1775530068436788026","flags":128,"ts_in_delta":920,"sequence":171686,"symbol":"FCEU SI 20260615 PS"}
{"ts_recv":"2026-04-07T02:47:48.436859085Z","hd":{"ts_event":"2026-04-07T02:47:48.436841759Z","rtype":160,"publisher_id":101,"instrument_id":436},"action":"C","side":"B","price":"1.156670000","size":30,"channel_id":23,"order_id":"10998902105291563834","flags":0,"ts_in_delta":955,"sequence":171687,"symbol":"FCEU SI 20260615 PS"}
{"ts_recv":"2026-04-07T02:47:48.436859085Z","hd":{"ts_event":"2026-04-07T02:47:48.436841759Z","rtype":160,"publisher_id":101,"instrument_id":436},"action":"A","side":"B","price":"1.156660000","size":30,"channel_id":23,"order_id":"10998902105291623487","flags":0,"ts_in_delta":955,"sequence":171687,"symbol":"FCEU SI 20260615 PS"}
{"ts_recv":"2026-04-07T02:47:48.436859085Z","hd":{"ts_event":"2026-04-07T02:47:48.436841759Z","rtype":160,"publisher_id":101,"instrument_id":436},"action":"C","side":"A","price":"1.156770000","size":30,"channel_id":23,"order_id":"1775530068436788026","flags":0,"ts_in_delta":955,"sequence":171687,"symbol":"FCEU SI 20260615 PS"}
{"ts_recv":"2026-04-07T02:47:48.436859085Z","hd":{"ts_event":"2026-04-07T02:47:48.436841759Z","rtype":160,"publisher_id":101,"instrument_id":436},"action":"A","side":"A","price":"1.156760000","size":30,"channel_id":23,"order_id":"1775530068436847679","flags":128,"ts_in_delta":955,"sequence":171687,"symbol":"FCEU SI 20260615 PS"}
{"ts_recv":"2026-04-07T02:47:48.840652241Z","hd":{"ts_event":"2026-04-07T02:47:48.840632877Z","rtype":160,"publisher_id":101,"instrument_id":436},"action":"C","side":"B","price":"1.156660000","size":30,"channel_id":23,"order_id":"10998902105291623487","flags":0,"ts_in_delta":862,"sequence":171733,"symbol":"FCEU SI 20260615 PS"}
{"ts_recv":"2026-04-07T02:47:48.840652241Z","hd":{"ts_event":"2026-04-07T02:47:48.840632877Z","rtype":160,"publisher_id":101,"instrument_id":436},"action":"A","side":"B","price":"1.156670000","size":30,"channel_id":23,"order_id":"10998902105695414522","flags":0,"ts_in_delta":862,"sequence":171733,"symbol":"FCEU SI 20260615 PS"}
{"ts_recv":"2026-04-07T02:47:48.840652241Z","hd":{"ts_event":"2026-04-07T02:47:48.840632877Z","rtype":160,"publisher_id":101,"instrument_id":436},"action":"C","side":"A","price":"1.156760000","size":30,"channel_id":23,"order_id":"1775530068436847679","flags":0,"ts_in_delta":862,"sequence":171733,"symbol":"FCEU SI 20260615 PS"}
{"ts_recv":"2026-04-07T02:47:48.840652241Z","hd":{"ts_event":"2026-04-07T02:47:48.840632877Z","rtype":160,"publisher_id":101,"instrument_id":436},"action":"A","side":"A","price":"1.156770000","size":30,"channel_id":23,"order_id":"1775530068840638714","flags":128,"ts_in_delta":862,"sequence":171733,"symbol":"FCEU SI 20260615 PS"}
{"ts_recv":"2026-04-07T02:47:48.840707926Z","hd":{"ts_event":"2026-04-07T02:47:48.840687271Z","rtype":160,"publisher_id":101,"instrument_id":436},"action":"C","side":"B","price":"1.156660000","size":30,"channel_id":23,"order_id":"10998902105291555401","flags":0,"ts_in_delta":912,"sequence":171734,"symbol":"FCEU SI 20260615 PS"}
{"ts_recv":"2026-04-07T02:47:48.840707926Z","hd":{"ts_event":"2026-04-07T02:47:48.840687271Z","rtype":160,"publisher_id":101,"instrument_id":436},"action":"A","side":"B","price":"1.156680000","size":30,"channel_id":23,"order_id":"10998902105695469370","flags":0,"ts_in_delta":912,"sequence":171734,"symbol":"FCEU SI 20260615 PS"}
{"ts_recv":"2026-04-07T02:47:48.840707926Z","hd":{"ts_event":"2026-04-07T02:47:48.840687271Z","rtype":160,"publisher_id":101,"instrument_id":436},"action":"C","side":"A","price":"1.156760000","size":30,"channel_id":23,"order_id":"1775530068436779593","flags":0,"ts_in_delta":912,"sequence":171734,"symbol":"FCEU SI 20260615 PS"}
{"ts_recv":"2026-04-07T02:47:48.840707926Z","hd":{"ts_event":"2026-04-07T02:47:48.840687271Z","rtype":160,"publisher_id":101,"instrument_id":436},"action":"A","side":"A","price":"1.156780000","size":30,"channel_id":23,"order_id":"1775530068840693562","flags":128,"ts_in_delta":912,"sequence":171734,"symbol":"FCEU SI 20260615 PS"}
{"ts_recv":"2026-04-07T02:47:48.840766022Z","hd":{"ts_event":"2026-04-07T02:47:48.840744991Z","rtype":160,"publisher_id":101,"instrument_id":436},"action":"C","side":"B","price":"1.156670000","size":30,"channel_id":23,"order_id":"10998902105695414522","flags":0,"ts_in_delta":839,"sequence":171735,"symbol":"FCEU SI 20260615 PS"}
{"ts_recv":"2026-04-07T02:47:48.840766022Z","hd":{"ts_event":"2026-04-07T02:47:48.840744991Z","rtype":160,"publisher_id":101,"instrument_id":436},"action":"A","side":"B","price":"1.156680000","size":30,"channel_id":23,"order_id":"10998902105695526688","flags":0,"ts_in_delta":839,"sequence":171735,"symbol":"FCEU SI 20260615 PS"}
{"ts_recv":"2026-04-07T02:47:48.840766022Z","hd":{"ts_event":"2026-04-07T02:47:48.840744991Z","rtype":160,"publisher_id":101,"instrument_id":436},"action":"C","side":"A","price":"1.156770000","size":30,"channel_id":23,"order_id":"1775530068840638714","flags":0,"ts_in_delta":839,"sequence":171735,"symbol":"FCEU SI 20260615 PS"}
{"ts_recv":"2026-04-07T02:47:48.840766022Z","hd":{"ts_event":"2026-04-07T02:47:48.840744991Z","rtype":160,"publisher_id":101,"instrument_id":436},"action":"A","side":"A","price":"1.156780000","size":30,"channel_id":23,"order_id":"1775530068840750880","flags":128,"ts_in_delta":839,"sequence":171735,"symbol":"FCEU SI 20260615 PS"}
{"ts_recv":"2026-04-07T02:48:03.856603776Z","hd":{"ts_event":"2026-04-07T02:48:03.856570787Z","rtype":160,"publisher_id":101,"instrument_id":436},"action":"C","side":"B","price":"1.156680000","size":30,"channel_id":23,"order_id":"10998902105695526688","flags":0,"ts_in_delta":1424,"sequence":171845,"symbol":"FCEU SI 20260615 PS"}
{"ts_recv":"2026-04-07T02:48:03.856603776Z","hd":{"ts_event":"2026-04-07T02:48:03.856570787Z","rtype":160,"publisher_id":101,"instrument_id":436},"action":"A","side":"B","price":"1.156690000","size":30,"channel_id":23,"order_id":"10998902120711359863","flags":0,"ts_in_delta":1424,"sequence":171845,"symbol":"FCEU SI 20260615 PS"}
{"ts_recv":"2026-04-07T02:48:03.856603776Z","hd":{"ts_event":"2026-04-07T02:48:03.856570787Z","rtype":160,"publisher_id":101,"instrument_id":436},"action":"C","side":"A","price":"1.156780000","size":30,"channel_id":23,"order_id":"1775530068840750880","flags":0,"ts_in_delta":1424,"sequence":171845,"symbol":"FCEU SI 20260615 PS"}
{"ts_recv":"2026-04-07T02:48:03.856603776Z","hd":{"ts_event":"2026-04-07T02:48:03.856570787Z","rtype":160,"publisher_id":101,"instrument_id":436},"action":"A","side":"A","price":"1.156790000","size":30,"channel_id":23,"order_id":"1775530083856584055","flags":128,"ts_in_delta":1424,"sequence":171845,"symbol":"FCEU SI 20260615 PS"}
{"ts_recv":"2026-04-07T02:48:03.856679805Z","hd":{"ts_event":"2026-04-07T02:48:03.856661145Z","rtype":160,"publisher_id":101,"instrument_id":436},"action":"C","side":"B","price":"1.156680000","size":30,"channel_id":23,"order_id":"10998902105695469370","flags":0,"ts_in_delta":964,"sequence":171846,"symbol":"FCEU SI 20260615 PS"}
{"ts_recv":"2026-04-07T02:48:03.856679805Z","hd":{"ts_event":"2026-04-07T02:48:03.856661145Z","rtype":160,"publisher_id":101,"instrument_id":436},"action":"A","side":"B","price":"1.156700000","size":30,"channel_id":23,"order_id":"10998902120711442849","flags":0,"ts_in_delta":964,"sequence":171846,"symbol":"FCEU SI 20260615 PS"}
{"ts_recv":"2026-04-07T02:48:03.856679805Z","hd":{"ts_event":"2026-04-07T02:48:03.856661145Z","rtype":160,"publisher_id":101,"instrument_id":436},"action":"C","side":"A","price":"1.156780000","size":30,"channel_id":23,"order_id":"1775530068840693562","flags":0,"ts_in_delta":964,"sequence":171846,"symbol":"FCEU SI 20260615 PS"}
{"ts_recv":"2026-04-07T02:48:03.856679805Z","hd":{"ts_event":"2026-04-07T02:48:03.856661145Z","rtype":160,"publisher_id":101,"instrument_id":436},"action":"A","side":"A","price":"1.156800000","size":30,"channel_id":23,"order_id":"1775530083856667041","flags":128,"ts_in_delta":964,"sequence":171846,"symbol":"FCEU SI 20260615 PS"}
{"ts_recv":"2026-04-07T02:48:03.856708427Z","hd":{"ts_event":"2026-04-07T02:48:03.856686099Z","rtype":160,"publisher_id":101,"instrument_id":436},"action":"C","side":"B","price":"1.156690000","size":30,"channel_id":23,"order_id":"10998902120711359863","flags":0,"ts_in_delta":919,"sequence":171847,"symbol":"FCEU SI 20260615 PS"}
{"ts_recv":"2026-04-07T02:48:03.856708427Z","hd":{"ts_event":"2026-04-07T02:48:03.856686099Z","rtype":160,"publisher_id":101,"instrument_id":436},"action":"A","side":"B","price":"1.156700000","size":30,"channel_id":23,"order_id":"10998902120711468241","flags":0,"ts_in_delta":919,"sequence":171847,"symbol":"FCEU SI 20260615 PS"}
{"ts_recv":"2026-04-07T02:48:03.856708427Z","hd":{"ts_event":"2026-04-07T02:48:03.856686099Z","rtype":160,"publisher_id":101,"instrument_id":436},"action":"C","side":"A","price":"1.156790000","size":30,"channel_id":23,"order_id":"1775530083856584055","flags":0,"ts_in_delta":919,"sequence":171847,"symbol":"FCEU SI 20260615 PS"}
{"ts_recv":"2026-04-07T02:48:03.856708427Z","hd":{"ts_event":"2026-04-07T02:48:03.856686099Z","rtype":160,"publisher_id":101,"instrument_id":436},"action":"A","side":"A","price":"1.156800000","size":30,"channel_id":23,"order_id":"1775530083856692433","flags":128,"ts_in_delta":919,"sequence":171847,"symbol":"FCEU SI 20260615 PS"}
{"ts_recv":"2026-04-07T02:48:03.866857680Z","hd":{"ts_event":"2026-04-07T02:48:03.866838147Z","rtype":160,"publisher_id":101,"instrument_id":436},"action":"C","side":"B","price":"1.156700000","size":30,"channel_id":23,"order_id":"10998902120711468241","flags":0,"ts_in_delta":928,"sequence":171857,"symbol":"FCEU SI 20260615 PS"}
{"ts_recv":"2026-04-07T02:48:03.866857680Z","hd":{"ts_event":"2026-04-07T02:48:03.866838147Z","rtype":160,"publisher_id":101,"instrument_id":436},"action":"A","side":"B","price":"1.156710000","size":30,"channel_id":23,"order_id":"10998902120721620334","flags":0,"ts_in_delta":928,"sequence":171857,"symbol":"FCEU SI 20260615 PS"}
{"ts_recv":"2026-04-07T02:48:03.866857680Z","hd":{"ts_event":"2026-04-07T02:48:03.866838147Z","rtype":160,"publisher_id":101,"instrument_id":436},"action":"C","side":"A","price":"1.156800000","size":30,"channel_id":23,"order_id":"1775530083856692433","flags":0,"ts_in_delta":928,"sequence":171857,"symbol":"FCEU SI 20260615 PS"}
{"ts_recv":"2026-04-07T02:48:03.866857680Z","hd":{"ts_event":"2026-04-07T02:48:03.866838147Z","rtype":160,"publisher_id":101,"instrument_id":436},"action":"A","side":"A","price":"1.156810000","size":30,"channel_id":23,"order_id":"1775530083866844526","flags":128,"ts_in_delta":928,"sequence":171857,"symbol":"FCEU SI 20260615 PS"}
{"ts_recv":"2026-04-07T02:48:05.018497582Z","hd":{"ts_event":"2026-04-07T02:48:05.018477821Z","rtype":160,"publisher_id":101,"instrument_id":436},"action":"C","side":"B","price":"1.156710000","size":30,"channel_id":23,"order_id":"10998902120721620334","flags":0,"ts_in_delta":930,"sequence":171905,"symbol":"FCEU SI 20260615 PS"}
{"ts_recv":"2026-04-07T02:48:05.018497582Z","hd":{"ts_event":"2026-04-07T02:48:05.018477821Z","rtype":160,"publisher_id":101,"instrument_id":436},"action":"A","side":"B","price":"1.156700000","size":30,"channel_id":23,"order_id":"10998902121873259837","flags":0,"ts_in_delta":930,"sequence":171905,"symbol":"FCEU SI 20260615 PS"}
{"ts_recv":"2026-04-07T02:48:05.018497582Z","hd":{"ts_event":"2026-04-07T02:48:05.018477821Z","rtype":160,"publisher_id":101,"instrument_id":436},"action":"C","side":"A","price":"1.156810000","size":30,"channel_id":23,"order_id":"1775530083866844526","flags":0,"ts_in_delta":930,"sequence":171905,"symbol":"FCEU SI 20260615 PS"}
{"ts_recv":"2026-04-07T02:48:05.018497582Z","hd":{"ts_event":"2026-04-07T02:48:05.018477821Z","rtype":160,"publisher_id":101,"instrument_id":436},"action":"A","side":"A","price":"1.156800000","size":30,"channel_id":23,"order_id":"1775530085018484029","flags":128,"ts_in_delta":930,"sequence":171905,"symbol":"FCEU SI 20260615 PS"}
{"ts_recv":"2026-04-07T02:48:35.275812701Z","hd":{"ts_event":"2026-04-07T02:48:35.275777773Z","rtype":160,"publisher_id":101,"instrument_id":436},"action":"C","side":"B","price":"1.156700000","size":30,"channel_id":23,"order_id":"10998902121873259837","flags":0,"ts_in_delta":1333,"sequence":172101,"symbol":"FCEU SI 20260615 PS"}
{"ts_recv":"2026-04-07T02:48:35.275812701Z","hd":{"ts_event":"2026-04-07T02:48:35.275777773Z","rtype":160,"publisher_id":101,"instrument_id":436},"action":"A","side":"B","price":"1.156710000","size":30,"channel_id":23,"order_id":"10998902152130567373","flags":0,"ts_in_delta":1333,"sequence":172101,"symbol":"FCEU SI 20260615 PS"}
{"ts_recv":"2026-04-07T02:48:35.275812701Z","hd":{"ts_event":"2026-04-07T02:48:35.275777773Z","rtype":160,"publisher_id":101,"instrument_id":436},"action":"C","side":"A","price":"1.156800000","size":30,"channel_id":23,"order_id":"1775530085018484029","flags":0,"ts_in_delta":1333,"sequence":172101,"symbol":"FCEU SI 20260615 PS"}
{"ts_recv":"2026-04-07T02:48:35.275812701Z","hd":{"ts_event":"2026-04-07T02:48:35.275777773Z","rtype":160,"publisher_id":101,"instrument_id":436},"action":"A","side":"A","price":"1.156810000","size":30,"channel_id":23,"order_id":"1775530115275791565","flags":128,"ts_in_delta":1333,"sequence":172101,"symbol":"FCEU SI 20260615 PS"}
{"ts_recv":"2026-04-07T02:48:35.550460247Z","hd":{"ts_event":"2026-04-07T02:48:35.550439171Z","rtype":160,"publisher_id":101,"instrument_id":436},"action":"C","side":"B","price":"1.156700000","size":30,"channel_id":23,"order_id":"10998902120711442849","flags":0,"ts_in_delta":1003,"sequence":172124,"symbol":"FCEU SI 20260615 PS"}
{"ts_recv":"2026-04-07T02:48:35.550460247Z","hd":{"ts_event":"2026-04-07T02:48:35.550439171Z","rtype":160,"publisher_id":101,"instrument_id":436},"action":"A","side":"B","price":"1.156720000","size":30,"channel_id":23,"order_id":"10998902152405220933","flags":0,"ts_in_delta":1003,"sequence":172124,"symbol":"FCEU SI 20260615 PS"}
{"ts_recv":"2026-04-07T02:48:35.550460247Z","hd":{"ts_event":"2026-04-07T02:48:35.550439171Z","rtype":160,"publisher_id":101,"instrument_id":436},"action":"C","side":"A","price":"1.156800000","size":30,"channel_id":23,"order_id":"1775530083856667041","flags":0,"ts_in_delta":1003,"sequence":172124,"symbol":"FCEU SI 20260615 PS"}
{"ts_recv":"2026-04-07T02:48:35.550460247Z","hd":{"ts_event":"2026-04-07T02:48:35.550439171Z","rtype":160,"publisher_id":101,"instrument_id":436},"action":"A","side":"A","price":"1.156820000","size":30,"channel_id":23,"order_id":"1775530115550445125","flags":128,"ts_in_delta":1003,"sequence":172124,"symbol":"FCEU SI 20260615 PS"}
{"ts_recv":"2026-04-07T02:48:35.550522491Z","hd":{"ts_event":"2026-04-07T02:48:35.550506205Z","rtype":160,"publisher_id":101,"instrument_id":436},"action":"C","side":"B","price":"1.156710000","size":30,"channel_id":23,"order_id":"10998902152130567373","flags":0,"ts_in_delta":1005,"sequence":172125,"symbol":"FCEU SI 20260615 PS"}
{"ts_recv":"2026-04-07T02:48:35.550522491Z","hd":{"ts_event":"2026-04-07T02:48:35.550506205Z","rtype":160,"publisher_id":101,"instrument_id":436},"action":"A","side":"B","price":"1.156720000","size":30,"channel_id":23,"order_id":"10998902152405287804","flags":0,"ts_in_delta":1005,"sequence":172125,"symbol":"FCEU SI 20260615 PS"}
{"ts_recv":"2026-04-07T02:48:35.550522491Z","hd":{"ts_event":"2026-04-07T02:48:35.550506205Z","rtype":160,"publisher_id":101,"instrument_id":436},"action":"C","side":"A","price":"1.156810000","size":30,"channel_id":23,"order_id":"1775530115275791565","flags":0,"ts_in_delta":1005,"sequence":172125,"symbol":"FCEU SI 20260615 PS"}
{"ts_recv":"2026-04-07T02:48:35.550522491Z","hd":{"ts_event":"2026-04-07T02:48:35.550506205Z","rtype":160,"publisher_id":101,"instrument_id":436},"action":"A","side":"A","price":"1.156820000","size":30,"channel_id":23,"order_id":"1775530115550511996","flags":128,"ts_in_delta":1005,"sequence":172125,"symbol":"FCEU SI 20260615 PS"}
{"ts_recv":"2026-04-07T02:49:10.035655333Z","hd":{"ts_event":"2026-04-07T02:49:10.035631707Z","rtype":160,"publisher_id":101,"instrument_id":436},"action":"C","side":"B","price":"1.156720000","size":30,"channel_id":23,"order_id":"10998902152405287804","flags":0,"ts_in_delta":943,"sequence":172369,"symbol":"FCEU SI 20260615 PS"}
{"ts_recv":"2026-04-07T02:49:10.035655333Z","hd":{"ts_event":"2026-04-07T02:49:10.035631707Z","rtype":160,"publisher_id":101,"instrument_id":436},"action":"A","side":"B","price":"1.156730000","size":30,"channel_id":23,"order_id":"10998902186890413639","flags":0,"ts_in_delta":943,"sequence":172369,"symbol":"FCEU SI 20260615 PS"}
{"ts_recv":"2026-04-07T02:49:10.035655333Z","hd":{"ts_event":"2026-04-07T02:49:10.035631707Z","rtype":160,"publisher_id":101,"instrument_id":436},"action":"C","side":"A","price":"1.156820000","size":30,"channel_id":23,"order_id":"1775530115550511996","flags":0,"ts_in_delta":943,"sequence":172369,"symbol":"FCEU SI 20260615 PS"}
{"ts_recv":"2026-04-07T02:49:10.035655333Z","hd":{"ts_event":"2026-04-07T02:49:10.035631707Z","rtype":160,"publisher_id":101,"instrument_id":436},"action":"A","side":"A","price":"1.156830000","size":30,"channel_id":23,"order_id":"1775530150035637831","flags":128,"ts_in_delta":943,"sequence":172369,"symbol":"FCEU SI 20260615 PS"}
{"ts_recv":"2026-04-07T02:49:10.095513135Z","hd":{"ts_event":"2026-04-07T02:49:10.095493223Z","rtype":160,"publisher_id":101,"instrument_id":436},"action":"C","side":"B","price":"1.156730000","size":30,"channel_id":23,"order_id":"10998902186890413639","flags":0,"ts_in_delta":910,"sequence":172386,"symbol":"FCEU SI 20260615 PS"}
{"ts_recv":"2026-04-07T02:49:10.095513135Z","hd":{"ts_event":"2026-04-07T02:49:10.095493223Z","rtype":160,"publisher_id":101,"instrument_id":436},"action":"A","side":"B","price":"1.156720000","size":30,"channel_id":23,"order_id":"10998902186950274894","flags":0,"ts_in_delta":910,"sequence":172386,"symbol":"FCEU SI 20260615 PS"}
{"ts_recv":"2026-04-07T02:49:10.095513135Z","hd":{"ts_event":"2026-04-07T02:49:10.095493223Z","rtype":160,"publisher_id":101,"instrument_id":436},"action":"C","side":"A","price":"1.156830000","size":30,"channel_id":23,"order_id":"1775530150035637831","flags":0,"ts_in_delta":910,"sequence":172386,"symbol":"FCEU SI 20260615 PS"}
{"ts_recv":"2026-04-07T02:49:10.095513135Z","hd":{"ts_event":"2026-04-07T02:49:10.095493223Z","rtype":160,"publisher_id":101,"instrument_id":436},"action":"A","side":"A","price":"1.156820000","size":30,"channel_id":23,"order_id":"1775530150095499086","flags":128,"ts_in_delta":910,"sequence":172386,"symbol":"FCEU SI 20260615 PS"}
{"ts_recv":"2026-04-07T02:49:11.732344316Z","hd":{"ts_event":"2026-04-07T02:49:11.732310741Z","rtype":160,"publisher_id":101,"instrument_id":436},"action":"C","side":"B","price":"1.156720000","size":30,"channel_id":23,"order_id":"10998902186950274894","flags":0,"ts_in_delta":1905,"sequence":172394,"symbol":"FCEU SI 20260615 PS"}
{"ts_recv":"2026-04-07T02:49:11.732344316Z","hd":{"ts_event":"2026-04-07T02:49:11.732310741Z","rtype":160,"publisher_id":101,"instrument_id":436},"action":"A","side":"B","price":"1.156730000","size":30,"channel_id":23,"order_id":"10998902188587099732","flags":0,"ts_in_delta":1905,"sequence":172394,"symbol":"FCEU SI 20260615 PS"}
{"ts_recv":"2026-04-07T02:49:11.732344316Z","hd":{"ts_event":"2026-04-07T02:49:11.732310741Z","rtype":160,"publisher_id":101,"instrument_id":436},"action":"C","side":"A","price":"1.156820000","size":30,"channel_id":23,"order_id":"1775530150095499086","flags":0,"ts_in_delta":1905,"sequence":172394,"symbol":"FCEU SI 20260615 PS"}
{"ts_recv":"2026-04-07T02:49:11.732344316Z","hd":{"ts_event":"2026-04-07T02:49:11.732310741Z","rtype":160,"publisher_id":101,"instrument_id":436},"action":"A","side":"A","price":"1.156830000","size":30,"channel_id":23,"order_id":"1775530151732323924","flags":128,"ts_in_delta":1905,"sequence":172394,"symbol":"FCEU SI 20260615 PS"}
{"ts_recv":"2026-04-07T02:49:11.745489835Z","hd":{"ts_event":"2026-04-07T02:49:11.745469421Z","rtype":160,"publisher_id":101,"instrument_id":436},"action":"C","side":"B","price":"1.156730000","size":30,"channel_id":23,"order_id":"10998902188587099732","flags":0,"ts_in_delta":979,"sequence":172400,"symbol":"FCEU SI 20260615 PS"}
{"ts_recv":"2026-04-07T02:49:11.745489835Z","hd":{"ts_event":"2026-04-07T02:49:11.745469421Z","rtype":160,"publisher_id":101,"instrument_id":436},"action":"A","side":"B","price":"1.156740000","size":30,"channel_id":23,"order_id":"10998902188600251306","flags":0,"ts_in_delta":979,"sequence":172400,"symbol":"FCEU SI 20260615 PS"}
{"ts_recv":"2026-04-07T02:49:11.745489835Z","hd":{"ts_event":"2026-04-07T02:49:11.745469421Z","rtype":160,"publisher_id":101,"instrument_id":436},"action":"C","side":"A","price":"1.156830000","size":30,"channel_id":23,"order_id":"1775530151732323924","flags":0,"ts_in_delta":979,"sequence":172400,"symbol":"FCEU SI 20260615 PS"}
{"ts_recv":"2026-04-07T02:49:11.745489835Z","hd":{"ts_event":"2026-04-07T02:49:11.745469421Z","rtype":160,"publisher_id":101,"instrument_id":436},"action":"A","side":"A","price":"1.156840000","size":30,"channel_id":23,"order_id":"1775530151745475498","flags":128,"ts_in_delta":979,"sequence":172400,"symbol":"FCEU SI 20260615 PS"}
{"ts_recv":"2026-04-07T02:49:11.751869640Z","hd":{"ts_event":"2026-04-07T02:49:11.751852881Z","rtype":160,"publisher_id":101,"instrument_id":436},"action":"C","side":"B","price":"1.156740000","size":30,"channel_id":23,"order_id":"10998902188600251306","flags":0,"ts_in_delta":1184,"sequence":172405,"symbol":"FCEU SI 20260615 PS"}
{"ts_recv":"2026-04-07T02:49:11.751869640Z","hd":{"ts_event":"2026-04-07T02:49:11.751852881Z","rtype":160,"publisher_id":101,"instrument_id":436},"action":"A","side":"B","price":"1.156730000","size":30,"channel_id":23,"order_id":"10998902188606634615","flags":0,"ts_in_delta":1184,"sequence":172405,"symbol":"FCEU SI 20260615 PS"}
{"ts_recv":"2026-04-07T02:49:11.751869640Z","hd":{"ts_event":"2026-04-07T02:49:11.751852881Z","rtype":160,"publisher_id":101,"instrument_id":436},"action":"C","side":"A","price":"1.156840000","size":30,"channel_id":23,"order_id":"1775530151745475498","flags":0,"ts_in_delta":1184,"sequence":172405,"symbol":"FCEU SI 20260615 PS"}
{"ts_recv":"2026-04-07T02:49:11.751869640Z","hd":{"ts_event":"2026-04-07T02:49:11.751852881Z","rtype":160,"publisher_id":101,"instrument_id":436},"action":"A","side":"A","price":"1.156830000","size":30,"channel_id":23,"order_id":"1775530151751858807","flags":128,"ts_in_delta":1184,"sequence":172405,"symbol":"FCEU SI 20260615 PS"}
{"ts_recv":"2026-04-07T02:49:11.838898235Z","hd":{"ts_event":"2026-04-07T02:49:11.838869977Z","rtype":160,"publisher_id":101,"instrument_id":436},"action":"C","side":"B","price":"1.156720000","size":30,"channel_id":23,"order_id":"10998902152405220933","flags":0,"ts_in_delta":1240,"sequence":172416,"symbol":"FCEU SI 20260615 PS"}
{"ts_recv":"2026-04-07T02:49:11.838898235Z","hd":{"ts_event":"2026-04-07T02:49:11.838869977Z","rtype":160,"publisher_id":101,"instrument_id":436},"action":"A","side":"B","price":"1.156750000","size":30,"channel_id":23,"order_id":"10998902188693656572","flags":0,"ts_in_delta":1240,"sequence":172416,"symbol":"FCEU SI 20260615 PS"}
{"ts_recv":"2026-04-07T02:49:11.838898235Z","hd":{"ts_event":"2026-04-07T02:49:11.838869977Z","rtype":160,"publisher_id":101,"instrument_id":436},"action":"C","side":"A","price":"1.156820000","size":30,"channel_id":23,"order_id":"1775530115550445125","flags":0,"ts_in_delta":1240,"sequence":172416,"symbol":"FCEU SI 20260615 PS"}
{"ts_recv":"2026-04-07T02:49:11.838898235Z","hd":{"ts_event":"2026-04-07T02:49:11.838869977Z","rtype":160,"publisher_id":101,"instrument_id":436},"action":"A","side":"A","price":"1.156850000","size":30,"channel_id":23,"order_id":"1775530151838880764","flags":128,"ts_in_delta":1240,"sequence":172416,"symbol":"FCEU SI 20260615 PS"}
{"ts_recv":"2026-04-07T02:49:11.838958013Z","hd":{"ts_event":"2026-04-07T02:49:11.838941171Z","rtype":160,"publisher_id":101,"instrument_id":436},"action":"C","side":"B","price":"1.156730000","size":30,"channel_id":23,"order_id":"10998902188606634615","flags":0,"ts_in_delta":923,"sequence":172417,"symbol":"FCEU SI 20260615 PS"}
{"ts_recv":"2026-04-07T02:49:11.838958013Z","hd":{"ts_event":"2026-04-07T02:49:11.838941171Z","rtype":160,"publisher_id":101,"instrument_id":436},"action":"A","side":"B","price":"1.156750000","size":30,"channel_id":23,"order_id":"10998902188693723205","flags":0,"ts_in_delta":923,"sequence":172417,"symbol":"FCEU SI 20260615 PS"}
{"ts_recv":"2026-04-07T02:49:11.838958013Z","hd":{"ts_event":"2026-04-07T02:49:11.838941171Z","rtype":160,"publisher_id":101,"instrument_id":436},"action":"C","side":"A","price":"1.156830000","size":30,"channel_id":23,"order_id":"1775530151751858807","flags":0,"ts_in_delta":923,"sequence":172417,"symbol":"FCEU SI 20260615 PS"}
{"ts_recv":"2026-04-07T02:49:11.838958013Z","hd":{"ts_event":"2026-04-07T02:49:11.838941171Z","rtype":160,"publisher_id":101,"instrument_id":436},"action":"A","side":"A","price":"1.156850000","size":30,"channel_id":23,"order_id":"1775530151838947397","flags":128,"ts_in_delta":923,"sequence":172417,"symbol":"FCEU SI 20260615 PS"}
{"ts_recv":"2026-04-07T02:49:11.844124159Z","hd":{"ts_event":"2026-04-07T02:49:11.844104427Z","rtype":160,"publisher_id":101,"instrument_id":436},"action":"C","side":"B","price":"1.156750000","size":30,"channel_id":23,"order_id":"10998902188693723205","flags":0,"ts_in_delta":960,"sequence":172420,"symbol":"FCEU SI 20260615 PS"}
{"ts_recv":"2026-04-07T02:49:11.844124159Z","hd":{"ts_event":"2026-04-07T02:49:11.844104427Z","rtype":160,"publisher_id":101,"instrument_id":436},"action":"A","side":"B","price":"1.156760000","size":30,"channel_id":23,"order_id":"10998902188698886207","flags":0,"ts_in_delta":960,"sequence":172420,"symbol":"FCEU SI 20260615 PS"}
{"ts_recv":"2026-04-07T02:49:11.844124159Z","hd":{"ts_event":"2026-04-07T02:49:11.844104427Z","rtype":160,"publisher_id":101,"instrument_id":436},"action":"C","side":"A","price":"1.156850000","size":30,"channel_id":23,"order_id":"1775530151838947397","flags":0,"ts_in_delta":960,"sequence":172420,"symbol":"FCEU SI 20260615 PS"}
{"ts_recv":"2026-04-07T02:49:11.844124159Z","hd":{"ts_event":"2026-04-07T02:49:11.844104427Z","rtype":160,"publisher_id":101,"instrument_id":436},"action":"A","side":"A","price":"1.156860000","size":30,"channel_id":23,"order_id":"1775530151844110399","flags":128,"ts_in_delta":960,"sequence":172420,"symbol":"FCEU SI 20260615 PS"}
{"ts_recv":"2026-04-07T02:49:11.846730200Z","hd":{"ts_event":"2026-04-07T02:49:11.846714565Z","rtype":160,"publisher_id":101,"instrument_id":436},"action":"C","side":"A","price":"1.156900000","size":20,"channel_id":23,"order_id":"1775529426663689821","flags":128,"ts_in_delta":1097,"sequence":172421,"symbol":"FCEU SI 20260615 PS"}
{"ts_recv":"2026-04-07T02:49:11.850924017Z","hd":{"ts_event":"2026-04-07T02:49:11.850904689Z","rtype":160,"publisher_id":101,"instrument_id":436},"action":"C","side":"B","price":"1.156750000","size":30,"channel_id":23,"order_id":"10998902188693656572","flags":0,"ts_in_delta":914,"sequence":172422,"symbol":"FCEU SI 20260615 PS"}
{"ts_recv":"2026-04-07T02:49:11.850924017Z","hd":{"ts_event":"2026-04-07T02:49:11.850904689Z","rtype":160,"publisher_id":101,"instrument_id":436},"action":"A","side":"B","price":"1.156770000","size":30,"channel_id":23,"order_id":"10998902188705686573","flags":0,"ts_in_delta":914,"sequence":172422,"symbol":"FCEU SI 20260615 PS"}
{"ts_recv":"2026-04-07T02:49:11.850924017Z","hd":{"ts_event":"2026-04-07T02:49:11.850904689Z","rtype":160,"publisher_id":101,"instrument_id":436},"action":"C","side":"A","price":"1.156850000","size":30,"channel_id":23,"order_id":"1775530151838880764","flags":0,"ts_in_delta":914,"sequence":172422,"symbol":"FCEU SI 20260615 PS"}
{"ts_recv":"2026-04-07T02:49:11.850924017Z","hd":{"ts_event":"2026-04-07T02:49:11.850904689Z","rtype":160,"publisher_id":101,"instrument_id":436},"action":"A","side":"A","price":"1.156870000","size":30,"channel_id":23,"order_id":"1775530151850910765","flags":128,"ts_in_delta":914,"sequence":172422,"symbol":"FCEU SI 20260615 PS"}
{"ts_recv":"2026-04-07T02:49:11.850979663Z","hd":{"ts_event":"2026-04-07T02:49:11.850961823Z","rtype":160,"publisher_id":101,"instrument_id":436},"action":"C","side":"B","price":"1.156760000","size":30,"channel_id":23,"order_id":"10998902188698886207","flags":0,"ts_in_delta":928,"sequence":172423,"symbol":"FCEU SI 20260615 PS"}
{"ts_recv":"2026-04-07T02:49:11.850979663Z","hd":{"ts_event":"2026-04-07T02:49:11.850961823Z","rtype":160,"publisher_id":101,"instrument_id":436},"action":"A","side":"B","price":"1.156770000","size":30,"channel_id":23,"order_id":"10998902188705743707","flags":0,"ts_in_delta":928,"sequence":172423,"symbol":"FCEU SI 20260615 PS"}
{"ts_recv":"2026-04-07T02:49:11.850979663Z","hd":{"ts_event":"2026-04-07T02:49:11.850961823Z","rtype":160,"publisher_id":101,"instrument_id":436},"action":"C","side":"A","price":"1.156860000","size":30,"channel_id":23,"order_id":"1775530151844110399","flags":0,"ts_in_delta":928,"sequence":172423,"symbol":"FCEU SI 20260615 PS"}
{"ts_recv":"2026-04-07T02:49:11.850979663Z","hd":{"ts_event":"2026-04-07T02:49:11.850961823Z","rtype":160,"publisher_id":101,"instrument_id":436},"action":"A","side":"A","price":"1.156870000","size":30,"channel_id":23,"order_id":"1775530151850967899","flags":128,"ts_in_delta":928,"sequence":172423,"symbol":"FCEU SI 20260615 PS"}
{"ts_recv":"2026-04-07T02:49:11.889451653Z","hd":{"ts_event":"2026-04-07T02:49:11.889436563Z","rtype":160,"publisher_id":101,"instrument_id":436},"action":"A","side":"A","price":"1.157100000","size":20,"channel_id":23,"order_id":"1775530151889442796","flags":128,"ts_in_delta":1038,"sequence":172429,"symbol":"FCEU SI 20260615 PS"}
{"ts_recv":"2026-04-07T02:49:16.002852579Z","hd":{"ts_event":"2026-04-07T02:49:16.002832519Z","rtype":160,"publisher_id":101,"instrument_id":436},"action":"C","side":"B","price":"1.156770000","size":30,"channel_id":23,"order_id":"10998902188705743707","flags":0,"ts_in_delta":795,"sequence":172487,"symbol":"FCEU SI 20260615 PS"}
{"ts_recv":"2026-04-07T02:49:16.002852579Z","hd":{"ts_event":"2026-04-07T02:49:16.002832519Z","rtype":160,"publisher_id":101,"instrument_id":436},"action":"A","side":"B","price":"1.156780000","size":30,"channel_id":23,"order_id":"10998902192857614337","flags":0,"ts_in_delta":795,"sequence":172487,"symbol":"FCEU SI 20260615 PS"}
{"ts_recv":"2026-04-07T02:49:16.002852579Z","hd":{"ts_event":"2026-04-07T02:49:16.002832519Z","rtype":160,"publisher_id":101,"instrument_id":436},"action":"C","side":"A","price":"1.156870000","size":30,"channel_id":23,"order_id":"1775530151850967899","flags":0,"ts_in_delta":795,"sequence":172487,"symbol":"FCEU SI 20260615 PS"}
{"ts_recv":"2026-04-07T02:49:16.002852579Z","hd":{"ts_event":"2026-04-07T02:49:16.002832519Z","rtype":160,"publisher_id":101,"instrument_id":436},"action":"A","side":"A","price":"1.156880000","size":30,"channel_id":23,"order_id":"1775530156002838529","flags":128,"ts_in_delta":795,"sequence":172487,"symbol":"FCEU SI 20260615 PS"}
{"ts_recv":"2026-04-07T02:49:16.145116138Z","hd":{"ts_event":"2026-04-07T02:49:16.145095663Z","rtype":160,"publisher_id":101,"instrument_id":436},"action":"C","side":"B","price":"1.156770000","size":30,"channel_id":23,"order_id":"10998902188705686573","flags":0,"ts_in_delta":805,"sequence":172503,"symbol":"FCEU SI 20260615 PS"}
{"ts_recv":"2026-04-07T02:49:16.145116138Z","hd":{"ts_event":"2026-04-07T02:49:16.145095663Z","rtype":160,"publisher_id":101,"instrument_id":436},"action":"A","side":"B","price":"1.156790000","size":30,"channel_id":23,"order_id":"10998902192999877454","flags":0,"ts_in_delta":805,"sequence":172503,"symbol":"FCEU SI 20260615 PS"}
{"ts_recv":"2026-04-07T02:49:16.145116138Z","hd":{"ts_event":"2026-04-07T02:49:16.145095663Z","rtype":160,"publisher_id":101,"instrument_id":436},"action":"C","side":"A","price":"1.156870000","size":30,"channel_id":23,"order_id":"1775530151850910765","flags":0,"ts_in_delta":805,"sequence":172503,"symbol":"FCEU SI 20260615 PS"}
{"ts_recv":"2026-04-07T02:49:16.145116138Z","hd":{"ts_event":"2026-04-07T02:49:16.145095663Z","rtype":160,"publisher_id":101,"instrument_id":436},"action":"A","side":"A","price":"1.156890000","size":30,"channel_id":23,"order_id":"1775530156145101646","flags":128,"ts_in_delta":805,"sequence":172503,"symbol":"FCEU SI 20260615 PS"}
{"ts_recv":"2026-04-07T02:49:16.145184172Z","hd":{"ts_event":"2026-04-07T02:49:16.145164767Z","rtype":160,"publisher_id":101,"instrument_id":436},"action":"C","side":"B","price":"1.156780000","size":30,"channel_id":23,"order_id":"10998902192857614337","flags":0,"ts_in_delta":819,"sequence":172504,"symbol":"FCEU SI 20260615 PS"}
{"ts_recv":"2026-04-07T02:49:16.145184172Z","hd":{"ts_event":"2026-04-07T02:49:16.145164767Z","rtype":160,"publisher_id":101,"instrument_id":436},"action":"A","side":"B","price":"1.156790000","size":30,"channel_id":23,"order_id":"10998902192999946614","flags":0,"ts_in_delta":819,"sequence":172504,"symbol":"FCEU SI 20260615 PS"}
{"ts_recv":"2026-04-07T02:49:16.145184172Z","hd":{"ts_event":"2026-04-07T02:49:16.145164767Z","rtype":160,"publisher_id":101,"instrument_id":436},"action":"C","side":"A","price":"1.156880000","size":30,"channel_id":23,"order_id":"1775530156002838529","flags":0,"ts_in_delta":819,"sequence":172504,"symbol":"FCEU SI 20260615 PS"}
{"ts_recv":"2026-04-07T02:49:16.145184172Z","hd":{"ts_event":"2026-04-07T02:49:16.145164767Z","rtype":160,"publisher_id":101,"instrument_id":436},"action":"A","side":"A","price":"1.156890000","size":30,"channel_id":23,"order_id":"1775530156145170806","flags":128,"ts_in_delta":819,"sequence":172504,"symbol":"FCEU SI 20260615 PS"}
{"ts_recv":"2026-04-07T02:49:16.585659131Z","hd":{"ts_event":"2026-04-07T02:49:16.585638373Z","rtype":160,"publisher_id":101,"instrument_id":436},"action":"C","side":"B","price":"1.156790000","size":30,"channel_id":23,"order_id":"10998902192999946614","flags":0,"ts_in_delta":787,"sequence":172515,"symbol":"FCEU SI 20260615 PS"}
{"ts_recv":"2026-04-07T02:49:16.585659131Z","hd":{"ts_event":"2026-04-07T02:49:16.585638373Z","rtype":160,"publisher_id":101,"instrument_id":436},"action":"A","side":"B","price":"1.156800000","size":30,"channel_id":23,"order_id":"10998902193440420240","flags":0,"ts_in_delta":787,"sequence":172515,"symbol":"FCEU SI 20260615 PS"}
{"ts_recv":"2026-04-07T02:49:16.585659131Z","hd":{"ts_event":"2026-04-07T02:49:16.585638373Z","rtype":160,"publisher_id":101,"instrument_id":436},"action":"C","side":"A","price":"1.156890000","size":30,"channel_id":23,"order_id":"1775530156145170806","flags":0,"ts_in_delta":787,"sequence":172515,"symbol":"FCEU SI 20260615 PS"}
{"ts_recv":"2026-04-07T02:49:16.585659131Z","hd":{"ts_event":"2026-04-07T02:49:16.585638373Z","rtype":160,"publisher_id":101,"instrument_id":436},"action":"A","side":"A","price":"1.156900000","size":30,"channel_id":23,"order_id":"1775530156585644432","flags":128,"ts_in_delta":787,"sequence":172515,"symbol":"FCEU SI 20260615 PS"}
{"ts_recv":"2026-04-07T02:49:16.585745296Z","hd":{"ts_event":"2026-04-07T02:49:16.585725965Z","rtype":160,"publisher_id":101,"instrument_id":436},"action":"C","side":"B","price":"1.156800000","size":30,"channel_id":23,"order_id":"10998902193440420240","flags":0,"ts_in_delta":791,"sequence":172516,"symbol":"FCEU SI 20260615 PS"}
{"ts_recv":"2026-04-07T02:49:16.585745296Z","hd":{"ts_event":"2026-04-07T02:49:16.585725965Z","rtype":160,"publisher_id":101,"instrument_id":436},"action":"A","side":"B","price":"1.156810000","size":30,"channel_id":23,"order_id":"10998902193440508041","flags":0,"ts_in_delta":791,"sequence":172516,"symbol":"FCEU SI 20260615 PS"}
{"ts_recv":"2026-04-07T02:49:16.585745296Z","hd":{"ts_event":"2026-04-07T02:49:16.585725965Z","rtype":160,"publisher_id":101,"instrument_id":436},"action":"C","side":"A","price":"1.156900000","size":30,"channel_id":23,"order_id":"1775530156585644432","flags":0,"ts_in_delta":791,"sequence":172516,"symbol":"FCEU SI 20260615 PS"}
{"ts_recv":"2026-04-07T02:49:16.585745296Z","hd":{"ts_event":"2026-04-07T02:49:16.585725965Z","rtype":160,"publisher_id":101,"instrument_id":436},"action":"A","side":"A","price":"1.156910000","size":30,"channel_id":23,"order_id":"1775530156585732233","flags":128,"ts_in_delta":791,"sequence":172516,"symbol":"FCEU SI 20260615 PS"}
{"ts_recv":"2026-04-07T02:49:16.585802318Z","hd":{"ts_event":"2026-04-07T02:49:16.585785541Z","rtype":160,"publisher_id":101,"instrument_id":436},"action":"C","side":"B","price":"1.156810000","size":30,"channel_id":23,"order_id":"10998902193440508041","flags":0,"ts_in_delta":776,"sequence":172517,"symbol":"FCEU SI 20260615 PS"}
{"ts_recv":"2026-04-07T02:49:16.585802318Z","hd":{"ts_event":"2026-04-07T02:49:16.585785541Z","rtype":160,"publisher_id":101,"instrument_id":436},"action":"A","side":"B","price":"1.156800000","size":30,"channel_id":23,"order_id":"10998902193440567298","flags":0,"ts_in_delta":776,"sequence":172517,"symbol":"FCEU SI 20260615 PS"}
{"ts_recv":"2026-04-07T02:49:16.585802318Z","hd":{"ts_event":"2026-04-07T02:49:16.585785541Z","rtype":160,"publisher_id":101,"instrument_id":436},"action":"C","side":"A","price":"1.156910000","size":30,"channel_id":23,"order_id":"1775530156585732233","flags":0,"ts_in_delta":776,"sequence":172517,"symbol":"FCEU SI 20260615 PS"}
{"ts_recv":"2026-04-07T02:49:16.585802318Z","hd":{"ts_event":"2026-04-07T02:49:16.585785541Z","rtype":160,"publisher_id":101,"instrument_id":436},"action":"A","side":"A","price":"1.156900000","size":30,"channel_id":23,"order_id":"1775530156585791490","flags":128,"ts_in_delta":776,"sequence":172517,"symbol":"FCEU SI 20260615 PS"}
{"ts_recv":"2026-04-07T02:49:16.740463888Z","hd":{"ts_event":"2026-04-07T02:49:16.740445453Z","rtype":160,"publisher_id":101,"instrument_id":436},"action":"C","side":"B","price":"1.156800000","size":30,"channel_id":23,"order_id":"10998902193440567298","flags":0,"ts_in_delta":1123,"sequence":172537,"symbol":"FCEU SI 20260615 PS"}
{"ts_recv":"2026-04-07T02:49:16.740463888Z","hd":{"ts_event":"2026-04-07T02:49:16.740445453Z","rtype":160,"publisher_id":101,"instrument_id":436},"action":"A","side":"B","price":"1.156790000","size":30,"channel_id":23,"order_id":"10998902193595227193","flags":0,"ts_in_delta":1123,"sequence":172537,"symbol":"FCEU SI 20260615 PS"}
{"ts_recv":"2026-04-07T02:49:16.740463888Z","hd":{"ts_event":"2026-04-07T02:49:16.740445453Z","rtype":160,"publisher_id":101,"instrument_id":436},"action":"C","side":"A","price":"1.156900000","size":30,"channel_id":23,"order_id":"1775530156585791490","flags":0,"ts_in_delta":1123,"sequence":172537,"symbol":"FCEU SI 20260615 PS"}
{"ts_recv":"2026-04-07T02:49:16.740463888Z","hd":{"ts_event":"2026-04-07T02:49:16.740445453Z","rtype":160,"publisher_id":101,"instrument_id":436},"action":"A","side":"A","price":"1.156890000","size":30,"channel_id":23,"order_id":"1775530156740451385","flags":128,"ts_in_delta":1123,"sequence":172537,"symbol":"FCEU SI 20260615 PS"}
{"ts_recv":"2026-04-07T02:49:22.396698581Z","hd":{"ts_event":"2026-04-07T02:49:22.396678817Z","rtype":160,"publisher_id":101,"instrument_id":436},"action":"C","side":"B","price":"1.156790000","size":30,"channel_id":23,"order_id":"10998902193595227193","flags":0,"ts_in_delta":933,"sequence":172586,"symbol":"FCEU SI 20260615 PS"}
{"ts_recv":"2026-04-07T02:49:22.396698581Z","hd":{"ts_event":"2026-04-07T02:49:22.396678817Z","rtype":160,"publisher_id":101,"instrument_id":436},"action":"A","side":"B","price":"1.156780000","size":30,"channel_id":23,"order_id":"10998902199251460660","flags":0,"ts_in_delta":933,"sequence":172586,"symbol":"FCEU SI 20260615 PS"}
{"ts_recv":"2026-04-07T02:49:22.396698581Z","hd":{"ts_event":"2026-04-07T02:49:22.396678817Z","rtype":160,"publisher_id":101,"instrument_id":436},"action":"C","side":"A","price":"1.156890000","size":30,"channel_id":23,"order_id":"1775530156740451385","flags":0,"ts_in_delta":933,"sequence":172586,"symbol":"FCEU SI 20260615 PS"}
{"ts_recv":"2026-04-07T02:49:22.396698581Z","hd":{"ts_event":"2026-04-07T02:49:22.396678817Z","rtype":160,"publisher_id":101,"instrument_id":436},"action":"A","side":"A","price":"1.156880000","size":30,"channel_id":23,"order_id":"1775530162396684852","flags":128,"ts_in_delta":933,"sequence":172586,"symbol":"FCEU SI 20260615 PS"}
{"ts_recv":"2026-04-07T02:49:26.131191732Z","hd":{"ts_event":"2026-04-07T02:49:26.131171029Z","rtype":160,"publisher_id":101,"instrument_id":436},"action":"C","side":"B","price":"1.156790000","size":30,"channel_id":23,"order_id":"10998902192999877454","flags":0,"ts_in_delta":778,"sequence":172622,"symbol":"FCEU SI 20260615 PS"}
{"ts_recv":"2026-04-07T02:49:26.131191732Z","hd":{"ts_event":"2026-04-07T02:49:26.131171029Z","rtype":160,"publisher_id":101,"instrument_id":436},"action":"A","side":"B","price":"1.156770000","size":30,"channel_id":23,"order_id":"10998902202985953079","flags":0,"ts_in_delta":778,"sequence":172622,"symbol":"FCEU SI 20260615 PS"}
{"ts_recv":"2026-04-07T02:49:26.131191732Z","hd":{"ts_event":"2026-04-07T02:49:26.131171029Z","rtype":160,"publisher_id":101,"instrument_id":436},"action":"C","side":"A","price":"1.156890000","size":30,"channel_id":23,"order_id":"1775530156145101646","flags":0,"ts_in_delta":778,"sequence":172622,"symbol":"FCEU SI 20260615 PS"}
{"ts_recv":"2026-04-07T02:49:26.131191732Z","hd":{"ts_event":"2026-04-07T02:49:26.131171029Z","rtype":160,"publisher_id":101,"instrument_id":436},"action":"A","side":"A","price":"1.156870000","size":30,"channel_id":23,"order_id":"1775530166131177271","flags":128,"ts_in_delta":778,"sequence":172622,"symbol":"FCEU SI 20260615 PS"}
{"ts_recv":"2026-04-07T02:49:26.131269496Z","hd":{"ts_event":"2026-04-07T02:49:26.131252737Z","rtype":160,"publisher_id":101,"instrument_id":436},"action":"C","side":"B","price":"1.156780000","size":30,"channel_id":23,"order_id":"10998902199251460660","flags":0,"ts_in_delta":943,"sequence":172623,"symbol":"FCEU SI 20260615 PS"}
{"ts_recv":"2026-04-07T02:49:26.131269496Z","hd":{"ts_event":"2026-04-07T02:49:26.131252737Z","rtype":160,"publisher_id":101,"instrument_id":436},"action":"A","side":"B","price":"1.156770000","size":30,"channel_id":23,"order_id":"10998902202986034786","flags":0,"ts_in_delta":943,"sequence":172623,"symbol":"FCEU SI 20260615 PS"}
{"ts_recv":"2026-04-07T02:49:26.131269496Z","hd":{"ts_event":"2026-04-07T02:49:26.131252737Z","rtype":160,"publisher_id":101,"instrument_id":436},"action":"C","side":"A","price":"1.156880000","size":30,"channel_id":23,"order_id":"1775530162396684852","flags":0,"ts_in_delta":943,"sequence":172623,"symbol":"FCEU SI 20260615 PS"}
{"ts_recv":"2026-04-07T02:49:26.131269496Z","hd":{"ts_event":"2026-04-07T02:49:26.131252737Z","rtype":160,"publisher_id":101,"instrument_id":436},"action":"A","side":"A","price":"1.156870000","size":30,"channel_id":23,"order_id":"1775530166131258978","flags":128,"ts_in_delta":943,"sequence":172623,"symbol":"FCEU SI 20260615 PS"}
{"ts_recv":"2026-04-07T02:49:26.435384948Z","hd":{"ts_event":"2026-04-07T02:49:26.435363435Z","rtype":160,"publisher_id":101,"instrument_id":436},"action":"C","side":"B","price":"1.156770000","size":30,"channel_id":23,"order_id":"10998902202986034786","flags":0,"ts_in_delta":1079,"sequence":172644,"symbol":"FCEU SI 20260615 PS"}
{"ts_recv":"2026-04-07T02:49:26.435384948Z","hd":{"ts_event":"2026-04-07T02:49:26.435363435Z","rtype":160,"publisher_id":101,"instrument_id":436},"action":"A","side":"B","price":"1.156780000","size":30,"channel_id":23,"order_id":"10998902203290145167","flags":0,"ts_in_delta":1079,"sequence":172644,"symbol":"FCEU SI 20260615 PS"}
{"ts_recv":"2026-04-07T02:49:26.435384948Z","hd":{"ts_event":"2026-04-07T02:49:26.435363435Z","rtype":160,"publisher_id":101,"instrument_id":436},"action":"C","side":"A","price":"1.156870000","size":30,"channel_id":23,"order_id":"1775530166131258978","flags":0,"ts_in_delta":1079,"sequence":172644,"symbol":"FCEU SI 20260615 PS"}
{"ts_recv":"2026-04-07T02:49:26.435384948Z","hd":{"ts_event":"2026-04-07T02:49:26.435363435Z","rtype":160,"publisher_id":101,"instrument_id":436},"action":"A","side":"A","price":"1.156880000","size":30,"channel_id":23,"order_id":"1775530166435369359","flags":128,"ts_in_delta":1079,"sequence":172644,"symbol":"FCEU SI 20260615 PS"}
{"ts_recv":"2026-04-07T02:49:26.435465983Z","hd":{"ts_event":"2026-04-07T02:49:26.435447127Z","rtype":160,"publisher_id":101,"instrument_id":436},"action":"C","side":"B","price":"1.156780000","size":30,"channel_id":23,"order_id":"10998902203290145167","flags":0,"ts_in_delta":922,"sequence":172645,"symbol":"FCEU SI 20260615 PS"}
{"ts_recv":"2026-04-07T02:49:26.435465983Z","hd":{"ts_event":"2026-04-07T02:49:26.435447127Z","rtype":160,"publisher_id":101,"instrument_id":436},"action":"A","side":"B","price":"1.156790000","size":30,"channel_id":23,"order_id":"10998902203290228715","flags":0,"ts_in_delta":922,"sequence":172645,"symbol":"FCEU SI 20260615 PS"}
{"ts_recv":"2026-04-07T02:49:26.435465983Z","hd":{"ts_event":"2026-04-07T02:49:26.435447127Z","rtype":160,"publisher_id":101,"instrument_id":436},"action":"C","side":"A","price":"1.156880000","size":30,"channel_id":23,"order_id":"1775530166435369359","flags":0,"ts_in_delta":922,"sequence":172645,"symbol":"FCEU SI 20260615 PS"}
{"ts_recv":"2026-04-07T02:49:26.435465983Z","hd":{"ts_event":"2026-04-07T02:49:26.435447127Z","rtype":160,"publisher_id":101,"instrument_id":436},"action":"A","side":"A","price":"1.156890000","size":30,"channel_id":23,"order_id":"1775530166435452907","flags":128,"ts_in_delta":922,"sequence":172645,"symbol":"FCEU SI 20260615 PS"}
{"ts_recv":"2026-04-07T02:49:26.435517752Z","hd":{"ts_event":"2026-04-07T02:49:26.435499121Z","rtype":160,"publisher_id":101,"instrument_id":436},"action":"C","side":"B","price":"1.156770000","size":30,"channel_id":23,"order_id":"10998902202985953079","flags":0,"ts_in_delta":908,"sequence":172646,"symbol":"FCEU SI 20260615 PS"}
{"ts_recv":"2026-04-07T02:49:26.435517752Z","hd":{"ts_event":"2026-04-07T02:49:26.435499121Z","rtype":160,"publisher_id":101,"instrument_id":436},"action":"A","side":"B","price":"1.156790000","size":30,"channel_id":23,"order_id":"10998902203290281430","flags":0,"ts_in_delta":908,"sequence":172646,"symbol":"FCEU SI 20260615 PS"}
{"ts_recv":"2026-04-07T02:49:26.435517752Z","hd":{"ts_event":"2026-04-07T02:49:26.435499121Z","rtype":160,"publisher_id":101,"instrument_id":436},"action":"C","side":"A","price":"1.156870000","size":30,"channel_id":23,"order_id":"1775530166131177271","flags":0,"ts_in_delta":908,"sequence":172646,"symbol":"FCEU SI 20260615 PS"}
{"ts_recv":"2026-04-07T02:49:26.435517752Z","hd":{"ts_event":"2026-04-07T02:49:26.435499121Z","rtype":160,"publisher_id":101,"instrument_id":436},"action":"A","side":"A","price":"1.156890000","size":30,"channel_id":23,"order_id":"1775530166435505622","flags":128,"ts_in_delta":908,"sequence":172646,"symbol":"FCEU SI 20260615 PS"}
{"ts_recv":"2026-04-07T02:49:26.435527682Z","hd":{"ts_event":"2026-04-07T02:49:26.435505421Z","rtype":160,"publisher_id":101,"instrument_id":436},"action":"C","side":"B","price":"1.156790000","size":30,"channel_id":23,"order_id":"10998902203290228715","flags":0,"ts_in_delta":1110,"sequence":172647,"symbol":"FCEU SI 20260615 PS"}
{"ts_recv":"2026-04-07T02:49:26.435527682Z","hd":{"ts_event":"2026-04-07T02:49:26.435505421Z","rtype":160,"publisher_id":101,"instrument_id":436},"action":"A","side":"B","price":"1.156780000","size":30,"channel_id":23,"order_id":"10998902203290290201","flags":0,"ts_in_delta":1110,"sequence":172647,"symbol":"FCEU SI 20260615 PS"}
{"ts_recv":"2026-04-07T02:49:26.435527682Z","hd":{"ts_event":"2026-04-07T02:49:26.435505421Z","rtype":160,"publisher_id":101,"instrument_id":436},"action":"C","side":"A","price":"1.156890000","size":30,"channel_id":23,"order_id":"1775530166435452907","flags":0,"ts_in_delta":1110,"sequence":172647,"symbol":"FCEU SI 20260615 PS"}
{"ts_recv":"2026-04-07T02:49:26.435527682Z","hd":{"ts_event":"2026-04-07T02:49:26.435505421Z","rtype":160,"publisher_id":101,"instrument_id":436},"action":"A","side":"A","price":"1.156880000","size":30,"channel_id":23,"order_id":"1775530166435514393","flags":128,"ts_in_delta":1110,"sequence":172647,"symbol":"FCEU SI 20260615 PS"}
{"ts_recv":"2026-04-07T02:49:26.435585241Z","hd":{"ts_event":"2026-04-07T02:49:26.435566949Z","rtype":160,"publisher_id":101,"instrument_id":436},"action":"C","side":"B","price":"1.156780000","size":30,"channel_id":23,"order_id":"10998902203290290201","flags":0,"ts_in_delta":922,"sequence":172648,"symbol":"FCEU SI 20260615 PS"}
{"ts_recv":"2026-04-07T02:49:26.435585241Z","hd":{"ts_event":"2026-04-07T02:49:26.435566949Z","rtype":160,"publisher_id":101,"instrument_id":436},"action":"A","side":"B","price":"1.156790000","size":30,"channel_id":23,"order_id":"10998902203290348834","flags":0,"ts_in_delta":922,"sequence":172648,"symbol":"FCEU SI 20260615 PS"}
{"ts_recv":"2026-04-07T02:49:26.435585241Z","hd":{"ts_event":"2026-04-07T02:49:26.435566949Z","rtype":160,"publisher_id":101,"instrument_id":436},"action":"C","side":"A","price":"1.156880000","size":30,"channel_id":23,"order_id":"1775530166435514393","flags":0,"ts_in_delta":922,"sequence":172648,"symbol":"FCEU SI 20260615 PS"}
{"ts_recv":"2026-04-07T02:49:26.435585241Z","hd":{"ts_event":"2026-04-07T02:49:26.435566949Z","rtype":160,"publisher_id":101,"instrument_id":436},"action":"A","side":"A","price":"1.156890000","size":30,"channel_id":23,"order_id":"1775530166435573026","flags":128,"ts_in_delta":922,"sequence":172648,"symbol":"FCEU SI 20260615 PS"}
{"ts_recv":"2026-04-07T02:49:39.049950800Z","hd":{"ts_event":"2026-04-07T02:49:39.049930049Z","rtype":160,"publisher_id":101,"instrument_id":436},"action":"C","side":"B","price":"1.156790000","size":30,"channel_id":23,"order_id":"10998902203290348834","flags":0,"ts_in_delta":727,"sequence":172796,"symbol":"FCEU SI 20260615 PS"}
{"ts_recv":"2026-04-07T02:49:39.049950800Z","hd":{"ts_event":"2026-04-07T02:49:39.049930049Z","rtype":160,"publisher_id":101,"instrument_id":436},"action":"A","side":"B","price":"1.156800000","size":30,"channel_id":23,"order_id":"10998902215904711836","flags":0,"ts_in_delta":727,"sequence":172796,"symbol":"FCEU SI 20260615 PS"}
{"ts_recv":"2026-04-07T02:49:39.049950800Z","hd":{"ts_event":"2026-04-07T02:49:39.049930049Z","rtype":160,"publisher_id":101,"instrument_id":436},"action":"C","side":"A","price":"1.156890000","size":30,"channel_id":23,"order_id":"1775530166435573026","flags":0,"ts_in_delta":727,"sequence":172796,"symbol":"FCEU SI 20260615 PS"}
{"ts_recv":"2026-04-07T02:49:39.049950800Z","hd":{"ts_event":"2026-04-07T02:49:39.049930049Z","rtype":160,"publisher_id":101,"instrument_id":436},"action":"A","side":"A","price":"1.156900000","size":30,"channel_id":23,"order_id":"1775530179049936028","flags":128,"ts_in_delta":727,"sequence":172796,"symbol":"FCEU SI 20260615 PS"}
{"ts_recv":"2026-04-07T02:49:39.050002814Z","hd":{"ts_event":"2026-04-07T02:49:39.049984463Z","rtype":160,"publisher_id":101,"instrument_id":436},"action":"C","side":"B","price":"1.156790000","size":30,"channel_id":23,"order_id":"10998902203290281430","flags":0,"ts_in_delta":723,"sequence":172797,"symbol":"FCEU SI 20260615 PS"}
{"ts_recv":"2026-04-07T02:49:39.050002814Z","hd":{"ts_event":"2026-04-07T02:49:39.049984463Z","rtype":160,"publisher_id":101,"instrument_id":436},"action":"A","side":"B","price":"1.156810000","size":30,"channel_id":23,"order_id":"10998902215904766083","flags":0,"ts_in_delta":723,"sequence":172797,"symbol":"FCEU SI 20260615 PS"}
{"ts_recv":"2026-04-07T02:49:39.050002814Z","hd":{"ts_event":"2026-04-07T02:49:39.049984463Z","rtype":160,"publisher_id":101,"instrument_id":436},"action":"C","side":"A","price":"1.156890000","size":30,"channel_id":23,"order_id":"1775530166435505622","flags":0,"ts_in_delta":723,"sequence":172797,"symbol":"FCEU SI 20260615 PS"}
{"ts_recv":"2026-04-07T02:49:39.050002814Z","hd":{"ts_event":"2026-04-07T02:49:39.049984463Z","rtype":160,"publisher_id":101,"instrument_id":436},"action":"A","side":"A","price":"1.156910000","size":30,"channel_id":23,"order_id":"1775530179049990275","flags":128,"ts_in_delta":723,"sequence":172797,"symbol":"FCEU SI 20260615 PS"}
{"ts_recv":"2026-04-07T02:49:39.050058860Z","hd":{"ts_event":"2026-04-07T02:49:39.050040179Z","rtype":160,"publisher_id":101,"instrument_id":436},"action":"C","side":"B","price":"1.156800000","size":30,"channel_id":23,"order_id":"10998902215904711836","flags":0,"ts_in_delta":736,"sequence":172798,"symbol":"FCEU SI 20260615 PS"}
{"ts_recv":"2026-04-07T02:49:39.050058860Z","hd":{"ts_event":"2026-04-07T02:49:39.050040179Z","rtype":160,"publisher_id":101,"instrument_id":436},"action":"A","side":"B","price":"1.156810000","size":30,"channel_id":23,"order_id":"10998902215904822029","flags":0,"ts_in_delta":736,"sequence":172798,"symbol":"FCEU SI 20260615 PS"}
{"ts_recv":"2026-04-07T02:49:39.050058860Z","hd":{"ts_event":"2026-04-07T02:49:39.050040179Z","rtype":160,"publisher_id":101,"instrument_id":436},"action":"C","side":"A","price":"1.156900000","size":30,"channel_id":23,"order_id":"1775530179049936028","flags":0,"ts_in_delta":736,"sequence":172798,"symbol":"FCEU SI 20260615 PS"}
{"ts_recv":"2026-04-07T02:49:39.050058860Z","hd":{"ts_event":"2026-04-07T02:49:39.050040179Z","rtype":160,"publisher_id":101,"instrument_id":436},"action":"A","side":"A","price":"1.156910000","size":30,"channel_id":23,"order_id":"1775530179050046221","flags":128,"ts_in_delta":736,"sequence":172798,"symbol":"FCEU SI 20260615 PS"}
{"ts_recv":"2026-04-07T02:49:39.101824890Z","hd":{"ts_event":"2026-04-07T02:49:39.101806129Z","rtype":160,"publisher_id":101,"instrument_id":436},"action":"C","side":"B","price":"1.156810000","size":30,"channel_id":23,"order_id":"10998902215904822029","flags":0,"ts_in_delta":1120,"sequence":172816,"symbol":"FCEU SI 20260615 PS"}
{"ts_recv":"2026-04-07T02:49:39.101824890Z","hd":{"ts_event":"2026-04-07T02:49:39.101806129Z","rtype":160,"publisher_id":101,"instrument_id":436},"action":"A","side":"B","price":"1.156820000","size":30,"channel_id":23,"order_id":"10998902215956587690","flags":0,"ts_in_delta":1120,"sequence":172816,"symbol":"FCEU SI 20260615 PS"}
{"ts_recv":"2026-04-07T02:49:39.101824890Z","hd":{"ts_event":"2026-04-07T02:49:39.101806129Z","rtype":160,"publisher_id":101,"instrument_id":436},"action":"C","side":"A","price":"1.156910000","size":30,"channel_id":23,"order_id":"1775530179050046221","flags":0,"ts_in_delta":1120,"sequence":172816,"symbol":"FCEU SI 20260615 PS"}
{"ts_recv":"2026-04-07T02:49:39.101824890Z","hd":{"ts_event":"2026-04-07T02:49:39.101806129Z","rtype":160,"publisher_id":101,"instrument_id":436},"action":"A","side":"A","price":"1.156920000","size":30,"channel_id":23,"order_id":"1775530179101811882","flags":128,"ts_in_delta":1120,"sequence":172816,"symbol":"FCEU SI 20260615 PS"}
{"ts_recv":"2026-04-07T02:49:39.142426155Z","hd":{"ts_event":"2026-04-07T02:49:39.142412573Z","rtype":160,"publisher_id":101,"instrument_id":436},"action":"A","side":"B","price":"1.156700000","size":20,"channel_id":23,"order_id":"10998902215997194481","flags":128,"ts_in_delta":781,"sequence":172822,"symbol":"FCEU SI 20260615 PS"}
{"ts_recv":"2026-04-07T02:49:39.142503904Z","hd":{"ts_event":"2026-04-07T02:49:39.142492163Z","rtype":160,"publisher_id":101,"instrument_id":436},"action":"C","side":"B","price":"1.156600000","size":20,"channel_id":23,"order_id":"10998901726623061222","flags":128,"ts_in_delta":733,"sequence":172823,"symbol":"FCEU SI 20260615 PS"}
{"ts_recv":"2026-04-07T02:49:40.454110472Z","hd":{"ts_event":"2026-04-07T02:49:40.454087673Z","rtype":160,"publisher_id":101,"instrument_id":436},"action":"C","side":"B","price":"1.156810000","size":30,"channel_id":23,"order_id":"10998902215904766083","flags":0,"ts_in_delta":903,"sequence":172843,"symbol":"FCEU SI 20260615 PS"}
{"ts_recv":"2026-04-07T02:49:40.454110472Z","hd":{"ts_event":"2026-04-07T02:49:40.454087673Z","rtype":160,"publisher_id":101,"instrument_id":436},"action":"A","side":"B","price":"1.156830000","size":30,"channel_id":23,"order_id":"10998902217308870051","flags":0,"ts_in_delta":903,"sequence":172843,"symbol":"FCEU SI 20260615 PS"}
{"ts_recv":"2026-04-07T02:49:40.454110472Z","hd":{"ts_event":"2026-04-07T02:49:40.454087673Z","rtype":160,"publisher_id":101,"instrument_id":436},"action":"C","side":"A","price":"1.156910000","size":30,"channel_id":23,"order_id":"1775530179049990275","flags":0,"ts_in_delta":903,"sequence":172843,"symbol":"FCEU SI 20260615 PS"}
{"ts_recv":"2026-04-07T02:49:40.454110472Z","hd":{"ts_event":"2026-04-07T02:49:40.454087673Z","rtype":160,"publisher_id":101,"instrument_id":436},"action":"A","side":"A","price":"1.156930000","size":30,"channel_id":23,"order_id":"1775530180454094243","flags":128,"ts_in_delta":903,"sequence":172843,"symbol":"FCEU SI 20260615 PS"}
{"ts_recv":"2026-04-07T02:49:40.454187329Z","hd":{"ts_event":"2026-04-07T02:49:40.454168837Z","rtype":160,"publisher_id":101,"instrument_id":436},"action":"C","side":"B","price":"1.156820000","size":30,"channel_id":23,"order_id":"10998902215956587690","flags":0,"ts_in_delta":910,"sequence":172844,"symbol":"FCEU SI 20260615 PS"}
{"ts_recv":"2026-04-07T02:49:40.454187329Z","hd":{"ts_event":"2026-04-07T02:49:40.454168837Z","rtype":160,"publisher_id":101,"instrument_id":436},"action":"A","side":"B","price":"1.156830000","size":30,"channel_id":23,"order_id":"10998902217308950822","flags":0,"ts_in_delta":910,"sequence":172844,"symbol":"FCEU SI 20260615 PS"}
{"ts_recv":"2026-04-07T02:49:40.454187329Z","hd":{"ts_event":"2026-04-07T02:49:40.454168837Z","rtype":160,"publisher_id":101,"instrument_id":436},"action":"C","side":"A","price":"1.156920000","size":30,"channel_id":23,"order_id":"1775530179101811882","flags":0,"ts_in_delta":910,"sequence":172844,"symbol":"FCEU SI 20260615 PS"}
{"ts_recv":"2026-04-07T02:49:40.454187329Z","hd":{"ts_event":"2026-04-07T02:49:40.454168837Z","rtype":160,"publisher_id":101,"instrument_id":436},"action":"A","side":"A","price":"1.156930000","size":30,"channel_id":23,"order_id":"1775530180454175014","flags":128,"ts_in_delta":910,"sequence":172844,"symbol":"FCEU SI 20260615 PS"}
{"ts_recv":"2026-04-07T02:49:53.005856960Z","hd":{"ts_event":"2026-04-07T02:49:53.005834987Z","rtype":160,"publisher_id":101,"instrument_id":436},"action":"C","side":"B","price":"1.156830000","size":30,"channel_id":23,"order_id":"10998902217308950822","flags":0,"ts_in_delta":1287,"sequence":172942,"symbol":"FCEU SI 20260615 PS"}
{"ts_recv":"2026-04-07T02:49:53.005856960Z","hd":{"ts_event":"2026-04-07T02:49:53.005834987Z","rtype":160,"publisher_id":101,"instrument_id":436},"action":"A","side":"B","price":"1.156840000","size":30,"channel_id":23,"order_id":"10998902229860616995","flags":0,"ts_in_delta":1287,"sequence":172942,"symbol":"FCEU SI 20260615 PS"}
{"ts_recv":"2026-04-07T02:49:53.005856960Z","hd":{"ts_event":"2026-04-07T02:49:53.005834987Z","rtype":160,"publisher_id":101,"instrument_id":436},"action":"C","side":"A","price":"1.156930000","size":30,"channel_id":23,"order_id":"1775530180454175014","flags":0,"ts_in_delta":1287,"sequence":172942,"symbol":"FCEU SI 20260615 PS"}
{"ts_recv":"2026-04-07T02:49:53.005856960Z","hd":{"ts_event":"2026-04-07T02:49:53.005834987Z","rtype":160,"publisher_id":101,"instrument_id":436},"action":"A","side":"A","price":"1.156940000","size":30,"channel_id":23,"order_id":"1775530193005841187","flags":128,"ts_in_delta":1287,"sequence":172942,"symbol":"FCEU SI 20260615 PS"}
{"ts_recv":"2026-04-07T02:49:53.007627304Z","hd":{"ts_event":"2026-04-07T02:49:53.007604189Z","rtype":160,"publisher_id":101,"instrument_id":436},"action":"C","side":"B","price":"1.156830000","size":30,"channel_id":23,"order_id":"10998902217308870051","flags":0,"ts_in_delta":875,"sequence":172943,"symbol":"FCEU SI 20260615 PS"}
{"ts_recv":"2026-04-07T02:49:53.007627304Z","hd":{"ts_event":"2026-04-07T02:49:53.007604189Z","rtype":160,"publisher_id":101,"instrument_id":436},"action":"A","side":"B","price":"1.156850000","size":30,"channel_id":23,"order_id":"10998902229862386237","flags":0,"ts_in_delta":875,"sequence":172943,"symbol":"FCEU SI 20260615 PS"}
{"ts_recv":"2026-04-07T02:49:53.007627304Z","hd":{"ts_event":"2026-04-07T02:49:53.007604189Z","rtype":160,"publisher_id":101,"instrument_id":436},"action":"C","side":"A","price":"1.156930000","size":30,"channel_id":23,"order_id":"1775530180454094243","flags":0,"ts_in_delta":875,"sequence":172943,"symbol":"FCEU SI 20260615 PS"}
{"ts_recv":"2026-04-07T02:49:53.007627304Z","hd":{"ts_event":"2026-04-07T02:49:53.007604189Z","rtype":160,"publisher_id":101,"instrument_id":436},"action":"A","side":"A","price":"1.156950000","size":30,"channel_id":23,"order_id":"1775530193007610429","flags":128,"ts_in_delta":875,"sequence":172943,"symbol":"FCEU SI 20260615 PS"}
{"ts_recv":"2026-04-07T02:49:53.007690668Z","hd":{"ts_event":"2026-04-07T02:49:53.007673637Z","rtype":160,"publisher_id":101,"instrument_id":436},"action":"C","side":"B","price":"1.156840000","size":30,"channel_id":23,"order_id":"10998902229860616995","flags":0,"ts_in_delta":911,"sequence":172944,"symbol":"FCEU SI 20260615 PS"}
{"ts_recv":"2026-04-07T02:49:53.007690668Z","hd":{"ts_event":"2026-04-07T02:49:53.007673637Z","rtype":160,"publisher_id":101,"instrument_id":436},"action":"A","side":"B","price":"1.156850000","size":30,"channel_id":23,"order_id":"10998902229862455602","flags":0,"ts_in_delta":911,"sequence":172944,"symbol":"FCEU SI 20260615 PS"}
{"ts_recv":"2026-04-07T02:49:53.007690668Z","hd":{"ts_event":"2026-04-07T02:49:53.007673637Z","rtype":160,"publisher_id":101,"instrument_id":436},"action":"C","side":"A","price":"1.156940000","size":30,"channel_id":23,"order_id":"1775530193005841187","flags":0,"ts_in_delta":911,"sequence":172944,"symbol":"FCEU SI 20260615 PS"}
{"ts_recv":"2026-04-07T02:49:53.007690668Z","hd":{"ts_event":"2026-04-07T02:49:53.007673637Z","rtype":160,"publisher_id":101,"instrument_id":436},"action":"A","side":"A","price":"1.156950000","size":30,"channel_id":23,"order_id":"1775530193007679794","flags":128,"ts_in_delta":911,"sequence":172944,"symbol":"FCEU SI 20260615 PS"}
{"ts_recv":"2026-04-07T02:49:53.093756025Z","hd":{"ts_event":"2026-04-07T02:49:53.093736023Z","rtype":160,"publisher_id":101,"instrument_id":436},"action":"C","side":"B","price":"1.156850000","size":30,"channel_id":23,"order_id":"10998902229862455602","flags":0,"ts_in_delta":894,"sequence":172949,"symbol":"FCEU SI 20260615 PS"}
{"ts_recv":"2026-04-07T02:49:53.093756025Z","hd":{"ts_event":"2026-04-07T02:49:53.093736023Z","rtype":160,"publisher_id":101,"instrument_id":436},"action":"A","side":"B","price":"1.156840000","size":30,"channel_id":23,"order_id":"10998902229948517882","flags":0,"ts_in_delta":894,"sequence":172949,"symbol":"FCEU SI 20260615 PS"}
{"ts_recv":"2026-04-07T02:49:53.093756025Z","hd":{"ts_event":"2026-04-07T02:49:53.093736023Z","rtype":160,"publisher_id":101,"instrument_id":436},"action":"C","side":"A","price":"1.156950000","size":30,"channel_id":23,"order_id":"1775530193007679794","flags":0,"ts_in_delta":894,"sequence":172949,"symbol":"FCEU SI 20260615 PS"}
{"ts_recv":"2026-04-07T02:49:53.093756025Z","hd":{"ts_event":"2026-04-07T02:49:53.093736023Z","rtype":160,"publisher_id":101,"instrument_id":436},"action":"A","side":"A","price":"1.156940000","size":30,"channel_id":23,"order_id":"1775530193093742074","flags":128,"ts_in_delta":894,"sequence":172949,"symbol":"FCEU SI 20260615 PS"}
{"ts_recv":"2026-04-07T02:49:53.093837952Z","hd":{"ts_event":"2026-04-07T02:49:53.093817721Z","rtype":160,"publisher_id":101,"instrument_id":436},"action":"C","side":"B","price":"1.156840000","size":30,"channel_id":23,"order_id":"10998902229948517882","flags":0,"ts_in_delta":894,"sequence":172950,"symbol":"FCEU SI 20260615 PS"}
{"ts_recv":"2026-04-07T02:49:53.093837952Z","hd":{"ts_event":"2026-04-07T02:49:53.093817721Z","rtype":160,"publisher_id":101,"instrument_id":436},"action":"A","side":"B","price":"1.156830000","size":30,"channel_id":23,"order_id":"10998902229948599586","flags":0,"ts_in_delta":894,"sequence":172950,"symbol":"FCEU SI 20260615 PS"}
{"ts_recv":"2026-04-07T02:49:53.093837952Z","hd":{"ts_event":"2026-04-07T02:49:53.093817721Z","rtype":160,"publisher_id":101,"instrument_id":436},"action":"C","side":"A","price":"1.156940000","size":30,"channel_id":23,"order_id":"1775530193093742074","flags":0,"ts_in_delta":894,"sequence":172950,"symbol":"FCEU SI 20260615 PS"}
{"ts_recv":"2026-04-07T02:49:53.093837952Z","hd":{"ts_event":"2026-04-07T02:49:53.093817721Z","rtype":160,"publisher_id":101,"instrument_id":436},"action":"A","side":"A","price":"1.156930000","size":30,"channel_id":23,"order_id":"1775530193093823778","flags":128,"ts_in_delta":894,"sequence":172950,"symbol":"FCEU SI 20260615 PS"}
{"ts_recv":"2026-04-07T02:49:53.093890473Z","hd":{"ts_event":"2026-04-07T02:49:53.093871117Z","rtype":160,"publisher_id":101,"instrument_id":436},"action":"C","side":"B","price":"1.156850000","size":30,"channel_id":23,"order_id":"10998902229862386237","flags":0,"ts_in_delta":899,"sequence":172951,"symbol":"FCEU SI 20260615 PS"}
{"ts_recv":"2026-04-07T02:49:53.093890473Z","hd":{"ts_event":"2026-04-07T02:49:53.093871117Z","rtype":160,"publisher_id":101,"instrument_id":436},"action":"A","side":"B","price":"1.156830000","size":30,"channel_id":23,"order_id":"10998902229948653190","flags":0,"ts_in_delta":899,"sequence":172951,"symbol":"FCEU SI 20260615 PS"}
{"ts_recv":"2026-04-07T02:49:53.093890473Z","hd":{"ts_event":"2026-04-07T02:49:53.093871117Z","rtype":160,"publisher_id":101,"instrument_id":436},"action":"C","side":"A","price":"1.156950000","size":30,"channel_id":23,"order_id":"1775530193007610429","flags":0,"ts_in_delta":899,"sequence":172951,"symbol":"FCEU SI 20260615 PS"}
{"ts_recv":"2026-04-07T02:49:53.093890473Z","hd":{"ts_event":"2026-04-07T02:49:53.093871117Z","rtype":160,"publisher_id":101,"instrument_id":436},"action":"A","side":"A","price":"1.156930000","size":30,"channel_id":23,"order_id":"1775530193093877382","flags":128,"ts_in_delta":899,"sequence":172951,"symbol":"FCEU SI 20260615 PS"}
{"ts_recv":"2026-04-07T02:49:53.093901370Z","hd":{"ts_event":"2026-04-07T02:49:53.093876455Z","rtype":160,"publisher_id":101,"instrument_id":436},"action":"C","side":"B","price":"1.156830000","size":30,"channel_id":23,"order_id":"10998902229948599586","flags":0,"ts_in_delta":893,"sequence":172952,"symbol":"FCEU SI 20260615 PS"}
{"ts_recv":"2026-04-07T02:49:53.093901370Z","hd":{"ts_event":"2026-04-07T02:49:53.093876455Z","rtype":160,"publisher_id":101,"instrument_id":436},"action":"A","side":"B","price":"1.156840000","size":30,"channel_id":23,"order_id":"10998902229948663327","flags":0,"ts_in_delta":893,"sequence":172952,"symbol":"FCEU SI 20260615 PS"}
{"ts_recv":"2026-04-07T02:49:53.093901370Z","hd":{"ts_event":"2026-04-07T02:49:53.093876455Z","rtype":160,"publisher_id":101,"instrument_id":436},"action":"C","side":"A","price":"1.156930000","size":30,"channel_id":23,"order_id":"1775530193093823778","flags":0,"ts_in_delta":893,"sequence":172952,"symbol":"FCEU SI 20260615 PS"}
{"ts_recv":"2026-04-07T02:49:53.093901370Z","hd":{"ts_event":"2026-04-07T02:49:53.093876455Z","rtype":160,"publisher_id":101,"instrument_id":436},"action":"A","side":"A","price":"1.156940000","size":30,"channel_id":23,"order_id":"1775530193093887519","flags":128,"ts_in_delta":893,"sequence":172952,"symbol":"FCEU SI 20260615 PS"}
{"ts_recv":"2026-04-07T02:49:53.093954943Z","hd":{"ts_event":"2026-04-07T02:49:53.093938413Z","rtype":160,"publisher_id":101,"instrument_id":436},"action":"C","side":"B","price":"1.156840000","size":30,"channel_id":23,"order_id":"10998902229948663327","flags":0,"ts_in_delta":856,"sequence":172953,"symbol":"FCEU SI 20260615 PS"}
{"ts_recv":"2026-04-07T02:49:53.093954943Z","hd":{"ts_event":"2026-04-07T02:49:53.093938413Z","rtype":160,"publisher_id":101,"instrument_id":436},"action":"A","side":"B","price":"1.156830000","size":30,"channel_id":23,"order_id":"10998902229948720202","flags":0,"ts_in_delta":856,"sequence":172953,"symbol":"FCEU SI 20260615 PS"}
{"ts_recv":"2026-04-07T02:49:53.093954943Z","hd":{"ts_event":"2026-04-07T02:49:53.093938413Z","rtype":160,"publisher_id":101,"instrument_id":436},"action":"C","side":"A","price":"1.156940000","size":30,"channel_id":23,"order_id":"1775530193093887519","flags":0,"ts_in_delta":856,"sequence":172953,"symbol":"FCEU SI 20260615 PS"}
{"ts_recv":"2026-04-07T02:49:53.093954943Z","hd":{"ts_event":"2026-04-07T02:49:53.093938413Z","rtype":160,"publisher_id":101,"instrument_id":436},"action":"A","side":"A","price":"1.156930000","size":30,"channel_id":23,"order_id":"1775530193093944394","flags":128,"ts_in_delta":856,"sequence":172953,"symbol":"FCEU SI 20260615 PS"}
{"ts_recv":"2026-04-07T02:49:55.669689131Z","hd":{"ts_event":"2026-04-07T02:49:55.669668739Z","rtype":160,"publisher_id":101,"instrument_id":436},"action":"C","side":"B","price":"1.156830000","size":30,"channel_id":23,"order_id":"10998902229948720202","flags":0,"ts_in_delta":902,"sequence":172972,"symbol":"FCEU SI 20260615 PS"}
{"ts_recv":"2026-04-07T02:49:55.669689131Z","hd":{"ts_event":"2026-04-07T02:49:55.669668739Z","rtype":160,"publisher_id":101,"instrument_id":436},"action":"A","side":"B","price":"1.156820000","size":30,"channel_id":23,"order_id":"10998902232524450593","flags":0,"ts_in_delta":902,"sequence":172972,"symbol":"FCEU SI 20260615 PS"}
{"ts_recv":"2026-04-07T02:49:55.669689131Z","hd":{"ts_event":"2026-04-07T02:49:55.669668739Z","rtype":160,"publisher_id":101,"instrument_id":436},"action":"C","side":"A","price":"1.156930000","size":30,"channel_id":23,"order_id":"1775530193093944394","flags":0,"ts_in_delta":902,"sequence":172972,"symbol":"FCEU SI 20260615 PS"}
{"ts_recv":"2026-04-07T02:49:55.669689131Z","hd":{"ts_event":"2026-04-07T02:49:55.669668739Z","rtype":160,"publisher_id":101,"instrument_id":436},"action":"A","side":"A","price":"1.156920000","size":30,"channel_id":23,"order_id":"1775530195669674785","flags":128,"ts_in_delta":902,"sequence":172972,"symbol":"FCEU SI 20260615 PS"}
{"ts_recv":"2026-04-07T02:49:55.669762425Z","hd":{"ts_event":"2026-04-07T02:49:55.669743391Z","rtype":160,"publisher_id":101,"instrument_id":436},"action":"C","side":"B","price":"1.156820000","size":30,"channel_id":23,"order_id":"10998902232524450593","flags":0,"ts_in_delta":917,"sequence":172973,"symbol":"FCEU SI 20260615 PS"}
{"ts_recv":"2026-04-07T02:49:55.669762425Z","hd":{"ts_event":"2026-04-07T02:49:55.669743391Z","rtype":160,"publisher_id":101,"instrument_id":436},"action":"A","side":"B","price":"1.156810000","size":30,"channel_id":23,"order_id":"10998902232524525210","flags":0,"ts_in_delta":917,"sequence":172973,"symbol":"FCEU SI 20260615 PS"}
{"ts_recv":"2026-04-07T02:49:55.669762425Z","hd":{"ts_event":"2026-04-07T02:49:55.669743391Z","rtype":160,"publisher_id":101,"instrument_id":436},"action":"C","side":"A","price":"1.156920000","size":30,"channel_id":23,"order_id":"1775530195669674785","flags":0,"ts_in_delta":917,"sequence":172973,"symbol":"FCEU SI 20260615 PS"}
{"ts_recv":"2026-04-07T02:49:55.669762425Z","hd":{"ts_event":"2026-04-07T02:49:55.669743391Z","rtype":160,"publisher_id":101,"instrument_id":436},"action":"A","side":"A","price":"1.156910000","size":30,"channel_id":23,"order_id":"1775530195669749402","flags":128,"ts_in_delta":917,"sequence":172973,"symbol":"FCEU SI 20260615 PS"}
{"ts_recv":"2026-04-07T02:49:55.669813810Z","hd":{"ts_event":"2026-04-07T02:49:55.669795979Z","rtype":160,"publisher_id":101,"instrument_id":436},"action":"C","side":"B","price":"1.156830000","size":30,"channel_id":23,"order_id":"10998902229948653190","flags":0,"ts_in_delta":916,"sequence":172974,"symbol":"FCEU SI 20260615 PS"}
{"ts_recv":"2026-04-07T02:49:55.669813810Z","hd":{"ts_event":"2026-04-07T02:49:55.669795979Z","rtype":160,"publisher_id":101,"instrument_id":436},"action":"A","side":"B","price":"1.156810000","size":30,"channel_id":23,"order_id":"10998902232524578078","flags":0,"ts_in_delta":916,"sequence":172974,"symbol":"FCEU SI 20260615 PS"}
{"ts_recv":"2026-04-07T02:49:55.669813810Z","hd":{"ts_event":"2026-04-07T02:49:55.669795979Z","rtype":160,"publisher_id":101,"instrument_id":436},"action":"C","side":"A","price":"1.156930000","size":30,"channel_id":23,"order_id":"1775530193093877382","flags":0,"ts_in_delta":916,"sequence":172974,"symbol":"FCEU SI 20260615 PS"}
{"ts_recv":"2026-04-07T02:49:55.669813810Z","hd":{"ts_event":"2026-04-07T02:49:55.669795979Z","rtype":160,"publisher_id":101,"instrument_id":436},"action":"A","side":"A","price":"1.156910000","size":30,"channel_id":23,"order_id":"1775530195669802270","flags":128,"ts_in_delta":916,"sequence":172974,"symbol":"FCEU SI 20260615 PS"}
{"ts_recv":"2026-04-07T02:49:55.669824062Z","hd":{"ts_event":"2026-04-07T02:49:55.669799741Z","rtype":160,"publisher_id":101,"instrument_id":436},"action":"C","side":"B","price":"1.156810000","size":30,"channel_id":23,"order_id":"10998902232524525210","flags":0,"ts_in_delta":873,"sequence":172975,"symbol":"FCEU SI 20260615 PS"}
{"ts_recv":"2026-04-07T02:49:55.669824062Z","hd":{"ts_event":"2026-04-07T02:49:55.669799741Z","rtype":160,"publisher_id":101,"instrument_id":436},"action":"A","side":"B","price":"1.156820000","size":30,"channel_id":23,"order_id":"10998902232524586700","flags":0,"ts_in_delta":873,"sequence":172975,"symbol":"FCEU SI 20260615 PS"}
{"ts_recv":"2026-04-07T02:49:55.669824062Z","hd":{"ts_event":"2026-04-07T02:49:55.669799741Z","rtype":160,"publisher_id":101,"instrument_id":436},"action":"C","side":"A","price":"1.156910000","size":30,"channel_id":23,"order_id":"1775530195669749402","flags":0,"ts_in_delta":873,"sequence":172975,"symbol":"FCEU SI 20260615 PS"}
{"ts_recv":"2026-04-07T02:49:55.669824062Z","hd":{"ts_event":"2026-04-07T02:49:55.669799741Z","rtype":160,"publisher_id":101,"instrument_id":436},"action":"A","side":"A","price":"1.156920000","size":30,"channel_id":23,"order_id":"1775530195669810892","flags":128,"ts_in_delta":873,"sequence":172975,"symbol":"FCEU SI 20260615 PS"}
{"ts_recv":"2026-04-07T02:49:55.669878549Z","hd":{"ts_event":"2026-04-07T02:49:55.669863101Z","rtype":160,"publisher_id":101,"instrument_id":436},"action":"C","side":"B","price":"1.156820000","size":30,"channel_id":23,"order_id":"10998902232524586700","flags":0,"ts_in_delta":899,"sequence":172976,"symbol":"FCEU SI 20260615 PS"}
{"ts_recv":"2026-04-07T02:49:55.669878549Z","hd":{"ts_event":"2026-04-07T02:49:55.669863101Z","rtype":160,"publisher_id":101,"instrument_id":436},"action":"A","side":"B","price":"1.156810000","size":30,"channel_id":23,"order_id":"10998902232524644929","flags":0,"ts_in_delta":899,"sequence":172976,"symbol":"FCEU SI 20260615 PS"}
{"ts_recv":"2026-04-07T02:49:55.669878549Z","hd":{"ts_event":"2026-04-07T02:49:55.669863101Z","rtype":160,"publisher_id":101,"instrument_id":436},"action":"C","side":"A","price":"1.156920000","size":30,"channel_id":23,"order_id":"1775530195669810892","flags":0,"ts_in_delta":899,"sequence":172976,"symbol":"FCEU SI 20260615 PS"}
{"ts_recv":"2026-04-07T02:49:55.669878549Z","hd":{"ts_event":"2026-04-07T02:49:55.669863101Z","rtype":160,"publisher_id":101,"instrument_id":436},"action":"A","side":"A","price":"1.156910000","size":30,"channel_id":23,"order_id":"1775530195669869121","flags":128,"ts_in_delta":899,"sequence":172976,"symbol":"FCEU SI 20260615 PS"}
{"ts_recv":"2026-04-07T02:49:59.212165042Z","hd":{"ts_event":"2026-04-07T02:49:59.212145499Z","rtype":160,"publisher_id":101,"instrument_id":436},"action":"C","side":"B","price":"1.156810000","size":30,"channel_id":23,"order_id":"10998902232524644929","flags":0,"ts_in_delta":1001,"sequence":173030,"symbol":"FCEU SI 20260615 PS"}
{"ts_recv":"2026-04-07T02:49:59.212165042Z","hd":{"ts_event":"2026-04-07T02:49:59.212145499Z","rtype":160,"publisher_id":101,"instrument_id":436},"action":"A","side":"B","price":"1.156800000","size":30,"channel_id":23,"order_id":"10998902236066927473","flags":0,"ts_in_delta":1001,"sequence":173030,"symbol":"FCEU SI 20260615 PS"}
{"ts_recv":"2026-04-07T02:49:59.212165042Z","hd":{"ts_event":"2026-04-07T02:49:59.212145499Z","rtype":160,"publisher_id":101,"instrument_id":436},"action":"C","side":"A","price":"1.156910000","size":30,"channel_id":23,"order_id":"1775530195669869121","flags":0,"ts_in_delta":1001,"sequence":173030,"symbol":"FCEU SI 20260615 PS"}
{"ts_recv":"2026-04-07T02:49:59.212165042Z","hd":{"ts_event":"2026-04-07T02:49:59.212145499Z","rtype":160,"publisher_id":101,"instrument_id":436},"action":"A","side":"A","price":"1.156900000","size":30,"channel_id":23,"order_id":"1775530199212151665","flags":128,"ts_in_delta":1001,"sequence":173030,"symbol":"FCEU SI 20260615 PS"}
{"ts_recv":"2026-04-07T02:49:59.214372772Z","hd":{"ts_event":"2026-04-07T02:49:59.214354455Z","rtype":160,"publisher_id":101,"instrument_id":436},"action":"C","side":"B","price":"1.156810000","size":30,"channel_id":23,"order_id":"10998902232524578078","flags":0,"ts_in_delta":771,"sequence":173031,"symbol":"FCEU SI 20260615 PS"}
{"ts_recv":"2026-04-07T02:49:59.214372772Z","hd":{"ts_event":"2026-04-07T02:49:59.214354455Z","rtype":160,"publisher_id":101,"instrument_id":436},"action":"A","side":"B","price":"1.156790000","size":30,"channel_id":23,"order_id":"10998902236069136480","flags":0,"ts_in_delta":771,"sequence":173031,"symbol":"FCEU SI 20260615 PS"}
{"ts_recv":"2026-04-07T02:49:59.214372772Z","hd":{"ts_event":"2026-04-07T02:49:59.214354455Z","rtype":160,"publisher_id":101,"instrument_id":436},"action":"C","side":"A","price":"1.156910000","size":30,"channel_id":23,"order_id":"1775530195669802270","flags":0,"ts_in_delta":771,"sequence":173031,"symbol":"FCEU SI 20260615 PS"}
{"ts_recv":"2026-04-07T02:49:59.214372772Z","hd":{"ts_event":"2026-04-07T02:49:59.214354455Z","rtype":160,"publisher_id":101,"instrument_id":436},"action":"A","side":"A","price":"1.156890000","size":30,"channel_id":23,"order_id":"1775530199214360672","flags":128,"ts_in_delta":771,"sequence":173031,"symbol":"FCEU SI 20260615 PS"}
{"ts_recv":"2026-04-07T02:49:59.214430254Z","hd":{"ts_event":"2026-04-07T02:49:59.214412779Z","rtype":160,"publisher_id":101,"instrument_id":436},"action":"C","side":"B","price":"1.156800000","size":30,"channel_id":23,"order_id":"10998902236066927473","flags":0,"ts_in_delta":763,"sequence":173032,"symbol":"FCEU SI 20260615 PS"}
{"ts_recv":"2026-04-07T02:49:59.214430254Z","hd":{"ts_event":"2026-04-07T02:49:59.214412779Z","rtype":160,"publisher_id":101,"instrument_id":436},"action":"A","side":"B","price":"1.156790000","size":30,"channel_id":23,"order_id":"10998902236069194802","flags":0,"ts_in_delta":763,"sequence":173032,"symbol":"FCEU SI 20260615 PS"}
{"ts_recv":"2026-04-07T02:49:59.214430254Z","hd":{"ts_event":"2026-04-07T02:49:59.214412779Z","rtype":160,"publisher_id":101,"instrument_id":436},"action":"C","side":"A","price":"1.156900000","size":30,"channel_id":23,"order_id":"1775530199212151665","flags":0,"ts_in_delta":763,"sequence":173032,"symbol":"FCEU SI 20260615 PS"}
{"ts_recv":"2026-04-07T02:49:59.214430254Z","hd":{"ts_event":"2026-04-07T02:49:59.214412779Z","rtype":160,"publisher_id":101,"instrument_id":436},"action":"A","side":"A","price":"1.156890000","size":30,"channel_id":23,"order_id":"1775530199214418994","flags":128,"ts_in_delta":763,"sequence":173032,"symbol":"FCEU SI 20260615 PS"}
{"ts_recv":"2026-04-07T02:49:59.453849692Z","hd":{"ts_event":"2026-04-07T02:49:59.453832115Z","rtype":160,"publisher_id":101,"instrument_id":436},"action":"C","side":"B","price":"1.156790000","size":30,"channel_id":23,"order_id":"10998902236069194802","flags":0,"ts_in_delta":955,"sequence":173040,"symbol":"FCEU SI 20260615 PS"}
{"ts_recv":"2026-04-07T02:49:59.453849692Z","hd":{"ts_event":"2026-04-07T02:49:59.453832115Z","rtype":160,"publisher_id":101,"instrument_id":436},"action":"A","side":"B","price":"1.156800000","size":30,"channel_id":23,"order_id":"10998902236308613754","flags":0,"ts_in_delta":955,"sequence":173040,"symbol":"FCEU SI 20260615 PS"}
{"ts_recv":"2026-04-07T02:49:59.453849692Z","hd":{"ts_event":"2026-04-07T02:49:59.453832115Z","rtype":160,"publisher_id":101,"instrument_id":436},"action":"C","side":"A","price":"1.156890000","size":30,"channel_id":23,"order_id":"1775530199214418994","flags":0,"ts_in_delta":955,"sequence":173040,"symbol":"FCEU SI 20260615 PS"}
{"ts_recv":"2026-04-07T02:49:59.453849692Z","hd":{"ts_event":"2026-04-07T02:49:59.453832115Z","rtype":160,"publisher_id":101,"instrument_id":436},"action":"A","side":"A","price":"1.156900000","size":30,"channel_id":23,"order_id":"1775530199453837946","flags":128,"ts_in_delta":955,"sequence":173040,"symbol":"FCEU SI 20260615 PS"}
{"ts_recv":"2026-04-07T02:49:59.453929384Z","hd":{"ts_event":"2026-04-07T02:49:59.453908857Z","rtype":160,"publisher_id":101,"instrument_id":436},"action":"C","side":"B","price":"1.156800000","size":30,"channel_id":23,"order_id":"10998902236308613754","flags":0,"ts_in_delta":875,"sequence":173041,"symbol":"FCEU SI 20260615 PS"}
{"ts_recv":"2026-04-07T02:49:59.453929384Z","hd":{"ts_event":"2026-04-07T02:49:59.453908857Z","rtype":160,"publisher_id":101,"instrument_id":436},"action":"A","side":"B","price":"1.156810000","size":30,"channel_id":23,"order_id":"10998902236308690476","flags":0,"ts_in_delta":875,"sequence":173041,"symbol":"FCEU SI 20260615 PS"}
{"ts_recv":"2026-04-07T02:49:59.453929384Z","hd":{"ts_event":"2026-04-07T02:49:59.453908857Z","rtype":160,"publisher_id":101,"instrument_id":436},"action":"C","side":"A","price":"1.156900000","size":30,"channel_id":23,"order_id":"1775530199453837946","flags":0,"ts_in_delta":875,"sequence":173041,"symbol":"FCEU SI 20260615 PS"}
{"ts_recv":"2026-04-07T02:49:59.453929384Z","hd":{"ts_event":"2026-04-07T02:49:59.453908857Z","rtype":160,"publisher_id":101,"instrument_id":436},"action":"A","side":"A","price":"1.156910000","size":30,"channel_id":23,"order_id":"1775530199453914668","flags":128,"ts_in_delta":875,"sequence":173041,"symbol":"FCEU SI 20260615 PS"}
{"ts_recv":"2026-04-07T02:49:59.453977904Z","hd":{"ts_event":"2026-04-07T02:49:59.453961523Z","rtype":160,"publisher_id":101,"instrument_id":436},"action":"C","side":"B","price":"1.156790000","size":30,"channel_id":23,"order_id":"10998902236069136480","flags":0,"ts_in_delta":928,"sequence":173042,"symbol":"FCEU SI 20260615 PS"}
{"ts_recv":"2026-04-07T02:49:59.453977904Z","hd":{"ts_event":"2026-04-07T02:49:59.453961523Z","rtype":160,"publisher_id":101,"instrument_id":436},"action":"A","side":"B","price":"1.156810000","size":30,"channel_id":23,"order_id":"10998902236308743373","flags":0,"ts_in_delta":928,"sequence":173042,"symbol":"FCEU SI 20260615 PS"}
{"ts_recv":"2026-04-07T02:49:59.453977904Z","hd":{"ts_event":"2026-04-07T02:49:59.453961523Z","rtype":160,"publisher_id":101,"instrument_id":436},"action":"C","side":"A","price":"1.156890000","size":30,"channel_id":23,"order_id":"1775530199214360672","flags":0,"ts_in_delta":928,"sequence":173042,"symbol":"FCEU SI 20260615 PS"}
{"ts_recv":"2026-04-07T02:49:59.453977904Z","hd":{"ts_event":"2026-04-07T02:49:59.453961523Z","rtype":160,"publisher_id":101,"instrument_id":436},"action":"A","side":"A","price":"1.156910000","size":30,"channel_id":23,"order_id":"1775530199453967565","flags":128,"ts_in_delta":928,"sequence":173042,"symbol":"FCEU SI 20260615 PS"}
{"ts_recv":"2026-04-07T02:49:59.453988502Z","hd":{"ts_event":"2026-04-07T02:49:59.453967379Z","rtype":160,"publisher_id":101,"instrument_id":436},"action":"C","side":"B","price":"1.156810000","size":30,"channel_id":23,"order_id":"10998902236308690476","flags":0,"ts_in_delta":928,"sequence":173043,"symbol":"FCEU SI 20260615 PS"}
{"ts_recv":"2026-04-07T02:49:59.453988502Z","hd":{"ts_event":"2026-04-07T02:49:59.453967379Z","rtype":160,"publisher_id":101,"instrument_id":436},"action":"A","side":"B","price":"1.156800000","size":30,"channel_id":23,"order_id":"10998902236308750820","flags":0,"ts_in_delta":928,"sequence":173043,"symbol":"FCEU SI 20260615 PS"}
{"ts_recv":"2026-04-07T02:49:59.453988502Z","hd":{"ts_event":"2026-04-07T02:49:59.453967379Z","rtype":160,"publisher_id":101,"instrument_id":436},"action":"C","side":"A","price":"1.156910000","size":30,"channel_id":23,"order_id":"1775530199453914668","flags":0,"ts_in_delta":928,"sequence":173043,"symbol":"FCEU SI 20260615 PS"}
{"ts_recv":"2026-04-07T02:49:59.453988502Z","hd":{"ts_event":"2026-04-07T02:49:59.453967379Z","rtype":160,"publisher_id":101,"instrument_id":436},"action":"A","side":"A","price":"1.156900000","size":30,"channel_id":23,"order_id":"1775530199453975012","flags":128,"ts_in_delta":928,"sequence":173043,"symbol":"FCEU SI 20260615 PS"}
{"ts_recv":"2026-04-07T02:49:59.454041530Z","hd":{"ts_event":"2026-04-07T02:49:59.454024383Z","rtype":160,"publisher_id":101,"instrument_id":436},"action":"C","side":"B","price":"1.156800000","size":30,"channel_id":23,"order_id":"10998902236308750820","flags":0,"ts_in_delta":757,"sequence":173044,"symbol":"FCEU SI 20260615 PS"}
{"ts_recv":"2026-04-07T02:49:59.454041530Z","hd":{"ts_event":"2026-04-07T02:49:59.454024383Z","rtype":160,"publisher_id":101,"instrument_id":436},"action":"A","side":"B","price":"1.156810000","size":30,"channel_id":23,"order_id":"10998902236308806138","flags":0,"ts_in_delta":757,"sequence":173044,"symbol":"FCEU SI 20260615 PS"}
{"ts_recv":"2026-04-07T02:49:59.454041530Z","hd":{"ts_event":"2026-04-07T02:49:59.454024383Z","rtype":160,"publisher_id":101,"instrument_id":436},"action":"C","side":"A","price":"1.156900000","size":30,"channel_id":23,"order_id":"1775530199453975012","flags":0,"ts_in_delta":757,"sequence":173044,"symbol":"FCEU SI 20260615 PS"}
{"ts_recv":"2026-04-07T02:49:59.454041530Z","hd":{"ts_event":"2026-04-07T02:49:59.454024383Z","rtype":160,"publisher_id":101,"instrument_id":436},"action":"A","side":"A","price":"1.156910000","size":30,"channel_id":23,"order_id":"1775530199454030330","flags":128,"ts_in_delta":757,"sequence":173044,"symbol":"FCEU SI 20260615 PS"}
{"ts_recv":"2026-04-07T02:50:00.596129683Z","hd":{"ts_event":"2026-04-07T02:50:00.596109537Z","rtype":160,"publisher_id":101,"instrument_id":436},"action":"C","side":"B","price":"1.156810000","size":30,"channel_id":23,"order_id":"10998902236308806138","flags":0,"ts_in_delta":957,"sequence":173060,"symbol":"FCEU SI 20260615 PS"}