{"ts_recv":"2026-04-07T02:57:56.831593976Z","hd":{"ts_event":"2026-04-07T02:57:56.831576643Z","rtype":160,"publisher_id":101,"instrument_id":436},"action":"C","side":"B","price":"1.156600000","size":30,"channel_id":23,"order_id":"10998902713674138080","flags":0,"ts_in_delta":929,"sequence":176848,"symbol":"FCEU SI 20260615 PS"}
{"ts_recv":"2026-04-07T02:57:56.831593976Z","hd":{"ts_event":"2026-04-07T02:57:56.831576643Z","rtype":160,"publisher_id":101,"instrument_id":436},"action":"A","side":"B","price":"1.156590000","size":30,"channel_id":23,"order_id":"10998902713686358318","flags":0,"ts_in_delta":929,"sequence":176848,"symbol":"FCEU SI 20260615 PS"}
{"ts_recv":"2026-04-07T02:57:56.831593976Z","hd":{"ts_event":"2026-04-07T02:57:56.831576643Z","rtype":160,"publisher_id":101,"instrument_id":436},"action":"C","side":"A","price":"1.156700000","size":30,"channel_id":23,"order_id":"1775530676819362272","flags":0,"ts_in_delta":929,"sequence":176848,"symbol":"FCEU SI 20260615 PS"}
{"ts_recv":"2026-04-07T02:57:56.831593976Z","hd":{"ts_event":"2026-04-07T02:57:56.831576643Z","rtype":160,"publisher_id":101,"instrument_id":436},"action":"A","side":"A","price":"1.156690000","size":30,"channel_id":23,"order_id":"1775530676831582510","flags":128,"ts_in_delta":929,"sequence":176848,"symbol":"FCEU SI 20260615 PS"}
{"ts_recv":"2026-04-07T02:58:02.778919081Z","hd":{"ts_event":"2026-04-07T02:58:02.778896555Z","rtype":160,"publisher_id":101,"instrument_id":436},"action":"C","side":"B","price":"1.156600000","size":30,"channel_id":23,"order_id":"10998902713645232998","flags":0,"ts_in_delta":920,"sequence":176900,"symbol":"FCEU SI 20260615 PS"}
{"ts_recv":"2026-04-07T02:58:02.778919081Z","hd":{"ts_event":"2026-04-07T02:58:02.778896555Z","rtype":160,"publisher_id":101,"instrument_id":436},"action":"A","side":"B","price":"1.156580000","size":30,"channel_id":23,"order_id":"10998902719633678681","flags":0,"ts_in_delta":920,"sequence":176900,"symbol":"FCEU SI 20260615 PS"}
{"ts_recv":"2026-04-07T02:58:02.778919081Z","hd":{"ts_event":"2026-04-07T02:58:02.778896555Z","rtype":160,"publisher_id":101,"instrument_id":436},"action":"C","side":"A","price":"1.156700000","size":30,"channel_id":23,"order_id":"1775530676790457190","flags":0,"ts_in_delta":920,"sequence":176900,"symbol":"FCEU SI 20260615 PS"}
{"ts_recv":"2026-04-07T02:58:02.778919081Z","hd":{"ts_event":"2026-04-07T02:58:02.778896555Z","rtype":160,"publisher_id":101,"instrument_id":436},"action":"A","side":"A","price":"1.156680000","size":30,"channel_id":23,"order_id":"1775530682778902873","flags":128,"ts_in_delta":920,"sequence":176900,"symbol":"FCEU SI 20260615 PS"}
{"ts_recv":"2026-04-07T02:58:02.779047085Z","hd":{"ts_event":"2026-04-07T02:58:02.779027071Z","rtype":160,"publisher_id":101,"instrument_id":436},"action":"C","side":"B","price":"1.156590000","size":30,"channel_id":23,"order_id":"10998902713686358318","flags":0,"ts_in_delta":1070,"sequence":176901,"symbol":"FCEU SI 20260615 PS"}
{"ts_recv":"2026-04-07T02:58:02.779047085Z","hd":{"ts_event":"2026-04-07T02:58:02.779027071Z","rtype":160,"publisher_id":101,"instrument_id":436},"action":"A","side":"B","price":"1.156580000","size":30,"channel_id":23,"order_id":"10998902719633809194","flags":0,"ts_in_delta":1070,"sequence":176901,"symbol":"FCEU SI 20260615 PS"}
{"ts_recv":"2026-04-07T02:58:02.779047085Z","hd":{"ts_event":"2026-04-07T02:58:02.779027071Z","rtype":160,"publisher_id":101,"instrument_id":436},"action":"C","side":"A","price":"1.156690000","size":30,"channel_id":23,"order_id":"1775530676831582510","flags":0,"ts_in_delta":1070,"sequence":176901,"symbol":"FCEU SI 20260615 PS"}
{"ts_recv":"2026-04-07T02:58:02.779047085Z","hd":{"ts_event":"2026-04-07T02:58:02.779027071Z","rtype":160,"publisher_id":101,"instrument_id":436},"action":"A","side":"A","price":"1.156680000","size":30,"channel_id":23,"order_id":"1775530682779033386","flags":128,"ts_in_delta":1070,"sequence":176901,"symbol":"FCEU SI 20260615 PS"}
{"ts_recv":"2026-04-07T02:58:03.177871167Z","hd":{"ts_event":"2026-04-07T02:58:03.177848161Z","rtype":160,"publisher_id":101,"instrument_id":436},"action":"C","side":"B","price":"1.156580000","size":30,"channel_id":23,"order_id":"10998902719633809194","flags":0,"ts_in_delta":948,"sequence":176910,"symbol":"FCEU SI 20260615 PS"}
{"ts_recv":"2026-04-07T02:58:03.177871167Z","hd":{"ts_event":"2026-04-07T02:58:03.177848161Z","rtype":160,"publisher_id":101,"instrument_id":436},"action":"A","side":"B","price":"1.156570000","size":30,"channel_id":23,"order_id":"10998902720032630786","flags":0,"ts_in_delta":948,"sequence":176910,"symbol":"FCEU SI 20260615 PS"}
{"ts_recv":"2026-04-07T02:58:03.177871167Z","hd":{"ts_event":"2026-04-07T02:58:03.177848161Z","rtype":160,"publisher_id":101,"instrument_id":436},"action":"C","side":"A","price":"1.156680000","size":30,"channel_id":23,"order_id":"1775530682779033386","flags":0,"ts_in_delta":948,"sequence":176910,"symbol":"FCEU SI 20260615 PS"}
{"ts_recv":"2026-04-07T02:58:03.177871167Z","hd":{"ts_event":"2026-04-07T02:58:03.177848161Z","rtype":160,"publisher_id":101,"instrument_id":436},"action":"A","side":"A","price":"1.156670000","size":30,"channel_id":23,"order_id":"1775530683177854978","flags":128,"ts_in_delta":948,"sequence":176910,"symbol":"FCEU SI 20260615 PS"}
{"ts_recv":"2026-04-07T02:58:03.177930746Z","hd":{"ts_event":"2026-04-07T02:58:03.177909199Z","rtype":160,"publisher_id":101,"instrument_id":436},"action":"C","side":"B","price":"1.156580000","size":30,"channel_id":23,"order_id":"10998902719633678681","flags":0,"ts_in_delta":948,"sequence":176911,"symbol":"FCEU SI 20260615 PS"}
{"ts_recv":"2026-04-07T02:58:03.177930746Z","hd":{"ts_event":"2026-04-07T02:58:03.177909199Z","rtype":160,"publisher_id":101,"instrument_id":436},"action":"A","side":"B","price":"1.156560000","size":30,"channel_id":23,"order_id":"10998902720032690934","flags":0,"ts_in_delta":948,"sequence":176911,"symbol":"FCEU SI 20260615 PS"}
{"ts_recv":"2026-04-07T02:58:03.177930746Z","hd":{"ts_event":"2026-04-07T02:58:03.177909199Z","rtype":160,"publisher_id":101,"instrument_id":436},"action":"C","side":"A","price":"1.156680000","size":30,"channel_id":23,"order_id":"1775530682778902873","flags":0,"ts_in_delta":948,"sequence":176911,"symbol":"FCEU SI 20260615 PS"}
{"ts_recv":"2026-04-07T02:58:03.177930746Z","hd":{"ts_event":"2026-04-07T02:58:03.177909199Z","rtype":160,"publisher_id":101,"instrument_id":436},"action":"A","side":"A","price":"1.156660000","size":30,"channel_id":23,"order_id":"1775530683177915126","flags":128,"ts_in_delta":948,"sequence":176911,"symbol":"FCEU SI 20260615 PS"}
{"ts_recv":"2026-04-07T02:58:03.177956012Z","hd":{"ts_event":"2026-04-07T02:58:03.177937325Z","rtype":160,"publisher_id":101,"instrument_id":436},"action":"C","side":"B","price":"1.156570000","size":30,"channel_id":23,"order_id":"10998902720032630786","flags":0,"ts_in_delta":924,"sequence":176912,"symbol":"FCEU SI 20260615 PS"}
{"ts_recv":"2026-04-07T02:58:03.177956012Z","hd":{"ts_event":"2026-04-07T02:58:03.177937325Z","rtype":160,"publisher_id":101,"instrument_id":436},"action":"A","side":"B","price":"1.156560000","size":30,"channel_id":23,"order_id":"10998902720032719216","flags":0,"ts_in_delta":924,"sequence":176912,"symbol":"FCEU SI 20260615 PS"}
{"ts_recv":"2026-04-07T02:58:03.177956012Z","hd":{"ts_event":"2026-04-07T02:58:03.177937325Z","rtype":160,"publisher_id":101,"instrument_id":436},"action":"C","side":"A","price":"1.156670000","size":30,"channel_id":23,"order_id":"1775530683177854978","flags":0,"ts_in_delta":924,"sequence":176912,"symbol":"FCEU SI 20260615 PS"}
{"ts_recv":"2026-04-07T02:58:03.177956012Z","hd":{"ts_event":"2026-04-07T02:58:03.177937325Z","rtype":160,"publisher_id":101,"instrument_id":436},"action":"A","side":"A","price":"1.156660000","size":30,"channel_id":23,"order_id":"1775530683177943408","flags":128,"ts_in_delta":924,"sequence":176912,"symbol":"FCEU SI 20260615 PS"}
{"ts_recv":"2026-04-07T02:58:03.260282532Z","hd":{"ts_event":"2026-04-07T02:58:03.260268021Z","rtype":160,"publisher_id":101,"instrument_id":436},"action":"A","side":"A","price":"1.156800000","size":20,"channel_id":23,"order_id":"1775530683260274162","flags":128,"ts_in_delta":842,"sequence":176928,"symbol":"FCEU SI 20260615 PS"}
{"ts_recv":"2026-04-07T02:58:03.260341995Z","hd":{"ts_event":"2026-04-07T02:58:03.260329577Z","rtype":160,"publisher_id":101,"instrument_id":436},"action":"C","side":"A","price":"1.156900000","size":20,"channel_id":23,"order_id":"1775530390839242642","flags":128,"ts_in_delta":976,"sequence":176930,"symbol":"FCEU SI 20260615 PS"}
{"ts_recv":"2026-04-07T02:58:03.320294972Z","hd":{"ts_event":"2026-04-07T02:58:03.320274313Z","rtype":160,"publisher_id":101,"instrument_id":436},"action":"C","side":"B","price":"1.156560000","size":30,"channel_id":23,"order_id":"10998902720032719216","flags":0,"ts_in_delta":1022,"sequence":176935,"symbol":"FCEU SI 20260615 PS"}
{"ts_recv":"2026-04-07T02:58:03.320294972Z","hd":{"ts_event":"2026-04-07T02:58:03.320274313Z","rtype":160,"publisher_id":101,"instrument_id":436},"action":"A","side":"B","price":"1.156550000","size":30,"channel_id":23,"order_id":"10998902720175055948","flags":0,"ts_in_delta":1022,"sequence":176935,"symbol":"FCEU SI 20260615 PS"}
{"ts_recv":"2026-04-07T02:58:03.320294972Z","hd":{"ts_event":"2026-04-07T02:58:03.320274313Z","rtype":160,"publisher_id":101,"instrument_id":436},"action":"C","side":"A","price":"1.156660000","size":30,"channel_id":23,"order_id":"1775530683177943408","flags":0,"ts_in_delta":1022,"sequence":176935,"symbol":"FCEU SI 20260615 PS"}
{"ts_recv":"2026-04-07T02:58:03.320294972Z","hd":{"ts_event":"2026-04-07T02:58:03.320274313Z","rtype":160,"publisher_id":101,"instrument_id":436},"action":"A","side":"A","price":"1.156650000","size":30,"channel_id":23,"order_id":"1775530683320280140","flags":128,"ts_in_delta":1022,"sequence":176935,"symbol":"FCEU SI 20260615 PS"}
{"ts_recv":"2026-04-07T02:58:03.320358114Z","hd":{"ts_event":"2026-04-07T02:58:03.320340233Z","rtype":160,"publisher_id":101,"instrument_id":436},"action":"C","side":"B","price":"1.156550000","size":30,"channel_id":23,"order_id":"10998902720175055948","flags":0,"ts_in_delta":1071,"sequence":176936,"symbol":"FCEU SI 20260615 PS"}
{"ts_recv":"2026-04-07T02:58:03.320358114Z","hd":{"ts_event":"2026-04-07T02:58:03.320340233Z","rtype":160,"publisher_id":101,"instrument_id":436},"action":"A","side":"B","price":"1.156540000","size":30,"channel_id":23,"order_id":"10998902720175121977","flags":0,"ts_in_delta":1071,"sequence":176936,"symbol":"FCEU SI 20260615 PS"}
{"ts_recv":"2026-04-07T02:58:03.320358114Z","hd":{"ts_event":"2026-04-07T02:58:03.320340233Z","rtype":160,"publisher_id":101,"instrument_id":436},"action":"C","side":"A","price":"1.156650000","size":30,"channel_id":23,"order_id":"1775530683320280140","flags":0,"ts_in_delta":1071,"sequence":176936,"symbol":"FCEU SI 20260615 PS"}
{"ts_recv":"2026-04-07T02:58:03.320358114Z","hd":{"ts_event":"2026-04-07T02:58:03.320340233Z","rtype":160,"publisher_id":101,"instrument_id":436},"action":"A","side":"A","price":"1.156640000","size":30,"channel_id":23,"order_id":"1775530683320346169","flags":128,"ts_in_delta":1071,"sequence":176936,"symbol":"FCEU SI 20260615 PS"}
{"ts_recv":"2026-04-07T02:58:03.320412801Z","hd":{"ts_event":"2026-04-07T02:58:03.320395145Z","rtype":160,"publisher_id":101,"instrument_id":436},"action":"C","side":"B","price":"1.156540000","size":30,"channel_id":23,"order_id":"10998902720175121977","flags":0,"ts_in_delta":1080,"sequence":176937,"symbol":"FCEU SI 20260615 PS"}
{"ts_recv":"2026-04-07T02:58:03.320412801Z","hd":{"ts_event":"2026-04-07T02:58:03.320395145Z","rtype":160,"publisher_id":101,"instrument_id":436},"action":"A","side":"B","price":"1.156550000","size":30,"channel_id":23,"order_id":"10998902720175177018","flags":0,"ts_in_delta":1080,"sequence":176937,"symbol":"FCEU SI 20260615 PS"}
{"ts_recv":"2026-04-07T02:58:03.320412801Z","hd":{"ts_event":"2026-04-07T02:58:03.320395145Z","rtype":160,"publisher_id":101,"instrument_id":436},"action":"C","side":"A","price":"1.156640000","size":30,"channel_id":23,"order_id":"1775530683320346169","flags":0,"ts_in_delta":1080,"sequence":176937,"symbol":"FCEU SI 20260615 PS"}
{"ts_recv":"2026-04-07T02:58:03.320412801Z","hd":{"ts_event":"2026-04-07T02:58:03.320395145Z","rtype":160,"publisher_id":101,"instrument_id":436},"action":"A","side":"A","price":"1.156650000","size":30,"channel_id":23,"order_id":"1775530683320401210","flags":128,"ts_in_delta":1080,"sequence":176937,"symbol":"FCEU SI 20260615 PS"}
{"ts_recv":"2026-04-07T02:58:16.188965220Z","hd":{"ts_event":"2026-04-07T02:58:16.188946099Z","rtype":160,"publisher_id":101,"instrument_id":436},"action":"C","side":"B","price":"1.156550000","size":30,"channel_id":23,"order_id":"10998902720175177018","flags":0,"ts_in_delta":749,"sequence":177031,"symbol":"FCEU SI 20260615 PS"}
{"ts_recv":"2026-04-07T02:58:16.188965220Z","hd":{"ts_event":"2026-04-07T02:58:16.188946099Z","rtype":160,"publisher_id":101,"instrument_id":436},"action":"A","side":"B","price":"1.156560000","size":30,"channel_id":23,"order_id":"10998902733043728191","flags":0,"ts_in_delta":749,"sequence":177031,"symbol":"FCEU SI 20260615 PS"}
{"ts_recv":"2026-04-07T02:58:16.188965220Z","hd":{"ts_event":"2026-04-07T02:58:16.188946099Z","rtype":160,"publisher_id":101,"instrument_id":436},"action":"C","side":"A","price":"1.156650000","size":30,"channel_id":23,"order_id":"1775530683320401210","flags":0,"ts_in_delta":749,"sequence":177031,"symbol":"FCEU SI 20260615 PS"}
{"ts_recv":"2026-04-07T02:58:16.188965220Z","hd":{"ts_event":"2026-04-07T02:58:16.188946099Z","rtype":160,"publisher_id":101,"instrument_id":436},"action":"A","side":"A","price":"1.156660000","size":30,"channel_id":23,"order_id":"1775530696188952383","flags":128,"ts_in_delta":749,"sequence":177031,"symbol":"FCEU SI 20260615 PS"}
{"ts_recv":"2026-04-07T02:58:23.292283012Z","hd":{"ts_event":"2026-04-07T02:58:23.292262015Z","rtype":160,"publisher_id":101,"instrument_id":436},"action":"C","side":"B","price":"1.156560000","size":30,"channel_id":23,"order_id":"10998902733043728191","flags":0,"ts_in_delta":887,"sequence":177099,"symbol":"FCEU SI 20260615 PS"}
{"ts_recv":"2026-04-07T02:58:23.292283012Z","hd":{"ts_event":"2026-04-07T02:58:23.292262015Z","rtype":160,"publisher_id":101,"instrument_id":436},"action":"A","side":"B","price":"1.156570000","size":30,"channel_id":23,"order_id":"10998902740147043989","flags":0,"ts_in_delta":887,"sequence":177099,"symbol":"FCEU SI 20260615 PS"}
{"ts_recv":"2026-04-07T02:58:23.292283012Z","hd":{"ts_event":"2026-04-07T02:58:23.292262015Z","rtype":160,"publisher_id":101,"instrument_id":436},"action":"C","side":"A","price":"1.156660000","size":30,"channel_id":23,"order_id":"1775530696188952383","flags":0,"ts_in_delta":887,"sequence":177099,"symbol":"FCEU SI 20260615 PS"}
{"ts_recv":"2026-04-07T02:58:23.292283012Z","hd":{"ts_event":"2026-04-07T02:58:23.292262015Z","rtype":160,"publisher_id":101,"instrument_id":436},"action":"A","side":"A","price":"1.156670000","size":30,"channel_id":23,"order_id":"1775530703292268181","flags":128,"ts_in_delta":887,"sequence":177099,"symbol":"FCEU SI 20260615 PS"}
{"ts_recv":"2026-04-07T02:58:26.326302159Z","hd":{"ts_event":"2026-04-07T02:58:26.326282157Z","rtype":160,"publisher_id":101,"instrument_id":436},"action":"C","side":"B","price":"1.156560000","size":30,"channel_id":23,"order_id":"10998902720032690934","flags":0,"ts_in_delta":951,"sequence":177126,"symbol":"FCEU SI 20260615 PS"}
{"ts_recv":"2026-04-07T02:58:26.326302159Z","hd":{"ts_event":"2026-04-07T02:58:26.326282157Z","rtype":160,"publisher_id":101,"instrument_id":436},"action":"A","side":"B","price":"1.156580000","size":30,"channel_id":23,"order_id":"10998902743181063916","flags":0,"ts_in_delta":951,"sequence":177126,"symbol":"FCEU SI 20260615 PS"}
{"ts_recv":"2026-04-07T02:58:26.326302159Z","hd":{"ts_event":"2026-04-07T02:58:26.326282157Z","rtype":160,"publisher_id":101,"instrument_id":436},"action":"C","side":"A","price":"1.156660000","size":30,"channel_id":23,"order_id":"1775530683177915126","flags":0,"ts_in_delta":951,"sequence":177126,"symbol":"FCEU SI 20260615 PS"}
{"ts_recv":"2026-04-07T02:58:26.326302159Z","hd":{"ts_event":"2026-04-07T02:58:26.326282157Z","rtype":160,"publisher_id":101,"instrument_id":436},"action":"A","side":"A","price":"1.156680000","size":30,"channel_id":23,"order_id":"1775530706326288108","flags":128,"ts_in_delta":951,"sequence":177126,"symbol":"FCEU SI 20260615 PS"}
{"ts_recv":"2026-04-07T02:58:26.326414205Z","hd":{"ts_event":"2026-04-07T02:58:26.326394325Z","rtype":160,"publisher_id":101,"instrument_id":436},"action":"C","side":"B","price":"1.156570000","size":30,"channel_id":23,"order_id":"10998902740147043989","flags":0,"ts_in_delta":930,"sequence":177127,"symbol":"FCEU SI 20260615 PS"}
{"ts_recv":"2026-04-07T02:58:26.326414205Z","hd":{"ts_event":"2026-04-07T02:58:26.326394325Z","rtype":160,"publisher_id":101,"instrument_id":436},"action":"A","side":"B","price":"1.156580000","size":30,"channel_id":23,"order_id":"10998902743181176304","flags":0,"ts_in_delta":930,"sequence":177127,"symbol":"FCEU SI 20260615 PS"}
{"ts_recv":"2026-04-07T02:58:26.326414205Z","hd":{"ts_event":"2026-04-07T02:58:26.326394325Z","rtype":160,"publisher_id":101,"instrument_id":436},"action":"C","side":"A","price":"1.156670000","size":30,"channel_id":23,"order_id":"1775530703292268181","flags":0,"ts_in_delta":930,"sequence":177127,"symbol":"FCEU SI 20260615 PS"}
{"ts_recv":"2026-04-07T02:58:26.326414205Z","hd":{"ts_event":"2026-04-07T02:58:26.326394325Z","rtype":160,"publisher_id":101,"instrument_id":436},"action":"A","side":"A","price":"1.156680000","size":30,"channel_id":23,"order_id":"1775530706326400496","flags":128,"ts_in_delta":930,"sequence":177127,"symbol":"FCEU SI 20260615 PS"}
{"ts_recv":"2026-04-07T02:58:27.183136216Z","hd":{"ts_event":"2026-04-07T02:58:27.183117183Z","rtype":160,"publisher_id":101,"instrument_id":436},"action":"C","side":"B","price":"1.156580000","size":30,"channel_id":23,"order_id":"10998902743181176304","flags":0,"ts_in_delta":956,"sequence":177154,"symbol":"FCEU SI 20260615 PS"}
{"ts_recv":"2026-04-07T02:58:27.183136216Z","hd":{"ts_event":"2026-04-07T02:58:27.183117183Z","rtype":160,"publisher_id":101,"instrument_id":436},"action":"A","side":"B","price":"1.156590000","size":30,"channel_id":23,"order_id":"10998902744037899186","flags":0,"ts_in_delta":956,"sequence":177154,"symbol":"FCEU SI 20260615 PS"}
{"ts_recv":"2026-04-07T02:58:27.183136216Z","hd":{"ts_event":"2026-04-07T02:58:27.183117183Z","rtype":160,"publisher_id":101,"instrument_id":436},"action":"C","side":"A","price":"1.156680000","size":30,"channel_id":23,"order_id":"1775530706326400496","flags":0,"ts_in_delta":956,"sequence":177154,"symbol":"FCEU SI 20260615 PS"}
{"ts_recv":"2026-04-07T02:58:27.183136216Z","hd":{"ts_event":"2026-04-07T02:58:27.183117183Z","rtype":160,"publisher_id":101,"instrument_id":436},"action":"A","side":"A","price":"1.156690000","size":30,"channel_id":23,"order_id":"1775530707183123378","flags":128,"ts_in_delta":956,"sequence":177154,"symbol":"FCEU SI 20260615 PS"}
{"ts_recv":"2026-04-07T02:58:27.183190012Z","hd":{"ts_event":"2026-04-07T02:58:27.183171329Z","rtype":160,"publisher_id":101,"instrument_id":436},"action":"C","side":"B","price":"1.156580000","size":30,"channel_id":23,"order_id":"10998902743181063916","flags":0,"ts_in_delta":910,"sequence":177155,"symbol":"FCEU SI 20260615 PS"}
{"ts_recv":"2026-04-07T02:58:27.183190012Z","hd":{"ts_event":"2026-04-07T02:58:27.183171329Z","rtype":160,"publisher_id":101,"instrument_id":436},"action":"A","side":"B","price":"1.156600000","size":30,"channel_id":23,"order_id":"10998902744037953312","flags":0,"ts_in_delta":910,"sequence":177155,"symbol":"FCEU SI 20260615 PS"}
{"ts_recv":"2026-04-07T02:58:27.183190012Z","hd":{"ts_event":"2026-04-07T02:58:27.183171329Z","rtype":160,"publisher_id":101,"instrument_id":436},"action":"C","side":"A","price":"1.156680000","size":30,"channel_id":23,"order_id":"1775530706326288108","flags":0,"ts_in_delta":910,"sequence":177155,"symbol":"FCEU SI 20260615 PS"}
{"ts_recv":"2026-04-07T02:58:27.183190012Z","hd":{"ts_event":"2026-04-07T02:58:27.183171329Z","rtype":160,"publisher_id":101,"instrument_id":436},"action":"A","side":"A","price":"1.156700000","size":30,"channel_id":23,"order_id":"1775530707183177504","flags":128,"ts_in_delta":910,"sequence":177155,"symbol":"FCEU SI 20260615 PS"}
{"ts_recv":"2026-04-07T02:58:27.183217098Z","hd":{"ts_event":"2026-04-07T02:58:27.183198433Z","rtype":160,"publisher_id":101,"instrument_id":436},"action":"C","side":"B","price":"1.156590000","size":30,"channel_id":23,"order_id":"10998902744037899186","flags":0,"ts_in_delta":941,"sequence":177156,"symbol":"FCEU SI 20260615 PS"}
{"ts_recv":"2026-04-07T02:58:27.183217098Z","hd":{"ts_event":"2026-04-07T02:58:27.183198433Z","rtype":160,"publisher_id":101,"instrument_id":436},"action":"A","side":"B","price":"1.156600000","size":30,"channel_id":23,"order_id":"10998902744037980310","flags":0,"ts_in_delta":941,"sequence":177156,"symbol":"FCEU SI 20260615 PS"}
{"ts_recv":"2026-04-07T02:58:27.183217098Z","hd":{"ts_event":"2026-04-07T02:58:27.183198433Z","rtype":160,"publisher_id":101,"instrument_id":436},"action":"C","side":"A","price":"1.156690000","size":30,"channel_id":23,"order_id":"1775530707183123378","flags":0,"ts_in_delta":941,"sequence":177156,"symbol":"FCEU SI 20260615 PS"}
{"ts_recv":"2026-04-07T02:58:27.183217098Z","hd":{"ts_event":"2026-04-07T02:58:27.183198433Z","rtype":160,"publisher_id":101,"instrument_id":436},"action":"A","side":"A","price":"1.156700000","size":30,"channel_id":23,"order_id":"1775530707183204502","flags":128,"ts_in_delta":941,"sequence":177156,"symbol":"FCEU SI 20260615 PS"}
{"ts_recv":"2026-04-07T02:58:59.164183957Z","hd":{"ts_event":"2026-04-07T02:58:59.164155829Z","rtype":160,"publisher_id":101,"instrument_id":436},"action":"C","side":"B","price":"1.156600000","size":30,"channel_id":23,"order_id":"10998902744037980310","flags":0,"ts_in_delta":917,"sequence":177345,"symbol":"FCEU SI 20260615 PS"}
{"ts_recv":"2026-04-07T02:58:59.164183957Z","hd":{"ts_event":"2026-04-07T02:58:59.164155829Z","rtype":160,"publisher_id":101,"instrument_id":436},"action":"A","side":"B","price":"1.156610000","size":30,"channel_id":23,"order_id":"10998902776018940177","flags":0,"ts_in_delta":917,"sequence":177345,"symbol":"FCEU SI 20260615 PS"}
{"ts_recv":"2026-04-07T02:58:59.164183957Z","hd":{"ts_event":"2026-04-07T02:58:59.164155829Z","rtype":160,"publisher_id":101,"instrument_id":436},"action":"C","side":"A","price":"1.156700000","size":30,"channel_id":23,"order_id":"1775530707183204502","flags":0,"ts_in_delta":917,"sequence":177345,"symbol":"FCEU SI 20260615 PS"}
{"ts_recv":"2026-04-07T02:58:59.164183957Z","hd":{"ts_event":"2026-04-07T02:58:59.164155829Z","rtype":160,"publisher_id":101,"instrument_id":436},"action":"A","side":"A","price":"1.156710000","size":30,"channel_id":23,"order_id":"1775530739164164369","flags":128,"ts_in_delta":917,"sequence":177345,"symbol":"FCEU SI 20260615 PS"}
{"ts_recv":"2026-04-07T02:58:59.164264439Z","hd":{"ts_event":"2026-04-07T02:58:59.164240809Z","rtype":160,"publisher_id":101,"instrument_id":436},"action":"C","side":"B","price":"1.156600000","size":30,"channel_id":23,"order_id":"10998902744037953312","flags":0,"ts_in_delta":901,"sequence":177346,"symbol":"FCEU SI 20260615 PS"}
{"ts_recv":"2026-04-07T02:58:59.164264439Z","hd":{"ts_event":"2026-04-07T02:58:59.164240809Z","rtype":160,"publisher_id":101,"instrument_id":436},"action":"A","side":"B","price":"1.156620000","size":30,"channel_id":23,"order_id":"10998902776019023068","flags":0,"ts_in_delta":901,"sequence":177346,"symbol":"FCEU SI 20260615 PS"}
{"ts_recv":"2026-04-07T02:58:59.164264439Z","hd":{"ts_event":"2026-04-07T02:58:59.164240809Z","rtype":160,"publisher_id":101,"instrument_id":436},"action":"C","side":"A","price":"1.156700000","size":30,"channel_id":23,"order_id":"1775530707183177504","flags":0,"ts_in_delta":901,"sequence":177346,"symbol":"FCEU SI 20260615 PS"}
{"ts_recv":"2026-04-07T02:58:59.164264439Z","hd":{"ts_event":"2026-04-07T02:58:59.164240809Z","rtype":160,"publisher_id":101,"instrument_id":436},"action":"A","side":"A","price":"1.156720000","size":30,"channel_id":23,"order_id":"1775530739164247260","flags":128,"ts_in_delta":901,"sequence":177346,"symbol":"FCEU SI 20260615 PS"}
{"ts_recv":"2026-04-07T02:58:59.164329432Z","hd":{"ts_event":"2026-04-07T02:58:59.164312023Z","rtype":160,"publisher_id":101,"instrument_id":436},"action":"C","side":"B","price":"1.156610000","size":30,"channel_id":23,"order_id":"10998902776018940177","flags":0,"ts_in_delta":939,"sequence":177347,"symbol":"FCEU SI 20260615 PS"}
{"ts_recv":"2026-04-07T02:58:59.164329432Z","hd":{"ts_event":"2026-04-07T02:58:59.164312023Z","rtype":160,"publisher_id":101,"instrument_id":436},"action":"A","side":"B","price":"1.156620000","size":30,"channel_id":23,"order_id":"10998902776019093926","flags":0,"ts_in_delta":939,"sequence":177347,"symbol":"FCEU SI 20260615 PS"}
{"ts_recv":"2026-04-07T02:58:59.164329432Z","hd":{"ts_event":"2026-04-07T02:58:59.164312023Z","rtype":160,"publisher_id":101,"instrument_id":436},"action":"C","side":"A","price":"1.156710000","size":30,"channel_id":23,"order_id":"1775530739164164369","flags":0,"ts_in_delta":939,"sequence":177347,"symbol":"FCEU SI 20260615 PS"}
{"ts_recv":"2026-04-07T02:58:59.164329432Z","hd":{"ts_event":"2026-04-07T02:58:59.164312023Z","rtype":160,"publisher_id":101,"instrument_id":436},"action":"A","side":"A","price":"1.156720000","size":30,"channel_id":23,"order_id":"1775530739164318118","flags":128,"ts_in_delta":939,"sequence":177347,"symbol":"FCEU SI 20260615 PS"}
{"ts_recv":"2026-04-07T02:59:13.084106166Z","hd":{"ts_event":"2026-04-07T02:59:13.084081803Z","rtype":160,"publisher_id":101,"instrument_id":436},"action":"C","side":"B","price":"1.156620000","size":30,"channel_id":23,"order_id":"10998902776019093926","flags":0,"ts_in_delta":1291,"sequence":177439,"symbol":"FCEU SI 20260615 PS"}
{"ts_recv":"2026-04-07T02:59:13.084106166Z","hd":{"ts_event":"2026-04-07T02:59:13.084081803Z","rtype":160,"publisher_id":101,"instrument_id":436},"action":"A","side":"B","price":"1.156610000","size":30,"channel_id":23,"order_id":"10998902789938864127","flags":0,"ts_in_delta":1291,"sequence":177439,"symbol":"FCEU SI 20260615 PS"}
{"ts_recv":"2026-04-07T02:59:13.084106166Z","hd":{"ts_event":"2026-04-07T02:59:13.084081803Z","rtype":160,"publisher_id":101,"instrument_id":436},"action":"C","side":"A","price":"1.156720000","size":30,"channel_id":23,"order_id":"1775530739164318118","flags":0,"ts_in_delta":1291,"sequence":177439,"symbol":"FCEU SI 20260615 PS"}
{"ts_recv":"2026-04-07T02:59:13.084106166Z","hd":{"ts_event":"2026-04-07T02:59:13.084081803Z","rtype":160,"publisher_id":101,"instrument_id":436},"action":"A","side":"A","price":"1.156710000","size":30,"channel_id":23,"order_id":"1775530753084088319","flags":128,"ts_in_delta":1291,"sequence":177439,"symbol":"FCEU SI 20260615 PS"}
{"ts_recv":"2026-04-07T02:59:13.135348288Z","hd":{"ts_event":"2026-04-07T02:59:13.135324641Z","rtype":160,"publisher_id":101,"instrument_id":436},"action":"C","side":"B","price":"1.156620000","size":30,"channel_id":23,"order_id":"10998902776019023068","flags":0,"ts_in_delta":934,"sequence":177443,"symbol":"FCEU SI 20260615 PS"}
{"ts_recv":"2026-04-07T02:59:13.135348288Z","hd":{"ts_event":"2026-04-07T02:59:13.135324641Z","rtype":160,"publisher_id":101,"instrument_id":436},"action":"A","side":"B","price":"1.156600000","size":30,"channel_id":23,"order_id":"10998902789990106701","flags":0,"ts_in_delta":934,"sequence":177443,"symbol":"FCEU SI 20260615 PS"}
{"ts_recv":"2026-04-07T02:59:13.135348288Z","hd":{"ts_event":"2026-04-07T02:59:13.135324641Z","rtype":160,"publisher_id":101,"instrument_id":436},"action":"C","side":"A","price":"1.156720000","size":30,"channel_id":23,"order_id":"1775530739164247260","flags":0,"ts_in_delta":934,"sequence":177443,"symbol":"FCEU SI 20260615 PS"}
{"ts_recv":"2026-04-07T02:59:13.135348288Z","hd":{"ts_event":"2026-04-07T02:59:13.135324641Z","rtype":160,"publisher_id":101,"instrument_id":436},"action":"A","side":"A","price":"1.156700000","size":30,"channel_id":23,"order_id":"1775530753135330893","flags":128,"ts_in_delta":934,"sequence":177443,"symbol":"FCEU SI 20260615 PS"}
{"ts_recv":"2026-04-07T02:59:13.135409233Z","hd":{"ts_event":"2026-04-07T02:59:13.135390773Z","rtype":160,"publisher_id":101,"instrument_id":436},"action":"C","side":"B","price":"1.156610000","size":30,"channel_id":23,"order_id":"10998902789938864127","flags":0,"ts_in_delta":909,"sequence":177444,"symbol":"FCEU SI 20260615 PS"}
{"ts_recv":"2026-04-07T02:59:13.135409233Z","hd":{"ts_event":"2026-04-07T02:59:13.135390773Z","rtype":160,"publisher_id":101,"instrument_id":436},"action":"A","side":"B","price":"1.156600000","size":30,"channel_id":23,"order_id":"10998902789990172563","flags":0,"ts_in_delta":909,"sequence":177444,"symbol":"FCEU SI 20260615 PS"}
{"ts_recv":"2026-04-07T02:59:13.135409233Z","hd":{"ts_event":"2026-04-07T02:59:13.135390773Z","rtype":160,"publisher_id":101,"instrument_id":436},"action":"C","side":"A","price":"1.156710000","size":30,"channel_id":23,"order_id":"1775530753084088319","flags":0,"ts_in_delta":909,"sequence":177444,"symbol":"FCEU SI 20260615 PS"}
{"ts_recv":"2026-04-07T02:59:13.135409233Z","hd":{"ts_event":"2026-04-07T02:59:13.135390773Z","rtype":160,"publisher_id":101,"instrument_id":436},"action":"A","side":"A","price":"1.156700000","size":30,"channel_id":23,"order_id":"1775530753135396755","flags":128,"ts_in_delta":909,"sequence":177444,"symbol":"FCEU SI 20260615 PS"}
{"ts_recv":"2026-04-07T02:59:33.832106940Z","hd":{"ts_event":"2026-04-07T02:59:33.832073663Z","rtype":160,"publisher_id":101,"instrument_id":436},"action":"C","side":"B","price":"1.156600000","size":30,"channel_id":23,"order_id":"10998902789990172563","flags":0,"ts_in_delta":1303,"sequence":177535,"symbol":"FCEU SI 20260615 PS"}
{"ts_recv":"2026-04-07T02:59:33.832106940Z","hd":{"ts_event":"2026-04-07T02:59:33.832073663Z","rtype":160,"publisher_id":101,"instrument_id":436},"action":"A","side":"B","price":"1.156610000","size":30,"channel_id":23,"order_id":"10998902810686862505","flags":0,"ts_in_delta":1303,"sequence":177535,"symbol":"FCEU SI 20260615 PS"}
{"ts_recv":"2026-04-07T02:59:33.832106940Z","hd":{"ts_event":"2026-04-07T02:59:33.832073663Z","rtype":160,"publisher_id":101,"instrument_id":436},"action":"C","side":"A","price":"1.156700000","size":30,"channel_id":23,"order_id":"1775530753135396755","flags":0,"ts_in_delta":1303,"sequence":177535,"symbol":"FCEU SI 20260615 PS"}
{"ts_recv":"2026-04-07T02:59:33.832106940Z","hd":{"ts_event":"2026-04-07T02:59:33.832073663Z","rtype":160,"publisher_id":101,"instrument_id":436},"action":"A","side":"A","price":"1.156710000","size":30,"channel_id":23,"order_id":"1775530773832086697","flags":128,"ts_in_delta":1303,"sequence":177535,"symbol":"FCEU SI 20260615 PS"}
{"ts_recv":"2026-04-07T02:59:33.871397170Z","hd":{"ts_event":"2026-04-07T02:59:33.871375437Z","rtype":160,"publisher_id":101,"instrument_id":436},"action":"C","side":"B","price":"1.156600000","size":30,"channel_id":23,"order_id":"10998902789990106701","flags":0,"ts_in_delta":948,"sequence":177539,"symbol":"FCEU SI 20260615 PS"}
{"ts_recv":"2026-04-07T02:59:33.871397170Z","hd":{"ts_event":"2026-04-07T02:59:33.871375437Z","rtype":160,"publisher_id":101,"instrument_id":436},"action":"A","side":"B","price":"1.156620000","size":30,"channel_id":23,"order_id":"10998902810726157574","flags":0,"ts_in_delta":948,"sequence":177539,"symbol":"FCEU SI 20260615 PS"}
{"ts_recv":"2026-04-07T02:59:33.871397170Z","hd":{"ts_event":"2026-04-07T02:59:33.871375437Z","rtype":160,"publisher_id":101,"instrument_id":436},"action":"C","side":"A","price":"1.156700000","size":30,"channel_id":23,"order_id":"1775530753135330893","flags":0,"ts_in_delta":948,"sequence":177539,"symbol":"FCEU SI 20260615 PS"}
{"ts_recv":"2026-04-07T02:59:33.871397170Z","hd":{"ts_event":"2026-04-07T02:59:33.871375437Z","rtype":160,"publisher_id":101,"instrument_id":436},"action":"A","side":"A","price":"1.156720000","size":30,"channel_id":23,"order_id":"1775530773871381766","flags":128,"ts_in_delta":948,"sequence":177539,"symbol":"FCEU SI 20260615 PS"}
{"ts_recv":"2026-04-07T02:59:33.871465096Z","hd":{"ts_event":"2026-04-07T02:59:33.871445487Z","rtype":160,"publisher_id":101,"instrument_id":436},"action":"C","side":"B","price":"1.156610000","size":30,"channel_id":23,"order_id":"10998902810686862505","flags":0,"ts_in_delta":924,"sequence":177540,"symbol":"FCEU SI 20260615 PS"}
{"ts_recv":"2026-04-07T02:59:33.871465096Z","hd":{"ts_event":"2026-04-07T02:59:33.871445487Z","rtype":160,"publisher_id":101,"instrument_id":436},"action":"A","side":"B","price":"1.156620000","size":30,"channel_id":23,"order_id":"10998902810726227473","flags":0,"ts_in_delta":924,"sequence":177540,"symbol":"FCEU SI 20260615 PS"}
{"ts_recv":"2026-04-07T02:59:33.871465096Z","hd":{"ts_event":"2026-04-07T02:59:33.871445487Z","rtype":160,"publisher_id":101,"instrument_id":436},"action":"C","side":"A","price":"1.156710000","size":30,"channel_id":23,"order_id":"1775530773832086697","flags":0,"ts_in_delta":924,"sequence":177540,"symbol":"FCEU SI 20260615 PS"}
{"ts_recv":"2026-04-07T02:59:33.871465096Z","hd":{"ts_event":"2026-04-07T02:59:33.871445487Z","rtype":160,"publisher_id":101,"instrument_id":436},"action":"A","side":"A","price":"1.156720000","size":30,"channel_id":23,"order_id":"1775530773871451665","flags":128,"ts_in_delta":924,"sequence":177540,"symbol":"FCEU SI 20260615 PS"}
{"ts_recv":"2026-04-07T03:00:48.228532097Z","hd":{"ts_event":"2026-04-07T03:00:48.228504383Z","rtype":160,"publisher_id":101,"instrument_id":436},"action":"C","side":"B","price":"1.156620000","size":30,"channel_id":23,"order_id":"10998902810726157574","flags":0,"ts_in_delta":925,"sequence":177907,"symbol":"FCEU SI 20260615 PS"}
{"ts_recv":"2026-04-07T03:00:48.228532097Z","hd":{"ts_event":"2026-04-07T03:00:48.228504383Z","rtype":160,"publisher_id":101,"instrument_id":436},"action":"A","side":"B","price":"1.156640000","size":30,"channel_id":23,"order_id":"10998902885083288324","flags":0,"ts_in_delta":925,"sequence":177907,"symbol":"FCEU SI 20260615 PS"}
{"ts_recv":"2026-04-07T03:00:48.228532097Z","hd":{"ts_event":"2026-04-07T03:00:48.228504383Z","rtype":160,"publisher_id":101,"instrument_id":436},"action":"C","side":"A","price":"1.156720000","size":30,"channel_id":23,"order_id":"1775530773871381766","flags":0,"ts_in_delta":925,"sequence":177907,"symbol":"FCEU SI 20260615 PS"}
{"ts_recv":"2026-04-07T03:00:48.228532097Z","hd":{"ts_event":"2026-04-07T03:00:48.228504383Z","rtype":160,"publisher_id":101,"instrument_id":436},"action":"A","side":"A","price":"1.156740000","size":30,"channel_id":23,"order_id":"1775530848228512516","flags":128,"ts_in_delta":925,"sequence":177907,"symbol":"FCEU SI 20260615 PS"}
{"ts_recv":"2026-04-07T03:00:48.228647353Z","hd":{"ts_event":"2026-04-07T03:00:48.228625183Z","rtype":160,"publisher_id":101,"instrument_id":436},"action":"C","side":"B","price":"1.156620000","size":30,"channel_id":23,"order_id":"10998902810726227473","flags":0,"ts_in_delta":933,"sequence":177908,"symbol":"FCEU SI 20260615 PS"}
{"ts_recv":"2026-04-07T03:00:48.228647353Z","hd":{"ts_event":"2026-04-07T03:00:48.228625183Z","rtype":160,"publisher_id":101,"instrument_id":436},"action":"A","side":"B","price":"1.156630000","size":30,"channel_id":23,"order_id":"10998902885083408528","flags":0,"ts_in_delta":933,"sequence":177908,"symbol":"FCEU SI 20260615 PS"}
{"ts_recv":"2026-04-07T03:00:48.228647353Z","hd":{"ts_event":"2026-04-07T03:00:48.228625183Z","rtype":160,"publisher_id":101,"instrument_id":436},"action":"C","side":"A","price":"1.156720000","size":30,"channel_id":23,"order_id":"1775530773871451665","flags":0,"ts_in_delta":933,"sequence":177908,"symbol":"FCEU SI 20260615 PS"}
{"ts_recv":"2026-04-07T03:00:48.228647353Z","hd":{"ts_event":"2026-04-07T03:00:48.228625183Z","rtype":160,"publisher_id":101,"instrument_id":436},"action":"A","side":"A","price":"1.156730000","size":30,"channel_id":23,"order_id":"1775530848228632720","flags":128,"ts_in_delta":933,"sequence":177908,"symbol":"FCEU SI 20260615 PS"}
{"ts_recv":"2026-04-07T03:00:48.231157377Z","hd":{"ts_event":"2026-04-07T03:00:48.231139277Z","rtype":160,"publisher_id":101,"instrument_id":436},"action":"C","side":"B","price":"1.156630000","size":30,"channel_id":23,"order_id":"10998902885083408528","flags":0,"ts_in_delta":1037,"sequence":177911,"symbol":"FCEU SI 20260615 PS"}
{"ts_recv":"2026-04-07T03:00:48.231157377Z","hd":{"ts_event":"2026-04-07T03:00:48.231139277Z","rtype":160,"publisher_id":101,"instrument_id":436},"action":"A","side":"B","price":"1.156640000","size":30,"channel_id":23,"order_id":"10998902885085921203","flags":0,"ts_in_delta":1037,"sequence":177911,"symbol":"FCEU SI 20260615 PS"}
{"ts_recv":"2026-04-07T03:00:48.231157377Z","hd":{"ts_event":"2026-04-07T03:00:48.231139277Z","rtype":160,"publisher_id":101,"instrument_id":436},"action":"C","side":"A","price":"1.156730000","size":30,"channel_id":23,"order_id":"1775530848228632720","flags":0,"ts_in_delta":1037,"sequence":177911,"symbol":"FCEU SI 20260615 PS"}
{"ts_recv":"2026-04-07T03:00:48.231157377Z","hd":{"ts_event":"2026-04-07T03:00:48.231139277Z","rtype":160,"publisher_id":101,"instrument_id":436},"action":"A","side":"A","price":"1.156740000","size":30,"channel_id":23,"order_id":"1775530848231145395","flags":128,"ts_in_delta":1037,"sequence":177911,"symbol":"FCEU SI 20260615 PS"}
{"ts_recv":"2026-04-07T03:00:48.240381555Z","hd":{"ts_event":"2026-04-07T03:00:48.240359249Z","rtype":160,"publisher_id":101,"instrument_id":436},"action":"C","side":"B","price":"1.156640000","size":30,"channel_id":23,"order_id":"10998902885085921203","flags":0,"ts_in_delta":923,"sequence":177921,"symbol":"FCEU SI 20260615 PS"}
{"ts_recv":"2026-04-07T03:00:48.240381555Z","hd":{"ts_event":"2026-04-07T03:00:48.240359249Z","rtype":160,"publisher_id":101,"instrument_id":436},"action":"A","side":"B","price":"1.156660000","size":30,"channel_id":23,"order_id":"10998902885095141008","flags":0,"ts_in_delta":923,"sequence":177921,"symbol":"FCEU SI 20260615 PS"}
{"ts_recv":"2026-04-07T03:00:48.240381555Z","hd":{"ts_event":"2026-04-07T03:00:48.240359249Z","rtype":160,"publisher_id":101,"instrument_id":436},"action":"C","side":"A","price":"1.156740000","size":30,"channel_id":23,"order_id":"1775530848231145395","flags":0,"ts_in_delta":923,"sequence":177921,"symbol":"FCEU SI 20260615 PS"}
{"ts_recv":"2026-04-07T03:00:48.240381555Z","hd":{"ts_event":"2026-04-07T03:00:48.240359249Z","rtype":160,"publisher_id":101,"instrument_id":436},"action":"A","side":"A","price":"1.156760000","size":30,"channel_id":23,"order_id":"1775530848240365200","flags":128,"ts_in_delta":923,"sequence":177921,"symbol":"FCEU SI 20260615 PS"}
{"ts_recv":"2026-04-07T03:00:48.240431112Z","hd":{"ts_event":"2026-04-07T03:00:48.240412183Z","rtype":160,"publisher_id":101,"instrument_id":436},"action":"C","side":"B","price":"1.156640000","size":30,"channel_id":23,"order_id":"10998902885083288324","flags":0,"ts_in_delta":947,"sequence":177922,"symbol":"FCEU SI 20260615 PS"}
{"ts_recv":"2026-04-07T03:00:48.240431112Z","hd":{"ts_event":"2026-04-07T03:00:48.240412183Z","rtype":160,"publisher_id":101,"instrument_id":436},"action":"A","side":"B","price":"1.156660000","size":30,"channel_id":23,"order_id":"10998902885095193743","flags":0,"ts_in_delta":947,"sequence":177922,"symbol":"FCEU SI 20260615 PS"}
{"ts_recv":"2026-04-07T03:00:48.240431112Z","hd":{"ts_event":"2026-04-07T03:00:48.240412183Z","rtype":160,"publisher_id":101,"instrument_id":436},"action":"C","side":"A","price":"1.156740000","size":30,"channel_id":23,"order_id":"1775530848228512516","flags":0,"ts_in_delta":947,"sequence":177922,"symbol":"FCEU SI 20260615 PS"}
{"ts_recv":"2026-04-07T03:00:48.240431112Z","hd":{"ts_event":"2026-04-07T03:00:48.240412183Z","rtype":160,"publisher_id":101,"instrument_id":436},"action":"A","side":"A","price":"1.156760000","size":30,"channel_id":23,"order_id":"1775530848240417935","flags":128,"ts_in_delta":947,"sequence":177922,"symbol":"FCEU SI 20260615 PS"}
{"ts_recv":"2026-04-07T03:00:48.240464518Z","hd":{"ts_event":"2026-04-07T03:00:48.240445879Z","rtype":160,"publisher_id":101,"instrument_id":436},"action":"C","side":"B","price":"1.156660000","size":30,"channel_id":23,"order_id":"10998902885095141008","flags":0,"ts_in_delta":949,"sequence":177923,"symbol":"FCEU SI 20260615 PS"}
{"ts_recv":"2026-04-07T03:00:48.240464518Z","hd":{"ts_event":"2026-04-07T03:00:48.240445879Z","rtype":160,"publisher_id":101,"instrument_id":436},"action":"A","side":"B","price":"1.156670000","size":30,"channel_id":23,"order_id":"10998902885095227803","flags":0,"ts_in_delta":949,"sequence":177923,"symbol":"FCEU SI 20260615 PS"}
{"ts_recv":"2026-04-07T03:00:48.240464518Z","hd":{"ts_event":"2026-04-07T03:00:48.240445879Z","rtype":160,"publisher_id":101,"instrument_id":436},"action":"C","side":"A","price":"1.156760000","size":30,"channel_id":23,"order_id":"1775530848240365200","flags":0,"ts_in_delta":949,"sequence":177923,"symbol":"FCEU SI 20260615 PS"}
{"ts_recv":"2026-04-07T03:00:48.240464518Z","hd":{"ts_event":"2026-04-07T03:00:48.240445879Z","rtype":160,"publisher_id":101,"instrument_id":436},"action":"A","side":"A","price":"1.156770000","size":30,"channel_id":23,"order_id":"1775530848240451995","flags":128,"ts_in_delta":949,"sequence":177923,"symbol":"FCEU SI 20260615 PS"}
{"ts_recv":"2026-04-07T03:00:48.243110764Z","hd":{"ts_event":"2026-04-07T03:00:48.243093425Z","rtype":160,"publisher_id":101,"instrument_id":436},"action":"C","side":"A","price":"1.156800000","size":20,"channel_id":23,"order_id":"1775530683260274162","flags":128,"ts_in_delta":940,"sequence":177925,"symbol":"FCEU SI 20260615 PS"}
{"ts_recv":"2026-04-07T03:00:48.257153836Z","hd":{"ts_event":"2026-04-07T03:00:48.257136185Z","rtype":160,"publisher_id":101,"instrument_id":436},"action":"C","side":"B","price":"1.156670000","size":30,"channel_id":23,"order_id":"10998902885095227803","flags":0,"ts_in_delta":945,"sequence":177942,"symbol":"FCEU SI 20260615 PS"}
{"ts_recv":"2026-04-07T03:00:48.257153836Z","hd":{"ts_event":"2026-04-07T03:00:48.257136185Z","rtype":160,"publisher_id":101,"instrument_id":436},"action":"A","side":"B","price":"1.156660000","size":30,"channel_id":23,"order_id":"10998902885111918058","flags":0,"ts_in_delta":945,"sequence":177942,"symbol":"FCEU SI 20260615 PS"}
{"ts_recv":"2026-04-07T03:00:48.257153836Z","hd":{"ts_event":"2026-04-07T03:00:48.257136185Z","rtype":160,"publisher_id":101,"instrument_id":436},"action":"C","side":"A","price":"1.156770000","size":30,"channel_id":23,"order_id":"1775530848240451995","flags":0,"ts_in_delta":945,"sequence":177942,"symbol":"FCEU SI 20260615 PS"}
{"ts_recv":"2026-04-07T03:00:48.257153836Z","hd":{"ts_event":"2026-04-07T03:00:48.257136185Z","rtype":160,"publisher_id":101,"instrument_id":436},"action":"A","side":"A","price":"1.156760000","size":30,"channel_id":23,"order_id":"1775530848257142250","flags":128,"ts_in_delta":945,"sequence":177942,"symbol":"FCEU SI 20260615 PS"}
{"ts_recv":"2026-04-07T03:00:48.303177586Z","hd":{"ts_event":"2026-04-07T03:00:48.303163155Z","rtype":160,"publisher_id":101,"instrument_id":436},"action":"A","side":"A","price":"1.157000000","size":20,"channel_id":23,"order_id":"1775530848303169499","flags":128,"ts_in_delta":817,"sequence":177950,"symbol":"FCEU SI 20260615 PS"}
{"ts_recv":"2026-04-07T03:00:57.354966854Z","hd":{"ts_event":"2026-04-07T03:00:57.354937217Z","rtype":160,"publisher_id":101,"instrument_id":436},"action":"C","side":"B","price":"1.156660000","size":30,"channel_id":23,"order_id":"10998902885111918058","flags":0,"ts_in_delta":1074,"sequence":178010,"symbol":"FCEU SI 20260615 PS"}
{"ts_recv":"2026-04-07T03:00:57.354966854Z","hd":{"ts_event":"2026-04-07T03:00:57.354937217Z","rtype":160,"publisher_id":101,"instrument_id":436},"action":"A","side":"B","price":"1.156670000","size":30,"channel_id":23,"order_id":"10998902894209726296","flags":0,"ts_in_delta":1074,"sequence":178010,"symbol":"FCEU SI 20260615 PS"}
{"ts_recv":"2026-04-07T03:00:57.354966854Z","hd":{"ts_event":"2026-04-07T03:00:57.354937217Z","rtype":160,"publisher_id":101,"instrument_id":436},"action":"C","side":"A","price":"1.156760000","size":30,"channel_id":23,"order_id":"1775530848257142250","flags":0,"ts_in_delta":1074,"sequence":178010,"symbol":"FCEU SI 20260615 PS"}
{"ts_recv":"2026-04-07T03:00:57.354966854Z","hd":{"ts_event":"2026-04-07T03:00:57.354937217Z","rtype":160,"publisher_id":101,"instrument_id":436},"action":"A","side":"A","price":"1.156770000","size":30,"channel_id":23,"order_id":"1775530857354950488","flags":128,"ts_in_delta":1074,"sequence":178010,"symbol":"FCEU SI 20260615 PS"}
{"ts_recv":"2026-04-07T03:01:03.058300418Z","hd":{"ts_event":"2026-04-07T03:01:03.058279857Z","rtype":160,"publisher_id":101,"instrument_id":436},"action":"C","side":"B","price":"1.156660000","size":30,"channel_id":23,"order_id":"10998902885095193743","flags":0,"ts_in_delta":1198,"sequence":178027,"symbol":"FCEU SI 20260615 PS"}
{"ts_recv":"2026-04-07T03:01:03.058300418Z","hd":{"ts_event":"2026-04-07T03:01:03.058279857Z","rtype":160,"publisher_id":101,"instrument_id":436},"action":"A","side":"B","price":"1.156680000","size":30,"channel_id":23,"order_id":"10998902899913061754","flags":0,"ts_in_delta":1198,"sequence":178027,"symbol":"FCEU SI 20260615 PS"}
{"ts_recv":"2026-04-07T03:01:03.058300418Z","hd":{"ts_event":"2026-04-07T03:01:03.058279857Z","rtype":160,"publisher_id":101,"instrument_id":436},"action":"C","side":"A","price":"1.156760000","size":30,"channel_id":23,"order_id":"1775530848240417935","flags":0,"ts_in_delta":1198,"sequence":178027,"symbol":"FCEU SI 20260615 PS"}
{"ts_recv":"2026-04-07T03:01:03.058300418Z","hd":{"ts_event":"2026-04-07T03:01:03.058279857Z","rtype":160,"publisher_id":101,"instrument_id":436},"action":"A","side":"A","price":"1.156780000","size":30,"channel_id":23,"order_id":"1775530863058285946","flags":128,"ts_in_delta":1198,"sequence":178027,"symbol":"FCEU SI 20260615 PS"}
{"ts_recv":"2026-04-07T03:01:03.058420351Z","hd":{"ts_event":"2026-04-07T03:01:03.058399019Z","rtype":160,"publisher_id":101,"instrument_id":436},"action":"C","side":"B","price":"1.156670000","size":30,"channel_id":23,"order_id":"10998902894209726296","flags":0,"ts_in_delta":928,"sequence":178028,"symbol":"FCEU SI 20260615 PS"}
{"ts_recv":"2026-04-07T03:01:03.058420351Z","hd":{"ts_event":"2026-04-07T03:01:03.058399019Z","rtype":160,"publisher_id":101,"instrument_id":436},"action":"A","side":"B","price":"1.156680000","size":30,"channel_id":23,"order_id":"10998902899913180918","flags":0,"ts_in_delta":928,"sequence":178028,"symbol":"FCEU SI 20260615 PS"}
{"ts_recv":"2026-04-07T03:01:03.058420351Z","hd":{"ts_event":"2026-04-07T03:01:03.058399019Z","rtype":160,"publisher_id":101,"instrument_id":436},"action":"C","side":"A","price":"1.156770000","size":30,"channel_id":23,"order_id":"1775530857354950488","flags":0,"ts_in_delta":928,"sequence":178028,"symbol":"FCEU SI 20260615 PS"}
{"ts_recv":"2026-04-07T03:01:03.058420351Z","hd":{"ts_event":"2026-04-07T03:01:03.058399019Z","rtype":160,"publisher_id":101,"instrument_id":436},"action":"A","side":"A","price":"1.156780000","size":30,"channel_id":23,"order_id":"1775530863058405110","flags":128,"ts_in_delta":928,"sequence":178028,"symbol":"FCEU SI 20260615 PS"}
{"ts_recv":"2026-04-07T03:01:16.218691733Z","hd":{"ts_event":"2026-04-07T03:01:16.218658169Z","rtype":160,"publisher_id":101,"instrument_id":436},"action":"C","side":"B","price":"1.156680000","size":30,"channel_id":23,"order_id":"10998902899913180918","flags":0,"ts_in_delta":1057,"sequence":178117,"symbol":"FCEU SI 20260615 PS"}
{"ts_recv":"2026-04-07T03:01:16.218691733Z","hd":{"ts_event":"2026-04-07T03:01:16.218658169Z","rtype":160,"publisher_id":101,"instrument_id":436},"action":"A","side":"B","price":"1.156690000","size":30,"channel_id":23,"order_id":"10998902913073447839","flags":0,"ts_in_delta":1057,"sequence":178117,"symbol":"FCEU SI 20260615 PS"}
{"ts_recv":"2026-04-07T03:01:16.218691733Z","hd":{"ts_event":"2026-04-07T03:01:16.218658169Z","rtype":160,"publisher_id":101,"instrument_id":436},"action":"C","side":"A","price":"1.156780000","size":30,"channel_id":23,"order_id":"1775530863058405110","flags":0,"ts_in_delta":1057,"sequence":178117,"symbol":"FCEU SI 20260615 PS"}
{"ts_recv":"2026-04-07T03:01:16.218691733Z","hd":{"ts_event":"2026-04-07T03:01:16.218658169Z","rtype":160,"publisher_id":101,"instrument_id":436},"action":"A","side":"A","price":"1.156790000","size":30,"channel_id":23,"order_id":"1775530876218672031","flags":128,"ts_in_delta":1057,"sequence":178117,"symbol":"FCEU SI 20260615 PS"}
{"ts_recv":"2026-04-07T03:01:16.218770917Z","hd":{"ts_event":"2026-04-07T03:01:16.218752665Z","rtype":160,"publisher_id":101,"instrument_id":436},"action":"C","side":"B","price":"1.156680000","size":30,"channel_id":23,"order_id":"10998902899913061754","flags":0,"ts_in_delta":956,"sequence":178118,"symbol":"FCEU SI 20260615 PS"}
{"ts_recv":"2026-04-07T03:01:16.218770917Z","hd":{"ts_event":"2026-04-07T03:01:16.218752665Z","rtype":160,"publisher_id":101,"instrument_id":436},"action":"A","side":"B","price":"1.156700000","size":30,"channel_id":23,"order_id":"10998902913073534521","flags":0,"ts_in_delta":956,"sequence":178118,"symbol":"FCEU SI 20260615 PS"}
{"ts_recv":"2026-04-07T03:01:16.218770917Z","hd":{"ts_event":"2026-04-07T03:01:16.218752665Z","rtype":160,"publisher_id":101,"instrument_id":436},"action":"C","side":"A","price":"1.156780000","size":30,"channel_id":23,"order_id":"1775530863058285946","flags":0,"ts_in_delta":956,"sequence":178118,"symbol":"FCEU SI 20260615 PS"}
{"ts_recv":"2026-04-07T03:01:16.218770917Z","hd":{"ts_event":"2026-04-07T03:01:16.218752665Z","rtype":160,"publisher_id":101,"instrument_id":436},"action":"A","side":"A","price":"1.156800000","size":30,"channel_id":23,"order_id":"1775530876218758713","flags":128,"ts_in_delta":956,"sequence":178118,"symbol":"FCEU SI 20260615 PS"}
{"ts_recv":"2026-04-07T03:01:16.218827263Z","hd":{"ts_event":"2026-04-07T03:01:16.218811097Z","rtype":160,"publisher_id":101,"instrument_id":436},"action":"C","side":"B","price":"1.156690000","size":30,"channel_id":23,"order_id":"10998902913073447839","flags":0,"ts_in_delta":917,"sequence":178119,"symbol":"FCEU SI 20260615 PS"}
{"ts_recv":"2026-04-07T03:01:16.218827263Z","hd":{"ts_event":"2026-04-07T03:01:16.218811097Z","rtype":160,"publisher_id":101,"instrument_id":436},"action":"A","side":"B","price":"1.156700000","size":30,"channel_id":23,"order_id":"10998902913073593055","flags":0,"ts_in_delta":917,"sequence":178119,"symbol":"FCEU SI 20260615 PS"}
{"ts_recv":"2026-04-07T03:01:16.218827263Z","hd":{"ts_event":"2026-04-07T03:01:16.218811097Z","rtype":160,"publisher_id":101,"instrument_id":436},"action":"C","side":"A","price":"1.156790000","size":30,"channel_id":23,"order_id":"1775530876218672031","flags":0,"ts_in_delta":917,"sequence":178119,"symbol":"FCEU SI 20260615 PS"}
{"ts_recv":"2026-04-07T03:01:16.218827263Z","hd":{"ts_event":"2026-04-07T03:01:16.218811097Z","rtype":160,"publisher_id":101,"instrument_id":436},"action":"A","side":"A","price":"1.156800000","size":30,"channel_id":23,"order_id":"1775530876218817247","flags":128,"ts_in_delta":917,"sequence":178119,"symbol":"FCEU SI 20260615 PS"}
{"ts_recv":"2026-04-07T03:01:22.335190646Z","hd":{"ts_event":"2026-04-07T03:01:22.335162145Z","rtype":160,"publisher_id":101,"instrument_id":436},"action":"C","side":"B","price":"1.156700000","size":30,"channel_id":23,"order_id":"10998902913073593055","flags":0,"ts_in_delta":1424,"sequence":178175,"symbol":"FCEU SI 20260615 PS"}
{"ts_recv":"2026-04-07T03:01:22.335190646Z","hd":{"ts_event":"2026-04-07T03:01:22.335162145Z","rtype":160,"publisher_id":101,"instrument_id":436},"action":"A","side":"B","price":"1.156710000","size":30,"channel_id":23,"order_id":"10998902919189946510","flags":0,"ts_in_delta":1424,"sequence":178175,"symbol":"FCEU SI 20260615 PS"}
{"ts_recv":"2026-04-07T03:01:22.335190646Z","hd":{"ts_event":"2026-04-07T03:01:22.335162145Z","rtype":160,"publisher_id":101,"instrument_id":436},"action":"C","side":"A","price":"1.156800000","size":30,"channel_id":23,"order_id":"1775530876218817247","flags":0,"ts_in_delta":1424,"sequence":178175,"symbol":"FCEU SI 20260615 PS"}
{"ts_recv":"2026-04-07T03:01:22.335190646Z","hd":{"ts_event":"2026-04-07T03:01:22.335162145Z","rtype":160,"publisher_id":101,"instrument_id":436},"action":"A","side":"A","price":"1.156810000","size":30,"channel_id":23,"order_id":"1775530882335170702","flags":128,"ts_in_delta":1424,"sequence":178175,"symbol":"FCEU SI 20260615 PS"}
{"ts_recv":"2026-04-07T03:01:22.336500533Z","hd":{"ts_event":"2026-04-07T03:01:22.336481791Z","rtype":160,"publisher_id":101,"instrument_id":436},"action":"C","side":"B","price":"1.156700000","size":30,"channel_id":23,"order_id":"10998902913073534521","flags":0,"ts_in_delta":1059,"sequence":178177,"symbol":"FCEU SI 20260615 PS"}
{"ts_recv":"2026-04-07T03:01:22.336500533Z","hd":{"ts_event":"2026-04-07T03:01:22.336481791Z","rtype":160,"publisher_id":101,"instrument_id":436},"action":"A","side":"B","price":"1.156720000","size":30,"channel_id":23,"order_id":"10998902919191263692","flags":0,"ts_in_delta":1059,"sequence":178177,"symbol":"FCEU SI 20260615 PS"}
{"ts_recv":"2026-04-07T03:01:22.336500533Z","hd":{"ts_event":"2026-04-07T03:01:22.336481791Z","rtype":160,"publisher_id":101,"instrument_id":436},"action":"C","side":"A","price":"1.156800000","size":30,"channel_id":23,"order_id":"1775530876218758713","flags":0,"ts_in_delta":1059,"sequence":178177,"symbol":"FCEU SI 20260615 PS"}
{"ts_recv":"2026-04-07T03:01:22.336500533Z","hd":{"ts_event":"2026-04-07T03:01:22.336481791Z","rtype":160,"publisher_id":101,"instrument_id":436},"action":"A","side":"A","price":"1.156820000","size":30,"channel_id":23,"order_id":"1775530882336487884","flags":128,"ts_in_delta":1059,"sequence":178177,"symbol":"FCEU SI 20260615 PS"}
{"ts_recv":"2026-04-07T03:01:22.336568153Z","hd":{"ts_event":"2026-04-07T03:01:22.336548837Z","rtype":160,"publisher_id":101,"instrument_id":436},"action":"C","side":"B","price":"1.156710000","size":30,"channel_id":23,"order_id":"10998902919189946510","flags":0,"ts_in_delta":960,"sequence":178178,"symbol":"FCEU SI 20260615 PS"}
{"ts_recv":"2026-04-07T03:01:22.336568153Z","hd":{"ts_event":"2026-04-07T03:01:22.336548837Z","rtype":160,"publisher_id":101,"instrument_id":436},"action":"A","side":"B","price":"1.156720000","size":30,"channel_id":23,"order_id":"10998902919191330661","flags":0,"ts_in_delta":960,"sequence":178178,"symbol":"FCEU SI 20260615 PS"}
{"ts_recv":"2026-04-07T03:01:22.336568153Z","hd":{"ts_event":"2026-04-07T03:01:22.336548837Z","rtype":160,"publisher_id":101,"instrument_id":436},"action":"C","side":"A","price":"1.156810000","size":30,"channel_id":23,"order_id":"1775530882335170702","flags":0,"ts_in_delta":960,"sequence":178178,"symbol":"FCEU SI 20260615 PS"}
{"ts_recv":"2026-04-07T03:01:22.336568153Z","hd":{"ts_event":"2026-04-07T03:01:22.336548837Z","rtype":160,"publisher_id":101,"instrument_id":436},"action":"A","side":"A","price":"1.156820000","size":30,"channel_id":23,"order_id":"1775530882336554853","flags":128,"ts_in_delta":960,"sequence":178178,"symbol":"FCEU SI 20260615 PS"}
{"ts_recv":"2026-04-07T03:01:22.412297043Z","hd":{"ts_event":"2026-04-07T03:01:22.412271719Z","rtype":160,"publisher_id":101,"instrument_id":436},"action":"C","side":"B","price":"1.156720000","size":30,"channel_id":23,"order_id":"10998902919191330661","flags":0,"ts_in_delta":1002,"sequence":178185,"symbol":"FCEU SI 20260615 PS"}
{"ts_recv":"2026-04-07T03:01:22.412297043Z","hd":{"ts_event":"2026-04-07T03:01:22.412271719Z","rtype":160,"publisher_id":101,"instrument_id":436},"action":"A","side":"B","price":"1.156710000","size":30,"channel_id":23,"order_id":"10998902919267058446","flags":0,"ts_in_delta":1002,"sequence":178185,"symbol":"FCEU SI 20260615 PS"}
{"ts_recv":"2026-04-07T03:01:22.412297043Z","hd":{"ts_event":"2026-04-07T03:01:22.412271719Z","rtype":160,"publisher_id":101,"instrument_id":436},"action":"C","side":"A","price":"1.156820000","size":30,"channel_id":23,"order_id":"1775530882336554853","flags":0,"ts_in_delta":1002,"sequence":178185,"symbol":"FCEU SI 20260615 PS"}
{"ts_recv":"2026-04-07T03:01:22.412297043Z","hd":{"ts_event":"2026-04-07T03:01:22.412271719Z","rtype":160,"publisher_id":101,"instrument_id":436},"action":"A","side":"A","price":"1.156810000","size":30,"channel_id":23,"order_id":"1775530882412282638","flags":128,"ts_in_delta":1002,"sequence":178185,"symbol":"FCEU SI 20260615 PS"}
{"ts_recv":"2026-04-07T03:01:22.412356983Z","hd":{"ts_event":"2026-04-07T03:01:22.412336865Z","rtype":160,"publisher_id":101,"instrument_id":436},"action":"C","side":"B","price":"1.156720000","size":30,"channel_id":23,"order_id":"10998902919191263692","flags":0,"ts_in_delta":1087,"sequence":178186,"symbol":"FCEU SI 20260615 PS"}
{"ts_recv":"2026-04-07T03:01:22.412356983Z","hd":{"ts_event":"2026-04-07T03:01:22.412336865Z","rtype":160,"publisher_id":101,"instrument_id":436},"action":"A","side":"B","price":"1.156700000","size":30,"channel_id":23,"order_id":"10998902919267119019","flags":0,"ts_in_delta":1087,"sequence":178186,"symbol":"FCEU SI 20260615 PS"}
{"ts_recv":"2026-04-07T03:01:22.412356983Z","hd":{"ts_event":"2026-04-07T03:01:22.412336865Z","rtype":160,"publisher_id":101,"instrument_id":436},"action":"C","side":"A","price":"1.156820000","size":30,"channel_id":23,"order_id":"1775530882336487884","flags":0,"ts_in_delta":1087,"sequence":178186,"symbol":"FCEU SI 20260615 PS"}
{"ts_recv":"2026-04-07T03:01:22.412356983Z","hd":{"ts_event":"2026-04-07T03:01:22.412336865Z","rtype":160,"publisher_id":101,"instrument_id":436},"action":"A","side":"A","price":"1.156800000","size":30,"channel_id":23,"order_id":"1775530882412343211","flags":128,"ts_in_delta":1087,"sequence":178186,"symbol":"FCEU SI 20260615 PS"}
{"ts_recv":"2026-04-07T03:01:22.412379930Z","hd":{"ts_event":"2026-04-07T03:01:22.412362785Z","rtype":160,"publisher_id":101,"instrument_id":436},"action":"C","side":"B","price":"1.156710000","size":30,"channel_id":23,"order_id":"10998902919267058446","flags":0,"ts_in_delta":787,"sequence":178187,"symbol":"FCEU SI 20260615 PS"}
{"ts_recv":"2026-04-07T03:01:22.412379930Z","hd":{"ts_event":"2026-04-07T03:01:22.412362785Z","rtype":160,"publisher_id":101,"instrument_id":436},"action":"A","side":"B","price":"1.156700000","size":30,"channel_id":23,"order_id":"10998902919267144731","flags":0,"ts_in_delta":787,"sequence":178187,"symbol":"FCEU SI 20260615 PS"}
{"ts_recv":"2026-04-07T03:01:22.412379930Z","hd":{"ts_event":"2026-04-07T03:01:22.412362785Z","rtype":160,"publisher_id":101,"instrument_id":436},"action":"C","side":"A","price":"1.156810000","size":30,"channel_id":23,"order_id":"1775530882412282638","flags":0,"ts_in_delta":787,"sequence":178187,"symbol":"FCEU SI 20260615 PS"}
{"ts_recv":"2026-04-07T03:01:22.412379930Z","hd":{"ts_event":"2026-04-07T03:01:22.412362785Z","rtype":160,"publisher_id":101,"instrument_id":436},"action":"A","side":"A","price":"1.156800000","size":30,"channel_id":23,"order_id":"1775530882412368923","flags":128,"ts_in_delta":787,"sequence":178187,"symbol":"FCEU SI 20260615 PS"}
{"ts_recv":"2026-04-07T03:01:28.640630921Z","hd":{"ts_event":"2026-04-07T03:01:28.640608687Z","rtype":160,"publisher_id":101,"instrument_id":436},"action":"C","side":"B","price":"1.156700000","size":30,"channel_id":23,"order_id":"10998902919267144731","flags":0,"ts_in_delta":971,"sequence":178264,"symbol":"FCEU SI 20260615 PS"}
{"ts_recv":"2026-04-07T03:01:28.640630921Z","hd":{"ts_event":"2026-04-07T03:01:28.640608687Z","rtype":160,"publisher_id":101,"instrument_id":436},"action":"A","side":"B","price":"1.156710000","size":30,"channel_id":23,"order_id":"10998902925495390765","flags":0,"ts_in_delta":971,"sequence":178264,"symbol":"FCEU SI 20260615 PS"}
{"ts_recv":"2026-04-07T03:01:28.640630921Z","hd":{"ts_event":"2026-04-07T03:01:28.640608687Z","rtype":160,"publisher_id":101,"instrument_id":436},"action":"C","side":"A","price":"1.156800000","size":30,"channel_id":23,"order_id":"1775530882412368923","flags":0,"ts_in_delta":971,"sequence":178264,"symbol":"FCEU SI 20260615 PS"}
{"ts_recv":"2026-04-07T03:01:28.640630921Z","hd":{"ts_event":"2026-04-07T03:01:28.640608687Z","rtype":160,"publisher_id":101,"instrument_id":436},"action":"A","side":"A","price":"1.156810000","size":30,"channel_id":23,"order_id":"1775530888640614957","flags":128,"ts_in_delta":971,"sequence":178264,"symbol":"FCEU SI 20260615 PS"}
{"ts_recv":"2026-04-07T03:01:28.775250146Z","hd":{"ts_event":"2026-04-07T03:01:28.775232875Z","rtype":160,"publisher_id":101,"instrument_id":436},"action":"A","side":"B","price":"1.156600000","size":20,"channel_id":23,"order_id":"10998902925630015146","flags":128,"ts_in_delta":1027,"sequence":178267,"symbol":"FCEU SI 20260615 PS"}
{"ts_recv":"2026-04-07T03:01:28.775296470Z","hd":{"ts_event":"2026-04-07T03:01:28.775280905Z","rtype":160,"publisher_id":101,"instrument_id":436},"action":"C","side":"B","price":"1.156500000","size":20,"channel_id":23,"order_id":"10998902395852505997","flags":128,"ts_in_delta":1016,"sequence":178269,"symbol":"FCEU SI 20260615 PS"}
{"ts_recv":"2026-04-07T03:01:29.620595032Z","hd":{"ts_event":"2026-04-07T03:01:29.620563985Z","rtype":160,"publisher_id":101,"instrument_id":436},"action":"C","side":"B","price":"1.156700000","size":30,"channel_id":23,"order_id":"10998902919267119019","flags":0,"ts_in_delta":1231,"sequence":178272,"symbol":"FCEU SI 20260615 PS"}
{"ts_recv":"2026-04-07T03:01:29.620595032Z","hd":{"ts_event":"2026-04-07T03:01:29.620563985Z","rtype":160,"publisher_id":101,"instrument_id":436},"action":"A","side":"B","price":"1.156720000","size":30,"channel_id":23,"order_id":"10998902926475352968","flags":0,"ts_in_delta":1231,"sequence":178272,"symbol":"FCEU SI 20260615 PS"}
{"ts_recv":"2026-04-07T03:01:29.620595032Z","hd":{"ts_event":"2026-04-07T03:01:29.620563985Z","rtype":160,"publisher_id":101,"instrument_id":436},"action":"C","side":"A","price":"1.156800000","size":30,"channel_id":23,"order_id":"1775530882412343211","flags":0,"ts_in_delta":1231,"sequence":178272,"symbol":"FCEU SI 20260615 PS"}
{"ts_recv":"2026-04-07T03:01:29.620595032Z","hd":{"ts_event":"2026-04-07T03:01:29.620563985Z","rtype":160,"publisher_id":101,"instrument_id":436},"action":"A","side":"A","price":"1.156820000","size":30,"channel_id":23,"order_id":"1775530889620577160","flags":128,"ts_in_delta":1231,"sequence":178272,"symbol":"FCEU SI 20260615 PS"}
{"ts_recv":"2026-04-07T03:01:29.620692433Z","hd":{"ts_event":"2026-04-07T03:01:29.620675691Z","rtype":160,"publisher_id":101,"instrument_id":436},"action":"C","side":"B","price":"1.156710000","size":30,"channel_id":23,"order_id":"10998902925495390765","flags":0,"ts_in_delta":959,"sequence":178273,"symbol":"FCEU SI 20260615 PS"}
{"ts_recv":"2026-04-07T03:01:29.620692433Z","hd":{"ts_event":"2026-04-07T03:01:29.620675691Z","rtype":160,"publisher_id":101,"instrument_id":436},"action":"A","side":"B","price":"1.156720000","size":30,"channel_id":23,"order_id":"10998902926475457930","flags":0,"ts_in_delta":959,"sequence":178273,"symbol":"FCEU SI 20260615 PS"}
{"ts_recv":"2026-04-07T03:01:29.620692433Z","hd":{"ts_event":"2026-04-07T03:01:29.620675691Z","rtype":160,"publisher_id":101,"instrument_id":436},"action":"C","side":"A","price":"1.156810000","size":30,"channel_id":23,"order_id":"1775530888640614957","flags":0,"ts_in_delta":959,"sequence":178273,"symbol":"FCEU SI 20260615 PS"}
{"ts_recv":"2026-04-07T03:01:29.620692433Z","hd":{"ts_event":"2026-04-07T03:01:29.620675691Z","rtype":160,"publisher_id":101,"instrument_id":436},"action":"A","side":"A","price":"1.156820000","size":30,"channel_id":23,"order_id":"1775530889620682122","flags":128,"ts_in_delta":959,"sequence":178273,"symbol":"FCEU SI 20260615 PS"}
{"ts_recv":"2026-04-07T03:01:31.359429214Z","hd":{"ts_event":"2026-04-07T03:01:31.359409251Z","rtype":160,"publisher_id":101,"instrument_id":436},"action":"C","side":"B","price":"1.156720000","size":30,"channel_id":23,"order_id":"10998902926475457930","flags":0,"ts_in_delta":938,"sequence":178314,"symbol":"FCEU SI 20260615 PS"}
{"ts_recv":"2026-04-07T03:01:31.359429214Z","hd":{"ts_event":"2026-04-07T03:01:31.359409251Z","rtype":160,"publisher_id":101,"instrument_id":436},"action":"A","side":"B","price":"1.156730000","size":30,"channel_id":23,"order_id":"10998902928214190817","flags":0,"ts_in_delta":938,"sequence":178314,"symbol":"FCEU SI 20260615 PS"}
{"ts_recv":"2026-04-07T03:01:31.359429214Z","hd":{"ts_event":"2026-04-07T03:01:31.359409251Z","rtype":160,"publisher_id":101,"instrument_id":436},"action":"C","side":"A","price":"1.156820000","size":30,"channel_id":23,"order_id":"1775530889620682122","flags":0,"ts_in_delta":938,"sequence":178314,"symbol":"FCEU SI 20260615 PS"}
{"ts_recv":"2026-04-07T03:01:31.359429214Z","hd":{"ts_event":"2026-04-07T03:01:31.359409251Z","rtype":160,"publisher_id":101,"instrument_id":436},"action":"A","side":"A","price":"1.156830000","size":30,"channel_id":23,"order_id":"1775530891359415009","flags":128,"ts_in_delta":938,"sequence":178314,"symbol":"FCEU SI 20260615 PS"}
{"ts_recv":"2026-04-07T03:01:48.755373167Z","hd":{"ts_event":"2026-04-07T03:01:48.755337727Z","rtype":160,"publisher_id":101,"instrument_id":436},"action":"C","side":"B","price":"1.156720000","size":30,"channel_id":23,"order_id":"10998902926475352968","flags":0,"ts_in_delta":1656,"sequence":178477,"symbol":"FCEU SI 20260615 PS"}
{"ts_recv":"2026-04-07T03:01:48.755373167Z","hd":{"ts_event":"2026-04-07T03:01:48.755337727Z","rtype":160,"publisher_id":101,"instrument_id":436},"action":"A","side":"B","price":"1.156750000","size":30,"channel_id":23,"order_id":"10998902945610126954","flags":0,"ts_in_delta":1656,"sequence":178477,"symbol":"FCEU SI 20260615 PS"}
{"ts_recv":"2026-04-07T03:01:48.755373167Z","hd":{"ts_event":"2026-04-07T03:01:48.755337727Z","rtype":160,"publisher_id":101,"instrument_id":436},"action":"C","side":"A","price":"1.156820000","size":30,"channel_id":23,"order_id":"1775530889620577160","flags":0,"ts_in_delta":1656,"sequence":178477,"symbol":"FCEU SI 20260615 PS"}
{"ts_recv":"2026-04-07T03:01:48.755373167Z","hd":{"ts_event":"2026-04-07T03:01:48.755337727Z","rtype":160,"publisher_id":101,"instrument_id":436},"action":"A","side":"A","price":"1.156850000","size":30,"channel_id":23,"order_id":"1775530908755351146","flags":128,"ts_in_delta":1656,"sequence":178477,"symbol":"FCEU SI 20260615 PS"}
{"ts_recv":"2026-04-07T03:01:48.755467611Z","hd":{"ts_event":"2026-04-07T03:01:48.755450623Z","rtype":160,"publisher_id":101,"instrument_id":436},"action":"C","side":"B","price":"1.156730000","size":30,"channel_id":23,"order_id":"10998902928214190817","flags":0,"ts_in_delta":1214,"sequence":178478,"symbol":"FCEU SI 20260615 PS"}
{"ts_recv":"2026-04-07T03:01:48.755467611Z","hd":{"ts_event":"2026-04-07T03:01:48.755450623Z","rtype":160,"publisher_id":101,"instrument_id":436},"action":"A","side":"B","price":"1.156750000","size":30,"channel_id":23,"order_id":"10998902945610232183","flags":0,"ts_in_delta":1214,"sequence":178478,"symbol":"FCEU SI 20260615 PS"}
{"ts_recv":"2026-04-07T03:01:48.755467611Z","hd":{"ts_event":"2026-04-07T03:01:48.755450623Z","rtype":160,"publisher_id":101,"instrument_id":436},"action":"C","side":"A","price":"1.156830000","size":30,"channel_id":23,"order_id":"1775530891359415009","flags":0,"ts_in_delta":1214,"sequence":178478,"symbol":"FCEU SI 20260615 PS"}
{"ts_recv":"2026-04-07T03:01:48.755467611Z","hd":{"ts_event":"2026-04-07T03:01:48.755450623Z","rtype":160,"publisher_id":101,"instrument_id":436},"action":"A","side":"A","price":"1.156850000","size":30,"channel_id":23,"order_id":"1775530908755456375","flags":128,"ts_in_delta":1214,"sequence":178478,"symbol":"FCEU SI 20260615 PS"}
{"ts_recv":"2026-04-07T03:01:48.771427441Z","hd":{"ts_event":"2026-04-07T03:01:48.771406799Z","rtype":160,"publisher_id":101,"instrument_id":436},"action":"C","side":"B","price":"1.156750000","size":30,"channel_id":23,"order_id":"10998902945610232183","flags":0,"ts_in_delta":1195,"sequence":178482,"symbol":"FCEU SI 20260615 PS"}
{"ts_recv":"2026-04-07T03:01:48.771427441Z","hd":{"ts_event":"2026-04-07T03:01:48.771406799Z","rtype":160,"publisher_id":101,"instrument_id":436},"action":"A","side":"B","price":"1.156760000","size":30,"channel_id":23,"order_id":"10998902945626188464","flags":0,"ts_in_delta":1195,"sequence":178482,"symbol":"FCEU SI 20260615 PS"}
{"ts_recv":"2026-04-07T03:01:48.771427441Z","hd":{"ts_event":"2026-04-07T03:01:48.771406799Z","rtype":160,"publisher_id":101,"instrument_id":436},"action":"C","side":"A","price":"1.156850000","size":30,"channel_id":23,"order_id":"1775530908755456375","flags":0,"ts_in_delta":1195,"sequence":178482,"symbol":"FCEU SI 20260615 PS"}
{"ts_recv":"2026-04-07T03:01:48.771427441Z","hd":{"ts_event":"2026-04-07T03:01:48.771406799Z","rtype":160,"publisher_id":101,"instrument_id":436},"action":"A","side":"A","price":"1.156860000","size":30,"channel_id":23,"order_id":"1775530908771412656","flags":128,"ts_in_delta":1195,"sequence":178482,"symbol":"FCEU SI 20260615 PS"}
{"ts_recv":"2026-04-07T03:01:48.771479455Z","hd":{"ts_event":"2026-04-07T03:01:48.771458883Z","rtype":160,"publisher_id":101,"instrument_id":436},"action":"C","side":"B","price":"1.156750000","size":30,"channel_id":23,"order_id":"10998902945610126954","flags":0,"ts_in_delta":924,"sequence":178483,"symbol":"FCEU SI 20260615 PS"}
{"ts_recv":"2026-04-07T03:01:48.771479455Z","hd":{"ts_event":"2026-04-07T03:01:48.771458883Z","rtype":160,"publisher_id":101,"instrument_id":436},"action":"A","side":"B","price":"1.156770000","size":30,"channel_id":23,"order_id":"10998902945626240510","flags":0,"ts_in_delta":924,"sequence":178483,"symbol":"FCEU SI 20260615 PS"}
{"ts_recv":"2026-04-07T03:01:48.771479455Z","hd":{"ts_event":"2026-04-07T03:01:48.771458883Z","rtype":160,"publisher_id":101,"instrument_id":436},"action":"C","side":"A","price":"1.156850000","size":30,"channel_id":23,"order_id":"1775530908755351146","flags":0,"ts_in_delta":924,"sequence":178483,"symbol":"FCEU SI 20260615 PS"}
{"ts_recv":"2026-04-07T03:01:48.771479455Z","hd":{"ts_event":"2026-04-07T03:01:48.771458883Z","rtype":160,"publisher_id":101,"instrument_id":436},"action":"A","side":"A","price":"1.156870000","size":30,"channel_id":23,"order_id":"1775530908771464702","flags":128,"ts_in_delta":924,"sequence":178483,"symbol":"FCEU SI 20260615 PS"}
{"ts_recv":"2026-04-07T03:01:48.771505059Z","hd":{"ts_event":"2026-04-07T03:01:48.771487895Z","rtype":160,"publisher_id":101,"instrument_id":436},"action":"C","side":"B","price":"1.156760000","size":30,"channel_id":23,"order_id":"10998902945626188464","flags":0,"ts_in_delta":733,"sequence":178484,"symbol":"FCEU SI 20260615 PS"}
{"ts_recv":"2026-04-07T03:01:48.771505059Z","hd":{"ts_event":"2026-04-07T03:01:48.771487895Z","rtype":160,"publisher_id":101,"instrument_id":436},"action":"A","side":"B","price":"1.156770000","size":30,"channel_id":23,"order_id":"10998902945626270044","flags":0,"ts_in_delta":733,"sequence":178484,"symbol":"FCEU SI 20260615 PS"}
{"ts_recv":"2026-04-07T03:01:48.771505059Z","hd":{"ts_event":"2026-04-07T03:01:48.771487895Z","rtype":160,"publisher_id":101,"instrument_id":436},"action":"C","side":"A","price":"1.156860000","size":30,"channel_id":23,"order_id":"1775530908771412656","flags":0,"ts_in_delta":733,"sequence":178484,"symbol":"FCEU SI 20260615 PS"}
{"ts_recv":"2026-04-07T03:01:48.771505059Z","hd":{"ts_event":"2026-04-07T03:01:48.771487895Z","rtype":160,"publisher_id":101,"instrument_id":436},"action":"A","side":"A","price":"1.156870000","size":30,"channel_id":23,"order_id":"1775530908771494236","flags":128,"ts_in_delta":733,"sequence":178484,"symbol":"FCEU SI 20260615 PS"}
{"ts_recv":"2026-04-07T03:01:48.775683786Z","hd":{"ts_event":"2026-04-07T03:01:48.775662779Z","rtype":160,"publisher_id":101,"instrument_id":436},"action":"C","side":"B","price":"1.156770000","size":30,"channel_id":23,"order_id":"10998902945626270044","flags":0,"ts_in_delta":943,"sequence":178490,"symbol":"FCEU SI 20260615 PS"}
{"ts_recv":"2026-04-07T03:01:48.775683786Z","hd":{"ts_event":"2026-04-07T03:01:48.775662779Z","rtype":160,"publisher_id":101,"instrument_id":436},"action":"A","side":"B","price":"1.156780000","size":30,"channel_id":23,"order_id":"10998902945630444703","flags":0,"ts_in_delta":943,"sequence":178490,"symbol":"FCEU SI 20260615 PS"}
{"ts_recv":"2026-04-07T03:01:48.775683786Z","hd":{"ts_event":"2026-04-07T03:01:48.775662779Z","rtype":160,"publisher_id":101,"instrument_id":436},"action":"C","side":"A","price":"1.156870000","size":30,"channel_id":23,"order_id":"1775530908771494236","flags":0,"ts_in_delta":943,"sequence":178490,"symbol":"FCEU SI 20260615 PS"}
{"ts_recv":"2026-04-07T03:01:48.775683786Z","hd":{"ts_event":"2026-04-07T03:01:48.775662779Z","rtype":160,"publisher_id":101,"instrument_id":436},"action":"A","side":"A","price":"1.156880000","size":30,"channel_id":23,"order_id":"1775530908775668895","flags":128,"ts_in_delta":943,"sequence":178490,"symbol":"FCEU SI 20260615 PS"}
{"ts_recv":"2026-04-07T03:01:52.775458316Z","hd":{"ts_event":"2026-04-07T03:01:52.775430083Z","rtype":160,"publisher_id":101,"instrument_id":436},"action":"C","side":"B","price":"1.156780000","size":30,"channel_id":23,"order_id":"10998902945630444703","flags":0,"ts_in_delta":921,"sequence":178531,"symbol":"FCEU SI 20260615 PS"}
{"ts_recv":"2026-04-07T03:01:52.775458316Z","hd":{"ts_event":"2026-04-07T03:01:52.775430083Z","rtype":160,"publisher_id":101,"instrument_id":436},"action":"A","side":"B","price":"1.156760000","size":30,"channel_id":23,"order_id":"10998902949630214898","flags":0,"ts_in_delta":921,"sequence":178531,"symbol":"FCEU SI 20260615 PS"}
{"ts_recv":"2026-04-07T03:01:52.775458316Z","hd":{"ts_event":"2026-04-07T03:01:52.775430083Z","rtype":160,"publisher_id":101,"instrument_id":436},"action":"C","side":"A","price":"1.156880000","size":30,"channel_id":23,"order_id":"1775530908775668895","flags":0,"ts_in_delta":921,"sequence":178531,"symbol":"FCEU SI 20260615 PS"}
{"ts_recv":"2026-04-07T03:01:52.775458316Z","hd":{"ts_event":"2026-04-07T03:01:52.775430083Z","rtype":160,"publisher_id":101,"instrument_id":436},"action":"A","side":"A","price":"1.156860000","size":30,"channel_id":23,"order_id":"1775530912775439090","flags":128,"ts_in_delta":921,"sequence":178531,"symbol":"FCEU SI 20260615 PS"}
{"ts_recv":"2026-04-07T03:01:52.775548283Z","hd":{"ts_event":"2026-04-07T03:01:52.775531889Z","rtype":160,"publisher_id":101,"instrument_id":436},"action":"C","side":"B","price":"1.156760000","size":30,"channel_id":23,"order_id":"10998902949630214898","flags":0,"ts_in_delta":903,"sequence":178532,"symbol":"FCEU SI 20260615 PS"}
{"ts_recv":"2026-04-07T03:01:52.775548283Z","hd":{"ts_event":"2026-04-07T03:01:52.775531889Z","rtype":160,"publisher_id":101,"instrument_id":436},"action":"A","side":"B","price":"1.156770000","size":30,"channel_id":23,"order_id":"10998902949630314118","flags":0,"ts_in_delta":903,"sequence":178532,"symbol":"FCEU SI 20260615 PS"}
{"ts_recv":"2026-04-07T03:01:52.775548283Z","hd":{"ts_event":"2026-04-07T03:01:52.775531889Z","rtype":160,"publisher_id":101,"instrument_id":436},"action":"C","side":"A","price":"1.156860000","size":30,"channel_id":23,"order_id":"1775530912775439090","flags":0,"ts_in_delta":903,"sequence":178532,"symbol":"FCEU SI 20260615 PS"}
{"ts_recv":"2026-04-07T03:01:52.775548283Z","hd":{"ts_event":"2026-04-07T03:01:52.775531889Z","rtype":160,"publisher_id":101,"instrument_id":436},"action":"A","side":"A","price":"1.156870000","size":30,"channel_id":23,"order_id":"1775530912775538310","flags":128,"ts_in_delta":903,"sequence":178532,"symbol":"FCEU SI 20260615 PS"}
{"ts_recv":"2026-04-07T03:01:52.998611323Z","hd":{"ts_event":"2026-04-07T03:01:52.998588941Z","rtype":160,"publisher_id":101,"instrument_id":436},"action":"C","side":"B","price":"1.156770000","size":30,"channel_id":23,"order_id":"10998902949630314118","flags":0,"ts_in_delta":1054,"sequence":178537,"symbol":"FCEU SI 20260615 PS"}
{"ts_recv":"2026-04-07T03:01:52.998611323Z","hd":{"ts_event":"2026-04-07T03:01:52.998588941Z","rtype":160,"publisher_id":101,"instrument_id":436},"action":"A","side":"B","price":"1.156780000","size":30,"channel_id":23,"order_id":"10998902949853370860","flags":0,"ts_in_delta":1054,"sequence":178537,"symbol":"FCEU SI 20260615 PS"}
{"ts_recv":"2026-04-07T03:01:52.998611323Z","hd":{"ts_event":"2026-04-07T03:01:52.998588941Z","rtype":160,"publisher_id":101,"instrument_id":436},"action":"C","side":"A","price":"1.156870000","size":30,"channel_id":23,"order_id":"1775530912775538310","flags":0,"ts_in_delta":1054,"sequence":178537,"symbol":"FCEU SI 20260615 PS"}
{"ts_recv":"2026-04-07T03:01:52.998611323Z","hd":{"ts_event":"2026-04-07T03:01:52.998588941Z","rtype":160,"publisher_id":101,"instrument_id":436},"action":"A","side":"A","price":"1.156880000","size":30,"channel_id":23,"order_id":"1775530912998595052","flags":128,"ts_in_delta":1054,"sequence":178537,"symbol":"FCEU SI 20260615 PS"}
{"ts_recv":"2026-04-07T03:01:53.574293373Z","hd":{"ts_event":"2026-04-07T03:01:53.574264481Z","rtype":160,"publisher_id":101,"instrument_id":436},"action":"C","side":"B","price":"1.156780000","size":30,"channel_id":23,"order_id":"10998902949853370860","flags":0,"ts_in_delta":1298,"sequence":178546,"symbol":"FCEU SI 20260615 PS"}
{"ts_recv":"2026-04-07T03:01:53.574293373Z","hd":{"ts_event":"2026-04-07T03:01:53.574264481Z","rtype":160,"publisher_id":101,"instrument_id":436},"action":"A","side":"B","price":"1.156770000","size":30,"channel_id":23,"order_id":"10998902950429053359","flags":0,"ts_in_delta":1298,"sequence":178546,"symbol":"FCEU SI 20260615 PS"}
{"ts_recv":"2026-04-07T03:01:53.574293373Z","hd":{"ts_event":"2026-04-07T03:01:53.574264481Z","rtype":160,"publisher_id":101,"instrument_id":436},"action":"C","side":"A","price":"1.156880000","size":30,"channel_id":23,"order_id":"1775530912998595052","flags":0,"ts_in_delta":1298,"sequence":178546,"symbol":"FCEU SI 20260615 PS"}
{"ts_recv":"2026-04-07T03:01:53.574293373Z","hd":{"ts_event":"2026-04-07T03:01:53.574264481Z","rtype":160,"publisher_id":101,"instrument_id":436},"action":"A","side":"A","price":"1.156870000","size":30,"channel_id":23,"order_id":"1775530913574277551","flags":128,"ts_in_delta":1298,"sequence":178546,"symbol":"FCEU SI 20260615 PS"}
{"ts_recv":"2026-04-07T03:01:53.609583793Z","hd":{"ts_event":"2026-04-07T03:01:53.609565811Z","rtype":160,"publisher_id":101,"instrument_id":436},"action":"C","side":"B","price":"1.156770000","size":30,"channel_id":23,"order_id":"10998902950429053359","flags":0,"ts_in_delta":1145,"sequence":178560,"symbol":"FCEU SI 20260615 PS"}
{"ts_recv":"2026-04-07T03:01:53.609583793Z","hd":{"ts_event":"2026-04-07T03:01:53.609565811Z","rtype":160,"publisher_id":101,"instrument_id":436},"action":"A","side":"B","price":"1.156760000","size":30,"channel_id":23,"order_id":"10998902950464347527","flags":0,"ts_in_delta":1145,"sequence":178560,"symbol":"FCEU SI 20260615 PS"}
{"ts_recv":"2026-04-07T03:01:53.609583793Z","hd":{"ts_event":"2026-04-07T03:01:53.609565811Z","rtype":160,"publisher_id":101,"instrument_id":436},"action":"C","side":"A","price":"1.156870000","size":30,"channel_id":23,"order_id":"1775530913574277551","flags":0,"ts_in_delta":1145,"sequence":178560,"symbol":"FCEU SI 20260615 PS"}
{"ts_recv":"2026-04-07T03:01:53.609583793Z","hd":{"ts_event":"2026-04-07T03:01:53.609565811Z","rtype":160,"publisher_id":101,"instrument_id":436},"action":"A","side":"A","price":"1.156860000","size":30,"channel_id":23,"order_id":"1775530913609571719","flags":128,"ts_in_delta":1145,"sequence":178560,"symbol":"FCEU SI 20260615 PS"}
{"ts_recv":"2026-04-07T03:01:53.609638026Z","hd":{"ts_event":"2026-04-07T03:01:53.609615077Z","rtype":160,"publisher_id":101,"instrument_id":436},"action":"C","side":"B","price":"1.156770000","size":30,"channel_id":23,"order_id":"10998902945626240510","flags":0,"ts_in_delta":944,"sequence":178562,"symbol":"FCEU SI 20260615 PS"}
{"ts_recv":"2026-04-07T03:01:53.609638026Z","hd":{"ts_event":"2026-04-07T03:01:53.609615077Z","rtype":160,"publisher_id":101,"instrument_id":436},"action":"A","side":"B","price":"1.156750000","size":30,"channel_id":23,"order_id":"10998902950464398292","flags":0,"ts_in_delta":944,"sequence":178562,"symbol":"FCEU SI 20260615 PS"}
{"ts_recv":"2026-04-07T03:01:53.609638026Z","hd":{"ts_event":"2026-04-07T03:01:53.609615077Z","rtype":160,"publisher_id":101,"instrument_id":436},"action":"C","side":"A","price":"1.156870000","size":30,"channel_id":23,"order_id":"1775530908771464702","flags":0,"ts_in_delta":944,"sequence":178562,"symbol":"FCEU SI 20260615 PS"}
{"ts_recv":"2026-04-07T03:01:53.609638026Z","hd":{"ts_event":"2026-04-07T03:01:53.609615077Z","rtype":160,"publisher_id":101,"instrument_id":436},"action":"A","side":"A","price":"1.156850000","size":30,"channel_id":23,"order_id":"1775530913609622484","flags":128,"ts_in_delta":944,"sequence":178562,"symbol":"FCEU SI 20260615 PS"}
{"ts_recv":"2026-04-07T03:01:53.609694072Z","hd":{"ts_event":"2026-04-07T03:01:53.609678037Z","rtype":160,"publisher_id":101,"instrument_id":436},"action":"C","side":"B","price":"1.156760000","size":30,"channel_id":23,"order_id":"10998902950464347527","flags":0,"ts_in_delta":957,"sequence":178563,"symbol":"FCEU SI 20260615 PS"}
{"ts_recv":"2026-04-07T03:01:53.609694072Z","hd":{"ts_event":"2026-04-07T03:01:53.609678037Z","rtype":160,"publisher_id":101,"instrument_id":436},"action":"A","side":"B","price":"1.156750000","size":30,"channel_id":23,"order_id":"10998902950464459739","flags":0,"ts_in_delta":957,"sequence":178563,"symbol":"FCEU SI 20260615 PS"}
{"ts_recv":"2026-04-07T03:01:53.609694072Z","hd":{"ts_event":"2026-04-07T03:01:53.609678037Z","rtype":160,"publisher_id":101,"instrument_id":436},"action":"C","side":"A","price":"1.156860000","size":30,"channel_id":23,"order_id":"1775530913609571719","flags":0,"ts_in_delta":957,"sequence":178563,"symbol":"FCEU SI 20260615 PS"}
{"ts_recv":"2026-04-07T03:01:53.609694072Z","hd":{"ts_event":"2026-04-07T03:01:53.609678037Z","rtype":160,"publisher_id":101,"instrument_id":436},"action":"A","side":"A","price":"1.156850000","size":30,"channel_id":23,"order_id":"1775530913609683931","flags":128,"ts_in_delta":957,"sequence":178563,"symbol":"FCEU SI 20260615 PS"}
{"ts_recv":"2026-04-07T03:01:54.086041540Z","hd":{"ts_event":"2026-04-07T03:01:54.086011909Z","rtype":160,"publisher_id":101,"instrument_id":436},"action":"C","side":"B","price":"1.156750000","size":30,"channel_id":23,"order_id":"10998902950464459739","flags":0,"ts_in_delta":1018,"sequence":178603,"symbol":"FCEU SI 20260615 PS"}
{"ts_recv":"2026-04-07T03:01:54.086041540Z","hd":{"ts_event":"2026-04-07T03:01:54.086011909Z","rtype":160,"publisher_id":101,"instrument_id":436},"action":"A","side":"B","price":"1.156740000","size":30,"channel_id":23,"order_id":"10998902950940800926","flags":0,"ts_in_delta":1018,"sequence":178603,"symbol":"FCEU SI 20260615 PS"}
{"ts_recv":"2026-04-07T03:01:54.086041540Z","hd":{"ts_event":"2026-04-07T03:01:54.086011909Z","rtype":160,"publisher_id":101,"instrument_id":436},"action":"C","side":"A","price":"1.156850000","size":30,"channel_id":23,"order_id":"1775530913609683931","flags":0,"ts_in_delta":1018,"sequence":178603,"symbol":"FCEU SI 20260615 PS"}
{"ts_recv":"2026-04-07T03:01:54.086041540Z","hd":{"ts_event":"2026-04-07T03:01:54.086011909Z","rtype":160,"publisher_id":101,"instrument_id":436},"action":"A","side":"A","price":"1.156840000","size":30,"channel_id":23,"order_id":"1775530914086025118","flags":128,"ts_in_delta":1018,"sequence":178603,"symbol":"FCEU SI 20260615 PS"}
{"ts_recv":"2026-04-07T03:01:54.086124426Z","hd":{"ts_event":"2026-04-07T03:01:54.086106451Z","rtype":160,"publisher_id":101,"instrument_id":436},"action":"C","side":"B","price":"1.156740000","size":30,"channel_id":23,"order_id":"10998902950940800926","flags":0,"ts_in_delta":989,"sequence":178604,"symbol":"FCEU SI 20260615 PS"}
{"ts_recv":"2026-04-07T03:01:54.086124426Z","hd":{"ts_event":"2026-04-07T03:01:54.086106451Z","rtype":160,"publisher_id":101,"instrument_id":436},"action":"A","side":"B","price":"1.156730000","size":30,"channel_id":23,"order_id":"10998902950940888416","flags":0,"ts_in_delta":989,"sequence":178604,"symbol":"FCEU SI 20260615 PS"}
{"ts_recv":"2026-04-07T03:01:54.086124426Z","hd":{"ts_event":"2026-04-07T03:01:54.086106451Z","rtype":160,"publisher_id":101,"instrument_id":436},"action":"C","side":"A","price":"1.156840000","size":30,"channel_id":23,"order_id":"1775530914086025118","flags":0,"ts_in_delta":989,"sequence":178604,"symbol":"FCEU SI 20260615 PS"}
{"ts_recv":"2026-04-07T03:01:54.086124426Z","hd":{"ts_event":"2026-04-07T03:01:54.086106451Z","rtype":160,"publisher_id":101,"instrument_id":436},"action":"A","side":"A","price":"1.156830000","size":30,"channel_id":23,"order_id":"1775530914086112608","flags":128,"ts_in_delta":989,"sequence":178604,"symbol":"FCEU SI 20260615 PS"}
{"ts_recv":"2026-04-07T03:01:54.086181686Z","hd":{"ts_event":"2026-04-07T03:01:54.086165549Z","rtype":160,"publisher_id":101,"instrument_id":436},"action":"C","side":"B","price":"1.156750000","size":30,"channel_id":23,"order_id":"10998902950464398292","flags":0,"ts_in_delta":1085,"sequence":178605,"symbol":"FCEU SI 20260615 PS"}
{"ts_recv":"2026-04-07T03:01:54.086181686Z","hd":{"ts_event":"2026-04-07T03:01:54.086165549Z","rtype":160,"publisher_id":101,"instrument_id":436},"action":"A","side":"B","price":"1.156730000","size":30,"channel_id":23,"order_id":"10998902950940947269","flags":0,"ts_in_delta":1085,"sequence":178605,"symbol":"FCEU SI 20260615 PS"}
{"ts_recv":"2026-04-07T03:01:54.086181686Z","hd":{"ts_event":"2026-04-07T03:01:54.086165549Z","rtype":160,"publisher_id":101,"instrument_id":436},"action":"C","side":"A","price":"1.156850000","size":30,"channel_id":23,"order_id":"1775530913609622484","flags":0,"ts_in_delta":1085,"sequence":178605,"symbol":"FCEU SI 20260615 PS"}
{"ts_recv":"2026-04-07T03:01:54.086181686Z","hd":{"ts_event":"2026-04-07T03:01:54.086165549Z","rtype":160,"publisher_id":101,"instrument_id":436},"action":"A","side":"A","price":"1.156830000","size":30,"channel_id":23,"order_id":"1775530914086171461","flags":128,"ts_in_delta":1085,"sequence":178605,"symbol":"FCEU SI 20260615 PS"}
{"ts_recv":"2026-04-07T03:01:54.086193121Z","hd":{"ts_event":"2026-04-07T03:01:54.086166373Z","rtype":160,"publisher_id":101,"instrument_id":436},"action":"C","side":"B","price":"1.156730000","size":30,"channel_id":23,"order_id":"10998902950940888416","flags":0,"ts_in_delta":942,"sequence":178606,"symbol":"FCEU SI 20260615 PS"}
{"ts_recv":"2026-04-07T03:01:54.086193121Z","hd":{"ts_event":"2026-04-07T03:01:54.086166373Z","rtype":160,"publisher_id":101,"instrument_id":436},"action":"A","side":"B","price":"1.156740000","size":30,"channel_id":23,"order_id":"10998902950940954327","flags":0,"ts_in_delta":942,"sequence":178606,"symbol":"FCEU SI 20260615 PS"}
{"ts_recv":"2026-04-07T03:01:54.086193121Z","hd":{"ts_event":"2026-04-07T03:01:54.086166373Z","rtype":160,"publisher_id":101,"instrument_id":436},"action":"C","side":"A","price":"1.156830000","size":30,"channel_id":23,"order_id":"1775530914086112608","flags":0,"ts_in_delta":942,"sequence":178606,"symbol":"FCEU SI 20260615 PS"}
{"ts_recv":"2026-04-07T03:01:54.086193121Z","hd":{"ts_event":"2026-04-07T03:01:54.086166373Z","rtype":160,"publisher_id":101,"instrument_id":436},"action":"A","side":"A","price":"1.156840000","size":30,"channel_id":23,"order_id":"1775530914086178519","flags":128,"ts_in_delta":942,"sequence":178606,"symbol":"FCEU SI 20260615 PS"}
{"ts_recv":"2026-04-07T03:01:54.086249489Z","hd":{"ts_event":"2026-04-07T03:01:54.086229103Z","rtype":160,"publisher_id":101,"instrument_id":436},"action":"C","side":"B","price":"1.156740000","size":30,"channel_id":23,"order_id":"10998902950940954327","flags":0,"ts_in_delta":938,"sequence":178607,"symbol":"FCEU SI 20260615 PS"}
{"ts_recv":"2026-04-07T03:01:54.086249489Z","hd":{"ts_event":"2026-04-07T03:01:54.086229103Z","rtype":160,"publisher_id":101,"instrument_id":436},"action":"A","side":"B","price":"1.156730000","size":30,"channel_id":23,"order_id":"10998902950941014904","flags":0,"ts_in_delta":938,"sequence":178607,"symbol":"FCEU SI 20260615 PS"}
{"ts_recv":"2026-04-07T03:01:54.086249489Z","hd":{"ts_event":"2026-04-07T03:01:54.086229103Z","rtype":160,"publisher_id":101,"instrument_id":436},"action":"C","side":"A","price":"1.156840000","size":30,"channel_id":23,"order_id":"1775530914086178519","flags":0,"ts_in_delta":938,"sequence":178607,"symbol":"FCEU SI 20260615 PS"}
{"ts_recv":"2026-04-07T03:01:54.086249489Z","hd":{"ts_event":"2026-04-07T03:01:54.086229103Z","rtype":160,"publisher_id":101,"instrument_id":436},"action":"A","side":"A","price":"1.156830000","size":30,"channel_id":23,"order_id":"1775530914086239096","flags":128,"ts_in_delta":938,"sequence":178607,"symbol":"FCEU SI 20260615 PS"}
{"ts_recv":"2026-04-07T03:02:20.196378612Z","hd":{"ts_event":"2026-04-07T03:02:20.196355665Z","rtype":160,"publisher_id":101,"instrument_id":436},"action":"C","side":"B","price":"1.156730000","size":30,"channel_id":23,"order_id":"10998902950941014904","flags":0,"ts_in_delta":928,"sequence":178830,"symbol":"FCEU SI 20260615 PS"}
{"ts_recv":"2026-04-07T03:02:20.196378612Z","hd":{"ts_event":"2026-04-07T03:02:20.196355665Z","rtype":160,"publisher_id":101,"instrument_id":436},"action":"A","side":"B","price":"1.156740000","size":30,"channel_id":23,"order_id":"10998902977051137542","flags":0,"ts_in_delta":928,"sequence":178830,"symbol":"FCEU SI 20260615 PS"}
{"ts_recv":"2026-04-07T03:02:20.196378612Z","hd":{"ts_event":"2026-04-07T03:02:20.196355665Z","rtype":160,"publisher_id":101,"instrument_id":436},"action":"C","side":"A","price":"1.156830000","size":30,"channel_id":23,"order_id":"1775530914086239096","flags":0,"ts_in_delta":928,"sequence":178830,"symbol":"FCEU SI 20260615 PS"}
{"ts_recv":"2026-04-07T03:02:20.196378612Z","hd":{"ts_event":"2026-04-07T03:02:20.196355665Z","rtype":160,"publisher_id":101,"instrument_id":436},"action":"A","side":"A","price":"1.156840000","size":30,"channel_id":23,"order_id":"1775530940196361734","flags":128,"ts_in_delta":928,"sequence":178830,"symbol":"FCEU SI 20260615 PS"}
{"ts_recv":"2026-04-07T03:02:20.196432077Z","hd":{"ts_event":"2026-04-07T03:02:20.196414147Z","rtype":160,"publisher_id":101,"instrument_id":436},"action":"C","side":"B","price":"1.156730000","size":30,"channel_id":23,"order_id":"10998902950940947269","flags":0,"ts_in_delta":937,"sequence":178831,"symbol":"FCEU SI 20260615 PS"}
{"ts_recv":"2026-04-07T03:02:20.196432077Z","hd":{"ts_event":"2026-04-07T03:02:20.196414147Z","rtype":160,"publisher_id":101,"instrument_id":436},"action":"A","side":"B","price":"1.156750000","size":30,"channel_id":23,"order_id":"10998902977051196060","flags":0,"ts_in_delta":937,"sequence":178831,"symbol":"FCEU SI 20260615 PS"}
{"ts_recv":"2026-04-07T03:02:20.196432077Z","hd":{"ts_event":"2026-04-07T03:02:20.196414147Z","rtype":160,"publisher_id":101,"instrument_id":436},"action":"C","side":"A","price":"1.156830000","size":30,"channel_id":23,"order_id":"1775530914086171461","flags":0,"ts_in_delta":937,"sequence":178831,"symbol":"FCEU SI 20260615 PS"}
{"ts_recv":"2026-04-07T03:02:20.196432077Z","hd":{"ts_event":"2026-04-07T03:02:20.196414147Z","rtype":160,"publisher_id":101,"instrument_id":436},"action":"A","side":"A","price":"1.156850000","size":30,"channel_id":23,"order_id":"1775530940196420252","flags":128,"ts_in_delta":937,"sequence":178831,"symbol":"FCEU SI 20260615 PS"}
{"ts_recv":"2026-04-07T03:02:20.196464501Z","hd":{"ts_event":"2026-04-07T03:02:20.196444637Z","rtype":160,"publisher_id":101,"instrument_id":436},"action":"C","side":"B","price":"1.156740000","size":30,"channel_id":23,"order_id":"10998902977051137542","flags":0,"ts_in_delta":928,"sequence":178832,"symbol":"FCEU SI 20260615 PS"}
{"ts_recv":"2026-04-07T03:02:20.196464501Z","hd":{"ts_event":"2026-04-07T03:02:20.196444637Z","rtype":160,"publisher_id":101,"instrument_id":436},"action":"A","side":"B","price":"1.156750000","size":30,"channel_id":23,"order_id":"10998902977051226701","flags":0,"ts_in_delta":928,"sequence":178832,"symbol":"FCEU SI 20260615 PS"}
{"ts_recv":"2026-04-07T03:02:20.196464501Z","hd":{"ts_event":"2026-04-07T03:02:20.196444637Z","rtype":160,"publisher_id":101,"instrument_id":436},"action":"C","side":"A","price":"1.156840000","size":30,"channel_id":23,"order_id":"1775530940196361734","flags":0,"ts_in_delta":928,"sequence":178832,"symbol":"FCEU SI 20260615 PS"}
{"ts_recv":"2026-04-07T03:02:20.196464501Z","hd":{"ts_event":"2026-04-07T03:02:20.196444637Z","rtype":160,"publisher_id":101,"instrument_id":436},"action":"A","side":"A","price":"1.156850000","size":30,"channel_id":23,"order_id":"1775530940196450893","flags":128,"ts_in_delta":928,"sequence":178832,"symbol":"FCEU SI 20260615 PS"}
{"ts_recv":"2026-04-07T03:02:20.201129142Z","hd":{"ts_event":"2026-04-07T03:02:20.201107891Z","rtype":160,"publisher_id":101,"instrument_id":436},"action":"C","side":"B","price":"1.156750000","size":30,"channel_id":23,"order_id":"10998902977051226701","flags":0,"ts_in_delta":891,"sequence":178837,"symbol":"FCEU SI 20260615 PS"}
{"ts_recv":"2026-04-07T03:02:20.201129142Z","hd":{"ts_event":"2026-04-07T03:02:20.201107891Z","rtype":160,"publisher_id":101,"instrument_id":436},"action":"A","side":"B","price":"1.156760000","size":30,"channel_id":23,"order_id":"10998902977055890086","flags":0,"ts_in_delta":891,"sequence":178837,"symbol":"FCEU SI 20260615 PS"}
{"ts_recv":"2026-04-07T03:02:20.201129142Z","hd":{"ts_event":"2026-04-07T03:02:20.201107891Z","rtype":160,"publisher_id":101,"instrument_id":436},"action":"C","side":"A","price":"1.156850000","size":30,"channel_id":23,"order_id":"1775530940196450893","flags":0,"ts_in_delta":891,"sequence":178837,"symbol":"FCEU SI 20260615 PS"}
{"ts_recv":"2026-04-07T03:02:20.201129142Z","hd":{"ts_event":"2026-04-07T03:02:20.201107891Z","rtype":160,"publisher_id":101,"instrument_id":436},"action":"A","side":"A","price":"1.156860000","size":30,"channel_id":23,"order_id":"1775530940201114278","flags":128,"ts_in_delta":891,"sequence":178837,"symbol":"FCEU SI 20260615 PS"}
{"ts_recv":"2026-04-07T03:02:20.206170892Z","hd":{"ts_event":"2026-04-07T03:02:20.206151589Z","rtype":160,"publisher_id":101,"instrument_id":436},"action":"C","side":"B","price":"1.156760000","size":30,"channel_id":23,"order_id":"10998902977055890086","flags":0,"ts_in_delta":893,"sequence":178848,"symbol":"FCEU SI 20260615 PS"}
{"ts_recv":"2026-04-07T03:02:20.206170892Z","hd":{"ts_event":"2026-04-07T03:02:20.206151589Z","rtype":160,"publisher_id":101,"instrument_id":436},"action":"A","side":"B","price":"1.156770000","size":30,"channel_id":23,"order_id":"10998902977060933510","flags":0,"ts_in_delta":893,"sequence":178848,"symbol":"FCEU SI 20260615 PS"}
{"ts_recv":"2026-04-07T03:02:20.206170892Z","hd":{"ts_event":"2026-04-07T03:02:20.206151589Z","rtype":160,"publisher_id":101,"instrument_id":436},"action":"C","side":"A","price":"1.156860000","size":30,"channel_id":23,"order_id":"1775530940201114278","flags":0,"ts_in_delta":893,"sequence":178848,"symbol":"FCEU SI 20260615 PS"}
{"ts_recv":"2026-04-07T03:02:20.206170892Z","hd":{"ts_event":"2026-04-07T03:02:20.206151589Z","rtype":160,"publisher_id":101,"instrument_id":436},"action":"A","side":"A","price":"1.156870000","size":30,"channel_id":23,"order_id":"1775530940206157702","flags":128,"ts_in_delta":893,"sequence":178848,"symbol":"FCEU SI 20260615 PS"}
{"ts_recv":"2026-04-07T03:02:20.206223589Z","hd":{"ts_event":"2026-04-07T03:02:20.206202373Z","rtype":160,"publisher_id":101,"instrument_id":436},"action":"C","side":"B","price":"1.156750000","size":30,"channel_id":23,"order_id":"10998902977051196060","flags":0,"ts_in_delta":839,"sequence":178850,"symbol":"FCEU SI 20260615 PS"}
{"ts_recv":"2026-04-07T03:02:20.206223589Z","hd":{"ts_event":"2026-04-07T03:02:20.206202373Z","rtype":160,"publisher_id":101,"instrument_id":436},"action":"A","side":"B","price":"1.156770000","size":30,"channel_id":23,"order_id":"10998902977060987422","flags":0,"ts_in_delta":839,"sequence":178850,"symbol":"FCEU SI 20260615 PS"}
{"ts_recv":"2026-04-07T03:02:20.206223589Z","hd":{"ts_event":"2026-04-07T03:02:20.206202373Z","rtype":160,"publisher_id":101,"instrument_id":436},"action":"C","side":"A","price":"1.156850000","size":30,"channel_id":23,"order_id":"1775530940196420252","flags":0,"ts_in_delta":839,"sequence":178850,"symbol":"FCEU SI 20260615 PS"}
{"ts_recv":"2026-04-07T03:02:20.206223589Z","hd":{"ts_event":"2026-04-07T03:02:20.206202373Z","rtype":160,"publisher_id":101,"instrument_id":436},"action":"A","side":"A","price":"1.156870000","size":30,"channel_id":23,"order_id":"1775530940206211614","flags":128,"ts_in_delta":839,"sequence":178850,"symbol":"FCEU SI 20260615 PS"}
{"ts_recv":"2026-04-07T03:02:20.206254938Z","hd":{"ts_event":"2026-04-07T03:02:20.206235877Z","rtype":160,"publisher_id":101,"instrument_id":436},"action":"C","side":"B","price":"1.156770000","size":30,"channel_id":23,"order_id":"10998902977060933510","flags":0,"ts_in_delta":1043,"sequence":178851,"symbol":"FCEU SI 20260615 PS"}
{"ts_recv":"2026-04-07T03:02:20.206254938Z","hd":{"ts_event":"2026-04-07T03:02:20.206235877Z","rtype":160,"publisher_id":101,"instrument_id":436},"action":"A","side":"B","price":"1.156760000","size":30,"channel_id":23,"order_id":"10998902977061017476","flags":0,"ts_in_delta":1043,"sequence":178851,"symbol":"FCEU SI 20260615 PS"}
{"ts_recv":"2026-04-07T03:02:20.206254938Z","hd":{"ts_event":"2026-04-07T03:02:20.206235877Z","rtype":160,"publisher_id":101,"instrument_id":436},"action":"C","side":"A","price":"1.156870000","size":30,"channel_id":23,"order_id":"1775530940206157702","flags":0,"ts_in_delta":1043,"sequence":178851,"symbol":"FCEU SI 20260615 PS"}
{"ts_recv":"2026-04-07T03:02:20.206254938Z","hd":{"ts_event":"2026-04-07T03:02:20.206235877Z","rtype":160,"publisher_id":101,"instrument_id":436},"action":"A","side":"A","price":"1.156860000","size":30,"channel_id":23,"order_id":"1775530940206241668","flags":128,"ts_in_delta":1043,"sequence":178851,"symbol":"FCEU SI 20260615 PS"}
{"ts_recv":"2026-04-07T03:02:20.206312466Z","hd":{"ts_event":"2026-04-07T03:02:20.206296819Z","rtype":160,"publisher_id":101,"instrument_id":436},"action":"C","side":"B","price":"1.156760000","size":30,"channel_id":23,"order_id":"10998902977061017476","flags":0,"ts_in_delta":903,"sequence":178852,"symbol":"FCEU SI 20260615 PS"}
{"ts_recv":"2026-04-07T03:02:20.206312466Z","hd":{"ts_event":"2026-04-07T03:02:20.206296819Z","rtype":160,"publisher_id":101,"instrument_id":436},"action":"A","side":"B","price":"1.156770000","size":30,"channel_id":23,"order_id":"10998902977061078693","flags":0,"ts_in_delta":903,"sequence":178852,"symbol":"FCEU SI 20260615 PS"}
{"ts_recv":"2026-04-07T03:02:20.206312466Z","hd":{"ts_event":"2026-04-07T03:02:20.206296819Z","rtype":160,"publisher_id":101,"instrument_id":436},"action":"C","side":"A","price":"1.156860000","size":30,"channel_id":23,"order_id":"1775530940206241668","flags":0,"ts_in_delta":903,"sequence":178852,"symbol":"FCEU SI 20260615 PS"}
{"ts_recv":"2026-04-07T03:02:20.206312466Z","hd":{"ts_event":"2026-04-07T03:02:20.206296819Z","rtype":160,"publisher_id":101,"instrument_id":436},"action":"A","side":"A","price":"1.156870000","size":30,"channel_id":23,"order_id":"1775530940206302885","flags":128,"ts_in_delta":903,"sequence":178852,"symbol":"FCEU SI 20260615 PS"}
{"ts_recv":"2026-04-07T03:02:20.210784654Z","hd":{"ts_event":"2026-04-07T03:02:20.210766917Z","rtype":160,"publisher_id":101,"instrument_id":436},"action":"C","side":"B","price":"1.156770000","size":30,"channel_id":23,"order_id":"10998902977061078693","flags":0,"ts_in_delta":883,"sequence":178854,"symbol":"FCEU SI 20260615 PS"}
{"ts_recv":"2026-04-07T03:02:20.210784654Z","hd":{"ts_event":"2026-04-07T03:02:20.210766917Z","rtype":160,"publisher_id":101,"instrument_id":436},"action":"A","side":"B","price":"1.156780000","size":30,"channel_id":23,"order_id":"10998902977065548997","flags":0,"ts_in_delta":883,"sequence":178854,"symbol":"FCEU SI 20260615 PS"}
{"ts_recv":"2026-04-07T03:02:20.210784654Z","hd":{"ts_event":"2026-04-07T03:02:20.210766917Z","rtype":160,"publisher_id":101,"instrument_id":436},"action":"C","side":"A","price":"1.156870000","size":30,"channel_id":23,"order_id":"1775530940206302885","flags":0,"ts_in_delta":883,"sequence":178854,"symbol":"FCEU SI 20260615 PS"}
{"ts_recv":"2026-04-07T03:02:20.210784654Z","hd":{"ts_event":"2026-04-07T03:02:20.210766917Z","rtype":160,"publisher_id":101,"instrument_id":436},"action":"A","side":"A","price":"1.156880000","size":30,"channel_id":23,"order_id":"1775530940210773189","flags":128,"ts_in_delta":883,"sequence":178854,"symbol":"FCEU SI 20260615 PS"}
{"ts_recv":"2026-04-07T03:02:35.309862052Z","hd":{"ts_event":"2026-04-07T03:02:35.309831759Z","rtype":160,"publisher_id":101,"instrument_id":436},"action":"C","side":"B","price":"1.156770000","size":30,"channel_id":23,"order_id":"10998902977060987422","flags":0,"ts_in_delta":935,"sequence":178985,"symbol":"FCEU SI 20260615 PS"}
{"ts_recv":"2026-04-07T03:02:35.309862052Z","hd":{"ts_event":"2026-04-07T03:02:35.309831759Z","rtype":160,"publisher_id":101,"instrument_id":436},"action":"A","side":"B","price":"1.156790000","size":30,"channel_id":23,"order_id":"10998902992164620261","flags":0,"ts_in_delta":935,"sequence":178985,"symbol":"FCEU SI 20260615 PS"}
{"ts_recv":"2026-04-07T03:02:35.309862052Z","hd":{"ts_event":"2026-04-07T03:02:35.309831759Z","rtype":160,"publisher_id":101,"instrument_id":436},"action":"C","side":"A","price":"1.156870000","size":30,"channel_id":23,"order_id":"1775530940206211614","flags":0,"ts_in_delta":935,"sequence":178985,"symbol":"FCEU SI 20260615 PS"}
{"ts_recv":"2026-04-07T03:02:35.309862052Z","hd":{"ts_event":"2026-04-07T03:02:35.309831759Z","rtype":160,"publisher_id":101,"instrument_id":436},"action":"A","side":"A","price":"1.156890000","size":30,"channel_id":23,"order_id":"1775530955309844453","flags":128,"ts_in_delta":935,"sequence":178985,"symbol":"FCEU SI 20260615 PS"}
{"ts_recv":"2026-04-07T03:02:35.309945575Z","hd":{"ts_event":"2026-04-07T03:02:35.309927701Z","rtype":160,"publisher_id":101,"instrument_id":436},"action":"C","side":"B","price":"1.156780000","size":30,"channel_id":23,"order_id":"10998902977065548997","flags":0,"ts_in_delta":1102,"sequence":178986,"symbol":"FCEU SI 20260615 PS"}
{"ts_recv":"2026-04-07T03:02:35.309945575Z","hd":{"ts_event":"2026-04-07T03:02:35.309927701Z","rtype":160,"publisher_id":101,"instrument_id":436},"action":"A","side":"B","price":"1.156790000","size":30,"channel_id":23,"order_id":"10998902992164709811","flags":0,"ts_in_delta":1102,"sequence":178986,"symbol":"FCEU SI 20260615 PS"}
{"ts_recv":"2026-04-07T03:02:35.309945575Z","hd":{"ts_event":"2026-04-07T03:02:35.309927701Z","rtype":160,"publisher_id":101,"instrument_id":436},"action":"C","side":"A","price":"1.156880000","size":30,"channel_id":23,"order_id":"1775530940210773189","flags":0,"ts_in_delta":1102,"sequence":178986,"symbol":"FCEU SI 20260615 PS"}
{"ts_recv":"2026-04-07T03:02:35.309945575Z","hd":{"ts_event":"2026-04-07T03:02:35.309927701Z","rtype":160,"publisher_id":101,"instrument_id":436},"action":"A","side":"A","price":"1.156890000","size":30,"channel_id":23,"order_id":"1775530955309934003","flags":128,"ts_in_delta":1102,"sequence":178986,"symbol":"FCEU SI 20260615 PS"}
{"ts_recv":"2026-04-07T03:02:35.921153778Z","hd":{"ts_event":"2026-04-07T03:02:35.921132879Z","rtype":160,"publisher_id":101,"instrument_id":436},"action":"C","side":"B","price":"1.156790000","size":30,"channel_id":23,"order_id":"10998902992164709811","flags":0,"ts_in_delta":1343,"sequence":179004,"symbol":"FCEU SI 20260615 PS"}
{"ts_recv":"2026-04-07T03:02:35.921153778Z","hd":{"ts_event":"2026-04-07T03:02:35.921132879Z","rtype":160,"publisher_id":101,"instrument_id":436},"action":"A","side":"B","price":"1.156800000","size":30,"channel_id":23,"order_id":"10998902992775914431","flags":0,"ts_in_delta":1343,"sequence":179004,"symbol":"FCEU SI 20260615 PS"}
{"ts_recv":"2026-04-07T03:02:35.921153778Z","hd":{"ts_event":"2026-04-07T03:02:35.921132879Z","rtype":160,"publisher_id":101,"instrument_id":436},"action":"C","side":"A","price":"1.156890000","size":30,"channel_id":23,"order_id":"1775530955309934003","flags":0,"ts_in_delta":1343,"sequence":179004,"symbol":"FCEU SI 20260615 PS"}
{"ts_recv":"2026-04-07T03:02:35.921153778Z","hd":{"ts_event":"2026-04-07T03:02:35.921132879Z","rtype":160,"publisher_id":101,"instrument_id":436},"action":"A","side":"A","price":"1.156900000","size":30,"channel_id":23,"order_id":"1775530955921138623","flags":128,"ts_in_delta":1343,"sequence":179004,"symbol":"FCEU SI 20260615 PS"}
{"ts_recv":"2026-04-07T03:02:35.921206591Z","hd":{"ts_event":"2026-04-07T03:02:35.921187849Z","rtype":160,"publisher_id":101,"instrument_id":436},"action":"C","side":"B","price":"1.156790000","size":30,"channel_id":23,"order_id":"10998902992164620261","flags":0,"ts_in_delta":1130,"sequence":179005,"symbol":"FCEU SI 20260615 PS"}
{"ts_recv":"2026-04-07T03:02:35.921206591Z","hd":{"ts_event":"2026-04-07T03:02:35.921187849Z","rtype":160,"publisher_id":101,"instrument_id":436},"action":"A","side":"B","price":"1.156810000","size":30,"channel_id":23,"order_id":"10998902992775970044","flags":0,"ts_in_delta":1130,"sequence":179005,"symbol":"FCEU SI 20260615 PS"}
{"ts_recv":"2026-04-07T03:02:35.921206591Z","hd":{"ts_event":"2026-04-07T03:02:35.921187849Z","rtype":160,"publisher_id":101,"instrument_id":436},"action":"C","side":"A","price":"1.156890000","size":30,"channel_id":23,"order_id":"1775530955309844453","flags":0,"ts_in_delta":1130,"sequence":179005,"symbol":"FCEU SI 20260615 PS"}
{"ts_recv":"2026-04-07T03:02:35.921206591Z","hd":{"ts_event":"2026-04-07T03:02:35.921187849Z","rtype":160,"publisher_id":101,"instrument_id":436},"action":"A","side":"A","price":"1.156910000","size":30,"channel_id":23,"order_id":"1775530955921194236","flags":128,"ts_in_delta":1130,"sequence":179005,"symbol":"FCEU SI 20260615 PS"}
{"ts_recv":"2026-04-07T03:02:35.921259412Z","hd":{"ts_event":"2026-04-07T03:02:35.921242161Z","rtype":160,"publisher_id":101,"instrument_id":436},"action":"C","side":"B","price":"1.156800000","size":30,"channel_id":23,"order_id":"10998902992775914431","flags":0,"ts_in_delta":945,"sequence":179006,"symbol":"FCEU SI 20260615 PS"}
{"ts_recv":"2026-04-07T03:02:35.921259412Z","hd":{"ts_event":"2026-04-07T03:02:35.921242161Z","rtype":160,"publisher_id":101,"instrument_id":436},"action":"A","side":"B","price":"1.156810000","size":30,"channel_id":23,"order_id":"10998902992776023906","flags":0,"ts_in_delta":945,"sequence":179006,"symbol":"FCEU SI 20260615 PS"}
{"ts_recv":"2026-04-07T03:02:35.921259412Z","hd":{"ts_event":"2026-04-07T03:02:35.921242161Z","rtype":160,"publisher_id":101,"instrument_id":436},"action":"C","side":"A","price":"1.156900000","size":30,"channel_id":23,"order_id":"1775530955921138623","flags":0,"ts_in_delta":945,"sequence":179006,"symbol":"FCEU SI 20260615 PS"}
{"ts_recv":"2026-04-07T03:02:35.921259412Z","hd":{"ts_event":"2026-04-07T03:02:35.921242161Z","rtype":160,"publisher_id":101,"instrument_id":436},"action":"A","side":"A","price":"1.156910000","size":30,"channel_id":23,"order_id":"1775530955921248098","flags":128,"ts_in_delta":945,"sequence":179006,"symbol":"FCEU SI 20260615 PS"}
{"ts_recv":"2026-04-07T03:02:35.964375465Z","hd":{"ts_event":"2026-04-07T03:02:35.964360347Z","rtype":160,"publisher_id":101,"instrument_id":436},"action":"A","side":"B","price":"1.156700000","size":20,"channel_id":23,"order_id":"10998902992819142637","flags":128,"ts_in_delta":1029,"sequence":179019,"symbol":"FCEU SI 20260615 PS"}
{"ts_recv":"2026-04-07T03:02:35.964398834Z","hd":{"ts_event":"2026-04-07T03:02:35.964385505Z","rtype":160,"publisher_id":101,"instrument_id":436},"action":"C","side":"B","price":"1.156600000","size":20,"channel_id":23,"order_id":"10998902925630015146","flags":128,"ts_in_delta":971,"sequence":179020,"symbol":"FCEU SI 20260615 PS"}
{"ts_recv":"2026-04-07T03:02:53.316115870Z","hd":{"ts_event":"2026-04-07T03:02:53.316090293Z","rtype":160,"publisher_id":101,"instrument_id":436},"action":"C","side":"B","price":"1.156810000","size":30,"channel_id":23,"order_id":"10998902992776023906","flags":0,"ts_in_delta":886,"sequence":179131,"symbol":"FCEU SI 20260615 PS"}
{"ts_recv":"2026-04-07T03:02:53.316115870Z","hd":{"ts_event":"2026-04-07T03:02:53.316090293Z","rtype":160,"publisher_id":101,"instrument_id":436},"action":"A","side":"B","price":"1.156820000","size":30,"channel_id":23,"order_id":"10998903010170872673","flags":0,"ts_in_delta":886,"sequence":179131,"symbol":"FCEU SI 20260615 PS"}
{"ts_recv":"2026-04-07T03:02:53.316115870Z","hd":{"ts_event":"2026-04-07T03:02:53.316090293Z","rtype":160,"publisher_id":101,"instrument_id":436},"action":"C","side":"A","price":"1.156910000","size":30,"channel_id":23,"order_id":"1775530955921248098","flags":0,"ts_in_delta":886,"sequence":179131,"symbol":"FCEU SI 20260615 PS"}
{"ts_recv":"2026-04-07T03:02:53.316115870Z","hd":{"ts_event":"2026-04-07T03:02:53.316090293Z","rtype":160,"publisher_id":101,"instrument_id":436},"action":"A","side":"A","price":"1.156920000","size":30,"channel_id":23,"order_id":"1775530973316096865","flags":128,"ts_in_delta":886,"sequence":179131,"symbol":"FCEU SI 20260615 PS"}
{"ts_recv":"2026-04-07T03:02:53.316215651Z","hd":{"ts_event":"2026-04-07T03:02:53.316193301Z","rtype":160,"publisher_id":101,"instrument_id":436},"action":"C","side":"B","price":"1.156810000","size":30,"channel_id":23,"order_id":"10998902992775970044","flags":0,"ts_in_delta":890,"sequence":179132,"symbol":"FCEU SI 20260615 PS"}
{"ts_recv":"2026-04-07T03:02:53.316215651Z","hd":{"ts_event":"2026-04-07T03:02:53.316193301Z","rtype":160,"publisher_id":101,"instrument_id":436},"action":"A","side":"B","price":"1.156830000","size":30,"channel_id":23,"order_id":"10998903010170975175","flags":0,"ts_in_delta":890,"sequence":179132,"symbol":"FCEU SI 20260615 PS"}
{"ts_recv":"2026-04-07T03:02:53.316215651Z","hd":{"ts_event":"2026-04-07T03:02:53.316193301Z","rtype":160,"publisher_id":101,"instrument_id":436},"action":"C","side":"A","price":"1.156910000","size":30,"channel_id":23,"order_id":"1775530955921194236","flags":0,"ts_in_delta":890,"sequence":179132,"symbol":"FCEU SI 20260615 PS"}
{"ts_recv":"2026-04-07T03:02:53.316215651Z","hd":{"ts_event":"2026-04-07T03:02:53.316193301Z","rtype":160,"publisher_id":101,"instrument_id":436},"action":"A","side":"A","price":"1.156930000","size":30,"channel_id":23,"order_id":"1775530973316199367","flags":128,"ts_in_delta":890,"sequence":179132,"symbol":"FCEU SI 20260615 PS"}
{"ts_recv":"2026-04-07T03:02:53.316282641Z","hd":{"ts_event":"2026-04-07T03:02:53.316262499Z","rtype":160,"publisher_id":101,"instrument_id":436},"action":"C","side":"B","price":"1.156820000","size":30,"channel_id":23,"order_id":"10998903010170872673","flags":0,"ts_in_delta":882,"sequence":179133,"symbol":"FCEU SI 20260615 PS"}
{"ts_recv":"2026-04-07T03:02:53.316282641Z","hd":{"ts_event":"2026-04-07T03:02:53.316262499Z","rtype":160,"publisher_id":101,"instrument_id":436},"action":"A","side":"B","price":"1.156830000","size":30,"channel_id":23,"order_id":"10998903010171044207","flags":0,"ts_in_delta":882,"sequence":179133,"symbol":"FCEU SI 20260615 PS"}
{"ts_recv":"2026-04-07T03:02:53.316282641Z","hd":{"ts_event":"2026-04-07T03:02:53.316262499Z","rtype":160,"publisher_id":101,"instrument_id":436},"action":"C","side":"A","price":"1.156920000","size":30,"channel_id":23,"order_id":"1775530973316096865","flags":0,"ts_in_delta":882,"sequence":179133,"symbol":"FCEU SI 20260615 PS"}
{"ts_recv":"2026-04-07T03:02:53.316282641Z","hd":{"ts_event":"2026-04-07T03:02:53.316262499Z","rtype":160,"publisher_id":101,"instrument_id":436},"action":"A","side":"A","price":"1.156930000","size":30,"channel_id":23,"order_id":"1775530973316268399","flags":128,"ts_in_delta":882,"sequence":179133,"symbol":"FCEU SI 20260615 PS"}
{"ts_recv":"2026-04-07T03:03:04.988657471Z","hd":{"ts_event":"2026-04-07T03:03:04.988632353Z","rtype":160,"publisher_id":101,"instrument_id":436},"action":"C","side":"B","price":"1.156830000","size":30,"channel_id":23,"order_id":"10998903010171044207","flags":0,"ts_in_delta":883,"sequence":179239,"symbol":"FCEU SI 20260615 PS"}
{"ts_recv":"2026-04-07T03:03:04.988657471Z","hd":{"ts_event":"2026-04-07T03:03:04.988632353Z","rtype":160,"publisher_id":101,"instrument_id":436},"action":"A","side":"B","price":"1.156820000","size":30,"channel_id":23,"order_id":"10998903021843416505","flags":0,"ts_in_delta":883,"sequence":179239,"symbol":"FCEU SI 20260615 PS"}
{"ts_recv":"2026-04-07T03:03:04.988657471Z","hd":{"ts_event":"2026-04-07T03:03:04.988632353Z","rtype":160,"publisher_id":101,"instrument_id":436},"action":"C","side":"A","price":"1.156930000","size":30,"channel_id":23,"order_id":"1775530973316268399","flags":0,"ts_in_delta":883,"sequence":179239,"symbol":"FCEU SI 20260615 PS"}
{"ts_recv":"2026-04-07T03:03:04.988657471Z","hd":{"ts_event":"2026-04-07T03:03:04.988632353Z","rtype":160,"publisher_id":101,"instrument_id":436},"action":"A","side":"A","price":"1.156920000","size":30,"channel_id":23,"order_id":"1775530984988640697","flags":128,"ts_in_delta":883,"sequence":179239,"symbol":"FCEU SI 20260615 PS"}
{"ts_recv":"2026-04-07T03:03:04.988744059Z","hd":{"ts_event":"2026-04-07T03:03:04.988725915Z","rtype":160,"publisher_id":101,"instrument_id":436},"action":"C","side":"B","price":"1.156820000","size":30,"channel_id":23,"order_id":"10998903021843416505","flags":0,"ts_in_delta":940,"sequence":179240,"symbol":"FCEU SI 20260615 PS"}
{"ts_recv":"2026-04-07T03:03:04.988744059Z","hd":{"ts_event":"2026-04-07T03:03:04.988725915Z","rtype":160,"publisher_id":101,"instrument_id":436},"action":"A","side":"B","price":"1.156810000","size":30,"channel_id":23,"order_id":"10998903021843507732","flags":0,"ts_in_delta":940,"sequence":179240,"symbol":"FCEU SI 20260615 PS"}
{"ts_recv":"2026-04-07T03:03:04.988744059Z","hd":{"ts_event":"2026-04-07T03:03:04.988725915Z","rtype":160,"publisher_id":101,"instrument_id":436},"action":"C","side":"A","price":"1.156920000","size":30,"channel_id":23,"order_id":"1775530984988640697","flags":0,"ts_in_delta":940,"sequence":179240,"symbol":"FCEU SI 20260615 PS"}
{"ts_recv":"2026-04-07T03:03:04.988744059Z","hd":{"ts_event":"2026-04-07T03:03:04.988725915Z","rtype":160,"publisher_id":101,"instrument_id":436},"action":"A","side":"A","price":"1.156910000","size":30,"channel_id":23,"order_id":"1775530984988731924","flags":128,"ts_in_delta":940,"sequence":179240,"symbol":"FCEU SI 20260615 PS"}
{"ts_recv":"2026-04-07T03:03:04.988799683Z","hd":{"ts_event":"2026-04-07T03:03:04.988784135Z","rtype":160,"publisher_id":101,"instrument_id":436},"action":"C","side":"B","price":"1.156810000","size":30,"channel_id":23,"order_id":"10998903021843507732","flags":0,"ts_in_delta":904,"sequence":179241,"symbol":"FCEU SI 20260615 PS"}
{"ts_recv":"2026-04-07T03:03:04.988799683Z","hd":{"ts_event":"2026-04-07T03:03:04.988784135Z","rtype":160,"publisher_id":101,"instrument_id":436},"action":"A","side":"B","price":"1.156820000","size":30,"channel_id":23,"order_id":"10998903021843566164","flags":0,"ts_in_delta":904,"sequence":179241,"symbol":"FCEU SI 20260615 PS"}
{"ts_recv":"2026-04-07T03:03:04.988799683Z","hd":{"ts_event":"2026-04-07T03:03:04.988784135Z","rtype":160,"publisher_id":101,"instrument_id":436},"action":"C","side":"A","price":"1.156910000","size":30,"channel_id":23,"order_id":"1775530984988731924","flags":0,"ts_in_delta":904,"sequence":179241,"symbol":"FCEU SI 20260615 PS"}
{"ts_recv":"2026-04-07T03:03:04.988799683Z","hd":{"ts_event":"2026-04-07T03:03:04.988784135Z","rtype":160,"publisher_id":101,"instrument_id":436},"action":"A","side":"A","price":"1.156920000","size":30,"channel_id":23,"order_id":"1775530984988790356","flags":128,"ts_in_delta":904,"sequence":179241,"symbol":"FCEU SI 20260615 PS"}
{"ts_recv":"2026-04-07T03:03:04.988811971Z","hd":{"ts_event":"2026-04-07T03:03:04.988785531Z","rtype":160,"publisher_id":101,"instrument_id":436},"action":"C","side":"B","price":"1.156830000","size":30,"channel_id":23,"order_id":"10998903010170975175","flags":0,"ts_in_delta":892,"sequence":179242,"symbol":"FCEU SI 20260615 PS"}
{"ts_recv":"2026-04-07T03:03:04.988811971Z","hd":{"ts_event":"2026-04-07T03:03:04.988785531Z","rtype":160,"publisher_id":101,"instrument_id":436},"action":"A","side":"B","price":"1.156810000","size":30,"channel_id":23,"order_id":"10998903021843572308","flags":0,"ts_in_delta":892,"sequence":179242,"symbol":"FCEU SI 20260615 PS"}
{"ts_recv":"2026-04-07T03:03:04.988811971Z","hd":{"ts_event":"2026-04-07T03:03:04.988785531Z","rtype":160,"publisher_id":101,"instrument_id":436},"action":"C","side":"A","price":"1.156930000","size":30,"channel_id":23,"order_id":"1775530973316199367","flags":0,"ts_in_delta":892,"sequence":179242,"symbol":"FCEU SI 20260615 PS"}
{"ts_recv":"2026-04-07T03:03:04.988811971Z","hd":{"ts_event":"2026-04-07T03:03:04.988785531Z","rtype":160,"publisher_id":101,"instrument_id":436},"action":"A","side":"A","price":"1.156910000","size":30,"channel_id":23,"order_id":"1775530984988796500","flags":128,"ts_in_delta":892,"sequence":179242,"symbol":"FCEU SI 20260615 PS"}
{"ts_recv":"2026-04-07T03:03:04.988872655Z","hd":{"ts_event":"2026-04-07T03:03:04.988855535Z","rtype":160,"publisher_id":101,"instrument_id":436},"action":"C","side":"B","price":"1.156820000","size":30,"channel_id":23,"order_id":"10998903021843566164","flags":0,"ts_in_delta":912,"sequence":179243,"symbol":"FCEU SI 20260615 PS"}
{"ts_recv":"2026-04-07T03:03:04.988872655Z","hd":{"ts_event":"2026-04-07T03:03:04.988855535Z","rtype":160,"publisher_id":101,"instrument_id":436},"action":"A","side":"B","price":"1.156810000","size":30,"channel_id":23,"order_id":"10998903021843638006","flags":0,"ts_in_delta":912,"sequence":179243,"symbol":"FCEU SI 20260615 PS"}
{"ts_recv":"2026-04-07T03:03:04.988872655Z","hd":{"ts_event":"2026-04-07T03:03:04.988855535Z","rtype":160,"publisher_id":101,"instrument_id":436},"action":"C","side":"A","price":"1.156920000","size":30,"channel_id":23,"order_id":"1775530984988790356","flags":0,"ts_in_delta":912,"sequence":179243,"symbol":"FCEU SI 20260615 PS"}
{"ts_recv":"2026-04-07T03:03:04.988872655Z","hd":{"ts_event":"2026-04-07T03:03:04.988855535Z","rtype":160,"publisher_id":101,"instrument_id":436},"action":"A","side":"A","price":"1.156910000","size":30,"channel_id":23,"order_id":"1775530984988862198","flags":128,"ts_in_delta":912,"sequence":179243,"symbol":"FCEU SI 20260615 PS"}
{"ts_recv":"2026-04-07T03:03:15.135246387Z","hd":{"ts_event":"2026-04-07T03:03:15.135224445Z","rtype":160,"publisher_id":101,"instrument_id":436},"action":"C","side":"B","price":"1.156810000","size":30,"channel_id":23,"order_id":"10998903021843638006","flags":0,"ts_in_delta":1003,"sequence":179335,"symbol":"FCEU SI 20260615 PS"}
{"ts_recv":"2026-04-07T03:03:15.135246387Z","hd":{"ts_event":"2026-04-07T03:03:15.135224445Z","rtype":160,"publisher_id":101,"instrument_id":436},"action":"A","side":"B","price":"1.156800000","size":30,"channel_id":23,"order_id":"10998903031990006458","flags":0,"ts_in_delta":1003,"sequence":179335,"symbol":"FCEU SI 20260615 PS"}
{"ts_recv":"2026-04-07T03:03:15.135246387Z","hd":{"ts_event":"2026-04-07T03:03:15.135224445Z","rtype":160,"publisher_id":101,"instrument_id":436},"action":"C","side":"A","price":"1.156910000","size":30,"channel_id":23,"order_id":"1775530984988862198","flags":0,"ts_in_delta":1003,"sequence":179335,"symbol":"FCEU SI 20260615 PS"}
{"ts_recv":"2026-04-07T03:03:15.135246387Z","hd":{"ts_event":"2026-04-07T03:03:15.135224445Z","rtype":160,"publisher_id":101,"instrument_id":436},"action":"A","side":"A","price":"1.156900000","size":30,"channel_id":23,"order_id":"1775530995135230650","flags":128,"ts_in_delta":1003,"sequence":179335,"symbol":"FCEU SI 20260615 PS"}
{"ts_recv":"2026-04-07T03:03:15.135310857Z","hd":{"ts_event":"2026-04-07T03:03:15.135287555Z","rtype":160,"publisher_id":101,"instrument_id":436},"action":"C","side":"B","price":"1.156810000","size":30,"channel_id":23,"order_id":"10998903021843572308","flags":0,"ts_in_delta":1113,"sequence":179336,"symbol":"FCEU SI 20260615 PS"}
{"ts_recv":"2026-04-07T03:03:15.135310857Z","hd":{"ts_event":"2026-04-07T03:03:15.135287555Z","rtype":160,"publisher_id":101,"instrument_id":436},"action":"A","side":"B","price":"1.156790000","size":30,"channel_id":23,"order_id":"10998903031990070121","flags":0,"ts_in_delta":1113,"sequence":179336,"symbol":"FCEU SI 20260615 PS"}
{"ts_recv":"2026-04-07T03:03:15.135310857Z","hd":{"ts_event":"2026-04-07T03:03:15.135287555Z","rtype":160,"publisher_id":101,"instrument_id":436},"action":"C","side":"A","price":"1.156910000","size":30,"channel_id":23,"order_id":"1775530984988796500","flags":0,"ts_in_delta":1113,"sequence":179336,"symbol":"FCEU SI 20260615 PS"}
{"ts_recv":"2026-04-07T03:03:15.135310857Z","hd":{"ts_event":"2026-04-07T03:03:15.135287555Z","rtype":160,"publisher_id":101,"instrument_id":436},"action":"A","side":"A","price":"1.156890000","size":30,"channel_id":23,"order_id":"1775530995135294313","flags":128,"ts_in_delta":1113,"sequence":179336,"symbol":"FCEU SI 20260615 PS"}
{"ts_recv":"2026-04-07T03:03:15.135375712Z","hd":{"ts_event":"2026-04-07T03:03:15.135357099Z","rtype":160,"publisher_id":101,"instrument_id":436},"action":"C","side":"B","price":"1.156800000","size":30,"channel_id":23,"order_id":"10998903031990006458","flags":0,"ts_in_delta":962,"sequence":179337,"symbol":"FCEU SI 20260615 PS"}
{"ts_recv":"2026-04-07T03:03:15.135375712Z","hd":{"ts_event":"2026-04-07T03:03:15.135357099Z","rtype":160,"publisher_id":101,"instrument_id":436},"action":"A","side":"B","price":"1.156790000","size":30,"channel_id":23,"order_id":"10998903031990138898","flags":0,"ts_in_delta":962,"sequence":179337,"symbol":"FCEU SI 20260615 PS"}
{"ts_recv":"2026-04-07T03:03:15.135375712Z","hd":{"ts_event":"2026-04-07T03:03:15.135357099Z","rtype":160,"publisher_id":101,"instrument_id":436},"action":"C","side":"A","price":"1.156900000","size":30,"channel_id":23,"order_id":"1775530995135230650","flags":0,"ts_in_delta":962,"sequence":179337,"symbol":"FCEU SI 20260615 PS"}
{"ts_recv":"2026-04-07T03:03:15.135375712Z","hd":{"ts_event":"2026-04-07T03:03:15.135357099Z","rtype":160,"publisher_id":101,"instrument_id":436},"action":"A","side":"A","price":"1.156890000","size":30,"channel_id":23,"order_id":"1775530995135363090","flags":128,"ts_in_delta":962,"sequence":179337,"symbol":"FCEU SI 20260615 PS"}
{"ts_recv":"2026-04-07T03:03:57.437530004Z","hd":{"ts_event":"2026-04-07T03:03:57.437506025Z","rtype":160,"publisher_id":101,"instrument_id":436},"action":"C","side":"B","price":"1.156790000","size":30,"channel_id":23,"order_id":"10998903031990070121","flags":0,"ts_in_delta":939,"sequence":179568,"symbol":"FCEU SI 20260615 PS"}
{"ts_recv":"2026-04-07T03:03:57.437530004Z","hd":{"ts_event":"2026-04-07T03:03:57.437506025Z","rtype":160,"publisher_id":101,"instrument_id":436},"action":"A","side":"B","price":"1.156770000","size":30,"channel_id":23,"order_id":"10998903074292288277","flags":0,"ts_in_delta":939,"sequence":179568,"symbol":"FCEU SI 20260615 PS"}
{"ts_recv":"2026-04-07T03:03:57.437530004Z","hd":{"ts_event":"2026-04-07T03:03:57.437506025Z","rtype":160,"publisher_id":101,"instrument_id":436},"action":"C","side":"A","price":"1.156890000","size":30,"channel_id":23,"order_id":"1775530995135294313","flags":0,"ts_in_delta":939,"sequence":179568,"symbol":"FCEU SI 20260615 PS"}
{"ts_recv":"2026-04-07T03:03:57.437530004Z","hd":{"ts_event":"2026-04-07T03:03:57.437506025Z","rtype":160,"publisher_id":101,"instrument_id":436},"action":"A","side":"A","price":"1.156870000","size":30,"channel_id":23,"order_id":"1775531037437512469","flags":128,"ts_in_delta":939,"sequence":179568,"symbol":"FCEU SI 20260615 PS"}
{"ts_recv":"2026-04-07T03:03:57.437597071Z","hd":{"ts_event":"2026-04-07T03:03:57.437576451Z","rtype":160,"publisher_id":101,"instrument_id":436},"action":"C","side":"B","price":"1.156790000","size":30,"channel_id":23,"order_id":"10998903031990138898","flags":0,"ts_in_delta":928,"sequence":179569,"symbol":"FCEU SI 20260615 PS"}
{"ts_recv":"2026-04-07T03:03:57.437597071Z","hd":{"ts_event":"2026-04-07T03:03:57.437576451Z","rtype":160,"publisher_id":101,"instrument_id":436},"action":"A","side":"B","price":"1.156780000","size":30,"channel_id":23,"order_id":"10998903074292358797","flags":0,"ts_in_delta":928,"sequence":179569,"symbol":"FCEU SI 20260615 PS"}
{"ts_recv":"2026-04-07T03:03:57.437597071Z","hd":{"ts_event":"2026-04-07T03:03:57.437576451Z","rtype":160,"publisher_id":101,"instrument_id":436},"action":"C","side":"A","price":"1.156890000","size":30,"channel_id":23,"order_id":"1775530995135363090","flags":0,"ts_in_delta":928,"sequence":179569,"symbol":"FCEU SI 20260615 PS"}
{"ts_recv":"2026-04-07T03:03:57.437597071Z","hd":{"ts_event":"2026-04-07T03:03:57.437576451Z","rtype":160,"publisher_id":101,"instrument_id":436},"action":"A","side":"A","price":"1.156880000","size":30,"channel_id":23,"order_id":"1775531037437582989","flags":128,"ts_in_delta":928,"sequence":179569,"symbol":"FCEU SI 20260615 PS"}
{"ts_recv":"2026-04-07T03:03:57.441990005Z","hd":{"ts_event":"2026-04-07T03:03:57.441971633Z","rtype":160,"publisher_id":101,"instrument_id":436},"action":"C","side":"B","price":"1.156780000","size":30,"channel_id":23,"order_id":"10998903074292358797","flags":0,"ts_in_delta":967,"sequence":179572,"symbol":"FCEU SI 20260615 PS"}
{"ts_recv":"2026-04-07T03:03:57.441990005Z","hd":{"ts_event":"2026-04-07T03:03:57.441971633Z","rtype":160,"publisher_id":101,"instrument_id":436},"action":"A","side":"B","price":"1.156770000","size":30,"channel_id":23,"order_id":"10998903074296753582","flags":0,"ts_in_delta":967,"sequence":179572,"symbol":"FCEU SI 20260615 PS"}
{"ts_recv":"2026-04-07T03:03:57.441990005Z","hd":{"ts_event":"2026-04-07T03:03:57.441971633Z","rtype":160,"publisher_id":101,"instrument_id":436},"action":"C","side":"A","price":"1.156880000","size":30,"channel_id":23,"order_id":"1775531037437582989","flags":0,"ts_in_delta":967,"sequence":179572,"symbol":"FCEU SI 20260615 PS"}
{"ts_recv":"2026-04-07T03:03:57.441990005Z","hd":{"ts_event":"2026-04-07T03:03:57.441971633Z","rtype":160,"publisher_id":101,"instrument_id":436},"action":"A","side":"A","price":"1.156870000","size":30,"channel_id":23,"order_id":"1775531037441977774","flags":128,"ts_in_delta":967,"sequence":179572,"symbol":"FCEU SI 20260615 PS"}
{"ts_recv":"2026-04-07T03:03:57.446740097Z","hd":{"ts_event":"2026-04-07T03:03:57.446721747Z","rtype":160,"publisher_id":101,"instrument_id":436},"action":"C","side":"B","price":"1.156770000","size":30,"channel_id":23,"order_id":"10998903074296753582","flags":0,"ts_in_delta":948,"sequence":179580,"symbol":"FCEU SI 20260615 PS"}
{"ts_recv":"2026-04-07T03:03:57.446740097Z","hd":{"ts_event":"2026-04-07T03:03:57.446721747Z","rtype":160,"publisher_id":101,"instrument_id":436},"action":"A","side":"B","price":"1.156760000","size":30,"channel_id":23,"order_id":"10998903074301503572","flags":0,"ts_in_delta":948,"sequence":179580,"symbol":"FCEU SI 20260615 PS"}
{"ts_recv":"2026-04-07T03:03:57.446740097Z","hd":{"ts_event":"2026-04-07T03:03:57.446721747Z","rtype":160,"publisher_id":101,"instrument_id":436},"action":"C","side":"A","price":"1.156870000","size":30,"channel_id":23,"order_id":"1775531037441977774","flags":0,"ts_in_delta":948,"sequence":179580,"symbol":"FCEU SI 20260615 PS"}
{"ts_recv":"2026-04-07T03:03:57.446740097Z","hd":{"ts_event":"2026-04-07T03:03:57.446721747Z","rtype":160,"publisher_id":101,"instrument_id":436},"action":"A","side":"A","price":"1.156860000","size":30,"channel_id":23,"order_id":"1775531037446727764","flags":128,"ts_in_delta":948,"sequence":179580,"symbol":"FCEU SI 20260615 PS"}
{"ts_recv":"2026-04-07T03:03:57.699283222Z","hd":{"ts_event":"2026-04-07T03:03:57.699254661Z","rtype":160,"publisher_id":101,"instrument_id":436},"action":"C","side":"B","price":"1.156770000","size":30,"channel_id":23,"order_id":"10998903074292288277","flags":0,"ts_in_delta":917,"sequence":179612,"symbol":"FCEU SI 20260615 PS"}
{"ts_recv":"2026-04-07T03:03:57.699283222Z","hd":{"ts_event":"2026-04-07T03:03:57.699254661Z","rtype":160,"publisher_id":101,"instrument_id":436},"action":"A","side":"B","price":"1.156750000","size":30,"channel_id":23,"order_id":"10998903074554041314","flags":0,"ts_in_delta":917,"sequence":179612,"symbol":"FCEU SI 20260615 PS"}
{"ts_recv":"2026-04-07T03:03:57.699283222Z","hd":{"ts_event":"2026-04-07T03:03:57.699254661Z","rtype":160,"publisher_id":101,"instrument_id":436},"action":"C","side":"A","price":"1.156870000","size":30,"channel_id":23,"order_id":"1775531037437512469","flags":0,"ts_in_delta":917,"sequence":179612,"symbol":"FCEU SI 20260615 PS"}
{"ts_recv":"2026-04-07T03:03:57.699283222Z","hd":{"ts_event":"2026-04-07T03:03:57.699254661Z","rtype":160,"publisher_id":101,"instrument_id":436},"action":"A","side":"A","price":"1.156850000","size":30,"channel_id":23,"order_id":"1775531037699265506","flags":128,"ts_in_delta":917,"sequence":179612,"symbol":"FCEU SI 20260615 PS"}
{"ts_recv":"2026-04-07T03:03:57.699349249Z","hd":{"ts_event":"2026-04-07T03:03:57.699328775Z","rtype":160,"publisher_id":101,"instrument_id":436},"action":"C","side":"B","price":"1.156760000","size":30,"channel_id":23,"order_id":"10998903074301503572","flags":0,"ts_in_delta":1612,"sequence":179613,"symbol":"FCEU SI 20260615 PS"}
{"ts_recv":"2026-04-07T03:03:57.699349249Z","hd":{"ts_event":"2026-04-07T03:03:57.699328775Z","rtype":160,"publisher_id":101,"instrument_id":436},"action":"A","side":"B","price":"1.156750000","size":30,"channel_id":23,"order_id":"10998903074554110664","flags":0,"ts_in_delta":1612,"sequence":179613,"symbol":"FCEU SI 20260615 PS"}
{"ts_recv":"2026-04-07T03:03:57.699349249Z","hd":{"ts_event":"2026-04-07T03:03:57.699328775Z","rtype":160,"publisher_id":101,"instrument_id":436},"action":"C","side":"A","price":"1.156860000","size":30,"channel_id":23,"order_id":"1775531037446727764","flags":0,"ts_in_delta":1612,"sequence":179613,"symbol":"FCEU SI 20260615 PS"}