{"ts_recv":"2026-04-07T02:50:00.596129683Z","hd":{"ts_event":"2026-04-07T02:50:00.596109537Z","rtype":160,"publisher_id":101,"instrument_id":436},"action":"A","side":"B","price":"1.156820000","size":30,"channel_id":23,"order_id":"10998902237450891556","flags":0,"ts_in_delta":957,"sequence":173060,"symbol":"FCEU SI 20260615 PS"}
{"ts_recv":"2026-04-07T02:50:00.596129683Z","hd":{"ts_event":"2026-04-07T02:50:00.596109537Z","rtype":160,"publisher_id":101,"instrument_id":436},"action":"C","side":"A","price":"1.156910000","size":30,"channel_id":23,"order_id":"1775530199454030330","flags":0,"ts_in_delta":957,"sequence":173060,"symbol":"FCEU SI 20260615 PS"}
{"ts_recv":"2026-04-07T02:50:00.596129683Z","hd":{"ts_event":"2026-04-07T02:50:00.596109537Z","rtype":160,"publisher_id":101,"instrument_id":436},"action":"A","side":"A","price":"1.156920000","size":30,"channel_id":23,"order_id":"1775530200596115748","flags":128,"ts_in_delta":957,"sequence":173060,"symbol":"FCEU SI 20260615 PS"}
{"ts_recv":"2026-04-07T02:50:04.794945103Z","hd":{"ts_event":"2026-04-07T02:50:04.794924371Z","rtype":160,"publisher_id":101,"instrument_id":436},"action":"C","side":"B","price":"1.156810000","size":30,"channel_id":23,"order_id":"10998902236308743373","flags":0,"ts_in_delta":1006,"sequence":173085,"symbol":"FCEU SI 20260615 PS"}
{"ts_recv":"2026-04-07T02:50:04.794945103Z","hd":{"ts_event":"2026-04-07T02:50:04.794924371Z","rtype":160,"publisher_id":101,"instrument_id":436},"action":"A","side":"B","price":"1.156830000","size":30,"channel_id":23,"order_id":"10998902241649706580","flags":0,"ts_in_delta":1006,"sequence":173085,"symbol":"FCEU SI 20260615 PS"}
{"ts_recv":"2026-04-07T02:50:04.794945103Z","hd":{"ts_event":"2026-04-07T02:50:04.794924371Z","rtype":160,"publisher_id":101,"instrument_id":436},"action":"C","side":"A","price":"1.156910000","size":30,"channel_id":23,"order_id":"1775530199453967565","flags":0,"ts_in_delta":1006,"sequence":173085,"symbol":"FCEU SI 20260615 PS"}
{"ts_recv":"2026-04-07T02:50:04.794945103Z","hd":{"ts_event":"2026-04-07T02:50:04.794924371Z","rtype":160,"publisher_id":101,"instrument_id":436},"action":"A","side":"A","price":"1.156930000","size":30,"channel_id":23,"order_id":"1775530204794930772","flags":128,"ts_in_delta":1006,"sequence":173085,"symbol":"FCEU SI 20260615 PS"}
{"ts_recv":"2026-04-07T02:50:04.795029226Z","hd":{"ts_event":"2026-04-07T02:50:04.795011539Z","rtype":160,"publisher_id":101,"instrument_id":436},"action":"C","side":"B","price":"1.156820000","size":30,"channel_id":23,"order_id":"10998902237450891556","flags":0,"ts_in_delta":932,"sequence":173087,"symbol":"FCEU SI 20260615 PS"}
{"ts_recv":"2026-04-07T02:50:04.795029226Z","hd":{"ts_event":"2026-04-07T02:50:04.795011539Z","rtype":160,"publisher_id":101,"instrument_id":436},"action":"A","side":"B","price":"1.156830000","size":30,"channel_id":23,"order_id":"10998902241649793590","flags":0,"ts_in_delta":932,"sequence":173087,"symbol":"FCEU SI 20260615 PS"}
{"ts_recv":"2026-04-07T02:50:04.795029226Z","hd":{"ts_event":"2026-04-07T02:50:04.795011539Z","rtype":160,"publisher_id":101,"instrument_id":436},"action":"C","side":"A","price":"1.156920000","size":30,"channel_id":23,"order_id":"1775530200596115748","flags":0,"ts_in_delta":932,"sequence":173087,"symbol":"FCEU SI 20260615 PS"}
{"ts_recv":"2026-04-07T02:50:04.795029226Z","hd":{"ts_event":"2026-04-07T02:50:04.795011539Z","rtype":160,"publisher_id":101,"instrument_id":436},"action":"A","side":"A","price":"1.156930000","size":30,"channel_id":23,"order_id":"1775530204795017782","flags":128,"ts_in_delta":932,"sequence":173087,"symbol":"FCEU SI 20260615 PS"}
{"ts_recv":"2026-04-07T02:50:17.558388235Z","hd":{"ts_event":"2026-04-07T02:50:17.558367929Z","rtype":160,"publisher_id":101,"instrument_id":436},"action":"C","side":"B","price":"1.156830000","size":30,"channel_id":23,"order_id":"10998902241649793590","flags":0,"ts_in_delta":886,"sequence":173189,"symbol":"FCEU SI 20260615 PS"}
{"ts_recv":"2026-04-07T02:50:17.558388235Z","hd":{"ts_event":"2026-04-07T02:50:17.558367929Z","rtype":160,"publisher_id":101,"instrument_id":436},"action":"A","side":"B","price":"1.156840000","size":30,"channel_id":23,"order_id":"10998902254413149806","flags":0,"ts_in_delta":886,"sequence":173189,"symbol":"FCEU SI 20260615 PS"}
{"ts_recv":"2026-04-07T02:50:17.558388235Z","hd":{"ts_event":"2026-04-07T02:50:17.558367929Z","rtype":160,"publisher_id":101,"instrument_id":436},"action":"C","side":"A","price":"1.156930000","size":30,"channel_id":23,"order_id":"1775530204795017782","flags":0,"ts_in_delta":886,"sequence":173189,"symbol":"FCEU SI 20260615 PS"}
{"ts_recv":"2026-04-07T02:50:17.558388235Z","hd":{"ts_event":"2026-04-07T02:50:17.558367929Z","rtype":160,"publisher_id":101,"instrument_id":436},"action":"A","side":"A","price":"1.156940000","size":30,"channel_id":23,"order_id":"1775530217558373998","flags":128,"ts_in_delta":886,"sequence":173189,"symbol":"FCEU SI 20260615 PS"}
{"ts_recv":"2026-04-07T02:50:20.755222344Z","hd":{"ts_event":"2026-04-07T02:50:20.755192761Z","rtype":160,"publisher_id":101,"instrument_id":436},"action":"C","side":"B","price":"1.156840000","size":30,"channel_id":23,"order_id":"10998902254413149806","flags":0,"ts_in_delta":1519,"sequence":173219,"symbol":"FCEU SI 20260615 PS"}
{"ts_recv":"2026-04-07T02:50:20.755222344Z","hd":{"ts_event":"2026-04-07T02:50:20.755192761Z","rtype":160,"publisher_id":101,"instrument_id":436},"action":"A","side":"B","price":"1.156830000","size":30,"channel_id":23,"order_id":"10998902257609981886","flags":0,"ts_in_delta":1519,"sequence":173219,"symbol":"FCEU SI 20260615 PS"}
{"ts_recv":"2026-04-07T02:50:20.755222344Z","hd":{"ts_event":"2026-04-07T02:50:20.755192761Z","rtype":160,"publisher_id":101,"instrument_id":436},"action":"C","side":"A","price":"1.156940000","size":30,"channel_id":23,"order_id":"1775530217558373998","flags":0,"ts_in_delta":1519,"sequence":173219,"symbol":"FCEU SI 20260615 PS"}
{"ts_recv":"2026-04-07T02:50:20.755222344Z","hd":{"ts_event":"2026-04-07T02:50:20.755192761Z","rtype":160,"publisher_id":101,"instrument_id":436},"action":"A","side":"A","price":"1.156930000","size":30,"channel_id":23,"order_id":"1775530220755206078","flags":128,"ts_in_delta":1519,"sequence":173219,"symbol":"FCEU SI 20260615 PS"}
{"ts_recv":"2026-04-07T02:50:22.280632053Z","hd":{"ts_event":"2026-04-07T02:50:22.280600689Z","rtype":160,"publisher_id":101,"instrument_id":436},"action":"C","side":"B","price":"1.156830000","size":30,"channel_id":23,"order_id":"10998902257609981886","flags":0,"ts_in_delta":1652,"sequence":173223,"symbol":"FCEU SI 20260615 PS"}
{"ts_recv":"2026-04-07T02:50:22.280632053Z","hd":{"ts_event":"2026-04-07T02:50:22.280600689Z","rtype":160,"publisher_id":101,"instrument_id":436},"action":"A","side":"B","price":"1.156840000","size":30,"channel_id":23,"order_id":"10998902259135389673","flags":0,"ts_in_delta":1652,"sequence":173223,"symbol":"FCEU SI 20260615 PS"}
{"ts_recv":"2026-04-07T02:50:22.280632053Z","hd":{"ts_event":"2026-04-07T02:50:22.280600689Z","rtype":160,"publisher_id":101,"instrument_id":436},"action":"C","side":"A","price":"1.156930000","size":30,"channel_id":23,"order_id":"1775530220755206078","flags":0,"ts_in_delta":1652,"sequence":173223,"symbol":"FCEU SI 20260615 PS"}
{"ts_recv":"2026-04-07T02:50:22.280632053Z","hd":{"ts_event":"2026-04-07T02:50:22.280600689Z","rtype":160,"publisher_id":101,"instrument_id":436},"action":"A","side":"A","price":"1.156940000","size":30,"channel_id":23,"order_id":"1775530222280613865","flags":128,"ts_in_delta":1652,"sequence":173223,"symbol":"FCEU SI 20260615 PS"}
{"ts_recv":"2026-04-07T02:50:30.351641943Z","hd":{"ts_event":"2026-04-07T02:50:30.351624775Z","rtype":160,"publisher_id":101,"instrument_id":436},"action":"C","side":"B","price":"1.156840000","size":30,"channel_id":23,"order_id":"10998902259135389673","flags":0,"ts_in_delta":901,"sequence":173255,"symbol":"FCEU SI 20260615 PS"}
{"ts_recv":"2026-04-07T02:50:30.351641943Z","hd":{"ts_event":"2026-04-07T02:50:30.351624775Z","rtype":160,"publisher_id":101,"instrument_id":436},"action":"A","side":"B","price":"1.156830000","size":30,"channel_id":23,"order_id":"10998902267206406884","flags":0,"ts_in_delta":901,"sequence":173255,"symbol":"FCEU SI 20260615 PS"}
{"ts_recv":"2026-04-07T02:50:30.351641943Z","hd":{"ts_event":"2026-04-07T02:50:30.351624775Z","rtype":160,"publisher_id":101,"instrument_id":436},"action":"C","side":"A","price":"1.156940000","size":30,"channel_id":23,"order_id":"1775530222280613865","flags":0,"ts_in_delta":901,"sequence":173255,"symbol":"FCEU SI 20260615 PS"}
{"ts_recv":"2026-04-07T02:50:30.351641943Z","hd":{"ts_event":"2026-04-07T02:50:30.351624775Z","rtype":160,"publisher_id":101,"instrument_id":436},"action":"A","side":"A","price":"1.156930000","size":30,"channel_id":23,"order_id":"1775530230351631076","flags":128,"ts_in_delta":901,"sequence":173255,"symbol":"FCEU SI 20260615 PS"}
{"ts_recv":"2026-04-07T02:50:40.590703245Z","hd":{"ts_event":"2026-04-07T02:50:40.590683329Z","rtype":160,"publisher_id":101,"instrument_id":436},"action":"C","side":"B","price":"1.156830000","size":30,"channel_id":23,"order_id":"10998902267206406884","flags":0,"ts_in_delta":957,"sequence":173306,"symbol":"FCEU SI 20260615 PS"}
{"ts_recv":"2026-04-07T02:50:40.590703245Z","hd":{"ts_event":"2026-04-07T02:50:40.590683329Z","rtype":160,"publisher_id":101,"instrument_id":436},"action":"A","side":"B","price":"1.156820000","size":30,"channel_id":23,"order_id":"10998902277445465214","flags":0,"ts_in_delta":957,"sequence":173306,"symbol":"FCEU SI 20260615 PS"}
{"ts_recv":"2026-04-07T02:50:40.590703245Z","hd":{"ts_event":"2026-04-07T02:50:40.590683329Z","rtype":160,"publisher_id":101,"instrument_id":436},"action":"C","side":"A","price":"1.156930000","size":30,"channel_id":23,"order_id":"1775530230351631076","flags":0,"ts_in_delta":957,"sequence":173306,"symbol":"FCEU SI 20260615 PS"}
{"ts_recv":"2026-04-07T02:50:40.590703245Z","hd":{"ts_event":"2026-04-07T02:50:40.590683329Z","rtype":160,"publisher_id":101,"instrument_id":436},"action":"A","side":"A","price":"1.156920000","size":30,"channel_id":23,"order_id":"1775530240590689406","flags":128,"ts_in_delta":957,"sequence":173306,"symbol":"FCEU SI 20260615 PS"}
{"ts_recv":"2026-04-07T02:50:40.590765335Z","hd":{"ts_event":"2026-04-07T02:50:40.590743341Z","rtype":160,"publisher_id":101,"instrument_id":436},"action":"C","side":"B","price":"1.156830000","size":30,"channel_id":23,"order_id":"10998902241649706580","flags":0,"ts_in_delta":926,"sequence":173307,"symbol":"FCEU SI 20260615 PS"}
{"ts_recv":"2026-04-07T02:50:40.590765335Z","hd":{"ts_event":"2026-04-07T02:50:40.590743341Z","rtype":160,"publisher_id":101,"instrument_id":436},"action":"A","side":"B","price":"1.156810000","size":30,"channel_id":23,"order_id":"10998902277445525805","flags":0,"ts_in_delta":926,"sequence":173307,"symbol":"FCEU SI 20260615 PS"}
{"ts_recv":"2026-04-07T02:50:40.590765335Z","hd":{"ts_event":"2026-04-07T02:50:40.590743341Z","rtype":160,"publisher_id":101,"instrument_id":436},"action":"C","side":"A","price":"1.156930000","size":30,"channel_id":23,"order_id":"1775530204794930772","flags":0,"ts_in_delta":926,"sequence":173307,"symbol":"FCEU SI 20260615 PS"}
{"ts_recv":"2026-04-07T02:50:40.590765335Z","hd":{"ts_event":"2026-04-07T02:50:40.590743341Z","rtype":160,"publisher_id":101,"instrument_id":436},"action":"A","side":"A","price":"1.156910000","size":30,"channel_id":23,"order_id":"1775530240590749997","flags":128,"ts_in_delta":926,"sequence":173307,"symbol":"FCEU SI 20260615 PS"}
{"ts_recv":"2026-04-07T02:50:40.590823032Z","hd":{"ts_event":"2026-04-07T02:50:40.590806307Z","rtype":160,"publisher_id":101,"instrument_id":436},"action":"C","side":"B","price":"1.156820000","size":30,"channel_id":23,"order_id":"10998902277445465214","flags":0,"ts_in_delta":745,"sequence":173308,"symbol":"FCEU SI 20260615 PS"}
{"ts_recv":"2026-04-07T02:50:40.590823032Z","hd":{"ts_event":"2026-04-07T02:50:40.590806307Z","rtype":160,"publisher_id":101,"instrument_id":436},"action":"A","side":"B","price":"1.156810000","size":30,"channel_id":23,"order_id":"10998902277445588117","flags":0,"ts_in_delta":745,"sequence":173308,"symbol":"FCEU SI 20260615 PS"}
{"ts_recv":"2026-04-07T02:50:40.590823032Z","hd":{"ts_event":"2026-04-07T02:50:40.590806307Z","rtype":160,"publisher_id":101,"instrument_id":436},"action":"C","side":"A","price":"1.156920000","size":30,"channel_id":23,"order_id":"1775530240590689406","flags":0,"ts_in_delta":745,"sequence":173308,"symbol":"FCEU SI 20260615 PS"}
{"ts_recv":"2026-04-07T02:50:40.590823032Z","hd":{"ts_event":"2026-04-07T02:50:40.590806307Z","rtype":160,"publisher_id":101,"instrument_id":436},"action":"A","side":"A","price":"1.156910000","size":30,"channel_id":23,"order_id":"1775530240590812309","flags":128,"ts_in_delta":745,"sequence":173308,"symbol":"FCEU SI 20260615 PS"}
{"ts_recv":"2026-04-07T02:50:40.658896268Z","hd":{"ts_event":"2026-04-07T02:50:40.658876029Z","rtype":160,"publisher_id":101,"instrument_id":436},"action":"C","side":"B","price":"1.156810000","size":30,"channel_id":23,"order_id":"10998902277445588117","flags":0,"ts_in_delta":896,"sequence":173328,"symbol":"FCEU SI 20260615 PS"}
{"ts_recv":"2026-04-07T02:50:40.658896268Z","hd":{"ts_event":"2026-04-07T02:50:40.658876029Z","rtype":160,"publisher_id":101,"instrument_id":436},"action":"A","side":"B","price":"1.156800000","size":30,"channel_id":23,"order_id":"10998902277513658310","flags":0,"ts_in_delta":896,"sequence":173328,"symbol":"FCEU SI 20260615 PS"}
{"ts_recv":"2026-04-07T02:50:40.658896268Z","hd":{"ts_event":"2026-04-07T02:50:40.658876029Z","rtype":160,"publisher_id":101,"instrument_id":436},"action":"C","side":"A","price":"1.156910000","size":30,"channel_id":23,"order_id":"1775530240590812309","flags":0,"ts_in_delta":896,"sequence":173328,"symbol":"FCEU SI 20260615 PS"}
{"ts_recv":"2026-04-07T02:50:40.658896268Z","hd":{"ts_event":"2026-04-07T02:50:40.658876029Z","rtype":160,"publisher_id":101,"instrument_id":436},"action":"A","side":"A","price":"1.156900000","size":30,"channel_id":23,"order_id":"1775530240658882502","flags":128,"ts_in_delta":896,"sequence":173328,"symbol":"FCEU SI 20260615 PS"}
{"ts_recv":"2026-04-07T02:50:40.658977649Z","hd":{"ts_event":"2026-04-07T02:50:40.658959173Z","rtype":160,"publisher_id":101,"instrument_id":436},"action":"C","side":"B","price":"1.156800000","size":30,"channel_id":23,"order_id":"10998902277513658310","flags":0,"ts_in_delta":959,"sequence":173329,"symbol":"FCEU SI 20260615 PS"}
{"ts_recv":"2026-04-07T02:50:40.658977649Z","hd":{"ts_event":"2026-04-07T02:50:40.658959173Z","rtype":160,"publisher_id":101,"instrument_id":436},"action":"A","side":"B","price":"1.156780000","size":30,"channel_id":23,"order_id":"10998902277513740655","flags":0,"ts_in_delta":959,"sequence":173329,"symbol":"FCEU SI 20260615 PS"}
{"ts_recv":"2026-04-07T02:50:40.658977649Z","hd":{"ts_event":"2026-04-07T02:50:40.658959173Z","rtype":160,"publisher_id":101,"instrument_id":436},"action":"C","side":"A","price":"1.156900000","size":30,"channel_id":23,"order_id":"1775530240658882502","flags":0,"ts_in_delta":959,"sequence":173329,"symbol":"FCEU SI 20260615 PS"}
{"ts_recv":"2026-04-07T02:50:40.658977649Z","hd":{"ts_event":"2026-04-07T02:50:40.658959173Z","rtype":160,"publisher_id":101,"instrument_id":436},"action":"A","side":"A","price":"1.156880000","size":30,"channel_id":23,"order_id":"1775530240658964847","flags":128,"ts_in_delta":959,"sequence":173329,"symbol":"FCEU SI 20260615 PS"}
{"ts_recv":"2026-04-07T02:50:40.659025908Z","hd":{"ts_event":"2026-04-07T02:50:40.659009131Z","rtype":160,"publisher_id":101,"instrument_id":436},"action":"C","side":"B","price":"1.156810000","size":30,"channel_id":23,"order_id":"10998902277445525805","flags":0,"ts_in_delta":808,"sequence":173330,"symbol":"FCEU SI 20260615 PS"}
{"ts_recv":"2026-04-07T02:50:40.659025908Z","hd":{"ts_event":"2026-04-07T02:50:40.659009131Z","rtype":160,"publisher_id":101,"instrument_id":436},"action":"A","side":"B","price":"1.156790000","size":30,"channel_id":23,"order_id":"10998902277513791045","flags":0,"ts_in_delta":808,"sequence":173330,"symbol":"FCEU SI 20260615 PS"}
{"ts_recv":"2026-04-07T02:50:40.659025908Z","hd":{"ts_event":"2026-04-07T02:50:40.659009131Z","rtype":160,"publisher_id":101,"instrument_id":436},"action":"C","side":"A","price":"1.156910000","size":30,"channel_id":23,"order_id":"1775530240590749997","flags":0,"ts_in_delta":808,"sequence":173330,"symbol":"FCEU SI 20260615 PS"}
{"ts_recv":"2026-04-07T02:50:40.659025908Z","hd":{"ts_event":"2026-04-07T02:50:40.659009131Z","rtype":160,"publisher_id":101,"instrument_id":436},"action":"A","side":"A","price":"1.156890000","size":30,"channel_id":23,"order_id":"1775530240659015237","flags":128,"ts_in_delta":808,"sequence":173330,"symbol":"FCEU SI 20260615 PS"}
{"ts_recv":"2026-04-07T02:50:40.659035707Z","hd":{"ts_event":"2026-04-07T02:50:40.659017241Z","rtype":160,"publisher_id":101,"instrument_id":436},"action":"C","side":"B","price":"1.156780000","size":30,"channel_id":23,"order_id":"10998902277513740655","flags":0,"ts_in_delta":759,"sequence":173331,"symbol":"FCEU SI 20260615 PS"}
{"ts_recv":"2026-04-07T02:50:40.659035707Z","hd":{"ts_event":"2026-04-07T02:50:40.659017241Z","rtype":160,"publisher_id":101,"instrument_id":436},"action":"A","side":"B","price":"1.156800000","size":30,"channel_id":23,"order_id":"10998902277513798722","flags":0,"ts_in_delta":759,"sequence":173331,"symbol":"FCEU SI 20260615 PS"}
{"ts_recv":"2026-04-07T02:50:40.659035707Z","hd":{"ts_event":"2026-04-07T02:50:40.659017241Z","rtype":160,"publisher_id":101,"instrument_id":436},"action":"C","side":"A","price":"1.156880000","size":30,"channel_id":23,"order_id":"1775530240658964847","flags":0,"ts_in_delta":759,"sequence":173331,"symbol":"FCEU SI 20260615 PS"}
{"ts_recv":"2026-04-07T02:50:40.659035707Z","hd":{"ts_event":"2026-04-07T02:50:40.659017241Z","rtype":160,"publisher_id":101,"instrument_id":436},"action":"A","side":"A","price":"1.156900000","size":30,"channel_id":23,"order_id":"1775530240659022914","flags":128,"ts_in_delta":759,"sequence":173331,"symbol":"FCEU SI 20260615 PS"}
{"ts_recv":"2026-04-07T02:50:40.659090140Z","hd":{"ts_event":"2026-04-07T02:50:40.659073115Z","rtype":160,"publisher_id":101,"instrument_id":436},"action":"C","side":"B","price":"1.156800000","size":30,"channel_id":23,"order_id":"10998902277513798722","flags":0,"ts_in_delta":739,"sequence":173332,"symbol":"FCEU SI 20260615 PS"}
{"ts_recv":"2026-04-07T02:50:40.659090140Z","hd":{"ts_event":"2026-04-07T02:50:40.659073115Z","rtype":160,"publisher_id":101,"instrument_id":436},"action":"A","side":"B","price":"1.156790000","size":30,"channel_id":23,"order_id":"10998902277513854903","flags":0,"ts_in_delta":739,"sequence":173332,"symbol":"FCEU SI 20260615 PS"}
{"ts_recv":"2026-04-07T02:50:40.659090140Z","hd":{"ts_event":"2026-04-07T02:50:40.659073115Z","rtype":160,"publisher_id":101,"instrument_id":436},"action":"C","side":"A","price":"1.156900000","size":30,"channel_id":23,"order_id":"1775530240659022914","flags":0,"ts_in_delta":739,"sequence":173332,"symbol":"FCEU SI 20260615 PS"}
{"ts_recv":"2026-04-07T02:50:40.659090140Z","hd":{"ts_event":"2026-04-07T02:50:40.659073115Z","rtype":160,"publisher_id":101,"instrument_id":436},"action":"A","side":"A","price":"1.156890000","size":30,"channel_id":23,"order_id":"1775530240659079095","flags":128,"ts_in_delta":739,"sequence":173332,"symbol":"FCEU SI 20260615 PS"}
{"ts_recv":"2026-04-07T02:51:01.191582150Z","hd":{"ts_event":"2026-04-07T02:51:01.191542223Z","rtype":160,"publisher_id":101,"instrument_id":436},"action":"C","side":"B","price":"1.156790000","size":30,"channel_id":23,"order_id":"10998902277513854903","flags":0,"ts_in_delta":1583,"sequence":173424,"symbol":"FCEU SI 20260615 PS"}
{"ts_recv":"2026-04-07T02:51:01.191582150Z","hd":{"ts_event":"2026-04-07T02:51:01.191542223Z","rtype":160,"publisher_id":101,"instrument_id":436},"action":"A","side":"B","price":"1.156780000","size":30,"channel_id":23,"order_id":"10998902298046331628","flags":0,"ts_in_delta":1583,"sequence":173424,"symbol":"FCEU SI 20260615 PS"}
{"ts_recv":"2026-04-07T02:51:01.191582150Z","hd":{"ts_event":"2026-04-07T02:51:01.191542223Z","rtype":160,"publisher_id":101,"instrument_id":436},"action":"C","side":"A","price":"1.156890000","size":30,"channel_id":23,"order_id":"1775530240659079095","flags":0,"ts_in_delta":1583,"sequence":173424,"symbol":"FCEU SI 20260615 PS"}
{"ts_recv":"2026-04-07T02:51:01.191582150Z","hd":{"ts_event":"2026-04-07T02:51:01.191542223Z","rtype":160,"publisher_id":101,"instrument_id":436},"action":"A","side":"A","price":"1.156880000","size":30,"channel_id":23,"order_id":"1775530261191555820","flags":128,"ts_in_delta":1583,"sequence":173424,"symbol":"FCEU SI 20260615 PS"}
{"ts_recv":"2026-04-07T02:51:01.191680204Z","hd":{"ts_event":"2026-04-07T02:51:01.191657321Z","rtype":160,"publisher_id":101,"instrument_id":436},"action":"C","side":"B","price":"1.156790000","size":30,"channel_id":23,"order_id":"10998902277513791045","flags":0,"ts_in_delta":1049,"sequence":173425,"symbol":"FCEU SI 20260615 PS"}
{"ts_recv":"2026-04-07T02:51:01.191680204Z","hd":{"ts_event":"2026-04-07T02:51:01.191657321Z","rtype":160,"publisher_id":101,"instrument_id":436},"action":"A","side":"B","price":"1.156770000","size":30,"channel_id":23,"order_id":"10998902298046439386","flags":0,"ts_in_delta":1049,"sequence":173425,"symbol":"FCEU SI 20260615 PS"}
{"ts_recv":"2026-04-07T02:51:01.191680204Z","hd":{"ts_event":"2026-04-07T02:51:01.191657321Z","rtype":160,"publisher_id":101,"instrument_id":436},"action":"C","side":"A","price":"1.156890000","size":30,"channel_id":23,"order_id":"1775530240659015237","flags":0,"ts_in_delta":1049,"sequence":173425,"symbol":"FCEU SI 20260615 PS"}
{"ts_recv":"2026-04-07T02:51:01.191680204Z","hd":{"ts_event":"2026-04-07T02:51:01.191657321Z","rtype":160,"publisher_id":101,"instrument_id":436},"action":"A","side":"A","price":"1.156870000","size":30,"channel_id":23,"order_id":"1775530261191663578","flags":128,"ts_in_delta":1049,"sequence":173425,"symbol":"FCEU SI 20260615 PS"}
{"ts_recv":"2026-04-07T02:51:01.191693205Z","hd":{"ts_event":"2026-04-07T02:51:01.191661297Z","rtype":160,"publisher_id":101,"instrument_id":436},"action":"C","side":"B","price":"1.156780000","size":30,"channel_id":23,"order_id":"10998902298046331628","flags":0,"ts_in_delta":934,"sequence":173426,"symbol":"FCEU SI 20260615 PS"}
{"ts_recv":"2026-04-07T02:51:01.191693205Z","hd":{"ts_event":"2026-04-07T02:51:01.191661297Z","rtype":160,"publisher_id":101,"instrument_id":436},"action":"A","side":"B","price":"1.156770000","size":30,"channel_id":23,"order_id":"10998902298046451606","flags":0,"ts_in_delta":934,"sequence":173426,"symbol":"FCEU SI 20260615 PS"}
{"ts_recv":"2026-04-07T02:51:01.191693205Z","hd":{"ts_event":"2026-04-07T02:51:01.191661297Z","rtype":160,"publisher_id":101,"instrument_id":436},"action":"C","side":"A","price":"1.156880000","size":30,"channel_id":23,"order_id":"1775530261191555820","flags":0,"ts_in_delta":934,"sequence":173426,"symbol":"FCEU SI 20260615 PS"}
{"ts_recv":"2026-04-07T02:51:01.191693205Z","hd":{"ts_event":"2026-04-07T02:51:01.191661297Z","rtype":160,"publisher_id":101,"instrument_id":436},"action":"A","side":"A","price":"1.156870000","size":30,"channel_id":23,"order_id":"1775530261191675798","flags":128,"ts_in_delta":934,"sequence":173426,"symbol":"FCEU SI 20260615 PS"}
{"ts_recv":"2026-04-07T02:51:04.337730959Z","hd":{"ts_event":"2026-04-07T02:51:04.337703545Z","rtype":160,"publisher_id":101,"instrument_id":436},"action":"C","side":"B","price":"1.156770000","size":30,"channel_id":23,"order_id":"10998902298046451606","flags":0,"ts_in_delta":1529,"sequence":173473,"symbol":"FCEU SI 20260615 PS"}
{"ts_recv":"2026-04-07T02:51:04.337730959Z","hd":{"ts_event":"2026-04-07T02:51:04.337703545Z","rtype":160,"publisher_id":101,"instrument_id":436},"action":"A","side":"B","price":"1.156760000","size":30,"channel_id":23,"order_id":"10998902301192487985","flags":0,"ts_in_delta":1529,"sequence":173473,"symbol":"FCEU SI 20260615 PS"}
{"ts_recv":"2026-04-07T02:51:04.337730959Z","hd":{"ts_event":"2026-04-07T02:51:04.337703545Z","rtype":160,"publisher_id":101,"instrument_id":436},"action":"C","side":"A","price":"1.156870000","size":30,"channel_id":23,"order_id":"1775530261191675798","flags":0,"ts_in_delta":1529,"sequence":173473,"symbol":"FCEU SI 20260615 PS"}
{"ts_recv":"2026-04-07T02:51:04.337730959Z","hd":{"ts_event":"2026-04-07T02:51:04.337703545Z","rtype":160,"publisher_id":101,"instrument_id":436},"action":"A","side":"A","price":"1.156860000","size":30,"channel_id":23,"order_id":"1775530264337712177","flags":128,"ts_in_delta":1529,"sequence":173473,"symbol":"FCEU SI 20260615 PS"}
{"ts_recv":"2026-04-07T02:51:04.337794547Z","hd":{"ts_event":"2026-04-07T02:51:04.337775143Z","rtype":160,"publisher_id":101,"instrument_id":436},"action":"C","side":"B","price":"1.156770000","size":30,"channel_id":23,"order_id":"10998902298046439386","flags":0,"ts_in_delta":981,"sequence":173474,"symbol":"FCEU SI 20260615 PS"}
{"ts_recv":"2026-04-07T02:51:04.337794547Z","hd":{"ts_event":"2026-04-07T02:51:04.337775143Z","rtype":160,"publisher_id":101,"instrument_id":436},"action":"A","side":"B","price":"1.156750000","size":30,"channel_id":23,"order_id":"10998902301192557345","flags":0,"ts_in_delta":981,"sequence":173474,"symbol":"FCEU SI 20260615 PS"}
{"ts_recv":"2026-04-07T02:51:04.337794547Z","hd":{"ts_event":"2026-04-07T02:51:04.337775143Z","rtype":160,"publisher_id":101,"instrument_id":436},"action":"C","side":"A","price":"1.156870000","size":30,"channel_id":23,"order_id":"1775530261191663578","flags":0,"ts_in_delta":981,"sequence":173474,"symbol":"FCEU SI 20260615 PS"}
{"ts_recv":"2026-04-07T02:51:04.337794547Z","hd":{"ts_event":"2026-04-07T02:51:04.337775143Z","rtype":160,"publisher_id":101,"instrument_id":436},"action":"A","side":"A","price":"1.156850000","size":30,"channel_id":23,"order_id":"1775530264337781537","flags":128,"ts_in_delta":981,"sequence":173474,"symbol":"FCEU SI 20260615 PS"}
{"ts_recv":"2026-04-07T02:51:04.337857642Z","hd":{"ts_event":"2026-04-07T02:51:04.337839079Z","rtype":160,"publisher_id":101,"instrument_id":436},"action":"C","side":"B","price":"1.156760000","size":30,"channel_id":23,"order_id":"10998902301192487985","flags":0,"ts_in_delta":919,"sequence":173475,"symbol":"FCEU SI 20260615 PS"}
{"ts_recv":"2026-04-07T02:51:04.337857642Z","hd":{"ts_event":"2026-04-07T02:51:04.337839079Z","rtype":160,"publisher_id":101,"instrument_id":436},"action":"A","side":"B","price":"1.156750000","size":30,"channel_id":23,"order_id":"10998902301192620888","flags":0,"ts_in_delta":919,"sequence":173475,"symbol":"FCEU SI 20260615 PS"}
{"ts_recv":"2026-04-07T02:51:04.337857642Z","hd":{"ts_event":"2026-04-07T02:51:04.337839079Z","rtype":160,"publisher_id":101,"instrument_id":436},"action":"C","side":"A","price":"1.156860000","size":30,"channel_id":23,"order_id":"1775530264337712177","flags":0,"ts_in_delta":919,"sequence":173475,"symbol":"FCEU SI 20260615 PS"}
{"ts_recv":"2026-04-07T02:51:04.337857642Z","hd":{"ts_event":"2026-04-07T02:51:04.337839079Z","rtype":160,"publisher_id":101,"instrument_id":436},"action":"A","side":"A","price":"1.156850000","size":30,"channel_id":23,"order_id":"1775530264337845080","flags":128,"ts_in_delta":919,"sequence":173475,"symbol":"FCEU SI 20260615 PS"}
{"ts_recv":"2026-04-07T02:51:04.388189658Z","hd":{"ts_event":"2026-04-07T02:51:04.388166273Z","rtype":160,"publisher_id":101,"instrument_id":436},"action":"A","side":"A","price":"1.157000000","size":20,"channel_id":23,"order_id":"1775530264388177366","flags":128,"ts_in_delta":1273,"sequence":173477,"symbol":"FCEU SI 20260615 PS"}
{"ts_recv":"2026-04-07T02:51:04.388209856Z","hd":{"ts_event":"2026-04-07T02:51:04.388194887Z","rtype":160,"publisher_id":101,"instrument_id":436},"action":"C","side":"A","price":"1.157100000","size":20,"channel_id":23,"order_id":"1775530151889442796","flags":128,"ts_in_delta":1013,"sequence":173478,"symbol":"FCEU SI 20260615 PS"}
{"ts_recv":"2026-04-07T02:51:09.082332955Z","hd":{"ts_event":"2026-04-07T02:51:09.082312309Z","rtype":160,"publisher_id":101,"instrument_id":436},"action":"C","side":"B","price":"1.156750000","size":30,"channel_id":23,"order_id":"10998902301192620888","flags":0,"ts_in_delta":979,"sequence":173573,"symbol":"FCEU SI 20260615 PS"}
{"ts_recv":"2026-04-07T02:51:09.082332955Z","hd":{"ts_event":"2026-04-07T02:51:09.082312309Z","rtype":160,"publisher_id":101,"instrument_id":436},"action":"A","side":"B","price":"1.156760000","size":30,"channel_id":23,"order_id":"10998902305937094462","flags":0,"ts_in_delta":979,"sequence":173573,"symbol":"FCEU SI 20260615 PS"}
{"ts_recv":"2026-04-07T02:51:09.082332955Z","hd":{"ts_event":"2026-04-07T02:51:09.082312309Z","rtype":160,"publisher_id":101,"instrument_id":436},"action":"C","side":"A","price":"1.156850000","size":30,"channel_id":23,"order_id":"1775530264337845080","flags":0,"ts_in_delta":979,"sequence":173573,"symbol":"FCEU SI 20260615 PS"}
{"ts_recv":"2026-04-07T02:51:09.082332955Z","hd":{"ts_event":"2026-04-07T02:51:09.082312309Z","rtype":160,"publisher_id":101,"instrument_id":436},"action":"A","side":"A","price":"1.156860000","size":30,"channel_id":23,"order_id":"1775530269082318654","flags":128,"ts_in_delta":979,"sequence":173573,"symbol":"FCEU SI 20260615 PS"}
{"ts_recv":"2026-04-07T02:51:09.082418468Z","hd":{"ts_event":"2026-04-07T02:51:09.082397385Z","rtype":160,"publisher_id":101,"instrument_id":436},"action":"C","side":"B","price":"1.156760000","size":30,"channel_id":23,"order_id":"10998902305937094462","flags":0,"ts_in_delta":974,"sequence":173574,"symbol":"FCEU SI 20260615 PS"}
{"ts_recv":"2026-04-07T02:51:09.082418468Z","hd":{"ts_event":"2026-04-07T02:51:09.082397385Z","rtype":160,"publisher_id":101,"instrument_id":436},"action":"A","side":"B","price":"1.156770000","size":30,"channel_id":23,"order_id":"10998902305937179135","flags":0,"ts_in_delta":974,"sequence":173574,"symbol":"FCEU SI 20260615 PS"}
{"ts_recv":"2026-04-07T02:51:09.082418468Z","hd":{"ts_event":"2026-04-07T02:51:09.082397385Z","rtype":160,"publisher_id":101,"instrument_id":436},"action":"C","side":"A","price":"1.156860000","size":30,"channel_id":23,"order_id":"1775530269082318654","flags":0,"ts_in_delta":974,"sequence":173574,"symbol":"FCEU SI 20260615 PS"}
{"ts_recv":"2026-04-07T02:51:09.082418468Z","hd":{"ts_event":"2026-04-07T02:51:09.082397385Z","rtype":160,"publisher_id":101,"instrument_id":436},"action":"A","side":"A","price":"1.156870000","size":30,"channel_id":23,"order_id":"1775530269082403327","flags":128,"ts_in_delta":974,"sequence":173574,"symbol":"FCEU SI 20260615 PS"}
{"ts_recv":"2026-04-07T02:51:09.082474045Z","hd":{"ts_event":"2026-04-07T02:51:09.082455389Z","rtype":160,"publisher_id":101,"instrument_id":436},"action":"C","side":"B","price":"1.156750000","size":30,"channel_id":23,"order_id":"10998902301192557345","flags":0,"ts_in_delta":962,"sequence":173576,"symbol":"FCEU SI 20260615 PS"}
{"ts_recv":"2026-04-07T02:51:09.082474045Z","hd":{"ts_event":"2026-04-07T02:51:09.082455389Z","rtype":160,"publisher_id":101,"instrument_id":436},"action":"A","side":"B","price":"1.156770000","size":30,"channel_id":23,"order_id":"10998902305937237266","flags":0,"ts_in_delta":962,"sequence":173576,"symbol":"FCEU SI 20260615 PS"}
{"ts_recv":"2026-04-07T02:51:09.082474045Z","hd":{"ts_event":"2026-04-07T02:51:09.082455389Z","rtype":160,"publisher_id":101,"instrument_id":436},"action":"C","side":"A","price":"1.156850000","size":30,"channel_id":23,"order_id":"1775530264337781537","flags":0,"ts_in_delta":962,"sequence":173576,"symbol":"FCEU SI 20260615 PS"}
{"ts_recv":"2026-04-07T02:51:09.082474045Z","hd":{"ts_event":"2026-04-07T02:51:09.082455389Z","rtype":160,"publisher_id":101,"instrument_id":436},"action":"A","side":"A","price":"1.156870000","size":30,"channel_id":23,"order_id":"1775530269082461458","flags":128,"ts_in_delta":962,"sequence":173576,"symbol":"FCEU SI 20260615 PS"}
{"ts_recv":"2026-04-07T02:51:09.082483967Z","hd":{"ts_event":"2026-04-07T02:51:09.082458287Z","rtype":160,"publisher_id":101,"instrument_id":436},"action":"C","side":"B","price":"1.156770000","size":30,"channel_id":23,"order_id":"10998902305937179135","flags":0,"ts_in_delta":1034,"sequence":173577,"symbol":"FCEU SI 20260615 PS"}
{"ts_recv":"2026-04-07T02:51:09.082483967Z","hd":{"ts_event":"2026-04-07T02:51:09.082458287Z","rtype":160,"publisher_id":101,"instrument_id":436},"action":"A","side":"B","price":"1.156760000","size":30,"channel_id":23,"order_id":"10998902305937246522","flags":0,"ts_in_delta":1034,"sequence":173577,"symbol":"FCEU SI 20260615 PS"}
{"ts_recv":"2026-04-07T02:51:09.082483967Z","hd":{"ts_event":"2026-04-07T02:51:09.082458287Z","rtype":160,"publisher_id":101,"instrument_id":436},"action":"C","side":"A","price":"1.156870000","size":30,"channel_id":23,"order_id":"1775530269082403327","flags":0,"ts_in_delta":1034,"sequence":173577,"symbol":"FCEU SI 20260615 PS"}
{"ts_recv":"2026-04-07T02:51:09.082483967Z","hd":{"ts_event":"2026-04-07T02:51:09.082458287Z","rtype":160,"publisher_id":101,"instrument_id":436},"action":"A","side":"A","price":"1.156860000","size":30,"channel_id":23,"order_id":"1775530269082470714","flags":128,"ts_in_delta":1034,"sequence":173577,"symbol":"FCEU SI 20260615 PS"}
{"ts_recv":"2026-04-07T02:51:09.082536872Z","hd":{"ts_event":"2026-04-07T02:51:09.082520937Z","rtype":160,"publisher_id":101,"instrument_id":436},"action":"C","side":"B","price":"1.156760000","size":30,"channel_id":23,"order_id":"10998902305937246522","flags":0,"ts_in_delta":963,"sequence":173578,"symbol":"FCEU SI 20260615 PS"}
{"ts_recv":"2026-04-07T02:51:09.082536872Z","hd":{"ts_event":"2026-04-07T02:51:09.082520937Z","rtype":160,"publisher_id":101,"instrument_id":436},"action":"A","side":"B","price":"1.156770000","size":30,"channel_id":23,"order_id":"10998902305937302668","flags":0,"ts_in_delta":963,"sequence":173578,"symbol":"FCEU SI 20260615 PS"}
{"ts_recv":"2026-04-07T02:51:09.082536872Z","hd":{"ts_event":"2026-04-07T02:51:09.082520937Z","rtype":160,"publisher_id":101,"instrument_id":436},"action":"C","side":"A","price":"1.156860000","size":30,"channel_id":23,"order_id":"1775530269082470714","flags":0,"ts_in_delta":963,"sequence":173578,"symbol":"FCEU SI 20260615 PS"}
{"ts_recv":"2026-04-07T02:51:09.082536872Z","hd":{"ts_event":"2026-04-07T02:51:09.082520937Z","rtype":160,"publisher_id":101,"instrument_id":436},"action":"A","side":"A","price":"1.156870000","size":30,"channel_id":23,"order_id":"1775530269082526860","flags":128,"ts_in_delta":963,"sequence":173578,"symbol":"FCEU SI 20260615 PS"}
{"ts_recv":"2026-04-07T02:51:09.087105971Z","hd":{"ts_event":"2026-04-07T02:51:09.087086649Z","rtype":160,"publisher_id":101,"instrument_id":436},"action":"C","side":"B","price":"1.156770000","size":30,"channel_id":23,"order_id":"10998902305937302668","flags":0,"ts_in_delta":1035,"sequence":173583,"symbol":"FCEU SI 20260615 PS"}
{"ts_recv":"2026-04-07T02:51:09.087105971Z","hd":{"ts_event":"2026-04-07T02:51:09.087086649Z","rtype":160,"publisher_id":101,"instrument_id":436},"action":"A","side":"B","price":"1.156780000","size":30,"channel_id":23,"order_id":"10998902305941868386","flags":0,"ts_in_delta":1035,"sequence":173583,"symbol":"FCEU SI 20260615 PS"}
{"ts_recv":"2026-04-07T02:51:09.087105971Z","hd":{"ts_event":"2026-04-07T02:51:09.087086649Z","rtype":160,"publisher_id":101,"instrument_id":436},"action":"C","side":"A","price":"1.156870000","size":30,"channel_id":23,"order_id":"1775530269082526860","flags":0,"ts_in_delta":1035,"sequence":173583,"symbol":"FCEU SI 20260615 PS"}
{"ts_recv":"2026-04-07T02:51:09.087105971Z","hd":{"ts_event":"2026-04-07T02:51:09.087086649Z","rtype":160,"publisher_id":101,"instrument_id":436},"action":"A","side":"A","price":"1.156880000","size":30,"channel_id":23,"order_id":"1775530269087092578","flags":128,"ts_in_delta":1035,"sequence":173583,"symbol":"FCEU SI 20260615 PS"}
{"ts_recv":"2026-04-07T02:51:24.694124421Z","hd":{"ts_event":"2026-04-07T02:51:24.694101435Z","rtype":160,"publisher_id":101,"instrument_id":436},"action":"C","side":"B","price":"1.156770000","size":30,"channel_id":23,"order_id":"10998902305937237266","flags":0,"ts_in_delta":1111,"sequence":173661,"symbol":"FCEU SI 20260615 PS"}
{"ts_recv":"2026-04-07T02:51:24.694124421Z","hd":{"ts_event":"2026-04-07T02:51:24.694101435Z","rtype":160,"publisher_id":101,"instrument_id":436},"action":"A","side":"B","price":"1.156790000","size":30,"channel_id":23,"order_id":"10998902321548883338","flags":0,"ts_in_delta":1111,"sequence":173661,"symbol":"FCEU SI 20260615 PS"}
{"ts_recv":"2026-04-07T02:51:24.694124421Z","hd":{"ts_event":"2026-04-07T02:51:24.694101435Z","rtype":160,"publisher_id":101,"instrument_id":436},"action":"C","side":"A","price":"1.156870000","size":30,"channel_id":23,"order_id":"1775530269082461458","flags":0,"ts_in_delta":1111,"sequence":173661,"symbol":"FCEU SI 20260615 PS"}
{"ts_recv":"2026-04-07T02:51:24.694124421Z","hd":{"ts_event":"2026-04-07T02:51:24.694101435Z","rtype":160,"publisher_id":101,"instrument_id":436},"action":"A","side":"A","price":"1.156890000","size":30,"channel_id":23,"order_id":"1775530284694107530","flags":128,"ts_in_delta":1111,"sequence":173661,"symbol":"FCEU SI 20260615 PS"}
{"ts_recv":"2026-04-07T02:51:24.694208882Z","hd":{"ts_event":"2026-04-07T02:51:24.694189327Z","rtype":160,"publisher_id":101,"instrument_id":436},"action":"C","side":"B","price":"1.156780000","size":30,"channel_id":23,"order_id":"10998902305941868386","flags":0,"ts_in_delta":1062,"sequence":173662,"symbol":"FCEU SI 20260615 PS"}
{"ts_recv":"2026-04-07T02:51:24.694208882Z","hd":{"ts_event":"2026-04-07T02:51:24.694189327Z","rtype":160,"publisher_id":101,"instrument_id":436},"action":"A","side":"B","price":"1.156790000","size":30,"channel_id":23,"order_id":"10998902321548971451","flags":0,"ts_in_delta":1062,"sequence":173662,"symbol":"FCEU SI 20260615 PS"}
{"ts_recv":"2026-04-07T02:51:24.694208882Z","hd":{"ts_event":"2026-04-07T02:51:24.694189327Z","rtype":160,"publisher_id":101,"instrument_id":436},"action":"C","side":"A","price":"1.156880000","size":30,"channel_id":23,"order_id":"1775530269087092578","flags":0,"ts_in_delta":1062,"sequence":173662,"symbol":"FCEU SI 20260615 PS"}
{"ts_recv":"2026-04-07T02:51:24.694208882Z","hd":{"ts_event":"2026-04-07T02:51:24.694189327Z","rtype":160,"publisher_id":101,"instrument_id":436},"action":"A","side":"A","price":"1.156890000","size":30,"channel_id":23,"order_id":"1775530284694195643","flags":128,"ts_in_delta":1062,"sequence":173662,"symbol":"FCEU SI 20260615 PS"}
{"ts_recv":"2026-04-07T02:51:50.215859840Z","hd":{"ts_event":"2026-04-07T02:51:50.215835725Z","rtype":160,"publisher_id":101,"instrument_id":436},"action":"C","side":"B","price":"1.156790000","size":30,"channel_id":23,"order_id":"10998902321548883338","flags":0,"ts_in_delta":1259,"sequence":173818,"symbol":"FCEU SI 20260615 PS"}
{"ts_recv":"2026-04-07T02:51:50.215859840Z","hd":{"ts_event":"2026-04-07T02:51:50.215835725Z","rtype":160,"publisher_id":101,"instrument_id":436},"action":"A","side":"B","price":"1.156770000","size":30,"channel_id":23,"order_id":"10998902347070618241","flags":0,"ts_in_delta":1259,"sequence":173818,"symbol":"FCEU SI 20260615 PS"}
{"ts_recv":"2026-04-07T02:51:50.215859840Z","hd":{"ts_event":"2026-04-07T02:51:50.215835725Z","rtype":160,"publisher_id":101,"instrument_id":436},"action":"C","side":"A","price":"1.156890000","size":30,"channel_id":23,"order_id":"1775530284694107530","flags":0,"ts_in_delta":1259,"sequence":173818,"symbol":"FCEU SI 20260615 PS"}
{"ts_recv":"2026-04-07T02:51:50.215859840Z","hd":{"ts_event":"2026-04-07T02:51:50.215835725Z","rtype":160,"publisher_id":101,"instrument_id":436},"action":"A","side":"A","price":"1.156870000","size":30,"channel_id":23,"order_id":"1775530310215842433","flags":128,"ts_in_delta":1259,"sequence":173818,"symbol":"FCEU SI 20260615 PS"}
{"ts_recv":"2026-04-07T02:51:50.215964552Z","hd":{"ts_event":"2026-04-07T02:51:50.215945895Z","rtype":160,"publisher_id":101,"instrument_id":436},"action":"C","side":"B","price":"1.156790000","size":30,"channel_id":23,"order_id":"10998902321548971451","flags":0,"ts_in_delta":1109,"sequence":173819,"symbol":"FCEU SI 20260615 PS"}
{"ts_recv":"2026-04-07T02:51:50.215964552Z","hd":{"ts_event":"2026-04-07T02:51:50.215945895Z","rtype":160,"publisher_id":101,"instrument_id":436},"action":"A","side":"B","price":"1.156780000","size":30,"channel_id":23,"order_id":"10998902347070729669","flags":0,"ts_in_delta":1109,"sequence":173819,"symbol":"FCEU SI 20260615 PS"}
{"ts_recv":"2026-04-07T02:51:50.215964552Z","hd":{"ts_event":"2026-04-07T02:51:50.215945895Z","rtype":160,"publisher_id":101,"instrument_id":436},"action":"C","side":"A","price":"1.156890000","size":30,"channel_id":23,"order_id":"1775530284694195643","flags":0,"ts_in_delta":1109,"sequence":173819,"symbol":"FCEU SI 20260615 PS"}
{"ts_recv":"2026-04-07T02:51:50.215964552Z","hd":{"ts_event":"2026-04-07T02:51:50.215945895Z","rtype":160,"publisher_id":101,"instrument_id":436},"action":"A","side":"A","price":"1.156880000","size":30,"channel_id":23,"order_id":"1775530310215953861","flags":128,"ts_in_delta":1109,"sequence":173819,"symbol":"FCEU SI 20260615 PS"}
{"ts_recv":"2026-04-07T02:51:50.221248334Z","hd":{"ts_event":"2026-04-07T02:51:50.221232733Z","rtype":160,"publisher_id":101,"instrument_id":436},"action":"C","side":"B","price":"1.156780000","size":30,"channel_id":23,"order_id":"10998902347070729669","flags":0,"ts_in_delta":988,"sequence":173827,"symbol":"FCEU SI 20260615 PS"}
{"ts_recv":"2026-04-07T02:51:50.221248334Z","hd":{"ts_event":"2026-04-07T02:51:50.221232733Z","rtype":160,"publisher_id":101,"instrument_id":436},"action":"A","side":"B","price":"1.156770000","size":30,"channel_id":23,"order_id":"10998902347076014436","flags":0,"ts_in_delta":988,"sequence":173827,"symbol":"FCEU SI 20260615 PS"}
{"ts_recv":"2026-04-07T02:51:50.221248334Z","hd":{"ts_event":"2026-04-07T02:51:50.221232733Z","rtype":160,"publisher_id":101,"instrument_id":436},"action":"C","side":"A","price":"1.156880000","size":30,"channel_id":23,"order_id":"1775530310215953861","flags":0,"ts_in_delta":988,"sequence":173827,"symbol":"FCEU SI 20260615 PS"}
{"ts_recv":"2026-04-07T02:51:50.221248334Z","hd":{"ts_event":"2026-04-07T02:51:50.221232733Z","rtype":160,"publisher_id":101,"instrument_id":436},"action":"A","side":"A","price":"1.156870000","size":30,"channel_id":23,"order_id":"1775530310221238628","flags":128,"ts_in_delta":988,"sequence":173827,"symbol":"FCEU SI 20260615 PS"}
{"ts_recv":"2026-04-07T02:51:50.226091971Z","hd":{"ts_event":"2026-04-07T02:51:50.226073753Z","rtype":160,"publisher_id":101,"instrument_id":436},"action":"C","side":"B","price":"1.156770000","size":30,"channel_id":23,"order_id":"10998902347076014436","flags":0,"ts_in_delta":780,"sequence":173840,"symbol":"FCEU SI 20260615 PS"}
{"ts_recv":"2026-04-07T02:51:50.226091971Z","hd":{"ts_event":"2026-04-07T02:51:50.226073753Z","rtype":160,"publisher_id":101,"instrument_id":436},"action":"A","side":"B","price":"1.156760000","size":30,"channel_id":23,"order_id":"10998902347080855864","flags":0,"ts_in_delta":780,"sequence":173840,"symbol":"FCEU SI 20260615 PS"}
{"ts_recv":"2026-04-07T02:51:50.226091971Z","hd":{"ts_event":"2026-04-07T02:51:50.226073753Z","rtype":160,"publisher_id":101,"instrument_id":436},"action":"C","side":"A","price":"1.156870000","size":30,"channel_id":23,"order_id":"1775530310221238628","flags":0,"ts_in_delta":780,"sequence":173840,"symbol":"FCEU SI 20260615 PS"}
{"ts_recv":"2026-04-07T02:51:50.226091971Z","hd":{"ts_event":"2026-04-07T02:51:50.226073753Z","rtype":160,"publisher_id":101,"instrument_id":436},"action":"A","side":"A","price":"1.156860000","size":30,"channel_id":23,"order_id":"1775530310226080056","flags":128,"ts_in_delta":780,"sequence":173840,"symbol":"FCEU SI 20260615 PS"}
{"ts_recv":"2026-04-07T02:51:50.226147910Z","hd":{"ts_event":"2026-04-07T02:51:50.226129857Z","rtype":160,"publisher_id":101,"instrument_id":436},"action":"C","side":"B","price":"1.156770000","size":30,"channel_id":23,"order_id":"10998902347070618241","flags":0,"ts_in_delta":812,"sequence":173841,"symbol":"FCEU SI 20260615 PS"}
{"ts_recv":"2026-04-07T02:51:50.226147910Z","hd":{"ts_event":"2026-04-07T02:51:50.226129857Z","rtype":160,"publisher_id":101,"instrument_id":436},"action":"A","side":"B","price":"1.156750000","size":30,"channel_id":23,"order_id":"10998902347080911796","flags":0,"ts_in_delta":812,"sequence":173841,"symbol":"FCEU SI 20260615 PS"}
{"ts_recv":"2026-04-07T02:51:50.226147910Z","hd":{"ts_event":"2026-04-07T02:51:50.226129857Z","rtype":160,"publisher_id":101,"instrument_id":436},"action":"C","side":"A","price":"1.156870000","size":30,"channel_id":23,"order_id":"1775530310215842433","flags":0,"ts_in_delta":812,"sequence":173841,"symbol":"FCEU SI 20260615 PS"}
{"ts_recv":"2026-04-07T02:51:50.226147910Z","hd":{"ts_event":"2026-04-07T02:51:50.226129857Z","rtype":160,"publisher_id":101,"instrument_id":436},"action":"A","side":"A","price":"1.156850000","size":30,"channel_id":23,"order_id":"1775530310226135988","flags":128,"ts_in_delta":812,"sequence":173841,"symbol":"FCEU SI 20260615 PS"}
{"ts_recv":"2026-04-07T02:51:50.226159277Z","hd":{"ts_event":"2026-04-07T02:51:50.226136769Z","rtype":160,"publisher_id":101,"instrument_id":436},"action":"C","side":"B","price":"1.156760000","size":30,"channel_id":23,"order_id":"10998902347080855864","flags":0,"ts_in_delta":767,"sequence":173842,"symbol":"FCEU SI 20260615 PS"}
{"ts_recv":"2026-04-07T02:51:50.226159277Z","hd":{"ts_event":"2026-04-07T02:51:50.226136769Z","rtype":160,"publisher_id":101,"instrument_id":436},"action":"A","side":"B","price":"1.156750000","size":30,"channel_id":23,"order_id":"10998902347080920813","flags":0,"ts_in_delta":767,"sequence":173842,"symbol":"FCEU SI 20260615 PS"}
{"ts_recv":"2026-04-07T02:51:50.226159277Z","hd":{"ts_event":"2026-04-07T02:51:50.226136769Z","rtype":160,"publisher_id":101,"instrument_id":436},"action":"C","side":"A","price":"1.156860000","size":30,"channel_id":23,"order_id":"1775530310226080056","flags":0,"ts_in_delta":767,"sequence":173842,"symbol":"FCEU SI 20260615 PS"}
{"ts_recv":"2026-04-07T02:51:50.226159277Z","hd":{"ts_event":"2026-04-07T02:51:50.226136769Z","rtype":160,"publisher_id":101,"instrument_id":436},"action":"A","side":"A","price":"1.156850000","size":30,"channel_id":23,"order_id":"1775530310226145005","flags":128,"ts_in_delta":767,"sequence":173842,"symbol":"FCEU SI 20260615 PS"}
{"ts_recv":"2026-04-07T02:52:00.233711086Z","hd":{"ts_event":"2026-04-07T02:52:00.233678297Z","rtype":160,"publisher_id":101,"instrument_id":436},"action":"C","side":"B","price":"1.156750000","size":30,"channel_id":23,"order_id":"10998902347080920813","flags":0,"ts_in_delta":1371,"sequence":173927,"symbol":"FCEU SI 20260615 PS"}
{"ts_recv":"2026-04-07T02:52:00.233711086Z","hd":{"ts_event":"2026-04-07T02:52:00.233678297Z","rtype":160,"publisher_id":101,"instrument_id":436},"action":"A","side":"B","price":"1.156740000","size":30,"channel_id":23,"order_id":"10998902357088467917","flags":0,"ts_in_delta":1371,"sequence":173927,"symbol":"FCEU SI 20260615 PS"}
{"ts_recv":"2026-04-07T02:52:00.233711086Z","hd":{"ts_event":"2026-04-07T02:52:00.233678297Z","rtype":160,"publisher_id":101,"instrument_id":436},"action":"C","side":"A","price":"1.156850000","size":30,"channel_id":23,"order_id":"1775530310226145005","flags":0,"ts_in_delta":1371,"sequence":173927,"symbol":"FCEU SI 20260615 PS"}
{"ts_recv":"2026-04-07T02:52:00.233711086Z","hd":{"ts_event":"2026-04-07T02:52:00.233678297Z","rtype":160,"publisher_id":101,"instrument_id":436},"action":"A","side":"A","price":"1.156840000","size":30,"channel_id":23,"order_id":"1775530320233692109","flags":128,"ts_in_delta":1371,"sequence":173927,"symbol":"FCEU SI 20260615 PS"}
{"ts_recv":"2026-04-07T02:52:01.609080737Z","hd":{"ts_event":"2026-04-07T02:52:01.609052969Z","rtype":160,"publisher_id":101,"instrument_id":436},"action":"C","side":"B","price":"1.156750000","size":30,"channel_id":23,"order_id":"10998902347080911796","flags":0,"ts_in_delta":1640,"sequence":173933,"symbol":"FCEU SI 20260615 PS"}
{"ts_recv":"2026-04-07T02:52:01.609080737Z","hd":{"ts_event":"2026-04-07T02:52:01.609052969Z","rtype":160,"publisher_id":101,"instrument_id":436},"action":"A","side":"B","price":"1.156730000","size":30,"channel_id":23,"order_id":"10998902358463837618","flags":0,"ts_in_delta":1640,"sequence":173933,"symbol":"FCEU SI 20260615 PS"}
{"ts_recv":"2026-04-07T02:52:01.609080737Z","hd":{"ts_event":"2026-04-07T02:52:01.609052969Z","rtype":160,"publisher_id":101,"instrument_id":436},"action":"C","side":"A","price":"1.156850000","size":30,"channel_id":23,"order_id":"1775530310226135988","flags":0,"ts_in_delta":1640,"sequence":173933,"symbol":"FCEU SI 20260615 PS"}
{"ts_recv":"2026-04-07T02:52:01.609080737Z","hd":{"ts_event":"2026-04-07T02:52:01.609052969Z","rtype":160,"publisher_id":101,"instrument_id":436},"action":"A","side":"A","price":"1.156830000","size":30,"channel_id":23,"order_id":"1775530321609061810","flags":128,"ts_in_delta":1640,"sequence":173933,"symbol":"FCEU SI 20260615 PS"}
{"ts_recv":"2026-04-07T02:52:01.609172032Z","hd":{"ts_event":"2026-04-07T02:52:01.609155479Z","rtype":160,"publisher_id":101,"instrument_id":436},"action":"C","side":"B","price":"1.156740000","size":30,"channel_id":23,"order_id":"10998902357088467917","flags":0,"ts_in_delta":953,"sequence":173934,"symbol":"FCEU SI 20260615 PS"}
{"ts_recv":"2026-04-07T02:52:01.609172032Z","hd":{"ts_event":"2026-04-07T02:52:01.609155479Z","rtype":160,"publisher_id":101,"instrument_id":436},"action":"A","side":"B","price":"1.156730000","size":30,"channel_id":23,"order_id":"10998902358463937467","flags":0,"ts_in_delta":953,"sequence":173934,"symbol":"FCEU SI 20260615 PS"}
{"ts_recv":"2026-04-07T02:52:01.609172032Z","hd":{"ts_event":"2026-04-07T02:52:01.609155479Z","rtype":160,"publisher_id":101,"instrument_id":436},"action":"C","side":"A","price":"1.156840000","size":30,"channel_id":23,"order_id":"1775530320233692109","flags":0,"ts_in_delta":953,"sequence":173934,"symbol":"FCEU SI 20260615 PS"}
{"ts_recv":"2026-04-07T02:52:01.609172032Z","hd":{"ts_event":"2026-04-07T02:52:01.609155479Z","rtype":160,"publisher_id":101,"instrument_id":436},"action":"A","side":"A","price":"1.156830000","size":30,"channel_id":23,"order_id":"1775530321609161659","flags":128,"ts_in_delta":953,"sequence":173934,"symbol":"FCEU SI 20260615 PS"}
{"ts_recv":"2026-04-07T02:52:03.717169588Z","hd":{"ts_event":"2026-04-07T02:52:03.717137089Z","rtype":160,"publisher_id":101,"instrument_id":436},"action":"C","side":"B","price":"1.156730000","size":30,"channel_id":23,"order_id":"10998902358463937467","flags":0,"ts_in_delta":1501,"sequence":173955,"symbol":"FCEU SI 20260615 PS"}
{"ts_recv":"2026-04-07T02:52:03.717169588Z","hd":{"ts_event":"2026-04-07T02:52:03.717137089Z","rtype":160,"publisher_id":101,"instrument_id":436},"action":"A","side":"B","price":"1.156740000","size":30,"channel_id":23,"order_id":"10998902360571926481","flags":0,"ts_in_delta":1501,"sequence":173955,"symbol":"FCEU SI 20260615 PS"}
{"ts_recv":"2026-04-07T02:52:03.717169588Z","hd":{"ts_event":"2026-04-07T02:52:03.717137089Z","rtype":160,"publisher_id":101,"instrument_id":436},"action":"C","side":"A","price":"1.156830000","size":30,"channel_id":23,"order_id":"1775530321609161659","flags":0,"ts_in_delta":1501,"sequence":173955,"symbol":"FCEU SI 20260615 PS"}
{"ts_recv":"2026-04-07T02:52:03.717169588Z","hd":{"ts_event":"2026-04-07T02:52:03.717137089Z","rtype":160,"publisher_id":101,"instrument_id":436},"action":"A","side":"A","price":"1.156840000","size":30,"channel_id":23,"order_id":"1775530323717150673","flags":128,"ts_in_delta":1501,"sequence":173955,"symbol":"FCEU SI 20260615 PS"}
{"ts_recv":"2026-04-07T02:52:03.717733796Z","hd":{"ts_event":"2026-04-07T02:52:03.717714623Z","rtype":160,"publisher_id":101,"instrument_id":436},"action":"C","side":"B","price":"1.156730000","size":30,"channel_id":23,"order_id":"10998902358463837618","flags":0,"ts_in_delta":957,"sequence":173956,"symbol":"FCEU SI 20260615 PS"}
{"ts_recv":"2026-04-07T02:52:03.717733796Z","hd":{"ts_event":"2026-04-07T02:52:03.717714623Z","rtype":160,"publisher_id":101,"instrument_id":436},"action":"A","side":"B","price":"1.156750000","size":30,"channel_id":23,"order_id":"10998902360572497022","flags":0,"ts_in_delta":957,"sequence":173956,"symbol":"FCEU SI 20260615 PS"}
{"ts_recv":"2026-04-07T02:52:03.717733796Z","hd":{"ts_event":"2026-04-07T02:52:03.717714623Z","rtype":160,"publisher_id":101,"instrument_id":436},"action":"C","side":"A","price":"1.156830000","size":30,"channel_id":23,"order_id":"1775530321609061810","flags":0,"ts_in_delta":957,"sequence":173956,"symbol":"FCEU SI 20260615 PS"}
{"ts_recv":"2026-04-07T02:52:03.717733796Z","hd":{"ts_event":"2026-04-07T02:52:03.717714623Z","rtype":160,"publisher_id":101,"instrument_id":436},"action":"A","side":"A","price":"1.156850000","size":30,"channel_id":23,"order_id":"1775530323717721214","flags":128,"ts_in_delta":957,"sequence":173956,"symbol":"FCEU SI 20260615 PS"}
{"ts_recv":"2026-04-07T02:52:03.717801208Z","hd":{"ts_event":"2026-04-07T02:52:03.717780429Z","rtype":160,"publisher_id":101,"instrument_id":436},"action":"C","side":"B","price":"1.156740000","size":30,"channel_id":23,"order_id":"10998902360571926481","flags":0,"ts_in_delta":966,"sequence":173957,"symbol":"FCEU SI 20260615 PS"}
{"ts_recv":"2026-04-07T02:52:03.717801208Z","hd":{"ts_event":"2026-04-07T02:52:03.717780429Z","rtype":160,"publisher_id":101,"instrument_id":436},"action":"A","side":"B","price":"1.156750000","size":30,"channel_id":23,"order_id":"10998902360572562456","flags":0,"ts_in_delta":966,"sequence":173957,"symbol":"FCEU SI 20260615 PS"}
{"ts_recv":"2026-04-07T02:52:03.717801208Z","hd":{"ts_event":"2026-04-07T02:52:03.717780429Z","rtype":160,"publisher_id":101,"instrument_id":436},"action":"C","side":"A","price":"1.156840000","size":30,"channel_id":23,"order_id":"1775530323717150673","flags":0,"ts_in_delta":966,"sequence":173957,"symbol":"FCEU SI 20260615 PS"}
{"ts_recv":"2026-04-07T02:52:03.717801208Z","hd":{"ts_event":"2026-04-07T02:52:03.717780429Z","rtype":160,"publisher_id":101,"instrument_id":436},"action":"A","side":"A","price":"1.156850000","size":30,"channel_id":23,"order_id":"1775530323717786648","flags":128,"ts_in_delta":966,"sequence":173957,"symbol":"FCEU SI 20260615 PS"}
{"ts_recv":"2026-04-07T02:52:06.786466957Z","hd":{"ts_event":"2026-04-07T02:52:06.786446215Z","rtype":160,"publisher_id":101,"instrument_id":436},"action":"C","side":"B","price":"1.156750000","size":30,"channel_id":23,"order_id":"10998902360572562456","flags":0,"ts_in_delta":1126,"sequence":173972,"symbol":"FCEU SI 20260615 PS"}
{"ts_recv":"2026-04-07T02:52:06.786466957Z","hd":{"ts_event":"2026-04-07T02:52:06.786446215Z","rtype":160,"publisher_id":101,"instrument_id":436},"action":"A","side":"B","price":"1.156740000","size":30,"channel_id":23,"order_id":"10998902363641228458","flags":0,"ts_in_delta":1126,"sequence":173972,"symbol":"FCEU SI 20260615 PS"}
{"ts_recv":"2026-04-07T02:52:06.786466957Z","hd":{"ts_event":"2026-04-07T02:52:06.786446215Z","rtype":160,"publisher_id":101,"instrument_id":436},"action":"C","side":"A","price":"1.156850000","size":30,"channel_id":23,"order_id":"1775530323717786648","flags":0,"ts_in_delta":1126,"sequence":173972,"symbol":"FCEU SI 20260615 PS"}
{"ts_recv":"2026-04-07T02:52:06.786466957Z","hd":{"ts_event":"2026-04-07T02:52:06.786446215Z","rtype":160,"publisher_id":101,"instrument_id":436},"action":"A","side":"A","price":"1.156840000","size":30,"channel_id":23,"order_id":"1775530326786452650","flags":128,"ts_in_delta":1126,"sequence":173972,"symbol":"FCEU SI 20260615 PS"}
{"ts_recv":"2026-04-07T02:52:06.786538117Z","hd":{"ts_event":"2026-04-07T02:52:06.786517179Z","rtype":160,"publisher_id":101,"instrument_id":436},"action":"C","side":"B","price":"1.156750000","size":30,"channel_id":23,"order_id":"10998902360572497022","flags":0,"ts_in_delta":1113,"sequence":173973,"symbol":"FCEU SI 20260615 PS"}
{"ts_recv":"2026-04-07T02:52:06.786538117Z","hd":{"ts_event":"2026-04-07T02:52:06.786517179Z","rtype":160,"publisher_id":101,"instrument_id":436},"action":"A","side":"B","price":"1.156730000","size":30,"channel_id":23,"order_id":"10998902363641299107","flags":0,"ts_in_delta":1113,"sequence":173973,"symbol":"FCEU SI 20260615 PS"}
{"ts_recv":"2026-04-07T02:52:06.786538117Z","hd":{"ts_event":"2026-04-07T02:52:06.786517179Z","rtype":160,"publisher_id":101,"instrument_id":436},"action":"C","side":"A","price":"1.156850000","size":30,"channel_id":23,"order_id":"1775530323717721214","flags":0,"ts_in_delta":1113,"sequence":173973,"symbol":"FCEU SI 20260615 PS"}
{"ts_recv":"2026-04-07T02:52:06.786538117Z","hd":{"ts_event":"2026-04-07T02:52:06.786517179Z","rtype":160,"publisher_id":101,"instrument_id":436},"action":"A","side":"A","price":"1.156830000","size":30,"channel_id":23,"order_id":"1775530326786523299","flags":128,"ts_in_delta":1113,"sequence":173973,"symbol":"FCEU SI 20260615 PS"}
{"ts_recv":"2026-04-07T02:52:06.786599424Z","hd":{"ts_event":"2026-04-07T02:52:06.786582383Z","rtype":160,"publisher_id":101,"instrument_id":436},"action":"C","side":"B","price":"1.156740000","size":30,"channel_id":23,"order_id":"10998902363641228458","flags":0,"ts_in_delta":941,"sequence":173974,"symbol":"FCEU SI 20260615 PS"}
{"ts_recv":"2026-04-07T02:52:06.786599424Z","hd":{"ts_event":"2026-04-07T02:52:06.786582383Z","rtype":160,"publisher_id":101,"instrument_id":436},"action":"A","side":"B","price":"1.156730000","size":30,"channel_id":23,"order_id":"10998902363641364016","flags":0,"ts_in_delta":941,"sequence":173974,"symbol":"FCEU SI 20260615 PS"}
{"ts_recv":"2026-04-07T02:52:06.786599424Z","hd":{"ts_event":"2026-04-07T02:52:06.786582383Z","rtype":160,"publisher_id":101,"instrument_id":436},"action":"C","side":"A","price":"1.156840000","size":30,"channel_id":23,"order_id":"1775530326786452650","flags":0,"ts_in_delta":941,"sequence":173974,"symbol":"FCEU SI 20260615 PS"}
{"ts_recv":"2026-04-07T02:52:06.786599424Z","hd":{"ts_event":"2026-04-07T02:52:06.786582383Z","rtype":160,"publisher_id":101,"instrument_id":436},"action":"A","side":"A","price":"1.156830000","size":30,"channel_id":23,"order_id":"1775530326786588208","flags":128,"ts_in_delta":941,"sequence":173974,"symbol":"FCEU SI 20260615 PS"}
{"ts_recv":"2026-04-07T02:52:20.047620955Z","hd":{"ts_event":"2026-04-07T02:52:20.047601147Z","rtype":160,"publisher_id":101,"instrument_id":436},"action":"C","side":"B","price":"1.156730000","size":30,"channel_id":23,"order_id":"10998902363641364016","flags":0,"ts_in_delta":1059,"sequence":174079,"symbol":"FCEU SI 20260615 PS"}
{"ts_recv":"2026-04-07T02:52:20.047620955Z","hd":{"ts_event":"2026-04-07T02:52:20.047601147Z","rtype":160,"publisher_id":101,"instrument_id":436},"action":"A","side":"B","price":"1.156740000","size":30,"channel_id":23,"order_id":"10998902376902382958","flags":0,"ts_in_delta":1059,"sequence":174079,"symbol":"FCEU SI 20260615 PS"}
{"ts_recv":"2026-04-07T02:52:20.047620955Z","hd":{"ts_event":"2026-04-07T02:52:20.047601147Z","rtype":160,"publisher_id":101,"instrument_id":436},"action":"C","side":"A","price":"1.156830000","size":30,"channel_id":23,"order_id":"1775530326786588208","flags":0,"ts_in_delta":1059,"sequence":174079,"symbol":"FCEU SI 20260615 PS"}
{"ts_recv":"2026-04-07T02:52:20.047620955Z","hd":{"ts_event":"2026-04-07T02:52:20.047601147Z","rtype":160,"publisher_id":101,"instrument_id":436},"action":"A","side":"A","price":"1.156840000","size":30,"channel_id":23,"order_id":"1775530340047607150","flags":128,"ts_in_delta":1059,"sequence":174079,"symbol":"FCEU SI 20260615 PS"}
{"ts_recv":"2026-04-07T02:52:38.550533936Z","hd":{"ts_event":"2026-04-07T02:52:38.550513405Z","rtype":160,"publisher_id":101,"instrument_id":436},"action":"C","side":"B","price":"1.156740000","size":30,"channel_id":23,"order_id":"10998902376902382958","flags":0,"ts_in_delta":945,"sequence":174209,"symbol":"FCEU SI 20260615 PS"}
{"ts_recv":"2026-04-07T02:52:38.550533936Z","hd":{"ts_event":"2026-04-07T02:52:38.550513405Z","rtype":160,"publisher_id":101,"instrument_id":436},"action":"A","side":"B","price":"1.156730000","size":30,"channel_id":23,"order_id":"10998902395405295272","flags":0,"ts_in_delta":945,"sequence":174209,"symbol":"FCEU SI 20260615 PS"}
{"ts_recv":"2026-04-07T02:52:38.550533936Z","hd":{"ts_event":"2026-04-07T02:52:38.550513405Z","rtype":160,"publisher_id":101,"instrument_id":436},"action":"C","side":"A","price":"1.156840000","size":30,"channel_id":23,"order_id":"1775530340047607150","flags":0,"ts_in_delta":945,"sequence":174209,"symbol":"FCEU SI 20260615 PS"}
{"ts_recv":"2026-04-07T02:52:38.550533936Z","hd":{"ts_event":"2026-04-07T02:52:38.550513405Z","rtype":160,"publisher_id":101,"instrument_id":436},"action":"A","side":"A","price":"1.156830000","size":30,"channel_id":23,"order_id":"1775530358550519464","flags":128,"ts_in_delta":945,"sequence":174209,"symbol":"FCEU SI 20260615 PS"}
{"ts_recv":"2026-04-07T02:52:38.555683271Z","hd":{"ts_event":"2026-04-07T02:52:38.555659863Z","rtype":160,"publisher_id":101,"instrument_id":436},"action":"C","side":"B","price":"1.156730000","size":30,"channel_id":23,"order_id":"10998902395405295272","flags":0,"ts_in_delta":963,"sequence":174215,"symbol":"FCEU SI 20260615 PS"}
{"ts_recv":"2026-04-07T02:52:38.555683271Z","hd":{"ts_event":"2026-04-07T02:52:38.555659863Z","rtype":160,"publisher_id":101,"instrument_id":436},"action":"A","side":"B","price":"1.156720000","size":30,"channel_id":23,"order_id":"10998902395410441670","flags":0,"ts_in_delta":963,"sequence":174215,"symbol":"FCEU SI 20260615 PS"}
{"ts_recv":"2026-04-07T02:52:38.555683271Z","hd":{"ts_event":"2026-04-07T02:52:38.555659863Z","rtype":160,"publisher_id":101,"instrument_id":436},"action":"C","side":"A","price":"1.156830000","size":30,"channel_id":23,"order_id":"1775530358550519464","flags":0,"ts_in_delta":963,"sequence":174215,"symbol":"FCEU SI 20260615 PS"}
{"ts_recv":"2026-04-07T02:52:38.555683271Z","hd":{"ts_event":"2026-04-07T02:52:38.555659863Z","rtype":160,"publisher_id":101,"instrument_id":436},"action":"A","side":"A","price":"1.156820000","size":30,"channel_id":23,"order_id":"1775530358555665862","flags":128,"ts_in_delta":963,"sequence":174215,"symbol":"FCEU SI 20260615 PS"}
{"ts_recv":"2026-04-07T02:52:38.555739885Z","hd":{"ts_event":"2026-04-07T02:52:38.555718015Z","rtype":160,"publisher_id":101,"instrument_id":436},"action":"C","side":"B","price":"1.156730000","size":30,"channel_id":23,"order_id":"10998902363641299107","flags":0,"ts_in_delta":973,"sequence":174216,"symbol":"FCEU SI 20260615 PS"}
{"ts_recv":"2026-04-07T02:52:38.555739885Z","hd":{"ts_event":"2026-04-07T02:52:38.555718015Z","rtype":160,"publisher_id":101,"instrument_id":436},"action":"A","side":"B","price":"1.156710000","size":30,"channel_id":23,"order_id":"10998902395410500032","flags":0,"ts_in_delta":973,"sequence":174216,"symbol":"FCEU SI 20260615 PS"}
{"ts_recv":"2026-04-07T02:52:38.555739885Z","hd":{"ts_event":"2026-04-07T02:52:38.555718015Z","rtype":160,"publisher_id":101,"instrument_id":436},"action":"C","side":"A","price":"1.156830000","size":30,"channel_id":23,"order_id":"1775530326786523299","flags":0,"ts_in_delta":973,"sequence":174216,"symbol":"FCEU SI 20260615 PS"}
{"ts_recv":"2026-04-07T02:52:38.555739885Z","hd":{"ts_event":"2026-04-07T02:52:38.555718015Z","rtype":160,"publisher_id":101,"instrument_id":436},"action":"A","side":"A","price":"1.156810000","size":30,"channel_id":23,"order_id":"1775530358555724224","flags":128,"ts_in_delta":973,"sequence":174216,"symbol":"FCEU SI 20260615 PS"}
{"ts_recv":"2026-04-07T02:52:38.555767232Z","hd":{"ts_event":"2026-04-07T02:52:38.555748203Z","rtype":160,"publisher_id":101,"instrument_id":436},"action":"C","side":"B","price":"1.156720000","size":30,"channel_id":23,"order_id":"10998902395410441670","flags":0,"ts_in_delta":926,"sequence":174217,"symbol":"FCEU SI 20260615 PS"}
{"ts_recv":"2026-04-07T02:52:38.555767232Z","hd":{"ts_event":"2026-04-07T02:52:38.555748203Z","rtype":160,"publisher_id":101,"instrument_id":436},"action":"A","side":"B","price":"1.156710000","size":30,"channel_id":23,"order_id":"10998902395410530043","flags":0,"ts_in_delta":926,"sequence":174217,"symbol":"FCEU SI 20260615 PS"}
{"ts_recv":"2026-04-07T02:52:38.555767232Z","hd":{"ts_event":"2026-04-07T02:52:38.555748203Z","rtype":160,"publisher_id":101,"instrument_id":436},"action":"C","side":"A","price":"1.156820000","size":30,"channel_id":23,"order_id":"1775530358555665862","flags":0,"ts_in_delta":926,"sequence":174217,"symbol":"FCEU SI 20260615 PS"}
{"ts_recv":"2026-04-07T02:52:38.555767232Z","hd":{"ts_event":"2026-04-07T02:52:38.555748203Z","rtype":160,"publisher_id":101,"instrument_id":436},"action":"A","side":"A","price":"1.156810000","size":30,"channel_id":23,"order_id":"1775530358555754235","flags":128,"ts_in_delta":926,"sequence":174217,"symbol":"FCEU SI 20260615 PS"}
{"ts_recv":"2026-04-07T02:52:38.955484975Z","hd":{"ts_event":"2026-04-07T02:52:38.955460837Z","rtype":160,"publisher_id":101,"instrument_id":436},"action":"C","side":"B","price":"1.156700000","size":20,"channel_id":23,"order_id":"10998902215997194481","flags":128,"ts_in_delta":956,"sequence":174245,"symbol":"FCEU SI 20260615 PS"}
{"ts_recv":"2026-04-07T02:52:38.997739248Z","hd":{"ts_event":"2026-04-07T02:52:38.997719005Z","rtype":160,"publisher_id":101,"instrument_id":436},"action":"A","side":"B","price":"1.156500000","size":20,"channel_id":23,"order_id":"10998902395852505997","flags":128,"ts_in_delta":1303,"sequence":174246,"symbol":"FCEU SI 20260615 PS"}
{"ts_recv":"2026-04-07T02:52:46.458360554Z","hd":{"ts_event":"2026-04-07T02:52:46.458337363Z","rtype":160,"publisher_id":101,"instrument_id":436},"action":"C","side":"B","price":"1.156710000","size":30,"channel_id":23,"order_id":"10998902395410500032","flags":0,"ts_in_delta":1212,"sequence":174283,"symbol":"FCEU SI 20260615 PS"}
{"ts_recv":"2026-04-07T02:52:46.458360554Z","hd":{"ts_event":"2026-04-07T02:52:46.458337363Z","rtype":160,"publisher_id":101,"instrument_id":436},"action":"A","side":"B","price":"1.156690000","size":30,"channel_id":23,"order_id":"10998902403313119784","flags":0,"ts_in_delta":1212,"sequence":174283,"symbol":"FCEU SI 20260615 PS"}
{"ts_recv":"2026-04-07T02:52:46.458360554Z","hd":{"ts_event":"2026-04-07T02:52:46.458337363Z","rtype":160,"publisher_id":101,"instrument_id":436},"action":"C","side":"A","price":"1.156810000","size":30,"channel_id":23,"order_id":"1775530358555724224","flags":0,"ts_in_delta":1212,"sequence":174283,"symbol":"FCEU SI 20260615 PS"}
{"ts_recv":"2026-04-07T02:52:46.458360554Z","hd":{"ts_event":"2026-04-07T02:52:46.458337363Z","rtype":160,"publisher_id":101,"instrument_id":436},"action":"A","side":"A","price":"1.156790000","size":30,"channel_id":23,"order_id":"1775530366458343976","flags":128,"ts_in_delta":1212,"sequence":174283,"symbol":"FCEU SI 20260615 PS"}
{"ts_recv":"2026-04-07T02:52:46.458463199Z","hd":{"ts_event":"2026-04-07T02:52:46.458444059Z","rtype":160,"publisher_id":101,"instrument_id":436},"action":"C","side":"B","price":"1.156710000","size":30,"channel_id":23,"order_id":"10998902395410530043","flags":0,"ts_in_delta":1034,"sequence":174284,"symbol":"FCEU SI 20260615 PS"}
{"ts_recv":"2026-04-07T02:52:46.458463199Z","hd":{"ts_event":"2026-04-07T02:52:46.458444059Z","rtype":160,"publisher_id":101,"instrument_id":436},"action":"A","side":"B","price":"1.156700000","size":30,"channel_id":23,"order_id":"10998902403313226053","flags":0,"ts_in_delta":1034,"sequence":174284,"symbol":"FCEU SI 20260615 PS"}
{"ts_recv":"2026-04-07T02:52:46.458463199Z","hd":{"ts_event":"2026-04-07T02:52:46.458444059Z","rtype":160,"publisher_id":101,"instrument_id":436},"action":"C","side":"A","price":"1.156810000","size":30,"channel_id":23,"order_id":"1775530358555754235","flags":0,"ts_in_delta":1034,"sequence":174284,"symbol":"FCEU SI 20260615 PS"}
{"ts_recv":"2026-04-07T02:52:46.458463199Z","hd":{"ts_event":"2026-04-07T02:52:46.458444059Z","rtype":160,"publisher_id":101,"instrument_id":436},"action":"A","side":"A","price":"1.156800000","size":30,"channel_id":23,"order_id":"1775530366458450245","flags":128,"ts_in_delta":1034,"sequence":174284,"symbol":"FCEU SI 20260615 PS"}
{"ts_recv":"2026-04-07T02:52:46.459405877Z","hd":{"ts_event":"2026-04-07T02:52:46.459390185Z","rtype":160,"publisher_id":101,"instrument_id":436},"action":"C","side":"B","price":"1.156700000","size":30,"channel_id":23,"order_id":"10998902403313226053","flags":0,"ts_in_delta":748,"sequence":174285,"symbol":"FCEU SI 20260615 PS"}
{"ts_recv":"2026-04-07T02:52:46.459405877Z","hd":{"ts_event":"2026-04-07T02:52:46.459390185Z","rtype":160,"publisher_id":101,"instrument_id":436},"action":"A","side":"B","price":"1.156690000","size":30,"channel_id":23,"order_id":"10998902403314172141","flags":0,"ts_in_delta":748,"sequence":174285,"symbol":"FCEU SI 20260615 PS"}
{"ts_recv":"2026-04-07T02:52:46.459405877Z","hd":{"ts_event":"2026-04-07T02:52:46.459390185Z","rtype":160,"publisher_id":101,"instrument_id":436},"action":"C","side":"A","price":"1.156800000","size":30,"channel_id":23,"order_id":"1775530366458450245","flags":0,"ts_in_delta":748,"sequence":174285,"symbol":"FCEU SI 20260615 PS"}
{"ts_recv":"2026-04-07T02:52:46.459405877Z","hd":{"ts_event":"2026-04-07T02:52:46.459390185Z","rtype":160,"publisher_id":101,"instrument_id":436},"action":"A","side":"A","price":"1.156790000","size":30,"channel_id":23,"order_id":"1775530366459396333","flags":128,"ts_in_delta":748,"sequence":174285,"symbol":"FCEU SI 20260615 PS"}
{"ts_recv":"2026-04-07T02:52:46.745366861Z","hd":{"ts_event":"2026-04-07T02:52:46.745347863Z","rtype":160,"publisher_id":101,"instrument_id":436},"action":"C","side":"B","price":"1.156690000","size":30,"channel_id":23,"order_id":"10998902403314172141","flags":0,"ts_in_delta":1084,"sequence":174311,"symbol":"FCEU SI 20260615 PS"}
{"ts_recv":"2026-04-07T02:52:46.745366861Z","hd":{"ts_event":"2026-04-07T02:52:46.745347863Z","rtype":160,"publisher_id":101,"instrument_id":436},"action":"A","side":"B","price":"1.156680000","size":30,"channel_id":23,"order_id":"10998902403600130097","flags":0,"ts_in_delta":1084,"sequence":174311,"symbol":"FCEU SI 20260615 PS"}
{"ts_recv":"2026-04-07T02:52:46.745366861Z","hd":{"ts_event":"2026-04-07T02:52:46.745347863Z","rtype":160,"publisher_id":101,"instrument_id":436},"action":"C","side":"A","price":"1.156790000","size":30,"channel_id":23,"order_id":"1775530366459396333","flags":0,"ts_in_delta":1084,"sequence":174311,"symbol":"FCEU SI 20260615 PS"}
{"ts_recv":"2026-04-07T02:52:46.745366861Z","hd":{"ts_event":"2026-04-07T02:52:46.745347863Z","rtype":160,"publisher_id":101,"instrument_id":436},"action":"A","side":"A","price":"1.156780000","size":30,"channel_id":23,"order_id":"1775530366745354289","flags":128,"ts_in_delta":1084,"sequence":174311,"symbol":"FCEU SI 20260615 PS"}
{"ts_recv":"2026-04-07T02:52:46.745452458Z","hd":{"ts_event":"2026-04-07T02:52:46.745431287Z","rtype":160,"publisher_id":101,"instrument_id":436},"action":"C","side":"B","price":"1.156680000","size":30,"channel_id":23,"order_id":"10998902403600130097","flags":0,"ts_in_delta":926,"sequence":174312,"symbol":"FCEU SI 20260615 PS"}
{"ts_recv":"2026-04-07T02:52:46.745452458Z","hd":{"ts_event":"2026-04-07T02:52:46.745431287Z","rtype":160,"publisher_id":101,"instrument_id":436},"action":"A","side":"B","price":"1.156670000","size":30,"channel_id":23,"order_id":"10998902403600212948","flags":0,"ts_in_delta":926,"sequence":174312,"symbol":"FCEU SI 20260615 PS"}
{"ts_recv":"2026-04-07T02:52:46.745452458Z","hd":{"ts_event":"2026-04-07T02:52:46.745431287Z","rtype":160,"publisher_id":101,"instrument_id":436},"action":"C","side":"A","price":"1.156780000","size":30,"channel_id":23,"order_id":"1775530366745354289","flags":0,"ts_in_delta":926,"sequence":174312,"symbol":"FCEU SI 20260615 PS"}
{"ts_recv":"2026-04-07T02:52:46.745452458Z","hd":{"ts_event":"2026-04-07T02:52:46.745431287Z","rtype":160,"publisher_id":101,"instrument_id":436},"action":"A","side":"A","price":"1.156770000","size":30,"channel_id":23,"order_id":"1775530366745437140","flags":128,"ts_in_delta":926,"sequence":174312,"symbol":"FCEU SI 20260615 PS"}
{"ts_recv":"2026-04-07T02:52:46.745503382Z","hd":{"ts_event":"2026-04-07T02:52:46.745484531Z","rtype":160,"publisher_id":101,"instrument_id":436},"action":"C","side":"B","price":"1.156690000","size":30,"channel_id":23,"order_id":"10998902403313119784","flags":0,"ts_in_delta":1114,"sequence":174313,"symbol":"FCEU SI 20260615 PS"}
{"ts_recv":"2026-04-07T02:52:46.745503382Z","hd":{"ts_event":"2026-04-07T02:52:46.745484531Z","rtype":160,"publisher_id":101,"instrument_id":436},"action":"A","side":"B","price":"1.156670000","size":30,"channel_id":23,"order_id":"10998902403600266425","flags":0,"ts_in_delta":1114,"sequence":174313,"symbol":"FCEU SI 20260615 PS"}
{"ts_recv":"2026-04-07T02:52:46.745503382Z","hd":{"ts_event":"2026-04-07T02:52:46.745484531Z","rtype":160,"publisher_id":101,"instrument_id":436},"action":"C","side":"A","price":"1.156790000","size":30,"channel_id":23,"order_id":"1775530366458343976","flags":0,"ts_in_delta":1114,"sequence":174313,"symbol":"FCEU SI 20260615 PS"}
{"ts_recv":"2026-04-07T02:52:46.745503382Z","hd":{"ts_event":"2026-04-07T02:52:46.745484531Z","rtype":160,"publisher_id":101,"instrument_id":436},"action":"A","side":"A","price":"1.156770000","size":30,"channel_id":23,"order_id":"1775530366745490617","flags":128,"ts_in_delta":1114,"sequence":174313,"symbol":"FCEU SI 20260615 PS"}
{"ts_recv":"2026-04-07T02:52:46.745513996Z","hd":{"ts_event":"2026-04-07T02:52:46.745491327Z","rtype":160,"publisher_id":101,"instrument_id":436},"action":"C","side":"B","price":"1.156670000","size":30,"channel_id":23,"order_id":"10998902403600212948","flags":0,"ts_in_delta":928,"sequence":174314,"symbol":"FCEU SI 20260615 PS"}
{"ts_recv":"2026-04-07T02:52:46.745513996Z","hd":{"ts_event":"2026-04-07T02:52:46.745491327Z","rtype":160,"publisher_id":101,"instrument_id":436},"action":"A","side":"B","price":"1.156680000","size":30,"channel_id":23,"order_id":"10998902403600275752","flags":0,"ts_in_delta":928,"sequence":174314,"symbol":"FCEU SI 20260615 PS"}
{"ts_recv":"2026-04-07T02:52:46.745513996Z","hd":{"ts_event":"2026-04-07T02:52:46.745491327Z","rtype":160,"publisher_id":101,"instrument_id":436},"action":"C","side":"A","price":"1.156770000","size":30,"channel_id":23,"order_id":"1775530366745437140","flags":0,"ts_in_delta":928,"sequence":174314,"symbol":"FCEU SI 20260615 PS"}
{"ts_recv":"2026-04-07T02:52:46.745513996Z","hd":{"ts_event":"2026-04-07T02:52:46.745491327Z","rtype":160,"publisher_id":101,"instrument_id":436},"action":"A","side":"A","price":"1.156780000","size":30,"channel_id":23,"order_id":"1775530366745499944","flags":128,"ts_in_delta":928,"sequence":174314,"symbol":"FCEU SI 20260615 PS"}
{"ts_recv":"2026-04-07T02:52:46.745566970Z","hd":{"ts_event":"2026-04-07T02:52:46.745551467Z","rtype":160,"publisher_id":101,"instrument_id":436},"action":"C","side":"B","price":"1.156680000","size":30,"channel_id":23,"order_id":"10998902403600275752","flags":0,"ts_in_delta":1086,"sequence":174315,"symbol":"FCEU SI 20260615 PS"}
{"ts_recv":"2026-04-07T02:52:46.745566970Z","hd":{"ts_event":"2026-04-07T02:52:46.745551467Z","rtype":160,"publisher_id":101,"instrument_id":436},"action":"A","side":"B","price":"1.156670000","size":30,"channel_id":23,"order_id":"10998902403600333000","flags":0,"ts_in_delta":1086,"sequence":174315,"symbol":"FCEU SI 20260615 PS"}
{"ts_recv":"2026-04-07T02:52:46.745566970Z","hd":{"ts_event":"2026-04-07T02:52:46.745551467Z","rtype":160,"publisher_id":101,"instrument_id":436},"action":"C","side":"A","price":"1.156780000","size":30,"channel_id":23,"order_id":"1775530366745499944","flags":0,"ts_in_delta":1086,"sequence":174315,"symbol":"FCEU SI 20260615 PS"}
{"ts_recv":"2026-04-07T02:52:46.745566970Z","hd":{"ts_event":"2026-04-07T02:52:46.745551467Z","rtype":160,"publisher_id":101,"instrument_id":436},"action":"A","side":"A","price":"1.156770000","size":30,"channel_id":23,"order_id":"1775530366745557192","flags":128,"ts_in_delta":1086,"sequence":174315,"symbol":"FCEU SI 20260615 PS"}
{"ts_recv":"2026-04-07T02:53:10.801209224Z","hd":{"ts_event":"2026-04-07T02:53:10.801186823Z","rtype":160,"publisher_id":101,"instrument_id":436},"action":"C","side":"B","price":"1.156670000","size":30,"channel_id":23,"order_id":"10998902403600333000","flags":0,"ts_in_delta":911,"sequence":174485,"symbol":"FCEU SI 20260615 PS"}
{"ts_recv":"2026-04-07T02:53:10.801209224Z","hd":{"ts_event":"2026-04-07T02:53:10.801186823Z","rtype":160,"publisher_id":101,"instrument_id":436},"action":"A","side":"B","price":"1.156650000","size":30,"channel_id":23,"order_id":"10998902427655968320","flags":0,"ts_in_delta":911,"sequence":174485,"symbol":"FCEU SI 20260615 PS"}
{"ts_recv":"2026-04-07T02:53:10.801209224Z","hd":{"ts_event":"2026-04-07T02:53:10.801186823Z","rtype":160,"publisher_id":101,"instrument_id":436},"action":"C","side":"A","price":"1.156770000","size":30,"channel_id":23,"order_id":"1775530366745557192","flags":0,"ts_in_delta":911,"sequence":174485,"symbol":"FCEU SI 20260615 PS"}
{"ts_recv":"2026-04-07T02:53:10.801209224Z","hd":{"ts_event":"2026-04-07T02:53:10.801186823Z","rtype":160,"publisher_id":101,"instrument_id":436},"action":"A","side":"A","price":"1.156750000","size":30,"channel_id":23,"order_id":"1775530390801192512","flags":128,"ts_in_delta":911,"sequence":174485,"symbol":"FCEU SI 20260615 PS"}
{"ts_recv":"2026-04-07T02:53:10.801266568Z","hd":{"ts_event":"2026-04-07T02:53:10.801246253Z","rtype":160,"publisher_id":101,"instrument_id":436},"action":"C","side":"B","price":"1.156670000","size":30,"channel_id":23,"order_id":"10998902403600266425","flags":0,"ts_in_delta":906,"sequence":174486,"symbol":"FCEU SI 20260615 PS"}
{"ts_recv":"2026-04-07T02:53:10.801266568Z","hd":{"ts_event":"2026-04-07T02:53:10.801246253Z","rtype":160,"publisher_id":101,"instrument_id":436},"action":"A","side":"B","price":"1.156650000","size":30,"channel_id":23,"order_id":"10998902427656028626","flags":0,"ts_in_delta":906,"sequence":174486,"symbol":"FCEU SI 20260615 PS"}
{"ts_recv":"2026-04-07T02:53:10.801266568Z","hd":{"ts_event":"2026-04-07T02:53:10.801246253Z","rtype":160,"publisher_id":101,"instrument_id":436},"action":"C","side":"A","price":"1.156770000","size":30,"channel_id":23,"order_id":"1775530366745490617","flags":0,"ts_in_delta":906,"sequence":174486,"symbol":"FCEU SI 20260615 PS"}
{"ts_recv":"2026-04-07T02:53:10.801266568Z","hd":{"ts_event":"2026-04-07T02:53:10.801246253Z","rtype":160,"publisher_id":101,"instrument_id":436},"action":"A","side":"A","price":"1.156750000","size":30,"channel_id":23,"order_id":"1775530390801252818","flags":128,"ts_in_delta":906,"sequence":174486,"symbol":"FCEU SI 20260615 PS"}
{"ts_recv":"2026-04-07T02:53:10.801322706Z","hd":{"ts_event":"2026-04-07T02:53:10.801303961Z","rtype":160,"publisher_id":101,"instrument_id":436},"action":"C","side":"B","price":"1.156650000","size":30,"channel_id":23,"order_id":"10998902427655968320","flags":0,"ts_in_delta":925,"sequence":174487,"symbol":"FCEU SI 20260615 PS"}
{"ts_recv":"2026-04-07T02:53:10.801322706Z","hd":{"ts_event":"2026-04-07T02:53:10.801303961Z","rtype":160,"publisher_id":101,"instrument_id":436},"action":"A","side":"B","price":"1.156640000","size":30,"channel_id":23,"order_id":"10998902427656085599","flags":0,"ts_in_delta":925,"sequence":174487,"symbol":"FCEU SI 20260615 PS"}
{"ts_recv":"2026-04-07T02:53:10.801322706Z","hd":{"ts_event":"2026-04-07T02:53:10.801303961Z","rtype":160,"publisher_id":101,"instrument_id":436},"action":"C","side":"A","price":"1.156750000","size":30,"channel_id":23,"order_id":"1775530390801192512","flags":0,"ts_in_delta":925,"sequence":174487,"symbol":"FCEU SI 20260615 PS"}
{"ts_recv":"2026-04-07T02:53:10.801322706Z","hd":{"ts_event":"2026-04-07T02:53:10.801303961Z","rtype":160,"publisher_id":101,"instrument_id":436},"action":"A","side":"A","price":"1.156740000","size":30,"channel_id":23,"order_id":"1775530390801309791","flags":128,"ts_in_delta":925,"sequence":174487,"symbol":"FCEU SI 20260615 PS"}
{"ts_recv":"2026-04-07T02:53:10.801408050Z","hd":{"ts_event":"2026-04-07T02:53:10.801386875Z","rtype":160,"publisher_id":101,"instrument_id":436},"action":"C","side":"B","price":"1.156640000","size":30,"channel_id":23,"order_id":"10998902427656085599","flags":0,"ts_in_delta":1035,"sequence":174488,"symbol":"FCEU SI 20260615 PS"}
{"ts_recv":"2026-04-07T02:53:10.801408050Z","hd":{"ts_event":"2026-04-07T02:53:10.801386875Z","rtype":160,"publisher_id":101,"instrument_id":436},"action":"A","side":"B","price":"1.156630000","size":30,"channel_id":23,"order_id":"10998902427656168919","flags":0,"ts_in_delta":1035,"sequence":174488,"symbol":"FCEU SI 20260615 PS"}
{"ts_recv":"2026-04-07T02:53:10.801408050Z","hd":{"ts_event":"2026-04-07T02:53:10.801386875Z","rtype":160,"publisher_id":101,"instrument_id":436},"action":"C","side":"A","price":"1.156740000","size":30,"channel_id":23,"order_id":"1775530390801309791","flags":0,"ts_in_delta":1035,"sequence":174488,"symbol":"FCEU SI 20260615 PS"}
{"ts_recv":"2026-04-07T02:53:10.801408050Z","hd":{"ts_event":"2026-04-07T02:53:10.801386875Z","rtype":160,"publisher_id":101,"instrument_id":436},"action":"A","side":"A","price":"1.156730000","size":30,"channel_id":23,"order_id":"1775530390801393111","flags":128,"ts_in_delta":1035,"sequence":174488,"symbol":"FCEU SI 20260615 PS"}
{"ts_recv":"2026-04-07T02:53:10.801464311Z","hd":{"ts_event":"2026-04-07T02:53:10.801447637Z","rtype":160,"publisher_id":101,"instrument_id":436},"action":"C","side":"B","price":"1.156630000","size":30,"channel_id":23,"order_id":"10998902427656168919","flags":0,"ts_in_delta":907,"sequence":174489,"symbol":"FCEU SI 20260615 PS"}
{"ts_recv":"2026-04-07T02:53:10.801464311Z","hd":{"ts_event":"2026-04-07T02:53:10.801447637Z","rtype":160,"publisher_id":101,"instrument_id":436},"action":"A","side":"B","price":"1.156640000","size":30,"channel_id":23,"order_id":"10998902427656229123","flags":0,"ts_in_delta":907,"sequence":174489,"symbol":"FCEU SI 20260615 PS"}
{"ts_recv":"2026-04-07T02:53:10.801464311Z","hd":{"ts_event":"2026-04-07T02:53:10.801447637Z","rtype":160,"publisher_id":101,"instrument_id":436},"action":"C","side":"A","price":"1.156730000","size":30,"channel_id":23,"order_id":"1775530390801393111","flags":0,"ts_in_delta":907,"sequence":174489,"symbol":"FCEU SI 20260615 PS"}
{"ts_recv":"2026-04-07T02:53:10.801464311Z","hd":{"ts_event":"2026-04-07T02:53:10.801447637Z","rtype":160,"publisher_id":101,"instrument_id":436},"action":"A","side":"A","price":"1.156740000","size":30,"channel_id":23,"order_id":"1775530390801453315","flags":128,"ts_in_delta":907,"sequence":174489,"symbol":"FCEU SI 20260615 PS"}
{"ts_recv":"2026-04-07T02:53:10.839252533Z","hd":{"ts_event":"2026-04-07T02:53:10.839236145Z","rtype":160,"publisher_id":101,"instrument_id":436},"action":"A","side":"A","price":"1.156900000","size":20,"channel_id":23,"order_id":"1775530390839242642","flags":128,"ts_in_delta":1338,"sequence":174507,"symbol":"FCEU SI 20260615 PS"}
{"ts_recv":"2026-04-07T02:53:10.839379785Z","hd":{"ts_event":"2026-04-07T02:53:10.839366181Z","rtype":160,"publisher_id":101,"instrument_id":436},"action":"C","side":"A","price":"1.157000000","size":20,"channel_id":23,"order_id":"1775530264388177366","flags":128,"ts_in_delta":949,"sequence":174508,"symbol":"FCEU SI 20260615 PS"}
{"ts_recv":"2026-04-07T02:54:03.542924746Z","hd":{"ts_event":"2026-04-07T02:54:03.542901567Z","rtype":160,"publisher_id":101,"instrument_id":436},"action":"C","side":"B","price":"1.156640000","size":30,"channel_id":23,"order_id":"10998902427656229123","flags":0,"ts_in_delta":1076,"sequence":174926,"symbol":"FCEU SI 20260615 PS"}
{"ts_recv":"2026-04-07T02:54:03.542924746Z","hd":{"ts_event":"2026-04-07T02:54:03.542901567Z","rtype":160,"publisher_id":101,"instrument_id":436},"action":"A","side":"B","price":"1.156650000","size":30,"channel_id":23,"order_id":"10998902480397683130","flags":0,"ts_in_delta":1076,"sequence":174926,"symbol":"FCEU SI 20260615 PS"}
{"ts_recv":"2026-04-07T02:54:03.542924746Z","hd":{"ts_event":"2026-04-07T02:54:03.542901567Z","rtype":160,"publisher_id":101,"instrument_id":436},"action":"C","side":"A","price":"1.156740000","size":30,"channel_id":23,"order_id":"1775530390801453315","flags":0,"ts_in_delta":1076,"sequence":174926,"symbol":"FCEU SI 20260615 PS"}
{"ts_recv":"2026-04-07T02:54:03.542924746Z","hd":{"ts_event":"2026-04-07T02:54:03.542901567Z","rtype":160,"publisher_id":101,"instrument_id":436},"action":"A","side":"A","price":"1.156750000","size":30,"channel_id":23,"order_id":"1775530443542907322","flags":128,"ts_in_delta":1076,"sequence":174926,"symbol":"FCEU SI 20260615 PS"}
{"ts_recv":"2026-04-07T02:54:03.556716757Z","hd":{"ts_event":"2026-04-07T02:54:03.556694901Z","rtype":160,"publisher_id":101,"instrument_id":436},"action":"C","side":"B","price":"1.156650000","size":30,"channel_id":23,"order_id":"10998902480397683130","flags":0,"ts_in_delta":935,"sequence":174933,"symbol":"FCEU SI 20260615 PS"}
{"ts_recv":"2026-04-07T02:54:03.556716757Z","hd":{"ts_event":"2026-04-07T02:54:03.556694901Z","rtype":160,"publisher_id":101,"instrument_id":436},"action":"A","side":"B","price":"1.156660000","size":30,"channel_id":23,"order_id":"10998902480411476595","flags":0,"ts_in_delta":935,"sequence":174933,"symbol":"FCEU SI 20260615 PS"}
{"ts_recv":"2026-04-07T02:54:03.556716757Z","hd":{"ts_event":"2026-04-07T02:54:03.556694901Z","rtype":160,"publisher_id":101,"instrument_id":436},"action":"C","side":"A","price":"1.156750000","size":30,"channel_id":23,"order_id":"1775530443542907322","flags":0,"ts_in_delta":935,"sequence":174933,"symbol":"FCEU SI 20260615 PS"}
{"ts_recv":"2026-04-07T02:54:03.556716757Z","hd":{"ts_event":"2026-04-07T02:54:03.556694901Z","rtype":160,"publisher_id":101,"instrument_id":436},"action":"A","side":"A","price":"1.156760000","size":30,"channel_id":23,"order_id":"1775530443556700787","flags":128,"ts_in_delta":935,"sequence":174933,"symbol":"FCEU SI 20260615 PS"}
{"ts_recv":"2026-04-07T02:54:03.556770768Z","hd":{"ts_event":"2026-04-07T02:54:03.556748381Z","rtype":160,"publisher_id":101,"instrument_id":436},"action":"C","side":"B","price":"1.156650000","size":30,"channel_id":23,"order_id":"10998902427656028626","flags":0,"ts_in_delta":907,"sequence":174934,"symbol":"FCEU SI 20260615 PS"}
{"ts_recv":"2026-04-07T02:54:03.556770768Z","hd":{"ts_event":"2026-04-07T02:54:03.556748381Z","rtype":160,"publisher_id":101,"instrument_id":436},"action":"A","side":"B","price":"1.156670000","size":30,"channel_id":23,"order_id":"10998902480411530319","flags":0,"ts_in_delta":907,"sequence":174934,"symbol":"FCEU SI 20260615 PS"}
{"ts_recv":"2026-04-07T02:54:03.556770768Z","hd":{"ts_event":"2026-04-07T02:54:03.556748381Z","rtype":160,"publisher_id":101,"instrument_id":436},"action":"C","side":"A","price":"1.156750000","size":30,"channel_id":23,"order_id":"1775530390801252818","flags":0,"ts_in_delta":907,"sequence":174934,"symbol":"FCEU SI 20260615 PS"}
{"ts_recv":"2026-04-07T02:54:03.556770768Z","hd":{"ts_event":"2026-04-07T02:54:03.556748381Z","rtype":160,"publisher_id":101,"instrument_id":436},"action":"A","side":"A","price":"1.156770000","size":30,"channel_id":23,"order_id":"1775530443556754511","flags":128,"ts_in_delta":907,"sequence":174934,"symbol":"FCEU SI 20260615 PS"}
{"ts_recv":"2026-04-07T02:54:03.556824717Z","hd":{"ts_event":"2026-04-07T02:54:03.556808357Z","rtype":160,"publisher_id":101,"instrument_id":436},"action":"C","side":"B","price":"1.156660000","size":30,"channel_id":23,"order_id":"10998902480411476595","flags":0,"ts_in_delta":920,"sequence":174935,"symbol":"FCEU SI 20260615 PS"}
{"ts_recv":"2026-04-07T02:54:03.556824717Z","hd":{"ts_event":"2026-04-07T02:54:03.556808357Z","rtype":160,"publisher_id":101,"instrument_id":436},"action":"A","side":"B","price":"1.156670000","size":30,"channel_id":23,"order_id":"10998902480411590058","flags":0,"ts_in_delta":920,"sequence":174935,"symbol":"FCEU SI 20260615 PS"}
{"ts_recv":"2026-04-07T02:54:03.556824717Z","hd":{"ts_event":"2026-04-07T02:54:03.556808357Z","rtype":160,"publisher_id":101,"instrument_id":436},"action":"C","side":"A","price":"1.156760000","size":30,"channel_id":23,"order_id":"1775530443556700787","flags":0,"ts_in_delta":920,"sequence":174935,"symbol":"FCEU SI 20260615 PS"}
{"ts_recv":"2026-04-07T02:54:03.556824717Z","hd":{"ts_event":"2026-04-07T02:54:03.556808357Z","rtype":160,"publisher_id":101,"instrument_id":436},"action":"A","side":"A","price":"1.156770000","size":30,"channel_id":23,"order_id":"1775530443556814250","flags":128,"ts_in_delta":920,"sequence":174935,"symbol":"FCEU SI 20260615 PS"}
{"ts_recv":"2026-04-07T02:54:22.965612849Z","hd":{"ts_event":"2026-04-07T02:54:22.965587795Z","rtype":160,"publisher_id":101,"instrument_id":436},"action":"C","side":"B","price":"1.156670000","size":30,"channel_id":23,"order_id":"10998902480411590058","flags":0,"ts_in_delta":1170,"sequence":175070,"symbol":"FCEU SI 20260615 PS"}
{"ts_recv":"2026-04-07T02:54:22.965612849Z","hd":{"ts_event":"2026-04-07T02:54:22.965587795Z","rtype":160,"publisher_id":101,"instrument_id":436},"action":"A","side":"B","price":"1.156650000","size":30,"channel_id":23,"order_id":"10998902499820369916","flags":0,"ts_in_delta":1170,"sequence":175070,"symbol":"FCEU SI 20260615 PS"}
{"ts_recv":"2026-04-07T02:54:22.965612849Z","hd":{"ts_event":"2026-04-07T02:54:22.965587795Z","rtype":160,"publisher_id":101,"instrument_id":436},"action":"C","side":"A","price":"1.156770000","size":30,"channel_id":23,"order_id":"1775530443556814250","flags":0,"ts_in_delta":1170,"sequence":175070,"symbol":"FCEU SI 20260615 PS"}
{"ts_recv":"2026-04-07T02:54:22.965612849Z","hd":{"ts_event":"2026-04-07T02:54:22.965587795Z","rtype":160,"publisher_id":101,"instrument_id":436},"action":"A","side":"A","price":"1.156750000","size":30,"channel_id":23,"order_id":"1775530462965594108","flags":128,"ts_in_delta":1170,"sequence":175070,"symbol":"FCEU SI 20260615 PS"}
{"ts_recv":"2026-04-07T02:54:22.965671306Z","hd":{"ts_event":"2026-04-07T02:54:22.965650657Z","rtype":160,"publisher_id":101,"instrument_id":436},"action":"C","side":"B","price":"1.156670000","size":30,"channel_id":23,"order_id":"10998902480411530319","flags":0,"ts_in_delta":842,"sequence":175071,"symbol":"FCEU SI 20260615 PS"}
{"ts_recv":"2026-04-07T02:54:22.965671306Z","hd":{"ts_event":"2026-04-07T02:54:22.965650657Z","rtype":160,"publisher_id":101,"instrument_id":436},"action":"A","side":"B","price":"1.156650000","size":30,"channel_id":23,"order_id":"10998902499820432834","flags":0,"ts_in_delta":842,"sequence":175071,"symbol":"FCEU SI 20260615 PS"}
{"ts_recv":"2026-04-07T02:54:22.965671306Z","hd":{"ts_event":"2026-04-07T02:54:22.965650657Z","rtype":160,"publisher_id":101,"instrument_id":436},"action":"C","side":"A","price":"1.156770000","size":30,"channel_id":23,"order_id":"1775530443556754511","flags":0,"ts_in_delta":842,"sequence":175071,"symbol":"FCEU SI 20260615 PS"}
{"ts_recv":"2026-04-07T02:54:22.965671306Z","hd":{"ts_event":"2026-04-07T02:54:22.965650657Z","rtype":160,"publisher_id":101,"instrument_id":436},"action":"A","side":"A","price":"1.156750000","size":30,"channel_id":23,"order_id":"1775530462965657026","flags":128,"ts_in_delta":842,"sequence":175071,"symbol":"FCEU SI 20260615 PS"}
{"ts_recv":"2026-04-07T02:54:22.965763332Z","hd":{"ts_event":"2026-04-07T02:54:22.965745369Z","rtype":160,"publisher_id":101,"instrument_id":436},"action":"C","side":"B","price":"1.156650000","size":30,"channel_id":23,"order_id":"10998902499820369916","flags":0,"ts_in_delta":874,"sequence":175073,"symbol":"FCEU SI 20260615 PS"}
{"ts_recv":"2026-04-07T02:54:22.965763332Z","hd":{"ts_event":"2026-04-07T02:54:22.965745369Z","rtype":160,"publisher_id":101,"instrument_id":436},"action":"A","side":"B","price":"1.156640000","size":30,"channel_id":23,"order_id":"10998902499820527005","flags":0,"ts_in_delta":874,"sequence":175073,"symbol":"FCEU SI 20260615 PS"}
{"ts_recv":"2026-04-07T02:54:22.965763332Z","hd":{"ts_event":"2026-04-07T02:54:22.965745369Z","rtype":160,"publisher_id":101,"instrument_id":436},"action":"C","side":"A","price":"1.156750000","size":30,"channel_id":23,"order_id":"1775530462965594108","flags":0,"ts_in_delta":874,"sequence":175073,"symbol":"FCEU SI 20260615 PS"}
{"ts_recv":"2026-04-07T02:54:22.965763332Z","hd":{"ts_event":"2026-04-07T02:54:22.965745369Z","rtype":160,"publisher_id":101,"instrument_id":436},"action":"A","side":"A","price":"1.156740000","size":30,"channel_id":23,"order_id":"1775530462965751197","flags":128,"ts_in_delta":874,"sequence":175073,"symbol":"FCEU SI 20260615 PS"}
{"ts_recv":"2026-04-07T02:55:13.051855412Z","hd":{"ts_event":"2026-04-07T02:55:13.051820185Z","rtype":160,"publisher_id":101,"instrument_id":436},"action":"C","side":"B","price":"1.156640000","size":30,"channel_id":23,"order_id":"10998902499820527005","flags":0,"ts_in_delta":1347,"sequence":175305,"symbol":"FCEU SI 20260615 PS"}
{"ts_recv":"2026-04-07T02:55:13.051855412Z","hd":{"ts_event":"2026-04-07T02:55:13.051820185Z","rtype":160,"publisher_id":101,"instrument_id":436},"action":"A","side":"B","price":"1.156630000","size":30,"channel_id":23,"order_id":"10998902549906608693","flags":0,"ts_in_delta":1347,"sequence":175305,"symbol":"FCEU SI 20260615 PS"}
{"ts_recv":"2026-04-07T02:55:13.051855412Z","hd":{"ts_event":"2026-04-07T02:55:13.051820185Z","rtype":160,"publisher_id":101,"instrument_id":436},"action":"C","side":"A","price":"1.156740000","size":30,"channel_id":23,"order_id":"1775530462965751197","flags":0,"ts_in_delta":1347,"sequence":175305,"symbol":"FCEU SI 20260615 PS"}
{"ts_recv":"2026-04-07T02:55:13.051855412Z","hd":{"ts_event":"2026-04-07T02:55:13.051820185Z","rtype":160,"publisher_id":101,"instrument_id":436},"action":"A","side":"A","price":"1.156730000","size":30,"channel_id":23,"order_id":"1775530513051832885","flags":128,"ts_in_delta":1347,"sequence":175305,"symbol":"FCEU SI 20260615 PS"}
{"ts_recv":"2026-04-07T02:55:13.051954748Z","hd":{"ts_event":"2026-04-07T02:55:13.051930055Z","rtype":160,"publisher_id":101,"instrument_id":436},"action":"C","side":"B","price":"1.156650000","size":30,"channel_id":23,"order_id":"10998902499820432834","flags":0,"ts_in_delta":901,"sequence":175306,"symbol":"FCEU SI 20260615 PS"}
{"ts_recv":"2026-04-07T02:55:13.051954748Z","hd":{"ts_event":"2026-04-07T02:55:13.051930055Z","rtype":160,"publisher_id":101,"instrument_id":436},"action":"A","side":"B","price":"1.156620000","size":30,"channel_id":23,"order_id":"10998902549906712387","flags":0,"ts_in_delta":901,"sequence":175306,"symbol":"FCEU SI 20260615 PS"}
{"ts_recv":"2026-04-07T02:55:13.051954748Z","hd":{"ts_event":"2026-04-07T02:55:13.051930055Z","rtype":160,"publisher_id":101,"instrument_id":436},"action":"C","side":"A","price":"1.156750000","size":30,"channel_id":23,"order_id":"1775530462965657026","flags":0,"ts_in_delta":901,"sequence":175306,"symbol":"FCEU SI 20260615 PS"}
{"ts_recv":"2026-04-07T02:55:13.051954748Z","hd":{"ts_event":"2026-04-07T02:55:13.051930055Z","rtype":160,"publisher_id":101,"instrument_id":436},"action":"A","side":"A","price":"1.156720000","size":30,"channel_id":23,"order_id":"1775530513051936579","flags":128,"ts_in_delta":901,"sequence":175306,"symbol":"FCEU SI 20260615 PS"}
{"ts_recv":"2026-04-07T02:55:13.052018028Z","hd":{"ts_event":"2026-04-07T02:55:13.051998037Z","rtype":160,"publisher_id":101,"instrument_id":436},"action":"C","side":"B","price":"1.156630000","size":30,"channel_id":23,"order_id":"10998902549906608693","flags":0,"ts_in_delta":925,"sequence":175307,"symbol":"FCEU SI 20260615 PS"}
{"ts_recv":"2026-04-07T02:55:13.052018028Z","hd":{"ts_event":"2026-04-07T02:55:13.051998037Z","rtype":160,"publisher_id":101,"instrument_id":436},"action":"A","side":"B","price":"1.156620000","size":30,"channel_id":23,"order_id":"10998902549906779721","flags":0,"ts_in_delta":925,"sequence":175307,"symbol":"FCEU SI 20260615 PS"}
{"ts_recv":"2026-04-07T02:55:13.052018028Z","hd":{"ts_event":"2026-04-07T02:55:13.051998037Z","rtype":160,"publisher_id":101,"instrument_id":436},"action":"C","side":"A","price":"1.156730000","size":30,"channel_id":23,"order_id":"1775530513051832885","flags":0,"ts_in_delta":925,"sequence":175307,"symbol":"FCEU SI 20260615 PS"}
{"ts_recv":"2026-04-07T02:55:13.052018028Z","hd":{"ts_event":"2026-04-07T02:55:13.051998037Z","rtype":160,"publisher_id":101,"instrument_id":436},"action":"A","side":"A","price":"1.156720000","size":30,"channel_id":23,"order_id":"1775530513052003913","flags":128,"ts_in_delta":925,"sequence":175307,"symbol":"FCEU SI 20260615 PS"}
{"ts_recv":"2026-04-07T02:55:13.081995632Z","hd":{"ts_event":"2026-04-07T02:55:13.081976325Z","rtype":160,"publisher_id":101,"instrument_id":436},"action":"C","side":"B","price":"1.156620000","size":30,"channel_id":23,"order_id":"10998902549906779721","flags":0,"ts_in_delta":723,"sequence":175332,"symbol":"FCEU SI 20260615 PS"}
{"ts_recv":"2026-04-07T02:55:13.081995632Z","hd":{"ts_event":"2026-04-07T02:55:13.081976325Z","rtype":160,"publisher_id":101,"instrument_id":436},"action":"A","side":"B","price":"1.156610000","size":30,"channel_id":23,"order_id":"10998902549936758816","flags":0,"ts_in_delta":723,"sequence":175332,"symbol":"FCEU SI 20260615 PS"}
{"ts_recv":"2026-04-07T02:55:13.081995632Z","hd":{"ts_event":"2026-04-07T02:55:13.081976325Z","rtype":160,"publisher_id":101,"instrument_id":436},"action":"C","side":"A","price":"1.156720000","size":30,"channel_id":23,"order_id":"1775530513052003913","flags":0,"ts_in_delta":723,"sequence":175332,"symbol":"FCEU SI 20260615 PS"}
{"ts_recv":"2026-04-07T02:55:13.081995632Z","hd":{"ts_event":"2026-04-07T02:55:13.081976325Z","rtype":160,"publisher_id":101,"instrument_id":436},"action":"A","side":"A","price":"1.156710000","size":30,"channel_id":23,"order_id":"1775530513081983008","flags":128,"ts_in_delta":723,"sequence":175332,"symbol":"FCEU SI 20260615 PS"}
{"ts_recv":"2026-04-07T02:55:13.082061447Z","hd":{"ts_event":"2026-04-07T02:55:13.082041237Z","rtype":160,"publisher_id":101,"instrument_id":436},"action":"C","side":"B","price":"1.156610000","size":30,"channel_id":23,"order_id":"10998902549936758816","flags":0,"ts_in_delta":730,"sequence":175333,"symbol":"FCEU SI 20260615 PS"}
{"ts_recv":"2026-04-07T02:55:13.082061447Z","hd":{"ts_event":"2026-04-07T02:55:13.082041237Z","rtype":160,"publisher_id":101,"instrument_id":436},"action":"A","side":"B","price":"1.156600000","size":30,"channel_id":23,"order_id":"10998902549936823060","flags":0,"ts_in_delta":730,"sequence":175333,"symbol":"FCEU SI 20260615 PS"}
{"ts_recv":"2026-04-07T02:55:13.082061447Z","hd":{"ts_event":"2026-04-07T02:55:13.082041237Z","rtype":160,"publisher_id":101,"instrument_id":436},"action":"C","side":"A","price":"1.156710000","size":30,"channel_id":23,"order_id":"1775530513081983008","flags":0,"ts_in_delta":730,"sequence":175333,"symbol":"FCEU SI 20260615 PS"}
{"ts_recv":"2026-04-07T02:55:13.082061447Z","hd":{"ts_event":"2026-04-07T02:55:13.082041237Z","rtype":160,"publisher_id":101,"instrument_id":436},"action":"A","side":"A","price":"1.156700000","size":30,"channel_id":23,"order_id":"1775530513082047252","flags":128,"ts_in_delta":730,"sequence":175333,"symbol":"FCEU SI 20260615 PS"}
{"ts_recv":"2026-04-07T02:55:13.082116272Z","hd":{"ts_event":"2026-04-07T02:55:13.082100045Z","rtype":160,"publisher_id":101,"instrument_id":436},"action":"C","side":"B","price":"1.156600000","size":30,"channel_id":23,"order_id":"10998902549936823060","flags":0,"ts_in_delta":736,"sequence":175334,"symbol":"FCEU SI 20260615 PS"}
{"ts_recv":"2026-04-07T02:55:13.082116272Z","hd":{"ts_event":"2026-04-07T02:55:13.082100045Z","rtype":160,"publisher_id":101,"instrument_id":436},"action":"A","side":"B","price":"1.156610000","size":30,"channel_id":23,"order_id":"10998902549936881420","flags":0,"ts_in_delta":736,"sequence":175334,"symbol":"FCEU SI 20260615 PS"}
{"ts_recv":"2026-04-07T02:55:13.082116272Z","hd":{"ts_event":"2026-04-07T02:55:13.082100045Z","rtype":160,"publisher_id":101,"instrument_id":436},"action":"C","side":"A","price":"1.156700000","size":30,"channel_id":23,"order_id":"1775530513082047252","flags":0,"ts_in_delta":736,"sequence":175334,"symbol":"FCEU SI 20260615 PS"}
{"ts_recv":"2026-04-07T02:55:13.082116272Z","hd":{"ts_event":"2026-04-07T02:55:13.082100045Z","rtype":160,"publisher_id":101,"instrument_id":436},"action":"A","side":"A","price":"1.156710000","size":30,"channel_id":23,"order_id":"1775530513082105612","flags":128,"ts_in_delta":736,"sequence":175334,"symbol":"FCEU SI 20260615 PS"}
{"ts_recv":"2026-04-07T02:55:13.082127500Z","hd":{"ts_event":"2026-04-07T02:55:13.082101467Z","rtype":160,"publisher_id":101,"instrument_id":436},"action":"C","side":"B","price":"1.156620000","size":30,"channel_id":23,"order_id":"10998902549906712387","flags":0,"ts_in_delta":731,"sequence":175335,"symbol":"FCEU SI 20260615 PS"}
{"ts_recv":"2026-04-07T02:55:13.082127500Z","hd":{"ts_event":"2026-04-07T02:55:13.082101467Z","rtype":160,"publisher_id":101,"instrument_id":436},"action":"A","side":"B","price":"1.156600000","size":30,"channel_id":23,"order_id":"10998902549936888924","flags":0,"ts_in_delta":731,"sequence":175335,"symbol":"FCEU SI 20260615 PS"}
{"ts_recv":"2026-04-07T02:55:13.082127500Z","hd":{"ts_event":"2026-04-07T02:55:13.082101467Z","rtype":160,"publisher_id":101,"instrument_id":436},"action":"C","side":"A","price":"1.156720000","size":30,"channel_id":23,"order_id":"1775530513051936579","flags":0,"ts_in_delta":731,"sequence":175335,"symbol":"FCEU SI 20260615 PS"}
{"ts_recv":"2026-04-07T02:55:13.082127500Z","hd":{"ts_event":"2026-04-07T02:55:13.082101467Z","rtype":160,"publisher_id":101,"instrument_id":436},"action":"A","side":"A","price":"1.156700000","size":30,"channel_id":23,"order_id":"1775530513082113116","flags":128,"ts_in_delta":731,"sequence":175335,"symbol":"FCEU SI 20260615 PS"}
{"ts_recv":"2026-04-07T02:55:13.082185465Z","hd":{"ts_event":"2026-04-07T02:55:13.082169813Z","rtype":160,"publisher_id":101,"instrument_id":436},"action":"C","side":"B","price":"1.156610000","size":30,"channel_id":23,"order_id":"10998902549936881420","flags":0,"ts_in_delta":706,"sequence":175336,"symbol":"FCEU SI 20260615 PS"}
{"ts_recv":"2026-04-07T02:55:13.082185465Z","hd":{"ts_event":"2026-04-07T02:55:13.082169813Z","rtype":160,"publisher_id":101,"instrument_id":436},"action":"A","side":"B","price":"1.156600000","size":30,"channel_id":23,"order_id":"10998902549936951401","flags":0,"ts_in_delta":706,"sequence":175336,"symbol":"FCEU SI 20260615 PS"}
{"ts_recv":"2026-04-07T02:55:13.082185465Z","hd":{"ts_event":"2026-04-07T02:55:13.082169813Z","rtype":160,"publisher_id":101,"instrument_id":436},"action":"C","side":"A","price":"1.156710000","size":30,"channel_id":23,"order_id":"1775530513082105612","flags":0,"ts_in_delta":706,"sequence":175336,"symbol":"FCEU SI 20260615 PS"}
{"ts_recv":"2026-04-07T02:55:13.082185465Z","hd":{"ts_event":"2026-04-07T02:55:13.082169813Z","rtype":160,"publisher_id":101,"instrument_id":436},"action":"A","side":"A","price":"1.156700000","size":30,"channel_id":23,"order_id":"1775530513082175593","flags":128,"ts_in_delta":706,"sequence":175336,"symbol":"FCEU SI 20260615 PS"}
{"ts_recv":"2026-04-07T02:55:14.466329010Z","hd":{"ts_event":"2026-04-07T02:55:14.466307313Z","rtype":160,"publisher_id":101,"instrument_id":436},"action":"C","side":"B","price":"1.156600000","size":30,"channel_id":23,"order_id":"10998902549936951401","flags":0,"ts_in_delta":1052,"sequence":175361,"symbol":"FCEU SI 20260615 PS"}
{"ts_recv":"2026-04-07T02:55:14.466329010Z","hd":{"ts_event":"2026-04-07T02:55:14.466307313Z","rtype":160,"publisher_id":101,"instrument_id":436},"action":"A","side":"B","price":"1.156610000","size":30,"channel_id":23,"order_id":"10998902551321089161","flags":0,"ts_in_delta":1052,"sequence":175361,"symbol":"FCEU SI 20260615 PS"}
{"ts_recv":"2026-04-07T02:55:14.466329010Z","hd":{"ts_event":"2026-04-07T02:55:14.466307313Z","rtype":160,"publisher_id":101,"instrument_id":436},"action":"C","side":"A","price":"1.156700000","size":30,"channel_id":23,"order_id":"1775530513082175593","flags":0,"ts_in_delta":1052,"sequence":175361,"symbol":"FCEU SI 20260615 PS"}
{"ts_recv":"2026-04-07T02:55:14.466329010Z","hd":{"ts_event":"2026-04-07T02:55:14.466307313Z","rtype":160,"publisher_id":101,"instrument_id":436},"action":"A","side":"A","price":"1.156710000","size":30,"channel_id":23,"order_id":"1775530514466313353","flags":128,"ts_in_delta":1052,"sequence":175361,"symbol":"FCEU SI 20260615 PS"}
{"ts_recv":"2026-04-07T02:55:14.466384404Z","hd":{"ts_event":"2026-04-07T02:55:14.466362251Z","rtype":160,"publisher_id":101,"instrument_id":436},"action":"C","side":"B","price":"1.156600000","size":30,"channel_id":23,"order_id":"10998902549936888924","flags":0,"ts_in_delta":982,"sequence":175362,"symbol":"FCEU SI 20260615 PS"}
{"ts_recv":"2026-04-07T02:55:14.466384404Z","hd":{"ts_event":"2026-04-07T02:55:14.466362251Z","rtype":160,"publisher_id":101,"instrument_id":436},"action":"A","side":"B","price":"1.156620000","size":30,"channel_id":23,"order_id":"10998902551321144151","flags":0,"ts_in_delta":982,"sequence":175362,"symbol":"FCEU SI 20260615 PS"}
{"ts_recv":"2026-04-07T02:55:14.466384404Z","hd":{"ts_event":"2026-04-07T02:55:14.466362251Z","rtype":160,"publisher_id":101,"instrument_id":436},"action":"C","side":"A","price":"1.156700000","size":30,"channel_id":23,"order_id":"1775530513082113116","flags":0,"ts_in_delta":982,"sequence":175362,"symbol":"FCEU SI 20260615 PS"}
{"ts_recv":"2026-04-07T02:55:14.466384404Z","hd":{"ts_event":"2026-04-07T02:55:14.466362251Z","rtype":160,"publisher_id":101,"instrument_id":436},"action":"A","side":"A","price":"1.156720000","size":30,"channel_id":23,"order_id":"1775530514466368343","flags":128,"ts_in_delta":982,"sequence":175362,"symbol":"FCEU SI 20260615 PS"}
{"ts_recv":"2026-04-07T02:55:14.466455502Z","hd":{"ts_event":"2026-04-07T02:55:14.466438367Z","rtype":160,"publisher_id":101,"instrument_id":436},"action":"C","side":"B","price":"1.156610000","size":30,"channel_id":23,"order_id":"10998902551321089161","flags":0,"ts_in_delta":997,"sequence":175364,"symbol":"FCEU SI 20260615 PS"}
{"ts_recv":"2026-04-07T02:55:14.466455502Z","hd":{"ts_event":"2026-04-07T02:55:14.466438367Z","rtype":160,"publisher_id":101,"instrument_id":436},"action":"A","side":"B","price":"1.156620000","size":30,"channel_id":23,"order_id":"10998902551321219958","flags":0,"ts_in_delta":997,"sequence":175364,"symbol":"FCEU SI 20260615 PS"}
{"ts_recv":"2026-04-07T02:55:14.466455502Z","hd":{"ts_event":"2026-04-07T02:55:14.466438367Z","rtype":160,"publisher_id":101,"instrument_id":436},"action":"C","side":"A","price":"1.156710000","size":30,"channel_id":23,"order_id":"1775530514466313353","flags":0,"ts_in_delta":997,"sequence":175364,"symbol":"FCEU SI 20260615 PS"}
{"ts_recv":"2026-04-07T02:55:14.466455502Z","hd":{"ts_event":"2026-04-07T02:55:14.466438367Z","rtype":160,"publisher_id":101,"instrument_id":436},"action":"A","side":"A","price":"1.156720000","size":30,"channel_id":23,"order_id":"1775530514466444150","flags":128,"ts_in_delta":997,"sequence":175364,"symbol":"FCEU SI 20260615 PS"}
{"ts_recv":"2026-04-07T02:55:26.874258841Z","hd":{"ts_event":"2026-04-07T02:55:26.874238169Z","rtype":160,"publisher_id":101,"instrument_id":436},"action":"C","side":"B","price":"1.156620000","size":30,"channel_id":23,"order_id":"10998902551321219958","flags":0,"ts_in_delta":976,"sequence":175470,"symbol":"FCEU SI 20260615 PS"}
{"ts_recv":"2026-04-07T02:55:26.874258841Z","hd":{"ts_event":"2026-04-07T02:55:26.874238169Z","rtype":160,"publisher_id":101,"instrument_id":436},"action":"A","side":"B","price":"1.156610000","size":30,"channel_id":23,"order_id":"10998902563729019759","flags":0,"ts_in_delta":976,"sequence":175470,"symbol":"FCEU SI 20260615 PS"}
{"ts_recv":"2026-04-07T02:55:26.874258841Z","hd":{"ts_event":"2026-04-07T02:55:26.874238169Z","rtype":160,"publisher_id":101,"instrument_id":436},"action":"C","side":"A","price":"1.156720000","size":30,"channel_id":23,"order_id":"1775530514466444150","flags":0,"ts_in_delta":976,"sequence":175470,"symbol":"FCEU SI 20260615 PS"}
{"ts_recv":"2026-04-07T02:55:26.874258841Z","hd":{"ts_event":"2026-04-07T02:55:26.874238169Z","rtype":160,"publisher_id":101,"instrument_id":436},"action":"A","side":"A","price":"1.156710000","size":30,"channel_id":23,"order_id":"1775530526874243951","flags":128,"ts_in_delta":976,"sequence":175470,"symbol":"FCEU SI 20260615 PS"}
{"ts_recv":"2026-04-07T02:55:28.618158867Z","hd":{"ts_event":"2026-04-07T02:55:28.618135377Z","rtype":160,"publisher_id":101,"instrument_id":436},"action":"C","side":"B","price":"1.156610000","size":30,"channel_id":23,"order_id":"10998902563729019759","flags":0,"ts_in_delta":1233,"sequence":175491,"symbol":"FCEU SI 20260615 PS"}
{"ts_recv":"2026-04-07T02:55:28.618158867Z","hd":{"ts_event":"2026-04-07T02:55:28.618135377Z","rtype":160,"publisher_id":101,"instrument_id":436},"action":"A","side":"B","price":"1.156620000","size":30,"channel_id":23,"order_id":"10998902565472922004","flags":0,"ts_in_delta":1233,"sequence":175491,"symbol":"FCEU SI 20260615 PS"}
{"ts_recv":"2026-04-07T02:55:28.618158867Z","hd":{"ts_event":"2026-04-07T02:55:28.618135377Z","rtype":160,"publisher_id":101,"instrument_id":436},"action":"C","side":"A","price":"1.156710000","size":30,"channel_id":23,"order_id":"1775530526874243951","flags":0,"ts_in_delta":1233,"sequence":175491,"symbol":"FCEU SI 20260615 PS"}
{"ts_recv":"2026-04-07T02:55:28.618158867Z","hd":{"ts_event":"2026-04-07T02:55:28.618135377Z","rtype":160,"publisher_id":101,"instrument_id":436},"action":"A","side":"A","price":"1.156720000","size":30,"channel_id":23,"order_id":"1775530528618146196","flags":128,"ts_in_delta":1233,"sequence":175491,"symbol":"FCEU SI 20260615 PS"}
{"ts_recv":"2026-04-07T02:55:44.687546700Z","hd":{"ts_event":"2026-04-07T02:55:44.687521689Z","rtype":160,"publisher_id":101,"instrument_id":436},"action":"C","side":"B","price":"1.156620000","size":30,"channel_id":23,"order_id":"10998902551321144151","flags":0,"ts_in_delta":913,"sequence":175582,"symbol":"FCEU SI 20260615 PS"}
{"ts_recv":"2026-04-07T02:55:44.687546700Z","hd":{"ts_event":"2026-04-07T02:55:44.687521689Z","rtype":160,"publisher_id":101,"instrument_id":436},"action":"A","side":"B","price":"1.156640000","size":30,"channel_id":23,"order_id":"10998902581542304186","flags":0,"ts_in_delta":913,"sequence":175582,"symbol":"FCEU SI 20260615 PS"}
{"ts_recv":"2026-04-07T02:55:44.687546700Z","hd":{"ts_event":"2026-04-07T02:55:44.687521689Z","rtype":160,"publisher_id":101,"instrument_id":436},"action":"C","side":"A","price":"1.156720000","size":30,"channel_id":23,"order_id":"1775530514466368343","flags":0,"ts_in_delta":913,"sequence":175582,"symbol":"FCEU SI 20260615 PS"}
{"ts_recv":"2026-04-07T02:55:44.687546700Z","hd":{"ts_event":"2026-04-07T02:55:44.687521689Z","rtype":160,"publisher_id":101,"instrument_id":436},"action":"A","side":"A","price":"1.156740000","size":30,"channel_id":23,"order_id":"1775530544687528378","flags":128,"ts_in_delta":913,"sequence":175582,"symbol":"FCEU SI 20260615 PS"}
{"ts_recv":"2026-04-07T02:55:44.687662447Z","hd":{"ts_event":"2026-04-07T02:55:44.687640877Z","rtype":160,"publisher_id":101,"instrument_id":436},"action":"C","side":"B","price":"1.156620000","size":30,"channel_id":23,"order_id":"10998902565472922004","flags":0,"ts_in_delta":900,"sequence":175583,"symbol":"FCEU SI 20260615 PS"}
{"ts_recv":"2026-04-07T02:55:44.687662447Z","hd":{"ts_event":"2026-04-07T02:55:44.687640877Z","rtype":160,"publisher_id":101,"instrument_id":436},"action":"A","side":"B","price":"1.156630000","size":30,"channel_id":23,"order_id":"10998902581542422995","flags":0,"ts_in_delta":900,"sequence":175583,"symbol":"FCEU SI 20260615 PS"}
{"ts_recv":"2026-04-07T02:55:44.687662447Z","hd":{"ts_event":"2026-04-07T02:55:44.687640877Z","rtype":160,"publisher_id":101,"instrument_id":436},"action":"C","side":"A","price":"1.156720000","size":30,"channel_id":23,"order_id":"1775530528618146196","flags":0,"ts_in_delta":900,"sequence":175583,"symbol":"FCEU SI 20260615 PS"}
{"ts_recv":"2026-04-07T02:55:44.687662447Z","hd":{"ts_event":"2026-04-07T02:55:44.687640877Z","rtype":160,"publisher_id":101,"instrument_id":436},"action":"A","side":"A","price":"1.156730000","size":30,"channel_id":23,"order_id":"1775530544687647187","flags":128,"ts_in_delta":900,"sequence":175583,"symbol":"FCEU SI 20260615 PS"}
{"ts_recv":"2026-04-07T02:55:44.687824926Z","hd":{"ts_event":"2026-04-07T02:55:44.687805257Z","rtype":160,"publisher_id":101,"instrument_id":436},"action":"C","side":"B","price":"1.156630000","size":30,"channel_id":23,"order_id":"10998902581542422995","flags":0,"ts_in_delta":916,"sequence":175584,"symbol":"FCEU SI 20260615 PS"}
{"ts_recv":"2026-04-07T02:55:44.687824926Z","hd":{"ts_event":"2026-04-07T02:55:44.687805257Z","rtype":160,"publisher_id":101,"instrument_id":436},"action":"A","side":"B","price":"1.156640000","size":30,"channel_id":23,"order_id":"10998902581542586974","flags":0,"ts_in_delta":916,"sequence":175584,"symbol":"FCEU SI 20260615 PS"}
{"ts_recv":"2026-04-07T02:55:44.687824926Z","hd":{"ts_event":"2026-04-07T02:55:44.687805257Z","rtype":160,"publisher_id":101,"instrument_id":436},"action":"C","side":"A","price":"1.156730000","size":30,"channel_id":23,"order_id":"1775530544687647187","flags":0,"ts_in_delta":916,"sequence":175584,"symbol":"FCEU SI 20260615 PS"}
{"ts_recv":"2026-04-07T02:55:44.687824926Z","hd":{"ts_event":"2026-04-07T02:55:44.687805257Z","rtype":160,"publisher_id":101,"instrument_id":436},"action":"A","side":"A","price":"1.156740000","size":30,"channel_id":23,"order_id":"1775530544687811166","flags":128,"ts_in_delta":916,"sequence":175584,"symbol":"FCEU SI 20260615 PS"}
{"ts_recv":"2026-04-07T02:55:44.697144110Z","hd":{"ts_event":"2026-04-07T02:55:44.697123809Z","rtype":160,"publisher_id":101,"instrument_id":436},"action":"C","side":"B","price":"1.156640000","size":30,"channel_id":23,"order_id":"10998902581542586974","flags":0,"ts_in_delta":970,"sequence":175596,"symbol":"FCEU SI 20260615 PS"}
{"ts_recv":"2026-04-07T02:55:44.697144110Z","hd":{"ts_event":"2026-04-07T02:55:44.697123809Z","rtype":160,"publisher_id":101,"instrument_id":436},"action":"A","side":"B","price":"1.156630000","size":30,"channel_id":23,"order_id":"10998902581551905823","flags":0,"ts_in_delta":970,"sequence":175596,"symbol":"FCEU SI 20260615 PS"}
{"ts_recv":"2026-04-07T02:55:44.697144110Z","hd":{"ts_event":"2026-04-07T02:55:44.697123809Z","rtype":160,"publisher_id":101,"instrument_id":436},"action":"C","side":"A","price":"1.156740000","size":30,"channel_id":23,"order_id":"1775530544687811166","flags":0,"ts_in_delta":970,"sequence":175596,"symbol":"FCEU SI 20260615 PS"}
{"ts_recv":"2026-04-07T02:55:44.697144110Z","hd":{"ts_event":"2026-04-07T02:55:44.697123809Z","rtype":160,"publisher_id":101,"instrument_id":436},"action":"A","side":"A","price":"1.156730000","size":30,"channel_id":23,"order_id":"1775530544697130015","flags":128,"ts_in_delta":970,"sequence":175596,"symbol":"FCEU SI 20260615 PS"}
{"ts_recv":"2026-04-07T02:55:44.697228363Z","hd":{"ts_event":"2026-04-07T02:55:44.697208737Z","rtype":160,"publisher_id":101,"instrument_id":436},"action":"C","side":"B","price":"1.156630000","size":30,"channel_id":23,"order_id":"10998902581551905823","flags":0,"ts_in_delta":896,"sequence":175597,"symbol":"FCEU SI 20260615 PS"}
{"ts_recv":"2026-04-07T02:55:44.697228363Z","hd":{"ts_event":"2026-04-07T02:55:44.697208737Z","rtype":160,"publisher_id":101,"instrument_id":436},"action":"A","side":"B","price":"1.156620000","size":30,"channel_id":23,"order_id":"10998902581551990392","flags":0,"ts_in_delta":896,"sequence":175597,"symbol":"FCEU SI 20260615 PS"}
{"ts_recv":"2026-04-07T02:55:44.697228363Z","hd":{"ts_event":"2026-04-07T02:55:44.697208737Z","rtype":160,"publisher_id":101,"instrument_id":436},"action":"C","side":"A","price":"1.156730000","size":30,"channel_id":23,"order_id":"1775530544697130015","flags":0,"ts_in_delta":896,"sequence":175597,"symbol":"FCEU SI 20260615 PS"}
{"ts_recv":"2026-04-07T02:55:44.697228363Z","hd":{"ts_event":"2026-04-07T02:55:44.697208737Z","rtype":160,"publisher_id":101,"instrument_id":436},"action":"A","side":"A","price":"1.156720000","size":30,"channel_id":23,"order_id":"1775530544697214584","flags":128,"ts_in_delta":896,"sequence":175597,"symbol":"FCEU SI 20260615 PS"}
{"ts_recv":"2026-04-07T02:55:44.697284593Z","hd":{"ts_event":"2026-04-07T02:55:44.697268085Z","rtype":160,"publisher_id":101,"instrument_id":436},"action":"C","side":"B","price":"1.156620000","size":30,"channel_id":23,"order_id":"10998902581551990392","flags":0,"ts_in_delta":874,"sequence":175598,"symbol":"FCEU SI 20260615 PS"}
{"ts_recv":"2026-04-07T02:55:44.697284593Z","hd":{"ts_event":"2026-04-07T02:55:44.697268085Z","rtype":160,"publisher_id":101,"instrument_id":436},"action":"A","side":"B","price":"1.156630000","size":30,"channel_id":23,"order_id":"10998902581552049996","flags":0,"ts_in_delta":874,"sequence":175598,"symbol":"FCEU SI 20260615 PS"}
{"ts_recv":"2026-04-07T02:55:44.697284593Z","hd":{"ts_event":"2026-04-07T02:55:44.697268085Z","rtype":160,"publisher_id":101,"instrument_id":436},"action":"C","side":"A","price":"1.156720000","size":30,"channel_id":23,"order_id":"1775530544697214584","flags":0,"ts_in_delta":874,"sequence":175598,"symbol":"FCEU SI 20260615 PS"}
{"ts_recv":"2026-04-07T02:55:44.697284593Z","hd":{"ts_event":"2026-04-07T02:55:44.697268085Z","rtype":160,"publisher_id":101,"instrument_id":436},"action":"A","side":"A","price":"1.156730000","size":30,"channel_id":23,"order_id":"1775530544697274188","flags":128,"ts_in_delta":874,"sequence":175598,"symbol":"FCEU SI 20260615 PS"}
{"ts_recv":"2026-04-07T02:55:44.702437399Z","hd":{"ts_event":"2026-04-07T02:55:44.702420585Z","rtype":160,"publisher_id":101,"instrument_id":436},"action":"C","side":"B","price":"1.156630000","size":30,"channel_id":23,"order_id":"10998902581552049996","flags":0,"ts_in_delta":907,"sequence":175604,"symbol":"FCEU SI 20260615 PS"}
{"ts_recv":"2026-04-07T02:55:44.702437399Z","hd":{"ts_event":"2026-04-07T02:55:44.702420585Z","rtype":160,"publisher_id":101,"instrument_id":436},"action":"A","side":"B","price":"1.156620000","size":30,"channel_id":23,"order_id":"10998902581557202230","flags":0,"ts_in_delta":907,"sequence":175604,"symbol":"FCEU SI 20260615 PS"}
{"ts_recv":"2026-04-07T02:55:44.702437399Z","hd":{"ts_event":"2026-04-07T02:55:44.702420585Z","rtype":160,"publisher_id":101,"instrument_id":436},"action":"C","side":"A","price":"1.156730000","size":30,"channel_id":23,"order_id":"1775530544697274188","flags":0,"ts_in_delta":907,"sequence":175604,"symbol":"FCEU SI 20260615 PS"}
{"ts_recv":"2026-04-07T02:55:44.702437399Z","hd":{"ts_event":"2026-04-07T02:55:44.702420585Z","rtype":160,"publisher_id":101,"instrument_id":436},"action":"A","side":"A","price":"1.156720000","size":30,"channel_id":23,"order_id":"1775530544702426422","flags":128,"ts_in_delta":907,"sequence":175604,"symbol":"FCEU SI 20260615 PS"}
{"ts_recv":"2026-04-07T02:55:44.702486234Z","hd":{"ts_event":"2026-04-07T02:55:44.702469141Z","rtype":160,"publisher_id":101,"instrument_id":436},"action":"C","side":"B","price":"1.156640000","size":30,"channel_id":23,"order_id":"10998902581542304186","flags":0,"ts_in_delta":876,"sequence":175605,"symbol":"FCEU SI 20260615 PS"}
{"ts_recv":"2026-04-07T02:55:44.702486234Z","hd":{"ts_event":"2026-04-07T02:55:44.702469141Z","rtype":160,"publisher_id":101,"instrument_id":436},"action":"A","side":"B","price":"1.156620000","size":30,"channel_id":23,"order_id":"10998902581557250712","flags":0,"ts_in_delta":876,"sequence":175605,"symbol":"FCEU SI 20260615 PS"}
{"ts_recv":"2026-04-07T02:55:44.702486234Z","hd":{"ts_event":"2026-04-07T02:55:44.702469141Z","rtype":160,"publisher_id":101,"instrument_id":436},"action":"C","side":"A","price":"1.156740000","size":30,"channel_id":23,"order_id":"1775530544687528378","flags":0,"ts_in_delta":876,"sequence":175605,"symbol":"FCEU SI 20260615 PS"}
{"ts_recv":"2026-04-07T02:55:44.702486234Z","hd":{"ts_event":"2026-04-07T02:55:44.702469141Z","rtype":160,"publisher_id":101,"instrument_id":436},"action":"A","side":"A","price":"1.156720000","size":30,"channel_id":23,"order_id":"1775530544702474904","flags":128,"ts_in_delta":876,"sequence":175605,"symbol":"FCEU SI 20260615 PS"}
{"ts_recv":"2026-04-07T02:55:44.702540583Z","hd":{"ts_event":"2026-04-07T02:55:44.702521845Z","rtype":160,"publisher_id":101,"instrument_id":436},"action":"C","side":"B","price":"1.156620000","size":30,"channel_id":23,"order_id":"10998902581557202230","flags":0,"ts_in_delta":856,"sequence":175606,"symbol":"FCEU SI 20260615 PS"}
{"ts_recv":"2026-04-07T02:55:44.702540583Z","hd":{"ts_event":"2026-04-07T02:55:44.702521845Z","rtype":160,"publisher_id":101,"instrument_id":436},"action":"A","side":"B","price":"1.156610000","size":30,"channel_id":23,"order_id":"10998902581557303714","flags":0,"ts_in_delta":856,"sequence":175606,"symbol":"FCEU SI 20260615 PS"}
{"ts_recv":"2026-04-07T02:55:44.702540583Z","hd":{"ts_event":"2026-04-07T02:55:44.702521845Z","rtype":160,"publisher_id":101,"instrument_id":436},"action":"C","side":"A","price":"1.156720000","size":30,"channel_id":23,"order_id":"1775530544702426422","flags":0,"ts_in_delta":856,"sequence":175606,"symbol":"FCEU SI 20260615 PS"}
{"ts_recv":"2026-04-07T02:55:44.702540583Z","hd":{"ts_event":"2026-04-07T02:55:44.702521845Z","rtype":160,"publisher_id":101,"instrument_id":436},"action":"A","side":"A","price":"1.156710000","size":30,"channel_id":23,"order_id":"1775530544702527906","flags":128,"ts_in_delta":856,"sequence":175606,"symbol":"FCEU SI 20260615 PS"}
{"ts_recv":"2026-04-07T02:55:44.811502469Z","hd":{"ts_event":"2026-04-07T02:55:44.811483091Z","rtype":160,"publisher_id":101,"instrument_id":436},"action":"C","side":"B","price":"1.156620000","size":30,"channel_id":23,"order_id":"10998902581557250712","flags":0,"ts_in_delta":883,"sequence":175634,"symbol":"FCEU SI 20260615 PS"}
{"ts_recv":"2026-04-07T02:55:44.811502469Z","hd":{"ts_event":"2026-04-07T02:55:44.811483091Z","rtype":160,"publisher_id":101,"instrument_id":436},"action":"A","side":"B","price":"1.156600000","size":30,"channel_id":23,"order_id":"10998902581666265407","flags":0,"ts_in_delta":883,"sequence":175634,"symbol":"FCEU SI 20260615 PS"}
{"ts_recv":"2026-04-07T02:55:44.811502469Z","hd":{"ts_event":"2026-04-07T02:55:44.811483091Z","rtype":160,"publisher_id":101,"instrument_id":436},"action":"C","side":"A","price":"1.156720000","size":30,"channel_id":23,"order_id":"1775530544702474904","flags":0,"ts_in_delta":883,"sequence":175634,"symbol":"FCEU SI 20260615 PS"}
{"ts_recv":"2026-04-07T02:55:44.811502469Z","hd":{"ts_event":"2026-04-07T02:55:44.811483091Z","rtype":160,"publisher_id":101,"instrument_id":436},"action":"A","side":"A","price":"1.156700000","size":30,"channel_id":23,"order_id":"1775530544811489599","flags":128,"ts_in_delta":883,"sequence":175634,"symbol":"FCEU SI 20260615 PS"}
{"ts_recv":"2026-04-07T02:55:44.811564828Z","hd":{"ts_event":"2026-04-07T02:55:44.811547199Z","rtype":160,"publisher_id":101,"instrument_id":436},"action":"C","side":"B","price":"1.156610000","size":30,"channel_id":23,"order_id":"10998902581557303714","flags":0,"ts_in_delta":874,"sequence":175635,"symbol":"FCEU SI 20260615 PS"}
{"ts_recv":"2026-04-07T02:55:44.811564828Z","hd":{"ts_event":"2026-04-07T02:55:44.811547199Z","rtype":160,"publisher_id":101,"instrument_id":436},"action":"A","side":"B","price":"1.156600000","size":30,"channel_id":23,"order_id":"10998902581666329098","flags":0,"ts_in_delta":874,"sequence":175635,"symbol":"FCEU SI 20260615 PS"}
{"ts_recv":"2026-04-07T02:55:44.811564828Z","hd":{"ts_event":"2026-04-07T02:55:44.811547199Z","rtype":160,"publisher_id":101,"instrument_id":436},"action":"C","side":"A","price":"1.156710000","size":30,"channel_id":23,"order_id":"1775530544702527906","flags":0,"ts_in_delta":874,"sequence":175635,"symbol":"FCEU SI 20260615 PS"}
{"ts_recv":"2026-04-07T02:55:44.811564828Z","hd":{"ts_event":"2026-04-07T02:55:44.811547199Z","rtype":160,"publisher_id":101,"instrument_id":436},"action":"A","side":"A","price":"1.156700000","size":30,"channel_id":23,"order_id":"1775530544811553290","flags":128,"ts_in_delta":874,"sequence":175635,"symbol":"FCEU SI 20260615 PS"}
{"ts_recv":"2026-04-07T02:55:50.650864139Z","hd":{"ts_event":"2026-04-07T02:55:50.650842927Z","rtype":160,"publisher_id":101,"instrument_id":436},"action":"C","side":"B","price":"1.156600000","size":30,"channel_id":23,"order_id":"10998902581666329098","flags":0,"ts_in_delta":917,"sequence":175678,"symbol":"FCEU SI 20260615 PS"}
{"ts_recv":"2026-04-07T02:55:50.650864139Z","hd":{"ts_event":"2026-04-07T02:55:50.650842927Z","rtype":160,"publisher_id":101,"instrument_id":436},"action":"A","side":"B","price":"1.156590000","size":30,"channel_id":23,"order_id":"10998902587505624721","flags":0,"ts_in_delta":917,"sequence":175678,"symbol":"FCEU SI 20260615 PS"}
{"ts_recv":"2026-04-07T02:55:50.650864139Z","hd":{"ts_event":"2026-04-07T02:55:50.650842927Z","rtype":160,"publisher_id":101,"instrument_id":436},"action":"C","side":"A","price":"1.156700000","size":30,"channel_id":23,"order_id":"1775530544811553290","flags":0,"ts_in_delta":917,"sequence":175678,"symbol":"FCEU SI 20260615 PS"}
{"ts_recv":"2026-04-07T02:55:50.650864139Z","hd":{"ts_event":"2026-04-07T02:55:50.650842927Z","rtype":160,"publisher_id":101,"instrument_id":436},"action":"A","side":"A","price":"1.156690000","size":30,"channel_id":23,"order_id":"1775530550650848913","flags":128,"ts_in_delta":917,"sequence":175678,"symbol":"FCEU SI 20260615 PS"}
{"ts_recv":"2026-04-07T02:55:50.650922965Z","hd":{"ts_event":"2026-04-07T02:55:50.650902735Z","rtype":160,"publisher_id":101,"instrument_id":436},"action":"C","side":"B","price":"1.156600000","size":30,"channel_id":23,"order_id":"10998902581666265407","flags":0,"ts_in_delta":909,"sequence":175679,"symbol":"FCEU SI 20260615 PS"}
{"ts_recv":"2026-04-07T02:55:50.650922965Z","hd":{"ts_event":"2026-04-07T02:55:50.650902735Z","rtype":160,"publisher_id":101,"instrument_id":436},"action":"A","side":"B","price":"1.156580000","size":30,"channel_id":23,"order_id":"10998902587505684699","flags":0,"ts_in_delta":909,"sequence":175679,"symbol":"FCEU SI 20260615 PS"}
{"ts_recv":"2026-04-07T02:55:50.650922965Z","hd":{"ts_event":"2026-04-07T02:55:50.650902735Z","rtype":160,"publisher_id":101,"instrument_id":436},"action":"C","side":"A","price":"1.156700000","size":30,"channel_id":23,"order_id":"1775530544811489599","flags":0,"ts_in_delta":909,"sequence":175679,"symbol":"FCEU SI 20260615 PS"}
{"ts_recv":"2026-04-07T02:55:50.650922965Z","hd":{"ts_event":"2026-04-07T02:55:50.650902735Z","rtype":160,"publisher_id":101,"instrument_id":436},"action":"A","side":"A","price":"1.156680000","size":30,"channel_id":23,"order_id":"1775530550650908891","flags":128,"ts_in_delta":909,"sequence":175679,"symbol":"FCEU SI 20260615 PS"}
{"ts_recv":"2026-04-07T02:55:50.650977444Z","hd":{"ts_event":"2026-04-07T02:55:50.650959113Z","rtype":160,"publisher_id":101,"instrument_id":436},"action":"C","side":"B","price":"1.156590000","size":30,"channel_id":23,"order_id":"10998902587505624721","flags":0,"ts_in_delta":937,"sequence":175680,"symbol":"FCEU SI 20260615 PS"}
{"ts_recv":"2026-04-07T02:55:50.650977444Z","hd":{"ts_event":"2026-04-07T02:55:50.650959113Z","rtype":160,"publisher_id":101,"instrument_id":436},"action":"A","side":"B","price":"1.156580000","size":30,"channel_id":23,"order_id":"10998902587505740584","flags":0,"ts_in_delta":937,"sequence":175680,"symbol":"FCEU SI 20260615 PS"}
{"ts_recv":"2026-04-07T02:55:50.650977444Z","hd":{"ts_event":"2026-04-07T02:55:50.650959113Z","rtype":160,"publisher_id":101,"instrument_id":436},"action":"C","side":"A","price":"1.156690000","size":30,"channel_id":23,"order_id":"1775530550650848913","flags":0,"ts_in_delta":937,"sequence":175680,"symbol":"FCEU SI 20260615 PS"}
{"ts_recv":"2026-04-07T02:55:50.650977444Z","hd":{"ts_event":"2026-04-07T02:55:50.650959113Z","rtype":160,"publisher_id":101,"instrument_id":436},"action":"A","side":"A","price":"1.156680000","size":30,"channel_id":23,"order_id":"1775530550650964776","flags":128,"ts_in_delta":937,"sequence":175680,"symbol":"FCEU SI 20260615 PS"}
{"ts_recv":"2026-04-07T02:55:50.660254046Z","hd":{"ts_event":"2026-04-07T02:55:50.660234619Z","rtype":160,"publisher_id":101,"instrument_id":436},"action":"C","side":"B","price":"1.156580000","size":30,"channel_id":23,"order_id":"10998902587505684699","flags":0,"ts_in_delta":936,"sequence":175688,"symbol":"FCEU SI 20260615 PS"}
{"ts_recv":"2026-04-07T02:55:50.660254046Z","hd":{"ts_event":"2026-04-07T02:55:50.660234619Z","rtype":160,"publisher_id":101,"instrument_id":436},"action":"A","side":"B","price":"1.156560000","size":30,"channel_id":23,"order_id":"10998902587515016599","flags":0,"ts_in_delta":936,"sequence":175688,"symbol":"FCEU SI 20260615 PS"}
{"ts_recv":"2026-04-07T02:55:50.660254046Z","hd":{"ts_event":"2026-04-07T02:55:50.660234619Z","rtype":160,"publisher_id":101,"instrument_id":436},"action":"C","side":"A","price":"1.156680000","size":30,"channel_id":23,"order_id":"1775530550650908891","flags":0,"ts_in_delta":936,"sequence":175688,"symbol":"FCEU SI 20260615 PS"}
{"ts_recv":"2026-04-07T02:55:50.660254046Z","hd":{"ts_event":"2026-04-07T02:55:50.660234619Z","rtype":160,"publisher_id":101,"instrument_id":436},"action":"A","side":"A","price":"1.156660000","size":30,"channel_id":23,"order_id":"1775530550660240791","flags":128,"ts_in_delta":936,"sequence":175688,"symbol":"FCEU SI 20260615 PS"}
{"ts_recv":"2026-04-07T02:55:50.660293366Z","hd":{"ts_event":"2026-04-07T02:55:50.660277819Z","rtype":160,"publisher_id":101,"instrument_id":436},"action":"C","side":"B","price":"1.156580000","size":30,"channel_id":23,"order_id":"10998902587505740584","flags":0,"ts_in_delta":906,"sequence":175689,"symbol":"FCEU SI 20260615 PS"}
{"ts_recv":"2026-04-07T02:55:50.660293366Z","hd":{"ts_event":"2026-04-07T02:55:50.660277819Z","rtype":160,"publisher_id":101,"instrument_id":436},"action":"A","side":"B","price":"1.156570000","size":30,"channel_id":23,"order_id":"10998902587515059429","flags":0,"ts_in_delta":906,"sequence":175689,"symbol":"FCEU SI 20260615 PS"}
{"ts_recv":"2026-04-07T02:55:50.660293366Z","hd":{"ts_event":"2026-04-07T02:55:50.660277819Z","rtype":160,"publisher_id":101,"instrument_id":436},"action":"C","side":"A","price":"1.156680000","size":30,"channel_id":23,"order_id":"1775530550650964776","flags":0,"ts_in_delta":906,"sequence":175689,"symbol":"FCEU SI 20260615 PS"}
{"ts_recv":"2026-04-07T02:55:50.660293366Z","hd":{"ts_event":"2026-04-07T02:55:50.660277819Z","rtype":160,"publisher_id":101,"instrument_id":436},"action":"A","side":"A","price":"1.156670000","size":30,"channel_id":23,"order_id":"1775530550660283621","flags":128,"ts_in_delta":906,"sequence":175689,"symbol":"FCEU SI 20260615 PS"}
{"ts_recv":"2026-04-07T02:55:50.660368365Z","hd":{"ts_event":"2026-04-07T02:55:50.660351431Z","rtype":160,"publisher_id":101,"instrument_id":436},"action":"C","side":"B","price":"1.156570000","size":30,"channel_id":23,"order_id":"10998902587515059429","flags":0,"ts_in_delta":931,"sequence":175690,"symbol":"FCEU SI 20260615 PS"}
{"ts_recv":"2026-04-07T02:55:50.660368365Z","hd":{"ts_event":"2026-04-07T02:55:50.660351431Z","rtype":160,"publisher_id":101,"instrument_id":436},"action":"A","side":"B","price":"1.156560000","size":30,"channel_id":23,"order_id":"10998902587515133305","flags":0,"ts_in_delta":931,"sequence":175690,"symbol":"FCEU SI 20260615 PS"}
{"ts_recv":"2026-04-07T02:55:50.660368365Z","hd":{"ts_event":"2026-04-07T02:55:50.660351431Z","rtype":160,"publisher_id":101,"instrument_id":436},"action":"C","side":"A","price":"1.156670000","size":30,"channel_id":23,"order_id":"1775530550660283621","flags":0,"ts_in_delta":931,"sequence":175690,"symbol":"FCEU SI 20260615 PS"}
{"ts_recv":"2026-04-07T02:55:50.660368365Z","hd":{"ts_event":"2026-04-07T02:55:50.660351431Z","rtype":160,"publisher_id":101,"instrument_id":436},"action":"A","side":"A","price":"1.156660000","size":30,"channel_id":23,"order_id":"1775530550660357497","flags":128,"ts_in_delta":931,"sequence":175690,"symbol":"FCEU SI 20260615 PS"}
{"ts_recv":"2026-04-07T02:55:50.665156549Z","hd":{"ts_event":"2026-04-07T02:55:50.665137817Z","rtype":160,"publisher_id":101,"instrument_id":436},"action":"C","side":"B","price":"1.156560000","size":30,"channel_id":23,"order_id":"10998902587515133305","flags":0,"ts_in_delta":907,"sequence":175692,"symbol":"FCEU SI 20260615 PS"}
{"ts_recv":"2026-04-07T02:55:50.665156549Z","hd":{"ts_event":"2026-04-07T02:55:50.665137817Z","rtype":160,"publisher_id":101,"instrument_id":436},"action":"A","side":"B","price":"1.156550000","size":30,"channel_id":23,"order_id":"10998902587519919725","flags":0,"ts_in_delta":907,"sequence":175692,"symbol":"FCEU SI 20260615 PS"}
{"ts_recv":"2026-04-07T02:55:50.665156549Z","hd":{"ts_event":"2026-04-07T02:55:50.665137817Z","rtype":160,"publisher_id":101,"instrument_id":436},"action":"C","side":"A","price":"1.156660000","size":30,"channel_id":23,"order_id":"1775530550660357497","flags":0,"ts_in_delta":907,"sequence":175692,"symbol":"FCEU SI 20260615 PS"}
{"ts_recv":"2026-04-07T02:55:50.665156549Z","hd":{"ts_event":"2026-04-07T02:55:50.665137817Z","rtype":160,"publisher_id":101,"instrument_id":436},"action":"A","side":"A","price":"1.156650000","size":30,"channel_id":23,"order_id":"1775530550665143917","flags":128,"ts_in_delta":907,"sequence":175692,"symbol":"FCEU SI 20260615 PS"}
{"ts_recv":"2026-04-07T02:55:50.670050145Z","hd":{"ts_event":"2026-04-07T02:55:50.670029743Z","rtype":160,"publisher_id":101,"instrument_id":436},"action":"C","side":"B","price":"1.156550000","size":30,"channel_id":23,"order_id":"10998902587519919725","flags":0,"ts_in_delta":741,"sequence":175698,"symbol":"FCEU SI 20260615 PS"}
{"ts_recv":"2026-04-07T02:55:50.670050145Z","hd":{"ts_event":"2026-04-07T02:55:50.670029743Z","rtype":160,"publisher_id":101,"instrument_id":436},"action":"A","side":"B","price":"1.156570000","size":30,"channel_id":23,"order_id":"10998902587524811825","flags":0,"ts_in_delta":741,"sequence":175698,"symbol":"FCEU SI 20260615 PS"}
{"ts_recv":"2026-04-07T02:55:50.670050145Z","hd":{"ts_event":"2026-04-07T02:55:50.670029743Z","rtype":160,"publisher_id":101,"instrument_id":436},"action":"C","side":"A","price":"1.156650000","size":30,"channel_id":23,"order_id":"1775530550665143917","flags":0,"ts_in_delta":741,"sequence":175698,"symbol":"FCEU SI 20260615 PS"}
{"ts_recv":"2026-04-07T02:55:50.670050145Z","hd":{"ts_event":"2026-04-07T02:55:50.670029743Z","rtype":160,"publisher_id":101,"instrument_id":436},"action":"A","side":"A","price":"1.156670000","size":30,"channel_id":23,"order_id":"1775530550670036017","flags":128,"ts_in_delta":741,"sequence":175698,"symbol":"FCEU SI 20260615 PS"}
{"ts_recv":"2026-04-07T02:55:50.674778727Z","hd":{"ts_event":"2026-04-07T02:55:50.674762181Z","rtype":160,"publisher_id":101,"instrument_id":436},"action":"C","side":"B","price":"1.156570000","size":30,"channel_id":23,"order_id":"10998902587524811825","flags":0,"ts_in_delta":810,"sequence":175699,"symbol":"FCEU SI 20260615 PS"}
{"ts_recv":"2026-04-07T02:55:50.674778727Z","hd":{"ts_event":"2026-04-07T02:55:50.674762181Z","rtype":160,"publisher_id":101,"instrument_id":436},"action":"A","side":"B","price":"1.156560000","size":30,"channel_id":23,"order_id":"10998902587529543588","flags":0,"ts_in_delta":810,"sequence":175699,"symbol":"FCEU SI 20260615 PS"}
{"ts_recv":"2026-04-07T02:55:50.674778727Z","hd":{"ts_event":"2026-04-07T02:55:50.674762181Z","rtype":160,"publisher_id":101,"instrument_id":436},"action":"C","side":"A","price":"1.156670000","size":30,"channel_id":23,"order_id":"1775530550670036017","flags":0,"ts_in_delta":810,"sequence":175699,"symbol":"FCEU SI 20260615 PS"}
{"ts_recv":"2026-04-07T02:55:50.674778727Z","hd":{"ts_event":"2026-04-07T02:55:50.674762181Z","rtype":160,"publisher_id":101,"instrument_id":436},"action":"A","side":"A","price":"1.156660000","size":30,"channel_id":23,"order_id":"1775530550674767780","flags":128,"ts_in_delta":810,"sequence":175699,"symbol":"FCEU SI 20260615 PS"}
{"ts_recv":"2026-04-07T02:55:50.682906760Z","hd":{"ts_event":"2026-04-07T02:55:50.682887885Z","rtype":160,"publisher_id":101,"instrument_id":436},"action":"C","side":"B","price":"1.156560000","size":30,"channel_id":23,"order_id":"10998902587529543588","flags":0,"ts_in_delta":759,"sequence":175704,"symbol":"FCEU SI 20260615 PS"}
{"ts_recv":"2026-04-07T02:55:50.682906760Z","hd":{"ts_event":"2026-04-07T02:55:50.682887885Z","rtype":160,"publisher_id":101,"instrument_id":436},"action":"A","side":"B","price":"1.156570000","size":30,"channel_id":23,"order_id":"10998902587537669810","flags":0,"ts_in_delta":759,"sequence":175704,"symbol":"FCEU SI 20260615 PS"}
{"ts_recv":"2026-04-07T02:55:50.682906760Z","hd":{"ts_event":"2026-04-07T02:55:50.682887885Z","rtype":160,"publisher_id":101,"instrument_id":436},"action":"C","side":"A","price":"1.156660000","size":30,"channel_id":23,"order_id":"1775530550674767780","flags":0,"ts_in_delta":759,"sequence":175704,"symbol":"FCEU SI 20260615 PS"}
{"ts_recv":"2026-04-07T02:55:50.682906760Z","hd":{"ts_event":"2026-04-07T02:55:50.682887885Z","rtype":160,"publisher_id":101,"instrument_id":436},"action":"A","side":"A","price":"1.156670000","size":30,"channel_id":23,"order_id":"1775530550682894002","flags":128,"ts_in_delta":759,"sequence":175704,"symbol":"FCEU SI 20260615 PS"}
{"ts_recv":"2026-04-07T02:55:50.682959720Z","hd":{"ts_event":"2026-04-07T02:55:50.682939879Z","rtype":160,"publisher_id":101,"instrument_id":436},"action":"C","side":"B","price":"1.156560000","size":30,"channel_id":23,"order_id":"10998902587515016599","flags":0,"ts_in_delta":744,"sequence":175705,"symbol":"FCEU SI 20260615 PS"}
{"ts_recv":"2026-04-07T02:55:50.682959720Z","hd":{"ts_event":"2026-04-07T02:55:50.682939879Z","rtype":160,"publisher_id":101,"instrument_id":436},"action":"A","side":"B","price":"1.156580000","size":30,"channel_id":23,"order_id":"10998902587537721688","flags":0,"ts_in_delta":744,"sequence":175705,"symbol":"FCEU SI 20260615 PS"}
{"ts_recv":"2026-04-07T02:55:50.682959720Z","hd":{"ts_event":"2026-04-07T02:55:50.682939879Z","rtype":160,"publisher_id":101,"instrument_id":436},"action":"C","side":"A","price":"1.156660000","size":30,"channel_id":23,"order_id":"1775530550660240791","flags":0,"ts_in_delta":744,"sequence":175705,"symbol":"FCEU SI 20260615 PS"}
{"ts_recv":"2026-04-07T02:55:50.682959720Z","hd":{"ts_event":"2026-04-07T02:55:50.682939879Z","rtype":160,"publisher_id":101,"instrument_id":436},"action":"A","side":"A","price":"1.156680000","size":30,"channel_id":23,"order_id":"1775530550682945880","flags":128,"ts_in_delta":744,"sequence":175705,"symbol":"FCEU SI 20260615 PS"}
{"ts_recv":"2026-04-07T02:55:50.683013109Z","hd":{"ts_event":"2026-04-07T02:55:50.682996269Z","rtype":160,"publisher_id":101,"instrument_id":436},"action":"C","side":"B","price":"1.156570000","size":30,"channel_id":23,"order_id":"10998902587537669810","flags":0,"ts_in_delta":1057,"sequence":175706,"symbol":"FCEU SI 20260615 PS"}
{"ts_recv":"2026-04-07T02:55:50.683013109Z","hd":{"ts_event":"2026-04-07T02:55:50.682996269Z","rtype":160,"publisher_id":101,"instrument_id":436},"action":"A","side":"B","price":"1.156580000","size":30,"channel_id":23,"order_id":"10998902587537778199","flags":0,"ts_in_delta":1057,"sequence":175706,"symbol":"FCEU SI 20260615 PS"}
{"ts_recv":"2026-04-07T02:55:50.683013109Z","hd":{"ts_event":"2026-04-07T02:55:50.682996269Z","rtype":160,"publisher_id":101,"instrument_id":436},"action":"C","side":"A","price":"1.156670000","size":30,"channel_id":23,"order_id":"1775530550682894002","flags":0,"ts_in_delta":1057,"sequence":175706,"symbol":"FCEU SI 20260615 PS"}
{"ts_recv":"2026-04-07T02:55:50.683013109Z","hd":{"ts_event":"2026-04-07T02:55:50.682996269Z","rtype":160,"publisher_id":101,"instrument_id":436},"action":"A","side":"A","price":"1.156680000","size":30,"channel_id":23,"order_id":"1775530550683002391","flags":128,"ts_in_delta":1057,"sequence":175706,"symbol":"FCEU SI 20260615 PS"}
{"ts_recv":"2026-04-07T02:56:10.047876733Z","hd":{"ts_event":"2026-04-07T02:56:10.047846527Z","rtype":160,"publisher_id":101,"instrument_id":436},"action":"C","side":"B","price":"1.156580000","size":30,"channel_id":23,"order_id":"10998902587537778199","flags":0,"ts_in_delta":1330,"sequence":175908,"symbol":"FCEU SI 20260615 PS"}
{"ts_recv":"2026-04-07T02:56:10.047876733Z","hd":{"ts_event":"2026-04-07T02:56:10.047846527Z","rtype":160,"publisher_id":101,"instrument_id":436},"action":"A","side":"B","price":"1.156590000","size":30,"channel_id":23,"order_id":"10998902606902631241","flags":0,"ts_in_delta":1330,"sequence":175908,"symbol":"FCEU SI 20260615 PS"}
{"ts_recv":"2026-04-07T02:56:10.047876733Z","hd":{"ts_event":"2026-04-07T02:56:10.047846527Z","rtype":160,"publisher_id":101,"instrument_id":436},"action":"C","side":"A","price":"1.156680000","size":30,"channel_id":23,"order_id":"1775530550683002391","flags":0,"ts_in_delta":1330,"sequence":175908,"symbol":"FCEU SI 20260615 PS"}
{"ts_recv":"2026-04-07T02:56:10.047876733Z","hd":{"ts_event":"2026-04-07T02:56:10.047846527Z","rtype":160,"publisher_id":101,"instrument_id":436},"action":"A","side":"A","price":"1.156690000","size":30,"channel_id":23,"order_id":"1775530570047855433","flags":128,"ts_in_delta":1330,"sequence":175908,"symbol":"FCEU SI 20260615 PS"}
{"ts_recv":"2026-04-07T02:56:40.323905286Z","hd":{"ts_event":"2026-04-07T02:56:40.323872803Z","rtype":160,"publisher_id":101,"instrument_id":436},"action":"C","side":"B","price":"1.156590000","size":30,"channel_id":23,"order_id":"10998902606902631241","flags":0,"ts_in_delta":1953,"sequence":176120,"symbol":"FCEU SI 20260615 PS"}
{"ts_recv":"2026-04-07T02:56:40.323905286Z","hd":{"ts_event":"2026-04-07T02:56:40.323872803Z","rtype":160,"publisher_id":101,"instrument_id":436},"action":"A","side":"B","price":"1.156580000","size":30,"channel_id":23,"order_id":"10998902637178661420","flags":0,"ts_in_delta":1953,"sequence":176120,"symbol":"FCEU SI 20260615 PS"}
{"ts_recv":"2026-04-07T02:56:40.323905286Z","hd":{"ts_event":"2026-04-07T02:56:40.323872803Z","rtype":160,"publisher_id":101,"instrument_id":436},"action":"C","side":"A","price":"1.156690000","size":30,"channel_id":23,"order_id":"1775530570047855433","flags":0,"ts_in_delta":1953,"sequence":176120,"symbol":"FCEU SI 20260615 PS"}
{"ts_recv":"2026-04-07T02:56:40.323905286Z","hd":{"ts_event":"2026-04-07T02:56:40.323872803Z","rtype":160,"publisher_id":101,"instrument_id":436},"action":"A","side":"A","price":"1.156680000","size":30,"channel_id":23,"order_id":"1775530600323885612","flags":128,"ts_in_delta":1953,"sequence":176120,"symbol":"FCEU SI 20260615 PS"}
{"ts_recv":"2026-04-07T02:57:06.318334914Z","hd":{"ts_event":"2026-04-07T02:57:06.318311509Z","rtype":160,"publisher_id":101,"instrument_id":436},"action":"C","side":"B","price":"1.156580000","size":30,"channel_id":23,"order_id":"10998902587537721688","flags":0,"ts_in_delta":980,"sequence":176278,"symbol":"FCEU SI 20260615 PS"}
{"ts_recv":"2026-04-07T02:57:06.318334914Z","hd":{"ts_event":"2026-04-07T02:57:06.318311509Z","rtype":160,"publisher_id":101,"instrument_id":436},"action":"A","side":"B","price":"1.156600000","size":30,"channel_id":23,"order_id":"10998902663173093208","flags":0,"ts_in_delta":980,"sequence":176278,"symbol":"FCEU SI 20260615 PS"}
{"ts_recv":"2026-04-07T02:57:06.318334914Z","hd":{"ts_event":"2026-04-07T02:57:06.318311509Z","rtype":160,"publisher_id":101,"instrument_id":436},"action":"C","side":"A","price":"1.156680000","size":30,"channel_id":23,"order_id":"1775530550682945880","flags":0,"ts_in_delta":980,"sequence":176278,"symbol":"FCEU SI 20260615 PS"}
{"ts_recv":"2026-04-07T02:57:06.318334914Z","hd":{"ts_event":"2026-04-07T02:57:06.318311509Z","rtype":160,"publisher_id":101,"instrument_id":436},"action":"A","side":"A","price":"1.156700000","size":30,"channel_id":23,"order_id":"1775530626318317400","flags":128,"ts_in_delta":980,"sequence":176278,"symbol":"FCEU SI 20260615 PS"}
{"ts_recv":"2026-04-07T02:57:06.318416572Z","hd":{"ts_event":"2026-04-07T02:57:06.318399683Z","rtype":160,"publisher_id":101,"instrument_id":436},"action":"C","side":"B","price":"1.156580000","size":30,"channel_id":23,"order_id":"10998902637178661420","flags":0,"ts_in_delta":945,"sequence":176279,"symbol":"FCEU SI 20260615 PS"}
{"ts_recv":"2026-04-07T02:57:06.318416572Z","hd":{"ts_event":"2026-04-07T02:57:06.318399683Z","rtype":160,"publisher_id":101,"instrument_id":436},"action":"A","side":"B","price":"1.156590000","size":30,"channel_id":23,"order_id":"10998902663173181445","flags":0,"ts_in_delta":945,"sequence":176279,"symbol":"FCEU SI 20260615 PS"}
{"ts_recv":"2026-04-07T02:57:06.318416572Z","hd":{"ts_event":"2026-04-07T02:57:06.318399683Z","rtype":160,"publisher_id":101,"instrument_id":436},"action":"C","side":"A","price":"1.156680000","size":30,"channel_id":23,"order_id":"1775530600323885612","flags":0,"ts_in_delta":945,"sequence":176279,"symbol":"FCEU SI 20260615 PS"}
{"ts_recv":"2026-04-07T02:57:06.318416572Z","hd":{"ts_event":"2026-04-07T02:57:06.318399683Z","rtype":160,"publisher_id":101,"instrument_id":436},"action":"A","side":"A","price":"1.156690000","size":30,"channel_id":23,"order_id":"1775530626318405637","flags":128,"ts_in_delta":945,"sequence":176279,"symbol":"FCEU SI 20260615 PS"}
{"ts_recv":"2026-04-07T02:57:06.320691391Z","hd":{"ts_event":"2026-04-07T02:57:06.320671437Z","rtype":160,"publisher_id":101,"instrument_id":436},"action":"C","side":"B","price":"1.156590000","size":30,"channel_id":23,"order_id":"10998902663173181445","flags":0,"ts_in_delta":971,"sequence":176282,"symbol":"FCEU SI 20260615 PS"}
{"ts_recv":"2026-04-07T02:57:06.320691391Z","hd":{"ts_event":"2026-04-07T02:57:06.320671437Z","rtype":160,"publisher_id":101,"instrument_id":436},"action":"A","side":"B","price":"1.156600000","size":30,"channel_id":23,"order_id":"10998902663175454153","flags":0,"ts_in_delta":971,"sequence":176282,"symbol":"FCEU SI 20260615 PS"}
{"ts_recv":"2026-04-07T02:57:06.320691391Z","hd":{"ts_event":"2026-04-07T02:57:06.320671437Z","rtype":160,"publisher_id":101,"instrument_id":436},"action":"C","side":"A","price":"1.156690000","size":30,"channel_id":23,"order_id":"1775530626318405637","flags":0,"ts_in_delta":971,"sequence":176282,"symbol":"FCEU SI 20260615 PS"}
{"ts_recv":"2026-04-07T02:57:06.320691391Z","hd":{"ts_event":"2026-04-07T02:57:06.320671437Z","rtype":160,"publisher_id":101,"instrument_id":436},"action":"A","side":"A","price":"1.156700000","size":30,"channel_id":23,"order_id":"1775530626320678345","flags":128,"ts_in_delta":971,"sequence":176282,"symbol":"FCEU SI 20260615 PS"}
{"ts_recv":"2026-04-07T02:57:06.325360340Z","hd":{"ts_event":"2026-04-07T02:57:06.325338831Z","rtype":160,"publisher_id":101,"instrument_id":436},"action":"C","side":"B","price":"1.156600000","size":30,"channel_id":23,"order_id":"10998902663175454153","flags":0,"ts_in_delta":773,"sequence":176286,"symbol":"FCEU SI 20260615 PS"}
{"ts_recv":"2026-04-07T02:57:06.325360340Z","hd":{"ts_event":"2026-04-07T02:57:06.325338831Z","rtype":160,"publisher_id":101,"instrument_id":436},"action":"A","side":"B","price":"1.156610000","size":30,"channel_id":23,"order_id":"10998902663180120447","flags":0,"ts_in_delta":773,"sequence":176286,"symbol":"FCEU SI 20260615 PS"}
{"ts_recv":"2026-04-07T02:57:06.325360340Z","hd":{"ts_event":"2026-04-07T02:57:06.325338831Z","rtype":160,"publisher_id":101,"instrument_id":436},"action":"C","side":"A","price":"1.156700000","size":30,"channel_id":23,"order_id":"1775530626320678345","flags":0,"ts_in_delta":773,"sequence":176286,"symbol":"FCEU SI 20260615 PS"}
{"ts_recv":"2026-04-07T02:57:06.325360340Z","hd":{"ts_event":"2026-04-07T02:57:06.325338831Z","rtype":160,"publisher_id":101,"instrument_id":436},"action":"A","side":"A","price":"1.156710000","size":30,"channel_id":23,"order_id":"1775530626325344639","flags":128,"ts_in_delta":773,"sequence":176286,"symbol":"FCEU SI 20260615 PS"}
{"ts_recv":"2026-04-07T02:57:06.325977684Z","hd":{"ts_event":"2026-04-07T02:57:06.325958229Z","rtype":160,"publisher_id":101,"instrument_id":436},"action":"C","side":"B","price":"1.156600000","size":30,"channel_id":23,"order_id":"10998902663173093208","flags":0,"ts_in_delta":798,"sequence":176287,"symbol":"FCEU SI 20260615 PS"}
{"ts_recv":"2026-04-07T02:57:06.325977684Z","hd":{"ts_event":"2026-04-07T02:57:06.325958229Z","rtype":160,"publisher_id":101,"instrument_id":436},"action":"A","side":"B","price":"1.156620000","size":30,"channel_id":23,"order_id":"10998902663180739948","flags":0,"ts_in_delta":798,"sequence":176287,"symbol":"FCEU SI 20260615 PS"}
{"ts_recv":"2026-04-07T02:57:06.325977684Z","hd":{"ts_event":"2026-04-07T02:57:06.325958229Z","rtype":160,"publisher_id":101,"instrument_id":436},"action":"C","side":"A","price":"1.156700000","size":30,"channel_id":23,"order_id":"1775530626318317400","flags":0,"ts_in_delta":798,"sequence":176287,"symbol":"FCEU SI 20260615 PS"}
{"ts_recv":"2026-04-07T02:57:06.325977684Z","hd":{"ts_event":"2026-04-07T02:57:06.325958229Z","rtype":160,"publisher_id":101,"instrument_id":436},"action":"A","side":"A","price":"1.156720000","size":30,"channel_id":23,"order_id":"1775530626325964140","flags":128,"ts_in_delta":798,"sequence":176287,"symbol":"FCEU SI 20260615 PS"}
{"ts_recv":"2026-04-07T02:57:06.326031971Z","hd":{"ts_event":"2026-04-07T02:57:06.326014639Z","rtype":160,"publisher_id":101,"instrument_id":436},"action":"C","side":"B","price":"1.156610000","size":30,"channel_id":23,"order_id":"10998902663180120447","flags":0,"ts_in_delta":768,"sequence":176288,"symbol":"FCEU SI 20260615 PS"}
{"ts_recv":"2026-04-07T02:57:06.326031971Z","hd":{"ts_event":"2026-04-07T02:57:06.326014639Z","rtype":160,"publisher_id":101,"instrument_id":436},"action":"A","side":"B","price":"1.156620000","size":30,"channel_id":23,"order_id":"10998902663180796758","flags":0,"ts_in_delta":768,"sequence":176288,"symbol":"FCEU SI 20260615 PS"}
{"ts_recv":"2026-04-07T02:57:06.326031971Z","hd":{"ts_event":"2026-04-07T02:57:06.326014639Z","rtype":160,"publisher_id":101,"instrument_id":436},"action":"C","side":"A","price":"1.156710000","size":30,"channel_id":23,"order_id":"1775530626325344639","flags":0,"ts_in_delta":768,"sequence":176288,"symbol":"FCEU SI 20260615 PS"}
{"ts_recv":"2026-04-07T02:57:06.326031971Z","hd":{"ts_event":"2026-04-07T02:57:06.326014639Z","rtype":160,"publisher_id":101,"instrument_id":436},"action":"A","side":"A","price":"1.156720000","size":30,"channel_id":23,"order_id":"1775530626326020950","flags":128,"ts_in_delta":768,"sequence":176288,"symbol":"FCEU SI 20260615 PS"}
{"ts_recv":"2026-04-07T02:57:06.422072727Z","hd":{"ts_event":"2026-04-07T02:57:06.422053893Z","rtype":160,"publisher_id":101,"instrument_id":436},"action":"C","side":"B","price":"1.156620000","size":30,"channel_id":23,"order_id":"10998902663180796758","flags":0,"ts_in_delta":992,"sequence":176317,"symbol":"FCEU SI 20260615 PS"}
{"ts_recv":"2026-04-07T02:57:06.422072727Z","hd":{"ts_event":"2026-04-07T02:57:06.422053893Z","rtype":160,"publisher_id":101,"instrument_id":436},"action":"A","side":"B","price":"1.156630000","size":30,"channel_id":23,"order_id":"10998902663276835851","flags":0,"ts_in_delta":992,"sequence":176317,"symbol":"FCEU SI 20260615 PS"}
{"ts_recv":"2026-04-07T02:57:06.422072727Z","hd":{"ts_event":"2026-04-07T02:57:06.422053893Z","rtype":160,"publisher_id":101,"instrument_id":436},"action":"C","side":"A","price":"1.156720000","size":30,"channel_id":23,"order_id":"1775530626326020950","flags":0,"ts_in_delta":992,"sequence":176317,"symbol":"FCEU SI 20260615 PS"}
{"ts_recv":"2026-04-07T02:57:06.422072727Z","hd":{"ts_event":"2026-04-07T02:57:06.422053893Z","rtype":160,"publisher_id":101,"instrument_id":436},"action":"A","side":"A","price":"1.156730000","size":30,"channel_id":23,"order_id":"1775530626422060043","flags":128,"ts_in_delta":992,"sequence":176317,"symbol":"FCEU SI 20260615 PS"}
{"ts_recv":"2026-04-07T02:57:06.516327413Z","hd":{"ts_event":"2026-04-07T02:57:06.516307785Z","rtype":160,"publisher_id":101,"instrument_id":436},"action":"C","side":"B","price":"1.156620000","size":30,"channel_id":23,"order_id":"10998902663180739948","flags":0,"ts_in_delta":964,"sequence":176332,"symbol":"FCEU SI 20260615 PS"}
{"ts_recv":"2026-04-07T02:57:06.516327413Z","hd":{"ts_event":"2026-04-07T02:57:06.516307785Z","rtype":160,"publisher_id":101,"instrument_id":436},"action":"A","side":"B","price":"1.156640000","size":30,"channel_id":23,"order_id":"10998902663371089734","flags":0,"ts_in_delta":964,"sequence":176332,"symbol":"FCEU SI 20260615 PS"}
{"ts_recv":"2026-04-07T02:57:06.516327413Z","hd":{"ts_event":"2026-04-07T02:57:06.516307785Z","rtype":160,"publisher_id":101,"instrument_id":436},"action":"C","side":"A","price":"1.156720000","size":30,"channel_id":23,"order_id":"1775530626325964140","flags":0,"ts_in_delta":964,"sequence":176332,"symbol":"FCEU SI 20260615 PS"}
{"ts_recv":"2026-04-07T02:57:06.516327413Z","hd":{"ts_event":"2026-04-07T02:57:06.516307785Z","rtype":160,"publisher_id":101,"instrument_id":436},"action":"A","side":"A","price":"1.156740000","size":30,"channel_id":23,"order_id":"1775530626516313926","flags":128,"ts_in_delta":964,"sequence":176332,"symbol":"FCEU SI 20260615 PS"}
{"ts_recv":"2026-04-07T02:57:06.516396361Z","hd":{"ts_event":"2026-04-07T02:57:06.516379651Z","rtype":160,"publisher_id":101,"instrument_id":436},"action":"C","side":"B","price":"1.156630000","size":30,"channel_id":23,"order_id":"10998902663276835851","flags":0,"ts_in_delta":1093,"sequence":176333,"symbol":"FCEU SI 20260615 PS"}
{"ts_recv":"2026-04-07T02:57:06.516396361Z","hd":{"ts_event":"2026-04-07T02:57:06.516379651Z","rtype":160,"publisher_id":101,"instrument_id":436},"action":"A","side":"B","price":"1.156640000","size":30,"channel_id":23,"order_id":"10998902663371162048","flags":0,"ts_in_delta":1093,"sequence":176333,"symbol":"FCEU SI 20260615 PS"}
{"ts_recv":"2026-04-07T02:57:06.516396361Z","hd":{"ts_event":"2026-04-07T02:57:06.516379651Z","rtype":160,"publisher_id":101,"instrument_id":436},"action":"C","side":"A","price":"1.156730000","size":30,"channel_id":23,"order_id":"1775530626422060043","flags":0,"ts_in_delta":1093,"sequence":176333,"symbol":"FCEU SI 20260615 PS"}
{"ts_recv":"2026-04-07T02:57:06.516396361Z","hd":{"ts_event":"2026-04-07T02:57:06.516379651Z","rtype":160,"publisher_id":101,"instrument_id":436},"action":"A","side":"A","price":"1.156740000","size":30,"channel_id":23,"order_id":"1775530626516386240","flags":128,"ts_in_delta":1093,"sequence":176333,"symbol":"FCEU SI 20260615 PS"}
{"ts_recv":"2026-04-07T02:57:13.393833696Z","hd":{"ts_event":"2026-04-07T02:57:13.393802061Z","rtype":160,"publisher_id":101,"instrument_id":436},"action":"C","side":"B","price":"1.156640000","size":30,"channel_id":23,"order_id":"10998902663371162048","flags":0,"ts_in_delta":984,"sequence":176379,"symbol":"FCEU SI 20260615 PS"}
{"ts_recv":"2026-04-07T02:57:13.393833696Z","hd":{"ts_event":"2026-04-07T02:57:13.393802061Z","rtype":160,"publisher_id":101,"instrument_id":436},"action":"A","side":"B","price":"1.156650000","size":30,"channel_id":23,"order_id":"10998902670248589099","flags":0,"ts_in_delta":984,"sequence":176379,"symbol":"FCEU SI 20260615 PS"}
{"ts_recv":"2026-04-07T02:57:13.393833696Z","hd":{"ts_event":"2026-04-07T02:57:13.393802061Z","rtype":160,"publisher_id":101,"instrument_id":436},"action":"C","side":"A","price":"1.156740000","size":30,"channel_id":23,"order_id":"1775530626516386240","flags":0,"ts_in_delta":984,"sequence":176379,"symbol":"FCEU SI 20260615 PS"}
{"ts_recv":"2026-04-07T02:57:13.393833696Z","hd":{"ts_event":"2026-04-07T02:57:13.393802061Z","rtype":160,"publisher_id":101,"instrument_id":436},"action":"A","side":"A","price":"1.156750000","size":30,"channel_id":23,"order_id":"1775530633393813291","flags":128,"ts_in_delta":984,"sequence":176379,"symbol":"FCEU SI 20260615 PS"}
{"ts_recv":"2026-04-07T02:57:13.397554808Z","hd":{"ts_event":"2026-04-07T02:57:13.397533421Z","rtype":160,"publisher_id":101,"instrument_id":436},"action":"C","side":"B","price":"1.156640000","size":30,"channel_id":23,"order_id":"10998902663371089734","flags":0,"ts_in_delta":996,"sequence":176380,"symbol":"FCEU SI 20260615 PS"}
{"ts_recv":"2026-04-07T02:57:13.397554808Z","hd":{"ts_event":"2026-04-07T02:57:13.397533421Z","rtype":160,"publisher_id":101,"instrument_id":436},"action":"A","side":"B","price":"1.156660000","size":30,"channel_id":23,"order_id":"10998902670252315618","flags":0,"ts_in_delta":996,"sequence":176380,"symbol":"FCEU SI 20260615 PS"}
{"ts_recv":"2026-04-07T02:57:13.397554808Z","hd":{"ts_event":"2026-04-07T02:57:13.397533421Z","rtype":160,"publisher_id":101,"instrument_id":436},"action":"C","side":"A","price":"1.156740000","size":30,"channel_id":23,"order_id":"1775530626516313926","flags":0,"ts_in_delta":996,"sequence":176380,"symbol":"FCEU SI 20260615 PS"}
{"ts_recv":"2026-04-07T02:57:13.397554808Z","hd":{"ts_event":"2026-04-07T02:57:13.397533421Z","rtype":160,"publisher_id":101,"instrument_id":436},"action":"A","side":"A","price":"1.156760000","size":30,"channel_id":23,"order_id":"1775530633397539810","flags":128,"ts_in_delta":996,"sequence":176380,"symbol":"FCEU SI 20260615 PS"}
{"ts_recv":"2026-04-07T02:57:13.397625914Z","hd":{"ts_event":"2026-04-07T02:57:13.397606613Z","rtype":160,"publisher_id":101,"instrument_id":436},"action":"C","side":"B","price":"1.156650000","size":30,"channel_id":23,"order_id":"10998902670248589099","flags":0,"ts_in_delta":987,"sequence":176381,"symbol":"FCEU SI 20260615 PS"}
{"ts_recv":"2026-04-07T02:57:13.397625914Z","hd":{"ts_event":"2026-04-07T02:57:13.397606613Z","rtype":160,"publisher_id":101,"instrument_id":436},"action":"A","side":"B","price":"1.156660000","size":30,"channel_id":23,"order_id":"10998902670252388400","flags":0,"ts_in_delta":987,"sequence":176381,"symbol":"FCEU SI 20260615 PS"}
{"ts_recv":"2026-04-07T02:57:13.397625914Z","hd":{"ts_event":"2026-04-07T02:57:13.397606613Z","rtype":160,"publisher_id":101,"instrument_id":436},"action":"C","side":"A","price":"1.156750000","size":30,"channel_id":23,"order_id":"1775530633393813291","flags":0,"ts_in_delta":987,"sequence":176381,"symbol":"FCEU SI 20260615 PS"}
{"ts_recv":"2026-04-07T02:57:13.397625914Z","hd":{"ts_event":"2026-04-07T02:57:13.397606613Z","rtype":160,"publisher_id":101,"instrument_id":436},"action":"A","side":"A","price":"1.156760000","size":30,"channel_id":23,"order_id":"1775530633397612592","flags":128,"ts_in_delta":987,"sequence":176381,"symbol":"FCEU SI 20260615 PS"}
{"ts_recv":"2026-04-07T02:57:13.406088540Z","hd":{"ts_event":"2026-04-07T02:57:13.406068417Z","rtype":160,"publisher_id":101,"instrument_id":436},"action":"C","side":"B","price":"1.156660000","size":30,"channel_id":23,"order_id":"10998902670252388400","flags":0,"ts_in_delta":987,"sequence":176386,"symbol":"FCEU SI 20260615 PS"}
{"ts_recv":"2026-04-07T02:57:13.406088540Z","hd":{"ts_event":"2026-04-07T02:57:13.406068417Z","rtype":160,"publisher_id":101,"instrument_id":436},"action":"A","side":"B","price":"1.156670000","size":30,"channel_id":23,"order_id":"10998902670260851146","flags":0,"ts_in_delta":987,"sequence":176386,"symbol":"FCEU SI 20260615 PS"}
{"ts_recv":"2026-04-07T02:57:13.406088540Z","hd":{"ts_event":"2026-04-07T02:57:13.406068417Z","rtype":160,"publisher_id":101,"instrument_id":436},"action":"C","side":"A","price":"1.156760000","size":30,"channel_id":23,"order_id":"1775530633397612592","flags":0,"ts_in_delta":987,"sequence":176386,"symbol":"FCEU SI 20260615 PS"}
{"ts_recv":"2026-04-07T02:57:13.406088540Z","hd":{"ts_event":"2026-04-07T02:57:13.406068417Z","rtype":160,"publisher_id":101,"instrument_id":436},"action":"A","side":"A","price":"1.156770000","size":30,"channel_id":23,"order_id":"1775530633406075338","flags":128,"ts_in_delta":987,"sequence":176386,"symbol":"FCEU SI 20260615 PS"}
{"ts_recv":"2026-04-07T02:57:17.287666927Z","hd":{"ts_event":"2026-04-07T02:57:17.287645415Z","rtype":160,"publisher_id":101,"instrument_id":436},"action":"C","side":"B","price":"1.156670000","size":30,"channel_id":23,"order_id":"10998902670260851146","flags":0,"ts_in_delta":1258,"sequence":176424,"symbol":"FCEU SI 20260615 PS"}
{"ts_recv":"2026-04-07T02:57:17.287666927Z","hd":{"ts_event":"2026-04-07T02:57:17.287645415Z","rtype":160,"publisher_id":101,"instrument_id":436},"action":"A","side":"B","price":"1.156660000","size":30,"channel_id":23,"order_id":"10998902674142427430","flags":0,"ts_in_delta":1258,"sequence":176424,"symbol":"FCEU SI 20260615 PS"}
{"ts_recv":"2026-04-07T02:57:17.287666927Z","hd":{"ts_event":"2026-04-07T02:57:17.287645415Z","rtype":160,"publisher_id":101,"instrument_id":436},"action":"C","side":"A","price":"1.156770000","size":30,"channel_id":23,"order_id":"1775530633406075338","flags":0,"ts_in_delta":1258,"sequence":176424,"symbol":"FCEU SI 20260615 PS"}
{"ts_recv":"2026-04-07T02:57:17.287666927Z","hd":{"ts_event":"2026-04-07T02:57:17.287645415Z","rtype":160,"publisher_id":101,"instrument_id":436},"action":"A","side":"A","price":"1.156760000","size":30,"channel_id":23,"order_id":"1775530637287651622","flags":128,"ts_in_delta":1258,"sequence":176424,"symbol":"FCEU SI 20260615 PS"}
{"ts_recv":"2026-04-07T02:57:33.619717101Z","hd":{"ts_event":"2026-04-07T02:57:33.619693861Z","rtype":160,"publisher_id":101,"instrument_id":436},"action":"C","side":"B","price":"1.156660000","size":30,"channel_id":23,"order_id":"10998902674142427430","flags":0,"ts_in_delta":1145,"sequence":176510,"symbol":"FCEU SI 20260615 PS"}
{"ts_recv":"2026-04-07T02:57:33.619717101Z","hd":{"ts_event":"2026-04-07T02:57:33.619693861Z","rtype":160,"publisher_id":101,"instrument_id":436},"action":"A","side":"B","price":"1.156650000","size":30,"channel_id":23,"order_id":"10998902690474475997","flags":0,"ts_in_delta":1145,"sequence":176510,"symbol":"FCEU SI 20260615 PS"}
{"ts_recv":"2026-04-07T02:57:33.619717101Z","hd":{"ts_event":"2026-04-07T02:57:33.619693861Z","rtype":160,"publisher_id":101,"instrument_id":436},"action":"C","side":"A","price":"1.156760000","size":30,"channel_id":23,"order_id":"1775530637287651622","flags":0,"ts_in_delta":1145,"sequence":176510,"symbol":"FCEU SI 20260615 PS"}
{"ts_recv":"2026-04-07T02:57:33.619717101Z","hd":{"ts_event":"2026-04-07T02:57:33.619693861Z","rtype":160,"publisher_id":101,"instrument_id":436},"action":"A","side":"A","price":"1.156750000","size":30,"channel_id":23,"order_id":"1775530653619700189","flags":128,"ts_in_delta":1145,"sequence":176510,"symbol":"FCEU SI 20260615 PS"}
{"ts_recv":"2026-04-07T02:57:33.619788245Z","hd":{"ts_event":"2026-04-07T02:57:33.619765619Z","rtype":160,"publisher_id":101,"instrument_id":436},"action":"C","side":"B","price":"1.156660000","size":30,"channel_id":23,"order_id":"10998902670252315618","flags":0,"ts_in_delta":981,"sequence":176511,"symbol":"FCEU SI 20260615 PS"}
{"ts_recv":"2026-04-07T02:57:33.619788245Z","hd":{"ts_event":"2026-04-07T02:57:33.619765619Z","rtype":160,"publisher_id":101,"instrument_id":436},"action":"A","side":"B","price":"1.156640000","size":30,"channel_id":23,"order_id":"10998902690474547943","flags":0,"ts_in_delta":981,"sequence":176511,"symbol":"FCEU SI 20260615 PS"}
{"ts_recv":"2026-04-07T02:57:33.619788245Z","hd":{"ts_event":"2026-04-07T02:57:33.619765619Z","rtype":160,"publisher_id":101,"instrument_id":436},"action":"C","side":"A","price":"1.156760000","size":30,"channel_id":23,"order_id":"1775530633397539810","flags":0,"ts_in_delta":981,"sequence":176511,"symbol":"FCEU SI 20260615 PS"}
{"ts_recv":"2026-04-07T02:57:33.619788245Z","hd":{"ts_event":"2026-04-07T02:57:33.619765619Z","rtype":160,"publisher_id":101,"instrument_id":436},"action":"A","side":"A","price":"1.156740000","size":30,"channel_id":23,"order_id":"1775530653619772135","flags":128,"ts_in_delta":981,"sequence":176511,"symbol":"FCEU SI 20260615 PS"}
{"ts_recv":"2026-04-07T02:57:33.619848796Z","hd":{"ts_event":"2026-04-07T02:57:33.619829989Z","rtype":160,"publisher_id":101,"instrument_id":436},"action":"C","side":"B","price":"1.156650000","size":30,"channel_id":23,"order_id":"10998902690474475997","flags":0,"ts_in_delta":2116,"sequence":176512,"symbol":"FCEU SI 20260615 PS"}
{"ts_recv":"2026-04-07T02:57:33.619848796Z","hd":{"ts_event":"2026-04-07T02:57:33.619829989Z","rtype":160,"publisher_id":101,"instrument_id":436},"action":"A","side":"B","price":"1.156640000","size":30,"channel_id":23,"order_id":"10998902690474612212","flags":0,"ts_in_delta":2116,"sequence":176512,"symbol":"FCEU SI 20260615 PS"}
{"ts_recv":"2026-04-07T02:57:33.619848796Z","hd":{"ts_event":"2026-04-07T02:57:33.619829989Z","rtype":160,"publisher_id":101,"instrument_id":436},"action":"C","side":"A","price":"1.156750000","size":30,"channel_id":23,"order_id":"1775530653619700189","flags":0,"ts_in_delta":2116,"sequence":176512,"symbol":"FCEU SI 20260615 PS"}
{"ts_recv":"2026-04-07T02:57:33.619848796Z","hd":{"ts_event":"2026-04-07T02:57:33.619829989Z","rtype":160,"publisher_id":101,"instrument_id":436},"action":"A","side":"A","price":"1.156740000","size":30,"channel_id":23,"order_id":"1775530653619836404","flags":128,"ts_in_delta":2116,"sequence":176512,"symbol":"FCEU SI 20260615 PS"}
{"ts_recv":"2026-04-07T02:57:35.928850573Z","hd":{"ts_event":"2026-04-07T02:57:35.928829715Z","rtype":160,"publisher_id":101,"instrument_id":436},"action":"C","side":"B","price":"1.156640000","size":30,"channel_id":23,"order_id":"10998902690474612212","flags":0,"ts_in_delta":883,"sequence":176552,"symbol":"FCEU SI 20260615 PS"}
{"ts_recv":"2026-04-07T02:57:35.928850573Z","hd":{"ts_event":"2026-04-07T02:57:35.928829715Z","rtype":160,"publisher_id":101,"instrument_id":436},"action":"A","side":"B","price":"1.156630000","size":30,"channel_id":23,"order_id":"10998902692783611606","flags":0,"ts_in_delta":883,"sequence":176552,"symbol":"FCEU SI 20260615 PS"}
{"ts_recv":"2026-04-07T02:57:35.928850573Z","hd":{"ts_event":"2026-04-07T02:57:35.928829715Z","rtype":160,"publisher_id":101,"instrument_id":436},"action":"C","side":"A","price":"1.156740000","size":30,"channel_id":23,"order_id":"1775530653619836404","flags":0,"ts_in_delta":883,"sequence":176552,"symbol":"FCEU SI 20260615 PS"}
{"ts_recv":"2026-04-07T02:57:35.928850573Z","hd":{"ts_event":"2026-04-07T02:57:35.928829715Z","rtype":160,"publisher_id":101,"instrument_id":436},"action":"A","side":"A","price":"1.156730000","size":30,"channel_id":23,"order_id":"1775530655928835798","flags":128,"ts_in_delta":883,"sequence":176552,"symbol":"FCEU SI 20260615 PS"}
{"ts_recv":"2026-04-07T02:57:35.928909077Z","hd":{"ts_event":"2026-04-07T02:57:35.928889215Z","rtype":160,"publisher_id":101,"instrument_id":436},"action":"C","side":"B","price":"1.156640000","size":30,"channel_id":23,"order_id":"10998902690474547943","flags":0,"ts_in_delta":875,"sequence":176553,"symbol":"FCEU SI 20260615 PS"}
{"ts_recv":"2026-04-07T02:57:35.928909077Z","hd":{"ts_event":"2026-04-07T02:57:35.928889215Z","rtype":160,"publisher_id":101,"instrument_id":436},"action":"A","side":"B","price":"1.156620000","size":30,"channel_id":23,"order_id":"10998902692783671031","flags":0,"ts_in_delta":875,"sequence":176553,"symbol":"FCEU SI 20260615 PS"}
{"ts_recv":"2026-04-07T02:57:35.928909077Z","hd":{"ts_event":"2026-04-07T02:57:35.928889215Z","rtype":160,"publisher_id":101,"instrument_id":436},"action":"C","side":"A","price":"1.156740000","size":30,"channel_id":23,"order_id":"1775530653619772135","flags":0,"ts_in_delta":875,"sequence":176553,"symbol":"FCEU SI 20260615 PS"}
{"ts_recv":"2026-04-07T02:57:35.928909077Z","hd":{"ts_event":"2026-04-07T02:57:35.928889215Z","rtype":160,"publisher_id":101,"instrument_id":436},"action":"A","side":"A","price":"1.156720000","size":30,"channel_id":23,"order_id":"1775530655928895223","flags":128,"ts_in_delta":875,"sequence":176553,"symbol":"FCEU SI 20260615 PS"}
{"ts_recv":"2026-04-07T02:57:35.928928107Z","hd":{"ts_event":"2026-04-07T02:57:35.928912423Z","rtype":160,"publisher_id":101,"instrument_id":436},"action":"C","side":"B","price":"1.156630000","size":30,"channel_id":23,"order_id":"10998902692783611606","flags":0,"ts_in_delta":874,"sequence":176554,"symbol":"FCEU SI 20260615 PS"}
{"ts_recv":"2026-04-07T02:57:35.928928107Z","hd":{"ts_event":"2026-04-07T02:57:35.928912423Z","rtype":160,"publisher_id":101,"instrument_id":436},"action":"A","side":"B","price":"1.156620000","size":30,"channel_id":23,"order_id":"10998902692783694180","flags":0,"ts_in_delta":874,"sequence":176554,"symbol":"FCEU SI 20260615 PS"}
{"ts_recv":"2026-04-07T02:57:35.928928107Z","hd":{"ts_event":"2026-04-07T02:57:35.928912423Z","rtype":160,"publisher_id":101,"instrument_id":436},"action":"C","side":"A","price":"1.156730000","size":30,"channel_id":23,"order_id":"1775530655928835798","flags":0,"ts_in_delta":874,"sequence":176554,"symbol":"FCEU SI 20260615 PS"}
{"ts_recv":"2026-04-07T02:57:35.928928107Z","hd":{"ts_event":"2026-04-07T02:57:35.928912423Z","rtype":160,"publisher_id":101,"instrument_id":436},"action":"A","side":"A","price":"1.156720000","size":30,"channel_id":23,"order_id":"1775530655928918372","flags":128,"ts_in_delta":874,"sequence":176554,"symbol":"FCEU SI 20260615 PS"}
{"ts_recv":"2026-04-07T02:57:35.929006862Z","hd":{"ts_event":"2026-04-07T02:57:35.928988749Z","rtype":160,"publisher_id":101,"instrument_id":436},"action":"C","side":"B","price":"1.156620000","size":30,"channel_id":23,"order_id":"10998902692783694180","flags":0,"ts_in_delta":844,"sequence":176556,"symbol":"FCEU SI 20260615 PS"}
{"ts_recv":"2026-04-07T02:57:35.929006862Z","hd":{"ts_event":"2026-04-07T02:57:35.928988749Z","rtype":160,"publisher_id":101,"instrument_id":436},"action":"A","side":"B","price":"1.156630000","size":30,"channel_id":23,"order_id":"10998902692783770483","flags":0,"ts_in_delta":844,"sequence":176556,"symbol":"FCEU SI 20260615 PS"}
{"ts_recv":"2026-04-07T02:57:35.929006862Z","hd":{"ts_event":"2026-04-07T02:57:35.928988749Z","rtype":160,"publisher_id":101,"instrument_id":436},"action":"C","side":"A","price":"1.156720000","size":30,"channel_id":23,"order_id":"1775530655928918372","flags":0,"ts_in_delta":844,"sequence":176556,"symbol":"FCEU SI 20260615 PS"}
{"ts_recv":"2026-04-07T02:57:35.929006862Z","hd":{"ts_event":"2026-04-07T02:57:35.928988749Z","rtype":160,"publisher_id":101,"instrument_id":436},"action":"A","side":"A","price":"1.156730000","size":30,"channel_id":23,"order_id":"1775530655928994675","flags":128,"ts_in_delta":844,"sequence":176556,"symbol":"FCEU SI 20260615 PS"}
{"ts_recv":"2026-04-07T02:57:35.929068261Z","hd":{"ts_event":"2026-04-07T02:57:35.929049997Z","rtype":160,"publisher_id":101,"instrument_id":436},"action":"C","side":"B","price":"1.156630000","size":30,"channel_id":23,"order_id":"10998902692783770483","flags":0,"ts_in_delta":931,"sequence":176557,"symbol":"FCEU SI 20260615 PS"}
{"ts_recv":"2026-04-07T02:57:35.929068261Z","hd":{"ts_event":"2026-04-07T02:57:35.929049997Z","rtype":160,"publisher_id":101,"instrument_id":436},"action":"A","side":"B","price":"1.156620000","size":30,"channel_id":23,"order_id":"10998902692783831646","flags":0,"ts_in_delta":931,"sequence":176557,"symbol":"FCEU SI 20260615 PS"}
{"ts_recv":"2026-04-07T02:57:35.929068261Z","hd":{"ts_event":"2026-04-07T02:57:35.929049997Z","rtype":160,"publisher_id":101,"instrument_id":436},"action":"C","side":"A","price":"1.156730000","size":30,"channel_id":23,"order_id":"1775530655928994675","flags":0,"ts_in_delta":931,"sequence":176557,"symbol":"FCEU SI 20260615 PS"}
{"ts_recv":"2026-04-07T02:57:35.929068261Z","hd":{"ts_event":"2026-04-07T02:57:35.929049997Z","rtype":160,"publisher_id":101,"instrument_id":436},"action":"A","side":"A","price":"1.156720000","size":30,"channel_id":23,"order_id":"1775530655929055838","flags":128,"ts_in_delta":931,"sequence":176557,"symbol":"FCEU SI 20260615 PS"}
{"ts_recv":"2026-04-07T02:57:36.076910696Z","hd":{"ts_event":"2026-04-07T02:57:36.076889745Z","rtype":160,"publisher_id":101,"instrument_id":436},"action":"C","side":"B","price":"1.156620000","size":30,"channel_id":23,"order_id":"10998902692783831646","flags":0,"ts_in_delta":707,"sequence":176586,"symbol":"FCEU SI 20260615 PS"}
{"ts_recv":"2026-04-07T02:57:36.076910696Z","hd":{"ts_event":"2026-04-07T02:57:36.076889745Z","rtype":160,"publisher_id":101,"instrument_id":436},"action":"A","side":"B","price":"1.156610000","size":30,"channel_id":23,"order_id":"10998902692931671572","flags":0,"ts_in_delta":707,"sequence":176586,"symbol":"FCEU SI 20260615 PS"}
{"ts_recv":"2026-04-07T02:57:36.076910696Z","hd":{"ts_event":"2026-04-07T02:57:36.076889745Z","rtype":160,"publisher_id":101,"instrument_id":436},"action":"C","side":"A","price":"1.156720000","size":30,"channel_id":23,"order_id":"1775530655929055838","flags":0,"ts_in_delta":707,"sequence":176586,"symbol":"FCEU SI 20260615 PS"}
{"ts_recv":"2026-04-07T02:57:36.076910696Z","hd":{"ts_event":"2026-04-07T02:57:36.076889745Z","rtype":160,"publisher_id":101,"instrument_id":436},"action":"A","side":"A","price":"1.156710000","size":30,"channel_id":23,"order_id":"1775530656076895764","flags":128,"ts_in_delta":707,"sequence":176586,"symbol":"FCEU SI 20260615 PS"}
{"ts_recv":"2026-04-07T02:57:36.076964806Z","hd":{"ts_event":"2026-04-07T02:57:36.076946327Z","rtype":160,"publisher_id":101,"instrument_id":436},"action":"C","side":"B","price":"1.156620000","size":30,"channel_id":23,"order_id":"10998902692783671031","flags":0,"ts_in_delta":759,"sequence":176587,"symbol":"FCEU SI 20260615 PS"}
{"ts_recv":"2026-04-07T02:57:36.076964806Z","hd":{"ts_event":"2026-04-07T02:57:36.076946327Z","rtype":160,"publisher_id":101,"instrument_id":436},"action":"A","side":"B","price":"1.156600000","size":30,"channel_id":23,"order_id":"10998902692931728394","flags":0,"ts_in_delta":759,"sequence":176587,"symbol":"FCEU SI 20260615 PS"}
{"ts_recv":"2026-04-07T02:57:36.076964806Z","hd":{"ts_event":"2026-04-07T02:57:36.076946327Z","rtype":160,"publisher_id":101,"instrument_id":436},"action":"C","side":"A","price":"1.156720000","size":30,"channel_id":23,"order_id":"1775530655928895223","flags":0,"ts_in_delta":759,"sequence":176587,"symbol":"FCEU SI 20260615 PS"}
{"ts_recv":"2026-04-07T02:57:36.076964806Z","hd":{"ts_event":"2026-04-07T02:57:36.076946327Z","rtype":160,"publisher_id":101,"instrument_id":436},"action":"A","side":"A","price":"1.156700000","size":30,"channel_id":23,"order_id":"1775530656076952586","flags":128,"ts_in_delta":759,"sequence":176587,"symbol":"FCEU SI 20260615 PS"}
{"ts_recv":"2026-04-07T02:57:36.076973430Z","hd":{"ts_event":"2026-04-07T02:57:36.076956177Z","rtype":160,"publisher_id":101,"instrument_id":436},"action":"C","side":"B","price":"1.156610000","size":30,"channel_id":23,"order_id":"10998902692931671572","flags":0,"ts_in_delta":705,"sequence":176588,"symbol":"FCEU SI 20260615 PS"}
{"ts_recv":"2026-04-07T02:57:36.076973430Z","hd":{"ts_event":"2026-04-07T02:57:36.076956177Z","rtype":160,"publisher_id":101,"instrument_id":436},"action":"A","side":"B","price":"1.156600000","size":30,"channel_id":23,"order_id":"10998902692931737728","flags":0,"ts_in_delta":705,"sequence":176588,"symbol":"FCEU SI 20260615 PS"}
{"ts_recv":"2026-04-07T02:57:36.076973430Z","hd":{"ts_event":"2026-04-07T02:57:36.076956177Z","rtype":160,"publisher_id":101,"instrument_id":436},"action":"C","side":"A","price":"1.156710000","size":30,"channel_id":23,"order_id":"1775530656076895764","flags":0,"ts_in_delta":705,"sequence":176588,"symbol":"FCEU SI 20260615 PS"}
{"ts_recv":"2026-04-07T02:57:36.076973430Z","hd":{"ts_event":"2026-04-07T02:57:36.076956177Z","rtype":160,"publisher_id":101,"instrument_id":436},"action":"A","side":"A","price":"1.156700000","size":30,"channel_id":23,"order_id":"1775530656076961920","flags":128,"ts_in_delta":705,"sequence":176588,"symbol":"FCEU SI 20260615 PS"}
{"ts_recv":"2026-04-07T02:57:38.161561178Z","hd":{"ts_event":"2026-04-07T02:57:38.161541247Z","rtype":160,"publisher_id":101,"instrument_id":436},"action":"C","side":"B","price":"1.156600000","size":30,"channel_id":23,"order_id":"10998902692931737728","flags":0,"ts_in_delta":979,"sequence":176615,"symbol":"FCEU SI 20260615 PS"}
{"ts_recv":"2026-04-07T02:57:38.161561178Z","hd":{"ts_event":"2026-04-07T02:57:38.161541247Z","rtype":160,"publisher_id":101,"instrument_id":436},"action":"A","side":"B","price":"1.156610000","size":30,"channel_id":23,"order_id":"10998902695016323343","flags":0,"ts_in_delta":979,"sequence":176615,"symbol":"FCEU SI 20260615 PS"}
{"ts_recv":"2026-04-07T02:57:38.161561178Z","hd":{"ts_event":"2026-04-07T02:57:38.161541247Z","rtype":160,"publisher_id":101,"instrument_id":436},"action":"C","side":"A","price":"1.156700000","size":30,"channel_id":23,"order_id":"1775530656076961920","flags":0,"ts_in_delta":979,"sequence":176615,"symbol":"FCEU SI 20260615 PS"}
{"ts_recv":"2026-04-07T02:57:38.161561178Z","hd":{"ts_event":"2026-04-07T02:57:38.161541247Z","rtype":160,"publisher_id":101,"instrument_id":436},"action":"A","side":"A","price":"1.156710000","size":30,"channel_id":23,"order_id":"1775530658161547535","flags":128,"ts_in_delta":979,"sequence":176615,"symbol":"FCEU SI 20260615 PS"}
{"ts_recv":"2026-04-07T02:57:38.161614997Z","hd":{"ts_event":"2026-04-07T02:57:38.161594923Z","rtype":160,"publisher_id":101,"instrument_id":436},"action":"C","side":"B","price":"1.156600000","size":30,"channel_id":23,"order_id":"10998902692931728394","flags":0,"ts_in_delta":985,"sequence":176616,"symbol":"FCEU SI 20260615 PS"}
{"ts_recv":"2026-04-07T02:57:38.161614997Z","hd":{"ts_event":"2026-04-07T02:57:38.161594923Z","rtype":160,"publisher_id":101,"instrument_id":436},"action":"A","side":"B","price":"1.156620000","size":30,"channel_id":23,"order_id":"10998902695016376919","flags":0,"ts_in_delta":985,"sequence":176616,"symbol":"FCEU SI 20260615 PS"}
{"ts_recv":"2026-04-07T02:57:38.161614997Z","hd":{"ts_event":"2026-04-07T02:57:38.161594923Z","rtype":160,"publisher_id":101,"instrument_id":436},"action":"C","side":"A","price":"1.156700000","size":30,"channel_id":23,"order_id":"1775530656076952586","flags":0,"ts_in_delta":985,"sequence":176616,"symbol":"FCEU SI 20260615 PS"}
{"ts_recv":"2026-04-07T02:57:38.161614997Z","hd":{"ts_event":"2026-04-07T02:57:38.161594923Z","rtype":160,"publisher_id":101,"instrument_id":436},"action":"A","side":"A","price":"1.156720000","size":30,"channel_id":23,"order_id":"1775530658161601111","flags":128,"ts_in_delta":985,"sequence":176616,"symbol":"FCEU SI 20260615 PS"}
{"ts_recv":"2026-04-07T02:57:38.161670175Z","hd":{"ts_event":"2026-04-07T02:57:38.161653331Z","rtype":160,"publisher_id":101,"instrument_id":436},"action":"C","side":"B","price":"1.156610000","size":30,"channel_id":23,"order_id":"10998902695016323343","flags":0,"ts_in_delta":982,"sequence":176617,"symbol":"FCEU SI 20260615 PS"}
{"ts_recv":"2026-04-07T02:57:38.161670175Z","hd":{"ts_event":"2026-04-07T02:57:38.161653331Z","rtype":160,"publisher_id":101,"instrument_id":436},"action":"A","side":"B","price":"1.156620000","size":30,"channel_id":23,"order_id":"10998902695016435057","flags":0,"ts_in_delta":982,"sequence":176617,"symbol":"FCEU SI 20260615 PS"}
{"ts_recv":"2026-04-07T02:57:38.161670175Z","hd":{"ts_event":"2026-04-07T02:57:38.161653331Z","rtype":160,"publisher_id":101,"instrument_id":436},"action":"C","side":"A","price":"1.156710000","size":30,"channel_id":23,"order_id":"1775530658161547535","flags":0,"ts_in_delta":982,"sequence":176617,"symbol":"FCEU SI 20260615 PS"}
{"ts_recv":"2026-04-07T02:57:38.161670175Z","hd":{"ts_event":"2026-04-07T02:57:38.161653331Z","rtype":160,"publisher_id":101,"instrument_id":436},"action":"A","side":"A","price":"1.156720000","size":30,"channel_id":23,"order_id":"1775530658161659249","flags":128,"ts_in_delta":982,"sequence":176617,"symbol":"FCEU SI 20260615 PS"}
{"ts_recv":"2026-04-07T02:57:39.482482679Z","hd":{"ts_event":"2026-04-07T02:57:39.482463011Z","rtype":160,"publisher_id":101,"instrument_id":436},"action":"C","side":"B","price":"1.156620000","size":30,"channel_id":23,"order_id":"10998902695016435057","flags":0,"ts_in_delta":927,"sequence":176650,"symbol":"FCEU SI 20260615 PS"}
{"ts_recv":"2026-04-07T02:57:39.482482679Z","hd":{"ts_event":"2026-04-07T02:57:39.482463011Z","rtype":160,"publisher_id":101,"instrument_id":436},"action":"A","side":"B","price":"1.156610000","size":30,"channel_id":23,"order_id":"10998902696337244688","flags":0,"ts_in_delta":927,"sequence":176650,"symbol":"FCEU SI 20260615 PS"}
{"ts_recv":"2026-04-07T02:57:39.482482679Z","hd":{"ts_event":"2026-04-07T02:57:39.482463011Z","rtype":160,"publisher_id":101,"instrument_id":436},"action":"C","side":"A","price":"1.156720000","size":30,"channel_id":23,"order_id":"1775530658161659249","flags":0,"ts_in_delta":927,"sequence":176650,"symbol":"FCEU SI 20260615 PS"}
{"ts_recv":"2026-04-07T02:57:39.482482679Z","hd":{"ts_event":"2026-04-07T02:57:39.482463011Z","rtype":160,"publisher_id":101,"instrument_id":436},"action":"A","side":"A","price":"1.156710000","size":30,"channel_id":23,"order_id":"1775530659482468880","flags":128,"ts_in_delta":927,"sequence":176650,"symbol":"FCEU SI 20260615 PS"}
{"ts_recv":"2026-04-07T02:57:40.115707391Z","hd":{"ts_event":"2026-04-07T02:57:40.115686277Z","rtype":160,"publisher_id":101,"instrument_id":436},"action":"C","side":"B","price":"1.156620000","size":30,"channel_id":23,"order_id":"10998902695016376919","flags":0,"ts_in_delta":965,"sequence":176662,"symbol":"FCEU SI 20260615 PS"}
{"ts_recv":"2026-04-07T02:57:40.115707391Z","hd":{"ts_event":"2026-04-07T02:57:40.115686277Z","rtype":160,"publisher_id":101,"instrument_id":436},"action":"A","side":"B","price":"1.156600000","size":30,"channel_id":23,"order_id":"10998902696970468581","flags":0,"ts_in_delta":965,"sequence":176662,"symbol":"FCEU SI 20260615 PS"}
{"ts_recv":"2026-04-07T02:57:40.115707391Z","hd":{"ts_event":"2026-04-07T02:57:40.115686277Z","rtype":160,"publisher_id":101,"instrument_id":436},"action":"C","side":"A","price":"1.156720000","size":30,"channel_id":23,"order_id":"1775530658161601111","flags":0,"ts_in_delta":965,"sequence":176662,"symbol":"FCEU SI 20260615 PS"}
{"ts_recv":"2026-04-07T02:57:40.115707391Z","hd":{"ts_event":"2026-04-07T02:57:40.115686277Z","rtype":160,"publisher_id":101,"instrument_id":436},"action":"A","side":"A","price":"1.156700000","size":30,"channel_id":23,"order_id":"1775530660115692773","flags":128,"ts_in_delta":965,"sequence":176662,"symbol":"FCEU SI 20260615 PS"}
{"ts_recv":"2026-04-07T02:57:40.115800860Z","hd":{"ts_event":"2026-04-07T02:57:40.115782893Z","rtype":160,"publisher_id":101,"instrument_id":436},"action":"C","side":"B","price":"1.156610000","size":30,"channel_id":23,"order_id":"10998902696337244688","flags":0,"ts_in_delta":952,"sequence":176663,"symbol":"FCEU SI 20260615 PS"}
{"ts_recv":"2026-04-07T02:57:40.115800860Z","hd":{"ts_event":"2026-04-07T02:57:40.115782893Z","rtype":160,"publisher_id":101,"instrument_id":436},"action":"A","side":"B","price":"1.156600000","size":30,"channel_id":23,"order_id":"10998902696970564799","flags":0,"ts_in_delta":952,"sequence":176663,"symbol":"FCEU SI 20260615 PS"}
{"ts_recv":"2026-04-07T02:57:40.115800860Z","hd":{"ts_event":"2026-04-07T02:57:40.115782893Z","rtype":160,"publisher_id":101,"instrument_id":436},"action":"C","side":"A","price":"1.156710000","size":30,"channel_id":23,"order_id":"1775530659482468880","flags":0,"ts_in_delta":952,"sequence":176663,"symbol":"FCEU SI 20260615 PS"}
{"ts_recv":"2026-04-07T02:57:40.115800860Z","hd":{"ts_event":"2026-04-07T02:57:40.115782893Z","rtype":160,"publisher_id":101,"instrument_id":436},"action":"A","side":"A","price":"1.156700000","size":30,"channel_id":23,"order_id":"1775530660115788991","flags":128,"ts_in_delta":952,"sequence":176663,"symbol":"FCEU SI 20260615 PS"}
{"ts_recv":"2026-04-07T02:57:44.047479554Z","hd":{"ts_event":"2026-04-07T02:57:44.047459831Z","rtype":160,"publisher_id":101,"instrument_id":436},"action":"C","side":"B","price":"1.156600000","size":30,"channel_id":23,"order_id":"10998902696970564799","flags":0,"ts_in_delta":926,"sequence":176690,"symbol":"FCEU SI 20260615 PS"}
{"ts_recv":"2026-04-07T02:57:44.047479554Z","hd":{"ts_event":"2026-04-07T02:57:44.047459831Z","rtype":160,"publisher_id":101,"instrument_id":436},"action":"A","side":"B","price":"1.156610000","size":30,"channel_id":23,"order_id":"10998902700902241693","flags":0,"ts_in_delta":926,"sequence":176690,"symbol":"FCEU SI 20260615 PS"}
{"ts_recv":"2026-04-07T02:57:44.047479554Z","hd":{"ts_event":"2026-04-07T02:57:44.047459831Z","rtype":160,"publisher_id":101,"instrument_id":436},"action":"C","side":"A","price":"1.156700000","size":30,"channel_id":23,"order_id":"1775530660115788991","flags":0,"ts_in_delta":926,"sequence":176690,"symbol":"FCEU SI 20260615 PS"}
{"ts_recv":"2026-04-07T02:57:44.047479554Z","hd":{"ts_event":"2026-04-07T02:57:44.047459831Z","rtype":160,"publisher_id":101,"instrument_id":436},"action":"A","side":"A","price":"1.156710000","size":30,"channel_id":23,"order_id":"1775530664047465885","flags":128,"ts_in_delta":926,"sequence":176690,"symbol":"FCEU SI 20260615 PS"}
{"ts_recv":"2026-04-07T02:57:44.047534471Z","hd":{"ts_event":"2026-04-07T02:57:44.047513571Z","rtype":160,"publisher_id":101,"instrument_id":436},"action":"C","side":"B","price":"1.156600000","size":30,"channel_id":23,"order_id":"10998902696970468581","flags":0,"ts_in_delta":892,"sequence":176691,"symbol":"FCEU SI 20260615 PS"}
{"ts_recv":"2026-04-07T02:57:44.047534471Z","hd":{"ts_event":"2026-04-07T02:57:44.047513571Z","rtype":160,"publisher_id":101,"instrument_id":436},"action":"A","side":"B","price":"1.156620000","size":30,"channel_id":23,"order_id":"10998902700902295870","flags":0,"ts_in_delta":892,"sequence":176691,"symbol":"FCEU SI 20260615 PS"}
{"ts_recv":"2026-04-07T02:57:44.047534471Z","hd":{"ts_event":"2026-04-07T02:57:44.047513571Z","rtype":160,"publisher_id":101,"instrument_id":436},"action":"C","side":"A","price":"1.156700000","size":30,"channel_id":23,"order_id":"1775530660115692773","flags":0,"ts_in_delta":892,"sequence":176691,"symbol":"FCEU SI 20260615 PS"}
{"ts_recv":"2026-04-07T02:57:44.047534471Z","hd":{"ts_event":"2026-04-07T02:57:44.047513571Z","rtype":160,"publisher_id":101,"instrument_id":436},"action":"A","side":"A","price":"1.156720000","size":30,"channel_id":23,"order_id":"1775530664047520062","flags":128,"ts_in_delta":892,"sequence":176691,"symbol":"FCEU SI 20260615 PS"}
{"ts_recv":"2026-04-07T02:57:44.047596100Z","hd":{"ts_event":"2026-04-07T02:57:44.047577759Z","rtype":160,"publisher_id":101,"instrument_id":436},"action":"C","side":"B","price":"1.156610000","size":30,"channel_id":23,"order_id":"10998902700902241693","flags":0,"ts_in_delta":900,"sequence":176692,"symbol":"FCEU SI 20260615 PS"}
{"ts_recv":"2026-04-07T02:57:44.047596100Z","hd":{"ts_event":"2026-04-07T02:57:44.047577759Z","rtype":160,"publisher_id":101,"instrument_id":436},"action":"A","side":"B","price":"1.156620000","size":30,"channel_id":23,"order_id":"10998902700902359347","flags":0,"ts_in_delta":900,"sequence":176692,"symbol":"FCEU SI 20260615 PS"}
{"ts_recv":"2026-04-07T02:57:44.047596100Z","hd":{"ts_event":"2026-04-07T02:57:44.047577759Z","rtype":160,"publisher_id":101,"instrument_id":436},"action":"C","side":"A","price":"1.156710000","size":30,"channel_id":23,"order_id":"1775530664047465885","flags":0,"ts_in_delta":900,"sequence":176692,"symbol":"FCEU SI 20260615 PS"}
{"ts_recv":"2026-04-07T02:57:44.047596100Z","hd":{"ts_event":"2026-04-07T02:57:44.047577759Z","rtype":160,"publisher_id":101,"instrument_id":436},"action":"A","side":"A","price":"1.156720000","size":30,"channel_id":23,"order_id":"1775530664047583539","flags":128,"ts_in_delta":900,"sequence":176692,"symbol":"FCEU SI 20260615 PS"}
{"ts_recv":"2026-04-07T02:57:44.447459831Z","hd":{"ts_event":"2026-04-07T02:57:44.447441157Z","rtype":160,"publisher_id":101,"instrument_id":436},"action":"C","side":"B","price":"1.156620000","size":30,"channel_id":23,"order_id":"10998902700902359347","flags":0,"ts_in_delta":850,"sequence":176715,"symbol":"FCEU SI 20260615 PS"}
{"ts_recv":"2026-04-07T02:57:44.447459831Z","hd":{"ts_event":"2026-04-07T02:57:44.447441157Z","rtype":160,"publisher_id":101,"instrument_id":436},"action":"A","side":"B","price":"1.156630000","size":30,"channel_id":23,"order_id":"10998902701302222611","flags":0,"ts_in_delta":850,"sequence":176715,"symbol":"FCEU SI 20260615 PS"}
{"ts_recv":"2026-04-07T02:57:44.447459831Z","hd":{"ts_event":"2026-04-07T02:57:44.447441157Z","rtype":160,"publisher_id":101,"instrument_id":436},"action":"C","side":"A","price":"1.156720000","size":30,"channel_id":23,"order_id":"1775530664047583539","flags":0,"ts_in_delta":850,"sequence":176715,"symbol":"FCEU SI 20260615 PS"}
{"ts_recv":"2026-04-07T02:57:44.447459831Z","hd":{"ts_event":"2026-04-07T02:57:44.447441157Z","rtype":160,"publisher_id":101,"instrument_id":436},"action":"A","side":"A","price":"1.156730000","size":30,"channel_id":23,"order_id":"1775530664447446803","flags":128,"ts_in_delta":850,"sequence":176715,"symbol":"FCEU SI 20260615 PS"}
{"ts_recv":"2026-04-07T02:57:51.352475882Z","hd":{"ts_event":"2026-04-07T02:57:51.352454391Z","rtype":160,"publisher_id":101,"instrument_id":436},"action":"C","side":"B","price":"1.156620000","size":30,"channel_id":23,"order_id":"10998902700902295870","flags":0,"ts_in_delta":965,"sequence":176771,"symbol":"FCEU SI 20260615 PS"}
{"ts_recv":"2026-04-07T02:57:51.352475882Z","hd":{"ts_event":"2026-04-07T02:57:51.352454391Z","rtype":160,"publisher_id":101,"instrument_id":436},"action":"A","side":"B","price":"1.156640000","size":30,"channel_id":23,"order_id":"10998902708207236433","flags":0,"ts_in_delta":965,"sequence":176771,"symbol":"FCEU SI 20260615 PS"}
{"ts_recv":"2026-04-07T02:57:51.352475882Z","hd":{"ts_event":"2026-04-07T02:57:51.352454391Z","rtype":160,"publisher_id":101,"instrument_id":436},"action":"C","side":"A","price":"1.156720000","size":30,"channel_id":23,"order_id":"1775530664047520062","flags":0,"ts_in_delta":965,"sequence":176771,"symbol":"FCEU SI 20260615 PS"}
{"ts_recv":"2026-04-07T02:57:51.352475882Z","hd":{"ts_event":"2026-04-07T02:57:51.352454391Z","rtype":160,"publisher_id":101,"instrument_id":436},"action":"A","side":"A","price":"1.156740000","size":30,"channel_id":23,"order_id":"1775530671352460625","flags":128,"ts_in_delta":965,"sequence":176771,"symbol":"FCEU SI 20260615 PS"}
{"ts_recv":"2026-04-07T02:57:51.352579642Z","hd":{"ts_event":"2026-04-07T02:57:51.352563295Z","rtype":160,"publisher_id":101,"instrument_id":436},"action":"C","side":"B","price":"1.156630000","size":30,"channel_id":23,"order_id":"10998902701302222611","flags":0,"ts_in_delta":958,"sequence":176772,"symbol":"FCEU SI 20260615 PS"}
{"ts_recv":"2026-04-07T02:57:51.352579642Z","hd":{"ts_event":"2026-04-07T02:57:51.352563295Z","rtype":160,"publisher_id":101,"instrument_id":436},"action":"A","side":"B","price":"1.156640000","size":30,"channel_id":23,"order_id":"10998902708207345247","flags":0,"ts_in_delta":958,"sequence":176772,"symbol":"FCEU SI 20260615 PS"}
{"ts_recv":"2026-04-07T02:57:51.352579642Z","hd":{"ts_event":"2026-04-07T02:57:51.352563295Z","rtype":160,"publisher_id":101,"instrument_id":436},"action":"C","side":"A","price":"1.156730000","size":30,"channel_id":23,"order_id":"1775530664447446803","flags":0,"ts_in_delta":958,"sequence":176772,"symbol":"FCEU SI 20260615 PS"}
{"ts_recv":"2026-04-07T02:57:51.352579642Z","hd":{"ts_event":"2026-04-07T02:57:51.352563295Z","rtype":160,"publisher_id":101,"instrument_id":436},"action":"A","side":"A","price":"1.156740000","size":30,"channel_id":23,"order_id":"1775530671352569439","flags":128,"ts_in_delta":958,"sequence":176772,"symbol":"FCEU SI 20260615 PS"}
{"ts_recv":"2026-04-07T02:57:56.763107590Z","hd":{"ts_event":"2026-04-07T02:57:56.763088591Z","rtype":160,"publisher_id":101,"instrument_id":436},"action":"C","side":"B","price":"1.156640000","size":30,"channel_id":23,"order_id":"10998902708207236433","flags":0,"ts_in_delta":935,"sequence":176826,"symbol":"FCEU SI 20260615 PS"}
{"ts_recv":"2026-04-07T02:57:56.763107590Z","hd":{"ts_event":"2026-04-07T02:57:56.763088591Z","rtype":160,"publisher_id":101,"instrument_id":436},"action":"A","side":"B","price":"1.156620000","size":30,"channel_id":23,"order_id":"10998902713617870073","flags":0,"ts_in_delta":935,"sequence":176826,"symbol":"FCEU SI 20260615 PS"}
{"ts_recv":"2026-04-07T02:57:56.763107590Z","hd":{"ts_event":"2026-04-07T02:57:56.763088591Z","rtype":160,"publisher_id":101,"instrument_id":436},"action":"C","side":"A","price":"1.156740000","size":30,"channel_id":23,"order_id":"1775530671352460625","flags":0,"ts_in_delta":935,"sequence":176826,"symbol":"FCEU SI 20260615 PS"}
{"ts_recv":"2026-04-07T02:57:56.763107590Z","hd":{"ts_event":"2026-04-07T02:57:56.763088591Z","rtype":160,"publisher_id":101,"instrument_id":436},"action":"A","side":"A","price":"1.156720000","size":30,"channel_id":23,"order_id":"1775530676763094265","flags":128,"ts_in_delta":935,"sequence":176826,"symbol":"FCEU SI 20260615 PS"}
{"ts_recv":"2026-04-07T02:57:56.763222578Z","hd":{"ts_event":"2026-04-07T02:57:56.763203291Z","rtype":160,"publisher_id":101,"instrument_id":436},"action":"C","side":"B","price":"1.156640000","size":30,"channel_id":23,"order_id":"10998902708207345247","flags":0,"ts_in_delta":915,"sequence":176827,"symbol":"FCEU SI 20260615 PS"}
{"ts_recv":"2026-04-07T02:57:56.763222578Z","hd":{"ts_event":"2026-04-07T02:57:56.763203291Z","rtype":160,"publisher_id":101,"instrument_id":436},"action":"A","side":"B","price":"1.156630000","size":30,"channel_id":23,"order_id":"10998902713617985142","flags":0,"ts_in_delta":915,"sequence":176827,"symbol":"FCEU SI 20260615 PS"}
{"ts_recv":"2026-04-07T02:57:56.763222578Z","hd":{"ts_event":"2026-04-07T02:57:56.763203291Z","rtype":160,"publisher_id":101,"instrument_id":436},"action":"C","side":"A","price":"1.156740000","size":30,"channel_id":23,"order_id":"1775530671352569439","flags":0,"ts_in_delta":915,"sequence":176827,"symbol":"FCEU SI 20260615 PS"}
{"ts_recv":"2026-04-07T02:57:56.763222578Z","hd":{"ts_event":"2026-04-07T02:57:56.763203291Z","rtype":160,"publisher_id":101,"instrument_id":436},"action":"A","side":"A","price":"1.156730000","size":30,"channel_id":23,"order_id":"1775530676763209334","flags":128,"ts_in_delta":915,"sequence":176827,"symbol":"FCEU SI 20260615 PS"}
{"ts_recv":"2026-04-07T02:57:56.764613415Z","hd":{"ts_event":"2026-04-07T02:57:56.764593989Z","rtype":160,"publisher_id":101,"instrument_id":436},"action":"C","side":"B","price":"1.156630000","size":30,"channel_id":23,"order_id":"10998902713617985142","flags":0,"ts_in_delta":967,"sequence":176828,"symbol":"FCEU SI 20260615 PS"}
{"ts_recv":"2026-04-07T02:57:56.764613415Z","hd":{"ts_event":"2026-04-07T02:57:56.764593989Z","rtype":160,"publisher_id":101,"instrument_id":436},"action":"A","side":"B","price":"1.156620000","size":30,"channel_id":23,"order_id":"10998902713619375921","flags":0,"ts_in_delta":967,"sequence":176828,"symbol":"FCEU SI 20260615 PS"}
{"ts_recv":"2026-04-07T02:57:56.764613415Z","hd":{"ts_event":"2026-04-07T02:57:56.764593989Z","rtype":160,"publisher_id":101,"instrument_id":436},"action":"C","side":"A","price":"1.156730000","size":30,"channel_id":23,"order_id":"1775530676763209334","flags":0,"ts_in_delta":967,"sequence":176828,"symbol":"FCEU SI 20260615 PS"}
{"ts_recv":"2026-04-07T02:57:56.764613415Z","hd":{"ts_event":"2026-04-07T02:57:56.764593989Z","rtype":160,"publisher_id":101,"instrument_id":436},"action":"A","side":"A","price":"1.156720000","size":30,"channel_id":23,"order_id":"1775530676764600113","flags":128,"ts_in_delta":967,"sequence":176828,"symbol":"FCEU SI 20260615 PS"}
{"ts_recv":"2026-04-07T02:57:56.790470601Z","hd":{"ts_event":"2026-04-07T02:57:56.790451117Z","rtype":160,"publisher_id":101,"instrument_id":436},"action":"C","side":"B","price":"1.156620000","size":30,"channel_id":23,"order_id":"10998902713617870073","flags":0,"ts_in_delta":902,"sequence":176830,"symbol":"FCEU SI 20260615 PS"}
{"ts_recv":"2026-04-07T02:57:56.790470601Z","hd":{"ts_event":"2026-04-07T02:57:56.790451117Z","rtype":160,"publisher_id":101,"instrument_id":436},"action":"A","side":"B","price":"1.156600000","size":30,"channel_id":23,"order_id":"10998902713645232998","flags":0,"ts_in_delta":902,"sequence":176830,"symbol":"FCEU SI 20260615 PS"}
{"ts_recv":"2026-04-07T02:57:56.790470601Z","hd":{"ts_event":"2026-04-07T02:57:56.790451117Z","rtype":160,"publisher_id":101,"instrument_id":436},"action":"C","side":"A","price":"1.156720000","size":30,"channel_id":23,"order_id":"1775530676763094265","flags":0,"ts_in_delta":902,"sequence":176830,"symbol":"FCEU SI 20260615 PS"}
{"ts_recv":"2026-04-07T02:57:56.790470601Z","hd":{"ts_event":"2026-04-07T02:57:56.790451117Z","rtype":160,"publisher_id":101,"instrument_id":436},"action":"A","side":"A","price":"1.156700000","size":30,"channel_id":23,"order_id":"1775530676790457190","flags":128,"ts_in_delta":902,"sequence":176830,"symbol":"FCEU SI 20260615 PS"}
{"ts_recv":"2026-04-07T02:57:56.790532430Z","hd":{"ts_event":"2026-04-07T02:57:56.790512979Z","rtype":160,"publisher_id":101,"instrument_id":436},"action":"C","side":"B","price":"1.156620000","size":30,"channel_id":23,"order_id":"10998902713619375921","flags":0,"ts_in_delta":938,"sequence":176831,"symbol":"FCEU SI 20260615 PS"}
{"ts_recv":"2026-04-07T02:57:56.790532430Z","hd":{"ts_event":"2026-04-07T02:57:56.790512979Z","rtype":160,"publisher_id":101,"instrument_id":436},"action":"A","side":"B","price":"1.156610000","size":30,"channel_id":23,"order_id":"10998902713645295041","flags":0,"ts_in_delta":938,"sequence":176831,"symbol":"FCEU SI 20260615 PS"}
{"ts_recv":"2026-04-07T02:57:56.790532430Z","hd":{"ts_event":"2026-04-07T02:57:56.790512979Z","rtype":160,"publisher_id":101,"instrument_id":436},"action":"C","side":"A","price":"1.156720000","size":30,"channel_id":23,"order_id":"1775530676764600113","flags":0,"ts_in_delta":938,"sequence":176831,"symbol":"FCEU SI 20260615 PS"}
{"ts_recv":"2026-04-07T02:57:56.790532430Z","hd":{"ts_event":"2026-04-07T02:57:56.790512979Z","rtype":160,"publisher_id":101,"instrument_id":436},"action":"A","side":"A","price":"1.156710000","size":30,"channel_id":23,"order_id":"1775530676790519233","flags":128,"ts_in_delta":938,"sequence":176831,"symbol":"FCEU SI 20260615 PS"}
{"ts_recv":"2026-04-07T02:57:56.819372207Z","hd":{"ts_event":"2026-04-07T02:57:56.819355981Z","rtype":160,"publisher_id":101,"instrument_id":436},"action":"C","side":"B","price":"1.156610000","size":30,"channel_id":23,"order_id":"10998902713645295041","flags":0,"ts_in_delta":1049,"sequence":176838,"symbol":"FCEU SI 20260615 PS"}
{"ts_recv":"2026-04-07T02:57:56.819372207Z","hd":{"ts_event":"2026-04-07T02:57:56.819355981Z","rtype":160,"publisher_id":101,"instrument_id":436},"action":"A","side":"B","price":"1.156600000","size":30,"channel_id":23,"order_id":"10998902713674138080","flags":0,"ts_in_delta":1049,"sequence":176838,"symbol":"FCEU SI 20260615 PS"}
{"ts_recv":"2026-04-07T02:57:56.819372207Z","hd":{"ts_event":"2026-04-07T02:57:56.819355981Z","rtype":160,"publisher_id":101,"instrument_id":436},"action":"C","side":"A","price":"1.156710000","size":30,"channel_id":23,"order_id":"1775530676790519233","flags":0,"ts_in_delta":1049,"sequence":176838,"symbol":"FCEU SI 20260615 PS"}
{"ts_recv":"2026-04-07T02:57:56.819372207Z","hd":{"ts_event":"2026-04-07T02:57:56.819355981Z","rtype":160,"publisher_id":101,"instrument_id":436},"action":"A","side":"A","price":"1.156700000","size":30,"channel_id":23,"order_id":"1775530676819362272","flags":128,"ts_in_delta":1049,"sequence":176838,"symbol":"FCEU SI 20260615 PS"}
