{"ts_recv":"2026-04-07T03:12:07.326019502Z","hd":{"ts_event":"2026-04-07T03:12:07.325997825Z","rtype":160,"publisher_id":101,"instrument_id":436},"action":"C","side":"B","price":"1.156810000","size":30,"channel_id":23,"order_id":"10998903552286406493","flags":0,"ts_in_delta":953,"sequence":183635,"symbol":"FCEU SI 20260615 PS"}
{"ts_recv":"2026-04-07T03:12:07.326019502Z","hd":{"ts_event":"2026-04-07T03:12:07.325997825Z","rtype":160,"publisher_id":101,"instrument_id":436},"action":"A","side":"B","price":"1.156800000","size":30,"channel_id":23,"order_id":"10998903564180780139","flags":0,"ts_in_delta":953,"sequence":183635,"symbol":"FCEU SI 20260615 PS"}
{"ts_recv":"2026-04-07T03:12:07.326019502Z","hd":{"ts_event":"2026-04-07T03:12:07.325997825Z","rtype":160,"publisher_id":101,"instrument_id":436},"action":"C","side":"A","price":"1.156910000","size":30,"channel_id":23,"order_id":"1775531515431630685","flags":0,"ts_in_delta":953,"sequence":183635,"symbol":"FCEU SI 20260615 PS"}
{"ts_recv":"2026-04-07T03:12:07.326019502Z","hd":{"ts_event":"2026-04-07T03:12:07.325997825Z","rtype":160,"publisher_id":101,"instrument_id":436},"action":"A","side":"A","price":"1.156900000","size":30,"channel_id":23,"order_id":"1775531527326004331","flags":128,"ts_in_delta":953,"sequence":183635,"symbol":"FCEU SI 20260615 PS"}
{"ts_recv":"2026-04-07T03:12:07.326094355Z","hd":{"ts_event":"2026-04-07T03:12:07.326070785Z","rtype":160,"publisher_id":101,"instrument_id":436},"action":"C","side":"B","price":"1.156810000","size":30,"channel_id":23,"order_id":"10998903552286289685","flags":0,"ts_in_delta":917,"sequence":183636,"symbol":"FCEU SI 20260615 PS"}
{"ts_recv":"2026-04-07T03:12:07.326094355Z","hd":{"ts_event":"2026-04-07T03:12:07.326070785Z","rtype":160,"publisher_id":101,"instrument_id":436},"action":"A","side":"B","price":"1.156790000","size":30,"channel_id":23,"order_id":"10998903564180853045","flags":0,"ts_in_delta":917,"sequence":183636,"symbol":"FCEU SI 20260615 PS"}
{"ts_recv":"2026-04-07T03:12:07.326094355Z","hd":{"ts_event":"2026-04-07T03:12:07.326070785Z","rtype":160,"publisher_id":101,"instrument_id":436},"action":"C","side":"A","price":"1.156910000","size":30,"channel_id":23,"order_id":"1775531515431513877","flags":0,"ts_in_delta":917,"sequence":183636,"symbol":"FCEU SI 20260615 PS"}
{"ts_recv":"2026-04-07T03:12:07.326094355Z","hd":{"ts_event":"2026-04-07T03:12:07.326070785Z","rtype":160,"publisher_id":101,"instrument_id":436},"action":"A","side":"A","price":"1.156890000","size":30,"channel_id":23,"order_id":"1775531527326077237","flags":128,"ts_in_delta":917,"sequence":183636,"symbol":"FCEU SI 20260615 PS"}
{"ts_recv":"2026-04-07T03:12:07.326156991Z","hd":{"ts_event":"2026-04-07T03:12:07.326137015Z","rtype":160,"publisher_id":101,"instrument_id":436},"action":"C","side":"B","price":"1.156800000","size":30,"channel_id":23,"order_id":"10998903564180780139","flags":0,"ts_in_delta":931,"sequence":183637,"symbol":"FCEU SI 20260615 PS"}
{"ts_recv":"2026-04-07T03:12:07.326156991Z","hd":{"ts_event":"2026-04-07T03:12:07.326137015Z","rtype":160,"publisher_id":101,"instrument_id":436},"action":"A","side":"B","price":"1.156790000","size":30,"channel_id":23,"order_id":"10998903564180918707","flags":0,"ts_in_delta":931,"sequence":183637,"symbol":"FCEU SI 20260615 PS"}
{"ts_recv":"2026-04-07T03:12:07.326156991Z","hd":{"ts_event":"2026-04-07T03:12:07.326137015Z","rtype":160,"publisher_id":101,"instrument_id":436},"action":"C","side":"A","price":"1.156900000","size":30,"channel_id":23,"order_id":"1775531527326004331","flags":0,"ts_in_delta":931,"sequence":183637,"symbol":"FCEU SI 20260615 PS"}
{"ts_recv":"2026-04-07T03:12:07.326156991Z","hd":{"ts_event":"2026-04-07T03:12:07.326137015Z","rtype":160,"publisher_id":101,"instrument_id":436},"action":"A","side":"A","price":"1.156890000","size":30,"channel_id":23,"order_id":"1775531527326142899","flags":128,"ts_in_delta":931,"sequence":183637,"symbol":"FCEU SI 20260615 PS"}
{"ts_recv":"2026-04-07T03:13:17.620175168Z","hd":{"ts_event":"2026-04-07T03:13:17.620147519Z","rtype":160,"publisher_id":101,"instrument_id":436},"action":"C","side":"B","price":"1.156790000","size":30,"channel_id":23,"order_id":"10998903564180853045","flags":0,"ts_in_delta":948,"sequence":184099,"symbol":"FCEU SI 20260615 PS"}
{"ts_recv":"2026-04-07T03:13:17.620175168Z","hd":{"ts_event":"2026-04-07T03:13:17.620147519Z","rtype":160,"publisher_id":101,"instrument_id":436},"action":"A","side":"B","price":"1.156770000","size":30,"channel_id":23,"order_id":"10998903634474930116","flags":0,"ts_in_delta":948,"sequence":184099,"symbol":"FCEU SI 20260615 PS"}
{"ts_recv":"2026-04-07T03:13:17.620175168Z","hd":{"ts_event":"2026-04-07T03:13:17.620147519Z","rtype":160,"publisher_id":101,"instrument_id":436},"action":"C","side":"A","price":"1.156890000","size":30,"channel_id":23,"order_id":"1775531527326077237","flags":0,"ts_in_delta":948,"sequence":184099,"symbol":"FCEU SI 20260615 PS"}
{"ts_recv":"2026-04-07T03:13:17.620175168Z","hd":{"ts_event":"2026-04-07T03:13:17.620147519Z","rtype":160,"publisher_id":101,"instrument_id":436},"action":"A","side":"A","price":"1.156870000","size":30,"channel_id":23,"order_id":"1775531597620154308","flags":128,"ts_in_delta":948,"sequence":184099,"symbol":"FCEU SI 20260615 PS"}
{"ts_recv":"2026-04-07T03:13:17.620256856Z","hd":{"ts_event":"2026-04-07T03:13:17.620235771Z","rtype":160,"publisher_id":101,"instrument_id":436},"action":"C","side":"B","price":"1.156790000","size":30,"channel_id":23,"order_id":"10998903564180918707","flags":0,"ts_in_delta":973,"sequence":184100,"symbol":"FCEU SI 20260615 PS"}
{"ts_recv":"2026-04-07T03:13:17.620256856Z","hd":{"ts_event":"2026-04-07T03:13:17.620235771Z","rtype":160,"publisher_id":101,"instrument_id":436},"action":"A","side":"B","price":"1.156780000","size":30,"channel_id":23,"order_id":"10998903634475017897","flags":0,"ts_in_delta":973,"sequence":184100,"symbol":"FCEU SI 20260615 PS"}
{"ts_recv":"2026-04-07T03:13:17.620256856Z","hd":{"ts_event":"2026-04-07T03:13:17.620235771Z","rtype":160,"publisher_id":101,"instrument_id":436},"action":"C","side":"A","price":"1.156890000","size":30,"channel_id":23,"order_id":"1775531527326142899","flags":0,"ts_in_delta":973,"sequence":184100,"symbol":"FCEU SI 20260615 PS"}
{"ts_recv":"2026-04-07T03:13:17.620256856Z","hd":{"ts_event":"2026-04-07T03:13:17.620235771Z","rtype":160,"publisher_id":101,"instrument_id":436},"action":"A","side":"A","price":"1.156880000","size":30,"channel_id":23,"order_id":"1775531597620242089","flags":128,"ts_in_delta":973,"sequence":184100,"symbol":"FCEU SI 20260615 PS"}
{"ts_recv":"2026-04-07T03:13:17.620540166Z","hd":{"ts_event":"2026-04-07T03:13:17.620521597Z","rtype":160,"publisher_id":101,"instrument_id":436},"action":"C","side":"B","price":"1.156780000","size":30,"channel_id":23,"order_id":"10998903634475017897","flags":0,"ts_in_delta":961,"sequence":184103,"symbol":"FCEU SI 20260615 PS"}
{"ts_recv":"2026-04-07T03:13:17.620540166Z","hd":{"ts_event":"2026-04-07T03:13:17.620521597Z","rtype":160,"publisher_id":101,"instrument_id":436},"action":"A","side":"B","price":"1.156770000","size":30,"channel_id":23,"order_id":"10998903634475303013","flags":0,"ts_in_delta":961,"sequence":184103,"symbol":"FCEU SI 20260615 PS"}
{"ts_recv":"2026-04-07T03:13:17.620540166Z","hd":{"ts_event":"2026-04-07T03:13:17.620521597Z","rtype":160,"publisher_id":101,"instrument_id":436},"action":"C","side":"A","price":"1.156880000","size":30,"channel_id":23,"order_id":"1775531597620242089","flags":0,"ts_in_delta":961,"sequence":184103,"symbol":"FCEU SI 20260615 PS"}
{"ts_recv":"2026-04-07T03:13:17.620540166Z","hd":{"ts_event":"2026-04-07T03:13:17.620521597Z","rtype":160,"publisher_id":101,"instrument_id":436},"action":"A","side":"A","price":"1.156870000","size":30,"channel_id":23,"order_id":"1775531597620527205","flags":128,"ts_in_delta":961,"sequence":184103,"symbol":"FCEU SI 20260615 PS"}
{"ts_recv":"2026-04-07T03:13:17.625781219Z","hd":{"ts_event":"2026-04-07T03:13:17.625761295Z","rtype":160,"publisher_id":101,"instrument_id":436},"action":"C","side":"B","price":"1.156770000","size":30,"channel_id":23,"order_id":"10998903634475303013","flags":0,"ts_in_delta":953,"sequence":184107,"symbol":"FCEU SI 20260615 PS"}
{"ts_recv":"2026-04-07T03:13:17.625781219Z","hd":{"ts_event":"2026-04-07T03:13:17.625761295Z","rtype":160,"publisher_id":101,"instrument_id":436},"action":"A","side":"B","price":"1.156760000","size":30,"channel_id":23,"order_id":"10998903634480543142","flags":0,"ts_in_delta":953,"sequence":184107,"symbol":"FCEU SI 20260615 PS"}
{"ts_recv":"2026-04-07T03:13:17.625781219Z","hd":{"ts_event":"2026-04-07T03:13:17.625761295Z","rtype":160,"publisher_id":101,"instrument_id":436},"action":"C","side":"A","price":"1.156870000","size":30,"channel_id":23,"order_id":"1775531597620527205","flags":0,"ts_in_delta":953,"sequence":184107,"symbol":"FCEU SI 20260615 PS"}
{"ts_recv":"2026-04-07T03:13:17.625781219Z","hd":{"ts_event":"2026-04-07T03:13:17.625761295Z","rtype":160,"publisher_id":101,"instrument_id":436},"action":"A","side":"A","price":"1.156860000","size":30,"channel_id":23,"order_id":"1775531597625767334","flags":128,"ts_in_delta":953,"sequence":184107,"symbol":"FCEU SI 20260615 PS"}
{"ts_recv":"2026-04-07T03:13:17.629393687Z","hd":{"ts_event":"2026-04-07T03:13:17.629375013Z","rtype":160,"publisher_id":101,"instrument_id":436},"action":"C","side":"B","price":"1.156770000","size":30,"channel_id":23,"order_id":"10998903634474930116","flags":0,"ts_in_delta":965,"sequence":184110,"symbol":"FCEU SI 20260615 PS"}
{"ts_recv":"2026-04-07T03:13:17.629393687Z","hd":{"ts_event":"2026-04-07T03:13:17.629375013Z","rtype":160,"publisher_id":101,"instrument_id":436},"action":"A","side":"B","price":"1.156750000","size":30,"channel_id":23,"order_id":"10998903634484157028","flags":0,"ts_in_delta":965,"sequence":184110,"symbol":"FCEU SI 20260615 PS"}
{"ts_recv":"2026-04-07T03:13:17.629393687Z","hd":{"ts_event":"2026-04-07T03:13:17.629375013Z","rtype":160,"publisher_id":101,"instrument_id":436},"action":"C","side":"A","price":"1.156870000","size":30,"channel_id":23,"order_id":"1775531597620154308","flags":0,"ts_in_delta":965,"sequence":184110,"symbol":"FCEU SI 20260615 PS"}
{"ts_recv":"2026-04-07T03:13:17.629393687Z","hd":{"ts_event":"2026-04-07T03:13:17.629375013Z","rtype":160,"publisher_id":101,"instrument_id":436},"action":"A","side":"A","price":"1.156850000","size":30,"channel_id":23,"order_id":"1775531597629381220","flags":128,"ts_in_delta":965,"sequence":184110,"symbol":"FCEU SI 20260615 PS"}
{"ts_recv":"2026-04-07T03:13:17.629454471Z","hd":{"ts_event":"2026-04-07T03:13:17.629434897Z","rtype":160,"publisher_id":101,"instrument_id":436},"action":"C","side":"B","price":"1.156760000","size":30,"channel_id":23,"order_id":"10998903634480543142","flags":0,"ts_in_delta":960,"sequence":184111,"symbol":"FCEU SI 20260615 PS"}
{"ts_recv":"2026-04-07T03:13:17.629454471Z","hd":{"ts_event":"2026-04-07T03:13:17.629434897Z","rtype":160,"publisher_id":101,"instrument_id":436},"action":"A","side":"B","price":"1.156750000","size":30,"channel_id":23,"order_id":"10998903634484216703","flags":0,"ts_in_delta":960,"sequence":184111,"symbol":"FCEU SI 20260615 PS"}
{"ts_recv":"2026-04-07T03:13:17.629454471Z","hd":{"ts_event":"2026-04-07T03:13:17.629434897Z","rtype":160,"publisher_id":101,"instrument_id":436},"action":"C","side":"A","price":"1.156860000","size":30,"channel_id":23,"order_id":"1775531597625767334","flags":0,"ts_in_delta":960,"sequence":184111,"symbol":"FCEU SI 20260615 PS"}
{"ts_recv":"2026-04-07T03:13:17.629454471Z","hd":{"ts_event":"2026-04-07T03:13:17.629434897Z","rtype":160,"publisher_id":101,"instrument_id":436},"action":"A","side":"A","price":"1.156850000","size":30,"channel_id":23,"order_id":"1775531597629440895","flags":128,"ts_in_delta":960,"sequence":184111,"symbol":"FCEU SI 20260615 PS"}
{"ts_recv":"2026-04-07T03:13:17.676969706Z","hd":{"ts_event":"2026-04-07T03:13:17.676955491Z","rtype":160,"publisher_id":101,"instrument_id":436},"action":"C","side":"B","price":"1.156700000","size":20,"channel_id":23,"order_id":"10998903500049961705","flags":128,"ts_in_delta":1027,"sequence":184120,"symbol":"FCEU SI 20260615 PS"}
{"ts_recv":"2026-04-07T03:13:17.713687732Z","hd":{"ts_event":"2026-04-07T03:13:17.713673119Z","rtype":160,"publisher_id":101,"instrument_id":436},"action":"A","side":"A","price":"1.157000000","size":20,"channel_id":23,"order_id":"1775531597713679010","flags":128,"ts_in_delta":870,"sequence":184126,"symbol":"FCEU SI 20260615 PS"}
{"ts_recv":"2026-04-07T03:13:17.713715448Z","hd":{"ts_event":"2026-04-07T03:13:17.713701913Z","rtype":160,"publisher_id":101,"instrument_id":436},"action":"C","side":"A","price":"1.157100000","size":20,"channel_id":23,"order_id":"1775531402660452288","flags":128,"ts_in_delta":1000,"sequence":184127,"symbol":"FCEU SI 20260615 PS"}
{"ts_recv":"2026-04-07T03:13:17.743464292Z","hd":{"ts_event":"2026-04-07T03:13:17.743449973Z","rtype":160,"publisher_id":101,"instrument_id":436},"action":"A","side":"B","price":"1.156600000","size":20,"channel_id":23,"order_id":"10998903634598232092","flags":128,"ts_in_delta":1126,"sequence":184134,"symbol":"FCEU SI 20260615 PS"}
{"ts_recv":"2026-04-07T03:13:19.860737907Z","hd":{"ts_event":"2026-04-07T03:13:19.860715597Z","rtype":160,"publisher_id":101,"instrument_id":436},"action":"C","side":"B","price":"1.156750000","size":30,"channel_id":23,"order_id":"10998903634484216703","flags":0,"ts_in_delta":913,"sequence":184155,"symbol":"FCEU SI 20260615 PS"}
{"ts_recv":"2026-04-07T03:13:19.860737907Z","hd":{"ts_event":"2026-04-07T03:13:19.860715597Z","rtype":160,"publisher_id":101,"instrument_id":436},"action":"A","side":"B","price":"1.156740000","size":30,"channel_id":23,"order_id":"10998903636715497877","flags":0,"ts_in_delta":913,"sequence":184155,"symbol":"FCEU SI 20260615 PS"}
{"ts_recv":"2026-04-07T03:13:19.860737907Z","hd":{"ts_event":"2026-04-07T03:13:19.860715597Z","rtype":160,"publisher_id":101,"instrument_id":436},"action":"C","side":"A","price":"1.156850000","size":30,"channel_id":23,"order_id":"1775531597629440895","flags":0,"ts_in_delta":913,"sequence":184155,"symbol":"FCEU SI 20260615 PS"}
{"ts_recv":"2026-04-07T03:13:19.860737907Z","hd":{"ts_event":"2026-04-07T03:13:19.860715597Z","rtype":160,"publisher_id":101,"instrument_id":436},"action":"A","side":"A","price":"1.156840000","size":30,"channel_id":23,"order_id":"1775531599860722069","flags":128,"ts_in_delta":913,"sequence":184155,"symbol":"FCEU SI 20260615 PS"}
{"ts_recv":"2026-04-07T03:13:19.860798637Z","hd":{"ts_event":"2026-04-07T03:13:19.860777345Z","rtype":160,"publisher_id":101,"instrument_id":436},"action":"C","side":"B","price":"1.156750000","size":30,"channel_id":23,"order_id":"10998903634484157028","flags":0,"ts_in_delta":723,"sequence":184156,"symbol":"FCEU SI 20260615 PS"}
{"ts_recv":"2026-04-07T03:13:19.860798637Z","hd":{"ts_event":"2026-04-07T03:13:19.860777345Z","rtype":160,"publisher_id":101,"instrument_id":436},"action":"A","side":"B","price":"1.156730000","size":30,"channel_id":23,"order_id":"10998903636715559460","flags":0,"ts_in_delta":723,"sequence":184156,"symbol":"FCEU SI 20260615 PS"}
{"ts_recv":"2026-04-07T03:13:19.860798637Z","hd":{"ts_event":"2026-04-07T03:13:19.860777345Z","rtype":160,"publisher_id":101,"instrument_id":436},"action":"C","side":"A","price":"1.156850000","size":30,"channel_id":23,"order_id":"1775531597629381220","flags":0,"ts_in_delta":723,"sequence":184156,"symbol":"FCEU SI 20260615 PS"}
{"ts_recv":"2026-04-07T03:13:19.860798637Z","hd":{"ts_event":"2026-04-07T03:13:19.860777345Z","rtype":160,"publisher_id":101,"instrument_id":436},"action":"A","side":"A","price":"1.156830000","size":30,"channel_id":23,"order_id":"1775531599860783652","flags":128,"ts_in_delta":723,"sequence":184156,"symbol":"FCEU SI 20260615 PS"}
{"ts_recv":"2026-04-07T03:13:19.860856104Z","hd":{"ts_event":"2026-04-07T03:13:19.860838343Z","rtype":160,"publisher_id":101,"instrument_id":436},"action":"C","side":"B","price":"1.156740000","size":30,"channel_id":23,"order_id":"10998903636715497877","flags":0,"ts_in_delta":723,"sequence":184157,"symbol":"FCEU SI 20260615 PS"}
{"ts_recv":"2026-04-07T03:13:19.860856104Z","hd":{"ts_event":"2026-04-07T03:13:19.860838343Z","rtype":160,"publisher_id":101,"instrument_id":436},"action":"A","side":"B","price":"1.156730000","size":30,"channel_id":23,"order_id":"10998903636715620296","flags":0,"ts_in_delta":723,"sequence":184157,"symbol":"FCEU SI 20260615 PS"}
{"ts_recv":"2026-04-07T03:13:19.860856104Z","hd":{"ts_event":"2026-04-07T03:13:19.860838343Z","rtype":160,"publisher_id":101,"instrument_id":436},"action":"C","side":"A","price":"1.156840000","size":30,"channel_id":23,"order_id":"1775531599860722069","flags":0,"ts_in_delta":723,"sequence":184157,"symbol":"FCEU SI 20260615 PS"}
{"ts_recv":"2026-04-07T03:13:19.860856104Z","hd":{"ts_event":"2026-04-07T03:13:19.860838343Z","rtype":160,"publisher_id":101,"instrument_id":436},"action":"A","side":"A","price":"1.156830000","size":30,"channel_id":23,"order_id":"1775531599860844488","flags":128,"ts_in_delta":723,"sequence":184157,"symbol":"FCEU SI 20260615 PS"}
{"ts_recv":"2026-04-07T03:13:33.427028443Z","hd":{"ts_event":"2026-04-07T03:13:33.426996099Z","rtype":160,"publisher_id":101,"instrument_id":436},"action":"C","side":"B","price":"1.156730000","size":30,"channel_id":23,"order_id":"10998903636715620296","flags":0,"ts_in_delta":1244,"sequence":184224,"symbol":"FCEU SI 20260615 PS"}
{"ts_recv":"2026-04-07T03:13:33.427028443Z","hd":{"ts_event":"2026-04-07T03:13:33.426996099Z","rtype":160,"publisher_id":101,"instrument_id":436},"action":"A","side":"B","price":"1.156740000","size":30,"channel_id":23,"order_id":"10998903650281784012","flags":0,"ts_in_delta":1244,"sequence":184224,"symbol":"FCEU SI 20260615 PS"}
{"ts_recv":"2026-04-07T03:13:33.427028443Z","hd":{"ts_event":"2026-04-07T03:13:33.426996099Z","rtype":160,"publisher_id":101,"instrument_id":436},"action":"C","side":"A","price":"1.156830000","size":30,"channel_id":23,"order_id":"1775531599860844488","flags":0,"ts_in_delta":1244,"sequence":184224,"symbol":"FCEU SI 20260615 PS"}
{"ts_recv":"2026-04-07T03:13:33.427028443Z","hd":{"ts_event":"2026-04-07T03:13:33.426996099Z","rtype":160,"publisher_id":101,"instrument_id":436},"action":"A","side":"A","price":"1.156840000","size":30,"channel_id":23,"order_id":"1775531613427008204","flags":128,"ts_in_delta":1244,"sequence":184224,"symbol":"FCEU SI 20260615 PS"}
{"ts_recv":"2026-04-07T03:13:33.453439918Z","hd":{"ts_event":"2026-04-07T03:13:33.453420397Z","rtype":160,"publisher_id":101,"instrument_id":436},"action":"C","side":"B","price":"1.156730000","size":30,"channel_id":23,"order_id":"10998903636715559460","flags":0,"ts_in_delta":1189,"sequence":184225,"symbol":"FCEU SI 20260615 PS"}
{"ts_recv":"2026-04-07T03:13:33.453439918Z","hd":{"ts_event":"2026-04-07T03:13:33.453420397Z","rtype":160,"publisher_id":101,"instrument_id":436},"action":"A","side":"B","price":"1.156750000","size":30,"channel_id":23,"order_id":"10998903650308202192","flags":0,"ts_in_delta":1189,"sequence":184225,"symbol":"FCEU SI 20260615 PS"}
{"ts_recv":"2026-04-07T03:13:33.453439918Z","hd":{"ts_event":"2026-04-07T03:13:33.453420397Z","rtype":160,"publisher_id":101,"instrument_id":436},"action":"C","side":"A","price":"1.156830000","size":30,"channel_id":23,"order_id":"1775531599860783652","flags":0,"ts_in_delta":1189,"sequence":184225,"symbol":"FCEU SI 20260615 PS"}
{"ts_recv":"2026-04-07T03:13:33.453439918Z","hd":{"ts_event":"2026-04-07T03:13:33.453420397Z","rtype":160,"publisher_id":101,"instrument_id":436},"action":"A","side":"A","price":"1.156850000","size":30,"channel_id":23,"order_id":"1775531613453426384","flags":128,"ts_in_delta":1189,"sequence":184225,"symbol":"FCEU SI 20260615 PS"}
{"ts_recv":"2026-04-07T03:13:33.453503099Z","hd":{"ts_event":"2026-04-07T03:13:33.453484289Z","rtype":160,"publisher_id":101,"instrument_id":436},"action":"C","side":"B","price":"1.156740000","size":30,"channel_id":23,"order_id":"10998903650281784012","flags":0,"ts_in_delta":1133,"sequence":184226,"symbol":"FCEU SI 20260615 PS"}
{"ts_recv":"2026-04-07T03:13:33.453503099Z","hd":{"ts_event":"2026-04-07T03:13:33.453484289Z","rtype":160,"publisher_id":101,"instrument_id":436},"action":"A","side":"B","price":"1.156750000","size":30,"channel_id":23,"order_id":"10998903650308265921","flags":0,"ts_in_delta":1133,"sequence":184226,"symbol":"FCEU SI 20260615 PS"}
{"ts_recv":"2026-04-07T03:13:33.453503099Z","hd":{"ts_event":"2026-04-07T03:13:33.453484289Z","rtype":160,"publisher_id":101,"instrument_id":436},"action":"C","side":"A","price":"1.156840000","size":30,"channel_id":23,"order_id":"1775531613427008204","flags":0,"ts_in_delta":1133,"sequence":184226,"symbol":"FCEU SI 20260615 PS"}
{"ts_recv":"2026-04-07T03:13:33.453503099Z","hd":{"ts_event":"2026-04-07T03:13:33.453484289Z","rtype":160,"publisher_id":101,"instrument_id":436},"action":"A","side":"A","price":"1.156850000","size":30,"channel_id":23,"order_id":"1775531613453490113","flags":128,"ts_in_delta":1133,"sequence":184226,"symbol":"FCEU SI 20260615 PS"}
{"ts_recv":"2026-04-07T03:13:41.046672186Z","hd":{"ts_event":"2026-04-07T03:13:41.046644619Z","rtype":160,"publisher_id":101,"instrument_id":436},"action":"C","side":"B","price":"1.156750000","size":30,"channel_id":23,"order_id":"10998903650308265921","flags":0,"ts_in_delta":893,"sequence":184263,"symbol":"FCEU SI 20260615 PS"}
{"ts_recv":"2026-04-07T03:13:41.046672186Z","hd":{"ts_event":"2026-04-07T03:13:41.046644619Z","rtype":160,"publisher_id":101,"instrument_id":436},"action":"A","side":"B","price":"1.156740000","size":30,"channel_id":23,"order_id":"10998903657901427064","flags":0,"ts_in_delta":893,"sequence":184263,"symbol":"FCEU SI 20260615 PS"}
{"ts_recv":"2026-04-07T03:13:41.046672186Z","hd":{"ts_event":"2026-04-07T03:13:41.046644619Z","rtype":160,"publisher_id":101,"instrument_id":436},"action":"C","side":"A","price":"1.156850000","size":30,"channel_id":23,"order_id":"1775531613453490113","flags":0,"ts_in_delta":893,"sequence":184263,"symbol":"FCEU SI 20260615 PS"}
{"ts_recv":"2026-04-07T03:13:41.046672186Z","hd":{"ts_event":"2026-04-07T03:13:41.046644619Z","rtype":160,"publisher_id":101,"instrument_id":436},"action":"A","side":"A","price":"1.156840000","size":30,"channel_id":23,"order_id":"1775531621046651256","flags":128,"ts_in_delta":893,"sequence":184263,"symbol":"FCEU SI 20260615 PS"}
{"ts_recv":"2026-04-07T03:13:41.055059007Z","hd":{"ts_event":"2026-04-07T03:13:41.055037829Z","rtype":160,"publisher_id":101,"instrument_id":436},"action":"C","side":"B","price":"1.156750000","size":30,"channel_id":23,"order_id":"10998903650308202192","flags":0,"ts_in_delta":963,"sequence":184266,"symbol":"FCEU SI 20260615 PS"}
{"ts_recv":"2026-04-07T03:13:41.055059007Z","hd":{"ts_event":"2026-04-07T03:13:41.055037829Z","rtype":160,"publisher_id":101,"instrument_id":436},"action":"A","side":"B","price":"1.156730000","size":30,"channel_id":23,"order_id":"10998903657909820125","flags":0,"ts_in_delta":963,"sequence":184266,"symbol":"FCEU SI 20260615 PS"}
{"ts_recv":"2026-04-07T03:13:41.055059007Z","hd":{"ts_event":"2026-04-07T03:13:41.055037829Z","rtype":160,"publisher_id":101,"instrument_id":436},"action":"C","side":"A","price":"1.156850000","size":30,"channel_id":23,"order_id":"1775531613453426384","flags":0,"ts_in_delta":963,"sequence":184266,"symbol":"FCEU SI 20260615 PS"}
{"ts_recv":"2026-04-07T03:13:41.055059007Z","hd":{"ts_event":"2026-04-07T03:13:41.055037829Z","rtype":160,"publisher_id":101,"instrument_id":436},"action":"A","side":"A","price":"1.156830000","size":30,"channel_id":23,"order_id":"1775531621055044317","flags":128,"ts_in_delta":963,"sequence":184266,"symbol":"FCEU SI 20260615 PS"}
{"ts_recv":"2026-04-07T03:13:41.055117848Z","hd":{"ts_event":"2026-04-07T03:13:41.055100459Z","rtype":160,"publisher_id":101,"instrument_id":436},"action":"C","side":"B","price":"1.156740000","size":30,"channel_id":23,"order_id":"10998903657901427064","flags":0,"ts_in_delta":957,"sequence":184267,"symbol":"FCEU SI 20260615 PS"}
{"ts_recv":"2026-04-07T03:13:41.055117848Z","hd":{"ts_event":"2026-04-07T03:13:41.055100459Z","rtype":160,"publisher_id":101,"instrument_id":436},"action":"A","side":"B","price":"1.156730000","size":30,"channel_id":23,"order_id":"10998903657909882197","flags":0,"ts_in_delta":957,"sequence":184267,"symbol":"FCEU SI 20260615 PS"}
{"ts_recv":"2026-04-07T03:13:41.055117848Z","hd":{"ts_event":"2026-04-07T03:13:41.055100459Z","rtype":160,"publisher_id":101,"instrument_id":436},"action":"C","side":"A","price":"1.156840000","size":30,"channel_id":23,"order_id":"1775531621046651256","flags":0,"ts_in_delta":957,"sequence":184267,"symbol":"FCEU SI 20260615 PS"}
{"ts_recv":"2026-04-07T03:13:41.055117848Z","hd":{"ts_event":"2026-04-07T03:13:41.055100459Z","rtype":160,"publisher_id":101,"instrument_id":436},"action":"A","side":"A","price":"1.156830000","size":30,"channel_id":23,"order_id":"1775531621055106389","flags":128,"ts_in_delta":957,"sequence":184267,"symbol":"FCEU SI 20260615 PS"}
{"ts_recv":"2026-04-07T03:14:04.751961334Z","hd":{"ts_event":"2026-04-07T03:14:04.751937509Z","rtype":160,"publisher_id":101,"instrument_id":436},"action":"C","side":"B","price":"1.156730000","size":30,"channel_id":23,"order_id":"10998903657909882197","flags":0,"ts_in_delta":1184,"sequence":184398,"symbol":"FCEU SI 20260615 PS"}
{"ts_recv":"2026-04-07T03:14:04.751961334Z","hd":{"ts_event":"2026-04-07T03:14:04.751937509Z","rtype":160,"publisher_id":101,"instrument_id":436},"action":"A","side":"B","price":"1.156740000","size":30,"channel_id":23,"order_id":"10998903681606719341","flags":0,"ts_in_delta":1184,"sequence":184398,"symbol":"FCEU SI 20260615 PS"}
{"ts_recv":"2026-04-07T03:14:04.751961334Z","hd":{"ts_event":"2026-04-07T03:14:04.751937509Z","rtype":160,"publisher_id":101,"instrument_id":436},"action":"C","side":"A","price":"1.156830000","size":30,"channel_id":23,"order_id":"1775531621055106389","flags":0,"ts_in_delta":1184,"sequence":184398,"symbol":"FCEU SI 20260615 PS"}
{"ts_recv":"2026-04-07T03:14:04.751961334Z","hd":{"ts_event":"2026-04-07T03:14:04.751937509Z","rtype":160,"publisher_id":101,"instrument_id":436},"action":"A","side":"A","price":"1.156840000","size":30,"channel_id":23,"order_id":"1775531644751943533","flags":128,"ts_in_delta":1184,"sequence":184398,"symbol":"FCEU SI 20260615 PS"}
{"ts_recv":"2026-04-07T03:14:16.732735319Z","hd":{"ts_event":"2026-04-07T03:14:16.732707209Z","rtype":160,"publisher_id":101,"instrument_id":436},"action":"C","side":"B","price":"1.156740000","size":30,"channel_id":23,"order_id":"10998903681606719341","flags":0,"ts_in_delta":918,"sequence":184452,"symbol":"FCEU SI 20260615 PS"}
{"ts_recv":"2026-04-07T03:14:16.732735319Z","hd":{"ts_event":"2026-04-07T03:14:16.732707209Z","rtype":160,"publisher_id":101,"instrument_id":436},"action":"A","side":"B","price":"1.156730000","size":30,"channel_id":23,"order_id":"10998903693587495440","flags":0,"ts_in_delta":918,"sequence":184452,"symbol":"FCEU SI 20260615 PS"}
{"ts_recv":"2026-04-07T03:14:16.732735319Z","hd":{"ts_event":"2026-04-07T03:14:16.732707209Z","rtype":160,"publisher_id":101,"instrument_id":436},"action":"C","side":"A","price":"1.156840000","size":30,"channel_id":23,"order_id":"1775531644751943533","flags":0,"ts_in_delta":918,"sequence":184452,"symbol":"FCEU SI 20260615 PS"}
{"ts_recv":"2026-04-07T03:14:16.732735319Z","hd":{"ts_event":"2026-04-07T03:14:16.732707209Z","rtype":160,"publisher_id":101,"instrument_id":436},"action":"A","side":"A","price":"1.156830000","size":30,"channel_id":23,"order_id":"1775531656732719632","flags":128,"ts_in_delta":918,"sequence":184452,"symbol":"FCEU SI 20260615 PS"}
{"ts_recv":"2026-04-07T03:14:35.520756910Z","hd":{"ts_event":"2026-04-07T03:14:35.520733265Z","rtype":160,"publisher_id":101,"instrument_id":436},"action":"C","side":"B","price":"1.156730000","size":30,"channel_id":23,"order_id":"10998903693587495440","flags":0,"ts_in_delta":957,"sequence":184544,"symbol":"FCEU SI 20260615 PS"}
{"ts_recv":"2026-04-07T03:14:35.520756910Z","hd":{"ts_event":"2026-04-07T03:14:35.520733265Z","rtype":160,"publisher_id":101,"instrument_id":436},"action":"A","side":"B","price":"1.156720000","size":30,"channel_id":23,"order_id":"10998903712375515213","flags":0,"ts_in_delta":957,"sequence":184544,"symbol":"FCEU SI 20260615 PS"}
{"ts_recv":"2026-04-07T03:14:35.520756910Z","hd":{"ts_event":"2026-04-07T03:14:35.520733265Z","rtype":160,"publisher_id":101,"instrument_id":436},"action":"C","side":"A","price":"1.156830000","size":30,"channel_id":23,"order_id":"1775531656732719632","flags":0,"ts_in_delta":957,"sequence":184544,"symbol":"FCEU SI 20260615 PS"}
{"ts_recv":"2026-04-07T03:14:35.520756910Z","hd":{"ts_event":"2026-04-07T03:14:35.520733265Z","rtype":160,"publisher_id":101,"instrument_id":436},"action":"A","side":"A","price":"1.156820000","size":30,"channel_id":23,"order_id":"1775531675520739405","flags":128,"ts_in_delta":957,"sequence":184544,"symbol":"FCEU SI 20260615 PS"}
{"ts_recv":"2026-04-07T03:14:35.520846225Z","hd":{"ts_event":"2026-04-07T03:14:35.520824537Z","rtype":160,"publisher_id":101,"instrument_id":436},"action":"C","side":"B","price":"1.156720000","size":30,"channel_id":23,"order_id":"10998903712375515213","flags":0,"ts_in_delta":920,"sequence":184545,"symbol":"FCEU SI 20260615 PS"}
{"ts_recv":"2026-04-07T03:14:35.520846225Z","hd":{"ts_event":"2026-04-07T03:14:35.520824537Z","rtype":160,"publisher_id":101,"instrument_id":436},"action":"A","side":"B","price":"1.156710000","size":30,"channel_id":23,"order_id":"10998903712375606482","flags":0,"ts_in_delta":920,"sequence":184545,"symbol":"FCEU SI 20260615 PS"}
{"ts_recv":"2026-04-07T03:14:35.520846225Z","hd":{"ts_event":"2026-04-07T03:14:35.520824537Z","rtype":160,"publisher_id":101,"instrument_id":436},"action":"C","side":"A","price":"1.156820000","size":30,"channel_id":23,"order_id":"1775531675520739405","flags":0,"ts_in_delta":920,"sequence":184545,"symbol":"FCEU SI 20260615 PS"}
{"ts_recv":"2026-04-07T03:14:35.520846225Z","hd":{"ts_event":"2026-04-07T03:14:35.520824537Z","rtype":160,"publisher_id":101,"instrument_id":436},"action":"A","side":"A","price":"1.156810000","size":30,"channel_id":23,"order_id":"1775531675520830674","flags":128,"ts_in_delta":920,"sequence":184545,"symbol":"FCEU SI 20260615 PS"}
{"ts_recv":"2026-04-07T03:14:35.520906717Z","hd":{"ts_event":"2026-04-07T03:14:35.520889017Z","rtype":160,"publisher_id":101,"instrument_id":436},"action":"C","side":"B","price":"1.156710000","size":30,"channel_id":23,"order_id":"10998903712375606482","flags":0,"ts_in_delta":938,"sequence":184546,"symbol":"FCEU SI 20260615 PS"}
{"ts_recv":"2026-04-07T03:14:35.520906717Z","hd":{"ts_event":"2026-04-07T03:14:35.520889017Z","rtype":160,"publisher_id":101,"instrument_id":436},"action":"A","side":"B","price":"1.156720000","size":30,"channel_id":23,"order_id":"10998903712375670780","flags":0,"ts_in_delta":938,"sequence":184546,"symbol":"FCEU SI 20260615 PS"}
{"ts_recv":"2026-04-07T03:14:35.520906717Z","hd":{"ts_event":"2026-04-07T03:14:35.520889017Z","rtype":160,"publisher_id":101,"instrument_id":436},"action":"C","side":"A","price":"1.156810000","size":30,"channel_id":23,"order_id":"1775531675520830674","flags":0,"ts_in_delta":938,"sequence":184546,"symbol":"FCEU SI 20260615 PS"}
{"ts_recv":"2026-04-07T03:14:35.520906717Z","hd":{"ts_event":"2026-04-07T03:14:35.520889017Z","rtype":160,"publisher_id":101,"instrument_id":436},"action":"A","side":"A","price":"1.156820000","size":30,"channel_id":23,"order_id":"1775531675520894972","flags":128,"ts_in_delta":938,"sequence":184546,"symbol":"FCEU SI 20260615 PS"}
{"ts_recv":"2026-04-07T03:14:35.553740329Z","hd":{"ts_event":"2026-04-07T03:14:35.553719843Z","rtype":160,"publisher_id":101,"instrument_id":436},"action":"C","side":"B","price":"1.156730000","size":30,"channel_id":23,"order_id":"10998903657909820125","flags":0,"ts_in_delta":922,"sequence":184552,"symbol":"FCEU SI 20260615 PS"}
{"ts_recv":"2026-04-07T03:14:35.553740329Z","hd":{"ts_event":"2026-04-07T03:14:35.553719843Z","rtype":160,"publisher_id":101,"instrument_id":436},"action":"A","side":"B","price":"1.156710000","size":30,"channel_id":23,"order_id":"10998903712408502132","flags":0,"ts_in_delta":922,"sequence":184552,"symbol":"FCEU SI 20260615 PS"}
{"ts_recv":"2026-04-07T03:14:35.553740329Z","hd":{"ts_event":"2026-04-07T03:14:35.553719843Z","rtype":160,"publisher_id":101,"instrument_id":436},"action":"C","side":"A","price":"1.156830000","size":30,"channel_id":23,"order_id":"1775531621055044317","flags":0,"ts_in_delta":922,"sequence":184552,"symbol":"FCEU SI 20260615 PS"}
{"ts_recv":"2026-04-07T03:14:35.553740329Z","hd":{"ts_event":"2026-04-07T03:14:35.553719843Z","rtype":160,"publisher_id":101,"instrument_id":436},"action":"A","side":"A","price":"1.156810000","size":30,"channel_id":23,"order_id":"1775531675553726324","flags":128,"ts_in_delta":922,"sequence":184552,"symbol":"FCEU SI 20260615 PS"}
{"ts_recv":"2026-04-07T03:14:35.553803387Z","hd":{"ts_event":"2026-04-07T03:14:35.553784823Z","rtype":160,"publisher_id":101,"instrument_id":436},"action":"C","side":"B","price":"1.156720000","size":30,"channel_id":23,"order_id":"10998903712375670780","flags":0,"ts_in_delta":931,"sequence":184553,"symbol":"FCEU SI 20260615 PS"}
{"ts_recv":"2026-04-07T03:14:35.553803387Z","hd":{"ts_event":"2026-04-07T03:14:35.553784823Z","rtype":160,"publisher_id":101,"instrument_id":436},"action":"A","side":"B","price":"1.156710000","size":30,"channel_id":23,"order_id":"10998903712408566997","flags":0,"ts_in_delta":931,"sequence":184553,"symbol":"FCEU SI 20260615 PS"}
{"ts_recv":"2026-04-07T03:14:35.553803387Z","hd":{"ts_event":"2026-04-07T03:14:35.553784823Z","rtype":160,"publisher_id":101,"instrument_id":436},"action":"C","side":"A","price":"1.156820000","size":30,"channel_id":23,"order_id":"1775531675520894972","flags":0,"ts_in_delta":931,"sequence":184553,"symbol":"FCEU SI 20260615 PS"}
{"ts_recv":"2026-04-07T03:14:35.553803387Z","hd":{"ts_event":"2026-04-07T03:14:35.553784823Z","rtype":160,"publisher_id":101,"instrument_id":436},"action":"A","side":"A","price":"1.156810000","size":30,"channel_id":23,"order_id":"1775531675553791189","flags":128,"ts_in_delta":931,"sequence":184553,"symbol":"FCEU SI 20260615 PS"}
{"ts_recv":"2026-04-07T03:15:01.198752230Z","hd":{"ts_event":"2026-04-07T03:15:01.198729369Z","rtype":160,"publisher_id":101,"instrument_id":436},"action":"C","side":"B","price":"1.156710000","size":30,"channel_id":23,"order_id":"10998903712408566997","flags":0,"ts_in_delta":1024,"sequence":184693,"symbol":"FCEU SI 20260615 PS"}
{"ts_recv":"2026-04-07T03:15:01.198752230Z","hd":{"ts_event":"2026-04-07T03:15:01.198729369Z","rtype":160,"publisher_id":101,"instrument_id":436},"action":"A","side":"B","price":"1.156720000","size":30,"channel_id":23,"order_id":"10998903738053511546","flags":0,"ts_in_delta":1024,"sequence":184693,"symbol":"FCEU SI 20260615 PS"}
{"ts_recv":"2026-04-07T03:15:01.198752230Z","hd":{"ts_event":"2026-04-07T03:15:01.198729369Z","rtype":160,"publisher_id":101,"instrument_id":436},"action":"C","side":"A","price":"1.156810000","size":30,"channel_id":23,"order_id":"1775531675553791189","flags":0,"ts_in_delta":1024,"sequence":184693,"symbol":"FCEU SI 20260615 PS"}
{"ts_recv":"2026-04-07T03:15:01.198752230Z","hd":{"ts_event":"2026-04-07T03:15:01.198729369Z","rtype":160,"publisher_id":101,"instrument_id":436},"action":"A","side":"A","price":"1.156820000","size":30,"channel_id":23,"order_id":"1775531701198735738","flags":128,"ts_in_delta":1024,"sequence":184693,"symbol":"FCEU SI 20260615 PS"}
{"ts_recv":"2026-04-07T03:15:01.199990258Z","hd":{"ts_event":"2026-04-07T03:15:01.199967445Z","rtype":160,"publisher_id":101,"instrument_id":436},"action":"C","side":"B","price":"1.156710000","size":30,"channel_id":23,"order_id":"10998903712408502132","flags":0,"ts_in_delta":1005,"sequence":184696,"symbol":"FCEU SI 20260615 PS"}
{"ts_recv":"2026-04-07T03:15:01.199990258Z","hd":{"ts_event":"2026-04-07T03:15:01.199967445Z","rtype":160,"publisher_id":101,"instrument_id":436},"action":"A","side":"B","price":"1.156730000","size":30,"channel_id":23,"order_id":"10998903738054749456","flags":0,"ts_in_delta":1005,"sequence":184696,"symbol":"FCEU SI 20260615 PS"}
{"ts_recv":"2026-04-07T03:15:01.199990258Z","hd":{"ts_event":"2026-04-07T03:15:01.199967445Z","rtype":160,"publisher_id":101,"instrument_id":436},"action":"C","side":"A","price":"1.156810000","size":30,"channel_id":23,"order_id":"1775531675553726324","flags":0,"ts_in_delta":1005,"sequence":184696,"symbol":"FCEU SI 20260615 PS"}
{"ts_recv":"2026-04-07T03:15:01.199990258Z","hd":{"ts_event":"2026-04-07T03:15:01.199967445Z","rtype":160,"publisher_id":101,"instrument_id":436},"action":"A","side":"A","price":"1.156830000","size":30,"channel_id":23,"order_id":"1775531701199973648","flags":128,"ts_in_delta":1005,"sequence":184696,"symbol":"FCEU SI 20260615 PS"}
{"ts_recv":"2026-04-07T03:15:01.200055504Z","hd":{"ts_event":"2026-04-07T03:15:01.200034779Z","rtype":160,"publisher_id":101,"instrument_id":436},"action":"C","side":"B","price":"1.156720000","size":30,"channel_id":23,"order_id":"10998903738053511546","flags":0,"ts_in_delta":993,"sequence":184697,"symbol":"FCEU SI 20260615 PS"}
{"ts_recv":"2026-04-07T03:15:01.200055504Z","hd":{"ts_event":"2026-04-07T03:15:01.200034779Z","rtype":160,"publisher_id":101,"instrument_id":436},"action":"A","side":"B","price":"1.156730000","size":30,"channel_id":23,"order_id":"10998903738054816487","flags":0,"ts_in_delta":993,"sequence":184697,"symbol":"FCEU SI 20260615 PS"}
{"ts_recv":"2026-04-07T03:15:01.200055504Z","hd":{"ts_event":"2026-04-07T03:15:01.200034779Z","rtype":160,"publisher_id":101,"instrument_id":436},"action":"C","side":"A","price":"1.156820000","size":30,"channel_id":23,"order_id":"1775531701198735738","flags":0,"ts_in_delta":993,"sequence":184697,"symbol":"FCEU SI 20260615 PS"}
{"ts_recv":"2026-04-07T03:15:01.200055504Z","hd":{"ts_event":"2026-04-07T03:15:01.200034779Z","rtype":160,"publisher_id":101,"instrument_id":436},"action":"A","side":"A","price":"1.156830000","size":30,"channel_id":23,"order_id":"1775531701200040679","flags":128,"ts_in_delta":993,"sequence":184697,"symbol":"FCEU SI 20260615 PS"}
{"ts_recv":"2026-04-07T03:15:01.904187791Z","hd":{"ts_event":"2026-04-07T03:15:01.904167595Z","rtype":160,"publisher_id":101,"instrument_id":436},"action":"C","side":"B","price":"1.156730000","size":30,"channel_id":23,"order_id":"10998903738054816487","flags":0,"ts_in_delta":891,"sequence":184735,"symbol":"FCEU SI 20260615 PS"}
{"ts_recv":"2026-04-07T03:15:01.904187791Z","hd":{"ts_event":"2026-04-07T03:15:01.904167595Z","rtype":160,"publisher_id":101,"instrument_id":436},"action":"A","side":"B","price":"1.156720000","size":30,"channel_id":23,"order_id":"10998903738758949579","flags":0,"ts_in_delta":891,"sequence":184735,"symbol":"FCEU SI 20260615 PS"}
{"ts_recv":"2026-04-07T03:15:01.904187791Z","hd":{"ts_event":"2026-04-07T03:15:01.904167595Z","rtype":160,"publisher_id":101,"instrument_id":436},"action":"C","side":"A","price":"1.156830000","size":30,"channel_id":23,"order_id":"1775531701200040679","flags":0,"ts_in_delta":891,"sequence":184735,"symbol":"FCEU SI 20260615 PS"}
{"ts_recv":"2026-04-07T03:15:01.904187791Z","hd":{"ts_event":"2026-04-07T03:15:01.904167595Z","rtype":160,"publisher_id":101,"instrument_id":436},"action":"A","side":"A","price":"1.156820000","size":30,"channel_id":23,"order_id":"1775531701904173771","flags":128,"ts_in_delta":891,"sequence":184735,"symbol":"FCEU SI 20260615 PS"}
{"ts_recv":"2026-04-07T03:15:01.904275485Z","hd":{"ts_event":"2026-04-07T03:15:01.904254627Z","rtype":160,"publisher_id":101,"instrument_id":436},"action":"C","side":"B","price":"1.156720000","size":30,"channel_id":23,"order_id":"10998903738758949579","flags":0,"ts_in_delta":906,"sequence":184736,"symbol":"FCEU SI 20260615 PS"}
{"ts_recv":"2026-04-07T03:15:01.904275485Z","hd":{"ts_event":"2026-04-07T03:15:01.904254627Z","rtype":160,"publisher_id":101,"instrument_id":436},"action":"A","side":"B","price":"1.156710000","size":30,"channel_id":23,"order_id":"10998903738759036601","flags":0,"ts_in_delta":906,"sequence":184736,"symbol":"FCEU SI 20260615 PS"}
{"ts_recv":"2026-04-07T03:15:01.904275485Z","hd":{"ts_event":"2026-04-07T03:15:01.904254627Z","rtype":160,"publisher_id":101,"instrument_id":436},"action":"C","side":"A","price":"1.156820000","size":30,"channel_id":23,"order_id":"1775531701904173771","flags":0,"ts_in_delta":906,"sequence":184736,"symbol":"FCEU SI 20260615 PS"}
{"ts_recv":"2026-04-07T03:15:01.904275485Z","hd":{"ts_event":"2026-04-07T03:15:01.904254627Z","rtype":160,"publisher_id":101,"instrument_id":436},"action":"A","side":"A","price":"1.156810000","size":30,"channel_id":23,"order_id":"1775531701904260793","flags":128,"ts_in_delta":906,"sequence":184736,"symbol":"FCEU SI 20260615 PS"}
{"ts_recv":"2026-04-07T03:15:01.904330962Z","hd":{"ts_event":"2026-04-07T03:15:01.904313599Z","rtype":160,"publisher_id":101,"instrument_id":436},"action":"C","side":"B","price":"1.156730000","size":30,"channel_id":23,"order_id":"10998903738054749456","flags":0,"ts_in_delta":983,"sequence":184737,"symbol":"FCEU SI 20260615 PS"}
{"ts_recv":"2026-04-07T03:15:01.904330962Z","hd":{"ts_event":"2026-04-07T03:15:01.904313599Z","rtype":160,"publisher_id":101,"instrument_id":436},"action":"A","side":"B","price":"1.156710000","size":30,"channel_id":23,"order_id":"10998903738759095500","flags":0,"ts_in_delta":983,"sequence":184737,"symbol":"FCEU SI 20260615 PS"}
{"ts_recv":"2026-04-07T03:15:01.904330962Z","hd":{"ts_event":"2026-04-07T03:15:01.904313599Z","rtype":160,"publisher_id":101,"instrument_id":436},"action":"C","side":"A","price":"1.156830000","size":30,"channel_id":23,"order_id":"1775531701199973648","flags":0,"ts_in_delta":983,"sequence":184737,"symbol":"FCEU SI 20260615 PS"}
{"ts_recv":"2026-04-07T03:15:01.904330962Z","hd":{"ts_event":"2026-04-07T03:15:01.904313599Z","rtype":160,"publisher_id":101,"instrument_id":436},"action":"A","side":"A","price":"1.156810000","size":30,"channel_id":23,"order_id":"1775531701904319692","flags":128,"ts_in_delta":983,"sequence":184737,"symbol":"FCEU SI 20260615 PS"}
{"ts_recv":"2026-04-07T03:15:01.904341100Z","hd":{"ts_event":"2026-04-07T03:15:01.904315663Z","rtype":160,"publisher_id":101,"instrument_id":436},"action":"C","side":"B","price":"1.156710000","size":30,"channel_id":23,"order_id":"10998903738759036601","flags":0,"ts_in_delta":1075,"sequence":184738,"symbol":"FCEU SI 20260615 PS"}
{"ts_recv":"2026-04-07T03:15:01.904341100Z","hd":{"ts_event":"2026-04-07T03:15:01.904315663Z","rtype":160,"publisher_id":101,"instrument_id":436},"action":"A","side":"B","price":"1.156720000","size":30,"channel_id":23,"order_id":"10998903738759103624","flags":0,"ts_in_delta":1075,"sequence":184738,"symbol":"FCEU SI 20260615 PS"}
{"ts_recv":"2026-04-07T03:15:01.904341100Z","hd":{"ts_event":"2026-04-07T03:15:01.904315663Z","rtype":160,"publisher_id":101,"instrument_id":436},"action":"C","side":"A","price":"1.156810000","size":30,"channel_id":23,"order_id":"1775531701904260793","flags":0,"ts_in_delta":1075,"sequence":184738,"symbol":"FCEU SI 20260615 PS"}
{"ts_recv":"2026-04-07T03:15:01.904341100Z","hd":{"ts_event":"2026-04-07T03:15:01.904315663Z","rtype":160,"publisher_id":101,"instrument_id":436},"action":"A","side":"A","price":"1.156820000","size":30,"channel_id":23,"order_id":"1775531701904327816","flags":128,"ts_in_delta":1075,"sequence":184738,"symbol":"FCEU SI 20260615 PS"}
{"ts_recv":"2026-04-07T03:15:01.904394166Z","hd":{"ts_event":"2026-04-07T03:15:01.904376433Z","rtype":160,"publisher_id":101,"instrument_id":436},"action":"C","side":"B","price":"1.156720000","size":30,"channel_id":23,"order_id":"10998903738759103624","flags":0,"ts_in_delta":921,"sequence":184739,"symbol":"FCEU SI 20260615 PS"}
{"ts_recv":"2026-04-07T03:15:01.904394166Z","hd":{"ts_event":"2026-04-07T03:15:01.904376433Z","rtype":160,"publisher_id":101,"instrument_id":436},"action":"A","side":"B","price":"1.156710000","size":30,"channel_id":23,"order_id":"10998903738759158087","flags":0,"ts_in_delta":921,"sequence":184739,"symbol":"FCEU SI 20260615 PS"}
{"ts_recv":"2026-04-07T03:15:01.904394166Z","hd":{"ts_event":"2026-04-07T03:15:01.904376433Z","rtype":160,"publisher_id":101,"instrument_id":436},"action":"C","side":"A","price":"1.156820000","size":30,"channel_id":23,"order_id":"1775531701904327816","flags":0,"ts_in_delta":921,"sequence":184739,"symbol":"FCEU SI 20260615 PS"}
{"ts_recv":"2026-04-07T03:15:01.904394166Z","hd":{"ts_event":"2026-04-07T03:15:01.904376433Z","rtype":160,"publisher_id":101,"instrument_id":436},"action":"A","side":"A","price":"1.156810000","size":30,"channel_id":23,"order_id":"1775531701904382279","flags":128,"ts_in_delta":921,"sequence":184739,"symbol":"FCEU SI 20260615 PS"}
{"ts_recv":"2026-04-07T03:15:07.192061146Z","hd":{"ts_event":"2026-04-07T03:15:07.192040301Z","rtype":160,"publisher_id":101,"instrument_id":436},"action":"C","side":"B","price":"1.156710000","size":30,"channel_id":23,"order_id":"10998903738759158087","flags":0,"ts_in_delta":978,"sequence":184781,"symbol":"FCEU SI 20260615 PS"}
{"ts_recv":"2026-04-07T03:15:07.192061146Z","hd":{"ts_event":"2026-04-07T03:15:07.192040301Z","rtype":160,"publisher_id":101,"instrument_id":436},"action":"A","side":"B","price":"1.156700000","size":30,"channel_id":23,"order_id":"10998903744046822449","flags":0,"ts_in_delta":978,"sequence":184781,"symbol":"FCEU SI 20260615 PS"}
{"ts_recv":"2026-04-07T03:15:07.192061146Z","hd":{"ts_event":"2026-04-07T03:15:07.192040301Z","rtype":160,"publisher_id":101,"instrument_id":436},"action":"C","side":"A","price":"1.156810000","size":30,"channel_id":23,"order_id":"1775531701904382279","flags":0,"ts_in_delta":978,"sequence":184781,"symbol":"FCEU SI 20260615 PS"}
{"ts_recv":"2026-04-07T03:15:07.192061146Z","hd":{"ts_event":"2026-04-07T03:15:07.192040301Z","rtype":160,"publisher_id":101,"instrument_id":436},"action":"A","side":"A","price":"1.156800000","size":30,"channel_id":23,"order_id":"1775531707192046641","flags":128,"ts_in_delta":978,"sequence":184781,"symbol":"FCEU SI 20260615 PS"}
{"ts_recv":"2026-04-07T03:15:07.192139571Z","hd":{"ts_event":"2026-04-07T03:15:07.192122709Z","rtype":160,"publisher_id":101,"instrument_id":436},"action":"C","side":"B","price":"1.156700000","size":30,"channel_id":23,"order_id":"10998903744046822449","flags":0,"ts_in_delta":989,"sequence":184782,"symbol":"FCEU SI 20260615 PS"}
{"ts_recv":"2026-04-07T03:15:07.192139571Z","hd":{"ts_event":"2026-04-07T03:15:07.192122709Z","rtype":160,"publisher_id":101,"instrument_id":436},"action":"A","side":"B","price":"1.156690000","size":30,"channel_id":23,"order_id":"10998903744046904419","flags":0,"ts_in_delta":989,"sequence":184782,"symbol":"FCEU SI 20260615 PS"}
{"ts_recv":"2026-04-07T03:15:07.192139571Z","hd":{"ts_event":"2026-04-07T03:15:07.192122709Z","rtype":160,"publisher_id":101,"instrument_id":436},"action":"C","side":"A","price":"1.156800000","size":30,"channel_id":23,"order_id":"1775531707192046641","flags":0,"ts_in_delta":989,"sequence":184782,"symbol":"FCEU SI 20260615 PS"}
{"ts_recv":"2026-04-07T03:15:07.192139571Z","hd":{"ts_event":"2026-04-07T03:15:07.192122709Z","rtype":160,"publisher_id":101,"instrument_id":436},"action":"A","side":"A","price":"1.156790000","size":30,"channel_id":23,"order_id":"1775531707192128611","flags":128,"ts_in_delta":989,"sequence":184782,"symbol":"FCEU SI 20260615 PS"}
{"ts_recv":"2026-04-07T03:15:07.192194926Z","hd":{"ts_event":"2026-04-07T03:15:07.192177737Z","rtype":160,"publisher_id":101,"instrument_id":436},"action":"C","side":"B","price":"1.156690000","size":30,"channel_id":23,"order_id":"10998903744046904419","flags":0,"ts_in_delta":997,"sequence":184783,"symbol":"FCEU SI 20260615 PS"}
{"ts_recv":"2026-04-07T03:15:07.192194926Z","hd":{"ts_event":"2026-04-07T03:15:07.192177737Z","rtype":160,"publisher_id":101,"instrument_id":436},"action":"A","side":"B","price":"1.156700000","size":30,"channel_id":23,"order_id":"10998903744046959226","flags":0,"ts_in_delta":997,"sequence":184783,"symbol":"FCEU SI 20260615 PS"}
{"ts_recv":"2026-04-07T03:15:07.192194926Z","hd":{"ts_event":"2026-04-07T03:15:07.192177737Z","rtype":160,"publisher_id":101,"instrument_id":436},"action":"C","side":"A","price":"1.156790000","size":30,"channel_id":23,"order_id":"1775531707192128611","flags":0,"ts_in_delta":997,"sequence":184783,"symbol":"FCEU SI 20260615 PS"}
{"ts_recv":"2026-04-07T03:15:07.192194926Z","hd":{"ts_event":"2026-04-07T03:15:07.192177737Z","rtype":160,"publisher_id":101,"instrument_id":436},"action":"A","side":"A","price":"1.156800000","size":30,"channel_id":23,"order_id":"1775531707192183418","flags":128,"ts_in_delta":997,"sequence":184783,"symbol":"FCEU SI 20260615 PS"}
{"ts_recv":"2026-04-07T03:15:07.192204817Z","hd":{"ts_event":"2026-04-07T03:15:07.192179887Z","rtype":160,"publisher_id":101,"instrument_id":436},"action":"C","side":"B","price":"1.156710000","size":30,"channel_id":23,"order_id":"10998903738759095500","flags":0,"ts_in_delta":950,"sequence":184784,"symbol":"FCEU SI 20260615 PS"}
{"ts_recv":"2026-04-07T03:15:07.192204817Z","hd":{"ts_event":"2026-04-07T03:15:07.192179887Z","rtype":160,"publisher_id":101,"instrument_id":436},"action":"A","side":"B","price":"1.156690000","size":30,"channel_id":23,"order_id":"10998903744046967345","flags":0,"ts_in_delta":950,"sequence":184784,"symbol":"FCEU SI 20260615 PS"}
{"ts_recv":"2026-04-07T03:15:07.192204817Z","hd":{"ts_event":"2026-04-07T03:15:07.192179887Z","rtype":160,"publisher_id":101,"instrument_id":436},"action":"C","side":"A","price":"1.156810000","size":30,"channel_id":23,"order_id":"1775531701904319692","flags":0,"ts_in_delta":950,"sequence":184784,"symbol":"FCEU SI 20260615 PS"}
{"ts_recv":"2026-04-07T03:15:07.192204817Z","hd":{"ts_event":"2026-04-07T03:15:07.192179887Z","rtype":160,"publisher_id":101,"instrument_id":436},"action":"A","side":"A","price":"1.156790000","size":30,"channel_id":23,"order_id":"1775531707192191537","flags":128,"ts_in_delta":950,"sequence":184784,"symbol":"FCEU SI 20260615 PS"}
{"ts_recv":"2026-04-07T03:15:07.192268205Z","hd":{"ts_event":"2026-04-07T03:15:07.192248431Z","rtype":160,"publisher_id":101,"instrument_id":436},"action":"C","side":"B","price":"1.156700000","size":30,"channel_id":23,"order_id":"10998903744046959226","flags":0,"ts_in_delta":922,"sequence":184785,"symbol":"FCEU SI 20260615 PS"}
{"ts_recv":"2026-04-07T03:15:07.192268205Z","hd":{"ts_event":"2026-04-07T03:15:07.192248431Z","rtype":160,"publisher_id":101,"instrument_id":436},"action":"A","side":"B","price":"1.156690000","size":30,"channel_id":23,"order_id":"10998903744047031353","flags":0,"ts_in_delta":922,"sequence":184785,"symbol":"FCEU SI 20260615 PS"}
{"ts_recv":"2026-04-07T03:15:07.192268205Z","hd":{"ts_event":"2026-04-07T03:15:07.192248431Z","rtype":160,"publisher_id":101,"instrument_id":436},"action":"C","side":"A","price":"1.156800000","size":30,"channel_id":23,"order_id":"1775531707192183418","flags":0,"ts_in_delta":922,"sequence":184785,"symbol":"FCEU SI 20260615 PS"}
{"ts_recv":"2026-04-07T03:15:07.192268205Z","hd":{"ts_event":"2026-04-07T03:15:07.192248431Z","rtype":160,"publisher_id":101,"instrument_id":436},"action":"A","side":"A","price":"1.156790000","size":30,"channel_id":23,"order_id":"1775531707192255545","flags":128,"ts_in_delta":922,"sequence":184785,"symbol":"FCEU SI 20260615 PS"}
{"ts_recv":"2026-04-07T03:15:29.977342075Z","hd":{"ts_event":"2026-04-07T03:15:29.977310237Z","rtype":160,"publisher_id":101,"instrument_id":436},"action":"C","side":"B","price":"1.156690000","size":30,"channel_id":23,"order_id":"10998903744046967345","flags":0,"ts_in_delta":1695,"sequence":184920,"symbol":"FCEU SI 20260615 PS"}
{"ts_recv":"2026-04-07T03:15:29.977342075Z","hd":{"ts_event":"2026-04-07T03:15:29.977310237Z","rtype":160,"publisher_id":101,"instrument_id":436},"action":"A","side":"B","price":"1.156710000","size":30,"channel_id":23,"order_id":"10998903766832095460","flags":0,"ts_in_delta":1695,"sequence":184920,"symbol":"FCEU SI 20260615 PS"}
{"ts_recv":"2026-04-07T03:15:29.977342075Z","hd":{"ts_event":"2026-04-07T03:15:29.977310237Z","rtype":160,"publisher_id":101,"instrument_id":436},"action":"C","side":"A","price":"1.156790000","size":30,"channel_id":23,"order_id":"1775531707192191537","flags":0,"ts_in_delta":1695,"sequence":184920,"symbol":"FCEU SI 20260615 PS"}
{"ts_recv":"2026-04-07T03:15:29.977342075Z","hd":{"ts_event":"2026-04-07T03:15:29.977310237Z","rtype":160,"publisher_id":101,"instrument_id":436},"action":"A","side":"A","price":"1.156810000","size":30,"channel_id":23,"order_id":"1775531729977319652","flags":128,"ts_in_delta":1695,"sequence":184920,"symbol":"FCEU SI 20260615 PS"}
{"ts_recv":"2026-04-07T03:15:29.977456755Z","hd":{"ts_event":"2026-04-07T03:15:29.977438917Z","rtype":160,"publisher_id":101,"instrument_id":436},"action":"C","side":"B","price":"1.156690000","size":30,"channel_id":23,"order_id":"10998903744047031353","flags":0,"ts_in_delta":1136,"sequence":184921,"symbol":"FCEU SI 20260615 PS"}
{"ts_recv":"2026-04-07T03:15:29.977456755Z","hd":{"ts_event":"2026-04-07T03:15:29.977438917Z","rtype":160,"publisher_id":101,"instrument_id":436},"action":"A","side":"B","price":"1.156700000","size":30,"channel_id":23,"order_id":"10998903766832221612","flags":0,"ts_in_delta":1136,"sequence":184921,"symbol":"FCEU SI 20260615 PS"}
{"ts_recv":"2026-04-07T03:15:29.977456755Z","hd":{"ts_event":"2026-04-07T03:15:29.977438917Z","rtype":160,"publisher_id":101,"instrument_id":436},"action":"C","side":"A","price":"1.156790000","size":30,"channel_id":23,"order_id":"1775531707192255545","flags":0,"ts_in_delta":1136,"sequence":184921,"symbol":"FCEU SI 20260615 PS"}
{"ts_recv":"2026-04-07T03:15:29.977456755Z","hd":{"ts_event":"2026-04-07T03:15:29.977438917Z","rtype":160,"publisher_id":101,"instrument_id":436},"action":"A","side":"A","price":"1.156800000","size":30,"channel_id":23,"order_id":"1775531729977445804","flags":128,"ts_in_delta":1136,"sequence":184921,"symbol":"FCEU SI 20260615 PS"}
{"ts_recv":"2026-04-07T03:15:29.977979555Z","hd":{"ts_event":"2026-04-07T03:15:29.977964425Z","rtype":160,"publisher_id":101,"instrument_id":436},"action":"C","side":"B","price":"1.156700000","size":30,"channel_id":23,"order_id":"10998903766832221612","flags":0,"ts_in_delta":806,"sequence":184922,"symbol":"FCEU SI 20260615 PS"}
{"ts_recv":"2026-04-07T03:15:29.977979555Z","hd":{"ts_event":"2026-04-07T03:15:29.977964425Z","rtype":160,"publisher_id":101,"instrument_id":436},"action":"A","side":"B","price":"1.156710000","size":30,"channel_id":23,"order_id":"10998903766832745867","flags":0,"ts_in_delta":806,"sequence":184922,"symbol":"FCEU SI 20260615 PS"}
{"ts_recv":"2026-04-07T03:15:29.977979555Z","hd":{"ts_event":"2026-04-07T03:15:29.977964425Z","rtype":160,"publisher_id":101,"instrument_id":436},"action":"C","side":"A","price":"1.156800000","size":30,"channel_id":23,"order_id":"1775531729977445804","flags":0,"ts_in_delta":806,"sequence":184922,"symbol":"FCEU SI 20260615 PS"}
{"ts_recv":"2026-04-07T03:15:29.977979555Z","hd":{"ts_event":"2026-04-07T03:15:29.977964425Z","rtype":160,"publisher_id":101,"instrument_id":436},"action":"A","side":"A","price":"1.156810000","size":30,"channel_id":23,"order_id":"1775531729977970059","flags":128,"ts_in_delta":806,"sequence":184922,"symbol":"FCEU SI 20260615 PS"}
{"ts_recv":"2026-04-07T03:15:30.168915557Z","hd":{"ts_event":"2026-04-07T03:15:30.168894773Z","rtype":160,"publisher_id":101,"instrument_id":436},"action":"C","side":"B","price":"1.156710000","size":30,"channel_id":23,"order_id":"10998903766832745867","flags":0,"ts_in_delta":1445,"sequence":184941,"symbol":"FCEU SI 20260615 PS"}
{"ts_recv":"2026-04-07T03:15:30.168915557Z","hd":{"ts_event":"2026-04-07T03:15:30.168894773Z","rtype":160,"publisher_id":101,"instrument_id":436},"action":"A","side":"B","price":"1.156720000","size":30,"channel_id":23,"order_id":"10998903767023676533","flags":0,"ts_in_delta":1445,"sequence":184941,"symbol":"FCEU SI 20260615 PS"}
{"ts_recv":"2026-04-07T03:15:30.168915557Z","hd":{"ts_event":"2026-04-07T03:15:30.168894773Z","rtype":160,"publisher_id":101,"instrument_id":436},"action":"C","side":"A","price":"1.156810000","size":30,"channel_id":23,"order_id":"1775531729977970059","flags":0,"ts_in_delta":1445,"sequence":184941,"symbol":"FCEU SI 20260615 PS"}
{"ts_recv":"2026-04-07T03:15:30.168915557Z","hd":{"ts_event":"2026-04-07T03:15:30.168894773Z","rtype":160,"publisher_id":101,"instrument_id":436},"action":"A","side":"A","price":"1.156820000","size":30,"channel_id":23,"order_id":"1775531730168900725","flags":128,"ts_in_delta":1445,"sequence":184941,"symbol":"FCEU SI 20260615 PS"}
{"ts_recv":"2026-04-07T03:15:30.168999480Z","hd":{"ts_event":"2026-04-07T03:15:30.168977965Z","rtype":160,"publisher_id":101,"instrument_id":436},"action":"C","side":"B","price":"1.156720000","size":30,"channel_id":23,"order_id":"10998903767023676533","flags":0,"ts_in_delta":1160,"sequence":184942,"symbol":"FCEU SI 20260615 PS"}
{"ts_recv":"2026-04-07T03:15:30.168999480Z","hd":{"ts_event":"2026-04-07T03:15:30.168977965Z","rtype":160,"publisher_id":101,"instrument_id":436},"action":"A","side":"B","price":"1.156730000","size":30,"channel_id":23,"order_id":"10998903767023759786","flags":0,"ts_in_delta":1160,"sequence":184942,"symbol":"FCEU SI 20260615 PS"}
{"ts_recv":"2026-04-07T03:15:30.168999480Z","hd":{"ts_event":"2026-04-07T03:15:30.168977965Z","rtype":160,"publisher_id":101,"instrument_id":436},"action":"C","side":"A","price":"1.156820000","size":30,"channel_id":23,"order_id":"1775531730168900725","flags":0,"ts_in_delta":1160,"sequence":184942,"symbol":"FCEU SI 20260615 PS"}
{"ts_recv":"2026-04-07T03:15:30.168999480Z","hd":{"ts_event":"2026-04-07T03:15:30.168977965Z","rtype":160,"publisher_id":101,"instrument_id":436},"action":"A","side":"A","price":"1.156830000","size":30,"channel_id":23,"order_id":"1775531730168983978","flags":128,"ts_in_delta":1160,"sequence":184942,"symbol":"FCEU SI 20260615 PS"}
{"ts_recv":"2026-04-07T03:15:30.169058613Z","hd":{"ts_event":"2026-04-07T03:15:30.169038273Z","rtype":160,"publisher_id":101,"instrument_id":436},"action":"C","side":"B","price":"1.156710000","size":30,"channel_id":23,"order_id":"10998903766832095460","flags":0,"ts_in_delta":1137,"sequence":184943,"symbol":"FCEU SI 20260615 PS"}
{"ts_recv":"2026-04-07T03:15:30.169058613Z","hd":{"ts_event":"2026-04-07T03:15:30.169038273Z","rtype":160,"publisher_id":101,"instrument_id":436},"action":"A","side":"B","price":"1.156730000","size":30,"channel_id":23,"order_id":"10998903767023821086","flags":0,"ts_in_delta":1137,"sequence":184943,"symbol":"FCEU SI 20260615 PS"}
{"ts_recv":"2026-04-07T03:15:30.169058613Z","hd":{"ts_event":"2026-04-07T03:15:30.169038273Z","rtype":160,"publisher_id":101,"instrument_id":436},"action":"C","side":"A","price":"1.156810000","size":30,"channel_id":23,"order_id":"1775531729977319652","flags":0,"ts_in_delta":1137,"sequence":184943,"symbol":"FCEU SI 20260615 PS"}
{"ts_recv":"2026-04-07T03:15:30.169058613Z","hd":{"ts_event":"2026-04-07T03:15:30.169038273Z","rtype":160,"publisher_id":101,"instrument_id":436},"action":"A","side":"A","price":"1.156830000","size":30,"channel_id":23,"order_id":"1775531730169045278","flags":128,"ts_in_delta":1137,"sequence":184943,"symbol":"FCEU SI 20260615 PS"}
{"ts_recv":"2026-04-07T03:15:30.169067860Z","hd":{"ts_event":"2026-04-07T03:15:30.169038445Z","rtype":160,"publisher_id":101,"instrument_id":436},"action":"C","side":"B","price":"1.156730000","size":30,"channel_id":23,"order_id":"10998903767023759786","flags":0,"ts_in_delta":964,"sequence":184944,"symbol":"FCEU SI 20260615 PS"}
{"ts_recv":"2026-04-07T03:15:30.169067860Z","hd":{"ts_event":"2026-04-07T03:15:30.169038445Z","rtype":160,"publisher_id":101,"instrument_id":436},"action":"A","side":"B","price":"1.156720000","size":30,"channel_id":23,"order_id":"10998903767023830962","flags":0,"ts_in_delta":964,"sequence":184944,"symbol":"FCEU SI 20260615 PS"}
{"ts_recv":"2026-04-07T03:15:30.169067860Z","hd":{"ts_event":"2026-04-07T03:15:30.169038445Z","rtype":160,"publisher_id":101,"instrument_id":436},"action":"C","side":"A","price":"1.156830000","size":30,"channel_id":23,"order_id":"1775531730168983978","flags":0,"ts_in_delta":964,"sequence":184944,"symbol":"FCEU SI 20260615 PS"}
{"ts_recv":"2026-04-07T03:15:30.169067860Z","hd":{"ts_event":"2026-04-07T03:15:30.169038445Z","rtype":160,"publisher_id":101,"instrument_id":436},"action":"A","side":"A","price":"1.156820000","size":30,"channel_id":23,"order_id":"1775531730169055154","flags":128,"ts_in_delta":964,"sequence":184944,"symbol":"FCEU SI 20260615 PS"}
{"ts_recv":"2026-04-07T03:15:30.169121341Z","hd":{"ts_event":"2026-04-07T03:15:30.169102327Z","rtype":160,"publisher_id":101,"instrument_id":436},"action":"C","side":"B","price":"1.156720000","size":30,"channel_id":23,"order_id":"10998903767023830962","flags":0,"ts_in_delta":950,"sequence":184945,"symbol":"FCEU SI 20260615 PS"}
{"ts_recv":"2026-04-07T03:15:30.169121341Z","hd":{"ts_event":"2026-04-07T03:15:30.169102327Z","rtype":160,"publisher_id":101,"instrument_id":436},"action":"A","side":"B","price":"1.156730000","size":30,"channel_id":23,"order_id":"10998903767023884087","flags":0,"ts_in_delta":950,"sequence":184945,"symbol":"FCEU SI 20260615 PS"}
{"ts_recv":"2026-04-07T03:15:30.169121341Z","hd":{"ts_event":"2026-04-07T03:15:30.169102327Z","rtype":160,"publisher_id":101,"instrument_id":436},"action":"C","side":"A","price":"1.156820000","size":30,"channel_id":23,"order_id":"1775531730169055154","flags":0,"ts_in_delta":950,"sequence":184945,"symbol":"FCEU SI 20260615 PS"}
{"ts_recv":"2026-04-07T03:15:30.169121341Z","hd":{"ts_event":"2026-04-07T03:15:30.169102327Z","rtype":160,"publisher_id":101,"instrument_id":436},"action":"A","side":"A","price":"1.156830000","size":30,"channel_id":23,"order_id":"1775531730169108279","flags":128,"ts_in_delta":950,"sequence":184945,"symbol":"FCEU SI 20260615 PS"}
{"ts_recv":"2026-04-07T03:15:37.217266297Z","hd":{"ts_event":"2026-04-07T03:15:37.217247077Z","rtype":160,"publisher_id":101,"instrument_id":436},"action":"C","side":"B","price":"1.156730000","size":30,"channel_id":23,"order_id":"10998903767023884087","flags":0,"ts_in_delta":1178,"sequence":184989,"symbol":"FCEU SI 20260615 PS"}
{"ts_recv":"2026-04-07T03:15:37.217266297Z","hd":{"ts_event":"2026-04-07T03:15:37.217247077Z","rtype":160,"publisher_id":101,"instrument_id":436},"action":"A","side":"B","price":"1.156720000","size":30,"channel_id":23,"order_id":"10998903774072028796","flags":0,"ts_in_delta":1178,"sequence":184989,"symbol":"FCEU SI 20260615 PS"}
{"ts_recv":"2026-04-07T03:15:37.217266297Z","hd":{"ts_event":"2026-04-07T03:15:37.217247077Z","rtype":160,"publisher_id":101,"instrument_id":436},"action":"C","side":"A","price":"1.156830000","size":30,"channel_id":23,"order_id":"1775531730169108279","flags":0,"ts_in_delta":1178,"sequence":184989,"symbol":"FCEU SI 20260615 PS"}
{"ts_recv":"2026-04-07T03:15:37.217266297Z","hd":{"ts_event":"2026-04-07T03:15:37.217247077Z","rtype":160,"publisher_id":101,"instrument_id":436},"action":"A","side":"A","price":"1.156820000","size":30,"channel_id":23,"order_id":"1775531737217252988","flags":128,"ts_in_delta":1178,"sequence":184989,"symbol":"FCEU SI 20260615 PS"}
{"ts_recv":"2026-04-07T03:15:37.240053909Z","hd":{"ts_event":"2026-04-07T03:15:37.240032863Z","rtype":160,"publisher_id":101,"instrument_id":436},"action":"C","side":"B","price":"1.156730000","size":30,"channel_id":23,"order_id":"10998903767023821086","flags":0,"ts_in_delta":924,"sequence":184995,"symbol":"FCEU SI 20260615 PS"}
{"ts_recv":"2026-04-07T03:15:37.240053909Z","hd":{"ts_event":"2026-04-07T03:15:37.240032863Z","rtype":160,"publisher_id":101,"instrument_id":436},"action":"A","side":"B","price":"1.156710000","size":30,"channel_id":23,"order_id":"10998903774094814761","flags":0,"ts_in_delta":924,"sequence":184995,"symbol":"FCEU SI 20260615 PS"}
{"ts_recv":"2026-04-07T03:15:37.240053909Z","hd":{"ts_event":"2026-04-07T03:15:37.240032863Z","rtype":160,"publisher_id":101,"instrument_id":436},"action":"C","side":"A","price":"1.156830000","size":30,"channel_id":23,"order_id":"1775531730169045278","flags":0,"ts_in_delta":924,"sequence":184995,"symbol":"FCEU SI 20260615 PS"}
{"ts_recv":"2026-04-07T03:15:37.240053909Z","hd":{"ts_event":"2026-04-07T03:15:37.240032863Z","rtype":160,"publisher_id":101,"instrument_id":436},"action":"A","side":"A","price":"1.156810000","size":30,"channel_id":23,"order_id":"1775531737240038953","flags":128,"ts_in_delta":924,"sequence":184995,"symbol":"FCEU SI 20260615 PS"}
{"ts_recv":"2026-04-07T03:15:37.240122058Z","hd":{"ts_event":"2026-04-07T03:15:37.240103353Z","rtype":160,"publisher_id":101,"instrument_id":436},"action":"C","side":"B","price":"1.156720000","size":30,"channel_id":23,"order_id":"10998903774072028796","flags":0,"ts_in_delta":930,"sequence":184996,"symbol":"FCEU SI 20260615 PS"}
{"ts_recv":"2026-04-07T03:15:37.240122058Z","hd":{"ts_event":"2026-04-07T03:15:37.240103353Z","rtype":160,"publisher_id":101,"instrument_id":436},"action":"A","side":"B","price":"1.156710000","size":30,"channel_id":23,"order_id":"10998903774094885207","flags":0,"ts_in_delta":930,"sequence":184996,"symbol":"FCEU SI 20260615 PS"}
{"ts_recv":"2026-04-07T03:15:37.240122058Z","hd":{"ts_event":"2026-04-07T03:15:37.240103353Z","rtype":160,"publisher_id":101,"instrument_id":436},"action":"C","side":"A","price":"1.156820000","size":30,"channel_id":23,"order_id":"1775531737217252988","flags":0,"ts_in_delta":930,"sequence":184996,"symbol":"FCEU SI 20260615 PS"}
{"ts_recv":"2026-04-07T03:15:37.240122058Z","hd":{"ts_event":"2026-04-07T03:15:37.240103353Z","rtype":160,"publisher_id":101,"instrument_id":436},"action":"A","side":"A","price":"1.156810000","size":30,"channel_id":23,"order_id":"1775531737240109399","flags":128,"ts_in_delta":930,"sequence":184996,"symbol":"FCEU SI 20260615 PS"}
{"ts_recv":"2026-04-07T03:16:09.229149714Z","hd":{"ts_event":"2026-04-07T03:16:09.229117031Z","rtype":160,"publisher_id":101,"instrument_id":436},"action":"C","side":"B","price":"1.156710000","size":30,"channel_id":23,"order_id":"10998903774094885207","flags":0,"ts_in_delta":1350,"sequence":185122,"symbol":"FCEU SI 20260615 PS"}
{"ts_recv":"2026-04-07T03:16:09.229149714Z","hd":{"ts_event":"2026-04-07T03:16:09.229117031Z","rtype":160,"publisher_id":101,"instrument_id":436},"action":"A","side":"B","price":"1.156700000","size":30,"channel_id":23,"order_id":"10998903806083901976","flags":0,"ts_in_delta":1350,"sequence":185122,"symbol":"FCEU SI 20260615 PS"}
{"ts_recv":"2026-04-07T03:16:09.229149714Z","hd":{"ts_event":"2026-04-07T03:16:09.229117031Z","rtype":160,"publisher_id":101,"instrument_id":436},"action":"C","side":"A","price":"1.156810000","size":30,"channel_id":23,"order_id":"1775531737240109399","flags":0,"ts_in_delta":1350,"sequence":185122,"symbol":"FCEU SI 20260615 PS"}
{"ts_recv":"2026-04-07T03:16:09.229149714Z","hd":{"ts_event":"2026-04-07T03:16:09.229117031Z","rtype":160,"publisher_id":101,"instrument_id":436},"action":"A","side":"A","price":"1.156800000","size":30,"channel_id":23,"order_id":"1775531769229126168","flags":128,"ts_in_delta":1350,"sequence":185122,"symbol":"FCEU SI 20260615 PS"}
{"ts_recv":"2026-04-07T03:16:09.893190270Z","hd":{"ts_event":"2026-04-07T03:16:09.893159345Z","rtype":160,"publisher_id":101,"instrument_id":436},"action":"C","side":"B","price":"1.156700000","size":30,"channel_id":23,"order_id":"10998903806083901976","flags":0,"ts_in_delta":1605,"sequence":185124,"symbol":"FCEU SI 20260615 PS"}
{"ts_recv":"2026-04-07T03:16:09.893190270Z","hd":{"ts_event":"2026-04-07T03:16:09.893159345Z","rtype":160,"publisher_id":101,"instrument_id":436},"action":"A","side":"B","price":"1.156710000","size":30,"channel_id":23,"order_id":"10998903806747948271","flags":0,"ts_in_delta":1605,"sequence":185124,"symbol":"FCEU SI 20260615 PS"}
{"ts_recv":"2026-04-07T03:16:09.893190270Z","hd":{"ts_event":"2026-04-07T03:16:09.893159345Z","rtype":160,"publisher_id":101,"instrument_id":436},"action":"C","side":"A","price":"1.156800000","size":30,"channel_id":23,"order_id":"1775531769229126168","flags":0,"ts_in_delta":1605,"sequence":185124,"symbol":"FCEU SI 20260615 PS"}
{"ts_recv":"2026-04-07T03:16:09.893190270Z","hd":{"ts_event":"2026-04-07T03:16:09.893159345Z","rtype":160,"publisher_id":101,"instrument_id":436},"action":"A","side":"A","price":"1.156810000","size":30,"channel_id":23,"order_id":"1775531769893172463","flags":128,"ts_in_delta":1605,"sequence":185124,"symbol":"FCEU SI 20260615 PS"}
{"ts_recv":"2026-04-07T03:16:09.897794872Z","hd":{"ts_event":"2026-04-07T03:16:09.897774703Z","rtype":160,"publisher_id":101,"instrument_id":436},"action":"C","side":"B","price":"1.156710000","size":30,"channel_id":23,"order_id":"10998903806747948271","flags":0,"ts_in_delta":902,"sequence":185126,"symbol":"FCEU SI 20260615 PS"}
{"ts_recv":"2026-04-07T03:16:09.897794872Z","hd":{"ts_event":"2026-04-07T03:16:09.897774703Z","rtype":160,"publisher_id":101,"instrument_id":436},"action":"A","side":"B","price":"1.156720000","size":30,"channel_id":23,"order_id":"10998903806752556443","flags":0,"ts_in_delta":902,"sequence":185126,"symbol":"FCEU SI 20260615 PS"}
{"ts_recv":"2026-04-07T03:16:09.897794872Z","hd":{"ts_event":"2026-04-07T03:16:09.897774703Z","rtype":160,"publisher_id":101,"instrument_id":436},"action":"C","side":"A","price":"1.156810000","size":30,"channel_id":23,"order_id":"1775531769893172463","flags":0,"ts_in_delta":902,"sequence":185126,"symbol":"FCEU SI 20260615 PS"}
{"ts_recv":"2026-04-07T03:16:09.897794872Z","hd":{"ts_event":"2026-04-07T03:16:09.897774703Z","rtype":160,"publisher_id":101,"instrument_id":436},"action":"A","side":"A","price":"1.156820000","size":30,"channel_id":23,"order_id":"1775531769897780635","flags":128,"ts_in_delta":902,"sequence":185126,"symbol":"FCEU SI 20260615 PS"}
{"ts_recv":"2026-04-07T03:16:09.897871107Z","hd":{"ts_event":"2026-04-07T03:16:09.897849653Z","rtype":160,"publisher_id":101,"instrument_id":436},"action":"C","side":"B","price":"1.156710000","size":30,"channel_id":23,"order_id":"10998903774094814761","flags":0,"ts_in_delta":892,"sequence":185127,"symbol":"FCEU SI 20260615 PS"}
{"ts_recv":"2026-04-07T03:16:09.897871107Z","hd":{"ts_event":"2026-04-07T03:16:09.897849653Z","rtype":160,"publisher_id":101,"instrument_id":436},"action":"A","side":"B","price":"1.156730000","size":30,"channel_id":23,"order_id":"10998903806752633357","flags":0,"ts_in_delta":892,"sequence":185127,"symbol":"FCEU SI 20260615 PS"}
{"ts_recv":"2026-04-07T03:16:09.897871107Z","hd":{"ts_event":"2026-04-07T03:16:09.897849653Z","rtype":160,"publisher_id":101,"instrument_id":436},"action":"C","side":"A","price":"1.156810000","size":30,"channel_id":23,"order_id":"1775531737240038953","flags":0,"ts_in_delta":892,"sequence":185127,"symbol":"FCEU SI 20260615 PS"}
{"ts_recv":"2026-04-07T03:16:09.897871107Z","hd":{"ts_event":"2026-04-07T03:16:09.897849653Z","rtype":160,"publisher_id":101,"instrument_id":436},"action":"A","side":"A","price":"1.156830000","size":30,"channel_id":23,"order_id":"1775531769897857549","flags":128,"ts_in_delta":892,"sequence":185127,"symbol":"FCEU SI 20260615 PS"}
{"ts_recv":"2026-04-07T03:16:09.897930663Z","hd":{"ts_event":"2026-04-07T03:16:09.897909539Z","rtype":160,"publisher_id":101,"instrument_id":436},"action":"C","side":"B","price":"1.156720000","size":30,"channel_id":23,"order_id":"10998903806752556443","flags":0,"ts_in_delta":868,"sequence":185128,"symbol":"FCEU SI 20260615 PS"}
{"ts_recv":"2026-04-07T03:16:09.897930663Z","hd":{"ts_event":"2026-04-07T03:16:09.897909539Z","rtype":160,"publisher_id":101,"instrument_id":436},"action":"A","side":"B","price":"1.156730000","size":30,"channel_id":23,"order_id":"10998903806752691524","flags":0,"ts_in_delta":868,"sequence":185128,"symbol":"FCEU SI 20260615 PS"}
{"ts_recv":"2026-04-07T03:16:09.897930663Z","hd":{"ts_event":"2026-04-07T03:16:09.897909539Z","rtype":160,"publisher_id":101,"instrument_id":436},"action":"C","side":"A","price":"1.156820000","size":30,"channel_id":23,"order_id":"1775531769897780635","flags":0,"ts_in_delta":868,"sequence":185128,"symbol":"FCEU SI 20260615 PS"}
{"ts_recv":"2026-04-07T03:16:09.897930663Z","hd":{"ts_event":"2026-04-07T03:16:09.897909539Z","rtype":160,"publisher_id":101,"instrument_id":436},"action":"A","side":"A","price":"1.156830000","size":30,"channel_id":23,"order_id":"1775531769897915716","flags":128,"ts_in_delta":868,"sequence":185128,"symbol":"FCEU SI 20260615 PS"}
{"ts_recv":"2026-04-07T03:16:09.902782472Z","hd":{"ts_event":"2026-04-07T03:16:09.902763685Z","rtype":160,"publisher_id":101,"instrument_id":436},"action":"C","side":"B","price":"1.156730000","size":30,"channel_id":23,"order_id":"10998903806752691524","flags":0,"ts_in_delta":868,"sequence":185130,"symbol":"FCEU SI 20260615 PS"}
{"ts_recv":"2026-04-07T03:16:09.902782472Z","hd":{"ts_event":"2026-04-07T03:16:09.902763685Z","rtype":160,"publisher_id":101,"instrument_id":436},"action":"A","side":"B","price":"1.156740000","size":30,"channel_id":23,"order_id":"10998903806757545735","flags":0,"ts_in_delta":868,"sequence":185130,"symbol":"FCEU SI 20260615 PS"}
{"ts_recv":"2026-04-07T03:16:09.902782472Z","hd":{"ts_event":"2026-04-07T03:16:09.902763685Z","rtype":160,"publisher_id":101,"instrument_id":436},"action":"C","side":"A","price":"1.156830000","size":30,"channel_id":23,"order_id":"1775531769897915716","flags":0,"ts_in_delta":868,"sequence":185130,"symbol":"FCEU SI 20260615 PS"}
{"ts_recv":"2026-04-07T03:16:09.902782472Z","hd":{"ts_event":"2026-04-07T03:16:09.902763685Z","rtype":160,"publisher_id":101,"instrument_id":436},"action":"A","side":"A","price":"1.156840000","size":30,"channel_id":23,"order_id":"1775531769902769927","flags":128,"ts_in_delta":868,"sequence":185130,"symbol":"FCEU SI 20260615 PS"}
{"ts_recv":"2026-04-07T03:16:09.951526991Z","hd":{"ts_event":"2026-04-07T03:16:09.951509517Z","rtype":160,"publisher_id":101,"instrument_id":436},"action":"C","side":"B","price":"1.156740000","size":30,"channel_id":23,"order_id":"10998903806757545735","flags":0,"ts_in_delta":878,"sequence":185136,"symbol":"FCEU SI 20260615 PS"}
{"ts_recv":"2026-04-07T03:16:09.951526991Z","hd":{"ts_event":"2026-04-07T03:16:09.951509517Z","rtype":160,"publisher_id":101,"instrument_id":436},"action":"A","side":"B","price":"1.156730000","size":30,"channel_id":23,"order_id":"10998903806806291307","flags":0,"ts_in_delta":878,"sequence":185136,"symbol":"FCEU SI 20260615 PS"}
{"ts_recv":"2026-04-07T03:16:09.951526991Z","hd":{"ts_event":"2026-04-07T03:16:09.951509517Z","rtype":160,"publisher_id":101,"instrument_id":436},"action":"C","side":"A","price":"1.156840000","size":30,"channel_id":23,"order_id":"1775531769902769927","flags":0,"ts_in_delta":878,"sequence":185136,"symbol":"FCEU SI 20260615 PS"}
{"ts_recv":"2026-04-07T03:16:09.951526991Z","hd":{"ts_event":"2026-04-07T03:16:09.951509517Z","rtype":160,"publisher_id":101,"instrument_id":436},"action":"A","side":"A","price":"1.156830000","size":30,"channel_id":23,"order_id":"1775531769951515499","flags":128,"ts_in_delta":878,"sequence":185136,"symbol":"FCEU SI 20260615 PS"}
{"ts_recv":"2026-04-07T03:16:12.433472529Z","hd":{"ts_event":"2026-04-07T03:16:12.433448815Z","rtype":160,"publisher_id":101,"instrument_id":436},"action":"C","side":"B","price":"1.156730000","size":30,"channel_id":23,"order_id":"10998903806806291307","flags":0,"ts_in_delta":934,"sequence":185156,"symbol":"FCEU SI 20260615 PS"}
{"ts_recv":"2026-04-07T03:16:12.433472529Z","hd":{"ts_event":"2026-04-07T03:16:12.433448815Z","rtype":160,"publisher_id":101,"instrument_id":436},"action":"A","side":"B","price":"1.156720000","size":30,"channel_id":23,"order_id":"10998903809288231087","flags":0,"ts_in_delta":934,"sequence":185156,"symbol":"FCEU SI 20260615 PS"}
{"ts_recv":"2026-04-07T03:16:12.433472529Z","hd":{"ts_event":"2026-04-07T03:16:12.433448815Z","rtype":160,"publisher_id":101,"instrument_id":436},"action":"C","side":"A","price":"1.156830000","size":30,"channel_id":23,"order_id":"1775531769951515499","flags":0,"ts_in_delta":934,"sequence":185156,"symbol":"FCEU SI 20260615 PS"}
{"ts_recv":"2026-04-07T03:16:12.433472529Z","hd":{"ts_event":"2026-04-07T03:16:12.433448815Z","rtype":160,"publisher_id":101,"instrument_id":436},"action":"A","side":"A","price":"1.156820000","size":30,"channel_id":23,"order_id":"1775531772433455279","flags":128,"ts_in_delta":934,"sequence":185156,"symbol":"FCEU SI 20260615 PS"}
{"ts_recv":"2026-04-07T03:16:12.433567027Z","hd":{"ts_event":"2026-04-07T03:16:12.433548893Z","rtype":160,"publisher_id":101,"instrument_id":436},"action":"C","side":"B","price":"1.156720000","size":30,"channel_id":23,"order_id":"10998903809288231087","flags":0,"ts_in_delta":914,"sequence":185157,"symbol":"FCEU SI 20260615 PS"}
{"ts_recv":"2026-04-07T03:16:12.433567027Z","hd":{"ts_event":"2026-04-07T03:16:12.433548893Z","rtype":160,"publisher_id":101,"instrument_id":436},"action":"A","side":"B","price":"1.156710000","size":30,"channel_id":23,"order_id":"10998903809288330950","flags":0,"ts_in_delta":914,"sequence":185157,"symbol":"FCEU SI 20260615 PS"}
{"ts_recv":"2026-04-07T03:16:12.433567027Z","hd":{"ts_event":"2026-04-07T03:16:12.433548893Z","rtype":160,"publisher_id":101,"instrument_id":436},"action":"C","side":"A","price":"1.156820000","size":30,"channel_id":23,"order_id":"1775531772433455279","flags":0,"ts_in_delta":914,"sequence":185157,"symbol":"FCEU SI 20260615 PS"}
{"ts_recv":"2026-04-07T03:16:12.433567027Z","hd":{"ts_event":"2026-04-07T03:16:12.433548893Z","rtype":160,"publisher_id":101,"instrument_id":436},"action":"A","side":"A","price":"1.156810000","size":30,"channel_id":23,"order_id":"1775531772433555142","flags":128,"ts_in_delta":914,"sequence":185157,"symbol":"FCEU SI 20260615 PS"}
{"ts_recv":"2026-04-07T03:16:12.433634746Z","hd":{"ts_event":"2026-04-07T03:16:12.433615657Z","rtype":160,"publisher_id":101,"instrument_id":436},"action":"C","side":"B","price":"1.156730000","size":30,"channel_id":23,"order_id":"10998903806752633357","flags":0,"ts_in_delta":883,"sequence":185158,"symbol":"FCEU SI 20260615 PS"}
{"ts_recv":"2026-04-07T03:16:12.433634746Z","hd":{"ts_event":"2026-04-07T03:16:12.433615657Z","rtype":160,"publisher_id":101,"instrument_id":436},"action":"A","side":"B","price":"1.156710000","size":30,"channel_id":23,"order_id":"10998903809288398041","flags":0,"ts_in_delta":883,"sequence":185158,"symbol":"FCEU SI 20260615 PS"}
{"ts_recv":"2026-04-07T03:16:12.433634746Z","hd":{"ts_event":"2026-04-07T03:16:12.433615657Z","rtype":160,"publisher_id":101,"instrument_id":436},"action":"C","side":"A","price":"1.156830000","size":30,"channel_id":23,"order_id":"1775531769897857549","flags":0,"ts_in_delta":883,"sequence":185158,"symbol":"FCEU SI 20260615 PS"}
{"ts_recv":"2026-04-07T03:16:12.433634746Z","hd":{"ts_event":"2026-04-07T03:16:12.433615657Z","rtype":160,"publisher_id":101,"instrument_id":436},"action":"A","side":"A","price":"1.156810000","size":30,"channel_id":23,"order_id":"1775531772433622233","flags":128,"ts_in_delta":883,"sequence":185158,"symbol":"FCEU SI 20260615 PS"}
{"ts_recv":"2026-04-07T03:16:12.433644891Z","hd":{"ts_event":"2026-04-07T03:16:12.433616041Z","rtype":160,"publisher_id":101,"instrument_id":436},"action":"C","side":"B","price":"1.156710000","size":30,"channel_id":23,"order_id":"10998903809288330950","flags":0,"ts_in_delta":921,"sequence":185159,"symbol":"FCEU SI 20260615 PS"}
{"ts_recv":"2026-04-07T03:16:12.433644891Z","hd":{"ts_event":"2026-04-07T03:16:12.433616041Z","rtype":160,"publisher_id":101,"instrument_id":436},"action":"A","side":"B","price":"1.156720000","size":30,"channel_id":23,"order_id":"10998903809288407381","flags":0,"ts_in_delta":921,"sequence":185159,"symbol":"FCEU SI 20260615 PS"}
{"ts_recv":"2026-04-07T03:16:12.433644891Z","hd":{"ts_event":"2026-04-07T03:16:12.433616041Z","rtype":160,"publisher_id":101,"instrument_id":436},"action":"C","side":"A","price":"1.156810000","size":30,"channel_id":23,"order_id":"1775531772433555142","flags":0,"ts_in_delta":921,"sequence":185159,"symbol":"FCEU SI 20260615 PS"}
{"ts_recv":"2026-04-07T03:16:12.433644891Z","hd":{"ts_event":"2026-04-07T03:16:12.433616041Z","rtype":160,"publisher_id":101,"instrument_id":436},"action":"A","side":"A","price":"1.156820000","size":30,"channel_id":23,"order_id":"1775531772433631573","flags":128,"ts_in_delta":921,"sequence":185159,"symbol":"FCEU SI 20260615 PS"}
{"ts_recv":"2026-04-07T03:16:12.433697328Z","hd":{"ts_event":"2026-04-07T03:16:12.433680113Z","rtype":160,"publisher_id":101,"instrument_id":436},"action":"C","side":"B","price":"1.156720000","size":30,"channel_id":23,"order_id":"10998903809288407381","flags":0,"ts_in_delta":907,"sequence":185160,"symbol":"FCEU SI 20260615 PS"}
{"ts_recv":"2026-04-07T03:16:12.433697328Z","hd":{"ts_event":"2026-04-07T03:16:12.433680113Z","rtype":160,"publisher_id":101,"instrument_id":436},"action":"A","side":"B","price":"1.156710000","size":30,"channel_id":23,"order_id":"10998903809288461793","flags":0,"ts_in_delta":907,"sequence":185160,"symbol":"FCEU SI 20260615 PS"}
{"ts_recv":"2026-04-07T03:16:12.433697328Z","hd":{"ts_event":"2026-04-07T03:16:12.433680113Z","rtype":160,"publisher_id":101,"instrument_id":436},"action":"C","side":"A","price":"1.156820000","size":30,"channel_id":23,"order_id":"1775531772433631573","flags":0,"ts_in_delta":907,"sequence":185160,"symbol":"FCEU SI 20260615 PS"}
{"ts_recv":"2026-04-07T03:16:12.433697328Z","hd":{"ts_event":"2026-04-07T03:16:12.433680113Z","rtype":160,"publisher_id":101,"instrument_id":436},"action":"A","side":"A","price":"1.156810000","size":30,"channel_id":23,"order_id":"1775531772433685985","flags":128,"ts_in_delta":907,"sequence":185160,"symbol":"FCEU SI 20260615 PS"}
{"ts_recv":"2026-04-07T03:17:20.222242159Z","hd":{"ts_event":"2026-04-07T03:17:20.222212815Z","rtype":160,"publisher_id":101,"instrument_id":436},"action":"C","side":"B","price":"1.156710000","size":30,"channel_id":23,"order_id":"10998903809288398041","flags":0,"ts_in_delta":1547,"sequence":185493,"symbol":"FCEU SI 20260615 PS"}
{"ts_recv":"2026-04-07T03:17:20.222242159Z","hd":{"ts_event":"2026-04-07T03:17:20.222212815Z","rtype":160,"publisher_id":101,"instrument_id":436},"action":"C","side":"A","price":"1.156810000","size":30,"channel_id":23,"order_id":"1775531772433622233","flags":128,"ts_in_delta":1547,"sequence":185493,"symbol":"FCEU SI 20260615 PS"}
{"ts_recv":"2026-04-07T03:17:20.222341357Z","hd":{"ts_event":"2026-04-07T03:17:20.222319055Z","rtype":160,"publisher_id":101,"instrument_id":436},"action":"C","side":"B","price":"1.156710000","size":30,"channel_id":23,"order_id":"10998903809288461793","flags":0,"ts_in_delta":1016,"sequence":185494,"symbol":"FCEU SI 20260615 PS"}
{"ts_recv":"2026-04-07T03:17:20.222341357Z","hd":{"ts_event":"2026-04-07T03:17:20.222319055Z","rtype":160,"publisher_id":101,"instrument_id":436},"action":"A","side":"B","price":"1.156700000","size":30,"channel_id":23,"order_id":"10998903877077101462","flags":0,"ts_in_delta":1016,"sequence":185494,"symbol":"FCEU SI 20260615 PS"}
{"ts_recv":"2026-04-07T03:17:20.222341357Z","hd":{"ts_event":"2026-04-07T03:17:20.222319055Z","rtype":160,"publisher_id":101,"instrument_id":436},"action":"C","side":"A","price":"1.156810000","size":30,"channel_id":23,"order_id":"1775531772433685985","flags":0,"ts_in_delta":1016,"sequence":185494,"symbol":"FCEU SI 20260615 PS"}
{"ts_recv":"2026-04-07T03:17:20.222341357Z","hd":{"ts_event":"2026-04-07T03:17:20.222319055Z","rtype":160,"publisher_id":101,"instrument_id":436},"action":"A","side":"A","price":"1.156800000","size":30,"channel_id":23,"order_id":"1775531840222325654","flags":128,"ts_in_delta":1016,"sequence":185494,"symbol":"FCEU SI 20260615 PS"}
{"ts_recv":"2026-04-07T03:17:23.884134339Z","hd":{"ts_event":"2026-04-07T03:17:23.884105319Z","rtype":160,"publisher_id":101,"instrument_id":436},"action":"C","side":"B","price":"1.156700000","size":30,"channel_id":23,"order_id":"10998903877077101462","flags":0,"ts_in_delta":996,"sequence":185513,"symbol":"FCEU SI 20260615 PS"}
{"ts_recv":"2026-04-07T03:17:23.884134339Z","hd":{"ts_event":"2026-04-07T03:17:23.884105319Z","rtype":160,"publisher_id":101,"instrument_id":436},"action":"C","side":"A","price":"1.156800000","size":30,"channel_id":23,"order_id":"1775531840222325654","flags":128,"ts_in_delta":996,"sequence":185513,"symbol":"FCEU SI 20260615 PS"}
{"ts_recv":"2026-04-07T03:17:32.564116745Z","hd":{"ts_event":"2026-04-07T03:17:32.564097571Z","rtype":160,"publisher_id":101,"instrument_id":436},"action":"C","side":"B","price":"1.156600000","size":20,"channel_id":23,"order_id":"10998903634598232092","flags":128,"ts_in_delta":1364,"sequence":185573,"symbol":"FCEU SI 20260615 PS"}
{"ts_recv":"2026-04-07T03:17:32.608041505Z","hd":{"ts_event":"2026-04-07T03:17:32.608023783Z","rtype":160,"publisher_id":101,"instrument_id":436},"action":"A","side":"B","price":"1.156500000","size":20,"channel_id":23,"order_id":"10998903889462805632","flags":128,"ts_in_delta":1309,"sequence":185581,"symbol":"FCEU SI 20260615 PS"}
{"ts_recv":"2026-04-07T03:17:32.752118111Z","hd":{"ts_event":"2026-04-07T03:17:32.752102857Z","rtype":160,"publisher_id":101,"instrument_id":436},"action":"A","side":"A","price":"1.156900000","size":20,"channel_id":23,"order_id":"1775531852752108937","flags":128,"ts_in_delta":696,"sequence":185612,"symbol":"FCEU SI 20260615 PS"}
{"ts_recv":"2026-04-07T03:17:32.752138002Z","hd":{"ts_event":"2026-04-07T03:17:32.752125051Z","rtype":160,"publisher_id":101,"instrument_id":436},"action":"C","side":"A","price":"1.157000000","size":20,"channel_id":23,"order_id":"1775531597713679010","flags":128,"ts_in_delta":856,"sequence":185613,"symbol":"FCEU SI 20260615 PS"}
{"ts_recv":"2026-04-07T03:17:42.414485949Z","hd":{"ts_event":"2026-04-07T03:17:42.414472201Z","rtype":160,"publisher_id":101,"instrument_id":436},"action":"C","side":"A","price":"1.156900000","size":20,"channel_id":23,"order_id":"1775531852752108937","flags":128,"ts_in_delta":886,"sequence":185668,"symbol":"FCEU SI 20260615 PS"}
{"ts_recv":"2026-04-07T03:17:42.457055074Z","hd":{"ts_event":"2026-04-07T03:17:42.457038725Z","rtype":160,"publisher_id":101,"instrument_id":436},"action":"A","side":"A","price":"1.157000000","size":20,"channel_id":23,"order_id":"1775531862457045016","flags":128,"ts_in_delta":1116,"sequence":185670,"symbol":"FCEU SI 20260615 PS"}
{"ts_recv":"2026-04-07T03:17:43.691910284Z","hd":{"ts_event":"2026-04-07T03:17:43.691888303Z","rtype":160,"publisher_id":101,"instrument_id":436},"action":"A","side":"B","price":"1.156600000","size":20,"channel_id":23,"order_id":"10998903900546677306","flags":128,"ts_in_delta":809,"sequence":185683,"symbol":"FCEU SI 20260615 PS"}
{"ts_recv":"2026-04-07T03:17:43.691919192Z","hd":{"ts_event":"2026-04-07T03:17:43.691903611Z","rtype":160,"publisher_id":101,"instrument_id":436},"action":"C","side":"B","price":"1.156500000","size":20,"channel_id":23,"order_id":"10998903889462805632","flags":128,"ts_in_delta":883,"sequence":185684,"symbol":"FCEU SI 20260615 PS"}
{"ts_recv":"2026-04-07T03:18:02.839524087Z","hd":{"ts_event":"2026-04-07T03:18:02.839498123Z","rtype":160,"publisher_id":101,"instrument_id":436},"action":"C","side":"B","price":"1.156600000","size":20,"channel_id":23,"order_id":"10998903900546677306","flags":128,"ts_in_delta":1253,"sequence":185756,"symbol":"FCEU SI 20260615 PS"}
{"ts_recv":"2026-04-07T03:18:02.882380370Z","hd":{"ts_event":"2026-04-07T03:18:02.882360941Z","rtype":160,"publisher_id":101,"instrument_id":436},"action":"A","side":"B","price":"1.156500000","size":20,"channel_id":23,"order_id":"10998903919737142715","flags":128,"ts_in_delta":874,"sequence":185759,"symbol":"FCEU SI 20260615 PS"}
{"ts_recv":"2026-04-07T03:18:10.522727011Z","hd":{"ts_event":"2026-04-07T03:18:10.522702283Z","rtype":160,"publisher_id":101,"instrument_id":436},"action":"A","side":"B","price":"1.156600000","size":20,"channel_id":23,"order_id":"10998903927377491282","flags":128,"ts_in_delta":1336,"sequence":185794,"symbol":"FCEU SI 20260615 PS"}
{"ts_recv":"2026-04-07T03:18:10.522730329Z","hd":{"ts_event":"2026-04-07T03:18:10.522714251Z","rtype":160,"publisher_id":101,"instrument_id":436},"action":"C","side":"B","price":"1.156500000","size":20,"channel_id":23,"order_id":"10998903919737142715","flags":128,"ts_in_delta":958,"sequence":185795,"symbol":"FCEU SI 20260615 PS"}
{"ts_recv":"2026-04-07T03:18:21.001566959Z","hd":{"ts_event":"2026-04-07T03:18:21.001543271Z","rtype":160,"publisher_id":101,"instrument_id":436},"action":"C","side":"B","price":"1.156600000","size":20,"channel_id":23,"order_id":"10998903927377491282","flags":128,"ts_in_delta":1308,"sequence":185859,"symbol":"FCEU SI 20260615 PS"}
{"ts_recv":"2026-04-07T03:18:21.044140041Z","hd":{"ts_event":"2026-04-07T03:18:21.044118837Z","rtype":160,"publisher_id":101,"instrument_id":436},"action":"A","side":"B","price":"1.156500000","size":20,"channel_id":23,"order_id":"10998903937898905614","flags":128,"ts_in_delta":1345,"sequence":185860,"symbol":"FCEU SI 20260615 PS"}
{"ts_recv":"2026-04-07T03:19:01.951536143Z","hd":{"ts_event":"2026-04-07T03:19:01.951506605Z","rtype":160,"publisher_id":101,"instrument_id":436},"action":"A","side":"B","price":"1.156600000","size":20,"channel_id":23,"order_id":"10998903978806296926","flags":128,"ts_in_delta":1526,"sequence":186052,"symbol":"FCEU SI 20260615 PS"}
{"ts_recv":"2026-04-07T03:19:01.951539269Z","hd":{"ts_event":"2026-04-07T03:19:01.951514869Z","rtype":160,"publisher_id":101,"instrument_id":436},"action":"C","side":"B","price":"1.156500000","size":20,"channel_id":23,"order_id":"10998903937898905614","flags":128,"ts_in_delta":746,"sequence":186053,"symbol":"FCEU SI 20260615 PS"}
{"ts_recv":"2026-04-07T03:19:07.392762618Z","hd":{"ts_event":"2026-04-07T03:19:07.392748441Z","rtype":160,"publisher_id":101,"instrument_id":436},"action":"C","side":"B","price":"1.156600000","size":20,"channel_id":23,"order_id":"10998903978806296926","flags":128,"ts_in_delta":629,"sequence":186091,"symbol":"FCEU SI 20260615 PS"}
{"ts_recv":"2026-04-07T03:19:07.436134775Z","hd":{"ts_event":"2026-04-07T03:19:07.436120709Z","rtype":160,"publisher_id":101,"instrument_id":436},"action":"A","side":"B","price":"1.156500000","size":20,"channel_id":23,"order_id":"10998903984290902428","flags":128,"ts_in_delta":855,"sequence":186099,"symbol":"FCEU SI 20260615 PS"}
{"ts_recv":"2026-04-07T03:19:07.730594141Z","hd":{"ts_event":"2026-04-07T03:19:07.730571643Z","rtype":160,"publisher_id":101,"instrument_id":436},"action":"A","side":"B","price":"1.156600000","size":20,"channel_id":23,"order_id":"10998903984585360360","flags":128,"ts_in_delta":1466,"sequence":186111,"symbol":"FCEU SI 20260615 PS"}
{"ts_recv":"2026-04-07T03:19:07.730597420Z","hd":{"ts_event":"2026-04-07T03:19:07.730583905Z","rtype":160,"publisher_id":101,"instrument_id":436},"action":"C","side":"B","price":"1.156500000","size":20,"channel_id":23,"order_id":"10998903984290902428","flags":128,"ts_in_delta":711,"sequence":186112,"symbol":"FCEU SI 20260615 PS"}
{"ts_recv":"2026-04-07T03:19:16.144473122Z","hd":{"ts_event":"2026-04-07T03:19:16.144459649Z","rtype":160,"publisher_id":101,"instrument_id":436},"action":"C","side":"B","price":"1.156600000","size":20,"channel_id":23,"order_id":"10998903984585360360","flags":128,"ts_in_delta":815,"sequence":186149,"symbol":"FCEU SI 20260615 PS"}
{"ts_recv":"2026-04-07T03:19:16.188655709Z","hd":{"ts_event":"2026-04-07T03:19:16.188640083Z","rtype":160,"publisher_id":101,"instrument_id":436},"action":"A","side":"B","price":"1.156500000","size":20,"channel_id":23,"order_id":"10998903993043422120","flags":128,"ts_in_delta":802,"sequence":186151,"symbol":"FCEU SI 20260615 PS"}
{"ts_recv":"2026-04-07T03:19:36.571171177Z","hd":{"ts_event":"2026-04-07T03:19:36.571152711Z","rtype":160,"publisher_id":101,"instrument_id":436},"action":"A","side":"A","price":"1.156900000","size":20,"channel_id":23,"order_id":"1775531976571160617","flags":128,"ts_in_delta":771,"sequence":186267,"symbol":"FCEU SI 20260615 PS"}
{"ts_recv":"2026-04-07T03:19:36.571221963Z","hd":{"ts_event":"2026-04-07T03:19:36.571206985Z","rtype":160,"publisher_id":101,"instrument_id":436},"action":"C","side":"A","price":"1.157000000","size":20,"channel_id":23,"order_id":"1775531862457045016","flags":128,"ts_in_delta":805,"sequence":186270,"symbol":"FCEU SI 20260615 PS"}
{"ts_recv":"2026-04-07T03:19:43.629142580Z","hd":{"ts_event":"2026-04-07T03:19:43.629128505Z","rtype":160,"publisher_id":101,"instrument_id":436},"action":"C","side":"B","price":"1.156500000","size":20,"channel_id":23,"order_id":"10998903993043422120","flags":128,"ts_in_delta":864,"sequence":186317,"symbol":"FCEU SI 20260615 PS"}
{"ts_recv":"2026-04-07T03:19:43.672064926Z","hd":{"ts_event":"2026-04-07T03:19:43.672048719Z","rtype":160,"publisher_id":101,"instrument_id":436},"action":"A","side":"B","price":"1.156400000","size":20,"channel_id":23,"order_id":"10998904020526830590","flags":128,"ts_in_delta":894,"sequence":186325,"symbol":"FCEU SI 20260615 PS"}
{"ts_recv":"2026-04-07T03:19:46.922134102Z","hd":{"ts_event":"2026-04-07T03:19:46.922118165Z","rtype":160,"publisher_id":101,"instrument_id":436},"action":"A","side":"A","price":"1.156800000","size":20,"channel_id":23,"order_id":"1775531986922124545","flags":128,"ts_in_delta":1085,"sequence":186394,"symbol":"FCEU SI 20260615 PS"}
{"ts_recv":"2026-04-07T03:19:46.922486920Z","hd":{"ts_event":"2026-04-07T03:19:46.922473527Z","rtype":160,"publisher_id":101,"instrument_id":436},"action":"C","side":"A","price":"1.156900000","size":20,"channel_id":23,"order_id":"1775531976571160617","flags":128,"ts_in_delta":774,"sequence":186397,"symbol":"FCEU SI 20260615 PS"}
{"ts_recv":"2026-04-07T03:20:35.183882262Z","hd":{"ts_event":"2026-04-07T03:20:35.183867155Z","rtype":160,"publisher_id":101,"instrument_id":436},"action":"C","side":"A","price":"1.156800000","size":20,"channel_id":23,"order_id":"1775531986922124545","flags":128,"ts_in_delta":757,"sequence":186686,"symbol":"FCEU SI 20260615 PS"}
{"ts_recv":"2026-04-07T03:20:35.227198779Z","hd":{"ts_event":"2026-04-07T03:20:35.227181823Z","rtype":160,"publisher_id":101,"instrument_id":436},"action":"A","side":"A","price":"1.156900000","size":20,"channel_id":23,"order_id":"1775532035227187679","flags":128,"ts_in_delta":836,"sequence":186690,"symbol":"FCEU SI 20260615 PS"}
{"ts_recv":"2026-04-07T03:20:37.653115561Z","hd":{"ts_event":"2026-04-07T03:20:37.653097889Z","rtype":160,"publisher_id":101,"instrument_id":436},"action":"A","side":"B","price":"1.156500000","size":20,"channel_id":23,"order_id":"10998904074507879950","flags":128,"ts_in_delta":858,"sequence":186723,"symbol":"FCEU SI 20260615 PS"}
{"ts_recv":"2026-04-07T03:20:37.653130652Z","hd":{"ts_event":"2026-04-07T03:20:37.653116539Z","rtype":160,"publisher_id":101,"instrument_id":436},"action":"C","side":"B","price":"1.156400000","size":20,"channel_id":23,"order_id":"10998904020526830590","flags":128,"ts_in_delta":870,"sequence":186724,"symbol":"FCEU SI 20260615 PS"}
{"ts_recv":"2026-04-07T03:20:56.870865302Z","hd":{"ts_event":"2026-04-07T03:20:56.870805717Z","rtype":160,"publisher_id":101,"instrument_id":436},"action":"A","side":"B","price":"1.156640000","size":30,"channel_id":23,"order_id":"10998904093725596897","flags":0,"ts_in_delta":1377,"sequence":186847,"symbol":"FCEU SI 20260615 PS"}
{"ts_recv":"2026-04-07T03:20:56.870865302Z","hd":{"ts_event":"2026-04-07T03:20:56.870805717Z","rtype":160,"publisher_id":101,"instrument_id":436},"action":"A","side":"A","price":"1.156740000","size":30,"channel_id":23,"order_id":"1775532056870821089","flags":128,"ts_in_delta":1377,"sequence":186847,"symbol":"FCEU SI 20260615 PS"}
{"ts_recv":"2026-04-07T03:21:04.871082860Z","hd":{"ts_event":"2026-04-07T03:21:04.871048179Z","rtype":160,"publisher_id":101,"instrument_id":436},"action":"C","side":"B","price":"1.156640000","size":30,"channel_id":23,"order_id":"10998904093725596897","flags":0,"ts_in_delta":1116,"sequence":186891,"symbol":"FCEU SI 20260615 PS"}
{"ts_recv":"2026-04-07T03:21:04.871082860Z","hd":{"ts_event":"2026-04-07T03:21:04.871048179Z","rtype":160,"publisher_id":101,"instrument_id":436},"action":"A","side":"B","price":"1.156650000","size":30,"channel_id":23,"order_id":"10998904101725835062","flags":0,"ts_in_delta":1116,"sequence":186891,"symbol":"FCEU SI 20260615 PS"}
{"ts_recv":"2026-04-07T03:21:04.871082860Z","hd":{"ts_event":"2026-04-07T03:21:04.871048179Z","rtype":160,"publisher_id":101,"instrument_id":436},"action":"C","side":"A","price":"1.156740000","size":30,"channel_id":23,"order_id":"1775532056870821089","flags":0,"ts_in_delta":1116,"sequence":186891,"symbol":"FCEU SI 20260615 PS"}
{"ts_recv":"2026-04-07T03:21:04.871082860Z","hd":{"ts_event":"2026-04-07T03:21:04.871048179Z","rtype":160,"publisher_id":101,"instrument_id":436},"action":"A","side":"A","price":"1.156750000","size":30,"channel_id":23,"order_id":"1775532064871059254","flags":128,"ts_in_delta":1116,"sequence":186891,"symbol":"FCEU SI 20260615 PS"}
{"ts_recv":"2026-04-07T03:21:05.875582007Z","hd":{"ts_event":"2026-04-07T03:21:05.875558991Z","rtype":160,"publisher_id":101,"instrument_id":436},"action":"C","side":"B","price":"1.156650000","size":30,"channel_id":23,"order_id":"10998904101725835062","flags":0,"ts_in_delta":881,"sequence":186922,"symbol":"FCEU SI 20260615 PS"}
{"ts_recv":"2026-04-07T03:21:05.875582007Z","hd":{"ts_event":"2026-04-07T03:21:05.875558991Z","rtype":160,"publisher_id":101,"instrument_id":436},"action":"A","side":"B","price":"1.156670000","size":30,"channel_id":23,"order_id":"10998904102730340845","flags":0,"ts_in_delta":881,"sequence":186922,"symbol":"FCEU SI 20260615 PS"}
{"ts_recv":"2026-04-07T03:21:05.875582007Z","hd":{"ts_event":"2026-04-07T03:21:05.875558991Z","rtype":160,"publisher_id":101,"instrument_id":436},"action":"C","side":"A","price":"1.156750000","size":30,"channel_id":23,"order_id":"1775532064871059254","flags":0,"ts_in_delta":881,"sequence":186922,"symbol":"FCEU SI 20260615 PS"}
{"ts_recv":"2026-04-07T03:21:05.875582007Z","hd":{"ts_event":"2026-04-07T03:21:05.875558991Z","rtype":160,"publisher_id":101,"instrument_id":436},"action":"A","side":"A","price":"1.156770000","size":30,"channel_id":23,"order_id":"1775532065875565037","flags":128,"ts_in_delta":881,"sequence":186922,"symbol":"FCEU SI 20260615 PS"}
{"ts_recv":"2026-04-07T03:21:07.065303984Z","hd":{"ts_event":"2026-04-07T03:21:07.065281121Z","rtype":160,"publisher_id":101,"instrument_id":436},"action":"C","side":"B","price":"1.156670000","size":30,"channel_id":23,"order_id":"10998904102730340845","flags":0,"ts_in_delta":1026,"sequence":186944,"symbol":"FCEU SI 20260615 PS"}
{"ts_recv":"2026-04-07T03:21:07.065303984Z","hd":{"ts_event":"2026-04-07T03:21:07.065281121Z","rtype":160,"publisher_id":101,"instrument_id":436},"action":"A","side":"B","price":"1.156680000","size":30,"channel_id":23,"order_id":"10998904103920063154","flags":0,"ts_in_delta":1026,"sequence":186944,"symbol":"FCEU SI 20260615 PS"}
{"ts_recv":"2026-04-07T03:21:07.065303984Z","hd":{"ts_event":"2026-04-07T03:21:07.065281121Z","rtype":160,"publisher_id":101,"instrument_id":436},"action":"C","side":"A","price":"1.156770000","size":30,"channel_id":23,"order_id":"1775532065875565037","flags":0,"ts_in_delta":1026,"sequence":186944,"symbol":"FCEU SI 20260615 PS"}
{"ts_recv":"2026-04-07T03:21:07.065303984Z","hd":{"ts_event":"2026-04-07T03:21:07.065281121Z","rtype":160,"publisher_id":101,"instrument_id":436},"action":"A","side":"A","price":"1.156780000","size":30,"channel_id":23,"order_id":"1775532067065287346","flags":128,"ts_in_delta":1026,"sequence":186944,"symbol":"FCEU SI 20260615 PS"}
{"ts_recv":"2026-04-07T03:21:10.441262041Z","hd":{"ts_event":"2026-04-07T03:21:10.441224655Z","rtype":160,"publisher_id":101,"instrument_id":436},"action":"A","side":"B","price":"1.156680000","size":30,"channel_id":23,"order_id":"10998904107296013447","flags":0,"ts_in_delta":1391,"sequence":186947,"symbol":"FCEU SI 20260615 PS"}
{"ts_recv":"2026-04-07T03:21:10.441262041Z","hd":{"ts_event":"2026-04-07T03:21:10.441224655Z","rtype":160,"publisher_id":101,"instrument_id":436},"action":"A","side":"A","price":"1.156780000","size":30,"channel_id":23,"order_id":"1775532070441237639","flags":128,"ts_in_delta":1391,"sequence":186947,"symbol":"FCEU SI 20260615 PS"}
{"ts_recv":"2026-04-07T03:21:21.253639750Z","hd":{"ts_event":"2026-04-07T03:21:21.253614891Z","rtype":160,"publisher_id":101,"instrument_id":436},"action":"C","side":"B","price":"1.156680000","size":30,"channel_id":23,"order_id":"10998904103920063154","flags":0,"ts_in_delta":966,"sequence":187018,"symbol":"FCEU SI 20260615 PS"}
{"ts_recv":"2026-04-07T03:21:21.253639750Z","hd":{"ts_event":"2026-04-07T03:21:21.253614891Z","rtype":160,"publisher_id":101,"instrument_id":436},"action":"A","side":"B","price":"1.156670000","size":30,"channel_id":23,"order_id":"10998904118108397284","flags":0,"ts_in_delta":966,"sequence":187018,"symbol":"FCEU SI 20260615 PS"}
{"ts_recv":"2026-04-07T03:21:21.253639750Z","hd":{"ts_event":"2026-04-07T03:21:21.253614891Z","rtype":160,"publisher_id":101,"instrument_id":436},"action":"C","side":"A","price":"1.156780000","size":30,"channel_id":23,"order_id":"1775532067065287346","flags":0,"ts_in_delta":966,"sequence":187018,"symbol":"FCEU SI 20260615 PS"}
{"ts_recv":"2026-04-07T03:21:21.253639750Z","hd":{"ts_event":"2026-04-07T03:21:21.253614891Z","rtype":160,"publisher_id":101,"instrument_id":436},"action":"A","side":"A","price":"1.156770000","size":30,"channel_id":23,"order_id":"1775532081253621476","flags":128,"ts_in_delta":966,"sequence":187018,"symbol":"FCEU SI 20260615 PS"}
{"ts_recv":"2026-04-07T03:21:21.253708261Z","hd":{"ts_event":"2026-04-07T03:21:21.253687449Z","rtype":160,"publisher_id":101,"instrument_id":436},"action":"C","side":"B","price":"1.156680000","size":30,"channel_id":23,"order_id":"10998904107296013447","flags":0,"ts_in_delta":1100,"sequence":187019,"symbol":"FCEU SI 20260615 PS"}
{"ts_recv":"2026-04-07T03:21:21.253708261Z","hd":{"ts_event":"2026-04-07T03:21:21.253687449Z","rtype":160,"publisher_id":101,"instrument_id":436},"action":"A","side":"B","price":"1.156660000","size":30,"channel_id":23,"order_id":"10998904118108469619","flags":0,"ts_in_delta":1100,"sequence":187019,"symbol":"FCEU SI 20260615 PS"}
{"ts_recv":"2026-04-07T03:21:21.253708261Z","hd":{"ts_event":"2026-04-07T03:21:21.253687449Z","rtype":160,"publisher_id":101,"instrument_id":436},"action":"C","side":"A","price":"1.156780000","size":30,"channel_id":23,"order_id":"1775532070441237639","flags":0,"ts_in_delta":1100,"sequence":187019,"symbol":"FCEU SI 20260615 PS"}
{"ts_recv":"2026-04-07T03:21:21.253708261Z","hd":{"ts_event":"2026-04-07T03:21:21.253687449Z","rtype":160,"publisher_id":101,"instrument_id":436},"action":"A","side":"A","price":"1.156760000","size":30,"channel_id":23,"order_id":"1775532081253693811","flags":128,"ts_in_delta":1100,"sequence":187019,"symbol":"FCEU SI 20260615 PS"}
{"ts_recv":"2026-04-07T03:21:21.253721562Z","hd":{"ts_event":"2026-04-07T03:21:21.253705683Z","rtype":160,"publisher_id":101,"instrument_id":436},"action":"C","side":"B","price":"1.156670000","size":30,"channel_id":23,"order_id":"10998904118108397284","flags":0,"ts_in_delta":974,"sequence":187020,"symbol":"FCEU SI 20260615 PS"}
{"ts_recv":"2026-04-07T03:21:21.253721562Z","hd":{"ts_event":"2026-04-07T03:21:21.253705683Z","rtype":160,"publisher_id":101,"instrument_id":436},"action":"A","side":"B","price":"1.156660000","size":30,"channel_id":23,"order_id":"10998904118108487174","flags":0,"ts_in_delta":974,"sequence":187020,"symbol":"FCEU SI 20260615 PS"}
{"ts_recv":"2026-04-07T03:21:21.253721562Z","hd":{"ts_event":"2026-04-07T03:21:21.253705683Z","rtype":160,"publisher_id":101,"instrument_id":436},"action":"C","side":"A","price":"1.156770000","size":30,"channel_id":23,"order_id":"1775532081253621476","flags":0,"ts_in_delta":974,"sequence":187020,"symbol":"FCEU SI 20260615 PS"}
{"ts_recv":"2026-04-07T03:21:21.253721562Z","hd":{"ts_event":"2026-04-07T03:21:21.253705683Z","rtype":160,"publisher_id":101,"instrument_id":436},"action":"A","side":"A","price":"1.156760000","size":30,"channel_id":23,"order_id":"1775532081253711366","flags":128,"ts_in_delta":974,"sequence":187020,"symbol":"FCEU SI 20260615 PS"}
{"ts_recv":"2026-04-07T03:21:24.383292883Z","hd":{"ts_event":"2026-04-07T03:21:24.383265755Z","rtype":160,"publisher_id":101,"instrument_id":436},"action":"C","side":"B","price":"1.156660000","size":30,"channel_id":23,"order_id":"10998904118108487174","flags":0,"ts_in_delta":1206,"sequence":187057,"symbol":"FCEU SI 20260615 PS"}
{"ts_recv":"2026-04-07T03:21:24.383292883Z","hd":{"ts_event":"2026-04-07T03:21:24.383265755Z","rtype":160,"publisher_id":101,"instrument_id":436},"action":"A","side":"B","price":"1.156670000","size":30,"channel_id":23,"order_id":"10998904121238052828","flags":0,"ts_in_delta":1206,"sequence":187057,"symbol":"FCEU SI 20260615 PS"}
{"ts_recv":"2026-04-07T03:21:24.383292883Z","hd":{"ts_event":"2026-04-07T03:21:24.383265755Z","rtype":160,"publisher_id":101,"instrument_id":436},"action":"C","side":"A","price":"1.156760000","size":30,"channel_id":23,"order_id":"1775532081253711366","flags":0,"ts_in_delta":1206,"sequence":187057,"symbol":"FCEU SI 20260615 PS"}
{"ts_recv":"2026-04-07T03:21:24.383292883Z","hd":{"ts_event":"2026-04-07T03:21:24.383265755Z","rtype":160,"publisher_id":101,"instrument_id":436},"action":"A","side":"A","price":"1.156770000","size":30,"channel_id":23,"order_id":"1775532084383277020","flags":128,"ts_in_delta":1206,"sequence":187057,"symbol":"FCEU SI 20260615 PS"}
{"ts_recv":"2026-04-07T03:21:24.396423689Z","hd":{"ts_event":"2026-04-07T03:21:24.396404823Z","rtype":160,"publisher_id":101,"instrument_id":436},"action":"C","side":"B","price":"1.156670000","size":30,"channel_id":23,"order_id":"10998904121238052828","flags":0,"ts_in_delta":942,"sequence":187068,"symbol":"FCEU SI 20260615 PS"}
{"ts_recv":"2026-04-07T03:21:24.396423689Z","hd":{"ts_event":"2026-04-07T03:21:24.396404823Z","rtype":160,"publisher_id":101,"instrument_id":436},"action":"A","side":"B","price":"1.156680000","size":30,"channel_id":23,"order_id":"10998904121251186742","flags":0,"ts_in_delta":942,"sequence":187068,"symbol":"FCEU SI 20260615 PS"}
{"ts_recv":"2026-04-07T03:21:24.396423689Z","hd":{"ts_event":"2026-04-07T03:21:24.396404823Z","rtype":160,"publisher_id":101,"instrument_id":436},"action":"C","side":"A","price":"1.156770000","size":30,"channel_id":23,"order_id":"1775532084383277020","flags":0,"ts_in_delta":942,"sequence":187068,"symbol":"FCEU SI 20260615 PS"}
{"ts_recv":"2026-04-07T03:21:24.396423689Z","hd":{"ts_event":"2026-04-07T03:21:24.396404823Z","rtype":160,"publisher_id":101,"instrument_id":436},"action":"A","side":"A","price":"1.156780000","size":30,"channel_id":23,"order_id":"1775532084396410934","flags":128,"ts_in_delta":942,"sequence":187068,"symbol":"FCEU SI 20260615 PS"}
{"ts_recv":"2026-04-07T03:21:24.396481271Z","hd":{"ts_event":"2026-04-07T03:21:24.396461605Z","rtype":160,"publisher_id":101,"instrument_id":436},"action":"C","side":"B","price":"1.156660000","size":30,"channel_id":23,"order_id":"10998904118108469619","flags":0,"ts_in_delta":928,"sequence":187069,"symbol":"FCEU SI 20260615 PS"}
{"ts_recv":"2026-04-07T03:21:24.396481271Z","hd":{"ts_event":"2026-04-07T03:21:24.396461605Z","rtype":160,"publisher_id":101,"instrument_id":436},"action":"A","side":"B","price":"1.156680000","size":30,"channel_id":23,"order_id":"10998904121251243528","flags":0,"ts_in_delta":928,"sequence":187069,"symbol":"FCEU SI 20260615 PS"}
{"ts_recv":"2026-04-07T03:21:24.396481271Z","hd":{"ts_event":"2026-04-07T03:21:24.396461605Z","rtype":160,"publisher_id":101,"instrument_id":436},"action":"C","side":"A","price":"1.156760000","size":30,"channel_id":23,"order_id":"1775532081253693811","flags":0,"ts_in_delta":928,"sequence":187069,"symbol":"FCEU SI 20260615 PS"}
{"ts_recv":"2026-04-07T03:21:24.396481271Z","hd":{"ts_event":"2026-04-07T03:21:24.396461605Z","rtype":160,"publisher_id":101,"instrument_id":436},"action":"A","side":"A","price":"1.156780000","size":30,"channel_id":23,"order_id":"1775532084396467720","flags":128,"ts_in_delta":928,"sequence":187069,"symbol":"FCEU SI 20260615 PS"}
{"ts_recv":"2026-04-07T03:21:24.396507520Z","hd":{"ts_event":"2026-04-07T03:21:24.396487727Z","rtype":160,"publisher_id":101,"instrument_id":436},"action":"C","side":"B","price":"1.156680000","size":30,"channel_id":23,"order_id":"10998904121251186742","flags":0,"ts_in_delta":925,"sequence":187070,"symbol":"FCEU SI 20260615 PS"}
{"ts_recv":"2026-04-07T03:21:24.396507520Z","hd":{"ts_event":"2026-04-07T03:21:24.396487727Z","rtype":160,"publisher_id":101,"instrument_id":436},"action":"A","side":"B","price":"1.156670000","size":30,"channel_id":23,"order_id":"10998904121251269745","flags":0,"ts_in_delta":925,"sequence":187070,"symbol":"FCEU SI 20260615 PS"}
{"ts_recv":"2026-04-07T03:21:24.396507520Z","hd":{"ts_event":"2026-04-07T03:21:24.396487727Z","rtype":160,"publisher_id":101,"instrument_id":436},"action":"C","side":"A","price":"1.156780000","size":30,"channel_id":23,"order_id":"1775532084396410934","flags":0,"ts_in_delta":925,"sequence":187070,"symbol":"FCEU SI 20260615 PS"}
{"ts_recv":"2026-04-07T03:21:24.396507520Z","hd":{"ts_event":"2026-04-07T03:21:24.396487727Z","rtype":160,"publisher_id":101,"instrument_id":436},"action":"A","side":"A","price":"1.156770000","size":30,"channel_id":23,"order_id":"1775532084396493937","flags":128,"ts_in_delta":925,"sequence":187070,"symbol":"FCEU SI 20260615 PS"}
{"ts_recv":"2026-04-07T03:21:24.396566991Z","hd":{"ts_event":"2026-04-07T03:21:24.396547921Z","rtype":160,"publisher_id":101,"instrument_id":436},"action":"C","side":"B","price":"1.156670000","size":30,"channel_id":23,"order_id":"10998904121251269745","flags":0,"ts_in_delta":912,"sequence":187072,"symbol":"FCEU SI 20260615 PS"}
{"ts_recv":"2026-04-07T03:21:24.396566991Z","hd":{"ts_event":"2026-04-07T03:21:24.396547921Z","rtype":160,"publisher_id":101,"instrument_id":436},"action":"A","side":"B","price":"1.156680000","size":30,"channel_id":23,"order_id":"10998904121251329766","flags":0,"ts_in_delta":912,"sequence":187072,"symbol":"FCEU SI 20260615 PS"}
{"ts_recv":"2026-04-07T03:21:24.396566991Z","hd":{"ts_event":"2026-04-07T03:21:24.396547921Z","rtype":160,"publisher_id":101,"instrument_id":436},"action":"C","side":"A","price":"1.156770000","size":30,"channel_id":23,"order_id":"1775532084396493937","flags":0,"ts_in_delta":912,"sequence":187072,"symbol":"FCEU SI 20260615 PS"}
{"ts_recv":"2026-04-07T03:21:24.396566991Z","hd":{"ts_event":"2026-04-07T03:21:24.396547921Z","rtype":160,"publisher_id":101,"instrument_id":436},"action":"A","side":"A","price":"1.156780000","size":30,"channel_id":23,"order_id":"1775532084396553958","flags":128,"ts_in_delta":912,"sequence":187072,"symbol":"FCEU SI 20260615 PS"}
{"ts_recv":"2026-04-07T03:21:25.200478684Z","hd":{"ts_event":"2026-04-07T03:21:25.200448135Z","rtype":160,"publisher_id":101,"instrument_id":436},"action":"C","side":"B","price":"1.156680000","size":30,"channel_id":23,"order_id":"10998904121251329766","flags":0,"ts_in_delta":1300,"sequence":187092,"symbol":"FCEU SI 20260615 PS"}
{"ts_recv":"2026-04-07T03:21:25.200478684Z","hd":{"ts_event":"2026-04-07T03:21:25.200448135Z","rtype":160,"publisher_id":101,"instrument_id":436},"action":"A","side":"B","price":"1.156670000","size":30,"channel_id":23,"order_id":"10998904122055237545","flags":0,"ts_in_delta":1300,"sequence":187092,"symbol":"FCEU SI 20260615 PS"}
{"ts_recv":"2026-04-07T03:21:25.200478684Z","hd":{"ts_event":"2026-04-07T03:21:25.200448135Z","rtype":160,"publisher_id":101,"instrument_id":436},"action":"C","side":"A","price":"1.156780000","size":30,"channel_id":23,"order_id":"1775532084396553958","flags":0,"ts_in_delta":1300,"sequence":187092,"symbol":"FCEU SI 20260615 PS"}
{"ts_recv":"2026-04-07T03:21:25.200478684Z","hd":{"ts_event":"2026-04-07T03:21:25.200448135Z","rtype":160,"publisher_id":101,"instrument_id":436},"action":"A","side":"A","price":"1.156770000","size":30,"channel_id":23,"order_id":"1775532085200461737","flags":128,"ts_in_delta":1300,"sequence":187092,"symbol":"FCEU SI 20260615 PS"}
{"ts_recv":"2026-04-07T03:21:25.200543623Z","hd":{"ts_event":"2026-04-07T03:21:25.200525545Z","rtype":160,"publisher_id":101,"instrument_id":436},"action":"C","side":"B","price":"1.156670000","size":30,"channel_id":23,"order_id":"10998904122055237545","flags":0,"ts_in_delta":916,"sequence":187093,"symbol":"FCEU SI 20260615 PS"}
{"ts_recv":"2026-04-07T03:21:25.200543623Z","hd":{"ts_event":"2026-04-07T03:21:25.200525545Z","rtype":160,"publisher_id":101,"instrument_id":436},"action":"A","side":"B","price":"1.156660000","size":30,"channel_id":23,"order_id":"10998904122055307588","flags":0,"ts_in_delta":916,"sequence":187093,"symbol":"FCEU SI 20260615 PS"}
{"ts_recv":"2026-04-07T03:21:25.200543623Z","hd":{"ts_event":"2026-04-07T03:21:25.200525545Z","rtype":160,"publisher_id":101,"instrument_id":436},"action":"C","side":"A","price":"1.156770000","size":30,"channel_id":23,"order_id":"1775532085200461737","flags":0,"ts_in_delta":916,"sequence":187093,"symbol":"FCEU SI 20260615 PS"}
{"ts_recv":"2026-04-07T03:21:25.200543623Z","hd":{"ts_event":"2026-04-07T03:21:25.200525545Z","rtype":160,"publisher_id":101,"instrument_id":436},"action":"A","side":"A","price":"1.156760000","size":30,"channel_id":23,"order_id":"1775532085200531780","flags":128,"ts_in_delta":916,"sequence":187093,"symbol":"FCEU SI 20260615 PS"}
{"ts_recv":"2026-04-07T03:21:25.200606557Z","hd":{"ts_event":"2026-04-07T03:21:25.200583753Z","rtype":160,"publisher_id":101,"instrument_id":436},"action":"C","side":"B","price":"1.156680000","size":30,"channel_id":23,"order_id":"10998904121251243528","flags":0,"ts_in_delta":887,"sequence":187095,"symbol":"FCEU SI 20260615 PS"}
{"ts_recv":"2026-04-07T03:21:25.200606557Z","hd":{"ts_event":"2026-04-07T03:21:25.200583753Z","rtype":160,"publisher_id":101,"instrument_id":436},"action":"A","side":"B","price":"1.156660000","size":30,"channel_id":23,"order_id":"10998904122055369770","flags":0,"ts_in_delta":887,"sequence":187095,"symbol":"FCEU SI 20260615 PS"}
{"ts_recv":"2026-04-07T03:21:25.200606557Z","hd":{"ts_event":"2026-04-07T03:21:25.200583753Z","rtype":160,"publisher_id":101,"instrument_id":436},"action":"C","side":"A","price":"1.156780000","size":30,"channel_id":23,"order_id":"1775532084396467720","flags":0,"ts_in_delta":887,"sequence":187095,"symbol":"FCEU SI 20260615 PS"}
{"ts_recv":"2026-04-07T03:21:25.200606557Z","hd":{"ts_event":"2026-04-07T03:21:25.200583753Z","rtype":160,"publisher_id":101,"instrument_id":436},"action":"A","side":"A","price":"1.156760000","size":30,"channel_id":23,"order_id":"1775532085200593962","flags":128,"ts_in_delta":887,"sequence":187095,"symbol":"FCEU SI 20260615 PS"}
{"ts_recv":"2026-04-07T03:21:25.200640563Z","hd":{"ts_event":"2026-04-07T03:21:25.200622901Z","rtype":160,"publisher_id":101,"instrument_id":436},"action":"C","side":"B","price":"1.156660000","size":30,"channel_id":23,"order_id":"10998904122055307588","flags":0,"ts_in_delta":985,"sequence":187096,"symbol":"FCEU SI 20260615 PS"}
{"ts_recv":"2026-04-07T03:21:25.200640563Z","hd":{"ts_event":"2026-04-07T03:21:25.200622901Z","rtype":160,"publisher_id":101,"instrument_id":436},"action":"A","side":"B","price":"1.156670000","size":30,"channel_id":23,"order_id":"10998904122055404692","flags":0,"ts_in_delta":985,"sequence":187096,"symbol":"FCEU SI 20260615 PS"}
{"ts_recv":"2026-04-07T03:21:25.200640563Z","hd":{"ts_event":"2026-04-07T03:21:25.200622901Z","rtype":160,"publisher_id":101,"instrument_id":436},"action":"C","side":"A","price":"1.156760000","size":30,"channel_id":23,"order_id":"1775532085200531780","flags":0,"ts_in_delta":985,"sequence":187096,"symbol":"FCEU SI 20260615 PS"}
{"ts_recv":"2026-04-07T03:21:25.200640563Z","hd":{"ts_event":"2026-04-07T03:21:25.200622901Z","rtype":160,"publisher_id":101,"instrument_id":436},"action":"A","side":"A","price":"1.156770000","size":30,"channel_id":23,"order_id":"1775532085200628884","flags":128,"ts_in_delta":985,"sequence":187096,"symbol":"FCEU SI 20260615 PS"}
{"ts_recv":"2026-04-07T03:21:25.200695342Z","hd":{"ts_event":"2026-04-07T03:21:25.200679767Z","rtype":160,"publisher_id":101,"instrument_id":436},"action":"C","side":"B","price":"1.156670000","size":30,"channel_id":23,"order_id":"10998904122055404692","flags":0,"ts_in_delta":935,"sequence":187097,"symbol":"FCEU SI 20260615 PS"}
{"ts_recv":"2026-04-07T03:21:25.200695342Z","hd":{"ts_event":"2026-04-07T03:21:25.200679767Z","rtype":160,"publisher_id":101,"instrument_id":436},"action":"A","side":"B","price":"1.156660000","size":30,"channel_id":23,"order_id":"10998904122055461518","flags":0,"ts_in_delta":935,"sequence":187097,"symbol":"FCEU SI 20260615 PS"}
{"ts_recv":"2026-04-07T03:21:25.200695342Z","hd":{"ts_event":"2026-04-07T03:21:25.200679767Z","rtype":160,"publisher_id":101,"instrument_id":436},"action":"C","side":"A","price":"1.156770000","size":30,"channel_id":23,"order_id":"1775532085200628884","flags":0,"ts_in_delta":935,"sequence":187097,"symbol":"FCEU SI 20260615 PS"}
{"ts_recv":"2026-04-07T03:21:25.200695342Z","hd":{"ts_event":"2026-04-07T03:21:25.200679767Z","rtype":160,"publisher_id":101,"instrument_id":436},"action":"A","side":"A","price":"1.156760000","size":30,"channel_id":23,"order_id":"1775532085200685710","flags":128,"ts_in_delta":935,"sequence":187097,"symbol":"FCEU SI 20260615 PS"}
{"ts_recv":"2026-04-07T03:21:31.856756107Z","hd":{"ts_event":"2026-04-07T03:21:31.856735555Z","rtype":160,"publisher_id":101,"instrument_id":436},"action":"C","side":"B","price":"1.156660000","size":30,"channel_id":23,"order_id":"10998904122055461518","flags":0,"ts_in_delta":899,"sequence":187185,"symbol":"FCEU SI 20260615 PS"}
{"ts_recv":"2026-04-07T03:21:31.856756107Z","hd":{"ts_event":"2026-04-07T03:21:31.856735555Z","rtype":160,"publisher_id":101,"instrument_id":436},"action":"A","side":"B","price":"1.156670000","size":30,"channel_id":23,"order_id":"10998904128711517346","flags":0,"ts_in_delta":899,"sequence":187185,"symbol":"FCEU SI 20260615 PS"}
{"ts_recv":"2026-04-07T03:21:31.856756107Z","hd":{"ts_event":"2026-04-07T03:21:31.856735555Z","rtype":160,"publisher_id":101,"instrument_id":436},"action":"C","side":"A","price":"1.156760000","size":30,"channel_id":23,"order_id":"1775532085200685710","flags":0,"ts_in_delta":899,"sequence":187185,"symbol":"FCEU SI 20260615 PS"}
{"ts_recv":"2026-04-07T03:21:31.856756107Z","hd":{"ts_event":"2026-04-07T03:21:31.856735555Z","rtype":160,"publisher_id":101,"instrument_id":436},"action":"A","side":"A","price":"1.156770000","size":30,"channel_id":23,"order_id":"1775532091856741538","flags":128,"ts_in_delta":899,"sequence":187185,"symbol":"FCEU SI 20260615 PS"}
{"ts_recv":"2026-04-07T03:21:31.856814995Z","hd":{"ts_event":"2026-04-07T03:21:31.856795957Z","rtype":160,"publisher_id":101,"instrument_id":436},"action":"C","side":"B","price":"1.156660000","size":30,"channel_id":23,"order_id":"10998904122055369770","flags":0,"ts_in_delta":1129,"sequence":187186,"symbol":"FCEU SI 20260615 PS"}
{"ts_recv":"2026-04-07T03:21:31.856814995Z","hd":{"ts_event":"2026-04-07T03:21:31.856795957Z","rtype":160,"publisher_id":101,"instrument_id":436},"action":"A","side":"B","price":"1.156680000","size":30,"channel_id":23,"order_id":"10998904128711577850","flags":0,"ts_in_delta":1129,"sequence":187186,"symbol":"FCEU SI 20260615 PS"}
{"ts_recv":"2026-04-07T03:21:31.856814995Z","hd":{"ts_event":"2026-04-07T03:21:31.856795957Z","rtype":160,"publisher_id":101,"instrument_id":436},"action":"C","side":"A","price":"1.156760000","size":30,"channel_id":23,"order_id":"1775532085200593962","flags":0,"ts_in_delta":1129,"sequence":187186,"symbol":"FCEU SI 20260615 PS"}
{"ts_recv":"2026-04-07T03:21:31.856814995Z","hd":{"ts_event":"2026-04-07T03:21:31.856795957Z","rtype":160,"publisher_id":101,"instrument_id":436},"action":"A","side":"A","price":"1.156780000","size":30,"channel_id":23,"order_id":"1775532091856802042","flags":128,"ts_in_delta":1129,"sequence":187186,"symbol":"FCEU SI 20260615 PS"}
{"ts_recv":"2026-04-07T03:21:31.856871763Z","hd":{"ts_event":"2026-04-07T03:21:31.856852041Z","rtype":160,"publisher_id":101,"instrument_id":436},"action":"C","side":"B","price":"1.156670000","size":30,"channel_id":23,"order_id":"10998904128711517346","flags":0,"ts_in_delta":876,"sequence":187187,"symbol":"FCEU SI 20260615 PS"}
{"ts_recv":"2026-04-07T03:21:31.856871763Z","hd":{"ts_event":"2026-04-07T03:21:31.856852041Z","rtype":160,"publisher_id":101,"instrument_id":436},"action":"A","side":"B","price":"1.156680000","size":30,"channel_id":23,"order_id":"10998904128711633883","flags":0,"ts_in_delta":876,"sequence":187187,"symbol":"FCEU SI 20260615 PS"}
{"ts_recv":"2026-04-07T03:21:31.856871763Z","hd":{"ts_event":"2026-04-07T03:21:31.856852041Z","rtype":160,"publisher_id":101,"instrument_id":436},"action":"C","side":"A","price":"1.156770000","size":30,"channel_id":23,"order_id":"1775532091856741538","flags":0,"ts_in_delta":876,"sequence":187187,"symbol":"FCEU SI 20260615 PS"}
{"ts_recv":"2026-04-07T03:21:31.856871763Z","hd":{"ts_event":"2026-04-07T03:21:31.856852041Z","rtype":160,"publisher_id":101,"instrument_id":436},"action":"A","side":"A","price":"1.156780000","size":30,"channel_id":23,"order_id":"1775532091856858075","flags":128,"ts_in_delta":876,"sequence":187187,"symbol":"FCEU SI 20260615 PS"}
{"ts_recv":"2026-04-07T03:21:32.010691593Z","hd":{"ts_event":"2026-04-07T03:21:32.010670553Z","rtype":160,"publisher_id":101,"instrument_id":436},"action":"C","side":"B","price":"1.156680000","size":30,"channel_id":23,"order_id":"10998904128711633883","flags":0,"ts_in_delta":1395,"sequence":187202,"symbol":"FCEU SI 20260615 PS"}
{"ts_recv":"2026-04-07T03:21:32.010691593Z","hd":{"ts_event":"2026-04-07T03:21:32.010670553Z","rtype":160,"publisher_id":101,"instrument_id":436},"action":"A","side":"B","price":"1.156670000","size":30,"channel_id":23,"order_id":"10998904128865452249","flags":0,"ts_in_delta":1395,"sequence":187202,"symbol":"FCEU SI 20260615 PS"}
{"ts_recv":"2026-04-07T03:21:32.010691593Z","hd":{"ts_event":"2026-04-07T03:21:32.010670553Z","rtype":160,"publisher_id":101,"instrument_id":436},"action":"C","side":"A","price":"1.156780000","size":30,"channel_id":23,"order_id":"1775532091856858075","flags":0,"ts_in_delta":1395,"sequence":187202,"symbol":"FCEU SI 20260615 PS"}
{"ts_recv":"2026-04-07T03:21:32.010691593Z","hd":{"ts_event":"2026-04-07T03:21:32.010670553Z","rtype":160,"publisher_id":101,"instrument_id":436},"action":"A","side":"A","price":"1.156770000","size":30,"channel_id":23,"order_id":"1775532092010676441","flags":128,"ts_in_delta":1395,"sequence":187202,"symbol":"FCEU SI 20260615 PS"}
{"ts_recv":"2026-04-07T03:21:32.010774633Z","hd":{"ts_event":"2026-04-07T03:21:32.010754093Z","rtype":160,"publisher_id":101,"instrument_id":436},"action":"C","side":"B","price":"1.156670000","size":30,"channel_id":23,"order_id":"10998904128865452249","flags":0,"ts_in_delta":1091,"sequence":187203,"symbol":"FCEU SI 20260615 PS"}
{"ts_recv":"2026-04-07T03:21:32.010774633Z","hd":{"ts_event":"2026-04-07T03:21:32.010754093Z","rtype":160,"publisher_id":101,"instrument_id":436},"action":"A","side":"B","price":"1.156660000","size":30,"channel_id":23,"order_id":"10998904128865535958","flags":0,"ts_in_delta":1091,"sequence":187203,"symbol":"FCEU SI 20260615 PS"}
{"ts_recv":"2026-04-07T03:21:32.010774633Z","hd":{"ts_event":"2026-04-07T03:21:32.010754093Z","rtype":160,"publisher_id":101,"instrument_id":436},"action":"C","side":"A","price":"1.156770000","size":30,"channel_id":23,"order_id":"1775532092010676441","flags":0,"ts_in_delta":1091,"sequence":187203,"symbol":"FCEU SI 20260615 PS"}
{"ts_recv":"2026-04-07T03:21:32.010774633Z","hd":{"ts_event":"2026-04-07T03:21:32.010754093Z","rtype":160,"publisher_id":101,"instrument_id":436},"action":"A","side":"A","price":"1.156760000","size":30,"channel_id":23,"order_id":"1775532092010760150","flags":128,"ts_in_delta":1091,"sequence":187203,"symbol":"FCEU SI 20260615 PS"}
{"ts_recv":"2026-04-07T03:21:32.010827646Z","hd":{"ts_event":"2026-04-07T03:21:32.010810983Z","rtype":160,"publisher_id":101,"instrument_id":436},"action":"C","side":"B","price":"1.156680000","size":30,"channel_id":23,"order_id":"10998904128711577850","flags":0,"ts_in_delta":1082,"sequence":187204,"symbol":"FCEU SI 20260615 PS"}
{"ts_recv":"2026-04-07T03:21:32.010827646Z","hd":{"ts_event":"2026-04-07T03:21:32.010810983Z","rtype":160,"publisher_id":101,"instrument_id":436},"action":"A","side":"B","price":"1.156660000","size":30,"channel_id":23,"order_id":"10998904128865592665","flags":0,"ts_in_delta":1082,"sequence":187204,"symbol":"FCEU SI 20260615 PS"}
{"ts_recv":"2026-04-07T03:21:32.010827646Z","hd":{"ts_event":"2026-04-07T03:21:32.010810983Z","rtype":160,"publisher_id":101,"instrument_id":436},"action":"C","side":"A","price":"1.156780000","size":30,"channel_id":23,"order_id":"1775532091856802042","flags":0,"ts_in_delta":1082,"sequence":187204,"symbol":"FCEU SI 20260615 PS"}
{"ts_recv":"2026-04-07T03:21:32.010827646Z","hd":{"ts_event":"2026-04-07T03:21:32.010810983Z","rtype":160,"publisher_id":101,"instrument_id":436},"action":"A","side":"A","price":"1.156760000","size":30,"channel_id":23,"order_id":"1775532092010816857","flags":128,"ts_in_delta":1082,"sequence":187204,"symbol":"FCEU SI 20260615 PS"}
{"ts_recv":"2026-04-07T03:21:32.010838037Z","hd":{"ts_event":"2026-04-07T03:21:32.010812961Z","rtype":160,"publisher_id":101,"instrument_id":436},"action":"C","side":"B","price":"1.156660000","size":30,"channel_id":23,"order_id":"10998904128865535958","flags":0,"ts_in_delta":1098,"sequence":187205,"symbol":"FCEU SI 20260615 PS"}
{"ts_recv":"2026-04-07T03:21:32.010838037Z","hd":{"ts_event":"2026-04-07T03:21:32.010812961Z","rtype":160,"publisher_id":101,"instrument_id":436},"action":"A","side":"B","price":"1.156670000","size":30,"channel_id":23,"order_id":"10998904128865599959","flags":0,"ts_in_delta":1098,"sequence":187205,"symbol":"FCEU SI 20260615 PS"}
{"ts_recv":"2026-04-07T03:21:32.010838037Z","hd":{"ts_event":"2026-04-07T03:21:32.010812961Z","rtype":160,"publisher_id":101,"instrument_id":436},"action":"C","side":"A","price":"1.156760000","size":30,"channel_id":23,"order_id":"1775532092010760150","flags":0,"ts_in_delta":1098,"sequence":187205,"symbol":"FCEU SI 20260615 PS"}
{"ts_recv":"2026-04-07T03:21:32.010838037Z","hd":{"ts_event":"2026-04-07T03:21:32.010812961Z","rtype":160,"publisher_id":101,"instrument_id":436},"action":"A","side":"A","price":"1.156770000","size":30,"channel_id":23,"order_id":"1775532092010824151","flags":128,"ts_in_delta":1098,"sequence":187205,"symbol":"FCEU SI 20260615 PS"}
{"ts_recv":"2026-04-07T03:21:32.010891832Z","hd":{"ts_event":"2026-04-07T03:21:32.010873363Z","rtype":160,"publisher_id":101,"instrument_id":436},"action":"C","side":"B","price":"1.156670000","size":30,"channel_id":23,"order_id":"10998904128865599959","flags":0,"ts_in_delta":894,"sequence":187206,"symbol":"FCEU SI 20260615 PS"}
{"ts_recv":"2026-04-07T03:21:32.010891832Z","hd":{"ts_event":"2026-04-07T03:21:32.010873363Z","rtype":160,"publisher_id":101,"instrument_id":436},"action":"A","side":"B","price":"1.156660000","size":30,"channel_id":23,"order_id":"10998904128865655003","flags":0,"ts_in_delta":894,"sequence":187206,"symbol":"FCEU SI 20260615 PS"}
{"ts_recv":"2026-04-07T03:21:32.010891832Z","hd":{"ts_event":"2026-04-07T03:21:32.010873363Z","rtype":160,"publisher_id":101,"instrument_id":436},"action":"C","side":"A","price":"1.156770000","size":30,"channel_id":23,"order_id":"1775532092010824151","flags":0,"ts_in_delta":894,"sequence":187206,"symbol":"FCEU SI 20260615 PS"}
{"ts_recv":"2026-04-07T03:21:32.010891832Z","hd":{"ts_event":"2026-04-07T03:21:32.010873363Z","rtype":160,"publisher_id":101,"instrument_id":436},"action":"A","side":"A","price":"1.156760000","size":30,"channel_id":23,"order_id":"1775532092010879195","flags":128,"ts_in_delta":894,"sequence":187206,"symbol":"FCEU SI 20260615 PS"}
{"ts_recv":"2026-04-07T03:21:34.130928071Z","hd":{"ts_event":"2026-04-07T03:21:34.130905365Z","rtype":160,"publisher_id":101,"instrument_id":436},"action":"C","side":"B","price":"1.156660000","size":30,"channel_id":23,"order_id":"10998904128865655003","flags":0,"ts_in_delta":997,"sequence":187215,"symbol":"FCEU SI 20260615 PS"}
{"ts_recv":"2026-04-07T03:21:34.130928071Z","hd":{"ts_event":"2026-04-07T03:21:34.130905365Z","rtype":160,"publisher_id":101,"instrument_id":436},"action":"A","side":"B","price":"1.156670000","size":30,"channel_id":23,"order_id":"10998904130985687707","flags":0,"ts_in_delta":997,"sequence":187215,"symbol":"FCEU SI 20260615 PS"}
{"ts_recv":"2026-04-07T03:21:34.130928071Z","hd":{"ts_event":"2026-04-07T03:21:34.130905365Z","rtype":160,"publisher_id":101,"instrument_id":436},"action":"C","side":"A","price":"1.156760000","size":30,"channel_id":23,"order_id":"1775532092010879195","flags":0,"ts_in_delta":997,"sequence":187215,"symbol":"FCEU SI 20260615 PS"}
{"ts_recv":"2026-04-07T03:21:34.130928071Z","hd":{"ts_event":"2026-04-07T03:21:34.130905365Z","rtype":160,"publisher_id":101,"instrument_id":436},"action":"A","side":"A","price":"1.156770000","size":30,"channel_id":23,"order_id":"1775532094130911899","flags":128,"ts_in_delta":997,"sequence":187215,"symbol":"FCEU SI 20260615 PS"}
{"ts_recv":"2026-04-07T03:21:39.024909148Z","hd":{"ts_event":"2026-04-07T03:21:39.024888045Z","rtype":160,"publisher_id":101,"instrument_id":436},"action":"C","side":"B","price":"1.156660000","size":30,"channel_id":23,"order_id":"10998904128865592665","flags":0,"ts_in_delta":931,"sequence":187256,"symbol":"FCEU SI 20260615 PS"}
{"ts_recv":"2026-04-07T03:21:39.024909148Z","hd":{"ts_event":"2026-04-07T03:21:39.024888045Z","rtype":160,"publisher_id":101,"instrument_id":436},"action":"A","side":"B","price":"1.156680000","size":30,"channel_id":23,"order_id":"10998904135879669796","flags":0,"ts_in_delta":931,"sequence":187256,"symbol":"FCEU SI 20260615 PS"}
{"ts_recv":"2026-04-07T03:21:39.024909148Z","hd":{"ts_event":"2026-04-07T03:21:39.024888045Z","rtype":160,"publisher_id":101,"instrument_id":436},"action":"C","side":"A","price":"1.156760000","size":30,"channel_id":23,"order_id":"1775532092010816857","flags":0,"ts_in_delta":931,"sequence":187256,"symbol":"FCEU SI 20260615 PS"}
