{"ts_recv":"2026-04-07T03:03:57.699349249Z","hd":{"ts_event":"2026-04-07T03:03:57.699328775Z","rtype":160,"publisher_id":101,"instrument_id":436},"action":"A","side":"A","price":"1.156850000","size":30,"channel_id":23,"order_id":"1775531037699334856","flags":128,"ts_in_delta":1612,"sequence":179613,"symbol":"FCEU SI 20260615 PS"}
{"ts_recv":"2026-04-07T03:04:53.585461125Z","hd":{"ts_event":"2026-04-07T03:04:53.585434033Z","rtype":160,"publisher_id":101,"instrument_id":436},"action":"C","side":"B","price":"1.156750000","size":30,"channel_id":23,"order_id":"10998903074554110664","flags":0,"ts_in_delta":1116,"sequence":179897,"symbol":"FCEU SI 20260615 PS"}
{"ts_recv":"2026-04-07T03:04:53.585461125Z","hd":{"ts_event":"2026-04-07T03:04:53.585434033Z","rtype":160,"publisher_id":101,"instrument_id":436},"action":"A","side":"B","price":"1.156760000","size":30,"channel_id":23,"order_id":"10998903130440216391","flags":0,"ts_in_delta":1116,"sequence":179897,"symbol":"FCEU SI 20260615 PS"}
{"ts_recv":"2026-04-07T03:04:53.585461125Z","hd":{"ts_event":"2026-04-07T03:04:53.585434033Z","rtype":160,"publisher_id":101,"instrument_id":436},"action":"C","side":"A","price":"1.156850000","size":30,"channel_id":23,"order_id":"1775531037699334856","flags":0,"ts_in_delta":1116,"sequence":179897,"symbol":"FCEU SI 20260615 PS"}
{"ts_recv":"2026-04-07T03:04:53.585461125Z","hd":{"ts_event":"2026-04-07T03:04:53.585434033Z","rtype":160,"publisher_id":101,"instrument_id":436},"action":"A","side":"A","price":"1.156860000","size":30,"channel_id":23,"order_id":"1775531093585440583","flags":128,"ts_in_delta":1116,"sequence":179897,"symbol":"FCEU SI 20260615 PS"}
{"ts_recv":"2026-04-07T03:04:53.585532507Z","hd":{"ts_event":"2026-04-07T03:04:53.585513021Z","rtype":160,"publisher_id":101,"instrument_id":436},"action":"C","side":"B","price":"1.156750000","size":30,"channel_id":23,"order_id":"10998903074554041314","flags":0,"ts_in_delta":938,"sequence":179898,"symbol":"FCEU SI 20260615 PS"}
{"ts_recv":"2026-04-07T03:04:53.585532507Z","hd":{"ts_event":"2026-04-07T03:04:53.585513021Z","rtype":160,"publisher_id":101,"instrument_id":436},"action":"A","side":"B","price":"1.156770000","size":30,"channel_id":23,"order_id":"10998903130440295337","flags":0,"ts_in_delta":938,"sequence":179898,"symbol":"FCEU SI 20260615 PS"}
{"ts_recv":"2026-04-07T03:04:53.585532507Z","hd":{"ts_event":"2026-04-07T03:04:53.585513021Z","rtype":160,"publisher_id":101,"instrument_id":436},"action":"C","side":"A","price":"1.156850000","size":30,"channel_id":23,"order_id":"1775531037699265506","flags":0,"ts_in_delta":938,"sequence":179898,"symbol":"FCEU SI 20260615 PS"}
{"ts_recv":"2026-04-07T03:04:53.585532507Z","hd":{"ts_event":"2026-04-07T03:04:53.585513021Z","rtype":160,"publisher_id":101,"instrument_id":436},"action":"A","side":"A","price":"1.156870000","size":30,"channel_id":23,"order_id":"1775531093585519529","flags":128,"ts_in_delta":938,"sequence":179898,"symbol":"FCEU SI 20260615 PS"}
{"ts_recv":"2026-04-07T03:04:53.585594297Z","hd":{"ts_event":"2026-04-07T03:04:53.585578419Z","rtype":160,"publisher_id":101,"instrument_id":436},"action":"C","side":"B","price":"1.156760000","size":30,"channel_id":23,"order_id":"10998903130440216391","flags":0,"ts_in_delta":992,"sequence":179899,"symbol":"FCEU SI 20260615 PS"}
{"ts_recv":"2026-04-07T03:04:53.585594297Z","hd":{"ts_event":"2026-04-07T03:04:53.585578419Z","rtype":160,"publisher_id":101,"instrument_id":436},"action":"A","side":"B","price":"1.156770000","size":30,"channel_id":23,"order_id":"10998903130440360265","flags":0,"ts_in_delta":992,"sequence":179899,"symbol":"FCEU SI 20260615 PS"}
{"ts_recv":"2026-04-07T03:04:53.585594297Z","hd":{"ts_event":"2026-04-07T03:04:53.585578419Z","rtype":160,"publisher_id":101,"instrument_id":436},"action":"C","side":"A","price":"1.156860000","size":30,"channel_id":23,"order_id":"1775531093585440583","flags":0,"ts_in_delta":992,"sequence":179899,"symbol":"FCEU SI 20260615 PS"}
{"ts_recv":"2026-04-07T03:04:53.585594297Z","hd":{"ts_event":"2026-04-07T03:04:53.585578419Z","rtype":160,"publisher_id":101,"instrument_id":436},"action":"A","side":"A","price":"1.156870000","size":30,"channel_id":23,"order_id":"1775531093585584457","flags":128,"ts_in_delta":992,"sequence":179899,"symbol":"FCEU SI 20260615 PS"}
{"ts_recv":"2026-04-07T03:05:00.189053319Z","hd":{"ts_event":"2026-04-07T03:05:00.189019209Z","rtype":160,"publisher_id":101,"instrument_id":436},"action":"C","side":"B","price":"1.156770000","size":30,"channel_id":23,"order_id":"10998903130440360265","flags":0,"ts_in_delta":1484,"sequence":179970,"symbol":"FCEU SI 20260615 PS"}
{"ts_recv":"2026-04-07T03:05:00.189053319Z","hd":{"ts_event":"2026-04-07T03:05:00.189019209Z","rtype":160,"publisher_id":101,"instrument_id":436},"action":"A","side":"B","price":"1.156760000","size":30,"channel_id":23,"order_id":"10998903137043808577","flags":0,"ts_in_delta":1484,"sequence":179970,"symbol":"FCEU SI 20260615 PS"}
{"ts_recv":"2026-04-07T03:05:00.189053319Z","hd":{"ts_event":"2026-04-07T03:05:00.189019209Z","rtype":160,"publisher_id":101,"instrument_id":436},"action":"C","side":"A","price":"1.156870000","size":30,"channel_id":23,"order_id":"1775531093585584457","flags":0,"ts_in_delta":1484,"sequence":179970,"symbol":"FCEU SI 20260615 PS"}
{"ts_recv":"2026-04-07T03:05:00.189053319Z","hd":{"ts_event":"2026-04-07T03:05:00.189019209Z","rtype":160,"publisher_id":101,"instrument_id":436},"action":"A","side":"A","price":"1.156860000","size":30,"channel_id":23,"order_id":"1775531100189032769","flags":128,"ts_in_delta":1484,"sequence":179970,"symbol":"FCEU SI 20260615 PS"}
{"ts_recv":"2026-04-07T03:05:00.189124195Z","hd":{"ts_event":"2026-04-07T03:05:00.189104907Z","rtype":160,"publisher_id":101,"instrument_id":436},"action":"C","side":"B","price":"1.156770000","size":30,"channel_id":23,"order_id":"10998903130440295337","flags":0,"ts_in_delta":1002,"sequence":179971,"symbol":"FCEU SI 20260615 PS"}
{"ts_recv":"2026-04-07T03:05:00.189124195Z","hd":{"ts_event":"2026-04-07T03:05:00.189104907Z","rtype":160,"publisher_id":101,"instrument_id":436},"action":"A","side":"B","price":"1.156750000","size":30,"channel_id":23,"order_id":"10998903137043887304","flags":0,"ts_in_delta":1002,"sequence":179971,"symbol":"FCEU SI 20260615 PS"}
{"ts_recv":"2026-04-07T03:05:00.189124195Z","hd":{"ts_event":"2026-04-07T03:05:00.189104907Z","rtype":160,"publisher_id":101,"instrument_id":436},"action":"C","side":"A","price":"1.156870000","size":30,"channel_id":23,"order_id":"1775531093585519529","flags":0,"ts_in_delta":1002,"sequence":179971,"symbol":"FCEU SI 20260615 PS"}
{"ts_recv":"2026-04-07T03:05:00.189124195Z","hd":{"ts_event":"2026-04-07T03:05:00.189104907Z","rtype":160,"publisher_id":101,"instrument_id":436},"action":"A","side":"A","price":"1.156850000","size":30,"channel_id":23,"order_id":"1775531100189111496","flags":128,"ts_in_delta":1002,"sequence":179971,"symbol":"FCEU SI 20260615 PS"}
{"ts_recv":"2026-04-07T03:05:00.189189526Z","hd":{"ts_event":"2026-04-07T03:05:00.189168111Z","rtype":160,"publisher_id":101,"instrument_id":436},"action":"C","side":"B","price":"1.156760000","size":30,"channel_id":23,"order_id":"10998903137043808577","flags":0,"ts_in_delta":950,"sequence":179972,"symbol":"FCEU SI 20260615 PS"}
{"ts_recv":"2026-04-07T03:05:00.189189526Z","hd":{"ts_event":"2026-04-07T03:05:00.189168111Z","rtype":160,"publisher_id":101,"instrument_id":436},"action":"A","side":"B","price":"1.156750000","size":30,"channel_id":23,"order_id":"10998903137043949804","flags":0,"ts_in_delta":950,"sequence":179972,"symbol":"FCEU SI 20260615 PS"}
{"ts_recv":"2026-04-07T03:05:00.189189526Z","hd":{"ts_event":"2026-04-07T03:05:00.189168111Z","rtype":160,"publisher_id":101,"instrument_id":436},"action":"C","side":"A","price":"1.156860000","size":30,"channel_id":23,"order_id":"1775531100189032769","flags":0,"ts_in_delta":950,"sequence":179972,"symbol":"FCEU SI 20260615 PS"}
{"ts_recv":"2026-04-07T03:05:00.189189526Z","hd":{"ts_event":"2026-04-07T03:05:00.189168111Z","rtype":160,"publisher_id":101,"instrument_id":436},"action":"A","side":"A","price":"1.156850000","size":30,"channel_id":23,"order_id":"1775531100189173996","flags":128,"ts_in_delta":950,"sequence":179972,"symbol":"FCEU SI 20260615 PS"}
{"ts_recv":"2026-04-07T03:05:00.204318548Z","hd":{"ts_event":"2026-04-07T03:05:00.204303327Z","rtype":160,"publisher_id":101,"instrument_id":436},"action":"C","side":"B","price":"1.156700000","size":20,"channel_id":23,"order_id":"10998902992819142637","flags":128,"ts_in_delta":902,"sequence":179980,"symbol":"FCEU SI 20260615 PS"}
{"ts_recv":"2026-04-07T03:05:00.267165135Z","hd":{"ts_event":"2026-04-07T03:05:00.267149641Z","rtype":160,"publisher_id":101,"instrument_id":436},"action":"A","side":"B","price":"1.156600000","size":20,"channel_id":23,"order_id":"10998903137121931343","flags":128,"ts_in_delta":1009,"sequence":179994,"symbol":"FCEU SI 20260615 PS"}
{"ts_recv":"2026-04-07T03:05:00.296180099Z","hd":{"ts_event":"2026-04-07T03:05:00.296156691Z","rtype":160,"publisher_id":101,"instrument_id":436},"action":"C","side":"B","price":"1.156750000","size":30,"channel_id":23,"order_id":"10998903137043887304","flags":0,"ts_in_delta":1127,"sequence":180001,"symbol":"FCEU SI 20260615 PS"}
{"ts_recv":"2026-04-07T03:05:00.296180099Z","hd":{"ts_event":"2026-04-07T03:05:00.296156691Z","rtype":160,"publisher_id":101,"instrument_id":436},"action":"A","side":"B","price":"1.156730000","size":30,"channel_id":23,"order_id":"10998903137150938849","flags":0,"ts_in_delta":1127,"sequence":180001,"symbol":"FCEU SI 20260615 PS"}
{"ts_recv":"2026-04-07T03:05:00.296180099Z","hd":{"ts_event":"2026-04-07T03:05:00.296156691Z","rtype":160,"publisher_id":101,"instrument_id":436},"action":"C","side":"A","price":"1.156850000","size":30,"channel_id":23,"order_id":"1775531100189111496","flags":0,"ts_in_delta":1127,"sequence":180001,"symbol":"FCEU SI 20260615 PS"}
{"ts_recv":"2026-04-07T03:05:00.296180099Z","hd":{"ts_event":"2026-04-07T03:05:00.296156691Z","rtype":160,"publisher_id":101,"instrument_id":436},"action":"A","side":"A","price":"1.156830000","size":30,"channel_id":23,"order_id":"1775531100296163041","flags":128,"ts_in_delta":1127,"sequence":180001,"symbol":"FCEU SI 20260615 PS"}
{"ts_recv":"2026-04-07T03:05:00.296239355Z","hd":{"ts_event":"2026-04-07T03:05:00.296221439Z","rtype":160,"publisher_id":101,"instrument_id":436},"action":"C","side":"B","price":"1.156750000","size":30,"channel_id":23,"order_id":"10998903137043949804","flags":0,"ts_in_delta":1113,"sequence":180002,"symbol":"FCEU SI 20260615 PS"}
{"ts_recv":"2026-04-07T03:05:00.296239355Z","hd":{"ts_event":"2026-04-07T03:05:00.296221439Z","rtype":160,"publisher_id":101,"instrument_id":436},"action":"A","side":"B","price":"1.156740000","size":30,"channel_id":23,"order_id":"10998903137151003366","flags":0,"ts_in_delta":1113,"sequence":180002,"symbol":"FCEU SI 20260615 PS"}
{"ts_recv":"2026-04-07T03:05:00.296239355Z","hd":{"ts_event":"2026-04-07T03:05:00.296221439Z","rtype":160,"publisher_id":101,"instrument_id":436},"action":"C","side":"A","price":"1.156850000","size":30,"channel_id":23,"order_id":"1775531100189173996","flags":0,"ts_in_delta":1113,"sequence":180002,"symbol":"FCEU SI 20260615 PS"}
{"ts_recv":"2026-04-07T03:05:00.296239355Z","hd":{"ts_event":"2026-04-07T03:05:00.296221439Z","rtype":160,"publisher_id":101,"instrument_id":436},"action":"A","side":"A","price":"1.156840000","size":30,"channel_id":23,"order_id":"1775531100296227558","flags":128,"ts_in_delta":1113,"sequence":180002,"symbol":"FCEU SI 20260615 PS"}
{"ts_recv":"2026-04-07T03:05:00.298695552Z","hd":{"ts_event":"2026-04-07T03:05:00.298677989Z","rtype":160,"publisher_id":101,"instrument_id":436},"action":"C","side":"B","price":"1.156740000","size":30,"channel_id":23,"order_id":"10998903137151003366","flags":0,"ts_in_delta":1063,"sequence":180003,"symbol":"FCEU SI 20260615 PS"}
{"ts_recv":"2026-04-07T03:05:00.298695552Z","hd":{"ts_event":"2026-04-07T03:05:00.298677989Z","rtype":160,"publisher_id":101,"instrument_id":436},"action":"A","side":"B","price":"1.156730000","size":30,"channel_id":23,"order_id":"10998903137153459588","flags":0,"ts_in_delta":1063,"sequence":180003,"symbol":"FCEU SI 20260615 PS"}
{"ts_recv":"2026-04-07T03:05:00.298695552Z","hd":{"ts_event":"2026-04-07T03:05:00.298677989Z","rtype":160,"publisher_id":101,"instrument_id":436},"action":"C","side":"A","price":"1.156840000","size":30,"channel_id":23,"order_id":"1775531100296227558","flags":0,"ts_in_delta":1063,"sequence":180003,"symbol":"FCEU SI 20260615 PS"}
{"ts_recv":"2026-04-07T03:05:00.298695552Z","hd":{"ts_event":"2026-04-07T03:05:00.298677989Z","rtype":160,"publisher_id":101,"instrument_id":436},"action":"A","side":"A","price":"1.156830000","size":30,"channel_id":23,"order_id":"1775531100298683780","flags":128,"ts_in_delta":1063,"sequence":180003,"symbol":"FCEU SI 20260615 PS"}
{"ts_recv":"2026-04-07T03:05:00.307273573Z","hd":{"ts_event":"2026-04-07T03:05:00.307252407Z","rtype":160,"publisher_id":101,"instrument_id":436},"action":"C","side":"B","price":"1.156730000","size":30,"channel_id":23,"order_id":"10998903137153459588","flags":0,"ts_in_delta":973,"sequence":180010,"symbol":"FCEU SI 20260615 PS"}
{"ts_recv":"2026-04-07T03:05:00.307273573Z","hd":{"ts_event":"2026-04-07T03:05:00.307252407Z","rtype":160,"publisher_id":101,"instrument_id":436},"action":"A","side":"B","price":"1.156720000","size":30,"channel_id":23,"order_id":"10998903137162034315","flags":0,"ts_in_delta":973,"sequence":180010,"symbol":"FCEU SI 20260615 PS"}
{"ts_recv":"2026-04-07T03:05:00.307273573Z","hd":{"ts_event":"2026-04-07T03:05:00.307252407Z","rtype":160,"publisher_id":101,"instrument_id":436},"action":"C","side":"A","price":"1.156830000","size":30,"channel_id":23,"order_id":"1775531100298683780","flags":0,"ts_in_delta":973,"sequence":180010,"symbol":"FCEU SI 20260615 PS"}
{"ts_recv":"2026-04-07T03:05:00.307273573Z","hd":{"ts_event":"2026-04-07T03:05:00.307252407Z","rtype":160,"publisher_id":101,"instrument_id":436},"action":"A","side":"A","price":"1.156820000","size":30,"channel_id":23,"order_id":"1775531100307258507","flags":128,"ts_in_delta":973,"sequence":180010,"symbol":"FCEU SI 20260615 PS"}
{"ts_recv":"2026-04-07T03:05:00.323241267Z","hd":{"ts_event":"2026-04-07T03:05:00.323219789Z","rtype":160,"publisher_id":101,"instrument_id":436},"action":"C","side":"B","price":"1.156730000","size":30,"channel_id":23,"order_id":"10998903137150938849","flags":0,"ts_in_delta":770,"sequence":180020,"symbol":"FCEU SI 20260615 PS"}
{"ts_recv":"2026-04-07T03:05:00.323241267Z","hd":{"ts_event":"2026-04-07T03:05:00.323219789Z","rtype":160,"publisher_id":101,"instrument_id":436},"action":"A","side":"B","price":"1.156710000","size":30,"channel_id":23,"order_id":"10998903137178001852","flags":0,"ts_in_delta":770,"sequence":180020,"symbol":"FCEU SI 20260615 PS"}
{"ts_recv":"2026-04-07T03:05:00.323241267Z","hd":{"ts_event":"2026-04-07T03:05:00.323219789Z","rtype":160,"publisher_id":101,"instrument_id":436},"action":"C","side":"A","price":"1.156830000","size":30,"channel_id":23,"order_id":"1775531100296163041","flags":0,"ts_in_delta":770,"sequence":180020,"symbol":"FCEU SI 20260615 PS"}
{"ts_recv":"2026-04-07T03:05:00.323241267Z","hd":{"ts_event":"2026-04-07T03:05:00.323219789Z","rtype":160,"publisher_id":101,"instrument_id":436},"action":"A","side":"A","price":"1.156810000","size":30,"channel_id":23,"order_id":"1775531100323226044","flags":128,"ts_in_delta":770,"sequence":180020,"symbol":"FCEU SI 20260615 PS"}
{"ts_recv":"2026-04-07T03:05:00.323300961Z","hd":{"ts_event":"2026-04-07T03:05:00.323282977Z","rtype":160,"publisher_id":101,"instrument_id":436},"action":"C","side":"B","price":"1.156720000","size":30,"channel_id":23,"order_id":"10998903137162034315","flags":0,"ts_in_delta":996,"sequence":180021,"symbol":"FCEU SI 20260615 PS"}
{"ts_recv":"2026-04-07T03:05:00.323300961Z","hd":{"ts_event":"2026-04-07T03:05:00.323282977Z","rtype":160,"publisher_id":101,"instrument_id":436},"action":"A","side":"B","price":"1.156710000","size":30,"channel_id":23,"order_id":"10998903137178064946","flags":0,"ts_in_delta":996,"sequence":180021,"symbol":"FCEU SI 20260615 PS"}
{"ts_recv":"2026-04-07T03:05:00.323300961Z","hd":{"ts_event":"2026-04-07T03:05:00.323282977Z","rtype":160,"publisher_id":101,"instrument_id":436},"action":"C","side":"A","price":"1.156820000","size":30,"channel_id":23,"order_id":"1775531100307258507","flags":0,"ts_in_delta":996,"sequence":180021,"symbol":"FCEU SI 20260615 PS"}
{"ts_recv":"2026-04-07T03:05:00.323300961Z","hd":{"ts_event":"2026-04-07T03:05:00.323282977Z","rtype":160,"publisher_id":101,"instrument_id":436},"action":"A","side":"A","price":"1.156810000","size":30,"channel_id":23,"order_id":"1775531100323289138","flags":128,"ts_in_delta":996,"sequence":180021,"symbol":"FCEU SI 20260615 PS"}
{"ts_recv":"2026-04-07T03:05:03.419131428Z","hd":{"ts_event":"2026-04-07T03:05:03.419110867Z","rtype":160,"publisher_id":101,"instrument_id":436},"action":"C","side":"B","price":"1.156710000","size":30,"channel_id":23,"order_id":"10998903137178001852","flags":0,"ts_in_delta":1090,"sequence":180081,"symbol":"FCEU SI 20260615 PS"}
{"ts_recv":"2026-04-07T03:05:03.419131428Z","hd":{"ts_event":"2026-04-07T03:05:03.419110867Z","rtype":160,"publisher_id":101,"instrument_id":436},"action":"A","side":"B","price":"1.156690000","size":30,"channel_id":23,"order_id":"10998903140273892851","flags":0,"ts_in_delta":1090,"sequence":180081,"symbol":"FCEU SI 20260615 PS"}
{"ts_recv":"2026-04-07T03:05:03.419131428Z","hd":{"ts_event":"2026-04-07T03:05:03.419110867Z","rtype":160,"publisher_id":101,"instrument_id":436},"action":"C","side":"A","price":"1.156810000","size":30,"channel_id":23,"order_id":"1775531100323226044","flags":0,"ts_in_delta":1090,"sequence":180081,"symbol":"FCEU SI 20260615 PS"}
{"ts_recv":"2026-04-07T03:05:03.419131428Z","hd":{"ts_event":"2026-04-07T03:05:03.419110867Z","rtype":160,"publisher_id":101,"instrument_id":436},"action":"A","side":"A","price":"1.156790000","size":30,"channel_id":23,"order_id":"1775531103419117043","flags":128,"ts_in_delta":1090,"sequence":180081,"symbol":"FCEU SI 20260615 PS"}
{"ts_recv":"2026-04-07T03:05:03.419212471Z","hd":{"ts_event":"2026-04-07T03:05:03.419192743Z","rtype":160,"publisher_id":101,"instrument_id":436},"action":"C","side":"B","price":"1.156710000","size":30,"channel_id":23,"order_id":"10998903137178064946","flags":0,"ts_in_delta":786,"sequence":180082,"symbol":"FCEU SI 20260615 PS"}
{"ts_recv":"2026-04-07T03:05:03.419212471Z","hd":{"ts_event":"2026-04-07T03:05:03.419192743Z","rtype":160,"publisher_id":101,"instrument_id":436},"action":"A","side":"B","price":"1.156700000","size":30,"channel_id":23,"order_id":"10998903140273975236","flags":0,"ts_in_delta":786,"sequence":180082,"symbol":"FCEU SI 20260615 PS"}
{"ts_recv":"2026-04-07T03:05:03.419212471Z","hd":{"ts_event":"2026-04-07T03:05:03.419192743Z","rtype":160,"publisher_id":101,"instrument_id":436},"action":"C","side":"A","price":"1.156810000","size":30,"channel_id":23,"order_id":"1775531100323289138","flags":0,"ts_in_delta":786,"sequence":180082,"symbol":"FCEU SI 20260615 PS"}
{"ts_recv":"2026-04-07T03:05:03.419212471Z","hd":{"ts_event":"2026-04-07T03:05:03.419192743Z","rtype":160,"publisher_id":101,"instrument_id":436},"action":"A","side":"A","price":"1.156800000","size":30,"channel_id":23,"order_id":"1775531103419199428","flags":128,"ts_in_delta":786,"sequence":180082,"symbol":"FCEU SI 20260615 PS"}
{"ts_recv":"2026-04-07T03:05:05.975559457Z","hd":{"ts_event":"2026-04-07T03:05:05.975530789Z","rtype":160,"publisher_id":101,"instrument_id":436},"action":"C","side":"B","price":"1.156690000","size":30,"channel_id":23,"order_id":"10998903140273892851","flags":0,"ts_in_delta":1452,"sequence":180124,"symbol":"FCEU SI 20260615 PS"}
{"ts_recv":"2026-04-07T03:05:05.975559457Z","hd":{"ts_event":"2026-04-07T03:05:05.975530789Z","rtype":160,"publisher_id":101,"instrument_id":436},"action":"A","side":"B","price":"1.156710000","size":30,"channel_id":23,"order_id":"10998903142830317559","flags":0,"ts_in_delta":1452,"sequence":180124,"symbol":"FCEU SI 20260615 PS"}
{"ts_recv":"2026-04-07T03:05:05.975559457Z","hd":{"ts_event":"2026-04-07T03:05:05.975530789Z","rtype":160,"publisher_id":101,"instrument_id":436},"action":"C","side":"A","price":"1.156790000","size":30,"channel_id":23,"order_id":"1775531103419117043","flags":0,"ts_in_delta":1452,"sequence":180124,"symbol":"FCEU SI 20260615 PS"}
{"ts_recv":"2026-04-07T03:05:05.975559457Z","hd":{"ts_event":"2026-04-07T03:05:05.975530789Z","rtype":160,"publisher_id":101,"instrument_id":436},"action":"A","side":"A","price":"1.156810000","size":30,"channel_id":23,"order_id":"1775531105975541751","flags":128,"ts_in_delta":1452,"sequence":180124,"symbol":"FCEU SI 20260615 PS"}
{"ts_recv":"2026-04-07T03:05:05.975670176Z","hd":{"ts_event":"2026-04-07T03:05:05.975650615Z","rtype":160,"publisher_id":101,"instrument_id":436},"action":"C","side":"B","price":"1.156700000","size":30,"channel_id":23,"order_id":"10998903140273975236","flags":0,"ts_in_delta":1076,"sequence":180125,"symbol":"FCEU SI 20260615 PS"}
{"ts_recv":"2026-04-07T03:05:05.975670176Z","hd":{"ts_event":"2026-04-07T03:05:05.975650615Z","rtype":160,"publisher_id":101,"instrument_id":436},"action":"A","side":"B","price":"1.156710000","size":30,"channel_id":23,"order_id":"10998903142830432682","flags":0,"ts_in_delta":1076,"sequence":180125,"symbol":"FCEU SI 20260615 PS"}
{"ts_recv":"2026-04-07T03:05:05.975670176Z","hd":{"ts_event":"2026-04-07T03:05:05.975650615Z","rtype":160,"publisher_id":101,"instrument_id":436},"action":"C","side":"A","price":"1.156800000","size":30,"channel_id":23,"order_id":"1775531103419199428","flags":0,"ts_in_delta":1076,"sequence":180125,"symbol":"FCEU SI 20260615 PS"}
{"ts_recv":"2026-04-07T03:05:05.975670176Z","hd":{"ts_event":"2026-04-07T03:05:05.975650615Z","rtype":160,"publisher_id":101,"instrument_id":436},"action":"A","side":"A","price":"1.156810000","size":30,"channel_id":23,"order_id":"1775531105975656874","flags":128,"ts_in_delta":1076,"sequence":180125,"symbol":"FCEU SI 20260615 PS"}
{"ts_recv":"2026-04-07T03:05:05.995283506Z","hd":{"ts_event":"2026-04-07T03:05:05.995263771Z","rtype":160,"publisher_id":101,"instrument_id":436},"action":"C","side":"B","price":"1.156710000","size":30,"channel_id":23,"order_id":"10998903142830432682","flags":0,"ts_in_delta":1082,"sequence":180141,"symbol":"FCEU SI 20260615 PS"}
{"ts_recv":"2026-04-07T03:05:05.995283506Z","hd":{"ts_event":"2026-04-07T03:05:05.995263771Z","rtype":160,"publisher_id":101,"instrument_id":436},"action":"A","side":"B","price":"1.156720000","size":30,"channel_id":23,"order_id":"10998903142850045545","flags":0,"ts_in_delta":1082,"sequence":180141,"symbol":"FCEU SI 20260615 PS"}
{"ts_recv":"2026-04-07T03:05:05.995283506Z","hd":{"ts_event":"2026-04-07T03:05:05.995263771Z","rtype":160,"publisher_id":101,"instrument_id":436},"action":"C","side":"A","price":"1.156810000","size":30,"channel_id":23,"order_id":"1775531105975656874","flags":0,"ts_in_delta":1082,"sequence":180141,"symbol":"FCEU SI 20260615 PS"}
{"ts_recv":"2026-04-07T03:05:05.995283506Z","hd":{"ts_event":"2026-04-07T03:05:05.995263771Z","rtype":160,"publisher_id":101,"instrument_id":436},"action":"A","side":"A","price":"1.156820000","size":30,"channel_id":23,"order_id":"1775531105995269737","flags":128,"ts_in_delta":1082,"sequence":180141,"symbol":"FCEU SI 20260615 PS"}
{"ts_recv":"2026-04-07T03:05:06.009150294Z","hd":{"ts_event":"2026-04-07T03:05:06.009128891Z","rtype":160,"publisher_id":101,"instrument_id":436},"action":"C","side":"B","price":"1.156710000","size":30,"channel_id":23,"order_id":"10998903142830317559","flags":0,"ts_in_delta":941,"sequence":180146,"symbol":"FCEU SI 20260615 PS"}
{"ts_recv":"2026-04-07T03:05:06.009150294Z","hd":{"ts_event":"2026-04-07T03:05:06.009128891Z","rtype":160,"publisher_id":101,"instrument_id":436},"action":"A","side":"B","price":"1.156730000","size":30,"channel_id":23,"order_id":"10998903142863910742","flags":0,"ts_in_delta":941,"sequence":180146,"symbol":"FCEU SI 20260615 PS"}
{"ts_recv":"2026-04-07T03:05:06.009150294Z","hd":{"ts_event":"2026-04-07T03:05:06.009128891Z","rtype":160,"publisher_id":101,"instrument_id":436},"action":"C","side":"A","price":"1.156810000","size":30,"channel_id":23,"order_id":"1775531105975541751","flags":0,"ts_in_delta":941,"sequence":180146,"symbol":"FCEU SI 20260615 PS"}
{"ts_recv":"2026-04-07T03:05:06.009150294Z","hd":{"ts_event":"2026-04-07T03:05:06.009128891Z","rtype":160,"publisher_id":101,"instrument_id":436},"action":"A","side":"A","price":"1.156830000","size":30,"channel_id":23,"order_id":"1775531106009134934","flags":128,"ts_in_delta":941,"sequence":180146,"symbol":"FCEU SI 20260615 PS"}
{"ts_recv":"2026-04-07T03:05:06.009208958Z","hd":{"ts_event":"2026-04-07T03:05:06.009191617Z","rtype":160,"publisher_id":101,"instrument_id":436},"action":"C","side":"B","price":"1.156720000","size":30,"channel_id":23,"order_id":"10998903142850045545","flags":0,"ts_in_delta":943,"sequence":180147,"symbol":"FCEU SI 20260615 PS"}
{"ts_recv":"2026-04-07T03:05:06.009208958Z","hd":{"ts_event":"2026-04-07T03:05:06.009191617Z","rtype":160,"publisher_id":101,"instrument_id":436},"action":"A","side":"B","price":"1.156730000","size":30,"channel_id":23,"order_id":"10998903142863973458","flags":0,"ts_in_delta":943,"sequence":180147,"symbol":"FCEU SI 20260615 PS"}
{"ts_recv":"2026-04-07T03:05:06.009208958Z","hd":{"ts_event":"2026-04-07T03:05:06.009191617Z","rtype":160,"publisher_id":101,"instrument_id":436},"action":"C","side":"A","price":"1.156820000","size":30,"channel_id":23,"order_id":"1775531105995269737","flags":0,"ts_in_delta":943,"sequence":180147,"symbol":"FCEU SI 20260615 PS"}
{"ts_recv":"2026-04-07T03:05:06.009208958Z","hd":{"ts_event":"2026-04-07T03:05:06.009191617Z","rtype":160,"publisher_id":101,"instrument_id":436},"action":"A","side":"A","price":"1.156830000","size":30,"channel_id":23,"order_id":"1775531106009197650","flags":128,"ts_in_delta":943,"sequence":180147,"symbol":"FCEU SI 20260615 PS"}
{"ts_recv":"2026-04-07T03:05:12.178611451Z","hd":{"ts_event":"2026-04-07T03:05:12.178589817Z","rtype":160,"publisher_id":101,"instrument_id":436},"action":"C","side":"B","price":"1.156730000","size":30,"channel_id":23,"order_id":"10998903142863973458","flags":0,"ts_in_delta":1131,"sequence":180224,"symbol":"FCEU SI 20260615 PS"}
{"ts_recv":"2026-04-07T03:05:12.178611451Z","hd":{"ts_event":"2026-04-07T03:05:12.178589817Z","rtype":160,"publisher_id":101,"instrument_id":436},"action":"A","side":"B","price":"1.156740000","size":30,"channel_id":23,"order_id":"10998903149033371664","flags":0,"ts_in_delta":1131,"sequence":180224,"symbol":"FCEU SI 20260615 PS"}
{"ts_recv":"2026-04-07T03:05:12.178611451Z","hd":{"ts_event":"2026-04-07T03:05:12.178589817Z","rtype":160,"publisher_id":101,"instrument_id":436},"action":"C","side":"A","price":"1.156830000","size":30,"channel_id":23,"order_id":"1775531106009197650","flags":0,"ts_in_delta":1131,"sequence":180224,"symbol":"FCEU SI 20260615 PS"}
{"ts_recv":"2026-04-07T03:05:12.178611451Z","hd":{"ts_event":"2026-04-07T03:05:12.178589817Z","rtype":160,"publisher_id":101,"instrument_id":436},"action":"A","side":"A","price":"1.156840000","size":30,"channel_id":23,"order_id":"1775531112178595856","flags":128,"ts_in_delta":1131,"sequence":180224,"symbol":"FCEU SI 20260615 PS"}
{"ts_recv":"2026-04-07T03:05:12.499906624Z","hd":{"ts_event":"2026-04-07T03:05:12.499884133Z","rtype":160,"publisher_id":101,"instrument_id":436},"action":"C","side":"B","price":"1.156730000","size":30,"channel_id":23,"order_id":"10998903142863910742","flags":0,"ts_in_delta":1159,"sequence":180232,"symbol":"FCEU SI 20260615 PS"}
{"ts_recv":"2026-04-07T03:05:12.499906624Z","hd":{"ts_event":"2026-04-07T03:05:12.499884133Z","rtype":160,"publisher_id":101,"instrument_id":436},"action":"A","side":"B","price":"1.156750000","size":30,"channel_id":23,"order_id":"10998903149354667374","flags":0,"ts_in_delta":1159,"sequence":180232,"symbol":"FCEU SI 20260615 PS"}
{"ts_recv":"2026-04-07T03:05:12.499906624Z","hd":{"ts_event":"2026-04-07T03:05:12.499884133Z","rtype":160,"publisher_id":101,"instrument_id":436},"action":"C","side":"A","price":"1.156830000","size":30,"channel_id":23,"order_id":"1775531106009134934","flags":0,"ts_in_delta":1159,"sequence":180232,"symbol":"FCEU SI 20260615 PS"}
{"ts_recv":"2026-04-07T03:05:12.499906624Z","hd":{"ts_event":"2026-04-07T03:05:12.499884133Z","rtype":160,"publisher_id":101,"instrument_id":436},"action":"A","side":"A","price":"1.156850000","size":30,"channel_id":23,"order_id":"1775531112499891566","flags":128,"ts_in_delta":1159,"sequence":180232,"symbol":"FCEU SI 20260615 PS"}
{"ts_recv":"2026-04-07T03:05:12.499971102Z","hd":{"ts_event":"2026-04-07T03:05:12.499954943Z","rtype":160,"publisher_id":101,"instrument_id":436},"action":"C","side":"B","price":"1.156740000","size":30,"channel_id":23,"order_id":"10998903149033371664","flags":0,"ts_in_delta":1116,"sequence":180233,"symbol":"FCEU SI 20260615 PS"}
{"ts_recv":"2026-04-07T03:05:12.499971102Z","hd":{"ts_event":"2026-04-07T03:05:12.499954943Z","rtype":160,"publisher_id":101,"instrument_id":436},"action":"A","side":"B","price":"1.156750000","size":30,"channel_id":23,"order_id":"10998903149354736804","flags":0,"ts_in_delta":1116,"sequence":180233,"symbol":"FCEU SI 20260615 PS"}
{"ts_recv":"2026-04-07T03:05:12.499971102Z","hd":{"ts_event":"2026-04-07T03:05:12.499954943Z","rtype":160,"publisher_id":101,"instrument_id":436},"action":"C","side":"A","price":"1.156840000","size":30,"channel_id":23,"order_id":"1775531112178595856","flags":0,"ts_in_delta":1116,"sequence":180233,"symbol":"FCEU SI 20260615 PS"}
{"ts_recv":"2026-04-07T03:05:12.499971102Z","hd":{"ts_event":"2026-04-07T03:05:12.499954943Z","rtype":160,"publisher_id":101,"instrument_id":436},"action":"A","side":"A","price":"1.156850000","size":30,"channel_id":23,"order_id":"1775531112499960996","flags":128,"ts_in_delta":1116,"sequence":180233,"symbol":"FCEU SI 20260615 PS"}
{"ts_recv":"2026-04-07T03:05:15.942487654Z","hd":{"ts_event":"2026-04-07T03:05:15.942466425Z","rtype":160,"publisher_id":101,"instrument_id":436},"action":"C","side":"B","price":"1.156750000","size":30,"channel_id":23,"order_id":"10998903149354736804","flags":0,"ts_in_delta":1223,"sequence":180283,"symbol":"FCEU SI 20260615 PS"}
{"ts_recv":"2026-04-07T03:05:15.942487654Z","hd":{"ts_event":"2026-04-07T03:05:15.942466425Z","rtype":160,"publisher_id":101,"instrument_id":436},"action":"A","side":"B","price":"1.156760000","size":30,"channel_id":23,"order_id":"10998903152797248382","flags":0,"ts_in_delta":1223,"sequence":180283,"symbol":"FCEU SI 20260615 PS"}
{"ts_recv":"2026-04-07T03:05:15.942487654Z","hd":{"ts_event":"2026-04-07T03:05:15.942466425Z","rtype":160,"publisher_id":101,"instrument_id":436},"action":"C","side":"A","price":"1.156850000","size":30,"channel_id":23,"order_id":"1775531112499960996","flags":0,"ts_in_delta":1223,"sequence":180283,"symbol":"FCEU SI 20260615 PS"}
{"ts_recv":"2026-04-07T03:05:15.942487654Z","hd":{"ts_event":"2026-04-07T03:05:15.942466425Z","rtype":160,"publisher_id":101,"instrument_id":436},"action":"A","side":"A","price":"1.156860000","size":30,"channel_id":23,"order_id":"1775531115942472574","flags":128,"ts_in_delta":1223,"sequence":180283,"symbol":"FCEU SI 20260615 PS"}
{"ts_recv":"2026-04-07T03:05:15.942545835Z","hd":{"ts_event":"2026-04-07T03:05:15.942524827Z","rtype":160,"publisher_id":101,"instrument_id":436},"action":"C","side":"B","price":"1.156750000","size":30,"channel_id":23,"order_id":"10998903149354667374","flags":0,"ts_in_delta":1131,"sequence":180284,"symbol":"FCEU SI 20260615 PS"}
{"ts_recv":"2026-04-07T03:05:15.942545835Z","hd":{"ts_event":"2026-04-07T03:05:15.942524827Z","rtype":160,"publisher_id":101,"instrument_id":436},"action":"A","side":"B","price":"1.156770000","size":30,"channel_id":23,"order_id":"10998903152797306454","flags":0,"ts_in_delta":1131,"sequence":180284,"symbol":"FCEU SI 20260615 PS"}
{"ts_recv":"2026-04-07T03:05:15.942545835Z","hd":{"ts_event":"2026-04-07T03:05:15.942524827Z","rtype":160,"publisher_id":101,"instrument_id":436},"action":"C","side":"A","price":"1.156850000","size":30,"channel_id":23,"order_id":"1775531112499891566","flags":0,"ts_in_delta":1131,"sequence":180284,"symbol":"FCEU SI 20260615 PS"}
{"ts_recv":"2026-04-07T03:05:15.942545835Z","hd":{"ts_event":"2026-04-07T03:05:15.942524827Z","rtype":160,"publisher_id":101,"instrument_id":436},"action":"A","side":"A","price":"1.156870000","size":30,"channel_id":23,"order_id":"1775531115942530646","flags":128,"ts_in_delta":1131,"sequence":180284,"symbol":"FCEU SI 20260615 PS"}
{"ts_recv":"2026-04-07T03:05:15.942600529Z","hd":{"ts_event":"2026-04-07T03:05:15.942582023Z","rtype":160,"publisher_id":101,"instrument_id":436},"action":"C","side":"B","price":"1.156760000","size":30,"channel_id":23,"order_id":"10998903152797248382","flags":0,"ts_in_delta":1040,"sequence":180285,"symbol":"FCEU SI 20260615 PS"}
{"ts_recv":"2026-04-07T03:05:15.942600529Z","hd":{"ts_event":"2026-04-07T03:05:15.942582023Z","rtype":160,"publisher_id":101,"instrument_id":436},"action":"A","side":"B","price":"1.156770000","size":30,"channel_id":23,"order_id":"10998903152797364070","flags":0,"ts_in_delta":1040,"sequence":180285,"symbol":"FCEU SI 20260615 PS"}
{"ts_recv":"2026-04-07T03:05:15.942600529Z","hd":{"ts_event":"2026-04-07T03:05:15.942582023Z","rtype":160,"publisher_id":101,"instrument_id":436},"action":"C","side":"A","price":"1.156860000","size":30,"channel_id":23,"order_id":"1775531115942472574","flags":0,"ts_in_delta":1040,"sequence":180285,"symbol":"FCEU SI 20260615 PS"}
{"ts_recv":"2026-04-07T03:05:15.942600529Z","hd":{"ts_event":"2026-04-07T03:05:15.942582023Z","rtype":160,"publisher_id":101,"instrument_id":436},"action":"A","side":"A","price":"1.156870000","size":30,"channel_id":23,"order_id":"1775531115942588262","flags":128,"ts_in_delta":1040,"sequence":180285,"symbol":"FCEU SI 20260615 PS"}
{"ts_recv":"2026-04-07T03:05:16.076670670Z","hd":{"ts_event":"2026-04-07T03:05:16.076649733Z","rtype":160,"publisher_id":101,"instrument_id":436},"action":"C","side":"B","price":"1.156770000","size":30,"channel_id":23,"order_id":"10998903152797364070","flags":0,"ts_in_delta":884,"sequence":180310,"symbol":"FCEU SI 20260615 PS"}
{"ts_recv":"2026-04-07T03:05:16.076670670Z","hd":{"ts_event":"2026-04-07T03:05:16.076649733Z","rtype":160,"publisher_id":101,"instrument_id":436},"action":"A","side":"B","price":"1.156780000","size":30,"channel_id":23,"order_id":"10998903152931431636","flags":0,"ts_in_delta":884,"sequence":180310,"symbol":"FCEU SI 20260615 PS"}
{"ts_recv":"2026-04-07T03:05:16.076670670Z","hd":{"ts_event":"2026-04-07T03:05:16.076649733Z","rtype":160,"publisher_id":101,"instrument_id":436},"action":"C","side":"A","price":"1.156870000","size":30,"channel_id":23,"order_id":"1775531115942588262","flags":0,"ts_in_delta":884,"sequence":180310,"symbol":"FCEU SI 20260615 PS"}
{"ts_recv":"2026-04-07T03:05:16.076670670Z","hd":{"ts_event":"2026-04-07T03:05:16.076649733Z","rtype":160,"publisher_id":101,"instrument_id":436},"action":"A","side":"A","price":"1.156880000","size":30,"channel_id":23,"order_id":"1775531116076655828","flags":128,"ts_in_delta":884,"sequence":180310,"symbol":"FCEU SI 20260615 PS"}
{"ts_recv":"2026-04-07T03:05:21.695298363Z","hd":{"ts_event":"2026-04-07T03:05:21.695279419Z","rtype":160,"publisher_id":101,"instrument_id":436},"action":"C","side":"B","price":"1.156780000","size":30,"channel_id":23,"order_id":"10998903152931431636","flags":0,"ts_in_delta":972,"sequence":180346,"symbol":"FCEU SI 20260615 PS"}
{"ts_recv":"2026-04-07T03:05:21.695298363Z","hd":{"ts_event":"2026-04-07T03:05:21.695279419Z","rtype":160,"publisher_id":101,"instrument_id":436},"action":"A","side":"B","price":"1.156770000","size":30,"channel_id":23,"order_id":"10998903158550061471","flags":0,"ts_in_delta":972,"sequence":180346,"symbol":"FCEU SI 20260615 PS"}
{"ts_recv":"2026-04-07T03:05:21.695298363Z","hd":{"ts_event":"2026-04-07T03:05:21.695279419Z","rtype":160,"publisher_id":101,"instrument_id":436},"action":"C","side":"A","price":"1.156880000","size":30,"channel_id":23,"order_id":"1775531116076655828","flags":0,"ts_in_delta":972,"sequence":180346,"symbol":"FCEU SI 20260615 PS"}
{"ts_recv":"2026-04-07T03:05:21.695298363Z","hd":{"ts_event":"2026-04-07T03:05:21.695279419Z","rtype":160,"publisher_id":101,"instrument_id":436},"action":"A","side":"A","price":"1.156870000","size":30,"channel_id":23,"order_id":"1775531121695285663","flags":128,"ts_in_delta":972,"sequence":180346,"symbol":"FCEU SI 20260615 PS"}
{"ts_recv":"2026-04-07T03:05:22.700344552Z","hd":{"ts_event":"2026-04-07T03:05:22.700325869Z","rtype":160,"publisher_id":101,"instrument_id":436},"action":"C","side":"B","price":"1.156770000","size":30,"channel_id":23,"order_id":"10998903158550061471","flags":0,"ts_in_delta":1016,"sequence":180374,"symbol":"FCEU SI 20260615 PS"}
{"ts_recv":"2026-04-07T03:05:22.700344552Z","hd":{"ts_event":"2026-04-07T03:05:22.700325869Z","rtype":160,"publisher_id":101,"instrument_id":436},"action":"A","side":"B","price":"1.156760000","size":30,"channel_id":23,"order_id":"10998903159555107798","flags":0,"ts_in_delta":1016,"sequence":180374,"symbol":"FCEU SI 20260615 PS"}
{"ts_recv":"2026-04-07T03:05:22.700344552Z","hd":{"ts_event":"2026-04-07T03:05:22.700325869Z","rtype":160,"publisher_id":101,"instrument_id":436},"action":"C","side":"A","price":"1.156870000","size":30,"channel_id":23,"order_id":"1775531121695285663","flags":0,"ts_in_delta":1016,"sequence":180374,"symbol":"FCEU SI 20260615 PS"}
{"ts_recv":"2026-04-07T03:05:22.700344552Z","hd":{"ts_event":"2026-04-07T03:05:22.700325869Z","rtype":160,"publisher_id":101,"instrument_id":436},"action":"A","side":"A","price":"1.156860000","size":30,"channel_id":23,"order_id":"1775531122700331990","flags":128,"ts_in_delta":1016,"sequence":180374,"symbol":"FCEU SI 20260615 PS"}
{"ts_recv":"2026-04-07T03:05:22.700403193Z","hd":{"ts_event":"2026-04-07T03:05:22.700382299Z","rtype":160,"publisher_id":101,"instrument_id":436},"action":"C","side":"B","price":"1.156770000","size":30,"channel_id":23,"order_id":"10998903152797306454","flags":0,"ts_in_delta":932,"sequence":180375,"symbol":"FCEU SI 20260615 PS"}
{"ts_recv":"2026-04-07T03:05:22.700403193Z","hd":{"ts_event":"2026-04-07T03:05:22.700382299Z","rtype":160,"publisher_id":101,"instrument_id":436},"action":"A","side":"B","price":"1.156750000","size":30,"channel_id":23,"order_id":"10998903159555164257","flags":0,"ts_in_delta":932,"sequence":180375,"symbol":"FCEU SI 20260615 PS"}
{"ts_recv":"2026-04-07T03:05:22.700403193Z","hd":{"ts_event":"2026-04-07T03:05:22.700382299Z","rtype":160,"publisher_id":101,"instrument_id":436},"action":"C","side":"A","price":"1.156870000","size":30,"channel_id":23,"order_id":"1775531115942530646","flags":0,"ts_in_delta":932,"sequence":180375,"symbol":"FCEU SI 20260615 PS"}
{"ts_recv":"2026-04-07T03:05:22.700403193Z","hd":{"ts_event":"2026-04-07T03:05:22.700382299Z","rtype":160,"publisher_id":101,"instrument_id":436},"action":"A","side":"A","price":"1.156850000","size":30,"channel_id":23,"order_id":"1775531122700388449","flags":128,"ts_in_delta":932,"sequence":180375,"symbol":"FCEU SI 20260615 PS"}
{"ts_recv":"2026-04-07T03:05:22.700455069Z","hd":{"ts_event":"2026-04-07T03:05:22.700437895Z","rtype":160,"publisher_id":101,"instrument_id":436},"action":"C","side":"B","price":"1.156760000","size":30,"channel_id":23,"order_id":"10998903159555107798","flags":0,"ts_in_delta":910,"sequence":180376,"symbol":"FCEU SI 20260615 PS"}
{"ts_recv":"2026-04-07T03:05:22.700455069Z","hd":{"ts_event":"2026-04-07T03:05:22.700437895Z","rtype":160,"publisher_id":101,"instrument_id":436},"action":"A","side":"B","price":"1.156750000","size":30,"channel_id":23,"order_id":"10998903159555219507","flags":0,"ts_in_delta":910,"sequence":180376,"symbol":"FCEU SI 20260615 PS"}
{"ts_recv":"2026-04-07T03:05:22.700455069Z","hd":{"ts_event":"2026-04-07T03:05:22.700437895Z","rtype":160,"publisher_id":101,"instrument_id":436},"action":"C","side":"A","price":"1.156860000","size":30,"channel_id":23,"order_id":"1775531122700331990","flags":0,"ts_in_delta":910,"sequence":180376,"symbol":"FCEU SI 20260615 PS"}
{"ts_recv":"2026-04-07T03:05:22.700455069Z","hd":{"ts_event":"2026-04-07T03:05:22.700437895Z","rtype":160,"publisher_id":101,"instrument_id":436},"action":"A","side":"A","price":"1.156850000","size":30,"channel_id":23,"order_id":"1775531122700443699","flags":128,"ts_in_delta":910,"sequence":180376,"symbol":"FCEU SI 20260615 PS"}
{"ts_recv":"2026-04-07T03:05:23.348772683Z","hd":{"ts_event":"2026-04-07T03:05:23.348751479Z","rtype":160,"publisher_id":101,"instrument_id":436},"action":"C","side":"B","price":"1.156750000","size":30,"channel_id":23,"order_id":"10998903159555219507","flags":0,"ts_in_delta":951,"sequence":180383,"symbol":"FCEU SI 20260615 PS"}
{"ts_recv":"2026-04-07T03:05:23.348772683Z","hd":{"ts_event":"2026-04-07T03:05:23.348751479Z","rtype":160,"publisher_id":101,"instrument_id":436},"action":"A","side":"B","price":"1.156740000","size":30,"channel_id":23,"order_id":"10998903160203533563","flags":0,"ts_in_delta":951,"sequence":180383,"symbol":"FCEU SI 20260615 PS"}
{"ts_recv":"2026-04-07T03:05:23.348772683Z","hd":{"ts_event":"2026-04-07T03:05:23.348751479Z","rtype":160,"publisher_id":101,"instrument_id":436},"action":"C","side":"A","price":"1.156850000","size":30,"channel_id":23,"order_id":"1775531122700443699","flags":0,"ts_in_delta":951,"sequence":180383,"symbol":"FCEU SI 20260615 PS"}
{"ts_recv":"2026-04-07T03:05:23.348772683Z","hd":{"ts_event":"2026-04-07T03:05:23.348751479Z","rtype":160,"publisher_id":101,"instrument_id":436},"action":"A","side":"A","price":"1.156840000","size":30,"channel_id":23,"order_id":"1775531123348757755","flags":128,"ts_in_delta":951,"sequence":180383,"symbol":"FCEU SI 20260615 PS"}
{"ts_recv":"2026-04-07T03:05:23.348853795Z","hd":{"ts_event":"2026-04-07T03:05:23.348834731Z","rtype":160,"publisher_id":101,"instrument_id":436},"action":"C","side":"B","price":"1.156750000","size":30,"channel_id":23,"order_id":"10998903159555164257","flags":0,"ts_in_delta":758,"sequence":180384,"symbol":"FCEU SI 20260615 PS"}
{"ts_recv":"2026-04-07T03:05:23.348853795Z","hd":{"ts_event":"2026-04-07T03:05:23.348834731Z","rtype":160,"publisher_id":101,"instrument_id":436},"action":"A","side":"B","price":"1.156730000","size":30,"channel_id":23,"order_id":"10998903160203617087","flags":0,"ts_in_delta":758,"sequence":180384,"symbol":"FCEU SI 20260615 PS"}
{"ts_recv":"2026-04-07T03:05:23.348853795Z","hd":{"ts_event":"2026-04-07T03:05:23.348834731Z","rtype":160,"publisher_id":101,"instrument_id":436},"action":"C","side":"A","price":"1.156850000","size":30,"channel_id":23,"order_id":"1775531122700388449","flags":0,"ts_in_delta":758,"sequence":180384,"symbol":"FCEU SI 20260615 PS"}
{"ts_recv":"2026-04-07T03:05:23.348853795Z","hd":{"ts_event":"2026-04-07T03:05:23.348834731Z","rtype":160,"publisher_id":101,"instrument_id":436},"action":"A","side":"A","price":"1.156830000","size":30,"channel_id":23,"order_id":"1775531123348841279","flags":128,"ts_in_delta":758,"sequence":180384,"symbol":"FCEU SI 20260615 PS"}
{"ts_recv":"2026-04-07T03:05:23.348862949Z","hd":{"ts_event":"2026-04-07T03:05:23.348838187Z","rtype":160,"publisher_id":101,"instrument_id":436},"action":"C","side":"B","price":"1.156740000","size":30,"channel_id":23,"order_id":"10998903160203533563","flags":0,"ts_in_delta":743,"sequence":180385,"symbol":"FCEU SI 20260615 PS"}
{"ts_recv":"2026-04-07T03:05:23.348862949Z","hd":{"ts_event":"2026-04-07T03:05:23.348838187Z","rtype":160,"publisher_id":101,"instrument_id":436},"action":"A","side":"B","price":"1.156730000","size":30,"channel_id":23,"order_id":"10998903160203626690","flags":0,"ts_in_delta":743,"sequence":180385,"symbol":"FCEU SI 20260615 PS"}
{"ts_recv":"2026-04-07T03:05:23.348862949Z","hd":{"ts_event":"2026-04-07T03:05:23.348838187Z","rtype":160,"publisher_id":101,"instrument_id":436},"action":"C","side":"A","price":"1.156840000","size":30,"channel_id":23,"order_id":"1775531123348757755","flags":0,"ts_in_delta":743,"sequence":180385,"symbol":"FCEU SI 20260615 PS"}
{"ts_recv":"2026-04-07T03:05:23.348862949Z","hd":{"ts_event":"2026-04-07T03:05:23.348838187Z","rtype":160,"publisher_id":101,"instrument_id":436},"action":"A","side":"A","price":"1.156830000","size":30,"channel_id":23,"order_id":"1775531123348850882","flags":128,"ts_in_delta":743,"sequence":180385,"symbol":"FCEU SI 20260615 PS"}
{"ts_recv":"2026-04-07T03:05:29.515240561Z","hd":{"ts_event":"2026-04-07T03:05:29.515207685Z","rtype":160,"publisher_id":101,"instrument_id":436},"action":"C","side":"B","price":"1.156730000","size":30,"channel_id":23,"order_id":"10998903160203626690","flags":0,"ts_in_delta":1476,"sequence":180458,"symbol":"FCEU SI 20260615 PS"}
{"ts_recv":"2026-04-07T03:05:29.515240561Z","hd":{"ts_event":"2026-04-07T03:05:29.515207685Z","rtype":160,"publisher_id":101,"instrument_id":436},"action":"A","side":"B","price":"1.156720000","size":30,"channel_id":23,"order_id":"10998903166369996401","flags":0,"ts_in_delta":1476,"sequence":180458,"symbol":"FCEU SI 20260615 PS"}
{"ts_recv":"2026-04-07T03:05:29.515240561Z","hd":{"ts_event":"2026-04-07T03:05:29.515207685Z","rtype":160,"publisher_id":101,"instrument_id":436},"action":"C","side":"A","price":"1.156830000","size":30,"channel_id":23,"order_id":"1775531123348850882","flags":0,"ts_in_delta":1476,"sequence":180458,"symbol":"FCEU SI 20260615 PS"}
{"ts_recv":"2026-04-07T03:05:29.515240561Z","hd":{"ts_event":"2026-04-07T03:05:29.515207685Z","rtype":160,"publisher_id":101,"instrument_id":436},"action":"A","side":"A","price":"1.156820000","size":30,"channel_id":23,"order_id":"1775531129515220593","flags":128,"ts_in_delta":1476,"sequence":180458,"symbol":"FCEU SI 20260615 PS"}
{"ts_recv":"2026-04-07T03:05:29.515324330Z","hd":{"ts_event":"2026-04-07T03:05:29.515306335Z","rtype":160,"publisher_id":101,"instrument_id":436},"action":"C","side":"B","price":"1.156720000","size":30,"channel_id":23,"order_id":"10998903166369996401","flags":0,"ts_in_delta":902,"sequence":180459,"symbol":"FCEU SI 20260615 PS"}
{"ts_recv":"2026-04-07T03:05:29.515324330Z","hd":{"ts_event":"2026-04-07T03:05:29.515306335Z","rtype":160,"publisher_id":101,"instrument_id":436},"action":"A","side":"B","price":"1.156710000","size":30,"channel_id":23,"order_id":"10998903166370088357","flags":0,"ts_in_delta":902,"sequence":180459,"symbol":"FCEU SI 20260615 PS"}
{"ts_recv":"2026-04-07T03:05:29.515324330Z","hd":{"ts_event":"2026-04-07T03:05:29.515306335Z","rtype":160,"publisher_id":101,"instrument_id":436},"action":"C","side":"A","price":"1.156820000","size":30,"channel_id":23,"order_id":"1775531129515220593","flags":0,"ts_in_delta":902,"sequence":180459,"symbol":"FCEU SI 20260615 PS"}
{"ts_recv":"2026-04-07T03:05:29.515324330Z","hd":{"ts_event":"2026-04-07T03:05:29.515306335Z","rtype":160,"publisher_id":101,"instrument_id":436},"action":"A","side":"A","price":"1.156810000","size":30,"channel_id":23,"order_id":"1775531129515312549","flags":128,"ts_in_delta":902,"sequence":180459,"symbol":"FCEU SI 20260615 PS"}
{"ts_recv":"2026-04-07T03:05:29.515379570Z","hd":{"ts_event":"2026-04-07T03:05:29.515360549Z","rtype":160,"publisher_id":101,"instrument_id":436},"action":"C","side":"B","price":"1.156730000","size":30,"channel_id":23,"order_id":"10998903160203617087","flags":0,"ts_in_delta":1071,"sequence":180460,"symbol":"FCEU SI 20260615 PS"}
{"ts_recv":"2026-04-07T03:05:29.515379570Z","hd":{"ts_event":"2026-04-07T03:05:29.515360549Z","rtype":160,"publisher_id":101,"instrument_id":436},"action":"A","side":"B","price":"1.156710000","size":30,"channel_id":23,"order_id":"10998903166370142549","flags":0,"ts_in_delta":1071,"sequence":180460,"symbol":"FCEU SI 20260615 PS"}
{"ts_recv":"2026-04-07T03:05:29.515379570Z","hd":{"ts_event":"2026-04-07T03:05:29.515360549Z","rtype":160,"publisher_id":101,"instrument_id":436},"action":"C","side":"A","price":"1.156830000","size":30,"channel_id":23,"order_id":"1775531123348841279","flags":0,"ts_in_delta":1071,"sequence":180460,"symbol":"FCEU SI 20260615 PS"}
{"ts_recv":"2026-04-07T03:05:29.515379570Z","hd":{"ts_event":"2026-04-07T03:05:29.515360549Z","rtype":160,"publisher_id":101,"instrument_id":436},"action":"A","side":"A","price":"1.156810000","size":30,"channel_id":23,"order_id":"1775531129515366741","flags":128,"ts_in_delta":1071,"sequence":180460,"symbol":"FCEU SI 20260615 PS"}
{"ts_recv":"2026-04-07T03:05:29.515390797Z","hd":{"ts_event":"2026-04-07T03:05:29.515364069Z","rtype":160,"publisher_id":101,"instrument_id":436},"action":"C","side":"B","price":"1.156710000","size":30,"channel_id":23,"order_id":"10998903166370088357","flags":0,"ts_in_delta":900,"sequence":180461,"symbol":"FCEU SI 20260615 PS"}
{"ts_recv":"2026-04-07T03:05:29.515390797Z","hd":{"ts_event":"2026-04-07T03:05:29.515364069Z","rtype":160,"publisher_id":101,"instrument_id":436},"action":"A","side":"B","price":"1.156720000","size":30,"channel_id":23,"order_id":"10998903166370151951","flags":0,"ts_in_delta":900,"sequence":180461,"symbol":"FCEU SI 20260615 PS"}
{"ts_recv":"2026-04-07T03:05:29.515390797Z","hd":{"ts_event":"2026-04-07T03:05:29.515364069Z","rtype":160,"publisher_id":101,"instrument_id":436},"action":"C","side":"A","price":"1.156810000","size":30,"channel_id":23,"order_id":"1775531129515312549","flags":0,"ts_in_delta":900,"sequence":180461,"symbol":"FCEU SI 20260615 PS"}
{"ts_recv":"2026-04-07T03:05:29.515390797Z","hd":{"ts_event":"2026-04-07T03:05:29.515364069Z","rtype":160,"publisher_id":101,"instrument_id":436},"action":"A","side":"A","price":"1.156820000","size":30,"channel_id":23,"order_id":"1775531129515376143","flags":128,"ts_in_delta":900,"sequence":180461,"symbol":"FCEU SI 20260615 PS"}
{"ts_recv":"2026-04-07T03:05:29.515447074Z","hd":{"ts_event":"2026-04-07T03:05:29.515429253Z","rtype":160,"publisher_id":101,"instrument_id":436},"action":"C","side":"B","price":"1.156720000","size":30,"channel_id":23,"order_id":"10998903166370151951","flags":0,"ts_in_delta":870,"sequence":180462,"symbol":"FCEU SI 20260615 PS"}
{"ts_recv":"2026-04-07T03:05:29.515447074Z","hd":{"ts_event":"2026-04-07T03:05:29.515429253Z","rtype":160,"publisher_id":101,"instrument_id":436},"action":"A","side":"B","price":"1.156710000","size":30,"channel_id":23,"order_id":"10998903166370210996","flags":0,"ts_in_delta":870,"sequence":180462,"symbol":"FCEU SI 20260615 PS"}
{"ts_recv":"2026-04-07T03:05:29.515447074Z","hd":{"ts_event":"2026-04-07T03:05:29.515429253Z","rtype":160,"publisher_id":101,"instrument_id":436},"action":"C","side":"A","price":"1.156820000","size":30,"channel_id":23,"order_id":"1775531129515376143","flags":0,"ts_in_delta":870,"sequence":180462,"symbol":"FCEU SI 20260615 PS"}
{"ts_recv":"2026-04-07T03:05:29.515447074Z","hd":{"ts_event":"2026-04-07T03:05:29.515429253Z","rtype":160,"publisher_id":101,"instrument_id":436},"action":"A","side":"A","price":"1.156810000","size":30,"channel_id":23,"order_id":"1775531129515435188","flags":128,"ts_in_delta":870,"sequence":180462,"symbol":"FCEU SI 20260615 PS"}
{"ts_recv":"2026-04-07T03:05:32.203181823Z","hd":{"ts_event":"2026-04-07T03:05:32.203162177Z","rtype":160,"publisher_id":101,"instrument_id":436},"action":"C","side":"B","price":"1.156710000","size":30,"channel_id":23,"order_id":"10998903166370210996","flags":0,"ts_in_delta":1102,"sequence":180494,"symbol":"FCEU SI 20260615 PS"}
{"ts_recv":"2026-04-07T03:05:32.203181823Z","hd":{"ts_event":"2026-04-07T03:05:32.203162177Z","rtype":160,"publisher_id":101,"instrument_id":436},"action":"A","side":"B","price":"1.156700000","size":30,"channel_id":23,"order_id":"10998903169057944116","flags":0,"ts_in_delta":1102,"sequence":180494,"symbol":"FCEU SI 20260615 PS"}
{"ts_recv":"2026-04-07T03:05:32.203181823Z","hd":{"ts_event":"2026-04-07T03:05:32.203162177Z","rtype":160,"publisher_id":101,"instrument_id":436},"action":"C","side":"A","price":"1.156810000","size":30,"channel_id":23,"order_id":"1775531129515435188","flags":0,"ts_in_delta":1102,"sequence":180494,"symbol":"FCEU SI 20260615 PS"}
{"ts_recv":"2026-04-07T03:05:32.203181823Z","hd":{"ts_event":"2026-04-07T03:05:32.203162177Z","rtype":160,"publisher_id":101,"instrument_id":436},"action":"A","side":"A","price":"1.156800000","size":30,"channel_id":23,"order_id":"1775531132203168308","flags":128,"ts_in_delta":1102,"sequence":180494,"symbol":"FCEU SI 20260615 PS"}
{"ts_recv":"2026-04-07T03:05:42.581455877Z","hd":{"ts_event":"2026-04-07T03:05:42.581435005Z","rtype":160,"publisher_id":101,"instrument_id":436},"action":"C","side":"B","price":"1.156710000","size":30,"channel_id":23,"order_id":"10998903166370142549","flags":0,"ts_in_delta":1174,"sequence":180547,"symbol":"FCEU SI 20260615 PS"}
{"ts_recv":"2026-04-07T03:05:42.581455877Z","hd":{"ts_event":"2026-04-07T03:05:42.581435005Z","rtype":160,"publisher_id":101,"instrument_id":436},"action":"A","side":"B","price":"1.156690000","size":30,"channel_id":23,"order_id":"10998903179436217411","flags":0,"ts_in_delta":1174,"sequence":180547,"symbol":"FCEU SI 20260615 PS"}
{"ts_recv":"2026-04-07T03:05:42.581455877Z","hd":{"ts_event":"2026-04-07T03:05:42.581435005Z","rtype":160,"publisher_id":101,"instrument_id":436},"action":"C","side":"A","price":"1.156810000","size":30,"channel_id":23,"order_id":"1775531129515366741","flags":0,"ts_in_delta":1174,"sequence":180547,"symbol":"FCEU SI 20260615 PS"}
{"ts_recv":"2026-04-07T03:05:42.581455877Z","hd":{"ts_event":"2026-04-07T03:05:42.581435005Z","rtype":160,"publisher_id":101,"instrument_id":436},"action":"A","side":"A","price":"1.156790000","size":30,"channel_id":23,"order_id":"1775531142581441603","flags":128,"ts_in_delta":1174,"sequence":180547,"symbol":"FCEU SI 20260615 PS"}
{"ts_recv":"2026-04-07T03:05:42.581550812Z","hd":{"ts_event":"2026-04-07T03:05:42.581531427Z","rtype":160,"publisher_id":101,"instrument_id":436},"action":"C","side":"B","price":"1.156700000","size":30,"channel_id":23,"order_id":"10998903169057944116","flags":0,"ts_in_delta":915,"sequence":180548,"symbol":"FCEU SI 20260615 PS"}
{"ts_recv":"2026-04-07T03:05:42.581550812Z","hd":{"ts_event":"2026-04-07T03:05:42.581531427Z","rtype":160,"publisher_id":101,"instrument_id":436},"action":"A","side":"B","price":"1.156690000","size":30,"channel_id":23,"order_id":"10998903179436313229","flags":0,"ts_in_delta":915,"sequence":180548,"symbol":"FCEU SI 20260615 PS"}
{"ts_recv":"2026-04-07T03:05:42.581550812Z","hd":{"ts_event":"2026-04-07T03:05:42.581531427Z","rtype":160,"publisher_id":101,"instrument_id":436},"action":"C","side":"A","price":"1.156800000","size":30,"channel_id":23,"order_id":"1775531132203168308","flags":0,"ts_in_delta":915,"sequence":180548,"symbol":"FCEU SI 20260615 PS"}
{"ts_recv":"2026-04-07T03:05:42.581550812Z","hd":{"ts_event":"2026-04-07T03:05:42.581531427Z","rtype":160,"publisher_id":101,"instrument_id":436},"action":"A","side":"A","price":"1.156790000","size":30,"channel_id":23,"order_id":"1775531142581537421","flags":128,"ts_in_delta":915,"sequence":180548,"symbol":"FCEU SI 20260615 PS"}
{"ts_recv":"2026-04-07T03:06:08.521246691Z","hd":{"ts_event":"2026-04-07T03:06:08.521221345Z","rtype":160,"publisher_id":101,"instrument_id":436},"action":"C","side":"B","price":"1.156690000","size":30,"channel_id":23,"order_id":"10998903179436313229","flags":0,"ts_in_delta":981,"sequence":180762,"symbol":"FCEU SI 20260615 PS"}
{"ts_recv":"2026-04-07T03:06:08.521246691Z","hd":{"ts_event":"2026-04-07T03:06:08.521221345Z","rtype":160,"publisher_id":101,"instrument_id":436},"action":"A","side":"B","price":"1.156700000","size":30,"channel_id":23,"order_id":"10998903205376003518","flags":0,"ts_in_delta":981,"sequence":180762,"symbol":"FCEU SI 20260615 PS"}
{"ts_recv":"2026-04-07T03:06:08.521246691Z","hd":{"ts_event":"2026-04-07T03:06:08.521221345Z","rtype":160,"publisher_id":101,"instrument_id":436},"action":"C","side":"A","price":"1.156790000","size":30,"channel_id":23,"order_id":"1775531142581537421","flags":0,"ts_in_delta":981,"sequence":180762,"symbol":"FCEU SI 20260615 PS"}
{"ts_recv":"2026-04-07T03:06:08.521246691Z","hd":{"ts_event":"2026-04-07T03:06:08.521221345Z","rtype":160,"publisher_id":101,"instrument_id":436},"action":"A","side":"A","price":"1.156800000","size":30,"channel_id":23,"order_id":"1775531168521227710","flags":128,"ts_in_delta":981,"sequence":180762,"symbol":"FCEU SI 20260615 PS"}
{"ts_recv":"2026-04-07T03:06:08.607367338Z","hd":{"ts_event":"2026-04-07T03:06:08.607346801Z","rtype":160,"publisher_id":101,"instrument_id":436},"action":"C","side":"B","price":"1.156700000","size":30,"channel_id":23,"order_id":"10998903205376003518","flags":0,"ts_in_delta":1167,"sequence":180765,"symbol":"FCEU SI 20260615 PS"}
{"ts_recv":"2026-04-07T03:06:08.607367338Z","hd":{"ts_event":"2026-04-07T03:06:08.607346801Z","rtype":160,"publisher_id":101,"instrument_id":436},"action":"A","side":"B","price":"1.156690000","size":30,"channel_id":23,"order_id":"10998903205462128792","flags":0,"ts_in_delta":1167,"sequence":180765,"symbol":"FCEU SI 20260615 PS"}
{"ts_recv":"2026-04-07T03:06:08.607367338Z","hd":{"ts_event":"2026-04-07T03:06:08.607346801Z","rtype":160,"publisher_id":101,"instrument_id":436},"action":"C","side":"A","price":"1.156800000","size":30,"channel_id":23,"order_id":"1775531168521227710","flags":0,"ts_in_delta":1167,"sequence":180765,"symbol":"FCEU SI 20260615 PS"}
{"ts_recv":"2026-04-07T03:06:08.607367338Z","hd":{"ts_event":"2026-04-07T03:06:08.607346801Z","rtype":160,"publisher_id":101,"instrument_id":436},"action":"A","side":"A","price":"1.156790000","size":30,"channel_id":23,"order_id":"1775531168607352984","flags":128,"ts_in_delta":1167,"sequence":180765,"symbol":"FCEU SI 20260615 PS"}
{"ts_recv":"2026-04-07T03:06:15.876055527Z","hd":{"ts_event":"2026-04-07T03:06:15.876025431Z","rtype":160,"publisher_id":101,"instrument_id":436},"action":"C","side":"B","price":"1.156690000","size":30,"channel_id":23,"order_id":"10998903205462128792","flags":0,"ts_in_delta":1159,"sequence":180829,"symbol":"FCEU SI 20260615 PS"}
{"ts_recv":"2026-04-07T03:06:15.876055527Z","hd":{"ts_event":"2026-04-07T03:06:15.876025431Z","rtype":160,"publisher_id":101,"instrument_id":436},"action":"A","side":"B","price":"1.156680000","size":30,"channel_id":23,"order_id":"10998903212730812441","flags":0,"ts_in_delta":1159,"sequence":180829,"symbol":"FCEU SI 20260615 PS"}
{"ts_recv":"2026-04-07T03:06:15.876055527Z","hd":{"ts_event":"2026-04-07T03:06:15.876025431Z","rtype":160,"publisher_id":101,"instrument_id":436},"action":"C","side":"A","price":"1.156790000","size":30,"channel_id":23,"order_id":"1775531168607352984","flags":0,"ts_in_delta":1159,"sequence":180829,"symbol":"FCEU SI 20260615 PS"}
{"ts_recv":"2026-04-07T03:06:15.876055527Z","hd":{"ts_event":"2026-04-07T03:06:15.876025431Z","rtype":160,"publisher_id":101,"instrument_id":436},"action":"A","side":"A","price":"1.156780000","size":30,"channel_id":23,"order_id":"1775531175876036633","flags":128,"ts_in_delta":1159,"sequence":180829,"symbol":"FCEU SI 20260615 PS"}
{"ts_recv":"2026-04-07T03:06:15.876125166Z","hd":{"ts_event":"2026-04-07T03:06:15.876102355Z","rtype":160,"publisher_id":101,"instrument_id":436},"action":"C","side":"B","price":"1.156690000","size":30,"channel_id":23,"order_id":"10998903179436217411","flags":0,"ts_in_delta":899,"sequence":180830,"symbol":"FCEU SI 20260615 PS"}
{"ts_recv":"2026-04-07T03:06:15.876125166Z","hd":{"ts_event":"2026-04-07T03:06:15.876102355Z","rtype":160,"publisher_id":101,"instrument_id":436},"action":"A","side":"B","price":"1.156670000","size":30,"channel_id":23,"order_id":"10998903212730884559","flags":0,"ts_in_delta":899,"sequence":180830,"symbol":"FCEU SI 20260615 PS"}
{"ts_recv":"2026-04-07T03:06:15.876125166Z","hd":{"ts_event":"2026-04-07T03:06:15.876102355Z","rtype":160,"publisher_id":101,"instrument_id":436},"action":"C","side":"A","price":"1.156790000","size":30,"channel_id":23,"order_id":"1775531142581441603","flags":0,"ts_in_delta":899,"sequence":180830,"symbol":"FCEU SI 20260615 PS"}
{"ts_recv":"2026-04-07T03:06:15.876125166Z","hd":{"ts_event":"2026-04-07T03:06:15.876102355Z","rtype":160,"publisher_id":101,"instrument_id":436},"action":"A","side":"A","price":"1.156770000","size":30,"channel_id":23,"order_id":"1775531175876108751","flags":128,"ts_in_delta":899,"sequence":180830,"symbol":"FCEU SI 20260615 PS"}
{"ts_recv":"2026-04-07T03:06:15.876210019Z","hd":{"ts_event":"2026-04-07T03:06:15.876190695Z","rtype":160,"publisher_id":101,"instrument_id":436},"action":"C","side":"B","price":"1.156680000","size":30,"channel_id":23,"order_id":"10998903212730812441","flags":0,"ts_in_delta":897,"sequence":180832,"symbol":"FCEU SI 20260615 PS"}
{"ts_recv":"2026-04-07T03:06:15.876210019Z","hd":{"ts_event":"2026-04-07T03:06:15.876190695Z","rtype":160,"publisher_id":101,"instrument_id":436},"action":"A","side":"B","price":"1.156670000","size":30,"channel_id":23,"order_id":"10998903212730972801","flags":0,"ts_in_delta":897,"sequence":180832,"symbol":"FCEU SI 20260615 PS"}
{"ts_recv":"2026-04-07T03:06:15.876210019Z","hd":{"ts_event":"2026-04-07T03:06:15.876190695Z","rtype":160,"publisher_id":101,"instrument_id":436},"action":"C","side":"A","price":"1.156780000","size":30,"channel_id":23,"order_id":"1775531175876036633","flags":0,"ts_in_delta":897,"sequence":180832,"symbol":"FCEU SI 20260615 PS"}
{"ts_recv":"2026-04-07T03:06:15.876210019Z","hd":{"ts_event":"2026-04-07T03:06:15.876190695Z","rtype":160,"publisher_id":101,"instrument_id":436},"action":"A","side":"A","price":"1.156770000","size":30,"channel_id":23,"order_id":"1775531175876196993","flags":128,"ts_in_delta":897,"sequence":180832,"symbol":"FCEU SI 20260615 PS"}
{"ts_recv":"2026-04-07T03:06:15.887431635Z","hd":{"ts_event":"2026-04-07T03:06:15.887411687Z","rtype":160,"publisher_id":101,"instrument_id":436},"action":"C","side":"B","price":"1.156670000","size":30,"channel_id":23,"order_id":"10998903212730884559","flags":0,"ts_in_delta":922,"sequence":180839,"symbol":"FCEU SI 20260615 PS"}
{"ts_recv":"2026-04-07T03:06:15.887431635Z","hd":{"ts_event":"2026-04-07T03:06:15.887411687Z","rtype":160,"publisher_id":101,"instrument_id":436},"action":"A","side":"B","price":"1.156650000","size":30,"channel_id":23,"order_id":"10998903212742193576","flags":0,"ts_in_delta":922,"sequence":180839,"symbol":"FCEU SI 20260615 PS"}
{"ts_recv":"2026-04-07T03:06:15.887431635Z","hd":{"ts_event":"2026-04-07T03:06:15.887411687Z","rtype":160,"publisher_id":101,"instrument_id":436},"action":"C","side":"A","price":"1.156770000","size":30,"channel_id":23,"order_id":"1775531175876108751","flags":0,"ts_in_delta":922,"sequence":180839,"symbol":"FCEU SI 20260615 PS"}
{"ts_recv":"2026-04-07T03:06:15.887431635Z","hd":{"ts_event":"2026-04-07T03:06:15.887411687Z","rtype":160,"publisher_id":101,"instrument_id":436},"action":"A","side":"A","price":"1.156750000","size":30,"channel_id":23,"order_id":"1775531175887417768","flags":128,"ts_in_delta":922,"sequence":180839,"symbol":"FCEU SI 20260615 PS"}
{"ts_recv":"2026-04-07T03:06:15.887495192Z","hd":{"ts_event":"2026-04-07T03:06:15.887479591Z","rtype":160,"publisher_id":101,"instrument_id":436},"action":"C","side":"B","price":"1.156670000","size":30,"channel_id":23,"order_id":"10998903212730972801","flags":0,"ts_in_delta":922,"sequence":180840,"symbol":"FCEU SI 20260615 PS"}
{"ts_recv":"2026-04-07T03:06:15.887495192Z","hd":{"ts_event":"2026-04-07T03:06:15.887479591Z","rtype":160,"publisher_id":101,"instrument_id":436},"action":"A","side":"B","price":"1.156660000","size":30,"channel_id":23,"order_id":"10998903212742261278","flags":0,"ts_in_delta":922,"sequence":180840,"symbol":"FCEU SI 20260615 PS"}
{"ts_recv":"2026-04-07T03:06:15.887495192Z","hd":{"ts_event":"2026-04-07T03:06:15.887479591Z","rtype":160,"publisher_id":101,"instrument_id":436},"action":"C","side":"A","price":"1.156770000","size":30,"channel_id":23,"order_id":"1775531175876196993","flags":0,"ts_in_delta":922,"sequence":180840,"symbol":"FCEU SI 20260615 PS"}
{"ts_recv":"2026-04-07T03:06:15.887495192Z","hd":{"ts_event":"2026-04-07T03:06:15.887479591Z","rtype":160,"publisher_id":101,"instrument_id":436},"action":"A","side":"A","price":"1.156760000","size":30,"channel_id":23,"order_id":"1775531175887485470","flags":128,"ts_in_delta":922,"sequence":180840,"symbol":"FCEU SI 20260615 PS"}
{"ts_recv":"2026-04-07T03:06:15.890392385Z","hd":{"ts_event":"2026-04-07T03:06:15.890376071Z","rtype":160,"publisher_id":101,"instrument_id":436},"action":"C","side":"B","price":"1.156660000","size":30,"channel_id":23,"order_id":"10998903212742261278","flags":0,"ts_in_delta":897,"sequence":180843,"symbol":"FCEU SI 20260615 PS"}
{"ts_recv":"2026-04-07T03:06:15.890392385Z","hd":{"ts_event":"2026-04-07T03:06:15.890376071Z","rtype":160,"publisher_id":101,"instrument_id":436},"action":"A","side":"B","price":"1.156650000","size":30,"channel_id":23,"order_id":"10998903212745158405","flags":0,"ts_in_delta":897,"sequence":180843,"symbol":"FCEU SI 20260615 PS"}
{"ts_recv":"2026-04-07T03:06:15.890392385Z","hd":{"ts_event":"2026-04-07T03:06:15.890376071Z","rtype":160,"publisher_id":101,"instrument_id":436},"action":"C","side":"A","price":"1.156760000","size":30,"channel_id":23,"order_id":"1775531175887485470","flags":0,"ts_in_delta":897,"sequence":180843,"symbol":"FCEU SI 20260615 PS"}
{"ts_recv":"2026-04-07T03:06:15.890392385Z","hd":{"ts_event":"2026-04-07T03:06:15.890376071Z","rtype":160,"publisher_id":101,"instrument_id":436},"action":"A","side":"A","price":"1.156750000","size":30,"channel_id":23,"order_id":"1775531175890382597","flags":128,"ts_in_delta":897,"sequence":180843,"symbol":"FCEU SI 20260615 PS"}
{"ts_recv":"2026-04-07T03:06:15.927312436Z","hd":{"ts_event":"2026-04-07T03:06:15.927296499Z","rtype":160,"publisher_id":101,"instrument_id":436},"action":"A","side":"A","price":"1.156900000","size":20,"channel_id":23,"order_id":"1775531175927302760","flags":128,"ts_in_delta":818,"sequence":180847,"symbol":"FCEU SI 20260615 PS"}
{"ts_recv":"2026-04-07T03:06:15.927523273Z","hd":{"ts_event":"2026-04-07T03:06:15.927508391Z","rtype":160,"publisher_id":101,"instrument_id":436},"action":"C","side":"A","price":"1.157000000","size":20,"channel_id":23,"order_id":"1775530848303169499","flags":128,"ts_in_delta":800,"sequence":180848,"symbol":"FCEU SI 20260615 PS"}
{"ts_recv":"2026-04-07T03:06:25.607630486Z","hd":{"ts_event":"2026-04-07T03:06:25.607601639Z","rtype":160,"publisher_id":101,"instrument_id":436},"action":"C","side":"B","price":"1.156650000","size":30,"channel_id":23,"order_id":"10998903212745158405","flags":0,"ts_in_delta":960,"sequence":180927,"symbol":"FCEU SI 20260615 PS"}
{"ts_recv":"2026-04-07T03:06:25.607630486Z","hd":{"ts_event":"2026-04-07T03:06:25.607601639Z","rtype":160,"publisher_id":101,"instrument_id":436},"action":"A","side":"B","price":"1.156640000","size":30,"channel_id":23,"order_id":"10998903222462388458","flags":0,"ts_in_delta":960,"sequence":180927,"symbol":"FCEU SI 20260615 PS"}
{"ts_recv":"2026-04-07T03:06:25.607630486Z","hd":{"ts_event":"2026-04-07T03:06:25.607601639Z","rtype":160,"publisher_id":101,"instrument_id":436},"action":"C","side":"A","price":"1.156750000","size":30,"channel_id":23,"order_id":"1775531175890382597","flags":0,"ts_in_delta":960,"sequence":180927,"symbol":"FCEU SI 20260615 PS"}
{"ts_recv":"2026-04-07T03:06:25.607630486Z","hd":{"ts_event":"2026-04-07T03:06:25.607601639Z","rtype":160,"publisher_id":101,"instrument_id":436},"action":"A","side":"A","price":"1.156740000","size":30,"channel_id":23,"order_id":"1775531185607612650","flags":128,"ts_in_delta":960,"sequence":180927,"symbol":"FCEU SI 20260615 PS"}
{"ts_recv":"2026-04-07T03:06:30.172288734Z","hd":{"ts_event":"2026-04-07T03:06:30.172255789Z","rtype":160,"publisher_id":101,"instrument_id":436},"action":"C","side":"B","price":"1.156600000","size":20,"channel_id":23,"order_id":"10998903137121931343","flags":128,"ts_in_delta":815,"sequence":180947,"symbol":"FCEU SI 20260615 PS"}
{"ts_recv":"2026-04-07T03:06:30.244829598Z","hd":{"ts_event":"2026-04-07T03:06:30.244812613Z","rtype":160,"publisher_id":101,"instrument_id":436},"action":"A","side":"B","price":"1.156500000","size":20,"channel_id":23,"order_id":"10998903227099594535","flags":128,"ts_in_delta":1217,"sequence":180952,"symbol":"FCEU SI 20260615 PS"}
{"ts_recv":"2026-04-07T03:06:39.122873949Z","hd":{"ts_event":"2026-04-07T03:06:39.122854023Z","rtype":160,"publisher_id":101,"instrument_id":436},"action":"C","side":"B","price":"1.156640000","size":30,"channel_id":23,"order_id":"10998903222462388458","flags":0,"ts_in_delta":951,"sequence":180999,"symbol":"FCEU SI 20260615 PS"}
{"ts_recv":"2026-04-07T03:06:39.122873949Z","hd":{"ts_event":"2026-04-07T03:06:39.122854023Z","rtype":160,"publisher_id":101,"instrument_id":436},"action":"A","side":"B","price":"1.156650000","size":30,"channel_id":23,"order_id":"10998903235977636146","flags":0,"ts_in_delta":951,"sequence":180999,"symbol":"FCEU SI 20260615 PS"}
{"ts_recv":"2026-04-07T03:06:39.122873949Z","hd":{"ts_event":"2026-04-07T03:06:39.122854023Z","rtype":160,"publisher_id":101,"instrument_id":436},"action":"C","side":"A","price":"1.156740000","size":30,"channel_id":23,"order_id":"1775531185607612650","flags":0,"ts_in_delta":951,"sequence":180999,"symbol":"FCEU SI 20260615 PS"}
{"ts_recv":"2026-04-07T03:06:39.122873949Z","hd":{"ts_event":"2026-04-07T03:06:39.122854023Z","rtype":160,"publisher_id":101,"instrument_id":436},"action":"A","side":"A","price":"1.156750000","size":30,"channel_id":23,"order_id":"1775531199122860338","flags":128,"ts_in_delta":951,"sequence":180999,"symbol":"FCEU SI 20260615 PS"}
{"ts_recv":"2026-04-07T03:06:40.277316824Z","hd":{"ts_event":"2026-04-07T03:06:40.277295661Z","rtype":160,"publisher_id":101,"instrument_id":436},"action":"C","side":"B","price":"1.156650000","size":30,"channel_id":23,"order_id":"10998903235977636146","flags":0,"ts_in_delta":927,"sequence":181037,"symbol":"FCEU SI 20260615 PS"}
{"ts_recv":"2026-04-07T03:06:40.277316824Z","hd":{"ts_event":"2026-04-07T03:06:40.277295661Z","rtype":160,"publisher_id":101,"instrument_id":436},"action":"A","side":"B","price":"1.156660000","size":30,"channel_id":23,"order_id":"10998903237132077455","flags":0,"ts_in_delta":927,"sequence":181037,"symbol":"FCEU SI 20260615 PS"}
{"ts_recv":"2026-04-07T03:06:40.277316824Z","hd":{"ts_event":"2026-04-07T03:06:40.277295661Z","rtype":160,"publisher_id":101,"instrument_id":436},"action":"C","side":"A","price":"1.156750000","size":30,"channel_id":23,"order_id":"1775531199122860338","flags":0,"ts_in_delta":927,"sequence":181037,"symbol":"FCEU SI 20260615 PS"}
{"ts_recv":"2026-04-07T03:06:40.277316824Z","hd":{"ts_event":"2026-04-07T03:06:40.277295661Z","rtype":160,"publisher_id":101,"instrument_id":436},"action":"A","side":"A","price":"1.156760000","size":30,"channel_id":23,"order_id":"1775531200277301647","flags":128,"ts_in_delta":927,"sequence":181037,"symbol":"FCEU SI 20260615 PS"}
{"ts_recv":"2026-04-07T03:06:40.277399019Z","hd":{"ts_event":"2026-04-07T03:06:40.277381249Z","rtype":160,"publisher_id":101,"instrument_id":436},"action":"C","side":"B","price":"1.156660000","size":30,"channel_id":23,"order_id":"10998903237132077455","flags":0,"ts_in_delta":912,"sequence":181038,"symbol":"FCEU SI 20260615 PS"}
{"ts_recv":"2026-04-07T03:06:40.277399019Z","hd":{"ts_event":"2026-04-07T03:06:40.277381249Z","rtype":160,"publisher_id":101,"instrument_id":436},"action":"A","side":"B","price":"1.156670000","size":30,"channel_id":23,"order_id":"10998903237132162866","flags":0,"ts_in_delta":912,"sequence":181038,"symbol":"FCEU SI 20260615 PS"}
{"ts_recv":"2026-04-07T03:06:40.277399019Z","hd":{"ts_event":"2026-04-07T03:06:40.277381249Z","rtype":160,"publisher_id":101,"instrument_id":436},"action":"C","side":"A","price":"1.156760000","size":30,"channel_id":23,"order_id":"1775531200277301647","flags":0,"ts_in_delta":912,"sequence":181038,"symbol":"FCEU SI 20260615 PS"}
{"ts_recv":"2026-04-07T03:06:40.277399019Z","hd":{"ts_event":"2026-04-07T03:06:40.277381249Z","rtype":160,"publisher_id":101,"instrument_id":436},"action":"A","side":"A","price":"1.156770000","size":30,"channel_id":23,"order_id":"1775531200277387058","flags":128,"ts_in_delta":912,"sequence":181038,"symbol":"FCEU SI 20260615 PS"}
{"ts_recv":"2026-04-07T03:06:40.277459066Z","hd":{"ts_event":"2026-04-07T03:06:40.277439529Z","rtype":160,"publisher_id":101,"instrument_id":436},"action":"C","side":"B","price":"1.156650000","size":30,"channel_id":23,"order_id":"10998903212742193576","flags":0,"ts_in_delta":926,"sequence":181039,"symbol":"FCEU SI 20260615 PS"}
{"ts_recv":"2026-04-07T03:06:40.277459066Z","hd":{"ts_event":"2026-04-07T03:06:40.277439529Z","rtype":160,"publisher_id":101,"instrument_id":436},"action":"A","side":"B","price":"1.156670000","size":30,"channel_id":23,"order_id":"10998903237132221386","flags":0,"ts_in_delta":926,"sequence":181039,"symbol":"FCEU SI 20260615 PS"}
{"ts_recv":"2026-04-07T03:06:40.277459066Z","hd":{"ts_event":"2026-04-07T03:06:40.277439529Z","rtype":160,"publisher_id":101,"instrument_id":436},"action":"C","side":"A","price":"1.156750000","size":30,"channel_id":23,"order_id":"1775531175887417768","flags":0,"ts_in_delta":926,"sequence":181039,"symbol":"FCEU SI 20260615 PS"}
{"ts_recv":"2026-04-07T03:06:40.277459066Z","hd":{"ts_event":"2026-04-07T03:06:40.277439529Z","rtype":160,"publisher_id":101,"instrument_id":436},"action":"A","side":"A","price":"1.156770000","size":30,"channel_id":23,"order_id":"1775531200277445578","flags":128,"ts_in_delta":926,"sequence":181039,"symbol":"FCEU SI 20260615 PS"}
{"ts_recv":"2026-04-07T03:06:40.277469580Z","hd":{"ts_event":"2026-04-07T03:06:40.277441563Z","rtype":160,"publisher_id":101,"instrument_id":436},"action":"C","side":"B","price":"1.156670000","size":30,"channel_id":23,"order_id":"10998903237132162866","flags":0,"ts_in_delta":921,"sequence":181040,"symbol":"FCEU SI 20260615 PS"}
{"ts_recv":"2026-04-07T03:06:40.277469580Z","hd":{"ts_event":"2026-04-07T03:06:40.277441563Z","rtype":160,"publisher_id":101,"instrument_id":436},"action":"A","side":"B","price":"1.156660000","size":30,"channel_id":23,"order_id":"10998903237132231737","flags":0,"ts_in_delta":921,"sequence":181040,"symbol":"FCEU SI 20260615 PS"}
{"ts_recv":"2026-04-07T03:06:40.277469580Z","hd":{"ts_event":"2026-04-07T03:06:40.277441563Z","rtype":160,"publisher_id":101,"instrument_id":436},"action":"C","side":"A","price":"1.156770000","size":30,"channel_id":23,"order_id":"1775531200277387058","flags":0,"ts_in_delta":921,"sequence":181040,"symbol":"FCEU SI 20260615 PS"}
{"ts_recv":"2026-04-07T03:06:40.277469580Z","hd":{"ts_event":"2026-04-07T03:06:40.277441563Z","rtype":160,"publisher_id":101,"instrument_id":436},"action":"A","side":"A","price":"1.156760000","size":30,"channel_id":23,"order_id":"1775531200277455929","flags":128,"ts_in_delta":921,"sequence":181040,"symbol":"FCEU SI 20260615 PS"}
{"ts_recv":"2026-04-07T03:06:40.277527354Z","hd":{"ts_event":"2026-04-07T03:06:40.277510285Z","rtype":160,"publisher_id":101,"instrument_id":436},"action":"C","side":"B","price":"1.156660000","size":30,"channel_id":23,"order_id":"10998903237132231737","flags":0,"ts_in_delta":938,"sequence":181041,"symbol":"FCEU SI 20260615 PS"}
{"ts_recv":"2026-04-07T03:06:40.277527354Z","hd":{"ts_event":"2026-04-07T03:06:40.277510285Z","rtype":160,"publisher_id":101,"instrument_id":436},"action":"A","side":"B","price":"1.156670000","size":30,"channel_id":23,"order_id":"10998903237132292146","flags":0,"ts_in_delta":938,"sequence":181041,"symbol":"FCEU SI 20260615 PS"}
{"ts_recv":"2026-04-07T03:06:40.277527354Z","hd":{"ts_event":"2026-04-07T03:06:40.277510285Z","rtype":160,"publisher_id":101,"instrument_id":436},"action":"C","side":"A","price":"1.156760000","size":30,"channel_id":23,"order_id":"1775531200277455929","flags":0,"ts_in_delta":938,"sequence":181041,"symbol":"FCEU SI 20260615 PS"}
{"ts_recv":"2026-04-07T03:06:40.277527354Z","hd":{"ts_event":"2026-04-07T03:06:40.277510285Z","rtype":160,"publisher_id":101,"instrument_id":436},"action":"A","side":"A","price":"1.156770000","size":30,"channel_id":23,"order_id":"1775531200277516338","flags":128,"ts_in_delta":938,"sequence":181041,"symbol":"FCEU SI 20260615 PS"}
{"ts_recv":"2026-04-07T03:06:40.874043438Z","hd":{"ts_event":"2026-04-07T03:06:40.874016483Z","rtype":160,"publisher_id":101,"instrument_id":436},"action":"C","side":"B","price":"1.156670000","size":30,"channel_id":23,"order_id":"10998903237132292146","flags":0,"ts_in_delta":1331,"sequence":181057,"symbol":"FCEU SI 20260615 PS"}
{"ts_recv":"2026-04-07T03:06:40.874043438Z","hd":{"ts_event":"2026-04-07T03:06:40.874016483Z","rtype":160,"publisher_id":101,"instrument_id":436},"action":"A","side":"B","price":"1.156680000","size":30,"channel_id":23,"order_id":"10998903237728802825","flags":0,"ts_in_delta":1331,"sequence":181057,"symbol":"FCEU SI 20260615 PS"}
{"ts_recv":"2026-04-07T03:06:40.874043438Z","hd":{"ts_event":"2026-04-07T03:06:40.874016483Z","rtype":160,"publisher_id":101,"instrument_id":436},"action":"C","side":"A","price":"1.156770000","size":30,"channel_id":23,"order_id":"1775531200277516338","flags":0,"ts_in_delta":1331,"sequence":181057,"symbol":"FCEU SI 20260615 PS"}
{"ts_recv":"2026-04-07T03:06:40.874043438Z","hd":{"ts_event":"2026-04-07T03:06:40.874016483Z","rtype":160,"publisher_id":101,"instrument_id":436},"action":"A","side":"A","price":"1.156780000","size":30,"channel_id":23,"order_id":"1775531200874027017","flags":128,"ts_in_delta":1331,"sequence":181057,"symbol":"FCEU SI 20260615 PS"}
{"ts_recv":"2026-04-07T03:06:40.888400026Z","hd":{"ts_event":"2026-04-07T03:06:40.888381081Z","rtype":160,"publisher_id":101,"instrument_id":436},"action":"C","side":"B","price":"1.156680000","size":30,"channel_id":23,"order_id":"10998903237728802825","flags":0,"ts_in_delta":874,"sequence":181060,"symbol":"FCEU SI 20260615 PS"}
{"ts_recv":"2026-04-07T03:06:40.888400026Z","hd":{"ts_event":"2026-04-07T03:06:40.888381081Z","rtype":160,"publisher_id":101,"instrument_id":436},"action":"A","side":"B","price":"1.156670000","size":30,"channel_id":23,"order_id":"10998903237743162642","flags":0,"ts_in_delta":874,"sequence":181060,"symbol":"FCEU SI 20260615 PS"}
{"ts_recv":"2026-04-07T03:06:40.888400026Z","hd":{"ts_event":"2026-04-07T03:06:40.888381081Z","rtype":160,"publisher_id":101,"instrument_id":436},"action":"C","side":"A","price":"1.156780000","size":30,"channel_id":23,"order_id":"1775531200874027017","flags":0,"ts_in_delta":874,"sequence":181060,"symbol":"FCEU SI 20260615 PS"}
{"ts_recv":"2026-04-07T03:06:40.888400026Z","hd":{"ts_event":"2026-04-07T03:06:40.888381081Z","rtype":160,"publisher_id":101,"instrument_id":436},"action":"A","side":"A","price":"1.156770000","size":30,"channel_id":23,"order_id":"1775531200888386834","flags":128,"ts_in_delta":874,"sequence":181060,"symbol":"FCEU SI 20260615 PS"}
{"ts_recv":"2026-04-07T03:06:40.893200467Z","hd":{"ts_event":"2026-04-07T03:06:40.893180041Z","rtype":160,"publisher_id":101,"instrument_id":436},"action":"C","side":"B","price":"1.156670000","size":30,"channel_id":23,"order_id":"10998903237743162642","flags":0,"ts_in_delta":978,"sequence":181067,"symbol":"FCEU SI 20260615 PS"}
{"ts_recv":"2026-04-07T03:06:40.893200467Z","hd":{"ts_event":"2026-04-07T03:06:40.893180041Z","rtype":160,"publisher_id":101,"instrument_id":436},"action":"A","side":"B","price":"1.156660000","size":30,"channel_id":23,"order_id":"10998903237747961894","flags":0,"ts_in_delta":978,"sequence":181067,"symbol":"FCEU SI 20260615 PS"}
{"ts_recv":"2026-04-07T03:06:40.893200467Z","hd":{"ts_event":"2026-04-07T03:06:40.893180041Z","rtype":160,"publisher_id":101,"instrument_id":436},"action":"C","side":"A","price":"1.156770000","size":30,"channel_id":23,"order_id":"1775531200888386834","flags":0,"ts_in_delta":978,"sequence":181067,"symbol":"FCEU SI 20260615 PS"}
{"ts_recv":"2026-04-07T03:06:40.893200467Z","hd":{"ts_event":"2026-04-07T03:06:40.893180041Z","rtype":160,"publisher_id":101,"instrument_id":436},"action":"A","side":"A","price":"1.156760000","size":30,"channel_id":23,"order_id":"1775531200893186086","flags":128,"ts_in_delta":978,"sequence":181067,"symbol":"FCEU SI 20260615 PS"}
{"ts_recv":"2026-04-07T03:06:40.920107620Z","hd":{"ts_event":"2026-04-07T03:06:40.920088043Z","rtype":160,"publisher_id":101,"instrument_id":436},"action":"C","side":"B","price":"1.156670000","size":30,"channel_id":23,"order_id":"10998903237132221386","flags":0,"ts_in_delta":1120,"sequence":181070,"symbol":"FCEU SI 20260615 PS"}
{"ts_recv":"2026-04-07T03:06:40.920107620Z","hd":{"ts_event":"2026-04-07T03:06:40.920088043Z","rtype":160,"publisher_id":101,"instrument_id":436},"action":"A","side":"B","price":"1.156650000","size":30,"channel_id":23,"order_id":"10998903237774869715","flags":0,"ts_in_delta":1120,"sequence":181070,"symbol":"FCEU SI 20260615 PS"}
{"ts_recv":"2026-04-07T03:06:40.920107620Z","hd":{"ts_event":"2026-04-07T03:06:40.920088043Z","rtype":160,"publisher_id":101,"instrument_id":436},"action":"C","side":"A","price":"1.156770000","size":30,"channel_id":23,"order_id":"1775531200277445578","flags":0,"ts_in_delta":1120,"sequence":181070,"symbol":"FCEU SI 20260615 PS"}
{"ts_recv":"2026-04-07T03:06:40.920107620Z","hd":{"ts_event":"2026-04-07T03:06:40.920088043Z","rtype":160,"publisher_id":101,"instrument_id":436},"action":"A","side":"A","price":"1.156750000","size":30,"channel_id":23,"order_id":"1775531200920093907","flags":128,"ts_in_delta":1120,"sequence":181070,"symbol":"FCEU SI 20260615 PS"}
{"ts_recv":"2026-04-07T03:06:40.920164303Z","hd":{"ts_event":"2026-04-07T03:06:40.920148465Z","rtype":160,"publisher_id":101,"instrument_id":436},"action":"C","side":"B","price":"1.156660000","size":30,"channel_id":23,"order_id":"10998903237747961894","flags":0,"ts_in_delta":1055,"sequence":181071,"symbol":"FCEU SI 20260615 PS"}
{"ts_recv":"2026-04-07T03:06:40.920164303Z","hd":{"ts_event":"2026-04-07T03:06:40.920148465Z","rtype":160,"publisher_id":101,"instrument_id":436},"action":"A","side":"B","price":"1.156650000","size":30,"channel_id":23,"order_id":"10998903237774929878","flags":0,"ts_in_delta":1055,"sequence":181071,"symbol":"FCEU SI 20260615 PS"}
{"ts_recv":"2026-04-07T03:06:40.920164303Z","hd":{"ts_event":"2026-04-07T03:06:40.920148465Z","rtype":160,"publisher_id":101,"instrument_id":436},"action":"C","side":"A","price":"1.156760000","size":30,"channel_id":23,"order_id":"1775531200893186086","flags":0,"ts_in_delta":1055,"sequence":181071,"symbol":"FCEU SI 20260615 PS"}
{"ts_recv":"2026-04-07T03:06:40.920164303Z","hd":{"ts_event":"2026-04-07T03:06:40.920148465Z","rtype":160,"publisher_id":101,"instrument_id":436},"action":"A","side":"A","price":"1.156750000","size":30,"channel_id":23,"order_id":"1775531200920154070","flags":128,"ts_in_delta":1055,"sequence":181071,"symbol":"FCEU SI 20260615 PS"}
{"ts_recv":"2026-04-07T03:06:43.130821155Z","hd":{"ts_event":"2026-04-07T03:06:43.130788001Z","rtype":160,"publisher_id":101,"instrument_id":436},"action":"C","side":"B","price":"1.156650000","size":30,"channel_id":23,"order_id":"10998903237774929878","flags":0,"ts_in_delta":2442,"sequence":181098,"symbol":"FCEU SI 20260615 PS"}
{"ts_recv":"2026-04-07T03:06:43.130821155Z","hd":{"ts_event":"2026-04-07T03:06:43.130788001Z","rtype":160,"publisher_id":101,"instrument_id":436},"action":"A","side":"B","price":"1.156640000","size":30,"channel_id":23,"order_id":"10998903239985577344","flags":0,"ts_in_delta":2442,"sequence":181098,"symbol":"FCEU SI 20260615 PS"}
{"ts_recv":"2026-04-07T03:06:43.130821155Z","hd":{"ts_event":"2026-04-07T03:06:43.130788001Z","rtype":160,"publisher_id":101,"instrument_id":436},"action":"C","side":"A","price":"1.156750000","size":30,"channel_id":23,"order_id":"1775531200920154070","flags":0,"ts_in_delta":2442,"sequence":181098,"symbol":"FCEU SI 20260615 PS"}
{"ts_recv":"2026-04-07T03:06:43.130821155Z","hd":{"ts_event":"2026-04-07T03:06:43.130788001Z","rtype":160,"publisher_id":101,"instrument_id":436},"action":"A","side":"A","price":"1.156740000","size":30,"channel_id":23,"order_id":"1775531203130801536","flags":128,"ts_in_delta":2442,"sequence":181098,"symbol":"FCEU SI 20260615 PS"}
{"ts_recv":"2026-04-07T03:06:43.130889892Z","hd":{"ts_event":"2026-04-07T03:06:43.130871829Z","rtype":160,"publisher_id":101,"instrument_id":436},"action":"C","side":"B","price":"1.156640000","size":30,"channel_id":23,"order_id":"10998903239985577344","flags":0,"ts_in_delta":920,"sequence":181099,"symbol":"FCEU SI 20260615 PS"}
{"ts_recv":"2026-04-07T03:06:43.130889892Z","hd":{"ts_event":"2026-04-07T03:06:43.130871829Z","rtype":160,"publisher_id":101,"instrument_id":436},"action":"A","side":"B","price":"1.156630000","size":30,"channel_id":23,"order_id":"10998903239985653660","flags":0,"ts_in_delta":920,"sequence":181099,"symbol":"FCEU SI 20260615 PS"}
{"ts_recv":"2026-04-07T03:06:43.130889892Z","hd":{"ts_event":"2026-04-07T03:06:43.130871829Z","rtype":160,"publisher_id":101,"instrument_id":436},"action":"C","side":"A","price":"1.156740000","size":30,"channel_id":23,"order_id":"1775531203130801536","flags":0,"ts_in_delta":920,"sequence":181099,"symbol":"FCEU SI 20260615 PS"}
{"ts_recv":"2026-04-07T03:06:43.130889892Z","hd":{"ts_event":"2026-04-07T03:06:43.130871829Z","rtype":160,"publisher_id":101,"instrument_id":436},"action":"A","side":"A","price":"1.156730000","size":30,"channel_id":23,"order_id":"1775531203130877852","flags":128,"ts_in_delta":920,"sequence":181099,"symbol":"FCEU SI 20260615 PS"}
{"ts_recv":"2026-04-07T03:06:43.130945432Z","hd":{"ts_event":"2026-04-07T03:06:43.130928085Z","rtype":160,"publisher_id":101,"instrument_id":436},"action":"C","side":"B","price":"1.156630000","size":30,"channel_id":23,"order_id":"10998903239985653660","flags":0,"ts_in_delta":881,"sequence":181100,"symbol":"FCEU SI 20260615 PS"}
{"ts_recv":"2026-04-07T03:06:43.130945432Z","hd":{"ts_event":"2026-04-07T03:06:43.130928085Z","rtype":160,"publisher_id":101,"instrument_id":436},"action":"A","side":"B","price":"1.156640000","size":30,"channel_id":23,"order_id":"10998903239985709853","flags":0,"ts_in_delta":881,"sequence":181100,"symbol":"FCEU SI 20260615 PS"}
{"ts_recv":"2026-04-07T03:06:43.130945432Z","hd":{"ts_event":"2026-04-07T03:06:43.130928085Z","rtype":160,"publisher_id":101,"instrument_id":436},"action":"C","side":"A","price":"1.156730000","size":30,"channel_id":23,"order_id":"1775531203130877852","flags":0,"ts_in_delta":881,"sequence":181100,"symbol":"FCEU SI 20260615 PS"}
{"ts_recv":"2026-04-07T03:06:43.130945432Z","hd":{"ts_event":"2026-04-07T03:06:43.130928085Z","rtype":160,"publisher_id":101,"instrument_id":436},"action":"A","side":"A","price":"1.156740000","size":30,"channel_id":23,"order_id":"1775531203130934045","flags":128,"ts_in_delta":881,"sequence":181100,"symbol":"FCEU SI 20260615 PS"}
{"ts_recv":"2026-04-07T03:07:08.692585215Z","hd":{"ts_event":"2026-04-07T03:07:08.692563973Z","rtype":160,"publisher_id":101,"instrument_id":436},"action":"C","side":"B","price":"1.156640000","size":30,"channel_id":23,"order_id":"10998903239985709853","flags":0,"ts_in_delta":906,"sequence":181301,"symbol":"FCEU SI 20260615 PS"}
{"ts_recv":"2026-04-07T03:07:08.692585215Z","hd":{"ts_event":"2026-04-07T03:07:08.692563973Z","rtype":160,"publisher_id":101,"instrument_id":436},"action":"A","side":"B","price":"1.156650000","size":30,"channel_id":23,"order_id":"10998903265547345937","flags":0,"ts_in_delta":906,"sequence":181301,"symbol":"FCEU SI 20260615 PS"}
{"ts_recv":"2026-04-07T03:07:08.692585215Z","hd":{"ts_event":"2026-04-07T03:07:08.692563973Z","rtype":160,"publisher_id":101,"instrument_id":436},"action":"C","side":"A","price":"1.156740000","size":30,"channel_id":23,"order_id":"1775531203130934045","flags":0,"ts_in_delta":906,"sequence":181301,"symbol":"FCEU SI 20260615 PS"}
{"ts_recv":"2026-04-07T03:07:08.692585215Z","hd":{"ts_event":"2026-04-07T03:07:08.692563973Z","rtype":160,"publisher_id":101,"instrument_id":436},"action":"A","side":"A","price":"1.156750000","size":30,"channel_id":23,"order_id":"1775531228692570129","flags":128,"ts_in_delta":906,"sequence":181301,"symbol":"FCEU SI 20260615 PS"}
{"ts_recv":"2026-04-07T03:07:08.720351466Z","hd":{"ts_event":"2026-04-07T03:07:08.720330701Z","rtype":160,"publisher_id":101,"instrument_id":436},"action":"C","side":"B","price":"1.156650000","size":30,"channel_id":23,"order_id":"10998903265547345937","flags":0,"ts_in_delta":976,"sequence":181305,"symbol":"FCEU SI 20260615 PS"}
{"ts_recv":"2026-04-07T03:07:08.720351466Z","hd":{"ts_event":"2026-04-07T03:07:08.720330701Z","rtype":160,"publisher_id":101,"instrument_id":436},"action":"A","side":"B","price":"1.156640000","size":30,"channel_id":23,"order_id":"10998903265575112328","flags":0,"ts_in_delta":976,"sequence":181305,"symbol":"FCEU SI 20260615 PS"}
{"ts_recv":"2026-04-07T03:07:08.720351466Z","hd":{"ts_event":"2026-04-07T03:07:08.720330701Z","rtype":160,"publisher_id":101,"instrument_id":436},"action":"C","side":"A","price":"1.156750000","size":30,"channel_id":23,"order_id":"1775531228692570129","flags":0,"ts_in_delta":976,"sequence":181305,"symbol":"FCEU SI 20260615 PS"}
{"ts_recv":"2026-04-07T03:07:08.720351466Z","hd":{"ts_event":"2026-04-07T03:07:08.720330701Z","rtype":160,"publisher_id":101,"instrument_id":436},"action":"A","side":"A","price":"1.156740000","size":30,"channel_id":23,"order_id":"1775531228720336520","flags":128,"ts_in_delta":976,"sequence":181305,"symbol":"FCEU SI 20260615 PS"}
{"ts_recv":"2026-04-07T03:07:08.720429760Z","hd":{"ts_event":"2026-04-07T03:07:08.720412627Z","rtype":160,"publisher_id":101,"instrument_id":436},"action":"C","side":"B","price":"1.156640000","size":30,"channel_id":23,"order_id":"10998903265575112328","flags":0,"ts_in_delta":694,"sequence":181306,"symbol":"FCEU SI 20260615 PS"}
{"ts_recv":"2026-04-07T03:07:08.720429760Z","hd":{"ts_event":"2026-04-07T03:07:08.720412627Z","rtype":160,"publisher_id":101,"instrument_id":436},"action":"A","side":"B","price":"1.156630000","size":30,"channel_id":23,"order_id":"10998903265575194256","flags":0,"ts_in_delta":694,"sequence":181306,"symbol":"FCEU SI 20260615 PS"}
{"ts_recv":"2026-04-07T03:07:08.720429760Z","hd":{"ts_event":"2026-04-07T03:07:08.720412627Z","rtype":160,"publisher_id":101,"instrument_id":436},"action":"C","side":"A","price":"1.156740000","size":30,"channel_id":23,"order_id":"1775531228720336520","flags":0,"ts_in_delta":694,"sequence":181306,"symbol":"FCEU SI 20260615 PS"}
{"ts_recv":"2026-04-07T03:07:08.720429760Z","hd":{"ts_event":"2026-04-07T03:07:08.720412627Z","rtype":160,"publisher_id":101,"instrument_id":436},"action":"A","side":"A","price":"1.156730000","size":30,"channel_id":23,"order_id":"1775531228720418448","flags":128,"ts_in_delta":694,"sequence":181306,"symbol":"FCEU SI 20260615 PS"}
{"ts_recv":"2026-04-07T03:07:08.720494415Z","hd":{"ts_event":"2026-04-07T03:07:08.720476539Z","rtype":160,"publisher_id":101,"instrument_id":436},"action":"C","side":"B","price":"1.156630000","size":30,"channel_id":23,"order_id":"10998903265575194256","flags":0,"ts_in_delta":717,"sequence":181307,"symbol":"FCEU SI 20260615 PS"}
{"ts_recv":"2026-04-07T03:07:08.720494415Z","hd":{"ts_event":"2026-04-07T03:07:08.720476539Z","rtype":160,"publisher_id":101,"instrument_id":436},"action":"A","side":"B","price":"1.156640000","size":30,"channel_id":23,"order_id":"10998903265575258294","flags":0,"ts_in_delta":717,"sequence":181307,"symbol":"FCEU SI 20260615 PS"}
{"ts_recv":"2026-04-07T03:07:08.720494415Z","hd":{"ts_event":"2026-04-07T03:07:08.720476539Z","rtype":160,"publisher_id":101,"instrument_id":436},"action":"C","side":"A","price":"1.156730000","size":30,"channel_id":23,"order_id":"1775531228720418448","flags":0,"ts_in_delta":717,"sequence":181307,"symbol":"FCEU SI 20260615 PS"}
{"ts_recv":"2026-04-07T03:07:08.720494415Z","hd":{"ts_event":"2026-04-07T03:07:08.720476539Z","rtype":160,"publisher_id":101,"instrument_id":436},"action":"A","side":"A","price":"1.156740000","size":30,"channel_id":23,"order_id":"1775531228720482486","flags":128,"ts_in_delta":717,"sequence":181307,"symbol":"FCEU SI 20260615 PS"}
{"ts_recv":"2026-04-07T03:07:59.252585649Z","hd":{"ts_event":"2026-04-07T03:07:59.252561613Z","rtype":160,"publisher_id":101,"instrument_id":436},"action":"C","side":"B","price":"1.156640000","size":30,"channel_id":23,"order_id":"10998903265575258294","flags":0,"ts_in_delta":951,"sequence":181665,"symbol":"FCEU SI 20260615 PS"}
{"ts_recv":"2026-04-07T03:07:59.252585649Z","hd":{"ts_event":"2026-04-07T03:07:59.252561613Z","rtype":160,"publisher_id":101,"instrument_id":436},"action":"A","side":"B","price":"1.156650000","size":30,"channel_id":23,"order_id":"10998903316107343746","flags":0,"ts_in_delta":951,"sequence":181665,"symbol":"FCEU SI 20260615 PS"}
{"ts_recv":"2026-04-07T03:07:59.252585649Z","hd":{"ts_event":"2026-04-07T03:07:59.252561613Z","rtype":160,"publisher_id":101,"instrument_id":436},"action":"C","side":"A","price":"1.156740000","size":30,"channel_id":23,"order_id":"1775531228720482486","flags":0,"ts_in_delta":951,"sequence":181665,"symbol":"FCEU SI 20260615 PS"}
{"ts_recv":"2026-04-07T03:07:59.252585649Z","hd":{"ts_event":"2026-04-07T03:07:59.252561613Z","rtype":160,"publisher_id":101,"instrument_id":436},"action":"A","side":"A","price":"1.156750000","size":30,"channel_id":23,"order_id":"1775531279252567938","flags":128,"ts_in_delta":951,"sequence":181665,"symbol":"FCEU SI 20260615 PS"}
{"ts_recv":"2026-04-07T03:07:59.272548349Z","hd":{"ts_event":"2026-04-07T03:07:59.272529939Z","rtype":160,"publisher_id":101,"instrument_id":436},"action":"C","side":"B","price":"1.156650000","size":30,"channel_id":23,"order_id":"10998903316107343746","flags":0,"ts_in_delta":1213,"sequence":181680,"symbol":"FCEU SI 20260615 PS"}
{"ts_recv":"2026-04-07T03:07:59.272548349Z","hd":{"ts_event":"2026-04-07T03:07:59.272529939Z","rtype":160,"publisher_id":101,"instrument_id":436},"action":"A","side":"B","price":"1.156660000","size":30,"channel_id":23,"order_id":"10998903316127311655","flags":0,"ts_in_delta":1213,"sequence":181680,"symbol":"FCEU SI 20260615 PS"}
{"ts_recv":"2026-04-07T03:07:59.272548349Z","hd":{"ts_event":"2026-04-07T03:07:59.272529939Z","rtype":160,"publisher_id":101,"instrument_id":436},"action":"C","side":"A","price":"1.156750000","size":30,"channel_id":23,"order_id":"1775531279252567938","flags":0,"ts_in_delta":1213,"sequence":181680,"symbol":"FCEU SI 20260615 PS"}
{"ts_recv":"2026-04-07T03:07:59.272548349Z","hd":{"ts_event":"2026-04-07T03:07:59.272529939Z","rtype":160,"publisher_id":101,"instrument_id":436},"action":"A","side":"A","price":"1.156760000","size":30,"channel_id":23,"order_id":"1775531279272535847","flags":128,"ts_in_delta":1213,"sequence":181680,"symbol":"FCEU SI 20260615 PS"}
{"ts_recv":"2026-04-07T03:07:59.272605010Z","hd":{"ts_event":"2026-04-07T03:07:59.272585593Z","rtype":160,"publisher_id":101,"instrument_id":436},"action":"C","side":"B","price":"1.156650000","size":30,"channel_id":23,"order_id":"10998903237774869715","flags":0,"ts_in_delta":783,"sequence":181681,"symbol":"FCEU SI 20260615 PS"}
{"ts_recv":"2026-04-07T03:07:59.272605010Z","hd":{"ts_event":"2026-04-07T03:07:59.272585593Z","rtype":160,"publisher_id":101,"instrument_id":436},"action":"A","side":"B","price":"1.156670000","size":30,"channel_id":23,"order_id":"10998903316127367556","flags":0,"ts_in_delta":783,"sequence":181681,"symbol":"FCEU SI 20260615 PS"}
{"ts_recv":"2026-04-07T03:07:59.272605010Z","hd":{"ts_event":"2026-04-07T03:07:59.272585593Z","rtype":160,"publisher_id":101,"instrument_id":436},"action":"C","side":"A","price":"1.156750000","size":30,"channel_id":23,"order_id":"1775531200920093907","flags":0,"ts_in_delta":783,"sequence":181681,"symbol":"FCEU SI 20260615 PS"}
{"ts_recv":"2026-04-07T03:07:59.272605010Z","hd":{"ts_event":"2026-04-07T03:07:59.272585593Z","rtype":160,"publisher_id":101,"instrument_id":436},"action":"A","side":"A","price":"1.156770000","size":30,"channel_id":23,"order_id":"1775531279272591748","flags":128,"ts_in_delta":783,"sequence":181681,"symbol":"FCEU SI 20260615 PS"}
{"ts_recv":"2026-04-07T03:07:59.272665881Z","hd":{"ts_event":"2026-04-07T03:07:59.272643489Z","rtype":160,"publisher_id":101,"instrument_id":436},"action":"C","side":"B","price":"1.156660000","size":30,"channel_id":23,"order_id":"10998903316127311655","flags":0,"ts_in_delta":780,"sequence":181682,"symbol":"FCEU SI 20260615 PS"}
{"ts_recv":"2026-04-07T03:07:59.272665881Z","hd":{"ts_event":"2026-04-07T03:07:59.272643489Z","rtype":160,"publisher_id":101,"instrument_id":436},"action":"A","side":"B","price":"1.156670000","size":30,"channel_id":23,"order_id":"10998903316127425483","flags":0,"ts_in_delta":780,"sequence":181682,"symbol":"FCEU SI 20260615 PS"}
{"ts_recv":"2026-04-07T03:07:59.272665881Z","hd":{"ts_event":"2026-04-07T03:07:59.272643489Z","rtype":160,"publisher_id":101,"instrument_id":436},"action":"C","side":"A","price":"1.156760000","size":30,"channel_id":23,"order_id":"1775531279272535847","flags":0,"ts_in_delta":780,"sequence":181682,"symbol":"FCEU SI 20260615 PS"}
{"ts_recv":"2026-04-07T03:07:59.272665881Z","hd":{"ts_event":"2026-04-07T03:07:59.272643489Z","rtype":160,"publisher_id":101,"instrument_id":436},"action":"A","side":"A","price":"1.156770000","size":30,"channel_id":23,"order_id":"1775531279272649675","flags":128,"ts_in_delta":780,"sequence":181682,"symbol":"FCEU SI 20260615 PS"}
{"ts_recv":"2026-04-07T03:08:04.477852864Z","hd":{"ts_event":"2026-04-07T03:08:04.477823367Z","rtype":160,"publisher_id":101,"instrument_id":436},"action":"C","side":"B","price":"1.156670000","size":30,"channel_id":23,"order_id":"10998903316127425483","flags":0,"ts_in_delta":1553,"sequence":181717,"symbol":"FCEU SI 20260615 PS"}
{"ts_recv":"2026-04-07T03:08:04.477852864Z","hd":{"ts_event":"2026-04-07T03:08:04.477823367Z","rtype":160,"publisher_id":101,"instrument_id":436},"action":"A","side":"B","price":"1.156680000","size":30,"channel_id":23,"order_id":"10998903321332606485","flags":0,"ts_in_delta":1553,"sequence":181717,"symbol":"FCEU SI 20260615 PS"}
{"ts_recv":"2026-04-07T03:08:04.477852864Z","hd":{"ts_event":"2026-04-07T03:08:04.477823367Z","rtype":160,"publisher_id":101,"instrument_id":436},"action":"C","side":"A","price":"1.156770000","size":30,"channel_id":23,"order_id":"1775531279272649675","flags":0,"ts_in_delta":1553,"sequence":181717,"symbol":"FCEU SI 20260615 PS"}
{"ts_recv":"2026-04-07T03:08:04.477852864Z","hd":{"ts_event":"2026-04-07T03:08:04.477823367Z","rtype":160,"publisher_id":101,"instrument_id":436},"action":"A","side":"A","price":"1.156780000","size":30,"channel_id":23,"order_id":"1775531284477830677","flags":128,"ts_in_delta":1553,"sequence":181717,"symbol":"FCEU SI 20260615 PS"}
{"ts_recv":"2026-04-07T03:08:10.439212334Z","hd":{"ts_event":"2026-04-07T03:08:10.439191039Z","rtype":160,"publisher_id":101,"instrument_id":436},"action":"C","side":"B","price":"1.156680000","size":30,"channel_id":23,"order_id":"10998903321332606485","flags":0,"ts_in_delta":919,"sequence":181773,"symbol":"FCEU SI 20260615 PS"}
{"ts_recv":"2026-04-07T03:08:10.439212334Z","hd":{"ts_event":"2026-04-07T03:08:10.439191039Z","rtype":160,"publisher_id":101,"instrument_id":436},"action":"A","side":"B","price":"1.156670000","size":30,"channel_id":23,"order_id":"10998903327293973091","flags":0,"ts_in_delta":919,"sequence":181773,"symbol":"FCEU SI 20260615 PS"}
{"ts_recv":"2026-04-07T03:08:10.439212334Z","hd":{"ts_event":"2026-04-07T03:08:10.439191039Z","rtype":160,"publisher_id":101,"instrument_id":436},"action":"C","side":"A","price":"1.156780000","size":30,"channel_id":23,"order_id":"1775531284477830677","flags":0,"ts_in_delta":919,"sequence":181773,"symbol":"FCEU SI 20260615 PS"}
{"ts_recv":"2026-04-07T03:08:10.439212334Z","hd":{"ts_event":"2026-04-07T03:08:10.439191039Z","rtype":160,"publisher_id":101,"instrument_id":436},"action":"A","side":"A","price":"1.156770000","size":30,"channel_id":23,"order_id":"1775531290439197283","flags":128,"ts_in_delta":919,"sequence":181773,"symbol":"FCEU SI 20260615 PS"}
{"ts_recv":"2026-04-07T03:08:10.443893478Z","hd":{"ts_event":"2026-04-07T03:08:10.443875795Z","rtype":160,"publisher_id":101,"instrument_id":436},"action":"C","side":"B","price":"1.156670000","size":30,"channel_id":23,"order_id":"10998903327293973091","flags":0,"ts_in_delta":903,"sequence":181777,"symbol":"FCEU SI 20260615 PS"}
{"ts_recv":"2026-04-07T03:08:10.443893478Z","hd":{"ts_event":"2026-04-07T03:08:10.443875795Z","rtype":160,"publisher_id":101,"instrument_id":436},"action":"A","side":"B","price":"1.156660000","size":30,"channel_id":23,"order_id":"10998903327298657411","flags":0,"ts_in_delta":903,"sequence":181777,"symbol":"FCEU SI 20260615 PS"}
{"ts_recv":"2026-04-07T03:08:10.443893478Z","hd":{"ts_event":"2026-04-07T03:08:10.443875795Z","rtype":160,"publisher_id":101,"instrument_id":436},"action":"C","side":"A","price":"1.156770000","size":30,"channel_id":23,"order_id":"1775531290439197283","flags":0,"ts_in_delta":903,"sequence":181777,"symbol":"FCEU SI 20260615 PS"}
{"ts_recv":"2026-04-07T03:08:10.443893478Z","hd":{"ts_event":"2026-04-07T03:08:10.443875795Z","rtype":160,"publisher_id":101,"instrument_id":436},"action":"A","side":"A","price":"1.156760000","size":30,"channel_id":23,"order_id":"1775531290443881603","flags":128,"ts_in_delta":903,"sequence":181777,"symbol":"FCEU SI 20260615 PS"}
{"ts_recv":"2026-04-07T03:08:10.443979114Z","hd":{"ts_event":"2026-04-07T03:08:10.443958877Z","rtype":160,"publisher_id":101,"instrument_id":436},"action":"C","side":"B","price":"1.156660000","size":30,"channel_id":23,"order_id":"10998903327298657411","flags":0,"ts_in_delta":907,"sequence":181778,"symbol":"FCEU SI 20260615 PS"}
{"ts_recv":"2026-04-07T03:08:10.443979114Z","hd":{"ts_event":"2026-04-07T03:08:10.443958877Z","rtype":160,"publisher_id":101,"instrument_id":436},"action":"A","side":"B","price":"1.156650000","size":30,"channel_id":23,"order_id":"10998903327298740598","flags":0,"ts_in_delta":907,"sequence":181778,"symbol":"FCEU SI 20260615 PS"}
{"ts_recv":"2026-04-07T03:08:10.443979114Z","hd":{"ts_event":"2026-04-07T03:08:10.443958877Z","rtype":160,"publisher_id":101,"instrument_id":436},"action":"C","side":"A","price":"1.156760000","size":30,"channel_id":23,"order_id":"1775531290443881603","flags":0,"ts_in_delta":907,"sequence":181778,"symbol":"FCEU SI 20260615 PS"}
{"ts_recv":"2026-04-07T03:08:10.443979114Z","hd":{"ts_event":"2026-04-07T03:08:10.443958877Z","rtype":160,"publisher_id":101,"instrument_id":436},"action":"A","side":"A","price":"1.156750000","size":30,"channel_id":23,"order_id":"1775531290443964790","flags":128,"ts_in_delta":907,"sequence":181778,"symbol":"FCEU SI 20260615 PS"}
{"ts_recv":"2026-04-07T03:08:10.444035021Z","hd":{"ts_event":"2026-04-07T03:08:10.444018473Z","rtype":160,"publisher_id":101,"instrument_id":436},"action":"C","side":"B","price":"1.156650000","size":30,"channel_id":23,"order_id":"10998903327298740598","flags":0,"ts_in_delta":905,"sequence":181779,"symbol":"FCEU SI 20260615 PS"}
{"ts_recv":"2026-04-07T03:08:10.444035021Z","hd":{"ts_event":"2026-04-07T03:08:10.444018473Z","rtype":160,"publisher_id":101,"instrument_id":436},"action":"A","side":"B","price":"1.156660000","size":30,"channel_id":23,"order_id":"10998903327298800637","flags":0,"ts_in_delta":905,"sequence":181779,"symbol":"FCEU SI 20260615 PS"}
{"ts_recv":"2026-04-07T03:08:10.444035021Z","hd":{"ts_event":"2026-04-07T03:08:10.444018473Z","rtype":160,"publisher_id":101,"instrument_id":436},"action":"C","side":"A","price":"1.156750000","size":30,"channel_id":23,"order_id":"1775531290443964790","flags":0,"ts_in_delta":905,"sequence":181779,"symbol":"FCEU SI 20260615 PS"}
{"ts_recv":"2026-04-07T03:08:10.444035021Z","hd":{"ts_event":"2026-04-07T03:08:10.444018473Z","rtype":160,"publisher_id":101,"instrument_id":436},"action":"A","side":"A","price":"1.156760000","size":30,"channel_id":23,"order_id":"1775531290444024829","flags":128,"ts_in_delta":905,"sequence":181779,"symbol":"FCEU SI 20260615 PS"}
{"ts_recv":"2026-04-07T03:08:10.513212084Z","hd":{"ts_event":"2026-04-07T03:08:10.513196021Z","rtype":160,"publisher_id":101,"instrument_id":436},"action":"C","side":"B","price":"1.156660000","size":30,"channel_id":23,"order_id":"10998903327298800637","flags":0,"ts_in_delta":1210,"sequence":181787,"symbol":"FCEU SI 20260615 PS"}
{"ts_recv":"2026-04-07T03:08:10.513212084Z","hd":{"ts_event":"2026-04-07T03:08:10.513196021Z","rtype":160,"publisher_id":101,"instrument_id":436},"action":"A","side":"B","price":"1.156670000","size":30,"channel_id":23,"order_id":"10998903327367978022","flags":0,"ts_in_delta":1210,"sequence":181787,"symbol":"FCEU SI 20260615 PS"}
{"ts_recv":"2026-04-07T03:08:10.513212084Z","hd":{"ts_event":"2026-04-07T03:08:10.513196021Z","rtype":160,"publisher_id":101,"instrument_id":436},"action":"C","side":"A","price":"1.156760000","size":30,"channel_id":23,"order_id":"1775531290444024829","flags":0,"ts_in_delta":1210,"sequence":181787,"symbol":"FCEU SI 20260615 PS"}
{"ts_recv":"2026-04-07T03:08:10.513212084Z","hd":{"ts_event":"2026-04-07T03:08:10.513196021Z","rtype":160,"publisher_id":101,"instrument_id":436},"action":"A","side":"A","price":"1.156770000","size":30,"channel_id":23,"order_id":"1775531290513202214","flags":128,"ts_in_delta":1210,"sequence":181787,"symbol":"FCEU SI 20260615 PS"}
{"ts_recv":"2026-04-07T03:08:40.651223790Z","hd":{"ts_event":"2026-04-07T03:08:40.651193887Z","rtype":160,"publisher_id":101,"instrument_id":436},"action":"C","side":"B","price":"1.156670000","size":30,"channel_id":23,"order_id":"10998903327367978022","flags":0,"ts_in_delta":1323,"sequence":181977,"symbol":"FCEU SI 20260615 PS"}
{"ts_recv":"2026-04-07T03:08:40.651223790Z","hd":{"ts_event":"2026-04-07T03:08:40.651193887Z","rtype":160,"publisher_id":101,"instrument_id":436},"action":"A","side":"B","price":"1.156680000","size":30,"channel_id":23,"order_id":"10998903357505978451","flags":0,"ts_in_delta":1323,"sequence":181977,"symbol":"FCEU SI 20260615 PS"}
{"ts_recv":"2026-04-07T03:08:40.651223790Z","hd":{"ts_event":"2026-04-07T03:08:40.651193887Z","rtype":160,"publisher_id":101,"instrument_id":436},"action":"C","side":"A","price":"1.156770000","size":30,"channel_id":23,"order_id":"1775531290513202214","flags":0,"ts_in_delta":1323,"sequence":181977,"symbol":"FCEU SI 20260615 PS"}
{"ts_recv":"2026-04-07T03:08:40.651223790Z","hd":{"ts_event":"2026-04-07T03:08:40.651193887Z","rtype":160,"publisher_id":101,"instrument_id":436},"action":"A","side":"A","price":"1.156780000","size":30,"channel_id":23,"order_id":"1775531320651202643","flags":128,"ts_in_delta":1323,"sequence":181977,"symbol":"FCEU SI 20260615 PS"}
{"ts_recv":"2026-04-07T03:08:40.651284290Z","hd":{"ts_event":"2026-04-07T03:08:40.651265573Z","rtype":160,"publisher_id":101,"instrument_id":436},"action":"C","side":"B","price":"1.156670000","size":30,"channel_id":23,"order_id":"10998903316127367556","flags":0,"ts_in_delta":924,"sequence":181978,"symbol":"FCEU SI 20260615 PS"}
{"ts_recv":"2026-04-07T03:08:40.651284290Z","hd":{"ts_event":"2026-04-07T03:08:40.651265573Z","rtype":160,"publisher_id":101,"instrument_id":436},"action":"A","side":"B","price":"1.156690000","size":30,"channel_id":23,"order_id":"10998903357506047524","flags":0,"ts_in_delta":924,"sequence":181978,"symbol":"FCEU SI 20260615 PS"}
{"ts_recv":"2026-04-07T03:08:40.651284290Z","hd":{"ts_event":"2026-04-07T03:08:40.651265573Z","rtype":160,"publisher_id":101,"instrument_id":436},"action":"C","side":"A","price":"1.156770000","size":30,"channel_id":23,"order_id":"1775531279272591748","flags":0,"ts_in_delta":924,"sequence":181978,"symbol":"FCEU SI 20260615 PS"}
{"ts_recv":"2026-04-07T03:08:40.651284290Z","hd":{"ts_event":"2026-04-07T03:08:40.651265573Z","rtype":160,"publisher_id":101,"instrument_id":436},"action":"A","side":"A","price":"1.156790000","size":30,"channel_id":23,"order_id":"1775531320651271716","flags":128,"ts_in_delta":924,"sequence":181978,"symbol":"FCEU SI 20260615 PS"}
{"ts_recv":"2026-04-07T03:08:40.651349083Z","hd":{"ts_event":"2026-04-07T03:08:40.651329203Z","rtype":160,"publisher_id":101,"instrument_id":436},"action":"C","side":"B","price":"1.156680000","size":30,"channel_id":23,"order_id":"10998903357505978451","flags":0,"ts_in_delta":966,"sequence":181979,"symbol":"FCEU SI 20260615 PS"}
{"ts_recv":"2026-04-07T03:08:40.651349083Z","hd":{"ts_event":"2026-04-07T03:08:40.651329203Z","rtype":160,"publisher_id":101,"instrument_id":436},"action":"A","side":"B","price":"1.156690000","size":30,"channel_id":23,"order_id":"10998903357506111000","flags":0,"ts_in_delta":966,"sequence":181979,"symbol":"FCEU SI 20260615 PS"}
{"ts_recv":"2026-04-07T03:08:40.651349083Z","hd":{"ts_event":"2026-04-07T03:08:40.651329203Z","rtype":160,"publisher_id":101,"instrument_id":436},"action":"C","side":"A","price":"1.156780000","size":30,"channel_id":23,"order_id":"1775531320651202643","flags":0,"ts_in_delta":966,"sequence":181979,"symbol":"FCEU SI 20260615 PS"}
{"ts_recv":"2026-04-07T03:08:40.651349083Z","hd":{"ts_event":"2026-04-07T03:08:40.651329203Z","rtype":160,"publisher_id":101,"instrument_id":436},"action":"A","side":"A","price":"1.156790000","size":30,"channel_id":23,"order_id":"1775531320651335192","flags":128,"ts_in_delta":966,"sequence":181979,"symbol":"FCEU SI 20260615 PS"}
{"ts_recv":"2026-04-07T03:08:43.409097132Z","hd":{"ts_event":"2026-04-07T03:08:43.409075379Z","rtype":160,"publisher_id":101,"instrument_id":436},"action":"C","side":"B","price":"1.156690000","size":30,"channel_id":23,"order_id":"10998903357506111000","flags":0,"ts_in_delta":934,"sequence":182000,"symbol":"FCEU SI 20260615 PS"}
{"ts_recv":"2026-04-07T03:08:43.409097132Z","hd":{"ts_event":"2026-04-07T03:08:43.409075379Z","rtype":160,"publisher_id":101,"instrument_id":436},"action":"A","side":"B","price":"1.156700000","size":30,"channel_id":23,"order_id":"10998903360263857207","flags":0,"ts_in_delta":934,"sequence":182000,"symbol":"FCEU SI 20260615 PS"}
{"ts_recv":"2026-04-07T03:08:43.409097132Z","hd":{"ts_event":"2026-04-07T03:08:43.409075379Z","rtype":160,"publisher_id":101,"instrument_id":436},"action":"C","side":"A","price":"1.156790000","size":30,"channel_id":23,"order_id":"1775531320651335192","flags":0,"ts_in_delta":934,"sequence":182000,"symbol":"FCEU SI 20260615 PS"}
{"ts_recv":"2026-04-07T03:08:43.409097132Z","hd":{"ts_event":"2026-04-07T03:08:43.409075379Z","rtype":160,"publisher_id":101,"instrument_id":436},"action":"A","side":"A","price":"1.156800000","size":30,"channel_id":23,"order_id":"1775531323409081399","flags":128,"ts_in_delta":934,"sequence":182000,"symbol":"FCEU SI 20260615 PS"}
{"ts_recv":"2026-04-07T03:08:43.409158208Z","hd":{"ts_event":"2026-04-07T03:08:43.409134901Z","rtype":160,"publisher_id":101,"instrument_id":436},"action":"C","side":"B","price":"1.156690000","size":30,"channel_id":23,"order_id":"10998903357506047524","flags":0,"ts_in_delta":1022,"sequence":182001,"symbol":"FCEU SI 20260615 PS"}
{"ts_recv":"2026-04-07T03:08:43.409158208Z","hd":{"ts_event":"2026-04-07T03:08:43.409134901Z","rtype":160,"publisher_id":101,"instrument_id":436},"action":"A","side":"B","price":"1.156710000","size":30,"channel_id":23,"order_id":"10998903360263917655","flags":0,"ts_in_delta":1022,"sequence":182001,"symbol":"FCEU SI 20260615 PS"}
{"ts_recv":"2026-04-07T03:08:43.409158208Z","hd":{"ts_event":"2026-04-07T03:08:43.409134901Z","rtype":160,"publisher_id":101,"instrument_id":436},"action":"C","side":"A","price":"1.156790000","size":30,"channel_id":23,"order_id":"1775531320651271716","flags":0,"ts_in_delta":1022,"sequence":182001,"symbol":"FCEU SI 20260615 PS"}
{"ts_recv":"2026-04-07T03:08:43.409158208Z","hd":{"ts_event":"2026-04-07T03:08:43.409134901Z","rtype":160,"publisher_id":101,"instrument_id":436},"action":"A","side":"A","price":"1.156810000","size":30,"channel_id":23,"order_id":"1775531323409141847","flags":128,"ts_in_delta":1022,"sequence":182001,"symbol":"FCEU SI 20260615 PS"}
{"ts_recv":"2026-04-07T03:08:43.409217879Z","hd":{"ts_event":"2026-04-07T03:08:43.409201005Z","rtype":160,"publisher_id":101,"instrument_id":436},"action":"C","side":"B","price":"1.156700000","size":30,"channel_id":23,"order_id":"10998903360263857207","flags":0,"ts_in_delta":877,"sequence":182002,"symbol":"FCEU SI 20260615 PS"}
{"ts_recv":"2026-04-07T03:08:43.409217879Z","hd":{"ts_event":"2026-04-07T03:08:43.409201005Z","rtype":160,"publisher_id":101,"instrument_id":436},"action":"A","side":"B","price":"1.156710000","size":30,"channel_id":23,"order_id":"10998903360263983062","flags":0,"ts_in_delta":877,"sequence":182002,"symbol":"FCEU SI 20260615 PS"}
{"ts_recv":"2026-04-07T03:08:43.409217879Z","hd":{"ts_event":"2026-04-07T03:08:43.409201005Z","rtype":160,"publisher_id":101,"instrument_id":436},"action":"C","side":"A","price":"1.156800000","size":30,"channel_id":23,"order_id":"1775531323409081399","flags":0,"ts_in_delta":877,"sequence":182002,"symbol":"FCEU SI 20260615 PS"}
{"ts_recv":"2026-04-07T03:08:43.409217879Z","hd":{"ts_event":"2026-04-07T03:08:43.409201005Z","rtype":160,"publisher_id":101,"instrument_id":436},"action":"A","side":"A","price":"1.156810000","size":30,"channel_id":23,"order_id":"1775531323409207254","flags":128,"ts_in_delta":877,"sequence":182002,"symbol":"FCEU SI 20260615 PS"}
{"ts_recv":"2026-04-07T03:08:43.414820244Z","hd":{"ts_event":"2026-04-07T03:08:43.414797437Z","rtype":160,"publisher_id":101,"instrument_id":436},"action":"C","side":"B","price":"1.156710000","size":30,"channel_id":23,"order_id":"10998903360263983062","flags":0,"ts_in_delta":756,"sequence":182006,"symbol":"FCEU SI 20260615 PS"}
{"ts_recv":"2026-04-07T03:08:43.414820244Z","hd":{"ts_event":"2026-04-07T03:08:43.414797437Z","rtype":160,"publisher_id":101,"instrument_id":436},"action":"A","side":"B","price":"1.156720000","size":30,"channel_id":23,"order_id":"10998903360269579754","flags":0,"ts_in_delta":756,"sequence":182006,"symbol":"FCEU SI 20260615 PS"}
{"ts_recv":"2026-04-07T03:08:43.414820244Z","hd":{"ts_event":"2026-04-07T03:08:43.414797437Z","rtype":160,"publisher_id":101,"instrument_id":436},"action":"C","side":"A","price":"1.156810000","size":30,"channel_id":23,"order_id":"1775531323409207254","flags":0,"ts_in_delta":756,"sequence":182006,"symbol":"FCEU SI 20260615 PS"}
{"ts_recv":"2026-04-07T03:08:43.414820244Z","hd":{"ts_event":"2026-04-07T03:08:43.414797437Z","rtype":160,"publisher_id":101,"instrument_id":436},"action":"A","side":"A","price":"1.156820000","size":30,"channel_id":23,"order_id":"1775531323414803946","flags":128,"ts_in_delta":756,"sequence":182006,"symbol":"FCEU SI 20260615 PS"}
{"ts_recv":"2026-04-07T03:08:43.453195818Z","hd":{"ts_event":"2026-04-07T03:08:43.453178387Z","rtype":160,"publisher_id":101,"instrument_id":436},"action":"A","side":"B","price":"1.156600000","size":20,"channel_id":23,"order_id":"10998903360307960696","flags":128,"ts_in_delta":1234,"sequence":182014,"symbol":"FCEU SI 20260615 PS"}
{"ts_recv":"2026-04-07T03:08:43.453314185Z","hd":{"ts_event":"2026-04-07T03:08:43.453298373Z","rtype":160,"publisher_id":101,"instrument_id":436},"action":"C","side":"B","price":"1.156500000","size":20,"channel_id":23,"order_id":"10998903227099594535","flags":128,"ts_in_delta":977,"sequence":182015,"symbol":"FCEU SI 20260615 PS"}
{"ts_recv":"2026-04-07T03:08:44.431262767Z","hd":{"ts_event":"2026-04-07T03:08:44.431241975Z","rtype":160,"publisher_id":101,"instrument_id":436},"action":"C","side":"B","price":"1.156710000","size":30,"channel_id":23,"order_id":"10998903360263917655","flags":0,"ts_in_delta":962,"sequence":182032,"symbol":"FCEU SI 20260615 PS"}
{"ts_recv":"2026-04-07T03:08:44.431262767Z","hd":{"ts_event":"2026-04-07T03:08:44.431241975Z","rtype":160,"publisher_id":101,"instrument_id":436},"action":"A","side":"B","price":"1.156730000","size":30,"channel_id":23,"order_id":"10998903361286023954","flags":0,"ts_in_delta":962,"sequence":182032,"symbol":"FCEU SI 20260615 PS"}
{"ts_recv":"2026-04-07T03:08:44.431262767Z","hd":{"ts_event":"2026-04-07T03:08:44.431241975Z","rtype":160,"publisher_id":101,"instrument_id":436},"action":"C","side":"A","price":"1.156810000","size":30,"channel_id":23,"order_id":"1775531323409141847","flags":0,"ts_in_delta":962,"sequence":182032,"symbol":"FCEU SI 20260615 PS"}
{"ts_recv":"2026-04-07T03:08:44.431262767Z","hd":{"ts_event":"2026-04-07T03:08:44.431241975Z","rtype":160,"publisher_id":101,"instrument_id":436},"action":"A","side":"A","price":"1.156830000","size":30,"channel_id":23,"order_id":"1775531324431248146","flags":128,"ts_in_delta":962,"sequence":182032,"symbol":"FCEU SI 20260615 PS"}
{"ts_recv":"2026-04-07T03:08:44.431327338Z","hd":{"ts_event":"2026-04-07T03:08:44.431310175Z","rtype":160,"publisher_id":101,"instrument_id":436},"action":"C","side":"B","price":"1.156720000","size":30,"channel_id":23,"order_id":"10998903360269579754","flags":0,"ts_in_delta":967,"sequence":182033,"symbol":"FCEU SI 20260615 PS"}
{"ts_recv":"2026-04-07T03:08:44.431327338Z","hd":{"ts_event":"2026-04-07T03:08:44.431310175Z","rtype":160,"publisher_id":101,"instrument_id":436},"action":"A","side":"B","price":"1.156730000","size":30,"channel_id":23,"order_id":"10998903361286091694","flags":0,"ts_in_delta":967,"sequence":182033,"symbol":"FCEU SI 20260615 PS"}
{"ts_recv":"2026-04-07T03:08:44.431327338Z","hd":{"ts_event":"2026-04-07T03:08:44.431310175Z","rtype":160,"publisher_id":101,"instrument_id":436},"action":"C","side":"A","price":"1.156820000","size":30,"channel_id":23,"order_id":"1775531323414803946","flags":0,"ts_in_delta":967,"sequence":182033,"symbol":"FCEU SI 20260615 PS"}
{"ts_recv":"2026-04-07T03:08:44.431327338Z","hd":{"ts_event":"2026-04-07T03:08:44.431310175Z","rtype":160,"publisher_id":101,"instrument_id":436},"action":"A","side":"A","price":"1.156830000","size":30,"channel_id":23,"order_id":"1775531324431315886","flags":128,"ts_in_delta":967,"sequence":182033,"symbol":"FCEU SI 20260615 PS"}
{"ts_recv":"2026-04-07T03:09:23.389988916Z","hd":{"ts_event":"2026-04-07T03:09:23.389965059Z","rtype":160,"publisher_id":101,"instrument_id":436},"action":"C","side":"B","price":"1.156730000","size":30,"channel_id":23,"order_id":"10998903361286091694","flags":0,"ts_in_delta":977,"sequence":182304,"symbol":"FCEU SI 20260615 PS"}
{"ts_recv":"2026-04-07T03:09:23.389988916Z","hd":{"ts_event":"2026-04-07T03:09:23.389965059Z","rtype":160,"publisher_id":101,"instrument_id":436},"action":"A","side":"B","price":"1.156740000","size":30,"channel_id":23,"order_id":"10998903400244746877","flags":0,"ts_in_delta":977,"sequence":182304,"symbol":"FCEU SI 20260615 PS"}
{"ts_recv":"2026-04-07T03:09:23.389988916Z","hd":{"ts_event":"2026-04-07T03:09:23.389965059Z","rtype":160,"publisher_id":101,"instrument_id":436},"action":"C","side":"A","price":"1.156830000","size":30,"channel_id":23,"order_id":"1775531324431315886","flags":0,"ts_in_delta":977,"sequence":182304,"symbol":"FCEU SI 20260615 PS"}
{"ts_recv":"2026-04-07T03:09:23.389988916Z","hd":{"ts_event":"2026-04-07T03:09:23.389965059Z","rtype":160,"publisher_id":101,"instrument_id":436},"action":"A","side":"A","price":"1.156840000","size":30,"channel_id":23,"order_id":"1775531363389971069","flags":128,"ts_in_delta":977,"sequence":182304,"symbol":"FCEU SI 20260615 PS"}
{"ts_recv":"2026-04-07T03:09:23.392629909Z","hd":{"ts_event":"2026-04-07T03:09:23.392607409Z","rtype":160,"publisher_id":101,"instrument_id":436},"action":"C","side":"B","price":"1.156730000","size":30,"channel_id":23,"order_id":"10998903361286023954","flags":0,"ts_in_delta":1147,"sequence":182305,"symbol":"FCEU SI 20260615 PS"}
{"ts_recv":"2026-04-07T03:09:23.392629909Z","hd":{"ts_event":"2026-04-07T03:09:23.392607409Z","rtype":160,"publisher_id":101,"instrument_id":436},"action":"A","side":"B","price":"1.156750000","size":30,"channel_id":23,"order_id":"10998903400247389592","flags":0,"ts_in_delta":1147,"sequence":182305,"symbol":"FCEU SI 20260615 PS"}
{"ts_recv":"2026-04-07T03:09:23.392629909Z","hd":{"ts_event":"2026-04-07T03:09:23.392607409Z","rtype":160,"publisher_id":101,"instrument_id":436},"action":"C","side":"A","price":"1.156830000","size":30,"channel_id":23,"order_id":"1775531324431248146","flags":0,"ts_in_delta":1147,"sequence":182305,"symbol":"FCEU SI 20260615 PS"}
{"ts_recv":"2026-04-07T03:09:23.392629909Z","hd":{"ts_event":"2026-04-07T03:09:23.392607409Z","rtype":160,"publisher_id":101,"instrument_id":436},"action":"A","side":"A","price":"1.156850000","size":30,"channel_id":23,"order_id":"1775531363392613784","flags":128,"ts_in_delta":1147,"sequence":182305,"symbol":"FCEU SI 20260615 PS"}
{"ts_recv":"2026-04-07T03:09:23.392699126Z","hd":{"ts_event":"2026-04-07T03:09:23.392682743Z","rtype":160,"publisher_id":101,"instrument_id":436},"action":"C","side":"B","price":"1.156740000","size":30,"channel_id":23,"order_id":"10998903400244746877","flags":0,"ts_in_delta":948,"sequence":182306,"symbol":"FCEU SI 20260615 PS"}
{"ts_recv":"2026-04-07T03:09:23.392699126Z","hd":{"ts_event":"2026-04-07T03:09:23.392682743Z","rtype":160,"publisher_id":101,"instrument_id":436},"action":"A","side":"B","price":"1.156750000","size":30,"channel_id":23,"order_id":"10998903400247464738","flags":0,"ts_in_delta":948,"sequence":182306,"symbol":"FCEU SI 20260615 PS"}
{"ts_recv":"2026-04-07T03:09:23.392699126Z","hd":{"ts_event":"2026-04-07T03:09:23.392682743Z","rtype":160,"publisher_id":101,"instrument_id":436},"action":"C","side":"A","price":"1.156840000","size":30,"channel_id":23,"order_id":"1775531363389971069","flags":0,"ts_in_delta":948,"sequence":182306,"symbol":"FCEU SI 20260615 PS"}
{"ts_recv":"2026-04-07T03:09:23.392699126Z","hd":{"ts_event":"2026-04-07T03:09:23.392682743Z","rtype":160,"publisher_id":101,"instrument_id":436},"action":"A","side":"A","price":"1.156850000","size":30,"channel_id":23,"order_id":"1775531363392688930","flags":128,"ts_in_delta":948,"sequence":182306,"symbol":"FCEU SI 20260615 PS"}
{"ts_recv":"2026-04-07T03:09:27.133870342Z","hd":{"ts_event":"2026-04-07T03:09:27.133846485Z","rtype":160,"publisher_id":101,"instrument_id":436},"action":"C","side":"B","price":"1.156750000","size":30,"channel_id":23,"order_id":"10998903400247464738","flags":0,"ts_in_delta":1131,"sequence":182334,"symbol":"FCEU SI 20260615 PS"}
{"ts_recv":"2026-04-07T03:09:27.133870342Z","hd":{"ts_event":"2026-04-07T03:09:27.133846485Z","rtype":160,"publisher_id":101,"instrument_id":436},"action":"A","side":"B","price":"1.156740000","size":30,"channel_id":23,"order_id":"10998903403988629108","flags":0,"ts_in_delta":1131,"sequence":182334,"symbol":"FCEU SI 20260615 PS"}
{"ts_recv":"2026-04-07T03:09:27.133870342Z","hd":{"ts_event":"2026-04-07T03:09:27.133846485Z","rtype":160,"publisher_id":101,"instrument_id":436},"action":"C","side":"A","price":"1.156850000","size":30,"channel_id":23,"order_id":"1775531363392688930","flags":0,"ts_in_delta":1131,"sequence":182334,"symbol":"FCEU SI 20260615 PS"}
{"ts_recv":"2026-04-07T03:09:27.133870342Z","hd":{"ts_event":"2026-04-07T03:09:27.133846485Z","rtype":160,"publisher_id":101,"instrument_id":436},"action":"A","side":"A","price":"1.156840000","size":30,"channel_id":23,"order_id":"1775531367133853300","flags":128,"ts_in_delta":1131,"sequence":182334,"symbol":"FCEU SI 20260615 PS"}
{"ts_recv":"2026-04-07T03:09:27.133967789Z","hd":{"ts_event":"2026-04-07T03:09:27.133949129Z","rtype":160,"publisher_id":101,"instrument_id":436},"action":"C","side":"B","price":"1.156750000","size":30,"channel_id":23,"order_id":"10998903400247389592","flags":0,"ts_in_delta":945,"sequence":182335,"symbol":"FCEU SI 20260615 PS"}
{"ts_recv":"2026-04-07T03:09:27.133967789Z","hd":{"ts_event":"2026-04-07T03:09:27.133949129Z","rtype":160,"publisher_id":101,"instrument_id":436},"action":"A","side":"B","price":"1.156730000","size":30,"channel_id":23,"order_id":"10998903403988731414","flags":0,"ts_in_delta":945,"sequence":182335,"symbol":"FCEU SI 20260615 PS"}
{"ts_recv":"2026-04-07T03:09:27.133967789Z","hd":{"ts_event":"2026-04-07T03:09:27.133949129Z","rtype":160,"publisher_id":101,"instrument_id":436},"action":"C","side":"A","price":"1.156850000","size":30,"channel_id":23,"order_id":"1775531363392613784","flags":0,"ts_in_delta":945,"sequence":182335,"symbol":"FCEU SI 20260615 PS"}
{"ts_recv":"2026-04-07T03:09:27.133967789Z","hd":{"ts_event":"2026-04-07T03:09:27.133949129Z","rtype":160,"publisher_id":101,"instrument_id":436},"action":"A","side":"A","price":"1.156830000","size":30,"channel_id":23,"order_id":"1775531367133955606","flags":128,"ts_in_delta":945,"sequence":182335,"symbol":"FCEU SI 20260615 PS"}
{"ts_recv":"2026-04-07T03:09:27.134030954Z","hd":{"ts_event":"2026-04-07T03:09:27.134010203Z","rtype":160,"publisher_id":101,"instrument_id":436},"action":"C","side":"B","price":"1.156740000","size":30,"channel_id":23,"order_id":"10998903403988629108","flags":0,"ts_in_delta":945,"sequence":182336,"symbol":"FCEU SI 20260615 PS"}
{"ts_recv":"2026-04-07T03:09:27.134030954Z","hd":{"ts_event":"2026-04-07T03:09:27.134010203Z","rtype":160,"publisher_id":101,"instrument_id":436},"action":"A","side":"B","price":"1.156730000","size":30,"channel_id":23,"order_id":"10998903403988792058","flags":0,"ts_in_delta":945,"sequence":182336,"symbol":"FCEU SI 20260615 PS"}
{"ts_recv":"2026-04-07T03:09:27.134030954Z","hd":{"ts_event":"2026-04-07T03:09:27.134010203Z","rtype":160,"publisher_id":101,"instrument_id":436},"action":"C","side":"A","price":"1.156840000","size":30,"channel_id":23,"order_id":"1775531367133853300","flags":0,"ts_in_delta":945,"sequence":182336,"symbol":"FCEU SI 20260615 PS"}
{"ts_recv":"2026-04-07T03:09:27.134030954Z","hd":{"ts_event":"2026-04-07T03:09:27.134010203Z","rtype":160,"publisher_id":101,"instrument_id":436},"action":"A","side":"A","price":"1.156830000","size":30,"channel_id":23,"order_id":"1775531367134016250","flags":128,"ts_in_delta":945,"sequence":182336,"symbol":"FCEU SI 20260615 PS"}
{"ts_recv":"2026-04-07T03:10:02.617451493Z","hd":{"ts_event":"2026-04-07T03:10:02.617433921Z","rtype":160,"publisher_id":101,"instrument_id":436},"action":"C","side":"A","price":"1.156900000","size":20,"channel_id":23,"order_id":"1775531175927302760","flags":128,"ts_in_delta":1001,"sequence":182602,"symbol":"FCEU SI 20260615 PS"}
{"ts_recv":"2026-04-07T03:10:02.619908526Z","hd":{"ts_event":"2026-04-07T03:10:02.619883573Z","rtype":160,"publisher_id":101,"instrument_id":436},"action":"C","side":"B","price":"1.156730000","size":30,"channel_id":23,"order_id":"10998903403988792058","flags":0,"ts_in_delta":877,"sequence":182604,"symbol":"FCEU SI 20260615 PS"}
{"ts_recv":"2026-04-07T03:10:02.619908526Z","hd":{"ts_event":"2026-04-07T03:10:02.619883573Z","rtype":160,"publisher_id":101,"instrument_id":436},"action":"A","side":"B","price":"1.156740000","size":30,"channel_id":23,"order_id":"10998903439474665751","flags":0,"ts_in_delta":877,"sequence":182604,"symbol":"FCEU SI 20260615 PS"}
{"ts_recv":"2026-04-07T03:10:02.619908526Z","hd":{"ts_event":"2026-04-07T03:10:02.619883573Z","rtype":160,"publisher_id":101,"instrument_id":436},"action":"C","side":"A","price":"1.156830000","size":30,"channel_id":23,"order_id":"1775531367134016250","flags":0,"ts_in_delta":877,"sequence":182604,"symbol":"FCEU SI 20260615 PS"}
{"ts_recv":"2026-04-07T03:10:02.619908526Z","hd":{"ts_event":"2026-04-07T03:10:02.619883573Z","rtype":160,"publisher_id":101,"instrument_id":436},"action":"A","side":"A","price":"1.156840000","size":30,"channel_id":23,"order_id":"1775531402619889943","flags":128,"ts_in_delta":877,"sequence":182604,"symbol":"FCEU SI 20260615 PS"}
{"ts_recv":"2026-04-07T03:10:02.619967153Z","hd":{"ts_event":"2026-04-07T03:10:02.619945397Z","rtype":160,"publisher_id":101,"instrument_id":436},"action":"C","side":"B","price":"1.156730000","size":30,"channel_id":23,"order_id":"10998903403988731414","flags":0,"ts_in_delta":912,"sequence":182605,"symbol":"FCEU SI 20260615 PS"}
{"ts_recv":"2026-04-07T03:10:02.619967153Z","hd":{"ts_event":"2026-04-07T03:10:02.619945397Z","rtype":160,"publisher_id":101,"instrument_id":436},"action":"A","side":"B","price":"1.156750000","size":30,"channel_id":23,"order_id":"10998903439474727356","flags":0,"ts_in_delta":912,"sequence":182605,"symbol":"FCEU SI 20260615 PS"}
{"ts_recv":"2026-04-07T03:10:02.619967153Z","hd":{"ts_event":"2026-04-07T03:10:02.619945397Z","rtype":160,"publisher_id":101,"instrument_id":436},"action":"C","side":"A","price":"1.156830000","size":30,"channel_id":23,"order_id":"1775531367133955606","flags":0,"ts_in_delta":912,"sequence":182605,"symbol":"FCEU SI 20260615 PS"}
{"ts_recv":"2026-04-07T03:10:02.619967153Z","hd":{"ts_event":"2026-04-07T03:10:02.619945397Z","rtype":160,"publisher_id":101,"instrument_id":436},"action":"A","side":"A","price":"1.156850000","size":30,"channel_id":23,"order_id":"1775531402619951548","flags":128,"ts_in_delta":912,"sequence":182605,"symbol":"FCEU SI 20260615 PS"}
{"ts_recv":"2026-04-07T03:10:02.620029351Z","hd":{"ts_event":"2026-04-07T03:10:02.620009621Z","rtype":160,"publisher_id":101,"instrument_id":436},"action":"C","side":"B","price":"1.156740000","size":30,"channel_id":23,"order_id":"10998903439474665751","flags":0,"ts_in_delta":1071,"sequence":182606,"symbol":"FCEU SI 20260615 PS"}
{"ts_recv":"2026-04-07T03:10:02.620029351Z","hd":{"ts_event":"2026-04-07T03:10:02.620009621Z","rtype":160,"publisher_id":101,"instrument_id":436},"action":"A","side":"B","price":"1.156750000","size":30,"channel_id":23,"order_id":"10998903439474791193","flags":0,"ts_in_delta":1071,"sequence":182606,"symbol":"FCEU SI 20260615 PS"}
{"ts_recv":"2026-04-07T03:10:02.620029351Z","hd":{"ts_event":"2026-04-07T03:10:02.620009621Z","rtype":160,"publisher_id":101,"instrument_id":436},"action":"C","side":"A","price":"1.156840000","size":30,"channel_id":23,"order_id":"1775531402619889943","flags":0,"ts_in_delta":1071,"sequence":182606,"symbol":"FCEU SI 20260615 PS"}
{"ts_recv":"2026-04-07T03:10:02.620029351Z","hd":{"ts_event":"2026-04-07T03:10:02.620009621Z","rtype":160,"publisher_id":101,"instrument_id":436},"action":"A","side":"A","price":"1.156850000","size":30,"channel_id":23,"order_id":"1775531402620015385","flags":128,"ts_in_delta":1071,"sequence":182606,"symbol":"FCEU SI 20260615 PS"}
{"ts_recv":"2026-04-07T03:10:02.623272043Z","hd":{"ts_event":"2026-04-07T03:10:02.623250707Z","rtype":160,"publisher_id":101,"instrument_id":436},"action":"C","side":"B","price":"1.156750000","size":30,"channel_id":23,"order_id":"10998903439474791193","flags":0,"ts_in_delta":1107,"sequence":182610,"symbol":"FCEU SI 20260615 PS"}
{"ts_recv":"2026-04-07T03:10:02.623272043Z","hd":{"ts_event":"2026-04-07T03:10:02.623250707Z","rtype":160,"publisher_id":101,"instrument_id":436},"action":"A","side":"B","price":"1.156770000","size":30,"channel_id":23,"order_id":"10998903439478032664","flags":0,"ts_in_delta":1107,"sequence":182610,"symbol":"FCEU SI 20260615 PS"}
{"ts_recv":"2026-04-07T03:10:02.623272043Z","hd":{"ts_event":"2026-04-07T03:10:02.623250707Z","rtype":160,"publisher_id":101,"instrument_id":436},"action":"C","side":"A","price":"1.156850000","size":30,"channel_id":23,"order_id":"1775531402620015385","flags":0,"ts_in_delta":1107,"sequence":182610,"symbol":"FCEU SI 20260615 PS"}
{"ts_recv":"2026-04-07T03:10:02.623272043Z","hd":{"ts_event":"2026-04-07T03:10:02.623250707Z","rtype":160,"publisher_id":101,"instrument_id":436},"action":"A","side":"A","price":"1.156870000","size":30,"channel_id":23,"order_id":"1775531402623256856","flags":128,"ts_in_delta":1107,"sequence":182610,"symbol":"FCEU SI 20260615 PS"}
{"ts_recv":"2026-04-07T03:10:02.623355421Z","hd":{"ts_event":"2026-04-07T03:10:02.623335227Z","rtype":160,"publisher_id":101,"instrument_id":436},"action":"C","side":"B","price":"1.156770000","size":30,"channel_id":23,"order_id":"10998903439478032664","flags":0,"ts_in_delta":1104,"sequence":182611,"symbol":"FCEU SI 20260615 PS"}
{"ts_recv":"2026-04-07T03:10:02.623355421Z","hd":{"ts_event":"2026-04-07T03:10:02.623335227Z","rtype":160,"publisher_id":101,"instrument_id":436},"action":"A","side":"B","price":"1.156780000","size":30,"channel_id":23,"order_id":"10998903439478117278","flags":0,"ts_in_delta":1104,"sequence":182611,"symbol":"FCEU SI 20260615 PS"}
{"ts_recv":"2026-04-07T03:10:02.623355421Z","hd":{"ts_event":"2026-04-07T03:10:02.623335227Z","rtype":160,"publisher_id":101,"instrument_id":436},"action":"C","side":"A","price":"1.156870000","size":30,"channel_id":23,"order_id":"1775531402623256856","flags":0,"ts_in_delta":1104,"sequence":182611,"symbol":"FCEU SI 20260615 PS"}
{"ts_recv":"2026-04-07T03:10:02.623355421Z","hd":{"ts_event":"2026-04-07T03:10:02.623335227Z","rtype":160,"publisher_id":101,"instrument_id":436},"action":"A","side":"A","price":"1.156880000","size":30,"channel_id":23,"order_id":"1775531402623341470","flags":128,"ts_in_delta":1104,"sequence":182611,"symbol":"FCEU SI 20260615 PS"}
{"ts_recv":"2026-04-07T03:10:02.623402444Z","hd":{"ts_event":"2026-04-07T03:10:02.623385203Z","rtype":160,"publisher_id":101,"instrument_id":436},"action":"C","side":"B","price":"1.156750000","size":30,"channel_id":23,"order_id":"10998903439474727356","flags":0,"ts_in_delta":1134,"sequence":182612,"symbol":"FCEU SI 20260615 PS"}
{"ts_recv":"2026-04-07T03:10:02.623402444Z","hd":{"ts_event":"2026-04-07T03:10:02.623385203Z","rtype":160,"publisher_id":101,"instrument_id":436},"action":"A","side":"B","price":"1.156770000","size":30,"channel_id":23,"order_id":"10998903439478167016","flags":0,"ts_in_delta":1134,"sequence":182612,"symbol":"FCEU SI 20260615 PS"}
{"ts_recv":"2026-04-07T03:10:02.623402444Z","hd":{"ts_event":"2026-04-07T03:10:02.623385203Z","rtype":160,"publisher_id":101,"instrument_id":436},"action":"C","side":"A","price":"1.156850000","size":30,"channel_id":23,"order_id":"1775531402619951548","flags":0,"ts_in_delta":1134,"sequence":182612,"symbol":"FCEU SI 20260615 PS"}
{"ts_recv":"2026-04-07T03:10:02.623402444Z","hd":{"ts_event":"2026-04-07T03:10:02.623385203Z","rtype":160,"publisher_id":101,"instrument_id":436},"action":"A","side":"A","price":"1.156870000","size":30,"channel_id":23,"order_id":"1775531402623391208","flags":128,"ts_in_delta":1134,"sequence":182612,"symbol":"FCEU SI 20260615 PS"}
{"ts_recv":"2026-04-07T03:10:02.623411413Z","hd":{"ts_event":"2026-04-07T03:10:02.623394739Z","rtype":160,"publisher_id":101,"instrument_id":436},"action":"C","side":"B","price":"1.156780000","size":30,"channel_id":23,"order_id":"10998903439478117278","flags":0,"ts_in_delta":1081,"sequence":182613,"symbol":"FCEU SI 20260615 PS"}
{"ts_recv":"2026-04-07T03:10:02.623411413Z","hd":{"ts_event":"2026-04-07T03:10:02.623394739Z","rtype":160,"publisher_id":101,"instrument_id":436},"action":"A","side":"B","price":"1.156770000","size":30,"channel_id":23,"order_id":"10998903439478176554","flags":0,"ts_in_delta":1081,"sequence":182613,"symbol":"FCEU SI 20260615 PS"}
{"ts_recv":"2026-04-07T03:10:02.623411413Z","hd":{"ts_event":"2026-04-07T03:10:02.623394739Z","rtype":160,"publisher_id":101,"instrument_id":436},"action":"C","side":"A","price":"1.156880000","size":30,"channel_id":23,"order_id":"1775531402623341470","flags":0,"ts_in_delta":1081,"sequence":182613,"symbol":"FCEU SI 20260615 PS"}
{"ts_recv":"2026-04-07T03:10:02.623411413Z","hd":{"ts_event":"2026-04-07T03:10:02.623394739Z","rtype":160,"publisher_id":101,"instrument_id":436},"action":"A","side":"A","price":"1.156870000","size":30,"channel_id":23,"order_id":"1775531402623400746","flags":128,"ts_in_delta":1081,"sequence":182613,"symbol":"FCEU SI 20260615 PS"}
{"ts_recv":"2026-04-07T03:10:02.623465732Z","hd":{"ts_event":"2026-04-07T03:10:02.623447201Z","rtype":160,"publisher_id":101,"instrument_id":436},"action":"C","side":"B","price":"1.156770000","size":30,"channel_id":23,"order_id":"10998903439478176554","flags":0,"ts_in_delta":1097,"sequence":182614,"symbol":"FCEU SI 20260615 PS"}
{"ts_recv":"2026-04-07T03:10:02.623465732Z","hd":{"ts_event":"2026-04-07T03:10:02.623447201Z","rtype":160,"publisher_id":101,"instrument_id":436},"action":"A","side":"B","price":"1.156780000","size":30,"channel_id":23,"order_id":"10998903439478228903","flags":0,"ts_in_delta":1097,"sequence":182614,"symbol":"FCEU SI 20260615 PS"}
{"ts_recv":"2026-04-07T03:10:02.623465732Z","hd":{"ts_event":"2026-04-07T03:10:02.623447201Z","rtype":160,"publisher_id":101,"instrument_id":436},"action":"C","side":"A","price":"1.156870000","size":30,"channel_id":23,"order_id":"1775531402623400746","flags":0,"ts_in_delta":1097,"sequence":182614,"symbol":"FCEU SI 20260615 PS"}
{"ts_recv":"2026-04-07T03:10:02.623465732Z","hd":{"ts_event":"2026-04-07T03:10:02.623447201Z","rtype":160,"publisher_id":101,"instrument_id":436},"action":"A","side":"A","price":"1.156880000","size":30,"channel_id":23,"order_id":"1775531402623453095","flags":128,"ts_in_delta":1097,"sequence":182614,"symbol":"FCEU SI 20260615 PS"}
{"ts_recv":"2026-04-07T03:10:02.660461687Z","hd":{"ts_event":"2026-04-07T03:10:02.660446193Z","rtype":160,"publisher_id":101,"instrument_id":436},"action":"A","side":"A","price":"1.157100000","size":20,"channel_id":23,"order_id":"1775531402660452288","flags":128,"ts_in_delta":1190,"sequence":182628,"symbol":"FCEU SI 20260615 PS"}
{"ts_recv":"2026-04-07T03:10:45.111658016Z","hd":{"ts_event":"2026-04-07T03:10:45.111633091Z","rtype":160,"publisher_id":101,"instrument_id":436},"action":"C","side":"B","price":"1.156770000","size":30,"channel_id":23,"order_id":"10998903439478167016","flags":0,"ts_in_delta":956,"sequence":182937,"symbol":"FCEU SI 20260615 PS"}
{"ts_recv":"2026-04-07T03:10:45.111658016Z","hd":{"ts_event":"2026-04-07T03:10:45.111633091Z","rtype":160,"publisher_id":101,"instrument_id":436},"action":"A","side":"B","price":"1.156790000","size":30,"channel_id":23,"order_id":"10998903481966414985","flags":0,"ts_in_delta":956,"sequence":182937,"symbol":"FCEU SI 20260615 PS"}
{"ts_recv":"2026-04-07T03:10:45.111658016Z","hd":{"ts_event":"2026-04-07T03:10:45.111633091Z","rtype":160,"publisher_id":101,"instrument_id":436},"action":"C","side":"A","price":"1.156870000","size":30,"channel_id":23,"order_id":"1775531402623391208","flags":0,"ts_in_delta":956,"sequence":182937,"symbol":"FCEU SI 20260615 PS"}
{"ts_recv":"2026-04-07T03:10:45.111658016Z","hd":{"ts_event":"2026-04-07T03:10:45.111633091Z","rtype":160,"publisher_id":101,"instrument_id":436},"action":"A","side":"A","price":"1.156890000","size":30,"channel_id":23,"order_id":"1775531445111639177","flags":128,"ts_in_delta":956,"sequence":182937,"symbol":"FCEU SI 20260615 PS"}
{"ts_recv":"2026-04-07T03:10:45.111763327Z","hd":{"ts_event":"2026-04-07T03:10:45.111746455Z","rtype":160,"publisher_id":101,"instrument_id":436},"action":"C","side":"B","price":"1.156780000","size":30,"channel_id":23,"order_id":"10998903439478228903","flags":0,"ts_in_delta":971,"sequence":182938,"symbol":"FCEU SI 20260615 PS"}
{"ts_recv":"2026-04-07T03:10:45.111763327Z","hd":{"ts_event":"2026-04-07T03:10:45.111746455Z","rtype":160,"publisher_id":101,"instrument_id":436},"action":"A","side":"B","price":"1.156790000","size":30,"channel_id":23,"order_id":"10998903481966528426","flags":0,"ts_in_delta":971,"sequence":182938,"symbol":"FCEU SI 20260615 PS"}
{"ts_recv":"2026-04-07T03:10:45.111763327Z","hd":{"ts_event":"2026-04-07T03:10:45.111746455Z","rtype":160,"publisher_id":101,"instrument_id":436},"action":"C","side":"A","price":"1.156880000","size":30,"channel_id":23,"order_id":"1775531402623453095","flags":0,"ts_in_delta":971,"sequence":182938,"symbol":"FCEU SI 20260615 PS"}
{"ts_recv":"2026-04-07T03:10:45.111763327Z","hd":{"ts_event":"2026-04-07T03:10:45.111746455Z","rtype":160,"publisher_id":101,"instrument_id":436},"action":"A","side":"A","price":"1.156890000","size":30,"channel_id":23,"order_id":"1775531445111752618","flags":128,"ts_in_delta":971,"sequence":182938,"symbol":"FCEU SI 20260615 PS"}
{"ts_recv":"2026-04-07T03:10:45.114887777Z","hd":{"ts_event":"2026-04-07T03:10:45.114869753Z","rtype":160,"publisher_id":101,"instrument_id":436},"action":"C","side":"B","price":"1.156790000","size":30,"channel_id":23,"order_id":"10998903481966528426","flags":0,"ts_in_delta":981,"sequence":182945,"symbol":"FCEU SI 20260615 PS"}
{"ts_recv":"2026-04-07T03:10:45.114887777Z","hd":{"ts_event":"2026-04-07T03:10:45.114869753Z","rtype":160,"publisher_id":101,"instrument_id":436},"action":"A","side":"B","price":"1.156800000","size":30,"channel_id":23,"order_id":"10998903481969651452","flags":0,"ts_in_delta":981,"sequence":182945,"symbol":"FCEU SI 20260615 PS"}
{"ts_recv":"2026-04-07T03:10:45.114887777Z","hd":{"ts_event":"2026-04-07T03:10:45.114869753Z","rtype":160,"publisher_id":101,"instrument_id":436},"action":"C","side":"A","price":"1.156890000","size":30,"channel_id":23,"order_id":"1775531445111752618","flags":0,"ts_in_delta":981,"sequence":182945,"symbol":"FCEU SI 20260615 PS"}
{"ts_recv":"2026-04-07T03:10:45.114887777Z","hd":{"ts_event":"2026-04-07T03:10:45.114869753Z","rtype":160,"publisher_id":101,"instrument_id":436},"action":"A","side":"A","price":"1.156900000","size":30,"channel_id":23,"order_id":"1775531445114875644","flags":128,"ts_in_delta":981,"sequence":182945,"symbol":"FCEU SI 20260615 PS"}
{"ts_recv":"2026-04-07T03:10:45.115013999Z","hd":{"ts_event":"2026-04-07T03:10:45.114991309Z","rtype":160,"publisher_id":101,"instrument_id":436},"action":"C","side":"B","price":"1.156790000","size":30,"channel_id":23,"order_id":"10998903481966414985","flags":0,"ts_in_delta":1009,"sequence":182946,"symbol":"FCEU SI 20260615 PS"}
{"ts_recv":"2026-04-07T03:10:45.115013999Z","hd":{"ts_event":"2026-04-07T03:10:45.114991309Z","rtype":160,"publisher_id":101,"instrument_id":436},"action":"A","side":"B","price":"1.156810000","size":30,"channel_id":23,"order_id":"10998903481969773294","flags":0,"ts_in_delta":1009,"sequence":182946,"symbol":"FCEU SI 20260615 PS"}
{"ts_recv":"2026-04-07T03:10:45.115013999Z","hd":{"ts_event":"2026-04-07T03:10:45.114991309Z","rtype":160,"publisher_id":101,"instrument_id":436},"action":"C","side":"A","price":"1.156890000","size":30,"channel_id":23,"order_id":"1775531445111639177","flags":0,"ts_in_delta":1009,"sequence":182946,"symbol":"FCEU SI 20260615 PS"}
{"ts_recv":"2026-04-07T03:10:45.115013999Z","hd":{"ts_event":"2026-04-07T03:10:45.114991309Z","rtype":160,"publisher_id":101,"instrument_id":436},"action":"A","side":"A","price":"1.156910000","size":30,"channel_id":23,"order_id":"1775531445114997486","flags":128,"ts_in_delta":1009,"sequence":182946,"symbol":"FCEU SI 20260615 PS"}
{"ts_recv":"2026-04-07T03:10:45.115067565Z","hd":{"ts_event":"2026-04-07T03:10:45.115048425Z","rtype":160,"publisher_id":101,"instrument_id":436},"action":"C","side":"B","price":"1.156800000","size":30,"channel_id":23,"order_id":"10998903481969651452","flags":0,"ts_in_delta":971,"sequence":182947,"symbol":"FCEU SI 20260615 PS"}
{"ts_recv":"2026-04-07T03:10:45.115067565Z","hd":{"ts_event":"2026-04-07T03:10:45.115048425Z","rtype":160,"publisher_id":101,"instrument_id":436},"action":"A","side":"B","price":"1.156810000","size":30,"channel_id":23,"order_id":"10998903481969830404","flags":0,"ts_in_delta":971,"sequence":182947,"symbol":"FCEU SI 20260615 PS"}
{"ts_recv":"2026-04-07T03:10:45.115067565Z","hd":{"ts_event":"2026-04-07T03:10:45.115048425Z","rtype":160,"publisher_id":101,"instrument_id":436},"action":"C","side":"A","price":"1.156900000","size":30,"channel_id":23,"order_id":"1775531445114875644","flags":0,"ts_in_delta":971,"sequence":182947,"symbol":"FCEU SI 20260615 PS"}
{"ts_recv":"2026-04-07T03:10:45.115067565Z","hd":{"ts_event":"2026-04-07T03:10:45.115048425Z","rtype":160,"publisher_id":101,"instrument_id":436},"action":"A","side":"A","price":"1.156910000","size":30,"channel_id":23,"order_id":"1775531445115054596","flags":128,"ts_in_delta":971,"sequence":182947,"symbol":"FCEU SI 20260615 PS"}
{"ts_recv":"2026-04-07T03:10:45.119585287Z","hd":{"ts_event":"2026-04-07T03:10:45.119564407Z","rtype":160,"publisher_id":101,"instrument_id":436},"action":"C","side":"B","price":"1.156810000","size":30,"channel_id":23,"order_id":"10998903481969830404","flags":0,"ts_in_delta":1057,"sequence":182955,"symbol":"FCEU SI 20260615 PS"}
{"ts_recv":"2026-04-07T03:10:45.119585287Z","hd":{"ts_event":"2026-04-07T03:10:45.119564407Z","rtype":160,"publisher_id":101,"instrument_id":436},"action":"A","side":"B","price":"1.156820000","size":30,"channel_id":23,"order_id":"10998903481974346145","flags":0,"ts_in_delta":1057,"sequence":182955,"symbol":"FCEU SI 20260615 PS"}
{"ts_recv":"2026-04-07T03:10:45.119585287Z","hd":{"ts_event":"2026-04-07T03:10:45.119564407Z","rtype":160,"publisher_id":101,"instrument_id":436},"action":"C","side":"A","price":"1.156910000","size":30,"channel_id":23,"order_id":"1775531445115054596","flags":0,"ts_in_delta":1057,"sequence":182955,"symbol":"FCEU SI 20260615 PS"}
{"ts_recv":"2026-04-07T03:10:45.119585287Z","hd":{"ts_event":"2026-04-07T03:10:45.119564407Z","rtype":160,"publisher_id":101,"instrument_id":436},"action":"A","side":"A","price":"1.156920000","size":30,"channel_id":23,"order_id":"1775531445119570337","flags":128,"ts_in_delta":1057,"sequence":182955,"symbol":"FCEU SI 20260615 PS"}
{"ts_recv":"2026-04-07T03:10:45.119651509Z","hd":{"ts_event":"2026-04-07T03:10:45.119631837Z","rtype":160,"publisher_id":101,"instrument_id":436},"action":"C","side":"B","price":"1.156820000","size":30,"channel_id":23,"order_id":"10998903481974346145","flags":0,"ts_in_delta":1152,"sequence":182956,"symbol":"FCEU SI 20260615 PS"}
{"ts_recv":"2026-04-07T03:10:45.119651509Z","hd":{"ts_event":"2026-04-07T03:10:45.119631837Z","rtype":160,"publisher_id":101,"instrument_id":436},"action":"A","side":"B","price":"1.156830000","size":30,"channel_id":23,"order_id":"10998903481974413726","flags":0,"ts_in_delta":1152,"sequence":182956,"symbol":"FCEU SI 20260615 PS"}
{"ts_recv":"2026-04-07T03:10:45.119651509Z","hd":{"ts_event":"2026-04-07T03:10:45.119631837Z","rtype":160,"publisher_id":101,"instrument_id":436},"action":"C","side":"A","price":"1.156920000","size":30,"channel_id":23,"order_id":"1775531445119570337","flags":0,"ts_in_delta":1152,"sequence":182956,"symbol":"FCEU SI 20260615 PS"}
{"ts_recv":"2026-04-07T03:10:45.119651509Z","hd":{"ts_event":"2026-04-07T03:10:45.119631837Z","rtype":160,"publisher_id":101,"instrument_id":436},"action":"A","side":"A","price":"1.156930000","size":30,"channel_id":23,"order_id":"1775531445119637918","flags":128,"ts_in_delta":1152,"sequence":182956,"symbol":"FCEU SI 20260615 PS"}
{"ts_recv":"2026-04-07T03:10:45.119706725Z","hd":{"ts_event":"2026-04-07T03:10:45.119689245Z","rtype":160,"publisher_id":101,"instrument_id":436},"action":"C","side":"B","price":"1.156830000","size":30,"channel_id":23,"order_id":"10998903481974413726","flags":0,"ts_in_delta":980,"sequence":182957,"symbol":"FCEU SI 20260615 PS"}
{"ts_recv":"2026-04-07T03:10:45.119706725Z","hd":{"ts_event":"2026-04-07T03:10:45.119689245Z","rtype":160,"publisher_id":101,"instrument_id":436},"action":"A","side":"B","price":"1.156820000","size":30,"channel_id":23,"order_id":"10998903481974470912","flags":0,"ts_in_delta":980,"sequence":182957,"symbol":"FCEU SI 20260615 PS"}
{"ts_recv":"2026-04-07T03:10:45.119706725Z","hd":{"ts_event":"2026-04-07T03:10:45.119689245Z","rtype":160,"publisher_id":101,"instrument_id":436},"action":"C","side":"A","price":"1.156930000","size":30,"channel_id":23,"order_id":"1775531445119637918","flags":0,"ts_in_delta":980,"sequence":182957,"symbol":"FCEU SI 20260615 PS"}
{"ts_recv":"2026-04-07T03:10:45.119706725Z","hd":{"ts_event":"2026-04-07T03:10:45.119689245Z","rtype":160,"publisher_id":101,"instrument_id":436},"action":"A","side":"A","price":"1.156920000","size":30,"channel_id":23,"order_id":"1775531445119695104","flags":128,"ts_in_delta":980,"sequence":182957,"symbol":"FCEU SI 20260615 PS"}
{"ts_recv":"2026-04-07T03:10:45.123462089Z","hd":{"ts_event":"2026-04-07T03:10:45.123445907Z","rtype":160,"publisher_id":101,"instrument_id":436},"action":"C","side":"B","price":"1.156820000","size":30,"channel_id":23,"order_id":"10998903481974470912","flags":0,"ts_in_delta":1036,"sequence":182959,"symbol":"FCEU SI 20260615 PS"}
{"ts_recv":"2026-04-07T03:10:45.123462089Z","hd":{"ts_event":"2026-04-07T03:10:45.123445907Z","rtype":160,"publisher_id":101,"instrument_id":436},"action":"A","side":"B","price":"1.156810000","size":30,"channel_id":23,"order_id":"10998903481978227595","flags":0,"ts_in_delta":1036,"sequence":182959,"symbol":"FCEU SI 20260615 PS"}
{"ts_recv":"2026-04-07T03:10:45.123462089Z","hd":{"ts_event":"2026-04-07T03:10:45.123445907Z","rtype":160,"publisher_id":101,"instrument_id":436},"action":"C","side":"A","price":"1.156920000","size":30,"channel_id":23,"order_id":"1775531445119695104","flags":0,"ts_in_delta":1036,"sequence":182959,"symbol":"FCEU SI 20260615 PS"}
{"ts_recv":"2026-04-07T03:10:45.123462089Z","hd":{"ts_event":"2026-04-07T03:10:45.123445907Z","rtype":160,"publisher_id":101,"instrument_id":436},"action":"A","side":"A","price":"1.156910000","size":30,"channel_id":23,"order_id":"1775531445123451787","flags":128,"ts_in_delta":1036,"sequence":182959,"symbol":"FCEU SI 20260615 PS"}
{"ts_recv":"2026-04-07T03:10:45.668569658Z","hd":{"ts_event":"2026-04-07T03:10:45.668549517Z","rtype":160,"publisher_id":101,"instrument_id":436},"action":"C","side":"B","price":"1.156810000","size":30,"channel_id":23,"order_id":"10998903481978227595","flags":0,"ts_in_delta":934,"sequence":183002,"symbol":"FCEU SI 20260615 PS"}
{"ts_recv":"2026-04-07T03:10:45.668569658Z","hd":{"ts_event":"2026-04-07T03:10:45.668549517Z","rtype":160,"publisher_id":101,"instrument_id":436},"action":"A","side":"B","price":"1.156800000","size":30,"channel_id":23,"order_id":"10998903482523331606","flags":0,"ts_in_delta":934,"sequence":183002,"symbol":"FCEU SI 20260615 PS"}
{"ts_recv":"2026-04-07T03:10:45.668569658Z","hd":{"ts_event":"2026-04-07T03:10:45.668549517Z","rtype":160,"publisher_id":101,"instrument_id":436},"action":"C","side":"A","price":"1.156910000","size":30,"channel_id":23,"order_id":"1775531445123451787","flags":0,"ts_in_delta":934,"sequence":183002,"symbol":"FCEU SI 20260615 PS"}
{"ts_recv":"2026-04-07T03:10:45.668569658Z","hd":{"ts_event":"2026-04-07T03:10:45.668549517Z","rtype":160,"publisher_id":101,"instrument_id":436},"action":"A","side":"A","price":"1.156900000","size":30,"channel_id":23,"order_id":"1775531445668555798","flags":128,"ts_in_delta":934,"sequence":183002,"symbol":"FCEU SI 20260615 PS"}
{"ts_recv":"2026-04-07T03:10:45.668625174Z","hd":{"ts_event":"2026-04-07T03:10:45.668605415Z","rtype":160,"publisher_id":101,"instrument_id":436},"action":"C","side":"B","price":"1.156810000","size":30,"channel_id":23,"order_id":"10998903481969773294","flags":0,"ts_in_delta":935,"sequence":183003,"symbol":"FCEU SI 20260615 PS"}
{"ts_recv":"2026-04-07T03:10:45.668625174Z","hd":{"ts_event":"2026-04-07T03:10:45.668605415Z","rtype":160,"publisher_id":101,"instrument_id":436},"action":"A","side":"B","price":"1.156790000","size":30,"channel_id":23,"order_id":"10998903482523387311","flags":0,"ts_in_delta":935,"sequence":183003,"symbol":"FCEU SI 20260615 PS"}
{"ts_recv":"2026-04-07T03:10:45.668625174Z","hd":{"ts_event":"2026-04-07T03:10:45.668605415Z","rtype":160,"publisher_id":101,"instrument_id":436},"action":"C","side":"A","price":"1.156910000","size":30,"channel_id":23,"order_id":"1775531445114997486","flags":0,"ts_in_delta":935,"sequence":183003,"symbol":"FCEU SI 20260615 PS"}
{"ts_recv":"2026-04-07T03:10:45.668625174Z","hd":{"ts_event":"2026-04-07T03:10:45.668605415Z","rtype":160,"publisher_id":101,"instrument_id":436},"action":"A","side":"A","price":"1.156890000","size":30,"channel_id":23,"order_id":"1775531445668611503","flags":128,"ts_in_delta":935,"sequence":183003,"symbol":"FCEU SI 20260615 PS"}
{"ts_recv":"2026-04-07T03:10:45.668687479Z","hd":{"ts_event":"2026-04-07T03:10:45.668669577Z","rtype":160,"publisher_id":101,"instrument_id":436},"action":"C","side":"B","price":"1.156800000","size":30,"channel_id":23,"order_id":"10998903482523331606","flags":0,"ts_in_delta":1023,"sequence":183004,"symbol":"FCEU SI 20260615 PS"}
{"ts_recv":"2026-04-07T03:10:45.668687479Z","hd":{"ts_event":"2026-04-07T03:10:45.668669577Z","rtype":160,"publisher_id":101,"instrument_id":436},"action":"A","side":"B","price":"1.156790000","size":30,"channel_id":23,"order_id":"10998903482523451200","flags":0,"ts_in_delta":1023,"sequence":183004,"symbol":"FCEU SI 20260615 PS"}
{"ts_recv":"2026-04-07T03:10:45.668687479Z","hd":{"ts_event":"2026-04-07T03:10:45.668669577Z","rtype":160,"publisher_id":101,"instrument_id":436},"action":"C","side":"A","price":"1.156900000","size":30,"channel_id":23,"order_id":"1775531445668555798","flags":0,"ts_in_delta":1023,"sequence":183004,"symbol":"FCEU SI 20260615 PS"}
{"ts_recv":"2026-04-07T03:10:45.668687479Z","hd":{"ts_event":"2026-04-07T03:10:45.668669577Z","rtype":160,"publisher_id":101,"instrument_id":436},"action":"A","side":"A","price":"1.156890000","size":30,"channel_id":23,"order_id":"1775531445668675392","flags":128,"ts_in_delta":1023,"sequence":183004,"symbol":"FCEU SI 20260615 PS"}
{"ts_recv":"2026-04-07T03:11:03.148681078Z","hd":{"ts_event":"2026-04-07T03:11:03.148648441Z","rtype":160,"publisher_id":101,"instrument_id":436},"action":"C","side":"B","price":"1.156790000","size":30,"channel_id":23,"order_id":"10998903482523451200","flags":0,"ts_in_delta":1324,"sequence":183101,"symbol":"FCEU SI 20260615 PS"}
{"ts_recv":"2026-04-07T03:11:03.148681078Z","hd":{"ts_event":"2026-04-07T03:11:03.148648441Z","rtype":160,"publisher_id":101,"instrument_id":436},"action":"A","side":"B","price":"1.156800000","size":30,"channel_id":23,"order_id":"10998903500003437594","flags":0,"ts_in_delta":1324,"sequence":183101,"symbol":"FCEU SI 20260615 PS"}
{"ts_recv":"2026-04-07T03:11:03.148681078Z","hd":{"ts_event":"2026-04-07T03:11:03.148648441Z","rtype":160,"publisher_id":101,"instrument_id":436},"action":"C","side":"A","price":"1.156890000","size":30,"channel_id":23,"order_id":"1775531445668675392","flags":0,"ts_in_delta":1324,"sequence":183101,"symbol":"FCEU SI 20260615 PS"}
{"ts_recv":"2026-04-07T03:11:03.148681078Z","hd":{"ts_event":"2026-04-07T03:11:03.148648441Z","rtype":160,"publisher_id":101,"instrument_id":436},"action":"A","side":"A","price":"1.156900000","size":30,"channel_id":23,"order_id":"1775531463148661786","flags":128,"ts_in_delta":1324,"sequence":183101,"symbol":"FCEU SI 20260615 PS"}
{"ts_recv":"2026-04-07T03:11:03.148758473Z","hd":{"ts_event":"2026-04-07T03:11:03.148736281Z","rtype":160,"publisher_id":101,"instrument_id":436},"action":"C","side":"B","price":"1.156790000","size":30,"channel_id":23,"order_id":"10998903482523387311","flags":0,"ts_in_delta":710,"sequence":183103,"symbol":"FCEU SI 20260615 PS"}
{"ts_recv":"2026-04-07T03:11:03.148758473Z","hd":{"ts_event":"2026-04-07T03:11:03.148736281Z","rtype":160,"publisher_id":101,"instrument_id":436},"action":"A","side":"B","price":"1.156810000","size":30,"channel_id":23,"order_id":"10998903500003518575","flags":0,"ts_in_delta":710,"sequence":183103,"symbol":"FCEU SI 20260615 PS"}
{"ts_recv":"2026-04-07T03:11:03.148758473Z","hd":{"ts_event":"2026-04-07T03:11:03.148736281Z","rtype":160,"publisher_id":101,"instrument_id":436},"action":"C","side":"A","price":"1.156890000","size":30,"channel_id":23,"order_id":"1775531445668611503","flags":0,"ts_in_delta":710,"sequence":183103,"symbol":"FCEU SI 20260615 PS"}
{"ts_recv":"2026-04-07T03:11:03.148758473Z","hd":{"ts_event":"2026-04-07T03:11:03.148736281Z","rtype":160,"publisher_id":101,"instrument_id":436},"action":"A","side":"A","price":"1.156910000","size":30,"channel_id":23,"order_id":"1775531463148742767","flags":128,"ts_in_delta":710,"sequence":183103,"symbol":"FCEU SI 20260615 PS"}
{"ts_recv":"2026-04-07T03:11:03.148824387Z","hd":{"ts_event":"2026-04-07T03:11:03.148807103Z","rtype":160,"publisher_id":101,"instrument_id":436},"action":"C","side":"B","price":"1.156800000","size":30,"channel_id":23,"order_id":"10998903500003437594","flags":0,"ts_in_delta":912,"sequence":183104,"symbol":"FCEU SI 20260615 PS"}
{"ts_recv":"2026-04-07T03:11:03.148824387Z","hd":{"ts_event":"2026-04-07T03:11:03.148807103Z","rtype":160,"publisher_id":101,"instrument_id":436},"action":"A","side":"B","price":"1.156810000","size":30,"channel_id":23,"order_id":"10998903500003589342","flags":0,"ts_in_delta":912,"sequence":183104,"symbol":"FCEU SI 20260615 PS"}
{"ts_recv":"2026-04-07T03:11:03.148824387Z","hd":{"ts_event":"2026-04-07T03:11:03.148807103Z","rtype":160,"publisher_id":101,"instrument_id":436},"action":"C","side":"A","price":"1.156900000","size":30,"channel_id":23,"order_id":"1775531463148661786","flags":0,"ts_in_delta":912,"sequence":183104,"symbol":"FCEU SI 20260615 PS"}
{"ts_recv":"2026-04-07T03:11:03.148824387Z","hd":{"ts_event":"2026-04-07T03:11:03.148807103Z","rtype":160,"publisher_id":101,"instrument_id":436},"action":"A","side":"A","price":"1.156910000","size":30,"channel_id":23,"order_id":"1775531463148813534","flags":128,"ts_in_delta":912,"sequence":183104,"symbol":"FCEU SI 20260615 PS"}
{"ts_recv":"2026-04-07T03:11:03.154624864Z","hd":{"ts_event":"2026-04-07T03:11:03.154606167Z","rtype":160,"publisher_id":101,"instrument_id":436},"action":"C","side":"B","price":"1.156810000","size":30,"channel_id":23,"order_id":"10998903500003589342","flags":0,"ts_in_delta":895,"sequence":183107,"symbol":"FCEU SI 20260615 PS"}
{"ts_recv":"2026-04-07T03:11:03.154624864Z","hd":{"ts_event":"2026-04-07T03:11:03.154606167Z","rtype":160,"publisher_id":101,"instrument_id":436},"action":"A","side":"B","price":"1.156820000","size":30,"channel_id":23,"order_id":"10998903500009387693","flags":0,"ts_in_delta":895,"sequence":183107,"symbol":"FCEU SI 20260615 PS"}
{"ts_recv":"2026-04-07T03:11:03.154624864Z","hd":{"ts_event":"2026-04-07T03:11:03.154606167Z","rtype":160,"publisher_id":101,"instrument_id":436},"action":"C","side":"A","price":"1.156910000","size":30,"channel_id":23,"order_id":"1775531463148813534","flags":0,"ts_in_delta":895,"sequence":183107,"symbol":"FCEU SI 20260615 PS"}
{"ts_recv":"2026-04-07T03:11:03.154624864Z","hd":{"ts_event":"2026-04-07T03:11:03.154606167Z","rtype":160,"publisher_id":101,"instrument_id":436},"action":"A","side":"A","price":"1.156920000","size":30,"channel_id":23,"order_id":"1775531463154611885","flags":128,"ts_in_delta":895,"sequence":183107,"symbol":"FCEU SI 20260615 PS"}
{"ts_recv":"2026-04-07T03:11:03.165211919Z","hd":{"ts_event":"2026-04-07T03:11:03.165190135Z","rtype":160,"publisher_id":101,"instrument_id":436},"action":"C","side":"B","price":"1.156810000","size":30,"channel_id":23,"order_id":"10998903500003518575","flags":0,"ts_in_delta":987,"sequence":183111,"symbol":"FCEU SI 20260615 PS"}
{"ts_recv":"2026-04-07T03:11:03.165211919Z","hd":{"ts_event":"2026-04-07T03:11:03.165190135Z","rtype":160,"publisher_id":101,"instrument_id":436},"action":"A","side":"B","price":"1.156830000","size":30,"channel_id":23,"order_id":"10998903500019971910","flags":0,"ts_in_delta":987,"sequence":183111,"symbol":"FCEU SI 20260615 PS"}
{"ts_recv":"2026-04-07T03:11:03.165211919Z","hd":{"ts_event":"2026-04-07T03:11:03.165190135Z","rtype":160,"publisher_id":101,"instrument_id":436},"action":"C","side":"A","price":"1.156910000","size":30,"channel_id":23,"order_id":"1775531463148742767","flags":0,"ts_in_delta":987,"sequence":183111,"symbol":"FCEU SI 20260615 PS"}
{"ts_recv":"2026-04-07T03:11:03.165211919Z","hd":{"ts_event":"2026-04-07T03:11:03.165190135Z","rtype":160,"publisher_id":101,"instrument_id":436},"action":"A","side":"A","price":"1.156930000","size":30,"channel_id":23,"order_id":"1775531463165196102","flags":128,"ts_in_delta":987,"sequence":183111,"symbol":"FCEU SI 20260615 PS"}
{"ts_recv":"2026-04-07T03:11:03.165269424Z","hd":{"ts_event":"2026-04-07T03:11:03.165252363Z","rtype":160,"publisher_id":101,"instrument_id":436},"action":"C","side":"B","price":"1.156820000","size":30,"channel_id":23,"order_id":"10998903500009387693","flags":0,"ts_in_delta":1036,"sequence":183112,"symbol":"FCEU SI 20260615 PS"}
{"ts_recv":"2026-04-07T03:11:03.165269424Z","hd":{"ts_event":"2026-04-07T03:11:03.165252363Z","rtype":160,"publisher_id":101,"instrument_id":436},"action":"A","side":"B","price":"1.156830000","size":30,"channel_id":23,"order_id":"10998903500020034180","flags":0,"ts_in_delta":1036,"sequence":183112,"symbol":"FCEU SI 20260615 PS"}
{"ts_recv":"2026-04-07T03:11:03.165269424Z","hd":{"ts_event":"2026-04-07T03:11:03.165252363Z","rtype":160,"publisher_id":101,"instrument_id":436},"action":"C","side":"A","price":"1.156920000","size":30,"channel_id":23,"order_id":"1775531463154611885","flags":0,"ts_in_delta":1036,"sequence":183112,"symbol":"FCEU SI 20260615 PS"}
{"ts_recv":"2026-04-07T03:11:03.165269424Z","hd":{"ts_event":"2026-04-07T03:11:03.165252363Z","rtype":160,"publisher_id":101,"instrument_id":436},"action":"A","side":"A","price":"1.156930000","size":30,"channel_id":23,"order_id":"1775531463165258372","flags":128,"ts_in_delta":1036,"sequence":183112,"symbol":"FCEU SI 20260615 PS"}
{"ts_recv":"2026-04-07T03:11:03.195196182Z","hd":{"ts_event":"2026-04-07T03:11:03.195179073Z","rtype":160,"publisher_id":101,"instrument_id":436},"action":"A","side":"B","price":"1.156700000","size":20,"channel_id":23,"order_id":"10998903500049961705","flags":128,"ts_in_delta":763,"sequence":183115,"symbol":"FCEU SI 20260615 PS"}
{"ts_recv":"2026-04-07T03:11:03.195239311Z","hd":{"ts_event":"2026-04-07T03:11:03.195225851Z","rtype":160,"publisher_id":101,"instrument_id":436},"action":"C","side":"B","price":"1.156600000","size":20,"channel_id":23,"order_id":"10998903360307960696","flags":128,"ts_in_delta":772,"sequence":183117,"symbol":"FCEU SI 20260615 PS"}
{"ts_recv":"2026-04-07T03:11:18.593470024Z","hd":{"ts_event":"2026-04-07T03:11:18.593447285Z","rtype":160,"publisher_id":101,"instrument_id":436},"action":"C","side":"B","price":"1.156830000","size":30,"channel_id":23,"order_id":"10998903500020034180","flags":0,"ts_in_delta":948,"sequence":183212,"symbol":"FCEU SI 20260615 PS"}
{"ts_recv":"2026-04-07T03:11:18.593470024Z","hd":{"ts_event":"2026-04-07T03:11:18.593447285Z","rtype":160,"publisher_id":101,"instrument_id":436},"action":"A","side":"B","price":"1.156840000","size":30,"channel_id":23,"order_id":"10998903515448229228","flags":0,"ts_in_delta":948,"sequence":183212,"symbol":"FCEU SI 20260615 PS"}
{"ts_recv":"2026-04-07T03:11:18.593470024Z","hd":{"ts_event":"2026-04-07T03:11:18.593447285Z","rtype":160,"publisher_id":101,"instrument_id":436},"action":"C","side":"A","price":"1.156930000","size":30,"channel_id":23,"order_id":"1775531463165258372","flags":0,"ts_in_delta":948,"sequence":183212,"symbol":"FCEU SI 20260615 PS"}
{"ts_recv":"2026-04-07T03:11:18.593470024Z","hd":{"ts_event":"2026-04-07T03:11:18.593447285Z","rtype":160,"publisher_id":101,"instrument_id":436},"action":"A","side":"A","price":"1.156940000","size":30,"channel_id":23,"order_id":"1775531478593453420","flags":128,"ts_in_delta":948,"sequence":183212,"symbol":"FCEU SI 20260615 PS"}
{"ts_recv":"2026-04-07T03:11:18.593539932Z","hd":{"ts_event":"2026-04-07T03:11:18.593520361Z","rtype":160,"publisher_id":101,"instrument_id":436},"action":"C","side":"B","price":"1.156830000","size":30,"channel_id":23,"order_id":"10998903500019971910","flags":0,"ts_in_delta":976,"sequence":183213,"symbol":"FCEU SI 20260615 PS"}
{"ts_recv":"2026-04-07T03:11:18.593539932Z","hd":{"ts_event":"2026-04-07T03:11:18.593520361Z","rtype":160,"publisher_id":101,"instrument_id":436},"action":"A","side":"B","price":"1.156850000","size":30,"channel_id":23,"order_id":"10998903515448302526","flags":0,"ts_in_delta":976,"sequence":183213,"symbol":"FCEU SI 20260615 PS"}
{"ts_recv":"2026-04-07T03:11:18.593539932Z","hd":{"ts_event":"2026-04-07T03:11:18.593520361Z","rtype":160,"publisher_id":101,"instrument_id":436},"action":"C","side":"A","price":"1.156930000","size":30,"channel_id":23,"order_id":"1775531463165196102","flags":0,"ts_in_delta":976,"sequence":183213,"symbol":"FCEU SI 20260615 PS"}
{"ts_recv":"2026-04-07T03:11:18.593539932Z","hd":{"ts_event":"2026-04-07T03:11:18.593520361Z","rtype":160,"publisher_id":101,"instrument_id":436},"action":"A","side":"A","price":"1.156950000","size":30,"channel_id":23,"order_id":"1775531478593526718","flags":128,"ts_in_delta":976,"sequence":183213,"symbol":"FCEU SI 20260615 PS"}
{"ts_recv":"2026-04-07T03:11:18.593552681Z","hd":{"ts_event":"2026-04-07T03:11:18.593533475Z","rtype":160,"publisher_id":101,"instrument_id":436},"action":"C","side":"B","price":"1.156840000","size":30,"channel_id":23,"order_id":"10998903515448229228","flags":0,"ts_in_delta":973,"sequence":183214,"symbol":"FCEU SI 20260615 PS"}
{"ts_recv":"2026-04-07T03:11:18.593552681Z","hd":{"ts_event":"2026-04-07T03:11:18.593533475Z","rtype":160,"publisher_id":101,"instrument_id":436},"action":"A","side":"B","price":"1.156850000","size":30,"channel_id":23,"order_id":"10998903515448315508","flags":0,"ts_in_delta":973,"sequence":183214,"symbol":"FCEU SI 20260615 PS"}
{"ts_recv":"2026-04-07T03:11:18.593552681Z","hd":{"ts_event":"2026-04-07T03:11:18.593533475Z","rtype":160,"publisher_id":101,"instrument_id":436},"action":"C","side":"A","price":"1.156940000","size":30,"channel_id":23,"order_id":"1775531478593453420","flags":0,"ts_in_delta":973,"sequence":183214,"symbol":"FCEU SI 20260615 PS"}
{"ts_recv":"2026-04-07T03:11:18.593552681Z","hd":{"ts_event":"2026-04-07T03:11:18.593533475Z","rtype":160,"publisher_id":101,"instrument_id":436},"action":"A","side":"A","price":"1.156950000","size":30,"channel_id":23,"order_id":"1775531478593539700","flags":128,"ts_in_delta":973,"sequence":183214,"symbol":"FCEU SI 20260615 PS"}
{"ts_recv":"2026-04-07T03:11:18.597759560Z","hd":{"ts_event":"2026-04-07T03:11:18.597738573Z","rtype":160,"publisher_id":101,"instrument_id":436},"action":"C","side":"B","price":"1.156850000","size":30,"channel_id":23,"order_id":"10998903515448315508","flags":0,"ts_in_delta":1118,"sequence":183217,"symbol":"FCEU SI 20260615 PS"}
{"ts_recv":"2026-04-07T03:11:18.597759560Z","hd":{"ts_event":"2026-04-07T03:11:18.597738573Z","rtype":160,"publisher_id":101,"instrument_id":436},"action":"A","side":"B","price":"1.156860000","size":30,"channel_id":23,"order_id":"10998903515452520406","flags":0,"ts_in_delta":1118,"sequence":183217,"symbol":"FCEU SI 20260615 PS"}
{"ts_recv":"2026-04-07T03:11:18.597759560Z","hd":{"ts_event":"2026-04-07T03:11:18.597738573Z","rtype":160,"publisher_id":101,"instrument_id":436},"action":"C","side":"A","price":"1.156950000","size":30,"channel_id":23,"order_id":"1775531478593539700","flags":0,"ts_in_delta":1118,"sequence":183217,"symbol":"FCEU SI 20260615 PS"}
{"ts_recv":"2026-04-07T03:11:18.597759560Z","hd":{"ts_event":"2026-04-07T03:11:18.597738573Z","rtype":160,"publisher_id":101,"instrument_id":436},"action":"A","side":"A","price":"1.156960000","size":30,"channel_id":23,"order_id":"1775531478597744598","flags":128,"ts_in_delta":1118,"sequence":183217,"symbol":"FCEU SI 20260615 PS"}
{"ts_recv":"2026-04-07T03:11:18.597825421Z","hd":{"ts_event":"2026-04-07T03:11:18.597802223Z","rtype":160,"publisher_id":101,"instrument_id":436},"action":"C","side":"B","price":"1.156860000","size":30,"channel_id":23,"order_id":"10998903515452520406","flags":0,"ts_in_delta":934,"sequence":183218,"symbol":"FCEU SI 20260615 PS"}
{"ts_recv":"2026-04-07T03:11:18.597825421Z","hd":{"ts_event":"2026-04-07T03:11:18.597802223Z","rtype":160,"publisher_id":101,"instrument_id":436},"action":"A","side":"B","price":"1.156870000","size":30,"channel_id":23,"order_id":"10998903515452583967","flags":0,"ts_in_delta":934,"sequence":183218,"symbol":"FCEU SI 20260615 PS"}
{"ts_recv":"2026-04-07T03:11:18.597825421Z","hd":{"ts_event":"2026-04-07T03:11:18.597802223Z","rtype":160,"publisher_id":101,"instrument_id":436},"action":"C","side":"A","price":"1.156960000","size":30,"channel_id":23,"order_id":"1775531478597744598","flags":0,"ts_in_delta":934,"sequence":183218,"symbol":"FCEU SI 20260615 PS"}
{"ts_recv":"2026-04-07T03:11:18.597825421Z","hd":{"ts_event":"2026-04-07T03:11:18.597802223Z","rtype":160,"publisher_id":101,"instrument_id":436},"action":"A","side":"A","price":"1.156970000","size":30,"channel_id":23,"order_id":"1775531478597808159","flags":128,"ts_in_delta":934,"sequence":183218,"symbol":"FCEU SI 20260615 PS"}
{"ts_recv":"2026-04-07T03:11:18.597874625Z","hd":{"ts_event":"2026-04-07T03:11:18.597856999Z","rtype":160,"publisher_id":101,"instrument_id":436},"action":"C","side":"B","price":"1.156850000","size":30,"channel_id":23,"order_id":"10998903515448302526","flags":0,"ts_in_delta":1062,"sequence":183219,"symbol":"FCEU SI 20260615 PS"}
{"ts_recv":"2026-04-07T03:11:18.597874625Z","hd":{"ts_event":"2026-04-07T03:11:18.597856999Z","rtype":160,"publisher_id":101,"instrument_id":436},"action":"A","side":"B","price":"1.156870000","size":30,"channel_id":23,"order_id":"10998903515452638816","flags":0,"ts_in_delta":1062,"sequence":183219,"symbol":"FCEU SI 20260615 PS"}
{"ts_recv":"2026-04-07T03:11:18.597874625Z","hd":{"ts_event":"2026-04-07T03:11:18.597856999Z","rtype":160,"publisher_id":101,"instrument_id":436},"action":"C","side":"A","price":"1.156950000","size":30,"channel_id":23,"order_id":"1775531478593526718","flags":0,"ts_in_delta":1062,"sequence":183219,"symbol":"FCEU SI 20260615 PS"}
{"ts_recv":"2026-04-07T03:11:18.597874625Z","hd":{"ts_event":"2026-04-07T03:11:18.597856999Z","rtype":160,"publisher_id":101,"instrument_id":436},"action":"A","side":"A","price":"1.156970000","size":30,"channel_id":23,"order_id":"1775531478597863008","flags":128,"ts_in_delta":1062,"sequence":183219,"symbol":"FCEU SI 20260615 PS"}
{"ts_recv":"2026-04-07T03:11:18.597884616Z","hd":{"ts_event":"2026-04-07T03:11:18.597864391Z","rtype":160,"publisher_id":101,"instrument_id":436},"action":"C","side":"B","price":"1.156870000","size":30,"channel_id":23,"order_id":"10998903515452583967","flags":0,"ts_in_delta":966,"sequence":183220,"symbol":"FCEU SI 20260615 PS"}
{"ts_recv":"2026-04-07T03:11:18.597884616Z","hd":{"ts_event":"2026-04-07T03:11:18.597864391Z","rtype":160,"publisher_id":101,"instrument_id":436},"action":"A","side":"B","price":"1.156860000","size":30,"channel_id":23,"order_id":"10998903515452647253","flags":0,"ts_in_delta":966,"sequence":183220,"symbol":"FCEU SI 20260615 PS"}
{"ts_recv":"2026-04-07T03:11:18.597884616Z","hd":{"ts_event":"2026-04-07T03:11:18.597864391Z","rtype":160,"publisher_id":101,"instrument_id":436},"action":"C","side":"A","price":"1.156970000","size":30,"channel_id":23,"order_id":"1775531478597808159","flags":0,"ts_in_delta":966,"sequence":183220,"symbol":"FCEU SI 20260615 PS"}
{"ts_recv":"2026-04-07T03:11:18.597884616Z","hd":{"ts_event":"2026-04-07T03:11:18.597864391Z","rtype":160,"publisher_id":101,"instrument_id":436},"action":"A","side":"A","price":"1.156960000","size":30,"channel_id":23,"order_id":"1775531478597871445","flags":128,"ts_in_delta":966,"sequence":183220,"symbol":"FCEU SI 20260615 PS"}
{"ts_recv":"2026-04-07T03:11:18.597939932Z","hd":{"ts_event":"2026-04-07T03:11:18.597921915Z","rtype":160,"publisher_id":101,"instrument_id":436},"action":"C","side":"B","price":"1.156860000","size":30,"channel_id":23,"order_id":"10998903515452647253","flags":0,"ts_in_delta":936,"sequence":183221,"symbol":"FCEU SI 20260615 PS"}
{"ts_recv":"2026-04-07T03:11:18.597939932Z","hd":{"ts_event":"2026-04-07T03:11:18.597921915Z","rtype":160,"publisher_id":101,"instrument_id":436},"action":"A","side":"B","price":"1.156870000","size":30,"channel_id":23,"order_id":"10998903515452704052","flags":0,"ts_in_delta":936,"sequence":183221,"symbol":"FCEU SI 20260615 PS"}
{"ts_recv":"2026-04-07T03:11:18.597939932Z","hd":{"ts_event":"2026-04-07T03:11:18.597921915Z","rtype":160,"publisher_id":101,"instrument_id":436},"action":"C","side":"A","price":"1.156960000","size":30,"channel_id":23,"order_id":"1775531478597871445","flags":0,"ts_in_delta":936,"sequence":183221,"symbol":"FCEU SI 20260615 PS"}
{"ts_recv":"2026-04-07T03:11:18.597939932Z","hd":{"ts_event":"2026-04-07T03:11:18.597921915Z","rtype":160,"publisher_id":101,"instrument_id":436},"action":"A","side":"A","price":"1.156970000","size":30,"channel_id":23,"order_id":"1775531478597928244","flags":128,"ts_in_delta":936,"sequence":183221,"symbol":"FCEU SI 20260615 PS"}
{"ts_recv":"2026-04-07T03:11:21.473050709Z","hd":{"ts_event":"2026-04-07T03:11:21.473025567Z","rtype":160,"publisher_id":101,"instrument_id":436},"action":"C","side":"B","price":"1.156870000","size":30,"channel_id":23,"order_id":"10998903515452704052","flags":0,"ts_in_delta":1550,"sequence":183248,"symbol":"FCEU SI 20260615 PS"}
{"ts_recv":"2026-04-07T03:11:21.473050709Z","hd":{"ts_event":"2026-04-07T03:11:21.473025567Z","rtype":160,"publisher_id":101,"instrument_id":436},"action":"A","side":"B","price":"1.156860000","size":30,"channel_id":23,"order_id":"10998903518327808315","flags":0,"ts_in_delta":1550,"sequence":183248,"symbol":"FCEU SI 20260615 PS"}
{"ts_recv":"2026-04-07T03:11:21.473050709Z","hd":{"ts_event":"2026-04-07T03:11:21.473025567Z","rtype":160,"publisher_id":101,"instrument_id":436},"action":"C","side":"A","price":"1.156970000","size":30,"channel_id":23,"order_id":"1775531478597928244","flags":0,"ts_in_delta":1550,"sequence":183248,"symbol":"FCEU SI 20260615 PS"}
{"ts_recv":"2026-04-07T03:11:21.473050709Z","hd":{"ts_event":"2026-04-07T03:11:21.473025567Z","rtype":160,"publisher_id":101,"instrument_id":436},"action":"A","side":"A","price":"1.156960000","size":30,"channel_id":23,"order_id":"1775531481473032507","flags":128,"ts_in_delta":1550,"sequence":183248,"symbol":"FCEU SI 20260615 PS"}
{"ts_recv":"2026-04-07T03:11:21.473139240Z","hd":{"ts_event":"2026-04-07T03:11:21.473117875Z","rtype":160,"publisher_id":101,"instrument_id":436},"action":"C","side":"B","price":"1.156860000","size":30,"channel_id":23,"order_id":"10998903518327808315","flags":0,"ts_in_delta":1102,"sequence":183249,"symbol":"FCEU SI 20260615 PS"}
{"ts_recv":"2026-04-07T03:11:21.473139240Z","hd":{"ts_event":"2026-04-07T03:11:21.473117875Z","rtype":160,"publisher_id":101,"instrument_id":436},"action":"A","side":"B","price":"1.156850000","size":30,"channel_id":23,"order_id":"10998903518327900013","flags":0,"ts_in_delta":1102,"sequence":183249,"symbol":"FCEU SI 20260615 PS"}
{"ts_recv":"2026-04-07T03:11:21.473139240Z","hd":{"ts_event":"2026-04-07T03:11:21.473117875Z","rtype":160,"publisher_id":101,"instrument_id":436},"action":"C","side":"A","price":"1.156960000","size":30,"channel_id":23,"order_id":"1775531481473032507","flags":0,"ts_in_delta":1102,"sequence":183249,"symbol":"FCEU SI 20260615 PS"}
{"ts_recv":"2026-04-07T03:11:21.473139240Z","hd":{"ts_event":"2026-04-07T03:11:21.473117875Z","rtype":160,"publisher_id":101,"instrument_id":436},"action":"A","side":"A","price":"1.156950000","size":30,"channel_id":23,"order_id":"1775531481473124205","flags":128,"ts_in_delta":1102,"sequence":183249,"symbol":"FCEU SI 20260615 PS"}
{"ts_recv":"2026-04-07T03:11:21.473194887Z","hd":{"ts_event":"2026-04-07T03:11:21.473177381Z","rtype":160,"publisher_id":101,"instrument_id":436},"action":"C","side":"B","price":"1.156850000","size":30,"channel_id":23,"order_id":"10998903518327900013","flags":0,"ts_in_delta":958,"sequence":183250,"symbol":"FCEU SI 20260615 PS"}
{"ts_recv":"2026-04-07T03:11:21.473194887Z","hd":{"ts_event":"2026-04-07T03:11:21.473177381Z","rtype":160,"publisher_id":101,"instrument_id":436},"action":"A","side":"B","price":"1.156860000","size":30,"channel_id":23,"order_id":"10998903518327959219","flags":0,"ts_in_delta":958,"sequence":183250,"symbol":"FCEU SI 20260615 PS"}
{"ts_recv":"2026-04-07T03:11:21.473194887Z","hd":{"ts_event":"2026-04-07T03:11:21.473177381Z","rtype":160,"publisher_id":101,"instrument_id":436},"action":"C","side":"A","price":"1.156950000","size":30,"channel_id":23,"order_id":"1775531481473124205","flags":0,"ts_in_delta":958,"sequence":183250,"symbol":"FCEU SI 20260615 PS"}
{"ts_recv":"2026-04-07T03:11:21.473194887Z","hd":{"ts_event":"2026-04-07T03:11:21.473177381Z","rtype":160,"publisher_id":101,"instrument_id":436},"action":"A","side":"A","price":"1.156960000","size":30,"channel_id":23,"order_id":"1775531481473183411","flags":128,"ts_in_delta":958,"sequence":183250,"symbol":"FCEU SI 20260615 PS"}
{"ts_recv":"2026-04-07T03:11:21.473218102Z","hd":{"ts_event":"2026-04-07T03:11:21.473198323Z","rtype":160,"publisher_id":101,"instrument_id":436},"action":"C","side":"B","price":"1.156870000","size":30,"channel_id":23,"order_id":"10998903515452638816","flags":0,"ts_in_delta":965,"sequence":183251,"symbol":"FCEU SI 20260615 PS"}
{"ts_recv":"2026-04-07T03:11:21.473218102Z","hd":{"ts_event":"2026-04-07T03:11:21.473198323Z","rtype":160,"publisher_id":101,"instrument_id":436},"action":"A","side":"B","price":"1.156850000","size":30,"channel_id":23,"order_id":"10998903518327980422","flags":0,"ts_in_delta":965,"sequence":183251,"symbol":"FCEU SI 20260615 PS"}
{"ts_recv":"2026-04-07T03:11:21.473218102Z","hd":{"ts_event":"2026-04-07T03:11:21.473198323Z","rtype":160,"publisher_id":101,"instrument_id":436},"action":"C","side":"A","price":"1.156970000","size":30,"channel_id":23,"order_id":"1775531478597863008","flags":0,"ts_in_delta":965,"sequence":183251,"symbol":"FCEU SI 20260615 PS"}
{"ts_recv":"2026-04-07T03:11:21.473218102Z","hd":{"ts_event":"2026-04-07T03:11:21.473198323Z","rtype":160,"publisher_id":101,"instrument_id":436},"action":"A","side":"A","price":"1.156950000","size":30,"channel_id":23,"order_id":"1775531481473204614","flags":128,"ts_in_delta":965,"sequence":183251,"symbol":"FCEU SI 20260615 PS"}
{"ts_recv":"2026-04-07T03:11:21.473277059Z","hd":{"ts_event":"2026-04-07T03:11:21.473259379Z","rtype":160,"publisher_id":101,"instrument_id":436},"action":"C","side":"B","price":"1.156860000","size":30,"channel_id":23,"order_id":"10998903518327959219","flags":0,"ts_in_delta":969,"sequence":183252,"symbol":"FCEU SI 20260615 PS"}
{"ts_recv":"2026-04-07T03:11:21.473277059Z","hd":{"ts_event":"2026-04-07T03:11:21.473259379Z","rtype":160,"publisher_id":101,"instrument_id":436},"action":"A","side":"B","price":"1.156850000","size":30,"channel_id":23,"order_id":"10998903518328041151","flags":0,"ts_in_delta":969,"sequence":183252,"symbol":"FCEU SI 20260615 PS"}
{"ts_recv":"2026-04-07T03:11:21.473277059Z","hd":{"ts_event":"2026-04-07T03:11:21.473259379Z","rtype":160,"publisher_id":101,"instrument_id":436},"action":"C","side":"A","price":"1.156960000","size":30,"channel_id":23,"order_id":"1775531481473183411","flags":0,"ts_in_delta":969,"sequence":183252,"symbol":"FCEU SI 20260615 PS"}
{"ts_recv":"2026-04-07T03:11:21.473277059Z","hd":{"ts_event":"2026-04-07T03:11:21.473259379Z","rtype":160,"publisher_id":101,"instrument_id":436},"action":"A","side":"A","price":"1.156950000","size":30,"channel_id":23,"order_id":"1775531481473265343","flags":128,"ts_in_delta":969,"sequence":183252,"symbol":"FCEU SI 20260615 PS"}
{"ts_recv":"2026-04-07T03:11:24.744104458Z","hd":{"ts_event":"2026-04-07T03:11:24.744084325Z","rtype":160,"publisher_id":101,"instrument_id":436},"action":"C","side":"B","price":"1.156850000","size":30,"channel_id":23,"order_id":"10998903518328041151","flags":0,"ts_in_delta":900,"sequence":183280,"symbol":"FCEU SI 20260615 PS"}
{"ts_recv":"2026-04-07T03:11:24.744104458Z","hd":{"ts_event":"2026-04-07T03:11:24.744084325Z","rtype":160,"publisher_id":101,"instrument_id":436},"action":"A","side":"B","price":"1.156840000","size":30,"channel_id":23,"order_id":"10998903521598865993","flags":0,"ts_in_delta":900,"sequence":183280,"symbol":"FCEU SI 20260615 PS"}
{"ts_recv":"2026-04-07T03:11:24.744104458Z","hd":{"ts_event":"2026-04-07T03:11:24.744084325Z","rtype":160,"publisher_id":101,"instrument_id":436},"action":"C","side":"A","price":"1.156950000","size":30,"channel_id":23,"order_id":"1775531481473265343","flags":0,"ts_in_delta":900,"sequence":183280,"symbol":"FCEU SI 20260615 PS"}
{"ts_recv":"2026-04-07T03:11:24.744104458Z","hd":{"ts_event":"2026-04-07T03:11:24.744084325Z","rtype":160,"publisher_id":101,"instrument_id":436},"action":"A","side":"A","price":"1.156940000","size":30,"channel_id":23,"order_id":"1775531484744090185","flags":128,"ts_in_delta":900,"sequence":183280,"symbol":"FCEU SI 20260615 PS"}
{"ts_recv":"2026-04-07T03:11:24.751529533Z","hd":{"ts_event":"2026-04-07T03:11:24.751508573Z","rtype":160,"publisher_id":101,"instrument_id":436},"action":"C","side":"B","price":"1.156850000","size":30,"channel_id":23,"order_id":"10998903518327980422","flags":0,"ts_in_delta":943,"sequence":183284,"symbol":"FCEU SI 20260615 PS"}
{"ts_recv":"2026-04-07T03:11:24.751529533Z","hd":{"ts_event":"2026-04-07T03:11:24.751508573Z","rtype":160,"publisher_id":101,"instrument_id":436},"action":"A","side":"B","price":"1.156830000","size":30,"channel_id":23,"order_id":"10998903521606290725","flags":0,"ts_in_delta":943,"sequence":183284,"symbol":"FCEU SI 20260615 PS"}
{"ts_recv":"2026-04-07T03:11:24.751529533Z","hd":{"ts_event":"2026-04-07T03:11:24.751508573Z","rtype":160,"publisher_id":101,"instrument_id":436},"action":"C","side":"A","price":"1.156950000","size":30,"channel_id":23,"order_id":"1775531481473204614","flags":0,"ts_in_delta":943,"sequence":183284,"symbol":"FCEU SI 20260615 PS"}
{"ts_recv":"2026-04-07T03:11:24.751529533Z","hd":{"ts_event":"2026-04-07T03:11:24.751508573Z","rtype":160,"publisher_id":101,"instrument_id":436},"action":"A","side":"A","price":"1.156930000","size":30,"channel_id":23,"order_id":"1775531484751514917","flags":128,"ts_in_delta":943,"sequence":183284,"symbol":"FCEU SI 20260615 PS"}
{"ts_recv":"2026-04-07T03:11:24.751592492Z","hd":{"ts_event":"2026-04-07T03:11:24.751573931Z","rtype":160,"publisher_id":101,"instrument_id":436},"action":"C","side":"B","price":"1.156840000","size":30,"channel_id":23,"order_id":"10998903521598865993","flags":0,"ts_in_delta":896,"sequence":183285,"symbol":"FCEU SI 20260615 PS"}
{"ts_recv":"2026-04-07T03:11:24.751592492Z","hd":{"ts_event":"2026-04-07T03:11:24.751573931Z","rtype":160,"publisher_id":101,"instrument_id":436},"action":"A","side":"B","price":"1.156830000","size":30,"channel_id":23,"order_id":"10998903521606355512","flags":0,"ts_in_delta":896,"sequence":183285,"symbol":"FCEU SI 20260615 PS"}
{"ts_recv":"2026-04-07T03:11:24.751592492Z","hd":{"ts_event":"2026-04-07T03:11:24.751573931Z","rtype":160,"publisher_id":101,"instrument_id":436},"action":"C","side":"A","price":"1.156940000","size":30,"channel_id":23,"order_id":"1775531484744090185","flags":0,"ts_in_delta":896,"sequence":183285,"symbol":"FCEU SI 20260615 PS"}
{"ts_recv":"2026-04-07T03:11:24.751592492Z","hd":{"ts_event":"2026-04-07T03:11:24.751573931Z","rtype":160,"publisher_id":101,"instrument_id":436},"action":"A","side":"A","price":"1.156930000","size":30,"channel_id":23,"order_id":"1775531484751579704","flags":128,"ts_in_delta":896,"sequence":183285,"symbol":"FCEU SI 20260615 PS"}
{"ts_recv":"2026-04-07T03:11:33.549148747Z","hd":{"ts_event":"2026-04-07T03:11:33.549126645Z","rtype":160,"publisher_id":101,"instrument_id":436},"action":"C","side":"B","price":"1.156830000","size":30,"channel_id":23,"order_id":"10998903521606355512","flags":0,"ts_in_delta":1184,"sequence":183348,"symbol":"FCEU SI 20260615 PS"}
{"ts_recv":"2026-04-07T03:11:33.549148747Z","hd":{"ts_event":"2026-04-07T03:11:33.549126645Z","rtype":160,"publisher_id":101,"instrument_id":436},"action":"A","side":"B","price":"1.156840000","size":30,"channel_id":23,"order_id":"10998903530403908699","flags":0,"ts_in_delta":1184,"sequence":183348,"symbol":"FCEU SI 20260615 PS"}
{"ts_recv":"2026-04-07T03:11:33.549148747Z","hd":{"ts_event":"2026-04-07T03:11:33.549126645Z","rtype":160,"publisher_id":101,"instrument_id":436},"action":"C","side":"A","price":"1.156930000","size":30,"channel_id":23,"order_id":"1775531484751579704","flags":0,"ts_in_delta":1184,"sequence":183348,"symbol":"FCEU SI 20260615 PS"}
{"ts_recv":"2026-04-07T03:11:33.549148747Z","hd":{"ts_event":"2026-04-07T03:11:33.549126645Z","rtype":160,"publisher_id":101,"instrument_id":436},"action":"A","side":"A","price":"1.156940000","size":30,"channel_id":23,"order_id":"1775531493549132891","flags":128,"ts_in_delta":1184,"sequence":183348,"symbol":"FCEU SI 20260615 PS"}
{"ts_recv":"2026-04-07T03:11:37.626129596Z","hd":{"ts_event":"2026-04-07T03:11:37.626098641Z","rtype":160,"publisher_id":101,"instrument_id":436},"action":"C","side":"B","price":"1.156840000","size":30,"channel_id":23,"order_id":"10998903530403908699","flags":0,"ts_in_delta":1607,"sequence":183370,"symbol":"FCEU SI 20260615 PS"}
{"ts_recv":"2026-04-07T03:11:37.626129596Z","hd":{"ts_event":"2026-04-07T03:11:37.626098641Z","rtype":160,"publisher_id":101,"instrument_id":436},"action":"A","side":"B","price":"1.156830000","size":30,"channel_id":23,"order_id":"10998903534480888370","flags":0,"ts_in_delta":1607,"sequence":183370,"symbol":"FCEU SI 20260615 PS"}
{"ts_recv":"2026-04-07T03:11:37.626129596Z","hd":{"ts_event":"2026-04-07T03:11:37.626098641Z","rtype":160,"publisher_id":101,"instrument_id":436},"action":"C","side":"A","price":"1.156940000","size":30,"channel_id":23,"order_id":"1775531493549132891","flags":0,"ts_in_delta":1607,"sequence":183370,"symbol":"FCEU SI 20260615 PS"}
{"ts_recv":"2026-04-07T03:11:37.626129596Z","hd":{"ts_event":"2026-04-07T03:11:37.626098641Z","rtype":160,"publisher_id":101,"instrument_id":436},"action":"A","side":"A","price":"1.156930000","size":30,"channel_id":23,"order_id":"1775531497626112562","flags":128,"ts_in_delta":1607,"sequence":183370,"symbol":"FCEU SI 20260615 PS"}
{"ts_recv":"2026-04-07T03:11:39.938963348Z","hd":{"ts_event":"2026-04-07T03:11:39.938943859Z","rtype":160,"publisher_id":101,"instrument_id":436},"action":"C","side":"B","price":"1.156830000","size":30,"channel_id":23,"order_id":"10998903534480888370","flags":0,"ts_in_delta":925,"sequence":183392,"symbol":"FCEU SI 20260615 PS"}
{"ts_recv":"2026-04-07T03:11:39.938963348Z","hd":{"ts_event":"2026-04-07T03:11:39.938943859Z","rtype":160,"publisher_id":101,"instrument_id":436},"action":"A","side":"B","price":"1.156820000","size":30,"channel_id":23,"order_id":"10998903536793726041","flags":0,"ts_in_delta":925,"sequence":183392,"symbol":"FCEU SI 20260615 PS"}
{"ts_recv":"2026-04-07T03:11:39.938963348Z","hd":{"ts_event":"2026-04-07T03:11:39.938943859Z","rtype":160,"publisher_id":101,"instrument_id":436},"action":"C","side":"A","price":"1.156930000","size":30,"channel_id":23,"order_id":"1775531497626112562","flags":0,"ts_in_delta":925,"sequence":183392,"symbol":"FCEU SI 20260615 PS"}
{"ts_recv":"2026-04-07T03:11:39.938963348Z","hd":{"ts_event":"2026-04-07T03:11:39.938943859Z","rtype":160,"publisher_id":101,"instrument_id":436},"action":"A","side":"A","price":"1.156920000","size":30,"channel_id":23,"order_id":"1775531499938950233","flags":128,"ts_in_delta":925,"sequence":183392,"symbol":"FCEU SI 20260615 PS"}
{"ts_recv":"2026-04-07T03:11:39.939026267Z","hd":{"ts_event":"2026-04-07T03:11:39.939005415Z","rtype":160,"publisher_id":101,"instrument_id":436},"action":"C","side":"B","price":"1.156830000","size":30,"channel_id":23,"order_id":"10998903521606290725","flags":0,"ts_in_delta":938,"sequence":183393,"symbol":"FCEU SI 20260615 PS"}
{"ts_recv":"2026-04-07T03:11:39.939026267Z","hd":{"ts_event":"2026-04-07T03:11:39.939005415Z","rtype":160,"publisher_id":101,"instrument_id":436},"action":"A","side":"B","price":"1.156810000","size":30,"channel_id":23,"order_id":"10998903536793787280","flags":0,"ts_in_delta":938,"sequence":183393,"symbol":"FCEU SI 20260615 PS"}
{"ts_recv":"2026-04-07T03:11:39.939026267Z","hd":{"ts_event":"2026-04-07T03:11:39.939005415Z","rtype":160,"publisher_id":101,"instrument_id":436},"action":"C","side":"A","price":"1.156930000","size":30,"channel_id":23,"order_id":"1775531484751514917","flags":0,"ts_in_delta":938,"sequence":183393,"symbol":"FCEU SI 20260615 PS"}
{"ts_recv":"2026-04-07T03:11:39.939026267Z","hd":{"ts_event":"2026-04-07T03:11:39.939005415Z","rtype":160,"publisher_id":101,"instrument_id":436},"action":"A","side":"A","price":"1.156910000","size":30,"channel_id":23,"order_id":"1775531499939011472","flags":128,"ts_in_delta":938,"sequence":183393,"symbol":"FCEU SI 20260615 PS"}
{"ts_recv":"2026-04-07T03:11:39.939079802Z","hd":{"ts_event":"2026-04-07T03:11:39.939063591Z","rtype":160,"publisher_id":101,"instrument_id":436},"action":"C","side":"B","price":"1.156820000","size":30,"channel_id":23,"order_id":"10998903536793726041","flags":0,"ts_in_delta":932,"sequence":183394,"symbol":"FCEU SI 20260615 PS"}
{"ts_recv":"2026-04-07T03:11:39.939079802Z","hd":{"ts_event":"2026-04-07T03:11:39.939063591Z","rtype":160,"publisher_id":101,"instrument_id":436},"action":"A","side":"B","price":"1.156810000","size":30,"channel_id":23,"order_id":"10998903536793845256","flags":0,"ts_in_delta":932,"sequence":183394,"symbol":"FCEU SI 20260615 PS"}
{"ts_recv":"2026-04-07T03:11:39.939079802Z","hd":{"ts_event":"2026-04-07T03:11:39.939063591Z","rtype":160,"publisher_id":101,"instrument_id":436},"action":"C","side":"A","price":"1.156920000","size":30,"channel_id":23,"order_id":"1775531499938950233","flags":0,"ts_in_delta":932,"sequence":183394,"symbol":"FCEU SI 20260615 PS"}
{"ts_recv":"2026-04-07T03:11:39.939079802Z","hd":{"ts_event":"2026-04-07T03:11:39.939063591Z","rtype":160,"publisher_id":101,"instrument_id":436},"action":"A","side":"A","price":"1.156910000","size":30,"channel_id":23,"order_id":"1775531499939069448","flags":128,"ts_in_delta":932,"sequence":183394,"symbol":"FCEU SI 20260615 PS"}
{"ts_recv":"2026-04-07T03:11:40.306502049Z","hd":{"ts_event":"2026-04-07T03:11:40.306481633Z","rtype":160,"publisher_id":101,"instrument_id":436},"action":"C","side":"B","price":"1.156810000","size":30,"channel_id":23,"order_id":"10998903536793845256","flags":0,"ts_in_delta":887,"sequence":183409,"symbol":"FCEU SI 20260615 PS"}
{"ts_recv":"2026-04-07T03:11:40.306502049Z","hd":{"ts_event":"2026-04-07T03:11:40.306481633Z","rtype":160,"publisher_id":101,"instrument_id":436},"action":"A","side":"B","price":"1.156820000","size":30,"channel_id":23,"order_id":"10998903537161263480","flags":0,"ts_in_delta":887,"sequence":183409,"symbol":"FCEU SI 20260615 PS"}
{"ts_recv":"2026-04-07T03:11:40.306502049Z","hd":{"ts_event":"2026-04-07T03:11:40.306481633Z","rtype":160,"publisher_id":101,"instrument_id":436},"action":"C","side":"A","price":"1.156910000","size":30,"channel_id":23,"order_id":"1775531499939069448","flags":0,"ts_in_delta":887,"sequence":183409,"symbol":"FCEU SI 20260615 PS"}
{"ts_recv":"2026-04-07T03:11:40.306502049Z","hd":{"ts_event":"2026-04-07T03:11:40.306481633Z","rtype":160,"publisher_id":101,"instrument_id":436},"action":"A","side":"A","price":"1.156920000","size":30,"channel_id":23,"order_id":"1775531500306487672","flags":128,"ts_in_delta":887,"sequence":183409,"symbol":"FCEU SI 20260615 PS"}
{"ts_recv":"2026-04-07T03:11:40.311575417Z","hd":{"ts_event":"2026-04-07T03:11:40.311559891Z","rtype":160,"publisher_id":101,"instrument_id":436},"action":"C","side":"B","price":"1.156820000","size":30,"channel_id":23,"order_id":"10998903537161263480","flags":0,"ts_in_delta":835,"sequence":183411,"symbol":"FCEU SI 20260615 PS"}
{"ts_recv":"2026-04-07T03:11:40.311575417Z","hd":{"ts_event":"2026-04-07T03:11:40.311559891Z","rtype":160,"publisher_id":101,"instrument_id":436},"action":"A","side":"B","price":"1.156810000","size":30,"channel_id":23,"order_id":"10998903537166341522","flags":0,"ts_in_delta":835,"sequence":183411,"symbol":"FCEU SI 20260615 PS"}
{"ts_recv":"2026-04-07T03:11:40.311575417Z","hd":{"ts_event":"2026-04-07T03:11:40.311559891Z","rtype":160,"publisher_id":101,"instrument_id":436},"action":"C","side":"A","price":"1.156920000","size":30,"channel_id":23,"order_id":"1775531500306487672","flags":0,"ts_in_delta":835,"sequence":183411,"symbol":"FCEU SI 20260615 PS"}
{"ts_recv":"2026-04-07T03:11:40.311575417Z","hd":{"ts_event":"2026-04-07T03:11:40.311559891Z","rtype":160,"publisher_id":101,"instrument_id":436},"action":"A","side":"A","price":"1.156910000","size":30,"channel_id":23,"order_id":"1775531500311565714","flags":128,"ts_in_delta":835,"sequence":183411,"symbol":"FCEU SI 20260615 PS"}
{"ts_recv":"2026-04-07T03:11:50.994623471Z","hd":{"ts_event":"2026-04-07T03:11:50.994600029Z","rtype":160,"publisher_id":101,"instrument_id":436},"action":"C","side":"B","price":"1.156810000","size":30,"channel_id":23,"order_id":"10998903537166341522","flags":0,"ts_in_delta":932,"sequence":183476,"symbol":"FCEU SI 20260615 PS"}
{"ts_recv":"2026-04-07T03:11:50.994623471Z","hd":{"ts_event":"2026-04-07T03:11:50.994600029Z","rtype":160,"publisher_id":101,"instrument_id":436},"action":"A","side":"B","price":"1.156800000","size":30,"channel_id":23,"order_id":"10998903547849382176","flags":0,"ts_in_delta":932,"sequence":183476,"symbol":"FCEU SI 20260615 PS"}
{"ts_recv":"2026-04-07T03:11:50.994623471Z","hd":{"ts_event":"2026-04-07T03:11:50.994600029Z","rtype":160,"publisher_id":101,"instrument_id":436},"action":"C","side":"A","price":"1.156910000","size":30,"channel_id":23,"order_id":"1775531500311565714","flags":0,"ts_in_delta":932,"sequence":183476,"symbol":"FCEU SI 20260615 PS"}
{"ts_recv":"2026-04-07T03:11:50.994623471Z","hd":{"ts_event":"2026-04-07T03:11:50.994600029Z","rtype":160,"publisher_id":101,"instrument_id":436},"action":"A","side":"A","price":"1.156900000","size":30,"channel_id":23,"order_id":"1775531510994606368","flags":128,"ts_in_delta":932,"sequence":183476,"symbol":"FCEU SI 20260615 PS"}
{"ts_recv":"2026-04-07T03:11:51.003420799Z","hd":{"ts_event":"2026-04-07T03:11:51.003400873Z","rtype":160,"publisher_id":101,"instrument_id":436},"action":"C","side":"B","price":"1.156810000","size":30,"channel_id":23,"order_id":"10998903536793787280","flags":0,"ts_in_delta":949,"sequence":183479,"symbol":"FCEU SI 20260615 PS"}
{"ts_recv":"2026-04-07T03:11:51.003420799Z","hd":{"ts_event":"2026-04-07T03:11:51.003400873Z","rtype":160,"publisher_id":101,"instrument_id":436},"action":"A","side":"B","price":"1.156790000","size":30,"channel_id":23,"order_id":"10998903547858183347","flags":0,"ts_in_delta":949,"sequence":183479,"symbol":"FCEU SI 20260615 PS"}
{"ts_recv":"2026-04-07T03:11:51.003420799Z","hd":{"ts_event":"2026-04-07T03:11:51.003400873Z","rtype":160,"publisher_id":101,"instrument_id":436},"action":"C","side":"A","price":"1.156910000","size":30,"channel_id":23,"order_id":"1775531499939011472","flags":0,"ts_in_delta":949,"sequence":183479,"symbol":"FCEU SI 20260615 PS"}
{"ts_recv":"2026-04-07T03:11:51.003420799Z","hd":{"ts_event":"2026-04-07T03:11:51.003400873Z","rtype":160,"publisher_id":101,"instrument_id":436},"action":"A","side":"A","price":"1.156890000","size":30,"channel_id":23,"order_id":"1775531511003407539","flags":128,"ts_in_delta":949,"sequence":183479,"symbol":"FCEU SI 20260615 PS"}
{"ts_recv":"2026-04-07T03:11:51.003484625Z","hd":{"ts_event":"2026-04-07T03:11:51.003469061Z","rtype":160,"publisher_id":101,"instrument_id":436},"action":"C","side":"B","price":"1.156800000","size":30,"channel_id":23,"order_id":"10998903547849382176","flags":0,"ts_in_delta":925,"sequence":183480,"symbol":"FCEU SI 20260615 PS"}
{"ts_recv":"2026-04-07T03:11:51.003484625Z","hd":{"ts_event":"2026-04-07T03:11:51.003469061Z","rtype":160,"publisher_id":101,"instrument_id":436},"action":"A","side":"B","price":"1.156790000","size":30,"channel_id":23,"order_id":"10998903547858250784","flags":0,"ts_in_delta":925,"sequence":183480,"symbol":"FCEU SI 20260615 PS"}
{"ts_recv":"2026-04-07T03:11:51.003484625Z","hd":{"ts_event":"2026-04-07T03:11:51.003469061Z","rtype":160,"publisher_id":101,"instrument_id":436},"action":"C","side":"A","price":"1.156900000","size":30,"channel_id":23,"order_id":"1775531510994606368","flags":0,"ts_in_delta":925,"sequence":183480,"symbol":"FCEU SI 20260615 PS"}
{"ts_recv":"2026-04-07T03:11:51.003484625Z","hd":{"ts_event":"2026-04-07T03:11:51.003469061Z","rtype":160,"publisher_id":101,"instrument_id":436},"action":"A","side":"A","price":"1.156890000","size":30,"channel_id":23,"order_id":"1775531511003474976","flags":128,"ts_in_delta":925,"sequence":183480,"symbol":"FCEU SI 20260615 PS"}
{"ts_recv":"2026-04-07T03:11:51.464872308Z","hd":{"ts_event":"2026-04-07T03:11:51.464851733Z","rtype":160,"publisher_id":101,"instrument_id":436},"action":"C","side":"B","price":"1.156790000","size":30,"channel_id":23,"order_id":"10998903547858250784","flags":0,"ts_in_delta":1092,"sequence":183504,"symbol":"FCEU SI 20260615 PS"}
{"ts_recv":"2026-04-07T03:11:51.464872308Z","hd":{"ts_event":"2026-04-07T03:11:51.464851733Z","rtype":160,"publisher_id":101,"instrument_id":436},"action":"A","side":"B","price":"1.156800000","size":30,"channel_id":23,"order_id":"10998903548319633760","flags":0,"ts_in_delta":1092,"sequence":183504,"symbol":"FCEU SI 20260615 PS"}
{"ts_recv":"2026-04-07T03:11:51.464872308Z","hd":{"ts_event":"2026-04-07T03:11:51.464851733Z","rtype":160,"publisher_id":101,"instrument_id":436},"action":"C","side":"A","price":"1.156890000","size":30,"channel_id":23,"order_id":"1775531511003474976","flags":0,"ts_in_delta":1092,"sequence":183504,"symbol":"FCEU SI 20260615 PS"}
{"ts_recv":"2026-04-07T03:11:51.464872308Z","hd":{"ts_event":"2026-04-07T03:11:51.464851733Z","rtype":160,"publisher_id":101,"instrument_id":436},"action":"A","side":"A","price":"1.156900000","size":30,"channel_id":23,"order_id":"1775531511464857952","flags":128,"ts_in_delta":1092,"sequence":183504,"symbol":"FCEU SI 20260615 PS"}
{"ts_recv":"2026-04-07T03:11:55.431529054Z","hd":{"ts_event":"2026-04-07T03:11:55.431508127Z","rtype":160,"publisher_id":101,"instrument_id":436},"action":"C","side":"B","price":"1.156790000","size":30,"channel_id":23,"order_id":"10998903547858183347","flags":0,"ts_in_delta":831,"sequence":183530,"symbol":"FCEU SI 20260615 PS"}
{"ts_recv":"2026-04-07T03:11:55.431529054Z","hd":{"ts_event":"2026-04-07T03:11:55.431508127Z","rtype":160,"publisher_id":101,"instrument_id":436},"action":"A","side":"B","price":"1.156810000","size":30,"channel_id":23,"order_id":"10998903552286289685","flags":0,"ts_in_delta":831,"sequence":183530,"symbol":"FCEU SI 20260615 PS"}
{"ts_recv":"2026-04-07T03:11:55.431529054Z","hd":{"ts_event":"2026-04-07T03:11:55.431508127Z","rtype":160,"publisher_id":101,"instrument_id":436},"action":"C","side":"A","price":"1.156890000","size":30,"channel_id":23,"order_id":"1775531511003407539","flags":0,"ts_in_delta":831,"sequence":183530,"symbol":"FCEU SI 20260615 PS"}
{"ts_recv":"2026-04-07T03:11:55.431529054Z","hd":{"ts_event":"2026-04-07T03:11:55.431508127Z","rtype":160,"publisher_id":101,"instrument_id":436},"action":"A","side":"A","price":"1.156910000","size":30,"channel_id":23,"order_id":"1775531515431513877","flags":128,"ts_in_delta":831,"sequence":183530,"symbol":"FCEU SI 20260615 PS"}
{"ts_recv":"2026-04-07T03:11:55.431644986Z","hd":{"ts_event":"2026-04-07T03:11:55.431624491Z","rtype":160,"publisher_id":101,"instrument_id":436},"action":"C","side":"B","price":"1.156800000","size":30,"channel_id":23,"order_id":"10998903548319633760","flags":0,"ts_in_delta":858,"sequence":183531,"symbol":"FCEU SI 20260615 PS"}
{"ts_recv":"2026-04-07T03:11:55.431644986Z","hd":{"ts_event":"2026-04-07T03:11:55.431624491Z","rtype":160,"publisher_id":101,"instrument_id":436},"action":"A","side":"B","price":"1.156810000","size":30,"channel_id":23,"order_id":"10998903552286406493","flags":0,"ts_in_delta":858,"sequence":183531,"symbol":"FCEU SI 20260615 PS"}
{"ts_recv":"2026-04-07T03:11:55.431644986Z","hd":{"ts_event":"2026-04-07T03:11:55.431624491Z","rtype":160,"publisher_id":101,"instrument_id":436},"action":"C","side":"A","price":"1.156900000","size":30,"channel_id":23,"order_id":"1775531511464857952","flags":0,"ts_in_delta":858,"sequence":183531,"symbol":"FCEU SI 20260615 PS"}
{"ts_recv":"2026-04-07T03:11:55.431644986Z","hd":{"ts_event":"2026-04-07T03:11:55.431624491Z","rtype":160,"publisher_id":101,"instrument_id":436},"action":"A","side":"A","price":"1.156910000","size":30,"channel_id":23,"order_id":"1775531515431630685","flags":128,"ts_in_delta":858,"sequence":183531,"symbol":"FCEU SI 20260615 PS"}
