{"ts_recv":"2026-03-10T08:02:04.384125749Z","hd":{"ts_event":"2026-03-10T08:02:04.383831223Z","rtype":160,"publisher_id":101,"instrument_id":34554},"action":"R","side":"N","price":null,"size":0,"channel_id":79,"order_id":"0","flags":8,"ts_in_delta":0,"sequence":0,"symbol":"EUCO SI 20260710 PS EU C 1.1725 0"}
{"ts_recv":"2026-03-10T08:02:04.384125749Z","hd":{"ts_event":"2026-03-10T08:02:04.383831223Z","rtype":160,"publisher_id":101,"instrument_id":34554},"action":"A","side":"B","price":"0.018080000","size":20,"channel_id":79,"order_id":"10996501761238634241","flags":0,"ts_in_delta":2420,"sequence":44935,"symbol":"EUCO SI 20260710 PS EU C 1.1725 0"}
{"ts_recv":"2026-03-10T08:02:04.384125749Z","hd":{"ts_event":"2026-03-10T08:02:04.383831223Z","rtype":160,"publisher_id":101,"instrument_id":34650},"action":"R","side":"N","price":null,"size":0,"channel_id":79,"order_id":"0","flags":8,"ts_in_delta":0,"sequence":0,"symbol":"EUCO SI 20260814 PS EU C 1.1775 0"}
{"ts_recv":"2026-03-10T08:02:04.384125749Z","hd":{"ts_event":"2026-03-10T08:02:04.383831223Z","rtype":160,"publisher_id":101,"instrument_id":34650},"action":"A","side":"B","price":"0.019000000","size":20,"channel_id":79,"order_id":"10996501761238634241","flags":0,"ts_in_delta":2420,"sequence":44935,"symbol":"EUCO SI 20260814 PS EU C 1.1775 0"}
{"ts_recv":"2026-03-10T08:02:04.384125749Z","hd":{"ts_event":"2026-03-10T08:02:04.383831223Z","rtype":160,"publisher_id":101,"instrument_id":34650},"action":"A","side":"A","price":"0.019430000","size":20,"channel_id":79,"order_id":"1773129724383858433","flags":128,"ts_in_delta":2420,"sequence":44935,"symbol":"EUCO SI 20260814 PS EU C 1.1775 0"}
{"ts_recv":"2026-03-10T08:02:04.384125749Z","hd":{"ts_event":"2026-03-10T08:02:04.383831223Z","rtype":160,"publisher_id":101,"instrument_id":34654},"action":"R","side":"N","price":null,"size":0,"channel_id":79,"order_id":"0","flags":8,"ts_in_delta":0,"sequence":0,"symbol":"EUCO SI 20260814 PS EU C 1.1825 0"}
{"ts_recv":"2026-03-10T08:02:04.384125749Z","hd":{"ts_event":"2026-03-10T08:02:04.383831223Z","rtype":160,"publisher_id":101,"instrument_id":34654},"action":"A","side":"B","price":"0.016790000","size":20,"channel_id":79,"order_id":"10996501761238634241","flags":0,"ts_in_delta":2420,"sequence":44935,"symbol":"EUCO SI 20260814 PS EU C 1.1825 0"}
{"ts_recv":"2026-03-10T08:02:04.384125749Z","hd":{"ts_event":"2026-03-10T08:02:04.383831223Z","rtype":160,"publisher_id":101,"instrument_id":34654},"action":"A","side":"A","price":"0.017220000","size":20,"channel_id":79,"order_id":"1773129724383858433","flags":128,"ts_in_delta":2420,"sequence":44935,"symbol":"EUCO SI 20260814 PS EU C 1.1825 0"}
{"ts_recv":"2026-03-10T08:02:04.384125749Z","hd":{"ts_event":"2026-03-10T08:02:04.383831223Z","rtype":160,"publisher_id":101,"instrument_id":34657},"action":"R","side":"N","price":null,"size":0,"channel_id":79,"order_id":"0","flags":8,"ts_in_delta":0,"sequence":0,"symbol":"EUCO SI 20260814 PS EU P 1.1850 0"}
{"ts_recv":"2026-03-10T08:02:04.384125749Z","hd":{"ts_event":"2026-03-10T08:02:04.383831223Z","rtype":160,"publisher_id":101,"instrument_id":34657},"action":"A","side":"B","price":"0.026270000","size":20,"channel_id":79,"order_id":"10996501761238634241","flags":0,"ts_in_delta":2420,"sequence":44935,"symbol":"EUCO SI 20260814 PS EU P 1.1850 0"}
{"ts_recv":"2026-03-10T08:02:04.384125749Z","hd":{"ts_event":"2026-03-10T08:02:04.383831223Z","rtype":160,"publisher_id":101,"instrument_id":34657},"action":"A","side":"A","price":"0.026700000","size":20,"channel_id":79,"order_id":"1773129724383858433","flags":128,"ts_in_delta":2420,"sequence":44935,"symbol":"EUCO SI 20260814 PS EU P 1.1850 0"}
{"ts_recv":"2026-03-10T08:02:04.384125749Z","hd":{"ts_event":"2026-03-10T08:02:04.383831223Z","rtype":160,"publisher_id":101,"instrument_id":34651},"action":"R","side":"N","price":null,"size":0,"channel_id":79,"order_id":"0","flags":8,"ts_in_delta":0,"sequence":0,"symbol":"EUCO SI 20260814 PS EU P 1.1775 0"}
{"ts_recv":"2026-03-10T08:02:04.384125749Z","hd":{"ts_event":"2026-03-10T08:02:04.383831223Z","rtype":160,"publisher_id":101,"instrument_id":34651},"action":"A","side":"B","price":"0.022130000","size":20,"channel_id":79,"order_id":"10996501761238634241","flags":0,"ts_in_delta":2420,"sequence":44935,"symbol":"EUCO SI 20260814 PS EU P 1.1775 0"}
{"ts_recv":"2026-03-10T08:02:04.384125749Z","hd":{"ts_event":"2026-03-10T08:02:04.383831223Z","rtype":160,"publisher_id":101,"instrument_id":34651},"action":"A","side":"A","price":"0.022550000","size":20,"channel_id":79,"order_id":"1773129724383858433","flags":128,"ts_in_delta":2420,"sequence":44935,"symbol":"EUCO SI 20260814 PS EU P 1.1775 0"}
{"ts_recv":"2026-03-10T08:02:04.384125749Z","hd":{"ts_event":"2026-03-10T08:02:04.383831223Z","rtype":160,"publisher_id":101,"instrument_id":34655},"action":"R","side":"N","price":null,"size":0,"channel_id":79,"order_id":"0","flags":8,"ts_in_delta":0,"sequence":0,"symbol":"EUCO SI 20260814 PS EU P 1.1825 0"}
{"ts_recv":"2026-03-10T08:02:04.384125749Z","hd":{"ts_event":"2026-03-10T08:02:04.383831223Z","rtype":160,"publisher_id":101,"instrument_id":34655},"action":"A","side":"B","price":"0.024840000","size":20,"channel_id":79,"order_id":"10996501761238634241","flags":0,"ts_in_delta":2420,"sequence":44935,"symbol":"EUCO SI 20260814 PS EU P 1.1825 0"}
{"ts_recv":"2026-03-10T08:02:04.384125749Z","hd":{"ts_event":"2026-03-10T08:02:04.383831223Z","rtype":160,"publisher_id":101,"instrument_id":34655},"action":"A","side":"A","price":"0.025260000","size":20,"channel_id":79,"order_id":"1773129724383858433","flags":128,"ts_in_delta":2420,"sequence":44935,"symbol":"EUCO SI 20260814 PS EU P 1.1825 0"}
{"ts_recv":"2026-03-10T08:02:04.384125749Z","hd":{"ts_event":"2026-03-10T08:02:04.383831223Z","rtype":160,"publisher_id":101,"instrument_id":34649},"action":"R","side":"N","price":null,"size":0,"channel_id":79,"order_id":"0","flags":8,"ts_in_delta":0,"sequence":0,"symbol":"EUCO SI 20260814 PS EU P 1.1750 0"}
{"ts_recv":"2026-03-10T08:02:04.384125749Z","hd":{"ts_event":"2026-03-10T08:02:04.383831223Z","rtype":160,"publisher_id":101,"instrument_id":34649},"action":"A","side":"B","price":"0.020850000","size":20,"channel_id":79,"order_id":"10996501761238634241","flags":0,"ts_in_delta":2420,"sequence":44935,"symbol":"EUCO SI 20260814 PS EU P 1.1750 0"}
{"ts_recv":"2026-03-10T08:02:04.384125749Z","hd":{"ts_event":"2026-03-10T08:02:04.383831223Z","rtype":160,"publisher_id":101,"instrument_id":34649},"action":"A","side":"A","price":"0.021280000","size":20,"channel_id":79,"order_id":"1773129724383858433","flags":128,"ts_in_delta":2420,"sequence":44935,"symbol":"EUCO SI 20260814 PS EU P 1.1750 0"}
{"ts_recv":"2026-03-10T08:02:04.384125749Z","hd":{"ts_event":"2026-03-10T08:02:04.383831223Z","rtype":160,"publisher_id":101,"instrument_id":34648},"action":"R","side":"N","price":null,"size":0,"channel_id":79,"order_id":"0","flags":8,"ts_in_delta":0,"sequence":0,"symbol":"EUCO SI 20260814 PS EU C 1.1750 0"}
{"ts_recv":"2026-03-10T08:02:04.384125749Z","hd":{"ts_event":"2026-03-10T08:02:04.383831223Z","rtype":160,"publisher_id":101,"instrument_id":34648},"action":"A","side":"B","price":"0.020190000","size":20,"channel_id":79,"order_id":"10996501761238634241","flags":0,"ts_in_delta":2420,"sequence":44935,"symbol":"EUCO SI 20260814 PS EU C 1.1750 0"}
{"ts_recv":"2026-03-10T08:02:04.384125749Z","hd":{"ts_event":"2026-03-10T08:02:04.383831223Z","rtype":160,"publisher_id":101,"instrument_id":34648},"action":"A","side":"A","price":"0.020610000","size":20,"channel_id":79,"order_id":"1773129724383858433","flags":128,"ts_in_delta":2420,"sequence":44935,"symbol":"EUCO SI 20260814 PS EU C 1.1750 0"}
{"ts_recv":"2026-03-10T08:02:04.384125749Z","hd":{"ts_event":"2026-03-10T08:02:04.383831223Z","rtype":160,"publisher_id":101,"instrument_id":34652},"action":"R","side":"N","price":null,"size":0,"channel_id":79,"order_id":"0","flags":8,"ts_in_delta":0,"sequence":0,"symbol":"EUCO SI 20260814 PS EU C 1.1800 0"}
{"ts_recv":"2026-03-10T08:02:04.384125749Z","hd":{"ts_event":"2026-03-10T08:02:04.383831223Z","rtype":160,"publisher_id":101,"instrument_id":34652},"action":"A","side":"B","price":"0.017870000","size":20,"channel_id":79,"order_id":"10996501761238634241","flags":0,"ts_in_delta":2420,"sequence":44935,"symbol":"EUCO SI 20260814 PS EU C 1.1800 0"}
{"ts_recv":"2026-03-10T08:02:04.384125749Z","hd":{"ts_event":"2026-03-10T08:02:04.383831223Z","rtype":160,"publisher_id":101,"instrument_id":34652},"action":"A","side":"A","price":"0.018300000","size":20,"channel_id":79,"order_id":"1773129724383858433","flags":128,"ts_in_delta":2420,"sequence":44935,"symbol":"EUCO SI 20260814 PS EU C 1.1800 0"}
{"ts_recv":"2026-03-10T08:02:04.384125749Z","hd":{"ts_event":"2026-03-10T08:02:04.383831223Z","rtype":160,"publisher_id":101,"instrument_id":34645},"action":"R","side":"N","price":null,"size":0,"channel_id":79,"order_id":"0","flags":8,"ts_in_delta":0,"sequence":0,"symbol":"EUCO SI 20260814 PS EU P 1.1700 0"}
{"ts_recv":"2026-03-10T08:02:04.384125749Z","hd":{"ts_event":"2026-03-10T08:02:04.383831223Z","rtype":160,"publisher_id":101,"instrument_id":34645},"action":"A","side":"B","price":"0.018460000","size":20,"channel_id":79,"order_id":"10996501761238634241","flags":0,"ts_in_delta":2420,"sequence":44935,"symbol":"EUCO SI 20260814 PS EU P 1.1700 0"}
{"ts_recv":"2026-03-10T08:02:04.384125749Z","hd":{"ts_event":"2026-03-10T08:02:04.383831223Z","rtype":160,"publisher_id":101,"instrument_id":34645},"action":"A","side":"A","price":"0.018890000","size":20,"channel_id":79,"order_id":"1773129724383858433","flags":128,"ts_in_delta":2420,"sequence":44935,"symbol":"EUCO SI 20260814 PS EU P 1.1700 0"}
{"ts_recv":"2026-03-10T08:02:04.384125749Z","hd":{"ts_event":"2026-03-10T08:02:04.383831223Z","rtype":160,"publisher_id":101,"instrument_id":34643},"action":"R","side":"N","price":null,"size":0,"channel_id":79,"order_id":"0","flags":8,"ts_in_delta":0,"sequence":0,"symbol":"EUCO SI 20260814 PS EU P 1.1675 0"}
{"ts_recv":"2026-03-10T08:02:04.384125749Z","hd":{"ts_event":"2026-03-10T08:02:04.383831223Z","rtype":160,"publisher_id":101,"instrument_id":34643},"action":"A","side":"B","price":"0.017350000","size":20,"channel_id":79,"order_id":"10996501761238634241","flags":0,"ts_in_delta":2420,"sequence":44935,"symbol":"EUCO SI 20260814 PS EU P 1.1675 0"}
{"ts_recv":"2026-03-10T08:02:04.384125749Z","hd":{"ts_event":"2026-03-10T08:02:04.383831223Z","rtype":160,"publisher_id":101,"instrument_id":34643},"action":"A","side":"A","price":"0.017780000","size":20,"channel_id":79,"order_id":"1773129724383858433","flags":128,"ts_in_delta":2420,"sequence":44935,"symbol":"EUCO SI 20260814 PS EU P 1.1675 0"}
{"ts_recv":"2026-03-10T08:02:04.384125749Z","hd":{"ts_event":"2026-03-10T08:02:04.383831223Z","rtype":160,"publisher_id":101,"instrument_id":34642},"action":"R","side":"N","price":null,"size":0,"channel_id":79,"order_id":"0","flags":8,"ts_in_delta":0,"sequence":0,"symbol":"EUCO SI 20260814 PS EU C 1.1675 0"}
{"ts_recv":"2026-03-10T08:02:04.384125749Z","hd":{"ts_event":"2026-03-10T08:02:04.383831223Z","rtype":160,"publisher_id":101,"instrument_id":34642},"action":"A","side":"B","price":"0.024070000","size":20,"channel_id":79,"order_id":"10996501761238634241","flags":0,"ts_in_delta":2420,"sequence":44935,"symbol":"EUCO SI 20260814 PS EU C 1.1675 0"}
{"ts_recv":"2026-03-10T08:02:04.384125749Z","hd":{"ts_event":"2026-03-10T08:02:04.383831223Z","rtype":160,"publisher_id":101,"instrument_id":34642},"action":"A","side":"A","price":"0.024490000","size":20,"channel_id":79,"order_id":"1773129724383858433","flags":128,"ts_in_delta":2420,"sequence":44935,"symbol":"EUCO SI 20260814 PS EU C 1.1675 0"}
