{"ts_recv":"2026-03-12T08:20:40.272617252Z","hd":{"ts_event":"2026-03-12T08:20:40.272326581Z","rtype":160,"publisher_id":101,"instrument_id":35054},"action":"R","side":"N","price":null,"size":0,"channel_id":79,"order_id":"0","flags":8,"ts_in_delta":0,"sequence":0,"symbol":"EUCO SI 20260814 PS EU C 1.1675 0"}
{"ts_recv":"2026-03-12T08:20:40.272617252Z","hd":{"ts_event":"2026-03-12T08:20:40.272326581Z","rtype":160,"publisher_id":101,"instrument_id":35054},"action":"A","side":"B","price":"0.019450000","size":20,"channel_id":79,"order_id":"10996675677127129266","flags":0,"ts_in_delta":2392,"sequence":46889,"symbol":"EUCO SI 20260814 PS EU C 1.1675 0"}
{"ts_recv":"2026-03-12T08:20:40.272617252Z","hd":{"ts_event":"2026-03-12T08:20:40.272326581Z","rtype":160,"publisher_id":101,"instrument_id":35054},"action":"A","side":"A","price":"0.019870000","size":20,"channel_id":79,"order_id":"1773303640272353458","flags":128,"ts_in_delta":2392,"sequence":46889,"symbol":"EUCO SI 20260814 PS EU C 1.1675 0"}
{"ts_recv":"2026-03-12T08:20:40.272617252Z","hd":{"ts_event":"2026-03-12T08:20:40.272326581Z","rtype":160,"publisher_id":101,"instrument_id":35057},"action":"R","side":"N","price":null,"size":0,"channel_id":79,"order_id":"0","flags":8,"ts_in_delta":0,"sequence":0,"symbol":"EUCO SI 20260814 PS EU P 1.1700 0"}
{"ts_recv":"2026-03-12T08:20:40.272617252Z","hd":{"ts_event":"2026-03-12T08:20:40.272326581Z","rtype":160,"publisher_id":101,"instrument_id":35057},"action":"A","side":"B","price":"0.024760000","size":20,"channel_id":79,"order_id":"10996675677127129266","flags":0,"ts_in_delta":2392,"sequence":46889,"symbol":"EUCO SI 20260814 PS EU P 1.1700 0"}
{"ts_recv":"2026-03-12T08:20:40.272617252Z","hd":{"ts_event":"2026-03-12T08:20:40.272326581Z","rtype":160,"publisher_id":101,"instrument_id":35057},"action":"A","side":"A","price":"0.025180000","size":20,"channel_id":79,"order_id":"1773303640272353458","flags":128,"ts_in_delta":2392,"sequence":46889,"symbol":"EUCO SI 20260814 PS EU P 1.1700 0"}
{"ts_recv":"2026-03-12T08:20:40.272617252Z","hd":{"ts_event":"2026-03-12T08:20:40.272326581Z","rtype":160,"publisher_id":101,"instrument_id":35056},"action":"R","side":"N","price":null,"size":0,"channel_id":79,"order_id":"0","flags":8,"ts_in_delta":0,"sequence":0,"symbol":"EUCO SI 20260814 PS EU C 1.1700 0"}
{"ts_recv":"2026-03-12T08:20:40.272617252Z","hd":{"ts_event":"2026-03-12T08:20:40.272326581Z","rtype":160,"publisher_id":101,"instrument_id":35056},"action":"A","side":"B","price":"0.018310000","size":20,"channel_id":79,"order_id":"10996675677127129266","flags":0,"ts_in_delta":2392,"sequence":46889,"symbol":"EUCO SI 20260814 PS EU C 1.1700 0"}
{"ts_recv":"2026-03-12T08:20:40.272617252Z","hd":{"ts_event":"2026-03-12T08:20:40.272326581Z","rtype":160,"publisher_id":101,"instrument_id":35056},"action":"A","side":"A","price":"0.018740000","size":20,"channel_id":79,"order_id":"1773303640272353458","flags":128,"ts_in_delta":2392,"sequence":46889,"symbol":"EUCO SI 20260814 PS EU C 1.1700 0"}
{"ts_recv":"2026-03-12T08:20:40.272617252Z","hd":{"ts_event":"2026-03-12T08:20:40.272326581Z","rtype":160,"publisher_id":101,"instrument_id":35051},"action":"R","side":"N","price":null,"size":0,"channel_id":79,"order_id":"0","flags":8,"ts_in_delta":0,"sequence":0,"symbol":"EUCO SI 20260814 PS EU P 1.1625 0"}
{"ts_recv":"2026-03-12T08:20:40.272617252Z","hd":{"ts_event":"2026-03-12T08:20:40.272326581Z","rtype":160,"publisher_id":101,"instrument_id":35051},"action":"A","side":"B","price":"0.020940000","size":20,"channel_id":79,"order_id":"10996675677127129266","flags":0,"ts_in_delta":2392,"sequence":46889,"symbol":"EUCO SI 20260814 PS EU P 1.1625 0"}
{"ts_recv":"2026-03-12T08:20:40.272617252Z","hd":{"ts_event":"2026-03-12T08:20:40.272326581Z","rtype":160,"publisher_id":101,"instrument_id":35051},"action":"A","side":"A","price":"0.021360000","size":20,"channel_id":79,"order_id":"1773303640272353458","flags":128,"ts_in_delta":2392,"sequence":46889,"symbol":"EUCO SI 20260814 PS EU P 1.1625 0"}
{"ts_recv":"2026-03-12T08:20:40.272617252Z","hd":{"ts_event":"2026-03-12T08:20:40.272326581Z","rtype":160,"publisher_id":101,"instrument_id":35050},"action":"R","side":"N","price":null,"size":0,"channel_id":79,"order_id":"0","flags":8,"ts_in_delta":0,"sequence":0,"symbol":"EUCO SI 20260814 PS EU C 1.1625 0"}
{"ts_recv":"2026-03-12T08:20:40.272617252Z","hd":{"ts_event":"2026-03-12T08:20:40.272326581Z","rtype":160,"publisher_id":101,"instrument_id":35050},"action":"A","side":"B","price":"0.021870000","size":20,"channel_id":79,"order_id":"10996675677127129266","flags":0,"ts_in_delta":2392,"sequence":46889,"symbol":"EUCO SI 20260814 PS EU C 1.1625 0"}
{"ts_recv":"2026-03-12T08:20:40.272617252Z","hd":{"ts_event":"2026-03-12T08:20:40.272326581Z","rtype":160,"publisher_id":101,"instrument_id":35050},"action":"A","side":"A","price":"0.022300000","size":20,"channel_id":79,"order_id":"1773303640272353458","flags":128,"ts_in_delta":2392,"sequence":46889,"symbol":"EUCO SI 20260814 PS EU C 1.1625 0"}
{"ts_recv":"2026-03-12T08:20:40.272617252Z","hd":{"ts_event":"2026-03-12T08:20:40.272326581Z","rtype":160,"publisher_id":101,"instrument_id":35049},"action":"R","side":"N","price":null,"size":0,"channel_id":79,"order_id":"0","flags":8,"ts_in_delta":0,"sequence":0,"symbol":"EUCO SI 20260814 PS EU P 1.1600 0"}
{"ts_recv":"2026-03-12T08:20:40.272617252Z","hd":{"ts_event":"2026-03-12T08:20:40.272326581Z","rtype":160,"publisher_id":101,"instrument_id":35049},"action":"A","side":"B","price":"0.019770000","size":20,"channel_id":79,"order_id":"10996675677127129266","flags":0,"ts_in_delta":2392,"sequence":46889,"symbol":"EUCO SI 20260814 PS EU P 1.1600 0"}
{"ts_recv":"2026-03-12T08:20:40.272617252Z","hd":{"ts_event":"2026-03-12T08:20:40.272326581Z","rtype":160,"publisher_id":101,"instrument_id":35049},"action":"A","side":"A","price":"0.020190000","size":20,"channel_id":79,"order_id":"1773303640272353458","flags":128,"ts_in_delta":2392,"sequence":46889,"symbol":"EUCO SI 20260814 PS EU P 1.1600 0"}
{"ts_recv":"2026-03-12T08:20:40.272617252Z","hd":{"ts_event":"2026-03-12T08:20:40.272326581Z","rtype":160,"publisher_id":101,"instrument_id":35047},"action":"R","side":"N","price":null,"size":0,"channel_id":79,"order_id":"0","flags":8,"ts_in_delta":0,"sequence":0,"symbol":"EUCO SI 20260814 PS EU P 1.1575 0"}
{"ts_recv":"2026-03-12T08:20:40.272617252Z","hd":{"ts_event":"2026-03-12T08:20:40.272326581Z","rtype":160,"publisher_id":101,"instrument_id":35047},"action":"A","side":"B","price":"0.018650000","size":20,"channel_id":79,"order_id":"10996675677127129266","flags":0,"ts_in_delta":2392,"sequence":46889,"symbol":"EUCO SI 20260814 PS EU P 1.1575 0"}
{"ts_recv":"2026-03-12T08:20:40.272617252Z","hd":{"ts_event":"2026-03-12T08:20:40.272326581Z","rtype":160,"publisher_id":101,"instrument_id":35047},"action":"A","side":"A","price":"0.019070000","size":20,"channel_id":79,"order_id":"1773303640272353458","flags":128,"ts_in_delta":2392,"sequence":46889,"symbol":"EUCO SI 20260814 PS EU P 1.1575 0"}
{"ts_recv":"2026-03-12T08:20:40.272617252Z","hd":{"ts_event":"2026-03-12T08:20:40.272326581Z","rtype":160,"publisher_id":101,"instrument_id":35045},"action":"R","side":"N","price":null,"size":0,"channel_id":79,"order_id":"0","flags":8,"ts_in_delta":0,"sequence":0,"symbol":"EUCO SI 20260814 PS EU P 1.1550 0"}
{"ts_recv":"2026-03-12T08:20:40.272617252Z","hd":{"ts_event":"2026-03-12T08:20:40.272326581Z","rtype":160,"publisher_id":101,"instrument_id":35045},"action":"A","side":"B","price":"0.017580000","size":20,"channel_id":79,"order_id":"10996675677127129266","flags":0,"ts_in_delta":2392,"sequence":46889,"symbol":"EUCO SI 20260814 PS EU P 1.1550 0"}
{"ts_recv":"2026-03-12T08:20:40.272617252Z","hd":{"ts_event":"2026-03-12T08:20:40.272326581Z","rtype":160,"publisher_id":101,"instrument_id":35045},"action":"A","side":"A","price":"0.018000000","size":20,"channel_id":79,"order_id":"1773303640272353458","flags":128,"ts_in_delta":2392,"sequence":46889,"symbol":"EUCO SI 20260814 PS EU P 1.1550 0"}
{"ts_recv":"2026-03-12T08:20:40.272617252Z","hd":{"ts_event":"2026-03-12T08:20:40.272326581Z","rtype":160,"publisher_id":101,"instrument_id":35044},"action":"R","side":"N","price":null,"size":0,"channel_id":79,"order_id":"0","flags":8,"ts_in_delta":0,"sequence":0,"symbol":"EUCO SI 20260814 PS EU C 1.1550 0"}
{"ts_recv":"2026-03-12T08:20:40.272617252Z","hd":{"ts_event":"2026-03-12T08:20:40.272326581Z","rtype":160,"publisher_id":101,"instrument_id":35044},"action":"A","side":"B","price":"0.025890000","size":20,"channel_id":79,"order_id":"10996675677127129266","flags":0,"ts_in_delta":2392,"sequence":46889,"symbol":"EUCO SI 20260814 PS EU C 1.1550 0"}
{"ts_recv":"2026-03-12T08:20:40.272617252Z","hd":{"ts_event":"2026-03-12T08:20:40.272326581Z","rtype":160,"publisher_id":101,"instrument_id":35044},"action":"A","side":"A","price":"0.026320000","size":20,"channel_id":79,"order_id":"1773303640272353458","flags":128,"ts_in_delta":2392,"sequence":46889,"symbol":"EUCO SI 20260814 PS EU C 1.1550 0"}
{"ts_recv":"2026-03-12T08:20:40.272617252Z","hd":{"ts_event":"2026-03-12T08:20:40.272326581Z","rtype":160,"publisher_id":101,"instrument_id":35043},"action":"R","side":"N","price":null,"size":0,"channel_id":79,"order_id":"0","flags":8,"ts_in_delta":0,"sequence":0,"symbol":"EUCO SI 20260814 PS EU P 1.1525 0"}
{"ts_recv":"2026-03-12T08:20:40.272617252Z","hd":{"ts_event":"2026-03-12T08:20:40.272326581Z","rtype":160,"publisher_id":101,"instrument_id":35043},"action":"A","side":"B","price":"0.016560000","size":20,"channel_id":79,"order_id":"10996675677127129266","flags":0,"ts_in_delta":2392,"sequence":46889,"symbol":"EUCO SI 20260814 PS EU P 1.1525 0"}
{"ts_recv":"2026-03-12T08:20:40.272617252Z","hd":{"ts_event":"2026-03-12T08:20:40.272326581Z","rtype":160,"publisher_id":101,"instrument_id":35043},"action":"A","side":"A","price":"0.016980000","size":20,"channel_id":79,"order_id":"1773303640272353458","flags":128,"ts_in_delta":2392,"sequence":46889,"symbol":"EUCO SI 20260814 PS EU P 1.1525 0"}
{"ts_recv":"2026-03-12T08:20:40.272617252Z","hd":{"ts_event":"2026-03-12T08:20:40.272326581Z","rtype":160,"publisher_id":101,"instrument_id":34951},"action":"R","side":"N","price":null,"size":0,"channel_id":79,"order_id":"0","flags":8,"ts_in_delta":0,"sequence":0,"symbol":"EUCO SI 20260710 PS EU P 1.1525 0"}
{"ts_recv":"2026-03-12T08:20:40.272617252Z","hd":{"ts_event":"2026-03-12T08:20:40.272326581Z","rtype":160,"publisher_id":101,"instrument_id":34951},"action":"A","side":"B","price":"0.014730000","size":20,"channel_id":79,"order_id":"10996675677127129266","flags":0,"ts_in_delta":2392,"sequence":46889,"symbol":"EUCO SI 20260710 PS EU P 1.1525 0"}
{"ts_recv":"2026-03-12T08:20:40.272617252Z","hd":{"ts_event":"2026-03-12T08:20:40.272326581Z","rtype":160,"publisher_id":101,"instrument_id":35048},"action":"R","side":"N","price":null,"size":0,"channel_id":79,"order_id":"0","flags":8,"ts_in_delta":0,"sequence":0,"symbol":"EUCO SI 20260814 PS EU C 1.1600 0"}
{"ts_recv":"2026-03-12T08:20:40.272617252Z","hd":{"ts_event":"2026-03-12T08:20:40.272326581Z","rtype":160,"publisher_id":101,"instrument_id":35048},"action":"A","side":"B","price":"0.023160000","size":20,"channel_id":79,"order_id":"10996675677127129266","flags":0,"ts_in_delta":2392,"sequence":46889,"symbol":"EUCO SI 20260814 PS EU C 1.1600 0"}
{"ts_recv":"2026-03-12T08:20:40.272617252Z","hd":{"ts_event":"2026-03-12T08:20:40.272326581Z","rtype":160,"publisher_id":101,"instrument_id":35048},"action":"A","side":"A","price":"0.023590000","size":20,"channel_id":79,"order_id":"1773303640272353458","flags":128,"ts_in_delta":2392,"sequence":46889,"symbol":"EUCO SI 20260814 PS EU C 1.1600 0"}
{"ts_recv":"2026-03-12T08:20:40.272618826Z","hd":{"ts_event":"2026-03-12T08:20:40.272326581Z","rtype":160,"publisher_id":101,"instrument_id":34951},"action":"A","side":"A","price":"0.015150000","size":20,"channel_id":79,"order_id":"1773303640272353458","flags":128,"ts_in_delta":2005,"sequence":46890,"symbol":"EUCO SI 20260710 PS EU P 1.1525 0"}
{"ts_recv":"2026-03-12T08:20:40.272618826Z","hd":{"ts_event":"2026-03-12T08:20:40.272326581Z","rtype":160,"publisher_id":101,"instrument_id":35046},"action":"R","side":"N","price":null,"size":0,"channel_id":79,"order_id":"0","flags":8,"ts_in_delta":0,"sequence":0,"symbol":"EUCO SI 20260814 PS EU C 1.1575 0"}
{"ts_recv":"2026-03-12T08:20:40.272618826Z","hd":{"ts_event":"2026-03-12T08:20:40.272326581Z","rtype":160,"publisher_id":101,"instrument_id":35046},"action":"A","side":"B","price":"0.024500000","size":20,"channel_id":79,"order_id":"10996675677127129266","flags":0,"ts_in_delta":2005,"sequence":46890,"symbol":"EUCO SI 20260814 PS EU C 1.1575 0"}
{"ts_recv":"2026-03-12T08:20:40.272618826Z","hd":{"ts_event":"2026-03-12T08:20:40.272326581Z","rtype":160,"publisher_id":101,"instrument_id":35046},"action":"A","side":"A","price":"0.024930000","size":20,"channel_id":79,"order_id":"1773303640272353458","flags":128,"ts_in_delta":2005,"sequence":46890,"symbol":"EUCO SI 20260814 PS EU C 1.1575 0"}
{"ts_recv":"2026-03-12T08:20:40.272618826Z","hd":{"ts_event":"2026-03-12T08:20:40.272326581Z","rtype":160,"publisher_id":101,"instrument_id":35059},"action":"R","side":"N","price":null,"size":0,"channel_id":79,"order_id":"0","flags":8,"ts_in_delta":0,"sequence":0,"symbol":"EUCO SI 20260814 PS EU P 1.1725 0"}
{"ts_recv":"2026-03-12T08:20:40.272618826Z","hd":{"ts_event":"2026-03-12T08:20:40.272326581Z","rtype":160,"publisher_id":101,"instrument_id":35059},"action":"A","side":"B","price":"0.026130000","size":20,"channel_id":79,"order_id":"10996675677127129266","flags":0,"ts_in_delta":2005,"sequence":46890,"symbol":"EUCO SI 20260814 PS EU P 1.1725 0"}
{"ts_recv":"2026-03-12T08:20:40.272618826Z","hd":{"ts_event":"2026-03-12T08:20:40.272326581Z","rtype":160,"publisher_id":101,"instrument_id":35059},"action":"A","side":"A","price":"0.026560000","size":20,"channel_id":79,"order_id":"1773303640272353458","flags":128,"ts_in_delta":2005,"sequence":46890,"symbol":"EUCO SI 20260814 PS EU P 1.1725 0"}
{"ts_recv":"2026-03-12T08:20:40.272618826Z","hd":{"ts_event":"2026-03-12T08:20:40.272326581Z","rtype":160,"publisher_id":101,"instrument_id":35055},"action":"R","side":"N","price":null,"size":0,"channel_id":79,"order_id":"0","flags":8,"ts_in_delta":0,"sequence":0,"symbol":"EUCO SI 20260814 PS EU P 1.1675 0"}
{"ts_recv":"2026-03-12T08:20:40.272618826Z","hd":{"ts_event":"2026-03-12T08:20:40.272326581Z","rtype":160,"publisher_id":101,"instrument_id":35055},"action":"A","side":"B","price":"0.023430000","size":20,"channel_id":79,"order_id":"10996675677127129266","flags":0,"ts_in_delta":2005,"sequence":46890,"symbol":"EUCO SI 20260814 PS EU P 1.1675 0"}
{"ts_recv":"2026-03-12T08:20:40.272618826Z","hd":{"ts_event":"2026-03-12T08:20:40.272326581Z","rtype":160,"publisher_id":101,"instrument_id":35055},"action":"A","side":"A","price":"0.023860000","size":20,"channel_id":79,"order_id":"1773303640272353458","flags":128,"ts_in_delta":2005,"sequence":46890,"symbol":"EUCO SI 20260814 PS EU P 1.1675 0"}
{"ts_recv":"2026-03-12T08:20:40.272618826Z","hd":{"ts_event":"2026-03-12T08:20:40.272326581Z","rtype":160,"publisher_id":101,"instrument_id":34962},"action":"R","side":"N","price":null,"size":0,"channel_id":79,"order_id":"0","flags":8,"ts_in_delta":0,"sequence":0,"symbol":"EUCO SI 20260710 PS EU C 1.1675 0"}
{"ts_recv":"2026-03-12T08:20:40.272618826Z","hd":{"ts_event":"2026-03-12T08:20:40.272326581Z","rtype":160,"publisher_id":101,"instrument_id":34962},"action":"A","side":"B","price":"0.016080000","size":20,"channel_id":79,"order_id":"10996675677127129266","flags":0,"ts_in_delta":2005,"sequence":46890,"symbol":"EUCO SI 20260710 PS EU C 1.1675 0"}
{"ts_recv":"2026-03-12T08:20:40.272618826Z","hd":{"ts_event":"2026-03-12T08:20:40.272326581Z","rtype":160,"publisher_id":101,"instrument_id":34962},"action":"A","side":"A","price":"0.016510000","size":20,"channel_id":79,"order_id":"1773303640272353458","flags":128,"ts_in_delta":2005,"sequence":46890,"symbol":"EUCO SI 20260710 PS EU C 1.1675 0"}
{"ts_recv":"2026-03-12T08:20:40.272618826Z","hd":{"ts_event":"2026-03-12T08:20:40.272326581Z","rtype":160,"publisher_id":101,"instrument_id":34961},"action":"R","side":"N","price":null,"size":0,"channel_id":79,"order_id":"0","flags":8,"ts_in_delta":0,"sequence":0,"symbol":"EUCO SI 20260710 PS EU P 1.1650 0"}
{"ts_recv":"2026-03-12T08:20:40.272618826Z","hd":{"ts_event":"2026-03-12T08:20:40.272326581Z","rtype":160,"publisher_id":101,"instrument_id":34961},"action":"A","side":"B","price":"0.020360000","size":20,"channel_id":79,"order_id":"10996675677127129266","flags":0,"ts_in_delta":2005,"sequence":46890,"symbol":"EUCO SI 20260710 PS EU P 1.1650 0"}
{"ts_recv":"2026-03-12T08:20:40.272618826Z","hd":{"ts_event":"2026-03-12T08:20:40.272326581Z","rtype":160,"publisher_id":101,"instrument_id":34961},"action":"A","side":"A","price":"0.020790000","size":20,"channel_id":79,"order_id":"1773303640272353458","flags":128,"ts_in_delta":2005,"sequence":46890,"symbol":"EUCO SI 20260710 PS EU P 1.1650 0"}
{"ts_recv":"2026-03-12T08:20:40.272618826Z","hd":{"ts_event":"2026-03-12T08:20:40.272326581Z","rtype":160,"publisher_id":101,"instrument_id":34960},"action":"R","side":"N","price":null,"size":0,"channel_id":79,"order_id":"0","flags":8,"ts_in_delta":0,"sequence":0,"symbol":"EUCO SI 20260710 PS EU C 1.1650 0"}
{"ts_recv":"2026-03-12T08:20:40.272618826Z","hd":{"ts_event":"2026-03-12T08:20:40.272326581Z","rtype":160,"publisher_id":101,"instrument_id":34960},"action":"A","side":"B","price":"0.017250000","size":20,"channel_id":79,"order_id":"10996675677127129266","flags":0,"ts_in_delta":2005,"sequence":46890,"symbol":"EUCO SI 20260710 PS EU C 1.1650 0"}
{"ts_recv":"2026-03-12T08:20:40.272618826Z","hd":{"ts_event":"2026-03-12T08:20:40.272326581Z","rtype":160,"publisher_id":101,"instrument_id":34960},"action":"A","side":"A","price":"0.017680000","size":20,"channel_id":79,"order_id":"1773303640272353458","flags":128,"ts_in_delta":2005,"sequence":46890,"symbol":"EUCO SI 20260710 PS EU C 1.1650 0"}
{"ts_recv":"2026-03-12T08:20:40.272618826Z","hd":{"ts_event":"2026-03-12T08:20:40.272326581Z","rtype":160,"publisher_id":101,"instrument_id":34957},"action":"R","side":"N","price":null,"size":0,"channel_id":79,"order_id":"0","flags":8,"ts_in_delta":0,"sequence":0,"symbol":"EUCO SI 20260710 PS EU P 1.1600 0"}
{"ts_recv":"2026-03-12T08:20:40.272618826Z","hd":{"ts_event":"2026-03-12T08:20:40.272326581Z","rtype":160,"publisher_id":101,"instrument_id":34957},"action":"A","side":"B","price":"0.017940000","size":20,"channel_id":79,"order_id":"10996675677127129266","flags":0,"ts_in_delta":2005,"sequence":46890,"symbol":"EUCO SI 20260710 PS EU P 1.1600 0"}
{"ts_recv":"2026-03-12T08:20:40.272618826Z","hd":{"ts_event":"2026-03-12T08:20:40.272326581Z","rtype":160,"publisher_id":101,"instrument_id":34957},"action":"A","side":"A","price":"0.018360000","size":20,"channel_id":79,"order_id":"1773303640272353458","flags":128,"ts_in_delta":2005,"sequence":46890,"symbol":"EUCO SI 20260710 PS EU P 1.1600 0"}
{"ts_recv":"2026-03-12T08:20:40.272618826Z","hd":{"ts_event":"2026-03-12T08:20:40.272326581Z","rtype":160,"publisher_id":101,"instrument_id":34956},"action":"R","side":"N","price":null,"size":0,"channel_id":79,"order_id":"0","flags":8,"ts_in_delta":0,"sequence":0,"symbol":"EUCO SI 20260710 PS EU C 1.1600 0"}
{"ts_recv":"2026-03-12T08:20:40.272618826Z","hd":{"ts_event":"2026-03-12T08:20:40.272326581Z","rtype":160,"publisher_id":101,"instrument_id":34956},"action":"A","side":"B","price":"0.019760000","size":20,"channel_id":79,"order_id":"10996675677127129266","flags":0,"ts_in_delta":2005,"sequence":46890,"symbol":"EUCO SI 20260710 PS EU C 1.1600 0"}
{"ts_recv":"2026-03-12T08:20:40.272618826Z","hd":{"ts_event":"2026-03-12T08:20:40.272326581Z","rtype":160,"publisher_id":101,"instrument_id":34956},"action":"A","side":"A","price":"0.020190000","size":20,"channel_id":79,"order_id":"1773303640272353458","flags":128,"ts_in_delta":2005,"sequence":46890,"symbol":"EUCO SI 20260710 PS EU C 1.1600 0"}
{"ts_recv":"2026-03-12T08:20:40.272618826Z","hd":{"ts_event":"2026-03-12T08:20:40.272326581Z","rtype":160,"publisher_id":101,"instrument_id":34953},"action":"R","side":"N","price":null,"size":0,"channel_id":79,"order_id":"0","flags":8,"ts_in_delta":0,"sequence":0,"symbol":"EUCO SI 20260710 PS EU P 1.1550 0"}
{"ts_recv":"2026-03-12T08:20:40.272618826Z","hd":{"ts_event":"2026-03-12T08:20:40.272326581Z","rtype":160,"publisher_id":101,"instrument_id":34953},"action":"A","side":"B","price":"0.015740000","size":20,"channel_id":79,"order_id":"10996675677127129266","flags":0,"ts_in_delta":2005,"sequence":46890,"symbol":"EUCO SI 20260710 PS EU P 1.1550 0"}
{"ts_recv":"2026-03-12T08:20:40.272618826Z","hd":{"ts_event":"2026-03-12T08:20:40.272326581Z","rtype":160,"publisher_id":101,"instrument_id":34953},"action":"A","side":"A","price":"0.016170000","size":20,"channel_id":79,"order_id":"1773303640272353458","flags":128,"ts_in_delta":2005,"sequence":46890,"symbol":"EUCO SI 20260710 PS EU P 1.1550 0"}
{"ts_recv":"2026-03-12T08:20:40.272618826Z","hd":{"ts_event":"2026-03-12T08:20:40.272326581Z","rtype":160,"publisher_id":101,"instrument_id":34952},"action":"R","side":"N","price":null,"size":0,"channel_id":79,"order_id":"0","flags":8,"ts_in_delta":0,"sequence":0,"symbol":"EUCO SI 20260710 PS EU C 1.1550 0"}
{"ts_recv":"2026-03-12T08:20:40.272618826Z","hd":{"ts_event":"2026-03-12T08:20:40.272326581Z","rtype":160,"publisher_id":101,"instrument_id":34952},"action":"A","side":"B","price":"0.022500000","size":20,"channel_id":79,"order_id":"10996675677127129266","flags":0,"ts_in_delta":2005,"sequence":46890,"symbol":"EUCO SI 20260710 PS EU C 1.1550 0"}
{"ts_recv":"2026-03-12T08:20:40.272618826Z","hd":{"ts_event":"2026-03-12T08:20:40.272326581Z","rtype":160,"publisher_id":101,"instrument_id":34952},"action":"A","side":"A","price":"0.022930000","size":20,"channel_id":79,"order_id":"1773303640272353458","flags":128,"ts_in_delta":2005,"sequence":46890,"symbol":"EUCO SI 20260710 PS EU C 1.1550 0"}
{"ts_recv":"2026-03-12T08:20:40.272618826Z","hd":{"ts_event":"2026-03-12T08:20:40.272326581Z","rtype":160,"publisher_id":101,"instrument_id":34949},"action":"R","side":"N","price":null,"size":0,"channel_id":79,"order_id":"0","flags":8,"ts_in_delta":0,"sequence":0,"symbol":"EUCO SI 20260710 PS EU P 1.1500 0"}
{"ts_recv":"2026-03-12T08:20:40.272618826Z","hd":{"ts_event":"2026-03-12T08:20:40.272326581Z","rtype":160,"publisher_id":101,"instrument_id":34949},"action":"A","side":"B","price":"0.013770000","size":20,"channel_id":79,"order_id":"10996675677127129266","flags":0,"ts_in_delta":2005,"sequence":46890,"symbol":"EUCO SI 20260710 PS EU P 1.1500 0"}
{"ts_recv":"2026-03-12T08:20:40.272618826Z","hd":{"ts_event":"2026-03-12T08:20:40.272326581Z","rtype":160,"publisher_id":101,"instrument_id":34949},"action":"A","side":"A","price":"0.014200000","size":20,"channel_id":79,"order_id":"1773303640272353458","flags":128,"ts_in_delta":2005,"sequence":46890,"symbol":"EUCO SI 20260710 PS EU P 1.1500 0"}
{"ts_recv":"2026-03-12T08:20:40.272620516Z","hd":{"ts_event":"2026-03-12T08:20:40.272326581Z","rtype":160,"publisher_id":101,"instrument_id":35052},"action":"R","side":"N","price":null,"size":0,"channel_id":79,"order_id":"0","flags":8,"ts_in_delta":0,"sequence":0,"symbol":"EUCO SI 20260814 PS EU C 1.1650 0"}
{"ts_recv":"2026-03-12T08:20:40.272620516Z","hd":{"ts_event":"2026-03-12T08:20:40.272326581Z","rtype":160,"publisher_id":101,"instrument_id":35052},"action":"A","side":"B","price":"0.020630000","size":20,"channel_id":79,"order_id":"10996675677127129266","flags":0,"ts_in_delta":2480,"sequence":46891,"symbol":"EUCO SI 20260814 PS EU C 1.1650 0"}
{"ts_recv":"2026-03-12T08:20:40.272620516Z","hd":{"ts_event":"2026-03-12T08:20:40.272326581Z","rtype":160,"publisher_id":101,"instrument_id":35052},"action":"A","side":"A","price":"0.021060000","size":20,"channel_id":79,"order_id":"1773303640272353458","flags":128,"ts_in_delta":2480,"sequence":46891,"symbol":"EUCO SI 20260814 PS EU C 1.1650 0"}
{"ts_recv":"2026-03-12T08:20:40.272620516Z","hd":{"ts_event":"2026-03-12T08:20:40.272326581Z","rtype":160,"publisher_id":101,"instrument_id":34766},"action":"R","side":"N","price":null,"size":0,"channel_id":79,"order_id":"0","flags":8,"ts_in_delta":0,"sequence":0,"symbol":"EUCO SI 20260508 PS EU C 1.1650 0"}
{"ts_recv":"2026-03-12T08:20:40.272620516Z","hd":{"ts_event":"2026-03-12T08:20:40.272326581Z","rtype":160,"publisher_id":101,"instrument_id":34766},"action":"A","side":"B","price":"0.010310000","size":20,"channel_id":79,"order_id":"10996675677127129266","flags":0,"ts_in_delta":2480,"sequence":46891,"symbol":"EUCO SI 20260508 PS EU C 1.1650 0"}
{"ts_recv":"2026-03-12T08:20:40.272620516Z","hd":{"ts_event":"2026-03-12T08:20:40.272326581Z","rtype":160,"publisher_id":101,"instrument_id":34766},"action":"A","side":"A","price":"0.010740000","size":20,"channel_id":79,"order_id":"1773303640272353458","flags":128,"ts_in_delta":2480,"sequence":46891,"symbol":"EUCO SI 20260508 PS EU C 1.1650 0"}
{"ts_recv":"2026-03-12T08:20:40.272620516Z","hd":{"ts_event":"2026-03-12T08:20:40.272326581Z","rtype":160,"publisher_id":101,"instrument_id":34753},"action":"R","side":"N","price":null,"size":0,"channel_id":79,"order_id":"0","flags":8,"ts_in_delta":0,"sequence":0,"symbol":"EUCO SI 20260508 PS EU P 1.1475 0"}
{"ts_recv":"2026-03-12T08:20:40.272620516Z","hd":{"ts_event":"2026-03-12T08:20:40.272326581Z","rtype":160,"publisher_id":101,"instrument_id":34753},"action":"A","side":"B","price":"0.008760000","size":20,"channel_id":79,"order_id":"10996675677127129266","flags":0,"ts_in_delta":2480,"sequence":46891,"symbol":"EUCO SI 20260508 PS EU P 1.1475 0"}
{"ts_recv":"2026-03-12T08:20:40.272620516Z","hd":{"ts_event":"2026-03-12T08:20:40.272326581Z","rtype":160,"publisher_id":101,"instrument_id":34753},"action":"A","side":"A","price":"0.009190000","size":20,"channel_id":79,"order_id":"1773303640272353458","flags":128,"ts_in_delta":2480,"sequence":46891,"symbol":"EUCO SI 20260508 PS EU P 1.1475 0"}
{"ts_recv":"2026-03-12T08:20:40.272620516Z","hd":{"ts_event":"2026-03-12T08:20:40.272326581Z","rtype":160,"publisher_id":101,"instrument_id":34658},"action":"R","side":"N","price":null,"size":0,"channel_id":79,"order_id":"0","flags":8,"ts_in_delta":0,"sequence":0,"symbol":"EUCO SI 20260410 PS EU C 1.1575 0"}
{"ts_recv":"2026-03-12T08:20:40.272620516Z","hd":{"ts_event":"2026-03-12T08:20:40.272326581Z","rtype":160,"publisher_id":101,"instrument_id":34658},"action":"A","side":"B","price":"0.009530000","size":20,"channel_id":79,"order_id":"10996675677127129266","flags":0,"ts_in_delta":2480,"sequence":46891,"symbol":"EUCO SI 20260410 PS EU C 1.1575 0"}
{"ts_recv":"2026-03-12T08:20:40.272620516Z","hd":{"ts_event":"2026-03-12T08:20:40.272326581Z","rtype":160,"publisher_id":101,"instrument_id":34658},"action":"A","side":"A","price":"0.009950000","size":20,"channel_id":79,"order_id":"1773303640272353458","flags":128,"ts_in_delta":2480,"sequence":46891,"symbol":"EUCO SI 20260410 PS EU C 1.1575 0"}
{"ts_recv":"2026-03-12T08:20:40.272620516Z","hd":{"ts_event":"2026-03-12T08:20:40.272326581Z","rtype":160,"publisher_id":101,"instrument_id":34657},"action":"R","side":"N","price":null,"size":0,"channel_id":79,"order_id":"0","flags":8,"ts_in_delta":0,"sequence":0,"symbol":"EUCO SI 20260410 PS EU P 1.1550 0"}
{"ts_recv":"2026-03-12T08:20:40.272620516Z","hd":{"ts_event":"2026-03-12T08:20:40.272326581Z","rtype":160,"publisher_id":101,"instrument_id":34657},"action":"A","side":"B","price":"0.008860000","size":20,"channel_id":79,"order_id":"10996675677127129266","flags":0,"ts_in_delta":2480,"sequence":46891,"symbol":"EUCO SI 20260410 PS EU P 1.1550 0"}
{"ts_recv":"2026-03-12T08:20:40.272620516Z","hd":{"ts_event":"2026-03-12T08:20:40.272326581Z","rtype":160,"publisher_id":101,"instrument_id":34657},"action":"A","side":"A","price":"0.009290000","size":20,"channel_id":79,"order_id":"1773303640272353458","flags":128,"ts_in_delta":2480,"sequence":46891,"symbol":"EUCO SI 20260410 PS EU P 1.1550 0"}
{"ts_recv":"2026-03-12T08:20:40.272620516Z","hd":{"ts_event":"2026-03-12T08:20:40.272326581Z","rtype":160,"publisher_id":101,"instrument_id":34656},"action":"R","side":"N","price":null,"size":0,"channel_id":79,"order_id":"0","flags":8,"ts_in_delta":0,"sequence":0,"symbol":"EUCO SI 20260410 PS EU C 1.1550 0"}
{"ts_recv":"2026-03-12T08:20:40.272620516Z","hd":{"ts_event":"2026-03-12T08:20:40.272326581Z","rtype":160,"publisher_id":101,"instrument_id":34656},"action":"A","side":"B","price":"0.010920000","size":20,"channel_id":79,"order_id":"10996675677127129266","flags":0,"ts_in_delta":2480,"sequence":46891,"symbol":"EUCO SI 20260410 PS EU C 1.1550 0"}
{"ts_recv":"2026-03-12T08:20:40.272620516Z","hd":{"ts_event":"2026-03-12T08:20:40.272326581Z","rtype":160,"publisher_id":101,"instrument_id":34656},"action":"A","side":"A","price":"0.011350000","size":20,"channel_id":79,"order_id":"1773303640272353458","flags":128,"ts_in_delta":2480,"sequence":46891,"symbol":"EUCO SI 20260410 PS EU C 1.1550 0"}
{"ts_recv":"2026-03-12T08:20:40.272620516Z","hd":{"ts_event":"2026-03-12T08:20:40.272326581Z","rtype":160,"publisher_id":101,"instrument_id":34654},"action":"R","side":"N","price":null,"size":0,"channel_id":79,"order_id":"0","flags":8,"ts_in_delta":0,"sequence":0,"symbol":"EUCO SI 20260410 PS EU C 1.1525 0"}
{"ts_recv":"2026-03-12T08:20:40.272620516Z","hd":{"ts_event":"2026-03-12T08:20:40.272326581Z","rtype":160,"publisher_id":101,"instrument_id":34654},"action":"A","side":"B","price":"0.012420000","size":20,"channel_id":79,"order_id":"10996675677127129266","flags":0,"ts_in_delta":2480,"sequence":46891,"symbol":"EUCO SI 20260410 PS EU C 1.1525 0"}
{"ts_recv":"2026-03-12T08:20:40.272620516Z","hd":{"ts_event":"2026-03-12T08:20:40.272326581Z","rtype":160,"publisher_id":101,"instrument_id":34654},"action":"A","side":"A","price":"0.012850000","size":20,"channel_id":79,"order_id":"1773303640272353458","flags":128,"ts_in_delta":2480,"sequence":46891,"symbol":"EUCO SI 20260410 PS EU C 1.1525 0"}
