{"ts_recv":"2026-04-06T18:53:11.430340287Z","hd":{"ts_event":"2026-04-06T18:53:11.430338519Z","rtype":160,"publisher_id":101,"instrument_id":33974},"action":"R","side":"N","price":null,"size":0,"channel_id":79,"order_id":"0","flags":128,"ts_in_delta":1768,"sequence":0,"symbol":"EUCO SI 20270312 PS EU P 1.2250 0"}
{"ts_recv":"2026-04-06T18:53:11.430340287Z","hd":{"ts_event":"2026-04-06T18:53:11.430338519Z","rtype":160,"publisher_id":101,"instrument_id":33973},"action":"R","side":"N","price":null,"size":0,"channel_id":79,"order_id":"0","flags":128,"ts_in_delta":1768,"sequence":0,"symbol":"EUCO SI 20270312 PS EU C 1.2250 0"}
{"ts_recv":"2026-04-06T18:53:11.430340287Z","hd":{"ts_event":"2026-04-06T18:53:11.430338519Z","rtype":160,"publisher_id":101,"instrument_id":33972},"action":"R","side":"N","price":null,"size":0,"channel_id":79,"order_id":"0","flags":128,"ts_in_delta":1768,"sequence":0,"symbol":"EUCO SI 20270312 PS EU P 1.2200 0"}
{"ts_recv":"2026-04-06T18:53:11.430340287Z","hd":{"ts_event":"2026-04-06T18:53:11.430338519Z","rtype":160,"publisher_id":101,"instrument_id":33971},"action":"R","side":"N","price":null,"size":0,"channel_id":79,"order_id":"0","flags":128,"ts_in_delta":1768,"sequence":0,"symbol":"EUCO SI 20270312 PS EU C 1.2200 0"}
{"ts_recv":"2026-04-06T18:53:11.430340287Z","hd":{"ts_event":"2026-04-06T18:53:11.430338519Z","rtype":160,"publisher_id":101,"instrument_id":33970},"action":"R","side":"N","price":null,"size":0,"channel_id":79,"order_id":"0","flags":128,"ts_in_delta":1768,"sequence":0,"symbol":"EUCO SI 20270312 PS EU P 1.2150 0"}
{"ts_recv":"2026-04-06T18:53:11.430340287Z","hd":{"ts_event":"2026-04-06T18:53:11.430338519Z","rtype":160,"publisher_id":101,"instrument_id":33969},"action":"R","side":"N","price":null,"size":0,"channel_id":79,"order_id":"0","flags":128,"ts_in_delta":1768,"sequence":0,"symbol":"EUCO SI 20270312 PS EU C 1.2150 0"}
{"ts_recv":"2026-04-06T18:53:11.430340287Z","hd":{"ts_event":"2026-04-06T18:53:11.430338519Z","rtype":160,"publisher_id":101,"instrument_id":33968},"action":"R","side":"N","price":null,"size":0,"channel_id":79,"order_id":"0","flags":128,"ts_in_delta":1768,"sequence":0,"symbol":"EUCO SI 20270312 PS EU P 1.2100 0"}
{"ts_recv":"2026-04-06T18:53:11.430340287Z","hd":{"ts_event":"2026-04-06T18:53:11.430338519Z","rtype":160,"publisher_id":101,"instrument_id":33967},"action":"R","side":"N","price":null,"size":0,"channel_id":79,"order_id":"0","flags":128,"ts_in_delta":1768,"sequence":0,"symbol":"EUCO SI 20270312 PS EU C 1.2100 0"}
{"ts_recv":"2026-04-06T18:53:11.430340287Z","hd":{"ts_event":"2026-04-06T18:53:11.430338519Z","rtype":160,"publisher_id":101,"instrument_id":33966},"action":"R","side":"N","price":null,"size":0,"channel_id":79,"order_id":"0","flags":128,"ts_in_delta":1768,"sequence":0,"symbol":"EUCO SI 20270312 PS EU P 1.2050 0"}
{"ts_recv":"2026-04-06T18:53:11.430340287Z","hd":{"ts_event":"2026-04-06T18:53:11.430338519Z","rtype":160,"publisher_id":101,"instrument_id":33965},"action":"R","side":"N","price":null,"size":0,"channel_id":79,"order_id":"0","flags":128,"ts_in_delta":1768,"sequence":0,"symbol":"EUCO SI 20270312 PS EU C 1.2050 0"}
{"ts_recv":"2026-04-06T18:53:11.430340287Z","hd":{"ts_event":"2026-04-06T18:53:11.430338519Z","rtype":160,"publisher_id":101,"instrument_id":33964},"action":"R","side":"N","price":null,"size":0,"channel_id":79,"order_id":"0","flags":128,"ts_in_delta":1768,"sequence":0,"symbol":"EUCO SI 20270312 PS EU P 1.2000 0"}
{"ts_recv":"2026-04-06T18:53:11.430340287Z","hd":{"ts_event":"2026-04-06T18:53:11.430338519Z","rtype":160,"publisher_id":101,"instrument_id":33963},"action":"R","side":"N","price":null,"size":0,"channel_id":79,"order_id":"0","flags":128,"ts_in_delta":1768,"sequence":0,"symbol":"EUCO SI 20270312 PS EU C 1.2000 0"}
{"ts_recv":"2026-04-06T18:53:11.430340287Z","hd":{"ts_event":"2026-04-06T18:53:11.430338519Z","rtype":160,"publisher_id":101,"instrument_id":33962},"action":"R","side":"N","price":null,"size":0,"channel_id":79,"order_id":"0","flags":128,"ts_in_delta":1768,"sequence":0,"symbol":"EUCO SI 20270312 PS EU P 1.1950 0"}
{"ts_recv":"2026-04-06T18:53:11.430340287Z","hd":{"ts_event":"2026-04-06T18:53:11.430338519Z","rtype":160,"publisher_id":101,"instrument_id":33961},"action":"R","side":"N","price":null,"size":0,"channel_id":79,"order_id":"0","flags":128,"ts_in_delta":1768,"sequence":0,"symbol":"EUCO SI 20270312 PS EU C 1.1950 0"}
{"ts_recv":"2026-04-06T18:53:11.430340287Z","hd":{"ts_event":"2026-04-06T18:53:11.430338519Z","rtype":160,"publisher_id":101,"instrument_id":33960},"action":"R","side":"N","price":null,"size":0,"channel_id":79,"order_id":"0","flags":128,"ts_in_delta":1768,"sequence":0,"symbol":"EUCO SI 20270312 PS EU P 1.1900 0"}
{"ts_recv":"2026-04-06T18:53:11.430340287Z","hd":{"ts_event":"2026-04-06T18:53:11.430338519Z","rtype":160,"publisher_id":101,"instrument_id":33959},"action":"R","side":"N","price":null,"size":0,"channel_id":79,"order_id":"0","flags":128,"ts_in_delta":1768,"sequence":0,"symbol":"EUCO SI 20270312 PS EU C 1.1900 0"}
{"ts_recv":"2026-04-06T18:53:11.430340287Z","hd":{"ts_event":"2026-04-06T18:53:11.430338519Z","rtype":160,"publisher_id":101,"instrument_id":33958},"action":"R","side":"N","price":null,"size":0,"channel_id":79,"order_id":"0","flags":128,"ts_in_delta":1768,"sequence":0,"symbol":"EUCO SI 20270312 PS EU P 1.1850 0"}
{"ts_recv":"2026-04-06T18:53:11.430340287Z","hd":{"ts_event":"2026-04-06T18:53:11.430338519Z","rtype":160,"publisher_id":101,"instrument_id":33957},"action":"R","side":"N","price":null,"size":0,"channel_id":79,"order_id":"0","flags":128,"ts_in_delta":1768,"sequence":0,"symbol":"EUCO SI 20270312 PS EU C 1.1850 0"}
{"ts_recv":"2026-04-06T18:53:11.430340287Z","hd":{"ts_event":"2026-04-06T18:53:11.430338519Z","rtype":160,"publisher_id":101,"instrument_id":33956},"action":"R","side":"N","price":null,"size":0,"channel_id":79,"order_id":"0","flags":128,"ts_in_delta":1768,"sequence":0,"symbol":"EUCO SI 20270312 PS EU P 1.1800 0"}
{"ts_recv":"2026-04-06T18:53:11.430340287Z","hd":{"ts_event":"2026-04-06T18:53:11.430338519Z","rtype":160,"publisher_id":101,"instrument_id":33955},"action":"R","side":"N","price":null,"size":0,"channel_id":79,"order_id":"0","flags":128,"ts_in_delta":1768,"sequence":0,"symbol":"EUCO SI 20270312 PS EU C 1.1800 0"}
{"ts_recv":"2026-04-06T18:53:11.430340287Z","hd":{"ts_event":"2026-04-06T18:53:11.430338519Z","rtype":160,"publisher_id":101,"instrument_id":33954},"action":"R","side":"N","price":null,"size":0,"channel_id":79,"order_id":"0","flags":128,"ts_in_delta":1768,"sequence":0,"symbol":"EUCO SI 20270312 PS EU P 1.1750 0"}
{"ts_recv":"2026-04-06T18:53:11.430340287Z","hd":{"ts_event":"2026-04-06T18:53:11.430338519Z","rtype":160,"publisher_id":101,"instrument_id":33953},"action":"R","side":"N","price":null,"size":0,"channel_id":79,"order_id":"0","flags":128,"ts_in_delta":1768,"sequence":0,"symbol":"EUCO SI 20270312 PS EU C 1.1750 0"}
{"ts_recv":"2026-04-06T18:53:11.430340287Z","hd":{"ts_event":"2026-04-06T18:53:11.430338519Z","rtype":160,"publisher_id":101,"instrument_id":33952},"action":"R","side":"N","price":null,"size":0,"channel_id":79,"order_id":"0","flags":128,"ts_in_delta":1768,"sequence":0,"symbol":"EUCO SI 20270312 PS EU P 1.1700 0"}
{"ts_recv":"2026-04-06T18:53:11.430340287Z","hd":{"ts_event":"2026-04-06T18:53:11.430338519Z","rtype":160,"publisher_id":101,"instrument_id":33951},"action":"R","side":"N","price":null,"size":0,"channel_id":79,"order_id":"0","flags":128,"ts_in_delta":1768,"sequence":0,"symbol":"EUCO SI 20270312 PS EU C 1.1700 0"}
{"ts_recv":"2026-04-06T18:53:11.430340287Z","hd":{"ts_event":"2026-04-06T18:53:11.430338519Z","rtype":160,"publisher_id":101,"instrument_id":33950},"action":"R","side":"N","price":null,"size":0,"channel_id":79,"order_id":"0","flags":128,"ts_in_delta":1768,"sequence":0,"symbol":"EUCO SI 20270312 PS EU P 1.1650 0"}
{"ts_recv":"2026-04-06T18:53:11.430340287Z","hd":{"ts_event":"2026-04-06T18:53:11.430338519Z","rtype":160,"publisher_id":101,"instrument_id":33949},"action":"R","side":"N","price":null,"size":0,"channel_id":79,"order_id":"0","flags":128,"ts_in_delta":1768,"sequence":0,"symbol":"EUCO SI 20270312 PS EU C 1.1650 0"}
{"ts_recv":"2026-04-06T18:53:11.430340287Z","hd":{"ts_event":"2026-04-06T18:53:11.430338519Z","rtype":160,"publisher_id":101,"instrument_id":33948},"action":"R","side":"N","price":null,"size":0,"channel_id":79,"order_id":"0","flags":128,"ts_in_delta":1768,"sequence":0,"symbol":"EUCO SI 20270312 PS EU P 1.1600 0"}
{"ts_recv":"2026-04-06T18:53:11.430340287Z","hd":{"ts_event":"2026-04-06T18:53:11.430338519Z","rtype":160,"publisher_id":101,"instrument_id":33947},"action":"R","side":"N","price":null,"size":0,"channel_id":79,"order_id":"0","flags":128,"ts_in_delta":1768,"sequence":0,"symbol":"EUCO SI 20270312 PS EU C 1.1600 0"}
{"ts_recv":"2026-04-06T18:53:11.430340287Z","hd":{"ts_event":"2026-04-06T18:53:11.430338519Z","rtype":160,"publisher_id":101,"instrument_id":33946},"action":"R","side":"N","price":null,"size":0,"channel_id":79,"order_id":"0","flags":128,"ts_in_delta":1768,"sequence":0,"symbol":"EUCO SI 20270312 PS EU P 1.1550 0"}
{"ts_recv":"2026-04-06T18:53:11.430340287Z","hd":{"ts_event":"2026-04-06T18:53:11.430338519Z","rtype":160,"publisher_id":101,"instrument_id":33945},"action":"R","side":"N","price":null,"size":0,"channel_id":79,"order_id":"0","flags":128,"ts_in_delta":1768,"sequence":0,"symbol":"EUCO SI 20270312 PS EU C 1.1550 0"}
{"ts_recv":"2026-04-06T18:53:11.430340287Z","hd":{"ts_event":"2026-04-06T18:53:11.430338519Z","rtype":160,"publisher_id":101,"instrument_id":33944},"action":"R","side":"N","price":null,"size":0,"channel_id":79,"order_id":"0","flags":128,"ts_in_delta":1768,"sequence":0,"symbol":"EUCO SI 20270312 PS EU P 1.1500 0"}
{"ts_recv":"2026-04-06T18:53:11.430340287Z","hd":{"ts_event":"2026-04-06T18:53:11.430338519Z","rtype":160,"publisher_id":101,"instrument_id":33943},"action":"R","side":"N","price":null,"size":0,"channel_id":79,"order_id":"0","flags":128,"ts_in_delta":1768,"sequence":0,"symbol":"EUCO SI 20270312 PS EU C 1.1500 0"}
{"ts_recv":"2026-04-06T18:53:11.430340287Z","hd":{"ts_event":"2026-04-06T18:53:11.430338519Z","rtype":160,"publisher_id":101,"instrument_id":33942},"action":"R","side":"N","price":null,"size":0,"channel_id":79,"order_id":"0","flags":128,"ts_in_delta":1768,"sequence":0,"symbol":"EUCO SI 20270312 PS EU P 1.1450 0"}
{"ts_recv":"2026-04-06T18:53:11.430340287Z","hd":{"ts_event":"2026-04-06T18:53:11.430338519Z","rtype":160,"publisher_id":101,"instrument_id":33941},"action":"R","side":"N","price":null,"size":0,"channel_id":79,"order_id":"0","flags":128,"ts_in_delta":1768,"sequence":0,"symbol":"EUCO SI 20270312 PS EU C 1.1450 0"}
{"ts_recv":"2026-04-06T18:53:11.430340287Z","hd":{"ts_event":"2026-04-06T18:53:11.430338519Z","rtype":160,"publisher_id":101,"instrument_id":33940},"action":"R","side":"N","price":null,"size":0,"channel_id":79,"order_id":"0","flags":128,"ts_in_delta":1768,"sequence":0,"symbol":"EUCO SI 20270312 PS EU P 1.1400 0"}
{"ts_recv":"2026-04-06T18:53:11.430340287Z","hd":{"ts_event":"2026-04-06T18:53:11.430338519Z","rtype":160,"publisher_id":101,"instrument_id":33939},"action":"R","side":"N","price":null,"size":0,"channel_id":79,"order_id":"0","flags":128,"ts_in_delta":1768,"sequence":0,"symbol":"EUCO SI 20270312 PS EU C 1.1400 0"}
{"ts_recv":"2026-04-06T18:53:11.430340287Z","hd":{"ts_event":"2026-04-06T18:53:11.430338519Z","rtype":160,"publisher_id":101,"instrument_id":33938},"action":"R","side":"N","price":null,"size":0,"channel_id":79,"order_id":"0","flags":128,"ts_in_delta":1768,"sequence":0,"symbol":"EUCO SI 20270312 PS EU P 1.1350 0"}
{"ts_recv":"2026-04-06T18:53:11.430340287Z","hd":{"ts_event":"2026-04-06T18:53:11.430338519Z","rtype":160,"publisher_id":101,"instrument_id":33937},"action":"R","side":"N","price":null,"size":0,"channel_id":79,"order_id":"0","flags":128,"ts_in_delta":1768,"sequence":0,"symbol":"EUCO SI 20270312 PS EU C 1.1350 0"}
{"ts_recv":"2026-04-06T18:53:11.430340287Z","hd":{"ts_event":"2026-04-06T18:53:11.430338519Z","rtype":160,"publisher_id":101,"instrument_id":33936},"action":"R","side":"N","price":null,"size":0,"channel_id":79,"order_id":"0","flags":128,"ts_in_delta":1768,"sequence":0,"symbol":"EUCO SI 20270312 PS EU P 1.1300 0"}
{"ts_recv":"2026-04-06T18:53:11.430340287Z","hd":{"ts_event":"2026-04-06T18:53:11.430338519Z","rtype":160,"publisher_id":101,"instrument_id":33935},"action":"R","side":"N","price":null,"size":0,"channel_id":79,"order_id":"0","flags":128,"ts_in_delta":1768,"sequence":0,"symbol":"EUCO SI 20270312 PS EU C 1.1300 0"}
{"ts_recv":"2026-04-06T18:53:11.430340287Z","hd":{"ts_event":"2026-04-06T18:53:11.430338519Z","rtype":160,"publisher_id":101,"instrument_id":33934},"action":"R","side":"N","price":null,"size":0,"channel_id":79,"order_id":"0","flags":128,"ts_in_delta":1768,"sequence":0,"symbol":"EUCO SI 20270312 PS EU P 1.1250 0"}
{"ts_recv":"2026-04-06T18:53:11.430340287Z","hd":{"ts_event":"2026-04-06T18:53:11.430338519Z","rtype":160,"publisher_id":101,"instrument_id":33933},"action":"R","side":"N","price":null,"size":0,"channel_id":79,"order_id":"0","flags":128,"ts_in_delta":1768,"sequence":0,"symbol":"EUCO SI 20270312 PS EU C 1.1250 0"}
{"ts_recv":"2026-04-06T18:53:11.430340287Z","hd":{"ts_event":"2026-04-06T18:53:11.430338519Z","rtype":160,"publisher_id":101,"instrument_id":33932},"action":"R","side":"N","price":null,"size":0,"channel_id":79,"order_id":"0","flags":128,"ts_in_delta":1768,"sequence":0,"symbol":"EUCO SI 20270312 PS EU P 1.1200 0"}
{"ts_recv":"2026-04-06T18:53:11.430340287Z","hd":{"ts_event":"2026-04-06T18:53:11.430338519Z","rtype":160,"publisher_id":101,"instrument_id":33931},"action":"R","side":"N","price":null,"size":0,"channel_id":79,"order_id":"0","flags":128,"ts_in_delta":1768,"sequence":0,"symbol":"EUCO SI 20270312 PS EU C 1.1200 0"}
{"ts_recv":"2026-04-06T18:53:11.430340287Z","hd":{"ts_event":"2026-04-06T18:53:11.430338519Z","rtype":160,"publisher_id":101,"instrument_id":33930},"action":"R","side":"N","price":null,"size":0,"channel_id":79,"order_id":"0","flags":128,"ts_in_delta":1768,"sequence":0,"symbol":"EUCO SI 20270312 PS EU P 1.1150 0"}
{"ts_recv":"2026-04-06T18:53:11.430340287Z","hd":{"ts_event":"2026-04-06T18:53:11.430338519Z","rtype":160,"publisher_id":101,"instrument_id":33929},"action":"R","side":"N","price":null,"size":0,"channel_id":79,"order_id":"0","flags":128,"ts_in_delta":1768,"sequence":0,"symbol":"EUCO SI 20270312 PS EU C 1.1150 0"}
{"ts_recv":"2026-04-06T18:53:11.430340287Z","hd":{"ts_event":"2026-04-06T18:53:11.430338519Z","rtype":160,"publisher_id":101,"instrument_id":33928},"action":"R","side":"N","price":null,"size":0,"channel_id":79,"order_id":"0","flags":128,"ts_in_delta":1768,"sequence":0,"symbol":"EUCO SI 20270212 PS EU P 1.2550 0"}
{"ts_recv":"2026-04-06T18:53:11.430340287Z","hd":{"ts_event":"2026-04-06T18:53:11.430338519Z","rtype":160,"publisher_id":101,"instrument_id":33927},"action":"R","side":"N","price":null,"size":0,"channel_id":79,"order_id":"0","flags":128,"ts_in_delta":1768,"sequence":0,"symbol":"EUCO SI 20270212 PS EU C 1.2550 0"}
{"ts_recv":"2026-04-06T18:53:11.430340287Z","hd":{"ts_event":"2026-04-06T18:53:11.430338519Z","rtype":160,"publisher_id":101,"instrument_id":33926},"action":"R","side":"N","price":null,"size":0,"channel_id":79,"order_id":"0","flags":128,"ts_in_delta":1768,"sequence":0,"symbol":"EUCO SI 20270212 PS EU P 1.2500 0"}
{"ts_recv":"2026-04-06T18:53:11.430340287Z","hd":{"ts_event":"2026-04-06T18:53:11.430338519Z","rtype":160,"publisher_id":101,"instrument_id":33925},"action":"R","side":"N","price":null,"size":0,"channel_id":79,"order_id":"0","flags":128,"ts_in_delta":1768,"sequence":0,"symbol":"EUCO SI 20270212 PS EU C 1.2500 0"}
{"ts_recv":"2026-04-06T18:53:11.430340287Z","hd":{"ts_event":"2026-04-06T18:53:11.430338519Z","rtype":160,"publisher_id":101,"instrument_id":33924},"action":"R","side":"N","price":null,"size":0,"channel_id":79,"order_id":"0","flags":128,"ts_in_delta":1768,"sequence":0,"symbol":"EUCO SI 20270212 PS EU P 1.2450 0"}
{"ts_recv":"2026-04-06T18:53:11.430340287Z","hd":{"ts_event":"2026-04-06T18:53:11.430338519Z","rtype":160,"publisher_id":101,"instrument_id":33923},"action":"R","side":"N","price":null,"size":0,"channel_id":79,"order_id":"0","flags":128,"ts_in_delta":1768,"sequence":0,"symbol":"EUCO SI 20270212 PS EU C 1.2450 0"}
{"ts_recv":"2026-04-06T18:53:11.430340287Z","hd":{"ts_event":"2026-04-06T18:53:11.430338519Z","rtype":160,"publisher_id":101,"instrument_id":33922},"action":"R","side":"N","price":null,"size":0,"channel_id":79,"order_id":"0","flags":128,"ts_in_delta":1768,"sequence":0,"symbol":"EUCO SI 20270212 PS EU P 1.2400 0"}
{"ts_recv":"2026-04-06T18:53:11.430340287Z","hd":{"ts_event":"2026-04-06T18:53:11.430338519Z","rtype":160,"publisher_id":101,"instrument_id":33921},"action":"R","side":"N","price":null,"size":0,"channel_id":79,"order_id":"0","flags":128,"ts_in_delta":1768,"sequence":0,"symbol":"EUCO SI 20270212 PS EU C 1.2400 0"}
{"ts_recv":"2026-04-06T18:53:11.430340287Z","hd":{"ts_event":"2026-04-06T18:53:11.430338519Z","rtype":160,"publisher_id":101,"instrument_id":33920},"action":"R","side":"N","price":null,"size":0,"channel_id":79,"order_id":"0","flags":128,"ts_in_delta":1768,"sequence":0,"symbol":"EUCO SI 20270212 PS EU P 1.2350 0"}
{"ts_recv":"2026-04-06T18:53:11.430340287Z","hd":{"ts_event":"2026-04-06T18:53:11.430338519Z","rtype":160,"publisher_id":101,"instrument_id":33919},"action":"R","side":"N","price":null,"size":0,"channel_id":79,"order_id":"0","flags":128,"ts_in_delta":1768,"sequence":0,"symbol":"EUCO SI 20270212 PS EU C 1.2350 0"}
{"ts_recv":"2026-04-06T18:53:11.430340287Z","hd":{"ts_event":"2026-04-06T18:53:11.430338519Z","rtype":160,"publisher_id":101,"instrument_id":33918},"action":"R","side":"N","price":null,"size":0,"channel_id":79,"order_id":"0","flags":128,"ts_in_delta":1768,"sequence":0,"symbol":"EUCO SI 20270212 PS EU P 1.2300 0"}
{"ts_recv":"2026-04-06T18:53:11.430340287Z","hd":{"ts_event":"2026-04-06T18:53:11.430338519Z","rtype":160,"publisher_id":101,"instrument_id":33917},"action":"R","side":"N","price":null,"size":0,"channel_id":79,"order_id":"0","flags":128,"ts_in_delta":1768,"sequence":0,"symbol":"EUCO SI 20270212 PS EU C 1.2300 0"}
{"ts_recv":"2026-04-06T18:53:11.430340287Z","hd":{"ts_event":"2026-04-06T18:53:11.430338519Z","rtype":160,"publisher_id":101,"instrument_id":33916},"action":"R","side":"N","price":null,"size":0,"channel_id":79,"order_id":"0","flags":128,"ts_in_delta":1768,"sequence":0,"symbol":"EUCO SI 20270212 PS EU P 1.2250 0"}
{"ts_recv":"2026-04-06T18:53:11.430340287Z","hd":{"ts_event":"2026-04-06T18:53:11.430338519Z","rtype":160,"publisher_id":101,"instrument_id":33915},"action":"R","side":"N","price":null,"size":0,"channel_id":79,"order_id":"0","flags":128,"ts_in_delta":1768,"sequence":0,"symbol":"EUCO SI 20270212 PS EU C 1.2250 0"}
{"ts_recv":"2026-04-06T18:53:11.430340287Z","hd":{"ts_event":"2026-04-06T18:53:11.430338519Z","rtype":160,"publisher_id":101,"instrument_id":33914},"action":"R","side":"N","price":null,"size":0,"channel_id":79,"order_id":"0","flags":128,"ts_in_delta":1768,"sequence":0,"symbol":"EUCO SI 20270212 PS EU P 1.2200 0"}
{"ts_recv":"2026-04-06T18:53:11.430340287Z","hd":{"ts_event":"2026-04-06T18:53:11.430338519Z","rtype":160,"publisher_id":101,"instrument_id":33913},"action":"R","side":"N","price":null,"size":0,"channel_id":79,"order_id":"0","flags":128,"ts_in_delta":1768,"sequence":0,"symbol":"EUCO SI 20270212 PS EU C 1.2200 0"}
{"ts_recv":"2026-04-06T18:53:11.430340287Z","hd":{"ts_event":"2026-04-06T18:53:11.430338519Z","rtype":160,"publisher_id":101,"instrument_id":33912},"action":"R","side":"N","price":null,"size":0,"channel_id":79,"order_id":"0","flags":128,"ts_in_delta":1768,"sequence":0,"symbol":"EUCO SI 20270212 PS EU P 1.2150 0"}
{"ts_recv":"2026-04-06T18:53:11.430340287Z","hd":{"ts_event":"2026-04-06T18:53:11.430338519Z","rtype":160,"publisher_id":101,"instrument_id":33911},"action":"R","side":"N","price":null,"size":0,"channel_id":79,"order_id":"0","flags":128,"ts_in_delta":1768,"sequence":0,"symbol":"EUCO SI 20270212 PS EU C 1.2150 0"}
{"ts_recv":"2026-04-06T18:53:11.430340287Z","hd":{"ts_event":"2026-04-06T18:53:11.430338519Z","rtype":160,"publisher_id":101,"instrument_id":33910},"action":"R","side":"N","price":null,"size":0,"channel_id":79,"order_id":"0","flags":128,"ts_in_delta":1768,"sequence":0,"symbol":"EUCO SI 20270212 PS EU P 1.2100 0"}
{"ts_recv":"2026-04-06T18:53:11.430340287Z","hd":{"ts_event":"2026-04-06T18:53:11.430338519Z","rtype":160,"publisher_id":101,"instrument_id":33909},"action":"R","side":"N","price":null,"size":0,"channel_id":79,"order_id":"0","flags":128,"ts_in_delta":1768,"sequence":0,"symbol":"EUCO SI 20270212 PS EU C 1.2100 0"}
{"ts_recv":"2026-04-06T18:53:11.430340287Z","hd":{"ts_event":"2026-04-06T18:53:11.430338519Z","rtype":160,"publisher_id":101,"instrument_id":33908},"action":"R","side":"N","price":null,"size":0,"channel_id":79,"order_id":"0","flags":128,"ts_in_delta":1768,"sequence":0,"symbol":"EUCO SI 20270212 PS EU P 1.2050 0"}
{"ts_recv":"2026-04-06T18:53:11.430340287Z","hd":{"ts_event":"2026-04-06T18:53:11.430338519Z","rtype":160,"publisher_id":101,"instrument_id":33907},"action":"R","side":"N","price":null,"size":0,"channel_id":79,"order_id":"0","flags":128,"ts_in_delta":1768,"sequence":0,"symbol":"EUCO SI 20270212 PS EU C 1.2050 0"}
{"ts_recv":"2026-04-06T18:53:11.430340287Z","hd":{"ts_event":"2026-04-06T18:53:11.430338519Z","rtype":160,"publisher_id":101,"instrument_id":33906},"action":"R","side":"N","price":null,"size":0,"channel_id":79,"order_id":"0","flags":128,"ts_in_delta":1768,"sequence":0,"symbol":"EUCO SI 20270212 PS EU P 1.2000 0"}
{"ts_recv":"2026-04-06T18:53:11.430340287Z","hd":{"ts_event":"2026-04-06T18:53:11.430338519Z","rtype":160,"publisher_id":101,"instrument_id":33905},"action":"R","side":"N","price":null,"size":0,"channel_id":79,"order_id":"0","flags":128,"ts_in_delta":1768,"sequence":0,"symbol":"EUCO SI 20270212 PS EU C 1.2000 0"}
{"ts_recv":"2026-04-06T18:53:11.430340287Z","hd":{"ts_event":"2026-04-06T18:53:11.430338519Z","rtype":160,"publisher_id":101,"instrument_id":33904},"action":"R","side":"N","price":null,"size":0,"channel_id":79,"order_id":"0","flags":128,"ts_in_delta":1768,"sequence":0,"symbol":"EUCO SI 20270212 PS EU P 1.1950 0"}
{"ts_recv":"2026-04-06T18:53:11.430340287Z","hd":{"ts_event":"2026-04-06T18:53:11.430338519Z","rtype":160,"publisher_id":101,"instrument_id":33903},"action":"R","side":"N","price":null,"size":0,"channel_id":79,"order_id":"0","flags":128,"ts_in_delta":1768,"sequence":0,"symbol":"EUCO SI 20270212 PS EU C 1.1950 0"}
{"ts_recv":"2026-04-06T18:53:11.430340287Z","hd":{"ts_event":"2026-04-06T18:53:11.430338519Z","rtype":160,"publisher_id":101,"instrument_id":33902},"action":"R","side":"N","price":null,"size":0,"channel_id":79,"order_id":"0","flags":128,"ts_in_delta":1768,"sequence":0,"symbol":"EUCO SI 20270212 PS EU P 1.1900 0"}
{"ts_recv":"2026-04-06T18:53:11.430340287Z","hd":{"ts_event":"2026-04-06T18:53:11.430338519Z","rtype":160,"publisher_id":101,"instrument_id":33901},"action":"R","side":"N","price":null,"size":0,"channel_id":79,"order_id":"0","flags":128,"ts_in_delta":1768,"sequence":0,"symbol":"EUCO SI 20270212 PS EU C 1.1900 0"}
{"ts_recv":"2026-04-06T18:53:11.430340287Z","hd":{"ts_event":"2026-04-06T18:53:11.430338519Z","rtype":160,"publisher_id":101,"instrument_id":33900},"action":"R","side":"N","price":null,"size":0,"channel_id":79,"order_id":"0","flags":128,"ts_in_delta":1768,"sequence":0,"symbol":"EUCO SI 20270212 PS EU P 1.1850 0"}
{"ts_recv":"2026-04-06T18:53:11.430340287Z","hd":{"ts_event":"2026-04-06T18:53:11.430338519Z","rtype":160,"publisher_id":101,"instrument_id":33899},"action":"R","side":"N","price":null,"size":0,"channel_id":79,"order_id":"0","flags":128,"ts_in_delta":1768,"sequence":0,"symbol":"EUCO SI 20270212 PS EU C 1.1850 0"}
{"ts_recv":"2026-04-06T18:53:11.430340287Z","hd":{"ts_event":"2026-04-06T18:53:11.430338519Z","rtype":160,"publisher_id":101,"instrument_id":33898},"action":"R","side":"N","price":null,"size":0,"channel_id":79,"order_id":"0","flags":128,"ts_in_delta":1768,"sequence":0,"symbol":"EUCO SI 20270212 PS EU P 1.1800 0"}
{"ts_recv":"2026-04-06T18:53:11.430340287Z","hd":{"ts_event":"2026-04-06T18:53:11.430338519Z","rtype":160,"publisher_id":101,"instrument_id":33897},"action":"R","side":"N","price":null,"size":0,"channel_id":79,"order_id":"0","flags":128,"ts_in_delta":1768,"sequence":0,"symbol":"EUCO SI 20270212 PS EU C 1.1800 0"}
{"ts_recv":"2026-04-06T18:53:11.430340287Z","hd":{"ts_event":"2026-04-06T18:53:11.430338519Z","rtype":160,"publisher_id":101,"instrument_id":33896},"action":"R","side":"N","price":null,"size":0,"channel_id":79,"order_id":"0","flags":128,"ts_in_delta":1768,"sequence":0,"symbol":"EUCO SI 20270212 PS EU P 1.1750 0"}
{"ts_recv":"2026-04-06T18:53:11.430340287Z","hd":{"ts_event":"2026-04-06T18:53:11.430338519Z","rtype":160,"publisher_id":101,"instrument_id":33895},"action":"R","side":"N","price":null,"size":0,"channel_id":79,"order_id":"0","flags":128,"ts_in_delta":1768,"sequence":0,"symbol":"EUCO SI 20270212 PS EU C 1.1750 0"}
{"ts_recv":"2026-04-06T18:53:11.430340287Z","hd":{"ts_event":"2026-04-06T18:53:11.430338519Z","rtype":160,"publisher_id":101,"instrument_id":33894},"action":"R","side":"N","price":null,"size":0,"channel_id":79,"order_id":"0","flags":128,"ts_in_delta":1768,"sequence":0,"symbol":"EUCO SI 20270212 PS EU P 1.1700 0"}
{"ts_recv":"2026-04-06T18:53:11.430340287Z","hd":{"ts_event":"2026-04-06T18:53:11.430338519Z","rtype":160,"publisher_id":101,"instrument_id":33893},"action":"R","side":"N","price":null,"size":0,"channel_id":79,"order_id":"0","flags":128,"ts_in_delta":1768,"sequence":0,"symbol":"EUCO SI 20270212 PS EU C 1.1700 0"}
{"ts_recv":"2026-04-06T18:53:11.430340287Z","hd":{"ts_event":"2026-04-06T18:53:11.430338519Z","rtype":160,"publisher_id":101,"instrument_id":33892},"action":"R","side":"N","price":null,"size":0,"channel_id":79,"order_id":"0","flags":128,"ts_in_delta":1768,"sequence":0,"symbol":"EUCO SI 20270212 PS EU P 1.1650 0"}
{"ts_recv":"2026-04-06T18:53:11.430340287Z","hd":{"ts_event":"2026-04-06T18:53:11.430338519Z","rtype":160,"publisher_id":101,"instrument_id":33891},"action":"R","side":"N","price":null,"size":0,"channel_id":79,"order_id":"0","flags":128,"ts_in_delta":1768,"sequence":0,"symbol":"EUCO SI 20270212 PS EU C 1.1650 0"}
{"ts_recv":"2026-04-06T18:53:11.430340287Z","hd":{"ts_event":"2026-04-06T18:53:11.430338519Z","rtype":160,"publisher_id":101,"instrument_id":33890},"action":"R","side":"N","price":null,"size":0,"channel_id":79,"order_id":"0","flags":128,"ts_in_delta":1768,"sequence":0,"symbol":"EUCO SI 20270212 PS EU P 1.1600 0"}
{"ts_recv":"2026-04-06T18:53:11.430340287Z","hd":{"ts_event":"2026-04-06T18:53:11.430338519Z","rtype":160,"publisher_id":101,"instrument_id":33889},"action":"R","side":"N","price":null,"size":0,"channel_id":79,"order_id":"0","flags":128,"ts_in_delta":1768,"sequence":0,"symbol":"EUCO SI 20270212 PS EU C 1.1600 0"}
{"ts_recv":"2026-04-06T18:53:11.430340287Z","hd":{"ts_event":"2026-04-06T18:53:11.430338519Z","rtype":160,"publisher_id":101,"instrument_id":33888},"action":"R","side":"N","price":null,"size":0,"channel_id":79,"order_id":"0","flags":128,"ts_in_delta":1768,"sequence":0,"symbol":"EUCO SI 20270212 PS EU P 1.1550 0"}
{"ts_recv":"2026-04-06T18:53:11.430340287Z","hd":{"ts_event":"2026-04-06T18:53:11.430338519Z","rtype":160,"publisher_id":101,"instrument_id":33887},"action":"R","side":"N","price":null,"size":0,"channel_id":79,"order_id":"0","flags":128,"ts_in_delta":1768,"sequence":0,"symbol":"EUCO SI 20270212 PS EU C 1.1550 0"}
{"ts_recv":"2026-04-06T18:53:11.430340287Z","hd":{"ts_event":"2026-04-06T18:53:11.430338519Z","rtype":160,"publisher_id":101,"instrument_id":33886},"action":"R","side":"N","price":null,"size":0,"channel_id":79,"order_id":"0","flags":128,"ts_in_delta":1768,"sequence":0,"symbol":"EUCO SI 20270212 PS EU P 1.1500 0"}
{"ts_recv":"2026-04-06T18:53:11.430340287Z","hd":{"ts_event":"2026-04-06T18:53:11.430338519Z","rtype":160,"publisher_id":101,"instrument_id":33885},"action":"R","side":"N","price":null,"size":0,"channel_id":79,"order_id":"0","flags":128,"ts_in_delta":1768,"sequence":0,"symbol":"EUCO SI 20270212 PS EU C 1.1500 0"}
{"ts_recv":"2026-04-06T18:53:11.430340287Z","hd":{"ts_event":"2026-04-06T18:53:11.430338519Z","rtype":160,"publisher_id":101,"instrument_id":33884},"action":"R","side":"N","price":null,"size":0,"channel_id":79,"order_id":"0","flags":128,"ts_in_delta":1768,"sequence":0,"symbol":"EUCO SI 20270212 PS EU P 1.1450 0"}
{"ts_recv":"2026-04-06T18:53:11.430340287Z","hd":{"ts_event":"2026-04-06T18:53:11.430338519Z","rtype":160,"publisher_id":101,"instrument_id":33883},"action":"R","side":"N","price":null,"size":0,"channel_id":79,"order_id":"0","flags":128,"ts_in_delta":1768,"sequence":0,"symbol":"EUCO SI 20270212 PS EU C 1.1450 0"}
{"ts_recv":"2026-04-06T18:53:11.430340287Z","hd":{"ts_event":"2026-04-06T18:53:11.430338519Z","rtype":160,"publisher_id":101,"instrument_id":33882},"action":"R","side":"N","price":null,"size":0,"channel_id":79,"order_id":"0","flags":128,"ts_in_delta":1768,"sequence":0,"symbol":"EUCO SI 20270212 PS EU P 1.1400 0"}
{"ts_recv":"2026-04-06T18:53:11.430340287Z","hd":{"ts_event":"2026-04-06T18:53:11.430338519Z","rtype":160,"publisher_id":101,"instrument_id":33881},"action":"R","side":"N","price":null,"size":0,"channel_id":79,"order_id":"0","flags":128,"ts_in_delta":1768,"sequence":0,"symbol":"EUCO SI 20270212 PS EU C 1.1400 0"}
{"ts_recv":"2026-04-06T18:53:11.430340287Z","hd":{"ts_event":"2026-04-06T18:53:11.430338519Z","rtype":160,"publisher_id":101,"instrument_id":33880},"action":"R","side":"N","price":null,"size":0,"channel_id":79,"order_id":"0","flags":128,"ts_in_delta":1768,"sequence":0,"symbol":"EUCO SI 20270212 PS EU P 1.1350 0"}
{"ts_recv":"2026-04-06T18:53:11.430340287Z","hd":{"ts_event":"2026-04-06T18:53:11.430338519Z","rtype":160,"publisher_id":101,"instrument_id":33879},"action":"R","side":"N","price":null,"size":0,"channel_id":79,"order_id":"0","flags":128,"ts_in_delta":1768,"sequence":0,"symbol":"EUCO SI 20270212 PS EU C 1.1350 0"}
{"ts_recv":"2026-04-06T18:53:11.430340287Z","hd":{"ts_event":"2026-04-06T18:53:11.430338519Z","rtype":160,"publisher_id":101,"instrument_id":33878},"action":"R","side":"N","price":null,"size":0,"channel_id":79,"order_id":"0","flags":128,"ts_in_delta":1768,"sequence":0,"symbol":"EUCO SI 20270212 PS EU P 1.1300 0"}
{"ts_recv":"2026-04-06T18:53:11.430340287Z","hd":{"ts_event":"2026-04-06T18:53:11.430338519Z","rtype":160,"publisher_id":101,"instrument_id":33877},"action":"R","side":"N","price":null,"size":0,"channel_id":79,"order_id":"0","flags":128,"ts_in_delta":1768,"sequence":0,"symbol":"EUCO SI 20270212 PS EU C 1.1300 0"}
{"ts_recv":"2026-04-06T18:53:11.430340287Z","hd":{"ts_event":"2026-04-06T18:53:11.430338519Z","rtype":160,"publisher_id":101,"instrument_id":33876},"action":"R","side":"N","price":null,"size":0,"channel_id":79,"order_id":"0","flags":128,"ts_in_delta":1768,"sequence":0,"symbol":"EUCO SI 20270212 PS EU P 1.1250 0"}
{"ts_recv":"2026-04-06T18:53:11.430340287Z","hd":{"ts_event":"2026-04-06T18:53:11.430338519Z","rtype":160,"publisher_id":101,"instrument_id":33875},"action":"R","side":"N","price":null,"size":0,"channel_id":79,"order_id":"0","flags":128,"ts_in_delta":1768,"sequence":0,"symbol":"EUCO SI 20270212 PS EU C 1.1250 0"}
{"ts_recv":"2026-04-06T18:53:11.430340287Z","hd":{"ts_event":"2026-04-06T18:53:11.430338519Z","rtype":160,"publisher_id":101,"instrument_id":33874},"action":"R","side":"N","price":null,"size":0,"channel_id":79,"order_id":"0","flags":128,"ts_in_delta":1768,"sequence":0,"symbol":"EUCO SI 20270212 PS EU P 1.1200 0"}
{"ts_recv":"2026-04-06T18:53:11.430340287Z","hd":{"ts_event":"2026-04-06T18:53:11.430338519Z","rtype":160,"publisher_id":101,"instrument_id":33873},"action":"R","side":"N","price":null,"size":0,"channel_id":79,"order_id":"0","flags":128,"ts_in_delta":1768,"sequence":0,"symbol":"EUCO SI 20270212 PS EU C 1.1200 0"}
{"ts_recv":"2026-04-06T18:53:11.430340287Z","hd":{"ts_event":"2026-04-06T18:53:11.430338519Z","rtype":160,"publisher_id":101,"instrument_id":33872},"action":"R","side":"N","price":null,"size":0,"channel_id":79,"order_id":"0","flags":128,"ts_in_delta":1768,"sequence":0,"symbol":"EUCO SI 20270212 PS EU P 1.1150 0"}
{"ts_recv":"2026-04-06T18:53:11.430340287Z","hd":{"ts_event":"2026-04-06T18:53:11.430338519Z","rtype":160,"publisher_id":101,"instrument_id":33871},"action":"R","side":"N","price":null,"size":0,"channel_id":79,"order_id":"0","flags":128,"ts_in_delta":1768,"sequence":0,"symbol":"EUCO SI 20270212 PS EU C 1.1150 0"}
{"ts_recv":"2026-04-06T18:53:11.430340287Z","hd":{"ts_event":"2026-04-06T18:53:11.430338519Z","rtype":160,"publisher_id":101,"instrument_id":33870},"action":"R","side":"N","price":null,"size":0,"channel_id":79,"order_id":"0","flags":128,"ts_in_delta":1768,"sequence":0,"symbol":"EUCO SI 20270212 PS EU P 1.1100 0"}
{"ts_recv":"2026-04-06T18:53:11.430340287Z","hd":{"ts_event":"2026-04-06T18:53:11.430338519Z","rtype":160,"publisher_id":101,"instrument_id":33869},"action":"R","side":"N","price":null,"size":0,"channel_id":79,"order_id":"0","flags":128,"ts_in_delta":1768,"sequence":0,"symbol":"EUCO SI 20270212 PS EU C 1.1100 0"}
{"ts_recv":"2026-04-06T18:53:11.430340287Z","hd":{"ts_event":"2026-04-06T18:53:11.430338519Z","rtype":160,"publisher_id":101,"instrument_id":33868},"action":"R","side":"N","price":null,"size":0,"channel_id":79,"order_id":"0","flags":128,"ts_in_delta":1768,"sequence":0,"symbol":"EUCO SI 20270108 PS EU P 1.2650 0"}
{"ts_recv":"2026-04-06T18:53:11.430340287Z","hd":{"ts_event":"2026-04-06T18:53:11.430338519Z","rtype":160,"publisher_id":101,"instrument_id":33867},"action":"R","side":"N","price":null,"size":0,"channel_id":79,"order_id":"0","flags":128,"ts_in_delta":1768,"sequence":0,"symbol":"EUCO SI 20270108 PS EU C 1.2650 0"}
{"ts_recv":"2026-04-06T18:53:11.430340287Z","hd":{"ts_event":"2026-04-06T18:53:11.430338519Z","rtype":160,"publisher_id":101,"instrument_id":33866},"action":"R","side":"N","price":null,"size":0,"channel_id":79,"order_id":"0","flags":128,"ts_in_delta":1768,"sequence":0,"symbol":"EUCO SI 20270108 PS EU P 1.2600 0"}
{"ts_recv":"2026-04-06T18:53:11.430340287Z","hd":{"ts_event":"2026-04-06T18:53:11.430338519Z","rtype":160,"publisher_id":101,"instrument_id":33865},"action":"R","side":"N","price":null,"size":0,"channel_id":79,"order_id":"0","flags":128,"ts_in_delta":1768,"sequence":0,"symbol":"EUCO SI 20270108 PS EU C 1.2600 0"}
{"ts_recv":"2026-04-06T18:53:11.430340287Z","hd":{"ts_event":"2026-04-06T18:53:11.430338519Z","rtype":160,"publisher_id":101,"instrument_id":33864},"action":"R","side":"N","price":null,"size":0,"channel_id":79,"order_id":"0","flags":128,"ts_in_delta":1768,"sequence":0,"symbol":"EUCO SI 20270108 PS EU P 1.2550 0"}
{"ts_recv":"2026-04-06T18:53:11.430340287Z","hd":{"ts_event":"2026-04-06T18:53:11.430338519Z","rtype":160,"publisher_id":101,"instrument_id":33863},"action":"R","side":"N","price":null,"size":0,"channel_id":79,"order_id":"0","flags":128,"ts_in_delta":1768,"sequence":0,"symbol":"EUCO SI 20270108 PS EU C 1.2550 0"}
{"ts_recv":"2026-04-06T18:53:11.430340287Z","hd":{"ts_event":"2026-04-06T18:53:11.430338519Z","rtype":160,"publisher_id":101,"instrument_id":33862},"action":"R","side":"N","price":null,"size":0,"channel_id":79,"order_id":"0","flags":128,"ts_in_delta":1768,"sequence":0,"symbol":"EUCO SI 20270108 PS EU P 1.2500 0"}
{"ts_recv":"2026-04-06T18:53:11.430340287Z","hd":{"ts_event":"2026-04-06T18:53:11.430338519Z","rtype":160,"publisher_id":101,"instrument_id":33861},"action":"R","side":"N","price":null,"size":0,"channel_id":79,"order_id":"0","flags":128,"ts_in_delta":1768,"sequence":0,"symbol":"EUCO SI 20270108 PS EU C 1.2500 0"}
{"ts_recv":"2026-04-06T18:53:11.430340287Z","hd":{"ts_event":"2026-04-06T18:53:11.430338519Z","rtype":160,"publisher_id":101,"instrument_id":33860},"action":"R","side":"N","price":null,"size":0,"channel_id":79,"order_id":"0","flags":128,"ts_in_delta":1768,"sequence":0,"symbol":"EUCO SI 20270108 PS EU P 1.2450 0"}
{"ts_recv":"2026-04-06T18:53:11.430340287Z","hd":{"ts_event":"2026-04-06T18:53:11.430338519Z","rtype":160,"publisher_id":101,"instrument_id":33859},"action":"R","side":"N","price":null,"size":0,"channel_id":79,"order_id":"0","flags":128,"ts_in_delta":1768,"sequence":0,"symbol":"EUCO SI 20270108 PS EU C 1.2450 0"}
{"ts_recv":"2026-04-06T18:53:11.430340287Z","hd":{"ts_event":"2026-04-06T18:53:11.430338519Z","rtype":160,"publisher_id":101,"instrument_id":33858},"action":"R","side":"N","price":null,"size":0,"channel_id":79,"order_id":"0","flags":128,"ts_in_delta":1768,"sequence":0,"symbol":"EUCO SI 20270108 PS EU P 1.2400 0"}
{"ts_recv":"2026-04-06T18:53:11.430340287Z","hd":{"ts_event":"2026-04-06T18:53:11.430338519Z","rtype":160,"publisher_id":101,"instrument_id":33857},"action":"R","side":"N","price":null,"size":0,"channel_id":79,"order_id":"0","flags":128,"ts_in_delta":1768,"sequence":0,"symbol":"EUCO SI 20270108 PS EU C 1.2400 0"}
{"ts_recv":"2026-04-06T18:53:11.430340287Z","hd":{"ts_event":"2026-04-06T18:53:11.430338519Z","rtype":160,"publisher_id":101,"instrument_id":33856},"action":"R","side":"N","price":null,"size":0,"channel_id":79,"order_id":"0","flags":128,"ts_in_delta":1768,"sequence":0,"symbol":"EUCO SI 20270108 PS EU P 1.2350 0"}
{"ts_recv":"2026-04-06T18:53:11.430340287Z","hd":{"ts_event":"2026-04-06T18:53:11.430338519Z","rtype":160,"publisher_id":101,"instrument_id":33855},"action":"R","side":"N","price":null,"size":0,"channel_id":79,"order_id":"0","flags":128,"ts_in_delta":1768,"sequence":0,"symbol":"EUCO SI 20270108 PS EU C 1.2350 0"}
{"ts_recv":"2026-04-06T18:53:11.430340287Z","hd":{"ts_event":"2026-04-06T18:53:11.430338519Z","rtype":160,"publisher_id":101,"instrument_id":33854},"action":"R","side":"N","price":null,"size":0,"channel_id":79,"order_id":"0","flags":128,"ts_in_delta":1768,"sequence":0,"symbol":"EUCO SI 20270108 PS EU P 1.2300 0"}
{"ts_recv":"2026-04-06T18:53:11.430340287Z","hd":{"ts_event":"2026-04-06T18:53:11.430338519Z","rtype":160,"publisher_id":101,"instrument_id":33853},"action":"R","side":"N","price":null,"size":0,"channel_id":79,"order_id":"0","flags":128,"ts_in_delta":1768,"sequence":0,"symbol":"EUCO SI 20270108 PS EU C 1.2300 0"}
{"ts_recv":"2026-04-06T18:53:11.430340287Z","hd":{"ts_event":"2026-04-06T18:53:11.430338519Z","rtype":160,"publisher_id":101,"instrument_id":33852},"action":"R","side":"N","price":null,"size":0,"channel_id":79,"order_id":"0","flags":128,"ts_in_delta":1768,"sequence":0,"symbol":"EUCO SI 20270108 PS EU P 1.2250 0"}
{"ts_recv":"2026-04-06T18:53:11.430340287Z","hd":{"ts_event":"2026-04-06T18:53:11.430338519Z","rtype":160,"publisher_id":101,"instrument_id":33851},"action":"R","side":"N","price":null,"size":0,"channel_id":79,"order_id":"0","flags":128,"ts_in_delta":1768,"sequence":0,"symbol":"EUCO SI 20270108 PS EU C 1.2250 0"}
{"ts_recv":"2026-04-06T18:53:11.430340287Z","hd":{"ts_event":"2026-04-06T18:53:11.430338519Z","rtype":160,"publisher_id":101,"instrument_id":33850},"action":"R","side":"N","price":null,"size":0,"channel_id":79,"order_id":"0","flags":128,"ts_in_delta":1768,"sequence":0,"symbol":"EUCO SI 20270108 PS EU P 1.2200 0"}
{"ts_recv":"2026-04-06T18:53:11.430340287Z","hd":{"ts_event":"2026-04-06T18:53:11.430338519Z","rtype":160,"publisher_id":101,"instrument_id":33849},"action":"R","side":"N","price":null,"size":0,"channel_id":79,"order_id":"0","flags":128,"ts_in_delta":1768,"sequence":0,"symbol":"EUCO SI 20270108 PS EU C 1.2200 0"}
{"ts_recv":"2026-04-06T18:53:11.430340287Z","hd":{"ts_event":"2026-04-06T18:53:11.430338519Z","rtype":160,"publisher_id":101,"instrument_id":33848},"action":"R","side":"N","price":null,"size":0,"channel_id":79,"order_id":"0","flags":128,"ts_in_delta":1768,"sequence":0,"symbol":"EUCO SI 20270108 PS EU P 1.2150 0"}
{"ts_recv":"2026-04-06T18:53:11.430340287Z","hd":{"ts_event":"2026-04-06T18:53:11.430338519Z","rtype":160,"publisher_id":101,"instrument_id":33847},"action":"R","side":"N","price":null,"size":0,"channel_id":79,"order_id":"0","flags":128,"ts_in_delta":1768,"sequence":0,"symbol":"EUCO SI 20270108 PS EU C 1.2150 0"}
{"ts_recv":"2026-04-06T18:53:11.430340287Z","hd":{"ts_event":"2026-04-06T18:53:11.430338519Z","rtype":160,"publisher_id":101,"instrument_id":33846},"action":"R","side":"N","price":null,"size":0,"channel_id":79,"order_id":"0","flags":128,"ts_in_delta":1768,"sequence":0,"symbol":"EUCO SI 20270108 PS EU P 1.2100 0"}
{"ts_recv":"2026-04-06T18:53:11.430340287Z","hd":{"ts_event":"2026-04-06T18:53:11.430338519Z","rtype":160,"publisher_id":101,"instrument_id":33845},"action":"R","side":"N","price":null,"size":0,"channel_id":79,"order_id":"0","flags":128,"ts_in_delta":1768,"sequence":0,"symbol":"EUCO SI 20270108 PS EU C 1.2100 0"}
{"ts_recv":"2026-04-06T18:53:11.430340287Z","hd":{"ts_event":"2026-04-06T18:53:11.430338519Z","rtype":160,"publisher_id":101,"instrument_id":33844},"action":"R","side":"N","price":null,"size":0,"channel_id":79,"order_id":"0","flags":128,"ts_in_delta":1768,"sequence":0,"symbol":"EUCO SI 20270108 PS EU P 1.2050 0"}
{"ts_recv":"2026-04-06T18:53:11.430340287Z","hd":{"ts_event":"2026-04-06T18:53:11.430338519Z","rtype":160,"publisher_id":101,"instrument_id":33843},"action":"R","side":"N","price":null,"size":0,"channel_id":79,"order_id":"0","flags":128,"ts_in_delta":1768,"sequence":0,"symbol":"EUCO SI 20270108 PS EU C 1.2050 0"}
{"ts_recv":"2026-04-06T18:53:11.430340287Z","hd":{"ts_event":"2026-04-06T18:53:11.430338519Z","rtype":160,"publisher_id":101,"instrument_id":33842},"action":"R","side":"N","price":null,"size":0,"channel_id":79,"order_id":"0","flags":128,"ts_in_delta":1768,"sequence":0,"symbol":"EUCO SI 20270108 PS EU P 1.2000 0"}
{"ts_recv":"2026-04-06T18:53:11.430340287Z","hd":{"ts_event":"2026-04-06T18:53:11.430338519Z","rtype":160,"publisher_id":101,"instrument_id":33841},"action":"R","side":"N","price":null,"size":0,"channel_id":79,"order_id":"0","flags":128,"ts_in_delta":1768,"sequence":0,"symbol":"EUCO SI 20270108 PS EU C 1.2000 0"}
{"ts_recv":"2026-04-06T18:53:11.430340287Z","hd":{"ts_event":"2026-04-06T18:53:11.430338519Z","rtype":160,"publisher_id":101,"instrument_id":33840},"action":"R","side":"N","price":null,"size":0,"channel_id":79,"order_id":"0","flags":128,"ts_in_delta":1768,"sequence":0,"symbol":"EUCO SI 20270108 PS EU P 1.1950 0"}
{"ts_recv":"2026-04-06T18:53:11.430340287Z","hd":{"ts_event":"2026-04-06T18:53:11.430338519Z","rtype":160,"publisher_id":101,"instrument_id":33839},"action":"R","side":"N","price":null,"size":0,"channel_id":79,"order_id":"0","flags":128,"ts_in_delta":1768,"sequence":0,"symbol":"EUCO SI 20270108 PS EU C 1.1950 0"}
{"ts_recv":"2026-04-06T18:53:11.430340287Z","hd":{"ts_event":"2026-04-06T18:53:11.430338519Z","rtype":160,"publisher_id":101,"instrument_id":33838},"action":"R","side":"N","price":null,"size":0,"channel_id":79,"order_id":"0","flags":128,"ts_in_delta":1768,"sequence":0,"symbol":"EUCO SI 20270108 PS EU P 1.1900 0"}
{"ts_recv":"2026-04-06T18:53:11.430340287Z","hd":{"ts_event":"2026-04-06T18:53:11.430338519Z","rtype":160,"publisher_id":101,"instrument_id":33837},"action":"R","side":"N","price":null,"size":0,"channel_id":79,"order_id":"0","flags":128,"ts_in_delta":1768,"sequence":0,"symbol":"EUCO SI 20270108 PS EU C 1.1900 0"}
{"ts_recv":"2026-04-06T18:53:11.430340287Z","hd":{"ts_event":"2026-04-06T18:53:11.430338519Z","rtype":160,"publisher_id":101,"instrument_id":33836},"action":"R","side":"N","price":null,"size":0,"channel_id":79,"order_id":"0","flags":128,"ts_in_delta":1768,"sequence":0,"symbol":"EUCO SI 20270108 PS EU P 1.1850 0"}
{"ts_recv":"2026-04-06T18:53:11.430340287Z","hd":{"ts_event":"2026-04-06T18:53:11.430338519Z","rtype":160,"publisher_id":101,"instrument_id":33835},"action":"R","side":"N","price":null,"size":0,"channel_id":79,"order_id":"0","flags":128,"ts_in_delta":1768,"sequence":0,"symbol":"EUCO SI 20270108 PS EU C 1.1850 0"}
{"ts_recv":"2026-04-06T18:53:11.430340287Z","hd":{"ts_event":"2026-04-06T18:53:11.430338519Z","rtype":160,"publisher_id":101,"instrument_id":33834},"action":"R","side":"N","price":null,"size":0,"channel_id":79,"order_id":"0","flags":128,"ts_in_delta":1768,"sequence":0,"symbol":"EUCO SI 20270108 PS EU P 1.1800 0"}
{"ts_recv":"2026-04-06T18:53:11.430340287Z","hd":{"ts_event":"2026-04-06T18:53:11.430338519Z","rtype":160,"publisher_id":101,"instrument_id":33833},"action":"R","side":"N","price":null,"size":0,"channel_id":79,"order_id":"0","flags":128,"ts_in_delta":1768,"sequence":0,"symbol":"EUCO SI 20270108 PS EU C 1.1800 0"}
{"ts_recv":"2026-04-06T18:53:11.430340287Z","hd":{"ts_event":"2026-04-06T18:53:11.430338519Z","rtype":160,"publisher_id":101,"instrument_id":33832},"action":"R","side":"N","price":null,"size":0,"channel_id":79,"order_id":"0","flags":128,"ts_in_delta":1768,"sequence":0,"symbol":"EUCO SI 20270108 PS EU P 1.1750 0"}
{"ts_recv":"2026-04-06T18:53:11.430340287Z","hd":{"ts_event":"2026-04-06T18:53:11.430338519Z","rtype":160,"publisher_id":101,"instrument_id":33831},"action":"R","side":"N","price":null,"size":0,"channel_id":79,"order_id":"0","flags":128,"ts_in_delta":1768,"sequence":0,"symbol":"EUCO SI 20270108 PS EU C 1.1750 0"}
{"ts_recv":"2026-04-06T18:53:11.430340287Z","hd":{"ts_event":"2026-04-06T18:53:11.430338519Z","rtype":160,"publisher_id":101,"instrument_id":33830},"action":"R","side":"N","price":null,"size":0,"channel_id":79,"order_id":"0","flags":128,"ts_in_delta":1768,"sequence":0,"symbol":"EUCO SI 20270108 PS EU P 1.1700 0"}
{"ts_recv":"2026-04-06T18:53:11.430340287Z","hd":{"ts_event":"2026-04-06T18:53:11.430338519Z","rtype":160,"publisher_id":101,"instrument_id":33829},"action":"R","side":"N","price":null,"size":0,"channel_id":79,"order_id":"0","flags":128,"ts_in_delta":1768,"sequence":0,"symbol":"EUCO SI 20270108 PS EU C 1.1700 0"}
{"ts_recv":"2026-04-06T18:53:11.430340287Z","hd":{"ts_event":"2026-04-06T18:53:11.430338519Z","rtype":160,"publisher_id":101,"instrument_id":33828},"action":"R","side":"N","price":null,"size":0,"channel_id":79,"order_id":"0","flags":128,"ts_in_delta":1768,"sequence":0,"symbol":"EUCO SI 20270108 PS EU P 1.1650 0"}
{"ts_recv":"2026-04-06T18:53:11.430340287Z","hd":{"ts_event":"2026-04-06T18:53:11.430338519Z","rtype":160,"publisher_id":101,"instrument_id":33827},"action":"R","side":"N","price":null,"size":0,"channel_id":79,"order_id":"0","flags":128,"ts_in_delta":1768,"sequence":0,"symbol":"EUCO SI 20270108 PS EU C 1.1650 0"}
{"ts_recv":"2026-04-06T18:53:11.430340287Z","hd":{"ts_event":"2026-04-06T18:53:11.430338519Z","rtype":160,"publisher_id":101,"instrument_id":33826},"action":"R","side":"N","price":null,"size":0,"channel_id":79,"order_id":"0","flags":128,"ts_in_delta":1768,"sequence":0,"symbol":"EUCO SI 20270108 PS EU P 1.1600 0"}
{"ts_recv":"2026-04-06T18:53:11.430340287Z","hd":{"ts_event":"2026-04-06T18:53:11.430338519Z","rtype":160,"publisher_id":101,"instrument_id":33825},"action":"R","side":"N","price":null,"size":0,"channel_id":79,"order_id":"0","flags":128,"ts_in_delta":1768,"sequence":0,"symbol":"EUCO SI 20270108 PS EU C 1.1600 0"}
{"ts_recv":"2026-04-06T18:53:11.430340287Z","hd":{"ts_event":"2026-04-06T18:53:11.430338519Z","rtype":160,"publisher_id":101,"instrument_id":33824},"action":"R","side":"N","price":null,"size":0,"channel_id":79,"order_id":"0","flags":128,"ts_in_delta":1768,"sequence":0,"symbol":"EUCO SI 20270108 PS EU P 1.1550 0"}
{"ts_recv":"2026-04-06T18:53:11.430340287Z","hd":{"ts_event":"2026-04-06T18:53:11.430338519Z","rtype":160,"publisher_id":101,"instrument_id":33823},"action":"R","side":"N","price":null,"size":0,"channel_id":79,"order_id":"0","flags":128,"ts_in_delta":1768,"sequence":0,"symbol":"EUCO SI 20270108 PS EU C 1.1550 0"}
{"ts_recv":"2026-04-06T18:53:11.430340287Z","hd":{"ts_event":"2026-04-06T18:53:11.430338519Z","rtype":160,"publisher_id":101,"instrument_id":33822},"action":"R","side":"N","price":null,"size":0,"channel_id":79,"order_id":"0","flags":128,"ts_in_delta":1768,"sequence":0,"symbol":"EUCO SI 20270108 PS EU P 1.1500 0"}
{"ts_recv":"2026-04-06T18:53:11.430340287Z","hd":{"ts_event":"2026-04-06T18:53:11.430338519Z","rtype":160,"publisher_id":101,"instrument_id":33821},"action":"R","side":"N","price":null,"size":0,"channel_id":79,"order_id":"0","flags":128,"ts_in_delta":1768,"sequence":0,"symbol":"EUCO SI 20270108 PS EU C 1.1500 0"}
{"ts_recv":"2026-04-06T18:53:11.430340287Z","hd":{"ts_event":"2026-04-06T18:53:11.430338519Z","rtype":160,"publisher_id":101,"instrument_id":33820},"action":"R","side":"N","price":null,"size":0,"channel_id":79,"order_id":"0","flags":128,"ts_in_delta":1768,"sequence":0,"symbol":"EUCO SI 20270108 PS EU P 1.1450 0"}
{"ts_recv":"2026-04-06T18:53:11.430340287Z","hd":{"ts_event":"2026-04-06T18:53:11.430338519Z","rtype":160,"publisher_id":101,"instrument_id":33819},"action":"R","side":"N","price":null,"size":0,"channel_id":79,"order_id":"0","flags":128,"ts_in_delta":1768,"sequence":0,"symbol":"EUCO SI 20270108 PS EU C 1.1450 0"}
{"ts_recv":"2026-04-06T18:53:11.430340287Z","hd":{"ts_event":"2026-04-06T18:53:11.430338519Z","rtype":160,"publisher_id":101,"instrument_id":33818},"action":"R","side":"N","price":null,"size":0,"channel_id":79,"order_id":"0","flags":128,"ts_in_delta":1768,"sequence":0,"symbol":"EUCO SI 20270108 PS EU P 1.1400 0"}
{"ts_recv":"2026-04-06T18:53:11.430340287Z","hd":{"ts_event":"2026-04-06T18:53:11.430338519Z","rtype":160,"publisher_id":101,"instrument_id":33817},"action":"R","side":"N","price":null,"size":0,"channel_id":79,"order_id":"0","flags":128,"ts_in_delta":1768,"sequence":0,"symbol":"EUCO SI 20270108 PS EU C 1.1400 0"}
{"ts_recv":"2026-04-06T18:53:11.430340287Z","hd":{"ts_event":"2026-04-06T18:53:11.430338519Z","rtype":160,"publisher_id":101,"instrument_id":33816},"action":"R","side":"N","price":null,"size":0,"channel_id":79,"order_id":"0","flags":128,"ts_in_delta":1768,"sequence":0,"symbol":"EUCO SI 20270108 PS EU P 1.1350 0"}
{"ts_recv":"2026-04-06T18:53:11.430340287Z","hd":{"ts_event":"2026-04-06T18:53:11.430338519Z","rtype":160,"publisher_id":101,"instrument_id":33815},"action":"R","side":"N","price":null,"size":0,"channel_id":79,"order_id":"0","flags":128,"ts_in_delta":1768,"sequence":0,"symbol":"EUCO SI 20270108 PS EU C 1.1350 0"}
{"ts_recv":"2026-04-06T18:53:11.430340287Z","hd":{"ts_event":"2026-04-06T18:53:11.430338519Z","rtype":160,"publisher_id":101,"instrument_id":33814},"action":"R","side":"N","price":null,"size":0,"channel_id":79,"order_id":"0","flags":128,"ts_in_delta":1768,"sequence":0,"symbol":"EUCO SI 20270108 PS EU P 1.1300 0"}
{"ts_recv":"2026-04-06T18:53:11.430340287Z","hd":{"ts_event":"2026-04-06T18:53:11.430338519Z","rtype":160,"publisher_id":101,"instrument_id":33813},"action":"R","side":"N","price":null,"size":0,"channel_id":79,"order_id":"0","flags":128,"ts_in_delta":1768,"sequence":0,"symbol":"EUCO SI 20270108 PS EU C 1.1300 0"}
{"ts_recv":"2026-04-06T18:53:11.430340287Z","hd":{"ts_event":"2026-04-06T18:53:11.430338519Z","rtype":160,"publisher_id":101,"instrument_id":33812},"action":"R","side":"N","price":null,"size":0,"channel_id":79,"order_id":"0","flags":128,"ts_in_delta":1768,"sequence":0,"symbol":"EUCO SI 20270108 PS EU P 1.1250 0"}
{"ts_recv":"2026-04-06T18:53:11.430340287Z","hd":{"ts_event":"2026-04-06T18:53:11.430338519Z","rtype":160,"publisher_id":101,"instrument_id":33811},"action":"R","side":"N","price":null,"size":0,"channel_id":79,"order_id":"0","flags":128,"ts_in_delta":1768,"sequence":0,"symbol":"EUCO SI 20270108 PS EU C 1.1250 0"}
{"ts_recv":"2026-04-06T18:53:11.430340287Z","hd":{"ts_event":"2026-04-06T18:53:11.430338519Z","rtype":160,"publisher_id":101,"instrument_id":33810},"action":"R","side":"N","price":null,"size":0,"channel_id":79,"order_id":"0","flags":128,"ts_in_delta":1768,"sequence":0,"symbol":"EUCO SI 20270108 PS EU P 1.1200 0"}
{"ts_recv":"2026-04-06T18:53:11.430340287Z","hd":{"ts_event":"2026-04-06T18:53:11.430338519Z","rtype":160,"publisher_id":101,"instrument_id":33809},"action":"R","side":"N","price":null,"size":0,"channel_id":79,"order_id":"0","flags":128,"ts_in_delta":1768,"sequence":0,"symbol":"EUCO SI 20270108 PS EU C 1.1200 0"}
{"ts_recv":"2026-04-06T18:53:11.430340287Z","hd":{"ts_event":"2026-04-06T18:53:11.430338519Z","rtype":160,"publisher_id":101,"instrument_id":33808},"action":"R","side":"N","price":null,"size":0,"channel_id":79,"order_id":"0","flags":128,"ts_in_delta":1768,"sequence":0,"symbol":"EUCO SI 20270108 PS EU P 1.1150 0"}
{"ts_recv":"2026-04-06T18:53:11.430340287Z","hd":{"ts_event":"2026-04-06T18:53:11.430338519Z","rtype":160,"publisher_id":101,"instrument_id":33807},"action":"R","side":"N","price":null,"size":0,"channel_id":79,"order_id":"0","flags":128,"ts_in_delta":1768,"sequence":0,"symbol":"EUCO SI 20270108 PS EU C 1.1150 0"}
{"ts_recv":"2026-04-06T18:53:11.430340287Z","hd":{"ts_event":"2026-04-06T18:53:11.430338519Z","rtype":160,"publisher_id":101,"instrument_id":33806},"action":"R","side":"N","price":null,"size":0,"channel_id":79,"order_id":"0","flags":128,"ts_in_delta":1768,"sequence":0,"symbol":"EUCO SI 20270108 PS EU P 1.1100 0"}
{"ts_recv":"2026-04-06T18:53:11.430340287Z","hd":{"ts_event":"2026-04-06T18:53:11.430338519Z","rtype":160,"publisher_id":101,"instrument_id":33805},"action":"R","side":"N","price":null,"size":0,"channel_id":79,"order_id":"0","flags":128,"ts_in_delta":1768,"sequence":0,"symbol":"EUCO SI 20270108 PS EU C 1.1100 0"}
{"ts_recv":"2026-04-06T18:53:11.430340287Z","hd":{"ts_event":"2026-04-06T18:53:11.430338519Z","rtype":160,"publisher_id":101,"instrument_id":33804},"action":"R","side":"N","price":null,"size":0,"channel_id":79,"order_id":"0","flags":128,"ts_in_delta":1768,"sequence":0,"symbol":"EUCO SI 20261211 PS EU P 1.2600 0"}
{"ts_recv":"2026-04-06T18:53:11.430340287Z","hd":{"ts_event":"2026-04-06T18:53:11.430338519Z","rtype":160,"publisher_id":101,"instrument_id":33803},"action":"R","side":"N","price":null,"size":0,"channel_id":79,"order_id":"0","flags":128,"ts_in_delta":1768,"sequence":0,"symbol":"EUCO SI 20261211 PS EU C 1.2600 0"}
{"ts_recv":"2026-04-06T18:53:11.430340287Z","hd":{"ts_event":"2026-04-06T18:53:11.430338519Z","rtype":160,"publisher_id":101,"instrument_id":33802},"action":"R","side":"N","price":null,"size":0,"channel_id":79,"order_id":"0","flags":128,"ts_in_delta":1768,"sequence":0,"symbol":"EUCO SI 20261211 PS EU P 1.2550 0"}
{"ts_recv":"2026-04-06T18:53:11.430340287Z","hd":{"ts_event":"2026-04-06T18:53:11.430338519Z","rtype":160,"publisher_id":101,"instrument_id":33801},"action":"R","side":"N","price":null,"size":0,"channel_id":79,"order_id":"0","flags":128,"ts_in_delta":1768,"sequence":0,"symbol":"EUCO SI 20261211 PS EU C 1.2550 0"}
{"ts_recv":"2026-04-06T18:53:11.430340287Z","hd":{"ts_event":"2026-04-06T18:53:11.430338519Z","rtype":160,"publisher_id":101,"instrument_id":33800},"action":"R","side":"N","price":null,"size":0,"channel_id":79,"order_id":"0","flags":128,"ts_in_delta":1768,"sequence":0,"symbol":"EUCO SI 20261211 PS EU P 1.2500 0"}
{"ts_recv":"2026-04-06T18:53:11.430340287Z","hd":{"ts_event":"2026-04-06T18:53:11.430338519Z","rtype":160,"publisher_id":101,"instrument_id":33799},"action":"R","side":"N","price":null,"size":0,"channel_id":79,"order_id":"0","flags":128,"ts_in_delta":1768,"sequence":0,"symbol":"EUCO SI 20261211 PS EU C 1.2500 0"}
{"ts_recv":"2026-04-06T18:53:11.430340287Z","hd":{"ts_event":"2026-04-06T18:53:11.430338519Z","rtype":160,"publisher_id":101,"instrument_id":33798},"action":"R","side":"N","price":null,"size":0,"channel_id":79,"order_id":"0","flags":128,"ts_in_delta":1768,"sequence":0,"symbol":"EUCO SI 20261211 PS EU P 1.2450 0"}
{"ts_recv":"2026-04-06T18:53:11.430340287Z","hd":{"ts_event":"2026-04-06T18:53:11.430338519Z","rtype":160,"publisher_id":101,"instrument_id":33797},"action":"R","side":"N","price":null,"size":0,"channel_id":79,"order_id":"0","flags":128,"ts_in_delta":1768,"sequence":0,"symbol":"EUCO SI 20261211 PS EU C 1.2450 0"}
{"ts_recv":"2026-04-06T18:53:11.430340287Z","hd":{"ts_event":"2026-04-06T18:53:11.430338519Z","rtype":160,"publisher_id":101,"instrument_id":33796},"action":"R","side":"N","price":null,"size":0,"channel_id":79,"order_id":"0","flags":128,"ts_in_delta":1768,"sequence":0,"symbol":"EUCO SI 20261211 PS EU P 1.2400 0"}
{"ts_recv":"2026-04-06T18:53:11.430340287Z","hd":{"ts_event":"2026-04-06T18:53:11.430338519Z","rtype":160,"publisher_id":101,"instrument_id":33795},"action":"R","side":"N","price":null,"size":0,"channel_id":79,"order_id":"0","flags":128,"ts_in_delta":1768,"sequence":0,"symbol":"EUCO SI 20261211 PS EU C 1.2400 0"}
{"ts_recv":"2026-04-06T18:53:11.430340287Z","hd":{"ts_event":"2026-04-06T18:53:11.430338519Z","rtype":160,"publisher_id":101,"instrument_id":33794},"action":"R","side":"N","price":null,"size":0,"channel_id":79,"order_id":"0","flags":128,"ts_in_delta":1768,"sequence":0,"symbol":"EUCO SI 20261211 PS EU P 1.2350 0"}
{"ts_recv":"2026-04-06T18:53:11.430340287Z","hd":{"ts_event":"2026-04-06T18:53:11.430338519Z","rtype":160,"publisher_id":101,"instrument_id":33793},"action":"R","side":"N","price":null,"size":0,"channel_id":79,"order_id":"0","flags":128,"ts_in_delta":1768,"sequence":0,"symbol":"EUCO SI 20261211 PS EU C 1.2350 0"}
{"ts_recv":"2026-04-06T18:53:11.430340287Z","hd":{"ts_event":"2026-04-06T18:53:11.430338519Z","rtype":160,"publisher_id":101,"instrument_id":33792},"action":"R","side":"N","price":null,"size":0,"channel_id":79,"order_id":"0","flags":128,"ts_in_delta":1768,"sequence":0,"symbol":"EUCO SI 20261211 PS EU P 1.2300 0"}
{"ts_recv":"2026-04-06T18:53:11.430340287Z","hd":{"ts_event":"2026-04-06T18:53:11.430338519Z","rtype":160,"publisher_id":101,"instrument_id":33791},"action":"R","side":"N","price":null,"size":0,"channel_id":79,"order_id":"0","flags":128,"ts_in_delta":1768,"sequence":0,"symbol":"EUCO SI 20261211 PS EU C 1.2300 0"}
{"ts_recv":"2026-04-06T18:53:11.430340287Z","hd":{"ts_event":"2026-04-06T18:53:11.430338519Z","rtype":160,"publisher_id":101,"instrument_id":33790},"action":"R","side":"N","price":null,"size":0,"channel_id":79,"order_id":"0","flags":128,"ts_in_delta":1768,"sequence":0,"symbol":"EUCO SI 20261211 PS EU P 1.2250 0"}
{"ts_recv":"2026-04-06T18:53:11.430340287Z","hd":{"ts_event":"2026-04-06T18:53:11.430338519Z","rtype":160,"publisher_id":101,"instrument_id":33789},"action":"R","side":"N","price":null,"size":0,"channel_id":79,"order_id":"0","flags":128,"ts_in_delta":1768,"sequence":0,"symbol":"EUCO SI 20261211 PS EU C 1.2250 0"}
{"ts_recv":"2026-04-06T18:53:11.430340287Z","hd":{"ts_event":"2026-04-06T18:53:11.430338519Z","rtype":160,"publisher_id":101,"instrument_id":33788},"action":"R","side":"N","price":null,"size":0,"channel_id":79,"order_id":"0","flags":128,"ts_in_delta":1768,"sequence":0,"symbol":"EUCO SI 20261211 PS EU P 1.2200 0"}
{"ts_recv":"2026-04-06T18:53:11.430340287Z","hd":{"ts_event":"2026-04-06T18:53:11.430338519Z","rtype":160,"publisher_id":101,"instrument_id":33787},"action":"R","side":"N","price":null,"size":0,"channel_id":79,"order_id":"0","flags":128,"ts_in_delta":1768,"sequence":0,"symbol":"EUCO SI 20261211 PS EU C 1.2200 0"}
{"ts_recv":"2026-04-06T18:53:11.430340287Z","hd":{"ts_event":"2026-04-06T18:53:11.430338519Z","rtype":160,"publisher_id":101,"instrument_id":33786},"action":"R","side":"N","price":null,"size":0,"channel_id":79,"order_id":"0","flags":128,"ts_in_delta":1768,"sequence":0,"symbol":"EUCO SI 20261211 PS EU P 1.2150 0"}
{"ts_recv":"2026-04-06T18:53:11.430340287Z","hd":{"ts_event":"2026-04-06T18:53:11.430338519Z","rtype":160,"publisher_id":101,"instrument_id":33785},"action":"R","side":"N","price":null,"size":0,"channel_id":79,"order_id":"0","flags":128,"ts_in_delta":1768,"sequence":0,"symbol":"EUCO SI 20261211 PS EU C 1.2150 0"}
{"ts_recv":"2026-04-06T18:53:11.430340287Z","hd":{"ts_event":"2026-04-06T18:53:11.430338519Z","rtype":160,"publisher_id":101,"instrument_id":33784},"action":"R","side":"N","price":null,"size":0,"channel_id":79,"order_id":"0","flags":128,"ts_in_delta":1768,"sequence":0,"symbol":"EUCO SI 20261211 PS EU P 1.2100 0"}
{"ts_recv":"2026-04-06T18:53:11.430340287Z","hd":{"ts_event":"2026-04-06T18:53:11.430338519Z","rtype":160,"publisher_id":101,"instrument_id":33783},"action":"R","side":"N","price":null,"size":0,"channel_id":79,"order_id":"0","flags":128,"ts_in_delta":1768,"sequence":0,"symbol":"EUCO SI 20261211 PS EU C 1.2100 0"}
{"ts_recv":"2026-04-06T18:53:11.430340287Z","hd":{"ts_event":"2026-04-06T18:53:11.430338519Z","rtype":160,"publisher_id":101,"instrument_id":33782},"action":"R","side":"N","price":null,"size":0,"channel_id":79,"order_id":"0","flags":128,"ts_in_delta":1768,"sequence":0,"symbol":"EUCO SI 20261211 PS EU P 1.2050 0"}
{"ts_recv":"2026-04-06T18:53:11.430340287Z","hd":{"ts_event":"2026-04-06T18:53:11.430338519Z","rtype":160,"publisher_id":101,"instrument_id":33781},"action":"R","side":"N","price":null,"size":0,"channel_id":79,"order_id":"0","flags":128,"ts_in_delta":1768,"sequence":0,"symbol":"EUCO SI 20261211 PS EU C 1.2050 0"}
{"ts_recv":"2026-04-06T18:53:11.430340287Z","hd":{"ts_event":"2026-04-06T18:53:11.430338519Z","rtype":160,"publisher_id":101,"instrument_id":33780},"action":"R","side":"N","price":null,"size":0,"channel_id":79,"order_id":"0","flags":128,"ts_in_delta":1768,"sequence":0,"symbol":"EUCO SI 20261211 PS EU P 1.2000 0"}
{"ts_recv":"2026-04-06T18:53:11.430340287Z","hd":{"ts_event":"2026-04-06T18:53:11.430338519Z","rtype":160,"publisher_id":101,"instrument_id":33779},"action":"R","side":"N","price":null,"size":0,"channel_id":79,"order_id":"0","flags":128,"ts_in_delta":1768,"sequence":0,"symbol":"EUCO SI 20261211 PS EU C 1.2000 0"}
{"ts_recv":"2026-04-06T18:53:11.430340287Z","hd":{"ts_event":"2026-04-06T18:53:11.430338519Z","rtype":160,"publisher_id":101,"instrument_id":33778},"action":"R","side":"N","price":null,"size":0,"channel_id":79,"order_id":"0","flags":128,"ts_in_delta":1768,"sequence":0,"symbol":"EUCO SI 20261211 PS EU P 1.1950 0"}
{"ts_recv":"2026-04-06T18:53:11.430340287Z","hd":{"ts_event":"2026-04-06T18:53:11.430338519Z","rtype":160,"publisher_id":101,"instrument_id":33777},"action":"R","side":"N","price":null,"size":0,"channel_id":79,"order_id":"0","flags":128,"ts_in_delta":1768,"sequence":0,"symbol":"EUCO SI 20261211 PS EU C 1.1950 0"}
{"ts_recv":"2026-04-06T18:53:11.430340287Z","hd":{"ts_event":"2026-04-06T18:53:11.430338519Z","rtype":160,"publisher_id":101,"instrument_id":33776},"action":"R","side":"N","price":null,"size":0,"channel_id":79,"order_id":"0","flags":128,"ts_in_delta":1768,"sequence":0,"symbol":"EUCO SI 20261211 PS EU P 1.1900 0"}
{"ts_recv":"2026-04-06T18:53:11.430340287Z","hd":{"ts_event":"2026-04-06T18:53:11.430338519Z","rtype":160,"publisher_id":101,"instrument_id":33775},"action":"R","side":"N","price":null,"size":0,"channel_id":79,"order_id":"0","flags":128,"ts_in_delta":1768,"sequence":0,"symbol":"EUCO SI 20261211 PS EU C 1.1900 0"}
{"ts_recv":"2026-04-06T18:53:11.430340287Z","hd":{"ts_event":"2026-04-06T18:53:11.430338519Z","rtype":160,"publisher_id":101,"instrument_id":33774},"action":"R","side":"N","price":null,"size":0,"channel_id":79,"order_id":"0","flags":128,"ts_in_delta":1768,"sequence":0,"symbol":"EUCO SI 20261211 PS EU P 1.1850 0"}
{"ts_recv":"2026-04-06T18:53:11.430340287Z","hd":{"ts_event":"2026-04-06T18:53:11.430338519Z","rtype":160,"publisher_id":101,"instrument_id":33773},"action":"R","side":"N","price":null,"size":0,"channel_id":79,"order_id":"0","flags":128,"ts_in_delta":1768,"sequence":0,"symbol":"EUCO SI 20261211 PS EU C 1.1850 0"}
{"ts_recv":"2026-04-06T18:53:11.430340287Z","hd":{"ts_event":"2026-04-06T18:53:11.430338519Z","rtype":160,"publisher_id":101,"instrument_id":33772},"action":"R","side":"N","price":null,"size":0,"channel_id":79,"order_id":"0","flags":128,"ts_in_delta":1768,"sequence":0,"symbol":"EUCO SI 20261211 PS EU P 1.1800 0"}
{"ts_recv":"2026-04-06T18:53:11.430340287Z","hd":{"ts_event":"2026-04-06T18:53:11.430338519Z","rtype":160,"publisher_id":101,"instrument_id":33771},"action":"R","side":"N","price":null,"size":0,"channel_id":79,"order_id":"0","flags":128,"ts_in_delta":1768,"sequence":0,"symbol":"EUCO SI 20261211 PS EU C 1.1800 0"}
{"ts_recv":"2026-04-06T18:53:11.430340287Z","hd":{"ts_event":"2026-04-06T18:53:11.430338519Z","rtype":160,"publisher_id":101,"instrument_id":33770},"action":"R","side":"N","price":null,"size":0,"channel_id":79,"order_id":"0","flags":128,"ts_in_delta":1768,"sequence":0,"symbol":"EUCO SI 20261211 PS EU P 1.1750 0"}
{"ts_recv":"2026-04-06T18:53:11.430340287Z","hd":{"ts_event":"2026-04-06T18:53:11.430338519Z","rtype":160,"publisher_id":101,"instrument_id":33769},"action":"R","side":"N","price":null,"size":0,"channel_id":79,"order_id":"0","flags":128,"ts_in_delta":1768,"sequence":0,"symbol":"EUCO SI 20261211 PS EU C 1.1750 0"}
{"ts_recv":"2026-04-06T18:53:11.430340287Z","hd":{"ts_event":"2026-04-06T18:53:11.430338519Z","rtype":160,"publisher_id":101,"instrument_id":33768},"action":"R","side":"N","price":null,"size":0,"channel_id":79,"order_id":"0","flags":128,"ts_in_delta":1768,"sequence":0,"symbol":"EUCO SI 20261211 PS EU P 1.1700 0"}
{"ts_recv":"2026-04-06T18:53:11.430340287Z","hd":{"ts_event":"2026-04-06T18:53:11.430338519Z","rtype":160,"publisher_id":101,"instrument_id":33767},"action":"R","side":"N","price":null,"size":0,"channel_id":79,"order_id":"0","flags":128,"ts_in_delta":1768,"sequence":0,"symbol":"EUCO SI 20261211 PS EU C 1.1700 0"}
{"ts_recv":"2026-04-06T18:53:11.430340287Z","hd":{"ts_event":"2026-04-06T18:53:11.430338519Z","rtype":160,"publisher_id":101,"instrument_id":33766},"action":"R","side":"N","price":null,"size":0,"channel_id":79,"order_id":"0","flags":128,"ts_in_delta":1768,"sequence":0,"symbol":"EUCO SI 20261211 PS EU P 1.1650 0"}
{"ts_recv":"2026-04-06T18:53:11.430340287Z","hd":{"ts_event":"2026-04-06T18:53:11.430338519Z","rtype":160,"publisher_id":101,"instrument_id":33765},"action":"R","side":"N","price":null,"size":0,"channel_id":79,"order_id":"0","flags":128,"ts_in_delta":1768,"sequence":0,"symbol":"EUCO SI 20261211 PS EU C 1.1650 0"}
{"ts_recv":"2026-04-06T18:53:11.430340287Z","hd":{"ts_event":"2026-04-06T18:53:11.430338519Z","rtype":160,"publisher_id":101,"instrument_id":33764},"action":"R","side":"N","price":null,"size":0,"channel_id":79,"order_id":"0","flags":128,"ts_in_delta":1768,"sequence":0,"symbol":"EUCO SI 20261211 PS EU P 1.1600 0"}
{"ts_recv":"2026-04-06T18:53:11.430340287Z","hd":{"ts_event":"2026-04-06T18:53:11.430338519Z","rtype":160,"publisher_id":101,"instrument_id":33763},"action":"R","side":"N","price":null,"size":0,"channel_id":79,"order_id":"0","flags":128,"ts_in_delta":1768,"sequence":0,"symbol":"EUCO SI 20261211 PS EU C 1.1600 0"}
{"ts_recv":"2026-04-06T18:53:11.430340287Z","hd":{"ts_event":"2026-04-06T18:53:11.430338519Z","rtype":160,"publisher_id":101,"instrument_id":33762},"action":"R","side":"N","price":null,"size":0,"channel_id":79,"order_id":"0","flags":128,"ts_in_delta":1768,"sequence":0,"symbol":"EUCO SI 20261211 PS EU P 1.1550 0"}
{"ts_recv":"2026-04-06T18:53:11.430340287Z","hd":{"ts_event":"2026-04-06T18:53:11.430338519Z","rtype":160,"publisher_id":101,"instrument_id":33761},"action":"R","side":"N","price":null,"size":0,"channel_id":79,"order_id":"0","flags":128,"ts_in_delta":1768,"sequence":0,"symbol":"EUCO SI 20261211 PS EU C 1.1550 0"}
{"ts_recv":"2026-04-06T18:53:11.430340287Z","hd":{"ts_event":"2026-04-06T18:53:11.430338519Z","rtype":160,"publisher_id":101,"instrument_id":33760},"action":"R","side":"N","price":null,"size":0,"channel_id":79,"order_id":"0","flags":128,"ts_in_delta":1768,"sequence":0,"symbol":"EUCO SI 20261211 PS EU P 1.1500 0"}
{"ts_recv":"2026-04-06T18:53:11.430340287Z","hd":{"ts_event":"2026-04-06T18:53:11.430338519Z","rtype":160,"publisher_id":101,"instrument_id":33759},"action":"R","side":"N","price":null,"size":0,"channel_id":79,"order_id":"0","flags":128,"ts_in_delta":1768,"sequence":0,"symbol":"EUCO SI 20261211 PS EU C 1.1500 0"}
{"ts_recv":"2026-04-06T18:53:11.430340287Z","hd":{"ts_event":"2026-04-06T18:53:11.430338519Z","rtype":160,"publisher_id":101,"instrument_id":33758},"action":"R","side":"N","price":null,"size":0,"channel_id":79,"order_id":"0","flags":128,"ts_in_delta":1768,"sequence":0,"symbol":"EUCO SI 20261211 PS EU P 1.1450 0"}
{"ts_recv":"2026-04-06T18:53:11.430340287Z","hd":{"ts_event":"2026-04-06T18:53:11.430338519Z","rtype":160,"publisher_id":101,"instrument_id":33757},"action":"R","side":"N","price":null,"size":0,"channel_id":79,"order_id":"0","flags":128,"ts_in_delta":1768,"sequence":0,"symbol":"EUCO SI 20261211 PS EU C 1.1450 0"}
{"ts_recv":"2026-04-06T18:53:11.430340287Z","hd":{"ts_event":"2026-04-06T18:53:11.430338519Z","rtype":160,"publisher_id":101,"instrument_id":33756},"action":"R","side":"N","price":null,"size":0,"channel_id":79,"order_id":"0","flags":128,"ts_in_delta":1768,"sequence":0,"symbol":"EUCO SI 20261211 PS EU P 1.1400 0"}
{"ts_recv":"2026-04-06T18:53:11.430340287Z","hd":{"ts_event":"2026-04-06T18:53:11.430338519Z","rtype":160,"publisher_id":101,"instrument_id":33755},"action":"R","side":"N","price":null,"size":0,"channel_id":79,"order_id":"0","flags":128,"ts_in_delta":1768,"sequence":0,"symbol":"EUCO SI 20261211 PS EU C 1.1400 0"}
{"ts_recv":"2026-04-06T18:53:11.430340287Z","hd":{"ts_event":"2026-04-06T18:53:11.430338519Z","rtype":160,"publisher_id":101,"instrument_id":33754},"action":"R","side":"N","price":null,"size":0,"channel_id":79,"order_id":"0","flags":128,"ts_in_delta":1768,"sequence":0,"symbol":"EUCO SI 20261211 PS EU P 1.1350 0"}
{"ts_recv":"2026-04-06T18:53:11.430340287Z","hd":{"ts_event":"2026-04-06T18:53:11.430338519Z","rtype":160,"publisher_id":101,"instrument_id":33753},"action":"R","side":"N","price":null,"size":0,"channel_id":79,"order_id":"0","flags":128,"ts_in_delta":1768,"sequence":0,"symbol":"EUCO SI 20261211 PS EU C 1.1350 0"}
{"ts_recv":"2026-04-06T18:53:11.430340287Z","hd":{"ts_event":"2026-04-06T18:53:11.430338519Z","rtype":160,"publisher_id":101,"instrument_id":33752},"action":"R","side":"N","price":null,"size":0,"channel_id":79,"order_id":"0","flags":128,"ts_in_delta":1768,"sequence":0,"symbol":"EUCO SI 20261211 PS EU P 1.1300 0"}
{"ts_recv":"2026-04-06T18:53:11.430340287Z","hd":{"ts_event":"2026-04-06T18:53:11.430338519Z","rtype":160,"publisher_id":101,"instrument_id":33751},"action":"R","side":"N","price":null,"size":0,"channel_id":79,"order_id":"0","flags":128,"ts_in_delta":1768,"sequence":0,"symbol":"EUCO SI 20261211 PS EU C 1.1300 0"}
{"ts_recv":"2026-04-06T18:53:11.430340287Z","hd":{"ts_event":"2026-04-06T18:53:11.430338519Z","rtype":160,"publisher_id":101,"instrument_id":33750},"action":"R","side":"N","price":null,"size":0,"channel_id":79,"order_id":"0","flags":128,"ts_in_delta":1768,"sequence":0,"symbol":"EUCO SI 20261211 PS EU P 1.1250 0"}
{"ts_recv":"2026-04-06T18:53:11.430340287Z","hd":{"ts_event":"2026-04-06T18:53:11.430338519Z","rtype":160,"publisher_id":101,"instrument_id":33749},"action":"R","side":"N","price":null,"size":0,"channel_id":79,"order_id":"0","flags":128,"ts_in_delta":1768,"sequence":0,"symbol":"EUCO SI 20261211 PS EU C 1.1250 0"}
{"ts_recv":"2026-04-06T18:53:11.430340287Z","hd":{"ts_event":"2026-04-06T18:53:11.430338519Z","rtype":160,"publisher_id":101,"instrument_id":33748},"action":"R","side":"N","price":null,"size":0,"channel_id":79,"order_id":"0","flags":128,"ts_in_delta":1768,"sequence":0,"symbol":"EUCO SI 20261211 PS EU P 1.1200 0"}
{"ts_recv":"2026-04-06T18:53:11.430340287Z","hd":{"ts_event":"2026-04-06T18:53:11.430338519Z","rtype":160,"publisher_id":101,"instrument_id":33747},"action":"R","side":"N","price":null,"size":0,"channel_id":79,"order_id":"0","flags":128,"ts_in_delta":1768,"sequence":0,"symbol":"EUCO SI 20261211 PS EU C 1.1200 0"}
{"ts_recv":"2026-04-06T18:53:11.430340287Z","hd":{"ts_event":"2026-04-06T18:53:11.430338519Z","rtype":160,"publisher_id":101,"instrument_id":33746},"action":"R","side":"N","price":null,"size":0,"channel_id":79,"order_id":"0","flags":128,"ts_in_delta":1768,"sequence":0,"symbol":"EUCO SI 20261211 PS EU P 1.1150 0"}
{"ts_recv":"2026-04-06T18:53:11.430340287Z","hd":{"ts_event":"2026-04-06T18:53:11.430338519Z","rtype":160,"publisher_id":101,"instrument_id":33745},"action":"R","side":"N","price":null,"size":0,"channel_id":79,"order_id":"0","flags":128,"ts_in_delta":1768,"sequence":0,"symbol":"EUCO SI 20261211 PS EU C 1.1150 0"}
{"ts_recv":"2026-04-06T18:53:11.430340287Z","hd":{"ts_event":"2026-04-06T18:53:11.430338519Z","rtype":160,"publisher_id":101,"instrument_id":33744},"action":"R","side":"N","price":null,"size":0,"channel_id":79,"order_id":"0","flags":128,"ts_in_delta":1768,"sequence":0,"symbol":"EUCO SI 20261211 PS EU P 1.1100 0"}
{"ts_recv":"2026-04-06T18:53:11.430340287Z","hd":{"ts_event":"2026-04-06T18:53:11.430338519Z","rtype":160,"publisher_id":101,"instrument_id":33743},"action":"R","side":"N","price":null,"size":0,"channel_id":79,"order_id":"0","flags":128,"ts_in_delta":1768,"sequence":0,"symbol":"EUCO SI 20261211 PS EU C 1.1100 0"}
{"ts_recv":"2026-04-06T18:53:11.430340287Z","hd":{"ts_event":"2026-04-06T18:53:11.430338519Z","rtype":160,"publisher_id":101,"instrument_id":33742},"action":"R","side":"N","price":null,"size":0,"channel_id":79,"order_id":"0","flags":128,"ts_in_delta":1768,"sequence":0,"symbol":"EUCO SI 20261113 PS EU P 1.2600 0"}
{"ts_recv":"2026-04-06T18:53:11.430340287Z","hd":{"ts_event":"2026-04-06T18:53:11.430338519Z","rtype":160,"publisher_id":101,"instrument_id":33741},"action":"R","side":"N","price":null,"size":0,"channel_id":79,"order_id":"0","flags":128,"ts_in_delta":1768,"sequence":0,"symbol":"EUCO SI 20261113 PS EU C 1.2600 0"}
{"ts_recv":"2026-04-06T18:53:11.430340287Z","hd":{"ts_event":"2026-04-06T18:53:11.430338519Z","rtype":160,"publisher_id":101,"instrument_id":33740},"action":"R","side":"N","price":null,"size":0,"channel_id":79,"order_id":"0","flags":128,"ts_in_delta":1768,"sequence":0,"symbol":"EUCO SI 20261113 PS EU P 1.2550 0"}
{"ts_recv":"2026-04-06T18:53:11.430340287Z","hd":{"ts_event":"2026-04-06T18:53:11.430338519Z","rtype":160,"publisher_id":101,"instrument_id":33739},"action":"R","side":"N","price":null,"size":0,"channel_id":79,"order_id":"0","flags":128,"ts_in_delta":1768,"sequence":0,"symbol":"EUCO SI 20261113 PS EU C 1.2550 0"}
{"ts_recv":"2026-04-06T18:53:11.430340287Z","hd":{"ts_event":"2026-04-06T18:53:11.430338519Z","rtype":160,"publisher_id":101,"instrument_id":33738},"action":"R","side":"N","price":null,"size":0,"channel_id":79,"order_id":"0","flags":128,"ts_in_delta":1768,"sequence":0,"symbol":"EUCO SI 20261113 PS EU P 1.2500 0"}
{"ts_recv":"2026-04-06T18:53:11.430340287Z","hd":{"ts_event":"2026-04-06T18:53:11.430338519Z","rtype":160,"publisher_id":101,"instrument_id":33737},"action":"R","side":"N","price":null,"size":0,"channel_id":79,"order_id":"0","flags":128,"ts_in_delta":1768,"sequence":0,"symbol":"EUCO SI 20261113 PS EU C 1.2500 0"}
{"ts_recv":"2026-04-06T18:53:11.430340287Z","hd":{"ts_event":"2026-04-06T18:53:11.430338519Z","rtype":160,"publisher_id":101,"instrument_id":33736},"action":"R","side":"N","price":null,"size":0,"channel_id":79,"order_id":"0","flags":128,"ts_in_delta":1768,"sequence":0,"symbol":"EUCO SI 20261113 PS EU P 1.2450 0"}
{"ts_recv":"2026-04-06T18:53:11.430340287Z","hd":{"ts_event":"2026-04-06T18:53:11.430338519Z","rtype":160,"publisher_id":101,"instrument_id":33735},"action":"R","side":"N","price":null,"size":0,"channel_id":79,"order_id":"0","flags":128,"ts_in_delta":1768,"sequence":0,"symbol":"EUCO SI 20261113 PS EU C 1.2450 0"}
{"ts_recv":"2026-04-06T18:53:11.430340287Z","hd":{"ts_event":"2026-04-06T18:53:11.430338519Z","rtype":160,"publisher_id":101,"instrument_id":33734},"action":"R","side":"N","price":null,"size":0,"channel_id":79,"order_id":"0","flags":128,"ts_in_delta":1768,"sequence":0,"symbol":"EUCO SI 20261113 PS EU P 1.2400 0"}
{"ts_recv":"2026-04-06T18:53:11.430340287Z","hd":{"ts_event":"2026-04-06T18:53:11.430338519Z","rtype":160,"publisher_id":101,"instrument_id":33733},"action":"R","side":"N","price":null,"size":0,"channel_id":79,"order_id":"0","flags":128,"ts_in_delta":1768,"sequence":0,"symbol":"EUCO SI 20261113 PS EU C 1.2400 0"}
{"ts_recv":"2026-04-06T18:53:11.430340287Z","hd":{"ts_event":"2026-04-06T18:53:11.430338519Z","rtype":160,"publisher_id":101,"instrument_id":33732},"action":"R","side":"N","price":null,"size":0,"channel_id":79,"order_id":"0","flags":128,"ts_in_delta":1768,"sequence":0,"symbol":"EUCO SI 20261113 PS EU P 1.2350 0"}
{"ts_recv":"2026-04-06T18:53:11.430340287Z","hd":{"ts_event":"2026-04-06T18:53:11.430338519Z","rtype":160,"publisher_id":101,"instrument_id":33731},"action":"R","side":"N","price":null,"size":0,"channel_id":79,"order_id":"0","flags":128,"ts_in_delta":1768,"sequence":0,"symbol":"EUCO SI 20261113 PS EU C 1.2350 0"}
{"ts_recv":"2026-04-06T18:53:11.430340287Z","hd":{"ts_event":"2026-04-06T18:53:11.430338519Z","rtype":160,"publisher_id":101,"instrument_id":33730},"action":"R","side":"N","price":null,"size":0,"channel_id":79,"order_id":"0","flags":128,"ts_in_delta":1768,"sequence":0,"symbol":"EUCO SI 20261113 PS EU P 1.2300 0"}
{"ts_recv":"2026-04-06T18:53:11.430340287Z","hd":{"ts_event":"2026-04-06T18:53:11.430338519Z","rtype":160,"publisher_id":101,"instrument_id":33729},"action":"R","side":"N","price":null,"size":0,"channel_id":79,"order_id":"0","flags":128,"ts_in_delta":1768,"sequence":0,"symbol":"EUCO SI 20261113 PS EU C 1.2300 0"}
{"ts_recv":"2026-04-06T18:53:11.430340287Z","hd":{"ts_event":"2026-04-06T18:53:11.430338519Z","rtype":160,"publisher_id":101,"instrument_id":33728},"action":"R","side":"N","price":null,"size":0,"channel_id":79,"order_id":"0","flags":128,"ts_in_delta":1768,"sequence":0,"symbol":"EUCO SI 20261113 PS EU P 1.2250 0"}
{"ts_recv":"2026-04-06T18:53:11.430340287Z","hd":{"ts_event":"2026-04-06T18:53:11.430338519Z","rtype":160,"publisher_id":101,"instrument_id":33727},"action":"R","side":"N","price":null,"size":0,"channel_id":79,"order_id":"0","flags":128,"ts_in_delta":1768,"sequence":0,"symbol":"EUCO SI 20261113 PS EU C 1.2250 0"}
{"ts_recv":"2026-04-06T18:53:11.430340287Z","hd":{"ts_event":"2026-04-06T18:53:11.430338519Z","rtype":160,"publisher_id":101,"instrument_id":33726},"action":"R","side":"N","price":null,"size":0,"channel_id":79,"order_id":"0","flags":128,"ts_in_delta":1768,"sequence":0,"symbol":"EUCO SI 20261113 PS EU P 1.2200 0"}
{"ts_recv":"2026-04-06T18:53:11.430340287Z","hd":{"ts_event":"2026-04-06T18:53:11.430338519Z","rtype":160,"publisher_id":101,"instrument_id":33725},"action":"R","side":"N","price":null,"size":0,"channel_id":79,"order_id":"0","flags":128,"ts_in_delta":1768,"sequence":0,"symbol":"EUCO SI 20261113 PS EU C 1.2200 0"}
{"ts_recv":"2026-04-06T18:53:11.430340287Z","hd":{"ts_event":"2026-04-06T18:53:11.430338519Z","rtype":160,"publisher_id":101,"instrument_id":33724},"action":"R","side":"N","price":null,"size":0,"channel_id":79,"order_id":"0","flags":128,"ts_in_delta":1768,"sequence":0,"symbol":"EUCO SI 20261113 PS EU P 1.2150 0"}
{"ts_recv":"2026-04-06T18:53:11.430340287Z","hd":{"ts_event":"2026-04-06T18:53:11.430338519Z","rtype":160,"publisher_id":101,"instrument_id":33723},"action":"R","side":"N","price":null,"size":0,"channel_id":79,"order_id":"0","flags":128,"ts_in_delta":1768,"sequence":0,"symbol":"EUCO SI 20261113 PS EU C 1.2150 0"}
{"ts_recv":"2026-04-06T18:53:11.430340287Z","hd":{"ts_event":"2026-04-06T18:53:11.430338519Z","rtype":160,"publisher_id":101,"instrument_id":33722},"action":"R","side":"N","price":null,"size":0,"channel_id":79,"order_id":"0","flags":128,"ts_in_delta":1768,"sequence":0,"symbol":"EUCO SI 20261113 PS EU P 1.2100 0"}
{"ts_recv":"2026-04-06T18:53:11.430340287Z","hd":{"ts_event":"2026-04-06T18:53:11.430338519Z","rtype":160,"publisher_id":101,"instrument_id":33721},"action":"R","side":"N","price":null,"size":0,"channel_id":79,"order_id":"0","flags":128,"ts_in_delta":1768,"sequence":0,"symbol":"EUCO SI 20261113 PS EU C 1.2100 0"}
{"ts_recv":"2026-04-06T18:53:11.430340287Z","hd":{"ts_event":"2026-04-06T18:53:11.430338519Z","rtype":160,"publisher_id":101,"instrument_id":33720},"action":"R","side":"N","price":null,"size":0,"channel_id":79,"order_id":"0","flags":128,"ts_in_delta":1768,"sequence":0,"symbol":"EUCO SI 20261113 PS EU P 1.2050 0"}
{"ts_recv":"2026-04-06T18:53:11.430340287Z","hd":{"ts_event":"2026-04-06T18:53:11.430338519Z","rtype":160,"publisher_id":101,"instrument_id":33719},"action":"R","side":"N","price":null,"size":0,"channel_id":79,"order_id":"0","flags":128,"ts_in_delta":1768,"sequence":0,"symbol":"EUCO SI 20261113 PS EU C 1.2050 0"}
{"ts_recv":"2026-04-06T18:53:11.430340287Z","hd":{"ts_event":"2026-04-06T18:53:11.430338519Z","rtype":160,"publisher_id":101,"instrument_id":33718},"action":"R","side":"N","price":null,"size":0,"channel_id":79,"order_id":"0","flags":128,"ts_in_delta":1768,"sequence":0,"symbol":"EUCO SI 20261113 PS EU P 1.2000 0"}
{"ts_recv":"2026-04-06T18:53:11.430340287Z","hd":{"ts_event":"2026-04-06T18:53:11.430338519Z","rtype":160,"publisher_id":101,"instrument_id":33717},"action":"R","side":"N","price":null,"size":0,"channel_id":79,"order_id":"0","flags":128,"ts_in_delta":1768,"sequence":0,"symbol":"EUCO SI 20261113 PS EU C 1.2000 0"}
{"ts_recv":"2026-04-06T18:53:11.430340287Z","hd":{"ts_event":"2026-04-06T18:53:11.430338519Z","rtype":160,"publisher_id":101,"instrument_id":33716},"action":"R","side":"N","price":null,"size":0,"channel_id":79,"order_id":"0","flags":128,"ts_in_delta":1768,"sequence":0,"symbol":"EUCO SI 20261113 PS EU P 1.1950 0"}
{"ts_recv":"2026-04-06T18:53:11.430340287Z","hd":{"ts_event":"2026-04-06T18:53:11.430338519Z","rtype":160,"publisher_id":101,"instrument_id":33715},"action":"R","side":"N","price":null,"size":0,"channel_id":79,"order_id":"0","flags":128,"ts_in_delta":1768,"sequence":0,"symbol":"EUCO SI 20261113 PS EU C 1.1950 0"}
{"ts_recv":"2026-04-06T18:53:11.430340287Z","hd":{"ts_event":"2026-04-06T18:53:11.430338519Z","rtype":160,"publisher_id":101,"instrument_id":33714},"action":"R","side":"N","price":null,"size":0,"channel_id":79,"order_id":"0","flags":128,"ts_in_delta":1768,"sequence":0,"symbol":"EUCO SI 20261113 PS EU P 1.1900 0"}
{"ts_recv":"2026-04-06T18:53:11.430340287Z","hd":{"ts_event":"2026-04-06T18:53:11.430338519Z","rtype":160,"publisher_id":101,"instrument_id":33713},"action":"R","side":"N","price":null,"size":0,"channel_id":79,"order_id":"0","flags":128,"ts_in_delta":1768,"sequence":0,"symbol":"EUCO SI 20261113 PS EU C 1.1900 0"}
{"ts_recv":"2026-04-06T18:53:11.430340287Z","hd":{"ts_event":"2026-04-06T18:53:11.430338519Z","rtype":160,"publisher_id":101,"instrument_id":33712},"action":"R","side":"N","price":null,"size":0,"channel_id":79,"order_id":"0","flags":128,"ts_in_delta":1768,"sequence":0,"symbol":"EUCO SI 20261113 PS EU P 1.1850 0"}
{"ts_recv":"2026-04-06T18:53:11.430340287Z","hd":{"ts_event":"2026-04-06T18:53:11.430338519Z","rtype":160,"publisher_id":101,"instrument_id":33711},"action":"R","side":"N","price":null,"size":0,"channel_id":79,"order_id":"0","flags":128,"ts_in_delta":1768,"sequence":0,"symbol":"EUCO SI 20261113 PS EU C 1.1850 0"}
{"ts_recv":"2026-04-06T18:53:11.430340287Z","hd":{"ts_event":"2026-04-06T18:53:11.430338519Z","rtype":160,"publisher_id":101,"instrument_id":33710},"action":"R","side":"N","price":null,"size":0,"channel_id":79,"order_id":"0","flags":128,"ts_in_delta":1768,"sequence":0,"symbol":"EUCO SI 20261113 PS EU P 1.1800 0"}
{"ts_recv":"2026-04-06T18:53:11.430340287Z","hd":{"ts_event":"2026-04-06T18:53:11.430338519Z","rtype":160,"publisher_id":101,"instrument_id":33709},"action":"R","side":"N","price":null,"size":0,"channel_id":79,"order_id":"0","flags":128,"ts_in_delta":1768,"sequence":0,"symbol":"EUCO SI 20261113 PS EU C 1.1800 0"}
{"ts_recv":"2026-04-06T18:53:11.430340287Z","hd":{"ts_event":"2026-04-06T18:53:11.430338519Z","rtype":160,"publisher_id":101,"instrument_id":33708},"action":"R","side":"N","price":null,"size":0,"channel_id":79,"order_id":"0","flags":128,"ts_in_delta":1768,"sequence":0,"symbol":"EUCO SI 20261113 PS EU P 1.1750 0"}
{"ts_recv":"2026-04-06T18:53:11.430340287Z","hd":{"ts_event":"2026-04-06T18:53:11.430338519Z","rtype":160,"publisher_id":101,"instrument_id":33707},"action":"R","side":"N","price":null,"size":0,"channel_id":79,"order_id":"0","flags":128,"ts_in_delta":1768,"sequence":0,"symbol":"EUCO SI 20261113 PS EU C 1.1750 0"}
{"ts_recv":"2026-04-06T18:53:11.430340287Z","hd":{"ts_event":"2026-04-06T18:53:11.430338519Z","rtype":160,"publisher_id":101,"instrument_id":33706},"action":"R","side":"N","price":null,"size":0,"channel_id":79,"order_id":"0","flags":128,"ts_in_delta":1768,"sequence":0,"symbol":"EUCO SI 20261113 PS EU P 1.1700 0"}
{"ts_recv":"2026-04-06T18:53:11.430340287Z","hd":{"ts_event":"2026-04-06T18:53:11.430338519Z","rtype":160,"publisher_id":101,"instrument_id":33705},"action":"R","side":"N","price":null,"size":0,"channel_id":79,"order_id":"0","flags":128,"ts_in_delta":1768,"sequence":0,"symbol":"EUCO SI 20261113 PS EU C 1.1700 0"}
{"ts_recv":"2026-04-06T18:53:11.430340287Z","hd":{"ts_event":"2026-04-06T18:53:11.430338519Z","rtype":160,"publisher_id":101,"instrument_id":33704},"action":"R","side":"N","price":null,"size":0,"channel_id":79,"order_id":"0","flags":128,"ts_in_delta":1768,"sequence":0,"symbol":"EUCO SI 20261113 PS EU P 1.1650 0"}
{"ts_recv":"2026-04-06T18:53:11.430340287Z","hd":{"ts_event":"2026-04-06T18:53:11.430338519Z","rtype":160,"publisher_id":101,"instrument_id":33703},"action":"R","side":"N","price":null,"size":0,"channel_id":79,"order_id":"0","flags":128,"ts_in_delta":1768,"sequence":0,"symbol":"EUCO SI 20261113 PS EU C 1.1650 0"}
{"ts_recv":"2026-04-06T18:53:11.430340287Z","hd":{"ts_event":"2026-04-06T18:53:11.430338519Z","rtype":160,"publisher_id":101,"instrument_id":33702},"action":"R","side":"N","price":null,"size":0,"channel_id":79,"order_id":"0","flags":128,"ts_in_delta":1768,"sequence":0,"symbol":"EUCO SI 20261113 PS EU P 1.1600 0"}
{"ts_recv":"2026-04-06T18:53:11.430340287Z","hd":{"ts_event":"2026-04-06T18:53:11.430338519Z","rtype":160,"publisher_id":101,"instrument_id":33701},"action":"R","side":"N","price":null,"size":0,"channel_id":79,"order_id":"0","flags":128,"ts_in_delta":1768,"sequence":0,"symbol":"EUCO SI 20261113 PS EU C 1.1600 0"}
{"ts_recv":"2026-04-06T18:53:11.430340287Z","hd":{"ts_event":"2026-04-06T18:53:11.430338519Z","rtype":160,"publisher_id":101,"instrument_id":33700},"action":"R","side":"N","price":null,"size":0,"channel_id":79,"order_id":"0","flags":128,"ts_in_delta":1768,"sequence":0,"symbol":"EUCO SI 20261113 PS EU P 1.1550 0"}
{"ts_recv":"2026-04-06T18:53:11.430340287Z","hd":{"ts_event":"2026-04-06T18:53:11.430338519Z","rtype":160,"publisher_id":101,"instrument_id":33699},"action":"R","side":"N","price":null,"size":0,"channel_id":79,"order_id":"0","flags":128,"ts_in_delta":1768,"sequence":0,"symbol":"EUCO SI 20261113 PS EU C 1.1550 0"}
{"ts_recv":"2026-04-06T18:53:11.430340287Z","hd":{"ts_event":"2026-04-06T18:53:11.430338519Z","rtype":160,"publisher_id":101,"instrument_id":33698},"action":"R","side":"N","price":null,"size":0,"channel_id":79,"order_id":"0","flags":128,"ts_in_delta":1768,"sequence":0,"symbol":"EUCO SI 20261113 PS EU P 1.1500 0"}
{"ts_recv":"2026-04-06T18:53:11.430340287Z","hd":{"ts_event":"2026-04-06T18:53:11.430338519Z","rtype":160,"publisher_id":101,"instrument_id":33697},"action":"R","side":"N","price":null,"size":0,"channel_id":79,"order_id":"0","flags":128,"ts_in_delta":1768,"sequence":0,"symbol":"EUCO SI 20261113 PS EU C 1.1500 0"}
{"ts_recv":"2026-04-06T18:53:11.430340287Z","hd":{"ts_event":"2026-04-06T18:53:11.430338519Z","rtype":160,"publisher_id":101,"instrument_id":33696},"action":"R","side":"N","price":null,"size":0,"channel_id":79,"order_id":"0","flags":128,"ts_in_delta":1768,"sequence":0,"symbol":"EUCO SI 20261113 PS EU P 1.1450 0"}
{"ts_recv":"2026-04-06T18:53:11.430340287Z","hd":{"ts_event":"2026-04-06T18:53:11.430338519Z","rtype":160,"publisher_id":101,"instrument_id":33695},"action":"R","side":"N","price":null,"size":0,"channel_id":79,"order_id":"0","flags":128,"ts_in_delta":1768,"sequence":0,"symbol":"EUCO SI 20261113 PS EU C 1.1450 0"}
{"ts_recv":"2026-04-06T18:53:11.430340287Z","hd":{"ts_event":"2026-04-06T18:53:11.430338519Z","rtype":160,"publisher_id":101,"instrument_id":33694},"action":"R","side":"N","price":null,"size":0,"channel_id":79,"order_id":"0","flags":128,"ts_in_delta":1768,"sequence":0,"symbol":"EUCO SI 20261113 PS EU P 1.1400 0"}
{"ts_recv":"2026-04-06T18:53:11.430340287Z","hd":{"ts_event":"2026-04-06T18:53:11.430338519Z","rtype":160,"publisher_id":101,"instrument_id":33693},"action":"R","side":"N","price":null,"size":0,"channel_id":79,"order_id":"0","flags":128,"ts_in_delta":1768,"sequence":0,"symbol":"EUCO SI 20261113 PS EU C 1.1400 0"}
{"ts_recv":"2026-04-06T18:53:11.430340287Z","hd":{"ts_event":"2026-04-06T18:53:11.430338519Z","rtype":160,"publisher_id":101,"instrument_id":33692},"action":"R","side":"N","price":null,"size":0,"channel_id":79,"order_id":"0","flags":128,"ts_in_delta":1768,"sequence":0,"symbol":"EUCO SI 20261113 PS EU P 1.1350 0"}
{"ts_recv":"2026-04-06T18:53:11.430340287Z","hd":{"ts_event":"2026-04-06T18:53:11.430338519Z","rtype":160,"publisher_id":101,"instrument_id":33691},"action":"R","side":"N","price":null,"size":0,"channel_id":79,"order_id":"0","flags":128,"ts_in_delta":1768,"sequence":0,"symbol":"EUCO SI 20261113 PS EU C 1.1350 0"}
{"ts_recv":"2026-04-06T18:53:11.430340287Z","hd":{"ts_event":"2026-04-06T18:53:11.430338519Z","rtype":160,"publisher_id":101,"instrument_id":33690},"action":"R","side":"N","price":null,"size":0,"channel_id":79,"order_id":"0","flags":128,"ts_in_delta":1768,"sequence":0,"symbol":"EUCO SI 20261113 PS EU P 1.1300 0"}
{"ts_recv":"2026-04-06T18:53:11.430340287Z","hd":{"ts_event":"2026-04-06T18:53:11.430338519Z","rtype":160,"publisher_id":101,"instrument_id":33689},"action":"R","side":"N","price":null,"size":0,"channel_id":79,"order_id":"0","flags":128,"ts_in_delta":1768,"sequence":0,"symbol":"EUCO SI 20261113 PS EU C 1.1300 0"}
{"ts_recv":"2026-04-06T18:53:11.430340287Z","hd":{"ts_event":"2026-04-06T18:53:11.430338519Z","rtype":160,"publisher_id":101,"instrument_id":33688},"action":"R","side":"N","price":null,"size":0,"channel_id":79,"order_id":"0","flags":128,"ts_in_delta":1768,"sequence":0,"symbol":"EUCO SI 20261113 PS EU P 1.1250 0"}
{"ts_recv":"2026-04-06T18:53:11.430340287Z","hd":{"ts_event":"2026-04-06T18:53:11.430338519Z","rtype":160,"publisher_id":101,"instrument_id":33687},"action":"R","side":"N","price":null,"size":0,"channel_id":79,"order_id":"0","flags":128,"ts_in_delta":1768,"sequence":0,"symbol":"EUCO SI 20261113 PS EU C 1.1250 0"}
{"ts_recv":"2026-04-06T18:53:11.430340287Z","hd":{"ts_event":"2026-04-06T18:53:11.430338519Z","rtype":160,"publisher_id":101,"instrument_id":33686},"action":"R","side":"N","price":null,"size":0,"channel_id":79,"order_id":"0","flags":128,"ts_in_delta":1768,"sequence":0,"symbol":"EUCO SI 20261113 PS EU P 1.1200 0"}
{"ts_recv":"2026-04-06T18:53:11.430340287Z","hd":{"ts_event":"2026-04-06T18:53:11.430338519Z","rtype":160,"publisher_id":101,"instrument_id":33685},"action":"R","side":"N","price":null,"size":0,"channel_id":79,"order_id":"0","flags":128,"ts_in_delta":1768,"sequence":0,"symbol":"EUCO SI 20261113 PS EU C 1.1200 0"}
{"ts_recv":"2026-04-06T18:53:11.430340287Z","hd":{"ts_event":"2026-04-06T18:53:11.430338519Z","rtype":160,"publisher_id":101,"instrument_id":33684},"action":"R","side":"N","price":null,"size":0,"channel_id":79,"order_id":"0","flags":128,"ts_in_delta":1768,"sequence":0,"symbol":"EUCO SI 20261113 PS EU P 1.1150 0"}
{"ts_recv":"2026-04-06T18:53:11.430340287Z","hd":{"ts_event":"2026-04-06T18:53:11.430338519Z","rtype":160,"publisher_id":101,"instrument_id":33683},"action":"R","side":"N","price":null,"size":0,"channel_id":79,"order_id":"0","flags":128,"ts_in_delta":1768,"sequence":0,"symbol":"EUCO SI 20261113 PS EU C 1.1150 0"}
{"ts_recv":"2026-04-06T18:53:11.430340287Z","hd":{"ts_event":"2026-04-06T18:53:11.430338519Z","rtype":160,"publisher_id":101,"instrument_id":33682},"action":"R","side":"N","price":null,"size":0,"channel_id":79,"order_id":"0","flags":128,"ts_in_delta":1768,"sequence":0,"symbol":"EUCO SI 20261113 PS EU P 1.1100 0"}
{"ts_recv":"2026-04-06T18:53:11.430340287Z","hd":{"ts_event":"2026-04-06T18:53:11.430338519Z","rtype":160,"publisher_id":101,"instrument_id":33681},"action":"R","side":"N","price":null,"size":0,"channel_id":79,"order_id":"0","flags":128,"ts_in_delta":1768,"sequence":0,"symbol":"EUCO SI 20261113 PS EU C 1.1100 0"}
{"ts_recv":"2026-04-06T18:53:11.430340287Z","hd":{"ts_event":"2026-04-06T18:53:11.430338519Z","rtype":160,"publisher_id":101,"instrument_id":33680},"action":"R","side":"N","price":null,"size":0,"channel_id":79,"order_id":"0","flags":128,"ts_in_delta":1768,"sequence":0,"symbol":"EUCO SI 20261009 PS EU P 1.2600 0"}
{"ts_recv":"2026-04-06T18:53:11.430340287Z","hd":{"ts_event":"2026-04-06T18:53:11.430338519Z","rtype":160,"publisher_id":101,"instrument_id":33679},"action":"R","side":"N","price":null,"size":0,"channel_id":79,"order_id":"0","flags":128,"ts_in_delta":1768,"sequence":0,"symbol":"EUCO SI 20261009 PS EU C 1.2600 0"}
{"ts_recv":"2026-04-06T18:53:11.430340287Z","hd":{"ts_event":"2026-04-06T18:53:11.430338519Z","rtype":160,"publisher_id":101,"instrument_id":33678},"action":"R","side":"N","price":null,"size":0,"channel_id":79,"order_id":"0","flags":128,"ts_in_delta":1768,"sequence":0,"symbol":"EUCO SI 20261009 PS EU P 1.2550 0"}
{"ts_recv":"2026-04-06T18:53:11.430340287Z","hd":{"ts_event":"2026-04-06T18:53:11.430338519Z","rtype":160,"publisher_id":101,"instrument_id":33677},"action":"R","side":"N","price":null,"size":0,"channel_id":79,"order_id":"0","flags":128,"ts_in_delta":1768,"sequence":0,"symbol":"EUCO SI 20261009 PS EU C 1.2550 0"}
{"ts_recv":"2026-04-06T18:53:11.430340287Z","hd":{"ts_event":"2026-04-06T18:53:11.430338519Z","rtype":160,"publisher_id":101,"instrument_id":33676},"action":"R","side":"N","price":null,"size":0,"channel_id":79,"order_id":"0","flags":128,"ts_in_delta":1768,"sequence":0,"symbol":"EUCO SI 20261009 PS EU P 1.2500 0"}
{"ts_recv":"2026-04-06T18:53:11.430340287Z","hd":{"ts_event":"2026-04-06T18:53:11.430338519Z","rtype":160,"publisher_id":101,"instrument_id":33675},"action":"R","side":"N","price":null,"size":0,"channel_id":79,"order_id":"0","flags":128,"ts_in_delta":1768,"sequence":0,"symbol":"EUCO SI 20261009 PS EU C 1.2500 0"}
{"ts_recv":"2026-04-06T18:53:11.430340287Z","hd":{"ts_event":"2026-04-06T18:53:11.430338519Z","rtype":160,"publisher_id":101,"instrument_id":33674},"action":"R","side":"N","price":null,"size":0,"channel_id":79,"order_id":"0","flags":128,"ts_in_delta":1768,"sequence":0,"symbol":"EUCO SI 20261009 PS EU P 1.2450 0"}
{"ts_recv":"2026-04-06T18:53:11.430340287Z","hd":{"ts_event":"2026-04-06T18:53:11.430338519Z","rtype":160,"publisher_id":101,"instrument_id":33673},"action":"R","side":"N","price":null,"size":0,"channel_id":79,"order_id":"0","flags":128,"ts_in_delta":1768,"sequence":0,"symbol":"EUCO SI 20261009 PS EU C 1.2450 0"}
{"ts_recv":"2026-04-06T18:53:11.430340287Z","hd":{"ts_event":"2026-04-06T18:53:11.430338519Z","rtype":160,"publisher_id":101,"instrument_id":33672},"action":"R","side":"N","price":null,"size":0,"channel_id":79,"order_id":"0","flags":128,"ts_in_delta":1768,"sequence":0,"symbol":"EUCO SI 20261009 PS EU P 1.2400 0"}
{"ts_recv":"2026-04-06T18:53:11.430340287Z","hd":{"ts_event":"2026-04-06T18:53:11.430338519Z","rtype":160,"publisher_id":101,"instrument_id":33671},"action":"R","side":"N","price":null,"size":0,"channel_id":79,"order_id":"0","flags":128,"ts_in_delta":1768,"sequence":0,"symbol":"EUCO SI 20261009 PS EU C 1.2400 0"}
{"ts_recv":"2026-04-06T18:53:11.430340287Z","hd":{"ts_event":"2026-04-06T18:53:11.430338519Z","rtype":160,"publisher_id":101,"instrument_id":33670},"action":"R","side":"N","price":null,"size":0,"channel_id":79,"order_id":"0","flags":128,"ts_in_delta":1768,"sequence":0,"symbol":"EUCO SI 20261009 PS EU P 1.2350 0"}
{"ts_recv":"2026-04-06T18:53:11.430340287Z","hd":{"ts_event":"2026-04-06T18:53:11.430338519Z","rtype":160,"publisher_id":101,"instrument_id":33669},"action":"R","side":"N","price":null,"size":0,"channel_id":79,"order_id":"0","flags":128,"ts_in_delta":1768,"sequence":0,"symbol":"EUCO SI 20261009 PS EU C 1.2350 0"}
{"ts_recv":"2026-04-06T18:53:11.430340287Z","hd":{"ts_event":"2026-04-06T18:53:11.430338519Z","rtype":160,"publisher_id":101,"instrument_id":33668},"action":"R","side":"N","price":null,"size":0,"channel_id":79,"order_id":"0","flags":128,"ts_in_delta":1768,"sequence":0,"symbol":"EUCO SI 20261009 PS EU P 1.2300 0"}
{"ts_recv":"2026-04-06T18:53:11.430340287Z","hd":{"ts_event":"2026-04-06T18:53:11.430338519Z","rtype":160,"publisher_id":101,"instrument_id":33667},"action":"R","side":"N","price":null,"size":0,"channel_id":79,"order_id":"0","flags":128,"ts_in_delta":1768,"sequence":0,"symbol":"EUCO SI 20261009 PS EU C 1.2300 0"}
{"ts_recv":"2026-04-06T18:53:11.430340287Z","hd":{"ts_event":"2026-04-06T18:53:11.430338519Z","rtype":160,"publisher_id":101,"instrument_id":33666},"action":"R","side":"N","price":null,"size":0,"channel_id":79,"order_id":"0","flags":128,"ts_in_delta":1768,"sequence":0,"symbol":"EUCO SI 20261009 PS EU P 1.2250 0"}
{"ts_recv":"2026-04-06T18:53:11.430340287Z","hd":{"ts_event":"2026-04-06T18:53:11.430338519Z","rtype":160,"publisher_id":101,"instrument_id":33665},"action":"R","side":"N","price":null,"size":0,"channel_id":79,"order_id":"0","flags":128,"ts_in_delta":1768,"sequence":0,"symbol":"EUCO SI 20261009 PS EU C 1.2250 0"}
{"ts_recv":"2026-04-06T18:53:11.430340287Z","hd":{"ts_event":"2026-04-06T18:53:11.430338519Z","rtype":160,"publisher_id":101,"instrument_id":33664},"action":"R","side":"N","price":null,"size":0,"channel_id":79,"order_id":"0","flags":128,"ts_in_delta":1768,"sequence":0,"symbol":"EUCO SI 20261009 PS EU P 1.2200 0"}
{"ts_recv":"2026-04-06T18:53:11.430340287Z","hd":{"ts_event":"2026-04-06T18:53:11.430338519Z","rtype":160,"publisher_id":101,"instrument_id":33663},"action":"R","side":"N","price":null,"size":0,"channel_id":79,"order_id":"0","flags":128,"ts_in_delta":1768,"sequence":0,"symbol":"EUCO SI 20261009 PS EU C 1.2200 0"}
{"ts_recv":"2026-04-06T18:53:11.430340287Z","hd":{"ts_event":"2026-04-06T18:53:11.430338519Z","rtype":160,"publisher_id":101,"instrument_id":33662},"action":"R","side":"N","price":null,"size":0,"channel_id":79,"order_id":"0","flags":128,"ts_in_delta":1768,"sequence":0,"symbol":"EUCO SI 20261009 PS EU P 1.2150 0"}
{"ts_recv":"2026-04-06T18:53:11.430340287Z","hd":{"ts_event":"2026-04-06T18:53:11.430338519Z","rtype":160,"publisher_id":101,"instrument_id":33661},"action":"R","side":"N","price":null,"size":0,"channel_id":79,"order_id":"0","flags":128,"ts_in_delta":1768,"sequence":0,"symbol":"EUCO SI 20261009 PS EU C 1.2150 0"}
{"ts_recv":"2026-04-06T18:53:11.430340287Z","hd":{"ts_event":"2026-04-06T18:53:11.430338519Z","rtype":160,"publisher_id":101,"instrument_id":33660},"action":"R","side":"N","price":null,"size":0,"channel_id":79,"order_id":"0","flags":128,"ts_in_delta":1768,"sequence":0,"symbol":"EUCO SI 20261009 PS EU P 1.2100 0"}
{"ts_recv":"2026-04-06T18:53:11.430340287Z","hd":{"ts_event":"2026-04-06T18:53:11.430338519Z","rtype":160,"publisher_id":101,"instrument_id":33659},"action":"R","side":"N","price":null,"size":0,"channel_id":79,"order_id":"0","flags":128,"ts_in_delta":1768,"sequence":0,"symbol":"EUCO SI 20261009 PS EU C 1.2100 0"}
{"ts_recv":"2026-04-06T18:53:11.430340287Z","hd":{"ts_event":"2026-04-06T18:53:11.430338519Z","rtype":160,"publisher_id":101,"instrument_id":33658},"action":"R","side":"N","price":null,"size":0,"channel_id":79,"order_id":"0","flags":128,"ts_in_delta":1768,"sequence":0,"symbol":"EUCO SI 20261009 PS EU P 1.2050 0"}
{"ts_recv":"2026-04-06T18:53:11.430340287Z","hd":{"ts_event":"2026-04-06T18:53:11.430338519Z","rtype":160,"publisher_id":101,"instrument_id":33657},"action":"R","side":"N","price":null,"size":0,"channel_id":79,"order_id":"0","flags":128,"ts_in_delta":1768,"sequence":0,"symbol":"EUCO SI 20261009 PS EU C 1.2050 0"}
{"ts_recv":"2026-04-06T18:53:11.430340287Z","hd":{"ts_event":"2026-04-06T18:53:11.430338519Z","rtype":160,"publisher_id":101,"instrument_id":33656},"action":"R","side":"N","price":null,"size":0,"channel_id":79,"order_id":"0","flags":128,"ts_in_delta":1768,"sequence":0,"symbol":"EUCO SI 20261009 PS EU P 1.2000 0"}
{"ts_recv":"2026-04-06T18:53:11.430340287Z","hd":{"ts_event":"2026-04-06T18:53:11.430338519Z","rtype":160,"publisher_id":101,"instrument_id":33655},"action":"R","side":"N","price":null,"size":0,"channel_id":79,"order_id":"0","flags":128,"ts_in_delta":1768,"sequence":0,"symbol":"EUCO SI 20261009 PS EU C 1.2000 0"}
{"ts_recv":"2026-04-06T18:53:11.430340287Z","hd":{"ts_event":"2026-04-06T18:53:11.430338519Z","rtype":160,"publisher_id":101,"instrument_id":33654},"action":"R","side":"N","price":null,"size":0,"channel_id":79,"order_id":"0","flags":128,"ts_in_delta":1768,"sequence":0,"symbol":"EUCO SI 20261009 PS EU P 1.1950 0"}
{"ts_recv":"2026-04-06T18:53:11.430340287Z","hd":{"ts_event":"2026-04-06T18:53:11.430338519Z","rtype":160,"publisher_id":101,"instrument_id":33653},"action":"R","side":"N","price":null,"size":0,"channel_id":79,"order_id":"0","flags":128,"ts_in_delta":1768,"sequence":0,"symbol":"EUCO SI 20261009 PS EU C 1.1950 0"}
{"ts_recv":"2026-04-06T18:53:11.430340287Z","hd":{"ts_event":"2026-04-06T18:53:11.430338519Z","rtype":160,"publisher_id":101,"instrument_id":33652},"action":"R","side":"N","price":null,"size":0,"channel_id":79,"order_id":"0","flags":128,"ts_in_delta":1768,"sequence":0,"symbol":"EUCO SI 20261009 PS EU P 1.1900 0"}
{"ts_recv":"2026-04-06T18:53:11.430340287Z","hd":{"ts_event":"2026-04-06T18:53:11.430338519Z","rtype":160,"publisher_id":101,"instrument_id":33651},"action":"R","side":"N","price":null,"size":0,"channel_id":79,"order_id":"0","flags":128,"ts_in_delta":1768,"sequence":0,"symbol":"EUCO SI 20261009 PS EU C 1.1900 0"}
{"ts_recv":"2026-04-06T18:53:11.430340287Z","hd":{"ts_event":"2026-04-06T18:53:11.430338519Z","rtype":160,"publisher_id":101,"instrument_id":33650},"action":"R","side":"N","price":null,"size":0,"channel_id":79,"order_id":"0","flags":128,"ts_in_delta":1768,"sequence":0,"symbol":"EUCO SI 20261009 PS EU P 1.1850 0"}
{"ts_recv":"2026-04-06T18:53:11.430340287Z","hd":{"ts_event":"2026-04-06T18:53:11.430338519Z","rtype":160,"publisher_id":101,"instrument_id":33649},"action":"R","side":"N","price":null,"size":0,"channel_id":79,"order_id":"0","flags":128,"ts_in_delta":1768,"sequence":0,"symbol":"EUCO SI 20261009 PS EU C 1.1850 0"}
{"ts_recv":"2026-04-06T18:53:11.430340287Z","hd":{"ts_event":"2026-04-06T18:53:11.430338519Z","rtype":160,"publisher_id":101,"instrument_id":33648},"action":"R","side":"N","price":null,"size":0,"channel_id":79,"order_id":"0","flags":128,"ts_in_delta":1768,"sequence":0,"symbol":"EUCO SI 20261009 PS EU P 1.1800 0"}
{"ts_recv":"2026-04-06T18:53:11.430340287Z","hd":{"ts_event":"2026-04-06T18:53:11.430338519Z","rtype":160,"publisher_id":101,"instrument_id":33647},"action":"R","side":"N","price":null,"size":0,"channel_id":79,"order_id":"0","flags":128,"ts_in_delta":1768,"sequence":0,"symbol":"EUCO SI 20261009 PS EU C 1.1800 0"}
{"ts_recv":"2026-04-06T18:53:11.430340287Z","hd":{"ts_event":"2026-04-06T18:53:11.430338519Z","rtype":160,"publisher_id":101,"instrument_id":33646},"action":"R","side":"N","price":null,"size":0,"channel_id":79,"order_id":"0","flags":128,"ts_in_delta":1768,"sequence":0,"symbol":"EUCO SI 20261009 PS EU P 1.1750 0"}
{"ts_recv":"2026-04-06T18:53:11.430340287Z","hd":{"ts_event":"2026-04-06T18:53:11.430338519Z","rtype":160,"publisher_id":101,"instrument_id":33645},"action":"R","side":"N","price":null,"size":0,"channel_id":79,"order_id":"0","flags":128,"ts_in_delta":1768,"sequence":0,"symbol":"EUCO SI 20261009 PS EU C 1.1750 0"}
{"ts_recv":"2026-04-06T18:53:11.430340287Z","hd":{"ts_event":"2026-04-06T18:53:11.430338519Z","rtype":160,"publisher_id":101,"instrument_id":33644},"action":"R","side":"N","price":null,"size":0,"channel_id":79,"order_id":"0","flags":128,"ts_in_delta":1768,"sequence":0,"symbol":"EUCO SI 20261009 PS EU P 1.1700 0"}
{"ts_recv":"2026-04-06T18:53:11.430340287Z","hd":{"ts_event":"2026-04-06T18:53:11.430338519Z","rtype":160,"publisher_id":101,"instrument_id":33643},"action":"R","side":"N","price":null,"size":0,"channel_id":79,"order_id":"0","flags":128,"ts_in_delta":1768,"sequence":0,"symbol":"EUCO SI 20261009 PS EU C 1.1700 0"}
{"ts_recv":"2026-04-06T18:53:11.430340287Z","hd":{"ts_event":"2026-04-06T18:53:11.430338519Z","rtype":160,"publisher_id":101,"instrument_id":33642},"action":"R","side":"N","price":null,"size":0,"channel_id":79,"order_id":"0","flags":128,"ts_in_delta":1768,"sequence":0,"symbol":"EUCO SI 20261009 PS EU P 1.1650 0"}
{"ts_recv":"2026-04-06T18:53:11.430340287Z","hd":{"ts_event":"2026-04-06T18:53:11.430338519Z","rtype":160,"publisher_id":101,"instrument_id":33641},"action":"R","side":"N","price":null,"size":0,"channel_id":79,"order_id":"0","flags":128,"ts_in_delta":1768,"sequence":0,"symbol":"EUCO SI 20261009 PS EU C 1.1650 0"}
{"ts_recv":"2026-04-06T18:53:11.430340287Z","hd":{"ts_event":"2026-04-06T18:53:11.430338519Z","rtype":160,"publisher_id":101,"instrument_id":33640},"action":"R","side":"N","price":null,"size":0,"channel_id":79,"order_id":"0","flags":128,"ts_in_delta":1768,"sequence":0,"symbol":"EUCO SI 20261009 PS EU P 1.1600 0"}
{"ts_recv":"2026-04-06T18:53:11.430340287Z","hd":{"ts_event":"2026-04-06T18:53:11.430338519Z","rtype":160,"publisher_id":101,"instrument_id":33639},"action":"R","side":"N","price":null,"size":0,"channel_id":79,"order_id":"0","flags":128,"ts_in_delta":1768,"sequence":0,"symbol":"EUCO SI 20261009 PS EU C 1.1600 0"}
{"ts_recv":"2026-04-06T18:53:11.430340287Z","hd":{"ts_event":"2026-04-06T18:53:11.430338519Z","rtype":160,"publisher_id":101,"instrument_id":33638},"action":"R","side":"N","price":null,"size":0,"channel_id":79,"order_id":"0","flags":128,"ts_in_delta":1768,"sequence":0,"symbol":"EUCO SI 20261009 PS EU P 1.1550 0"}
{"ts_recv":"2026-04-06T18:53:11.430340287Z","hd":{"ts_event":"2026-04-06T18:53:11.430338519Z","rtype":160,"publisher_id":101,"instrument_id":33637},"action":"R","side":"N","price":null,"size":0,"channel_id":79,"order_id":"0","flags":128,"ts_in_delta":1768,"sequence":0,"symbol":"EUCO SI 20261009 PS EU C 1.1550 0"}
{"ts_recv":"2026-04-06T18:53:11.430340287Z","hd":{"ts_event":"2026-04-06T18:53:11.430338519Z","rtype":160,"publisher_id":101,"instrument_id":33636},"action":"R","side":"N","price":null,"size":0,"channel_id":79,"order_id":"0","flags":128,"ts_in_delta":1768,"sequence":0,"symbol":"EUCO SI 20261009 PS EU P 1.1500 0"}
{"ts_recv":"2026-04-06T18:53:11.430340287Z","hd":{"ts_event":"2026-04-06T18:53:11.430338519Z","rtype":160,"publisher_id":101,"instrument_id":33635},"action":"R","side":"N","price":null,"size":0,"channel_id":79,"order_id":"0","flags":128,"ts_in_delta":1768,"sequence":0,"symbol":"EUCO SI 20261009 PS EU C 1.1500 0"}
{"ts_recv":"2026-04-06T18:53:11.430340287Z","hd":{"ts_event":"2026-04-06T18:53:11.430338519Z","rtype":160,"publisher_id":101,"instrument_id":33634},"action":"R","side":"N","price":null,"size":0,"channel_id":79,"order_id":"0","flags":128,"ts_in_delta":1768,"sequence":0,"symbol":"EUCO SI 20261009 PS EU P 1.1450 0"}
{"ts_recv":"2026-04-06T18:53:11.430340287Z","hd":{"ts_event":"2026-04-06T18:53:11.430338519Z","rtype":160,"publisher_id":101,"instrument_id":33633},"action":"R","side":"N","price":null,"size":0,"channel_id":79,"order_id":"0","flags":128,"ts_in_delta":1768,"sequence":0,"symbol":"EUCO SI 20261009 PS EU C 1.1450 0"}
{"ts_recv":"2026-04-06T18:53:11.430340287Z","hd":{"ts_event":"2026-04-06T18:53:11.430338519Z","rtype":160,"publisher_id":101,"instrument_id":33632},"action":"R","side":"N","price":null,"size":0,"channel_id":79,"order_id":"0","flags":128,"ts_in_delta":1768,"sequence":0,"symbol":"EUCO SI 20261009 PS EU P 1.1400 0"}
{"ts_recv":"2026-04-06T18:53:11.430340287Z","hd":{"ts_event":"2026-04-06T18:53:11.430338519Z","rtype":160,"publisher_id":101,"instrument_id":33631},"action":"R","side":"N","price":null,"size":0,"channel_id":79,"order_id":"0","flags":128,"ts_in_delta":1768,"sequence":0,"symbol":"EUCO SI 20261009 PS EU C 1.1400 0"}
{"ts_recv":"2026-04-06T18:53:11.430340287Z","hd":{"ts_event":"2026-04-06T18:53:11.430338519Z","rtype":160,"publisher_id":101,"instrument_id":33630},"action":"R","side":"N","price":null,"size":0,"channel_id":79,"order_id":"0","flags":128,"ts_in_delta":1768,"sequence":0,"symbol":"EUCO SI 20261009 PS EU P 1.1350 0"}
{"ts_recv":"2026-04-06T18:53:11.430340287Z","hd":{"ts_event":"2026-04-06T18:53:11.430338519Z","rtype":160,"publisher_id":101,"instrument_id":33629},"action":"R","side":"N","price":null,"size":0,"channel_id":79,"order_id":"0","flags":128,"ts_in_delta":1768,"sequence":0,"symbol":"EUCO SI 20261009 PS EU C 1.1350 0"}
{"ts_recv":"2026-04-06T18:53:11.430340287Z","hd":{"ts_event":"2026-04-06T18:53:11.430338519Z","rtype":160,"publisher_id":101,"instrument_id":33628},"action":"R","side":"N","price":null,"size":0,"channel_id":79,"order_id":"0","flags":128,"ts_in_delta":1768,"sequence":0,"symbol":"EUCO SI 20261009 PS EU P 1.1300 0"}
{"ts_recv":"2026-04-06T18:53:11.430340287Z","hd":{"ts_event":"2026-04-06T18:53:11.430338519Z","rtype":160,"publisher_id":101,"instrument_id":33627},"action":"R","side":"N","price":null,"size":0,"channel_id":79,"order_id":"0","flags":128,"ts_in_delta":1768,"sequence":0,"symbol":"EUCO SI 20261009 PS EU C 1.1300 0"}
{"ts_recv":"2026-04-06T18:53:11.430340287Z","hd":{"ts_event":"2026-04-06T18:53:11.430338519Z","rtype":160,"publisher_id":101,"instrument_id":33626},"action":"R","side":"N","price":null,"size":0,"channel_id":79,"order_id":"0","flags":128,"ts_in_delta":1768,"sequence":0,"symbol":"EUCO SI 20261009 PS EU P 1.1250 0"}
{"ts_recv":"2026-04-06T18:53:11.430340287Z","hd":{"ts_event":"2026-04-06T18:53:11.430338519Z","rtype":160,"publisher_id":101,"instrument_id":33625},"action":"R","side":"N","price":null,"size":0,"channel_id":79,"order_id":"0","flags":128,"ts_in_delta":1768,"sequence":0,"symbol":"EUCO SI 20261009 PS EU C 1.1250 0"}
{"ts_recv":"2026-04-06T18:53:11.430340287Z","hd":{"ts_event":"2026-04-06T18:53:11.430338519Z","rtype":160,"publisher_id":101,"instrument_id":33624},"action":"R","side":"N","price":null,"size":0,"channel_id":79,"order_id":"0","flags":128,"ts_in_delta":1768,"sequence":0,"symbol":"EUCO SI 20261009 PS EU P 1.1200 0"}
{"ts_recv":"2026-04-06T18:53:11.430340287Z","hd":{"ts_event":"2026-04-06T18:53:11.430338519Z","rtype":160,"publisher_id":101,"instrument_id":33623},"action":"R","side":"N","price":null,"size":0,"channel_id":79,"order_id":"0","flags":128,"ts_in_delta":1768,"sequence":0,"symbol":"EUCO SI 20261009 PS EU C 1.1200 0"}
{"ts_recv":"2026-04-06T18:53:11.430340287Z","hd":{"ts_event":"2026-04-06T18:53:11.430338519Z","rtype":160,"publisher_id":101,"instrument_id":33622},"action":"R","side":"N","price":null,"size":0,"channel_id":79,"order_id":"0","flags":128,"ts_in_delta":1768,"sequence":0,"symbol":"EUCO SI 20261009 PS EU P 1.1150 0"}
{"ts_recv":"2026-04-06T18:53:11.430340287Z","hd":{"ts_event":"2026-04-06T18:53:11.430338519Z","rtype":160,"publisher_id":101,"instrument_id":33621},"action":"R","side":"N","price":null,"size":0,"channel_id":79,"order_id":"0","flags":128,"ts_in_delta":1768,"sequence":0,"symbol":"EUCO SI 20261009 PS EU C 1.1150 0"}
{"ts_recv":"2026-04-06T18:53:11.430340287Z","hd":{"ts_event":"2026-04-06T18:53:11.430338519Z","rtype":160,"publisher_id":101,"instrument_id":33620},"action":"R","side":"N","price":null,"size":0,"channel_id":79,"order_id":"0","flags":128,"ts_in_delta":1768,"sequence":0,"symbol":"EUCO SI 20261009 PS EU P 1.1100 0"}
{"ts_recv":"2026-04-06T18:53:11.430340287Z","hd":{"ts_event":"2026-04-06T18:53:11.430338519Z","rtype":160,"publisher_id":101,"instrument_id":33619},"action":"R","side":"N","price":null,"size":0,"channel_id":79,"order_id":"0","flags":128,"ts_in_delta":1768,"sequence":0,"symbol":"EUCO SI 20261009 PS EU C 1.1100 0"}
{"ts_recv":"2026-04-06T18:53:11.430340287Z","hd":{"ts_event":"2026-04-06T18:53:11.430338519Z","rtype":160,"publisher_id":101,"instrument_id":33618},"action":"R","side":"N","price":null,"size":0,"channel_id":79,"order_id":"0","flags":128,"ts_in_delta":1768,"sequence":0,"symbol":"EUCO SI 20260911 PS EU P 1.2600 0"}
{"ts_recv":"2026-04-06T18:53:11.430340287Z","hd":{"ts_event":"2026-04-06T18:53:11.430338519Z","rtype":160,"publisher_id":101,"instrument_id":33617},"action":"R","side":"N","price":null,"size":0,"channel_id":79,"order_id":"0","flags":128,"ts_in_delta":1768,"sequence":0,"symbol":"EUCO SI 20260911 PS EU C 1.2600 0"}
{"ts_recv":"2026-04-06T18:53:11.430340287Z","hd":{"ts_event":"2026-04-06T18:53:11.430338519Z","rtype":160,"publisher_id":101,"instrument_id":33616},"action":"R","side":"N","price":null,"size":0,"channel_id":79,"order_id":"0","flags":128,"ts_in_delta":1768,"sequence":0,"symbol":"EUCO SI 20260911 PS EU P 1.2550 0"}
{"ts_recv":"2026-04-06T18:53:11.430340287Z","hd":{"ts_event":"2026-04-06T18:53:11.430338519Z","rtype":160,"publisher_id":101,"instrument_id":33615},"action":"R","side":"N","price":null,"size":0,"channel_id":79,"order_id":"0","flags":128,"ts_in_delta":1768,"sequence":0,"symbol":"EUCO SI 20260911 PS EU C 1.2550 0"}
{"ts_recv":"2026-04-06T18:53:11.430340287Z","hd":{"ts_event":"2026-04-06T18:53:11.430338519Z","rtype":160,"publisher_id":101,"instrument_id":33614},"action":"R","side":"N","price":null,"size":0,"channel_id":79,"order_id":"0","flags":128,"ts_in_delta":1768,"sequence":0,"symbol":"EUCO SI 20260911 PS EU P 1.2500 0"}
{"ts_recv":"2026-04-06T18:53:11.430340287Z","hd":{"ts_event":"2026-04-06T18:53:11.430338519Z","rtype":160,"publisher_id":101,"instrument_id":33613},"action":"R","side":"N","price":null,"size":0,"channel_id":79,"order_id":"0","flags":128,"ts_in_delta":1768,"sequence":0,"symbol":"EUCO SI 20260911 PS EU C 1.2500 0"}
{"ts_recv":"2026-04-06T18:53:11.430340287Z","hd":{"ts_event":"2026-04-06T18:53:11.430338519Z","rtype":160,"publisher_id":101,"instrument_id":33612},"action":"R","side":"N","price":null,"size":0,"channel_id":79,"order_id":"0","flags":128,"ts_in_delta":1768,"sequence":0,"symbol":"EUCO SI 20260911 PS EU P 1.2450 0"}
{"ts_recv":"2026-04-06T18:53:11.430340287Z","hd":{"ts_event":"2026-04-06T18:53:11.430338519Z","rtype":160,"publisher_id":101,"instrument_id":33611},"action":"R","side":"N","price":null,"size":0,"channel_id":79,"order_id":"0","flags":128,"ts_in_delta":1768,"sequence":0,"symbol":"EUCO SI 20260911 PS EU C 1.2450 0"}
{"ts_recv":"2026-04-06T18:53:11.430340287Z","hd":{"ts_event":"2026-04-06T18:53:11.430338519Z","rtype":160,"publisher_id":101,"instrument_id":33610},"action":"R","side":"N","price":null,"size":0,"channel_id":79,"order_id":"0","flags":128,"ts_in_delta":1768,"sequence":0,"symbol":"EUCO SI 20260911 PS EU P 1.2400 0"}
{"ts_recv":"2026-04-06T18:53:11.430340287Z","hd":{"ts_event":"2026-04-06T18:53:11.430338519Z","rtype":160,"publisher_id":101,"instrument_id":33609},"action":"R","side":"N","price":null,"size":0,"channel_id":79,"order_id":"0","flags":128,"ts_in_delta":1768,"sequence":0,"symbol":"EUCO SI 20260911 PS EU C 1.2400 0"}
{"ts_recv":"2026-04-06T18:53:11.430340287Z","hd":{"ts_event":"2026-04-06T18:53:11.430338519Z","rtype":160,"publisher_id":101,"instrument_id":33608},"action":"R","side":"N","price":null,"size":0,"channel_id":79,"order_id":"0","flags":128,"ts_in_delta":1768,"sequence":0,"symbol":"EUCO SI 20260911 PS EU P 1.2350 0"}
{"ts_recv":"2026-04-06T18:53:11.430340287Z","hd":{"ts_event":"2026-04-06T18:53:11.430338519Z","rtype":160,"publisher_id":101,"instrument_id":33607},"action":"R","side":"N","price":null,"size":0,"channel_id":79,"order_id":"0","flags":128,"ts_in_delta":1768,"sequence":0,"symbol":"EUCO SI 20260911 PS EU C 1.2350 0"}
{"ts_recv":"2026-04-06T18:53:11.430340287Z","hd":{"ts_event":"2026-04-06T18:53:11.430338519Z","rtype":160,"publisher_id":101,"instrument_id":33606},"action":"R","side":"N","price":null,"size":0,"channel_id":79,"order_id":"0","flags":128,"ts_in_delta":1768,"sequence":0,"symbol":"EUCO SI 20260911 PS EU P 1.2300 0"}
{"ts_recv":"2026-04-06T18:53:11.430340287Z","hd":{"ts_event":"2026-04-06T18:53:11.430338519Z","rtype":160,"publisher_id":101,"instrument_id":33605},"action":"R","side":"N","price":null,"size":0,"channel_id":79,"order_id":"0","flags":128,"ts_in_delta":1768,"sequence":0,"symbol":"EUCO SI 20260911 PS EU C 1.2300 0"}
{"ts_recv":"2026-04-06T18:53:11.430340287Z","hd":{"ts_event":"2026-04-06T18:53:11.430338519Z","rtype":160,"publisher_id":101,"instrument_id":33604},"action":"R","side":"N","price":null,"size":0,"channel_id":79,"order_id":"0","flags":128,"ts_in_delta":1768,"sequence":0,"symbol":"EUCO SI 20260911 PS EU P 1.2250 0"}
{"ts_recv":"2026-04-06T18:53:11.430340287Z","hd":{"ts_event":"2026-04-06T18:53:11.430338519Z","rtype":160,"publisher_id":101,"instrument_id":33603},"action":"R","side":"N","price":null,"size":0,"channel_id":79,"order_id":"0","flags":128,"ts_in_delta":1768,"sequence":0,"symbol":"EUCO SI 20260911 PS EU C 1.2250 0"}
{"ts_recv":"2026-04-06T18:53:11.430340287Z","hd":{"ts_event":"2026-04-06T18:53:11.430338519Z","rtype":160,"publisher_id":101,"instrument_id":33602},"action":"R","side":"N","price":null,"size":0,"channel_id":79,"order_id":"0","flags":128,"ts_in_delta":1768,"sequence":0,"symbol":"EUCO SI 20260911 PS EU P 1.2200 0"}
{"ts_recv":"2026-04-06T18:53:11.430340287Z","hd":{"ts_event":"2026-04-06T18:53:11.430338519Z","rtype":160,"publisher_id":101,"instrument_id":33601},"action":"R","side":"N","price":null,"size":0,"channel_id":79,"order_id":"0","flags":128,"ts_in_delta":1768,"sequence":0,"symbol":"EUCO SI 20260911 PS EU C 1.2200 0"}
{"ts_recv":"2026-04-06T18:53:11.430340287Z","hd":{"ts_event":"2026-04-06T18:53:11.430338519Z","rtype":160,"publisher_id":101,"instrument_id":33600},"action":"R","side":"N","price":null,"size":0,"channel_id":79,"order_id":"0","flags":128,"ts_in_delta":1768,"sequence":0,"symbol":"EUCO SI 20260911 PS EU P 1.2150 0"}
{"ts_recv":"2026-04-06T18:53:11.430340287Z","hd":{"ts_event":"2026-04-06T18:53:11.430338519Z","rtype":160,"publisher_id":101,"instrument_id":33599},"action":"R","side":"N","price":null,"size":0,"channel_id":79,"order_id":"0","flags":128,"ts_in_delta":1768,"sequence":0,"symbol":"EUCO SI 20260911 PS EU C 1.2150 0"}
{"ts_recv":"2026-04-06T18:53:11.430340287Z","hd":{"ts_event":"2026-04-06T18:53:11.430338519Z","rtype":160,"publisher_id":101,"instrument_id":33598},"action":"R","side":"N","price":null,"size":0,"channel_id":79,"order_id":"0","flags":128,"ts_in_delta":1768,"sequence":0,"symbol":"EUCO SI 20260911 PS EU P 1.2100 0"}
{"ts_recv":"2026-04-06T18:53:11.430340287Z","hd":{"ts_event":"2026-04-06T18:53:11.430338519Z","rtype":160,"publisher_id":101,"instrument_id":33597},"action":"R","side":"N","price":null,"size":0,"channel_id":79,"order_id":"0","flags":128,"ts_in_delta":1768,"sequence":0,"symbol":"EUCO SI 20260911 PS EU C 1.2100 0"}
{"ts_recv":"2026-04-06T18:53:11.430340287Z","hd":{"ts_event":"2026-04-06T18:53:11.430338519Z","rtype":160,"publisher_id":101,"instrument_id":33596},"action":"R","side":"N","price":null,"size":0,"channel_id":79,"order_id":"0","flags":128,"ts_in_delta":1768,"sequence":0,"symbol":"EUCO SI 20260911 PS EU P 1.2050 0"}
{"ts_recv":"2026-04-06T18:53:11.430340287Z","hd":{"ts_event":"2026-04-06T18:53:11.430338519Z","rtype":160,"publisher_id":101,"instrument_id":33595},"action":"R","side":"N","price":null,"size":0,"channel_id":79,"order_id":"0","flags":128,"ts_in_delta":1768,"sequence":0,"symbol":"EUCO SI 20260911 PS EU C 1.2050 0"}
{"ts_recv":"2026-04-06T18:53:11.430340287Z","hd":{"ts_event":"2026-04-06T18:53:11.430338519Z","rtype":160,"publisher_id":101,"instrument_id":33594},"action":"R","side":"N","price":null,"size":0,"channel_id":79,"order_id":"0","flags":128,"ts_in_delta":1768,"sequence":0,"symbol":"EUCO SI 20260911 PS EU P 1.2000 0"}
{"ts_recv":"2026-04-06T18:53:11.430340287Z","hd":{"ts_event":"2026-04-06T18:53:11.430338519Z","rtype":160,"publisher_id":101,"instrument_id":33593},"action":"R","side":"N","price":null,"size":0,"channel_id":79,"order_id":"0","flags":128,"ts_in_delta":1768,"sequence":0,"symbol":"EUCO SI 20260911 PS EU C 1.2000 0"}
{"ts_recv":"2026-04-06T18:53:11.430340287Z","hd":{"ts_event":"2026-04-06T18:53:11.430338519Z","rtype":160,"publisher_id":101,"instrument_id":33592},"action":"R","side":"N","price":null,"size":0,"channel_id":79,"order_id":"0","flags":128,"ts_in_delta":1768,"sequence":0,"symbol":"EUCO SI 20260911 PS EU P 1.1950 0"}
{"ts_recv":"2026-04-06T18:53:11.430340287Z","hd":{"ts_event":"2026-04-06T18:53:11.430338519Z","rtype":160,"publisher_id":101,"instrument_id":33591},"action":"R","side":"N","price":null,"size":0,"channel_id":79,"order_id":"0","flags":128,"ts_in_delta":1768,"sequence":0,"symbol":"EUCO SI 20260911 PS EU C 1.1950 0"}
{"ts_recv":"2026-04-06T18:53:11.430340287Z","hd":{"ts_event":"2026-04-06T18:53:11.430338519Z","rtype":160,"publisher_id":101,"instrument_id":33590},"action":"R","side":"N","price":null,"size":0,"channel_id":79,"order_id":"0","flags":128,"ts_in_delta":1768,"sequence":0,"symbol":"EUCO SI 20260911 PS EU P 1.1925 0"}
{"ts_recv":"2026-04-06T18:53:11.430340287Z","hd":{"ts_event":"2026-04-06T18:53:11.430338519Z","rtype":160,"publisher_id":101,"instrument_id":33589},"action":"R","side":"N","price":null,"size":0,"channel_id":79,"order_id":"0","flags":128,"ts_in_delta":1768,"sequence":0,"symbol":"EUCO SI 20260911 PS EU C 1.1925 0"}
{"ts_recv":"2026-04-06T18:53:11.430340287Z","hd":{"ts_event":"2026-04-06T18:53:11.430338519Z","rtype":160,"publisher_id":101,"instrument_id":33588},"action":"R","side":"N","price":null,"size":0,"channel_id":79,"order_id":"0","flags":128,"ts_in_delta":1768,"sequence":0,"symbol":"EUCO SI 20260911 PS EU P 1.1900 0"}
{"ts_recv":"2026-04-06T18:53:11.430340287Z","hd":{"ts_event":"2026-04-06T18:53:11.430338519Z","rtype":160,"publisher_id":101,"instrument_id":33587},"action":"R","side":"N","price":null,"size":0,"channel_id":79,"order_id":"0","flags":128,"ts_in_delta":1768,"sequence":0,"symbol":"EUCO SI 20260911 PS EU C 1.1900 0"}
{"ts_recv":"2026-04-06T18:53:11.430340287Z","hd":{"ts_event":"2026-04-06T18:53:11.430338519Z","rtype":160,"publisher_id":101,"instrument_id":33586},"action":"R","side":"N","price":null,"size":0,"channel_id":79,"order_id":"0","flags":128,"ts_in_delta":1768,"sequence":0,"symbol":"EUCO SI 20260911 PS EU P 1.1875 0"}
{"ts_recv":"2026-04-06T18:53:11.430340287Z","hd":{"ts_event":"2026-04-06T18:53:11.430338519Z","rtype":160,"publisher_id":101,"instrument_id":33585},"action":"R","side":"N","price":null,"size":0,"channel_id":79,"order_id":"0","flags":128,"ts_in_delta":1768,"sequence":0,"symbol":"EUCO SI 20260911 PS EU C 1.1875 0"}
{"ts_recv":"2026-04-06T18:53:11.430340287Z","hd":{"ts_event":"2026-04-06T18:53:11.430338519Z","rtype":160,"publisher_id":101,"instrument_id":33584},"action":"R","side":"N","price":null,"size":0,"channel_id":79,"order_id":"0","flags":128,"ts_in_delta":1768,"sequence":0,"symbol":"EUCO SI 20260911 PS EU P 1.1850 0"}
{"ts_recv":"2026-04-06T18:53:11.430340287Z","hd":{"ts_event":"2026-04-06T18:53:11.430338519Z","rtype":160,"publisher_id":101,"instrument_id":33583},"action":"R","side":"N","price":null,"size":0,"channel_id":79,"order_id":"0","flags":128,"ts_in_delta":1768,"sequence":0,"symbol":"EUCO SI 20260911 PS EU C 1.1850 0"}
{"ts_recv":"2026-04-06T18:53:11.430340287Z","hd":{"ts_event":"2026-04-06T18:53:11.430338519Z","rtype":160,"publisher_id":101,"instrument_id":33582},"action":"R","side":"N","price":null,"size":0,"channel_id":79,"order_id":"0","flags":128,"ts_in_delta":1768,"sequence":0,"symbol":"EUCO SI 20260911 PS EU P 1.1825 0"}
{"ts_recv":"2026-04-06T18:53:11.430340287Z","hd":{"ts_event":"2026-04-06T18:53:11.430338519Z","rtype":160,"publisher_id":101,"instrument_id":33581},"action":"R","side":"N","price":null,"size":0,"channel_id":79,"order_id":"0","flags":128,"ts_in_delta":1768,"sequence":0,"symbol":"EUCO SI 20260911 PS EU C 1.1825 0"}
{"ts_recv":"2026-04-06T18:53:11.430340287Z","hd":{"ts_event":"2026-04-06T18:53:11.430338519Z","rtype":160,"publisher_id":101,"instrument_id":33580},"action":"R","side":"N","price":null,"size":0,"channel_id":79,"order_id":"0","flags":128,"ts_in_delta":1768,"sequence":0,"symbol":"EUCO SI 20260911 PS EU P 1.1800 0"}
{"ts_recv":"2026-04-06T18:53:11.430340287Z","hd":{"ts_event":"2026-04-06T18:53:11.430338519Z","rtype":160,"publisher_id":101,"instrument_id":33579},"action":"R","side":"N","price":null,"size":0,"channel_id":79,"order_id":"0","flags":128,"ts_in_delta":1768,"sequence":0,"symbol":"EUCO SI 20260911 PS EU C 1.1800 0"}
{"ts_recv":"2026-04-06T18:53:11.430340287Z","hd":{"ts_event":"2026-04-06T18:53:11.430338519Z","rtype":160,"publisher_id":101,"instrument_id":33578},"action":"R","side":"N","price":null,"size":0,"channel_id":79,"order_id":"0","flags":128,"ts_in_delta":1768,"sequence":0,"symbol":"EUCO SI 20260911 PS EU P 1.1775 0"}
{"ts_recv":"2026-04-06T18:53:11.430340287Z","hd":{"ts_event":"2026-04-06T18:53:11.430338519Z","rtype":160,"publisher_id":101,"instrument_id":33577},"action":"R","side":"N","price":null,"size":0,"channel_id":79,"order_id":"0","flags":128,"ts_in_delta":1768,"sequence":0,"symbol":"EUCO SI 20260911 PS EU C 1.1775 0"}
{"ts_recv":"2026-04-06T18:53:11.430340287Z","hd":{"ts_event":"2026-04-06T18:53:11.430338519Z","rtype":160,"publisher_id":101,"instrument_id":33576},"action":"R","side":"N","price":null,"size":0,"channel_id":79,"order_id":"0","flags":128,"ts_in_delta":1768,"sequence":0,"symbol":"EUCO SI 20260911 PS EU P 1.1750 0"}
{"ts_recv":"2026-04-06T18:53:11.430340287Z","hd":{"ts_event":"2026-04-06T18:53:11.430338519Z","rtype":160,"publisher_id":101,"instrument_id":33575},"action":"R","side":"N","price":null,"size":0,"channel_id":79,"order_id":"0","flags":128,"ts_in_delta":1768,"sequence":0,"symbol":"EUCO SI 20260911 PS EU C 1.1750 0"}
{"ts_recv":"2026-04-06T18:53:11.430340287Z","hd":{"ts_event":"2026-04-06T18:53:11.430338519Z","rtype":160,"publisher_id":101,"instrument_id":33574},"action":"R","side":"N","price":null,"size":0,"channel_id":79,"order_id":"0","flags":128,"ts_in_delta":1768,"sequence":0,"symbol":"EUCO SI 20260911 PS EU P 1.1725 0"}
{"ts_recv":"2026-04-06T18:53:11.430340287Z","hd":{"ts_event":"2026-04-06T18:53:11.430338519Z","rtype":160,"publisher_id":101,"instrument_id":33573},"action":"R","side":"N","price":null,"size":0,"channel_id":79,"order_id":"0","flags":128,"ts_in_delta":1768,"sequence":0,"symbol":"EUCO SI 20260911 PS EU C 1.1725 0"}
{"ts_recv":"2026-04-06T18:53:11.430340287Z","hd":{"ts_event":"2026-04-06T18:53:11.430338519Z","rtype":160,"publisher_id":101,"instrument_id":33572},"action":"R","side":"N","price":null,"size":0,"channel_id":79,"order_id":"0","flags":128,"ts_in_delta":1768,"sequence":0,"symbol":"EUCO SI 20260911 PS EU P 1.1700 0"}
{"ts_recv":"2026-04-06T18:53:11.430340287Z","hd":{"ts_event":"2026-04-06T18:53:11.430338519Z","rtype":160,"publisher_id":101,"instrument_id":33571},"action":"R","side":"N","price":null,"size":0,"channel_id":79,"order_id":"0","flags":128,"ts_in_delta":1768,"sequence":0,"symbol":"EUCO SI 20260911 PS EU C 1.1700 0"}
{"ts_recv":"2026-04-06T18:53:11.430340287Z","hd":{"ts_event":"2026-04-06T18:53:11.430338519Z","rtype":160,"publisher_id":101,"instrument_id":33570},"action":"R","side":"N","price":null,"size":0,"channel_id":79,"order_id":"0","flags":128,"ts_in_delta":1768,"sequence":0,"symbol":"EUCO SI 20260911 PS EU P 1.1675 0"}
{"ts_recv":"2026-04-06T18:53:11.430340287Z","hd":{"ts_event":"2026-04-06T18:53:11.430338519Z","rtype":160,"publisher_id":101,"instrument_id":33569},"action":"R","side":"N","price":null,"size":0,"channel_id":79,"order_id":"0","flags":128,"ts_in_delta":1768,"sequence":0,"symbol":"EUCO SI 20260911 PS EU C 1.1675 0"}
{"ts_recv":"2026-04-06T18:53:11.430340287Z","hd":{"ts_event":"2026-04-06T18:53:11.430338519Z","rtype":160,"publisher_id":101,"instrument_id":33568},"action":"R","side":"N","price":null,"size":0,"channel_id":79,"order_id":"0","flags":128,"ts_in_delta":1768,"sequence":0,"symbol":"EUCO SI 20260911 PS EU P 1.1650 0"}
{"ts_recv":"2026-04-06T18:53:11.430340287Z","hd":{"ts_event":"2026-04-06T18:53:11.430338519Z","rtype":160,"publisher_id":101,"instrument_id":33567},"action":"R","side":"N","price":null,"size":0,"channel_id":79,"order_id":"0","flags":128,"ts_in_delta":1768,"sequence":0,"symbol":"EUCO SI 20260911 PS EU C 1.1650 0"}
{"ts_recv":"2026-04-06T18:53:11.430340287Z","hd":{"ts_event":"2026-04-06T18:53:11.430338519Z","rtype":160,"publisher_id":101,"instrument_id":33566},"action":"R","side":"N","price":null,"size":0,"channel_id":79,"order_id":"0","flags":128,"ts_in_delta":1768,"sequence":0,"symbol":"EUCO SI 20260911 PS EU P 1.1625 0"}
{"ts_recv":"2026-04-06T18:53:11.430340287Z","hd":{"ts_event":"2026-04-06T18:53:11.430338519Z","rtype":160,"publisher_id":101,"instrument_id":33565},"action":"R","side":"N","price":null,"size":0,"channel_id":79,"order_id":"0","flags":128,"ts_in_delta":1768,"sequence":0,"symbol":"EUCO SI 20260911 PS EU C 1.1625 0"}
{"ts_recv":"2026-04-06T18:53:11.430340287Z","hd":{"ts_event":"2026-04-06T18:53:11.430338519Z","rtype":160,"publisher_id":101,"instrument_id":33564},"action":"R","side":"N","price":null,"size":0,"channel_id":79,"order_id":"0","flags":128,"ts_in_delta":1768,"sequence":0,"symbol":"EUCO SI 20260911 PS EU P 1.1600 0"}
{"ts_recv":"2026-04-06T18:53:11.430340287Z","hd":{"ts_event":"2026-04-06T18:53:11.430338519Z","rtype":160,"publisher_id":101,"instrument_id":33563},"action":"R","side":"N","price":null,"size":0,"channel_id":79,"order_id":"0","flags":128,"ts_in_delta":1768,"sequence":0,"symbol":"EUCO SI 20260911 PS EU C 1.1600 0"}
{"ts_recv":"2026-04-06T18:53:11.430340287Z","hd":{"ts_event":"2026-04-06T18:53:11.430338519Z","rtype":160,"publisher_id":101,"instrument_id":33562},"action":"R","side":"N","price":null,"size":0,"channel_id":79,"order_id":"0","flags":128,"ts_in_delta":1768,"sequence":0,"symbol":"EUCO SI 20260911 PS EU P 1.1575 0"}
{"ts_recv":"2026-04-06T18:53:11.430340287Z","hd":{"ts_event":"2026-04-06T18:53:11.430338519Z","rtype":160,"publisher_id":101,"instrument_id":33561},"action":"R","side":"N","price":null,"size":0,"channel_id":79,"order_id":"0","flags":128,"ts_in_delta":1768,"sequence":0,"symbol":"EUCO SI 20260911 PS EU C 1.1575 0"}
{"ts_recv":"2026-04-06T18:53:11.430340287Z","hd":{"ts_event":"2026-04-06T18:53:11.430338519Z","rtype":160,"publisher_id":101,"instrument_id":33560},"action":"R","side":"N","price":null,"size":0,"channel_id":79,"order_id":"0","flags":128,"ts_in_delta":1768,"sequence":0,"symbol":"EUCO SI 20260911 PS EU P 1.1550 0"}
{"ts_recv":"2026-04-06T18:53:11.430340287Z","hd":{"ts_event":"2026-04-06T18:53:11.430338519Z","rtype":160,"publisher_id":101,"instrument_id":33559},"action":"R","side":"N","price":null,"size":0,"channel_id":79,"order_id":"0","flags":128,"ts_in_delta":1768,"sequence":0,"symbol":"EUCO SI 20260911 PS EU C 1.1550 0"}
{"ts_recv":"2026-04-06T18:53:11.430340287Z","hd":{"ts_event":"2026-04-06T18:53:11.430338519Z","rtype":160,"publisher_id":101,"instrument_id":33558},"action":"R","side":"N","price":null,"size":0,"channel_id":79,"order_id":"0","flags":128,"ts_in_delta":1768,"sequence":0,"symbol":"EUCO SI 20260911 PS EU P 1.1525 0"}
{"ts_recv":"2026-04-06T18:53:11.430340287Z","hd":{"ts_event":"2026-04-06T18:53:11.430338519Z","rtype":160,"publisher_id":101,"instrument_id":33557},"action":"R","side":"N","price":null,"size":0,"channel_id":79,"order_id":"0","flags":128,"ts_in_delta":1768,"sequence":0,"symbol":"EUCO SI 20260911 PS EU C 1.1525 0"}
{"ts_recv":"2026-04-06T18:53:11.430340287Z","hd":{"ts_event":"2026-04-06T18:53:11.430338519Z","rtype":160,"publisher_id":101,"instrument_id":33556},"action":"R","side":"N","price":null,"size":0,"channel_id":79,"order_id":"0","flags":128,"ts_in_delta":1768,"sequence":0,"symbol":"EUCO SI 20260911 PS EU P 1.1500 0"}
{"ts_recv":"2026-04-06T18:53:11.430340287Z","hd":{"ts_event":"2026-04-06T18:53:11.430338519Z","rtype":160,"publisher_id":101,"instrument_id":33555},"action":"R","side":"N","price":null,"size":0,"channel_id":79,"order_id":"0","flags":128,"ts_in_delta":1768,"sequence":0,"symbol":"EUCO SI 20260911 PS EU C 1.1500 0"}
{"ts_recv":"2026-04-06T18:53:11.430340287Z","hd":{"ts_event":"2026-04-06T18:53:11.430338519Z","rtype":160,"publisher_id":101,"instrument_id":33554},"action":"R","side":"N","price":null,"size":0,"channel_id":79,"order_id":"0","flags":128,"ts_in_delta":1768,"sequence":0,"symbol":"EUCO SI 20260911 PS EU P 1.1475 0"}
{"ts_recv":"2026-04-06T18:53:11.430340287Z","hd":{"ts_event":"2026-04-06T18:53:11.430338519Z","rtype":160,"publisher_id":101,"instrument_id":33553},"action":"R","side":"N","price":null,"size":0,"channel_id":79,"order_id":"0","flags":128,"ts_in_delta":1768,"sequence":0,"symbol":"EUCO SI 20260911 PS EU C 1.1475 0"}
{"ts_recv":"2026-04-06T18:53:11.430340287Z","hd":{"ts_event":"2026-04-06T18:53:11.430338519Z","rtype":160,"publisher_id":101,"instrument_id":33552},"action":"R","side":"N","price":null,"size":0,"channel_id":79,"order_id":"0","flags":128,"ts_in_delta":1768,"sequence":0,"symbol":"EUCO SI 20260911 PS EU P 1.1450 0"}
{"ts_recv":"2026-04-06T18:53:11.430340287Z","hd":{"ts_event":"2026-04-06T18:53:11.430338519Z","rtype":160,"publisher_id":101,"instrument_id":33551},"action":"R","side":"N","price":null,"size":0,"channel_id":79,"order_id":"0","flags":128,"ts_in_delta":1768,"sequence":0,"symbol":"EUCO SI 20260911 PS EU C 1.1450 0"}
{"ts_recv":"2026-04-06T18:53:11.430340287Z","hd":{"ts_event":"2026-04-06T18:53:11.430338519Z","rtype":160,"publisher_id":101,"instrument_id":33550},"action":"R","side":"N","price":null,"size":0,"channel_id":79,"order_id":"0","flags":128,"ts_in_delta":1768,"sequence":0,"symbol":"EUCO SI 20260911 PS EU P 1.1425 0"}
{"ts_recv":"2026-04-06T18:53:11.430340287Z","hd":{"ts_event":"2026-04-06T18:53:11.430338519Z","rtype":160,"publisher_id":101,"instrument_id":33549},"action":"R","side":"N","price":null,"size":0,"channel_id":79,"order_id":"0","flags":128,"ts_in_delta":1768,"sequence":0,"symbol":"EUCO SI 20260911 PS EU C 1.1425 0"}
{"ts_recv":"2026-04-06T18:53:11.430340287Z","hd":{"ts_event":"2026-04-06T18:53:11.430338519Z","rtype":160,"publisher_id":101,"instrument_id":33548},"action":"R","side":"N","price":null,"size":0,"channel_id":79,"order_id":"0","flags":128,"ts_in_delta":1768,"sequence":0,"symbol":"EUCO SI 20260911 PS EU P 1.1400 0"}
{"ts_recv":"2026-04-06T18:53:11.430340287Z","hd":{"ts_event":"2026-04-06T18:53:11.430338519Z","rtype":160,"publisher_id":101,"instrument_id":33547},"action":"R","side":"N","price":null,"size":0,"channel_id":79,"order_id":"0","flags":128,"ts_in_delta":1768,"sequence":0,"symbol":"EUCO SI 20260911 PS EU C 1.1400 0"}
{"ts_recv":"2026-04-06T18:53:11.430340287Z","hd":{"ts_event":"2026-04-06T18:53:11.430338519Z","rtype":160,"publisher_id":101,"instrument_id":33546},"action":"R","side":"N","price":null,"size":0,"channel_id":79,"order_id":"0","flags":128,"ts_in_delta":1768,"sequence":0,"symbol":"EUCO SI 20260911 PS EU P 1.1375 0"}
{"ts_recv":"2026-04-06T18:53:11.430340287Z","hd":{"ts_event":"2026-04-06T18:53:11.430338519Z","rtype":160,"publisher_id":101,"instrument_id":33545},"action":"R","side":"N","price":null,"size":0,"channel_id":79,"order_id":"0","flags":128,"ts_in_delta":1768,"sequence":0,"symbol":"EUCO SI 20260911 PS EU C 1.1375 0"}
{"ts_recv":"2026-04-06T18:53:11.430340287Z","hd":{"ts_event":"2026-04-06T18:53:11.430338519Z","rtype":160,"publisher_id":101,"instrument_id":33544},"action":"R","side":"N","price":null,"size":0,"channel_id":79,"order_id":"0","flags":128,"ts_in_delta":1768,"sequence":0,"symbol":"EUCO SI 20260911 PS EU P 1.1350 0"}
{"ts_recv":"2026-04-06T18:53:11.430340287Z","hd":{"ts_event":"2026-04-06T18:53:11.430338519Z","rtype":160,"publisher_id":101,"instrument_id":33543},"action":"R","side":"N","price":null,"size":0,"channel_id":79,"order_id":"0","flags":128,"ts_in_delta":1768,"sequence":0,"symbol":"EUCO SI 20260911 PS EU C 1.1350 0"}
{"ts_recv":"2026-04-06T18:53:11.430340287Z","hd":{"ts_event":"2026-04-06T18:53:11.430338519Z","rtype":160,"publisher_id":101,"instrument_id":33542},"action":"R","side":"N","price":null,"size":0,"channel_id":79,"order_id":"0","flags":128,"ts_in_delta":1768,"sequence":0,"symbol":"EUCO SI 20260911 PS EU P 1.1325 0"}
{"ts_recv":"2026-04-06T18:53:11.430340287Z","hd":{"ts_event":"2026-04-06T18:53:11.430338519Z","rtype":160,"publisher_id":101,"instrument_id":33541},"action":"R","side":"N","price":null,"size":0,"channel_id":79,"order_id":"0","flags":128,"ts_in_delta":1768,"sequence":0,"symbol":"EUCO SI 20260911 PS EU C 1.1325 0"}
{"ts_recv":"2026-04-06T18:53:11.430340287Z","hd":{"ts_event":"2026-04-06T18:53:11.430338519Z","rtype":160,"publisher_id":101,"instrument_id":33540},"action":"R","side":"N","price":null,"size":0,"channel_id":79,"order_id":"0","flags":128,"ts_in_delta":1768,"sequence":0,"symbol":"EUCO SI 20260911 PS EU P 1.1300 0"}
{"ts_recv":"2026-04-06T18:53:11.430340287Z","hd":{"ts_event":"2026-04-06T18:53:11.430338519Z","rtype":160,"publisher_id":101,"instrument_id":33539},"action":"R","side":"N","price":null,"size":0,"channel_id":79,"order_id":"0","flags":128,"ts_in_delta":1768,"sequence":0,"symbol":"EUCO SI 20260911 PS EU C 1.1300 0"}
{"ts_recv":"2026-04-06T18:53:11.430340287Z","hd":{"ts_event":"2026-04-06T18:53:11.430338519Z","rtype":160,"publisher_id":101,"instrument_id":33538},"action":"R","side":"N","price":null,"size":0,"channel_id":79,"order_id":"0","flags":128,"ts_in_delta":1768,"sequence":0,"symbol":"EUCO SI 20260911 PS EU P 1.1250 0"}
{"ts_recv":"2026-04-06T18:53:11.430340287Z","hd":{"ts_event":"2026-04-06T18:53:11.430338519Z","rtype":160,"publisher_id":101,"instrument_id":33537},"action":"R","side":"N","price":null,"size":0,"channel_id":79,"order_id":"0","flags":128,"ts_in_delta":1768,"sequence":0,"symbol":"EUCO SI 20260911 PS EU C 1.1250 0"}
{"ts_recv":"2026-04-06T18:53:11.430340287Z","hd":{"ts_event":"2026-04-06T18:53:11.430338519Z","rtype":160,"publisher_id":101,"instrument_id":33536},"action":"R","side":"N","price":null,"size":0,"channel_id":79,"order_id":"0","flags":128,"ts_in_delta":1768,"sequence":0,"symbol":"EUCO SI 20260911 PS EU P 1.1200 0"}
{"ts_recv":"2026-04-06T18:53:11.430340287Z","hd":{"ts_event":"2026-04-06T18:53:11.430338519Z","rtype":160,"publisher_id":101,"instrument_id":33535},"action":"R","side":"N","price":null,"size":0,"channel_id":79,"order_id":"0","flags":128,"ts_in_delta":1768,"sequence":0,"symbol":"EUCO SI 20260911 PS EU C 1.1200 0"}
{"ts_recv":"2026-04-06T18:53:11.430340287Z","hd":{"ts_event":"2026-04-06T18:53:11.430338519Z","rtype":160,"publisher_id":101,"instrument_id":33534},"action":"R","side":"N","price":null,"size":0,"channel_id":79,"order_id":"0","flags":128,"ts_in_delta":1768,"sequence":0,"symbol":"EUCO SI 20260911 PS EU P 1.1150 0"}
{"ts_recv":"2026-04-06T18:53:11.430340287Z","hd":{"ts_event":"2026-04-06T18:53:11.430338519Z","rtype":160,"publisher_id":101,"instrument_id":33533},"action":"R","side":"N","price":null,"size":0,"channel_id":79,"order_id":"0","flags":128,"ts_in_delta":1768,"sequence":0,"symbol":"EUCO SI 20260911 PS EU C 1.1150 0"}
{"ts_recv":"2026-04-06T18:53:11.430340287Z","hd":{"ts_event":"2026-04-06T18:53:11.430338519Z","rtype":160,"publisher_id":101,"instrument_id":33532},"action":"R","side":"N","price":null,"size":0,"channel_id":79,"order_id":"0","flags":128,"ts_in_delta":1768,"sequence":0,"symbol":"EUCO SI 20260911 PS EU P 1.1100 0"}
{"ts_recv":"2026-04-06T18:53:11.430340287Z","hd":{"ts_event":"2026-04-06T18:53:11.430338519Z","rtype":160,"publisher_id":101,"instrument_id":33531},"action":"R","side":"N","price":null,"size":0,"channel_id":79,"order_id":"0","flags":128,"ts_in_delta":1768,"sequence":0,"symbol":"EUCO SI 20260911 PS EU C 1.1100 0"}
{"ts_recv":"2026-04-06T18:53:11.430340287Z","hd":{"ts_event":"2026-04-06T18:53:11.430338519Z","rtype":160,"publisher_id":101,"instrument_id":33530},"action":"R","side":"N","price":null,"size":0,"channel_id":79,"order_id":"0","flags":128,"ts_in_delta":1768,"sequence":0,"symbol":"EUCO SI 20260814 PS EU P 1.2550 0"}
{"ts_recv":"2026-04-06T18:53:11.430340287Z","hd":{"ts_event":"2026-04-06T18:53:11.430338519Z","rtype":160,"publisher_id":101,"instrument_id":33529},"action":"R","side":"N","price":null,"size":0,"channel_id":79,"order_id":"0","flags":128,"ts_in_delta":1768,"sequence":0,"symbol":"EUCO SI 20260814 PS EU C 1.2550 0"}
{"ts_recv":"2026-04-06T18:53:11.430340287Z","hd":{"ts_event":"2026-04-06T18:53:11.430338519Z","rtype":160,"publisher_id":101,"instrument_id":33528},"action":"R","side":"N","price":null,"size":0,"channel_id":79,"order_id":"0","flags":128,"ts_in_delta":1768,"sequence":0,"symbol":"EUCO SI 20260814 PS EU P 1.2500 0"}
{"ts_recv":"2026-04-06T18:53:11.430340287Z","hd":{"ts_event":"2026-04-06T18:53:11.430338519Z","rtype":160,"publisher_id":101,"instrument_id":33527},"action":"R","side":"N","price":null,"size":0,"channel_id":79,"order_id":"0","flags":128,"ts_in_delta":1768,"sequence":0,"symbol":"EUCO SI 20260814 PS EU C 1.2500 0"}
{"ts_recv":"2026-04-06T18:53:11.430340287Z","hd":{"ts_event":"2026-04-06T18:53:11.430338519Z","rtype":160,"publisher_id":101,"instrument_id":33526},"action":"R","side":"N","price":null,"size":0,"channel_id":79,"order_id":"0","flags":128,"ts_in_delta":1768,"sequence":0,"symbol":"EUCO SI 20260814 PS EU P 1.2450 0"}
{"ts_recv":"2026-04-06T18:53:11.430340287Z","hd":{"ts_event":"2026-04-06T18:53:11.430338519Z","rtype":160,"publisher_id":101,"instrument_id":33525},"action":"R","side":"N","price":null,"size":0,"channel_id":79,"order_id":"0","flags":128,"ts_in_delta":1768,"sequence":0,"symbol":"EUCO SI 20260814 PS EU C 1.2450 0"}
{"ts_recv":"2026-04-06T18:53:11.430340287Z","hd":{"ts_event":"2026-04-06T18:53:11.430338519Z","rtype":160,"publisher_id":101,"instrument_id":33524},"action":"R","side":"N","price":null,"size":0,"channel_id":79,"order_id":"0","flags":128,"ts_in_delta":1768,"sequence":0,"symbol":"EUCO SI 20260814 PS EU P 1.2400 0"}
{"ts_recv":"2026-04-06T18:53:11.430340287Z","hd":{"ts_event":"2026-04-06T18:53:11.430338519Z","rtype":160,"publisher_id":101,"instrument_id":33523},"action":"R","side":"N","price":null,"size":0,"channel_id":79,"order_id":"0","flags":128,"ts_in_delta":1768,"sequence":0,"symbol":"EUCO SI 20260814 PS EU C 1.2400 0"}
{"ts_recv":"2026-04-06T18:53:11.430340287Z","hd":{"ts_event":"2026-04-06T18:53:11.430338519Z","rtype":160,"publisher_id":101,"instrument_id":33522},"action":"R","side":"N","price":null,"size":0,"channel_id":79,"order_id":"0","flags":128,"ts_in_delta":1768,"sequence":0,"symbol":"EUCO SI 20260814 PS EU P 1.2350 0"}
{"ts_recv":"2026-04-06T18:53:11.430340287Z","hd":{"ts_event":"2026-04-06T18:53:11.430338519Z","rtype":160,"publisher_id":101,"instrument_id":33521},"action":"R","side":"N","price":null,"size":0,"channel_id":79,"order_id":"0","flags":128,"ts_in_delta":1768,"sequence":0,"symbol":"EUCO SI 20260814 PS EU C 1.2350 0"}
{"ts_recv":"2026-04-06T18:53:11.430340287Z","hd":{"ts_event":"2026-04-06T18:53:11.430338519Z","rtype":160,"publisher_id":101,"instrument_id":33520},"action":"R","side":"N","price":null,"size":0,"channel_id":79,"order_id":"0","flags":128,"ts_in_delta":1768,"sequence":0,"symbol":"EUCO SI 20260814 PS EU P 1.2300 0"}
{"ts_recv":"2026-04-06T18:53:11.430340287Z","hd":{"ts_event":"2026-04-06T18:53:11.430338519Z","rtype":160,"publisher_id":101,"instrument_id":33519},"action":"R","side":"N","price":null,"size":0,"channel_id":79,"order_id":"0","flags":128,"ts_in_delta":1768,"sequence":0,"symbol":"EUCO SI 20260814 PS EU C 1.2300 0"}
{"ts_recv":"2026-04-06T18:53:11.430340287Z","hd":{"ts_event":"2026-04-06T18:53:11.430338519Z","rtype":160,"publisher_id":101,"instrument_id":33518},"action":"R","side":"N","price":null,"size":0,"channel_id":79,"order_id":"0","flags":128,"ts_in_delta":1768,"sequence":0,"symbol":"EUCO SI 20260814 PS EU P 1.2250 0"}
{"ts_recv":"2026-04-06T18:53:11.430340287Z","hd":{"ts_event":"2026-04-06T18:53:11.430338519Z","rtype":160,"publisher_id":101,"instrument_id":33517},"action":"R","side":"N","price":null,"size":0,"channel_id":79,"order_id":"0","flags":128,"ts_in_delta":1768,"sequence":0,"symbol":"EUCO SI 20260814 PS EU C 1.2250 0"}
{"ts_recv":"2026-04-06T18:53:11.430340287Z","hd":{"ts_event":"2026-04-06T18:53:11.430338519Z","rtype":160,"publisher_id":101,"instrument_id":33516},"action":"R","side":"N","price":null,"size":0,"channel_id":79,"order_id":"0","flags":128,"ts_in_delta":1768,"sequence":0,"symbol":"EUCO SI 20260814 PS EU P 1.2225 0"}
{"ts_recv":"2026-04-06T18:53:11.430340287Z","hd":{"ts_event":"2026-04-06T18:53:11.430338519Z","rtype":160,"publisher_id":101,"instrument_id":33515},"action":"R","side":"N","price":null,"size":0,"channel_id":79,"order_id":"0","flags":128,"ts_in_delta":1768,"sequence":0,"symbol":"EUCO SI 20260814 PS EU C 1.2225 0"}
{"ts_recv":"2026-04-06T18:53:11.430340287Z","hd":{"ts_event":"2026-04-06T18:53:11.430338519Z","rtype":160,"publisher_id":101,"instrument_id":33514},"action":"R","side":"N","price":null,"size":0,"channel_id":79,"order_id":"0","flags":128,"ts_in_delta":1768,"sequence":0,"symbol":"EUCO SI 20260814 PS EU P 1.2200 0"}
{"ts_recv":"2026-04-06T18:53:11.430340287Z","hd":{"ts_event":"2026-04-06T18:53:11.430338519Z","rtype":160,"publisher_id":101,"instrument_id":33513},"action":"R","side":"N","price":null,"size":0,"channel_id":79,"order_id":"0","flags":128,"ts_in_delta":1768,"sequence":0,"symbol":"EUCO SI 20260814 PS EU C 1.2200 0"}
{"ts_recv":"2026-04-06T18:53:11.430340287Z","hd":{"ts_event":"2026-04-06T18:53:11.430338519Z","rtype":160,"publisher_id":101,"instrument_id":33512},"action":"R","side":"N","price":null,"size":0,"channel_id":79,"order_id":"0","flags":128,"ts_in_delta":1768,"sequence":0,"symbol":"EUCO SI 20260814 PS EU P 1.2175 0"}
{"ts_recv":"2026-04-06T18:53:11.430340287Z","hd":{"ts_event":"2026-04-06T18:53:11.430338519Z","rtype":160,"publisher_id":101,"instrument_id":33511},"action":"R","side":"N","price":null,"size":0,"channel_id":79,"order_id":"0","flags":128,"ts_in_delta":1768,"sequence":0,"symbol":"EUCO SI 20260814 PS EU C 1.2175 0"}
{"ts_recv":"2026-04-06T18:53:11.430340287Z","hd":{"ts_event":"2026-04-06T18:53:11.430338519Z","rtype":160,"publisher_id":101,"instrument_id":33510},"action":"R","side":"N","price":null,"size":0,"channel_id":79,"order_id":"0","flags":128,"ts_in_delta":1768,"sequence":0,"symbol":"EUCO SI 20260814 PS EU P 1.2150 0"}
{"ts_recv":"2026-04-06T18:53:11.430340287Z","hd":{"ts_event":"2026-04-06T18:53:11.430338519Z","rtype":160,"publisher_id":101,"instrument_id":33509},"action":"R","side":"N","price":null,"size":0,"channel_id":79,"order_id":"0","flags":128,"ts_in_delta":1768,"sequence":0,"symbol":"EUCO SI 20260814 PS EU C 1.2150 0"}
{"ts_recv":"2026-04-06T18:53:11.430340287Z","hd":{"ts_event":"2026-04-06T18:53:11.430338519Z","rtype":160,"publisher_id":101,"instrument_id":33508},"action":"R","side":"N","price":null,"size":0,"channel_id":79,"order_id":"0","flags":128,"ts_in_delta":1768,"sequence":0,"symbol":"EUCO SI 20260814 PS EU P 1.2125 0"}
{"ts_recv":"2026-04-06T18:53:11.430340287Z","hd":{"ts_event":"2026-04-06T18:53:11.430338519Z","rtype":160,"publisher_id":101,"instrument_id":33507},"action":"R","side":"N","price":null,"size":0,"channel_id":79,"order_id":"0","flags":128,"ts_in_delta":1768,"sequence":0,"symbol":"EUCO SI 20260814 PS EU C 1.2125 0"}
{"ts_recv":"2026-04-06T18:53:11.430340287Z","hd":{"ts_event":"2026-04-06T18:53:11.430338519Z","rtype":160,"publisher_id":101,"instrument_id":33506},"action":"R","side":"N","price":null,"size":0,"channel_id":79,"order_id":"0","flags":128,"ts_in_delta":1768,"sequence":0,"symbol":"EUCO SI 20260814 PS EU P 1.2100 0"}
{"ts_recv":"2026-04-06T18:53:11.430340287Z","hd":{"ts_event":"2026-04-06T18:53:11.430338519Z","rtype":160,"publisher_id":101,"instrument_id":33505},"action":"R","side":"N","price":null,"size":0,"channel_id":79,"order_id":"0","flags":128,"ts_in_delta":1768,"sequence":0,"symbol":"EUCO SI 20260814 PS EU C 1.2100 0"}
{"ts_recv":"2026-04-06T18:53:11.430340287Z","hd":{"ts_event":"2026-04-06T18:53:11.430338519Z","rtype":160,"publisher_id":101,"instrument_id":33504},"action":"R","side":"N","price":null,"size":0,"channel_id":79,"order_id":"0","flags":128,"ts_in_delta":1768,"sequence":0,"symbol":"EUCO SI 20260814 PS EU P 1.2075 0"}
{"ts_recv":"2026-04-06T18:53:11.430340287Z","hd":{"ts_event":"2026-04-06T18:53:11.430338519Z","rtype":160,"publisher_id":101,"instrument_id":33503},"action":"R","side":"N","price":null,"size":0,"channel_id":79,"order_id":"0","flags":128,"ts_in_delta":1768,"sequence":0,"symbol":"EUCO SI 20260814 PS EU C 1.2075 0"}
{"ts_recv":"2026-04-06T18:53:11.430340287Z","hd":{"ts_event":"2026-04-06T18:53:11.430338519Z","rtype":160,"publisher_id":101,"instrument_id":33502},"action":"R","side":"N","price":null,"size":0,"channel_id":79,"order_id":"0","flags":128,"ts_in_delta":1768,"sequence":0,"symbol":"EUCO SI 20260814 PS EU P 1.2050 0"}
{"ts_recv":"2026-04-06T18:53:11.430340287Z","hd":{"ts_event":"2026-04-06T18:53:11.430338519Z","rtype":160,"publisher_id":101,"instrument_id":33501},"action":"R","side":"N","price":null,"size":0,"channel_id":79,"order_id":"0","flags":128,"ts_in_delta":1768,"sequence":0,"symbol":"EUCO SI 20260814 PS EU C 1.2050 0"}
{"ts_recv":"2026-04-06T18:53:11.430340287Z","hd":{"ts_event":"2026-04-06T18:53:11.430338519Z","rtype":160,"publisher_id":101,"instrument_id":33500},"action":"R","side":"N","price":null,"size":0,"channel_id":79,"order_id":"0","flags":128,"ts_in_delta":1768,"sequence":0,"symbol":"EUCO SI 20260814 PS EU P 1.2025 0"}
{"ts_recv":"2026-04-06T18:53:11.430340287Z","hd":{"ts_event":"2026-04-06T18:53:11.430338519Z","rtype":160,"publisher_id":101,"instrument_id":33499},"action":"R","side":"N","price":null,"size":0,"channel_id":79,"order_id":"0","flags":128,"ts_in_delta":1768,"sequence":0,"symbol":"EUCO SI 20260814 PS EU C 1.2025 0"}
{"ts_recv":"2026-04-06T18:53:11.430340287Z","hd":{"ts_event":"2026-04-06T18:53:11.430338519Z","rtype":160,"publisher_id":101,"instrument_id":33498},"action":"R","side":"N","price":null,"size":0,"channel_id":79,"order_id":"0","flags":128,"ts_in_delta":1768,"sequence":0,"symbol":"EUCO SI 20260814 PS EU P 1.2000 0"}
{"ts_recv":"2026-04-06T18:53:11.430340287Z","hd":{"ts_event":"2026-04-06T18:53:11.430338519Z","rtype":160,"publisher_id":101,"instrument_id":33497},"action":"R","side":"N","price":null,"size":0,"channel_id":79,"order_id":"0","flags":128,"ts_in_delta":1768,"sequence":0,"symbol":"EUCO SI 20260814 PS EU C 1.2000 0"}
{"ts_recv":"2026-04-06T18:53:11.430340287Z","hd":{"ts_event":"2026-04-06T18:53:11.430338519Z","rtype":160,"publisher_id":101,"instrument_id":33496},"action":"R","side":"N","price":null,"size":0,"channel_id":79,"order_id":"0","flags":128,"ts_in_delta":1768,"sequence":0,"symbol":"EUCO SI 20260814 PS EU P 1.1975 0"}
{"ts_recv":"2026-04-06T18:53:11.430340287Z","hd":{"ts_event":"2026-04-06T18:53:11.430338519Z","rtype":160,"publisher_id":101,"instrument_id":33495},"action":"R","side":"N","price":null,"size":0,"channel_id":79,"order_id":"0","flags":128,"ts_in_delta":1768,"sequence":0,"symbol":"EUCO SI 20260814 PS EU C 1.1975 0"}
{"ts_recv":"2026-04-06T18:53:11.430340287Z","hd":{"ts_event":"2026-04-06T18:53:11.430338519Z","rtype":160,"publisher_id":101,"instrument_id":33494},"action":"R","side":"N","price":null,"size":0,"channel_id":79,"order_id":"0","flags":128,"ts_in_delta":1768,"sequence":0,"symbol":"EUCO SI 20260814 PS EU P 1.1950 0"}
{"ts_recv":"2026-04-06T18:53:11.430340287Z","hd":{"ts_event":"2026-04-06T18:53:11.430338519Z","rtype":160,"publisher_id":101,"instrument_id":33493},"action":"R","side":"N","price":null,"size":0,"channel_id":79,"order_id":"0","flags":128,"ts_in_delta":1768,"sequence":0,"symbol":"EUCO SI 20260814 PS EU C 1.1950 0"}
{"ts_recv":"2026-04-06T18:53:11.430340287Z","hd":{"ts_event":"2026-04-06T18:53:11.430338519Z","rtype":160,"publisher_id":101,"instrument_id":33492},"action":"R","side":"N","price":null,"size":0,"channel_id":79,"order_id":"0","flags":128,"ts_in_delta":1768,"sequence":0,"symbol":"EUCO SI 20260814 PS EU P 1.1925 0"}
{"ts_recv":"2026-04-06T18:53:11.430340287Z","hd":{"ts_event":"2026-04-06T18:53:11.430338519Z","rtype":160,"publisher_id":101,"instrument_id":33491},"action":"R","side":"N","price":null,"size":0,"channel_id":79,"order_id":"0","flags":128,"ts_in_delta":1768,"sequence":0,"symbol":"EUCO SI 20260814 PS EU C 1.1925 0"}
{"ts_recv":"2026-04-06T18:53:11.430340287Z","hd":{"ts_event":"2026-04-06T18:53:11.430338519Z","rtype":160,"publisher_id":101,"instrument_id":33490},"action":"R","side":"N","price":null,"size":0,"channel_id":79,"order_id":"0","flags":128,"ts_in_delta":1768,"sequence":0,"symbol":"EUCO SI 20260814 PS EU P 1.1900 0"}
{"ts_recv":"2026-04-06T18:53:11.430340287Z","hd":{"ts_event":"2026-04-06T18:53:11.430338519Z","rtype":160,"publisher_id":101,"instrument_id":33489},"action":"R","side":"N","price":null,"size":0,"channel_id":79,"order_id":"0","flags":128,"ts_in_delta":1768,"sequence":0,"symbol":"EUCO SI 20260814 PS EU C 1.1900 0"}
{"ts_recv":"2026-04-06T18:53:11.430340287Z","hd":{"ts_event":"2026-04-06T18:53:11.430338519Z","rtype":160,"publisher_id":101,"instrument_id":33488},"action":"R","side":"N","price":null,"size":0,"channel_id":79,"order_id":"0","flags":128,"ts_in_delta":1768,"sequence":0,"symbol":"EUCO SI 20260814 PS EU P 1.1875 0"}
{"ts_recv":"2026-04-06T18:53:11.430340287Z","hd":{"ts_event":"2026-04-06T18:53:11.430338519Z","rtype":160,"publisher_id":101,"instrument_id":33487},"action":"R","side":"N","price":null,"size":0,"channel_id":79,"order_id":"0","flags":128,"ts_in_delta":1768,"sequence":0,"symbol":"EUCO SI 20260814 PS EU C 1.1875 0"}
{"ts_recv":"2026-04-06T18:53:11.430340287Z","hd":{"ts_event":"2026-04-06T18:53:11.430338519Z","rtype":160,"publisher_id":101,"instrument_id":33486},"action":"R","side":"N","price":null,"size":0,"channel_id":79,"order_id":"0","flags":128,"ts_in_delta":1768,"sequence":0,"symbol":"EUCO SI 20260814 PS EU P 1.1850 0"}
{"ts_recv":"2026-04-06T18:53:11.430340287Z","hd":{"ts_event":"2026-04-06T18:53:11.430338519Z","rtype":160,"publisher_id":101,"instrument_id":33485},"action":"R","side":"N","price":null,"size":0,"channel_id":79,"order_id":"0","flags":128,"ts_in_delta":1768,"sequence":0,"symbol":"EUCO SI 20260814 PS EU C 1.1850 0"}
{"ts_recv":"2026-04-06T18:53:11.430340287Z","hd":{"ts_event":"2026-04-06T18:53:11.430338519Z","rtype":160,"publisher_id":101,"instrument_id":33484},"action":"R","side":"N","price":null,"size":0,"channel_id":79,"order_id":"0","flags":128,"ts_in_delta":1768,"sequence":0,"symbol":"EUCO SI 20260814 PS EU P 1.1825 0"}
{"ts_recv":"2026-04-06T18:53:11.430340287Z","hd":{"ts_event":"2026-04-06T18:53:11.430338519Z","rtype":160,"publisher_id":101,"instrument_id":33483},"action":"R","side":"N","price":null,"size":0,"channel_id":79,"order_id":"0","flags":128,"ts_in_delta":1768,"sequence":0,"symbol":"EUCO SI 20260814 PS EU C 1.1825 0"}
{"ts_recv":"2026-04-06T18:53:11.430340287Z","hd":{"ts_event":"2026-04-06T18:53:11.430338519Z","rtype":160,"publisher_id":101,"instrument_id":33482},"action":"R","side":"N","price":null,"size":0,"channel_id":79,"order_id":"0","flags":128,"ts_in_delta":1768,"sequence":0,"symbol":"EUCO SI 20260814 PS EU P 1.1800 0"}
{"ts_recv":"2026-04-06T18:53:11.430340287Z","hd":{"ts_event":"2026-04-06T18:53:11.430338519Z","rtype":160,"publisher_id":101,"instrument_id":33481},"action":"R","side":"N","price":null,"size":0,"channel_id":79,"order_id":"0","flags":128,"ts_in_delta":1768,"sequence":0,"symbol":"EUCO SI 20260814 PS EU C 1.1800 0"}
{"ts_recv":"2026-04-06T18:53:11.430340287Z","hd":{"ts_event":"2026-04-06T18:53:11.430338519Z","rtype":160,"publisher_id":101,"instrument_id":33480},"action":"R","side":"N","price":null,"size":0,"channel_id":79,"order_id":"0","flags":128,"ts_in_delta":1768,"sequence":0,"symbol":"EUCO SI 20260814 PS EU P 1.1775 0"}
{"ts_recv":"2026-04-06T18:53:11.430340287Z","hd":{"ts_event":"2026-04-06T18:53:11.430338519Z","rtype":160,"publisher_id":101,"instrument_id":33479},"action":"R","side":"N","price":null,"size":0,"channel_id":79,"order_id":"0","flags":128,"ts_in_delta":1768,"sequence":0,"symbol":"EUCO SI 20260814 PS EU C 1.1775 0"}
{"ts_recv":"2026-04-06T18:53:11.430340287Z","hd":{"ts_event":"2026-04-06T18:53:11.430338519Z","rtype":160,"publisher_id":101,"instrument_id":33478},"action":"R","side":"N","price":null,"size":0,"channel_id":79,"order_id":"0","flags":128,"ts_in_delta":1768,"sequence":0,"symbol":"EUCO SI 20260814 PS EU P 1.1750 0"}
{"ts_recv":"2026-04-06T18:53:11.430340287Z","hd":{"ts_event":"2026-04-06T18:53:11.430338519Z","rtype":160,"publisher_id":101,"instrument_id":33477},"action":"R","side":"N","price":null,"size":0,"channel_id":79,"order_id":"0","flags":128,"ts_in_delta":1768,"sequence":0,"symbol":"EUCO SI 20260814 PS EU C 1.1750 0"}
{"ts_recv":"2026-04-06T18:53:11.430340287Z","hd":{"ts_event":"2026-04-06T18:53:11.430338519Z","rtype":160,"publisher_id":101,"instrument_id":33476},"action":"R","side":"N","price":null,"size":0,"channel_id":79,"order_id":"0","flags":128,"ts_in_delta":1768,"sequence":0,"symbol":"EUCO SI 20260814 PS EU P 1.1725 0"}
{"ts_recv":"2026-04-06T18:53:11.430340287Z","hd":{"ts_event":"2026-04-06T18:53:11.430338519Z","rtype":160,"publisher_id":101,"instrument_id":33475},"action":"R","side":"N","price":null,"size":0,"channel_id":79,"order_id":"0","flags":128,"ts_in_delta":1768,"sequence":0,"symbol":"EUCO SI 20260814 PS EU C 1.1725 0"}
{"ts_recv":"2026-04-06T18:53:11.430340287Z","hd":{"ts_event":"2026-04-06T18:53:11.430338519Z","rtype":160,"publisher_id":101,"instrument_id":33474},"action":"R","side":"N","price":null,"size":0,"channel_id":79,"order_id":"0","flags":128,"ts_in_delta":1768,"sequence":0,"symbol":"EUCO SI 20260814 PS EU P 1.1700 0"}
{"ts_recv":"2026-04-06T18:53:11.430340287Z","hd":{"ts_event":"2026-04-06T18:53:11.430338519Z","rtype":160,"publisher_id":101,"instrument_id":33473},"action":"R","side":"N","price":null,"size":0,"channel_id":79,"order_id":"0","flags":128,"ts_in_delta":1768,"sequence":0,"symbol":"EUCO SI 20260814 PS EU C 1.1700 0"}
{"ts_recv":"2026-04-06T18:53:11.430340287Z","hd":{"ts_event":"2026-04-06T18:53:11.430338519Z","rtype":160,"publisher_id":101,"instrument_id":33472},"action":"R","side":"N","price":null,"size":0,"channel_id":79,"order_id":"0","flags":128,"ts_in_delta":1768,"sequence":0,"symbol":"EUCO SI 20260814 PS EU P 1.1675 0"}
{"ts_recv":"2026-04-06T18:53:11.430340287Z","hd":{"ts_event":"2026-04-06T18:53:11.430338519Z","rtype":160,"publisher_id":101,"instrument_id":33471},"action":"R","side":"N","price":null,"size":0,"channel_id":79,"order_id":"0","flags":128,"ts_in_delta":1768,"sequence":0,"symbol":"EUCO SI 20260814 PS EU C 1.1675 0"}
{"ts_recv":"2026-04-06T18:53:11.430340287Z","hd":{"ts_event":"2026-04-06T18:53:11.430338519Z","rtype":160,"publisher_id":101,"instrument_id":33470},"action":"R","side":"N","price":null,"size":0,"channel_id":79,"order_id":"0","flags":128,"ts_in_delta":1768,"sequence":0,"symbol":"EUCO SI 20260814 PS EU P 1.1650 0"}
{"ts_recv":"2026-04-06T18:53:11.430340287Z","hd":{"ts_event":"2026-04-06T18:53:11.430338519Z","rtype":160,"publisher_id":101,"instrument_id":33469},"action":"R","side":"N","price":null,"size":0,"channel_id":79,"order_id":"0","flags":128,"ts_in_delta":1768,"sequence":0,"symbol":"EUCO SI 20260814 PS EU C 1.1650 0"}
{"ts_recv":"2026-04-06T18:53:11.430340287Z","hd":{"ts_event":"2026-04-06T18:53:11.430338519Z","rtype":160,"publisher_id":101,"instrument_id":33468},"action":"R","side":"N","price":null,"size":0,"channel_id":79,"order_id":"0","flags":128,"ts_in_delta":1768,"sequence":0,"symbol":"EUCO SI 20260814 PS EU P 1.1625 0"}
{"ts_recv":"2026-04-06T18:53:11.430340287Z","hd":{"ts_event":"2026-04-06T18:53:11.430338519Z","rtype":160,"publisher_id":101,"instrument_id":33467},"action":"R","side":"N","price":null,"size":0,"channel_id":79,"order_id":"0","flags":128,"ts_in_delta":1768,"sequence":0,"symbol":"EUCO SI 20260814 PS EU C 1.1625 0"}
{"ts_recv":"2026-04-06T18:53:11.430340287Z","hd":{"ts_event":"2026-04-06T18:53:11.430338519Z","rtype":160,"publisher_id":101,"instrument_id":33466},"action":"R","side":"N","price":null,"size":0,"channel_id":79,"order_id":"0","flags":128,"ts_in_delta":1768,"sequence":0,"symbol":"EUCO SI 20260814 PS EU P 1.1600 0"}
{"ts_recv":"2026-04-06T18:53:11.430340287Z","hd":{"ts_event":"2026-04-06T18:53:11.430338519Z","rtype":160,"publisher_id":101,"instrument_id":33465},"action":"R","side":"N","price":null,"size":0,"channel_id":79,"order_id":"0","flags":128,"ts_in_delta":1768,"sequence":0,"symbol":"EUCO SI 20260814 PS EU C 1.1600 0"}
{"ts_recv":"2026-04-06T18:53:11.430340287Z","hd":{"ts_event":"2026-04-06T18:53:11.430338519Z","rtype":160,"publisher_id":101,"instrument_id":33464},"action":"R","side":"N","price":null,"size":0,"channel_id":79,"order_id":"0","flags":128,"ts_in_delta":1768,"sequence":0,"symbol":"EUCO SI 20260814 PS EU P 1.1575 0"}
{"ts_recv":"2026-04-06T18:53:11.430340287Z","hd":{"ts_event":"2026-04-06T18:53:11.430338519Z","rtype":160,"publisher_id":101,"instrument_id":33463},"action":"R","side":"N","price":null,"size":0,"channel_id":79,"order_id":"0","flags":128,"ts_in_delta":1768,"sequence":0,"symbol":"EUCO SI 20260814 PS EU C 1.1575 0"}
{"ts_recv":"2026-04-06T18:53:11.430340287Z","hd":{"ts_event":"2026-04-06T18:53:11.430338519Z","rtype":160,"publisher_id":101,"instrument_id":33462},"action":"R","side":"N","price":null,"size":0,"channel_id":79,"order_id":"0","flags":128,"ts_in_delta":1768,"sequence":0,"symbol":"EUCO SI 20260814 PS EU P 1.1550 0"}
{"ts_recv":"2026-04-06T18:53:11.430340287Z","hd":{"ts_event":"2026-04-06T18:53:11.430338519Z","rtype":160,"publisher_id":101,"instrument_id":33461},"action":"R","side":"N","price":null,"size":0,"channel_id":79,"order_id":"0","flags":128,"ts_in_delta":1768,"sequence":0,"symbol":"EUCO SI 20260814 PS EU C 1.1550 0"}
{"ts_recv":"2026-04-06T18:53:11.430340287Z","hd":{"ts_event":"2026-04-06T18:53:11.430338519Z","rtype":160,"publisher_id":101,"instrument_id":33460},"action":"R","side":"N","price":null,"size":0,"channel_id":79,"order_id":"0","flags":128,"ts_in_delta":1768,"sequence":0,"symbol":"EUCO SI 20260814 PS EU P 1.1525 0"}
{"ts_recv":"2026-04-06T18:53:11.430340287Z","hd":{"ts_event":"2026-04-06T18:53:11.430338519Z","rtype":160,"publisher_id":101,"instrument_id":33459},"action":"R","side":"N","price":null,"size":0,"channel_id":79,"order_id":"0","flags":128,"ts_in_delta":1768,"sequence":0,"symbol":"EUCO SI 20260814 PS EU C 1.1525 0"}
{"ts_recv":"2026-04-06T18:53:11.430340287Z","hd":{"ts_event":"2026-04-06T18:53:11.430338519Z","rtype":160,"publisher_id":101,"instrument_id":33458},"action":"R","side":"N","price":null,"size":0,"channel_id":79,"order_id":"0","flags":128,"ts_in_delta":1768,"sequence":0,"symbol":"EUCO SI 20260814 PS EU P 1.1500 0"}
{"ts_recv":"2026-04-06T18:53:11.430340287Z","hd":{"ts_event":"2026-04-06T18:53:11.430338519Z","rtype":160,"publisher_id":101,"instrument_id":33457},"action":"R","side":"N","price":null,"size":0,"channel_id":79,"order_id":"0","flags":128,"ts_in_delta":1768,"sequence":0,"symbol":"EUCO SI 20260814 PS EU C 1.1500 0"}
{"ts_recv":"2026-04-06T18:53:11.430340287Z","hd":{"ts_event":"2026-04-06T18:53:11.430338519Z","rtype":160,"publisher_id":101,"instrument_id":33456},"action":"R","side":"N","price":null,"size":0,"channel_id":79,"order_id":"0","flags":128,"ts_in_delta":1768,"sequence":0,"symbol":"EUCO SI 20260814 PS EU P 1.1475 0"}
{"ts_recv":"2026-04-06T18:53:11.430340287Z","hd":{"ts_event":"2026-04-06T18:53:11.430338519Z","rtype":160,"publisher_id":101,"instrument_id":33455},"action":"R","side":"N","price":null,"size":0,"channel_id":79,"order_id":"0","flags":128,"ts_in_delta":1768,"sequence":0,"symbol":"EUCO SI 20260814 PS EU C 1.1475 0"}
{"ts_recv":"2026-04-06T18:53:11.430340287Z","hd":{"ts_event":"2026-04-06T18:53:11.430338519Z","rtype":160,"publisher_id":101,"instrument_id":33454},"action":"R","side":"N","price":null,"size":0,"channel_id":79,"order_id":"0","flags":128,"ts_in_delta":1768,"sequence":0,"symbol":"EUCO SI 20260814 PS EU P 1.1450 0"}
{"ts_recv":"2026-04-06T18:53:11.430340287Z","hd":{"ts_event":"2026-04-06T18:53:11.430338519Z","rtype":160,"publisher_id":101,"instrument_id":33453},"action":"R","side":"N","price":null,"size":0,"channel_id":79,"order_id":"0","flags":128,"ts_in_delta":1768,"sequence":0,"symbol":"EUCO SI 20260814 PS EU C 1.1450 0"}
{"ts_recv":"2026-04-06T18:53:11.430340287Z","hd":{"ts_event":"2026-04-06T18:53:11.430338519Z","rtype":160,"publisher_id":101,"instrument_id":33452},"action":"R","side":"N","price":null,"size":0,"channel_id":79,"order_id":"0","flags":128,"ts_in_delta":1768,"sequence":0,"symbol":"EUCO SI 20260814 PS EU P 1.1425 0"}
{"ts_recv":"2026-04-06T18:53:11.430340287Z","hd":{"ts_event":"2026-04-06T18:53:11.430338519Z","rtype":160,"publisher_id":101,"instrument_id":33451},"action":"R","side":"N","price":null,"size":0,"channel_id":79,"order_id":"0","flags":128,"ts_in_delta":1768,"sequence":0,"symbol":"EUCO SI 20260814 PS EU C 1.1425 0"}
{"ts_recv":"2026-04-06T18:53:11.430340287Z","hd":{"ts_event":"2026-04-06T18:53:11.430338519Z","rtype":160,"publisher_id":101,"instrument_id":33450},"action":"R","side":"N","price":null,"size":0,"channel_id":79,"order_id":"0","flags":128,"ts_in_delta":1768,"sequence":0,"symbol":"EUCO SI 20260814 PS EU P 1.1400 0"}
{"ts_recv":"2026-04-06T18:53:11.430340287Z","hd":{"ts_event":"2026-04-06T18:53:11.430338519Z","rtype":160,"publisher_id":101,"instrument_id":33449},"action":"R","side":"N","price":null,"size":0,"channel_id":79,"order_id":"0","flags":128,"ts_in_delta":1768,"sequence":0,"symbol":"EUCO SI 20260814 PS EU C 1.1400 0"}
{"ts_recv":"2026-04-06T18:53:11.430340287Z","hd":{"ts_event":"2026-04-06T18:53:11.430338519Z","rtype":160,"publisher_id":101,"instrument_id":33448},"action":"R","side":"N","price":null,"size":0,"channel_id":79,"order_id":"0","flags":128,"ts_in_delta":1768,"sequence":0,"symbol":"EUCO SI 20260814 PS EU P 1.1375 0"}
{"ts_recv":"2026-04-06T18:53:11.430340287Z","hd":{"ts_event":"2026-04-06T18:53:11.430338519Z","rtype":160,"publisher_id":101,"instrument_id":33447},"action":"R","side":"N","price":null,"size":0,"channel_id":79,"order_id":"0","flags":128,"ts_in_delta":1768,"sequence":0,"symbol":"EUCO SI 20260814 PS EU C 1.1375 0"}
{"ts_recv":"2026-04-06T18:53:11.430340287Z","hd":{"ts_event":"2026-04-06T18:53:11.430338519Z","rtype":160,"publisher_id":101,"instrument_id":33446},"action":"R","side":"N","price":null,"size":0,"channel_id":79,"order_id":"0","flags":128,"ts_in_delta":1768,"sequence":0,"symbol":"EUCO SI 20260814 PS EU P 1.1350 0"}
{"ts_recv":"2026-04-06T18:53:11.430340287Z","hd":{"ts_event":"2026-04-06T18:53:11.430338519Z","rtype":160,"publisher_id":101,"instrument_id":33445},"action":"R","side":"N","price":null,"size":0,"channel_id":79,"order_id":"0","flags":128,"ts_in_delta":1768,"sequence":0,"symbol":"EUCO SI 20260814 PS EU C 1.1350 0"}
{"ts_recv":"2026-04-06T18:53:11.430340287Z","hd":{"ts_event":"2026-04-06T18:53:11.430338519Z","rtype":160,"publisher_id":101,"instrument_id":33444},"action":"R","side":"N","price":null,"size":0,"channel_id":79,"order_id":"0","flags":128,"ts_in_delta":1768,"sequence":0,"symbol":"EUCO SI 20260814 PS EU P 1.1325 0"}
{"ts_recv":"2026-04-06T18:53:11.430340287Z","hd":{"ts_event":"2026-04-06T18:53:11.430338519Z","rtype":160,"publisher_id":101,"instrument_id":33443},"action":"R","side":"N","price":null,"size":0,"channel_id":79,"order_id":"0","flags":128,"ts_in_delta":1768,"sequence":0,"symbol":"EUCO SI 20260814 PS EU C 1.1325 0"}
{"ts_recv":"2026-04-06T18:53:11.430340287Z","hd":{"ts_event":"2026-04-06T18:53:11.430338519Z","rtype":160,"publisher_id":101,"instrument_id":33442},"action":"R","side":"N","price":null,"size":0,"channel_id":79,"order_id":"0","flags":128,"ts_in_delta":1768,"sequence":0,"symbol":"EUCO SI 20260814 PS EU P 1.1300 0"}
{"ts_recv":"2026-04-06T18:53:11.430340287Z","hd":{"ts_event":"2026-04-06T18:53:11.430338519Z","rtype":160,"publisher_id":101,"instrument_id":33441},"action":"R","side":"N","price":null,"size":0,"channel_id":79,"order_id":"0","flags":128,"ts_in_delta":1768,"sequence":0,"symbol":"EUCO SI 20260814 PS EU C 1.1300 0"}
{"ts_recv":"2026-04-06T18:53:11.430340287Z","hd":{"ts_event":"2026-04-06T18:53:11.430338519Z","rtype":160,"publisher_id":101,"instrument_id":33440},"action":"R","side":"N","price":null,"size":0,"channel_id":79,"order_id":"0","flags":128,"ts_in_delta":1768,"sequence":0,"symbol":"EUCO SI 20260814 PS EU P 1.1250 0"}
{"ts_recv":"2026-04-06T18:53:11.430340287Z","hd":{"ts_event":"2026-04-06T18:53:11.430338519Z","rtype":160,"publisher_id":101,"instrument_id":33439},"action":"R","side":"N","price":null,"size":0,"channel_id":79,"order_id":"0","flags":128,"ts_in_delta":1768,"sequence":0,"symbol":"EUCO SI 20260814 PS EU C 1.1250 0"}
{"ts_recv":"2026-04-06T18:53:11.430340287Z","hd":{"ts_event":"2026-04-06T18:53:11.430338519Z","rtype":160,"publisher_id":101,"instrument_id":33438},"action":"R","side":"N","price":null,"size":0,"channel_id":79,"order_id":"0","flags":128,"ts_in_delta":1768,"sequence":0,"symbol":"EUCO SI 20260814 PS EU P 1.1200 0"}
{"ts_recv":"2026-04-06T18:53:11.430340287Z","hd":{"ts_event":"2026-04-06T18:53:11.430338519Z","rtype":160,"publisher_id":101,"instrument_id":33437},"action":"R","side":"N","price":null,"size":0,"channel_id":79,"order_id":"0","flags":128,"ts_in_delta":1768,"sequence":0,"symbol":"EUCO SI 20260814 PS EU C 1.1200 0"}
{"ts_recv":"2026-04-06T18:53:11.430340287Z","hd":{"ts_event":"2026-04-06T18:53:11.430338519Z","rtype":160,"publisher_id":101,"instrument_id":33436},"action":"R","side":"N","price":null,"size":0,"channel_id":79,"order_id":"0","flags":128,"ts_in_delta":1768,"sequence":0,"symbol":"EUCO SI 20260814 PS EU P 1.1150 0"}
{"ts_recv":"2026-04-06T18:53:11.430340287Z","hd":{"ts_event":"2026-04-06T18:53:11.430338519Z","rtype":160,"publisher_id":101,"instrument_id":33435},"action":"R","side":"N","price":null,"size":0,"channel_id":79,"order_id":"0","flags":128,"ts_in_delta":1768,"sequence":0,"symbol":"EUCO SI 20260814 PS EU C 1.1150 0"}
{"ts_recv":"2026-04-06T18:53:11.430340287Z","hd":{"ts_event":"2026-04-06T18:53:11.430338519Z","rtype":160,"publisher_id":101,"instrument_id":33434},"action":"R","side":"N","price":null,"size":0,"channel_id":79,"order_id":"0","flags":128,"ts_in_delta":1768,"sequence":0,"symbol":"EUCO SI 20260710 PS EU P 1.2500 0"}
{"ts_recv":"2026-04-06T18:53:11.430340287Z","hd":{"ts_event":"2026-04-06T18:53:11.430338519Z","rtype":160,"publisher_id":101,"instrument_id":33433},"action":"R","side":"N","price":null,"size":0,"channel_id":79,"order_id":"0","flags":128,"ts_in_delta":1768,"sequence":0,"symbol":"EUCO SI 20260710 PS EU C 1.2500 0"}
{"ts_recv":"2026-04-06T18:53:11.430340287Z","hd":{"ts_event":"2026-04-06T18:53:11.430338519Z","rtype":160,"publisher_id":101,"instrument_id":33432},"action":"R","side":"N","price":null,"size":0,"channel_id":79,"order_id":"0","flags":128,"ts_in_delta":1768,"sequence":0,"symbol":"EUCO SI 20260710 PS EU P 1.2450 0"}
{"ts_recv":"2026-04-06T18:53:11.430340287Z","hd":{"ts_event":"2026-04-06T18:53:11.430338519Z","rtype":160,"publisher_id":101,"instrument_id":33431},"action":"R","side":"N","price":null,"size":0,"channel_id":79,"order_id":"0","flags":128,"ts_in_delta":1768,"sequence":0,"symbol":"EUCO SI 20260710 PS EU C 1.2450 0"}
{"ts_recv":"2026-04-06T18:53:11.430340287Z","hd":{"ts_event":"2026-04-06T18:53:11.430338519Z","rtype":160,"publisher_id":101,"instrument_id":33430},"action":"R","side":"N","price":null,"size":0,"channel_id":79,"order_id":"0","flags":128,"ts_in_delta":1768,"sequence":0,"symbol":"EUCO SI 20260710 PS EU P 1.2400 0"}
{"ts_recv":"2026-04-06T18:53:11.430340287Z","hd":{"ts_event":"2026-04-06T18:53:11.430338519Z","rtype":160,"publisher_id":101,"instrument_id":33429},"action":"R","side":"N","price":null,"size":0,"channel_id":79,"order_id":"0","flags":128,"ts_in_delta":1768,"sequence":0,"symbol":"EUCO SI 20260710 PS EU C 1.2400 0"}
{"ts_recv":"2026-04-06T18:53:11.430340287Z","hd":{"ts_event":"2026-04-06T18:53:11.430338519Z","rtype":160,"publisher_id":101,"instrument_id":33428},"action":"R","side":"N","price":null,"size":0,"channel_id":79,"order_id":"0","flags":128,"ts_in_delta":1768,"sequence":0,"symbol":"EUCO SI 20260710 PS EU P 1.2350 0"}
{"ts_recv":"2026-04-06T18:53:11.430340287Z","hd":{"ts_event":"2026-04-06T18:53:11.430338519Z","rtype":160,"publisher_id":101,"instrument_id":33427},"action":"R","side":"N","price":null,"size":0,"channel_id":79,"order_id":"0","flags":128,"ts_in_delta":1768,"sequence":0,"symbol":"EUCO SI 20260710 PS EU C 1.2350 0"}
{"ts_recv":"2026-04-06T18:53:11.430340287Z","hd":{"ts_event":"2026-04-06T18:53:11.430338519Z","rtype":160,"publisher_id":101,"instrument_id":33426},"action":"R","side":"N","price":null,"size":0,"channel_id":79,"order_id":"0","flags":128,"ts_in_delta":1768,"sequence":0,"symbol":"EUCO SI 20260710 PS EU P 1.2300 0"}
{"ts_recv":"2026-04-06T18:53:11.430340287Z","hd":{"ts_event":"2026-04-06T18:53:11.430338519Z","rtype":160,"publisher_id":101,"instrument_id":33425},"action":"R","side":"N","price":null,"size":0,"channel_id":79,"order_id":"0","flags":128,"ts_in_delta":1768,"sequence":0,"symbol":"EUCO SI 20260710 PS EU C 1.2300 0"}
{"ts_recv":"2026-04-06T18:53:11.430340287Z","hd":{"ts_event":"2026-04-06T18:53:11.430338519Z","rtype":160,"publisher_id":101,"instrument_id":33424},"action":"R","side":"N","price":null,"size":0,"channel_id":79,"order_id":"0","flags":128,"ts_in_delta":1768,"sequence":0,"symbol":"EUCO SI 20260710 PS EU P 1.2275 0"}
{"ts_recv":"2026-04-06T18:53:11.430340287Z","hd":{"ts_event":"2026-04-06T18:53:11.430338519Z","rtype":160,"publisher_id":101,"instrument_id":33423},"action":"R","side":"N","price":null,"size":0,"channel_id":79,"order_id":"0","flags":128,"ts_in_delta":1768,"sequence":0,"symbol":"EUCO SI 20260710 PS EU C 1.2275 0"}
{"ts_recv":"2026-04-06T18:53:11.430340287Z","hd":{"ts_event":"2026-04-06T18:53:11.430338519Z","rtype":160,"publisher_id":101,"instrument_id":33422},"action":"R","side":"N","price":null,"size":0,"channel_id":79,"order_id":"0","flags":128,"ts_in_delta":1768,"sequence":0,"symbol":"EUCO SI 20260710 PS EU P 1.2250 0"}
{"ts_recv":"2026-04-06T18:53:11.430340287Z","hd":{"ts_event":"2026-04-06T18:53:11.430338519Z","rtype":160,"publisher_id":101,"instrument_id":33421},"action":"R","side":"N","price":null,"size":0,"channel_id":79,"order_id":"0","flags":128,"ts_in_delta":1768,"sequence":0,"symbol":"EUCO SI 20260710 PS EU C 1.2250 0"}
{"ts_recv":"2026-04-06T18:53:11.430340287Z","hd":{"ts_event":"2026-04-06T18:53:11.430338519Z","rtype":160,"publisher_id":101,"instrument_id":33420},"action":"R","side":"N","price":null,"size":0,"channel_id":79,"order_id":"0","flags":128,"ts_in_delta":1768,"sequence":0,"symbol":"EUCO SI 20260710 PS EU P 1.2225 0"}
{"ts_recv":"2026-04-06T18:53:11.430340287Z","hd":{"ts_event":"2026-04-06T18:53:11.430338519Z","rtype":160,"publisher_id":101,"instrument_id":33419},"action":"R","side":"N","price":null,"size":0,"channel_id":79,"order_id":"0","flags":128,"ts_in_delta":1768,"sequence":0,"symbol":"EUCO SI 20260710 PS EU C 1.2225 0"}
{"ts_recv":"2026-04-06T18:53:11.430340287Z","hd":{"ts_event":"2026-04-06T18:53:11.430338519Z","rtype":160,"publisher_id":101,"instrument_id":33418},"action":"R","side":"N","price":null,"size":0,"channel_id":79,"order_id":"0","flags":128,"ts_in_delta":1768,"sequence":0,"symbol":"EUCO SI 20260710 PS EU P 1.2200 0"}
{"ts_recv":"2026-04-06T18:53:11.430340287Z","hd":{"ts_event":"2026-04-06T18:53:11.430338519Z","rtype":160,"publisher_id":101,"instrument_id":33417},"action":"R","side":"N","price":null,"size":0,"channel_id":79,"order_id":"0","flags":128,"ts_in_delta":1768,"sequence":0,"symbol":"EUCO SI 20260710 PS EU C 1.2200 0"}
{"ts_recv":"2026-04-06T18:53:11.430340287Z","hd":{"ts_event":"2026-04-06T18:53:11.430338519Z","rtype":160,"publisher_id":101,"instrument_id":33416},"action":"R","side":"N","price":null,"size":0,"channel_id":79,"order_id":"0","flags":128,"ts_in_delta":1768,"sequence":0,"symbol":"EUCO SI 20260710 PS EU P 1.2175 0"}
{"ts_recv":"2026-04-06T18:53:11.430340287Z","hd":{"ts_event":"2026-04-06T18:53:11.430338519Z","rtype":160,"publisher_id":101,"instrument_id":33415},"action":"R","side":"N","price":null,"size":0,"channel_id":79,"order_id":"0","flags":128,"ts_in_delta":1768,"sequence":0,"symbol":"EUCO SI 20260710 PS EU C 1.2175 0"}
{"ts_recv":"2026-04-06T18:53:11.430340287Z","hd":{"ts_event":"2026-04-06T18:53:11.430338519Z","rtype":160,"publisher_id":101,"instrument_id":33414},"action":"R","side":"N","price":null,"size":0,"channel_id":79,"order_id":"0","flags":128,"ts_in_delta":1768,"sequence":0,"symbol":"EUCO SI 20260710 PS EU P 1.2150 0"}
{"ts_recv":"2026-04-06T18:53:11.430340287Z","hd":{"ts_event":"2026-04-06T18:53:11.430338519Z","rtype":160,"publisher_id":101,"instrument_id":33413},"action":"R","side":"N","price":null,"size":0,"channel_id":79,"order_id":"0","flags":128,"ts_in_delta":1768,"sequence":0,"symbol":"EUCO SI 20260710 PS EU C 1.2150 0"}
{"ts_recv":"2026-04-06T18:53:11.430340287Z","hd":{"ts_event":"2026-04-06T18:53:11.430338519Z","rtype":160,"publisher_id":101,"instrument_id":33412},"action":"R","side":"N","price":null,"size":0,"channel_id":79,"order_id":"0","flags":128,"ts_in_delta":1768,"sequence":0,"symbol":"EUCO SI 20260710 PS EU P 1.2125 0"}
{"ts_recv":"2026-04-06T18:53:11.430340287Z","hd":{"ts_event":"2026-04-06T18:53:11.430338519Z","rtype":160,"publisher_id":101,"instrument_id":33411},"action":"R","side":"N","price":null,"size":0,"channel_id":79,"order_id":"0","flags":128,"ts_in_delta":1768,"sequence":0,"symbol":"EUCO SI 20260710 PS EU C 1.2125 0"}
{"ts_recv":"2026-04-06T18:53:11.430340287Z","hd":{"ts_event":"2026-04-06T18:53:11.430338519Z","rtype":160,"publisher_id":101,"instrument_id":33410},"action":"R","side":"N","price":null,"size":0,"channel_id":79,"order_id":"0","flags":128,"ts_in_delta":1768,"sequence":0,"symbol":"EUCO SI 20260710 PS EU P 1.2100 0"}
{"ts_recv":"2026-04-06T18:53:11.430340287Z","hd":{"ts_event":"2026-04-06T18:53:11.430338519Z","rtype":160,"publisher_id":101,"instrument_id":33409},"action":"R","side":"N","price":null,"size":0,"channel_id":79,"order_id":"0","flags":128,"ts_in_delta":1768,"sequence":0,"symbol":"EUCO SI 20260710 PS EU C 1.2100 0"}
{"ts_recv":"2026-04-06T18:53:11.430340287Z","hd":{"ts_event":"2026-04-06T18:53:11.430338519Z","rtype":160,"publisher_id":101,"instrument_id":33408},"action":"R","side":"N","price":null,"size":0,"channel_id":79,"order_id":"0","flags":128,"ts_in_delta":1768,"sequence":0,"symbol":"EUCO SI 20260710 PS EU P 1.2075 0"}
{"ts_recv":"2026-04-06T18:53:11.430340287Z","hd":{"ts_event":"2026-04-06T18:53:11.430338519Z","rtype":160,"publisher_id":101,"instrument_id":33407},"action":"R","side":"N","price":null,"size":0,"channel_id":79,"order_id":"0","flags":128,"ts_in_delta":1768,"sequence":0,"symbol":"EUCO SI 20260710 PS EU C 1.2075 0"}
{"ts_recv":"2026-04-06T18:53:11.430340287Z","hd":{"ts_event":"2026-04-06T18:53:11.430338519Z","rtype":160,"publisher_id":101,"instrument_id":33406},"action":"R","side":"N","price":null,"size":0,"channel_id":79,"order_id":"0","flags":128,"ts_in_delta":1768,"sequence":0,"symbol":"EUCO SI 20260710 PS EU P 1.2050 0"}
{"ts_recv":"2026-04-06T18:53:11.430340287Z","hd":{"ts_event":"2026-04-06T18:53:11.430338519Z","rtype":160,"publisher_id":101,"instrument_id":33405},"action":"R","side":"N","price":null,"size":0,"channel_id":79,"order_id":"0","flags":128,"ts_in_delta":1768,"sequence":0,"symbol":"EUCO SI 20260710 PS EU C 1.2050 0"}
{"ts_recv":"2026-04-06T18:53:11.430340287Z","hd":{"ts_event":"2026-04-06T18:53:11.430338519Z","rtype":160,"publisher_id":101,"instrument_id":33404},"action":"R","side":"N","price":null,"size":0,"channel_id":79,"order_id":"0","flags":128,"ts_in_delta":1768,"sequence":0,"symbol":"EUCO SI 20260710 PS EU P 1.2025 0"}
{"ts_recv":"2026-04-06T18:53:11.430340287Z","hd":{"ts_event":"2026-04-06T18:53:11.430338519Z","rtype":160,"publisher_id":101,"instrument_id":33403},"action":"R","side":"N","price":null,"size":0,"channel_id":79,"order_id":"0","flags":128,"ts_in_delta":1768,"sequence":0,"symbol":"EUCO SI 20260710 PS EU C 1.2025 0"}
{"ts_recv":"2026-04-06T18:53:11.430340287Z","hd":{"ts_event":"2026-04-06T18:53:11.430338519Z","rtype":160,"publisher_id":101,"instrument_id":33402},"action":"R","side":"N","price":null,"size":0,"channel_id":79,"order_id":"0","flags":128,"ts_in_delta":1768,"sequence":0,"symbol":"EUCO SI 20260710 PS EU P 1.2000 0"}
{"ts_recv":"2026-04-06T18:53:11.430340287Z","hd":{"ts_event":"2026-04-06T18:53:11.430338519Z","rtype":160,"publisher_id":101,"instrument_id":33401},"action":"R","side":"N","price":null,"size":0,"channel_id":79,"order_id":"0","flags":128,"ts_in_delta":1768,"sequence":0,"symbol":"EUCO SI 20260710 PS EU C 1.2000 0"}
{"ts_recv":"2026-04-06T18:53:11.430340287Z","hd":{"ts_event":"2026-04-06T18:53:11.430338519Z","rtype":160,"publisher_id":101,"instrument_id":33400},"action":"R","side":"N","price":null,"size":0,"channel_id":79,"order_id":"0","flags":128,"ts_in_delta":1768,"sequence":0,"symbol":"EUCO SI 20260710 PS EU P 1.1975 0"}
{"ts_recv":"2026-04-06T18:53:11.430340287Z","hd":{"ts_event":"2026-04-06T18:53:11.430338519Z","rtype":160,"publisher_id":101,"instrument_id":33399},"action":"R","side":"N","price":null,"size":0,"channel_id":79,"order_id":"0","flags":128,"ts_in_delta":1768,"sequence":0,"symbol":"EUCO SI 20260710 PS EU C 1.1975 0"}
{"ts_recv":"2026-04-06T18:53:11.430340287Z","hd":{"ts_event":"2026-04-06T18:53:11.430338519Z","rtype":160,"publisher_id":101,"instrument_id":33398},"action":"R","side":"N","price":null,"size":0,"channel_id":79,"order_id":"0","flags":128,"ts_in_delta":1768,"sequence":0,"symbol":"EUCO SI 20260710 PS EU P 1.1950 0"}
{"ts_recv":"2026-04-06T18:53:11.430340287Z","hd":{"ts_event":"2026-04-06T18:53:11.430338519Z","rtype":160,"publisher_id":101,"instrument_id":33397},"action":"R","side":"N","price":null,"size":0,"channel_id":79,"order_id":"0","flags":128,"ts_in_delta":1768,"sequence":0,"symbol":"EUCO SI 20260710 PS EU C 1.1950 0"}
{"ts_recv":"2026-04-06T18:53:11.430340287Z","hd":{"ts_event":"2026-04-06T18:53:11.430338519Z","rtype":160,"publisher_id":101,"instrument_id":33396},"action":"R","side":"N","price":null,"size":0,"channel_id":79,"order_id":"0","flags":128,"ts_in_delta":1768,"sequence":0,"symbol":"EUCO SI 20260710 PS EU P 1.1925 0"}
{"ts_recv":"2026-04-06T18:53:11.430340287Z","hd":{"ts_event":"2026-04-06T18:53:11.430338519Z","rtype":160,"publisher_id":101,"instrument_id":33395},"action":"R","side":"N","price":null,"size":0,"channel_id":79,"order_id":"0","flags":128,"ts_in_delta":1768,"sequence":0,"symbol":"EUCO SI 20260710 PS EU C 1.1925 0"}
{"ts_recv":"2026-04-06T18:53:11.430340287Z","hd":{"ts_event":"2026-04-06T18:53:11.430338519Z","rtype":160,"publisher_id":101,"instrument_id":33394},"action":"R","side":"N","price":null,"size":0,"channel_id":79,"order_id":"0","flags":128,"ts_in_delta":1768,"sequence":0,"symbol":"EUCO SI 20260710 PS EU P 1.1900 0"}
{"ts_recv":"2026-04-06T18:53:11.430340287Z","hd":{"ts_event":"2026-04-06T18:53:11.430338519Z","rtype":160,"publisher_id":101,"instrument_id":33393},"action":"R","side":"N","price":null,"size":0,"channel_id":79,"order_id":"0","flags":128,"ts_in_delta":1768,"sequence":0,"symbol":"EUCO SI 20260710 PS EU C 1.1900 0"}
{"ts_recv":"2026-04-06T18:53:11.430340287Z","hd":{"ts_event":"2026-04-06T18:53:11.430338519Z","rtype":160,"publisher_id":101,"instrument_id":33392},"action":"R","side":"N","price":null,"size":0,"channel_id":79,"order_id":"0","flags":128,"ts_in_delta":1768,"sequence":0,"symbol":"EUCO SI 20260710 PS EU P 1.1875 0"}
{"ts_recv":"2026-04-06T18:53:11.430340287Z","hd":{"ts_event":"2026-04-06T18:53:11.430338519Z","rtype":160,"publisher_id":101,"instrument_id":33391},"action":"R","side":"N","price":null,"size":0,"channel_id":79,"order_id":"0","flags":128,"ts_in_delta":1768,"sequence":0,"symbol":"EUCO SI 20260710 PS EU C 1.1875 0"}
{"ts_recv":"2026-04-06T18:53:11.430340287Z","hd":{"ts_event":"2026-04-06T18:53:11.430338519Z","rtype":160,"publisher_id":101,"instrument_id":33390},"action":"R","side":"N","price":null,"size":0,"channel_id":79,"order_id":"0","flags":128,"ts_in_delta":1768,"sequence":0,"symbol":"EUCO SI 20260710 PS EU P 1.1850 0"}
{"ts_recv":"2026-04-06T18:53:11.430340287Z","hd":{"ts_event":"2026-04-06T18:53:11.430338519Z","rtype":160,"publisher_id":101,"instrument_id":33389},"action":"R","side":"N","price":null,"size":0,"channel_id":79,"order_id":"0","flags":128,"ts_in_delta":1768,"sequence":0,"symbol":"EUCO SI 20260710 PS EU C 1.1850 0"}
{"ts_recv":"2026-04-06T18:53:11.430340287Z","hd":{"ts_event":"2026-04-06T18:53:11.430338519Z","rtype":160,"publisher_id":101,"instrument_id":33388},"action":"R","side":"N","price":null,"size":0,"channel_id":79,"order_id":"0","flags":128,"ts_in_delta":1768,"sequence":0,"symbol":"EUCO SI 20260710 PS EU P 1.1825 0"}
{"ts_recv":"2026-04-06T18:53:11.430340287Z","hd":{"ts_event":"2026-04-06T18:53:11.430338519Z","rtype":160,"publisher_id":101,"instrument_id":33387},"action":"R","side":"N","price":null,"size":0,"channel_id":79,"order_id":"0","flags":128,"ts_in_delta":1768,"sequence":0,"symbol":"EUCO SI 20260710 PS EU C 1.1825 0"}
{"ts_recv":"2026-04-06T18:53:11.430340287Z","hd":{"ts_event":"2026-04-06T18:53:11.430338519Z","rtype":160,"publisher_id":101,"instrument_id":33386},"action":"R","side":"N","price":null,"size":0,"channel_id":79,"order_id":"0","flags":128,"ts_in_delta":1768,"sequence":0,"symbol":"EUCO SI 20260710 PS EU P 1.1800 0"}
{"ts_recv":"2026-04-06T18:53:11.430340287Z","hd":{"ts_event":"2026-04-06T18:53:11.430338519Z","rtype":160,"publisher_id":101,"instrument_id":33385},"action":"R","side":"N","price":null,"size":0,"channel_id":79,"order_id":"0","flags":128,"ts_in_delta":1768,"sequence":0,"symbol":"EUCO SI 20260710 PS EU C 1.1800 0"}
{"ts_recv":"2026-04-06T18:53:11.430340287Z","hd":{"ts_event":"2026-04-06T18:53:11.430338519Z","rtype":160,"publisher_id":101,"instrument_id":33384},"action":"R","side":"N","price":null,"size":0,"channel_id":79,"order_id":"0","flags":128,"ts_in_delta":1768,"sequence":0,"symbol":"EUCO SI 20260710 PS EU P 1.1775 0"}
{"ts_recv":"2026-04-06T18:53:11.430340287Z","hd":{"ts_event":"2026-04-06T18:53:11.430338519Z","rtype":160,"publisher_id":101,"instrument_id":33383},"action":"R","side":"N","price":null,"size":0,"channel_id":79,"order_id":"0","flags":128,"ts_in_delta":1768,"sequence":0,"symbol":"EUCO SI 20260710 PS EU C 1.1775 0"}
{"ts_recv":"2026-04-06T18:53:11.430340287Z","hd":{"ts_event":"2026-04-06T18:53:11.430338519Z","rtype":160,"publisher_id":101,"instrument_id":33382},"action":"R","side":"N","price":null,"size":0,"channel_id":79,"order_id":"0","flags":128,"ts_in_delta":1768,"sequence":0,"symbol":"EUCO SI 20260710 PS EU P 1.1750 0"}
{"ts_recv":"2026-04-06T18:53:11.430340287Z","hd":{"ts_event":"2026-04-06T18:53:11.430338519Z","rtype":160,"publisher_id":101,"instrument_id":33381},"action":"R","side":"N","price":null,"size":0,"channel_id":79,"order_id":"0","flags":128,"ts_in_delta":1768,"sequence":0,"symbol":"EUCO SI 20260710 PS EU C 1.1750 0"}
{"ts_recv":"2026-04-06T18:53:11.430340287Z","hd":{"ts_event":"2026-04-06T18:53:11.430338519Z","rtype":160,"publisher_id":101,"instrument_id":33380},"action":"R","side":"N","price":null,"size":0,"channel_id":79,"order_id":"0","flags":128,"ts_in_delta":1768,"sequence":0,"symbol":"EUCO SI 20260710 PS EU P 1.1725 0"}
{"ts_recv":"2026-04-06T18:53:11.430340287Z","hd":{"ts_event":"2026-04-06T18:53:11.430338519Z","rtype":160,"publisher_id":101,"instrument_id":33379},"action":"R","side":"N","price":null,"size":0,"channel_id":79,"order_id":"0","flags":128,"ts_in_delta":1768,"sequence":0,"symbol":"EUCO SI 20260710 PS EU C 1.1725 0"}
{"ts_recv":"2026-04-06T18:53:11.430340287Z","hd":{"ts_event":"2026-04-06T18:53:11.430338519Z","rtype":160,"publisher_id":101,"instrument_id":33378},"action":"R","side":"N","price":null,"size":0,"channel_id":79,"order_id":"0","flags":128,"ts_in_delta":1768,"sequence":0,"symbol":"EUCO SI 20260710 PS EU P 1.1700 0"}
{"ts_recv":"2026-04-06T18:53:11.430340287Z","hd":{"ts_event":"2026-04-06T18:53:11.430338519Z","rtype":160,"publisher_id":101,"instrument_id":33377},"action":"R","side":"N","price":null,"size":0,"channel_id":79,"order_id":"0","flags":128,"ts_in_delta":1768,"sequence":0,"symbol":"EUCO SI 20260710 PS EU C 1.1700 0"}
{"ts_recv":"2026-04-06T18:53:11.430340287Z","hd":{"ts_event":"2026-04-06T18:53:11.430338519Z","rtype":160,"publisher_id":101,"instrument_id":33376},"action":"R","side":"N","price":null,"size":0,"channel_id":79,"order_id":"0","flags":128,"ts_in_delta":1768,"sequence":0,"symbol":"EUCO SI 20260710 PS EU P 1.1675 0"}
{"ts_recv":"2026-04-06T18:53:11.430340287Z","hd":{"ts_event":"2026-04-06T18:53:11.430338519Z","rtype":160,"publisher_id":101,"instrument_id":33375},"action":"R","side":"N","price":null,"size":0,"channel_id":79,"order_id":"0","flags":128,"ts_in_delta":1768,"sequence":0,"symbol":"EUCO SI 20260710 PS EU C 1.1675 0"}
{"ts_recv":"2026-04-06T18:53:11.430340287Z","hd":{"ts_event":"2026-04-06T18:53:11.430338519Z","rtype":160,"publisher_id":101,"instrument_id":33374},"action":"R","side":"N","price":null,"size":0,"channel_id":79,"order_id":"0","flags":128,"ts_in_delta":1768,"sequence":0,"symbol":"EUCO SI 20260710 PS EU P 1.1650 0"}
{"ts_recv":"2026-04-06T18:53:11.430340287Z","hd":{"ts_event":"2026-04-06T18:53:11.430338519Z","rtype":160,"publisher_id":101,"instrument_id":33373},"action":"R","side":"N","price":null,"size":0,"channel_id":79,"order_id":"0","flags":128,"ts_in_delta":1768,"sequence":0,"symbol":"EUCO SI 20260710 PS EU C 1.1650 0"}
{"ts_recv":"2026-04-06T18:53:11.430340287Z","hd":{"ts_event":"2026-04-06T18:53:11.430338519Z","rtype":160,"publisher_id":101,"instrument_id":33372},"action":"R","side":"N","price":null,"size":0,"channel_id":79,"order_id":"0","flags":128,"ts_in_delta":1768,"sequence":0,"symbol":"EUCO SI 20260710 PS EU P 1.1625 0"}
{"ts_recv":"2026-04-06T18:53:11.430340287Z","hd":{"ts_event":"2026-04-06T18:53:11.430338519Z","rtype":160,"publisher_id":101,"instrument_id":33371},"action":"R","side":"N","price":null,"size":0,"channel_id":79,"order_id":"0","flags":128,"ts_in_delta":1768,"sequence":0,"symbol":"EUCO SI 20260710 PS EU C 1.1625 0"}
{"ts_recv":"2026-04-06T18:53:11.430340287Z","hd":{"ts_event":"2026-04-06T18:53:11.430338519Z","rtype":160,"publisher_id":101,"instrument_id":33370},"action":"R","side":"N","price":null,"size":0,"channel_id":79,"order_id":"0","flags":128,"ts_in_delta":1768,"sequence":0,"symbol":"EUCO SI 20260710 PS EU P 1.1600 0"}
{"ts_recv":"2026-04-06T18:53:11.430340287Z","hd":{"ts_event":"2026-04-06T18:53:11.430338519Z","rtype":160,"publisher_id":101,"instrument_id":33369},"action":"R","side":"N","price":null,"size":0,"channel_id":79,"order_id":"0","flags":128,"ts_in_delta":1768,"sequence":0,"symbol":"EUCO SI 20260710 PS EU C 1.1600 0"}
{"ts_recv":"2026-04-06T18:53:11.430340287Z","hd":{"ts_event":"2026-04-06T18:53:11.430338519Z","rtype":160,"publisher_id":101,"instrument_id":33368},"action":"R","side":"N","price":null,"size":0,"channel_id":79,"order_id":"0","flags":128,"ts_in_delta":1768,"sequence":0,"symbol":"EUCO SI 20260710 PS EU P 1.1575 0"}
{"ts_recv":"2026-04-06T18:53:11.430340287Z","hd":{"ts_event":"2026-04-06T18:53:11.430338519Z","rtype":160,"publisher_id":101,"instrument_id":33367},"action":"R","side":"N","price":null,"size":0,"channel_id":79,"order_id":"0","flags":128,"ts_in_delta":1768,"sequence":0,"symbol":"EUCO SI 20260710 PS EU C 1.1575 0"}
{"ts_recv":"2026-04-06T18:53:11.430340287Z","hd":{"ts_event":"2026-04-06T18:53:11.430338519Z","rtype":160,"publisher_id":101,"instrument_id":33366},"action":"R","side":"N","price":null,"size":0,"channel_id":79,"order_id":"0","flags":128,"ts_in_delta":1768,"sequence":0,"symbol":"EUCO SI 20260710 PS EU P 1.1550 0"}
{"ts_recv":"2026-04-06T18:53:11.430340287Z","hd":{"ts_event":"2026-04-06T18:53:11.430338519Z","rtype":160,"publisher_id":101,"instrument_id":33365},"action":"R","side":"N","price":null,"size":0,"channel_id":79,"order_id":"0","flags":128,"ts_in_delta":1768,"sequence":0,"symbol":"EUCO SI 20260710 PS EU C 1.1550 0"}
{"ts_recv":"2026-04-06T18:53:11.430340287Z","hd":{"ts_event":"2026-04-06T18:53:11.430338519Z","rtype":160,"publisher_id":101,"instrument_id":33364},"action":"R","side":"N","price":null,"size":0,"channel_id":79,"order_id":"0","flags":128,"ts_in_delta":1768,"sequence":0,"symbol":"EUCO SI 20260710 PS EU P 1.1525 0"}
{"ts_recv":"2026-04-06T18:53:11.430340287Z","hd":{"ts_event":"2026-04-06T18:53:11.430338519Z","rtype":160,"publisher_id":101,"instrument_id":33363},"action":"R","side":"N","price":null,"size":0,"channel_id":79,"order_id":"0","flags":128,"ts_in_delta":1768,"sequence":0,"symbol":"EUCO SI 20260710 PS EU C 1.1525 0"}
{"ts_recv":"2026-04-06T18:53:11.430340287Z","hd":{"ts_event":"2026-04-06T18:53:11.430338519Z","rtype":160,"publisher_id":101,"instrument_id":33362},"action":"R","side":"N","price":null,"size":0,"channel_id":79,"order_id":"0","flags":128,"ts_in_delta":1768,"sequence":0,"symbol":"EUCO SI 20260710 PS EU P 1.1500 0"}
{"ts_recv":"2026-04-06T18:53:11.430340287Z","hd":{"ts_event":"2026-04-06T18:53:11.430338519Z","rtype":160,"publisher_id":101,"instrument_id":33361},"action":"R","side":"N","price":null,"size":0,"channel_id":79,"order_id":"0","flags":128,"ts_in_delta":1768,"sequence":0,"symbol":"EUCO SI 20260710 PS EU C 1.1500 0"}
{"ts_recv":"2026-04-06T18:53:11.430340287Z","hd":{"ts_event":"2026-04-06T18:53:11.430338519Z","rtype":160,"publisher_id":101,"instrument_id":33360},"action":"R","side":"N","price":null,"size":0,"channel_id":79,"order_id":"0","flags":128,"ts_in_delta":1768,"sequence":0,"symbol":"EUCO SI 20260710 PS EU P 1.1475 0"}
{"ts_recv":"2026-04-06T18:53:11.430340287Z","hd":{"ts_event":"2026-04-06T18:53:11.430338519Z","rtype":160,"publisher_id":101,"instrument_id":33359},"action":"R","side":"N","price":null,"size":0,"channel_id":79,"order_id":"0","flags":128,"ts_in_delta":1768,"sequence":0,"symbol":"EUCO SI 20260710 PS EU C 1.1475 0"}
{"ts_recv":"2026-04-06T18:53:11.430340287Z","hd":{"ts_event":"2026-04-06T18:53:11.430338519Z","rtype":160,"publisher_id":101,"instrument_id":33358},"action":"R","side":"N","price":null,"size":0,"channel_id":79,"order_id":"0","flags":128,"ts_in_delta":1768,"sequence":0,"symbol":"EUCO SI 20260710 PS EU P 1.1450 0"}
{"ts_recv":"2026-04-06T18:53:11.430340287Z","hd":{"ts_event":"2026-04-06T18:53:11.430338519Z","rtype":160,"publisher_id":101,"instrument_id":33357},"action":"R","side":"N","price":null,"size":0,"channel_id":79,"order_id":"0","flags":128,"ts_in_delta":1768,"sequence":0,"symbol":"EUCO SI 20260710 PS EU C 1.1450 0"}
{"ts_recv":"2026-04-06T18:53:11.430340287Z","hd":{"ts_event":"2026-04-06T18:53:11.430338519Z","rtype":160,"publisher_id":101,"instrument_id":33356},"action":"R","side":"N","price":null,"size":0,"channel_id":79,"order_id":"0","flags":128,"ts_in_delta":1768,"sequence":0,"symbol":"EUCO SI 20260710 PS EU P 1.1425 0"}
{"ts_recv":"2026-04-06T18:53:11.430340287Z","hd":{"ts_event":"2026-04-06T18:53:11.430338519Z","rtype":160,"publisher_id":101,"instrument_id":33355},"action":"R","side":"N","price":null,"size":0,"channel_id":79,"order_id":"0","flags":128,"ts_in_delta":1768,"sequence":0,"symbol":"EUCO SI 20260710 PS EU C 1.1425 0"}
{"ts_recv":"2026-04-06T18:53:11.430340287Z","hd":{"ts_event":"2026-04-06T18:53:11.430338519Z","rtype":160,"publisher_id":101,"instrument_id":33354},"action":"R","side":"N","price":null,"size":0,"channel_id":79,"order_id":"0","flags":128,"ts_in_delta":1768,"sequence":0,"symbol":"EUCO SI 20260710 PS EU P 1.1400 0"}
{"ts_recv":"2026-04-06T18:53:11.430340287Z","hd":{"ts_event":"2026-04-06T18:53:11.430338519Z","rtype":160,"publisher_id":101,"instrument_id":33353},"action":"R","side":"N","price":null,"size":0,"channel_id":79,"order_id":"0","flags":128,"ts_in_delta":1768,"sequence":0,"symbol":"EUCO SI 20260710 PS EU C 1.1400 0"}
{"ts_recv":"2026-04-06T18:53:11.430340287Z","hd":{"ts_event":"2026-04-06T18:53:11.430338519Z","rtype":160,"publisher_id":101,"instrument_id":33352},"action":"R","side":"N","price":null,"size":0,"channel_id":79,"order_id":"0","flags":128,"ts_in_delta":1768,"sequence":0,"symbol":"EUCO SI 20260710 PS EU P 1.1375 0"}
{"ts_recv":"2026-04-06T18:53:11.430340287Z","hd":{"ts_event":"2026-04-06T18:53:11.430338519Z","rtype":160,"publisher_id":101,"instrument_id":33351},"action":"R","side":"N","price":null,"size":0,"channel_id":79,"order_id":"0","flags":128,"ts_in_delta":1768,"sequence":0,"symbol":"EUCO SI 20260710 PS EU C 1.1375 0"}
{"ts_recv":"2026-04-06T18:53:11.430340287Z","hd":{"ts_event":"2026-04-06T18:53:11.430338519Z","rtype":160,"publisher_id":101,"instrument_id":33350},"action":"R","side":"N","price":null,"size":0,"channel_id":79,"order_id":"0","flags":128,"ts_in_delta":1768,"sequence":0,"symbol":"EUCO SI 20260710 PS EU P 1.1350 0"}
{"ts_recv":"2026-04-06T18:53:11.430340287Z","hd":{"ts_event":"2026-04-06T18:53:11.430338519Z","rtype":160,"publisher_id":101,"instrument_id":33349},"action":"R","side":"N","price":null,"size":0,"channel_id":79,"order_id":"0","flags":128,"ts_in_delta":1768,"sequence":0,"symbol":"EUCO SI 20260710 PS EU C 1.1350 0"}
{"ts_recv":"2026-04-06T18:53:11.430340287Z","hd":{"ts_event":"2026-04-06T18:53:11.430338519Z","rtype":160,"publisher_id":101,"instrument_id":33348},"action":"R","side":"N","price":null,"size":0,"channel_id":79,"order_id":"0","flags":128,"ts_in_delta":1768,"sequence":0,"symbol":"EUCO SI 20260710 PS EU P 1.1325 0"}
{"ts_recv":"2026-04-06T18:53:11.430340287Z","hd":{"ts_event":"2026-04-06T18:53:11.430338519Z","rtype":160,"publisher_id":101,"instrument_id":33347},"action":"R","side":"N","price":null,"size":0,"channel_id":79,"order_id":"0","flags":128,"ts_in_delta":1768,"sequence":0,"symbol":"EUCO SI 20260710 PS EU C 1.1325 0"}
{"ts_recv":"2026-04-06T18:53:11.430340287Z","hd":{"ts_event":"2026-04-06T18:53:11.430338519Z","rtype":160,"publisher_id":101,"instrument_id":33346},"action":"R","side":"N","price":null,"size":0,"channel_id":79,"order_id":"0","flags":128,"ts_in_delta":1768,"sequence":0,"symbol":"EUCO SI 20260710 PS EU P 1.1300 0"}
{"ts_recv":"2026-04-06T18:53:11.430340287Z","hd":{"ts_event":"2026-04-06T18:53:11.430338519Z","rtype":160,"publisher_id":101,"instrument_id":33345},"action":"R","side":"N","price":null,"size":0,"channel_id":79,"order_id":"0","flags":128,"ts_in_delta":1768,"sequence":0,"symbol":"EUCO SI 20260710 PS EU C 1.1300 0"}
{"ts_recv":"2026-04-06T18:53:11.430340287Z","hd":{"ts_event":"2026-04-06T18:53:11.430338519Z","rtype":160,"publisher_id":101,"instrument_id":33344},"action":"R","side":"N","price":null,"size":0,"channel_id":79,"order_id":"0","flags":128,"ts_in_delta":1768,"sequence":0,"symbol":"EUCO SI 20260710 PS EU P 1.1275 0"}
{"ts_recv":"2026-04-06T18:53:11.430340287Z","hd":{"ts_event":"2026-04-06T18:53:11.430338519Z","rtype":160,"publisher_id":101,"instrument_id":33343},"action":"R","side":"N","price":null,"size":0,"channel_id":79,"order_id":"0","flags":128,"ts_in_delta":1768,"sequence":0,"symbol":"EUCO SI 20260710 PS EU C 1.1275 0"}
{"ts_recv":"2026-04-06T18:53:11.430340287Z","hd":{"ts_event":"2026-04-06T18:53:11.430338519Z","rtype":160,"publisher_id":101,"instrument_id":33342},"action":"R","side":"N","price":null,"size":0,"channel_id":79,"order_id":"0","flags":128,"ts_in_delta":1768,"sequence":0,"symbol":"EUCO SI 20260710 PS EU P 1.1250 0"}
{"ts_recv":"2026-04-06T18:53:11.430340287Z","hd":{"ts_event":"2026-04-06T18:53:11.430338519Z","rtype":160,"publisher_id":101,"instrument_id":33341},"action":"R","side":"N","price":null,"size":0,"channel_id":79,"order_id":"0","flags":128,"ts_in_delta":1768,"sequence":0,"symbol":"EUCO SI 20260710 PS EU C 1.1250 0"}
