{"ts_recv":"2026-03-19T08:01:07.844160662Z","hd":{"ts_event":"2026-03-19T08:01:07.843837153Z","rtype":160,"publisher_id":101,"instrument_id":34549},"action":"R","side":"N","price":null,"size":0,"channel_id":79,"order_id":"0","flags":8,"ts_in_delta":0,"sequence":0,"symbol":"EUCO SI 20260814 PS EU P 1.1600 0"}
{"ts_recv":"2026-03-19T08:01:07.844160662Z","hd":{"ts_event":"2026-03-19T08:01:07.843837153Z","rtype":160,"publisher_id":101,"instrument_id":34549},"action":"A","side":"B","price":"0.024750000","size":20,"channel_id":79,"order_id":"10997279304698641024","flags":0,"ts_in_delta":2393,"sequence":45571,"symbol":"EUCO SI 20260814 PS EU P 1.1600 0"}
{"ts_recv":"2026-03-19T08:01:07.844160662Z","hd":{"ts_event":"2026-03-19T08:01:07.843837153Z","rtype":160,"publisher_id":101,"instrument_id":34549},"action":"A","side":"A","price":"0.025170000","size":20,"channel_id":79,"order_id":"1773907267843865216","flags":128,"ts_in_delta":2393,"sequence":45571,"symbol":"EUCO SI 20260814 PS EU P 1.1600 0"}
{"ts_recv":"2026-03-19T08:01:07.844160662Z","hd":{"ts_event":"2026-03-19T08:01:07.843837153Z","rtype":160,"publisher_id":101,"instrument_id":34548},"action":"R","side":"N","price":null,"size":0,"channel_id":79,"order_id":"0","flags":8,"ts_in_delta":0,"sequence":0,"symbol":"EUCO SI 20260814 PS EU C 1.1600 0"}
{"ts_recv":"2026-03-19T08:01:07.844160662Z","hd":{"ts_event":"2026-03-19T08:01:07.843837153Z","rtype":160,"publisher_id":101,"instrument_id":34548},"action":"A","side":"B","price":"0.017970000","size":20,"channel_id":79,"order_id":"10997279304698641024","flags":0,"ts_in_delta":2393,"sequence":45571,"symbol":"EUCO SI 20260814 PS EU C 1.1600 0"}
{"ts_recv":"2026-03-19T08:01:07.844160662Z","hd":{"ts_event":"2026-03-19T08:01:07.843837153Z","rtype":160,"publisher_id":101,"instrument_id":34538},"action":"R","side":"N","price":null,"size":0,"channel_id":79,"order_id":"0","flags":8,"ts_in_delta":0,"sequence":0,"symbol":"EUCO SI 20260814 PS EU C 1.1475 0"}
{"ts_recv":"2026-03-19T08:01:07.844160662Z","hd":{"ts_event":"2026-03-19T08:01:07.843837153Z","rtype":160,"publisher_id":101,"instrument_id":34538},"action":"A","side":"B","price":"0.024210000","size":20,"channel_id":79,"order_id":"10997279304698641024","flags":0,"ts_in_delta":2393,"sequence":45571,"symbol":"EUCO SI 20260814 PS EU C 1.1475 0"}
{"ts_recv":"2026-03-19T08:01:07.844160662Z","hd":{"ts_event":"2026-03-19T08:01:07.843837153Z","rtype":160,"publisher_id":101,"instrument_id":34538},"action":"A","side":"A","price":"0.024640000","size":20,"channel_id":79,"order_id":"1773907267843865216","flags":128,"ts_in_delta":2393,"sequence":45571,"symbol":"EUCO SI 20260814 PS EU C 1.1475 0"}
{"ts_recv":"2026-03-19T08:01:07.844160662Z","hd":{"ts_event":"2026-03-19T08:01:07.843837153Z","rtype":160,"publisher_id":101,"instrument_id":34642},"action":"R","side":"N","price":null,"size":0,"channel_id":79,"order_id":"0","flags":8,"ts_in_delta":0,"sequence":0,"symbol":"EUCO SI 20260911 PS EU C 1.1550 0"}
{"ts_recv":"2026-03-19T08:01:07.844160662Z","hd":{"ts_event":"2026-03-19T08:01:07.843837153Z","rtype":160,"publisher_id":101,"instrument_id":34642},"action":"A","side":"B","price":"0.022730000","size":20,"channel_id":79,"order_id":"10997279304698641024","flags":0,"ts_in_delta":2393,"sequence":45571,"symbol":"EUCO SI 20260911 PS EU C 1.1550 0"}
{"ts_recv":"2026-03-19T08:01:07.844160662Z","hd":{"ts_event":"2026-03-19T08:01:07.843837153Z","rtype":160,"publisher_id":101,"instrument_id":34642},"action":"A","side":"A","price":"0.023150000","size":20,"channel_id":79,"order_id":"1773907267843865216","flags":128,"ts_in_delta":2393,"sequence":45571,"symbol":"EUCO SI 20260911 PS EU C 1.1550 0"}
{"ts_recv":"2026-03-19T08:01:07.844160662Z","hd":{"ts_event":"2026-03-19T08:01:07.843837153Z","rtype":160,"publisher_id":101,"instrument_id":34644},"action":"R","side":"N","price":null,"size":0,"channel_id":79,"order_id":"0","flags":8,"ts_in_delta":0,"sequence":0,"symbol":"EUCO SI 20260911 PS EU C 1.1575 0"}
{"ts_recv":"2026-03-19T08:01:07.844160662Z","hd":{"ts_event":"2026-03-19T08:01:07.843837153Z","rtype":160,"publisher_id":101,"instrument_id":34644},"action":"A","side":"B","price":"0.021520000","size":20,"channel_id":79,"order_id":"10997279304698641024","flags":0,"ts_in_delta":2393,"sequence":45571,"symbol":"EUCO SI 20260911 PS EU C 1.1575 0"}
{"ts_recv":"2026-03-19T08:01:07.844160662Z","hd":{"ts_event":"2026-03-19T08:01:07.843837153Z","rtype":160,"publisher_id":101,"instrument_id":34644},"action":"A","side":"A","price":"0.021940000","size":20,"channel_id":79,"order_id":"1773907267843865216","flags":128,"ts_in_delta":2393,"sequence":45571,"symbol":"EUCO SI 20260911 PS EU C 1.1575 0"}
{"ts_recv":"2026-03-19T08:01:07.844160662Z","hd":{"ts_event":"2026-03-19T08:01:07.843837153Z","rtype":160,"publisher_id":101,"instrument_id":34645},"action":"R","side":"N","price":null,"size":0,"channel_id":79,"order_id":"0","flags":8,"ts_in_delta":0,"sequence":0,"symbol":"EUCO SI 20260911 PS EU P 1.1575 0"}
{"ts_recv":"2026-03-19T08:01:07.844160662Z","hd":{"ts_event":"2026-03-19T08:01:07.843837153Z","rtype":160,"publisher_id":101,"instrument_id":34645},"action":"A","side":"B","price":"0.024600000","size":20,"channel_id":79,"order_id":"10997279304698641024","flags":0,"ts_in_delta":2393,"sequence":45571,"symbol":"EUCO SI 20260911 PS EU P 1.1575 0"}
{"ts_recv":"2026-03-19T08:01:07.844160662Z","hd":{"ts_event":"2026-03-19T08:01:07.843837153Z","rtype":160,"publisher_id":101,"instrument_id":34645},"action":"A","side":"A","price":"0.025030000","size":20,"channel_id":79,"order_id":"1773907267843865216","flags":128,"ts_in_delta":2393,"sequence":45571,"symbol":"EUCO SI 20260911 PS EU P 1.1575 0"}
{"ts_recv":"2026-03-19T08:01:07.844160662Z","hd":{"ts_event":"2026-03-19T08:01:07.843837153Z","rtype":160,"publisher_id":101,"instrument_id":34637},"action":"R","side":"N","price":null,"size":0,"channel_id":79,"order_id":"0","flags":8,"ts_in_delta":0,"sequence":0,"symbol":"EUCO SI 20260911 PS EU P 1.1475 0"}
{"ts_recv":"2026-03-19T08:01:07.844160662Z","hd":{"ts_event":"2026-03-19T08:01:07.843837153Z","rtype":160,"publisher_id":101,"instrument_id":34637},"action":"A","side":"B","price":"0.019910000","size":20,"channel_id":79,"order_id":"10997279304698641024","flags":0,"ts_in_delta":2393,"sequence":45571,"symbol":"EUCO SI 20260911 PS EU P 1.1475 0"}
{"ts_recv":"2026-03-19T08:01:07.844160662Z","hd":{"ts_event":"2026-03-19T08:01:07.843837153Z","rtype":160,"publisher_id":101,"instrument_id":34637},"action":"A","side":"A","price":"0.020330000","size":20,"channel_id":79,"order_id":"1773907267843865216","flags":128,"ts_in_delta":2393,"sequence":45571,"symbol":"EUCO SI 20260911 PS EU P 1.1475 0"}
{"ts_recv":"2026-03-19T08:01:07.844160662Z","hd":{"ts_event":"2026-03-19T08:01:07.843837153Z","rtype":160,"publisher_id":101,"instrument_id":34651},"action":"R","side":"N","price":null,"size":0,"channel_id":79,"order_id":"0","flags":8,"ts_in_delta":0,"sequence":0,"symbol":"EUCO SI 20260911 PS EU P 1.1650 0"}
{"ts_recv":"2026-03-19T08:01:07.844160662Z","hd":{"ts_event":"2026-03-19T08:01:07.843837153Z","rtype":160,"publisher_id":101,"instrument_id":34651},"action":"A","side":"B","price":"0.028640000","size":20,"channel_id":79,"order_id":"10997279304698641024","flags":0,"ts_in_delta":2393,"sequence":45571,"symbol":"EUCO SI 20260911 PS EU P 1.1650 0"}
{"ts_recv":"2026-03-19T08:01:07.844160662Z","hd":{"ts_event":"2026-03-19T08:01:07.843837153Z","rtype":160,"publisher_id":101,"instrument_id":34651},"action":"A","side":"A","price":"0.029070000","size":20,"channel_id":79,"order_id":"1773907267843865216","flags":128,"ts_in_delta":2393,"sequence":45571,"symbol":"EUCO SI 20260911 PS EU P 1.1650 0"}
{"ts_recv":"2026-03-19T08:01:07.844160662Z","hd":{"ts_event":"2026-03-19T08:01:07.843837153Z","rtype":160,"publisher_id":101,"instrument_id":34646},"action":"R","side":"N","price":null,"size":0,"channel_id":79,"order_id":"0","flags":8,"ts_in_delta":0,"sequence":0,"symbol":"EUCO SI 20260911 PS EU C 1.1600 0"}
{"ts_recv":"2026-03-19T08:01:07.844160662Z","hd":{"ts_event":"2026-03-19T08:01:07.843837153Z","rtype":160,"publisher_id":101,"instrument_id":34646},"action":"A","side":"B","price":"0.020360000","size":20,"channel_id":79,"order_id":"10997279304698641024","flags":0,"ts_in_delta":2393,"sequence":45571,"symbol":"EUCO SI 20260911 PS EU C 1.1600 0"}
{"ts_recv":"2026-03-19T08:01:07.844160662Z","hd":{"ts_event":"2026-03-19T08:01:07.843837153Z","rtype":160,"publisher_id":101,"instrument_id":34646},"action":"A","side":"A","price":"0.020790000","size":20,"channel_id":79,"order_id":"1773907267843865216","flags":128,"ts_in_delta":2393,"sequence":45571,"symbol":"EUCO SI 20260911 PS EU C 1.1600 0"}
{"ts_recv":"2026-03-19T08:01:07.844160662Z","hd":{"ts_event":"2026-03-19T08:01:07.843837153Z","rtype":160,"publisher_id":101,"instrument_id":34643},"action":"R","side":"N","price":null,"size":0,"channel_id":79,"order_id":"0","flags":8,"ts_in_delta":0,"sequence":0,"symbol":"EUCO SI 20260911 PS EU P 1.1550 0"}
{"ts_recv":"2026-03-19T08:01:07.844160662Z","hd":{"ts_event":"2026-03-19T08:01:07.843837153Z","rtype":160,"publisher_id":101,"instrument_id":34643},"action":"A","side":"B","price":"0.023360000","size":20,"channel_id":79,"order_id":"10997279304698641024","flags":0,"ts_in_delta":2393,"sequence":45571,"symbol":"EUCO SI 20260911 PS EU P 1.1550 0"}
{"ts_recv":"2026-03-19T08:01:07.844160662Z","hd":{"ts_event":"2026-03-19T08:01:07.843837153Z","rtype":160,"publisher_id":101,"instrument_id":34643},"action":"A","side":"A","price":"0.023780000","size":20,"channel_id":79,"order_id":"1773907267843865216","flags":128,"ts_in_delta":2393,"sequence":45571,"symbol":"EUCO SI 20260911 PS EU P 1.1550 0"}
{"ts_recv":"2026-03-19T08:01:07.844160662Z","hd":{"ts_event":"2026-03-19T08:01:07.843837153Z","rtype":160,"publisher_id":101,"instrument_id":34636},"action":"R","side":"N","price":null,"size":0,"channel_id":79,"order_id":"0","flags":8,"ts_in_delta":0,"sequence":0,"symbol":"EUCO SI 20260911 PS EU C 1.1475 0"}
{"ts_recv":"2026-03-19T08:01:07.844160662Z","hd":{"ts_event":"2026-03-19T08:01:07.843837153Z","rtype":160,"publisher_id":101,"instrument_id":34636},"action":"A","side":"B","price":"0.026640000","size":20,"channel_id":79,"order_id":"10997279304698641024","flags":0,"ts_in_delta":2393,"sequence":45571,"symbol":"EUCO SI 20260911 PS EU C 1.1475 0"}
{"ts_recv":"2026-03-19T08:01:07.844160662Z","hd":{"ts_event":"2026-03-19T08:01:07.843837153Z","rtype":160,"publisher_id":101,"instrument_id":34636},"action":"A","side":"A","price":"0.027070000","size":20,"channel_id":79,"order_id":"1773907267843865216","flags":128,"ts_in_delta":2393,"sequence":45571,"symbol":"EUCO SI 20260911 PS EU C 1.1475 0"}
{"ts_recv":"2026-03-19T08:01:07.844160662Z","hd":{"ts_event":"2026-03-19T08:01:07.843837153Z","rtype":160,"publisher_id":101,"instrument_id":34542},"action":"R","side":"N","price":null,"size":0,"channel_id":79,"order_id":"0","flags":8,"ts_in_delta":0,"sequence":0,"symbol":"EUCO SI 20260814 PS EU C 1.1525 0"}
{"ts_recv":"2026-03-19T08:01:07.844160662Z","hd":{"ts_event":"2026-03-19T08:01:07.843837153Z","rtype":160,"publisher_id":101,"instrument_id":34542},"action":"A","side":"B","price":"0.021560000","size":20,"channel_id":79,"order_id":"10997279304698641024","flags":0,"ts_in_delta":2393,"sequence":45571,"symbol":"EUCO SI 20260814 PS EU C 1.1525 0"}
{"ts_recv":"2026-03-19T08:01:07.844160662Z","hd":{"ts_event":"2026-03-19T08:01:07.843837153Z","rtype":160,"publisher_id":101,"instrument_id":34542},"action":"A","side":"A","price":"0.021980000","size":20,"channel_id":79,"order_id":"1773907267843865216","flags":128,"ts_in_delta":2393,"sequence":45571,"symbol":"EUCO SI 20260814 PS EU C 1.1525 0"}
{"ts_recv":"2026-03-19T08:01:07.844162205Z","hd":{"ts_event":"2026-03-19T08:01:07.843837153Z","rtype":160,"publisher_id":101,"instrument_id":34548},"action":"A","side":"A","price":"0.018400000","size":20,"channel_id":79,"order_id":"1773907267843865216","flags":128,"ts_in_delta":2111,"sequence":45572,"symbol":"EUCO SI 20260814 PS EU C 1.1600 0"}
{"ts_recv":"2026-03-19T08:01:07.844162205Z","hd":{"ts_event":"2026-03-19T08:01:07.843837153Z","rtype":160,"publisher_id":101,"instrument_id":34551},"action":"R","side":"N","price":null,"size":0,"channel_id":79,"order_id":"0","flags":8,"ts_in_delta":0,"sequence":0,"symbol":"EUCO SI 20260814 PS EU P 1.1625 0"}
{"ts_recv":"2026-03-19T08:01:07.844162205Z","hd":{"ts_event":"2026-03-19T08:01:07.843837153Z","rtype":160,"publisher_id":101,"instrument_id":34551},"action":"A","side":"B","price":"0.026120000","size":20,"channel_id":79,"order_id":"10997279304698641024","flags":0,"ts_in_delta":2111,"sequence":45572,"symbol":"EUCO SI 20260814 PS EU P 1.1625 0"}
{"ts_recv":"2026-03-19T08:01:07.844162205Z","hd":{"ts_event":"2026-03-19T08:01:07.843837153Z","rtype":160,"publisher_id":101,"instrument_id":34551},"action":"A","side":"A","price":"0.026550000","size":20,"channel_id":79,"order_id":"1773907267843865216","flags":128,"ts_in_delta":2111,"sequence":45572,"symbol":"EUCO SI 20260814 PS EU P 1.1625 0"}
{"ts_recv":"2026-03-19T08:01:07.844162205Z","hd":{"ts_event":"2026-03-19T08:01:07.843837153Z","rtype":160,"publisher_id":101,"instrument_id":34550},"action":"R","side":"N","price":null,"size":0,"channel_id":79,"order_id":"0","flags":8,"ts_in_delta":0,"sequence":0,"symbol":"EUCO SI 20260814 PS EU C 1.1625 0"}
{"ts_recv":"2026-03-19T08:01:07.844162205Z","hd":{"ts_event":"2026-03-19T08:01:07.843837153Z","rtype":160,"publisher_id":101,"instrument_id":34550},"action":"A","side":"B","price":"0.016890000","size":20,"channel_id":79,"order_id":"10997279304698641024","flags":0,"ts_in_delta":2111,"sequence":45572,"symbol":"EUCO SI 20260814 PS EU C 1.1625 0"}
{"ts_recv":"2026-03-19T08:01:07.844162205Z","hd":{"ts_event":"2026-03-19T08:01:07.843837153Z","rtype":160,"publisher_id":101,"instrument_id":34550},"action":"A","side":"A","price":"0.017310000","size":20,"channel_id":79,"order_id":"1773907267843865216","flags":128,"ts_in_delta":2111,"sequence":45572,"symbol":"EUCO SI 20260814 PS EU C 1.1625 0"}
{"ts_recv":"2026-03-19T08:01:07.844162205Z","hd":{"ts_event":"2026-03-19T08:01:07.843837153Z","rtype":160,"publisher_id":101,"instrument_id":34547},"action":"R","side":"N","price":null,"size":0,"channel_id":79,"order_id":"0","flags":8,"ts_in_delta":0,"sequence":0,"symbol":"EUCO SI 20260814 PS EU P 1.1575 0"}
{"ts_recv":"2026-03-19T08:01:07.844162205Z","hd":{"ts_event":"2026-03-19T08:01:07.843837153Z","rtype":160,"publisher_id":101,"instrument_id":34547},"action":"A","side":"B","price":"0.023430000","size":20,"channel_id":79,"order_id":"10997279304698641024","flags":0,"ts_in_delta":2111,"sequence":45572,"symbol":"EUCO SI 20260814 PS EU P 1.1575 0"}
{"ts_recv":"2026-03-19T08:01:07.844162205Z","hd":{"ts_event":"2026-03-19T08:01:07.843837153Z","rtype":160,"publisher_id":101,"instrument_id":34547},"action":"A","side":"A","price":"0.023850000","size":20,"channel_id":79,"order_id":"1773907267843865216","flags":128,"ts_in_delta":2111,"sequence":45572,"symbol":"EUCO SI 20260814 PS EU P 1.1575 0"}
{"ts_recv":"2026-03-19T08:01:07.844162205Z","hd":{"ts_event":"2026-03-19T08:01:07.843837153Z","rtype":160,"publisher_id":101,"instrument_id":34539},"action":"R","side":"N","price":null,"size":0,"channel_id":79,"order_id":"0","flags":8,"ts_in_delta":0,"sequence":0,"symbol":"EUCO SI 20260814 PS EU P 1.1475 0"}
{"ts_recv":"2026-03-19T08:01:07.844162205Z","hd":{"ts_event":"2026-03-19T08:01:07.843837153Z","rtype":160,"publisher_id":101,"instrument_id":34539},"action":"A","side":"B","price":"0.018670000","size":20,"channel_id":79,"order_id":"10997279304698641024","flags":0,"ts_in_delta":2111,"sequence":45572,"symbol":"EUCO SI 20260814 PS EU P 1.1475 0"}
{"ts_recv":"2026-03-19T08:01:07.844162205Z","hd":{"ts_event":"2026-03-19T08:01:07.843837153Z","rtype":160,"publisher_id":101,"instrument_id":34539},"action":"A","side":"A","price":"0.019100000","size":20,"channel_id":79,"order_id":"1773907267843865216","flags":128,"ts_in_delta":2111,"sequence":45572,"symbol":"EUCO SI 20260814 PS EU P 1.1475 0"}
{"ts_recv":"2026-03-19T08:01:07.844162205Z","hd":{"ts_event":"2026-03-19T08:01:07.843837153Z","rtype":160,"publisher_id":101,"instrument_id":34543},"action":"R","side":"N","price":null,"size":0,"channel_id":79,"order_id":"0","flags":8,"ts_in_delta":0,"sequence":0,"symbol":"EUCO SI 20260814 PS EU P 1.1525 0"}
{"ts_recv":"2026-03-19T08:01:07.844162205Z","hd":{"ts_event":"2026-03-19T08:01:07.843837153Z","rtype":160,"publisher_id":101,"instrument_id":34543},"action":"A","side":"B","price":"0.020940000","size":20,"channel_id":79,"order_id":"10997279304698641024","flags":0,"ts_in_delta":2111,"sequence":45572,"symbol":"EUCO SI 20260814 PS EU P 1.1525 0"}
{"ts_recv":"2026-03-19T08:01:07.844162205Z","hd":{"ts_event":"2026-03-19T08:01:07.843837153Z","rtype":160,"publisher_id":101,"instrument_id":34543},"action":"A","side":"A","price":"0.021370000","size":20,"channel_id":79,"order_id":"1773907267843865216","flags":128,"ts_in_delta":2111,"sequence":45572,"symbol":"EUCO SI 20260814 PS EU P 1.1525 0"}
{"ts_recv":"2026-03-19T08:01:07.844162205Z","hd":{"ts_event":"2026-03-19T08:01:07.843837153Z","rtype":160,"publisher_id":101,"instrument_id":34449},"action":"R","side":"N","price":null,"size":0,"channel_id":79,"order_id":"0","flags":8,"ts_in_delta":0,"sequence":0,"symbol":"EUCO SI 20260710 PS EU P 1.1550 0"}
{"ts_recv":"2026-03-19T08:01:07.844162205Z","hd":{"ts_event":"2026-03-19T08:01:07.843837153Z","rtype":160,"publisher_id":101,"instrument_id":34449},"action":"A","side":"B","price":"0.020330000","size":20,"channel_id":79,"order_id":"10997279304698641024","flags":0,"ts_in_delta":2111,"sequence":45572,"symbol":"EUCO SI 20260710 PS EU P 1.1550 0"}
{"ts_recv":"2026-03-19T08:01:07.844162205Z","hd":{"ts_event":"2026-03-19T08:01:07.843837153Z","rtype":160,"publisher_id":101,"instrument_id":34449},"action":"A","side":"A","price":"0.020760000","size":20,"channel_id":79,"order_id":"1773907267843865216","flags":128,"ts_in_delta":2111,"sequence":45572,"symbol":"EUCO SI 20260710 PS EU P 1.1550 0"}
{"ts_recv":"2026-03-19T08:01:07.844162205Z","hd":{"ts_event":"2026-03-19T08:01:07.843837153Z","rtype":160,"publisher_id":101,"instrument_id":34444},"action":"R","side":"N","price":null,"size":0,"channel_id":79,"order_id":"0","flags":8,"ts_in_delta":0,"sequence":0,"symbol":"EUCO SI 20260710 PS EU C 1.1500 0"}
{"ts_recv":"2026-03-19T08:01:07.844162205Z","hd":{"ts_event":"2026-03-19T08:01:07.843837153Z","rtype":160,"publisher_id":101,"instrument_id":34444},"action":"A","side":"B","price":"0.019390000","size":20,"channel_id":79,"order_id":"10997279304698641024","flags":0,"ts_in_delta":2111,"sequence":45572,"symbol":"EUCO SI 20260710 PS EU C 1.1500 0"}
{"ts_recv":"2026-03-19T08:01:07.844162205Z","hd":{"ts_event":"2026-03-19T08:01:07.843837153Z","rtype":160,"publisher_id":101,"instrument_id":34444},"action":"A","side":"A","price":"0.019820000","size":20,"channel_id":79,"order_id":"1773907267843865216","flags":128,"ts_in_delta":2111,"sequence":45572,"symbol":"EUCO SI 20260710 PS EU C 1.1500 0"}
{"ts_recv":"2026-03-19T08:01:07.844162205Z","hd":{"ts_event":"2026-03-19T08:01:07.843837153Z","rtype":160,"publisher_id":101,"instrument_id":34640},"action":"R","side":"N","price":null,"size":0,"channel_id":79,"order_id":"0","flags":8,"ts_in_delta":0,"sequence":0,"symbol":"EUCO SI 20260911 PS EU C 1.1525 0"}
{"ts_recv":"2026-03-19T08:01:07.844162205Z","hd":{"ts_event":"2026-03-19T08:01:07.843837153Z","rtype":160,"publisher_id":101,"instrument_id":34640},"action":"A","side":"B","price":"0.023980000","size":20,"channel_id":79,"order_id":"10997279304698641024","flags":0,"ts_in_delta":2111,"sequence":45572,"symbol":"EUCO SI 20260911 PS EU C 1.1525 0"}
{"ts_recv":"2026-03-19T08:01:07.844162205Z","hd":{"ts_event":"2026-03-19T08:01:07.843837153Z","rtype":160,"publisher_id":101,"instrument_id":34640},"action":"A","side":"A","price":"0.024410000","size":20,"channel_id":79,"order_id":"1773907267843865216","flags":128,"ts_in_delta":2111,"sequence":45572,"symbol":"EUCO SI 20260911 PS EU C 1.1525 0"}
{"ts_recv":"2026-03-19T08:01:07.844162205Z","hd":{"ts_event":"2026-03-19T08:01:07.843837153Z","rtype":160,"publisher_id":101,"instrument_id":34639},"action":"R","side":"N","price":null,"size":0,"channel_id":79,"order_id":"0","flags":8,"ts_in_delta":0,"sequence":0,"symbol":"EUCO SI 20260911 PS EU P 1.1500 0"}
{"ts_recv":"2026-03-19T08:01:07.844162205Z","hd":{"ts_event":"2026-03-19T08:01:07.843837153Z","rtype":160,"publisher_id":101,"instrument_id":34639},"action":"A","side":"B","price":"0.021010000","size":20,"channel_id":79,"order_id":"10997279304698641024","flags":0,"ts_in_delta":2111,"sequence":45572,"symbol":"EUCO SI 20260911 PS EU P 1.1500 0"}
{"ts_recv":"2026-03-19T08:01:07.844162205Z","hd":{"ts_event":"2026-03-19T08:01:07.843837153Z","rtype":160,"publisher_id":101,"instrument_id":34639},"action":"A","side":"A","price":"0.021430000","size":20,"channel_id":79,"order_id":"1773907267843865216","flags":128,"ts_in_delta":2111,"sequence":45572,"symbol":"EUCO SI 20260911 PS EU P 1.1500 0"}
{"ts_recv":"2026-03-19T08:01:07.844162205Z","hd":{"ts_event":"2026-03-19T08:01:07.843837153Z","rtype":160,"publisher_id":101,"instrument_id":34545},"action":"R","side":"N","price":null,"size":0,"channel_id":79,"order_id":"0","flags":8,"ts_in_delta":0,"sequence":0,"symbol":"EUCO SI 20260814 PS EU P 1.1550 0"}
{"ts_recv":"2026-03-19T08:01:07.844162205Z","hd":{"ts_event":"2026-03-19T08:01:07.843837153Z","rtype":160,"publisher_id":101,"instrument_id":34545},"action":"A","side":"B","price":"0.022160000","size":20,"channel_id":79,"order_id":"10997279304698641024","flags":0,"ts_in_delta":2111,"sequence":45572,"symbol":"EUCO SI 20260814 PS EU P 1.1550 0"}
{"ts_recv":"2026-03-19T08:01:07.844162205Z","hd":{"ts_event":"2026-03-19T08:01:07.843837153Z","rtype":160,"publisher_id":101,"instrument_id":34545},"action":"A","side":"A","price":"0.022580000","size":20,"channel_id":79,"order_id":"1773907267843865216","flags":128,"ts_in_delta":2111,"sequence":45572,"symbol":"EUCO SI 20260814 PS EU P 1.1550 0"}
{"ts_recv":"2026-03-19T08:01:07.844162205Z","hd":{"ts_event":"2026-03-19T08:01:07.843837153Z","rtype":160,"publisher_id":101,"instrument_id":34544},"action":"R","side":"N","price":null,"size":0,"channel_id":79,"order_id":"0","flags":8,"ts_in_delta":0,"sequence":0,"symbol":"EUCO SI 20260814 PS EU C 1.1550 0"}
{"ts_recv":"2026-03-19T08:01:07.844162205Z","hd":{"ts_event":"2026-03-19T08:01:07.843837153Z","rtype":160,"publisher_id":101,"instrument_id":34544},"action":"A","side":"B","price":"0.020310000","size":20,"channel_id":79,"order_id":"10997279304698641024","flags":0,"ts_in_delta":2111,"sequence":45572,"symbol":"EUCO SI 20260814 PS EU C 1.1550 0"}
{"ts_recv":"2026-03-19T08:01:07.844162205Z","hd":{"ts_event":"2026-03-19T08:01:07.843837153Z","rtype":160,"publisher_id":101,"instrument_id":34544},"action":"A","side":"A","price":"0.020740000","size":20,"channel_id":79,"order_id":"1773907267843865216","flags":128,"ts_in_delta":2111,"sequence":45572,"symbol":"EUCO SI 20260814 PS EU C 1.1550 0"}
{"ts_recv":"2026-03-19T08:01:07.844163642Z","hd":{"ts_event":"2026-03-19T08:01:07.843837153Z","rtype":160,"publisher_id":101,"instrument_id":34552},"action":"R","side":"N","price":null,"size":0,"channel_id":79,"order_id":"0","flags":8,"ts_in_delta":0,"sequence":0,"symbol":"EUCO SI 20260814 PS EU C 1.1650 0"}
{"ts_recv":"2026-03-19T08:01:07.844163642Z","hd":{"ts_event":"2026-03-19T08:01:07.843837153Z","rtype":160,"publisher_id":101,"instrument_id":34552},"action":"A","side":"B","price":"0.015850000","size":20,"channel_id":79,"order_id":"10997279304698641024","flags":0,"ts_in_delta":2544,"sequence":45573,"symbol":"EUCO SI 20260814 PS EU C 1.1650 0"}
{"ts_recv":"2026-03-19T08:01:07.844163642Z","hd":{"ts_event":"2026-03-19T08:01:07.843837153Z","rtype":160,"publisher_id":101,"instrument_id":34552},"action":"A","side":"A","price":"0.016280000","size":20,"channel_id":79,"order_id":"1773907267843865216","flags":128,"ts_in_delta":2544,"sequence":45573,"symbol":"EUCO SI 20260814 PS EU C 1.1650 0"}
{"ts_recv":"2026-03-19T08:01:07.844163642Z","hd":{"ts_event":"2026-03-19T08:01:07.843837153Z","rtype":160,"publisher_id":101,"instrument_id":34250},"action":"R","side":"N","price":null,"size":0,"channel_id":79,"order_id":"0","flags":8,"ts_in_delta":0,"sequence":0,"symbol":"EUCO SI 20260508 PS EU C 1.1575 0"}
{"ts_recv":"2026-03-19T08:01:07.844163642Z","hd":{"ts_event":"2026-03-19T08:01:07.843837153Z","rtype":160,"publisher_id":101,"instrument_id":34250},"action":"A","side":"B","price":"0.008750000","size":20,"channel_id":79,"order_id":"10997279304698641024","flags":0,"ts_in_delta":2544,"sequence":45573,"symbol":"EUCO SI 20260508 PS EU C 1.1575 0"}
{"ts_recv":"2026-03-19T08:01:07.844163642Z","hd":{"ts_event":"2026-03-19T08:01:07.843837153Z","rtype":160,"publisher_id":101,"instrument_id":34250},"action":"A","side":"A","price":"0.009170000","size":20,"channel_id":79,"order_id":"1773907267843865216","flags":128,"ts_in_delta":2544,"sequence":45573,"symbol":"EUCO SI 20260508 PS EU C 1.1575 0"}
