{"ts_recv":"2026-04-06T18:53:11.558341309Z","hd":{"ts_event":"2026-04-06T18:53:11.558339853Z","rtype":160,"publisher_id":101,"instrument_id":33345},"action":"R","side":"N","price":null,"size":0,"channel_id":79,"order_id":"0","flags":128,"ts_in_delta":1456,"sequence":2,"symbol":"EUCO SI 20260710 PS EU C 1.1300 0"}
{"ts_recv":"2026-04-06T18:53:11.558341309Z","hd":{"ts_event":"2026-04-06T18:53:11.558339853Z","rtype":160,"publisher_id":101,"instrument_id":33344},"action":"R","side":"N","price":null,"size":0,"channel_id":79,"order_id":"0","flags":128,"ts_in_delta":1456,"sequence":2,"symbol":"EUCO SI 20260710 PS EU P 1.1275 0"}
{"ts_recv":"2026-04-06T18:53:11.558341309Z","hd":{"ts_event":"2026-04-06T18:53:11.558339853Z","rtype":160,"publisher_id":101,"instrument_id":33343},"action":"R","side":"N","price":null,"size":0,"channel_id":79,"order_id":"0","flags":128,"ts_in_delta":1456,"sequence":2,"symbol":"EUCO SI 20260710 PS EU C 1.1275 0"}
{"ts_recv":"2026-04-06T18:53:11.558341309Z","hd":{"ts_event":"2026-04-06T18:53:11.558339853Z","rtype":160,"publisher_id":101,"instrument_id":33342},"action":"R","side":"N","price":null,"size":0,"channel_id":79,"order_id":"0","flags":128,"ts_in_delta":1456,"sequence":2,"symbol":"EUCO SI 20260710 PS EU P 1.1250 0"}
{"ts_recv":"2026-04-06T18:53:11.558341309Z","hd":{"ts_event":"2026-04-06T18:53:11.558339853Z","rtype":160,"publisher_id":101,"instrument_id":33341},"action":"R","side":"N","price":null,"size":0,"channel_id":79,"order_id":"0","flags":128,"ts_in_delta":1456,"sequence":2,"symbol":"EUCO SI 20260710 PS EU C 1.1250 0"}
{"ts_recv":"2026-04-06T18:53:11.558341309Z","hd":{"ts_event":"2026-04-06T18:53:11.558339853Z","rtype":160,"publisher_id":101,"instrument_id":33340},"action":"R","side":"N","price":null,"size":0,"channel_id":79,"order_id":"0","flags":128,"ts_in_delta":1456,"sequence":2,"symbol":"EUCO SI 20260710 PS EU P 1.1200 0"}
{"ts_recv":"2026-04-06T18:53:11.558341309Z","hd":{"ts_event":"2026-04-06T18:53:11.558339853Z","rtype":160,"publisher_id":101,"instrument_id":33339},"action":"R","side":"N","price":null,"size":0,"channel_id":79,"order_id":"0","flags":128,"ts_in_delta":1456,"sequence":2,"symbol":"EUCO SI 20260710 PS EU C 1.1200 0"}
{"ts_recv":"2026-04-06T18:53:11.558341309Z","hd":{"ts_event":"2026-04-06T18:53:11.558339853Z","rtype":160,"publisher_id":101,"instrument_id":33338},"action":"R","side":"N","price":null,"size":0,"channel_id":79,"order_id":"0","flags":128,"ts_in_delta":1456,"sequence":2,"symbol":"EUCO SI 20260710 PS EU P 1.1150 0"}
{"ts_recv":"2026-04-06T18:53:11.558341309Z","hd":{"ts_event":"2026-04-06T18:53:11.558339853Z","rtype":160,"publisher_id":101,"instrument_id":33337},"action":"R","side":"N","price":null,"size":0,"channel_id":79,"order_id":"0","flags":128,"ts_in_delta":1456,"sequence":2,"symbol":"EUCO SI 20260710 PS EU C 1.1150 0"}
{"ts_recv":"2026-04-06T18:53:11.558341309Z","hd":{"ts_event":"2026-04-06T18:53:11.558339853Z","rtype":160,"publisher_id":101,"instrument_id":33336},"action":"R","side":"N","price":null,"size":0,"channel_id":79,"order_id":"0","flags":128,"ts_in_delta":1456,"sequence":2,"symbol":"EUCO SI 20260710 PS EU P 1.1100 0"}
{"ts_recv":"2026-04-06T18:53:11.558341309Z","hd":{"ts_event":"2026-04-06T18:53:11.558339853Z","rtype":160,"publisher_id":101,"instrument_id":33335},"action":"R","side":"N","price":null,"size":0,"channel_id":79,"order_id":"0","flags":128,"ts_in_delta":1456,"sequence":2,"symbol":"EUCO SI 20260710 PS EU C 1.1100 0"}
{"ts_recv":"2026-04-06T18:53:11.558341309Z","hd":{"ts_event":"2026-04-06T18:53:11.558339853Z","rtype":160,"publisher_id":101,"instrument_id":33334},"action":"R","side":"N","price":null,"size":0,"channel_id":79,"order_id":"0","flags":128,"ts_in_delta":1456,"sequence":2,"symbol":"EUCO SI 20260612 PS EU P 1.2550 0"}
{"ts_recv":"2026-04-06T18:53:11.558341309Z","hd":{"ts_event":"2026-04-06T18:53:11.558339853Z","rtype":160,"publisher_id":101,"instrument_id":33333},"action":"R","side":"N","price":null,"size":0,"channel_id":79,"order_id":"0","flags":128,"ts_in_delta":1456,"sequence":2,"symbol":"EUCO SI 20260612 PS EU C 1.2550 0"}
{"ts_recv":"2026-04-06T18:53:11.558341309Z","hd":{"ts_event":"2026-04-06T18:53:11.558339853Z","rtype":160,"publisher_id":101,"instrument_id":33332},"action":"R","side":"N","price":null,"size":0,"channel_id":79,"order_id":"0","flags":128,"ts_in_delta":1456,"sequence":2,"symbol":"EUCO SI 20260612 PS EU P 1.2500 0"}
{"ts_recv":"2026-04-06T18:53:11.558341309Z","hd":{"ts_event":"2026-04-06T18:53:11.558339853Z","rtype":160,"publisher_id":101,"instrument_id":33331},"action":"R","side":"N","price":null,"size":0,"channel_id":79,"order_id":"0","flags":128,"ts_in_delta":1456,"sequence":2,"symbol":"EUCO SI 20260612 PS EU C 1.2500 0"}
{"ts_recv":"2026-04-06T18:53:11.558341309Z","hd":{"ts_event":"2026-04-06T18:53:11.558339853Z","rtype":160,"publisher_id":101,"instrument_id":33330},"action":"R","side":"N","price":null,"size":0,"channel_id":79,"order_id":"0","flags":128,"ts_in_delta":1456,"sequence":2,"symbol":"EUCO SI 20260612 PS EU P 1.2450 0"}
{"ts_recv":"2026-04-06T18:53:11.558341309Z","hd":{"ts_event":"2026-04-06T18:53:11.558339853Z","rtype":160,"publisher_id":101,"instrument_id":33329},"action":"R","side":"N","price":null,"size":0,"channel_id":79,"order_id":"0","flags":128,"ts_in_delta":1456,"sequence":2,"symbol":"EUCO SI 20260612 PS EU C 1.2450 0"}
{"ts_recv":"2026-04-06T18:53:11.558341309Z","hd":{"ts_event":"2026-04-06T18:53:11.558339853Z","rtype":160,"publisher_id":101,"instrument_id":33328},"action":"R","side":"N","price":null,"size":0,"channel_id":79,"order_id":"0","flags":128,"ts_in_delta":1456,"sequence":2,"symbol":"EUCO SI 20260612 PS EU P 1.2400 0"}
{"ts_recv":"2026-04-06T18:53:11.558341309Z","hd":{"ts_event":"2026-04-06T18:53:11.558339853Z","rtype":160,"publisher_id":101,"instrument_id":33327},"action":"R","side":"N","price":null,"size":0,"channel_id":79,"order_id":"0","flags":128,"ts_in_delta":1456,"sequence":2,"symbol":"EUCO SI 20260612 PS EU C 1.2400 0"}
{"ts_recv":"2026-04-06T18:53:11.558341309Z","hd":{"ts_event":"2026-04-06T18:53:11.558339853Z","rtype":160,"publisher_id":101,"instrument_id":33326},"action":"R","side":"N","price":null,"size":0,"channel_id":79,"order_id":"0","flags":128,"ts_in_delta":1456,"sequence":2,"symbol":"EUCO SI 20260612 PS EU P 1.2350 0"}
{"ts_recv":"2026-04-06T18:53:11.558341309Z","hd":{"ts_event":"2026-04-06T18:53:11.558339853Z","rtype":160,"publisher_id":101,"instrument_id":33325},"action":"R","side":"N","price":null,"size":0,"channel_id":79,"order_id":"0","flags":128,"ts_in_delta":1456,"sequence":2,"symbol":"EUCO SI 20260612 PS EU C 1.2350 0"}
{"ts_recv":"2026-04-06T18:53:11.558341309Z","hd":{"ts_event":"2026-04-06T18:53:11.558339853Z","rtype":160,"publisher_id":101,"instrument_id":33324},"action":"R","side":"N","price":null,"size":0,"channel_id":79,"order_id":"0","flags":128,"ts_in_delta":1456,"sequence":2,"symbol":"EUCO SI 20260612 PS EU P 1.2300 0"}
{"ts_recv":"2026-04-06T18:53:11.558341309Z","hd":{"ts_event":"2026-04-06T18:53:11.558339853Z","rtype":160,"publisher_id":101,"instrument_id":33323},"action":"R","side":"N","price":null,"size":0,"channel_id":79,"order_id":"0","flags":128,"ts_in_delta":1456,"sequence":2,"symbol":"EUCO SI 20260612 PS EU C 1.2300 0"}
{"ts_recv":"2026-04-06T18:53:11.558341309Z","hd":{"ts_event":"2026-04-06T18:53:11.558339853Z","rtype":160,"publisher_id":101,"instrument_id":33322},"action":"R","side":"N","price":null,"size":0,"channel_id":79,"order_id":"0","flags":128,"ts_in_delta":1456,"sequence":2,"symbol":"EUCO SI 20260612 PS EU P 1.2275 0"}
{"ts_recv":"2026-04-06T18:53:11.558341309Z","hd":{"ts_event":"2026-04-06T18:53:11.558339853Z","rtype":160,"publisher_id":101,"instrument_id":33321},"action":"R","side":"N","price":null,"size":0,"channel_id":79,"order_id":"0","flags":128,"ts_in_delta":1456,"sequence":2,"symbol":"EUCO SI 20260612 PS EU C 1.2275 0"}
{"ts_recv":"2026-04-06T18:53:11.558341309Z","hd":{"ts_event":"2026-04-06T18:53:11.558339853Z","rtype":160,"publisher_id":101,"instrument_id":33320},"action":"R","side":"N","price":null,"size":0,"channel_id":79,"order_id":"0","flags":128,"ts_in_delta":1456,"sequence":2,"symbol":"EUCO SI 20260612 PS EU P 1.2250 0"}
{"ts_recv":"2026-04-06T18:53:11.558341309Z","hd":{"ts_event":"2026-04-06T18:53:11.558339853Z","rtype":160,"publisher_id":101,"instrument_id":33319},"action":"R","side":"N","price":null,"size":0,"channel_id":79,"order_id":"0","flags":128,"ts_in_delta":1456,"sequence":2,"symbol":"EUCO SI 20260612 PS EU C 1.2250 0"}
{"ts_recv":"2026-04-06T18:53:11.558341309Z","hd":{"ts_event":"2026-04-06T18:53:11.558339853Z","rtype":160,"publisher_id":101,"instrument_id":33318},"action":"R","side":"N","price":null,"size":0,"channel_id":79,"order_id":"0","flags":128,"ts_in_delta":1456,"sequence":2,"symbol":"EUCO SI 20260612 PS EU P 1.2225 0"}
{"ts_recv":"2026-04-06T18:53:11.558341309Z","hd":{"ts_event":"2026-04-06T18:53:11.558339853Z","rtype":160,"publisher_id":101,"instrument_id":33317},"action":"R","side":"N","price":null,"size":0,"channel_id":79,"order_id":"0","flags":128,"ts_in_delta":1456,"sequence":2,"symbol":"EUCO SI 20260612 PS EU C 1.2225 0"}
{"ts_recv":"2026-04-06T18:53:11.558341309Z","hd":{"ts_event":"2026-04-06T18:53:11.558339853Z","rtype":160,"publisher_id":101,"instrument_id":33316},"action":"R","side":"N","price":null,"size":0,"channel_id":79,"order_id":"0","flags":128,"ts_in_delta":1456,"sequence":2,"symbol":"EUCO SI 20260612 PS EU P 1.2200 0"}
{"ts_recv":"2026-04-06T18:53:11.558341309Z","hd":{"ts_event":"2026-04-06T18:53:11.558339853Z","rtype":160,"publisher_id":101,"instrument_id":33315},"action":"R","side":"N","price":null,"size":0,"channel_id":79,"order_id":"0","flags":128,"ts_in_delta":1456,"sequence":2,"symbol":"EUCO SI 20260612 PS EU C 1.2200 0"}
{"ts_recv":"2026-04-06T18:53:11.558341309Z","hd":{"ts_event":"2026-04-06T18:53:11.558339853Z","rtype":160,"publisher_id":101,"instrument_id":33314},"action":"R","side":"N","price":null,"size":0,"channel_id":79,"order_id":"0","flags":128,"ts_in_delta":1456,"sequence":2,"symbol":"EUCO SI 20260612 PS EU P 1.2175 0"}
{"ts_recv":"2026-04-06T18:53:11.558341309Z","hd":{"ts_event":"2026-04-06T18:53:11.558339853Z","rtype":160,"publisher_id":101,"instrument_id":33313},"action":"R","side":"N","price":null,"size":0,"channel_id":79,"order_id":"0","flags":128,"ts_in_delta":1456,"sequence":2,"symbol":"EUCO SI 20260612 PS EU C 1.2175 0"}
{"ts_recv":"2026-04-06T18:53:11.558341309Z","hd":{"ts_event":"2026-04-06T18:53:11.558339853Z","rtype":160,"publisher_id":101,"instrument_id":33312},"action":"R","side":"N","price":null,"size":0,"channel_id":79,"order_id":"0","flags":128,"ts_in_delta":1456,"sequence":2,"symbol":"EUCO SI 20260612 PS EU P 1.2150 0"}
{"ts_recv":"2026-04-06T18:53:11.558341309Z","hd":{"ts_event":"2026-04-06T18:53:11.558339853Z","rtype":160,"publisher_id":101,"instrument_id":33311},"action":"R","side":"N","price":null,"size":0,"channel_id":79,"order_id":"0","flags":128,"ts_in_delta":1456,"sequence":2,"symbol":"EUCO SI 20260612 PS EU C 1.2150 0"}
{"ts_recv":"2026-04-06T18:53:11.558341309Z","hd":{"ts_event":"2026-04-06T18:53:11.558339853Z","rtype":160,"publisher_id":101,"instrument_id":33310},"action":"R","side":"N","price":null,"size":0,"channel_id":79,"order_id":"0","flags":128,"ts_in_delta":1456,"sequence":2,"symbol":"EUCO SI 20260612 PS EU P 1.2125 0"}
{"ts_recv":"2026-04-06T18:53:11.558341309Z","hd":{"ts_event":"2026-04-06T18:53:11.558339853Z","rtype":160,"publisher_id":101,"instrument_id":33309},"action":"R","side":"N","price":null,"size":0,"channel_id":79,"order_id":"0","flags":128,"ts_in_delta":1456,"sequence":2,"symbol":"EUCO SI 20260612 PS EU C 1.2125 0"}
{"ts_recv":"2026-04-06T18:53:11.558341309Z","hd":{"ts_event":"2026-04-06T18:53:11.558339853Z","rtype":160,"publisher_id":101,"instrument_id":33308},"action":"R","side":"N","price":null,"size":0,"channel_id":79,"order_id":"0","flags":128,"ts_in_delta":1456,"sequence":2,"symbol":"EUCO SI 20260612 PS EU P 1.2100 0"}
{"ts_recv":"2026-04-06T18:53:11.558341309Z","hd":{"ts_event":"2026-04-06T18:53:11.558339853Z","rtype":160,"publisher_id":101,"instrument_id":33307},"action":"R","side":"N","price":null,"size":0,"channel_id":79,"order_id":"0","flags":128,"ts_in_delta":1456,"sequence":2,"symbol":"EUCO SI 20260612 PS EU C 1.2100 0"}
{"ts_recv":"2026-04-06T18:53:11.558341309Z","hd":{"ts_event":"2026-04-06T18:53:11.558339853Z","rtype":160,"publisher_id":101,"instrument_id":33306},"action":"R","side":"N","price":null,"size":0,"channel_id":79,"order_id":"0","flags":128,"ts_in_delta":1456,"sequence":2,"symbol":"EUCO SI 20260612 PS EU P 1.2075 0"}
{"ts_recv":"2026-04-06T18:53:11.558341309Z","hd":{"ts_event":"2026-04-06T18:53:11.558339853Z","rtype":160,"publisher_id":101,"instrument_id":33305},"action":"R","side":"N","price":null,"size":0,"channel_id":79,"order_id":"0","flags":128,"ts_in_delta":1456,"sequence":2,"symbol":"EUCO SI 20260612 PS EU C 1.2075 0"}
{"ts_recv":"2026-04-06T18:53:11.558341309Z","hd":{"ts_event":"2026-04-06T18:53:11.558339853Z","rtype":160,"publisher_id":101,"instrument_id":33304},"action":"R","side":"N","price":null,"size":0,"channel_id":79,"order_id":"0","flags":128,"ts_in_delta":1456,"sequence":2,"symbol":"EUCO SI 20260612 PS EU P 1.2050 0"}
{"ts_recv":"2026-04-06T18:53:11.558341309Z","hd":{"ts_event":"2026-04-06T18:53:11.558339853Z","rtype":160,"publisher_id":101,"instrument_id":33303},"action":"R","side":"N","price":null,"size":0,"channel_id":79,"order_id":"0","flags":128,"ts_in_delta":1456,"sequence":2,"symbol":"EUCO SI 20260612 PS EU C 1.2050 0"}
{"ts_recv":"2026-04-06T18:53:11.558341309Z","hd":{"ts_event":"2026-04-06T18:53:11.558339853Z","rtype":160,"publisher_id":101,"instrument_id":33302},"action":"R","side":"N","price":null,"size":0,"channel_id":79,"order_id":"0","flags":128,"ts_in_delta":1456,"sequence":2,"symbol":"EUCO SI 20260612 PS EU P 1.2025 0"}
{"ts_recv":"2026-04-06T18:53:11.558341309Z","hd":{"ts_event":"2026-04-06T18:53:11.558339853Z","rtype":160,"publisher_id":101,"instrument_id":33301},"action":"R","side":"N","price":null,"size":0,"channel_id":79,"order_id":"0","flags":128,"ts_in_delta":1456,"sequence":2,"symbol":"EUCO SI 20260612 PS EU C 1.2025 0"}
{"ts_recv":"2026-04-06T18:53:11.558341309Z","hd":{"ts_event":"2026-04-06T18:53:11.558339853Z","rtype":160,"publisher_id":101,"instrument_id":33300},"action":"R","side":"N","price":null,"size":0,"channel_id":79,"order_id":"0","flags":128,"ts_in_delta":1456,"sequence":2,"symbol":"EUCO SI 20260612 PS EU P 1.2000 0"}
{"ts_recv":"2026-04-06T18:53:11.558341309Z","hd":{"ts_event":"2026-04-06T18:53:11.558339853Z","rtype":160,"publisher_id":101,"instrument_id":33299},"action":"R","side":"N","price":null,"size":0,"channel_id":79,"order_id":"0","flags":128,"ts_in_delta":1456,"sequence":2,"symbol":"EUCO SI 20260612 PS EU C 1.2000 0"}
{"ts_recv":"2026-04-06T18:53:11.558341309Z","hd":{"ts_event":"2026-04-06T18:53:11.558339853Z","rtype":160,"publisher_id":101,"instrument_id":33298},"action":"R","side":"N","price":null,"size":0,"channel_id":79,"order_id":"0","flags":128,"ts_in_delta":1456,"sequence":2,"symbol":"EUCO SI 20260612 PS EU P 1.1975 0"}
{"ts_recv":"2026-04-06T18:53:11.558341309Z","hd":{"ts_event":"2026-04-06T18:53:11.558339853Z","rtype":160,"publisher_id":101,"instrument_id":33297},"action":"R","side":"N","price":null,"size":0,"channel_id":79,"order_id":"0","flags":128,"ts_in_delta":1456,"sequence":2,"symbol":"EUCO SI 20260612 PS EU C 1.1975 0"}
{"ts_recv":"2026-04-06T18:53:11.558341309Z","hd":{"ts_event":"2026-04-06T18:53:11.558339853Z","rtype":160,"publisher_id":101,"instrument_id":33296},"action":"R","side":"N","price":null,"size":0,"channel_id":79,"order_id":"0","flags":128,"ts_in_delta":1456,"sequence":2,"symbol":"EUCO SI 20260612 PS EU P 1.1950 0"}
{"ts_recv":"2026-04-06T18:53:11.558341309Z","hd":{"ts_event":"2026-04-06T18:53:11.558339853Z","rtype":160,"publisher_id":101,"instrument_id":33295},"action":"R","side":"N","price":null,"size":0,"channel_id":79,"order_id":"0","flags":128,"ts_in_delta":1456,"sequence":2,"symbol":"EUCO SI 20260612 PS EU C 1.1950 0"}
{"ts_recv":"2026-04-06T18:53:11.558341309Z","hd":{"ts_event":"2026-04-06T18:53:11.558339853Z","rtype":160,"publisher_id":101,"instrument_id":33294},"action":"R","side":"N","price":null,"size":0,"channel_id":79,"order_id":"0","flags":128,"ts_in_delta":1456,"sequence":2,"symbol":"EUCO SI 20260612 PS EU P 1.1925 0"}
{"ts_recv":"2026-04-06T18:53:11.558341309Z","hd":{"ts_event":"2026-04-06T18:53:11.558339853Z","rtype":160,"publisher_id":101,"instrument_id":33293},"action":"R","side":"N","price":null,"size":0,"channel_id":79,"order_id":"0","flags":128,"ts_in_delta":1456,"sequence":2,"symbol":"EUCO SI 20260612 PS EU C 1.1925 0"}
{"ts_recv":"2026-04-06T18:53:11.558341309Z","hd":{"ts_event":"2026-04-06T18:53:11.558339853Z","rtype":160,"publisher_id":101,"instrument_id":33292},"action":"R","side":"N","price":null,"size":0,"channel_id":79,"order_id":"0","flags":128,"ts_in_delta":1456,"sequence":2,"symbol":"EUCO SI 20260612 PS EU P 1.1900 0"}
{"ts_recv":"2026-04-06T18:53:11.558341309Z","hd":{"ts_event":"2026-04-06T18:53:11.558339853Z","rtype":160,"publisher_id":101,"instrument_id":33291},"action":"R","side":"N","price":null,"size":0,"channel_id":79,"order_id":"0","flags":128,"ts_in_delta":1456,"sequence":2,"symbol":"EUCO SI 20260612 PS EU C 1.1900 0"}
{"ts_recv":"2026-04-06T18:53:11.558341309Z","hd":{"ts_event":"2026-04-06T18:53:11.558339853Z","rtype":160,"publisher_id":101,"instrument_id":33290},"action":"R","side":"N","price":null,"size":0,"channel_id":79,"order_id":"0","flags":128,"ts_in_delta":1456,"sequence":2,"symbol":"EUCO SI 20260612 PS EU P 1.1875 0"}
{"ts_recv":"2026-04-06T18:53:11.558341309Z","hd":{"ts_event":"2026-04-06T18:53:11.558339853Z","rtype":160,"publisher_id":101,"instrument_id":33289},"action":"R","side":"N","price":null,"size":0,"channel_id":79,"order_id":"0","flags":128,"ts_in_delta":1456,"sequence":2,"symbol":"EUCO SI 20260612 PS EU C 1.1875 0"}
{"ts_recv":"2026-04-06T18:53:11.558341309Z","hd":{"ts_event":"2026-04-06T18:53:11.558339853Z","rtype":160,"publisher_id":101,"instrument_id":33288},"action":"R","side":"N","price":null,"size":0,"channel_id":79,"order_id":"0","flags":128,"ts_in_delta":1456,"sequence":2,"symbol":"EUCO SI 20260612 PS EU P 1.1850 0"}
{"ts_recv":"2026-04-06T18:53:11.558341309Z","hd":{"ts_event":"2026-04-06T18:53:11.558339853Z","rtype":160,"publisher_id":101,"instrument_id":33287},"action":"R","side":"N","price":null,"size":0,"channel_id":79,"order_id":"0","flags":128,"ts_in_delta":1456,"sequence":2,"symbol":"EUCO SI 20260612 PS EU C 1.1850 0"}
{"ts_recv":"2026-04-06T18:53:11.558341309Z","hd":{"ts_event":"2026-04-06T18:53:11.558339853Z","rtype":160,"publisher_id":101,"instrument_id":33286},"action":"R","side":"N","price":null,"size":0,"channel_id":79,"order_id":"0","flags":128,"ts_in_delta":1456,"sequence":2,"symbol":"EUCO SI 20260612 PS EU P 1.1825 0"}
{"ts_recv":"2026-04-06T18:53:11.558341309Z","hd":{"ts_event":"2026-04-06T18:53:11.558339853Z","rtype":160,"publisher_id":101,"instrument_id":33285},"action":"R","side":"N","price":null,"size":0,"channel_id":79,"order_id":"0","flags":128,"ts_in_delta":1456,"sequence":2,"symbol":"EUCO SI 20260612 PS EU C 1.1825 0"}
{"ts_recv":"2026-04-06T18:53:11.558341309Z","hd":{"ts_event":"2026-04-06T18:53:11.558339853Z","rtype":160,"publisher_id":101,"instrument_id":33284},"action":"R","side":"N","price":null,"size":0,"channel_id":79,"order_id":"0","flags":128,"ts_in_delta":1456,"sequence":2,"symbol":"EUCO SI 20260612 PS EU P 1.1800 0"}
{"ts_recv":"2026-04-06T18:53:11.558341309Z","hd":{"ts_event":"2026-04-06T18:53:11.558339853Z","rtype":160,"publisher_id":101,"instrument_id":33283},"action":"R","side":"N","price":null,"size":0,"channel_id":79,"order_id":"0","flags":128,"ts_in_delta":1456,"sequence":2,"symbol":"EUCO SI 20260612 PS EU C 1.1800 0"}
{"ts_recv":"2026-04-06T18:53:11.558341309Z","hd":{"ts_event":"2026-04-06T18:53:11.558339853Z","rtype":160,"publisher_id":101,"instrument_id":33282},"action":"R","side":"N","price":null,"size":0,"channel_id":79,"order_id":"0","flags":128,"ts_in_delta":1456,"sequence":2,"symbol":"EUCO SI 20260612 PS EU P 1.1775 0"}
{"ts_recv":"2026-04-06T18:53:11.558341309Z","hd":{"ts_event":"2026-04-06T18:53:11.558339853Z","rtype":160,"publisher_id":101,"instrument_id":33281},"action":"R","side":"N","price":null,"size":0,"channel_id":79,"order_id":"0","flags":128,"ts_in_delta":1456,"sequence":2,"symbol":"EUCO SI 20260612 PS EU C 1.1775 0"}
{"ts_recv":"2026-04-06T18:53:11.558341309Z","hd":{"ts_event":"2026-04-06T18:53:11.558339853Z","rtype":160,"publisher_id":101,"instrument_id":33280},"action":"R","side":"N","price":null,"size":0,"channel_id":79,"order_id":"0","flags":128,"ts_in_delta":1456,"sequence":2,"symbol":"EUCO SI 20260612 PS EU P 1.1750 0"}
{"ts_recv":"2026-04-06T18:53:11.558341309Z","hd":{"ts_event":"2026-04-06T18:53:11.558339853Z","rtype":160,"publisher_id":101,"instrument_id":33279},"action":"R","side":"N","price":null,"size":0,"channel_id":79,"order_id":"0","flags":128,"ts_in_delta":1456,"sequence":2,"symbol":"EUCO SI 20260612 PS EU C 1.1750 0"}
{"ts_recv":"2026-04-06T18:53:11.558341309Z","hd":{"ts_event":"2026-04-06T18:53:11.558339853Z","rtype":160,"publisher_id":101,"instrument_id":33278},"action":"R","side":"N","price":null,"size":0,"channel_id":79,"order_id":"0","flags":128,"ts_in_delta":1456,"sequence":2,"symbol":"EUCO SI 20260612 PS EU P 1.1725 0"}
{"ts_recv":"2026-04-06T18:53:11.558341309Z","hd":{"ts_event":"2026-04-06T18:53:11.558339853Z","rtype":160,"publisher_id":101,"instrument_id":33277},"action":"R","side":"N","price":null,"size":0,"channel_id":79,"order_id":"0","flags":128,"ts_in_delta":1456,"sequence":2,"symbol":"EUCO SI 20260612 PS EU C 1.1725 0"}
{"ts_recv":"2026-04-06T18:53:11.558341309Z","hd":{"ts_event":"2026-04-06T18:53:11.558339853Z","rtype":160,"publisher_id":101,"instrument_id":33276},"action":"R","side":"N","price":null,"size":0,"channel_id":79,"order_id":"0","flags":128,"ts_in_delta":1456,"sequence":2,"symbol":"EUCO SI 20260612 PS EU P 1.1700 0"}
{"ts_recv":"2026-04-06T18:53:11.558341309Z","hd":{"ts_event":"2026-04-06T18:53:11.558339853Z","rtype":160,"publisher_id":101,"instrument_id":33275},"action":"R","side":"N","price":null,"size":0,"channel_id":79,"order_id":"0","flags":128,"ts_in_delta":1456,"sequence":2,"symbol":"EUCO SI 20260612 PS EU C 1.1700 0"}
{"ts_recv":"2026-04-06T18:53:11.558341309Z","hd":{"ts_event":"2026-04-06T18:53:11.558339853Z","rtype":160,"publisher_id":101,"instrument_id":33274},"action":"R","side":"N","price":null,"size":0,"channel_id":79,"order_id":"0","flags":128,"ts_in_delta":1456,"sequence":2,"symbol":"EUCO SI 20260612 PS EU P 1.1675 0"}
{"ts_recv":"2026-04-06T18:53:11.558341309Z","hd":{"ts_event":"2026-04-06T18:53:11.558339853Z","rtype":160,"publisher_id":101,"instrument_id":33273},"action":"R","side":"N","price":null,"size":0,"channel_id":79,"order_id":"0","flags":128,"ts_in_delta":1456,"sequence":2,"symbol":"EUCO SI 20260612 PS EU C 1.1675 0"}
{"ts_recv":"2026-04-06T18:53:11.558341309Z","hd":{"ts_event":"2026-04-06T18:53:11.558339853Z","rtype":160,"publisher_id":101,"instrument_id":33272},"action":"R","side":"N","price":null,"size":0,"channel_id":79,"order_id":"0","flags":128,"ts_in_delta":1456,"sequence":2,"symbol":"EUCO SI 20260612 PS EU P 1.1650 0"}
{"ts_recv":"2026-04-06T18:53:11.558341309Z","hd":{"ts_event":"2026-04-06T18:53:11.558339853Z","rtype":160,"publisher_id":101,"instrument_id":33271},"action":"R","side":"N","price":null,"size":0,"channel_id":79,"order_id":"0","flags":128,"ts_in_delta":1456,"sequence":2,"symbol":"EUCO SI 20260612 PS EU C 1.1650 0"}
{"ts_recv":"2026-04-06T18:53:11.558341309Z","hd":{"ts_event":"2026-04-06T18:53:11.558339853Z","rtype":160,"publisher_id":101,"instrument_id":33270},"action":"R","side":"N","price":null,"size":0,"channel_id":79,"order_id":"0","flags":128,"ts_in_delta":1456,"sequence":2,"symbol":"EUCO SI 20260612 PS EU P 1.1625 0"}
{"ts_recv":"2026-04-06T18:53:11.558341309Z","hd":{"ts_event":"2026-04-06T18:53:11.558339853Z","rtype":160,"publisher_id":101,"instrument_id":33269},"action":"R","side":"N","price":null,"size":0,"channel_id":79,"order_id":"0","flags":128,"ts_in_delta":1456,"sequence":2,"symbol":"EUCO SI 20260612 PS EU C 1.1625 0"}
{"ts_recv":"2026-04-06T18:53:11.558341309Z","hd":{"ts_event":"2026-04-06T18:53:11.558339853Z","rtype":160,"publisher_id":101,"instrument_id":33268},"action":"R","side":"N","price":null,"size":0,"channel_id":79,"order_id":"0","flags":128,"ts_in_delta":1456,"sequence":2,"symbol":"EUCO SI 20260612 PS EU P 1.1600 0"}
{"ts_recv":"2026-04-06T18:53:11.558341309Z","hd":{"ts_event":"2026-04-06T18:53:11.558339853Z","rtype":160,"publisher_id":101,"instrument_id":33267},"action":"R","side":"N","price":null,"size":0,"channel_id":79,"order_id":"0","flags":128,"ts_in_delta":1456,"sequence":2,"symbol":"EUCO SI 20260612 PS EU C 1.1600 0"}
{"ts_recv":"2026-04-06T18:53:11.558341309Z","hd":{"ts_event":"2026-04-06T18:53:11.558339853Z","rtype":160,"publisher_id":101,"instrument_id":33266},"action":"R","side":"N","price":null,"size":0,"channel_id":79,"order_id":"0","flags":128,"ts_in_delta":1456,"sequence":2,"symbol":"EUCO SI 20260612 PS EU P 1.1575 0"}
{"ts_recv":"2026-04-06T18:53:11.558341309Z","hd":{"ts_event":"2026-04-06T18:53:11.558339853Z","rtype":160,"publisher_id":101,"instrument_id":33265},"action":"R","side":"N","price":null,"size":0,"channel_id":79,"order_id":"0","flags":128,"ts_in_delta":1456,"sequence":2,"symbol":"EUCO SI 20260612 PS EU C 1.1575 0"}
{"ts_recv":"2026-04-06T18:53:11.558341309Z","hd":{"ts_event":"2026-04-06T18:53:11.558339853Z","rtype":160,"publisher_id":101,"instrument_id":33264},"action":"R","side":"N","price":null,"size":0,"channel_id":79,"order_id":"0","flags":128,"ts_in_delta":1456,"sequence":2,"symbol":"EUCO SI 20260612 PS EU P 1.1550 0"}
{"ts_recv":"2026-04-06T18:53:11.558341309Z","hd":{"ts_event":"2026-04-06T18:53:11.558339853Z","rtype":160,"publisher_id":101,"instrument_id":33263},"action":"R","side":"N","price":null,"size":0,"channel_id":79,"order_id":"0","flags":128,"ts_in_delta":1456,"sequence":2,"symbol":"EUCO SI 20260612 PS EU C 1.1550 0"}
{"ts_recv":"2026-04-06T18:53:11.558341309Z","hd":{"ts_event":"2026-04-06T18:53:11.558339853Z","rtype":160,"publisher_id":101,"instrument_id":33262},"action":"R","side":"N","price":null,"size":0,"channel_id":79,"order_id":"0","flags":128,"ts_in_delta":1456,"sequence":2,"symbol":"EUCO SI 20260612 PS EU P 1.1525 0"}
{"ts_recv":"2026-04-06T18:53:11.558341309Z","hd":{"ts_event":"2026-04-06T18:53:11.558339853Z","rtype":160,"publisher_id":101,"instrument_id":33261},"action":"R","side":"N","price":null,"size":0,"channel_id":79,"order_id":"0","flags":128,"ts_in_delta":1456,"sequence":2,"symbol":"EUCO SI 20260612 PS EU C 1.1525 0"}
{"ts_recv":"2026-04-06T18:53:11.558341309Z","hd":{"ts_event":"2026-04-06T18:53:11.558339853Z","rtype":160,"publisher_id":101,"instrument_id":33260},"action":"R","side":"N","price":null,"size":0,"channel_id":79,"order_id":"0","flags":128,"ts_in_delta":1456,"sequence":2,"symbol":"EUCO SI 20260612 PS EU P 1.1500 0"}
{"ts_recv":"2026-04-06T18:53:11.558341309Z","hd":{"ts_event":"2026-04-06T18:53:11.558339853Z","rtype":160,"publisher_id":101,"instrument_id":33259},"action":"R","side":"N","price":null,"size":0,"channel_id":79,"order_id":"0","flags":128,"ts_in_delta":1456,"sequence":2,"symbol":"EUCO SI 20260612 PS EU C 1.1500 0"}
{"ts_recv":"2026-04-06T18:53:11.558341309Z","hd":{"ts_event":"2026-04-06T18:53:11.558339853Z","rtype":160,"publisher_id":101,"instrument_id":33258},"action":"R","side":"N","price":null,"size":0,"channel_id":79,"order_id":"0","flags":128,"ts_in_delta":1456,"sequence":2,"symbol":"EUCO SI 20260612 PS EU P 1.1475 0"}
{"ts_recv":"2026-04-06T18:53:11.558341309Z","hd":{"ts_event":"2026-04-06T18:53:11.558339853Z","rtype":160,"publisher_id":101,"instrument_id":33257},"action":"R","side":"N","price":null,"size":0,"channel_id":79,"order_id":"0","flags":128,"ts_in_delta":1456,"sequence":2,"symbol":"EUCO SI 20260612 PS EU C 1.1475 0"}
{"ts_recv":"2026-04-06T18:53:11.558341309Z","hd":{"ts_event":"2026-04-06T18:53:11.558339853Z","rtype":160,"publisher_id":101,"instrument_id":33256},"action":"R","side":"N","price":null,"size":0,"channel_id":79,"order_id":"0","flags":128,"ts_in_delta":1456,"sequence":2,"symbol":"EUCO SI 20260612 PS EU P 1.1450 0"}
{"ts_recv":"2026-04-06T18:53:11.558341309Z","hd":{"ts_event":"2026-04-06T18:53:11.558339853Z","rtype":160,"publisher_id":101,"instrument_id":33255},"action":"R","side":"N","price":null,"size":0,"channel_id":79,"order_id":"0","flags":128,"ts_in_delta":1456,"sequence":2,"symbol":"EUCO SI 20260612 PS EU C 1.1450 0"}
{"ts_recv":"2026-04-06T18:53:11.558341309Z","hd":{"ts_event":"2026-04-06T18:53:11.558339853Z","rtype":160,"publisher_id":101,"instrument_id":33254},"action":"R","side":"N","price":null,"size":0,"channel_id":79,"order_id":"0","flags":128,"ts_in_delta":1456,"sequence":2,"symbol":"EUCO SI 20260612 PS EU P 1.1425 0"}
{"ts_recv":"2026-04-06T18:53:11.558341309Z","hd":{"ts_event":"2026-04-06T18:53:11.558339853Z","rtype":160,"publisher_id":101,"instrument_id":33253},"action":"R","side":"N","price":null,"size":0,"channel_id":79,"order_id":"0","flags":128,"ts_in_delta":1456,"sequence":2,"symbol":"EUCO SI 20260612 PS EU C 1.1425 0"}
{"ts_recv":"2026-04-06T18:53:11.558341309Z","hd":{"ts_event":"2026-04-06T18:53:11.558339853Z","rtype":160,"publisher_id":101,"instrument_id":33252},"action":"R","side":"N","price":null,"size":0,"channel_id":79,"order_id":"0","flags":128,"ts_in_delta":1456,"sequence":2,"symbol":"EUCO SI 20260612 PS EU P 1.1400 0"}
{"ts_recv":"2026-04-06T18:53:11.558341309Z","hd":{"ts_event":"2026-04-06T18:53:11.558339853Z","rtype":160,"publisher_id":101,"instrument_id":33251},"action":"R","side":"N","price":null,"size":0,"channel_id":79,"order_id":"0","flags":128,"ts_in_delta":1456,"sequence":2,"symbol":"EUCO SI 20260612 PS EU C 1.1400 0"}
{"ts_recv":"2026-04-06T18:53:11.558341309Z","hd":{"ts_event":"2026-04-06T18:53:11.558339853Z","rtype":160,"publisher_id":101,"instrument_id":33250},"action":"R","side":"N","price":null,"size":0,"channel_id":79,"order_id":"0","flags":128,"ts_in_delta":1456,"sequence":2,"symbol":"EUCO SI 20260612 PS EU P 1.1375 0"}
{"ts_recv":"2026-04-06T18:53:11.558341309Z","hd":{"ts_event":"2026-04-06T18:53:11.558339853Z","rtype":160,"publisher_id":101,"instrument_id":33249},"action":"R","side":"N","price":null,"size":0,"channel_id":79,"order_id":"0","flags":128,"ts_in_delta":1456,"sequence":2,"symbol":"EUCO SI 20260612 PS EU C 1.1375 0"}
{"ts_recv":"2026-04-06T18:53:11.558341309Z","hd":{"ts_event":"2026-04-06T18:53:11.558339853Z","rtype":160,"publisher_id":101,"instrument_id":33248},"action":"R","side":"N","price":null,"size":0,"channel_id":79,"order_id":"0","flags":128,"ts_in_delta":1456,"sequence":2,"symbol":"EUCO SI 20260612 PS EU P 1.1350 0"}
{"ts_recv":"2026-04-06T18:53:11.558341309Z","hd":{"ts_event":"2026-04-06T18:53:11.558339853Z","rtype":160,"publisher_id":101,"instrument_id":33247},"action":"R","side":"N","price":null,"size":0,"channel_id":79,"order_id":"0","flags":128,"ts_in_delta":1456,"sequence":2,"symbol":"EUCO SI 20260612 PS EU C 1.1350 0"}
{"ts_recv":"2026-04-06T18:53:11.558341309Z","hd":{"ts_event":"2026-04-06T18:53:11.558339853Z","rtype":160,"publisher_id":101,"instrument_id":33246},"action":"R","side":"N","price":null,"size":0,"channel_id":79,"order_id":"0","flags":128,"ts_in_delta":1456,"sequence":2,"symbol":"EUCO SI 20260612 PS EU P 1.1325 0"}
{"ts_recv":"2026-04-06T18:53:11.558341309Z","hd":{"ts_event":"2026-04-06T18:53:11.558339853Z","rtype":160,"publisher_id":101,"instrument_id":33245},"action":"R","side":"N","price":null,"size":0,"channel_id":79,"order_id":"0","flags":128,"ts_in_delta":1456,"sequence":2,"symbol":"EUCO SI 20260612 PS EU C 1.1325 0"}
{"ts_recv":"2026-04-06T18:53:11.558341309Z","hd":{"ts_event":"2026-04-06T18:53:11.558339853Z","rtype":160,"publisher_id":101,"instrument_id":33244},"action":"R","side":"N","price":null,"size":0,"channel_id":79,"order_id":"0","flags":128,"ts_in_delta":1456,"sequence":2,"symbol":"EUCO SI 20260612 PS EU P 1.1300 0"}
{"ts_recv":"2026-04-06T18:53:11.558341309Z","hd":{"ts_event":"2026-04-06T18:53:11.558339853Z","rtype":160,"publisher_id":101,"instrument_id":33243},"action":"R","side":"N","price":null,"size":0,"channel_id":79,"order_id":"0","flags":128,"ts_in_delta":1456,"sequence":2,"symbol":"EUCO SI 20260612 PS EU C 1.1300 0"}
{"ts_recv":"2026-04-06T18:53:11.558341309Z","hd":{"ts_event":"2026-04-06T18:53:11.558339853Z","rtype":160,"publisher_id":101,"instrument_id":33242},"action":"R","side":"N","price":null,"size":0,"channel_id":79,"order_id":"0","flags":128,"ts_in_delta":1456,"sequence":2,"symbol":"EUCO SI 20260612 PS EU P 1.1275 0"}
{"ts_recv":"2026-04-06T18:53:11.558341309Z","hd":{"ts_event":"2026-04-06T18:53:11.558339853Z","rtype":160,"publisher_id":101,"instrument_id":33241},"action":"R","side":"N","price":null,"size":0,"channel_id":79,"order_id":"0","flags":128,"ts_in_delta":1456,"sequence":2,"symbol":"EUCO SI 20260612 PS EU C 1.1275 0"}
{"ts_recv":"2026-04-06T18:53:11.558341309Z","hd":{"ts_event":"2026-04-06T18:53:11.558339853Z","rtype":160,"publisher_id":101,"instrument_id":33240},"action":"R","side":"N","price":null,"size":0,"channel_id":79,"order_id":"0","flags":128,"ts_in_delta":1456,"sequence":2,"symbol":"EUCO SI 20260612 PS EU P 1.1250 0"}
{"ts_recv":"2026-04-06T18:53:11.558341309Z","hd":{"ts_event":"2026-04-06T18:53:11.558339853Z","rtype":160,"publisher_id":101,"instrument_id":33239},"action":"R","side":"N","price":null,"size":0,"channel_id":79,"order_id":"0","flags":128,"ts_in_delta":1456,"sequence":2,"symbol":"EUCO SI 20260612 PS EU C 1.1250 0"}
{"ts_recv":"2026-04-06T18:53:11.558341309Z","hd":{"ts_event":"2026-04-06T18:53:11.558339853Z","rtype":160,"publisher_id":101,"instrument_id":33238},"action":"R","side":"N","price":null,"size":0,"channel_id":79,"order_id":"0","flags":128,"ts_in_delta":1456,"sequence":2,"symbol":"EUCO SI 20260612 PS EU P 1.1200 0"}
{"ts_recv":"2026-04-06T18:53:11.558341309Z","hd":{"ts_event":"2026-04-06T18:53:11.558339853Z","rtype":160,"publisher_id":101,"instrument_id":33237},"action":"R","side":"N","price":null,"size":0,"channel_id":79,"order_id":"0","flags":128,"ts_in_delta":1456,"sequence":2,"symbol":"EUCO SI 20260612 PS EU C 1.1200 0"}
{"ts_recv":"2026-04-06T18:53:11.558341309Z","hd":{"ts_event":"2026-04-06T18:53:11.558339853Z","rtype":160,"publisher_id":101,"instrument_id":33236},"action":"R","side":"N","price":null,"size":0,"channel_id":79,"order_id":"0","flags":128,"ts_in_delta":1456,"sequence":2,"symbol":"EUCO SI 20260612 PS EU P 1.1150 0"}
{"ts_recv":"2026-04-06T18:53:11.558341309Z","hd":{"ts_event":"2026-04-06T18:53:11.558339853Z","rtype":160,"publisher_id":101,"instrument_id":33235},"action":"R","side":"N","price":null,"size":0,"channel_id":79,"order_id":"0","flags":128,"ts_in_delta":1456,"sequence":2,"symbol":"EUCO SI 20260612 PS EU C 1.1150 0"}
{"ts_recv":"2026-04-06T18:53:11.558341309Z","hd":{"ts_event":"2026-04-06T18:53:11.558339853Z","rtype":160,"publisher_id":101,"instrument_id":33234},"action":"R","side":"N","price":null,"size":0,"channel_id":79,"order_id":"0","flags":128,"ts_in_delta":1456,"sequence":2,"symbol":"EUCO SI 20260612 PS EU P 1.1100 0"}
{"ts_recv":"2026-04-06T18:53:11.558341309Z","hd":{"ts_event":"2026-04-06T18:53:11.558339853Z","rtype":160,"publisher_id":101,"instrument_id":33233},"action":"R","side":"N","price":null,"size":0,"channel_id":79,"order_id":"0","flags":128,"ts_in_delta":1456,"sequence":2,"symbol":"EUCO SI 20260612 PS EU C 1.1100 0"}
{"ts_recv":"2026-04-06T18:53:11.558341309Z","hd":{"ts_event":"2026-04-06T18:53:11.558339853Z","rtype":160,"publisher_id":101,"instrument_id":33232},"action":"R","side":"N","price":null,"size":0,"channel_id":79,"order_id":"0","flags":128,"ts_in_delta":1456,"sequence":2,"symbol":"EUCO SI 20260508 PS EU P 1.2550 0"}
{"ts_recv":"2026-04-06T18:53:11.558341309Z","hd":{"ts_event":"2026-04-06T18:53:11.558339853Z","rtype":160,"publisher_id":101,"instrument_id":33231},"action":"R","side":"N","price":null,"size":0,"channel_id":79,"order_id":"0","flags":128,"ts_in_delta":1456,"sequence":2,"symbol":"EUCO SI 20260508 PS EU C 1.2550 0"}
{"ts_recv":"2026-04-06T18:53:11.558341309Z","hd":{"ts_event":"2026-04-06T18:53:11.558339853Z","rtype":160,"publisher_id":101,"instrument_id":33230},"action":"R","side":"N","price":null,"size":0,"channel_id":79,"order_id":"0","flags":128,"ts_in_delta":1456,"sequence":2,"symbol":"EUCO SI 20260508 PS EU P 1.2500 0"}
{"ts_recv":"2026-04-06T18:53:11.558341309Z","hd":{"ts_event":"2026-04-06T18:53:11.558339853Z","rtype":160,"publisher_id":101,"instrument_id":33229},"action":"R","side":"N","price":null,"size":0,"channel_id":79,"order_id":"0","flags":128,"ts_in_delta":1456,"sequence":2,"symbol":"EUCO SI 20260508 PS EU C 1.2500 0"}
{"ts_recv":"2026-04-06T18:53:11.558341309Z","hd":{"ts_event":"2026-04-06T18:53:11.558339853Z","rtype":160,"publisher_id":101,"instrument_id":33228},"action":"R","side":"N","price":null,"size":0,"channel_id":79,"order_id":"0","flags":128,"ts_in_delta":1456,"sequence":2,"symbol":"EUCO SI 20260508 PS EU P 1.2450 0"}
{"ts_recv":"2026-04-06T18:53:11.558341309Z","hd":{"ts_event":"2026-04-06T18:53:11.558339853Z","rtype":160,"publisher_id":101,"instrument_id":33227},"action":"R","side":"N","price":null,"size":0,"channel_id":79,"order_id":"0","flags":128,"ts_in_delta":1456,"sequence":2,"symbol":"EUCO SI 20260508 PS EU C 1.2450 0"}
{"ts_recv":"2026-04-06T18:53:11.558341309Z","hd":{"ts_event":"2026-04-06T18:53:11.558339853Z","rtype":160,"publisher_id":101,"instrument_id":33226},"action":"R","side":"N","price":null,"size":0,"channel_id":79,"order_id":"0","flags":128,"ts_in_delta":1456,"sequence":2,"symbol":"EUCO SI 20260508 PS EU P 1.2400 0"}
{"ts_recv":"2026-04-06T18:53:11.558341309Z","hd":{"ts_event":"2026-04-06T18:53:11.558339853Z","rtype":160,"publisher_id":101,"instrument_id":33225},"action":"R","side":"N","price":null,"size":0,"channel_id":79,"order_id":"0","flags":128,"ts_in_delta":1456,"sequence":2,"symbol":"EUCO SI 20260508 PS EU C 1.2400 0"}
{"ts_recv":"2026-04-06T18:53:11.558341309Z","hd":{"ts_event":"2026-04-06T18:53:11.558339853Z","rtype":160,"publisher_id":101,"instrument_id":33224},"action":"R","side":"N","price":null,"size":0,"channel_id":79,"order_id":"0","flags":128,"ts_in_delta":1456,"sequence":2,"symbol":"EUCO SI 20260508 PS EU P 1.2350 0"}
{"ts_recv":"2026-04-06T18:53:11.558341309Z","hd":{"ts_event":"2026-04-06T18:53:11.558339853Z","rtype":160,"publisher_id":101,"instrument_id":33223},"action":"R","side":"N","price":null,"size":0,"channel_id":79,"order_id":"0","flags":128,"ts_in_delta":1456,"sequence":2,"symbol":"EUCO SI 20260508 PS EU C 1.2350 0"}
{"ts_recv":"2026-04-06T18:53:11.558341309Z","hd":{"ts_event":"2026-04-06T18:53:11.558339853Z","rtype":160,"publisher_id":101,"instrument_id":33222},"action":"R","side":"N","price":null,"size":0,"channel_id":79,"order_id":"0","flags":128,"ts_in_delta":1456,"sequence":2,"symbol":"EUCO SI 20260508 PS EU P 1.2300 0"}
{"ts_recv":"2026-04-06T18:53:11.558341309Z","hd":{"ts_event":"2026-04-06T18:53:11.558339853Z","rtype":160,"publisher_id":101,"instrument_id":33221},"action":"R","side":"N","price":null,"size":0,"channel_id":79,"order_id":"0","flags":128,"ts_in_delta":1456,"sequence":2,"symbol":"EUCO SI 20260508 PS EU C 1.2300 0"}
{"ts_recv":"2026-04-06T18:53:11.558341309Z","hd":{"ts_event":"2026-04-06T18:53:11.558339853Z","rtype":160,"publisher_id":101,"instrument_id":33220},"action":"R","side":"N","price":null,"size":0,"channel_id":79,"order_id":"0","flags":128,"ts_in_delta":1456,"sequence":2,"symbol":"EUCO SI 20260508 PS EU P 1.2250 0"}
{"ts_recv":"2026-04-06T18:53:11.558341309Z","hd":{"ts_event":"2026-04-06T18:53:11.558339853Z","rtype":160,"publisher_id":101,"instrument_id":33219},"action":"R","side":"N","price":null,"size":0,"channel_id":79,"order_id":"0","flags":128,"ts_in_delta":1456,"sequence":2,"symbol":"EUCO SI 20260508 PS EU C 1.2250 0"}
{"ts_recv":"2026-04-06T18:53:11.558341309Z","hd":{"ts_event":"2026-04-06T18:53:11.558339853Z","rtype":160,"publisher_id":101,"instrument_id":33218},"action":"R","side":"N","price":null,"size":0,"channel_id":79,"order_id":"0","flags":128,"ts_in_delta":1456,"sequence":2,"symbol":"EUCO SI 20260508 PS EU P 1.2225 0"}
{"ts_recv":"2026-04-06T18:53:11.558341309Z","hd":{"ts_event":"2026-04-06T18:53:11.558339853Z","rtype":160,"publisher_id":101,"instrument_id":33217},"action":"R","side":"N","price":null,"size":0,"channel_id":79,"order_id":"0","flags":128,"ts_in_delta":1456,"sequence":2,"symbol":"EUCO SI 20260508 PS EU C 1.2225 0"}
{"ts_recv":"2026-04-06T18:53:11.558341309Z","hd":{"ts_event":"2026-04-06T18:53:11.558339853Z","rtype":160,"publisher_id":101,"instrument_id":33216},"action":"R","side":"N","price":null,"size":0,"channel_id":79,"order_id":"0","flags":128,"ts_in_delta":1456,"sequence":2,"symbol":"EUCO SI 20260508 PS EU P 1.2200 0"}
{"ts_recv":"2026-04-06T18:53:11.558341309Z","hd":{"ts_event":"2026-04-06T18:53:11.558339853Z","rtype":160,"publisher_id":101,"instrument_id":33215},"action":"R","side":"N","price":null,"size":0,"channel_id":79,"order_id":"0","flags":128,"ts_in_delta":1456,"sequence":2,"symbol":"EUCO SI 20260508 PS EU C 1.2200 0"}
{"ts_recv":"2026-04-06T18:53:11.558341309Z","hd":{"ts_event":"2026-04-06T18:53:11.558339853Z","rtype":160,"publisher_id":101,"instrument_id":33214},"action":"R","side":"N","price":null,"size":0,"channel_id":79,"order_id":"0","flags":128,"ts_in_delta":1456,"sequence":2,"symbol":"EUCO SI 20260508 PS EU P 1.2175 0"}
{"ts_recv":"2026-04-06T18:53:11.558341309Z","hd":{"ts_event":"2026-04-06T18:53:11.558339853Z","rtype":160,"publisher_id":101,"instrument_id":33213},"action":"R","side":"N","price":null,"size":0,"channel_id":79,"order_id":"0","flags":128,"ts_in_delta":1456,"sequence":2,"symbol":"EUCO SI 20260508 PS EU C 1.2175 0"}
{"ts_recv":"2026-04-06T18:53:11.558341309Z","hd":{"ts_event":"2026-04-06T18:53:11.558339853Z","rtype":160,"publisher_id":101,"instrument_id":33212},"action":"R","side":"N","price":null,"size":0,"channel_id":79,"order_id":"0","flags":128,"ts_in_delta":1456,"sequence":2,"symbol":"EUCO SI 20260508 PS EU P 1.2150 0"}
{"ts_recv":"2026-04-06T18:53:11.558341309Z","hd":{"ts_event":"2026-04-06T18:53:11.558339853Z","rtype":160,"publisher_id":101,"instrument_id":33211},"action":"R","side":"N","price":null,"size":0,"channel_id":79,"order_id":"0","flags":128,"ts_in_delta":1456,"sequence":2,"symbol":"EUCO SI 20260508 PS EU C 1.2150 0"}
{"ts_recv":"2026-04-06T18:53:11.558341309Z","hd":{"ts_event":"2026-04-06T18:53:11.558339853Z","rtype":160,"publisher_id":101,"instrument_id":33210},"action":"R","side":"N","price":null,"size":0,"channel_id":79,"order_id":"0","flags":128,"ts_in_delta":1456,"sequence":2,"symbol":"EUCO SI 20260508 PS EU P 1.2125 0"}
{"ts_recv":"2026-04-06T18:53:11.558341309Z","hd":{"ts_event":"2026-04-06T18:53:11.558339853Z","rtype":160,"publisher_id":101,"instrument_id":33209},"action":"R","side":"N","price":null,"size":0,"channel_id":79,"order_id":"0","flags":128,"ts_in_delta":1456,"sequence":2,"symbol":"EUCO SI 20260508 PS EU C 1.2125 0"}
{"ts_recv":"2026-04-06T18:53:11.558341309Z","hd":{"ts_event":"2026-04-06T18:53:11.558339853Z","rtype":160,"publisher_id":101,"instrument_id":33208},"action":"R","side":"N","price":null,"size":0,"channel_id":79,"order_id":"0","flags":128,"ts_in_delta":1456,"sequence":2,"symbol":"EUCO SI 20260508 PS EU P 1.2100 0"}
{"ts_recv":"2026-04-06T18:53:11.558341309Z","hd":{"ts_event":"2026-04-06T18:53:11.558339853Z","rtype":160,"publisher_id":101,"instrument_id":33207},"action":"R","side":"N","price":null,"size":0,"channel_id":79,"order_id":"0","flags":128,"ts_in_delta":1456,"sequence":2,"symbol":"EUCO SI 20260508 PS EU C 1.2100 0"}
{"ts_recv":"2026-04-06T18:53:11.558341309Z","hd":{"ts_event":"2026-04-06T18:53:11.558339853Z","rtype":160,"publisher_id":101,"instrument_id":33206},"action":"R","side":"N","price":null,"size":0,"channel_id":79,"order_id":"0","flags":128,"ts_in_delta":1456,"sequence":2,"symbol":"EUCO SI 20260508 PS EU P 1.2075 0"}
{"ts_recv":"2026-04-06T18:53:11.558341309Z","hd":{"ts_event":"2026-04-06T18:53:11.558339853Z","rtype":160,"publisher_id":101,"instrument_id":33205},"action":"R","side":"N","price":null,"size":0,"channel_id":79,"order_id":"0","flags":128,"ts_in_delta":1456,"sequence":2,"symbol":"EUCO SI 20260508 PS EU C 1.2075 0"}
{"ts_recv":"2026-04-06T18:53:11.558341309Z","hd":{"ts_event":"2026-04-06T18:53:11.558339853Z","rtype":160,"publisher_id":101,"instrument_id":33204},"action":"R","side":"N","price":null,"size":0,"channel_id":79,"order_id":"0","flags":128,"ts_in_delta":1456,"sequence":2,"symbol":"EUCO SI 20260508 PS EU P 1.2050 0"}
{"ts_recv":"2026-04-06T18:53:11.558341309Z","hd":{"ts_event":"2026-04-06T18:53:11.558339853Z","rtype":160,"publisher_id":101,"instrument_id":33203},"action":"R","side":"N","price":null,"size":0,"channel_id":79,"order_id":"0","flags":128,"ts_in_delta":1456,"sequence":2,"symbol":"EUCO SI 20260508 PS EU C 1.2050 0"}
{"ts_recv":"2026-04-06T18:53:11.558341309Z","hd":{"ts_event":"2026-04-06T18:53:11.558339853Z","rtype":160,"publisher_id":101,"instrument_id":33202},"action":"R","side":"N","price":null,"size":0,"channel_id":79,"order_id":"0","flags":128,"ts_in_delta":1456,"sequence":2,"symbol":"EUCO SI 20260508 PS EU P 1.2025 0"}
{"ts_recv":"2026-04-06T18:53:11.558341309Z","hd":{"ts_event":"2026-04-06T18:53:11.558339853Z","rtype":160,"publisher_id":101,"instrument_id":33201},"action":"R","side":"N","price":null,"size":0,"channel_id":79,"order_id":"0","flags":128,"ts_in_delta":1456,"sequence":2,"symbol":"EUCO SI 20260508 PS EU C 1.2025 0"}
{"ts_recv":"2026-04-06T18:53:11.558341309Z","hd":{"ts_event":"2026-04-06T18:53:11.558339853Z","rtype":160,"publisher_id":101,"instrument_id":33200},"action":"R","side":"N","price":null,"size":0,"channel_id":79,"order_id":"0","flags":128,"ts_in_delta":1456,"sequence":2,"symbol":"EUCO SI 20260508 PS EU P 1.2000 0"}
{"ts_recv":"2026-04-06T18:53:11.558341309Z","hd":{"ts_event":"2026-04-06T18:53:11.558339853Z","rtype":160,"publisher_id":101,"instrument_id":33199},"action":"R","side":"N","price":null,"size":0,"channel_id":79,"order_id":"0","flags":128,"ts_in_delta":1456,"sequence":2,"symbol":"EUCO SI 20260508 PS EU C 1.2000 0"}
{"ts_recv":"2026-04-06T18:53:11.558341309Z","hd":{"ts_event":"2026-04-06T18:53:11.558339853Z","rtype":160,"publisher_id":101,"instrument_id":33198},"action":"R","side":"N","price":null,"size":0,"channel_id":79,"order_id":"0","flags":128,"ts_in_delta":1456,"sequence":2,"symbol":"EUCO SI 20260508 PS EU P 1.1975 0"}
{"ts_recv":"2026-04-06T18:53:11.558341309Z","hd":{"ts_event":"2026-04-06T18:53:11.558339853Z","rtype":160,"publisher_id":101,"instrument_id":33197},"action":"R","side":"N","price":null,"size":0,"channel_id":79,"order_id":"0","flags":128,"ts_in_delta":1456,"sequence":2,"symbol":"EUCO SI 20260508 PS EU C 1.1975 0"}
{"ts_recv":"2026-04-06T18:53:11.558341309Z","hd":{"ts_event":"2026-04-06T18:53:11.558339853Z","rtype":160,"publisher_id":101,"instrument_id":33196},"action":"R","side":"N","price":null,"size":0,"channel_id":79,"order_id":"0","flags":128,"ts_in_delta":1456,"sequence":2,"symbol":"EUCO SI 20260508 PS EU P 1.1950 0"}
{"ts_recv":"2026-04-06T18:53:11.558341309Z","hd":{"ts_event":"2026-04-06T18:53:11.558339853Z","rtype":160,"publisher_id":101,"instrument_id":33195},"action":"R","side":"N","price":null,"size":0,"channel_id":79,"order_id":"0","flags":128,"ts_in_delta":1456,"sequence":2,"symbol":"EUCO SI 20260508 PS EU C 1.1950 0"}
{"ts_recv":"2026-04-06T18:53:11.558341309Z","hd":{"ts_event":"2026-04-06T18:53:11.558339853Z","rtype":160,"publisher_id":101,"instrument_id":33194},"action":"R","side":"N","price":null,"size":0,"channel_id":79,"order_id":"0","flags":128,"ts_in_delta":1456,"sequence":2,"symbol":"EUCO SI 20260508 PS EU P 1.1925 0"}
{"ts_recv":"2026-04-06T18:53:11.558341309Z","hd":{"ts_event":"2026-04-06T18:53:11.558339853Z","rtype":160,"publisher_id":101,"instrument_id":33193},"action":"R","side":"N","price":null,"size":0,"channel_id":79,"order_id":"0","flags":128,"ts_in_delta":1456,"sequence":2,"symbol":"EUCO SI 20260508 PS EU C 1.1925 0"}
{"ts_recv":"2026-04-06T18:53:11.558341309Z","hd":{"ts_event":"2026-04-06T18:53:11.558339853Z","rtype":160,"publisher_id":101,"instrument_id":33192},"action":"R","side":"N","price":null,"size":0,"channel_id":79,"order_id":"0","flags":128,"ts_in_delta":1456,"sequence":2,"symbol":"EUCO SI 20260508 PS EU P 1.1900 0"}
{"ts_recv":"2026-04-06T18:53:11.558341309Z","hd":{"ts_event":"2026-04-06T18:53:11.558339853Z","rtype":160,"publisher_id":101,"instrument_id":33191},"action":"R","side":"N","price":null,"size":0,"channel_id":79,"order_id":"0","flags":128,"ts_in_delta":1456,"sequence":2,"symbol":"EUCO SI 20260508 PS EU C 1.1900 0"}
{"ts_recv":"2026-04-06T18:53:11.558341309Z","hd":{"ts_event":"2026-04-06T18:53:11.558339853Z","rtype":160,"publisher_id":101,"instrument_id":33190},"action":"R","side":"N","price":null,"size":0,"channel_id":79,"order_id":"0","flags":128,"ts_in_delta":1456,"sequence":2,"symbol":"EUCO SI 20260508 PS EU P 1.1875 0"}
{"ts_recv":"2026-04-06T18:53:11.558341309Z","hd":{"ts_event":"2026-04-06T18:53:11.558339853Z","rtype":160,"publisher_id":101,"instrument_id":33189},"action":"R","side":"N","price":null,"size":0,"channel_id":79,"order_id":"0","flags":128,"ts_in_delta":1456,"sequence":2,"symbol":"EUCO SI 20260508 PS EU C 1.1875 0"}
{"ts_recv":"2026-04-06T18:53:11.558341309Z","hd":{"ts_event":"2026-04-06T18:53:11.558339853Z","rtype":160,"publisher_id":101,"instrument_id":33188},"action":"R","side":"N","price":null,"size":0,"channel_id":79,"order_id":"0","flags":128,"ts_in_delta":1456,"sequence":2,"symbol":"EUCO SI 20260508 PS EU P 1.1850 0"}
{"ts_recv":"2026-04-06T18:53:11.558341309Z","hd":{"ts_event":"2026-04-06T18:53:11.558339853Z","rtype":160,"publisher_id":101,"instrument_id":33187},"action":"R","side":"N","price":null,"size":0,"channel_id":79,"order_id":"0","flags":128,"ts_in_delta":1456,"sequence":2,"symbol":"EUCO SI 20260508 PS EU C 1.1850 0"}
{"ts_recv":"2026-04-06T18:53:11.558341309Z","hd":{"ts_event":"2026-04-06T18:53:11.558339853Z","rtype":160,"publisher_id":101,"instrument_id":33186},"action":"R","side":"N","price":null,"size":0,"channel_id":79,"order_id":"0","flags":128,"ts_in_delta":1456,"sequence":2,"symbol":"EUCO SI 20260508 PS EU P 1.1825 0"}
{"ts_recv":"2026-04-06T18:53:11.558341309Z","hd":{"ts_event":"2026-04-06T18:53:11.558339853Z","rtype":160,"publisher_id":101,"instrument_id":33185},"action":"R","side":"N","price":null,"size":0,"channel_id":79,"order_id":"0","flags":128,"ts_in_delta":1456,"sequence":2,"symbol":"EUCO SI 20260508 PS EU C 1.1825 0"}
{"ts_recv":"2026-04-06T18:53:11.558341309Z","hd":{"ts_event":"2026-04-06T18:53:11.558339853Z","rtype":160,"publisher_id":101,"instrument_id":33184},"action":"R","side":"N","price":null,"size":0,"channel_id":79,"order_id":"0","flags":128,"ts_in_delta":1456,"sequence":2,"symbol":"EUCO SI 20260508 PS EU P 1.1800 0"}
{"ts_recv":"2026-04-06T18:53:11.558341309Z","hd":{"ts_event":"2026-04-06T18:53:11.558339853Z","rtype":160,"publisher_id":101,"instrument_id":33183},"action":"R","side":"N","price":null,"size":0,"channel_id":79,"order_id":"0","flags":128,"ts_in_delta":1456,"sequence":2,"symbol":"EUCO SI 20260508 PS EU C 1.1800 0"}
{"ts_recv":"2026-04-06T18:53:11.558341309Z","hd":{"ts_event":"2026-04-06T18:53:11.558339853Z","rtype":160,"publisher_id":101,"instrument_id":33182},"action":"R","side":"N","price":null,"size":0,"channel_id":79,"order_id":"0","flags":128,"ts_in_delta":1456,"sequence":2,"symbol":"EUCO SI 20260508 PS EU P 1.1775 0"}
{"ts_recv":"2026-04-06T18:53:11.558341309Z","hd":{"ts_event":"2026-04-06T18:53:11.558339853Z","rtype":160,"publisher_id":101,"instrument_id":33181},"action":"R","side":"N","price":null,"size":0,"channel_id":79,"order_id":"0","flags":128,"ts_in_delta":1456,"sequence":2,"symbol":"EUCO SI 20260508 PS EU C 1.1775 0"}
{"ts_recv":"2026-04-06T18:53:11.558341309Z","hd":{"ts_event":"2026-04-06T18:53:11.558339853Z","rtype":160,"publisher_id":101,"instrument_id":33180},"action":"R","side":"N","price":null,"size":0,"channel_id":79,"order_id":"0","flags":128,"ts_in_delta":1456,"sequence":2,"symbol":"EUCO SI 20260508 PS EU P 1.1750 0"}
{"ts_recv":"2026-04-06T18:53:11.558341309Z","hd":{"ts_event":"2026-04-06T18:53:11.558339853Z","rtype":160,"publisher_id":101,"instrument_id":33179},"action":"R","side":"N","price":null,"size":0,"channel_id":79,"order_id":"0","flags":128,"ts_in_delta":1456,"sequence":2,"symbol":"EUCO SI 20260508 PS EU C 1.1750 0"}
{"ts_recv":"2026-04-06T18:53:11.558341309Z","hd":{"ts_event":"2026-04-06T18:53:11.558339853Z","rtype":160,"publisher_id":101,"instrument_id":33178},"action":"R","side":"N","price":null,"size":0,"channel_id":79,"order_id":"0","flags":128,"ts_in_delta":1456,"sequence":2,"symbol":"EUCO SI 20260508 PS EU P 1.1725 0"}
{"ts_recv":"2026-04-06T18:53:11.558341309Z","hd":{"ts_event":"2026-04-06T18:53:11.558339853Z","rtype":160,"publisher_id":101,"instrument_id":33177},"action":"R","side":"N","price":null,"size":0,"channel_id":79,"order_id":"0","flags":128,"ts_in_delta":1456,"sequence":2,"symbol":"EUCO SI 20260508 PS EU C 1.1725 0"}
{"ts_recv":"2026-04-06T18:53:11.558341309Z","hd":{"ts_event":"2026-04-06T18:53:11.558339853Z","rtype":160,"publisher_id":101,"instrument_id":33176},"action":"R","side":"N","price":null,"size":0,"channel_id":79,"order_id":"0","flags":128,"ts_in_delta":1456,"sequence":2,"symbol":"EUCO SI 20260508 PS EU P 1.1700 0"}
{"ts_recv":"2026-04-06T18:53:11.558341309Z","hd":{"ts_event":"2026-04-06T18:53:11.558339853Z","rtype":160,"publisher_id":101,"instrument_id":33175},"action":"R","side":"N","price":null,"size":0,"channel_id":79,"order_id":"0","flags":128,"ts_in_delta":1456,"sequence":2,"symbol":"EUCO SI 20260508 PS EU C 1.1700 0"}
{"ts_recv":"2026-04-06T18:53:11.558341309Z","hd":{"ts_event":"2026-04-06T18:53:11.558339853Z","rtype":160,"publisher_id":101,"instrument_id":33174},"action":"R","side":"N","price":null,"size":0,"channel_id":79,"order_id":"0","flags":128,"ts_in_delta":1456,"sequence":2,"symbol":"EUCO SI 20260508 PS EU P 1.1675 0"}
{"ts_recv":"2026-04-06T18:53:11.558341309Z","hd":{"ts_event":"2026-04-06T18:53:11.558339853Z","rtype":160,"publisher_id":101,"instrument_id":33173},"action":"R","side":"N","price":null,"size":0,"channel_id":79,"order_id":"0","flags":128,"ts_in_delta":1456,"sequence":2,"symbol":"EUCO SI 20260508 PS EU C 1.1675 0"}
{"ts_recv":"2026-04-06T18:53:11.558341309Z","hd":{"ts_event":"2026-04-06T18:53:11.558339853Z","rtype":160,"publisher_id":101,"instrument_id":33172},"action":"R","side":"N","price":null,"size":0,"channel_id":79,"order_id":"0","flags":128,"ts_in_delta":1456,"sequence":2,"symbol":"EUCO SI 20260508 PS EU P 1.1650 0"}
{"ts_recv":"2026-04-06T18:53:11.558341309Z","hd":{"ts_event":"2026-04-06T18:53:11.558339853Z","rtype":160,"publisher_id":101,"instrument_id":33171},"action":"R","side":"N","price":null,"size":0,"channel_id":79,"order_id":"0","flags":128,"ts_in_delta":1456,"sequence":2,"symbol":"EUCO SI 20260508 PS EU C 1.1650 0"}
{"ts_recv":"2026-04-06T18:53:11.558341309Z","hd":{"ts_event":"2026-04-06T18:53:11.558339853Z","rtype":160,"publisher_id":101,"instrument_id":33170},"action":"R","side":"N","price":null,"size":0,"channel_id":79,"order_id":"0","flags":128,"ts_in_delta":1456,"sequence":2,"symbol":"EUCO SI 20260508 PS EU P 1.1625 0"}
{"ts_recv":"2026-04-06T18:53:11.558341309Z","hd":{"ts_event":"2026-04-06T18:53:11.558339853Z","rtype":160,"publisher_id":101,"instrument_id":33169},"action":"R","side":"N","price":null,"size":0,"channel_id":79,"order_id":"0","flags":128,"ts_in_delta":1456,"sequence":2,"symbol":"EUCO SI 20260508 PS EU C 1.1625 0"}
{"ts_recv":"2026-04-06T18:53:11.558341309Z","hd":{"ts_event":"2026-04-06T18:53:11.558339853Z","rtype":160,"publisher_id":101,"instrument_id":33168},"action":"R","side":"N","price":null,"size":0,"channel_id":79,"order_id":"0","flags":128,"ts_in_delta":1456,"sequence":2,"symbol":"EUCO SI 20260508 PS EU P 1.1600 0"}
{"ts_recv":"2026-04-06T18:53:11.558341309Z","hd":{"ts_event":"2026-04-06T18:53:11.558339853Z","rtype":160,"publisher_id":101,"instrument_id":33167},"action":"R","side":"N","price":null,"size":0,"channel_id":79,"order_id":"0","flags":128,"ts_in_delta":1456,"sequence":2,"symbol":"EUCO SI 20260508 PS EU C 1.1600 0"}
{"ts_recv":"2026-04-06T18:53:11.558341309Z","hd":{"ts_event":"2026-04-06T18:53:11.558339853Z","rtype":160,"publisher_id":101,"instrument_id":33166},"action":"R","side":"N","price":null,"size":0,"channel_id":79,"order_id":"0","flags":128,"ts_in_delta":1456,"sequence":2,"symbol":"EUCO SI 20260508 PS EU P 1.1575 0"}
{"ts_recv":"2026-04-06T18:53:11.558341309Z","hd":{"ts_event":"2026-04-06T18:53:11.558339853Z","rtype":160,"publisher_id":101,"instrument_id":33165},"action":"R","side":"N","price":null,"size":0,"channel_id":79,"order_id":"0","flags":128,"ts_in_delta":1456,"sequence":2,"symbol":"EUCO SI 20260508 PS EU C 1.1575 0"}
{"ts_recv":"2026-04-06T18:53:11.558341309Z","hd":{"ts_event":"2026-04-06T18:53:11.558339853Z","rtype":160,"publisher_id":101,"instrument_id":33164},"action":"R","side":"N","price":null,"size":0,"channel_id":79,"order_id":"0","flags":128,"ts_in_delta":1456,"sequence":2,"symbol":"EUCO SI 20260508 PS EU P 1.1550 0"}
{"ts_recv":"2026-04-06T18:53:11.558341309Z","hd":{"ts_event":"2026-04-06T18:53:11.558339853Z","rtype":160,"publisher_id":101,"instrument_id":33163},"action":"R","side":"N","price":null,"size":0,"channel_id":79,"order_id":"0","flags":128,"ts_in_delta":1456,"sequence":2,"symbol":"EUCO SI 20260508 PS EU C 1.1550 0"}
{"ts_recv":"2026-04-06T18:53:11.558341309Z","hd":{"ts_event":"2026-04-06T18:53:11.558339853Z","rtype":160,"publisher_id":101,"instrument_id":33162},"action":"R","side":"N","price":null,"size":0,"channel_id":79,"order_id":"0","flags":128,"ts_in_delta":1456,"sequence":2,"symbol":"EUCO SI 20260508 PS EU P 1.1525 0"}
{"ts_recv":"2026-04-06T18:53:11.558341309Z","hd":{"ts_event":"2026-04-06T18:53:11.558339853Z","rtype":160,"publisher_id":101,"instrument_id":33161},"action":"R","side":"N","price":null,"size":0,"channel_id":79,"order_id":"0","flags":128,"ts_in_delta":1456,"sequence":2,"symbol":"EUCO SI 20260508 PS EU C 1.1525 0"}
{"ts_recv":"2026-04-06T18:53:11.558341309Z","hd":{"ts_event":"2026-04-06T18:53:11.558339853Z","rtype":160,"publisher_id":101,"instrument_id":33160},"action":"R","side":"N","price":null,"size":0,"channel_id":79,"order_id":"0","flags":128,"ts_in_delta":1456,"sequence":2,"symbol":"EUCO SI 20260508 PS EU P 1.1500 0"}
{"ts_recv":"2026-04-06T18:53:11.558341309Z","hd":{"ts_event":"2026-04-06T18:53:11.558339853Z","rtype":160,"publisher_id":101,"instrument_id":33159},"action":"R","side":"N","price":null,"size":0,"channel_id":79,"order_id":"0","flags":128,"ts_in_delta":1456,"sequence":2,"symbol":"EUCO SI 20260508 PS EU C 1.1500 0"}
{"ts_recv":"2026-04-06T18:53:11.558341309Z","hd":{"ts_event":"2026-04-06T18:53:11.558339853Z","rtype":160,"publisher_id":101,"instrument_id":33158},"action":"R","side":"N","price":null,"size":0,"channel_id":79,"order_id":"0","flags":128,"ts_in_delta":1456,"sequence":2,"symbol":"EUCO SI 20260508 PS EU P 1.1475 0"}
{"ts_recv":"2026-04-06T18:53:11.558341309Z","hd":{"ts_event":"2026-04-06T18:53:11.558339853Z","rtype":160,"publisher_id":101,"instrument_id":33157},"action":"R","side":"N","price":null,"size":0,"channel_id":79,"order_id":"0","flags":128,"ts_in_delta":1456,"sequence":2,"symbol":"EUCO SI 20260508 PS EU C 1.1475 0"}
{"ts_recv":"2026-04-06T18:53:11.558341309Z","hd":{"ts_event":"2026-04-06T18:53:11.558339853Z","rtype":160,"publisher_id":101,"instrument_id":33156},"action":"R","side":"N","price":null,"size":0,"channel_id":79,"order_id":"0","flags":128,"ts_in_delta":1456,"sequence":2,"symbol":"EUCO SI 20260508 PS EU P 1.1450 0"}
{"ts_recv":"2026-04-06T18:53:11.558341309Z","hd":{"ts_event":"2026-04-06T18:53:11.558339853Z","rtype":160,"publisher_id":101,"instrument_id":33155},"action":"R","side":"N","price":null,"size":0,"channel_id":79,"order_id":"0","flags":128,"ts_in_delta":1456,"sequence":2,"symbol":"EUCO SI 20260508 PS EU C 1.1450 0"}
{"ts_recv":"2026-04-06T18:53:11.558341309Z","hd":{"ts_event":"2026-04-06T18:53:11.558339853Z","rtype":160,"publisher_id":101,"instrument_id":33154},"action":"R","side":"N","price":null,"size":0,"channel_id":79,"order_id":"0","flags":128,"ts_in_delta":1456,"sequence":2,"symbol":"EUCO SI 20260508 PS EU P 1.1425 0"}
{"ts_recv":"2026-04-06T18:53:11.558341309Z","hd":{"ts_event":"2026-04-06T18:53:11.558339853Z","rtype":160,"publisher_id":101,"instrument_id":33153},"action":"R","side":"N","price":null,"size":0,"channel_id":79,"order_id":"0","flags":128,"ts_in_delta":1456,"sequence":2,"symbol":"EUCO SI 20260508 PS EU C 1.1425 0"}
{"ts_recv":"2026-04-06T18:53:11.558341309Z","hd":{"ts_event":"2026-04-06T18:53:11.558339853Z","rtype":160,"publisher_id":101,"instrument_id":33152},"action":"R","side":"N","price":null,"size":0,"channel_id":79,"order_id":"0","flags":128,"ts_in_delta":1456,"sequence":2,"symbol":"EUCO SI 20260508 PS EU P 1.1400 0"}
{"ts_recv":"2026-04-06T18:53:11.558341309Z","hd":{"ts_event":"2026-04-06T18:53:11.558339853Z","rtype":160,"publisher_id":101,"instrument_id":33151},"action":"R","side":"N","price":null,"size":0,"channel_id":79,"order_id":"0","flags":128,"ts_in_delta":1456,"sequence":2,"symbol":"EUCO SI 20260508 PS EU C 1.1400 0"}
{"ts_recv":"2026-04-06T18:53:11.558341309Z","hd":{"ts_event":"2026-04-06T18:53:11.558339853Z","rtype":160,"publisher_id":101,"instrument_id":33150},"action":"R","side":"N","price":null,"size":0,"channel_id":79,"order_id":"0","flags":128,"ts_in_delta":1456,"sequence":2,"symbol":"EUCO SI 20260508 PS EU P 1.1375 0"}
{"ts_recv":"2026-04-06T18:53:11.558341309Z","hd":{"ts_event":"2026-04-06T18:53:11.558339853Z","rtype":160,"publisher_id":101,"instrument_id":33149},"action":"R","side":"N","price":null,"size":0,"channel_id":79,"order_id":"0","flags":128,"ts_in_delta":1456,"sequence":2,"symbol":"EUCO SI 20260508 PS EU C 1.1375 0"}
{"ts_recv":"2026-04-06T18:53:11.558341309Z","hd":{"ts_event":"2026-04-06T18:53:11.558339853Z","rtype":160,"publisher_id":101,"instrument_id":33148},"action":"R","side":"N","price":null,"size":0,"channel_id":79,"order_id":"0","flags":128,"ts_in_delta":1456,"sequence":2,"symbol":"EUCO SI 20260508 PS EU P 1.1350 0"}
{"ts_recv":"2026-04-06T18:53:11.558341309Z","hd":{"ts_event":"2026-04-06T18:53:11.558339853Z","rtype":160,"publisher_id":101,"instrument_id":33147},"action":"R","side":"N","price":null,"size":0,"channel_id":79,"order_id":"0","flags":128,"ts_in_delta":1456,"sequence":2,"symbol":"EUCO SI 20260508 PS EU C 1.1350 0"}
{"ts_recv":"2026-04-06T18:53:11.558341309Z","hd":{"ts_event":"2026-04-06T18:53:11.558339853Z","rtype":160,"publisher_id":101,"instrument_id":33146},"action":"R","side":"N","price":null,"size":0,"channel_id":79,"order_id":"0","flags":128,"ts_in_delta":1456,"sequence":2,"symbol":"EUCO SI 20260508 PS EU P 1.1325 0"}
{"ts_recv":"2026-04-06T18:53:11.558341309Z","hd":{"ts_event":"2026-04-06T18:53:11.558339853Z","rtype":160,"publisher_id":101,"instrument_id":33145},"action":"R","side":"N","price":null,"size":0,"channel_id":79,"order_id":"0","flags":128,"ts_in_delta":1456,"sequence":2,"symbol":"EUCO SI 20260508 PS EU C 1.1325 0"}
{"ts_recv":"2026-04-06T18:53:11.558341309Z","hd":{"ts_event":"2026-04-06T18:53:11.558339853Z","rtype":160,"publisher_id":101,"instrument_id":33144},"action":"R","side":"N","price":null,"size":0,"channel_id":79,"order_id":"0","flags":128,"ts_in_delta":1456,"sequence":2,"symbol":"EUCO SI 20260508 PS EU P 1.1300 0"}
{"ts_recv":"2026-04-06T18:53:11.558341309Z","hd":{"ts_event":"2026-04-06T18:53:11.558339853Z","rtype":160,"publisher_id":101,"instrument_id":33143},"action":"R","side":"N","price":null,"size":0,"channel_id":79,"order_id":"0","flags":128,"ts_in_delta":1456,"sequence":2,"symbol":"EUCO SI 20260508 PS EU C 1.1300 0"}
{"ts_recv":"2026-04-06T18:53:11.558341309Z","hd":{"ts_event":"2026-04-06T18:53:11.558339853Z","rtype":160,"publisher_id":101,"instrument_id":33142},"action":"R","side":"N","price":null,"size":0,"channel_id":79,"order_id":"0","flags":128,"ts_in_delta":1456,"sequence":2,"symbol":"EUCO SI 20260508 PS EU P 1.1275 0"}
{"ts_recv":"2026-04-06T18:53:11.558341309Z","hd":{"ts_event":"2026-04-06T18:53:11.558339853Z","rtype":160,"publisher_id":101,"instrument_id":33141},"action":"R","side":"N","price":null,"size":0,"channel_id":79,"order_id":"0","flags":128,"ts_in_delta":1456,"sequence":2,"symbol":"EUCO SI 20260508 PS EU C 1.1275 0"}
{"ts_recv":"2026-04-06T18:53:11.558341309Z","hd":{"ts_event":"2026-04-06T18:53:11.558339853Z","rtype":160,"publisher_id":101,"instrument_id":33140},"action":"R","side":"N","price":null,"size":0,"channel_id":79,"order_id":"0","flags":128,"ts_in_delta":1456,"sequence":2,"symbol":"EUCO SI 20260508 PS EU P 1.1250 0"}
{"ts_recv":"2026-04-06T18:53:11.558341309Z","hd":{"ts_event":"2026-04-06T18:53:11.558339853Z","rtype":160,"publisher_id":101,"instrument_id":33139},"action":"R","side":"N","price":null,"size":0,"channel_id":79,"order_id":"0","flags":128,"ts_in_delta":1456,"sequence":2,"symbol":"EUCO SI 20260508 PS EU C 1.1250 0"}
{"ts_recv":"2026-04-06T18:53:11.558341309Z","hd":{"ts_event":"2026-04-06T18:53:11.558339853Z","rtype":160,"publisher_id":101,"instrument_id":33138},"action":"R","side":"N","price":null,"size":0,"channel_id":79,"order_id":"0","flags":128,"ts_in_delta":1456,"sequence":2,"symbol":"EUCO SI 20260508 PS EU P 1.1200 0"}
{"ts_recv":"2026-04-06T18:53:11.558341309Z","hd":{"ts_event":"2026-04-06T18:53:11.558339853Z","rtype":160,"publisher_id":101,"instrument_id":33137},"action":"R","side":"N","price":null,"size":0,"channel_id":79,"order_id":"0","flags":128,"ts_in_delta":1456,"sequence":2,"symbol":"EUCO SI 20260508 PS EU C 1.1200 0"}
{"ts_recv":"2026-04-06T18:53:11.558341309Z","hd":{"ts_event":"2026-04-06T18:53:11.558339853Z","rtype":160,"publisher_id":101,"instrument_id":33136},"action":"R","side":"N","price":null,"size":0,"channel_id":79,"order_id":"0","flags":128,"ts_in_delta":1456,"sequence":2,"symbol":"EUCO SI 20260508 PS EU P 1.1150 0"}
{"ts_recv":"2026-04-06T18:53:11.558341309Z","hd":{"ts_event":"2026-04-06T18:53:11.558339853Z","rtype":160,"publisher_id":101,"instrument_id":33135},"action":"R","side":"N","price":null,"size":0,"channel_id":79,"order_id":"0","flags":128,"ts_in_delta":1456,"sequence":2,"symbol":"EUCO SI 20260508 PS EU C 1.1150 0"}
{"ts_recv":"2026-04-06T18:53:11.558341309Z","hd":{"ts_event":"2026-04-06T18:53:11.558339853Z","rtype":160,"publisher_id":101,"instrument_id":33134},"action":"R","side":"N","price":null,"size":0,"channel_id":79,"order_id":"0","flags":128,"ts_in_delta":1456,"sequence":2,"symbol":"EUCO SI 20260508 PS EU P 1.1100 0"}
{"ts_recv":"2026-04-06T18:53:11.558341309Z","hd":{"ts_event":"2026-04-06T18:53:11.558339853Z","rtype":160,"publisher_id":101,"instrument_id":33133},"action":"R","side":"N","price":null,"size":0,"channel_id":79,"order_id":"0","flags":128,"ts_in_delta":1456,"sequence":2,"symbol":"EUCO SI 20260508 PS EU C 1.1100 0"}
{"ts_recv":"2026-04-06T18:53:11.558341309Z","hd":{"ts_event":"2026-04-06T18:53:11.558339853Z","rtype":160,"publisher_id":101,"instrument_id":33132},"action":"R","side":"N","price":null,"size":0,"channel_id":79,"order_id":"0","flags":128,"ts_in_delta":1456,"sequence":2,"symbol":"EUCO SI 20260508 PS EU P 1.1050 0"}
{"ts_recv":"2026-04-06T18:53:11.558341309Z","hd":{"ts_event":"2026-04-06T18:53:11.558339853Z","rtype":160,"publisher_id":101,"instrument_id":33131},"action":"R","side":"N","price":null,"size":0,"channel_id":79,"order_id":"0","flags":128,"ts_in_delta":1456,"sequence":2,"symbol":"EUCO SI 20260508 PS EU C 1.1050 0"}
{"ts_recv":"2026-04-06T18:53:11.558341309Z","hd":{"ts_event":"2026-04-06T18:53:11.558339853Z","rtype":160,"publisher_id":101,"instrument_id":33130},"action":"R","side":"N","price":null,"size":0,"channel_id":79,"order_id":"0","flags":128,"ts_in_delta":1456,"sequence":2,"symbol":"EUCO SI 20260508 PS EU P 1.1000 0"}
{"ts_recv":"2026-04-06T18:53:11.558341309Z","hd":{"ts_event":"2026-04-06T18:53:11.558339853Z","rtype":160,"publisher_id":101,"instrument_id":33129},"action":"R","side":"N","price":null,"size":0,"channel_id":79,"order_id":"0","flags":128,"ts_in_delta":1456,"sequence":2,"symbol":"EUCO SI 20260508 PS EU C 1.1000 0"}
{"ts_recv":"2026-04-06T18:53:11.558341309Z","hd":{"ts_event":"2026-04-06T18:53:11.558339853Z","rtype":160,"publisher_id":101,"instrument_id":33128},"action":"R","side":"N","price":null,"size":0,"channel_id":79,"order_id":"0","flags":128,"ts_in_delta":1456,"sequence":2,"symbol":"EUCO SI 20260508 PS EU P 1.0950 0"}
{"ts_recv":"2026-04-06T18:53:11.558341309Z","hd":{"ts_event":"2026-04-06T18:53:11.558339853Z","rtype":160,"publisher_id":101,"instrument_id":33127},"action":"R","side":"N","price":null,"size":0,"channel_id":79,"order_id":"0","flags":128,"ts_in_delta":1456,"sequence":2,"symbol":"EUCO SI 20260508 PS EU C 1.0950 0"}
{"ts_recv":"2026-04-06T18:53:11.558341309Z","hd":{"ts_event":"2026-04-06T18:53:11.558339853Z","rtype":160,"publisher_id":101,"instrument_id":33126},"action":"R","side":"N","price":null,"size":0,"channel_id":79,"order_id":"0","flags":128,"ts_in_delta":1456,"sequence":2,"symbol":"EUCO SI 20260508 PS EU P 1.0900 0"}
{"ts_recv":"2026-04-06T18:53:11.558341309Z","hd":{"ts_event":"2026-04-06T18:53:11.558339853Z","rtype":160,"publisher_id":101,"instrument_id":33125},"action":"R","side":"N","price":null,"size":0,"channel_id":79,"order_id":"0","flags":128,"ts_in_delta":1456,"sequence":2,"symbol":"EUCO SI 20260508 PS EU C 1.0900 0"}
{"ts_recv":"2026-04-06T18:53:11.558341309Z","hd":{"ts_event":"2026-04-06T18:53:11.558339853Z","rtype":160,"publisher_id":101,"instrument_id":33124},"action":"R","side":"N","price":null,"size":0,"channel_id":79,"order_id":"0","flags":128,"ts_in_delta":1456,"sequence":2,"symbol":"EUCO SI 20260410 PS EU P 1.2500 0"}
{"ts_recv":"2026-04-06T18:53:11.558341309Z","hd":{"ts_event":"2026-04-06T18:53:11.558339853Z","rtype":160,"publisher_id":101,"instrument_id":33123},"action":"R","side":"N","price":null,"size":0,"channel_id":79,"order_id":"0","flags":128,"ts_in_delta":1456,"sequence":2,"symbol":"EUCO SI 20260410 PS EU C 1.2500 0"}
{"ts_recv":"2026-04-06T18:53:11.558341309Z","hd":{"ts_event":"2026-04-06T18:53:11.558339853Z","rtype":160,"publisher_id":101,"instrument_id":33122},"action":"R","side":"N","price":null,"size":0,"channel_id":79,"order_id":"0","flags":128,"ts_in_delta":1456,"sequence":2,"symbol":"EUCO SI 20260410 PS EU P 1.2450 0"}
{"ts_recv":"2026-04-06T18:53:11.558341309Z","hd":{"ts_event":"2026-04-06T18:53:11.558339853Z","rtype":160,"publisher_id":101,"instrument_id":33121},"action":"R","side":"N","price":null,"size":0,"channel_id":79,"order_id":"0","flags":128,"ts_in_delta":1456,"sequence":2,"symbol":"EUCO SI 20260410 PS EU C 1.2450 0"}
{"ts_recv":"2026-04-06T18:53:11.558341309Z","hd":{"ts_event":"2026-04-06T18:53:11.558339853Z","rtype":160,"publisher_id":101,"instrument_id":33120},"action":"R","side":"N","price":null,"size":0,"channel_id":79,"order_id":"0","flags":128,"ts_in_delta":1456,"sequence":2,"symbol":"EUCO SI 20260410 PS EU P 1.2400 0"}
{"ts_recv":"2026-04-06T18:53:11.558341309Z","hd":{"ts_event":"2026-04-06T18:53:11.558339853Z","rtype":160,"publisher_id":101,"instrument_id":33119},"action":"R","side":"N","price":null,"size":0,"channel_id":79,"order_id":"0","flags":128,"ts_in_delta":1456,"sequence":2,"symbol":"EUCO SI 20260410 PS EU C 1.2400 0"}
{"ts_recv":"2026-04-06T18:53:11.558341309Z","hd":{"ts_event":"2026-04-06T18:53:11.558339853Z","rtype":160,"publisher_id":101,"instrument_id":33118},"action":"R","side":"N","price":null,"size":0,"channel_id":79,"order_id":"0","flags":128,"ts_in_delta":1456,"sequence":2,"symbol":"EUCO SI 20260410 PS EU P 1.2350 0"}
{"ts_recv":"2026-04-06T18:53:11.558341309Z","hd":{"ts_event":"2026-04-06T18:53:11.558339853Z","rtype":160,"publisher_id":101,"instrument_id":33117},"action":"R","side":"N","price":null,"size":0,"channel_id":79,"order_id":"0","flags":128,"ts_in_delta":1456,"sequence":2,"symbol":"EUCO SI 20260410 PS EU C 1.2350 0"}
{"ts_recv":"2026-04-06T18:53:11.558341309Z","hd":{"ts_event":"2026-04-06T18:53:11.558339853Z","rtype":160,"publisher_id":101,"instrument_id":33116},"action":"R","side":"N","price":null,"size":0,"channel_id":79,"order_id":"0","flags":128,"ts_in_delta":1456,"sequence":2,"symbol":"EUCO SI 20260410 PS EU P 1.2300 0"}
{"ts_recv":"2026-04-06T18:53:11.558341309Z","hd":{"ts_event":"2026-04-06T18:53:11.558339853Z","rtype":160,"publisher_id":101,"instrument_id":33115},"action":"R","side":"N","price":null,"size":0,"channel_id":79,"order_id":"0","flags":128,"ts_in_delta":1456,"sequence":2,"symbol":"EUCO SI 20260410 PS EU C 1.2300 0"}
{"ts_recv":"2026-04-06T18:53:11.558341309Z","hd":{"ts_event":"2026-04-06T18:53:11.558339853Z","rtype":160,"publisher_id":101,"instrument_id":33114},"action":"R","side":"N","price":null,"size":0,"channel_id":79,"order_id":"0","flags":128,"ts_in_delta":1456,"sequence":2,"symbol":"EUCO SI 20260410 PS EU P 1.2250 0"}
{"ts_recv":"2026-04-06T18:53:11.558341309Z","hd":{"ts_event":"2026-04-06T18:53:11.558339853Z","rtype":160,"publisher_id":101,"instrument_id":33113},"action":"R","side":"N","price":null,"size":0,"channel_id":79,"order_id":"0","flags":128,"ts_in_delta":1456,"sequence":2,"symbol":"EUCO SI 20260410 PS EU C 1.2250 0"}
{"ts_recv":"2026-04-06T18:53:11.558341309Z","hd":{"ts_event":"2026-04-06T18:53:11.558339853Z","rtype":160,"publisher_id":101,"instrument_id":33112},"action":"R","side":"N","price":null,"size":0,"channel_id":79,"order_id":"0","flags":128,"ts_in_delta":1456,"sequence":2,"symbol":"EUCO SI 20260410 PS EU P 1.2225 0"}
{"ts_recv":"2026-04-06T18:53:11.558341309Z","hd":{"ts_event":"2026-04-06T18:53:11.558339853Z","rtype":160,"publisher_id":101,"instrument_id":33111},"action":"R","side":"N","price":null,"size":0,"channel_id":79,"order_id":"0","flags":128,"ts_in_delta":1456,"sequence":2,"symbol":"EUCO SI 20260410 PS EU C 1.2225 0"}
{"ts_recv":"2026-04-06T18:53:11.558341309Z","hd":{"ts_event":"2026-04-06T18:53:11.558339853Z","rtype":160,"publisher_id":101,"instrument_id":33110},"action":"R","side":"N","price":null,"size":0,"channel_id":79,"order_id":"0","flags":128,"ts_in_delta":1456,"sequence":2,"symbol":"EUCO SI 20260410 PS EU P 1.2200 0"}
{"ts_recv":"2026-04-06T18:53:11.558341309Z","hd":{"ts_event":"2026-04-06T18:53:11.558339853Z","rtype":160,"publisher_id":101,"instrument_id":33109},"action":"R","side":"N","price":null,"size":0,"channel_id":79,"order_id":"0","flags":128,"ts_in_delta":1456,"sequence":2,"symbol":"EUCO SI 20260410 PS EU C 1.2200 0"}
{"ts_recv":"2026-04-06T18:53:11.558341309Z","hd":{"ts_event":"2026-04-06T18:53:11.558339853Z","rtype":160,"publisher_id":101,"instrument_id":33108},"action":"R","side":"N","price":null,"size":0,"channel_id":79,"order_id":"0","flags":128,"ts_in_delta":1456,"sequence":2,"symbol":"EUCO SI 20260410 PS EU P 1.2175 0"}
{"ts_recv":"2026-04-06T18:53:11.558341309Z","hd":{"ts_event":"2026-04-06T18:53:11.558339853Z","rtype":160,"publisher_id":101,"instrument_id":33107},"action":"R","side":"N","price":null,"size":0,"channel_id":79,"order_id":"0","flags":128,"ts_in_delta":1456,"sequence":2,"symbol":"EUCO SI 20260410 PS EU C 1.2175 0"}
{"ts_recv":"2026-04-06T18:53:11.558341309Z","hd":{"ts_event":"2026-04-06T18:53:11.558339853Z","rtype":160,"publisher_id":101,"instrument_id":33106},"action":"R","side":"N","price":null,"size":0,"channel_id":79,"order_id":"0","flags":128,"ts_in_delta":1456,"sequence":2,"symbol":"EUCO SI 20260410 PS EU P 1.2150 0"}
{"ts_recv":"2026-04-06T18:53:11.558341309Z","hd":{"ts_event":"2026-04-06T18:53:11.558339853Z","rtype":160,"publisher_id":101,"instrument_id":33105},"action":"R","side":"N","price":null,"size":0,"channel_id":79,"order_id":"0","flags":128,"ts_in_delta":1456,"sequence":2,"symbol":"EUCO SI 20260410 PS EU C 1.2150 0"}
{"ts_recv":"2026-04-06T18:53:11.558341309Z","hd":{"ts_event":"2026-04-06T18:53:11.558339853Z","rtype":160,"publisher_id":101,"instrument_id":33104},"action":"R","side":"N","price":null,"size":0,"channel_id":79,"order_id":"0","flags":128,"ts_in_delta":1456,"sequence":2,"symbol":"EUCO SI 20260410 PS EU P 1.2125 0"}
{"ts_recv":"2026-04-06T18:53:11.558341309Z","hd":{"ts_event":"2026-04-06T18:53:11.558339853Z","rtype":160,"publisher_id":101,"instrument_id":33103},"action":"R","side":"N","price":null,"size":0,"channel_id":79,"order_id":"0","flags":128,"ts_in_delta":1456,"sequence":2,"symbol":"EUCO SI 20260410 PS EU C 1.2125 0"}
{"ts_recv":"2026-04-06T18:53:11.558341309Z","hd":{"ts_event":"2026-04-06T18:53:11.558339853Z","rtype":160,"publisher_id":101,"instrument_id":33102},"action":"R","side":"N","price":null,"size":0,"channel_id":79,"order_id":"0","flags":128,"ts_in_delta":1456,"sequence":2,"symbol":"EUCO SI 20260410 PS EU P 1.2100 0"}
{"ts_recv":"2026-04-06T18:53:11.558341309Z","hd":{"ts_event":"2026-04-06T18:53:11.558339853Z","rtype":160,"publisher_id":101,"instrument_id":33101},"action":"R","side":"N","price":null,"size":0,"channel_id":79,"order_id":"0","flags":128,"ts_in_delta":1456,"sequence":2,"symbol":"EUCO SI 20260410 PS EU C 1.2100 0"}
{"ts_recv":"2026-04-06T18:53:11.558341309Z","hd":{"ts_event":"2026-04-06T18:53:11.558339853Z","rtype":160,"publisher_id":101,"instrument_id":33100},"action":"R","side":"N","price":null,"size":0,"channel_id":79,"order_id":"0","flags":128,"ts_in_delta":1456,"sequence":2,"symbol":"EUCO SI 20260410 PS EU P 1.2075 0"}
{"ts_recv":"2026-04-06T18:53:11.558341309Z","hd":{"ts_event":"2026-04-06T18:53:11.558339853Z","rtype":160,"publisher_id":101,"instrument_id":33099},"action":"R","side":"N","price":null,"size":0,"channel_id":79,"order_id":"0","flags":128,"ts_in_delta":1456,"sequence":2,"symbol":"EUCO SI 20260410 PS EU C 1.2075 0"}
{"ts_recv":"2026-04-06T18:53:11.558341309Z","hd":{"ts_event":"2026-04-06T18:53:11.558339853Z","rtype":160,"publisher_id":101,"instrument_id":33098},"action":"R","side":"N","price":null,"size":0,"channel_id":79,"order_id":"0","flags":128,"ts_in_delta":1456,"sequence":2,"symbol":"EUCO SI 20260410 PS EU P 1.2050 0"}
{"ts_recv":"2026-04-06T18:53:11.558341309Z","hd":{"ts_event":"2026-04-06T18:53:11.558339853Z","rtype":160,"publisher_id":101,"instrument_id":33097},"action":"R","side":"N","price":null,"size":0,"channel_id":79,"order_id":"0","flags":128,"ts_in_delta":1456,"sequence":2,"symbol":"EUCO SI 20260410 PS EU C 1.2050 0"}
{"ts_recv":"2026-04-06T18:53:11.558341309Z","hd":{"ts_event":"2026-04-06T18:53:11.558339853Z","rtype":160,"publisher_id":101,"instrument_id":33096},"action":"R","side":"N","price":null,"size":0,"channel_id":79,"order_id":"0","flags":128,"ts_in_delta":1456,"sequence":2,"symbol":"EUCO SI 20260410 PS EU P 1.2025 0"}
{"ts_recv":"2026-04-06T18:53:11.558341309Z","hd":{"ts_event":"2026-04-06T18:53:11.558339853Z","rtype":160,"publisher_id":101,"instrument_id":33095},"action":"R","side":"N","price":null,"size":0,"channel_id":79,"order_id":"0","flags":128,"ts_in_delta":1456,"sequence":2,"symbol":"EUCO SI 20260410 PS EU C 1.2025 0"}
{"ts_recv":"2026-04-06T18:53:11.558341309Z","hd":{"ts_event":"2026-04-06T18:53:11.558339853Z","rtype":160,"publisher_id":101,"instrument_id":33094},"action":"R","side":"N","price":null,"size":0,"channel_id":79,"order_id":"0","flags":128,"ts_in_delta":1456,"sequence":2,"symbol":"EUCO SI 20260410 PS EU P 1.2000 0"}
{"ts_recv":"2026-04-06T18:53:11.558341309Z","hd":{"ts_event":"2026-04-06T18:53:11.558339853Z","rtype":160,"publisher_id":101,"instrument_id":33093},"action":"R","side":"N","price":null,"size":0,"channel_id":79,"order_id":"0","flags":128,"ts_in_delta":1456,"sequence":2,"symbol":"EUCO SI 20260410 PS EU C 1.2000 0"}
{"ts_recv":"2026-04-06T18:53:11.558341309Z","hd":{"ts_event":"2026-04-06T18:53:11.558339853Z","rtype":160,"publisher_id":101,"instrument_id":33092},"action":"R","side":"N","price":null,"size":0,"channel_id":79,"order_id":"0","flags":128,"ts_in_delta":1456,"sequence":2,"symbol":"EUCO SI 20260410 PS EU P 1.1975 0"}
{"ts_recv":"2026-04-06T18:53:11.558341309Z","hd":{"ts_event":"2026-04-06T18:53:11.558339853Z","rtype":160,"publisher_id":101,"instrument_id":33091},"action":"R","side":"N","price":null,"size":0,"channel_id":79,"order_id":"0","flags":128,"ts_in_delta":1456,"sequence":2,"symbol":"EUCO SI 20260410 PS EU C 1.1975 0"}
{"ts_recv":"2026-04-06T18:53:11.558341309Z","hd":{"ts_event":"2026-04-06T18:53:11.558339853Z","rtype":160,"publisher_id":101,"instrument_id":33090},"action":"R","side":"N","price":null,"size":0,"channel_id":79,"order_id":"0","flags":128,"ts_in_delta":1456,"sequence":2,"symbol":"EUCO SI 20260410 PS EU P 1.1950 0"}
{"ts_recv":"2026-04-06T18:53:11.558341309Z","hd":{"ts_event":"2026-04-06T18:53:11.558339853Z","rtype":160,"publisher_id":101,"instrument_id":33089},"action":"R","side":"N","price":null,"size":0,"channel_id":79,"order_id":"0","flags":128,"ts_in_delta":1456,"sequence":2,"symbol":"EUCO SI 20260410 PS EU C 1.1950 0"}
{"ts_recv":"2026-04-06T18:53:11.558341309Z","hd":{"ts_event":"2026-04-06T18:53:11.558339853Z","rtype":160,"publisher_id":101,"instrument_id":33088},"action":"R","side":"N","price":null,"size":0,"channel_id":79,"order_id":"0","flags":128,"ts_in_delta":1456,"sequence":2,"symbol":"EUCO SI 20260410 PS EU P 1.1925 0"}
{"ts_recv":"2026-04-06T18:53:11.558341309Z","hd":{"ts_event":"2026-04-06T18:53:11.558339853Z","rtype":160,"publisher_id":101,"instrument_id":33087},"action":"R","side":"N","price":null,"size":0,"channel_id":79,"order_id":"0","flags":128,"ts_in_delta":1456,"sequence":2,"symbol":"EUCO SI 20260410 PS EU C 1.1925 0"}
{"ts_recv":"2026-04-06T18:53:11.558341309Z","hd":{"ts_event":"2026-04-06T18:53:11.558339853Z","rtype":160,"publisher_id":101,"instrument_id":33086},"action":"R","side":"N","price":null,"size":0,"channel_id":79,"order_id":"0","flags":128,"ts_in_delta":1456,"sequence":2,"symbol":"EUCO SI 20260410 PS EU P 1.1900 0"}
{"ts_recv":"2026-04-06T18:53:11.558341309Z","hd":{"ts_event":"2026-04-06T18:53:11.558339853Z","rtype":160,"publisher_id":101,"instrument_id":33085},"action":"R","side":"N","price":null,"size":0,"channel_id":79,"order_id":"0","flags":128,"ts_in_delta":1456,"sequence":2,"symbol":"EUCO SI 20260410 PS EU C 1.1900 0"}
{"ts_recv":"2026-04-06T18:53:11.558341309Z","hd":{"ts_event":"2026-04-06T18:53:11.558339853Z","rtype":160,"publisher_id":101,"instrument_id":33084},"action":"R","side":"N","price":null,"size":0,"channel_id":79,"order_id":"0","flags":128,"ts_in_delta":1456,"sequence":2,"symbol":"EUCO SI 20260410 PS EU P 1.1875 0"}
{"ts_recv":"2026-04-06T18:53:11.558341309Z","hd":{"ts_event":"2026-04-06T18:53:11.558339853Z","rtype":160,"publisher_id":101,"instrument_id":33083},"action":"R","side":"N","price":null,"size":0,"channel_id":79,"order_id":"0","flags":128,"ts_in_delta":1456,"sequence":2,"symbol":"EUCO SI 20260410 PS EU C 1.1875 0"}
{"ts_recv":"2026-04-06T18:53:11.558341309Z","hd":{"ts_event":"2026-04-06T18:53:11.558339853Z","rtype":160,"publisher_id":101,"instrument_id":33082},"action":"R","side":"N","price":null,"size":0,"channel_id":79,"order_id":"0","flags":128,"ts_in_delta":1456,"sequence":2,"symbol":"EUCO SI 20260410 PS EU P 1.1850 0"}
{"ts_recv":"2026-04-06T18:53:11.558341309Z","hd":{"ts_event":"2026-04-06T18:53:11.558339853Z","rtype":160,"publisher_id":101,"instrument_id":33081},"action":"R","side":"N","price":null,"size":0,"channel_id":79,"order_id":"0","flags":128,"ts_in_delta":1456,"sequence":2,"symbol":"EUCO SI 20260410 PS EU C 1.1850 0"}
{"ts_recv":"2026-04-06T18:53:11.558341309Z","hd":{"ts_event":"2026-04-06T18:53:11.558339853Z","rtype":160,"publisher_id":101,"instrument_id":33080},"action":"R","side":"N","price":null,"size":0,"channel_id":79,"order_id":"0","flags":128,"ts_in_delta":1456,"sequence":2,"symbol":"EUCO SI 20260410 PS EU P 1.1825 0"}
{"ts_recv":"2026-04-06T18:53:11.558341309Z","hd":{"ts_event":"2026-04-06T18:53:11.558339853Z","rtype":160,"publisher_id":101,"instrument_id":33079},"action":"R","side":"N","price":null,"size":0,"channel_id":79,"order_id":"0","flags":128,"ts_in_delta":1456,"sequence":2,"symbol":"EUCO SI 20260410 PS EU C 1.1825 0"}
{"ts_recv":"2026-04-06T18:53:11.558341309Z","hd":{"ts_event":"2026-04-06T18:53:11.558339853Z","rtype":160,"publisher_id":101,"instrument_id":33078},"action":"R","side":"N","price":null,"size":0,"channel_id":79,"order_id":"0","flags":128,"ts_in_delta":1456,"sequence":2,"symbol":"EUCO SI 20260410 PS EU P 1.1800 0"}
{"ts_recv":"2026-04-06T18:53:11.558341309Z","hd":{"ts_event":"2026-04-06T18:53:11.558339853Z","rtype":160,"publisher_id":101,"instrument_id":33077},"action":"R","side":"N","price":null,"size":0,"channel_id":79,"order_id":"0","flags":128,"ts_in_delta":1456,"sequence":2,"symbol":"EUCO SI 20260410 PS EU C 1.1800 0"}
{"ts_recv":"2026-04-06T18:53:11.558341309Z","hd":{"ts_event":"2026-04-06T18:53:11.558339853Z","rtype":160,"publisher_id":101,"instrument_id":33076},"action":"R","side":"N","price":null,"size":0,"channel_id":79,"order_id":"0","flags":128,"ts_in_delta":1456,"sequence":2,"symbol":"EUCO SI 20260410 PS EU P 1.1775 0"}
{"ts_recv":"2026-04-06T18:53:11.558341309Z","hd":{"ts_event":"2026-04-06T18:53:11.558339853Z","rtype":160,"publisher_id":101,"instrument_id":33075},"action":"R","side":"N","price":null,"size":0,"channel_id":79,"order_id":"0","flags":128,"ts_in_delta":1456,"sequence":2,"symbol":"EUCO SI 20260410 PS EU C 1.1775 0"}
{"ts_recv":"2026-04-06T18:53:11.558341309Z","hd":{"ts_event":"2026-04-06T18:53:11.558339853Z","rtype":160,"publisher_id":101,"instrument_id":33074},"action":"R","side":"N","price":null,"size":0,"channel_id":79,"order_id":"0","flags":128,"ts_in_delta":1456,"sequence":2,"symbol":"EUCO SI 20260410 PS EU P 1.1750 0"}
{"ts_recv":"2026-04-06T18:53:11.558341309Z","hd":{"ts_event":"2026-04-06T18:53:11.558339853Z","rtype":160,"publisher_id":101,"instrument_id":33073},"action":"R","side":"N","price":null,"size":0,"channel_id":79,"order_id":"0","flags":128,"ts_in_delta":1456,"sequence":2,"symbol":"EUCO SI 20260410 PS EU C 1.1750 0"}
{"ts_recv":"2026-04-06T18:53:11.558341309Z","hd":{"ts_event":"2026-04-06T18:53:11.558339853Z","rtype":160,"publisher_id":101,"instrument_id":33072},"action":"R","side":"N","price":null,"size":0,"channel_id":79,"order_id":"0","flags":128,"ts_in_delta":1456,"sequence":2,"symbol":"EUCO SI 20260410 PS EU P 1.1725 0"}
{"ts_recv":"2026-04-06T18:53:11.558341309Z","hd":{"ts_event":"2026-04-06T18:53:11.558339853Z","rtype":160,"publisher_id":101,"instrument_id":33071},"action":"R","side":"N","price":null,"size":0,"channel_id":79,"order_id":"0","flags":128,"ts_in_delta":1456,"sequence":2,"symbol":"EUCO SI 20260410 PS EU C 1.1725 0"}
{"ts_recv":"2026-04-06T18:53:11.558341309Z","hd":{"ts_event":"2026-04-06T18:53:11.558339853Z","rtype":160,"publisher_id":101,"instrument_id":33070},"action":"R","side":"N","price":null,"size":0,"channel_id":79,"order_id":"0","flags":128,"ts_in_delta":1456,"sequence":2,"symbol":"EUCO SI 20260410 PS EU P 1.1700 0"}
{"ts_recv":"2026-04-06T18:53:11.558341309Z","hd":{"ts_event":"2026-04-06T18:53:11.558339853Z","rtype":160,"publisher_id":101,"instrument_id":33069},"action":"R","side":"N","price":null,"size":0,"channel_id":79,"order_id":"0","flags":128,"ts_in_delta":1456,"sequence":2,"symbol":"EUCO SI 20260410 PS EU C 1.1700 0"}
{"ts_recv":"2026-04-06T18:53:11.558341309Z","hd":{"ts_event":"2026-04-06T18:53:11.558339853Z","rtype":160,"publisher_id":101,"instrument_id":33068},"action":"R","side":"N","price":null,"size":0,"channel_id":79,"order_id":"0","flags":128,"ts_in_delta":1456,"sequence":2,"symbol":"EUCO SI 20260410 PS EU P 1.1675 0"}
{"ts_recv":"2026-04-06T18:53:11.558341309Z","hd":{"ts_event":"2026-04-06T18:53:11.558339853Z","rtype":160,"publisher_id":101,"instrument_id":33067},"action":"R","side":"N","price":null,"size":0,"channel_id":79,"order_id":"0","flags":128,"ts_in_delta":1456,"sequence":2,"symbol":"EUCO SI 20260410 PS EU C 1.1675 0"}
{"ts_recv":"2026-04-06T18:53:11.558341309Z","hd":{"ts_event":"2026-04-06T18:53:11.558339853Z","rtype":160,"publisher_id":101,"instrument_id":33066},"action":"R","side":"N","price":null,"size":0,"channel_id":79,"order_id":"0","flags":128,"ts_in_delta":1456,"sequence":2,"symbol":"EUCO SI 20260410 PS EU P 1.1650 0"}
{"ts_recv":"2026-04-06T18:53:11.558341309Z","hd":{"ts_event":"2026-04-06T18:53:11.558339853Z","rtype":160,"publisher_id":101,"instrument_id":33065},"action":"R","side":"N","price":null,"size":0,"channel_id":79,"order_id":"0","flags":128,"ts_in_delta":1456,"sequence":2,"symbol":"EUCO SI 20260410 PS EU C 1.1650 0"}
{"ts_recv":"2026-04-06T18:53:11.558341309Z","hd":{"ts_event":"2026-04-06T18:53:11.558339853Z","rtype":160,"publisher_id":101,"instrument_id":33064},"action":"R","side":"N","price":null,"size":0,"channel_id":79,"order_id":"0","flags":128,"ts_in_delta":1456,"sequence":2,"symbol":"EUCO SI 20260410 PS EU P 1.1625 0"}
{"ts_recv":"2026-04-06T18:53:11.558341309Z","hd":{"ts_event":"2026-04-06T18:53:11.558339853Z","rtype":160,"publisher_id":101,"instrument_id":33063},"action":"R","side":"N","price":null,"size":0,"channel_id":79,"order_id":"0","flags":128,"ts_in_delta":1456,"sequence":2,"symbol":"EUCO SI 20260410 PS EU C 1.1625 0"}
{"ts_recv":"2026-04-06T18:53:11.558341309Z","hd":{"ts_event":"2026-04-06T18:53:11.558339853Z","rtype":160,"publisher_id":101,"instrument_id":33062},"action":"R","side":"N","price":null,"size":0,"channel_id":79,"order_id":"0","flags":128,"ts_in_delta":1456,"sequence":2,"symbol":"EUCO SI 20260410 PS EU P 1.1600 0"}
{"ts_recv":"2026-04-06T18:53:11.558341309Z","hd":{"ts_event":"2026-04-06T18:53:11.558339853Z","rtype":160,"publisher_id":101,"instrument_id":33061},"action":"R","side":"N","price":null,"size":0,"channel_id":79,"order_id":"0","flags":128,"ts_in_delta":1456,"sequence":2,"symbol":"EUCO SI 20260410 PS EU C 1.1600 0"}
{"ts_recv":"2026-04-06T18:53:11.558341309Z","hd":{"ts_event":"2026-04-06T18:53:11.558339853Z","rtype":160,"publisher_id":101,"instrument_id":33060},"action":"R","side":"N","price":null,"size":0,"channel_id":79,"order_id":"0","flags":128,"ts_in_delta":1456,"sequence":2,"symbol":"EUCO SI 20260410 PS EU P 1.1575 0"}
{"ts_recv":"2026-04-06T18:53:11.558341309Z","hd":{"ts_event":"2026-04-06T18:53:11.558339853Z","rtype":160,"publisher_id":101,"instrument_id":33059},"action":"R","side":"N","price":null,"size":0,"channel_id":79,"order_id":"0","flags":128,"ts_in_delta":1456,"sequence":2,"symbol":"EUCO SI 20260410 PS EU C 1.1575 0"}
{"ts_recv":"2026-04-06T18:53:11.558341309Z","hd":{"ts_event":"2026-04-06T18:53:11.558339853Z","rtype":160,"publisher_id":101,"instrument_id":33058},"action":"R","side":"N","price":null,"size":0,"channel_id":79,"order_id":"0","flags":128,"ts_in_delta":1456,"sequence":2,"symbol":"EUCO SI 20260410 PS EU P 1.1550 0"}
{"ts_recv":"2026-04-06T18:53:11.558341309Z","hd":{"ts_event":"2026-04-06T18:53:11.558339853Z","rtype":160,"publisher_id":101,"instrument_id":33057},"action":"R","side":"N","price":null,"size":0,"channel_id":79,"order_id":"0","flags":128,"ts_in_delta":1456,"sequence":2,"symbol":"EUCO SI 20260410 PS EU C 1.1550 0"}
{"ts_recv":"2026-04-06T18:53:11.558341309Z","hd":{"ts_event":"2026-04-06T18:53:11.558339853Z","rtype":160,"publisher_id":101,"instrument_id":33056},"action":"R","side":"N","price":null,"size":0,"channel_id":79,"order_id":"0","flags":128,"ts_in_delta":1456,"sequence":2,"symbol":"EUCO SI 20260410 PS EU P 1.1525 0"}
{"ts_recv":"2026-04-06T18:53:11.558341309Z","hd":{"ts_event":"2026-04-06T18:53:11.558339853Z","rtype":160,"publisher_id":101,"instrument_id":33055},"action":"R","side":"N","price":null,"size":0,"channel_id":79,"order_id":"0","flags":128,"ts_in_delta":1456,"sequence":2,"symbol":"EUCO SI 20260410 PS EU C 1.1525 0"}
{"ts_recv":"2026-04-06T18:53:11.558341309Z","hd":{"ts_event":"2026-04-06T18:53:11.558339853Z","rtype":160,"publisher_id":101,"instrument_id":33054},"action":"R","side":"N","price":null,"size":0,"channel_id":79,"order_id":"0","flags":128,"ts_in_delta":1456,"sequence":2,"symbol":"EUCO SI 20260410 PS EU P 1.1500 0"}
{"ts_recv":"2026-04-06T18:53:11.558341309Z","hd":{"ts_event":"2026-04-06T18:53:11.558339853Z","rtype":160,"publisher_id":101,"instrument_id":33053},"action":"R","side":"N","price":null,"size":0,"channel_id":79,"order_id":"0","flags":128,"ts_in_delta":1456,"sequence":2,"symbol":"EUCO SI 20260410 PS EU C 1.1500 0"}
{"ts_recv":"2026-04-06T18:53:11.558341309Z","hd":{"ts_event":"2026-04-06T18:53:11.558339853Z","rtype":160,"publisher_id":101,"instrument_id":33052},"action":"R","side":"N","price":null,"size":0,"channel_id":79,"order_id":"0","flags":128,"ts_in_delta":1456,"sequence":2,"symbol":"EUCO SI 20260410 PS EU P 1.1475 0"}
{"ts_recv":"2026-04-06T18:53:11.558341309Z","hd":{"ts_event":"2026-04-06T18:53:11.558339853Z","rtype":160,"publisher_id":101,"instrument_id":33051},"action":"R","side":"N","price":null,"size":0,"channel_id":79,"order_id":"0","flags":128,"ts_in_delta":1456,"sequence":2,"symbol":"EUCO SI 20260410 PS EU C 1.1475 0"}
{"ts_recv":"2026-04-06T18:53:11.558341309Z","hd":{"ts_event":"2026-04-06T18:53:11.558339853Z","rtype":160,"publisher_id":101,"instrument_id":33050},"action":"R","side":"N","price":null,"size":0,"channel_id":79,"order_id":"0","flags":128,"ts_in_delta":1456,"sequence":2,"symbol":"EUCO SI 20260410 PS EU P 1.1450 0"}
{"ts_recv":"2026-04-06T18:53:11.558341309Z","hd":{"ts_event":"2026-04-06T18:53:11.558339853Z","rtype":160,"publisher_id":101,"instrument_id":33049},"action":"R","side":"N","price":null,"size":0,"channel_id":79,"order_id":"0","flags":128,"ts_in_delta":1456,"sequence":2,"symbol":"EUCO SI 20260410 PS EU C 1.1450 0"}
{"ts_recv":"2026-04-06T18:53:11.558341309Z","hd":{"ts_event":"2026-04-06T18:53:11.558339853Z","rtype":160,"publisher_id":101,"instrument_id":33048},"action":"R","side":"N","price":null,"size":0,"channel_id":79,"order_id":"0","flags":128,"ts_in_delta":1456,"sequence":2,"symbol":"EUCO SI 20260410 PS EU P 1.1425 0"}
{"ts_recv":"2026-04-06T18:53:11.558341309Z","hd":{"ts_event":"2026-04-06T18:53:11.558339853Z","rtype":160,"publisher_id":101,"instrument_id":33047},"action":"R","side":"N","price":null,"size":0,"channel_id":79,"order_id":"0","flags":128,"ts_in_delta":1456,"sequence":2,"symbol":"EUCO SI 20260410 PS EU C 1.1425 0"}
{"ts_recv":"2026-04-06T18:53:11.558341309Z","hd":{"ts_event":"2026-04-06T18:53:11.558339853Z","rtype":160,"publisher_id":101,"instrument_id":33046},"action":"R","side":"N","price":null,"size":0,"channel_id":79,"order_id":"0","flags":128,"ts_in_delta":1456,"sequence":2,"symbol":"EUCO SI 20260410 PS EU P 1.1400 0"}
{"ts_recv":"2026-04-06T18:53:11.558341309Z","hd":{"ts_event":"2026-04-06T18:53:11.558339853Z","rtype":160,"publisher_id":101,"instrument_id":33045},"action":"R","side":"N","price":null,"size":0,"channel_id":79,"order_id":"0","flags":128,"ts_in_delta":1456,"sequence":2,"symbol":"EUCO SI 20260410 PS EU C 1.1400 0"}
{"ts_recv":"2026-04-06T18:53:11.558341309Z","hd":{"ts_event":"2026-04-06T18:53:11.558339853Z","rtype":160,"publisher_id":101,"instrument_id":33044},"action":"R","side":"N","price":null,"size":0,"channel_id":79,"order_id":"0","flags":128,"ts_in_delta":1456,"sequence":2,"symbol":"EUCO SI 20260410 PS EU P 1.1375 0"}
{"ts_recv":"2026-04-06T18:53:11.558341309Z","hd":{"ts_event":"2026-04-06T18:53:11.558339853Z","rtype":160,"publisher_id":101,"instrument_id":33043},"action":"R","side":"N","price":null,"size":0,"channel_id":79,"order_id":"0","flags":128,"ts_in_delta":1456,"sequence":2,"symbol":"EUCO SI 20260410 PS EU C 1.1375 0"}
{"ts_recv":"2026-04-06T18:53:11.558341309Z","hd":{"ts_event":"2026-04-06T18:53:11.558339853Z","rtype":160,"publisher_id":101,"instrument_id":33042},"action":"R","side":"N","price":null,"size":0,"channel_id":79,"order_id":"0","flags":128,"ts_in_delta":1456,"sequence":2,"symbol":"EUCO SI 20260410 PS EU P 1.1350 0"}
{"ts_recv":"2026-04-06T18:53:11.558341309Z","hd":{"ts_event":"2026-04-06T18:53:11.558339853Z","rtype":160,"publisher_id":101,"instrument_id":33041},"action":"R","side":"N","price":null,"size":0,"channel_id":79,"order_id":"0","flags":128,"ts_in_delta":1456,"sequence":2,"symbol":"EUCO SI 20260410 PS EU C 1.1350 0"}
{"ts_recv":"2026-04-06T18:53:11.558341309Z","hd":{"ts_event":"2026-04-06T18:53:11.558339853Z","rtype":160,"publisher_id":101,"instrument_id":33040},"action":"R","side":"N","price":null,"size":0,"channel_id":79,"order_id":"0","flags":128,"ts_in_delta":1456,"sequence":2,"symbol":"EUCO SI 20260410 PS EU P 1.1325 0"}
{"ts_recv":"2026-04-06T18:53:11.558341309Z","hd":{"ts_event":"2026-04-06T18:53:11.558339853Z","rtype":160,"publisher_id":101,"instrument_id":33039},"action":"R","side":"N","price":null,"size":0,"channel_id":79,"order_id":"0","flags":128,"ts_in_delta":1456,"sequence":2,"symbol":"EUCO SI 20260410 PS EU C 1.1325 0"}
{"ts_recv":"2026-04-06T18:53:11.558341309Z","hd":{"ts_event":"2026-04-06T18:53:11.558339853Z","rtype":160,"publisher_id":101,"instrument_id":33038},"action":"R","side":"N","price":null,"size":0,"channel_id":79,"order_id":"0","flags":128,"ts_in_delta":1456,"sequence":2,"symbol":"EUCO SI 20260410 PS EU P 1.1300 0"}
{"ts_recv":"2026-04-06T18:53:11.558341309Z","hd":{"ts_event":"2026-04-06T18:53:11.558339853Z","rtype":160,"publisher_id":101,"instrument_id":33037},"action":"R","side":"N","price":null,"size":0,"channel_id":79,"order_id":"0","flags":128,"ts_in_delta":1456,"sequence":2,"symbol":"EUCO SI 20260410 PS EU C 1.1300 0"}
{"ts_recv":"2026-04-06T18:53:11.558341309Z","hd":{"ts_event":"2026-04-06T18:53:11.558339853Z","rtype":160,"publisher_id":101,"instrument_id":33036},"action":"R","side":"N","price":null,"size":0,"channel_id":79,"order_id":"0","flags":128,"ts_in_delta":1456,"sequence":2,"symbol":"EUCO SI 20260410 PS EU P 1.1275 0"}
{"ts_recv":"2026-04-06T18:53:11.558341309Z","hd":{"ts_event":"2026-04-06T18:53:11.558339853Z","rtype":160,"publisher_id":101,"instrument_id":33035},"action":"R","side":"N","price":null,"size":0,"channel_id":79,"order_id":"0","flags":128,"ts_in_delta":1456,"sequence":2,"symbol":"EUCO SI 20260410 PS EU C 1.1275 0"}
{"ts_recv":"2026-04-06T18:53:11.558341309Z","hd":{"ts_event":"2026-04-06T18:53:11.558339853Z","rtype":160,"publisher_id":101,"instrument_id":33034},"action":"R","side":"N","price":null,"size":0,"channel_id":79,"order_id":"0","flags":128,"ts_in_delta":1456,"sequence":2,"symbol":"EUCO SI 20260410 PS EU P 1.1250 0"}
{"ts_recv":"2026-04-06T18:53:11.558341309Z","hd":{"ts_event":"2026-04-06T18:53:11.558339853Z","rtype":160,"publisher_id":101,"instrument_id":33033},"action":"R","side":"N","price":null,"size":0,"channel_id":79,"order_id":"0","flags":128,"ts_in_delta":1456,"sequence":2,"symbol":"EUCO SI 20260410 PS EU C 1.1250 0"}
{"ts_recv":"2026-04-06T18:53:11.558341309Z","hd":{"ts_event":"2026-04-06T18:53:11.558339853Z","rtype":160,"publisher_id":101,"instrument_id":33032},"action":"R","side":"N","price":null,"size":0,"channel_id":79,"order_id":"0","flags":128,"ts_in_delta":1456,"sequence":2,"symbol":"EUCO SI 20260410 PS EU P 1.1200 0"}
{"ts_recv":"2026-04-06T18:53:11.558341309Z","hd":{"ts_event":"2026-04-06T18:53:11.558339853Z","rtype":160,"publisher_id":101,"instrument_id":33031},"action":"R","side":"N","price":null,"size":0,"channel_id":79,"order_id":"0","flags":128,"ts_in_delta":1456,"sequence":2,"symbol":"EUCO SI 20260410 PS EU C 1.1200 0"}
{"ts_recv":"2026-04-06T18:53:11.558341309Z","hd":{"ts_event":"2026-04-06T18:53:11.558339853Z","rtype":160,"publisher_id":101,"instrument_id":33030},"action":"R","side":"N","price":null,"size":0,"channel_id":79,"order_id":"0","flags":128,"ts_in_delta":1456,"sequence":2,"symbol":"EUCO SI 20260410 PS EU P 1.1150 0"}
{"ts_recv":"2026-04-06T18:53:11.558341309Z","hd":{"ts_event":"2026-04-06T18:53:11.558339853Z","rtype":160,"publisher_id":101,"instrument_id":33029},"action":"R","side":"N","price":null,"size":0,"channel_id":79,"order_id":"0","flags":128,"ts_in_delta":1456,"sequence":2,"symbol":"EUCO SI 20260410 PS EU C 1.1150 0"}
{"ts_recv":"2026-04-06T18:53:11.558341309Z","hd":{"ts_event":"2026-04-06T18:53:11.558339853Z","rtype":160,"publisher_id":101,"instrument_id":33028},"action":"R","side":"N","price":null,"size":0,"channel_id":79,"order_id":"0","flags":128,"ts_in_delta":1456,"sequence":2,"symbol":"EUCO SI 20260410 PS EU P 1.1100 0"}
{"ts_recv":"2026-04-06T18:53:11.558341309Z","hd":{"ts_event":"2026-04-06T18:53:11.558339853Z","rtype":160,"publisher_id":101,"instrument_id":33027},"action":"R","side":"N","price":null,"size":0,"channel_id":79,"order_id":"0","flags":128,"ts_in_delta":1456,"sequence":2,"symbol":"EUCO SI 20260410 PS EU C 1.1100 0"}
{"ts_recv":"2026-04-06T18:53:11.558341309Z","hd":{"ts_event":"2026-04-06T18:53:11.558339853Z","rtype":160,"publisher_id":101,"instrument_id":33026},"action":"R","side":"N","price":null,"size":0,"channel_id":79,"order_id":"0","flags":128,"ts_in_delta":1456,"sequence":2,"symbol":"EUCO SI 20260410 PS EU P 1.1050 0"}
{"ts_recv":"2026-04-06T18:53:11.558341309Z","hd":{"ts_event":"2026-04-06T18:53:11.558339853Z","rtype":160,"publisher_id":101,"instrument_id":33025},"action":"R","side":"N","price":null,"size":0,"channel_id":79,"order_id":"0","flags":128,"ts_in_delta":1456,"sequence":2,"symbol":"EUCO SI 20260410 PS EU C 1.1050 0"}
{"ts_recv":"2026-04-06T18:53:11.558341309Z","hd":{"ts_event":"2026-04-06T18:53:11.558339853Z","rtype":160,"publisher_id":101,"instrument_id":33024},"action":"R","side":"N","price":null,"size":0,"channel_id":79,"order_id":"0","flags":128,"ts_in_delta":1456,"sequence":2,"symbol":"EUCO SI 20260410 PS EU P 1.1000 0"}
{"ts_recv":"2026-04-06T18:53:11.558341309Z","hd":{"ts_event":"2026-04-06T18:53:11.558339853Z","rtype":160,"publisher_id":101,"instrument_id":33023},"action":"R","side":"N","price":null,"size":0,"channel_id":79,"order_id":"0","flags":128,"ts_in_delta":1456,"sequence":2,"symbol":"EUCO SI 20260410 PS EU C 1.1000 0"}
{"ts_recv":"2026-04-06T18:53:11.558351950Z","hd":{"ts_event":"2026-04-06T18:53:11.558339853Z","rtype":160,"publisher_id":101,"instrument_id":33023},"action":"R","side":"N","price":null,"size":0,"channel_id":79,"order_id":"0","flags":128,"ts_in_delta":12097,"sequence":3,"symbol":"EUCO SI 20260410 PS EU C 1.1000 0"}
{"ts_recv":"2026-04-06T18:53:11.558351950Z","hd":{"ts_event":"2026-04-06T18:53:11.558339853Z","rtype":160,"publisher_id":101,"instrument_id":33024},"action":"R","side":"N","price":null,"size":0,"channel_id":79,"order_id":"0","flags":128,"ts_in_delta":12097,"sequence":3,"symbol":"EUCO SI 20260410 PS EU P 1.1000 0"}
{"ts_recv":"2026-04-06T18:53:11.558351950Z","hd":{"ts_event":"2026-04-06T18:53:11.558339853Z","rtype":160,"publisher_id":101,"instrument_id":33025},"action":"R","side":"N","price":null,"size":0,"channel_id":79,"order_id":"0","flags":128,"ts_in_delta":12097,"sequence":3,"symbol":"EUCO SI 20260410 PS EU C 1.1050 0"}
{"ts_recv":"2026-04-06T18:53:11.558351950Z","hd":{"ts_event":"2026-04-06T18:53:11.558339853Z","rtype":160,"publisher_id":101,"instrument_id":33026},"action":"R","side":"N","price":null,"size":0,"channel_id":79,"order_id":"0","flags":128,"ts_in_delta":12097,"sequence":3,"symbol":"EUCO SI 20260410 PS EU P 1.1050 0"}
{"ts_recv":"2026-04-06T18:53:11.558351950Z","hd":{"ts_event":"2026-04-06T18:53:11.558339853Z","rtype":160,"publisher_id":101,"instrument_id":33027},"action":"R","side":"N","price":null,"size":0,"channel_id":79,"order_id":"0","flags":128,"ts_in_delta":12097,"sequence":3,"symbol":"EUCO SI 20260410 PS EU C 1.1100 0"}
{"ts_recv":"2026-04-06T18:53:11.558351950Z","hd":{"ts_event":"2026-04-06T18:53:11.558339853Z","rtype":160,"publisher_id":101,"instrument_id":33028},"action":"R","side":"N","price":null,"size":0,"channel_id":79,"order_id":"0","flags":128,"ts_in_delta":12097,"sequence":3,"symbol":"EUCO SI 20260410 PS EU P 1.1100 0"}
{"ts_recv":"2026-04-06T18:53:11.558351950Z","hd":{"ts_event":"2026-04-06T18:53:11.558339853Z","rtype":160,"publisher_id":101,"instrument_id":33029},"action":"R","side":"N","price":null,"size":0,"channel_id":79,"order_id":"0","flags":128,"ts_in_delta":12097,"sequence":3,"symbol":"EUCO SI 20260410 PS EU C 1.1150 0"}
{"ts_recv":"2026-04-06T18:53:11.558351950Z","hd":{"ts_event":"2026-04-06T18:53:11.558339853Z","rtype":160,"publisher_id":101,"instrument_id":33030},"action":"R","side":"N","price":null,"size":0,"channel_id":79,"order_id":"0","flags":128,"ts_in_delta":12097,"sequence":3,"symbol":"EUCO SI 20260410 PS EU P 1.1150 0"}
{"ts_recv":"2026-04-06T18:53:11.558351950Z","hd":{"ts_event":"2026-04-06T18:53:11.558339853Z","rtype":160,"publisher_id":101,"instrument_id":33031},"action":"R","side":"N","price":null,"size":0,"channel_id":79,"order_id":"0","flags":128,"ts_in_delta":12097,"sequence":3,"symbol":"EUCO SI 20260410 PS EU C 1.1200 0"}
{"ts_recv":"2026-04-06T18:53:11.558351950Z","hd":{"ts_event":"2026-04-06T18:53:11.558339853Z","rtype":160,"publisher_id":101,"instrument_id":33032},"action":"R","side":"N","price":null,"size":0,"channel_id":79,"order_id":"0","flags":128,"ts_in_delta":12097,"sequence":3,"symbol":"EUCO SI 20260410 PS EU P 1.1200 0"}
{"ts_recv":"2026-04-06T18:53:11.558351950Z","hd":{"ts_event":"2026-04-06T18:53:11.558339853Z","rtype":160,"publisher_id":101,"instrument_id":33033},"action":"R","side":"N","price":null,"size":0,"channel_id":79,"order_id":"0","flags":128,"ts_in_delta":12097,"sequence":3,"symbol":"EUCO SI 20260410 PS EU C 1.1250 0"}
{"ts_recv":"2026-04-06T18:53:11.558351950Z","hd":{"ts_event":"2026-04-06T18:53:11.558339853Z","rtype":160,"publisher_id":101,"instrument_id":33034},"action":"R","side":"N","price":null,"size":0,"channel_id":79,"order_id":"0","flags":128,"ts_in_delta":12097,"sequence":3,"symbol":"EUCO SI 20260410 PS EU P 1.1250 0"}
{"ts_recv":"2026-04-06T18:53:11.558351950Z","hd":{"ts_event":"2026-04-06T18:53:11.558339853Z","rtype":160,"publisher_id":101,"instrument_id":33035},"action":"R","side":"N","price":null,"size":0,"channel_id":79,"order_id":"0","flags":128,"ts_in_delta":12097,"sequence":3,"symbol":"EUCO SI 20260410 PS EU C 1.1275 0"}
{"ts_recv":"2026-04-06T18:53:11.558351950Z","hd":{"ts_event":"2026-04-06T18:53:11.558339853Z","rtype":160,"publisher_id":101,"instrument_id":33036},"action":"R","side":"N","price":null,"size":0,"channel_id":79,"order_id":"0","flags":128,"ts_in_delta":12097,"sequence":3,"symbol":"EUCO SI 20260410 PS EU P 1.1275 0"}
{"ts_recv":"2026-04-06T18:53:11.558351950Z","hd":{"ts_event":"2026-04-06T18:53:11.558339853Z","rtype":160,"publisher_id":101,"instrument_id":33037},"action":"R","side":"N","price":null,"size":0,"channel_id":79,"order_id":"0","flags":128,"ts_in_delta":12097,"sequence":3,"symbol":"EUCO SI 20260410 PS EU C 1.1300 0"}
{"ts_recv":"2026-04-06T18:53:11.558351950Z","hd":{"ts_event":"2026-04-06T18:53:11.558339853Z","rtype":160,"publisher_id":101,"instrument_id":33038},"action":"R","side":"N","price":null,"size":0,"channel_id":79,"order_id":"0","flags":128,"ts_in_delta":12097,"sequence":3,"symbol":"EUCO SI 20260410 PS EU P 1.1300 0"}
{"ts_recv":"2026-04-06T18:53:11.558351950Z","hd":{"ts_event":"2026-04-06T18:53:11.558339853Z","rtype":160,"publisher_id":101,"instrument_id":33039},"action":"R","side":"N","price":null,"size":0,"channel_id":79,"order_id":"0","flags":128,"ts_in_delta":12097,"sequence":3,"symbol":"EUCO SI 20260410 PS EU C 1.1325 0"}
{"ts_recv":"2026-04-06T18:53:11.558351950Z","hd":{"ts_event":"2026-04-06T18:53:11.558339853Z","rtype":160,"publisher_id":101,"instrument_id":33040},"action":"R","side":"N","price":null,"size":0,"channel_id":79,"order_id":"0","flags":128,"ts_in_delta":12097,"sequence":3,"symbol":"EUCO SI 20260410 PS EU P 1.1325 0"}
{"ts_recv":"2026-04-06T18:53:11.558351950Z","hd":{"ts_event":"2026-04-06T18:53:11.558339853Z","rtype":160,"publisher_id":101,"instrument_id":33041},"action":"R","side":"N","price":null,"size":0,"channel_id":79,"order_id":"0","flags":128,"ts_in_delta":12097,"sequence":3,"symbol":"EUCO SI 20260410 PS EU C 1.1350 0"}
{"ts_recv":"2026-04-06T18:53:11.558351950Z","hd":{"ts_event":"2026-04-06T18:53:11.558339853Z","rtype":160,"publisher_id":101,"instrument_id":33042},"action":"R","side":"N","price":null,"size":0,"channel_id":79,"order_id":"0","flags":128,"ts_in_delta":12097,"sequence":3,"symbol":"EUCO SI 20260410 PS EU P 1.1350 0"}
{"ts_recv":"2026-04-06T18:53:11.558351950Z","hd":{"ts_event":"2026-04-06T18:53:11.558339853Z","rtype":160,"publisher_id":101,"instrument_id":33043},"action":"R","side":"N","price":null,"size":0,"channel_id":79,"order_id":"0","flags":128,"ts_in_delta":12097,"sequence":3,"symbol":"EUCO SI 20260410 PS EU C 1.1375 0"}
{"ts_recv":"2026-04-06T18:53:11.558351950Z","hd":{"ts_event":"2026-04-06T18:53:11.558339853Z","rtype":160,"publisher_id":101,"instrument_id":33044},"action":"R","side":"N","price":null,"size":0,"channel_id":79,"order_id":"0","flags":128,"ts_in_delta":12097,"sequence":3,"symbol":"EUCO SI 20260410 PS EU P 1.1375 0"}
{"ts_recv":"2026-04-06T18:53:11.558351950Z","hd":{"ts_event":"2026-04-06T18:53:11.558339853Z","rtype":160,"publisher_id":101,"instrument_id":33045},"action":"R","side":"N","price":null,"size":0,"channel_id":79,"order_id":"0","flags":128,"ts_in_delta":12097,"sequence":3,"symbol":"EUCO SI 20260410 PS EU C 1.1400 0"}
{"ts_recv":"2026-04-06T18:53:11.558351950Z","hd":{"ts_event":"2026-04-06T18:53:11.558339853Z","rtype":160,"publisher_id":101,"instrument_id":33046},"action":"R","side":"N","price":null,"size":0,"channel_id":79,"order_id":"0","flags":128,"ts_in_delta":12097,"sequence":3,"symbol":"EUCO SI 20260410 PS EU P 1.1400 0"}
{"ts_recv":"2026-04-06T18:53:11.558351950Z","hd":{"ts_event":"2026-04-06T18:53:11.558339853Z","rtype":160,"publisher_id":101,"instrument_id":33047},"action":"R","side":"N","price":null,"size":0,"channel_id":79,"order_id":"0","flags":128,"ts_in_delta":12097,"sequence":3,"symbol":"EUCO SI 20260410 PS EU C 1.1425 0"}
{"ts_recv":"2026-04-06T18:53:11.558351950Z","hd":{"ts_event":"2026-04-06T18:53:11.558339853Z","rtype":160,"publisher_id":101,"instrument_id":33048},"action":"R","side":"N","price":null,"size":0,"channel_id":79,"order_id":"0","flags":128,"ts_in_delta":12097,"sequence":3,"symbol":"EUCO SI 20260410 PS EU P 1.1425 0"}
{"ts_recv":"2026-04-06T18:53:11.558351950Z","hd":{"ts_event":"2026-04-06T18:53:11.558339853Z","rtype":160,"publisher_id":101,"instrument_id":33049},"action":"R","side":"N","price":null,"size":0,"channel_id":79,"order_id":"0","flags":128,"ts_in_delta":12097,"sequence":3,"symbol":"EUCO SI 20260410 PS EU C 1.1450 0"}
{"ts_recv":"2026-04-06T18:53:11.558351950Z","hd":{"ts_event":"2026-04-06T18:53:11.558339853Z","rtype":160,"publisher_id":101,"instrument_id":33050},"action":"R","side":"N","price":null,"size":0,"channel_id":79,"order_id":"0","flags":128,"ts_in_delta":12097,"sequence":3,"symbol":"EUCO SI 20260410 PS EU P 1.1450 0"}
{"ts_recv":"2026-04-06T18:53:11.558351950Z","hd":{"ts_event":"2026-04-06T18:53:11.558339853Z","rtype":160,"publisher_id":101,"instrument_id":33051},"action":"R","side":"N","price":null,"size":0,"channel_id":79,"order_id":"0","flags":128,"ts_in_delta":12097,"sequence":3,"symbol":"EUCO SI 20260410 PS EU C 1.1475 0"}
{"ts_recv":"2026-04-06T18:53:11.558351950Z","hd":{"ts_event":"2026-04-06T18:53:11.558339853Z","rtype":160,"publisher_id":101,"instrument_id":33052},"action":"R","side":"N","price":null,"size":0,"channel_id":79,"order_id":"0","flags":128,"ts_in_delta":12097,"sequence":3,"symbol":"EUCO SI 20260410 PS EU P 1.1475 0"}
{"ts_recv":"2026-04-06T18:53:11.558351950Z","hd":{"ts_event":"2026-04-06T18:53:11.558339853Z","rtype":160,"publisher_id":101,"instrument_id":33053},"action":"R","side":"N","price":null,"size":0,"channel_id":79,"order_id":"0","flags":128,"ts_in_delta":12097,"sequence":3,"symbol":"EUCO SI 20260410 PS EU C 1.1500 0"}
{"ts_recv":"2026-04-06T18:53:11.558351950Z","hd":{"ts_event":"2026-04-06T18:53:11.558339853Z","rtype":160,"publisher_id":101,"instrument_id":33054},"action":"R","side":"N","price":null,"size":0,"channel_id":79,"order_id":"0","flags":128,"ts_in_delta":12097,"sequence":3,"symbol":"EUCO SI 20260410 PS EU P 1.1500 0"}
{"ts_recv":"2026-04-06T18:53:11.558351950Z","hd":{"ts_event":"2026-04-06T18:53:11.558339853Z","rtype":160,"publisher_id":101,"instrument_id":33055},"action":"R","side":"N","price":null,"size":0,"channel_id":79,"order_id":"0","flags":128,"ts_in_delta":12097,"sequence":3,"symbol":"EUCO SI 20260410 PS EU C 1.1525 0"}
{"ts_recv":"2026-04-06T18:53:11.558351950Z","hd":{"ts_event":"2026-04-06T18:53:11.558339853Z","rtype":160,"publisher_id":101,"instrument_id":33056},"action":"R","side":"N","price":null,"size":0,"channel_id":79,"order_id":"0","flags":128,"ts_in_delta":12097,"sequence":3,"symbol":"EUCO SI 20260410 PS EU P 1.1525 0"}
{"ts_recv":"2026-04-06T18:53:11.558351950Z","hd":{"ts_event":"2026-04-06T18:53:11.558339853Z","rtype":160,"publisher_id":101,"instrument_id":33057},"action":"R","side":"N","price":null,"size":0,"channel_id":79,"order_id":"0","flags":128,"ts_in_delta":12097,"sequence":3,"symbol":"EUCO SI 20260410 PS EU C 1.1550 0"}
{"ts_recv":"2026-04-06T18:53:11.558351950Z","hd":{"ts_event":"2026-04-06T18:53:11.558339853Z","rtype":160,"publisher_id":101,"instrument_id":33058},"action":"R","side":"N","price":null,"size":0,"channel_id":79,"order_id":"0","flags":128,"ts_in_delta":12097,"sequence":3,"symbol":"EUCO SI 20260410 PS EU P 1.1550 0"}
{"ts_recv":"2026-04-06T18:53:11.558351950Z","hd":{"ts_event":"2026-04-06T18:53:11.558339853Z","rtype":160,"publisher_id":101,"instrument_id":33059},"action":"R","side":"N","price":null,"size":0,"channel_id":79,"order_id":"0","flags":128,"ts_in_delta":12097,"sequence":3,"symbol":"EUCO SI 20260410 PS EU C 1.1575 0"}
{"ts_recv":"2026-04-06T18:53:11.558351950Z","hd":{"ts_event":"2026-04-06T18:53:11.558339853Z","rtype":160,"publisher_id":101,"instrument_id":33060},"action":"R","side":"N","price":null,"size":0,"channel_id":79,"order_id":"0","flags":128,"ts_in_delta":12097,"sequence":3,"symbol":"EUCO SI 20260410 PS EU P 1.1575 0"}
{"ts_recv":"2026-04-06T18:53:11.558351950Z","hd":{"ts_event":"2026-04-06T18:53:11.558339853Z","rtype":160,"publisher_id":101,"instrument_id":33061},"action":"R","side":"N","price":null,"size":0,"channel_id":79,"order_id":"0","flags":128,"ts_in_delta":12097,"sequence":3,"symbol":"EUCO SI 20260410 PS EU C 1.1600 0"}
{"ts_recv":"2026-04-06T18:53:11.558351950Z","hd":{"ts_event":"2026-04-06T18:53:11.558339853Z","rtype":160,"publisher_id":101,"instrument_id":33062},"action":"R","side":"N","price":null,"size":0,"channel_id":79,"order_id":"0","flags":128,"ts_in_delta":12097,"sequence":3,"symbol":"EUCO SI 20260410 PS EU P 1.1600 0"}
{"ts_recv":"2026-04-06T18:53:11.558351950Z","hd":{"ts_event":"2026-04-06T18:53:11.558339853Z","rtype":160,"publisher_id":101,"instrument_id":33063},"action":"R","side":"N","price":null,"size":0,"channel_id":79,"order_id":"0","flags":128,"ts_in_delta":12097,"sequence":3,"symbol":"EUCO SI 20260410 PS EU C 1.1625 0"}
{"ts_recv":"2026-04-06T18:53:11.558351950Z","hd":{"ts_event":"2026-04-06T18:53:11.558339853Z","rtype":160,"publisher_id":101,"instrument_id":33064},"action":"R","side":"N","price":null,"size":0,"channel_id":79,"order_id":"0","flags":128,"ts_in_delta":12097,"sequence":3,"symbol":"EUCO SI 20260410 PS EU P 1.1625 0"}
{"ts_recv":"2026-04-06T18:53:11.558351950Z","hd":{"ts_event":"2026-04-06T18:53:11.558339853Z","rtype":160,"publisher_id":101,"instrument_id":33065},"action":"R","side":"N","price":null,"size":0,"channel_id":79,"order_id":"0","flags":128,"ts_in_delta":12097,"sequence":3,"symbol":"EUCO SI 20260410 PS EU C 1.1650 0"}
{"ts_recv":"2026-04-06T18:53:11.558351950Z","hd":{"ts_event":"2026-04-06T18:53:11.558339853Z","rtype":160,"publisher_id":101,"instrument_id":33066},"action":"R","side":"N","price":null,"size":0,"channel_id":79,"order_id":"0","flags":128,"ts_in_delta":12097,"sequence":3,"symbol":"EUCO SI 20260410 PS EU P 1.1650 0"}
{"ts_recv":"2026-04-06T18:53:11.558351950Z","hd":{"ts_event":"2026-04-06T18:53:11.558339853Z","rtype":160,"publisher_id":101,"instrument_id":33067},"action":"R","side":"N","price":null,"size":0,"channel_id":79,"order_id":"0","flags":128,"ts_in_delta":12097,"sequence":3,"symbol":"EUCO SI 20260410 PS EU C 1.1675 0"}
{"ts_recv":"2026-04-06T18:53:11.558351950Z","hd":{"ts_event":"2026-04-06T18:53:11.558339853Z","rtype":160,"publisher_id":101,"instrument_id":33068},"action":"R","side":"N","price":null,"size":0,"channel_id":79,"order_id":"0","flags":128,"ts_in_delta":12097,"sequence":3,"symbol":"EUCO SI 20260410 PS EU P 1.1675 0"}
{"ts_recv":"2026-04-06T18:53:11.558351950Z","hd":{"ts_event":"2026-04-06T18:53:11.558339853Z","rtype":160,"publisher_id":101,"instrument_id":33069},"action":"R","side":"N","price":null,"size":0,"channel_id":79,"order_id":"0","flags":128,"ts_in_delta":12097,"sequence":3,"symbol":"EUCO SI 20260410 PS EU C 1.1700 0"}
{"ts_recv":"2026-04-06T18:53:11.558351950Z","hd":{"ts_event":"2026-04-06T18:53:11.558339853Z","rtype":160,"publisher_id":101,"instrument_id":33070},"action":"R","side":"N","price":null,"size":0,"channel_id":79,"order_id":"0","flags":128,"ts_in_delta":12097,"sequence":3,"symbol":"EUCO SI 20260410 PS EU P 1.1700 0"}
{"ts_recv":"2026-04-06T18:53:11.558351950Z","hd":{"ts_event":"2026-04-06T18:53:11.558339853Z","rtype":160,"publisher_id":101,"instrument_id":33071},"action":"R","side":"N","price":null,"size":0,"channel_id":79,"order_id":"0","flags":128,"ts_in_delta":12097,"sequence":3,"symbol":"EUCO SI 20260410 PS EU C 1.1725 0"}
{"ts_recv":"2026-04-06T18:53:11.558351950Z","hd":{"ts_event":"2026-04-06T18:53:11.558339853Z","rtype":160,"publisher_id":101,"instrument_id":33072},"action":"R","side":"N","price":null,"size":0,"channel_id":79,"order_id":"0","flags":128,"ts_in_delta":12097,"sequence":3,"symbol":"EUCO SI 20260410 PS EU P 1.1725 0"}
{"ts_recv":"2026-04-06T18:53:11.558351950Z","hd":{"ts_event":"2026-04-06T18:53:11.558339853Z","rtype":160,"publisher_id":101,"instrument_id":33073},"action":"R","side":"N","price":null,"size":0,"channel_id":79,"order_id":"0","flags":128,"ts_in_delta":12097,"sequence":3,"symbol":"EUCO SI 20260410 PS EU C 1.1750 0"}
{"ts_recv":"2026-04-06T18:53:11.558351950Z","hd":{"ts_event":"2026-04-06T18:53:11.558339853Z","rtype":160,"publisher_id":101,"instrument_id":33074},"action":"R","side":"N","price":null,"size":0,"channel_id":79,"order_id":"0","flags":128,"ts_in_delta":12097,"sequence":3,"symbol":"EUCO SI 20260410 PS EU P 1.1750 0"}
{"ts_recv":"2026-04-06T18:53:11.558351950Z","hd":{"ts_event":"2026-04-06T18:53:11.558339853Z","rtype":160,"publisher_id":101,"instrument_id":33075},"action":"R","side":"N","price":null,"size":0,"channel_id":79,"order_id":"0","flags":128,"ts_in_delta":12097,"sequence":3,"symbol":"EUCO SI 20260410 PS EU C 1.1775 0"}
{"ts_recv":"2026-04-06T18:53:11.558351950Z","hd":{"ts_event":"2026-04-06T18:53:11.558339853Z","rtype":160,"publisher_id":101,"instrument_id":33076},"action":"R","side":"N","price":null,"size":0,"channel_id":79,"order_id":"0","flags":128,"ts_in_delta":12097,"sequence":3,"symbol":"EUCO SI 20260410 PS EU P 1.1775 0"}
{"ts_recv":"2026-04-06T18:53:11.558351950Z","hd":{"ts_event":"2026-04-06T18:53:11.558339853Z","rtype":160,"publisher_id":101,"instrument_id":33077},"action":"R","side":"N","price":null,"size":0,"channel_id":79,"order_id":"0","flags":128,"ts_in_delta":12097,"sequence":3,"symbol":"EUCO SI 20260410 PS EU C 1.1800 0"}
{"ts_recv":"2026-04-06T18:53:11.558351950Z","hd":{"ts_event":"2026-04-06T18:53:11.558339853Z","rtype":160,"publisher_id":101,"instrument_id":33078},"action":"R","side":"N","price":null,"size":0,"channel_id":79,"order_id":"0","flags":128,"ts_in_delta":12097,"sequence":3,"symbol":"EUCO SI 20260410 PS EU P 1.1800 0"}
{"ts_recv":"2026-04-06T18:53:11.558351950Z","hd":{"ts_event":"2026-04-06T18:53:11.558339853Z","rtype":160,"publisher_id":101,"instrument_id":33079},"action":"R","side":"N","price":null,"size":0,"channel_id":79,"order_id":"0","flags":128,"ts_in_delta":12097,"sequence":3,"symbol":"EUCO SI 20260410 PS EU C 1.1825 0"}
{"ts_recv":"2026-04-06T18:53:11.558351950Z","hd":{"ts_event":"2026-04-06T18:53:11.558339853Z","rtype":160,"publisher_id":101,"instrument_id":33080},"action":"R","side":"N","price":null,"size":0,"channel_id":79,"order_id":"0","flags":128,"ts_in_delta":12097,"sequence":3,"symbol":"EUCO SI 20260410 PS EU P 1.1825 0"}
{"ts_recv":"2026-04-06T18:53:11.558351950Z","hd":{"ts_event":"2026-04-06T18:53:11.558339853Z","rtype":160,"publisher_id":101,"instrument_id":33081},"action":"R","side":"N","price":null,"size":0,"channel_id":79,"order_id":"0","flags":128,"ts_in_delta":12097,"sequence":3,"symbol":"EUCO SI 20260410 PS EU C 1.1850 0"}
{"ts_recv":"2026-04-06T18:53:11.558351950Z","hd":{"ts_event":"2026-04-06T18:53:11.558339853Z","rtype":160,"publisher_id":101,"instrument_id":33082},"action":"R","side":"N","price":null,"size":0,"channel_id":79,"order_id":"0","flags":128,"ts_in_delta":12097,"sequence":3,"symbol":"EUCO SI 20260410 PS EU P 1.1850 0"}
{"ts_recv":"2026-04-06T18:53:11.558351950Z","hd":{"ts_event":"2026-04-06T18:53:11.558339853Z","rtype":160,"publisher_id":101,"instrument_id":33083},"action":"R","side":"N","price":null,"size":0,"channel_id":79,"order_id":"0","flags":128,"ts_in_delta":12097,"sequence":3,"symbol":"EUCO SI 20260410 PS EU C 1.1875 0"}
{"ts_recv":"2026-04-06T18:53:11.558351950Z","hd":{"ts_event":"2026-04-06T18:53:11.558339853Z","rtype":160,"publisher_id":101,"instrument_id":33084},"action":"R","side":"N","price":null,"size":0,"channel_id":79,"order_id":"0","flags":128,"ts_in_delta":12097,"sequence":3,"symbol":"EUCO SI 20260410 PS EU P 1.1875 0"}
{"ts_recv":"2026-04-06T18:53:11.558351950Z","hd":{"ts_event":"2026-04-06T18:53:11.558339853Z","rtype":160,"publisher_id":101,"instrument_id":33085},"action":"R","side":"N","price":null,"size":0,"channel_id":79,"order_id":"0","flags":128,"ts_in_delta":12097,"sequence":3,"symbol":"EUCO SI 20260410 PS EU C 1.1900 0"}
{"ts_recv":"2026-04-06T18:53:11.558351950Z","hd":{"ts_event":"2026-04-06T18:53:11.558339853Z","rtype":160,"publisher_id":101,"instrument_id":33086},"action":"R","side":"N","price":null,"size":0,"channel_id":79,"order_id":"0","flags":128,"ts_in_delta":12097,"sequence":3,"symbol":"EUCO SI 20260410 PS EU P 1.1900 0"}
{"ts_recv":"2026-04-06T18:53:11.558351950Z","hd":{"ts_event":"2026-04-06T18:53:11.558339853Z","rtype":160,"publisher_id":101,"instrument_id":33087},"action":"R","side":"N","price":null,"size":0,"channel_id":79,"order_id":"0","flags":128,"ts_in_delta":12097,"sequence":3,"symbol":"EUCO SI 20260410 PS EU C 1.1925 0"}
{"ts_recv":"2026-04-06T18:53:11.558351950Z","hd":{"ts_event":"2026-04-06T18:53:11.558339853Z","rtype":160,"publisher_id":101,"instrument_id":33088},"action":"R","side":"N","price":null,"size":0,"channel_id":79,"order_id":"0","flags":128,"ts_in_delta":12097,"sequence":3,"symbol":"EUCO SI 20260410 PS EU P 1.1925 0"}
{"ts_recv":"2026-04-06T18:53:11.558351950Z","hd":{"ts_event":"2026-04-06T18:53:11.558339853Z","rtype":160,"publisher_id":101,"instrument_id":33089},"action":"R","side":"N","price":null,"size":0,"channel_id":79,"order_id":"0","flags":128,"ts_in_delta":12097,"sequence":3,"symbol":"EUCO SI 20260410 PS EU C 1.1950 0"}
{"ts_recv":"2026-04-06T18:53:11.558351950Z","hd":{"ts_event":"2026-04-06T18:53:11.558339853Z","rtype":160,"publisher_id":101,"instrument_id":33090},"action":"R","side":"N","price":null,"size":0,"channel_id":79,"order_id":"0","flags":128,"ts_in_delta":12097,"sequence":3,"symbol":"EUCO SI 20260410 PS EU P 1.1950 0"}
{"ts_recv":"2026-04-06T18:53:11.558351950Z","hd":{"ts_event":"2026-04-06T18:53:11.558339853Z","rtype":160,"publisher_id":101,"instrument_id":33091},"action":"R","side":"N","price":null,"size":0,"channel_id":79,"order_id":"0","flags":128,"ts_in_delta":12097,"sequence":3,"symbol":"EUCO SI 20260410 PS EU C 1.1975 0"}
{"ts_recv":"2026-04-06T18:53:11.558351950Z","hd":{"ts_event":"2026-04-06T18:53:11.558339853Z","rtype":160,"publisher_id":101,"instrument_id":33092},"action":"R","side":"N","price":null,"size":0,"channel_id":79,"order_id":"0","flags":128,"ts_in_delta":12097,"sequence":3,"symbol":"EUCO SI 20260410 PS EU P 1.1975 0"}
{"ts_recv":"2026-04-06T18:53:11.558351950Z","hd":{"ts_event":"2026-04-06T18:53:11.558339853Z","rtype":160,"publisher_id":101,"instrument_id":33093},"action":"R","side":"N","price":null,"size":0,"channel_id":79,"order_id":"0","flags":128,"ts_in_delta":12097,"sequence":3,"symbol":"EUCO SI 20260410 PS EU C 1.2000 0"}
{"ts_recv":"2026-04-06T18:53:11.558351950Z","hd":{"ts_event":"2026-04-06T18:53:11.558339853Z","rtype":160,"publisher_id":101,"instrument_id":33094},"action":"R","side":"N","price":null,"size":0,"channel_id":79,"order_id":"0","flags":128,"ts_in_delta":12097,"sequence":3,"symbol":"EUCO SI 20260410 PS EU P 1.2000 0"}
{"ts_recv":"2026-04-06T18:53:11.558351950Z","hd":{"ts_event":"2026-04-06T18:53:11.558339853Z","rtype":160,"publisher_id":101,"instrument_id":33095},"action":"R","side":"N","price":null,"size":0,"channel_id":79,"order_id":"0","flags":128,"ts_in_delta":12097,"sequence":3,"symbol":"EUCO SI 20260410 PS EU C 1.2025 0"}
{"ts_recv":"2026-04-06T18:53:11.558351950Z","hd":{"ts_event":"2026-04-06T18:53:11.558339853Z","rtype":160,"publisher_id":101,"instrument_id":33096},"action":"R","side":"N","price":null,"size":0,"channel_id":79,"order_id":"0","flags":128,"ts_in_delta":12097,"sequence":3,"symbol":"EUCO SI 20260410 PS EU P 1.2025 0"}
{"ts_recv":"2026-04-06T18:53:11.558351950Z","hd":{"ts_event":"2026-04-06T18:53:11.558339853Z","rtype":160,"publisher_id":101,"instrument_id":33097},"action":"R","side":"N","price":null,"size":0,"channel_id":79,"order_id":"0","flags":128,"ts_in_delta":12097,"sequence":3,"symbol":"EUCO SI 20260410 PS EU C 1.2050 0"}
{"ts_recv":"2026-04-06T18:53:11.558351950Z","hd":{"ts_event":"2026-04-06T18:53:11.558339853Z","rtype":160,"publisher_id":101,"instrument_id":33098},"action":"R","side":"N","price":null,"size":0,"channel_id":79,"order_id":"0","flags":128,"ts_in_delta":12097,"sequence":3,"symbol":"EUCO SI 20260410 PS EU P 1.2050 0"}
{"ts_recv":"2026-04-06T18:53:11.558351950Z","hd":{"ts_event":"2026-04-06T18:53:11.558339853Z","rtype":160,"publisher_id":101,"instrument_id":33099},"action":"R","side":"N","price":null,"size":0,"channel_id":79,"order_id":"0","flags":128,"ts_in_delta":12097,"sequence":3,"symbol":"EUCO SI 20260410 PS EU C 1.2075 0"}
{"ts_recv":"2026-04-06T18:53:11.558351950Z","hd":{"ts_event":"2026-04-06T18:53:11.558339853Z","rtype":160,"publisher_id":101,"instrument_id":33100},"action":"R","side":"N","price":null,"size":0,"channel_id":79,"order_id":"0","flags":128,"ts_in_delta":12097,"sequence":3,"symbol":"EUCO SI 20260410 PS EU P 1.2075 0"}
{"ts_recv":"2026-04-06T18:53:11.558351950Z","hd":{"ts_event":"2026-04-06T18:53:11.558339853Z","rtype":160,"publisher_id":101,"instrument_id":33101},"action":"R","side":"N","price":null,"size":0,"channel_id":79,"order_id":"0","flags":128,"ts_in_delta":12097,"sequence":3,"symbol":"EUCO SI 20260410 PS EU C 1.2100 0"}
{"ts_recv":"2026-04-06T18:53:11.558351950Z","hd":{"ts_event":"2026-04-06T18:53:11.558339853Z","rtype":160,"publisher_id":101,"instrument_id":33102},"action":"R","side":"N","price":null,"size":0,"channel_id":79,"order_id":"0","flags":128,"ts_in_delta":12097,"sequence":3,"symbol":"EUCO SI 20260410 PS EU P 1.2100 0"}
{"ts_recv":"2026-04-06T18:53:11.558351950Z","hd":{"ts_event":"2026-04-06T18:53:11.558339853Z","rtype":160,"publisher_id":101,"instrument_id":33103},"action":"R","side":"N","price":null,"size":0,"channel_id":79,"order_id":"0","flags":128,"ts_in_delta":12097,"sequence":3,"symbol":"EUCO SI 20260410 PS EU C 1.2125 0"}
{"ts_recv":"2026-04-06T18:53:11.558351950Z","hd":{"ts_event":"2026-04-06T18:53:11.558339853Z","rtype":160,"publisher_id":101,"instrument_id":33104},"action":"R","side":"N","price":null,"size":0,"channel_id":79,"order_id":"0","flags":128,"ts_in_delta":12097,"sequence":3,"symbol":"EUCO SI 20260410 PS EU P 1.2125 0"}
{"ts_recv":"2026-04-06T18:53:11.558351950Z","hd":{"ts_event":"2026-04-06T18:53:11.558339853Z","rtype":160,"publisher_id":101,"instrument_id":33105},"action":"R","side":"N","price":null,"size":0,"channel_id":79,"order_id":"0","flags":128,"ts_in_delta":12097,"sequence":3,"symbol":"EUCO SI 20260410 PS EU C 1.2150 0"}
{"ts_recv":"2026-04-06T18:53:11.558351950Z","hd":{"ts_event":"2026-04-06T18:53:11.558339853Z","rtype":160,"publisher_id":101,"instrument_id":33106},"action":"R","side":"N","price":null,"size":0,"channel_id":79,"order_id":"0","flags":128,"ts_in_delta":12097,"sequence":3,"symbol":"EUCO SI 20260410 PS EU P 1.2150 0"}
{"ts_recv":"2026-04-06T18:53:11.558351950Z","hd":{"ts_event":"2026-04-06T18:53:11.558339853Z","rtype":160,"publisher_id":101,"instrument_id":33107},"action":"R","side":"N","price":null,"size":0,"channel_id":79,"order_id":"0","flags":128,"ts_in_delta":12097,"sequence":3,"symbol":"EUCO SI 20260410 PS EU C 1.2175 0"}
{"ts_recv":"2026-04-06T18:53:11.558351950Z","hd":{"ts_event":"2026-04-06T18:53:11.558339853Z","rtype":160,"publisher_id":101,"instrument_id":33108},"action":"R","side":"N","price":null,"size":0,"channel_id":79,"order_id":"0","flags":128,"ts_in_delta":12097,"sequence":3,"symbol":"EUCO SI 20260410 PS EU P 1.2175 0"}
{"ts_recv":"2026-04-06T18:53:11.558351950Z","hd":{"ts_event":"2026-04-06T18:53:11.558339853Z","rtype":160,"publisher_id":101,"instrument_id":33109},"action":"R","side":"N","price":null,"size":0,"channel_id":79,"order_id":"0","flags":128,"ts_in_delta":12097,"sequence":3,"symbol":"EUCO SI 20260410 PS EU C 1.2200 0"}
{"ts_recv":"2026-04-06T18:53:11.558351950Z","hd":{"ts_event":"2026-04-06T18:53:11.558339853Z","rtype":160,"publisher_id":101,"instrument_id":33110},"action":"R","side":"N","price":null,"size":0,"channel_id":79,"order_id":"0","flags":128,"ts_in_delta":12097,"sequence":3,"symbol":"EUCO SI 20260410 PS EU P 1.2200 0"}
{"ts_recv":"2026-04-06T18:53:11.558351950Z","hd":{"ts_event":"2026-04-06T18:53:11.558339853Z","rtype":160,"publisher_id":101,"instrument_id":33111},"action":"R","side":"N","price":null,"size":0,"channel_id":79,"order_id":"0","flags":128,"ts_in_delta":12097,"sequence":3,"symbol":"EUCO SI 20260410 PS EU C 1.2225 0"}
{"ts_recv":"2026-04-06T18:53:11.558351950Z","hd":{"ts_event":"2026-04-06T18:53:11.558339853Z","rtype":160,"publisher_id":101,"instrument_id":33112},"action":"R","side":"N","price":null,"size":0,"channel_id":79,"order_id":"0","flags":128,"ts_in_delta":12097,"sequence":3,"symbol":"EUCO SI 20260410 PS EU P 1.2225 0"}
{"ts_recv":"2026-04-06T18:53:11.558351950Z","hd":{"ts_event":"2026-04-06T18:53:11.558339853Z","rtype":160,"publisher_id":101,"instrument_id":33113},"action":"R","side":"N","price":null,"size":0,"channel_id":79,"order_id":"0","flags":128,"ts_in_delta":12097,"sequence":3,"symbol":"EUCO SI 20260410 PS EU C 1.2250 0"}
{"ts_recv":"2026-04-06T18:53:11.558351950Z","hd":{"ts_event":"2026-04-06T18:53:11.558339853Z","rtype":160,"publisher_id":101,"instrument_id":33114},"action":"R","side":"N","price":null,"size":0,"channel_id":79,"order_id":"0","flags":128,"ts_in_delta":12097,"sequence":3,"symbol":"EUCO SI 20260410 PS EU P 1.2250 0"}
{"ts_recv":"2026-04-06T18:53:11.558351950Z","hd":{"ts_event":"2026-04-06T18:53:11.558339853Z","rtype":160,"publisher_id":101,"instrument_id":33115},"action":"R","side":"N","price":null,"size":0,"channel_id":79,"order_id":"0","flags":128,"ts_in_delta":12097,"sequence":3,"symbol":"EUCO SI 20260410 PS EU C 1.2300 0"}
{"ts_recv":"2026-04-06T18:53:11.558351950Z","hd":{"ts_event":"2026-04-06T18:53:11.558339853Z","rtype":160,"publisher_id":101,"instrument_id":33116},"action":"R","side":"N","price":null,"size":0,"channel_id":79,"order_id":"0","flags":128,"ts_in_delta":12097,"sequence":3,"symbol":"EUCO SI 20260410 PS EU P 1.2300 0"}
{"ts_recv":"2026-04-06T18:53:11.558351950Z","hd":{"ts_event":"2026-04-06T18:53:11.558339853Z","rtype":160,"publisher_id":101,"instrument_id":33117},"action":"R","side":"N","price":null,"size":0,"channel_id":79,"order_id":"0","flags":128,"ts_in_delta":12097,"sequence":3,"symbol":"EUCO SI 20260410 PS EU C 1.2350 0"}
{"ts_recv":"2026-04-06T18:53:11.558351950Z","hd":{"ts_event":"2026-04-06T18:53:11.558339853Z","rtype":160,"publisher_id":101,"instrument_id":33118},"action":"R","side":"N","price":null,"size":0,"channel_id":79,"order_id":"0","flags":128,"ts_in_delta":12097,"sequence":3,"symbol":"EUCO SI 20260410 PS EU P 1.2350 0"}
{"ts_recv":"2026-04-06T18:53:11.558351950Z","hd":{"ts_event":"2026-04-06T18:53:11.558339853Z","rtype":160,"publisher_id":101,"instrument_id":33119},"action":"R","side":"N","price":null,"size":0,"channel_id":79,"order_id":"0","flags":128,"ts_in_delta":12097,"sequence":3,"symbol":"EUCO SI 20260410 PS EU C 1.2400 0"}
{"ts_recv":"2026-04-06T18:53:11.558351950Z","hd":{"ts_event":"2026-04-06T18:53:11.558339853Z","rtype":160,"publisher_id":101,"instrument_id":33120},"action":"R","side":"N","price":null,"size":0,"channel_id":79,"order_id":"0","flags":128,"ts_in_delta":12097,"sequence":3,"symbol":"EUCO SI 20260410 PS EU P 1.2400 0"}
{"ts_recv":"2026-04-06T18:53:11.558351950Z","hd":{"ts_event":"2026-04-06T18:53:11.558339853Z","rtype":160,"publisher_id":101,"instrument_id":33121},"action":"R","side":"N","price":null,"size":0,"channel_id":79,"order_id":"0","flags":128,"ts_in_delta":12097,"sequence":3,"symbol":"EUCO SI 20260410 PS EU C 1.2450 0"}
{"ts_recv":"2026-04-06T18:53:11.558351950Z","hd":{"ts_event":"2026-04-06T18:53:11.558339853Z","rtype":160,"publisher_id":101,"instrument_id":33122},"action":"R","side":"N","price":null,"size":0,"channel_id":79,"order_id":"0","flags":128,"ts_in_delta":12097,"sequence":3,"symbol":"EUCO SI 20260410 PS EU P 1.2450 0"}
{"ts_recv":"2026-04-06T18:53:11.558351950Z","hd":{"ts_event":"2026-04-06T18:53:11.558339853Z","rtype":160,"publisher_id":101,"instrument_id":33123},"action":"R","side":"N","price":null,"size":0,"channel_id":79,"order_id":"0","flags":128,"ts_in_delta":12097,"sequence":3,"symbol":"EUCO SI 20260410 PS EU C 1.2500 0"}
{"ts_recv":"2026-04-06T18:53:11.558351950Z","hd":{"ts_event":"2026-04-06T18:53:11.558339853Z","rtype":160,"publisher_id":101,"instrument_id":33124},"action":"R","side":"N","price":null,"size":0,"channel_id":79,"order_id":"0","flags":128,"ts_in_delta":12097,"sequence":3,"symbol":"EUCO SI 20260410 PS EU P 1.2500 0"}
{"ts_recv":"2026-04-06T18:53:11.558351950Z","hd":{"ts_event":"2026-04-06T18:53:11.558339853Z","rtype":160,"publisher_id":101,"instrument_id":33125},"action":"R","side":"N","price":null,"size":0,"channel_id":79,"order_id":"0","flags":128,"ts_in_delta":12097,"sequence":3,"symbol":"EUCO SI 20260508 PS EU C 1.0900 0"}
{"ts_recv":"2026-04-06T18:53:11.558351950Z","hd":{"ts_event":"2026-04-06T18:53:11.558339853Z","rtype":160,"publisher_id":101,"instrument_id":33126},"action":"R","side":"N","price":null,"size":0,"channel_id":79,"order_id":"0","flags":128,"ts_in_delta":12097,"sequence":3,"symbol":"EUCO SI 20260508 PS EU P 1.0900 0"}
{"ts_recv":"2026-04-06T18:53:11.558351950Z","hd":{"ts_event":"2026-04-06T18:53:11.558339853Z","rtype":160,"publisher_id":101,"instrument_id":33127},"action":"R","side":"N","price":null,"size":0,"channel_id":79,"order_id":"0","flags":128,"ts_in_delta":12097,"sequence":3,"symbol":"EUCO SI 20260508 PS EU C 1.0950 0"}
{"ts_recv":"2026-04-06T18:53:11.558351950Z","hd":{"ts_event":"2026-04-06T18:53:11.558339853Z","rtype":160,"publisher_id":101,"instrument_id":33128},"action":"R","side":"N","price":null,"size":0,"channel_id":79,"order_id":"0","flags":128,"ts_in_delta":12097,"sequence":3,"symbol":"EUCO SI 20260508 PS EU P 1.0950 0"}
{"ts_recv":"2026-04-06T18:53:11.558351950Z","hd":{"ts_event":"2026-04-06T18:53:11.558339853Z","rtype":160,"publisher_id":101,"instrument_id":33129},"action":"R","side":"N","price":null,"size":0,"channel_id":79,"order_id":"0","flags":128,"ts_in_delta":12097,"sequence":3,"symbol":"EUCO SI 20260508 PS EU C 1.1000 0"}
{"ts_recv":"2026-04-06T18:53:11.558351950Z","hd":{"ts_event":"2026-04-06T18:53:11.558339853Z","rtype":160,"publisher_id":101,"instrument_id":33130},"action":"R","side":"N","price":null,"size":0,"channel_id":79,"order_id":"0","flags":128,"ts_in_delta":12097,"sequence":3,"symbol":"EUCO SI 20260508 PS EU P 1.1000 0"}
{"ts_recv":"2026-04-06T18:53:11.558351950Z","hd":{"ts_event":"2026-04-06T18:53:11.558339853Z","rtype":160,"publisher_id":101,"instrument_id":33131},"action":"R","side":"N","price":null,"size":0,"channel_id":79,"order_id":"0","flags":128,"ts_in_delta":12097,"sequence":3,"symbol":"EUCO SI 20260508 PS EU C 1.1050 0"}
{"ts_recv":"2026-04-06T18:53:11.558351950Z","hd":{"ts_event":"2026-04-06T18:53:11.558339853Z","rtype":160,"publisher_id":101,"instrument_id":33132},"action":"R","side":"N","price":null,"size":0,"channel_id":79,"order_id":"0","flags":128,"ts_in_delta":12097,"sequence":3,"symbol":"EUCO SI 20260508 PS EU P 1.1050 0"}
{"ts_recv":"2026-04-06T18:53:11.558351950Z","hd":{"ts_event":"2026-04-06T18:53:11.558339853Z","rtype":160,"publisher_id":101,"instrument_id":33133},"action":"R","side":"N","price":null,"size":0,"channel_id":79,"order_id":"0","flags":128,"ts_in_delta":12097,"sequence":3,"symbol":"EUCO SI 20260508 PS EU C 1.1100 0"}
{"ts_recv":"2026-04-06T18:53:11.558351950Z","hd":{"ts_event":"2026-04-06T18:53:11.558339853Z","rtype":160,"publisher_id":101,"instrument_id":33134},"action":"R","side":"N","price":null,"size":0,"channel_id":79,"order_id":"0","flags":128,"ts_in_delta":12097,"sequence":3,"symbol":"EUCO SI 20260508 PS EU P 1.1100 0"}
{"ts_recv":"2026-04-06T18:53:11.558351950Z","hd":{"ts_event":"2026-04-06T18:53:11.558339853Z","rtype":160,"publisher_id":101,"instrument_id":33135},"action":"R","side":"N","price":null,"size":0,"channel_id":79,"order_id":"0","flags":128,"ts_in_delta":12097,"sequence":3,"symbol":"EUCO SI 20260508 PS EU C 1.1150 0"}
{"ts_recv":"2026-04-06T18:53:11.558351950Z","hd":{"ts_event":"2026-04-06T18:53:11.558339853Z","rtype":160,"publisher_id":101,"instrument_id":33136},"action":"R","side":"N","price":null,"size":0,"channel_id":79,"order_id":"0","flags":128,"ts_in_delta":12097,"sequence":3,"symbol":"EUCO SI 20260508 PS EU P 1.1150 0"}
{"ts_recv":"2026-04-06T18:53:11.558351950Z","hd":{"ts_event":"2026-04-06T18:53:11.558339853Z","rtype":160,"publisher_id":101,"instrument_id":33137},"action":"R","side":"N","price":null,"size":0,"channel_id":79,"order_id":"0","flags":128,"ts_in_delta":12097,"sequence":3,"symbol":"EUCO SI 20260508 PS EU C 1.1200 0"}
{"ts_recv":"2026-04-06T18:53:11.558351950Z","hd":{"ts_event":"2026-04-06T18:53:11.558339853Z","rtype":160,"publisher_id":101,"instrument_id":33138},"action":"R","side":"N","price":null,"size":0,"channel_id":79,"order_id":"0","flags":128,"ts_in_delta":12097,"sequence":3,"symbol":"EUCO SI 20260508 PS EU P 1.1200 0"}
{"ts_recv":"2026-04-06T18:53:11.558351950Z","hd":{"ts_event":"2026-04-06T18:53:11.558339853Z","rtype":160,"publisher_id":101,"instrument_id":33139},"action":"R","side":"N","price":null,"size":0,"channel_id":79,"order_id":"0","flags":128,"ts_in_delta":12097,"sequence":3,"symbol":"EUCO SI 20260508 PS EU C 1.1250 0"}
{"ts_recv":"2026-04-06T18:53:11.558351950Z","hd":{"ts_event":"2026-04-06T18:53:11.558339853Z","rtype":160,"publisher_id":101,"instrument_id":33140},"action":"R","side":"N","price":null,"size":0,"channel_id":79,"order_id":"0","flags":128,"ts_in_delta":12097,"sequence":3,"symbol":"EUCO SI 20260508 PS EU P 1.1250 0"}
{"ts_recv":"2026-04-06T18:53:11.558351950Z","hd":{"ts_event":"2026-04-06T18:53:11.558339853Z","rtype":160,"publisher_id":101,"instrument_id":33141},"action":"R","side":"N","price":null,"size":0,"channel_id":79,"order_id":"0","flags":128,"ts_in_delta":12097,"sequence":3,"symbol":"EUCO SI 20260508 PS EU C 1.1275 0"}
{"ts_recv":"2026-04-06T18:53:11.558351950Z","hd":{"ts_event":"2026-04-06T18:53:11.558339853Z","rtype":160,"publisher_id":101,"instrument_id":33142},"action":"R","side":"N","price":null,"size":0,"channel_id":79,"order_id":"0","flags":128,"ts_in_delta":12097,"sequence":3,"symbol":"EUCO SI 20260508 PS EU P 1.1275 0"}
{"ts_recv":"2026-04-06T18:53:11.558351950Z","hd":{"ts_event":"2026-04-06T18:53:11.558339853Z","rtype":160,"publisher_id":101,"instrument_id":33143},"action":"R","side":"N","price":null,"size":0,"channel_id":79,"order_id":"0","flags":128,"ts_in_delta":12097,"sequence":3,"symbol":"EUCO SI 20260508 PS EU C 1.1300 0"}
{"ts_recv":"2026-04-06T18:53:11.558351950Z","hd":{"ts_event":"2026-04-06T18:53:11.558339853Z","rtype":160,"publisher_id":101,"instrument_id":33144},"action":"R","side":"N","price":null,"size":0,"channel_id":79,"order_id":"0","flags":128,"ts_in_delta":12097,"sequence":3,"symbol":"EUCO SI 20260508 PS EU P 1.1300 0"}
{"ts_recv":"2026-04-06T18:53:11.558351950Z","hd":{"ts_event":"2026-04-06T18:53:11.558339853Z","rtype":160,"publisher_id":101,"instrument_id":33145},"action":"R","side":"N","price":null,"size":0,"channel_id":79,"order_id":"0","flags":128,"ts_in_delta":12097,"sequence":3,"symbol":"EUCO SI 20260508 PS EU C 1.1325 0"}
{"ts_recv":"2026-04-06T18:53:11.558351950Z","hd":{"ts_event":"2026-04-06T18:53:11.558339853Z","rtype":160,"publisher_id":101,"instrument_id":33146},"action":"R","side":"N","price":null,"size":0,"channel_id":79,"order_id":"0","flags":128,"ts_in_delta":12097,"sequence":3,"symbol":"EUCO SI 20260508 PS EU P 1.1325 0"}
{"ts_recv":"2026-04-06T18:53:11.558351950Z","hd":{"ts_event":"2026-04-06T18:53:11.558339853Z","rtype":160,"publisher_id":101,"instrument_id":33147},"action":"R","side":"N","price":null,"size":0,"channel_id":79,"order_id":"0","flags":128,"ts_in_delta":12097,"sequence":3,"symbol":"EUCO SI 20260508 PS EU C 1.1350 0"}
{"ts_recv":"2026-04-06T18:53:11.558351950Z","hd":{"ts_event":"2026-04-06T18:53:11.558339853Z","rtype":160,"publisher_id":101,"instrument_id":33148},"action":"R","side":"N","price":null,"size":0,"channel_id":79,"order_id":"0","flags":128,"ts_in_delta":12097,"sequence":3,"symbol":"EUCO SI 20260508 PS EU P 1.1350 0"}
{"ts_recv":"2026-04-06T18:53:11.558351950Z","hd":{"ts_event":"2026-04-06T18:53:11.558339853Z","rtype":160,"publisher_id":101,"instrument_id":33149},"action":"R","side":"N","price":null,"size":0,"channel_id":79,"order_id":"0","flags":128,"ts_in_delta":12097,"sequence":3,"symbol":"EUCO SI 20260508 PS EU C 1.1375 0"}
{"ts_recv":"2026-04-06T18:53:11.558351950Z","hd":{"ts_event":"2026-04-06T18:53:11.558339853Z","rtype":160,"publisher_id":101,"instrument_id":33150},"action":"R","side":"N","price":null,"size":0,"channel_id":79,"order_id":"0","flags":128,"ts_in_delta":12097,"sequence":3,"symbol":"EUCO SI 20260508 PS EU P 1.1375 0"}
{"ts_recv":"2026-04-06T18:53:11.558351950Z","hd":{"ts_event":"2026-04-06T18:53:11.558339853Z","rtype":160,"publisher_id":101,"instrument_id":33151},"action":"R","side":"N","price":null,"size":0,"channel_id":79,"order_id":"0","flags":128,"ts_in_delta":12097,"sequence":3,"symbol":"EUCO SI 20260508 PS EU C 1.1400 0"}
{"ts_recv":"2026-04-06T18:53:11.558351950Z","hd":{"ts_event":"2026-04-06T18:53:11.558339853Z","rtype":160,"publisher_id":101,"instrument_id":33152},"action":"R","side":"N","price":null,"size":0,"channel_id":79,"order_id":"0","flags":128,"ts_in_delta":12097,"sequence":3,"symbol":"EUCO SI 20260508 PS EU P 1.1400 0"}
{"ts_recv":"2026-04-06T18:53:11.558351950Z","hd":{"ts_event":"2026-04-06T18:53:11.558339853Z","rtype":160,"publisher_id":101,"instrument_id":33153},"action":"R","side":"N","price":null,"size":0,"channel_id":79,"order_id":"0","flags":128,"ts_in_delta":12097,"sequence":3,"symbol":"EUCO SI 20260508 PS EU C 1.1425 0"}
{"ts_recv":"2026-04-06T18:53:11.558351950Z","hd":{"ts_event":"2026-04-06T18:53:11.558339853Z","rtype":160,"publisher_id":101,"instrument_id":33154},"action":"R","side":"N","price":null,"size":0,"channel_id":79,"order_id":"0","flags":128,"ts_in_delta":12097,"sequence":3,"symbol":"EUCO SI 20260508 PS EU P 1.1425 0"}
{"ts_recv":"2026-04-06T18:53:11.558351950Z","hd":{"ts_event":"2026-04-06T18:53:11.558339853Z","rtype":160,"publisher_id":101,"instrument_id":33155},"action":"R","side":"N","price":null,"size":0,"channel_id":79,"order_id":"0","flags":128,"ts_in_delta":12097,"sequence":3,"symbol":"EUCO SI 20260508 PS EU C 1.1450 0"}
{"ts_recv":"2026-04-06T18:53:11.558351950Z","hd":{"ts_event":"2026-04-06T18:53:11.558339853Z","rtype":160,"publisher_id":101,"instrument_id":33156},"action":"R","side":"N","price":null,"size":0,"channel_id":79,"order_id":"0","flags":128,"ts_in_delta":12097,"sequence":3,"symbol":"EUCO SI 20260508 PS EU P 1.1450 0"}
{"ts_recv":"2026-04-06T18:53:11.558351950Z","hd":{"ts_event":"2026-04-06T18:53:11.558339853Z","rtype":160,"publisher_id":101,"instrument_id":33157},"action":"R","side":"N","price":null,"size":0,"channel_id":79,"order_id":"0","flags":128,"ts_in_delta":12097,"sequence":3,"symbol":"EUCO SI 20260508 PS EU C 1.1475 0"}
{"ts_recv":"2026-04-06T18:53:11.558351950Z","hd":{"ts_event":"2026-04-06T18:53:11.558339853Z","rtype":160,"publisher_id":101,"instrument_id":33158},"action":"R","side":"N","price":null,"size":0,"channel_id":79,"order_id":"0","flags":128,"ts_in_delta":12097,"sequence":3,"symbol":"EUCO SI 20260508 PS EU P 1.1475 0"}
{"ts_recv":"2026-04-06T18:53:11.558351950Z","hd":{"ts_event":"2026-04-06T18:53:11.558339853Z","rtype":160,"publisher_id":101,"instrument_id":33159},"action":"R","side":"N","price":null,"size":0,"channel_id":79,"order_id":"0","flags":128,"ts_in_delta":12097,"sequence":3,"symbol":"EUCO SI 20260508 PS EU C 1.1500 0"}
{"ts_recv":"2026-04-06T18:53:11.558351950Z","hd":{"ts_event":"2026-04-06T18:53:11.558339853Z","rtype":160,"publisher_id":101,"instrument_id":33160},"action":"R","side":"N","price":null,"size":0,"channel_id":79,"order_id":"0","flags":128,"ts_in_delta":12097,"sequence":3,"symbol":"EUCO SI 20260508 PS EU P 1.1500 0"}
{"ts_recv":"2026-04-06T18:53:11.558351950Z","hd":{"ts_event":"2026-04-06T18:53:11.558339853Z","rtype":160,"publisher_id":101,"instrument_id":33161},"action":"R","side":"N","price":null,"size":0,"channel_id":79,"order_id":"0","flags":128,"ts_in_delta":12097,"sequence":3,"symbol":"EUCO SI 20260508 PS EU C 1.1525 0"}
{"ts_recv":"2026-04-06T18:53:11.558351950Z","hd":{"ts_event":"2026-04-06T18:53:11.558339853Z","rtype":160,"publisher_id":101,"instrument_id":33162},"action":"R","side":"N","price":null,"size":0,"channel_id":79,"order_id":"0","flags":128,"ts_in_delta":12097,"sequence":3,"symbol":"EUCO SI 20260508 PS EU P 1.1525 0"}
{"ts_recv":"2026-04-06T18:53:11.558351950Z","hd":{"ts_event":"2026-04-06T18:53:11.558339853Z","rtype":160,"publisher_id":101,"instrument_id":33163},"action":"R","side":"N","price":null,"size":0,"channel_id":79,"order_id":"0","flags":128,"ts_in_delta":12097,"sequence":3,"symbol":"EUCO SI 20260508 PS EU C 1.1550 0"}
{"ts_recv":"2026-04-06T18:53:11.558351950Z","hd":{"ts_event":"2026-04-06T18:53:11.558339853Z","rtype":160,"publisher_id":101,"instrument_id":33164},"action":"R","side":"N","price":null,"size":0,"channel_id":79,"order_id":"0","flags":128,"ts_in_delta":12097,"sequence":3,"symbol":"EUCO SI 20260508 PS EU P 1.1550 0"}
{"ts_recv":"2026-04-06T18:53:11.558351950Z","hd":{"ts_event":"2026-04-06T18:53:11.558339853Z","rtype":160,"publisher_id":101,"instrument_id":33165},"action":"R","side":"N","price":null,"size":0,"channel_id":79,"order_id":"0","flags":128,"ts_in_delta":12097,"sequence":3,"symbol":"EUCO SI 20260508 PS EU C 1.1575 0"}
{"ts_recv":"2026-04-06T18:53:11.558351950Z","hd":{"ts_event":"2026-04-06T18:53:11.558339853Z","rtype":160,"publisher_id":101,"instrument_id":33166},"action":"R","side":"N","price":null,"size":0,"channel_id":79,"order_id":"0","flags":128,"ts_in_delta":12097,"sequence":3,"symbol":"EUCO SI 20260508 PS EU P 1.1575 0"}
{"ts_recv":"2026-04-06T18:53:11.558351950Z","hd":{"ts_event":"2026-04-06T18:53:11.558339853Z","rtype":160,"publisher_id":101,"instrument_id":33167},"action":"R","side":"N","price":null,"size":0,"channel_id":79,"order_id":"0","flags":128,"ts_in_delta":12097,"sequence":3,"symbol":"EUCO SI 20260508 PS EU C 1.1600 0"}
{"ts_recv":"2026-04-06T18:53:11.558351950Z","hd":{"ts_event":"2026-04-06T18:53:11.558339853Z","rtype":160,"publisher_id":101,"instrument_id":33168},"action":"R","side":"N","price":null,"size":0,"channel_id":79,"order_id":"0","flags":128,"ts_in_delta":12097,"sequence":3,"symbol":"EUCO SI 20260508 PS EU P 1.1600 0"}
{"ts_recv":"2026-04-06T18:53:11.558351950Z","hd":{"ts_event":"2026-04-06T18:53:11.558339853Z","rtype":160,"publisher_id":101,"instrument_id":33169},"action":"R","side":"N","price":null,"size":0,"channel_id":79,"order_id":"0","flags":128,"ts_in_delta":12097,"sequence":3,"symbol":"EUCO SI 20260508 PS EU C 1.1625 0"}
{"ts_recv":"2026-04-06T18:53:11.558351950Z","hd":{"ts_event":"2026-04-06T18:53:11.558339853Z","rtype":160,"publisher_id":101,"instrument_id":33170},"action":"R","side":"N","price":null,"size":0,"channel_id":79,"order_id":"0","flags":128,"ts_in_delta":12097,"sequence":3,"symbol":"EUCO SI 20260508 PS EU P 1.1625 0"}
{"ts_recv":"2026-04-06T18:53:11.558351950Z","hd":{"ts_event":"2026-04-06T18:53:11.558339853Z","rtype":160,"publisher_id":101,"instrument_id":33171},"action":"R","side":"N","price":null,"size":0,"channel_id":79,"order_id":"0","flags":128,"ts_in_delta":12097,"sequence":3,"symbol":"EUCO SI 20260508 PS EU C 1.1650 0"}
{"ts_recv":"2026-04-06T18:53:11.558351950Z","hd":{"ts_event":"2026-04-06T18:53:11.558339853Z","rtype":160,"publisher_id":101,"instrument_id":33172},"action":"R","side":"N","price":null,"size":0,"channel_id":79,"order_id":"0","flags":128,"ts_in_delta":12097,"sequence":3,"symbol":"EUCO SI 20260508 PS EU P 1.1650 0"}
{"ts_recv":"2026-04-06T18:53:11.558351950Z","hd":{"ts_event":"2026-04-06T18:53:11.558339853Z","rtype":160,"publisher_id":101,"instrument_id":33173},"action":"R","side":"N","price":null,"size":0,"channel_id":79,"order_id":"0","flags":128,"ts_in_delta":12097,"sequence":3,"symbol":"EUCO SI 20260508 PS EU C 1.1675 0"}
{"ts_recv":"2026-04-06T18:53:11.558351950Z","hd":{"ts_event":"2026-04-06T18:53:11.558339853Z","rtype":160,"publisher_id":101,"instrument_id":33174},"action":"R","side":"N","price":null,"size":0,"channel_id":79,"order_id":"0","flags":128,"ts_in_delta":12097,"sequence":3,"symbol":"EUCO SI 20260508 PS EU P 1.1675 0"}
{"ts_recv":"2026-04-06T18:53:11.558351950Z","hd":{"ts_event":"2026-04-06T18:53:11.558339853Z","rtype":160,"publisher_id":101,"instrument_id":33175},"action":"R","side":"N","price":null,"size":0,"channel_id":79,"order_id":"0","flags":128,"ts_in_delta":12097,"sequence":3,"symbol":"EUCO SI 20260508 PS EU C 1.1700 0"}
{"ts_recv":"2026-04-06T18:53:11.558351950Z","hd":{"ts_event":"2026-04-06T18:53:11.558339853Z","rtype":160,"publisher_id":101,"instrument_id":33176},"action":"R","side":"N","price":null,"size":0,"channel_id":79,"order_id":"0","flags":128,"ts_in_delta":12097,"sequence":3,"symbol":"EUCO SI 20260508 PS EU P 1.1700 0"}
{"ts_recv":"2026-04-06T18:53:11.558351950Z","hd":{"ts_event":"2026-04-06T18:53:11.558339853Z","rtype":160,"publisher_id":101,"instrument_id":33177},"action":"R","side":"N","price":null,"size":0,"channel_id":79,"order_id":"0","flags":128,"ts_in_delta":12097,"sequence":3,"symbol":"EUCO SI 20260508 PS EU C 1.1725 0"}
{"ts_recv":"2026-04-06T18:53:11.558351950Z","hd":{"ts_event":"2026-04-06T18:53:11.558339853Z","rtype":160,"publisher_id":101,"instrument_id":33178},"action":"R","side":"N","price":null,"size":0,"channel_id":79,"order_id":"0","flags":128,"ts_in_delta":12097,"sequence":3,"symbol":"EUCO SI 20260508 PS EU P 1.1725 0"}
{"ts_recv":"2026-04-06T18:53:11.558351950Z","hd":{"ts_event":"2026-04-06T18:53:11.558339853Z","rtype":160,"publisher_id":101,"instrument_id":33179},"action":"R","side":"N","price":null,"size":0,"channel_id":79,"order_id":"0","flags":128,"ts_in_delta":12097,"sequence":3,"symbol":"EUCO SI 20260508 PS EU C 1.1750 0"}
{"ts_recv":"2026-04-06T18:53:11.558351950Z","hd":{"ts_event":"2026-04-06T18:53:11.558339853Z","rtype":160,"publisher_id":101,"instrument_id":33180},"action":"R","side":"N","price":null,"size":0,"channel_id":79,"order_id":"0","flags":128,"ts_in_delta":12097,"sequence":3,"symbol":"EUCO SI 20260508 PS EU P 1.1750 0"}
{"ts_recv":"2026-04-06T18:53:11.558351950Z","hd":{"ts_event":"2026-04-06T18:53:11.558339853Z","rtype":160,"publisher_id":101,"instrument_id":33181},"action":"R","side":"N","price":null,"size":0,"channel_id":79,"order_id":"0","flags":128,"ts_in_delta":12097,"sequence":3,"symbol":"EUCO SI 20260508 PS EU C 1.1775 0"}
{"ts_recv":"2026-04-06T18:53:11.558351950Z","hd":{"ts_event":"2026-04-06T18:53:11.558339853Z","rtype":160,"publisher_id":101,"instrument_id":33182},"action":"R","side":"N","price":null,"size":0,"channel_id":79,"order_id":"0","flags":128,"ts_in_delta":12097,"sequence":3,"symbol":"EUCO SI 20260508 PS EU P 1.1775 0"}
{"ts_recv":"2026-04-06T18:53:11.558351950Z","hd":{"ts_event":"2026-04-06T18:53:11.558339853Z","rtype":160,"publisher_id":101,"instrument_id":33183},"action":"R","side":"N","price":null,"size":0,"channel_id":79,"order_id":"0","flags":128,"ts_in_delta":12097,"sequence":3,"symbol":"EUCO SI 20260508 PS EU C 1.1800 0"}
{"ts_recv":"2026-04-06T18:53:11.558351950Z","hd":{"ts_event":"2026-04-06T18:53:11.558339853Z","rtype":160,"publisher_id":101,"instrument_id":33184},"action":"R","side":"N","price":null,"size":0,"channel_id":79,"order_id":"0","flags":128,"ts_in_delta":12097,"sequence":3,"symbol":"EUCO SI 20260508 PS EU P 1.1800 0"}
{"ts_recv":"2026-04-06T18:53:11.558351950Z","hd":{"ts_event":"2026-04-06T18:53:11.558339853Z","rtype":160,"publisher_id":101,"instrument_id":33185},"action":"R","side":"N","price":null,"size":0,"channel_id":79,"order_id":"0","flags":128,"ts_in_delta":12097,"sequence":3,"symbol":"EUCO SI 20260508 PS EU C 1.1825 0"}
{"ts_recv":"2026-04-06T18:53:11.558351950Z","hd":{"ts_event":"2026-04-06T18:53:11.558339853Z","rtype":160,"publisher_id":101,"instrument_id":33186},"action":"R","side":"N","price":null,"size":0,"channel_id":79,"order_id":"0","flags":128,"ts_in_delta":12097,"sequence":3,"symbol":"EUCO SI 20260508 PS EU P 1.1825 0"}
{"ts_recv":"2026-04-06T18:53:11.558351950Z","hd":{"ts_event":"2026-04-06T18:53:11.558339853Z","rtype":160,"publisher_id":101,"instrument_id":33187},"action":"R","side":"N","price":null,"size":0,"channel_id":79,"order_id":"0","flags":128,"ts_in_delta":12097,"sequence":3,"symbol":"EUCO SI 20260508 PS EU C 1.1850 0"}
{"ts_recv":"2026-04-06T18:53:11.558351950Z","hd":{"ts_event":"2026-04-06T18:53:11.558339853Z","rtype":160,"publisher_id":101,"instrument_id":33188},"action":"R","side":"N","price":null,"size":0,"channel_id":79,"order_id":"0","flags":128,"ts_in_delta":12097,"sequence":3,"symbol":"EUCO SI 20260508 PS EU P 1.1850 0"}
{"ts_recv":"2026-04-06T18:53:11.558351950Z","hd":{"ts_event":"2026-04-06T18:53:11.558339853Z","rtype":160,"publisher_id":101,"instrument_id":33189},"action":"R","side":"N","price":null,"size":0,"channel_id":79,"order_id":"0","flags":128,"ts_in_delta":12097,"sequence":3,"symbol":"EUCO SI 20260508 PS EU C 1.1875 0"}
{"ts_recv":"2026-04-06T18:53:11.558351950Z","hd":{"ts_event":"2026-04-06T18:53:11.558339853Z","rtype":160,"publisher_id":101,"instrument_id":33190},"action":"R","side":"N","price":null,"size":0,"channel_id":79,"order_id":"0","flags":128,"ts_in_delta":12097,"sequence":3,"symbol":"EUCO SI 20260508 PS EU P 1.1875 0"}
{"ts_recv":"2026-04-06T18:53:11.558351950Z","hd":{"ts_event":"2026-04-06T18:53:11.558339853Z","rtype":160,"publisher_id":101,"instrument_id":33191},"action":"R","side":"N","price":null,"size":0,"channel_id":79,"order_id":"0","flags":128,"ts_in_delta":12097,"sequence":3,"symbol":"EUCO SI 20260508 PS EU C 1.1900 0"}
{"ts_recv":"2026-04-06T18:53:11.558351950Z","hd":{"ts_event":"2026-04-06T18:53:11.558339853Z","rtype":160,"publisher_id":101,"instrument_id":33192},"action":"R","side":"N","price":null,"size":0,"channel_id":79,"order_id":"0","flags":128,"ts_in_delta":12097,"sequence":3,"symbol":"EUCO SI 20260508 PS EU P 1.1900 0"}
{"ts_recv":"2026-04-06T18:53:11.558351950Z","hd":{"ts_event":"2026-04-06T18:53:11.558339853Z","rtype":160,"publisher_id":101,"instrument_id":33193},"action":"R","side":"N","price":null,"size":0,"channel_id":79,"order_id":"0","flags":128,"ts_in_delta":12097,"sequence":3,"symbol":"EUCO SI 20260508 PS EU C 1.1925 0"}
{"ts_recv":"2026-04-06T18:53:11.558351950Z","hd":{"ts_event":"2026-04-06T18:53:11.558339853Z","rtype":160,"publisher_id":101,"instrument_id":33194},"action":"R","side":"N","price":null,"size":0,"channel_id":79,"order_id":"0","flags":128,"ts_in_delta":12097,"sequence":3,"symbol":"EUCO SI 20260508 PS EU P 1.1925 0"}
{"ts_recv":"2026-04-06T18:53:11.558351950Z","hd":{"ts_event":"2026-04-06T18:53:11.558339853Z","rtype":160,"publisher_id":101,"instrument_id":33195},"action":"R","side":"N","price":null,"size":0,"channel_id":79,"order_id":"0","flags":128,"ts_in_delta":12097,"sequence":3,"symbol":"EUCO SI 20260508 PS EU C 1.1950 0"}
{"ts_recv":"2026-04-06T18:53:11.558351950Z","hd":{"ts_event":"2026-04-06T18:53:11.558339853Z","rtype":160,"publisher_id":101,"instrument_id":33196},"action":"R","side":"N","price":null,"size":0,"channel_id":79,"order_id":"0","flags":128,"ts_in_delta":12097,"sequence":3,"symbol":"EUCO SI 20260508 PS EU P 1.1950 0"}
{"ts_recv":"2026-04-06T18:53:11.558351950Z","hd":{"ts_event":"2026-04-06T18:53:11.558339853Z","rtype":160,"publisher_id":101,"instrument_id":33197},"action":"R","side":"N","price":null,"size":0,"channel_id":79,"order_id":"0","flags":128,"ts_in_delta":12097,"sequence":3,"symbol":"EUCO SI 20260508 PS EU C 1.1975 0"}
{"ts_recv":"2026-04-06T18:53:11.558351950Z","hd":{"ts_event":"2026-04-06T18:53:11.558339853Z","rtype":160,"publisher_id":101,"instrument_id":33198},"action":"R","side":"N","price":null,"size":0,"channel_id":79,"order_id":"0","flags":128,"ts_in_delta":12097,"sequence":3,"symbol":"EUCO SI 20260508 PS EU P 1.1975 0"}
{"ts_recv":"2026-04-06T18:53:11.558351950Z","hd":{"ts_event":"2026-04-06T18:53:11.558339853Z","rtype":160,"publisher_id":101,"instrument_id":33199},"action":"R","side":"N","price":null,"size":0,"channel_id":79,"order_id":"0","flags":128,"ts_in_delta":12097,"sequence":3,"symbol":"EUCO SI 20260508 PS EU C 1.2000 0"}
{"ts_recv":"2026-04-06T18:53:11.558351950Z","hd":{"ts_event":"2026-04-06T18:53:11.558339853Z","rtype":160,"publisher_id":101,"instrument_id":33200},"action":"R","side":"N","price":null,"size":0,"channel_id":79,"order_id":"0","flags":128,"ts_in_delta":12097,"sequence":3,"symbol":"EUCO SI 20260508 PS EU P 1.2000 0"}
{"ts_recv":"2026-04-06T18:53:11.558351950Z","hd":{"ts_event":"2026-04-06T18:53:11.558339853Z","rtype":160,"publisher_id":101,"instrument_id":33201},"action":"R","side":"N","price":null,"size":0,"channel_id":79,"order_id":"0","flags":128,"ts_in_delta":12097,"sequence":3,"symbol":"EUCO SI 20260508 PS EU C 1.2025 0"}
{"ts_recv":"2026-04-06T18:53:11.558351950Z","hd":{"ts_event":"2026-04-06T18:53:11.558339853Z","rtype":160,"publisher_id":101,"instrument_id":33202},"action":"R","side":"N","price":null,"size":0,"channel_id":79,"order_id":"0","flags":128,"ts_in_delta":12097,"sequence":3,"symbol":"EUCO SI 20260508 PS EU P 1.2025 0"}
{"ts_recv":"2026-04-06T18:53:11.558351950Z","hd":{"ts_event":"2026-04-06T18:53:11.558339853Z","rtype":160,"publisher_id":101,"instrument_id":33203},"action":"R","side":"N","price":null,"size":0,"channel_id":79,"order_id":"0","flags":128,"ts_in_delta":12097,"sequence":3,"symbol":"EUCO SI 20260508 PS EU C 1.2050 0"}
{"ts_recv":"2026-04-06T18:53:11.558351950Z","hd":{"ts_event":"2026-04-06T18:53:11.558339853Z","rtype":160,"publisher_id":101,"instrument_id":33204},"action":"R","side":"N","price":null,"size":0,"channel_id":79,"order_id":"0","flags":128,"ts_in_delta":12097,"sequence":3,"symbol":"EUCO SI 20260508 PS EU P 1.2050 0"}
{"ts_recv":"2026-04-06T18:53:11.558351950Z","hd":{"ts_event":"2026-04-06T18:53:11.558339853Z","rtype":160,"publisher_id":101,"instrument_id":33205},"action":"R","side":"N","price":null,"size":0,"channel_id":79,"order_id":"0","flags":128,"ts_in_delta":12097,"sequence":3,"symbol":"EUCO SI 20260508 PS EU C 1.2075 0"}
{"ts_recv":"2026-04-06T18:53:11.558351950Z","hd":{"ts_event":"2026-04-06T18:53:11.558339853Z","rtype":160,"publisher_id":101,"instrument_id":33206},"action":"R","side":"N","price":null,"size":0,"channel_id":79,"order_id":"0","flags":128,"ts_in_delta":12097,"sequence":3,"symbol":"EUCO SI 20260508 PS EU P 1.2075 0"}
{"ts_recv":"2026-04-06T18:53:11.558351950Z","hd":{"ts_event":"2026-04-06T18:53:11.558339853Z","rtype":160,"publisher_id":101,"instrument_id":33207},"action":"R","side":"N","price":null,"size":0,"channel_id":79,"order_id":"0","flags":128,"ts_in_delta":12097,"sequence":3,"symbol":"EUCO SI 20260508 PS EU C 1.2100 0"}
{"ts_recv":"2026-04-06T18:53:11.558351950Z","hd":{"ts_event":"2026-04-06T18:53:11.558339853Z","rtype":160,"publisher_id":101,"instrument_id":33208},"action":"R","side":"N","price":null,"size":0,"channel_id":79,"order_id":"0","flags":128,"ts_in_delta":12097,"sequence":3,"symbol":"EUCO SI 20260508 PS EU P 1.2100 0"}
{"ts_recv":"2026-04-06T18:53:11.558351950Z","hd":{"ts_event":"2026-04-06T18:53:11.558339853Z","rtype":160,"publisher_id":101,"instrument_id":33209},"action":"R","side":"N","price":null,"size":0,"channel_id":79,"order_id":"0","flags":128,"ts_in_delta":12097,"sequence":3,"symbol":"EUCO SI 20260508 PS EU C 1.2125 0"}
{"ts_recv":"2026-04-06T18:53:11.558351950Z","hd":{"ts_event":"2026-04-06T18:53:11.558339853Z","rtype":160,"publisher_id":101,"instrument_id":33210},"action":"R","side":"N","price":null,"size":0,"channel_id":79,"order_id":"0","flags":128,"ts_in_delta":12097,"sequence":3,"symbol":"EUCO SI 20260508 PS EU P 1.2125 0"}
{"ts_recv":"2026-04-06T18:53:11.558351950Z","hd":{"ts_event":"2026-04-06T18:53:11.558339853Z","rtype":160,"publisher_id":101,"instrument_id":33211},"action":"R","side":"N","price":null,"size":0,"channel_id":79,"order_id":"0","flags":128,"ts_in_delta":12097,"sequence":3,"symbol":"EUCO SI 20260508 PS EU C 1.2150 0"}
{"ts_recv":"2026-04-06T18:53:11.558351950Z","hd":{"ts_event":"2026-04-06T18:53:11.558339853Z","rtype":160,"publisher_id":101,"instrument_id":33212},"action":"R","side":"N","price":null,"size":0,"channel_id":79,"order_id":"0","flags":128,"ts_in_delta":12097,"sequence":3,"symbol":"EUCO SI 20260508 PS EU P 1.2150 0"}
{"ts_recv":"2026-04-06T18:53:11.558351950Z","hd":{"ts_event":"2026-04-06T18:53:11.558339853Z","rtype":160,"publisher_id":101,"instrument_id":33213},"action":"R","side":"N","price":null,"size":0,"channel_id":79,"order_id":"0","flags":128,"ts_in_delta":12097,"sequence":3,"symbol":"EUCO SI 20260508 PS EU C 1.2175 0"}
{"ts_recv":"2026-04-06T18:53:11.558351950Z","hd":{"ts_event":"2026-04-06T18:53:11.558339853Z","rtype":160,"publisher_id":101,"instrument_id":33214},"action":"R","side":"N","price":null,"size":0,"channel_id":79,"order_id":"0","flags":128,"ts_in_delta":12097,"sequence":3,"symbol":"EUCO SI 20260508 PS EU P 1.2175 0"}
{"ts_recv":"2026-04-06T18:53:11.558351950Z","hd":{"ts_event":"2026-04-06T18:53:11.558339853Z","rtype":160,"publisher_id":101,"instrument_id":33215},"action":"R","side":"N","price":null,"size":0,"channel_id":79,"order_id":"0","flags":128,"ts_in_delta":12097,"sequence":3,"symbol":"EUCO SI 20260508 PS EU C 1.2200 0"}
{"ts_recv":"2026-04-06T18:53:11.558351950Z","hd":{"ts_event":"2026-04-06T18:53:11.558339853Z","rtype":160,"publisher_id":101,"instrument_id":33216},"action":"R","side":"N","price":null,"size":0,"channel_id":79,"order_id":"0","flags":128,"ts_in_delta":12097,"sequence":3,"symbol":"EUCO SI 20260508 PS EU P 1.2200 0"}
{"ts_recv":"2026-04-06T18:53:11.558351950Z","hd":{"ts_event":"2026-04-06T18:53:11.558339853Z","rtype":160,"publisher_id":101,"instrument_id":33217},"action":"R","side":"N","price":null,"size":0,"channel_id":79,"order_id":"0","flags":128,"ts_in_delta":12097,"sequence":3,"symbol":"EUCO SI 20260508 PS EU C 1.2225 0"}
{"ts_recv":"2026-04-06T18:53:11.558351950Z","hd":{"ts_event":"2026-04-06T18:53:11.558339853Z","rtype":160,"publisher_id":101,"instrument_id":33218},"action":"R","side":"N","price":null,"size":0,"channel_id":79,"order_id":"0","flags":128,"ts_in_delta":12097,"sequence":3,"symbol":"EUCO SI 20260508 PS EU P 1.2225 0"}
{"ts_recv":"2026-04-06T18:53:11.558351950Z","hd":{"ts_event":"2026-04-06T18:53:11.558339853Z","rtype":160,"publisher_id":101,"instrument_id":33219},"action":"R","side":"N","price":null,"size":0,"channel_id":79,"order_id":"0","flags":128,"ts_in_delta":12097,"sequence":3,"symbol":"EUCO SI 20260508 PS EU C 1.2250 0"}
{"ts_recv":"2026-04-06T18:53:11.558351950Z","hd":{"ts_event":"2026-04-06T18:53:11.558339853Z","rtype":160,"publisher_id":101,"instrument_id":33220},"action":"R","side":"N","price":null,"size":0,"channel_id":79,"order_id":"0","flags":128,"ts_in_delta":12097,"sequence":3,"symbol":"EUCO SI 20260508 PS EU P 1.2250 0"}
{"ts_recv":"2026-04-06T18:53:11.558351950Z","hd":{"ts_event":"2026-04-06T18:53:11.558339853Z","rtype":160,"publisher_id":101,"instrument_id":33221},"action":"R","side":"N","price":null,"size":0,"channel_id":79,"order_id":"0","flags":128,"ts_in_delta":12097,"sequence":3,"symbol":"EUCO SI 20260508 PS EU C 1.2300 0"}
{"ts_recv":"2026-04-06T18:53:11.558351950Z","hd":{"ts_event":"2026-04-06T18:53:11.558339853Z","rtype":160,"publisher_id":101,"instrument_id":33222},"action":"R","side":"N","price":null,"size":0,"channel_id":79,"order_id":"0","flags":128,"ts_in_delta":12097,"sequence":3,"symbol":"EUCO SI 20260508 PS EU P 1.2300 0"}
{"ts_recv":"2026-04-06T18:53:11.558351950Z","hd":{"ts_event":"2026-04-06T18:53:11.558339853Z","rtype":160,"publisher_id":101,"instrument_id":33223},"action":"R","side":"N","price":null,"size":0,"channel_id":79,"order_id":"0","flags":128,"ts_in_delta":12097,"sequence":3,"symbol":"EUCO SI 20260508 PS EU C 1.2350 0"}
{"ts_recv":"2026-04-06T18:53:11.558351950Z","hd":{"ts_event":"2026-04-06T18:53:11.558339853Z","rtype":160,"publisher_id":101,"instrument_id":33224},"action":"R","side":"N","price":null,"size":0,"channel_id":79,"order_id":"0","flags":128,"ts_in_delta":12097,"sequence":3,"symbol":"EUCO SI 20260508 PS EU P 1.2350 0"}
{"ts_recv":"2026-04-06T18:53:11.558351950Z","hd":{"ts_event":"2026-04-06T18:53:11.558339853Z","rtype":160,"publisher_id":101,"instrument_id":33225},"action":"R","side":"N","price":null,"size":0,"channel_id":79,"order_id":"0","flags":128,"ts_in_delta":12097,"sequence":3,"symbol":"EUCO SI 20260508 PS EU C 1.2400 0"}
{"ts_recv":"2026-04-06T18:53:11.558351950Z","hd":{"ts_event":"2026-04-06T18:53:11.558339853Z","rtype":160,"publisher_id":101,"instrument_id":33226},"action":"R","side":"N","price":null,"size":0,"channel_id":79,"order_id":"0","flags":128,"ts_in_delta":12097,"sequence":3,"symbol":"EUCO SI 20260508 PS EU P 1.2400 0"}
{"ts_recv":"2026-04-06T18:53:11.558351950Z","hd":{"ts_event":"2026-04-06T18:53:11.558339853Z","rtype":160,"publisher_id":101,"instrument_id":33227},"action":"R","side":"N","price":null,"size":0,"channel_id":79,"order_id":"0","flags":128,"ts_in_delta":12097,"sequence":3,"symbol":"EUCO SI 20260508 PS EU C 1.2450 0"}
{"ts_recv":"2026-04-06T18:53:11.558351950Z","hd":{"ts_event":"2026-04-06T18:53:11.558339853Z","rtype":160,"publisher_id":101,"instrument_id":33228},"action":"R","side":"N","price":null,"size":0,"channel_id":79,"order_id":"0","flags":128,"ts_in_delta":12097,"sequence":3,"symbol":"EUCO SI 20260508 PS EU P 1.2450 0"}
{"ts_recv":"2026-04-06T18:53:11.558351950Z","hd":{"ts_event":"2026-04-06T18:53:11.558339853Z","rtype":160,"publisher_id":101,"instrument_id":33229},"action":"R","side":"N","price":null,"size":0,"channel_id":79,"order_id":"0","flags":128,"ts_in_delta":12097,"sequence":3,"symbol":"EUCO SI 20260508 PS EU C 1.2500 0"}
{"ts_recv":"2026-04-06T18:53:11.558351950Z","hd":{"ts_event":"2026-04-06T18:53:11.558339853Z","rtype":160,"publisher_id":101,"instrument_id":33230},"action":"R","side":"N","price":null,"size":0,"channel_id":79,"order_id":"0","flags":128,"ts_in_delta":12097,"sequence":3,"symbol":"EUCO SI 20260508 PS EU P 1.2500 0"}
{"ts_recv":"2026-04-06T18:53:11.558351950Z","hd":{"ts_event":"2026-04-06T18:53:11.558339853Z","rtype":160,"publisher_id":101,"instrument_id":33231},"action":"R","side":"N","price":null,"size":0,"channel_id":79,"order_id":"0","flags":128,"ts_in_delta":12097,"sequence":3,"symbol":"EUCO SI 20260508 PS EU C 1.2550 0"}
{"ts_recv":"2026-04-06T18:53:11.558351950Z","hd":{"ts_event":"2026-04-06T18:53:11.558339853Z","rtype":160,"publisher_id":101,"instrument_id":33232},"action":"R","side":"N","price":null,"size":0,"channel_id":79,"order_id":"0","flags":128,"ts_in_delta":12097,"sequence":3,"symbol":"EUCO SI 20260508 PS EU P 1.2550 0"}
{"ts_recv":"2026-04-06T18:53:11.558351950Z","hd":{"ts_event":"2026-04-06T18:53:11.558339853Z","rtype":160,"publisher_id":101,"instrument_id":33233},"action":"R","side":"N","price":null,"size":0,"channel_id":79,"order_id":"0","flags":128,"ts_in_delta":12097,"sequence":3,"symbol":"EUCO SI 20260612 PS EU C 1.1100 0"}
{"ts_recv":"2026-04-06T18:53:11.558351950Z","hd":{"ts_event":"2026-04-06T18:53:11.558339853Z","rtype":160,"publisher_id":101,"instrument_id":33234},"action":"R","side":"N","price":null,"size":0,"channel_id":79,"order_id":"0","flags":128,"ts_in_delta":12097,"sequence":3,"symbol":"EUCO SI 20260612 PS EU P 1.1100 0"}
{"ts_recv":"2026-04-06T18:53:11.558351950Z","hd":{"ts_event":"2026-04-06T18:53:11.558339853Z","rtype":160,"publisher_id":101,"instrument_id":33235},"action":"R","side":"N","price":null,"size":0,"channel_id":79,"order_id":"0","flags":128,"ts_in_delta":12097,"sequence":3,"symbol":"EUCO SI 20260612 PS EU C 1.1150 0"}
{"ts_recv":"2026-04-06T18:53:11.558351950Z","hd":{"ts_event":"2026-04-06T18:53:11.558339853Z","rtype":160,"publisher_id":101,"instrument_id":33236},"action":"R","side":"N","price":null,"size":0,"channel_id":79,"order_id":"0","flags":128,"ts_in_delta":12097,"sequence":3,"symbol":"EUCO SI 20260612 PS EU P 1.1150 0"}
{"ts_recv":"2026-04-06T18:53:11.558351950Z","hd":{"ts_event":"2026-04-06T18:53:11.558339853Z","rtype":160,"publisher_id":101,"instrument_id":33237},"action":"R","side":"N","price":null,"size":0,"channel_id":79,"order_id":"0","flags":128,"ts_in_delta":12097,"sequence":3,"symbol":"EUCO SI 20260612 PS EU C 1.1200 0"}
{"ts_recv":"2026-04-06T18:53:11.558351950Z","hd":{"ts_event":"2026-04-06T18:53:11.558339853Z","rtype":160,"publisher_id":101,"instrument_id":33238},"action":"R","side":"N","price":null,"size":0,"channel_id":79,"order_id":"0","flags":128,"ts_in_delta":12097,"sequence":3,"symbol":"EUCO SI 20260612 PS EU P 1.1200 0"}
{"ts_recv":"2026-04-06T18:53:11.558351950Z","hd":{"ts_event":"2026-04-06T18:53:11.558339853Z","rtype":160,"publisher_id":101,"instrument_id":33239},"action":"R","side":"N","price":null,"size":0,"channel_id":79,"order_id":"0","flags":128,"ts_in_delta":12097,"sequence":3,"symbol":"EUCO SI 20260612 PS EU C 1.1250 0"}
{"ts_recv":"2026-04-06T18:53:11.558351950Z","hd":{"ts_event":"2026-04-06T18:53:11.558339853Z","rtype":160,"publisher_id":101,"instrument_id":33240},"action":"R","side":"N","price":null,"size":0,"channel_id":79,"order_id":"0","flags":128,"ts_in_delta":12097,"sequence":3,"symbol":"EUCO SI 20260612 PS EU P 1.1250 0"}
{"ts_recv":"2026-04-06T18:53:11.558351950Z","hd":{"ts_event":"2026-04-06T18:53:11.558339853Z","rtype":160,"publisher_id":101,"instrument_id":33241},"action":"R","side":"N","price":null,"size":0,"channel_id":79,"order_id":"0","flags":128,"ts_in_delta":12097,"sequence":3,"symbol":"EUCO SI 20260612 PS EU C 1.1275 0"}
{"ts_recv":"2026-04-06T18:53:11.558351950Z","hd":{"ts_event":"2026-04-06T18:53:11.558339853Z","rtype":160,"publisher_id":101,"instrument_id":33242},"action":"R","side":"N","price":null,"size":0,"channel_id":79,"order_id":"0","flags":128,"ts_in_delta":12097,"sequence":3,"symbol":"EUCO SI 20260612 PS EU P 1.1275 0"}
{"ts_recv":"2026-04-06T18:53:11.558351950Z","hd":{"ts_event":"2026-04-06T18:53:11.558339853Z","rtype":160,"publisher_id":101,"instrument_id":33243},"action":"R","side":"N","price":null,"size":0,"channel_id":79,"order_id":"0","flags":128,"ts_in_delta":12097,"sequence":3,"symbol":"EUCO SI 20260612 PS EU C 1.1300 0"}
{"ts_recv":"2026-04-06T18:53:11.558351950Z","hd":{"ts_event":"2026-04-06T18:53:11.558339853Z","rtype":160,"publisher_id":101,"instrument_id":33244},"action":"R","side":"N","price":null,"size":0,"channel_id":79,"order_id":"0","flags":128,"ts_in_delta":12097,"sequence":3,"symbol":"EUCO SI 20260612 PS EU P 1.1300 0"}
{"ts_recv":"2026-04-06T18:53:11.558351950Z","hd":{"ts_event":"2026-04-06T18:53:11.558339853Z","rtype":160,"publisher_id":101,"instrument_id":33245},"action":"R","side":"N","price":null,"size":0,"channel_id":79,"order_id":"0","flags":128,"ts_in_delta":12097,"sequence":3,"symbol":"EUCO SI 20260612 PS EU C 1.1325 0"}
{"ts_recv":"2026-04-06T18:53:11.558351950Z","hd":{"ts_event":"2026-04-06T18:53:11.558339853Z","rtype":160,"publisher_id":101,"instrument_id":33246},"action":"R","side":"N","price":null,"size":0,"channel_id":79,"order_id":"0","flags":128,"ts_in_delta":12097,"sequence":3,"symbol":"EUCO SI 20260612 PS EU P 1.1325 0"}
{"ts_recv":"2026-04-06T18:53:11.558351950Z","hd":{"ts_event":"2026-04-06T18:53:11.558339853Z","rtype":160,"publisher_id":101,"instrument_id":33247},"action":"R","side":"N","price":null,"size":0,"channel_id":79,"order_id":"0","flags":128,"ts_in_delta":12097,"sequence":3,"symbol":"EUCO SI 20260612 PS EU C 1.1350 0"}
{"ts_recv":"2026-04-06T18:53:11.558351950Z","hd":{"ts_event":"2026-04-06T18:53:11.558339853Z","rtype":160,"publisher_id":101,"instrument_id":33248},"action":"R","side":"N","price":null,"size":0,"channel_id":79,"order_id":"0","flags":128,"ts_in_delta":12097,"sequence":3,"symbol":"EUCO SI 20260612 PS EU P 1.1350 0"}
{"ts_recv":"2026-04-06T18:53:11.558351950Z","hd":{"ts_event":"2026-04-06T18:53:11.558339853Z","rtype":160,"publisher_id":101,"instrument_id":33249},"action":"R","side":"N","price":null,"size":0,"channel_id":79,"order_id":"0","flags":128,"ts_in_delta":12097,"sequence":3,"symbol":"EUCO SI 20260612 PS EU C 1.1375 0"}
{"ts_recv":"2026-04-06T18:53:11.558351950Z","hd":{"ts_event":"2026-04-06T18:53:11.558339853Z","rtype":160,"publisher_id":101,"instrument_id":33250},"action":"R","side":"N","price":null,"size":0,"channel_id":79,"order_id":"0","flags":128,"ts_in_delta":12097,"sequence":3,"symbol":"EUCO SI 20260612 PS EU P 1.1375 0"}
{"ts_recv":"2026-04-06T18:53:11.558351950Z","hd":{"ts_event":"2026-04-06T18:53:11.558339853Z","rtype":160,"publisher_id":101,"instrument_id":33251},"action":"R","side":"N","price":null,"size":0,"channel_id":79,"order_id":"0","flags":128,"ts_in_delta":12097,"sequence":3,"symbol":"EUCO SI 20260612 PS EU C 1.1400 0"}
{"ts_recv":"2026-04-06T18:53:11.558351950Z","hd":{"ts_event":"2026-04-06T18:53:11.558339853Z","rtype":160,"publisher_id":101,"instrument_id":33252},"action":"R","side":"N","price":null,"size":0,"channel_id":79,"order_id":"0","flags":128,"ts_in_delta":12097,"sequence":3,"symbol":"EUCO SI 20260612 PS EU P 1.1400 0"}
{"ts_recv":"2026-04-06T18:53:11.558351950Z","hd":{"ts_event":"2026-04-06T18:53:11.558339853Z","rtype":160,"publisher_id":101,"instrument_id":33253},"action":"R","side":"N","price":null,"size":0,"channel_id":79,"order_id":"0","flags":128,"ts_in_delta":12097,"sequence":3,"symbol":"EUCO SI 20260612 PS EU C 1.1425 0"}
{"ts_recv":"2026-04-06T18:53:11.558351950Z","hd":{"ts_event":"2026-04-06T18:53:11.558339853Z","rtype":160,"publisher_id":101,"instrument_id":33254},"action":"R","side":"N","price":null,"size":0,"channel_id":79,"order_id":"0","flags":128,"ts_in_delta":12097,"sequence":3,"symbol":"EUCO SI 20260612 PS EU P 1.1425 0"}
{"ts_recv":"2026-04-06T18:53:11.558351950Z","hd":{"ts_event":"2026-04-06T18:53:11.558339853Z","rtype":160,"publisher_id":101,"instrument_id":33255},"action":"R","side":"N","price":null,"size":0,"channel_id":79,"order_id":"0","flags":128,"ts_in_delta":12097,"sequence":3,"symbol":"EUCO SI 20260612 PS EU C 1.1450 0"}
{"ts_recv":"2026-04-06T18:53:11.558351950Z","hd":{"ts_event":"2026-04-06T18:53:11.558339853Z","rtype":160,"publisher_id":101,"instrument_id":33256},"action":"R","side":"N","price":null,"size":0,"channel_id":79,"order_id":"0","flags":128,"ts_in_delta":12097,"sequence":3,"symbol":"EUCO SI 20260612 PS EU P 1.1450 0"}
{"ts_recv":"2026-04-06T18:53:11.558351950Z","hd":{"ts_event":"2026-04-06T18:53:11.558339853Z","rtype":160,"publisher_id":101,"instrument_id":33257},"action":"R","side":"N","price":null,"size":0,"channel_id":79,"order_id":"0","flags":128,"ts_in_delta":12097,"sequence":3,"symbol":"EUCO SI 20260612 PS EU C 1.1475 0"}
{"ts_recv":"2026-04-06T18:53:11.558351950Z","hd":{"ts_event":"2026-04-06T18:53:11.558339853Z","rtype":160,"publisher_id":101,"instrument_id":33258},"action":"R","side":"N","price":null,"size":0,"channel_id":79,"order_id":"0","flags":128,"ts_in_delta":12097,"sequence":3,"symbol":"EUCO SI 20260612 PS EU P 1.1475 0"}
{"ts_recv":"2026-04-06T18:53:11.558351950Z","hd":{"ts_event":"2026-04-06T18:53:11.558339853Z","rtype":160,"publisher_id":101,"instrument_id":33259},"action":"R","side":"N","price":null,"size":0,"channel_id":79,"order_id":"0","flags":128,"ts_in_delta":12097,"sequence":3,"symbol":"EUCO SI 20260612 PS EU C 1.1500 0"}
{"ts_recv":"2026-04-06T18:53:11.558351950Z","hd":{"ts_event":"2026-04-06T18:53:11.558339853Z","rtype":160,"publisher_id":101,"instrument_id":33260},"action":"R","side":"N","price":null,"size":0,"channel_id":79,"order_id":"0","flags":128,"ts_in_delta":12097,"sequence":3,"symbol":"EUCO SI 20260612 PS EU P 1.1500 0"}
{"ts_recv":"2026-04-06T18:53:11.558351950Z","hd":{"ts_event":"2026-04-06T18:53:11.558339853Z","rtype":160,"publisher_id":101,"instrument_id":33261},"action":"R","side":"N","price":null,"size":0,"channel_id":79,"order_id":"0","flags":128,"ts_in_delta":12097,"sequence":3,"symbol":"EUCO SI 20260612 PS EU C 1.1525 0"}
{"ts_recv":"2026-04-06T18:53:11.558351950Z","hd":{"ts_event":"2026-04-06T18:53:11.558339853Z","rtype":160,"publisher_id":101,"instrument_id":33262},"action":"R","side":"N","price":null,"size":0,"channel_id":79,"order_id":"0","flags":128,"ts_in_delta":12097,"sequence":3,"symbol":"EUCO SI 20260612 PS EU P 1.1525 0"}
{"ts_recv":"2026-04-06T18:53:11.558351950Z","hd":{"ts_event":"2026-04-06T18:53:11.558339853Z","rtype":160,"publisher_id":101,"instrument_id":33263},"action":"R","side":"N","price":null,"size":0,"channel_id":79,"order_id":"0","flags":128,"ts_in_delta":12097,"sequence":3,"symbol":"EUCO SI 20260612 PS EU C 1.1550 0"}
{"ts_recv":"2026-04-06T18:53:11.558351950Z","hd":{"ts_event":"2026-04-06T18:53:11.558339853Z","rtype":160,"publisher_id":101,"instrument_id":33264},"action":"R","side":"N","price":null,"size":0,"channel_id":79,"order_id":"0","flags":128,"ts_in_delta":12097,"sequence":3,"symbol":"EUCO SI 20260612 PS EU P 1.1550 0"}
{"ts_recv":"2026-04-06T18:53:11.558351950Z","hd":{"ts_event":"2026-04-06T18:53:11.558339853Z","rtype":160,"publisher_id":101,"instrument_id":33265},"action":"R","side":"N","price":null,"size":0,"channel_id":79,"order_id":"0","flags":128,"ts_in_delta":12097,"sequence":3,"symbol":"EUCO SI 20260612 PS EU C 1.1575 0"}
{"ts_recv":"2026-04-06T18:53:11.558351950Z","hd":{"ts_event":"2026-04-06T18:53:11.558339853Z","rtype":160,"publisher_id":101,"instrument_id":33266},"action":"R","side":"N","price":null,"size":0,"channel_id":79,"order_id":"0","flags":128,"ts_in_delta":12097,"sequence":3,"symbol":"EUCO SI 20260612 PS EU P 1.1575 0"}
{"ts_recv":"2026-04-06T18:53:11.558351950Z","hd":{"ts_event":"2026-04-06T18:53:11.558339853Z","rtype":160,"publisher_id":101,"instrument_id":33267},"action":"R","side":"N","price":null,"size":0,"channel_id":79,"order_id":"0","flags":128,"ts_in_delta":12097,"sequence":3,"symbol":"EUCO SI 20260612 PS EU C 1.1600 0"}
{"ts_recv":"2026-04-06T18:53:11.558351950Z","hd":{"ts_event":"2026-04-06T18:53:11.558339853Z","rtype":160,"publisher_id":101,"instrument_id":33268},"action":"R","side":"N","price":null,"size":0,"channel_id":79,"order_id":"0","flags":128,"ts_in_delta":12097,"sequence":3,"symbol":"EUCO SI 20260612 PS EU P 1.1600 0"}
{"ts_recv":"2026-04-06T18:53:11.558351950Z","hd":{"ts_event":"2026-04-06T18:53:11.558339853Z","rtype":160,"publisher_id":101,"instrument_id":33269},"action":"R","side":"N","price":null,"size":0,"channel_id":79,"order_id":"0","flags":128,"ts_in_delta":12097,"sequence":3,"symbol":"EUCO SI 20260612 PS EU C 1.1625 0"}
{"ts_recv":"2026-04-06T18:53:11.558351950Z","hd":{"ts_event":"2026-04-06T18:53:11.558339853Z","rtype":160,"publisher_id":101,"instrument_id":33270},"action":"R","side":"N","price":null,"size":0,"channel_id":79,"order_id":"0","flags":128,"ts_in_delta":12097,"sequence":3,"symbol":"EUCO SI 20260612 PS EU P 1.1625 0"}
{"ts_recv":"2026-04-06T18:53:11.558351950Z","hd":{"ts_event":"2026-04-06T18:53:11.558339853Z","rtype":160,"publisher_id":101,"instrument_id":33271},"action":"R","side":"N","price":null,"size":0,"channel_id":79,"order_id":"0","flags":128,"ts_in_delta":12097,"sequence":3,"symbol":"EUCO SI 20260612 PS EU C 1.1650 0"}
{"ts_recv":"2026-04-06T18:53:11.558351950Z","hd":{"ts_event":"2026-04-06T18:53:11.558339853Z","rtype":160,"publisher_id":101,"instrument_id":33272},"action":"R","side":"N","price":null,"size":0,"channel_id":79,"order_id":"0","flags":128,"ts_in_delta":12097,"sequence":3,"symbol":"EUCO SI 20260612 PS EU P 1.1650 0"}
{"ts_recv":"2026-04-06T18:53:11.558351950Z","hd":{"ts_event":"2026-04-06T18:53:11.558339853Z","rtype":160,"publisher_id":101,"instrument_id":33273},"action":"R","side":"N","price":null,"size":0,"channel_id":79,"order_id":"0","flags":128,"ts_in_delta":12097,"sequence":3,"symbol":"EUCO SI 20260612 PS EU C 1.1675 0"}
{"ts_recv":"2026-04-06T18:53:11.558351950Z","hd":{"ts_event":"2026-04-06T18:53:11.558339853Z","rtype":160,"publisher_id":101,"instrument_id":33274},"action":"R","side":"N","price":null,"size":0,"channel_id":79,"order_id":"0","flags":128,"ts_in_delta":12097,"sequence":3,"symbol":"EUCO SI 20260612 PS EU P 1.1675 0"}
{"ts_recv":"2026-04-06T18:53:11.558351950Z","hd":{"ts_event":"2026-04-06T18:53:11.558339853Z","rtype":160,"publisher_id":101,"instrument_id":33275},"action":"R","side":"N","price":null,"size":0,"channel_id":79,"order_id":"0","flags":128,"ts_in_delta":12097,"sequence":3,"symbol":"EUCO SI 20260612 PS EU C 1.1700 0"}
{"ts_recv":"2026-04-06T18:53:11.558351950Z","hd":{"ts_event":"2026-04-06T18:53:11.558339853Z","rtype":160,"publisher_id":101,"instrument_id":33276},"action":"R","side":"N","price":null,"size":0,"channel_id":79,"order_id":"0","flags":128,"ts_in_delta":12097,"sequence":3,"symbol":"EUCO SI 20260612 PS EU P 1.1700 0"}
{"ts_recv":"2026-04-06T18:53:11.558351950Z","hd":{"ts_event":"2026-04-06T18:53:11.558339853Z","rtype":160,"publisher_id":101,"instrument_id":33277},"action":"R","side":"N","price":null,"size":0,"channel_id":79,"order_id":"0","flags":128,"ts_in_delta":12097,"sequence":3,"symbol":"EUCO SI 20260612 PS EU C 1.1725 0"}
{"ts_recv":"2026-04-06T18:53:11.558351950Z","hd":{"ts_event":"2026-04-06T18:53:11.558339853Z","rtype":160,"publisher_id":101,"instrument_id":33278},"action":"R","side":"N","price":null,"size":0,"channel_id":79,"order_id":"0","flags":128,"ts_in_delta":12097,"sequence":3,"symbol":"EUCO SI 20260612 PS EU P 1.1725 0"}
{"ts_recv":"2026-04-06T18:53:11.558351950Z","hd":{"ts_event":"2026-04-06T18:53:11.558339853Z","rtype":160,"publisher_id":101,"instrument_id":33279},"action":"R","side":"N","price":null,"size":0,"channel_id":79,"order_id":"0","flags":128,"ts_in_delta":12097,"sequence":3,"symbol":"EUCO SI 20260612 PS EU C 1.1750 0"}
{"ts_recv":"2026-04-06T18:53:11.558351950Z","hd":{"ts_event":"2026-04-06T18:53:11.558339853Z","rtype":160,"publisher_id":101,"instrument_id":33280},"action":"R","side":"N","price":null,"size":0,"channel_id":79,"order_id":"0","flags":128,"ts_in_delta":12097,"sequence":3,"symbol":"EUCO SI 20260612 PS EU P 1.1750 0"}
{"ts_recv":"2026-04-06T18:53:11.558351950Z","hd":{"ts_event":"2026-04-06T18:53:11.558339853Z","rtype":160,"publisher_id":101,"instrument_id":33281},"action":"R","side":"N","price":null,"size":0,"channel_id":79,"order_id":"0","flags":128,"ts_in_delta":12097,"sequence":3,"symbol":"EUCO SI 20260612 PS EU C 1.1775 0"}
{"ts_recv":"2026-04-06T18:53:11.558351950Z","hd":{"ts_event":"2026-04-06T18:53:11.558339853Z","rtype":160,"publisher_id":101,"instrument_id":33282},"action":"R","side":"N","price":null,"size":0,"channel_id":79,"order_id":"0","flags":128,"ts_in_delta":12097,"sequence":3,"symbol":"EUCO SI 20260612 PS EU P 1.1775 0"}
{"ts_recv":"2026-04-06T18:53:11.558351950Z","hd":{"ts_event":"2026-04-06T18:53:11.558339853Z","rtype":160,"publisher_id":101,"instrument_id":33283},"action":"R","side":"N","price":null,"size":0,"channel_id":79,"order_id":"0","flags":128,"ts_in_delta":12097,"sequence":3,"symbol":"EUCO SI 20260612 PS EU C 1.1800 0"}
{"ts_recv":"2026-04-06T18:53:11.558351950Z","hd":{"ts_event":"2026-04-06T18:53:11.558339853Z","rtype":160,"publisher_id":101,"instrument_id":33284},"action":"R","side":"N","price":null,"size":0,"channel_id":79,"order_id":"0","flags":128,"ts_in_delta":12097,"sequence":3,"symbol":"EUCO SI 20260612 PS EU P 1.1800 0"}
{"ts_recv":"2026-04-06T18:53:11.558351950Z","hd":{"ts_event":"2026-04-06T18:53:11.558339853Z","rtype":160,"publisher_id":101,"instrument_id":33285},"action":"R","side":"N","price":null,"size":0,"channel_id":79,"order_id":"0","flags":128,"ts_in_delta":12097,"sequence":3,"symbol":"EUCO SI 20260612 PS EU C 1.1825 0"}
{"ts_recv":"2026-04-06T18:53:11.558351950Z","hd":{"ts_event":"2026-04-06T18:53:11.558339853Z","rtype":160,"publisher_id":101,"instrument_id":33286},"action":"R","side":"N","price":null,"size":0,"channel_id":79,"order_id":"0","flags":128,"ts_in_delta":12097,"sequence":3,"symbol":"EUCO SI 20260612 PS EU P 1.1825 0"}
{"ts_recv":"2026-04-06T18:53:11.558351950Z","hd":{"ts_event":"2026-04-06T18:53:11.558339853Z","rtype":160,"publisher_id":101,"instrument_id":33287},"action":"R","side":"N","price":null,"size":0,"channel_id":79,"order_id":"0","flags":128,"ts_in_delta":12097,"sequence":3,"symbol":"EUCO SI 20260612 PS EU C 1.1850 0"}
{"ts_recv":"2026-04-06T18:53:11.558351950Z","hd":{"ts_event":"2026-04-06T18:53:11.558339853Z","rtype":160,"publisher_id":101,"instrument_id":33288},"action":"R","side":"N","price":null,"size":0,"channel_id":79,"order_id":"0","flags":128,"ts_in_delta":12097,"sequence":3,"symbol":"EUCO SI 20260612 PS EU P 1.1850 0"}
{"ts_recv":"2026-04-06T18:53:11.558351950Z","hd":{"ts_event":"2026-04-06T18:53:11.558339853Z","rtype":160,"publisher_id":101,"instrument_id":33289},"action":"R","side":"N","price":null,"size":0,"channel_id":79,"order_id":"0","flags":128,"ts_in_delta":12097,"sequence":3,"symbol":"EUCO SI 20260612 PS EU C 1.1875 0"}
{"ts_recv":"2026-04-06T18:53:11.558351950Z","hd":{"ts_event":"2026-04-06T18:53:11.558339853Z","rtype":160,"publisher_id":101,"instrument_id":33290},"action":"R","side":"N","price":null,"size":0,"channel_id":79,"order_id":"0","flags":128,"ts_in_delta":12097,"sequence":3,"symbol":"EUCO SI 20260612 PS EU P 1.1875 0"}
{"ts_recv":"2026-04-06T18:53:11.558351950Z","hd":{"ts_event":"2026-04-06T18:53:11.558339853Z","rtype":160,"publisher_id":101,"instrument_id":33291},"action":"R","side":"N","price":null,"size":0,"channel_id":79,"order_id":"0","flags":128,"ts_in_delta":12097,"sequence":3,"symbol":"EUCO SI 20260612 PS EU C 1.1900 0"}
{"ts_recv":"2026-04-06T18:53:11.558351950Z","hd":{"ts_event":"2026-04-06T18:53:11.558339853Z","rtype":160,"publisher_id":101,"instrument_id":33292},"action":"R","side":"N","price":null,"size":0,"channel_id":79,"order_id":"0","flags":128,"ts_in_delta":12097,"sequence":3,"symbol":"EUCO SI 20260612 PS EU P 1.1900 0"}
{"ts_recv":"2026-04-06T18:53:11.558351950Z","hd":{"ts_event":"2026-04-06T18:53:11.558339853Z","rtype":160,"publisher_id":101,"instrument_id":33293},"action":"R","side":"N","price":null,"size":0,"channel_id":79,"order_id":"0","flags":128,"ts_in_delta":12097,"sequence":3,"symbol":"EUCO SI 20260612 PS EU C 1.1925 0"}
{"ts_recv":"2026-04-06T18:53:11.558351950Z","hd":{"ts_event":"2026-04-06T18:53:11.558339853Z","rtype":160,"publisher_id":101,"instrument_id":33294},"action":"R","side":"N","price":null,"size":0,"channel_id":79,"order_id":"0","flags":128,"ts_in_delta":12097,"sequence":3,"symbol":"EUCO SI 20260612 PS EU P 1.1925 0"}
{"ts_recv":"2026-04-06T18:53:11.558351950Z","hd":{"ts_event":"2026-04-06T18:53:11.558339853Z","rtype":160,"publisher_id":101,"instrument_id":33295},"action":"R","side":"N","price":null,"size":0,"channel_id":79,"order_id":"0","flags":128,"ts_in_delta":12097,"sequence":3,"symbol":"EUCO SI 20260612 PS EU C 1.1950 0"}
{"ts_recv":"2026-04-06T18:53:11.558351950Z","hd":{"ts_event":"2026-04-06T18:53:11.558339853Z","rtype":160,"publisher_id":101,"instrument_id":33296},"action":"R","side":"N","price":null,"size":0,"channel_id":79,"order_id":"0","flags":128,"ts_in_delta":12097,"sequence":3,"symbol":"EUCO SI 20260612 PS EU P 1.1950 0"}
{"ts_recv":"2026-04-06T18:53:11.558351950Z","hd":{"ts_event":"2026-04-06T18:53:11.558339853Z","rtype":160,"publisher_id":101,"instrument_id":33297},"action":"R","side":"N","price":null,"size":0,"channel_id":79,"order_id":"0","flags":128,"ts_in_delta":12097,"sequence":3,"symbol":"EUCO SI 20260612 PS EU C 1.1975 0"}
{"ts_recv":"2026-04-06T18:53:11.558351950Z","hd":{"ts_event":"2026-04-06T18:53:11.558339853Z","rtype":160,"publisher_id":101,"instrument_id":33298},"action":"R","side":"N","price":null,"size":0,"channel_id":79,"order_id":"0","flags":128,"ts_in_delta":12097,"sequence":3,"symbol":"EUCO SI 20260612 PS EU P 1.1975 0"}
{"ts_recv":"2026-04-06T18:53:11.558351950Z","hd":{"ts_event":"2026-04-06T18:53:11.558339853Z","rtype":160,"publisher_id":101,"instrument_id":33299},"action":"R","side":"N","price":null,"size":0,"channel_id":79,"order_id":"0","flags":128,"ts_in_delta":12097,"sequence":3,"symbol":"EUCO SI 20260612 PS EU C 1.2000 0"}
{"ts_recv":"2026-04-06T18:53:11.558351950Z","hd":{"ts_event":"2026-04-06T18:53:11.558339853Z","rtype":160,"publisher_id":101,"instrument_id":33300},"action":"R","side":"N","price":null,"size":0,"channel_id":79,"order_id":"0","flags":128,"ts_in_delta":12097,"sequence":3,"symbol":"EUCO SI 20260612 PS EU P 1.2000 0"}
{"ts_recv":"2026-04-06T18:53:11.558351950Z","hd":{"ts_event":"2026-04-06T18:53:11.558339853Z","rtype":160,"publisher_id":101,"instrument_id":33301},"action":"R","side":"N","price":null,"size":0,"channel_id":79,"order_id":"0","flags":128,"ts_in_delta":12097,"sequence":3,"symbol":"EUCO SI 20260612 PS EU C 1.2025 0"}
{"ts_recv":"2026-04-06T18:53:11.558351950Z","hd":{"ts_event":"2026-04-06T18:53:11.558339853Z","rtype":160,"publisher_id":101,"instrument_id":33302},"action":"R","side":"N","price":null,"size":0,"channel_id":79,"order_id":"0","flags":128,"ts_in_delta":12097,"sequence":3,"symbol":"EUCO SI 20260612 PS EU P 1.2025 0"}
{"ts_recv":"2026-04-06T18:53:11.558351950Z","hd":{"ts_event":"2026-04-06T18:53:11.558339853Z","rtype":160,"publisher_id":101,"instrument_id":33303},"action":"R","side":"N","price":null,"size":0,"channel_id":79,"order_id":"0","flags":128,"ts_in_delta":12097,"sequence":3,"symbol":"EUCO SI 20260612 PS EU C 1.2050 0"}
{"ts_recv":"2026-04-06T18:53:11.558351950Z","hd":{"ts_event":"2026-04-06T18:53:11.558339853Z","rtype":160,"publisher_id":101,"instrument_id":33304},"action":"R","side":"N","price":null,"size":0,"channel_id":79,"order_id":"0","flags":128,"ts_in_delta":12097,"sequence":3,"symbol":"EUCO SI 20260612 PS EU P 1.2050 0"}
{"ts_recv":"2026-04-06T18:53:11.558351950Z","hd":{"ts_event":"2026-04-06T18:53:11.558339853Z","rtype":160,"publisher_id":101,"instrument_id":33305},"action":"R","side":"N","price":null,"size":0,"channel_id":79,"order_id":"0","flags":128,"ts_in_delta":12097,"sequence":3,"symbol":"EUCO SI 20260612 PS EU C 1.2075 0"}
{"ts_recv":"2026-04-06T18:53:11.558351950Z","hd":{"ts_event":"2026-04-06T18:53:11.558339853Z","rtype":160,"publisher_id":101,"instrument_id":33306},"action":"R","side":"N","price":null,"size":0,"channel_id":79,"order_id":"0","flags":128,"ts_in_delta":12097,"sequence":3,"symbol":"EUCO SI 20260612 PS EU P 1.2075 0"}
{"ts_recv":"2026-04-06T18:53:11.558351950Z","hd":{"ts_event":"2026-04-06T18:53:11.558339853Z","rtype":160,"publisher_id":101,"instrument_id":33307},"action":"R","side":"N","price":null,"size":0,"channel_id":79,"order_id":"0","flags":128,"ts_in_delta":12097,"sequence":3,"symbol":"EUCO SI 20260612 PS EU C 1.2100 0"}
{"ts_recv":"2026-04-06T18:53:11.558351950Z","hd":{"ts_event":"2026-04-06T18:53:11.558339853Z","rtype":160,"publisher_id":101,"instrument_id":33308},"action":"R","side":"N","price":null,"size":0,"channel_id":79,"order_id":"0","flags":128,"ts_in_delta":12097,"sequence":3,"symbol":"EUCO SI 20260612 PS EU P 1.2100 0"}
{"ts_recv":"2026-04-06T18:53:11.558351950Z","hd":{"ts_event":"2026-04-06T18:53:11.558339853Z","rtype":160,"publisher_id":101,"instrument_id":33309},"action":"R","side":"N","price":null,"size":0,"channel_id":79,"order_id":"0","flags":128,"ts_in_delta":12097,"sequence":3,"symbol":"EUCO SI 20260612 PS EU C 1.2125 0"}
{"ts_recv":"2026-04-06T18:53:11.558351950Z","hd":{"ts_event":"2026-04-06T18:53:11.558339853Z","rtype":160,"publisher_id":101,"instrument_id":33310},"action":"R","side":"N","price":null,"size":0,"channel_id":79,"order_id":"0","flags":128,"ts_in_delta":12097,"sequence":3,"symbol":"EUCO SI 20260612 PS EU P 1.2125 0"}
{"ts_recv":"2026-04-06T18:53:11.558351950Z","hd":{"ts_event":"2026-04-06T18:53:11.558339853Z","rtype":160,"publisher_id":101,"instrument_id":33311},"action":"R","side":"N","price":null,"size":0,"channel_id":79,"order_id":"0","flags":128,"ts_in_delta":12097,"sequence":3,"symbol":"EUCO SI 20260612 PS EU C 1.2150 0"}
{"ts_recv":"2026-04-06T18:53:11.558351950Z","hd":{"ts_event":"2026-04-06T18:53:11.558339853Z","rtype":160,"publisher_id":101,"instrument_id":33312},"action":"R","side":"N","price":null,"size":0,"channel_id":79,"order_id":"0","flags":128,"ts_in_delta":12097,"sequence":3,"symbol":"EUCO SI 20260612 PS EU P 1.2150 0"}
{"ts_recv":"2026-04-06T18:53:11.558351950Z","hd":{"ts_event":"2026-04-06T18:53:11.558339853Z","rtype":160,"publisher_id":101,"instrument_id":33313},"action":"R","side":"N","price":null,"size":0,"channel_id":79,"order_id":"0","flags":128,"ts_in_delta":12097,"sequence":3,"symbol":"EUCO SI 20260612 PS EU C 1.2175 0"}
{"ts_recv":"2026-04-06T18:53:11.558351950Z","hd":{"ts_event":"2026-04-06T18:53:11.558339853Z","rtype":160,"publisher_id":101,"instrument_id":33314},"action":"R","side":"N","price":null,"size":0,"channel_id":79,"order_id":"0","flags":128,"ts_in_delta":12097,"sequence":3,"symbol":"EUCO SI 20260612 PS EU P 1.2175 0"}
{"ts_recv":"2026-04-06T18:53:11.558351950Z","hd":{"ts_event":"2026-04-06T18:53:11.558339853Z","rtype":160,"publisher_id":101,"instrument_id":33315},"action":"R","side":"N","price":null,"size":0,"channel_id":79,"order_id":"0","flags":128,"ts_in_delta":12097,"sequence":3,"symbol":"EUCO SI 20260612 PS EU C 1.2200 0"}
{"ts_recv":"2026-04-06T18:53:11.558351950Z","hd":{"ts_event":"2026-04-06T18:53:11.558339853Z","rtype":160,"publisher_id":101,"instrument_id":33316},"action":"R","side":"N","price":null,"size":0,"channel_id":79,"order_id":"0","flags":128,"ts_in_delta":12097,"sequence":3,"symbol":"EUCO SI 20260612 PS EU P 1.2200 0"}
{"ts_recv":"2026-04-06T18:53:11.558351950Z","hd":{"ts_event":"2026-04-06T18:53:11.558339853Z","rtype":160,"publisher_id":101,"instrument_id":33317},"action":"R","side":"N","price":null,"size":0,"channel_id":79,"order_id":"0","flags":128,"ts_in_delta":12097,"sequence":3,"symbol":"EUCO SI 20260612 PS EU C 1.2225 0"}
{"ts_recv":"2026-04-06T18:53:11.558351950Z","hd":{"ts_event":"2026-04-06T18:53:11.558339853Z","rtype":160,"publisher_id":101,"instrument_id":33318},"action":"R","side":"N","price":null,"size":0,"channel_id":79,"order_id":"0","flags":128,"ts_in_delta":12097,"sequence":3,"symbol":"EUCO SI 20260612 PS EU P 1.2225 0"}
{"ts_recv":"2026-04-06T18:53:11.558351950Z","hd":{"ts_event":"2026-04-06T18:53:11.558339853Z","rtype":160,"publisher_id":101,"instrument_id":33319},"action":"R","side":"N","price":null,"size":0,"channel_id":79,"order_id":"0","flags":128,"ts_in_delta":12097,"sequence":3,"symbol":"EUCO SI 20260612 PS EU C 1.2250 0"}
{"ts_recv":"2026-04-06T18:53:11.558351950Z","hd":{"ts_event":"2026-04-06T18:53:11.558339853Z","rtype":160,"publisher_id":101,"instrument_id":33320},"action":"R","side":"N","price":null,"size":0,"channel_id":79,"order_id":"0","flags":128,"ts_in_delta":12097,"sequence":3,"symbol":"EUCO SI 20260612 PS EU P 1.2250 0"}
{"ts_recv":"2026-04-06T18:53:11.558351950Z","hd":{"ts_event":"2026-04-06T18:53:11.558339853Z","rtype":160,"publisher_id":101,"instrument_id":33321},"action":"R","side":"N","price":null,"size":0,"channel_id":79,"order_id":"0","flags":128,"ts_in_delta":12097,"sequence":3,"symbol":"EUCO SI 20260612 PS EU C 1.2275 0"}
{"ts_recv":"2026-04-06T18:53:11.558351950Z","hd":{"ts_event":"2026-04-06T18:53:11.558339853Z","rtype":160,"publisher_id":101,"instrument_id":33322},"action":"R","side":"N","price":null,"size":0,"channel_id":79,"order_id":"0","flags":128,"ts_in_delta":12097,"sequence":3,"symbol":"EUCO SI 20260612 PS EU P 1.2275 0"}
{"ts_recv":"2026-04-06T18:53:11.558351950Z","hd":{"ts_event":"2026-04-06T18:53:11.558339853Z","rtype":160,"publisher_id":101,"instrument_id":33323},"action":"R","side":"N","price":null,"size":0,"channel_id":79,"order_id":"0","flags":128,"ts_in_delta":12097,"sequence":3,"symbol":"EUCO SI 20260612 PS EU C 1.2300 0"}
{"ts_recv":"2026-04-06T18:53:11.558351950Z","hd":{"ts_event":"2026-04-06T18:53:11.558339853Z","rtype":160,"publisher_id":101,"instrument_id":33324},"action":"R","side":"N","price":null,"size":0,"channel_id":79,"order_id":"0","flags":128,"ts_in_delta":12097,"sequence":3,"symbol":"EUCO SI 20260612 PS EU P 1.2300 0"}
{"ts_recv":"2026-04-06T18:53:11.558351950Z","hd":{"ts_event":"2026-04-06T18:53:11.558339853Z","rtype":160,"publisher_id":101,"instrument_id":33325},"action":"R","side":"N","price":null,"size":0,"channel_id":79,"order_id":"0","flags":128,"ts_in_delta":12097,"sequence":3,"symbol":"EUCO SI 20260612 PS EU C 1.2350 0"}
{"ts_recv":"2026-04-06T18:53:11.558351950Z","hd":{"ts_event":"2026-04-06T18:53:11.558339853Z","rtype":160,"publisher_id":101,"instrument_id":33326},"action":"R","side":"N","price":null,"size":0,"channel_id":79,"order_id":"0","flags":128,"ts_in_delta":12097,"sequence":3,"symbol":"EUCO SI 20260612 PS EU P 1.2350 0"}
{"ts_recv":"2026-04-06T18:53:11.558351950Z","hd":{"ts_event":"2026-04-06T18:53:11.558339853Z","rtype":160,"publisher_id":101,"instrument_id":33327},"action":"R","side":"N","price":null,"size":0,"channel_id":79,"order_id":"0","flags":128,"ts_in_delta":12097,"sequence":3,"symbol":"EUCO SI 20260612 PS EU C 1.2400 0"}
{"ts_recv":"2026-04-06T18:53:11.558351950Z","hd":{"ts_event":"2026-04-06T18:53:11.558339853Z","rtype":160,"publisher_id":101,"instrument_id":33328},"action":"R","side":"N","price":null,"size":0,"channel_id":79,"order_id":"0","flags":128,"ts_in_delta":12097,"sequence":3,"symbol":"EUCO SI 20260612 PS EU P 1.2400 0"}
{"ts_recv":"2026-04-06T18:53:11.558351950Z","hd":{"ts_event":"2026-04-06T18:53:11.558339853Z","rtype":160,"publisher_id":101,"instrument_id":33329},"action":"R","side":"N","price":null,"size":0,"channel_id":79,"order_id":"0","flags":128,"ts_in_delta":12097,"sequence":3,"symbol":"EUCO SI 20260612 PS EU C 1.2450 0"}
{"ts_recv":"2026-04-06T18:53:11.558351950Z","hd":{"ts_event":"2026-04-06T18:53:11.558339853Z","rtype":160,"publisher_id":101,"instrument_id":33330},"action":"R","side":"N","price":null,"size":0,"channel_id":79,"order_id":"0","flags":128,"ts_in_delta":12097,"sequence":3,"symbol":"EUCO SI 20260612 PS EU P 1.2450 0"}
{"ts_recv":"2026-04-06T18:53:11.558351950Z","hd":{"ts_event":"2026-04-06T18:53:11.558339853Z","rtype":160,"publisher_id":101,"instrument_id":33331},"action":"R","side":"N","price":null,"size":0,"channel_id":79,"order_id":"0","flags":128,"ts_in_delta":12097,"sequence":3,"symbol":"EUCO SI 20260612 PS EU C 1.2500 0"}
{"ts_recv":"2026-04-06T18:53:11.558351950Z","hd":{"ts_event":"2026-04-06T18:53:11.558339853Z","rtype":160,"publisher_id":101,"instrument_id":33332},"action":"R","side":"N","price":null,"size":0,"channel_id":79,"order_id":"0","flags":128,"ts_in_delta":12097,"sequence":3,"symbol":"EUCO SI 20260612 PS EU P 1.2500 0"}
