{"ts_recv":"2026-04-07T02:00:01.086486835Z","hd":{"ts_event":"2026-04-07T02:00:01.086458959Z","rtype":160,"publisher_id":101,"instrument_id":436},"action":"C","side":"A","price":"1.156770000","size":30,"channel_id":23,"order_id":"1775527200582312107","flags":0,"ts_in_delta":1199,"sequence":140987,"symbol":"FCEU SI 20260615 PS"}
{"ts_recv":"2026-04-07T02:00:01.086486835Z","hd":{"ts_event":"2026-04-07T02:00:01.086458959Z","rtype":160,"publisher_id":101,"instrument_id":436},"action":"A","side":"A","price":"1.156760000","size":30,"channel_id":23,"order_id":"1775527201086470456","flags":128,"ts_in_delta":1199,"sequence":140987,"symbol":"FCEU SI 20260615 PS"}
{"ts_recv":"2026-04-07T02:00:02.028331161Z","hd":{"ts_event":"2026-04-07T02:00:02.028305005Z","rtype":160,"publisher_id":101,"instrument_id":436},"action":"C","side":"B","price":"1.156660000","size":30,"channel_id":23,"order_id":"10998899237941246264","flags":0,"ts_in_delta":1174,"sequence":140993,"symbol":"FCEU SI 20260615 PS"}
{"ts_recv":"2026-04-07T02:00:02.028331161Z","hd":{"ts_event":"2026-04-07T02:00:02.028305005Z","rtype":160,"publisher_id":101,"instrument_id":436},"action":"A","side":"B","price":"1.156640000","size":30,"channel_id":23,"order_id":"10998899238883087552","flags":0,"ts_in_delta":1174,"sequence":140993,"symbol":"FCEU SI 20260615 PS"}
{"ts_recv":"2026-04-07T02:00:02.028331161Z","hd":{"ts_event":"2026-04-07T02:00:02.028305005Z","rtype":160,"publisher_id":101,"instrument_id":436},"action":"C","side":"A","price":"1.156760000","size":30,"channel_id":23,"order_id":"1775527201086470456","flags":0,"ts_in_delta":1174,"sequence":140993,"symbol":"FCEU SI 20260615 PS"}
{"ts_recv":"2026-04-07T02:00:02.028331161Z","hd":{"ts_event":"2026-04-07T02:00:02.028305005Z","rtype":160,"publisher_id":101,"instrument_id":436},"action":"A","side":"A","price":"1.156740000","size":30,"channel_id":23,"order_id":"1775527202028311744","flags":128,"ts_in_delta":1174,"sequence":140993,"symbol":"FCEU SI 20260615 PS"}
{"ts_recv":"2026-04-07T02:00:03.359930829Z","hd":{"ts_event":"2026-04-07T02:00:03.359907639Z","rtype":160,"publisher_id":101,"instrument_id":436},"action":"C","side":"B","price":"1.156640000","size":30,"channel_id":23,"order_id":"10998899238883087552","flags":0,"ts_in_delta":882,"sequence":141006,"symbol":"FCEU SI 20260615 PS"}
{"ts_recv":"2026-04-07T02:00:03.359930829Z","hd":{"ts_event":"2026-04-07T02:00:03.359907639Z","rtype":160,"publisher_id":101,"instrument_id":436},"action":"A","side":"B","price":"1.156650000","size":30,"channel_id":23,"order_id":"10998899240214689884","flags":0,"ts_in_delta":882,"sequence":141006,"symbol":"FCEU SI 20260615 PS"}
{"ts_recv":"2026-04-07T02:00:03.359930829Z","hd":{"ts_event":"2026-04-07T02:00:03.359907639Z","rtype":160,"publisher_id":101,"instrument_id":436},"action":"C","side":"A","price":"1.156740000","size":30,"channel_id":23,"order_id":"1775527202028311744","flags":0,"ts_in_delta":882,"sequence":141006,"symbol":"FCEU SI 20260615 PS"}
{"ts_recv":"2026-04-07T02:00:03.359930829Z","hd":{"ts_event":"2026-04-07T02:00:03.359907639Z","rtype":160,"publisher_id":101,"instrument_id":436},"action":"A","side":"A","price":"1.156750000","size":30,"channel_id":23,"order_id":"1775527203359914076","flags":128,"ts_in_delta":882,"sequence":141006,"symbol":"FCEU SI 20260615 PS"}
{"ts_recv":"2026-04-07T02:00:03.365064597Z","hd":{"ts_event":"2026-04-07T02:00:03.365045399Z","rtype":160,"publisher_id":101,"instrument_id":436},"action":"C","side":"B","price":"1.156650000","size":30,"channel_id":23,"order_id":"10998899240214689884","flags":0,"ts_in_delta":673,"sequence":141012,"symbol":"FCEU SI 20260615 PS"}
{"ts_recv":"2026-04-07T02:00:03.365064597Z","hd":{"ts_event":"2026-04-07T02:00:03.365045399Z","rtype":160,"publisher_id":101,"instrument_id":436},"action":"A","side":"B","price":"1.156670000","size":30,"channel_id":23,"order_id":"10998899240219827040","flags":0,"ts_in_delta":673,"sequence":141012,"symbol":"FCEU SI 20260615 PS"}
{"ts_recv":"2026-04-07T02:00:03.365064597Z","hd":{"ts_event":"2026-04-07T02:00:03.365045399Z","rtype":160,"publisher_id":101,"instrument_id":436},"action":"C","side":"A","price":"1.156750000","size":30,"channel_id":23,"order_id":"1775527203359914076","flags":0,"ts_in_delta":673,"sequence":141012,"symbol":"FCEU SI 20260615 PS"}
{"ts_recv":"2026-04-07T02:00:03.365064597Z","hd":{"ts_event":"2026-04-07T02:00:03.365045399Z","rtype":160,"publisher_id":101,"instrument_id":436},"action":"A","side":"A","price":"1.156770000","size":30,"channel_id":23,"order_id":"1775527203365051232","flags":128,"ts_in_delta":673,"sequence":141012,"symbol":"FCEU SI 20260615 PS"}
{"ts_recv":"2026-04-07T02:00:03.728116751Z","hd":{"ts_event":"2026-04-07T02:00:03.728092349Z","rtype":160,"publisher_id":101,"instrument_id":436},"action":"C","side":"B","price":"1.156670000","size":30,"channel_id":23,"order_id":"10998899240219827040","flags":0,"ts_in_delta":1820,"sequence":141031,"symbol":"FCEU SI 20260615 PS"}
{"ts_recv":"2026-04-07T02:00:03.728116751Z","hd":{"ts_event":"2026-04-07T02:00:03.728092349Z","rtype":160,"publisher_id":101,"instrument_id":436},"action":"A","side":"B","price":"1.156680000","size":30,"channel_id":23,"order_id":"10998899240582876983","flags":0,"ts_in_delta":1820,"sequence":141031,"symbol":"FCEU SI 20260615 PS"}
{"ts_recv":"2026-04-07T02:00:03.728116751Z","hd":{"ts_event":"2026-04-07T02:00:03.728092349Z","rtype":160,"publisher_id":101,"instrument_id":436},"action":"C","side":"A","price":"1.156770000","size":30,"channel_id":23,"order_id":"1775527203365051232","flags":0,"ts_in_delta":1820,"sequence":141031,"symbol":"FCEU SI 20260615 PS"}
{"ts_recv":"2026-04-07T02:00:03.728116751Z","hd":{"ts_event":"2026-04-07T02:00:03.728092349Z","rtype":160,"publisher_id":101,"instrument_id":436},"action":"A","side":"A","price":"1.156780000","size":30,"channel_id":23,"order_id":"1775527203728101175","flags":128,"ts_in_delta":1820,"sequence":141031,"symbol":"FCEU SI 20260615 PS"}
{"ts_recv":"2026-04-07T02:00:04.977212027Z","hd":{"ts_event":"2026-04-07T02:00:04.977182927Z","rtype":160,"publisher_id":101,"instrument_id":436},"action":"C","side":"B","price":"1.156680000","size":30,"channel_id":23,"order_id":"10998899240582876983","flags":0,"ts_in_delta":1214,"sequence":141041,"symbol":"FCEU SI 20260615 PS"}
{"ts_recv":"2026-04-07T02:00:04.977212027Z","hd":{"ts_event":"2026-04-07T02:00:04.977182927Z","rtype":160,"publisher_id":101,"instrument_id":436},"action":"A","side":"B","price":"1.156660000","size":30,"channel_id":23,"order_id":"10998899241831967536","flags":0,"ts_in_delta":1214,"sequence":141041,"symbol":"FCEU SI 20260615 PS"}
{"ts_recv":"2026-04-07T02:00:04.977212027Z","hd":{"ts_event":"2026-04-07T02:00:04.977182927Z","rtype":160,"publisher_id":101,"instrument_id":436},"action":"C","side":"A","price":"1.156780000","size":30,"channel_id":23,"order_id":"1775527203728101175","flags":0,"ts_in_delta":1214,"sequence":141041,"symbol":"FCEU SI 20260615 PS"}
{"ts_recv":"2026-04-07T02:00:04.977212027Z","hd":{"ts_event":"2026-04-07T02:00:04.977182927Z","rtype":160,"publisher_id":101,"instrument_id":436},"action":"A","side":"A","price":"1.156760000","size":30,"channel_id":23,"order_id":"1775527204977191728","flags":128,"ts_in_delta":1214,"sequence":141041,"symbol":"FCEU SI 20260615 PS"}
{"ts_recv":"2026-04-07T02:00:05.063970680Z","hd":{"ts_event":"2026-04-07T02:00:05.063944833Z","rtype":160,"publisher_id":101,"instrument_id":436},"action":"C","side":"B","price":"1.156660000","size":30,"channel_id":23,"order_id":"10998899241831967536","flags":0,"ts_in_delta":932,"sequence":141051,"symbol":"FCEU SI 20260615 PS"}
{"ts_recv":"2026-04-07T02:00:05.063970680Z","hd":{"ts_event":"2026-04-07T02:00:05.063944833Z","rtype":160,"publisher_id":101,"instrument_id":436},"action":"A","side":"B","price":"1.156650000","size":30,"channel_id":23,"order_id":"10998899241918731586","flags":0,"ts_in_delta":932,"sequence":141051,"symbol":"FCEU SI 20260615 PS"}
{"ts_recv":"2026-04-07T02:00:05.063970680Z","hd":{"ts_event":"2026-04-07T02:00:05.063944833Z","rtype":160,"publisher_id":101,"instrument_id":436},"action":"C","side":"A","price":"1.156760000","size":30,"channel_id":23,"order_id":"1775527204977191728","flags":0,"ts_in_delta":932,"sequence":141051,"symbol":"FCEU SI 20260615 PS"}
{"ts_recv":"2026-04-07T02:00:05.063970680Z","hd":{"ts_event":"2026-04-07T02:00:05.063944833Z","rtype":160,"publisher_id":101,"instrument_id":436},"action":"A","side":"A","price":"1.156750000","size":30,"channel_id":23,"order_id":"1775527205063955778","flags":128,"ts_in_delta":932,"sequence":141051,"symbol":"FCEU SI 20260615 PS"}
{"ts_recv":"2026-04-07T02:00:05.719337420Z","hd":{"ts_event":"2026-04-07T02:00:05.719305061Z","rtype":160,"publisher_id":101,"instrument_id":436},"action":"C","side":"B","price":"1.156650000","size":30,"channel_id":23,"order_id":"10998899241918731586","flags":0,"ts_in_delta":1382,"sequence":141060,"symbol":"FCEU SI 20260615 PS"}
{"ts_recv":"2026-04-07T02:00:05.719337420Z","hd":{"ts_event":"2026-04-07T02:00:05.719305061Z","rtype":160,"publisher_id":101,"instrument_id":436},"action":"A","side":"B","price":"1.156640000","size":30,"channel_id":23,"order_id":"10998899242574093760","flags":0,"ts_in_delta":1382,"sequence":141060,"symbol":"FCEU SI 20260615 PS"}
{"ts_recv":"2026-04-07T02:00:05.719337420Z","hd":{"ts_event":"2026-04-07T02:00:05.719305061Z","rtype":160,"publisher_id":101,"instrument_id":436},"action":"C","side":"A","price":"1.156750000","size":30,"channel_id":23,"order_id":"1775527205063955778","flags":0,"ts_in_delta":1382,"sequence":141060,"symbol":"FCEU SI 20260615 PS"}
{"ts_recv":"2026-04-07T02:00:05.719337420Z","hd":{"ts_event":"2026-04-07T02:00:05.719305061Z","rtype":160,"publisher_id":101,"instrument_id":436},"action":"A","side":"A","price":"1.156740000","size":30,"channel_id":23,"order_id":"1775527205719317952","flags":128,"ts_in_delta":1382,"sequence":141060,"symbol":"FCEU SI 20260615 PS"}
{"ts_recv":"2026-04-07T02:00:09.692411934Z","hd":{"ts_event":"2026-04-07T02:00:09.692389571Z","rtype":160,"publisher_id":101,"instrument_id":436},"action":"C","side":"B","price":"1.156640000","size":30,"channel_id":23,"order_id":"10998899242574093760","flags":0,"ts_in_delta":911,"sequence":141077,"symbol":"FCEU SI 20260615 PS"}
{"ts_recv":"2026-04-07T02:00:09.692411934Z","hd":{"ts_event":"2026-04-07T02:00:09.692389571Z","rtype":160,"publisher_id":101,"instrument_id":436},"action":"A","side":"B","price":"1.156630000","size":30,"channel_id":23,"order_id":"10998899246547172995","flags":0,"ts_in_delta":911,"sequence":141077,"symbol":"FCEU SI 20260615 PS"}
{"ts_recv":"2026-04-07T02:00:09.692411934Z","hd":{"ts_event":"2026-04-07T02:00:09.692389571Z","rtype":160,"publisher_id":101,"instrument_id":436},"action":"C","side":"A","price":"1.156740000","size":30,"channel_id":23,"order_id":"1775527205719317952","flags":0,"ts_in_delta":911,"sequence":141077,"symbol":"FCEU SI 20260615 PS"}
{"ts_recv":"2026-04-07T02:00:09.692411934Z","hd":{"ts_event":"2026-04-07T02:00:09.692389571Z","rtype":160,"publisher_id":101,"instrument_id":436},"action":"A","side":"A","price":"1.156730000","size":30,"channel_id":23,"order_id":"1775527209692397187","flags":128,"ts_in_delta":911,"sequence":141077,"symbol":"FCEU SI 20260615 PS"}
{"ts_recv":"2026-04-07T02:00:09.702768777Z","hd":{"ts_event":"2026-04-07T02:00:09.702748187Z","rtype":160,"publisher_id":101,"instrument_id":436},"action":"C","side":"B","price":"1.156630000","size":30,"channel_id":23,"order_id":"10998899246547172995","flags":0,"ts_in_delta":911,"sequence":141079,"symbol":"FCEU SI 20260615 PS"}
{"ts_recv":"2026-04-07T02:00:09.702768777Z","hd":{"ts_event":"2026-04-07T02:00:09.702748187Z","rtype":160,"publisher_id":101,"instrument_id":436},"action":"A","side":"B","price":"1.156620000","size":30,"channel_id":23,"order_id":"10998899246557529906","flags":0,"ts_in_delta":911,"sequence":141079,"symbol":"FCEU SI 20260615 PS"}
{"ts_recv":"2026-04-07T02:00:09.702768777Z","hd":{"ts_event":"2026-04-07T02:00:09.702748187Z","rtype":160,"publisher_id":101,"instrument_id":436},"action":"C","side":"A","price":"1.156730000","size":30,"channel_id":23,"order_id":"1775527209692397187","flags":0,"ts_in_delta":911,"sequence":141079,"symbol":"FCEU SI 20260615 PS"}
{"ts_recv":"2026-04-07T02:00:09.702768777Z","hd":{"ts_event":"2026-04-07T02:00:09.702748187Z","rtype":160,"publisher_id":101,"instrument_id":436},"action":"A","side":"A","price":"1.156720000","size":30,"channel_id":23,"order_id":"1775527209702754098","flags":128,"ts_in_delta":911,"sequence":141079,"symbol":"FCEU SI 20260615 PS"}
{"ts_recv":"2026-04-07T02:00:10.214810598Z","hd":{"ts_event":"2026-04-07T02:00:10.214791591Z","rtype":160,"publisher_id":101,"instrument_id":436},"action":"C","side":"B","price":"1.156620000","size":30,"channel_id":23,"order_id":"10998899246557529906","flags":0,"ts_in_delta":1108,"sequence":141108,"symbol":"FCEU SI 20260615 PS"}
{"ts_recv":"2026-04-07T02:00:10.214810598Z","hd":{"ts_event":"2026-04-07T02:00:10.214791591Z","rtype":160,"publisher_id":101,"instrument_id":436},"action":"A","side":"B","price":"1.156610000","size":30,"channel_id":23,"order_id":"10998899247069573679","flags":0,"ts_in_delta":1108,"sequence":141108,"symbol":"FCEU SI 20260615 PS"}
{"ts_recv":"2026-04-07T02:00:10.214810598Z","hd":{"ts_event":"2026-04-07T02:00:10.214791591Z","rtype":160,"publisher_id":101,"instrument_id":436},"action":"C","side":"A","price":"1.156720000","size":30,"channel_id":23,"order_id":"1775527209702754098","flags":0,"ts_in_delta":1108,"sequence":141108,"symbol":"FCEU SI 20260615 PS"}
{"ts_recv":"2026-04-07T02:00:10.214810598Z","hd":{"ts_event":"2026-04-07T02:00:10.214791591Z","rtype":160,"publisher_id":101,"instrument_id":436},"action":"A","side":"A","price":"1.156710000","size":30,"channel_id":23,"order_id":"1775527210214797871","flags":128,"ts_in_delta":1108,"sequence":141108,"symbol":"FCEU SI 20260615 PS"}
{"ts_recv":"2026-04-07T02:00:10.224402156Z","hd":{"ts_event":"2026-04-07T02:00:10.224381691Z","rtype":160,"publisher_id":101,"instrument_id":436},"action":"C","side":"B","price":"1.156610000","size":30,"channel_id":23,"order_id":"10998899247069573679","flags":0,"ts_in_delta":890,"sequence":141112,"symbol":"FCEU SI 20260615 PS"}
{"ts_recv":"2026-04-07T02:00:10.224402156Z","hd":{"ts_event":"2026-04-07T02:00:10.224381691Z","rtype":160,"publisher_id":101,"instrument_id":436},"action":"A","side":"B","price":"1.156600000","size":30,"channel_id":23,"order_id":"10998899247079164042","flags":0,"ts_in_delta":890,"sequence":141112,"symbol":"FCEU SI 20260615 PS"}
{"ts_recv":"2026-04-07T02:00:10.224402156Z","hd":{"ts_event":"2026-04-07T02:00:10.224381691Z","rtype":160,"publisher_id":101,"instrument_id":436},"action":"C","side":"A","price":"1.156710000","size":30,"channel_id":23,"order_id":"1775527210214797871","flags":0,"ts_in_delta":890,"sequence":141112,"symbol":"FCEU SI 20260615 PS"}
{"ts_recv":"2026-04-07T02:00:10.224402156Z","hd":{"ts_event":"2026-04-07T02:00:10.224381691Z","rtype":160,"publisher_id":101,"instrument_id":436},"action":"A","side":"A","price":"1.156700000","size":30,"channel_id":23,"order_id":"1775527210224388234","flags":128,"ts_in_delta":890,"sequence":141112,"symbol":"FCEU SI 20260615 PS"}
{"ts_recv":"2026-04-07T02:00:11.209502373Z","hd":{"ts_event":"2026-04-07T02:00:11.209482779Z","rtype":160,"publisher_id":101,"instrument_id":436},"action":"C","side":"B","price":"1.156600000","size":30,"channel_id":23,"order_id":"10998899247079164042","flags":0,"ts_in_delta":915,"sequence":141122,"symbol":"FCEU SI 20260615 PS"}
{"ts_recv":"2026-04-07T02:00:11.209502373Z","hd":{"ts_event":"2026-04-07T02:00:11.209482779Z","rtype":160,"publisher_id":101,"instrument_id":436},"action":"A","side":"B","price":"1.156610000","size":30,"channel_id":23,"order_id":"10998899248064264894","flags":0,"ts_in_delta":915,"sequence":141122,"symbol":"FCEU SI 20260615 PS"}
{"ts_recv":"2026-04-07T02:00:11.209502373Z","hd":{"ts_event":"2026-04-07T02:00:11.209482779Z","rtype":160,"publisher_id":101,"instrument_id":436},"action":"C","side":"A","price":"1.156700000","size":30,"channel_id":23,"order_id":"1775527210224388234","flags":0,"ts_in_delta":915,"sequence":141122,"symbol":"FCEU SI 20260615 PS"}
{"ts_recv":"2026-04-07T02:00:11.209502373Z","hd":{"ts_event":"2026-04-07T02:00:11.209482779Z","rtype":160,"publisher_id":101,"instrument_id":436},"action":"A","side":"A","price":"1.156710000","size":30,"channel_id":23,"order_id":"1775527211209489086","flags":128,"ts_in_delta":915,"sequence":141122,"symbol":"FCEU SI 20260615 PS"}
{"ts_recv":"2026-04-07T02:00:11.215678507Z","hd":{"ts_event":"2026-04-07T02:00:11.215655543Z","rtype":160,"publisher_id":101,"instrument_id":436},"action":"C","side":"B","price":"1.156610000","size":30,"channel_id":23,"order_id":"10998899248064264894","flags":0,"ts_in_delta":884,"sequence":141127,"symbol":"FCEU SI 20260615 PS"}
{"ts_recv":"2026-04-07T02:00:11.215678507Z","hd":{"ts_event":"2026-04-07T02:00:11.215655543Z","rtype":160,"publisher_id":101,"instrument_id":436},"action":"A","side":"B","price":"1.156620000","size":30,"channel_id":23,"order_id":"10998899248070437273","flags":0,"ts_in_delta":884,"sequence":141127,"symbol":"FCEU SI 20260615 PS"}
{"ts_recv":"2026-04-07T02:00:11.215678507Z","hd":{"ts_event":"2026-04-07T02:00:11.215655543Z","rtype":160,"publisher_id":101,"instrument_id":436},"action":"C","side":"A","price":"1.156710000","size":30,"channel_id":23,"order_id":"1775527211209489086","flags":0,"ts_in_delta":884,"sequence":141127,"symbol":"FCEU SI 20260615 PS"}
{"ts_recv":"2026-04-07T02:00:11.215678507Z","hd":{"ts_event":"2026-04-07T02:00:11.215655543Z","rtype":160,"publisher_id":101,"instrument_id":436},"action":"A","side":"A","price":"1.156720000","size":30,"channel_id":23,"order_id":"1775527211215661465","flags":128,"ts_in_delta":884,"sequence":141127,"symbol":"FCEU SI 20260615 PS"}
{"ts_recv":"2026-04-07T02:00:15.427044525Z","hd":{"ts_event":"2026-04-07T02:00:15.427010861Z","rtype":160,"publisher_id":101,"instrument_id":436},"action":"C","side":"B","price":"1.156620000","size":30,"channel_id":23,"order_id":"10998899248070437273","flags":0,"ts_in_delta":1403,"sequence":141158,"symbol":"FCEU SI 20260615 PS"}
{"ts_recv":"2026-04-07T02:00:15.427044525Z","hd":{"ts_event":"2026-04-07T02:00:15.427010861Z","rtype":160,"publisher_id":101,"instrument_id":436},"action":"A","side":"B","price":"1.156610000","size":30,"channel_id":23,"order_id":"10998899252281800455","flags":0,"ts_in_delta":1403,"sequence":141158,"symbol":"FCEU SI 20260615 PS"}
{"ts_recv":"2026-04-07T02:00:15.427044525Z","hd":{"ts_event":"2026-04-07T02:00:15.427010861Z","rtype":160,"publisher_id":101,"instrument_id":436},"action":"C","side":"A","price":"1.156720000","size":30,"channel_id":23,"order_id":"1775527211215661465","flags":0,"ts_in_delta":1403,"sequence":141158,"symbol":"FCEU SI 20260615 PS"}
{"ts_recv":"2026-04-07T02:00:15.427044525Z","hd":{"ts_event":"2026-04-07T02:00:15.427010861Z","rtype":160,"publisher_id":101,"instrument_id":436},"action":"A","side":"A","price":"1.156710000","size":30,"channel_id":23,"order_id":"1775527215427024647","flags":128,"ts_in_delta":1403,"sequence":141158,"symbol":"FCEU SI 20260615 PS"}
{"ts_recv":"2026-04-07T02:00:16.769907249Z","hd":{"ts_event":"2026-04-07T02:00:16.769885683Z","rtype":160,"publisher_id":101,"instrument_id":436},"action":"C","side":"B","price":"1.156610000","size":30,"channel_id":23,"order_id":"10998899252281800455","flags":0,"ts_in_delta":1062,"sequence":141171,"symbol":"FCEU SI 20260615 PS"}
{"ts_recv":"2026-04-07T02:00:16.769907249Z","hd":{"ts_event":"2026-04-07T02:00:16.769885683Z","rtype":160,"publisher_id":101,"instrument_id":436},"action":"A","side":"B","price":"1.156600000","size":30,"channel_id":23,"order_id":"10998899253624667750","flags":0,"ts_in_delta":1062,"sequence":141171,"symbol":"FCEU SI 20260615 PS"}
{"ts_recv":"2026-04-07T02:00:16.769907249Z","hd":{"ts_event":"2026-04-07T02:00:16.769885683Z","rtype":160,"publisher_id":101,"instrument_id":436},"action":"C","side":"A","price":"1.156710000","size":30,"channel_id":23,"order_id":"1775527215427024647","flags":0,"ts_in_delta":1062,"sequence":141171,"symbol":"FCEU SI 20260615 PS"}
{"ts_recv":"2026-04-07T02:00:16.769907249Z","hd":{"ts_event":"2026-04-07T02:00:16.769885683Z","rtype":160,"publisher_id":101,"instrument_id":436},"action":"A","side":"A","price":"1.156700000","size":30,"channel_id":23,"order_id":"1775527216769891942","flags":128,"ts_in_delta":1062,"sequence":141171,"symbol":"FCEU SI 20260615 PS"}
{"ts_recv":"2026-04-07T02:00:18.337343954Z","hd":{"ts_event":"2026-04-07T02:00:18.337316611Z","rtype":160,"publisher_id":101,"instrument_id":436},"action":"C","side":"B","price":"1.156600000","size":30,"channel_id":23,"order_id":"10998899253624667750","flags":0,"ts_in_delta":1134,"sequence":141187,"symbol":"FCEU SI 20260615 PS"}
{"ts_recv":"2026-04-07T02:00:18.337343954Z","hd":{"ts_event":"2026-04-07T02:00:18.337316611Z","rtype":160,"publisher_id":101,"instrument_id":436},"action":"A","side":"B","price":"1.156610000","size":30,"channel_id":23,"order_id":"10998899255192104139","flags":0,"ts_in_delta":1134,"sequence":141187,"symbol":"FCEU SI 20260615 PS"}
{"ts_recv":"2026-04-07T02:00:18.337343954Z","hd":{"ts_event":"2026-04-07T02:00:18.337316611Z","rtype":160,"publisher_id":101,"instrument_id":436},"action":"C","side":"A","price":"1.156700000","size":30,"channel_id":23,"order_id":"1775527216769891942","flags":0,"ts_in_delta":1134,"sequence":141187,"symbol":"FCEU SI 20260615 PS"}
{"ts_recv":"2026-04-07T02:00:18.337343954Z","hd":{"ts_event":"2026-04-07T02:00:18.337316611Z","rtype":160,"publisher_id":101,"instrument_id":436},"action":"A","side":"A","price":"1.156710000","size":30,"channel_id":23,"order_id":"1775527218337328331","flags":128,"ts_in_delta":1134,"sequence":141187,"symbol":"FCEU SI 20260615 PS"}
{"ts_recv":"2026-04-07T02:00:19.143423216Z","hd":{"ts_event":"2026-04-07T02:00:19.143400111Z","rtype":160,"publisher_id":101,"instrument_id":436},"action":"C","side":"B","price":"1.156610000","size":30,"channel_id":23,"order_id":"10998899255192104139","flags":0,"ts_in_delta":918,"sequence":141201,"symbol":"FCEU SI 20260615 PS"}
{"ts_recv":"2026-04-07T02:00:19.143423216Z","hd":{"ts_event":"2026-04-07T02:00:19.143400111Z","rtype":160,"publisher_id":101,"instrument_id":436},"action":"A","side":"B","price":"1.156620000","size":30,"channel_id":23,"order_id":"10998899255998182628","flags":0,"ts_in_delta":918,"sequence":141201,"symbol":"FCEU SI 20260615 PS"}
{"ts_recv":"2026-04-07T02:00:19.143423216Z","hd":{"ts_event":"2026-04-07T02:00:19.143400111Z","rtype":160,"publisher_id":101,"instrument_id":436},"action":"C","side":"A","price":"1.156710000","size":30,"channel_id":23,"order_id":"1775527218337328331","flags":0,"ts_in_delta":918,"sequence":141201,"symbol":"FCEU SI 20260615 PS"}
{"ts_recv":"2026-04-07T02:00:19.143423216Z","hd":{"ts_event":"2026-04-07T02:00:19.143400111Z","rtype":160,"publisher_id":101,"instrument_id":436},"action":"A","side":"A","price":"1.156720000","size":30,"channel_id":23,"order_id":"1775527219143406820","flags":128,"ts_in_delta":918,"sequence":141201,"symbol":"FCEU SI 20260615 PS"}
{"ts_recv":"2026-04-07T02:00:19.285202349Z","hd":{"ts_event":"2026-04-07T02:00:19.285181187Z","rtype":160,"publisher_id":101,"instrument_id":436},"action":"C","side":"B","price":"1.156620000","size":30,"channel_id":23,"order_id":"10998899255998182628","flags":0,"ts_in_delta":1348,"sequence":141212,"symbol":"FCEU SI 20260615 PS"}
{"ts_recv":"2026-04-07T02:00:19.285202349Z","hd":{"ts_event":"2026-04-07T02:00:19.285181187Z","rtype":160,"publisher_id":101,"instrument_id":436},"action":"A","side":"B","price":"1.156610000","size":30,"channel_id":23,"order_id":"10998899256139963351","flags":0,"ts_in_delta":1348,"sequence":141212,"symbol":"FCEU SI 20260615 PS"}
{"ts_recv":"2026-04-07T02:00:19.285202349Z","hd":{"ts_event":"2026-04-07T02:00:19.285181187Z","rtype":160,"publisher_id":101,"instrument_id":436},"action":"C","side":"A","price":"1.156720000","size":30,"channel_id":23,"order_id":"1775527219143406820","flags":0,"ts_in_delta":1348,"sequence":141212,"symbol":"FCEU SI 20260615 PS"}
{"ts_recv":"2026-04-07T02:00:19.285202349Z","hd":{"ts_event":"2026-04-07T02:00:19.285181187Z","rtype":160,"publisher_id":101,"instrument_id":436},"action":"A","side":"A","price":"1.156710000","size":30,"channel_id":23,"order_id":"1775527219285187543","flags":128,"ts_in_delta":1348,"sequence":141212,"symbol":"FCEU SI 20260615 PS"}
{"ts_recv":"2026-04-07T02:00:19.289655055Z","hd":{"ts_event":"2026-04-07T02:00:19.289634705Z","rtype":160,"publisher_id":101,"instrument_id":436},"action":"C","side":"B","price":"1.156610000","size":30,"channel_id":23,"order_id":"10998899256139963351","flags":0,"ts_in_delta":917,"sequence":141213,"symbol":"FCEU SI 20260615 PS"}
{"ts_recv":"2026-04-07T02:00:19.289655055Z","hd":{"ts_event":"2026-04-07T02:00:19.289634705Z","rtype":160,"publisher_id":101,"instrument_id":436},"action":"A","side":"B","price":"1.156600000","size":30,"channel_id":23,"order_id":"10998899256144416581","flags":0,"ts_in_delta":917,"sequence":141213,"symbol":"FCEU SI 20260615 PS"}
{"ts_recv":"2026-04-07T02:00:19.289655055Z","hd":{"ts_event":"2026-04-07T02:00:19.289634705Z","rtype":160,"publisher_id":101,"instrument_id":436},"action":"C","side":"A","price":"1.156710000","size":30,"channel_id":23,"order_id":"1775527219285187543","flags":0,"ts_in_delta":917,"sequence":141213,"symbol":"FCEU SI 20260615 PS"}
{"ts_recv":"2026-04-07T02:00:19.289655055Z","hd":{"ts_event":"2026-04-07T02:00:19.289634705Z","rtype":160,"publisher_id":101,"instrument_id":436},"action":"A","side":"A","price":"1.156700000","size":30,"channel_id":23,"order_id":"1775527219289640773","flags":128,"ts_in_delta":917,"sequence":141213,"symbol":"FCEU SI 20260615 PS"}
{"ts_recv":"2026-04-07T02:00:19.315050429Z","hd":{"ts_event":"2026-04-07T02:00:19.315030907Z","rtype":160,"publisher_id":101,"instrument_id":436},"action":"C","side":"B","price":"1.156600000","size":30,"channel_id":23,"order_id":"10998899256144416581","flags":0,"ts_in_delta":871,"sequence":141215,"symbol":"FCEU SI 20260615 PS"}
{"ts_recv":"2026-04-07T02:00:19.315050429Z","hd":{"ts_event":"2026-04-07T02:00:19.315030907Z","rtype":160,"publisher_id":101,"instrument_id":436},"action":"A","side":"B","price":"1.156610000","size":30,"channel_id":23,"order_id":"10998899256169812633","flags":0,"ts_in_delta":871,"sequence":141215,"symbol":"FCEU SI 20260615 PS"}
{"ts_recv":"2026-04-07T02:00:19.315050429Z","hd":{"ts_event":"2026-04-07T02:00:19.315030907Z","rtype":160,"publisher_id":101,"instrument_id":436},"action":"C","side":"A","price":"1.156700000","size":30,"channel_id":23,"order_id":"1775527219289640773","flags":0,"ts_in_delta":871,"sequence":141215,"symbol":"FCEU SI 20260615 PS"}
{"ts_recv":"2026-04-07T02:00:19.315050429Z","hd":{"ts_event":"2026-04-07T02:00:19.315030907Z","rtype":160,"publisher_id":101,"instrument_id":436},"action":"A","side":"A","price":"1.156710000","size":30,"channel_id":23,"order_id":"1775527219315036825","flags":128,"ts_in_delta":871,"sequence":141215,"symbol":"FCEU SI 20260615 PS"}
{"ts_recv":"2026-04-07T02:00:20.786411798Z","hd":{"ts_event":"2026-04-07T02:00:20.786382985Z","rtype":160,"publisher_id":101,"instrument_id":436},"action":"C","side":"B","price":"1.156610000","size":30,"channel_id":23,"order_id":"10998899256169812633","flags":0,"ts_in_delta":1412,"sequence":141228,"symbol":"FCEU SI 20260615 PS"}
{"ts_recv":"2026-04-07T02:00:20.786411798Z","hd":{"ts_event":"2026-04-07T02:00:20.786382985Z","rtype":160,"publisher_id":101,"instrument_id":436},"action":"A","side":"B","price":"1.156600000","size":30,"channel_id":23,"order_id":"10998899257641171204","flags":0,"ts_in_delta":1412,"sequence":141228,"symbol":"FCEU SI 20260615 PS"}
{"ts_recv":"2026-04-07T02:00:20.786411798Z","hd":{"ts_event":"2026-04-07T02:00:20.786382985Z","rtype":160,"publisher_id":101,"instrument_id":436},"action":"C","side":"A","price":"1.156710000","size":30,"channel_id":23,"order_id":"1775527219315036825","flags":0,"ts_in_delta":1412,"sequence":141228,"symbol":"FCEU SI 20260615 PS"}
{"ts_recv":"2026-04-07T02:00:20.786411798Z","hd":{"ts_event":"2026-04-07T02:00:20.786382985Z","rtype":160,"publisher_id":101,"instrument_id":436},"action":"A","side":"A","price":"1.156700000","size":30,"channel_id":23,"order_id":"1775527220786395396","flags":128,"ts_in_delta":1412,"sequence":141228,"symbol":"FCEU SI 20260615 PS"}
{"ts_recv":"2026-04-07T02:00:21.563202134Z","hd":{"ts_event":"2026-04-07T02:00:21.563172951Z","rtype":160,"publisher_id":101,"instrument_id":436},"action":"C","side":"B","price":"1.156600000","size":30,"channel_id":23,"order_id":"10998899257641171204","flags":0,"ts_in_delta":1586,"sequence":141237,"symbol":"FCEU SI 20260615 PS"}
{"ts_recv":"2026-04-07T02:00:21.563202134Z","hd":{"ts_event":"2026-04-07T02:00:21.563172951Z","rtype":160,"publisher_id":101,"instrument_id":436},"action":"A","side":"B","price":"1.156610000","size":30,"channel_id":23,"order_id":"10998899258417959392","flags":0,"ts_in_delta":1586,"sequence":141237,"symbol":"FCEU SI 20260615 PS"}
{"ts_recv":"2026-04-07T02:00:21.563202134Z","hd":{"ts_event":"2026-04-07T02:00:21.563172951Z","rtype":160,"publisher_id":101,"instrument_id":436},"action":"C","side":"A","price":"1.156700000","size":30,"channel_id":23,"order_id":"1775527220786395396","flags":0,"ts_in_delta":1586,"sequence":141237,"symbol":"FCEU SI 20260615 PS"}
{"ts_recv":"2026-04-07T02:00:21.563202134Z","hd":{"ts_event":"2026-04-07T02:00:21.563172951Z","rtype":160,"publisher_id":101,"instrument_id":436},"action":"A","side":"A","price":"1.156710000","size":30,"channel_id":23,"order_id":"1775527221563183584","flags":128,"ts_in_delta":1586,"sequence":141237,"symbol":"FCEU SI 20260615 PS"}
{"ts_recv":"2026-04-07T02:00:24.175778410Z","hd":{"ts_event":"2026-04-07T02:00:24.175713447Z","rtype":160,"publisher_id":101,"instrument_id":436},"action":"A","side":"B","price":"1.156610000","size":30,"channel_id":23,"order_id":"10998899261030529586","flags":0,"ts_in_delta":1541,"sequence":141252,"symbol":"FCEU SI 20260615 PS"}
{"ts_recv":"2026-04-07T02:00:24.175778410Z","hd":{"ts_event":"2026-04-07T02:00:24.175713447Z","rtype":160,"publisher_id":101,"instrument_id":436},"action":"A","side":"A","price":"1.156710000","size":30,"channel_id":23,"order_id":"1775527224175753778","flags":128,"ts_in_delta":1541,"sequence":141252,"symbol":"FCEU SI 20260615 PS"}
{"ts_recv":"2026-04-07T02:00:33.142181373Z","hd":{"ts_event":"2026-04-07T02:00:33.142159981Z","rtype":160,"publisher_id":101,"instrument_id":436},"action":"C","side":"B","price":"1.156610000","size":30,"channel_id":23,"order_id":"10998899258417959392","flags":0,"ts_in_delta":962,"sequence":141333,"symbol":"FCEU SI 20260615 PS"}
{"ts_recv":"2026-04-07T02:00:33.142181373Z","hd":{"ts_event":"2026-04-07T02:00:33.142159981Z","rtype":160,"publisher_id":101,"instrument_id":436},"action":"A","side":"B","price":"1.156600000","size":30,"channel_id":23,"order_id":"10998899269996941509","flags":0,"ts_in_delta":962,"sequence":141333,"symbol":"FCEU SI 20260615 PS"}
{"ts_recv":"2026-04-07T02:00:33.142181373Z","hd":{"ts_event":"2026-04-07T02:00:33.142159981Z","rtype":160,"publisher_id":101,"instrument_id":436},"action":"C","side":"A","price":"1.156710000","size":30,"channel_id":23,"order_id":"1775527221563183584","flags":0,"ts_in_delta":962,"sequence":141333,"symbol":"FCEU SI 20260615 PS"}
{"ts_recv":"2026-04-07T02:00:33.142181373Z","hd":{"ts_event":"2026-04-07T02:00:33.142159981Z","rtype":160,"publisher_id":101,"instrument_id":436},"action":"A","side":"A","price":"1.156700000","size":30,"channel_id":23,"order_id":"1775527233142165701","flags":128,"ts_in_delta":962,"sequence":141333,"symbol":"FCEU SI 20260615 PS"}
{"ts_recv":"2026-04-07T02:00:33.151626188Z","hd":{"ts_event":"2026-04-07T02:00:33.151602035Z","rtype":160,"publisher_id":101,"instrument_id":436},"action":"C","side":"B","price":"1.156610000","size":30,"channel_id":23,"order_id":"10998899261030529586","flags":0,"ts_in_delta":970,"sequence":141337,"symbol":"FCEU SI 20260615 PS"}
{"ts_recv":"2026-04-07T02:00:33.151626188Z","hd":{"ts_event":"2026-04-07T02:00:33.151602035Z","rtype":160,"publisher_id":101,"instrument_id":436},"action":"A","side":"B","price":"1.156590000","size":30,"channel_id":23,"order_id":"10998899270006384532","flags":0,"ts_in_delta":970,"sequence":141337,"symbol":"FCEU SI 20260615 PS"}
{"ts_recv":"2026-04-07T02:00:33.151626188Z","hd":{"ts_event":"2026-04-07T02:00:33.151602035Z","rtype":160,"publisher_id":101,"instrument_id":436},"action":"C","side":"A","price":"1.156710000","size":30,"channel_id":23,"order_id":"1775527224175753778","flags":0,"ts_in_delta":970,"sequence":141337,"symbol":"FCEU SI 20260615 PS"}
{"ts_recv":"2026-04-07T02:00:33.151626188Z","hd":{"ts_event":"2026-04-07T02:00:33.151602035Z","rtype":160,"publisher_id":101,"instrument_id":436},"action":"A","side":"A","price":"1.156690000","size":30,"channel_id":23,"order_id":"1775527233151608724","flags":128,"ts_in_delta":970,"sequence":141337,"symbol":"FCEU SI 20260615 PS"}
{"ts_recv":"2026-04-07T02:00:33.151688062Z","hd":{"ts_event":"2026-04-07T02:00:33.151668161Z","rtype":160,"publisher_id":101,"instrument_id":436},"action":"C","side":"B","price":"1.156600000","size":30,"channel_id":23,"order_id":"10998899269996941509","flags":0,"ts_in_delta":1143,"sequence":141338,"symbol":"FCEU SI 20260615 PS"}
{"ts_recv":"2026-04-07T02:00:33.151688062Z","hd":{"ts_event":"2026-04-07T02:00:33.151668161Z","rtype":160,"publisher_id":101,"instrument_id":436},"action":"A","side":"B","price":"1.156590000","size":30,"channel_id":23,"order_id":"10998899270006451010","flags":0,"ts_in_delta":1143,"sequence":141338,"symbol":"FCEU SI 20260615 PS"}
{"ts_recv":"2026-04-07T02:00:33.151688062Z","hd":{"ts_event":"2026-04-07T02:00:33.151668161Z","rtype":160,"publisher_id":101,"instrument_id":436},"action":"C","side":"A","price":"1.156700000","size":30,"channel_id":23,"order_id":"1775527233142165701","flags":0,"ts_in_delta":1143,"sequence":141338,"symbol":"FCEU SI 20260615 PS"}
{"ts_recv":"2026-04-07T02:00:33.151688062Z","hd":{"ts_event":"2026-04-07T02:00:33.151668161Z","rtype":160,"publisher_id":101,"instrument_id":436},"action":"A","side":"A","price":"1.156690000","size":30,"channel_id":23,"order_id":"1775527233151675202","flags":128,"ts_in_delta":1143,"sequence":141338,"symbol":"FCEU SI 20260615 PS"}
{"ts_recv":"2026-04-07T02:00:35.431573841Z","hd":{"ts_event":"2026-04-07T02:00:35.431551511Z","rtype":160,"publisher_id":101,"instrument_id":436},"action":"C","side":"B","price":"1.156590000","size":30,"channel_id":23,"order_id":"10998899270006451010","flags":0,"ts_in_delta":899,"sequence":141377,"symbol":"FCEU SI 20260615 PS"}
{"ts_recv":"2026-04-07T02:00:35.431573841Z","hd":{"ts_event":"2026-04-07T02:00:35.431551511Z","rtype":160,"publisher_id":101,"instrument_id":436},"action":"A","side":"B","price":"1.156580000","size":30,"channel_id":23,"order_id":"10998899272286333898","flags":0,"ts_in_delta":899,"sequence":141377,"symbol":"FCEU SI 20260615 PS"}
{"ts_recv":"2026-04-07T02:00:35.431573841Z","hd":{"ts_event":"2026-04-07T02:00:35.431551511Z","rtype":160,"publisher_id":101,"instrument_id":436},"action":"C","side":"A","price":"1.156690000","size":30,"channel_id":23,"order_id":"1775527233151675202","flags":0,"ts_in_delta":899,"sequence":141377,"symbol":"FCEU SI 20260615 PS"}
{"ts_recv":"2026-04-07T02:00:35.431573841Z","hd":{"ts_event":"2026-04-07T02:00:35.431551511Z","rtype":160,"publisher_id":101,"instrument_id":436},"action":"A","side":"A","price":"1.156680000","size":30,"channel_id":23,"order_id":"1775527235431558090","flags":128,"ts_in_delta":899,"sequence":141377,"symbol":"FCEU SI 20260615 PS"}
{"ts_recv":"2026-04-07T02:00:35.447743509Z","hd":{"ts_event":"2026-04-07T02:00:35.447720475Z","rtype":160,"publisher_id":101,"instrument_id":436},"action":"C","side":"B","price":"1.156590000","size":30,"channel_id":23,"order_id":"10998899270006384532","flags":0,"ts_in_delta":1024,"sequence":141379,"symbol":"FCEU SI 20260615 PS"}
{"ts_recv":"2026-04-07T02:00:35.447743509Z","hd":{"ts_event":"2026-04-07T02:00:35.447720475Z","rtype":160,"publisher_id":101,"instrument_id":436},"action":"A","side":"B","price":"1.156570000","size":30,"channel_id":23,"order_id":"10998899272302502864","flags":0,"ts_in_delta":1024,"sequence":141379,"symbol":"FCEU SI 20260615 PS"}
{"ts_recv":"2026-04-07T02:00:35.447743509Z","hd":{"ts_event":"2026-04-07T02:00:35.447720475Z","rtype":160,"publisher_id":101,"instrument_id":436},"action":"C","side":"A","price":"1.156690000","size":30,"channel_id":23,"order_id":"1775527233151608724","flags":0,"ts_in_delta":1024,"sequence":141379,"symbol":"FCEU SI 20260615 PS"}
{"ts_recv":"2026-04-07T02:00:35.447743509Z","hd":{"ts_event":"2026-04-07T02:00:35.447720475Z","rtype":160,"publisher_id":101,"instrument_id":436},"action":"A","side":"A","price":"1.156670000","size":30,"channel_id":23,"order_id":"1775527235447727056","flags":128,"ts_in_delta":1024,"sequence":141379,"symbol":"FCEU SI 20260615 PS"}
{"ts_recv":"2026-04-07T02:00:35.447808940Z","hd":{"ts_event":"2026-04-07T02:00:35.447792405Z","rtype":160,"publisher_id":101,"instrument_id":436},"action":"C","side":"B","price":"1.156580000","size":30,"channel_id":23,"order_id":"10998899272286333898","flags":0,"ts_in_delta":943,"sequence":141380,"symbol":"FCEU SI 20260615 PS"}
{"ts_recv":"2026-04-07T02:00:35.447808940Z","hd":{"ts_event":"2026-04-07T02:00:35.447792405Z","rtype":160,"publisher_id":101,"instrument_id":436},"action":"A","side":"B","price":"1.156570000","size":30,"channel_id":23,"order_id":"10998899272302574137","flags":0,"ts_in_delta":943,"sequence":141380,"symbol":"FCEU SI 20260615 PS"}
{"ts_recv":"2026-04-07T02:00:35.447808940Z","hd":{"ts_event":"2026-04-07T02:00:35.447792405Z","rtype":160,"publisher_id":101,"instrument_id":436},"action":"C","side":"A","price":"1.156680000","size":30,"channel_id":23,"order_id":"1775527235431558090","flags":0,"ts_in_delta":943,"sequence":141380,"symbol":"FCEU SI 20260615 PS"}
{"ts_recv":"2026-04-07T02:00:35.447808940Z","hd":{"ts_event":"2026-04-07T02:00:35.447792405Z","rtype":160,"publisher_id":101,"instrument_id":436},"action":"A","side":"A","price":"1.156670000","size":30,"channel_id":23,"order_id":"1775527235447798329","flags":128,"ts_in_delta":943,"sequence":141380,"symbol":"FCEU SI 20260615 PS"}
{"ts_recv":"2026-04-07T02:00:55.345544784Z","hd":{"ts_event":"2026-04-07T02:00:55.345520089Z","rtype":160,"publisher_id":101,"instrument_id":436},"action":"C","side":"B","price":"1.156570000","size":30,"channel_id":23,"order_id":"10998899272302574137","flags":0,"ts_in_delta":879,"sequence":141537,"symbol":"FCEU SI 20260615 PS"}
{"ts_recv":"2026-04-07T02:00:55.345544784Z","hd":{"ts_event":"2026-04-07T02:00:55.345520089Z","rtype":160,"publisher_id":101,"instrument_id":436},"action":"A","side":"B","price":"1.156580000","size":30,"channel_id":23,"order_id":"10998899292200302068","flags":0,"ts_in_delta":879,"sequence":141537,"symbol":"FCEU SI 20260615 PS"}
{"ts_recv":"2026-04-07T02:00:55.345544784Z","hd":{"ts_event":"2026-04-07T02:00:55.345520089Z","rtype":160,"publisher_id":101,"instrument_id":436},"action":"C","side":"A","price":"1.156670000","size":30,"channel_id":23,"order_id":"1775527235447798329","flags":0,"ts_in_delta":879,"sequence":141537,"symbol":"FCEU SI 20260615 PS"}
{"ts_recv":"2026-04-07T02:00:55.345544784Z","hd":{"ts_event":"2026-04-07T02:00:55.345520089Z","rtype":160,"publisher_id":101,"instrument_id":436},"action":"A","side":"A","price":"1.156680000","size":30,"channel_id":23,"order_id":"1775527255345526260","flags":128,"ts_in_delta":879,"sequence":141537,"symbol":"FCEU SI 20260615 PS"}
{"ts_recv":"2026-04-07T02:00:55.978570090Z","hd":{"ts_event":"2026-04-07T02:00:55.978547343Z","rtype":160,"publisher_id":101,"instrument_id":436},"action":"C","side":"B","price":"1.156570000","size":30,"channel_id":23,"order_id":"10998899272302502864","flags":0,"ts_in_delta":1166,"sequence":141568,"symbol":"FCEU SI 20260615 PS"}
{"ts_recv":"2026-04-07T02:00:55.978570090Z","hd":{"ts_event":"2026-04-07T02:00:55.978547343Z","rtype":160,"publisher_id":101,"instrument_id":436},"action":"A","side":"B","price":"1.156590000","size":30,"channel_id":23,"order_id":"10998899292833329382","flags":0,"ts_in_delta":1166,"sequence":141568,"symbol":"FCEU SI 20260615 PS"}
{"ts_recv":"2026-04-07T02:00:55.978570090Z","hd":{"ts_event":"2026-04-07T02:00:55.978547343Z","rtype":160,"publisher_id":101,"instrument_id":436},"action":"C","side":"A","price":"1.156670000","size":30,"channel_id":23,"order_id":"1775527235447727056","flags":0,"ts_in_delta":1166,"sequence":141568,"symbol":"FCEU SI 20260615 PS"}
{"ts_recv":"2026-04-07T02:00:55.978570090Z","hd":{"ts_event":"2026-04-07T02:00:55.978547343Z","rtype":160,"publisher_id":101,"instrument_id":436},"action":"A","side":"A","price":"1.156690000","size":30,"channel_id":23,"order_id":"1775527255978553574","flags":128,"ts_in_delta":1166,"sequence":141568,"symbol":"FCEU SI 20260615 PS"}
{"ts_recv":"2026-04-07T02:00:55.978636327Z","hd":{"ts_event":"2026-04-07T02:00:55.978616655Z","rtype":160,"publisher_id":101,"instrument_id":436},"action":"C","side":"B","price":"1.156580000","size":30,"channel_id":23,"order_id":"10998899292200302068","flags":0,"ts_in_delta":928,"sequence":141569,"symbol":"FCEU SI 20260615 PS"}
{"ts_recv":"2026-04-07T02:00:55.978636327Z","hd":{"ts_event":"2026-04-07T02:00:55.978616655Z","rtype":160,"publisher_id":101,"instrument_id":436},"action":"A","side":"B","price":"1.156590000","size":30,"channel_id":23,"order_id":"10998899292833398552","flags":0,"ts_in_delta":928,"sequence":141569,"symbol":"FCEU SI 20260615 PS"}
{"ts_recv":"2026-04-07T02:00:55.978636327Z","hd":{"ts_event":"2026-04-07T02:00:55.978616655Z","rtype":160,"publisher_id":101,"instrument_id":436},"action":"C","side":"A","price":"1.156680000","size":30,"channel_id":23,"order_id":"1775527255345526260","flags":0,"ts_in_delta":928,"sequence":141569,"symbol":"FCEU SI 20260615 PS"}
{"ts_recv":"2026-04-07T02:00:55.978636327Z","hd":{"ts_event":"2026-04-07T02:00:55.978616655Z","rtype":160,"publisher_id":101,"instrument_id":436},"action":"A","side":"A","price":"1.156690000","size":30,"channel_id":23,"order_id":"1775527255978622744","flags":128,"ts_in_delta":928,"sequence":141569,"symbol":"FCEU SI 20260615 PS"}
{"ts_recv":"2026-04-07T02:00:56.542978500Z","hd":{"ts_event":"2026-04-07T02:00:56.542956329Z","rtype":160,"publisher_id":101,"instrument_id":436},"action":"C","side":"B","price":"1.156590000","size":30,"channel_id":23,"order_id":"10998899292833398552","flags":0,"ts_in_delta":1061,"sequence":141591,"symbol":"FCEU SI 20260615 PS"}
{"ts_recv":"2026-04-07T02:00:56.542978500Z","hd":{"ts_event":"2026-04-07T02:00:56.542956329Z","rtype":160,"publisher_id":101,"instrument_id":436},"action":"A","side":"B","price":"1.156600000","size":30,"channel_id":23,"order_id":"10998899293397738323","flags":0,"ts_in_delta":1061,"sequence":141591,"symbol":"FCEU SI 20260615 PS"}
{"ts_recv":"2026-04-07T02:00:56.542978500Z","hd":{"ts_event":"2026-04-07T02:00:56.542956329Z","rtype":160,"publisher_id":101,"instrument_id":436},"action":"C","side":"A","price":"1.156690000","size":30,"channel_id":23,"order_id":"1775527255978622744","flags":0,"ts_in_delta":1061,"sequence":141591,"symbol":"FCEU SI 20260615 PS"}
{"ts_recv":"2026-04-07T02:00:56.542978500Z","hd":{"ts_event":"2026-04-07T02:00:56.542956329Z","rtype":160,"publisher_id":101,"instrument_id":436},"action":"A","side":"A","price":"1.156700000","size":30,"channel_id":23,"order_id":"1775527256542962515","flags":128,"ts_in_delta":1061,"sequence":141591,"symbol":"FCEU SI 20260615 PS"}
{"ts_recv":"2026-04-07T02:00:56.552602113Z","hd":{"ts_event":"2026-04-07T02:00:56.552581469Z","rtype":160,"publisher_id":101,"instrument_id":436},"action":"C","side":"B","price":"1.156590000","size":30,"channel_id":23,"order_id":"10998899292833329382","flags":0,"ts_in_delta":915,"sequence":141595,"symbol":"FCEU SI 20260615 PS"}
{"ts_recv":"2026-04-07T02:00:56.552602113Z","hd":{"ts_event":"2026-04-07T02:00:56.552581469Z","rtype":160,"publisher_id":101,"instrument_id":436},"action":"A","side":"B","price":"1.156610000","size":30,"channel_id":23,"order_id":"10998899293407363179","flags":0,"ts_in_delta":915,"sequence":141595,"symbol":"FCEU SI 20260615 PS"}
{"ts_recv":"2026-04-07T02:00:56.552602113Z","hd":{"ts_event":"2026-04-07T02:00:56.552581469Z","rtype":160,"publisher_id":101,"instrument_id":436},"action":"C","side":"A","price":"1.156690000","size":30,"channel_id":23,"order_id":"1775527255978553574","flags":0,"ts_in_delta":915,"sequence":141595,"symbol":"FCEU SI 20260615 PS"}
{"ts_recv":"2026-04-07T02:00:56.552602113Z","hd":{"ts_event":"2026-04-07T02:00:56.552581469Z","rtype":160,"publisher_id":101,"instrument_id":436},"action":"A","side":"A","price":"1.156710000","size":30,"channel_id":23,"order_id":"1775527256552587371","flags":128,"ts_in_delta":915,"sequence":141595,"symbol":"FCEU SI 20260615 PS"}
{"ts_recv":"2026-04-07T02:00:56.552663750Z","hd":{"ts_event":"2026-04-07T02:00:56.552645241Z","rtype":160,"publisher_id":101,"instrument_id":436},"action":"C","side":"B","price":"1.156600000","size":30,"channel_id":23,"order_id":"10998899293397738323","flags":0,"ts_in_delta":929,"sequence":141596,"symbol":"FCEU SI 20260615 PS"}
{"ts_recv":"2026-04-07T02:00:56.552663750Z","hd":{"ts_event":"2026-04-07T02:00:56.552645241Z","rtype":160,"publisher_id":101,"instrument_id":436},"action":"A","side":"B","price":"1.156610000","size":30,"channel_id":23,"order_id":"10998899293407426857","flags":0,"ts_in_delta":929,"sequence":141596,"symbol":"FCEU SI 20260615 PS"}
{"ts_recv":"2026-04-07T02:00:56.552663750Z","hd":{"ts_event":"2026-04-07T02:00:56.552645241Z","rtype":160,"publisher_id":101,"instrument_id":436},"action":"C","side":"A","price":"1.156700000","size":30,"channel_id":23,"order_id":"1775527256542962515","flags":0,"ts_in_delta":929,"sequence":141596,"symbol":"FCEU SI 20260615 PS"}
{"ts_recv":"2026-04-07T02:00:56.552663750Z","hd":{"ts_event":"2026-04-07T02:00:56.552645241Z","rtype":160,"publisher_id":101,"instrument_id":436},"action":"A","side":"A","price":"1.156710000","size":30,"channel_id":23,"order_id":"1775527256552651049","flags":128,"ts_in_delta":929,"sequence":141596,"symbol":"FCEU SI 20260615 PS"}
{"ts_recv":"2026-04-07T02:01:04.240659859Z","hd":{"ts_event":"2026-04-07T02:01:04.240638485Z","rtype":160,"publisher_id":101,"instrument_id":436},"action":"C","side":"B","price":"1.156610000","size":30,"channel_id":23,"order_id":"10998899293407426857","flags":0,"ts_in_delta":942,"sequence":141735,"symbol":"FCEU SI 20260615 PS"}
{"ts_recv":"2026-04-07T02:01:04.240659859Z","hd":{"ts_event":"2026-04-07T02:01:04.240638485Z","rtype":160,"publisher_id":101,"instrument_id":436},"action":"A","side":"B","price":"1.156600000","size":30,"channel_id":23,"order_id":"10998899301095420134","flags":0,"ts_in_delta":942,"sequence":141735,"symbol":"FCEU SI 20260615 PS"}
{"ts_recv":"2026-04-07T02:01:04.240659859Z","hd":{"ts_event":"2026-04-07T02:01:04.240638485Z","rtype":160,"publisher_id":101,"instrument_id":436},"action":"C","side":"A","price":"1.156710000","size":30,"channel_id":23,"order_id":"1775527256552651049","flags":0,"ts_in_delta":942,"sequence":141735,"symbol":"FCEU SI 20260615 PS"}
{"ts_recv":"2026-04-07T02:01:04.240659859Z","hd":{"ts_event":"2026-04-07T02:01:04.240638485Z","rtype":160,"publisher_id":101,"instrument_id":436},"action":"A","side":"A","price":"1.156700000","size":30,"channel_id":23,"order_id":"1775527264240644326","flags":128,"ts_in_delta":942,"sequence":141735,"symbol":"FCEU SI 20260615 PS"}
{"ts_recv":"2026-04-07T02:01:04.240714669Z","hd":{"ts_event":"2026-04-07T02:01:04.240695637Z","rtype":160,"publisher_id":101,"instrument_id":436},"action":"C","side":"B","price":"1.156610000","size":30,"channel_id":23,"order_id":"10998899293407363179","flags":0,"ts_in_delta":952,"sequence":141736,"symbol":"FCEU SI 20260615 PS"}
{"ts_recv":"2026-04-07T02:01:04.240714669Z","hd":{"ts_event":"2026-04-07T02:01:04.240695637Z","rtype":160,"publisher_id":101,"instrument_id":436},"action":"A","side":"B","price":"1.156590000","size":30,"channel_id":23,"order_id":"10998899301095477635","flags":0,"ts_in_delta":952,"sequence":141736,"symbol":"FCEU SI 20260615 PS"}
{"ts_recv":"2026-04-07T02:01:04.240714669Z","hd":{"ts_event":"2026-04-07T02:01:04.240695637Z","rtype":160,"publisher_id":101,"instrument_id":436},"action":"C","side":"A","price":"1.156710000","size":30,"channel_id":23,"order_id":"1775527256552587371","flags":0,"ts_in_delta":952,"sequence":141736,"symbol":"FCEU SI 20260615 PS"}
{"ts_recv":"2026-04-07T02:01:04.240714669Z","hd":{"ts_event":"2026-04-07T02:01:04.240695637Z","rtype":160,"publisher_id":101,"instrument_id":436},"action":"A","side":"A","price":"1.156690000","size":30,"channel_id":23,"order_id":"1775527264240701827","flags":128,"ts_in_delta":952,"sequence":141736,"symbol":"FCEU SI 20260615 PS"}
{"ts_recv":"2026-04-07T02:01:04.240766391Z","hd":{"ts_event":"2026-04-07T02:01:04.240750761Z","rtype":160,"publisher_id":101,"instrument_id":436},"action":"C","side":"B","price":"1.156600000","size":30,"channel_id":23,"order_id":"10998899301095420134","flags":0,"ts_in_delta":943,"sequence":141737,"symbol":"FCEU SI 20260615 PS"}
{"ts_recv":"2026-04-07T02:01:04.240766391Z","hd":{"ts_event":"2026-04-07T02:01:04.240750761Z","rtype":160,"publisher_id":101,"instrument_id":436},"action":"A","side":"B","price":"1.156590000","size":30,"channel_id":23,"order_id":"10998899301095532512","flags":0,"ts_in_delta":943,"sequence":141737,"symbol":"FCEU SI 20260615 PS"}
{"ts_recv":"2026-04-07T02:01:04.240766391Z","hd":{"ts_event":"2026-04-07T02:01:04.240750761Z","rtype":160,"publisher_id":101,"instrument_id":436},"action":"C","side":"A","price":"1.156700000","size":30,"channel_id":23,"order_id":"1775527264240644326","flags":0,"ts_in_delta":943,"sequence":141737,"symbol":"FCEU SI 20260615 PS"}
{"ts_recv":"2026-04-07T02:01:04.240766391Z","hd":{"ts_event":"2026-04-07T02:01:04.240750761Z","rtype":160,"publisher_id":101,"instrument_id":436},"action":"A","side":"A","price":"1.156690000","size":30,"channel_id":23,"order_id":"1775527264240756704","flags":128,"ts_in_delta":943,"sequence":141737,"symbol":"FCEU SI 20260615 PS"}
{"ts_recv":"2026-04-07T02:01:14.301622544Z","hd":{"ts_event":"2026-04-07T02:01:14.301600927Z","rtype":160,"publisher_id":101,"instrument_id":436},"action":"C","side":"B","price":"1.156590000","size":30,"channel_id":23,"order_id":"10998899301095532512","flags":0,"ts_in_delta":906,"sequence":141865,"symbol":"FCEU SI 20260615 PS"}
{"ts_recv":"2026-04-07T02:01:14.301622544Z","hd":{"ts_event":"2026-04-07T02:01:14.301600927Z","rtype":160,"publisher_id":101,"instrument_id":436},"action":"A","side":"B","price":"1.156600000","size":30,"channel_id":23,"order_id":"10998899311156382959","flags":0,"ts_in_delta":906,"sequence":141865,"symbol":"FCEU SI 20260615 PS"}
{"ts_recv":"2026-04-07T02:01:14.301622544Z","hd":{"ts_event":"2026-04-07T02:01:14.301600927Z","rtype":160,"publisher_id":101,"instrument_id":436},"action":"C","side":"A","price":"1.156690000","size":30,"channel_id":23,"order_id":"1775527264240756704","flags":0,"ts_in_delta":906,"sequence":141865,"symbol":"FCEU SI 20260615 PS"}
{"ts_recv":"2026-04-07T02:01:14.301622544Z","hd":{"ts_event":"2026-04-07T02:01:14.301600927Z","rtype":160,"publisher_id":101,"instrument_id":436},"action":"A","side":"A","price":"1.156700000","size":30,"channel_id":23,"order_id":"1775527274301607151","flags":128,"ts_in_delta":906,"sequence":141865,"symbol":"FCEU SI 20260615 PS"}
{"ts_recv":"2026-04-07T02:01:14.337033616Z","hd":{"ts_event":"2026-04-07T02:01:14.337014795Z","rtype":160,"publisher_id":101,"instrument_id":436},"action":"C","side":"B","price":"1.156590000","size":30,"channel_id":23,"order_id":"10998899301095477635","flags":0,"ts_in_delta":1084,"sequence":141868,"symbol":"FCEU SI 20260615 PS"}
{"ts_recv":"2026-04-07T02:01:14.337033616Z","hd":{"ts_event":"2026-04-07T02:01:14.337014795Z","rtype":160,"publisher_id":101,"instrument_id":436},"action":"A","side":"B","price":"1.156610000","size":30,"channel_id":23,"order_id":"10998899311191796599","flags":0,"ts_in_delta":1084,"sequence":141868,"symbol":"FCEU SI 20260615 PS"}
{"ts_recv":"2026-04-07T02:01:14.337033616Z","hd":{"ts_event":"2026-04-07T02:01:14.337014795Z","rtype":160,"publisher_id":101,"instrument_id":436},"action":"C","side":"A","price":"1.156690000","size":30,"channel_id":23,"order_id":"1775527264240701827","flags":0,"ts_in_delta":1084,"sequence":141868,"symbol":"FCEU SI 20260615 PS"}
{"ts_recv":"2026-04-07T02:01:14.337033616Z","hd":{"ts_event":"2026-04-07T02:01:14.337014795Z","rtype":160,"publisher_id":101,"instrument_id":436},"action":"A","side":"A","price":"1.156710000","size":30,"channel_id":23,"order_id":"1775527274337020791","flags":128,"ts_in_delta":1084,"sequence":141868,"symbol":"FCEU SI 20260615 PS"}
{"ts_recv":"2026-04-07T02:01:14.337101143Z","hd":{"ts_event":"2026-04-07T02:01:14.337081169Z","rtype":160,"publisher_id":101,"instrument_id":436},"action":"C","side":"B","price":"1.156600000","size":30,"channel_id":23,"order_id":"10998899311156382959","flags":0,"ts_in_delta":927,"sequence":141869,"symbol":"FCEU SI 20260615 PS"}
{"ts_recv":"2026-04-07T02:01:14.337101143Z","hd":{"ts_event":"2026-04-07T02:01:14.337081169Z","rtype":160,"publisher_id":101,"instrument_id":436},"action":"A","side":"B","price":"1.156610000","size":30,"channel_id":23,"order_id":"10998899311191863071","flags":0,"ts_in_delta":927,"sequence":141869,"symbol":"FCEU SI 20260615 PS"}
{"ts_recv":"2026-04-07T02:01:14.337101143Z","hd":{"ts_event":"2026-04-07T02:01:14.337081169Z","rtype":160,"publisher_id":101,"instrument_id":436},"action":"C","side":"A","price":"1.156700000","size":30,"channel_id":23,"order_id":"1775527274301607151","flags":0,"ts_in_delta":927,"sequence":141869,"symbol":"FCEU SI 20260615 PS"}
{"ts_recv":"2026-04-07T02:01:14.337101143Z","hd":{"ts_event":"2026-04-07T02:01:14.337081169Z","rtype":160,"publisher_id":101,"instrument_id":436},"action":"A","side":"A","price":"1.156710000","size":30,"channel_id":23,"order_id":"1775527274337087263","flags":128,"ts_in_delta":927,"sequence":141869,"symbol":"FCEU SI 20260615 PS"}
{"ts_recv":"2026-04-07T02:01:21.094250789Z","hd":{"ts_event":"2026-04-07T02:01:21.094217365Z","rtype":160,"publisher_id":101,"instrument_id":436},"action":"C","side":"B","price":"1.156610000","size":30,"channel_id":23,"order_id":"10998899311191863071","flags":0,"ts_in_delta":1688,"sequence":141943,"symbol":"FCEU SI 20260615 PS"}
{"ts_recv":"2026-04-07T02:01:21.094250789Z","hd":{"ts_event":"2026-04-07T02:01:21.094217365Z","rtype":160,"publisher_id":101,"instrument_id":436},"action":"A","side":"B","price":"1.156600000","size":30,"channel_id":23,"order_id":"10998899317949007027","flags":0,"ts_in_delta":1688,"sequence":141943,"symbol":"FCEU SI 20260615 PS"}
{"ts_recv":"2026-04-07T02:01:21.094250789Z","hd":{"ts_event":"2026-04-07T02:01:21.094217365Z","rtype":160,"publisher_id":101,"instrument_id":436},"action":"C","side":"A","price":"1.156710000","size":30,"channel_id":23,"order_id":"1775527274337087263","flags":0,"ts_in_delta":1688,"sequence":141943,"symbol":"FCEU SI 20260615 PS"}
{"ts_recv":"2026-04-07T02:01:21.094250789Z","hd":{"ts_event":"2026-04-07T02:01:21.094217365Z","rtype":160,"publisher_id":101,"instrument_id":436},"action":"A","side":"A","price":"1.156700000","size":30,"channel_id":23,"order_id":"1775527281094231219","flags":128,"ts_in_delta":1688,"sequence":141943,"symbol":"FCEU SI 20260615 PS"}
{"ts_recv":"2026-04-07T02:01:21.094344242Z","hd":{"ts_event":"2026-04-07T02:01:21.094326403Z","rtype":160,"publisher_id":101,"instrument_id":436},"action":"C","side":"B","price":"1.156600000","size":30,"channel_id":23,"order_id":"10998899317949007027","flags":0,"ts_in_delta":1024,"sequence":141944,"symbol":"FCEU SI 20260615 PS"}
{"ts_recv":"2026-04-07T02:01:21.094344242Z","hd":{"ts_event":"2026-04-07T02:01:21.094326403Z","rtype":160,"publisher_id":101,"instrument_id":436},"action":"A","side":"B","price":"1.156590000","size":30,"channel_id":23,"order_id":"10998899317949108382","flags":0,"ts_in_delta":1024,"sequence":141944,"symbol":"FCEU SI 20260615 PS"}
{"ts_recv":"2026-04-07T02:01:21.094344242Z","hd":{"ts_event":"2026-04-07T02:01:21.094326403Z","rtype":160,"publisher_id":101,"instrument_id":436},"action":"C","side":"A","price":"1.156700000","size":30,"channel_id":23,"order_id":"1775527281094231219","flags":0,"ts_in_delta":1024,"sequence":141944,"symbol":"FCEU SI 20260615 PS"}
{"ts_recv":"2026-04-07T02:01:21.094344242Z","hd":{"ts_event":"2026-04-07T02:01:21.094326403Z","rtype":160,"publisher_id":101,"instrument_id":436},"action":"A","side":"A","price":"1.156690000","size":30,"channel_id":23,"order_id":"1775527281094332574","flags":128,"ts_in_delta":1024,"sequence":141944,"symbol":"FCEU SI 20260615 PS"}
{"ts_recv":"2026-04-07T02:01:21.094404950Z","hd":{"ts_event":"2026-04-07T02:01:21.094384963Z","rtype":160,"publisher_id":101,"instrument_id":436},"action":"C","side":"B","price":"1.156610000","size":30,"channel_id":23,"order_id":"10998899311191796599","flags":0,"ts_in_delta":983,"sequence":141945,"symbol":"FCEU SI 20260615 PS"}
{"ts_recv":"2026-04-07T02:01:21.094404950Z","hd":{"ts_event":"2026-04-07T02:01:21.094384963Z","rtype":160,"publisher_id":101,"instrument_id":436},"action":"A","side":"B","price":"1.156590000","size":30,"channel_id":23,"order_id":"10998899317949166913","flags":0,"ts_in_delta":983,"sequence":141945,"symbol":"FCEU SI 20260615 PS"}
{"ts_recv":"2026-04-07T02:01:21.094404950Z","hd":{"ts_event":"2026-04-07T02:01:21.094384963Z","rtype":160,"publisher_id":101,"instrument_id":436},"action":"C","side":"A","price":"1.156710000","size":30,"channel_id":23,"order_id":"1775527274337020791","flags":0,"ts_in_delta":983,"sequence":141945,"symbol":"FCEU SI 20260615 PS"}
{"ts_recv":"2026-04-07T02:01:21.094404950Z","hd":{"ts_event":"2026-04-07T02:01:21.094384963Z","rtype":160,"publisher_id":101,"instrument_id":436},"action":"A","side":"A","price":"1.156690000","size":30,"channel_id":23,"order_id":"1775527281094391105","flags":128,"ts_in_delta":983,"sequence":141945,"symbol":"FCEU SI 20260615 PS"}
{"ts_recv":"2026-04-07T02:01:21.094414764Z","hd":{"ts_event":"2026-04-07T02:01:21.094396291Z","rtype":160,"publisher_id":101,"instrument_id":436},"action":"C","side":"B","price":"1.156590000","size":30,"channel_id":23,"order_id":"10998899317949108382","flags":0,"ts_in_delta":929,"sequence":141946,"symbol":"FCEU SI 20260615 PS"}
{"ts_recv":"2026-04-07T02:01:21.094414764Z","hd":{"ts_event":"2026-04-07T02:01:21.094396291Z","rtype":160,"publisher_id":101,"instrument_id":436},"action":"A","side":"B","price":"1.156600000","size":30,"channel_id":23,"order_id":"10998899317949177968","flags":0,"ts_in_delta":929,"sequence":141946,"symbol":"FCEU SI 20260615 PS"}
{"ts_recv":"2026-04-07T02:01:21.094414764Z","hd":{"ts_event":"2026-04-07T02:01:21.094396291Z","rtype":160,"publisher_id":101,"instrument_id":436},"action":"C","side":"A","price":"1.156690000","size":30,"channel_id":23,"order_id":"1775527281094332574","flags":0,"ts_in_delta":929,"sequence":141946,"symbol":"FCEU SI 20260615 PS"}
{"ts_recv":"2026-04-07T02:01:21.094414764Z","hd":{"ts_event":"2026-04-07T02:01:21.094396291Z","rtype":160,"publisher_id":101,"instrument_id":436},"action":"A","side":"A","price":"1.156700000","size":30,"channel_id":23,"order_id":"1775527281094402160","flags":128,"ts_in_delta":929,"sequence":141946,"symbol":"FCEU SI 20260615 PS"}
{"ts_recv":"2026-04-07T02:01:21.094473959Z","hd":{"ts_event":"2026-04-07T02:01:21.094454039Z","rtype":160,"publisher_id":101,"instrument_id":436},"action":"C","side":"B","price":"1.156600000","size":30,"channel_id":23,"order_id":"10998899317949177968","flags":0,"ts_in_delta":941,"sequence":141947,"symbol":"FCEU SI 20260615 PS"}
{"ts_recv":"2026-04-07T02:01:21.094473959Z","hd":{"ts_event":"2026-04-07T02:01:21.094454039Z","rtype":160,"publisher_id":101,"instrument_id":436},"action":"A","side":"B","price":"1.156590000","size":30,"channel_id":23,"order_id":"10998899317949236050","flags":0,"ts_in_delta":941,"sequence":141947,"symbol":"FCEU SI 20260615 PS"}
{"ts_recv":"2026-04-07T02:01:21.094473959Z","hd":{"ts_event":"2026-04-07T02:01:21.094454039Z","rtype":160,"publisher_id":101,"instrument_id":436},"action":"C","side":"A","price":"1.156700000","size":30,"channel_id":23,"order_id":"1775527281094402160","flags":0,"ts_in_delta":941,"sequence":141947,"symbol":"FCEU SI 20260615 PS"}
{"ts_recv":"2026-04-07T02:01:21.094473959Z","hd":{"ts_event":"2026-04-07T02:01:21.094454039Z","rtype":160,"publisher_id":101,"instrument_id":436},"action":"A","side":"A","price":"1.156690000","size":30,"channel_id":23,"order_id":"1775527281094460242","flags":128,"ts_in_delta":941,"sequence":141947,"symbol":"FCEU SI 20260615 PS"}
{"ts_recv":"2026-04-07T02:01:25.843493379Z","hd":{"ts_event":"2026-04-07T02:01:25.843473441Z","rtype":160,"publisher_id":101,"instrument_id":436},"action":"C","side":"B","price":"1.156590000","size":30,"channel_id":23,"order_id":"10998899317949236050","flags":0,"ts_in_delta":1100,"sequence":142024,"symbol":"FCEU SI 20260615 PS"}
{"ts_recv":"2026-04-07T02:01:25.843493379Z","hd":{"ts_event":"2026-04-07T02:01:25.843473441Z","rtype":160,"publisher_id":101,"instrument_id":436},"action":"A","side":"B","price":"1.156600000","size":30,"channel_id":23,"order_id":"10998899322698255190","flags":0,"ts_in_delta":1100,"sequence":142024,"symbol":"FCEU SI 20260615 PS"}
{"ts_recv":"2026-04-07T02:01:25.843493379Z","hd":{"ts_event":"2026-04-07T02:01:25.843473441Z","rtype":160,"publisher_id":101,"instrument_id":436},"action":"C","side":"A","price":"1.156690000","size":30,"channel_id":23,"order_id":"1775527281094460242","flags":0,"ts_in_delta":1100,"sequence":142024,"symbol":"FCEU SI 20260615 PS"}
{"ts_recv":"2026-04-07T02:01:25.843493379Z","hd":{"ts_event":"2026-04-07T02:01:25.843473441Z","rtype":160,"publisher_id":101,"instrument_id":436},"action":"A","side":"A","price":"1.156700000","size":30,"channel_id":23,"order_id":"1775527285843479382","flags":128,"ts_in_delta":1100,"sequence":142024,"symbol":"FCEU SI 20260615 PS"}
{"ts_recv":"2026-04-07T02:01:26.973152822Z","hd":{"ts_event":"2026-04-07T02:01:26.973135619Z","rtype":160,"publisher_id":101,"instrument_id":436},"action":"C","side":"B","price":"1.156600000","size":30,"channel_id":23,"order_id":"10998899322698255190","flags":0,"ts_in_delta":887,"sequence":142032,"symbol":"FCEU SI 20260615 PS"}
{"ts_recv":"2026-04-07T02:01:26.973152822Z","hd":{"ts_event":"2026-04-07T02:01:26.973135619Z","rtype":160,"publisher_id":101,"instrument_id":436},"action":"A","side":"B","price":"1.156590000","size":30,"channel_id":23,"order_id":"10998899323827917291","flags":0,"ts_in_delta":887,"sequence":142032,"symbol":"FCEU SI 20260615 PS"}
{"ts_recv":"2026-04-07T02:01:26.973152822Z","hd":{"ts_event":"2026-04-07T02:01:26.973135619Z","rtype":160,"publisher_id":101,"instrument_id":436},"action":"C","side":"A","price":"1.156700000","size":30,"channel_id":23,"order_id":"1775527285843479382","flags":0,"ts_in_delta":887,"sequence":142032,"symbol":"FCEU SI 20260615 PS"}
{"ts_recv":"2026-04-07T02:01:26.973152822Z","hd":{"ts_event":"2026-04-07T02:01:26.973135619Z","rtype":160,"publisher_id":101,"instrument_id":436},"action":"A","side":"A","price":"1.156690000","size":30,"channel_id":23,"order_id":"1775527286973141483","flags":128,"ts_in_delta":887,"sequence":142032,"symbol":"FCEU SI 20260615 PS"}
{"ts_recv":"2026-04-07T02:01:29.299006826Z","hd":{"ts_event":"2026-04-07T02:01:29.298987759Z","rtype":160,"publisher_id":101,"instrument_id":436},"action":"C","side":"B","price":"1.156590000","size":30,"channel_id":23,"order_id":"10998899323827917291","flags":0,"ts_in_delta":881,"sequence":142053,"symbol":"FCEU SI 20260615 PS"}
{"ts_recv":"2026-04-07T02:01:29.299006826Z","hd":{"ts_event":"2026-04-07T02:01:29.298987759Z","rtype":160,"publisher_id":101,"instrument_id":436},"action":"A","side":"B","price":"1.156580000","size":30,"channel_id":23,"order_id":"10998899326153769713","flags":0,"ts_in_delta":881,"sequence":142053,"symbol":"FCEU SI 20260615 PS"}
{"ts_recv":"2026-04-07T02:01:29.299006826Z","hd":{"ts_event":"2026-04-07T02:01:29.298987759Z","rtype":160,"publisher_id":101,"instrument_id":436},"action":"C","side":"A","price":"1.156690000","size":30,"channel_id":23,"order_id":"1775527286973141483","flags":0,"ts_in_delta":881,"sequence":142053,"symbol":"FCEU SI 20260615 PS"}
{"ts_recv":"2026-04-07T02:01:29.299006826Z","hd":{"ts_event":"2026-04-07T02:01:29.298987759Z","rtype":160,"publisher_id":101,"instrument_id":436},"action":"A","side":"A","price":"1.156680000","size":30,"channel_id":23,"order_id":"1775527289298993905","flags":128,"ts_in_delta":881,"sequence":142053,"symbol":"FCEU SI 20260615 PS"}
{"ts_recv":"2026-04-07T02:01:29.299062104Z","hd":{"ts_event":"2026-04-07T02:01:29.299040059Z","rtype":160,"publisher_id":101,"instrument_id":436},"action":"C","side":"B","price":"1.156590000","size":30,"channel_id":23,"order_id":"10998899317949166913","flags":0,"ts_in_delta":885,"sequence":142054,"symbol":"FCEU SI 20260615 PS"}
{"ts_recv":"2026-04-07T02:01:29.299062104Z","hd":{"ts_event":"2026-04-07T02:01:29.299040059Z","rtype":160,"publisher_id":101,"instrument_id":436},"action":"A","side":"B","price":"1.156570000","size":30,"channel_id":23,"order_id":"10998899326153822121","flags":0,"ts_in_delta":885,"sequence":142054,"symbol":"FCEU SI 20260615 PS"}
{"ts_recv":"2026-04-07T02:01:29.299062104Z","hd":{"ts_event":"2026-04-07T02:01:29.299040059Z","rtype":160,"publisher_id":101,"instrument_id":436},"action":"C","side":"A","price":"1.156690000","size":30,"channel_id":23,"order_id":"1775527281094391105","flags":0,"ts_in_delta":885,"sequence":142054,"symbol":"FCEU SI 20260615 PS"}
{"ts_recv":"2026-04-07T02:01:29.299062104Z","hd":{"ts_event":"2026-04-07T02:01:29.299040059Z","rtype":160,"publisher_id":101,"instrument_id":436},"action":"A","side":"A","price":"1.156670000","size":30,"channel_id":23,"order_id":"1775527289299046313","flags":128,"ts_in_delta":885,"sequence":142054,"symbol":"FCEU SI 20260615 PS"}
{"ts_recv":"2026-04-07T02:01:29.299116890Z","hd":{"ts_event":"2026-04-07T02:01:29.299100143Z","rtype":160,"publisher_id":101,"instrument_id":436},"action":"C","side":"B","price":"1.156580000","size":30,"channel_id":23,"order_id":"10998899326153769713","flags":0,"ts_in_delta":902,"sequence":142055,"symbol":"FCEU SI 20260615 PS"}
{"ts_recv":"2026-04-07T02:01:29.299116890Z","hd":{"ts_event":"2026-04-07T02:01:29.299100143Z","rtype":160,"publisher_id":101,"instrument_id":436},"action":"A","side":"B","price":"1.156570000","size":30,"channel_id":23,"order_id":"10998899326153881641","flags":0,"ts_in_delta":902,"sequence":142055,"symbol":"FCEU SI 20260615 PS"}
{"ts_recv":"2026-04-07T02:01:29.299116890Z","hd":{"ts_event":"2026-04-07T02:01:29.299100143Z","rtype":160,"publisher_id":101,"instrument_id":436},"action":"C","side":"A","price":"1.156680000","size":30,"channel_id":23,"order_id":"1775527289298993905","flags":0,"ts_in_delta":902,"sequence":142055,"symbol":"FCEU SI 20260615 PS"}
{"ts_recv":"2026-04-07T02:01:29.299116890Z","hd":{"ts_event":"2026-04-07T02:01:29.299100143Z","rtype":160,"publisher_id":101,"instrument_id":436},"action":"A","side":"A","price":"1.156670000","size":30,"channel_id":23,"order_id":"1775527289299105833","flags":128,"ts_in_delta":902,"sequence":142055,"symbol":"FCEU SI 20260615 PS"}
{"ts_recv":"2026-04-07T02:01:31.823170243Z","hd":{"ts_event":"2026-04-07T02:01:31.823149145Z","rtype":160,"publisher_id":101,"instrument_id":436},"action":"C","side":"B","price":"1.156570000","size":30,"channel_id":23,"order_id":"10998899326153881641","flags":0,"ts_in_delta":1389,"sequence":142121,"symbol":"FCEU SI 20260615 PS"}
{"ts_recv":"2026-04-07T02:01:31.823170243Z","hd":{"ts_event":"2026-04-07T02:01:31.823149145Z","rtype":160,"publisher_id":101,"instrument_id":436},"action":"A","side":"B","price":"1.156580000","size":30,"channel_id":23,"order_id":"10998899328677931425","flags":0,"ts_in_delta":1389,"sequence":142121,"symbol":"FCEU SI 20260615 PS"}
{"ts_recv":"2026-04-07T02:01:31.823170243Z","hd":{"ts_event":"2026-04-07T02:01:31.823149145Z","rtype":160,"publisher_id":101,"instrument_id":436},"action":"C","side":"A","price":"1.156670000","size":30,"channel_id":23,"order_id":"1775527289299105833","flags":0,"ts_in_delta":1389,"sequence":142121,"symbol":"FCEU SI 20260615 PS"}
{"ts_recv":"2026-04-07T02:01:31.823170243Z","hd":{"ts_event":"2026-04-07T02:01:31.823149145Z","rtype":160,"publisher_id":101,"instrument_id":436},"action":"A","side":"A","price":"1.156680000","size":30,"channel_id":23,"order_id":"1775527291823155617","flags":128,"ts_in_delta":1389,"sequence":142121,"symbol":"FCEU SI 20260615 PS"}
{"ts_recv":"2026-04-07T02:01:34.830726976Z","hd":{"ts_event":"2026-04-07T02:01:34.830706331Z","rtype":160,"publisher_id":101,"instrument_id":436},"action":"C","side":"B","price":"1.156570000","size":30,"channel_id":23,"order_id":"10998899326153822121","flags":0,"ts_in_delta":943,"sequence":142169,"symbol":"FCEU SI 20260615 PS"}
{"ts_recv":"2026-04-07T02:01:34.830726976Z","hd":{"ts_event":"2026-04-07T02:01:34.830706331Z","rtype":160,"publisher_id":101,"instrument_id":436},"action":"A","side":"B","price":"1.156590000","size":30,"channel_id":23,"order_id":"10998899331685488194","flags":0,"ts_in_delta":943,"sequence":142169,"symbol":"FCEU SI 20260615 PS"}
{"ts_recv":"2026-04-07T02:01:34.830726976Z","hd":{"ts_event":"2026-04-07T02:01:34.830706331Z","rtype":160,"publisher_id":101,"instrument_id":436},"action":"C","side":"A","price":"1.156670000","size":30,"channel_id":23,"order_id":"1775527289299046313","flags":0,"ts_in_delta":943,"sequence":142169,"symbol":"FCEU SI 20260615 PS"}
{"ts_recv":"2026-04-07T02:01:34.830726976Z","hd":{"ts_event":"2026-04-07T02:01:34.830706331Z","rtype":160,"publisher_id":101,"instrument_id":436},"action":"A","side":"A","price":"1.156690000","size":30,"channel_id":23,"order_id":"1775527294830712386","flags":128,"ts_in_delta":943,"sequence":142169,"symbol":"FCEU SI 20260615 PS"}
{"ts_recv":"2026-04-07T02:01:34.830832195Z","hd":{"ts_event":"2026-04-07T02:01:34.830813795Z","rtype":160,"publisher_id":101,"instrument_id":436},"action":"C","side":"B","price":"1.156580000","size":30,"channel_id":23,"order_id":"10998899328677931425","flags":0,"ts_in_delta":949,"sequence":142170,"symbol":"FCEU SI 20260615 PS"}
{"ts_recv":"2026-04-07T02:01:34.830832195Z","hd":{"ts_event":"2026-04-07T02:01:34.830813795Z","rtype":160,"publisher_id":101,"instrument_id":436},"action":"A","side":"B","price":"1.156590000","size":30,"channel_id":23,"order_id":"10998899331685595802","flags":0,"ts_in_delta":949,"sequence":142170,"symbol":"FCEU SI 20260615 PS"}
{"ts_recv":"2026-04-07T02:01:34.830832195Z","hd":{"ts_event":"2026-04-07T02:01:34.830813795Z","rtype":160,"publisher_id":101,"instrument_id":436},"action":"C","side":"A","price":"1.156680000","size":30,"channel_id":23,"order_id":"1775527291823155617","flags":0,"ts_in_delta":949,"sequence":142170,"symbol":"FCEU SI 20260615 PS"}
{"ts_recv":"2026-04-07T02:01:34.830832195Z","hd":{"ts_event":"2026-04-07T02:01:34.830813795Z","rtype":160,"publisher_id":101,"instrument_id":436},"action":"A","side":"A","price":"1.156690000","size":30,"channel_id":23,"order_id":"1775527294830819994","flags":128,"ts_in_delta":949,"sequence":142170,"symbol":"FCEU SI 20260615 PS"}
{"ts_recv":"2026-04-07T02:01:34.848256278Z","hd":{"ts_event":"2026-04-07T02:01:34.848238045Z","rtype":160,"publisher_id":101,"instrument_id":436},"action":"C","side":"B","price":"1.156590000","size":30,"channel_id":23,"order_id":"10998899331685595802","flags":0,"ts_in_delta":955,"sequence":142172,"symbol":"FCEU SI 20260615 PS"}
{"ts_recv":"2026-04-07T02:01:34.848256278Z","hd":{"ts_event":"2026-04-07T02:01:34.848238045Z","rtype":160,"publisher_id":101,"instrument_id":436},"action":"A","side":"B","price":"1.156580000","size":30,"channel_id":23,"order_id":"10998899331703020092","flags":0,"ts_in_delta":955,"sequence":142172,"symbol":"FCEU SI 20260615 PS"}
{"ts_recv":"2026-04-07T02:01:34.848256278Z","hd":{"ts_event":"2026-04-07T02:01:34.848238045Z","rtype":160,"publisher_id":101,"instrument_id":436},"action":"C","side":"A","price":"1.156690000","size":30,"channel_id":23,"order_id":"1775527294830819994","flags":0,"ts_in_delta":955,"sequence":142172,"symbol":"FCEU SI 20260615 PS"}
{"ts_recv":"2026-04-07T02:01:34.848256278Z","hd":{"ts_event":"2026-04-07T02:01:34.848238045Z","rtype":160,"publisher_id":101,"instrument_id":436},"action":"A","side":"A","price":"1.156680000","size":30,"channel_id":23,"order_id":"1775527294848244284","flags":128,"ts_in_delta":955,"sequence":142172,"symbol":"FCEU SI 20260615 PS"}
{"ts_recv":"2026-04-07T02:01:35.060908928Z","hd":{"ts_event":"2026-04-07T02:01:35.060891035Z","rtype":160,"publisher_id":101,"instrument_id":436},"action":"C","side":"B","price":"1.156580000","size":30,"channel_id":23,"order_id":"10998899331703020092","flags":0,"ts_in_delta":1074,"sequence":142187,"symbol":"FCEU SI 20260615 PS"}
{"ts_recv":"2026-04-07T02:01:35.060908928Z","hd":{"ts_event":"2026-04-07T02:01:35.060891035Z","rtype":160,"publisher_id":101,"instrument_id":436},"action":"A","side":"B","price":"1.156590000","size":30,"channel_id":23,"order_id":"10998899331915672783","flags":0,"ts_in_delta":1074,"sequence":142187,"symbol":"FCEU SI 20260615 PS"}
{"ts_recv":"2026-04-07T02:01:35.060908928Z","hd":{"ts_event":"2026-04-07T02:01:35.060891035Z","rtype":160,"publisher_id":101,"instrument_id":436},"action":"C","side":"A","price":"1.156680000","size":30,"channel_id":23,"order_id":"1775527294848244284","flags":0,"ts_in_delta":1074,"sequence":142187,"symbol":"FCEU SI 20260615 PS"}
{"ts_recv":"2026-04-07T02:01:35.060908928Z","hd":{"ts_event":"2026-04-07T02:01:35.060891035Z","rtype":160,"publisher_id":101,"instrument_id":436},"action":"A","side":"A","price":"1.156690000","size":30,"channel_id":23,"order_id":"1775527295060896975","flags":128,"ts_in_delta":1074,"sequence":142187,"symbol":"FCEU SI 20260615 PS"}
{"ts_recv":"2026-04-07T02:01:51.741239658Z","hd":{"ts_event":"2026-04-07T02:01:51.741217145Z","rtype":160,"publisher_id":101,"instrument_id":436},"action":"C","side":"B","price":"1.156590000","size":30,"channel_id":23,"order_id":"10998899331915672783","flags":0,"ts_in_delta":1105,"sequence":142328,"symbol":"FCEU SI 20260615 PS"}
{"ts_recv":"2026-04-07T02:01:51.741239658Z","hd":{"ts_event":"2026-04-07T02:01:51.741217145Z","rtype":160,"publisher_id":101,"instrument_id":436},"action":"A","side":"B","price":"1.156580000","size":30,"channel_id":23,"order_id":"10998899348595999085","flags":0,"ts_in_delta":1105,"sequence":142328,"symbol":"FCEU SI 20260615 PS"}
{"ts_recv":"2026-04-07T02:01:51.741239658Z","hd":{"ts_event":"2026-04-07T02:01:51.741217145Z","rtype":160,"publisher_id":101,"instrument_id":436},"action":"C","side":"A","price":"1.156690000","size":30,"channel_id":23,"order_id":"1775527295060896975","flags":0,"ts_in_delta":1105,"sequence":142328,"symbol":"FCEU SI 20260615 PS"}
{"ts_recv":"2026-04-07T02:01:51.741239658Z","hd":{"ts_event":"2026-04-07T02:01:51.741217145Z","rtype":160,"publisher_id":101,"instrument_id":436},"action":"A","side":"A","price":"1.156680000","size":30,"channel_id":23,"order_id":"1775527311741223277","flags":128,"ts_in_delta":1105,"sequence":142328,"symbol":"FCEU SI 20260615 PS"}
{"ts_recv":"2026-04-07T02:01:51.741300980Z","hd":{"ts_event":"2026-04-07T02:01:51.741278951Z","rtype":160,"publisher_id":101,"instrument_id":436},"action":"C","side":"B","price":"1.156590000","size":30,"channel_id":23,"order_id":"10998899331685488194","flags":0,"ts_in_delta":884,"sequence":142329,"symbol":"FCEU SI 20260615 PS"}
{"ts_recv":"2026-04-07T02:01:51.741300980Z","hd":{"ts_event":"2026-04-07T02:01:51.741278951Z","rtype":160,"publisher_id":101,"instrument_id":436},"action":"A","side":"B","price":"1.156570000","size":30,"channel_id":23,"order_id":"10998899348596061325","flags":0,"ts_in_delta":884,"sequence":142329,"symbol":"FCEU SI 20260615 PS"}
{"ts_recv":"2026-04-07T02:01:51.741300980Z","hd":{"ts_event":"2026-04-07T02:01:51.741278951Z","rtype":160,"publisher_id":101,"instrument_id":436},"action":"C","side":"A","price":"1.156690000","size":30,"channel_id":23,"order_id":"1775527294830712386","flags":0,"ts_in_delta":884,"sequence":142329,"symbol":"FCEU SI 20260615 PS"}
{"ts_recv":"2026-04-07T02:01:51.741300980Z","hd":{"ts_event":"2026-04-07T02:01:51.741278951Z","rtype":160,"publisher_id":101,"instrument_id":436},"action":"A","side":"A","price":"1.156670000","size":30,"channel_id":23,"order_id":"1775527311741285517","flags":128,"ts_in_delta":884,"sequence":142329,"symbol":"FCEU SI 20260615 PS"}
{"ts_recv":"2026-04-07T02:01:51.741354238Z","hd":{"ts_event":"2026-04-07T02:01:51.741338297Z","rtype":160,"publisher_id":101,"instrument_id":436},"action":"C","side":"B","price":"1.156580000","size":30,"channel_id":23,"order_id":"10998899348595999085","flags":0,"ts_in_delta":1039,"sequence":142330,"symbol":"FCEU SI 20260615 PS"}
{"ts_recv":"2026-04-07T02:01:51.741354238Z","hd":{"ts_event":"2026-04-07T02:01:51.741338297Z","rtype":160,"publisher_id":101,"instrument_id":436},"action":"A","side":"B","price":"1.156570000","size":30,"channel_id":23,"order_id":"10998899348596119857","flags":0,"ts_in_delta":1039,"sequence":142330,"symbol":"FCEU SI 20260615 PS"}
{"ts_recv":"2026-04-07T02:01:51.741354238Z","hd":{"ts_event":"2026-04-07T02:01:51.741338297Z","rtype":160,"publisher_id":101,"instrument_id":436},"action":"C","side":"A","price":"1.156680000","size":30,"channel_id":23,"order_id":"1775527311741223277","flags":0,"ts_in_delta":1039,"sequence":142330,"symbol":"FCEU SI 20260615 PS"}
{"ts_recv":"2026-04-07T02:01:51.741354238Z","hd":{"ts_event":"2026-04-07T02:01:51.741338297Z","rtype":160,"publisher_id":101,"instrument_id":436},"action":"A","side":"A","price":"1.156670000","size":30,"channel_id":23,"order_id":"1775527311741344049","flags":128,"ts_in_delta":1039,"sequence":142330,"symbol":"FCEU SI 20260615 PS"}
{"ts_recv":"2026-04-07T02:01:51.755732489Z","hd":{"ts_event":"2026-04-07T02:01:51.755711619Z","rtype":160,"publisher_id":101,"instrument_id":436},"action":"C","side":"B","price":"1.156570000","size":30,"channel_id":23,"order_id":"10998899348596119857","flags":0,"ts_in_delta":897,"sequence":142339,"symbol":"FCEU SI 20260615 PS"}
{"ts_recv":"2026-04-07T02:01:51.755732489Z","hd":{"ts_event":"2026-04-07T02:01:51.755711619Z","rtype":160,"publisher_id":101,"instrument_id":436},"action":"A","side":"B","price":"1.156560000","size":30,"channel_id":23,"order_id":"10998899348610494036","flags":0,"ts_in_delta":897,"sequence":142339,"symbol":"FCEU SI 20260615 PS"}
{"ts_recv":"2026-04-07T02:01:51.755732489Z","hd":{"ts_event":"2026-04-07T02:01:51.755711619Z","rtype":160,"publisher_id":101,"instrument_id":436},"action":"C","side":"A","price":"1.156670000","size":30,"channel_id":23,"order_id":"1775527311741344049","flags":0,"ts_in_delta":897,"sequence":142339,"symbol":"FCEU SI 20260615 PS"}
{"ts_recv":"2026-04-07T02:01:51.755732489Z","hd":{"ts_event":"2026-04-07T02:01:51.755711619Z","rtype":160,"publisher_id":101,"instrument_id":436},"action":"A","side":"A","price":"1.156660000","size":30,"channel_id":23,"order_id":"1775527311755718228","flags":128,"ts_in_delta":897,"sequence":142339,"symbol":"FCEU SI 20260615 PS"}
{"ts_recv":"2026-04-07T02:01:51.971044616Z","hd":{"ts_event":"2026-04-07T02:01:51.971020429Z","rtype":160,"publisher_id":101,"instrument_id":436},"action":"C","side":"B","price":"1.156570000","size":30,"channel_id":23,"order_id":"10998899348596061325","flags":0,"ts_in_delta":1237,"sequence":142360,"symbol":"FCEU SI 20260615 PS"}
{"ts_recv":"2026-04-07T02:01:51.971044616Z","hd":{"ts_event":"2026-04-07T02:01:51.971020429Z","rtype":160,"publisher_id":101,"instrument_id":436},"action":"A","side":"B","price":"1.156550000","size":30,"channel_id":23,"order_id":"10998899348825802354","flags":0,"ts_in_delta":1237,"sequence":142360,"symbol":"FCEU SI 20260615 PS"}
{"ts_recv":"2026-04-07T02:01:51.971044616Z","hd":{"ts_event":"2026-04-07T02:01:51.971020429Z","rtype":160,"publisher_id":101,"instrument_id":436},"action":"C","side":"A","price":"1.156670000","size":30,"channel_id":23,"order_id":"1775527311741285517","flags":0,"ts_in_delta":1237,"sequence":142360,"symbol":"FCEU SI 20260615 PS"}
{"ts_recv":"2026-04-07T02:01:51.971044616Z","hd":{"ts_event":"2026-04-07T02:01:51.971020429Z","rtype":160,"publisher_id":101,"instrument_id":436},"action":"A","side":"A","price":"1.156650000","size":30,"channel_id":23,"order_id":"1775527311971026546","flags":128,"ts_in_delta":1237,"sequence":142360,"symbol":"FCEU SI 20260615 PS"}
{"ts_recv":"2026-04-07T02:01:51.971107719Z","hd":{"ts_event":"2026-04-07T02:01:51.971090261Z","rtype":160,"publisher_id":101,"instrument_id":436},"action":"C","side":"B","price":"1.156560000","size":30,"channel_id":23,"order_id":"10998899348610494036","flags":0,"ts_in_delta":1088,"sequence":142361,"symbol":"FCEU SI 20260615 PS"}
{"ts_recv":"2026-04-07T02:01:51.971107719Z","hd":{"ts_event":"2026-04-07T02:01:51.971090261Z","rtype":160,"publisher_id":101,"instrument_id":436},"action":"A","side":"B","price":"1.156550000","size":30,"channel_id":23,"order_id":"10998899348825872139","flags":0,"ts_in_delta":1088,"sequence":142361,"symbol":"FCEU SI 20260615 PS"}
{"ts_recv":"2026-04-07T02:01:51.971107719Z","hd":{"ts_event":"2026-04-07T02:01:51.971090261Z","rtype":160,"publisher_id":101,"instrument_id":436},"action":"C","side":"A","price":"1.156660000","size":30,"channel_id":23,"order_id":"1775527311755718228","flags":0,"ts_in_delta":1088,"sequence":142361,"symbol":"FCEU SI 20260615 PS"}
{"ts_recv":"2026-04-07T02:01:51.971107719Z","hd":{"ts_event":"2026-04-07T02:01:51.971090261Z","rtype":160,"publisher_id":101,"instrument_id":436},"action":"A","side":"A","price":"1.156650000","size":30,"channel_id":23,"order_id":"1775527311971096331","flags":128,"ts_in_delta":1088,"sequence":142361,"symbol":"FCEU SI 20260615 PS"}
{"ts_recv":"2026-04-07T02:01:52.322271224Z","hd":{"ts_event":"2026-04-07T02:01:52.322255707Z","rtype":160,"publisher_id":101,"instrument_id":436},"action":"A","side":"A","price":"1.156800000","size":20,"channel_id":23,"order_id":"1775527312322261988","flags":128,"ts_in_delta":714,"sequence":142378,"symbol":"FCEU SI 20260615 PS"}
{"ts_recv":"2026-04-07T02:01:52.322306989Z","hd":{"ts_event":"2026-04-07T02:01:52.322294537Z","rtype":160,"publisher_id":101,"instrument_id":436},"action":"C","side":"A","price":"1.156900000","size":20,"channel_id":23,"order_id":"1775527082430313364","flags":128,"ts_in_delta":690,"sequence":142379,"symbol":"FCEU SI 20260615 PS"}
{"ts_recv":"2026-04-07T02:01:56.306117268Z","hd":{"ts_event":"2026-04-07T02:01:56.306097043Z","rtype":160,"publisher_id":101,"instrument_id":436},"action":"C","side":"B","price":"1.156550000","size":30,"channel_id":23,"order_id":"10998899348825872139","flags":0,"ts_in_delta":886,"sequence":142463,"symbol":"FCEU SI 20260615 PS"}
{"ts_recv":"2026-04-07T02:01:56.306117268Z","hd":{"ts_event":"2026-04-07T02:01:56.306097043Z","rtype":160,"publisher_id":101,"instrument_id":436},"action":"A","side":"B","price":"1.156540000","size":30,"channel_id":23,"order_id":"10998899353160878801","flags":0,"ts_in_delta":886,"sequence":142463,"symbol":"FCEU SI 20260615 PS"}
{"ts_recv":"2026-04-07T02:01:56.306117268Z","hd":{"ts_event":"2026-04-07T02:01:56.306097043Z","rtype":160,"publisher_id":101,"instrument_id":436},"action":"C","side":"A","price":"1.156650000","size":30,"channel_id":23,"order_id":"1775527311971096331","flags":0,"ts_in_delta":886,"sequence":142463,"symbol":"FCEU SI 20260615 PS"}
{"ts_recv":"2026-04-07T02:01:56.306117268Z","hd":{"ts_event":"2026-04-07T02:01:56.306097043Z","rtype":160,"publisher_id":101,"instrument_id":436},"action":"A","side":"A","price":"1.156640000","size":30,"channel_id":23,"order_id":"1775527316306102993","flags":128,"ts_in_delta":886,"sequence":142463,"symbol":"FCEU SI 20260615 PS"}
{"ts_recv":"2026-04-07T02:01:56.306204493Z","hd":{"ts_event":"2026-04-07T02:01:56.306182675Z","rtype":160,"publisher_id":101,"instrument_id":436},"action":"C","side":"B","price":"1.156540000","size":30,"channel_id":23,"order_id":"10998899353160878801","flags":0,"ts_in_delta":861,"sequence":142464,"symbol":"FCEU SI 20260615 PS"}
{"ts_recv":"2026-04-07T02:01:56.306204493Z","hd":{"ts_event":"2026-04-07T02:01:56.306182675Z","rtype":160,"publisher_id":101,"instrument_id":436},"action":"A","side":"B","price":"1.156530000","size":30,"channel_id":23,"order_id":"10998899353160964849","flags":0,"ts_in_delta":861,"sequence":142464,"symbol":"FCEU SI 20260615 PS"}
{"ts_recv":"2026-04-07T02:01:56.306204493Z","hd":{"ts_event":"2026-04-07T02:01:56.306182675Z","rtype":160,"publisher_id":101,"instrument_id":436},"action":"C","side":"A","price":"1.156640000","size":30,"channel_id":23,"order_id":"1775527316306102993","flags":0,"ts_in_delta":861,"sequence":142464,"symbol":"FCEU SI 20260615 PS"}
{"ts_recv":"2026-04-07T02:01:56.306204493Z","hd":{"ts_event":"2026-04-07T02:01:56.306182675Z","rtype":160,"publisher_id":101,"instrument_id":436},"action":"A","side":"A","price":"1.156630000","size":30,"channel_id":23,"order_id":"1775527316306189041","flags":128,"ts_in_delta":861,"sequence":142464,"symbol":"FCEU SI 20260615 PS"}
{"ts_recv":"2026-04-07T02:01:56.306263450Z","hd":{"ts_event":"2026-04-07T02:01:56.306244633Z","rtype":160,"publisher_id":101,"instrument_id":436},"action":"C","side":"B","price":"1.156530000","size":30,"channel_id":23,"order_id":"10998899353160964849","flags":0,"ts_in_delta":947,"sequence":142465,"symbol":"FCEU SI 20260615 PS"}
{"ts_recv":"2026-04-07T02:01:56.306263450Z","hd":{"ts_event":"2026-04-07T02:01:56.306244633Z","rtype":160,"publisher_id":101,"instrument_id":436},"action":"A","side":"B","price":"1.156540000","size":30,"channel_id":23,"order_id":"10998899353161026657","flags":0,"ts_in_delta":947,"sequence":142465,"symbol":"FCEU SI 20260615 PS"}
{"ts_recv":"2026-04-07T02:01:56.306263450Z","hd":{"ts_event":"2026-04-07T02:01:56.306244633Z","rtype":160,"publisher_id":101,"instrument_id":436},"action":"C","side":"A","price":"1.156630000","size":30,"channel_id":23,"order_id":"1775527316306189041","flags":0,"ts_in_delta":947,"sequence":142465,"symbol":"FCEU SI 20260615 PS"}
{"ts_recv":"2026-04-07T02:01:56.306263450Z","hd":{"ts_event":"2026-04-07T02:01:56.306244633Z","rtype":160,"publisher_id":101,"instrument_id":436},"action":"A","side":"A","price":"1.156640000","size":30,"channel_id":23,"order_id":"1775527316306250849","flags":128,"ts_in_delta":947,"sequence":142465,"symbol":"FCEU SI 20260615 PS"}
{"ts_recv":"2026-04-07T02:01:56.306287464Z","hd":{"ts_event":"2026-04-07T02:01:56.306268077Z","rtype":160,"publisher_id":101,"instrument_id":436},"action":"C","side":"B","price":"1.156550000","size":30,"channel_id":23,"order_id":"10998899348825802354","flags":0,"ts_in_delta":1088,"sequence":142466,"symbol":"FCEU SI 20260615 PS"}
{"ts_recv":"2026-04-07T02:01:56.306287464Z","hd":{"ts_event":"2026-04-07T02:01:56.306268077Z","rtype":160,"publisher_id":101,"instrument_id":436},"action":"A","side":"B","price":"1.156530000","size":30,"channel_id":23,"order_id":"10998899353161049988","flags":0,"ts_in_delta":1088,"sequence":142466,"symbol":"FCEU SI 20260615 PS"}
{"ts_recv":"2026-04-07T02:01:56.306287464Z","hd":{"ts_event":"2026-04-07T02:01:56.306268077Z","rtype":160,"publisher_id":101,"instrument_id":436},"action":"C","side":"A","price":"1.156650000","size":30,"channel_id":23,"order_id":"1775527311971026546","flags":0,"ts_in_delta":1088,"sequence":142466,"symbol":"FCEU SI 20260615 PS"}
{"ts_recv":"2026-04-07T02:01:56.306287464Z","hd":{"ts_event":"2026-04-07T02:01:56.306268077Z","rtype":160,"publisher_id":101,"instrument_id":436},"action":"A","side":"A","price":"1.156630000","size":30,"channel_id":23,"order_id":"1775527316306274180","flags":128,"ts_in_delta":1088,"sequence":142466,"symbol":"FCEU SI 20260615 PS"}
{"ts_recv":"2026-04-07T02:01:56.306345414Z","hd":{"ts_event":"2026-04-07T02:01:56.306327251Z","rtype":160,"publisher_id":101,"instrument_id":436},"action":"C","side":"B","price":"1.156540000","size":30,"channel_id":23,"order_id":"10998899353161026657","flags":0,"ts_in_delta":940,"sequence":142467,"symbol":"FCEU SI 20260615 PS"}
{"ts_recv":"2026-04-07T02:01:56.306345414Z","hd":{"ts_event":"2026-04-07T02:01:56.306327251Z","rtype":160,"publisher_id":101,"instrument_id":436},"action":"A","side":"B","price":"1.156530000","size":30,"channel_id":23,"order_id":"10998899353161108911","flags":0,"ts_in_delta":940,"sequence":142467,"symbol":"FCEU SI 20260615 PS"}
{"ts_recv":"2026-04-07T02:01:56.306345414Z","hd":{"ts_event":"2026-04-07T02:01:56.306327251Z","rtype":160,"publisher_id":101,"instrument_id":436},"action":"C","side":"A","price":"1.156640000","size":30,"channel_id":23,"order_id":"1775527316306250849","flags":0,"ts_in_delta":940,"sequence":142467,"symbol":"FCEU SI 20260615 PS"}
{"ts_recv":"2026-04-07T02:01:56.306345414Z","hd":{"ts_event":"2026-04-07T02:01:56.306327251Z","rtype":160,"publisher_id":101,"instrument_id":436},"action":"A","side":"A","price":"1.156630000","size":30,"channel_id":23,"order_id":"1775527316306333103","flags":128,"ts_in_delta":940,"sequence":142467,"symbol":"FCEU SI 20260615 PS"}
{"ts_recv":"2026-04-07T02:01:56.333405744Z","hd":{"ts_event":"2026-04-07T02:01:56.333387119Z","rtype":160,"publisher_id":101,"instrument_id":436},"action":"C","side":"B","price":"1.156530000","size":30,"channel_id":23,"order_id":"10998899353161108911","flags":0,"ts_in_delta":949,"sequence":142470,"symbol":"FCEU SI 20260615 PS"}
{"ts_recv":"2026-04-07T02:01:56.333405744Z","hd":{"ts_event":"2026-04-07T02:01:56.333387119Z","rtype":160,"publisher_id":101,"instrument_id":436},"action":"A","side":"B","price":"1.156540000","size":30,"channel_id":23,"order_id":"10998899353188168729","flags":0,"ts_in_delta":949,"sequence":142470,"symbol":"FCEU SI 20260615 PS"}
{"ts_recv":"2026-04-07T02:01:56.333405744Z","hd":{"ts_event":"2026-04-07T02:01:56.333387119Z","rtype":160,"publisher_id":101,"instrument_id":436},"action":"C","side":"A","price":"1.156630000","size":30,"channel_id":23,"order_id":"1775527316306333103","flags":0,"ts_in_delta":949,"sequence":142470,"symbol":"FCEU SI 20260615 PS"}
{"ts_recv":"2026-04-07T02:01:56.333405744Z","hd":{"ts_event":"2026-04-07T02:01:56.333387119Z","rtype":160,"publisher_id":101,"instrument_id":436},"action":"A","side":"A","price":"1.156640000","size":30,"channel_id":23,"order_id":"1775527316333392921","flags":128,"ts_in_delta":949,"sequence":142470,"symbol":"FCEU SI 20260615 PS"}
{"ts_recv":"2026-04-07T02:01:57.053222662Z","hd":{"ts_event":"2026-04-07T02:01:57.053204675Z","rtype":160,"publisher_id":101,"instrument_id":436},"action":"C","side":"B","price":"1.156540000","size":30,"channel_id":23,"order_id":"10998899353188168729","flags":0,"ts_in_delta":956,"sequence":142478,"symbol":"FCEU SI 20260615 PS"}
{"ts_recv":"2026-04-07T02:01:57.053222662Z","hd":{"ts_event":"2026-04-07T02:01:57.053204675Z","rtype":160,"publisher_id":101,"instrument_id":436},"action":"A","side":"B","price":"1.156560000","size":30,"channel_id":23,"order_id":"10998899353907986445","flags":0,"ts_in_delta":956,"sequence":142478,"symbol":"FCEU SI 20260615 PS"}
{"ts_recv":"2026-04-07T02:01:57.053222662Z","hd":{"ts_event":"2026-04-07T02:01:57.053204675Z","rtype":160,"publisher_id":101,"instrument_id":436},"action":"C","side":"A","price":"1.156640000","size":30,"channel_id":23,"order_id":"1775527316333392921","flags":0,"ts_in_delta":956,"sequence":142478,"symbol":"FCEU SI 20260615 PS"}
{"ts_recv":"2026-04-07T02:01:57.053222662Z","hd":{"ts_event":"2026-04-07T02:01:57.053204675Z","rtype":160,"publisher_id":101,"instrument_id":436},"action":"A","side":"A","price":"1.156660000","size":30,"channel_id":23,"order_id":"1775527317053210637","flags":128,"ts_in_delta":956,"sequence":142478,"symbol":"FCEU SI 20260615 PS"}
{"ts_recv":"2026-04-07T02:01:57.053290964Z","hd":{"ts_event":"2026-04-07T02:01:57.053273719Z","rtype":160,"publisher_id":101,"instrument_id":436},"action":"C","side":"B","price":"1.156530000","size":30,"channel_id":23,"order_id":"10998899353161049988","flags":0,"ts_in_delta":866,"sequence":142479,"symbol":"FCEU SI 20260615 PS"}
{"ts_recv":"2026-04-07T02:01:57.053290964Z","hd":{"ts_event":"2026-04-07T02:01:57.053273719Z","rtype":160,"publisher_id":101,"instrument_id":436},"action":"A","side":"B","price":"1.156550000","size":30,"channel_id":23,"order_id":"10998899353908055374","flags":0,"ts_in_delta":866,"sequence":142479,"symbol":"FCEU SI 20260615 PS"}
{"ts_recv":"2026-04-07T02:01:57.053290964Z","hd":{"ts_event":"2026-04-07T02:01:57.053273719Z","rtype":160,"publisher_id":101,"instrument_id":436},"action":"C","side":"A","price":"1.156630000","size":30,"channel_id":23,"order_id":"1775527316306274180","flags":0,"ts_in_delta":866,"sequence":142479,"symbol":"FCEU SI 20260615 PS"}
{"ts_recv":"2026-04-07T02:01:57.053290964Z","hd":{"ts_event":"2026-04-07T02:01:57.053273719Z","rtype":160,"publisher_id":101,"instrument_id":436},"action":"A","side":"A","price":"1.156650000","size":30,"channel_id":23,"order_id":"1775527317053279566","flags":128,"ts_in_delta":866,"sequence":142479,"symbol":"FCEU SI 20260615 PS"}
{"ts_recv":"2026-04-07T02:01:57.053303498Z","hd":{"ts_event":"2026-04-07T02:01:57.053284549Z","rtype":160,"publisher_id":101,"instrument_id":436},"action":"C","side":"B","price":"1.156560000","size":30,"channel_id":23,"order_id":"10998899353907986445","flags":0,"ts_in_delta":935,"sequence":142480,"symbol":"FCEU SI 20260615 PS"}
{"ts_recv":"2026-04-07T02:01:57.053303498Z","hd":{"ts_event":"2026-04-07T02:01:57.053284549Z","rtype":160,"publisher_id":101,"instrument_id":436},"action":"A","side":"B","price":"1.156540000","size":30,"channel_id":23,"order_id":"10998899353908066078","flags":0,"ts_in_delta":935,"sequence":142480,"symbol":"FCEU SI 20260615 PS"}
{"ts_recv":"2026-04-07T02:01:57.053303498Z","hd":{"ts_event":"2026-04-07T02:01:57.053284549Z","rtype":160,"publisher_id":101,"instrument_id":436},"action":"C","side":"A","price":"1.156660000","size":30,"channel_id":23,"order_id":"1775527317053210637","flags":0,"ts_in_delta":935,"sequence":142480,"symbol":"FCEU SI 20260615 PS"}
{"ts_recv":"2026-04-07T02:01:57.053303498Z","hd":{"ts_event":"2026-04-07T02:01:57.053284549Z","rtype":160,"publisher_id":101,"instrument_id":436},"action":"A","side":"A","price":"1.156640000","size":30,"channel_id":23,"order_id":"1775527317053290270","flags":128,"ts_in_delta":935,"sequence":142480,"symbol":"FCEU SI 20260615 PS"}
{"ts_recv":"2026-04-07T02:01:57.053358399Z","hd":{"ts_event":"2026-04-07T02:01:57.053341265Z","rtype":160,"publisher_id":101,"instrument_id":436},"action":"C","side":"B","price":"1.156540000","size":30,"channel_id":23,"order_id":"10998899353908066078","flags":0,"ts_in_delta":988,"sequence":142481,"symbol":"FCEU SI 20260615 PS"}
{"ts_recv":"2026-04-07T02:01:57.053358399Z","hd":{"ts_event":"2026-04-07T02:01:57.053341265Z","rtype":160,"publisher_id":101,"instrument_id":436},"action":"A","side":"B","price":"1.156550000","size":30,"channel_id":23,"order_id":"10998899353908122962","flags":0,"ts_in_delta":988,"sequence":142481,"symbol":"FCEU SI 20260615 PS"}
{"ts_recv":"2026-04-07T02:01:57.053358399Z","hd":{"ts_event":"2026-04-07T02:01:57.053341265Z","rtype":160,"publisher_id":101,"instrument_id":436},"action":"C","side":"A","price":"1.156640000","size":30,"channel_id":23,"order_id":"1775527317053290270","flags":0,"ts_in_delta":988,"sequence":142481,"symbol":"FCEU SI 20260615 PS"}
{"ts_recv":"2026-04-07T02:01:57.053358399Z","hd":{"ts_event":"2026-04-07T02:01:57.053341265Z","rtype":160,"publisher_id":101,"instrument_id":436},"action":"A","side":"A","price":"1.156650000","size":30,"channel_id":23,"order_id":"1775527317053347154","flags":128,"ts_in_delta":988,"sequence":142481,"symbol":"FCEU SI 20260615 PS"}
{"ts_recv":"2026-04-07T02:01:58.698253838Z","hd":{"ts_event":"2026-04-07T02:01:58.698234625Z","rtype":160,"publisher_id":101,"instrument_id":436},"action":"C","side":"B","price":"1.156550000","size":30,"channel_id":23,"order_id":"10998899353908122962","flags":0,"ts_in_delta":756,"sequence":142508,"symbol":"FCEU SI 20260615 PS"}
{"ts_recv":"2026-04-07T02:01:58.698253838Z","hd":{"ts_event":"2026-04-07T02:01:58.698234625Z","rtype":160,"publisher_id":101,"instrument_id":436},"action":"A","side":"B","price":"1.156560000","size":30,"channel_id":23,"order_id":"10998899355553016425","flags":0,"ts_in_delta":756,"sequence":142508,"symbol":"FCEU SI 20260615 PS"}
{"ts_recv":"2026-04-07T02:01:58.698253838Z","hd":{"ts_event":"2026-04-07T02:01:58.698234625Z","rtype":160,"publisher_id":101,"instrument_id":436},"action":"C","side":"A","price":"1.156650000","size":30,"channel_id":23,"order_id":"1775527317053347154","flags":0,"ts_in_delta":756,"sequence":142508,"symbol":"FCEU SI 20260615 PS"}
{"ts_recv":"2026-04-07T02:01:58.698253838Z","hd":{"ts_event":"2026-04-07T02:01:58.698234625Z","rtype":160,"publisher_id":101,"instrument_id":436},"action":"A","side":"A","price":"1.156660000","size":30,"channel_id":23,"order_id":"1775527318698240617","flags":128,"ts_in_delta":756,"sequence":142508,"symbol":"FCEU SI 20260615 PS"}
{"ts_recv":"2026-04-07T02:01:58.698325773Z","hd":{"ts_event":"2026-04-07T02:01:58.698306969Z","rtype":160,"publisher_id":101,"instrument_id":436},"action":"C","side":"B","price":"1.156560000","size":30,"channel_id":23,"order_id":"10998899355553016425","flags":0,"ts_in_delta":729,"sequence":142509,"symbol":"FCEU SI 20260615 PS"}
{"ts_recv":"2026-04-07T02:01:58.698325773Z","hd":{"ts_event":"2026-04-07T02:01:58.698306969Z","rtype":160,"publisher_id":101,"instrument_id":436},"action":"A","side":"B","price":"1.156570000","size":30,"channel_id":23,"order_id":"10998899355553088579","flags":0,"ts_in_delta":729,"sequence":142509,"symbol":"FCEU SI 20260615 PS"}
{"ts_recv":"2026-04-07T02:01:58.698325773Z","hd":{"ts_event":"2026-04-07T02:01:58.698306969Z","rtype":160,"publisher_id":101,"instrument_id":436},"action":"C","side":"A","price":"1.156660000","size":30,"channel_id":23,"order_id":"1775527318698240617","flags":0,"ts_in_delta":729,"sequence":142509,"symbol":"FCEU SI 20260615 PS"}
{"ts_recv":"2026-04-07T02:01:58.698325773Z","hd":{"ts_event":"2026-04-07T02:01:58.698306969Z","rtype":160,"publisher_id":101,"instrument_id":436},"action":"A","side":"A","price":"1.156670000","size":30,"channel_id":23,"order_id":"1775527318698312771","flags":128,"ts_in_delta":729,"sequence":142509,"symbol":"FCEU SI 20260615 PS"}
{"ts_recv":"2026-04-07T02:01:58.698380844Z","hd":{"ts_event":"2026-04-07T02:01:58.698364301Z","rtype":160,"publisher_id":101,"instrument_id":436},"action":"C","side":"B","price":"1.156570000","size":30,"channel_id":23,"order_id":"10998899355553088579","flags":0,"ts_in_delta":758,"sequence":142510,"symbol":"FCEU SI 20260615 PS"}
{"ts_recv":"2026-04-07T02:01:58.698380844Z","hd":{"ts_event":"2026-04-07T02:01:58.698364301Z","rtype":160,"publisher_id":101,"instrument_id":436},"action":"A","side":"B","price":"1.156560000","size":30,"channel_id":23,"order_id":"10998899355553145962","flags":0,"ts_in_delta":758,"sequence":142510,"symbol":"FCEU SI 20260615 PS"}
{"ts_recv":"2026-04-07T02:01:58.698380844Z","hd":{"ts_event":"2026-04-07T02:01:58.698364301Z","rtype":160,"publisher_id":101,"instrument_id":436},"action":"C","side":"A","price":"1.156670000","size":30,"channel_id":23,"order_id":"1775527318698312771","flags":0,"ts_in_delta":758,"sequence":142510,"symbol":"FCEU SI 20260615 PS"}
{"ts_recv":"2026-04-07T02:01:58.698380844Z","hd":{"ts_event":"2026-04-07T02:01:58.698364301Z","rtype":160,"publisher_id":101,"instrument_id":436},"action":"A","side":"A","price":"1.156660000","size":30,"channel_id":23,"order_id":"1775527318698370154","flags":128,"ts_in_delta":758,"sequence":142510,"symbol":"FCEU SI 20260615 PS"}
{"ts_recv":"2026-04-07T02:01:58.698402662Z","hd":{"ts_event":"2026-04-07T02:01:58.698380967Z","rtype":160,"publisher_id":101,"instrument_id":436},"action":"C","side":"B","price":"1.156550000","size":30,"channel_id":23,"order_id":"10998899353908055374","flags":0,"ts_in_delta":742,"sequence":142511,"symbol":"FCEU SI 20260615 PS"}
{"ts_recv":"2026-04-07T02:01:58.698402662Z","hd":{"ts_event":"2026-04-07T02:01:58.698380967Z","rtype":160,"publisher_id":101,"instrument_id":436},"action":"A","side":"B","price":"1.156570000","size":30,"channel_id":23,"order_id":"10998899355553166749","flags":0,"ts_in_delta":742,"sequence":142511,"symbol":"FCEU SI 20260615 PS"}
{"ts_recv":"2026-04-07T02:01:58.698402662Z","hd":{"ts_event":"2026-04-07T02:01:58.698380967Z","rtype":160,"publisher_id":101,"instrument_id":436},"action":"C","side":"A","price":"1.156650000","size":30,"channel_id":23,"order_id":"1775527317053279566","flags":0,"ts_in_delta":742,"sequence":142511,"symbol":"FCEU SI 20260615 PS"}
{"ts_recv":"2026-04-07T02:01:58.698402662Z","hd":{"ts_event":"2026-04-07T02:01:58.698380967Z","rtype":160,"publisher_id":101,"instrument_id":436},"action":"A","side":"A","price":"1.156670000","size":30,"channel_id":23,"order_id":"1775527318698390941","flags":128,"ts_in_delta":742,"sequence":142511,"symbol":"FCEU SI 20260615 PS"}
{"ts_recv":"2026-04-07T02:01:58.698458447Z","hd":{"ts_event":"2026-04-07T02:01:58.698440987Z","rtype":160,"publisher_id":101,"instrument_id":436},"action":"C","side":"B","price":"1.156560000","size":30,"channel_id":23,"order_id":"10998899355553145962","flags":0,"ts_in_delta":935,"sequence":142512,"symbol":"FCEU SI 20260615 PS"}
{"ts_recv":"2026-04-07T02:01:58.698458447Z","hd":{"ts_event":"2026-04-07T02:01:58.698440987Z","rtype":160,"publisher_id":101,"instrument_id":436},"action":"A","side":"B","price":"1.156570000","size":30,"channel_id":23,"order_id":"10998899355553222830","flags":0,"ts_in_delta":935,"sequence":142512,"symbol":"FCEU SI 20260615 PS"}
{"ts_recv":"2026-04-07T02:01:58.698458447Z","hd":{"ts_event":"2026-04-07T02:01:58.698440987Z","rtype":160,"publisher_id":101,"instrument_id":436},"action":"C","side":"A","price":"1.156660000","size":30,"channel_id":23,"order_id":"1775527318698370154","flags":0,"ts_in_delta":935,"sequence":142512,"symbol":"FCEU SI 20260615 PS"}
{"ts_recv":"2026-04-07T02:01:58.698458447Z","hd":{"ts_event":"2026-04-07T02:01:58.698440987Z","rtype":160,"publisher_id":101,"instrument_id":436},"action":"A","side":"A","price":"1.156670000","size":30,"channel_id":23,"order_id":"1775527318698447022","flags":128,"ts_in_delta":935,"sequence":142512,"symbol":"FCEU SI 20260615 PS"}
{"ts_recv":"2026-04-07T02:02:03.676517261Z","hd":{"ts_event":"2026-04-07T02:02:03.676484189Z","rtype":160,"publisher_id":101,"instrument_id":436},"action":"C","side":"B","price":"1.156570000","size":30,"channel_id":23,"order_id":"10998899355553222830","flags":0,"ts_in_delta":2052,"sequence":142549,"symbol":"FCEU SI 20260615 PS"}
{"ts_recv":"2026-04-07T02:02:03.676517261Z","hd":{"ts_event":"2026-04-07T02:02:03.676484189Z","rtype":160,"publisher_id":101,"instrument_id":436},"action":"A","side":"B","price":"1.156580000","size":30,"channel_id":23,"order_id":"10998899360531273321","flags":0,"ts_in_delta":2052,"sequence":142549,"symbol":"FCEU SI 20260615 PS"}
{"ts_recv":"2026-04-07T02:02:03.676517261Z","hd":{"ts_event":"2026-04-07T02:02:03.676484189Z","rtype":160,"publisher_id":101,"instrument_id":436},"action":"C","side":"A","price":"1.156670000","size":30,"channel_id":23,"order_id":"1775527318698447022","flags":0,"ts_in_delta":2052,"sequence":142549,"symbol":"FCEU SI 20260615 PS"}
{"ts_recv":"2026-04-07T02:02:03.676517261Z","hd":{"ts_event":"2026-04-07T02:02:03.676484189Z","rtype":160,"publisher_id":101,"instrument_id":436},"action":"A","side":"A","price":"1.156680000","size":30,"channel_id":23,"order_id":"1775527323676497513","flags":128,"ts_in_delta":2052,"sequence":142549,"symbol":"FCEU SI 20260615 PS"}
{"ts_recv":"2026-04-07T02:02:07.585842680Z","hd":{"ts_event":"2026-04-07T02:02:07.585822057Z","rtype":160,"publisher_id":101,"instrument_id":436},"action":"C","side":"B","price":"1.156580000","size":30,"channel_id":23,"order_id":"10998899360531273321","flags":0,"ts_in_delta":906,"sequence":142619,"symbol":"FCEU SI 20260615 PS"}
{"ts_recv":"2026-04-07T02:02:07.585842680Z","hd":{"ts_event":"2026-04-07T02:02:07.585822057Z","rtype":160,"publisher_id":101,"instrument_id":436},"action":"A","side":"B","price":"1.156590000","size":30,"channel_id":23,"order_id":"10998899364440603863","flags":0,"ts_in_delta":906,"sequence":142619,"symbol":"FCEU SI 20260615 PS"}
{"ts_recv":"2026-04-07T02:02:07.585842680Z","hd":{"ts_event":"2026-04-07T02:02:07.585822057Z","rtype":160,"publisher_id":101,"instrument_id":436},"action":"C","side":"A","price":"1.156680000","size":30,"channel_id":23,"order_id":"1775527323676497513","flags":0,"ts_in_delta":906,"sequence":142619,"symbol":"FCEU SI 20260615 PS"}
{"ts_recv":"2026-04-07T02:02:07.585842680Z","hd":{"ts_event":"2026-04-07T02:02:07.585822057Z","rtype":160,"publisher_id":101,"instrument_id":436},"action":"A","side":"A","price":"1.156690000","size":30,"channel_id":23,"order_id":"1775527327585828055","flags":128,"ts_in_delta":906,"sequence":142619,"symbol":"FCEU SI 20260615 PS"}
{"ts_recv":"2026-04-07T02:02:07.585900001Z","hd":{"ts_event":"2026-04-07T02:02:07.585880563Z","rtype":160,"publisher_id":101,"instrument_id":436},"action":"C","side":"B","price":"1.156570000","size":30,"channel_id":23,"order_id":"10998899355553166749","flags":0,"ts_in_delta":919,"sequence":142620,"symbol":"FCEU SI 20260615 PS"}
{"ts_recv":"2026-04-07T02:02:07.585900001Z","hd":{"ts_event":"2026-04-07T02:02:07.585880563Z","rtype":160,"publisher_id":101,"instrument_id":436},"action":"A","side":"B","price":"1.156590000","size":30,"channel_id":23,"order_id":"10998899364440662571","flags":0,"ts_in_delta":919,"sequence":142620,"symbol":"FCEU SI 20260615 PS"}
{"ts_recv":"2026-04-07T02:02:07.585900001Z","hd":{"ts_event":"2026-04-07T02:02:07.585880563Z","rtype":160,"publisher_id":101,"instrument_id":436},"action":"C","side":"A","price":"1.156670000","size":30,"channel_id":23,"order_id":"1775527318698390941","flags":0,"ts_in_delta":919,"sequence":142620,"symbol":"FCEU SI 20260615 PS"}
{"ts_recv":"2026-04-07T02:02:07.585900001Z","hd":{"ts_event":"2026-04-07T02:02:07.585880563Z","rtype":160,"publisher_id":101,"instrument_id":436},"action":"A","side":"A","price":"1.156690000","size":30,"channel_id":23,"order_id":"1775527327585886763","flags":128,"ts_in_delta":919,"sequence":142620,"symbol":"FCEU SI 20260615 PS"}
{"ts_recv":"2026-04-07T02:02:19.063446001Z","hd":{"ts_event":"2026-04-07T02:02:19.063422365Z","rtype":160,"publisher_id":101,"instrument_id":436},"action":"C","side":"B","price":"1.156590000","size":30,"channel_id":23,"order_id":"10998899364440603863","flags":0,"ts_in_delta":927,"sequence":142787,"symbol":"FCEU SI 20260615 PS"}
{"ts_recv":"2026-04-07T02:02:19.063446001Z","hd":{"ts_event":"2026-04-07T02:02:19.063422365Z","rtype":160,"publisher_id":101,"instrument_id":436},"action":"A","side":"B","price":"1.156600000","size":30,"channel_id":23,"order_id":"10998899375918204220","flags":0,"ts_in_delta":927,"sequence":142787,"symbol":"FCEU SI 20260615 PS"}
{"ts_recv":"2026-04-07T02:02:19.063446001Z","hd":{"ts_event":"2026-04-07T02:02:19.063422365Z","rtype":160,"publisher_id":101,"instrument_id":436},"action":"C","side":"A","price":"1.156690000","size":30,"channel_id":23,"order_id":"1775527327585828055","flags":0,"ts_in_delta":927,"sequence":142787,"symbol":"FCEU SI 20260615 PS"}
{"ts_recv":"2026-04-07T02:02:19.063446001Z","hd":{"ts_event":"2026-04-07T02:02:19.063422365Z","rtype":160,"publisher_id":101,"instrument_id":436},"action":"A","side":"A","price":"1.156700000","size":30,"channel_id":23,"order_id":"1775527339063428412","flags":128,"ts_in_delta":927,"sequence":142787,"symbol":"FCEU SI 20260615 PS"}
{"ts_recv":"2026-04-07T02:02:25.650798660Z","hd":{"ts_event":"2026-04-07T02:02:25.650770369Z","rtype":160,"publisher_id":101,"instrument_id":436},"action":"C","side":"B","price":"1.156600000","size":30,"channel_id":23,"order_id":"10998899375918204220","flags":0,"ts_in_delta":1283,"sequence":142849,"symbol":"FCEU SI 20260615 PS"}
{"ts_recv":"2026-04-07T02:02:25.650798660Z","hd":{"ts_event":"2026-04-07T02:02:25.650770369Z","rtype":160,"publisher_id":101,"instrument_id":436},"action":"A","side":"B","price":"1.156590000","size":30,"channel_id":23,"order_id":"10998899382505557461","flags":0,"ts_in_delta":1283,"sequence":142849,"symbol":"FCEU SI 20260615 PS"}
{"ts_recv":"2026-04-07T02:02:25.650798660Z","hd":{"ts_event":"2026-04-07T02:02:25.650770369Z","rtype":160,"publisher_id":101,"instrument_id":436},"action":"C","side":"A","price":"1.156700000","size":30,"channel_id":23,"order_id":"1775527339063428412","flags":0,"ts_in_delta":1283,"sequence":142849,"symbol":"FCEU SI 20260615 PS"}
{"ts_recv":"2026-04-07T02:02:25.650798660Z","hd":{"ts_event":"2026-04-07T02:02:25.650770369Z","rtype":160,"publisher_id":101,"instrument_id":436},"action":"A","side":"A","price":"1.156690000","size":30,"channel_id":23,"order_id":"1775527345650781653","flags":128,"ts_in_delta":1283,"sequence":142849,"symbol":"FCEU SI 20260615 PS"}
{"ts_recv":"2026-04-07T02:02:36.879833171Z","hd":{"ts_event":"2026-04-07T02:02:36.879810807Z","rtype":160,"publisher_id":101,"instrument_id":436},"action":"C","side":"B","price":"1.156590000","size":30,"channel_id":23,"order_id":"10998899382505557461","flags":0,"ts_in_delta":931,"sequence":142958,"symbol":"FCEU SI 20260615 PS"}
{"ts_recv":"2026-04-07T02:02:36.879833171Z","hd":{"ts_event":"2026-04-07T02:02:36.879810807Z","rtype":160,"publisher_id":101,"instrument_id":436},"action":"A","side":"B","price":"1.156600000","size":30,"channel_id":23,"order_id":"10998899393734592981","flags":0,"ts_in_delta":931,"sequence":142958,"symbol":"FCEU SI 20260615 PS"}
{"ts_recv":"2026-04-07T02:02:36.879833171Z","hd":{"ts_event":"2026-04-07T02:02:36.879810807Z","rtype":160,"publisher_id":101,"instrument_id":436},"action":"C","side":"A","price":"1.156690000","size":30,"channel_id":23,"order_id":"1775527345650781653","flags":0,"ts_in_delta":931,"sequence":142958,"symbol":"FCEU SI 20260615 PS"}
{"ts_recv":"2026-04-07T02:02:36.879833171Z","hd":{"ts_event":"2026-04-07T02:02:36.879810807Z","rtype":160,"publisher_id":101,"instrument_id":436},"action":"A","side":"A","price":"1.156700000","size":30,"channel_id":23,"order_id":"1775527356879817173","flags":128,"ts_in_delta":931,"sequence":142958,"symbol":"FCEU SI 20260615 PS"}
{"ts_recv":"2026-04-07T02:02:36.890676994Z","hd":{"ts_event":"2026-04-07T02:02:36.890653293Z","rtype":160,"publisher_id":101,"instrument_id":436},"action":"C","side":"B","price":"1.156590000","size":30,"channel_id":23,"order_id":"10998899364440662571","flags":0,"ts_in_delta":929,"sequence":142959,"symbol":"FCEU SI 20260615 PS"}
{"ts_recv":"2026-04-07T02:02:36.890676994Z","hd":{"ts_event":"2026-04-07T02:02:36.890653293Z","rtype":160,"publisher_id":101,"instrument_id":436},"action":"A","side":"B","price":"1.156610000","size":30,"channel_id":23,"order_id":"10998899393745435492","flags":0,"ts_in_delta":929,"sequence":142959,"symbol":"FCEU SI 20260615 PS"}
{"ts_recv":"2026-04-07T02:02:36.890676994Z","hd":{"ts_event":"2026-04-07T02:02:36.890653293Z","rtype":160,"publisher_id":101,"instrument_id":436},"action":"C","side":"A","price":"1.156690000","size":30,"channel_id":23,"order_id":"1775527327585886763","flags":0,"ts_in_delta":929,"sequence":142959,"symbol":"FCEU SI 20260615 PS"}
{"ts_recv":"2026-04-07T02:02:36.890676994Z","hd":{"ts_event":"2026-04-07T02:02:36.890653293Z","rtype":160,"publisher_id":101,"instrument_id":436},"action":"A","side":"A","price":"1.156710000","size":30,"channel_id":23,"order_id":"1775527356890659684","flags":128,"ts_in_delta":929,"sequence":142959,"symbol":"FCEU SI 20260615 PS"}
{"ts_recv":"2026-04-07T02:02:36.890744844Z","hd":{"ts_event":"2026-04-07T02:02:36.890728537Z","rtype":160,"publisher_id":101,"instrument_id":436},"action":"C","side":"B","price":"1.156600000","size":30,"channel_id":23,"order_id":"10998899393734592981","flags":0,"ts_in_delta":900,"sequence":142960,"symbol":"FCEU SI 20260615 PS"}
{"ts_recv":"2026-04-07T02:02:36.890744844Z","hd":{"ts_event":"2026-04-07T02:02:36.890728537Z","rtype":160,"publisher_id":101,"instrument_id":436},"action":"A","side":"B","price":"1.156610000","size":30,"channel_id":23,"order_id":"10998899393745510358","flags":0,"ts_in_delta":900,"sequence":142960,"symbol":"FCEU SI 20260615 PS"}
{"ts_recv":"2026-04-07T02:02:36.890744844Z","hd":{"ts_event":"2026-04-07T02:02:36.890728537Z","rtype":160,"publisher_id":101,"instrument_id":436},"action":"C","side":"A","price":"1.156700000","size":30,"channel_id":23,"order_id":"1775527356879817173","flags":0,"ts_in_delta":900,"sequence":142960,"symbol":"FCEU SI 20260615 PS"}
{"ts_recv":"2026-04-07T02:02:36.890744844Z","hd":{"ts_event":"2026-04-07T02:02:36.890728537Z","rtype":160,"publisher_id":101,"instrument_id":436},"action":"A","side":"A","price":"1.156710000","size":30,"channel_id":23,"order_id":"1775527356890734550","flags":128,"ts_in_delta":900,"sequence":142960,"symbol":"FCEU SI 20260615 PS"}
{"ts_recv":"2026-04-07T02:02:38.705728542Z","hd":{"ts_event":"2026-04-07T02:02:38.705708399Z","rtype":160,"publisher_id":101,"instrument_id":436},"action":"C","side":"B","price":"1.156610000","size":30,"channel_id":23,"order_id":"10998899393745510358","flags":0,"ts_in_delta":1023,"sequence":142999,"symbol":"FCEU SI 20260615 PS"}
{"ts_recv":"2026-04-07T02:02:38.705728542Z","hd":{"ts_event":"2026-04-07T02:02:38.705708399Z","rtype":160,"publisher_id":101,"instrument_id":436},"action":"A","side":"B","price":"1.156620000","size":30,"channel_id":23,"order_id":"10998899395560490348","flags":0,"ts_in_delta":1023,"sequence":142999,"symbol":"FCEU SI 20260615 PS"}
{"ts_recv":"2026-04-07T02:02:38.705728542Z","hd":{"ts_event":"2026-04-07T02:02:38.705708399Z","rtype":160,"publisher_id":101,"instrument_id":436},"action":"C","side":"A","price":"1.156710000","size":30,"channel_id":23,"order_id":"1775527356890734550","flags":0,"ts_in_delta":1023,"sequence":142999,"symbol":"FCEU SI 20260615 PS"}
{"ts_recv":"2026-04-07T02:02:38.705728542Z","hd":{"ts_event":"2026-04-07T02:02:38.705708399Z","rtype":160,"publisher_id":101,"instrument_id":436},"action":"A","side":"A","price":"1.156720000","size":30,"channel_id":23,"order_id":"1775527358705714540","flags":128,"ts_in_delta":1023,"sequence":142999,"symbol":"FCEU SI 20260615 PS"}
{"ts_recv":"2026-04-07T02:02:38.770954494Z","hd":{"ts_event":"2026-04-07T02:02:38.770935529Z","rtype":160,"publisher_id":101,"instrument_id":436},"action":"C","side":"B","price":"1.156610000","size":30,"channel_id":23,"order_id":"10998899393745435492","flags":0,"ts_in_delta":921,"sequence":143002,"symbol":"FCEU SI 20260615 PS"}
{"ts_recv":"2026-04-07T02:02:38.770954494Z","hd":{"ts_event":"2026-04-07T02:02:38.770935529Z","rtype":160,"publisher_id":101,"instrument_id":436},"action":"A","side":"B","price":"1.156630000","size":30,"channel_id":23,"order_id":"10998899395625717471","flags":0,"ts_in_delta":921,"sequence":143002,"symbol":"FCEU SI 20260615 PS"}
{"ts_recv":"2026-04-07T02:02:38.770954494Z","hd":{"ts_event":"2026-04-07T02:02:38.770935529Z","rtype":160,"publisher_id":101,"instrument_id":436},"action":"C","side":"A","price":"1.156710000","size":30,"channel_id":23,"order_id":"1775527356890659684","flags":0,"ts_in_delta":921,"sequence":143002,"symbol":"FCEU SI 20260615 PS"}
{"ts_recv":"2026-04-07T02:02:38.770954494Z","hd":{"ts_event":"2026-04-07T02:02:38.770935529Z","rtype":160,"publisher_id":101,"instrument_id":436},"action":"A","side":"A","price":"1.156730000","size":30,"channel_id":23,"order_id":"1775527358770941663","flags":128,"ts_in_delta":921,"sequence":143002,"symbol":"FCEU SI 20260615 PS"}
{"ts_recv":"2026-04-07T02:02:38.771038679Z","hd":{"ts_event":"2026-04-07T02:02:38.771017981Z","rtype":160,"publisher_id":101,"instrument_id":436},"action":"C","side":"B","price":"1.156620000","size":30,"channel_id":23,"order_id":"10998899395560490348","flags":0,"ts_in_delta":1112,"sequence":143003,"symbol":"FCEU SI 20260615 PS"}
{"ts_recv":"2026-04-07T02:02:38.771038679Z","hd":{"ts_event":"2026-04-07T02:02:38.771017981Z","rtype":160,"publisher_id":101,"instrument_id":436},"action":"A","side":"B","price":"1.156630000","size":30,"channel_id":23,"order_id":"10998899395625799881","flags":0,"ts_in_delta":1112,"sequence":143003,"symbol":"FCEU SI 20260615 PS"}
{"ts_recv":"2026-04-07T02:02:38.771038679Z","hd":{"ts_event":"2026-04-07T02:02:38.771017981Z","rtype":160,"publisher_id":101,"instrument_id":436},"action":"C","side":"A","price":"1.156720000","size":30,"channel_id":23,"order_id":"1775527358705714540","flags":0,"ts_in_delta":1112,"sequence":143003,"symbol":"FCEU SI 20260615 PS"}
{"ts_recv":"2026-04-07T02:02:38.771038679Z","hd":{"ts_event":"2026-04-07T02:02:38.771017981Z","rtype":160,"publisher_id":101,"instrument_id":436},"action":"A","side":"A","price":"1.156730000","size":30,"channel_id":23,"order_id":"1775527358771024073","flags":128,"ts_in_delta":1112,"sequence":143003,"symbol":"FCEU SI 20260615 PS"}
{"ts_recv":"2026-04-07T02:02:58.706943885Z","hd":{"ts_event":"2026-04-07T02:02:58.706921561Z","rtype":160,"publisher_id":101,"instrument_id":436},"action":"C","side":"B","price":"1.156630000","size":30,"channel_id":23,"order_id":"10998899395625717471","flags":0,"ts_in_delta":776,"sequence":143279,"symbol":"FCEU SI 20260615 PS"}
{"ts_recv":"2026-04-07T02:02:58.706943885Z","hd":{"ts_event":"2026-04-07T02:02:58.706921561Z","rtype":160,"publisher_id":101,"instrument_id":436},"action":"A","side":"B","price":"1.156610000","size":30,"channel_id":23,"order_id":"10998899415561703273","flags":0,"ts_in_delta":776,"sequence":143279,"symbol":"FCEU SI 20260615 PS"}
{"ts_recv":"2026-04-07T02:02:58.706943885Z","hd":{"ts_event":"2026-04-07T02:02:58.706921561Z","rtype":160,"publisher_id":101,"instrument_id":436},"action":"C","side":"A","price":"1.156730000","size":30,"channel_id":23,"order_id":"1775527358770941663","flags":0,"ts_in_delta":776,"sequence":143279,"symbol":"FCEU SI 20260615 PS"}
{"ts_recv":"2026-04-07T02:02:58.706943885Z","hd":{"ts_event":"2026-04-07T02:02:58.706921561Z","rtype":160,"publisher_id":101,"instrument_id":436},"action":"A","side":"A","price":"1.156710000","size":30,"channel_id":23,"order_id":"1775527378706927465","flags":128,"ts_in_delta":776,"sequence":143279,"symbol":"FCEU SI 20260615 PS"}
{"ts_recv":"2026-04-07T02:02:58.707005883Z","hd":{"ts_event":"2026-04-07T02:02:58.706990199Z","rtype":160,"publisher_id":101,"instrument_id":436},"action":"C","side":"B","price":"1.156630000","size":30,"channel_id":23,"order_id":"10998899395625799881","flags":0,"ts_in_delta":801,"sequence":143280,"symbol":"FCEU SI 20260615 PS"}
{"ts_recv":"2026-04-07T02:02:58.707005883Z","hd":{"ts_event":"2026-04-07T02:02:58.706990199Z","rtype":160,"publisher_id":101,"instrument_id":436},"action":"A","side":"B","price":"1.156620000","size":30,"channel_id":23,"order_id":"10998899415561771707","flags":0,"ts_in_delta":801,"sequence":143280,"symbol":"FCEU SI 20260615 PS"}
{"ts_recv":"2026-04-07T02:02:58.707005883Z","hd":{"ts_event":"2026-04-07T02:02:58.706990199Z","rtype":160,"publisher_id":101,"instrument_id":436},"action":"C","side":"A","price":"1.156730000","size":30,"channel_id":23,"order_id":"1775527358771024073","flags":0,"ts_in_delta":801,"sequence":143280,"symbol":"FCEU SI 20260615 PS"}
{"ts_recv":"2026-04-07T02:02:58.707005883Z","hd":{"ts_event":"2026-04-07T02:02:58.706990199Z","rtype":160,"publisher_id":101,"instrument_id":436},"action":"A","side":"A","price":"1.156720000","size":30,"channel_id":23,"order_id":"1775527378706995899","flags":128,"ts_in_delta":801,"sequence":143280,"symbol":"FCEU SI 20260615 PS"}
{"ts_recv":"2026-04-07T02:02:58.707486997Z","hd":{"ts_event":"2026-04-07T02:02:58.707465243Z","rtype":160,"publisher_id":101,"instrument_id":436},"action":"C","side":"B","price":"1.156620000","size":30,"channel_id":23,"order_id":"10998899415561771707","flags":0,"ts_in_delta":789,"sequence":143281,"symbol":"FCEU SI 20260615 PS"}
{"ts_recv":"2026-04-07T02:02:58.707486997Z","hd":{"ts_event":"2026-04-07T02:02:58.707465243Z","rtype":160,"publisher_id":101,"instrument_id":436},"action":"A","side":"B","price":"1.156600000","size":30,"channel_id":23,"order_id":"10998899415562246960","flags":0,"ts_in_delta":789,"sequence":143281,"symbol":"FCEU SI 20260615 PS"}
{"ts_recv":"2026-04-07T02:02:58.707486997Z","hd":{"ts_event":"2026-04-07T02:02:58.707465243Z","rtype":160,"publisher_id":101,"instrument_id":436},"action":"C","side":"A","price":"1.156720000","size":30,"channel_id":23,"order_id":"1775527378706995899","flags":0,"ts_in_delta":789,"sequence":143281,"symbol":"FCEU SI 20260615 PS"}
{"ts_recv":"2026-04-07T02:02:58.707486997Z","hd":{"ts_event":"2026-04-07T02:02:58.707465243Z","rtype":160,"publisher_id":101,"instrument_id":436},"action":"A","side":"A","price":"1.156700000","size":30,"channel_id":23,"order_id":"1775527378707471152","flags":128,"ts_in_delta":789,"sequence":143281,"symbol":"FCEU SI 20260615 PS"}
{"ts_recv":"2026-04-07T02:02:58.717078056Z","hd":{"ts_event":"2026-04-07T02:02:58.717056193Z","rtype":160,"publisher_id":101,"instrument_id":436},"action":"C","side":"B","price":"1.156610000","size":30,"channel_id":23,"order_id":"10998899415561703273","flags":0,"ts_in_delta":982,"sequence":143289,"symbol":"FCEU SI 20260615 PS"}
{"ts_recv":"2026-04-07T02:02:58.717078056Z","hd":{"ts_event":"2026-04-07T02:02:58.717056193Z","rtype":160,"publisher_id":101,"instrument_id":436},"action":"A","side":"B","price":"1.156590000","size":30,"channel_id":23,"order_id":"10998899415571838139","flags":0,"ts_in_delta":982,"sequence":143289,"symbol":"FCEU SI 20260615 PS"}
{"ts_recv":"2026-04-07T02:02:58.717078056Z","hd":{"ts_event":"2026-04-07T02:02:58.717056193Z","rtype":160,"publisher_id":101,"instrument_id":436},"action":"C","side":"A","price":"1.156710000","size":30,"channel_id":23,"order_id":"1775527378706927465","flags":0,"ts_in_delta":982,"sequence":143289,"symbol":"FCEU SI 20260615 PS"}
{"ts_recv":"2026-04-07T02:02:58.717078056Z","hd":{"ts_event":"2026-04-07T02:02:58.717056193Z","rtype":160,"publisher_id":101,"instrument_id":436},"action":"A","side":"A","price":"1.156690000","size":30,"channel_id":23,"order_id":"1775527378717062331","flags":128,"ts_in_delta":982,"sequence":143289,"symbol":"FCEU SI 20260615 PS"}
{"ts_recv":"2026-04-07T02:02:58.717137389Z","hd":{"ts_event":"2026-04-07T02:02:58.717120459Z","rtype":160,"publisher_id":101,"instrument_id":436},"action":"C","side":"B","price":"1.156600000","size":30,"channel_id":23,"order_id":"10998899415562246960","flags":0,"ts_in_delta":985,"sequence":143290,"symbol":"FCEU SI 20260615 PS"}
{"ts_recv":"2026-04-07T02:02:58.717137389Z","hd":{"ts_event":"2026-04-07T02:02:58.717120459Z","rtype":160,"publisher_id":101,"instrument_id":436},"action":"A","side":"B","price":"1.156590000","size":30,"channel_id":23,"order_id":"10998899415571902117","flags":0,"ts_in_delta":985,"sequence":143290,"symbol":"FCEU SI 20260615 PS"}
{"ts_recv":"2026-04-07T02:02:58.717137389Z","hd":{"ts_event":"2026-04-07T02:02:58.717120459Z","rtype":160,"publisher_id":101,"instrument_id":436},"action":"C","side":"A","price":"1.156700000","size":30,"channel_id":23,"order_id":"1775527378707471152","flags":0,"ts_in_delta":985,"sequence":143290,"symbol":"FCEU SI 20260615 PS"}
{"ts_recv":"2026-04-07T02:02:58.717137389Z","hd":{"ts_event":"2026-04-07T02:02:58.717120459Z","rtype":160,"publisher_id":101,"instrument_id":436},"action":"A","side":"A","price":"1.156690000","size":30,"channel_id":23,"order_id":"1775527378717126309","flags":128,"ts_in_delta":985,"sequence":143290,"symbol":"FCEU SI 20260615 PS"}
{"ts_recv":"2026-04-07T02:03:04.157538232Z","hd":{"ts_event":"2026-04-07T02:03:04.157516177Z","rtype":160,"publisher_id":101,"instrument_id":436},"action":"C","side":"B","price":"1.156590000","size":30,"channel_id":23,"order_id":"10998899415571902117","flags":0,"ts_in_delta":1001,"sequence":143432,"symbol":"FCEU SI 20260615 PS"}
{"ts_recv":"2026-04-07T02:03:04.157538232Z","hd":{"ts_event":"2026-04-07T02:03:04.157516177Z","rtype":160,"publisher_id":101,"instrument_id":436},"action":"A","side":"B","price":"1.156600000","size":30,"channel_id":23,"order_id":"10998899421012298391","flags":0,"ts_in_delta":1001,"sequence":143432,"symbol":"FCEU SI 20260615 PS"}
{"ts_recv":"2026-04-07T02:03:04.157538232Z","hd":{"ts_event":"2026-04-07T02:03:04.157516177Z","rtype":160,"publisher_id":101,"instrument_id":436},"action":"C","side":"A","price":"1.156690000","size":30,"channel_id":23,"order_id":"1775527378717126309","flags":0,"ts_in_delta":1001,"sequence":143432,"symbol":"FCEU SI 20260615 PS"}
{"ts_recv":"2026-04-07T02:03:04.157538232Z","hd":{"ts_event":"2026-04-07T02:03:04.157516177Z","rtype":160,"publisher_id":101,"instrument_id":436},"action":"A","side":"A","price":"1.156700000","size":30,"channel_id":23,"order_id":"1775527384157522583","flags":128,"ts_in_delta":1001,"sequence":143432,"symbol":"FCEU SI 20260615 PS"}
{"ts_recv":"2026-04-07T02:03:04.191491068Z","hd":{"ts_event":"2026-04-07T02:03:04.191468377Z","rtype":160,"publisher_id":101,"instrument_id":436},"action":"C","side":"B","price":"1.156590000","size":30,"channel_id":23,"order_id":"10998899415571838139","flags":0,"ts_in_delta":895,"sequence":143446,"symbol":"FCEU SI 20260615 PS"}
{"ts_recv":"2026-04-07T02:03:04.191491068Z","hd":{"ts_event":"2026-04-07T02:03:04.191468377Z","rtype":160,"publisher_id":101,"instrument_id":436},"action":"A","side":"B","price":"1.156610000","size":30,"channel_id":23,"order_id":"10998899421046250270","flags":0,"ts_in_delta":895,"sequence":143446,"symbol":"FCEU SI 20260615 PS"}
{"ts_recv":"2026-04-07T02:03:04.191491068Z","hd":{"ts_event":"2026-04-07T02:03:04.191468377Z","rtype":160,"publisher_id":101,"instrument_id":436},"action":"C","side":"A","price":"1.156690000","size":30,"channel_id":23,"order_id":"1775527378717062331","flags":0,"ts_in_delta":895,"sequence":143446,"symbol":"FCEU SI 20260615 PS"}
{"ts_recv":"2026-04-07T02:03:04.191491068Z","hd":{"ts_event":"2026-04-07T02:03:04.191468377Z","rtype":160,"publisher_id":101,"instrument_id":436},"action":"A","side":"A","price":"1.156710000","size":30,"channel_id":23,"order_id":"1775527384191474462","flags":128,"ts_in_delta":895,"sequence":143446,"symbol":"FCEU SI 20260615 PS"}
{"ts_recv":"2026-04-07T02:03:04.191553534Z","hd":{"ts_event":"2026-04-07T02:03:04.191536825Z","rtype":160,"publisher_id":101,"instrument_id":436},"action":"C","side":"B","price":"1.156600000","size":30,"channel_id":23,"order_id":"10998899421012298391","flags":0,"ts_in_delta":951,"sequence":143447,"symbol":"FCEU SI 20260615 PS"}
{"ts_recv":"2026-04-07T02:03:04.191553534Z","hd":{"ts_event":"2026-04-07T02:03:04.191536825Z","rtype":160,"publisher_id":101,"instrument_id":436},"action":"A","side":"B","price":"1.156610000","size":30,"channel_id":23,"order_id":"10998899421046318775","flags":0,"ts_in_delta":951,"sequence":143447,"symbol":"FCEU SI 20260615 PS"}
{"ts_recv":"2026-04-07T02:03:04.191553534Z","hd":{"ts_event":"2026-04-07T02:03:04.191536825Z","rtype":160,"publisher_id":101,"instrument_id":436},"action":"C","side":"A","price":"1.156700000","size":30,"channel_id":23,"order_id":"1775527384157522583","flags":0,"ts_in_delta":951,"sequence":143447,"symbol":"FCEU SI 20260615 PS"}
{"ts_recv":"2026-04-07T02:03:04.191553534Z","hd":{"ts_event":"2026-04-07T02:03:04.191536825Z","rtype":160,"publisher_id":101,"instrument_id":436},"action":"A","side":"A","price":"1.156710000","size":30,"channel_id":23,"order_id":"1775527384191542967","flags":128,"ts_in_delta":951,"sequence":143447,"symbol":"FCEU SI 20260615 PS"}
{"ts_recv":"2026-04-07T02:03:04.348719871Z","hd":{"ts_event":"2026-04-07T02:03:04.348698949Z","rtype":160,"publisher_id":101,"instrument_id":436},"action":"C","side":"B","price":"1.156610000","size":30,"channel_id":23,"order_id":"10998899421046318775","flags":0,"ts_in_delta":901,"sequence":143481,"symbol":"FCEU SI 20260615 PS"}
{"ts_recv":"2026-04-07T02:03:04.348719871Z","hd":{"ts_event":"2026-04-07T02:03:04.348698949Z","rtype":160,"publisher_id":101,"instrument_id":436},"action":"A","side":"B","price":"1.156620000","size":30,"channel_id":23,"order_id":"10998899421203480963","flags":0,"ts_in_delta":901,"sequence":143481,"symbol":"FCEU SI 20260615 PS"}
{"ts_recv":"2026-04-07T02:03:04.348719871Z","hd":{"ts_event":"2026-04-07T02:03:04.348698949Z","rtype":160,"publisher_id":101,"instrument_id":436},"action":"C","side":"A","price":"1.156710000","size":30,"channel_id":23,"order_id":"1775527384191542967","flags":0,"ts_in_delta":901,"sequence":143481,"symbol":"FCEU SI 20260615 PS"}
{"ts_recv":"2026-04-07T02:03:04.348719871Z","hd":{"ts_event":"2026-04-07T02:03:04.348698949Z","rtype":160,"publisher_id":101,"instrument_id":436},"action":"A","side":"A","price":"1.156720000","size":30,"channel_id":23,"order_id":"1775527384348705155","flags":128,"ts_in_delta":901,"sequence":143481,"symbol":"FCEU SI 20260615 PS"}
{"ts_recv":"2026-04-07T02:03:05.159527401Z","hd":{"ts_event":"2026-04-07T02:03:05.159502589Z","rtype":160,"publisher_id":101,"instrument_id":436},"action":"C","side":"B","price":"1.156620000","size":30,"channel_id":23,"order_id":"10998899421203480963","flags":0,"ts_in_delta":1444,"sequence":143505,"symbol":"FCEU SI 20260615 PS"}
{"ts_recv":"2026-04-07T02:03:05.159527401Z","hd":{"ts_event":"2026-04-07T02:03:05.159502589Z","rtype":160,"publisher_id":101,"instrument_id":436},"action":"A","side":"B","price":"1.156610000","size":30,"channel_id":23,"order_id":"10998899422014289148","flags":0,"ts_in_delta":1444,"sequence":143505,"symbol":"FCEU SI 20260615 PS"}
{"ts_recv":"2026-04-07T02:03:05.159527401Z","hd":{"ts_event":"2026-04-07T02:03:05.159502589Z","rtype":160,"publisher_id":101,"instrument_id":436},"action":"C","side":"A","price":"1.156720000","size":30,"channel_id":23,"order_id":"1775527384348705155","flags":0,"ts_in_delta":1444,"sequence":143505,"symbol":"FCEU SI 20260615 PS"}
{"ts_recv":"2026-04-07T02:03:05.159527401Z","hd":{"ts_event":"2026-04-07T02:03:05.159502589Z","rtype":160,"publisher_id":101,"instrument_id":436},"action":"A","side":"A","price":"1.156710000","size":30,"channel_id":23,"order_id":"1775527385159513340","flags":128,"ts_in_delta":1444,"sequence":143505,"symbol":"FCEU SI 20260615 PS"}
{"ts_recv":"2026-04-07T02:03:09.735172844Z","hd":{"ts_event":"2026-04-07T02:03:09.735153711Z","rtype":160,"publisher_id":101,"instrument_id":436},"action":"C","side":"B","price":"1.156610000","size":30,"channel_id":23,"order_id":"10998899422014289148","flags":0,"ts_in_delta":920,"sequence":143561,"symbol":"FCEU SI 20260615 PS"}
{"ts_recv":"2026-04-07T02:03:09.735172844Z","hd":{"ts_event":"2026-04-07T02:03:09.735153711Z","rtype":160,"publisher_id":101,"instrument_id":436},"action":"A","side":"B","price":"1.156620000","size":30,"channel_id":23,"order_id":"10998899426589935398","flags":0,"ts_in_delta":920,"sequence":143561,"symbol":"FCEU SI 20260615 PS"}
{"ts_recv":"2026-04-07T02:03:09.735172844Z","hd":{"ts_event":"2026-04-07T02:03:09.735153711Z","rtype":160,"publisher_id":101,"instrument_id":436},"action":"C","side":"A","price":"1.156710000","size":30,"channel_id":23,"order_id":"1775527385159513340","flags":0,"ts_in_delta":920,"sequence":143561,"symbol":"FCEU SI 20260615 PS"}
{"ts_recv":"2026-04-07T02:03:09.735172844Z","hd":{"ts_event":"2026-04-07T02:03:09.735153711Z","rtype":160,"publisher_id":101,"instrument_id":436},"action":"A","side":"A","price":"1.156720000","size":30,"channel_id":23,"order_id":"1775527389735159590","flags":128,"ts_in_delta":920,"sequence":143561,"symbol":"FCEU SI 20260615 PS"}
{"ts_recv":"2026-04-07T02:03:09.800538271Z","hd":{"ts_event":"2026-04-07T02:03:09.800516133Z","rtype":160,"publisher_id":101,"instrument_id":436},"action":"C","side":"B","price":"1.156610000","size":30,"channel_id":23,"order_id":"10998899421046250270","flags":0,"ts_in_delta":1246,"sequence":143573,"symbol":"FCEU SI 20260615 PS"}
{"ts_recv":"2026-04-07T02:03:09.800538271Z","hd":{"ts_event":"2026-04-07T02:03:09.800516133Z","rtype":160,"publisher_id":101,"instrument_id":436},"action":"A","side":"B","price":"1.156630000","size":30,"channel_id":23,"order_id":"10998899426655298245","flags":0,"ts_in_delta":1246,"sequence":143573,"symbol":"FCEU SI 20260615 PS"}
{"ts_recv":"2026-04-07T02:03:09.800538271Z","hd":{"ts_event":"2026-04-07T02:03:09.800516133Z","rtype":160,"publisher_id":101,"instrument_id":436},"action":"C","side":"A","price":"1.156710000","size":30,"channel_id":23,"order_id":"1775527384191474462","flags":0,"ts_in_delta":1246,"sequence":143573,"symbol":"FCEU SI 20260615 PS"}
{"ts_recv":"2026-04-07T02:03:09.800538271Z","hd":{"ts_event":"2026-04-07T02:03:09.800516133Z","rtype":160,"publisher_id":101,"instrument_id":436},"action":"A","side":"A","price":"1.156730000","size":30,"channel_id":23,"order_id":"1775527389800522437","flags":128,"ts_in_delta":1246,"sequence":143573,"symbol":"FCEU SI 20260615 PS"}
{"ts_recv":"2026-04-07T02:03:09.800599094Z","hd":{"ts_event":"2026-04-07T02:03:09.800581163Z","rtype":160,"publisher_id":101,"instrument_id":436},"action":"C","side":"B","price":"1.156620000","size":30,"channel_id":23,"order_id":"10998899426589935398","flags":0,"ts_in_delta":892,"sequence":143574,"symbol":"FCEU SI 20260615 PS"}
{"ts_recv":"2026-04-07T02:03:09.800599094Z","hd":{"ts_event":"2026-04-07T02:03:09.800581163Z","rtype":160,"publisher_id":101,"instrument_id":436},"action":"A","side":"B","price":"1.156630000","size":30,"channel_id":23,"order_id":"10998899426655363013","flags":0,"ts_in_delta":892,"sequence":143574,"symbol":"FCEU SI 20260615 PS"}
{"ts_recv":"2026-04-07T02:03:09.800599094Z","hd":{"ts_event":"2026-04-07T02:03:09.800581163Z","rtype":160,"publisher_id":101,"instrument_id":436},"action":"C","side":"A","price":"1.156720000","size":30,"channel_id":23,"order_id":"1775527389735159590","flags":0,"ts_in_delta":892,"sequence":143574,"symbol":"FCEU SI 20260615 PS"}
{"ts_recv":"2026-04-07T02:03:09.800599094Z","hd":{"ts_event":"2026-04-07T02:03:09.800581163Z","rtype":160,"publisher_id":101,"instrument_id":436},"action":"A","side":"A","price":"1.156730000","size":30,"channel_id":23,"order_id":"1775527389800587205","flags":128,"ts_in_delta":892,"sequence":143574,"symbol":"FCEU SI 20260615 PS"}
{"ts_recv":"2026-04-07T02:03:16.378938908Z","hd":{"ts_event":"2026-04-07T02:03:16.378917649Z","rtype":160,"publisher_id":101,"instrument_id":436},"action":"C","side":"B","price":"1.156630000","size":30,"channel_id":23,"order_id":"10998899426655363013","flags":0,"ts_in_delta":986,"sequence":143664,"symbol":"FCEU SI 20260615 PS"}
{"ts_recv":"2026-04-07T02:03:16.378938908Z","hd":{"ts_event":"2026-04-07T02:03:16.378917649Z","rtype":160,"publisher_id":101,"instrument_id":436},"action":"A","side":"B","price":"1.156620000","size":30,"channel_id":23,"order_id":"10998899433233699605","flags":0,"ts_in_delta":986,"sequence":143664,"symbol":"FCEU SI 20260615 PS"}
{"ts_recv":"2026-04-07T02:03:16.378938908Z","hd":{"ts_event":"2026-04-07T02:03:16.378917649Z","rtype":160,"publisher_id":101,"instrument_id":436},"action":"C","side":"A","price":"1.156730000","size":30,"channel_id":23,"order_id":"1775527389800587205","flags":0,"ts_in_delta":986,"sequence":143664,"symbol":"FCEU SI 20260615 PS"}
{"ts_recv":"2026-04-07T02:03:16.378938908Z","hd":{"ts_event":"2026-04-07T02:03:16.378917649Z","rtype":160,"publisher_id":101,"instrument_id":436},"action":"A","side":"A","price":"1.156720000","size":30,"channel_id":23,"order_id":"1775527396378923797","flags":128,"ts_in_delta":986,"sequence":143664,"symbol":"FCEU SI 20260615 PS"}
{"ts_recv":"2026-04-07T02:03:16.382975015Z","hd":{"ts_event":"2026-04-07T02:03:16.382956303Z","rtype":160,"publisher_id":101,"instrument_id":436},"action":"C","side":"B","price":"1.156630000","size":30,"channel_id":23,"order_id":"10998899426655298245","flags":0,"ts_in_delta":917,"sequence":143665,"symbol":"FCEU SI 20260615 PS"}
{"ts_recv":"2026-04-07T02:03:16.382975015Z","hd":{"ts_event":"2026-04-07T02:03:16.382956303Z","rtype":160,"publisher_id":101,"instrument_id":436},"action":"A","side":"B","price":"1.156610000","size":30,"channel_id":23,"order_id":"10998899433237738565","flags":0,"ts_in_delta":917,"sequence":143665,"symbol":"FCEU SI 20260615 PS"}
{"ts_recv":"2026-04-07T02:03:16.382975015Z","hd":{"ts_event":"2026-04-07T02:03:16.382956303Z","rtype":160,"publisher_id":101,"instrument_id":436},"action":"C","side":"A","price":"1.156730000","size":30,"channel_id":23,"order_id":"1775527389800522437","flags":0,"ts_in_delta":917,"sequence":143665,"symbol":"FCEU SI 20260615 PS"}
{"ts_recv":"2026-04-07T02:03:16.382975015Z","hd":{"ts_event":"2026-04-07T02:03:16.382956303Z","rtype":160,"publisher_id":101,"instrument_id":436},"action":"A","side":"A","price":"1.156710000","size":30,"channel_id":23,"order_id":"1775527396382962757","flags":128,"ts_in_delta":917,"sequence":143665,"symbol":"FCEU SI 20260615 PS"}
{"ts_recv":"2026-04-07T02:03:16.383044731Z","hd":{"ts_event":"2026-04-07T02:03:16.383025635Z","rtype":160,"publisher_id":101,"instrument_id":436},"action":"C","side":"B","price":"1.156620000","size":30,"channel_id":23,"order_id":"10998899433233699605","flags":0,"ts_in_delta":883,"sequence":143666,"symbol":"FCEU SI 20260615 PS"}
{"ts_recv":"2026-04-07T02:03:16.383044731Z","hd":{"ts_event":"2026-04-07T02:03:16.383025635Z","rtype":160,"publisher_id":101,"instrument_id":436},"action":"A","side":"B","price":"1.156610000","size":30,"channel_id":23,"order_id":"10998899433237807445","flags":0,"ts_in_delta":883,"sequence":143666,"symbol":"FCEU SI 20260615 PS"}
{"ts_recv":"2026-04-07T02:03:16.383044731Z","hd":{"ts_event":"2026-04-07T02:03:16.383025635Z","rtype":160,"publisher_id":101,"instrument_id":436},"action":"C","side":"A","price":"1.156720000","size":30,"channel_id":23,"order_id":"1775527396378923797","flags":0,"ts_in_delta":883,"sequence":143666,"symbol":"FCEU SI 20260615 PS"}
{"ts_recv":"2026-04-07T02:03:16.383044731Z","hd":{"ts_event":"2026-04-07T02:03:16.383025635Z","rtype":160,"publisher_id":101,"instrument_id":436},"action":"A","side":"A","price":"1.156710000","size":30,"channel_id":23,"order_id":"1775527396383031637","flags":128,"ts_in_delta":883,"sequence":143666,"symbol":"FCEU SI 20260615 PS"}
{"ts_recv":"2026-04-07T02:03:25.774442277Z","hd":{"ts_event":"2026-04-07T02:03:25.774421031Z","rtype":160,"publisher_id":101,"instrument_id":436},"action":"C","side":"B","price":"1.156610000","size":30,"channel_id":23,"order_id":"10998899433237807445","flags":0,"ts_in_delta":944,"sequence":143781,"symbol":"FCEU SI 20260615 PS"}
{"ts_recv":"2026-04-07T02:03:25.774442277Z","hd":{"ts_event":"2026-04-07T02:03:25.774421031Z","rtype":160,"publisher_id":101,"instrument_id":436},"action":"A","side":"B","price":"1.156600000","size":30,"channel_id":23,"order_id":"10998899442629203323","flags":0,"ts_in_delta":944,"sequence":143781,"symbol":"FCEU SI 20260615 PS"}
{"ts_recv":"2026-04-07T02:03:25.774442277Z","hd":{"ts_event":"2026-04-07T02:03:25.774421031Z","rtype":160,"publisher_id":101,"instrument_id":436},"action":"C","side":"A","price":"1.156710000","size":30,"channel_id":23,"order_id":"1775527396383031637","flags":0,"ts_in_delta":944,"sequence":143781,"symbol":"FCEU SI 20260615 PS"}
{"ts_recv":"2026-04-07T02:03:25.774442277Z","hd":{"ts_event":"2026-04-07T02:03:25.774421031Z","rtype":160,"publisher_id":101,"instrument_id":436},"action":"A","side":"A","price":"1.156700000","size":30,"channel_id":23,"order_id":"1775527405774427515","flags":128,"ts_in_delta":944,"sequence":143781,"symbol":"FCEU SI 20260615 PS"}
{"ts_recv":"2026-04-07T02:03:25.799218533Z","hd":{"ts_event":"2026-04-07T02:03:25.799194545Z","rtype":160,"publisher_id":101,"instrument_id":436},"action":"C","side":"B","price":"1.156610000","size":30,"channel_id":23,"order_id":"10998899433237738565","flags":0,"ts_in_delta":1102,"sequence":143787,"symbol":"FCEU SI 20260615 PS"}
{"ts_recv":"2026-04-07T02:03:25.799218533Z","hd":{"ts_event":"2026-04-07T02:03:25.799194545Z","rtype":160,"publisher_id":101,"instrument_id":436},"action":"A","side":"B","price":"1.156590000","size":30,"channel_id":23,"order_id":"10998899442653978957","flags":0,"ts_in_delta":1102,"sequence":143787,"symbol":"FCEU SI 20260615 PS"}
{"ts_recv":"2026-04-07T02:03:25.799218533Z","hd":{"ts_event":"2026-04-07T02:03:25.799194545Z","rtype":160,"publisher_id":101,"instrument_id":436},"action":"C","side":"A","price":"1.156710000","size":30,"channel_id":23,"order_id":"1775527396382962757","flags":0,"ts_in_delta":1102,"sequence":143787,"symbol":"FCEU SI 20260615 PS"}
{"ts_recv":"2026-04-07T02:03:25.799218533Z","hd":{"ts_event":"2026-04-07T02:03:25.799194545Z","rtype":160,"publisher_id":101,"instrument_id":436},"action":"A","side":"A","price":"1.156690000","size":30,"channel_id":23,"order_id":"1775527405799203149","flags":128,"ts_in_delta":1102,"sequence":143787,"symbol":"FCEU SI 20260615 PS"}
{"ts_recv":"2026-04-07T02:03:25.799278765Z","hd":{"ts_event":"2026-04-07T02:03:25.799262391Z","rtype":160,"publisher_id":101,"instrument_id":436},"action":"C","side":"B","price":"1.156600000","size":30,"channel_id":23,"order_id":"10998899442629203323","flags":0,"ts_in_delta":1003,"sequence":143788,"symbol":"FCEU SI 20260615 PS"}
{"ts_recv":"2026-04-07T02:03:25.799278765Z","hd":{"ts_event":"2026-04-07T02:03:25.799262391Z","rtype":160,"publisher_id":101,"instrument_id":436},"action":"A","side":"B","price":"1.156590000","size":30,"channel_id":23,"order_id":"10998899442654044073","flags":0,"ts_in_delta":1003,"sequence":143788,"symbol":"FCEU SI 20260615 PS"}
{"ts_recv":"2026-04-07T02:03:25.799278765Z","hd":{"ts_event":"2026-04-07T02:03:25.799262391Z","rtype":160,"publisher_id":101,"instrument_id":436},"action":"C","side":"A","price":"1.156700000","size":30,"channel_id":23,"order_id":"1775527405774427515","flags":0,"ts_in_delta":1003,"sequence":143788,"symbol":"FCEU SI 20260615 PS"}
{"ts_recv":"2026-04-07T02:03:25.799278765Z","hd":{"ts_event":"2026-04-07T02:03:25.799262391Z","rtype":160,"publisher_id":101,"instrument_id":436},"action":"A","side":"A","price":"1.156690000","size":30,"channel_id":23,"order_id":"1775527405799268265","flags":128,"ts_in_delta":1003,"sequence":143788,"symbol":"FCEU SI 20260615 PS"}
{"ts_recv":"2026-04-07T02:03:37.388299483Z","hd":{"ts_event":"2026-04-07T02:03:37.388279061Z","rtype":160,"publisher_id":101,"instrument_id":436},"action":"C","side":"B","price":"1.156590000","size":30,"channel_id":23,"order_id":"10998899442654044073","flags":0,"ts_in_delta":771,"sequence":143881,"symbol":"FCEU SI 20260615 PS"}
{"ts_recv":"2026-04-07T02:03:37.388299483Z","hd":{"ts_event":"2026-04-07T02:03:37.388279061Z","rtype":160,"publisher_id":101,"instrument_id":436},"action":"A","side":"B","price":"1.156600000","size":30,"channel_id":23,"order_id":"10998899454243061001","flags":0,"ts_in_delta":771,"sequence":143881,"symbol":"FCEU SI 20260615 PS"}
{"ts_recv":"2026-04-07T02:03:37.388299483Z","hd":{"ts_event":"2026-04-07T02:03:37.388279061Z","rtype":160,"publisher_id":101,"instrument_id":436},"action":"C","side":"A","price":"1.156690000","size":30,"channel_id":23,"order_id":"1775527405799268265","flags":0,"ts_in_delta":771,"sequence":143881,"symbol":"FCEU SI 20260615 PS"}
{"ts_recv":"2026-04-07T02:03:37.388299483Z","hd":{"ts_event":"2026-04-07T02:03:37.388279061Z","rtype":160,"publisher_id":101,"instrument_id":436},"action":"A","side":"A","price":"1.156700000","size":30,"channel_id":23,"order_id":"1775527417388285193","flags":128,"ts_in_delta":771,"sequence":143881,"symbol":"FCEU SI 20260615 PS"}
{"ts_recv":"2026-04-07T02:03:37.388908118Z","hd":{"ts_event":"2026-04-07T02:03:37.388889511Z","rtype":160,"publisher_id":101,"instrument_id":436},"action":"C","side":"B","price":"1.156590000","size":30,"channel_id":23,"order_id":"10998899442653978957","flags":0,"ts_in_delta":780,"sequence":143883,"symbol":"FCEU SI 20260615 PS"}
{"ts_recv":"2026-04-07T02:03:37.388908118Z","hd":{"ts_event":"2026-04-07T02:03:37.388889511Z","rtype":160,"publisher_id":101,"instrument_id":436},"action":"A","side":"B","price":"1.156610000","size":30,"channel_id":23,"order_id":"10998899454243671457","flags":0,"ts_in_delta":780,"sequence":143883,"symbol":"FCEU SI 20260615 PS"}
{"ts_recv":"2026-04-07T02:03:37.388908118Z","hd":{"ts_event":"2026-04-07T02:03:37.388889511Z","rtype":160,"publisher_id":101,"instrument_id":436},"action":"C","side":"A","price":"1.156690000","size":30,"channel_id":23,"order_id":"1775527405799203149","flags":0,"ts_in_delta":780,"sequence":143883,"symbol":"FCEU SI 20260615 PS"}
{"ts_recv":"2026-04-07T02:03:37.388908118Z","hd":{"ts_event":"2026-04-07T02:03:37.388889511Z","rtype":160,"publisher_id":101,"instrument_id":436},"action":"A","side":"A","price":"1.156710000","size":30,"channel_id":23,"order_id":"1775527417388895649","flags":128,"ts_in_delta":780,"sequence":143883,"symbol":"FCEU SI 20260615 PS"}
{"ts_recv":"2026-04-07T02:03:37.388972043Z","hd":{"ts_event":"2026-04-07T02:03:37.388952117Z","rtype":160,"publisher_id":101,"instrument_id":436},"action":"C","side":"B","price":"1.156600000","size":30,"channel_id":23,"order_id":"10998899454243061001","flags":0,"ts_in_delta":940,"sequence":143884,"symbol":"FCEU SI 20260615 PS"}
{"ts_recv":"2026-04-07T02:03:37.388972043Z","hd":{"ts_event":"2026-04-07T02:03:37.388952117Z","rtype":160,"publisher_id":101,"instrument_id":436},"action":"A","side":"B","price":"1.156610000","size":30,"channel_id":23,"order_id":"10998899454243733551","flags":0,"ts_in_delta":940,"sequence":143884,"symbol":"FCEU SI 20260615 PS"}
{"ts_recv":"2026-04-07T02:03:37.388972043Z","hd":{"ts_event":"2026-04-07T02:03:37.388952117Z","rtype":160,"publisher_id":101,"instrument_id":436},"action":"C","side":"A","price":"1.156700000","size":30,"channel_id":23,"order_id":"1775527417388285193","flags":0,"ts_in_delta":940,"sequence":143884,"symbol":"FCEU SI 20260615 PS"}
{"ts_recv":"2026-04-07T02:03:37.388972043Z","hd":{"ts_event":"2026-04-07T02:03:37.388952117Z","rtype":160,"publisher_id":101,"instrument_id":436},"action":"A","side":"A","price":"1.156710000","size":30,"channel_id":23,"order_id":"1775527417388957743","flags":128,"ts_in_delta":940,"sequence":143884,"symbol":"FCEU SI 20260615 PS"}
{"ts_recv":"2026-04-07T02:03:59.394723881Z","hd":{"ts_event":"2026-04-07T02:03:59.394693609Z","rtype":160,"publisher_id":101,"instrument_id":436},"action":"C","side":"B","price":"1.156610000","size":30,"channel_id":23,"order_id":"10998899454243733551","flags":0,"ts_in_delta":1309,"sequence":143993,"symbol":"FCEU SI 20260615 PS"}
{"ts_recv":"2026-04-07T02:03:59.394723881Z","hd":{"ts_event":"2026-04-07T02:03:59.394693609Z","rtype":160,"publisher_id":101,"instrument_id":436},"action":"A","side":"B","price":"1.156600000","size":30,"channel_id":23,"order_id":"10998899476249480782","flags":0,"ts_in_delta":1309,"sequence":143993,"symbol":"FCEU SI 20260615 PS"}
{"ts_recv":"2026-04-07T02:03:59.394723881Z","hd":{"ts_event":"2026-04-07T02:03:59.394693609Z","rtype":160,"publisher_id":101,"instrument_id":436},"action":"C","side":"A","price":"1.156710000","size":30,"channel_id":23,"order_id":"1775527417388957743","flags":0,"ts_in_delta":1309,"sequence":143993,"symbol":"FCEU SI 20260615 PS"}
{"ts_recv":"2026-04-07T02:03:59.394723881Z","hd":{"ts_event":"2026-04-07T02:03:59.394693609Z","rtype":160,"publisher_id":101,"instrument_id":436},"action":"A","side":"A","price":"1.156700000","size":30,"channel_id":23,"order_id":"1775527439394704974","flags":128,"ts_in_delta":1309,"sequence":143993,"symbol":"FCEU SI 20260615 PS"}
{"ts_recv":"2026-04-07T02:03:59.420624793Z","hd":{"ts_event":"2026-04-07T02:03:59.420602663Z","rtype":160,"publisher_id":101,"instrument_id":436},"action":"C","side":"B","price":"1.156610000","size":30,"channel_id":23,"order_id":"10998899454243671457","flags":0,"ts_in_delta":908,"sequence":143999,"symbol":"FCEU SI 20260615 PS"}
{"ts_recv":"2026-04-07T02:03:59.420624793Z","hd":{"ts_event":"2026-04-07T02:03:59.420602663Z","rtype":160,"publisher_id":101,"instrument_id":436},"action":"A","side":"B","price":"1.156590000","size":30,"channel_id":23,"order_id":"10998899476275384292","flags":0,"ts_in_delta":908,"sequence":143999,"symbol":"FCEU SI 20260615 PS"}
{"ts_recv":"2026-04-07T02:03:59.420624793Z","hd":{"ts_event":"2026-04-07T02:03:59.420602663Z","rtype":160,"publisher_id":101,"instrument_id":436},"action":"C","side":"A","price":"1.156710000","size":30,"channel_id":23,"order_id":"1775527417388895649","flags":0,"ts_in_delta":908,"sequence":143999,"symbol":"FCEU SI 20260615 PS"}
{"ts_recv":"2026-04-07T02:03:59.420624793Z","hd":{"ts_event":"2026-04-07T02:03:59.420602663Z","rtype":160,"publisher_id":101,"instrument_id":436},"action":"A","side":"A","price":"1.156690000","size":30,"channel_id":23,"order_id":"1775527439420608484","flags":128,"ts_in_delta":908,"sequence":143999,"symbol":"FCEU SI 20260615 PS"}
{"ts_recv":"2026-04-07T02:03:59.420688104Z","hd":{"ts_event":"2026-04-07T02:03:59.420669005Z","rtype":160,"publisher_id":101,"instrument_id":436},"action":"C","side":"B","price":"1.156600000","size":30,"channel_id":23,"order_id":"10998899476249480782","flags":0,"ts_in_delta":917,"sequence":144000,"symbol":"FCEU SI 20260615 PS"}
{"ts_recv":"2026-04-07T02:03:59.420688104Z","hd":{"ts_event":"2026-04-07T02:03:59.420669005Z","rtype":160,"publisher_id":101,"instrument_id":436},"action":"A","side":"B","price":"1.156590000","size":30,"channel_id":23,"order_id":"10998899476275450993","flags":0,"ts_in_delta":917,"sequence":144000,"symbol":"FCEU SI 20260615 PS"}
{"ts_recv":"2026-04-07T02:03:59.420688104Z","hd":{"ts_event":"2026-04-07T02:03:59.420669005Z","rtype":160,"publisher_id":101,"instrument_id":436},"action":"C","side":"A","price":"1.156700000","size":30,"channel_id":23,"order_id":"1775527439394704974","flags":0,"ts_in_delta":917,"sequence":144000,"symbol":"FCEU SI 20260615 PS"}
{"ts_recv":"2026-04-07T02:03:59.420688104Z","hd":{"ts_event":"2026-04-07T02:03:59.420669005Z","rtype":160,"publisher_id":101,"instrument_id":436},"action":"A","side":"A","price":"1.156690000","size":30,"channel_id":23,"order_id":"1775527439420675185","flags":128,"ts_in_delta":917,"sequence":144000,"symbol":"FCEU SI 20260615 PS"}
{"ts_recv":"2026-04-07T02:04:06.092134734Z","hd":{"ts_event":"2026-04-07T02:04:06.092112243Z","rtype":160,"publisher_id":101,"instrument_id":436},"action":"C","side":"B","price":"1.156590000","size":30,"channel_id":23,"order_id":"10998899476275450993","flags":0,"ts_in_delta":873,"sequence":144111,"symbol":"FCEU SI 20260615 PS"}
{"ts_recv":"2026-04-07T02:04:06.092134734Z","hd":{"ts_event":"2026-04-07T02:04:06.092112243Z","rtype":160,"publisher_id":101,"instrument_id":436},"action":"A","side":"B","price":"1.156580000","size":30,"channel_id":23,"order_id":"10998899482946894153","flags":0,"ts_in_delta":873,"sequence":144111,"symbol":"FCEU SI 20260615 PS"}
{"ts_recv":"2026-04-07T02:04:06.092134734Z","hd":{"ts_event":"2026-04-07T02:04:06.092112243Z","rtype":160,"publisher_id":101,"instrument_id":436},"action":"C","side":"A","price":"1.156690000","size":30,"channel_id":23,"order_id":"1775527439420675185","flags":0,"ts_in_delta":873,"sequence":144111,"symbol":"FCEU SI 20260615 PS"}
{"ts_recv":"2026-04-07T02:04:06.092134734Z","hd":{"ts_event":"2026-04-07T02:04:06.092112243Z","rtype":160,"publisher_id":101,"instrument_id":436},"action":"A","side":"A","price":"1.156680000","size":30,"channel_id":23,"order_id":"1775527446092118345","flags":128,"ts_in_delta":873,"sequence":144111,"symbol":"FCEU SI 20260615 PS"}
{"ts_recv":"2026-04-07T02:04:06.092186932Z","hd":{"ts_event":"2026-04-07T02:04:06.092169313Z","rtype":160,"publisher_id":101,"instrument_id":436},"action":"C","side":"B","price":"1.156590000","size":30,"channel_id":23,"order_id":"10998899476275384292","flags":0,"ts_in_delta":897,"sequence":144112,"symbol":"FCEU SI 20260615 PS"}
{"ts_recv":"2026-04-07T02:04:06.092186932Z","hd":{"ts_event":"2026-04-07T02:04:06.092169313Z","rtype":160,"publisher_id":101,"instrument_id":436},"action":"A","side":"B","price":"1.156570000","size":30,"channel_id":23,"order_id":"10998899482946951106","flags":0,"ts_in_delta":897,"sequence":144112,"symbol":"FCEU SI 20260615 PS"}
{"ts_recv":"2026-04-07T02:04:06.092186932Z","hd":{"ts_event":"2026-04-07T02:04:06.092169313Z","rtype":160,"publisher_id":101,"instrument_id":436},"action":"C","side":"A","price":"1.156690000","size":30,"channel_id":23,"order_id":"1775527439420608484","flags":0,"ts_in_delta":897,"sequence":144112,"symbol":"FCEU SI 20260615 PS"}
{"ts_recv":"2026-04-07T02:04:06.092186932Z","hd":{"ts_event":"2026-04-07T02:04:06.092169313Z","rtype":160,"publisher_id":101,"instrument_id":436},"action":"A","side":"A","price":"1.156670000","size":30,"channel_id":23,"order_id":"1775527446092175298","flags":128,"ts_in_delta":897,"sequence":144112,"symbol":"FCEU SI 20260615 PS"}
{"ts_recv":"2026-04-07T02:04:06.092246188Z","hd":{"ts_event":"2026-04-07T02:04:06.092226415Z","rtype":160,"publisher_id":101,"instrument_id":436},"action":"C","side":"B","price":"1.156580000","size":30,"channel_id":23,"order_id":"10998899482946894153","flags":0,"ts_in_delta":952,"sequence":144113,"symbol":"FCEU SI 20260615 PS"}
{"ts_recv":"2026-04-07T02:04:06.092246188Z","hd":{"ts_event":"2026-04-07T02:04:06.092226415Z","rtype":160,"publisher_id":101,"instrument_id":436},"action":"A","side":"B","price":"1.156570000","size":30,"channel_id":23,"order_id":"10998899482947008500","flags":0,"ts_in_delta":952,"sequence":144113,"symbol":"FCEU SI 20260615 PS"}
{"ts_recv":"2026-04-07T02:04:06.092246188Z","hd":{"ts_event":"2026-04-07T02:04:06.092226415Z","rtype":160,"publisher_id":101,"instrument_id":436},"action":"C","side":"A","price":"1.156680000","size":30,"channel_id":23,"order_id":"1775527446092118345","flags":0,"ts_in_delta":952,"sequence":144113,"symbol":"FCEU SI 20260615 PS"}
{"ts_recv":"2026-04-07T02:04:06.092246188Z","hd":{"ts_event":"2026-04-07T02:04:06.092226415Z","rtype":160,"publisher_id":101,"instrument_id":436},"action":"A","side":"A","price":"1.156670000","size":30,"channel_id":23,"order_id":"1775527446092232692","flags":128,"ts_in_delta":952,"sequence":144113,"symbol":"FCEU SI 20260615 PS"}
{"ts_recv":"2026-04-07T02:04:23.988838330Z","hd":{"ts_event":"2026-04-07T02:04:23.988815163Z","rtype":160,"publisher_id":101,"instrument_id":436},"action":"C","side":"B","price":"1.156570000","size":30,"channel_id":23,"order_id":"10998899482947008500","flags":0,"ts_in_delta":898,"sequence":144250,"symbol":"FCEU SI 20260615 PS"}
{"ts_recv":"2026-04-07T02:04:23.988838330Z","hd":{"ts_event":"2026-04-07T02:04:23.988815163Z","rtype":160,"publisher_id":101,"instrument_id":436},"action":"A","side":"B","price":"1.156580000","size":30,"channel_id":23,"order_id":"10998899500843596991","flags":0,"ts_in_delta":898,"sequence":144250,"symbol":"FCEU SI 20260615 PS"}
{"ts_recv":"2026-04-07T02:04:23.988838330Z","hd":{"ts_event":"2026-04-07T02:04:23.988815163Z","rtype":160,"publisher_id":101,"instrument_id":436},"action":"C","side":"A","price":"1.156670000","size":30,"channel_id":23,"order_id":"1775527446092232692","flags":0,"ts_in_delta":898,"sequence":144250,"symbol":"FCEU SI 20260615 PS"}
{"ts_recv":"2026-04-07T02:04:23.988838330Z","hd":{"ts_event":"2026-04-07T02:04:23.988815163Z","rtype":160,"publisher_id":101,"instrument_id":436},"action":"A","side":"A","price":"1.156680000","size":30,"channel_id":23,"order_id":"1775527463988821183","flags":128,"ts_in_delta":898,"sequence":144250,"symbol":"FCEU SI 20260615 PS"}
{"ts_recv":"2026-04-07T02:04:29.098560605Z","hd":{"ts_event":"2026-04-07T02:04:29.098538629Z","rtype":160,"publisher_id":101,"instrument_id":436},"action":"C","side":"B","price":"1.156570000","size":30,"channel_id":23,"order_id":"10998899482946951106","flags":0,"ts_in_delta":920,"sequence":144269,"symbol":"FCEU SI 20260615 PS"}
{"ts_recv":"2026-04-07T02:04:29.098560605Z","hd":{"ts_event":"2026-04-07T02:04:29.098538629Z","rtype":160,"publisher_id":101,"instrument_id":436},"action":"A","side":"B","price":"1.156590000","size":30,"channel_id":23,"order_id":"10998899505953320602","flags":0,"ts_in_delta":920,"sequence":144269,"symbol":"FCEU SI 20260615 PS"}
{"ts_recv":"2026-04-07T02:04:29.098560605Z","hd":{"ts_event":"2026-04-07T02:04:29.098538629Z","rtype":160,"publisher_id":101,"instrument_id":436},"action":"C","side":"A","price":"1.156670000","size":30,"channel_id":23,"order_id":"1775527446092175298","flags":0,"ts_in_delta":920,"sequence":144269,"symbol":"FCEU SI 20260615 PS"}
{"ts_recv":"2026-04-07T02:04:29.098560605Z","hd":{"ts_event":"2026-04-07T02:04:29.098538629Z","rtype":160,"publisher_id":101,"instrument_id":436},"action":"A","side":"A","price":"1.156690000","size":30,"channel_id":23,"order_id":"1775527469098544794","flags":128,"ts_in_delta":920,"sequence":144269,"symbol":"FCEU SI 20260615 PS"}
{"ts_recv":"2026-04-07T02:04:29.098639598Z","hd":{"ts_event":"2026-04-07T02:04:29.098618265Z","rtype":160,"publisher_id":101,"instrument_id":436},"action":"C","side":"B","price":"1.156580000","size":30,"channel_id":23,"order_id":"10998899500843596991","flags":0,"ts_in_delta":930,"sequence":144270,"symbol":"FCEU SI 20260615 PS"}
{"ts_recv":"2026-04-07T02:04:29.098639598Z","hd":{"ts_event":"2026-04-07T02:04:29.098618265Z","rtype":160,"publisher_id":101,"instrument_id":436},"action":"A","side":"B","price":"1.156590000","size":30,"channel_id":23,"order_id":"10998899505953400166","flags":0,"ts_in_delta":930,"sequence":144270,"symbol":"FCEU SI 20260615 PS"}
{"ts_recv":"2026-04-07T02:04:29.098639598Z","hd":{"ts_event":"2026-04-07T02:04:29.098618265Z","rtype":160,"publisher_id":101,"instrument_id":436},"action":"C","side":"A","price":"1.156680000","size":30,"channel_id":23,"order_id":"1775527463988821183","flags":0,"ts_in_delta":930,"sequence":144270,"symbol":"FCEU SI 20260615 PS"}
{"ts_recv":"2026-04-07T02:04:29.098639598Z","hd":{"ts_event":"2026-04-07T02:04:29.098618265Z","rtype":160,"publisher_id":101,"instrument_id":436},"action":"A","side":"A","price":"1.156690000","size":30,"channel_id":23,"order_id":"1775527469098624358","flags":128,"ts_in_delta":930,"sequence":144270,"symbol":"FCEU SI 20260615 PS"}
{"ts_recv":"2026-04-07T02:04:29.589532386Z","hd":{"ts_event":"2026-04-07T02:04:29.589511573Z","rtype":160,"publisher_id":101,"instrument_id":436},"action":"C","side":"B","price":"1.156590000","size":30,"channel_id":23,"order_id":"10998899505953400166","flags":0,"ts_in_delta":1095,"sequence":144308,"symbol":"FCEU SI 20260615 PS"}
{"ts_recv":"2026-04-07T02:04:29.589532386Z","hd":{"ts_event":"2026-04-07T02:04:29.589511573Z","rtype":160,"publisher_id":101,"instrument_id":436},"action":"A","side":"B","price":"1.156600000","size":30,"channel_id":23,"order_id":"10998899506444293327","flags":0,"ts_in_delta":1095,"sequence":144308,"symbol":"FCEU SI 20260615 PS"}
{"ts_recv":"2026-04-07T02:04:29.589532386Z","hd":{"ts_event":"2026-04-07T02:04:29.589511573Z","rtype":160,"publisher_id":101,"instrument_id":436},"action":"C","side":"A","price":"1.156690000","size":30,"channel_id":23,"order_id":"1775527469098624358","flags":0,"ts_in_delta":1095,"sequence":144308,"symbol":"FCEU SI 20260615 PS"}
{"ts_recv":"2026-04-07T02:04:29.589532386Z","hd":{"ts_event":"2026-04-07T02:04:29.589511573Z","rtype":160,"publisher_id":101,"instrument_id":436},"action":"A","side":"A","price":"1.156700000","size":30,"channel_id":23,"order_id":"1775527469589517519","flags":128,"ts_in_delta":1095,"sequence":144308,"symbol":"FCEU SI 20260615 PS"}
{"ts_recv":"2026-04-07T02:04:29.589588916Z","hd":{"ts_event":"2026-04-07T02:04:29.589567293Z","rtype":160,"publisher_id":101,"instrument_id":436},"action":"C","side":"B","price":"1.156590000","size":30,"channel_id":23,"order_id":"10998899505953320602","flags":0,"ts_in_delta":946,"sequence":144309,"symbol":"FCEU SI 20260615 PS"}
{"ts_recv":"2026-04-07T02:04:29.589588916Z","hd":{"ts_event":"2026-04-07T02:04:29.589567293Z","rtype":160,"publisher_id":101,"instrument_id":436},"action":"A","side":"B","price":"1.156610000","size":30,"channel_id":23,"order_id":"10998899506444349271","flags":0,"ts_in_delta":946,"sequence":144309,"symbol":"FCEU SI 20260615 PS"}
{"ts_recv":"2026-04-07T02:04:29.589588916Z","hd":{"ts_event":"2026-04-07T02:04:29.589567293Z","rtype":160,"publisher_id":101,"instrument_id":436},"action":"C","side":"A","price":"1.156690000","size":30,"channel_id":23,"order_id":"1775527469098544794","flags":0,"ts_in_delta":946,"sequence":144309,"symbol":"FCEU SI 20260615 PS"}
{"ts_recv":"2026-04-07T02:04:29.589588916Z","hd":{"ts_event":"2026-04-07T02:04:29.589567293Z","rtype":160,"publisher_id":101,"instrument_id":436},"action":"A","side":"A","price":"1.156710000","size":30,"channel_id":23,"order_id":"1775527469589573463","flags":128,"ts_in_delta":946,"sequence":144309,"symbol":"FCEU SI 20260615 PS"}
{"ts_recv":"2026-04-07T02:04:29.589645868Z","hd":{"ts_event":"2026-04-07T02:04:29.589627119Z","rtype":160,"publisher_id":101,"instrument_id":436},"action":"C","side":"B","price":"1.156600000","size":30,"channel_id":23,"order_id":"10998899506444293327","flags":0,"ts_in_delta":926,"sequence":144310,"symbol":"FCEU SI 20260615 PS"}
{"ts_recv":"2026-04-07T02:04:29.589645868Z","hd":{"ts_event":"2026-04-07T02:04:29.589627119Z","rtype":160,"publisher_id":101,"instrument_id":436},"action":"A","side":"B","price":"1.156610000","size":30,"channel_id":23,"order_id":"10998899506444409665","flags":0,"ts_in_delta":926,"sequence":144310,"symbol":"FCEU SI 20260615 PS"}
{"ts_recv":"2026-04-07T02:04:29.589645868Z","hd":{"ts_event":"2026-04-07T02:04:29.589627119Z","rtype":160,"publisher_id":101,"instrument_id":436},"action":"C","side":"A","price":"1.156700000","size":30,"channel_id":23,"order_id":"1775527469589517519","flags":0,"ts_in_delta":926,"sequence":144310,"symbol":"FCEU SI 20260615 PS"}
{"ts_recv":"2026-04-07T02:04:29.589645868Z","hd":{"ts_event":"2026-04-07T02:04:29.589627119Z","rtype":160,"publisher_id":101,"instrument_id":436},"action":"A","side":"A","price":"1.156710000","size":30,"channel_id":23,"order_id":"1775527469589633857","flags":128,"ts_in_delta":926,"sequence":144310,"symbol":"FCEU SI 20260615 PS"}
{"ts_recv":"2026-04-07T02:04:33.540554851Z","hd":{"ts_event":"2026-04-07T02:04:33.540535221Z","rtype":160,"publisher_id":101,"instrument_id":436},"action":"C","side":"B","price":"1.156610000","size":30,"channel_id":23,"order_id":"10998899506444409665","flags":0,"ts_in_delta":1039,"sequence":144361,"symbol":"FCEU SI 20260615 PS"}
{"ts_recv":"2026-04-07T02:04:33.540554851Z","hd":{"ts_event":"2026-04-07T02:04:33.540535221Z","rtype":160,"publisher_id":101,"instrument_id":436},"action":"A","side":"B","price":"1.156600000","size":30,"channel_id":23,"order_id":"10998899510395316990","flags":0,"ts_in_delta":1039,"sequence":144361,"symbol":"FCEU SI 20260615 PS"}
{"ts_recv":"2026-04-07T02:04:33.540554851Z","hd":{"ts_event":"2026-04-07T02:04:33.540535221Z","rtype":160,"publisher_id":101,"instrument_id":436},"action":"C","side":"A","price":"1.156710000","size":30,"channel_id":23,"order_id":"1775527469589633857","flags":0,"ts_in_delta":1039,"sequence":144361,"symbol":"FCEU SI 20260615 PS"}
{"ts_recv":"2026-04-07T02:04:33.540554851Z","hd":{"ts_event":"2026-04-07T02:04:33.540535221Z","rtype":160,"publisher_id":101,"instrument_id":436},"action":"A","side":"A","price":"1.156700000","size":30,"channel_id":23,"order_id":"1775527473540541182","flags":128,"ts_in_delta":1039,"sequence":144361,"symbol":"FCEU SI 20260615 PS"}
{"ts_recv":"2026-04-07T02:04:33.740979015Z","hd":{"ts_event":"2026-04-07T02:04:33.740962499Z","rtype":160,"publisher_id":101,"instrument_id":436},"action":"C","side":"B","price":"1.156600000","size":30,"channel_id":23,"order_id":"10998899510395316990","flags":0,"ts_in_delta":971,"sequence":144390,"symbol":"FCEU SI 20260615 PS"}
{"ts_recv":"2026-04-07T02:04:33.740979015Z","hd":{"ts_event":"2026-04-07T02:04:33.740962499Z","rtype":160,"publisher_id":101,"instrument_id":436},"action":"A","side":"B","price":"1.156610000","size":30,"channel_id":23,"order_id":"10998899510595744366","flags":0,"ts_in_delta":971,"sequence":144390,"symbol":"FCEU SI 20260615 PS"}
{"ts_recv":"2026-04-07T02:04:33.740979015Z","hd":{"ts_event":"2026-04-07T02:04:33.740962499Z","rtype":160,"publisher_id":101,"instrument_id":436},"action":"C","side":"A","price":"1.156700000","size":30,"channel_id":23,"order_id":"1775527473540541182","flags":0,"ts_in_delta":971,"sequence":144390,"symbol":"FCEU SI 20260615 PS"}
{"ts_recv":"2026-04-07T02:04:33.740979015Z","hd":{"ts_event":"2026-04-07T02:04:33.740962499Z","rtype":160,"publisher_id":101,"instrument_id":436},"action":"A","side":"A","price":"1.156710000","size":30,"channel_id":23,"order_id":"1775527473740968558","flags":128,"ts_in_delta":971,"sequence":144390,"symbol":"FCEU SI 20260615 PS"}
{"ts_recv":"2026-04-07T02:04:36.050987141Z","hd":{"ts_event":"2026-04-07T02:04:36.050966401Z","rtype":160,"publisher_id":101,"instrument_id":436},"action":"C","side":"B","price":"1.156610000","size":30,"channel_id":23,"order_id":"10998899510595744366","flags":0,"ts_in_delta":934,"sequence":144436,"symbol":"FCEU SI 20260615 PS"}
{"ts_recv":"2026-04-07T02:04:36.050987141Z","hd":{"ts_event":"2026-04-07T02:04:36.050966401Z","rtype":160,"publisher_id":101,"instrument_id":436},"action":"A","side":"B","price":"1.156600000","size":30,"channel_id":23,"order_id":"10998899512905748440","flags":0,"ts_in_delta":934,"sequence":144436,"symbol":"FCEU SI 20260615 PS"}
{"ts_recv":"2026-04-07T02:04:36.050987141Z","hd":{"ts_event":"2026-04-07T02:04:36.050966401Z","rtype":160,"publisher_id":101,"instrument_id":436},"action":"C","side":"A","price":"1.156710000","size":30,"channel_id":23,"order_id":"1775527473740968558","flags":0,"ts_in_delta":934,"sequence":144436,"symbol":"FCEU SI 20260615 PS"}
{"ts_recv":"2026-04-07T02:04:36.050987141Z","hd":{"ts_event":"2026-04-07T02:04:36.050966401Z","rtype":160,"publisher_id":101,"instrument_id":436},"action":"A","side":"A","price":"1.156700000","size":30,"channel_id":23,"order_id":"1775527476050972632","flags":128,"ts_in_delta":934,"sequence":144436,"symbol":"FCEU SI 20260615 PS"}
{"ts_recv":"2026-04-07T02:04:36.069239530Z","hd":{"ts_event":"2026-04-07T02:04:36.069220065Z","rtype":160,"publisher_id":101,"instrument_id":436},"action":"C","side":"B","price":"1.156600000","size":30,"channel_id":23,"order_id":"10998899512905748440","flags":0,"ts_in_delta":894,"sequence":144437,"symbol":"FCEU SI 20260615 PS"}
{"ts_recv":"2026-04-07T02:04:36.069239530Z","hd":{"ts_event":"2026-04-07T02:04:36.069220065Z","rtype":160,"publisher_id":101,"instrument_id":436},"action":"A","side":"B","price":"1.156610000","size":30,"channel_id":23,"order_id":"10998899512924001691","flags":0,"ts_in_delta":894,"sequence":144437,"symbol":"FCEU SI 20260615 PS"}
{"ts_recv":"2026-04-07T02:04:36.069239530Z","hd":{"ts_event":"2026-04-07T02:04:36.069220065Z","rtype":160,"publisher_id":101,"instrument_id":436},"action":"C","side":"A","price":"1.156700000","size":30,"channel_id":23,"order_id":"1775527476050972632","flags":0,"ts_in_delta":894,"sequence":144437,"symbol":"FCEU SI 20260615 PS"}
{"ts_recv":"2026-04-07T02:04:36.069239530Z","hd":{"ts_event":"2026-04-07T02:04:36.069220065Z","rtype":160,"publisher_id":101,"instrument_id":436},"action":"A","side":"A","price":"1.156710000","size":30,"channel_id":23,"order_id":"1775527476069225883","flags":128,"ts_in_delta":894,"sequence":144437,"symbol":"FCEU SI 20260615 PS"}
{"ts_recv":"2026-04-07T02:04:41.688745011Z","hd":{"ts_event":"2026-04-07T02:04:41.688724719Z","rtype":160,"publisher_id":101,"instrument_id":436},"action":"C","side":"B","price":"1.156610000","size":30,"channel_id":23,"order_id":"10998899512924001691","flags":0,"ts_in_delta":996,"sequence":144497,"symbol":"FCEU SI 20260615 PS"}
{"ts_recv":"2026-04-07T02:04:41.688745011Z","hd":{"ts_event":"2026-04-07T02:04:41.688724719Z","rtype":160,"publisher_id":101,"instrument_id":436},"action":"A","side":"B","price":"1.156600000","size":30,"channel_id":23,"order_id":"10998899518543506561","flags":0,"ts_in_delta":996,"sequence":144497,"symbol":"FCEU SI 20260615 PS"}
{"ts_recv":"2026-04-07T02:04:41.688745011Z","hd":{"ts_event":"2026-04-07T02:04:41.688724719Z","rtype":160,"publisher_id":101,"instrument_id":436},"action":"C","side":"A","price":"1.156710000","size":30,"channel_id":23,"order_id":"1775527476069225883","flags":0,"ts_in_delta":996,"sequence":144497,"symbol":"FCEU SI 20260615 PS"}
{"ts_recv":"2026-04-07T02:04:41.688745011Z","hd":{"ts_event":"2026-04-07T02:04:41.688724719Z","rtype":160,"publisher_id":101,"instrument_id":436},"action":"A","side":"A","price":"1.156700000","size":30,"channel_id":23,"order_id":"1775527481688730753","flags":128,"ts_in_delta":996,"sequence":144497,"symbol":"FCEU SI 20260615 PS"}
{"ts_recv":"2026-04-07T02:04:42.279510169Z","hd":{"ts_event":"2026-04-07T02:04:42.279492223Z","rtype":160,"publisher_id":101,"instrument_id":436},"action":"C","side":"B","price":"1.156600000","size":30,"channel_id":23,"order_id":"10998899518543506561","flags":0,"ts_in_delta":979,"sequence":144508,"symbol":"FCEU SI 20260615 PS"}
{"ts_recv":"2026-04-07T02:04:42.279510169Z","hd":{"ts_event":"2026-04-07T02:04:42.279492223Z","rtype":160,"publisher_id":101,"instrument_id":436},"action":"A","side":"B","price":"1.156610000","size":30,"channel_id":23,"order_id":"10998899519134274185","flags":0,"ts_in_delta":979,"sequence":144508,"symbol":"FCEU SI 20260615 PS"}
{"ts_recv":"2026-04-07T02:04:42.279510169Z","hd":{"ts_event":"2026-04-07T02:04:42.279492223Z","rtype":160,"publisher_id":101,"instrument_id":436},"action":"C","side":"A","price":"1.156700000","size":30,"channel_id":23,"order_id":"1775527481688730753","flags":0,"ts_in_delta":979,"sequence":144508,"symbol":"FCEU SI 20260615 PS"}
{"ts_recv":"2026-04-07T02:04:42.279510169Z","hd":{"ts_event":"2026-04-07T02:04:42.279492223Z","rtype":160,"publisher_id":101,"instrument_id":436},"action":"A","side":"A","price":"1.156710000","size":30,"channel_id":23,"order_id":"1775527482279498377","flags":128,"ts_in_delta":979,"sequence":144508,"symbol":"FCEU SI 20260615 PS"}
{"ts_recv":"2026-04-07T02:04:43.585138148Z","hd":{"ts_event":"2026-04-07T02:04:43.585113081Z","rtype":160,"publisher_id":101,"instrument_id":436},"action":"C","side":"B","price":"1.156610000","size":30,"channel_id":23,"order_id":"10998899519134274185","flags":0,"ts_in_delta":1815,"sequence":144519,"symbol":"FCEU SI 20260615 PS"}
{"ts_recv":"2026-04-07T02:04:43.585138148Z","hd":{"ts_event":"2026-04-07T02:04:43.585113081Z","rtype":160,"publisher_id":101,"instrument_id":436},"action":"A","side":"B","price":"1.156600000","size":30,"channel_id":23,"order_id":"10998899520439897119","flags":0,"ts_in_delta":1815,"sequence":144519,"symbol":"FCEU SI 20260615 PS"}
{"ts_recv":"2026-04-07T02:04:43.585138148Z","hd":{"ts_event":"2026-04-07T02:04:43.585113081Z","rtype":160,"publisher_id":101,"instrument_id":436},"action":"C","side":"A","price":"1.156710000","size":30,"channel_id":23,"order_id":"1775527482279498377","flags":0,"ts_in_delta":1815,"sequence":144519,"symbol":"FCEU SI 20260615 PS"}
{"ts_recv":"2026-04-07T02:04:43.585138148Z","hd":{"ts_event":"2026-04-07T02:04:43.585113081Z","rtype":160,"publisher_id":101,"instrument_id":436},"action":"A","side":"A","price":"1.156700000","size":30,"channel_id":23,"order_id":"1775527483585121311","flags":128,"ts_in_delta":1815,"sequence":144519,"symbol":"FCEU SI 20260615 PS"}
{"ts_recv":"2026-04-07T02:04:43.586341818Z","hd":{"ts_event":"2026-04-07T02:04:43.586320339Z","rtype":160,"publisher_id":101,"instrument_id":436},"action":"C","side":"B","price":"1.156610000","size":30,"channel_id":23,"order_id":"10998899506444349271","flags":0,"ts_in_delta":936,"sequence":144521,"symbol":"FCEU SI 20260615 PS"}
{"ts_recv":"2026-04-07T02:04:43.586341818Z","hd":{"ts_event":"2026-04-07T02:04:43.586320339Z","rtype":160,"publisher_id":101,"instrument_id":436},"action":"A","side":"B","price":"1.156590000","size":30,"channel_id":23,"order_id":"10998899520441102933","flags":0,"ts_in_delta":936,"sequence":144521,"symbol":"FCEU SI 20260615 PS"}
{"ts_recv":"2026-04-07T02:04:43.586341818Z","hd":{"ts_event":"2026-04-07T02:04:43.586320339Z","rtype":160,"publisher_id":101,"instrument_id":436},"action":"C","side":"A","price":"1.156710000","size":30,"channel_id":23,"order_id":"1775527469589573463","flags":0,"ts_in_delta":936,"sequence":144521,"symbol":"FCEU SI 20260615 PS"}
{"ts_recv":"2026-04-07T02:04:43.586341818Z","hd":{"ts_event":"2026-04-07T02:04:43.586320339Z","rtype":160,"publisher_id":101,"instrument_id":436},"action":"A","side":"A","price":"1.156690000","size":30,"channel_id":23,"order_id":"1775527483586327125","flags":128,"ts_in_delta":936,"sequence":144521,"symbol":"FCEU SI 20260615 PS"}
{"ts_recv":"2026-04-07T02:04:43.586405199Z","hd":{"ts_event":"2026-04-07T02:04:43.586388041Z","rtype":160,"publisher_id":101,"instrument_id":436},"action":"C","side":"B","price":"1.156600000","size":30,"channel_id":23,"order_id":"10998899520439897119","flags":0,"ts_in_delta":1063,"sequence":144522,"symbol":"FCEU SI 20260615 PS"}
{"ts_recv":"2026-04-07T02:04:43.586405199Z","hd":{"ts_event":"2026-04-07T02:04:43.586388041Z","rtype":160,"publisher_id":101,"instrument_id":436},"action":"A","side":"B","price":"1.156590000","size":30,"channel_id":23,"order_id":"10998899520441169843","flags":0,"ts_in_delta":1063,"sequence":144522,"symbol":"FCEU SI 20260615 PS"}
{"ts_recv":"2026-04-07T02:04:43.586405199Z","hd":{"ts_event":"2026-04-07T02:04:43.586388041Z","rtype":160,"publisher_id":101,"instrument_id":436},"action":"C","side":"A","price":"1.156700000","size":30,"channel_id":23,"order_id":"1775527483585121311","flags":0,"ts_in_delta":1063,"sequence":144522,"symbol":"FCEU SI 20260615 PS"}
{"ts_recv":"2026-04-07T02:04:43.586405199Z","hd":{"ts_event":"2026-04-07T02:04:43.586388041Z","rtype":160,"publisher_id":101,"instrument_id":436},"action":"A","side":"A","price":"1.156690000","size":30,"channel_id":23,"order_id":"1775527483586394035","flags":128,"ts_in_delta":1063,"sequence":144522,"symbol":"FCEU SI 20260615 PS"}
{"ts_recv":"2026-04-07T02:04:43.589886583Z","hd":{"ts_event":"2026-04-07T02:04:43.589868745Z","rtype":160,"publisher_id":101,"instrument_id":436},"action":"C","side":"B","price":"1.156590000","size":30,"channel_id":23,"order_id":"10998899520441169843","flags":0,"ts_in_delta":947,"sequence":144526,"symbol":"FCEU SI 20260615 PS"}
{"ts_recv":"2026-04-07T02:04:43.589886583Z","hd":{"ts_event":"2026-04-07T02:04:43.589868745Z","rtype":160,"publisher_id":101,"instrument_id":436},"action":"A","side":"B","price":"1.156580000","size":30,"channel_id":23,"order_id":"10998899520444650849","flags":0,"ts_in_delta":947,"sequence":144526,"symbol":"FCEU SI 20260615 PS"}
{"ts_recv":"2026-04-07T02:04:43.589886583Z","hd":{"ts_event":"2026-04-07T02:04:43.589868745Z","rtype":160,"publisher_id":101,"instrument_id":436},"action":"C","side":"A","price":"1.156690000","size":30,"channel_id":23,"order_id":"1775527483586394035","flags":0,"ts_in_delta":947,"sequence":144526,"symbol":"FCEU SI 20260615 PS"}
{"ts_recv":"2026-04-07T02:04:43.589886583Z","hd":{"ts_event":"2026-04-07T02:04:43.589868745Z","rtype":160,"publisher_id":101,"instrument_id":436},"action":"A","side":"A","price":"1.156680000","size":30,"channel_id":23,"order_id":"1775527483589875041","flags":128,"ts_in_delta":947,"sequence":144526,"symbol":"FCEU SI 20260615 PS"}
{"ts_recv":"2026-04-07T02:04:43.633479888Z","hd":{"ts_event":"2026-04-07T02:04:43.633458467Z","rtype":160,"publisher_id":101,"instrument_id":436},"action":"C","side":"B","price":"1.156590000","size":30,"channel_id":23,"order_id":"10998899520441102933","flags":0,"ts_in_delta":953,"sequence":144539,"symbol":"FCEU SI 20260615 PS"}
{"ts_recv":"2026-04-07T02:04:43.633479888Z","hd":{"ts_event":"2026-04-07T02:04:43.633458467Z","rtype":160,"publisher_id":101,"instrument_id":436},"action":"A","side":"B","price":"1.156570000","size":30,"channel_id":23,"order_id":"10998899520488240623","flags":0,"ts_in_delta":953,"sequence":144539,"symbol":"FCEU SI 20260615 PS"}
{"ts_recv":"2026-04-07T02:04:43.633479888Z","hd":{"ts_event":"2026-04-07T02:04:43.633458467Z","rtype":160,"publisher_id":101,"instrument_id":436},"action":"C","side":"A","price":"1.156690000","size":30,"channel_id":23,"order_id":"1775527483586327125","flags":0,"ts_in_delta":953,"sequence":144539,"symbol":"FCEU SI 20260615 PS"}
{"ts_recv":"2026-04-07T02:04:43.633479888Z","hd":{"ts_event":"2026-04-07T02:04:43.633458467Z","rtype":160,"publisher_id":101,"instrument_id":436},"action":"A","side":"A","price":"1.156670000","size":30,"channel_id":23,"order_id":"1775527483633464815","flags":128,"ts_in_delta":953,"sequence":144539,"symbol":"FCEU SI 20260615 PS"}
{"ts_recv":"2026-04-07T02:04:43.633540627Z","hd":{"ts_event":"2026-04-07T02:04:43.633525015Z","rtype":160,"publisher_id":101,"instrument_id":436},"action":"C","side":"B","price":"1.156580000","size":30,"channel_id":23,"order_id":"10998899520444650849","flags":0,"ts_in_delta":929,"sequence":144540,"symbol":"FCEU SI 20260615 PS"}
{"ts_recv":"2026-04-07T02:04:43.633540627Z","hd":{"ts_event":"2026-04-07T02:04:43.633525015Z","rtype":160,"publisher_id":101,"instrument_id":436},"action":"A","side":"B","price":"1.156570000","size":30,"channel_id":23,"order_id":"10998899520488306641","flags":0,"ts_in_delta":929,"sequence":144540,"symbol":"FCEU SI 20260615 PS"}
{"ts_recv":"2026-04-07T02:04:43.633540627Z","hd":{"ts_event":"2026-04-07T02:04:43.633525015Z","rtype":160,"publisher_id":101,"instrument_id":436},"action":"C","side":"A","price":"1.156680000","size":30,"channel_id":23,"order_id":"1775527483589875041","flags":0,"ts_in_delta":929,"sequence":144540,"symbol":"FCEU SI 20260615 PS"}
{"ts_recv":"2026-04-07T02:04:43.633540627Z","hd":{"ts_event":"2026-04-07T02:04:43.633525015Z","rtype":160,"publisher_id":101,"instrument_id":436},"action":"A","side":"A","price":"1.156670000","size":30,"channel_id":23,"order_id":"1775527483633530833","flags":128,"ts_in_delta":929,"sequence":144540,"symbol":"FCEU SI 20260615 PS"}
{"ts_recv":"2026-04-07T02:04:56.533898479Z","hd":{"ts_event":"2026-04-07T02:04:56.533869257Z","rtype":160,"publisher_id":101,"instrument_id":436},"action":"C","side":"B","price":"1.156570000","size":30,"channel_id":23,"order_id":"10998899520488306641","flags":0,"ts_in_delta":1314,"sequence":144600,"symbol":"FCEU SI 20260615 PS"}
{"ts_recv":"2026-04-07T02:04:56.533898479Z","hd":{"ts_event":"2026-04-07T02:04:56.533869257Z","rtype":160,"publisher_id":101,"instrument_id":436},"action":"A","side":"B","price":"1.156560000","size":30,"channel_id":23,"order_id":"10998899533388655788","flags":0,"ts_in_delta":1314,"sequence":144600,"symbol":"FCEU SI 20260615 PS"}
{"ts_recv":"2026-04-07T02:04:56.533898479Z","hd":{"ts_event":"2026-04-07T02:04:56.533869257Z","rtype":160,"publisher_id":101,"instrument_id":436},"action":"C","side":"A","price":"1.156670000","size":30,"channel_id":23,"order_id":"1775527483633530833","flags":0,"ts_in_delta":1314,"sequence":144600,"symbol":"FCEU SI 20260615 PS"}
{"ts_recv":"2026-04-07T02:04:56.533898479Z","hd":{"ts_event":"2026-04-07T02:04:56.533869257Z","rtype":160,"publisher_id":101,"instrument_id":436},"action":"A","side":"A","price":"1.156660000","size":30,"channel_id":23,"order_id":"1775527496533879980","flags":128,"ts_in_delta":1314,"sequence":144600,"symbol":"FCEU SI 20260615 PS"}
{"ts_recv":"2026-04-07T02:04:56.533965330Z","hd":{"ts_event":"2026-04-07T02:04:56.533944061Z","rtype":160,"publisher_id":101,"instrument_id":436},"action":"C","side":"B","price":"1.156570000","size":30,"channel_id":23,"order_id":"10998899520488240623","flags":0,"ts_in_delta":891,"sequence":144601,"symbol":"FCEU SI 20260615 PS"}
{"ts_recv":"2026-04-07T02:04:56.533965330Z","hd":{"ts_event":"2026-04-07T02:04:56.533944061Z","rtype":160,"publisher_id":101,"instrument_id":436},"action":"A","side":"B","price":"1.156550000","size":30,"channel_id":23,"order_id":"10998899533388726607","flags":0,"ts_in_delta":891,"sequence":144601,"symbol":"FCEU SI 20260615 PS"}
{"ts_recv":"2026-04-07T02:04:56.533965330Z","hd":{"ts_event":"2026-04-07T02:04:56.533944061Z","rtype":160,"publisher_id":101,"instrument_id":436},"action":"C","side":"A","price":"1.156670000","size":30,"channel_id":23,"order_id":"1775527483633464815","flags":0,"ts_in_delta":891,"sequence":144601,"symbol":"FCEU SI 20260615 PS"}
{"ts_recv":"2026-04-07T02:04:56.533965330Z","hd":{"ts_event":"2026-04-07T02:04:56.533944061Z","rtype":160,"publisher_id":101,"instrument_id":436},"action":"A","side":"A","price":"1.156650000","size":30,"channel_id":23,"order_id":"1775527496533950799","flags":128,"ts_in_delta":891,"sequence":144601,"symbol":"FCEU SI 20260615 PS"}
{"ts_recv":"2026-04-07T02:04:56.534027889Z","hd":{"ts_event":"2026-04-07T02:04:56.534010473Z","rtype":160,"publisher_id":101,"instrument_id":436},"action":"C","side":"B","price":"1.156560000","size":30,"channel_id":23,"order_id":"10998899533388655788","flags":0,"ts_in_delta":881,"sequence":144602,"symbol":"FCEU SI 20260615 PS"}
{"ts_recv":"2026-04-07T02:04:56.534027889Z","hd":{"ts_event":"2026-04-07T02:04:56.534010473Z","rtype":160,"publisher_id":101,"instrument_id":436},"action":"A","side":"B","price":"1.156550000","size":30,"channel_id":23,"order_id":"10998899533388792523","flags":0,"ts_in_delta":881,"sequence":144602,"symbol":"FCEU SI 20260615 PS"}
{"ts_recv":"2026-04-07T02:04:56.534027889Z","hd":{"ts_event":"2026-04-07T02:04:56.534010473Z","rtype":160,"publisher_id":101,"instrument_id":436},"action":"C","side":"A","price":"1.156660000","size":30,"channel_id":23,"order_id":"1775527496533879980","flags":0,"ts_in_delta":881,"sequence":144602,"symbol":"FCEU SI 20260615 PS"}
{"ts_recv":"2026-04-07T02:04:56.534027889Z","hd":{"ts_event":"2026-04-07T02:04:56.534010473Z","rtype":160,"publisher_id":101,"instrument_id":436},"action":"A","side":"A","price":"1.156650000","size":30,"channel_id":23,"order_id":"1775527496534016715","flags":128,"ts_in_delta":881,"sequence":144602,"symbol":"FCEU SI 20260615 PS"}
{"ts_recv":"2026-04-07T02:05:16.711541939Z","hd":{"ts_event":"2026-04-07T02:05:16.711510175Z","rtype":160,"publisher_id":101,"instrument_id":436},"action":"C","side":"B","price":"1.156550000","size":30,"channel_id":23,"order_id":"10998899533388792523","flags":0,"ts_in_delta":1405,"sequence":144836,"symbol":"FCEU SI 20260615 PS"}
{"ts_recv":"2026-04-07T02:05:16.711541939Z","hd":{"ts_event":"2026-04-07T02:05:16.711510175Z","rtype":160,"publisher_id":101,"instrument_id":436},"action":"A","side":"B","price":"1.156540000","size":30,"channel_id":23,"order_id":"10998899553566298879","flags":0,"ts_in_delta":1405,"sequence":144836,"symbol":"FCEU SI 20260615 PS"}
{"ts_recv":"2026-04-07T02:05:16.711541939Z","hd":{"ts_event":"2026-04-07T02:05:16.711510175Z","rtype":160,"publisher_id":101,"instrument_id":436},"action":"C","side":"A","price":"1.156650000","size":30,"channel_id":23,"order_id":"1775527496534016715","flags":0,"ts_in_delta":1405,"sequence":144836,"symbol":"FCEU SI 20260615 PS"}
{"ts_recv":"2026-04-07T02:05:16.711541939Z","hd":{"ts_event":"2026-04-07T02:05:16.711510175Z","rtype":160,"publisher_id":101,"instrument_id":436},"action":"A","side":"A","price":"1.156640000","size":30,"channel_id":23,"order_id":"1775527516711523071","flags":128,"ts_in_delta":1405,"sequence":144836,"symbol":"FCEU SI 20260615 PS"}
{"ts_recv":"2026-04-07T02:05:16.711624380Z","hd":{"ts_event":"2026-04-07T02:05:16.711606421Z","rtype":160,"publisher_id":101,"instrument_id":436},"action":"C","side":"B","price":"1.156540000","size":30,"channel_id":23,"order_id":"10998899553566298879","flags":0,"ts_in_delta":986,"sequence":144837,"symbol":"FCEU SI 20260615 PS"}
{"ts_recv":"2026-04-07T02:05:16.711624380Z","hd":{"ts_event":"2026-04-07T02:05:16.711606421Z","rtype":160,"publisher_id":101,"instrument_id":436},"action":"A","side":"B","price":"1.156530000","size":30,"channel_id":23,"order_id":"10998899553566388221","flags":0,"ts_in_delta":986,"sequence":144837,"symbol":"FCEU SI 20260615 PS"}
{"ts_recv":"2026-04-07T02:05:16.711624380Z","hd":{"ts_event":"2026-04-07T02:05:16.711606421Z","rtype":160,"publisher_id":101,"instrument_id":436},"action":"C","side":"A","price":"1.156640000","size":30,"channel_id":23,"order_id":"1775527516711523071","flags":0,"ts_in_delta":986,"sequence":144837,"symbol":"FCEU SI 20260615 PS"}
{"ts_recv":"2026-04-07T02:05:16.711624380Z","hd":{"ts_event":"2026-04-07T02:05:16.711606421Z","rtype":160,"publisher_id":101,"instrument_id":436},"action":"A","side":"A","price":"1.156630000","size":30,"channel_id":23,"order_id":"1775527516711612413","flags":128,"ts_in_delta":986,"sequence":144837,"symbol":"FCEU SI 20260615 PS"}
{"ts_recv":"2026-04-07T02:05:16.711674973Z","hd":{"ts_event":"2026-04-07T02:05:16.711658995Z","rtype":160,"publisher_id":101,"instrument_id":436},"action":"C","side":"B","price":"1.156550000","size":30,"channel_id":23,"order_id":"10998899533388726607","flags":0,"ts_in_delta":957,"sequence":144838,"symbol":"FCEU SI 20260615 PS"}
{"ts_recv":"2026-04-07T02:05:16.711674973Z","hd":{"ts_event":"2026-04-07T02:05:16.711658995Z","rtype":160,"publisher_id":101,"instrument_id":436},"action":"A","side":"B","price":"1.156530000","size":30,"channel_id":23,"order_id":"10998899553566440625","flags":0,"ts_in_delta":957,"sequence":144838,"symbol":"FCEU SI 20260615 PS"}
{"ts_recv":"2026-04-07T02:05:16.711674973Z","hd":{"ts_event":"2026-04-07T02:05:16.711658995Z","rtype":160,"publisher_id":101,"instrument_id":436},"action":"C","side":"A","price":"1.156650000","size":30,"channel_id":23,"order_id":"1775527496533950799","flags":0,"ts_in_delta":957,"sequence":144838,"symbol":"FCEU SI 20260615 PS"}
{"ts_recv":"2026-04-07T02:05:16.711674973Z","hd":{"ts_event":"2026-04-07T02:05:16.711658995Z","rtype":160,"publisher_id":101,"instrument_id":436},"action":"A","side":"A","price":"1.156630000","size":30,"channel_id":23,"order_id":"1775527516711664817","flags":128,"ts_in_delta":957,"sequence":144838,"symbol":"FCEU SI 20260615 PS"}
{"ts_recv":"2026-04-07T02:05:16.711688405Z","hd":{"ts_event":"2026-04-07T02:05:16.711666107Z","rtype":160,"publisher_id":101,"instrument_id":436},"action":"C","side":"B","price":"1.156530000","size":30,"channel_id":23,"order_id":"10998899553566388221","flags":0,"ts_in_delta":937,"sequence":144839,"symbol":"FCEU SI 20260615 PS"}
{"ts_recv":"2026-04-07T02:05:16.711688405Z","hd":{"ts_event":"2026-04-07T02:05:16.711666107Z","rtype":160,"publisher_id":101,"instrument_id":436},"action":"A","side":"B","price":"1.156540000","size":30,"channel_id":23,"order_id":"10998899553566448116","flags":0,"ts_in_delta":937,"sequence":144839,"symbol":"FCEU SI 20260615 PS"}
{"ts_recv":"2026-04-07T02:05:16.711688405Z","hd":{"ts_event":"2026-04-07T02:05:16.711666107Z","rtype":160,"publisher_id":101,"instrument_id":436},"action":"C","side":"A","price":"1.156630000","size":30,"channel_id":23,"order_id":"1775527516711612413","flags":0,"ts_in_delta":937,"sequence":144839,"symbol":"FCEU SI 20260615 PS"}
{"ts_recv":"2026-04-07T02:05:16.711688405Z","hd":{"ts_event":"2026-04-07T02:05:16.711666107Z","rtype":160,"publisher_id":101,"instrument_id":436},"action":"A","side":"A","price":"1.156640000","size":30,"channel_id":23,"order_id":"1775527516711672308","flags":128,"ts_in_delta":937,"sequence":144839,"symbol":"FCEU SI 20260615 PS"}
{"ts_recv":"2026-04-07T02:05:16.711745196Z","hd":{"ts_event":"2026-04-07T02:05:16.711725545Z","rtype":160,"publisher_id":101,"instrument_id":436},"action":"C","side":"B","price":"1.156540000","size":30,"channel_id":23,"order_id":"10998899553566448116","flags":0,"ts_in_delta":1147,"sequence":144840,"symbol":"FCEU SI 20260615 PS"}
{"ts_recv":"2026-04-07T02:05:16.711745196Z","hd":{"ts_event":"2026-04-07T02:05:16.711725545Z","rtype":160,"publisher_id":101,"instrument_id":436},"action":"A","side":"B","price":"1.156530000","size":30,"channel_id":23,"order_id":"10998899553566507347","flags":0,"ts_in_delta":1147,"sequence":144840,"symbol":"FCEU SI 20260615 PS"}
{"ts_recv":"2026-04-07T02:05:16.711745196Z","hd":{"ts_event":"2026-04-07T02:05:16.711725545Z","rtype":160,"publisher_id":101,"instrument_id":436},"action":"C","side":"A","price":"1.156640000","size":30,"channel_id":23,"order_id":"1775527516711672308","flags":0,"ts_in_delta":1147,"sequence":144840,"symbol":"FCEU SI 20260615 PS"}
{"ts_recv":"2026-04-07T02:05:16.711745196Z","hd":{"ts_event":"2026-04-07T02:05:16.711725545Z","rtype":160,"publisher_id":101,"instrument_id":436},"action":"A","side":"A","price":"1.156630000","size":30,"channel_id":23,"order_id":"1775527516711731539","flags":128,"ts_in_delta":1147,"sequence":144840,"symbol":"FCEU SI 20260615 PS"}
{"ts_recv":"2026-04-07T02:05:19.084425366Z","hd":{"ts_event":"2026-04-07T02:05:19.084405193Z","rtype":160,"publisher_id":101,"instrument_id":436},"action":"C","side":"B","price":"1.156530000","size":30,"channel_id":23,"order_id":"10998899553566507347","flags":0,"ts_in_delta":965,"sequence":144865,"symbol":"FCEU SI 20260615 PS"}
{"ts_recv":"2026-04-07T02:05:19.084425366Z","hd":{"ts_event":"2026-04-07T02:05:19.084405193Z","rtype":160,"publisher_id":101,"instrument_id":436},"action":"A","side":"B","price":"1.156540000","size":30,"channel_id":23,"order_id":"10998899555939186942","flags":0,"ts_in_delta":965,"sequence":144865,"symbol":"FCEU SI 20260615 PS"}
{"ts_recv":"2026-04-07T02:05:19.084425366Z","hd":{"ts_event":"2026-04-07T02:05:19.084405193Z","rtype":160,"publisher_id":101,"instrument_id":436},"action":"C","side":"A","price":"1.156630000","size":30,"channel_id":23,"order_id":"1775527516711731539","flags":0,"ts_in_delta":965,"sequence":144865,"symbol":"FCEU SI 20260615 PS"}
{"ts_recv":"2026-04-07T02:05:19.084425366Z","hd":{"ts_event":"2026-04-07T02:05:19.084405193Z","rtype":160,"publisher_id":101,"instrument_id":436},"action":"A","side":"A","price":"1.156640000","size":30,"channel_id":23,"order_id":"1775527519084411134","flags":128,"ts_in_delta":965,"sequence":144865,"symbol":"FCEU SI 20260615 PS"}
{"ts_recv":"2026-04-07T02:05:25.139552561Z","hd":{"ts_event":"2026-04-07T02:05:25.139526445Z","rtype":160,"publisher_id":101,"instrument_id":436},"action":"C","side":"B","price":"1.156530000","size":30,"channel_id":23,"order_id":"10998899553566440625","flags":0,"ts_in_delta":967,"sequence":144945,"symbol":"FCEU SI 20260615 PS"}
{"ts_recv":"2026-04-07T02:05:25.139552561Z","hd":{"ts_event":"2026-04-07T02:05:25.139526445Z","rtype":160,"publisher_id":101,"instrument_id":436},"action":"A","side":"B","price":"1.156550000","size":30,"channel_id":23,"order_id":"10998899561994313069","flags":0,"ts_in_delta":967,"sequence":144945,"symbol":"FCEU SI 20260615 PS"}
{"ts_recv":"2026-04-07T02:05:25.139552561Z","hd":{"ts_event":"2026-04-07T02:05:25.139526445Z","rtype":160,"publisher_id":101,"instrument_id":436},"action":"C","side":"A","price":"1.156630000","size":30,"channel_id":23,"order_id":"1775527516711664817","flags":0,"ts_in_delta":967,"sequence":144945,"symbol":"FCEU SI 20260615 PS"}
{"ts_recv":"2026-04-07T02:05:25.139552561Z","hd":{"ts_event":"2026-04-07T02:05:25.139526445Z","rtype":160,"publisher_id":101,"instrument_id":436},"action":"A","side":"A","price":"1.156650000","size":30,"channel_id":23,"order_id":"1775527525139537261","flags":128,"ts_in_delta":967,"sequence":144945,"symbol":"FCEU SI 20260615 PS"}
{"ts_recv":"2026-04-07T02:05:25.139624211Z","hd":{"ts_event":"2026-04-07T02:05:25.139607847Z","rtype":160,"publisher_id":101,"instrument_id":436},"action":"C","side":"B","price":"1.156540000","size":30,"channel_id":23,"order_id":"10998899555939186942","flags":0,"ts_in_delta":926,"sequence":144946,"symbol":"FCEU SI 20260615 PS"}
{"ts_recv":"2026-04-07T02:05:25.139624211Z","hd":{"ts_event":"2026-04-07T02:05:25.139607847Z","rtype":160,"publisher_id":101,"instrument_id":436},"action":"A","side":"B","price":"1.156550000","size":30,"channel_id":23,"order_id":"10998899561994389957","flags":0,"ts_in_delta":926,"sequence":144946,"symbol":"FCEU SI 20260615 PS"}
{"ts_recv":"2026-04-07T02:05:25.139624211Z","hd":{"ts_event":"2026-04-07T02:05:25.139607847Z","rtype":160,"publisher_id":101,"instrument_id":436},"action":"C","side":"A","price":"1.156640000","size":30,"channel_id":23,"order_id":"1775527519084411134","flags":0,"ts_in_delta":926,"sequence":144946,"symbol":"FCEU SI 20260615 PS"}
{"ts_recv":"2026-04-07T02:05:25.139624211Z","hd":{"ts_event":"2026-04-07T02:05:25.139607847Z","rtype":160,"publisher_id":101,"instrument_id":436},"action":"A","side":"A","price":"1.156650000","size":30,"channel_id":23,"order_id":"1775527525139614149","flags":128,"ts_in_delta":926,"sequence":144946,"symbol":"FCEU SI 20260615 PS"}
{"ts_recv":"2026-04-07T02:05:31.346567537Z","hd":{"ts_event":"2026-04-07T02:05:31.346542749Z","rtype":160,"publisher_id":101,"instrument_id":436},"action":"C","side":"B","price":"1.156550000","size":30,"channel_id":23,"order_id":"10998899561994389957","flags":0,"ts_in_delta":1208,"sequence":145014,"symbol":"FCEU SI 20260615 PS"}
{"ts_recv":"2026-04-07T02:05:31.346567537Z","hd":{"ts_event":"2026-04-07T02:05:31.346542749Z","rtype":160,"publisher_id":101,"instrument_id":436},"action":"A","side":"B","price":"1.156560000","size":30,"channel_id":23,"order_id":"10998899568201324818","flags":0,"ts_in_delta":1208,"sequence":145014,"symbol":"FCEU SI 20260615 PS"}
{"ts_recv":"2026-04-07T02:05:31.346567537Z","hd":{"ts_event":"2026-04-07T02:05:31.346542749Z","rtype":160,"publisher_id":101,"instrument_id":436},"action":"C","side":"A","price":"1.156650000","size":30,"channel_id":23,"order_id":"1775527525139614149","flags":0,"ts_in_delta":1208,"sequence":145014,"symbol":"FCEU SI 20260615 PS"}
{"ts_recv":"2026-04-07T02:05:31.346567537Z","hd":{"ts_event":"2026-04-07T02:05:31.346542749Z","rtype":160,"publisher_id":101,"instrument_id":436},"action":"A","side":"A","price":"1.156660000","size":30,"channel_id":23,"order_id":"1775527531346549010","flags":128,"ts_in_delta":1208,"sequence":145014,"symbol":"FCEU SI 20260615 PS"}
{"ts_recv":"2026-04-07T02:05:31.346625565Z","hd":{"ts_event":"2026-04-07T02:05:31.346603197Z","rtype":160,"publisher_id":101,"instrument_id":436},"action":"C","side":"B","price":"1.156550000","size":30,"channel_id":23,"order_id":"10998899561994313069","flags":0,"ts_in_delta":1135,"sequence":145015,"symbol":"FCEU SI 20260615 PS"}
{"ts_recv":"2026-04-07T02:05:31.346625565Z","hd":{"ts_event":"2026-04-07T02:05:31.346603197Z","rtype":160,"publisher_id":101,"instrument_id":436},"action":"A","side":"B","price":"1.156570000","size":30,"channel_id":23,"order_id":"10998899568201385305","flags":0,"ts_in_delta":1135,"sequence":145015,"symbol":"FCEU SI 20260615 PS"}
{"ts_recv":"2026-04-07T02:05:31.346625565Z","hd":{"ts_event":"2026-04-07T02:05:31.346603197Z","rtype":160,"publisher_id":101,"instrument_id":436},"action":"C","side":"A","price":"1.156650000","size":30,"channel_id":23,"order_id":"1775527525139537261","flags":0,"ts_in_delta":1135,"sequence":145015,"symbol":"FCEU SI 20260615 PS"}
{"ts_recv":"2026-04-07T02:05:31.346625565Z","hd":{"ts_event":"2026-04-07T02:05:31.346603197Z","rtype":160,"publisher_id":101,"instrument_id":436},"action":"A","side":"A","price":"1.156670000","size":30,"channel_id":23,"order_id":"1775527531346609497","flags":128,"ts_in_delta":1135,"sequence":145015,"symbol":"FCEU SI 20260615 PS"}
{"ts_recv":"2026-04-07T02:05:31.346681012Z","hd":{"ts_event":"2026-04-07T02:05:31.346661815Z","rtype":160,"publisher_id":101,"instrument_id":436},"action":"C","side":"B","price":"1.156560000","size":30,"channel_id":23,"order_id":"10998899568201324818","flags":0,"ts_in_delta":1092,"sequence":145016,"symbol":"FCEU SI 20260615 PS"}
{"ts_recv":"2026-04-07T02:05:31.346681012Z","hd":{"ts_event":"2026-04-07T02:05:31.346661815Z","rtype":160,"publisher_id":101,"instrument_id":436},"action":"A","side":"B","price":"1.156570000","size":30,"channel_id":23,"order_id":"10998899568201444196","flags":0,"ts_in_delta":1092,"sequence":145016,"symbol":"FCEU SI 20260615 PS"}
{"ts_recv":"2026-04-07T02:05:31.346681012Z","hd":{"ts_event":"2026-04-07T02:05:31.346661815Z","rtype":160,"publisher_id":101,"instrument_id":436},"action":"C","side":"A","price":"1.156660000","size":30,"channel_id":23,"order_id":"1775527531346549010","flags":0,"ts_in_delta":1092,"sequence":145016,"symbol":"FCEU SI 20260615 PS"}
{"ts_recv":"2026-04-07T02:05:31.346681012Z","hd":{"ts_event":"2026-04-07T02:05:31.346661815Z","rtype":160,"publisher_id":101,"instrument_id":436},"action":"A","side":"A","price":"1.156670000","size":30,"channel_id":23,"order_id":"1775527531346668388","flags":128,"ts_in_delta":1092,"sequence":145016,"symbol":"FCEU SI 20260615 PS"}
{"ts_recv":"2026-04-07T02:05:32.306429547Z","hd":{"ts_event":"2026-04-07T02:05:32.306402715Z","rtype":160,"publisher_id":101,"instrument_id":436},"action":"C","side":"B","price":"1.156570000","size":30,"channel_id":23,"order_id":"10998899568201444196","flags":0,"ts_in_delta":1180,"sequence":145035,"symbol":"FCEU SI 20260615 PS"}
{"ts_recv":"2026-04-07T02:05:32.306429547Z","hd":{"ts_event":"2026-04-07T02:05:32.306402715Z","rtype":160,"publisher_id":101,"instrument_id":436},"action":"A","side":"B","price":"1.156560000","size":30,"channel_id":23,"order_id":"10998899569161189862","flags":0,"ts_in_delta":1180,"sequence":145035,"symbol":"FCEU SI 20260615 PS"}
{"ts_recv":"2026-04-07T02:05:32.306429547Z","hd":{"ts_event":"2026-04-07T02:05:32.306402715Z","rtype":160,"publisher_id":101,"instrument_id":436},"action":"C","side":"A","price":"1.156670000","size":30,"channel_id":23,"order_id":"1775527531346668388","flags":0,"ts_in_delta":1180,"sequence":145035,"symbol":"FCEU SI 20260615 PS"}
{"ts_recv":"2026-04-07T02:05:32.306429547Z","hd":{"ts_event":"2026-04-07T02:05:32.306402715Z","rtype":160,"publisher_id":101,"instrument_id":436},"action":"A","side":"A","price":"1.156660000","size":30,"channel_id":23,"order_id":"1775527532306414054","flags":128,"ts_in_delta":1180,"sequence":145035,"symbol":"FCEU SI 20260615 PS"}
{"ts_recv":"2026-04-07T02:05:32.306516197Z","hd":{"ts_event":"2026-04-07T02:05:32.306496201Z","rtype":160,"publisher_id":101,"instrument_id":436},"action":"C","side":"B","price":"1.156560000","size":30,"channel_id":23,"order_id":"10998899569161189862","flags":0,"ts_in_delta":763,"sequence":145036,"symbol":"FCEU SI 20260615 PS"}
{"ts_recv":"2026-04-07T02:05:32.306516197Z","hd":{"ts_event":"2026-04-07T02:05:32.306496201Z","rtype":160,"publisher_id":101,"instrument_id":436},"action":"A","side":"B","price":"1.156550000","size":30,"channel_id":23,"order_id":"10998899569161278028","flags":0,"ts_in_delta":763,"sequence":145036,"symbol":"FCEU SI 20260615 PS"}
{"ts_recv":"2026-04-07T02:05:32.306516197Z","hd":{"ts_event":"2026-04-07T02:05:32.306496201Z","rtype":160,"publisher_id":101,"instrument_id":436},"action":"C","side":"A","price":"1.156660000","size":30,"channel_id":23,"order_id":"1775527532306414054","flags":0,"ts_in_delta":763,"sequence":145036,"symbol":"FCEU SI 20260615 PS"}
{"ts_recv":"2026-04-07T02:05:32.306516197Z","hd":{"ts_event":"2026-04-07T02:05:32.306496201Z","rtype":160,"publisher_id":101,"instrument_id":436},"action":"A","side":"A","price":"1.156650000","size":30,"channel_id":23,"order_id":"1775527532306502220","flags":128,"ts_in_delta":763,"sequence":145036,"symbol":"FCEU SI 20260615 PS"}
{"ts_recv":"2026-04-07T02:05:32.306568119Z","hd":{"ts_event":"2026-04-07T02:05:32.306550807Z","rtype":160,"publisher_id":101,"instrument_id":436},"action":"C","side":"B","price":"1.156570000","size":30,"channel_id":23,"order_id":"10998899568201385305","flags":0,"ts_in_delta":750,"sequence":145037,"symbol":"FCEU SI 20260615 PS"}
{"ts_recv":"2026-04-07T02:05:32.306568119Z","hd":{"ts_event":"2026-04-07T02:05:32.306550807Z","rtype":160,"publisher_id":101,"instrument_id":436},"action":"A","side":"B","price":"1.156550000","size":30,"channel_id":23,"order_id":"10998899569161332922","flags":0,"ts_in_delta":750,"sequence":145037,"symbol":"FCEU SI 20260615 PS"}
{"ts_recv":"2026-04-07T02:05:32.306568119Z","hd":{"ts_event":"2026-04-07T02:05:32.306550807Z","rtype":160,"publisher_id":101,"instrument_id":436},"action":"C","side":"A","price":"1.156670000","size":30,"channel_id":23,"order_id":"1775527531346609497","flags":0,"ts_in_delta":750,"sequence":145037,"symbol":"FCEU SI 20260615 PS"}
