{"ts_recv":"2026-04-07T02:07:57.685511558Z","hd":{"ts_event":"2026-04-07T02:07:57.685481193Z","rtype":160,"publisher_id":101,"instrument_id":436},"action":"C","side":"B","price":"1.156090000","size":30,"channel_id":23,"order_id":"10998899713918063000","flags":0,"ts_in_delta":1758,"sequence":147544,"symbol":"FCEU SI 20260615 PS"}
{"ts_recv":"2026-04-07T02:07:57.685511558Z","hd":{"ts_event":"2026-04-07T02:07:57.685481193Z","rtype":160,"publisher_id":101,"instrument_id":436},"action":"A","side":"B","price":"1.156070000","size":30,"channel_id":23,"order_id":"10998899714540270124","flags":0,"ts_in_delta":1758,"sequence":147544,"symbol":"FCEU SI 20260615 PS"}
{"ts_recv":"2026-04-07T02:07:57.685511558Z","hd":{"ts_event":"2026-04-07T02:07:57.685481193Z","rtype":160,"publisher_id":101,"instrument_id":436},"action":"C","side":"A","price":"1.156190000","size":30,"channel_id":23,"order_id":"1775527677063287192","flags":0,"ts_in_delta":1758,"sequence":147544,"symbol":"FCEU SI 20260615 PS"}
{"ts_recv":"2026-04-07T02:07:57.685511558Z","hd":{"ts_event":"2026-04-07T02:07:57.685481193Z","rtype":160,"publisher_id":101,"instrument_id":436},"action":"A","side":"A","price":"1.156170000","size":30,"channel_id":23,"order_id":"1775527677685494316","flags":128,"ts_in_delta":1758,"sequence":147544,"symbol":"FCEU SI 20260615 PS"}
{"ts_recv":"2026-04-07T02:07:57.685595181Z","hd":{"ts_event":"2026-04-07T02:07:57.685578517Z","rtype":160,"publisher_id":101,"instrument_id":436},"action":"C","side":"B","price":"1.156080000","size":30,"channel_id":23,"order_id":"10998899714130457599","flags":0,"ts_in_delta":1052,"sequence":147545,"symbol":"FCEU SI 20260615 PS"}
{"ts_recv":"2026-04-07T02:07:57.685595181Z","hd":{"ts_event":"2026-04-07T02:07:57.685578517Z","rtype":160,"publisher_id":101,"instrument_id":436},"action":"A","side":"B","price":"1.156070000","size":30,"channel_id":23,"order_id":"10998899714540360466","flags":0,"ts_in_delta":1052,"sequence":147545,"symbol":"FCEU SI 20260615 PS"}
{"ts_recv":"2026-04-07T02:07:57.685595181Z","hd":{"ts_event":"2026-04-07T02:07:57.685578517Z","rtype":160,"publisher_id":101,"instrument_id":436},"action":"C","side":"A","price":"1.156180000","size":30,"channel_id":23,"order_id":"1775527677275681791","flags":0,"ts_in_delta":1052,"sequence":147545,"symbol":"FCEU SI 20260615 PS"}
{"ts_recv":"2026-04-07T02:07:57.685595181Z","hd":{"ts_event":"2026-04-07T02:07:57.685578517Z","rtype":160,"publisher_id":101,"instrument_id":436},"action":"A","side":"A","price":"1.156170000","size":30,"channel_id":23,"order_id":"1775527677685584658","flags":128,"ts_in_delta":1052,"sequence":147545,"symbol":"FCEU SI 20260615 PS"}
{"ts_recv":"2026-04-07T02:07:57.687945637Z","hd":{"ts_event":"2026-04-07T02:07:57.687927745Z","rtype":160,"publisher_id":101,"instrument_id":436},"action":"C","side":"B","price":"1.156070000","size":30,"channel_id":23,"order_id":"10998899714540360466","flags":0,"ts_in_delta":894,"sequence":147546,"symbol":"FCEU SI 20260615 PS"}
{"ts_recv":"2026-04-07T02:07:57.687945637Z","hd":{"ts_event":"2026-04-07T02:07:57.687927745Z","rtype":160,"publisher_id":101,"instrument_id":436},"action":"A","side":"B","price":"1.156060000","size":30,"channel_id":23,"order_id":"10998899714542709265","flags":0,"ts_in_delta":894,"sequence":147546,"symbol":"FCEU SI 20260615 PS"}
{"ts_recv":"2026-04-07T02:07:57.687945637Z","hd":{"ts_event":"2026-04-07T02:07:57.687927745Z","rtype":160,"publisher_id":101,"instrument_id":436},"action":"C","side":"A","price":"1.156170000","size":30,"channel_id":23,"order_id":"1775527677685584658","flags":0,"ts_in_delta":894,"sequence":147546,"symbol":"FCEU SI 20260615 PS"}
{"ts_recv":"2026-04-07T02:07:57.687945637Z","hd":{"ts_event":"2026-04-07T02:07:57.687927745Z","rtype":160,"publisher_id":101,"instrument_id":436},"action":"A","side":"A","price":"1.156160000","size":30,"channel_id":23,"order_id":"1775527677687933457","flags":128,"ts_in_delta":894,"sequence":147546,"symbol":"FCEU SI 20260615 PS"}
{"ts_recv":"2026-04-07T02:07:57.705286597Z","hd":{"ts_event":"2026-04-07T02:07:57.705269223Z","rtype":160,"publisher_id":101,"instrument_id":436},"action":"C","side":"B","price":"1.156060000","size":30,"channel_id":23,"order_id":"10998899714542709265","flags":0,"ts_in_delta":877,"sequence":147549,"symbol":"FCEU SI 20260615 PS"}
{"ts_recv":"2026-04-07T02:07:57.705286597Z","hd":{"ts_event":"2026-04-07T02:07:57.705269223Z","rtype":160,"publisher_id":101,"instrument_id":436},"action":"A","side":"B","price":"1.156070000","size":30,"channel_id":23,"order_id":"10998899714560051015","flags":0,"ts_in_delta":877,"sequence":147549,"symbol":"FCEU SI 20260615 PS"}
{"ts_recv":"2026-04-07T02:07:57.705286597Z","hd":{"ts_event":"2026-04-07T02:07:57.705269223Z","rtype":160,"publisher_id":101,"instrument_id":436},"action":"C","side":"A","price":"1.156160000","size":30,"channel_id":23,"order_id":"1775527677687933457","flags":0,"ts_in_delta":877,"sequence":147549,"symbol":"FCEU SI 20260615 PS"}
{"ts_recv":"2026-04-07T02:07:57.705286597Z","hd":{"ts_event":"2026-04-07T02:07:57.705269223Z","rtype":160,"publisher_id":101,"instrument_id":436},"action":"A","side":"A","price":"1.156170000","size":30,"channel_id":23,"order_id":"1775527677705275207","flags":128,"ts_in_delta":877,"sequence":147549,"symbol":"FCEU SI 20260615 PS"}
{"ts_recv":"2026-04-07T02:07:58.814853355Z","hd":{"ts_event":"2026-04-07T02:07:58.814833537Z","rtype":160,"publisher_id":101,"instrument_id":436},"action":"C","side":"B","price":"1.156070000","size":30,"channel_id":23,"order_id":"10998899714540270124","flags":0,"ts_in_delta":1165,"sequence":147579,"symbol":"FCEU SI 20260615 PS"}
{"ts_recv":"2026-04-07T02:07:58.814853355Z","hd":{"ts_event":"2026-04-07T02:07:58.814833537Z","rtype":160,"publisher_id":101,"instrument_id":436},"action":"A","side":"B","price":"1.156090000","size":30,"channel_id":23,"order_id":"10998899715669615172","flags":0,"ts_in_delta":1165,"sequence":147579,"symbol":"FCEU SI 20260615 PS"}
{"ts_recv":"2026-04-07T02:07:58.814853355Z","hd":{"ts_event":"2026-04-07T02:07:58.814833537Z","rtype":160,"publisher_id":101,"instrument_id":436},"action":"C","side":"A","price":"1.156170000","size":30,"channel_id":23,"order_id":"1775527677685494316","flags":0,"ts_in_delta":1165,"sequence":147579,"symbol":"FCEU SI 20260615 PS"}
{"ts_recv":"2026-04-07T02:07:58.814853355Z","hd":{"ts_event":"2026-04-07T02:07:58.814833537Z","rtype":160,"publisher_id":101,"instrument_id":436},"action":"A","side":"A","price":"1.156190000","size":30,"channel_id":23,"order_id":"1775527678814839364","flags":128,"ts_in_delta":1165,"sequence":147579,"symbol":"FCEU SI 20260615 PS"}
{"ts_recv":"2026-04-07T02:07:58.814947738Z","hd":{"ts_event":"2026-04-07T02:07:58.814930735Z","rtype":160,"publisher_id":101,"instrument_id":436},"action":"C","side":"B","price":"1.156070000","size":30,"channel_id":23,"order_id":"10998899714560051015","flags":0,"ts_in_delta":907,"sequence":147580,"symbol":"FCEU SI 20260615 PS"}
{"ts_recv":"2026-04-07T02:07:58.814947738Z","hd":{"ts_event":"2026-04-07T02:07:58.814930735Z","rtype":160,"publisher_id":101,"instrument_id":436},"action":"A","side":"B","price":"1.156080000","size":30,"channel_id":23,"order_id":"10998899715669712566","flags":0,"ts_in_delta":907,"sequence":147580,"symbol":"FCEU SI 20260615 PS"}
{"ts_recv":"2026-04-07T02:07:58.814947738Z","hd":{"ts_event":"2026-04-07T02:07:58.814930735Z","rtype":160,"publisher_id":101,"instrument_id":436},"action":"C","side":"A","price":"1.156170000","size":30,"channel_id":23,"order_id":"1775527677705275207","flags":0,"ts_in_delta":907,"sequence":147580,"symbol":"FCEU SI 20260615 PS"}
{"ts_recv":"2026-04-07T02:07:58.814947738Z","hd":{"ts_event":"2026-04-07T02:07:58.814930735Z","rtype":160,"publisher_id":101,"instrument_id":436},"action":"A","side":"A","price":"1.156180000","size":30,"channel_id":23,"order_id":"1775527678814936758","flags":128,"ts_in_delta":907,"sequence":147580,"symbol":"FCEU SI 20260615 PS"}
{"ts_recv":"2026-04-07T02:07:58.816547985Z","hd":{"ts_event":"2026-04-07T02:07:58.816532393Z","rtype":160,"publisher_id":101,"instrument_id":436},"action":"C","side":"B","price":"1.156080000","size":30,"channel_id":23,"order_id":"10998899715669712566","flags":0,"ts_in_delta":1090,"sequence":147585,"symbol":"FCEU SI 20260615 PS"}
{"ts_recv":"2026-04-07T02:07:58.816547985Z","hd":{"ts_event":"2026-04-07T02:07:58.816532393Z","rtype":160,"publisher_id":101,"instrument_id":436},"action":"A","side":"B","price":"1.156090000","size":30,"channel_id":23,"order_id":"10998899715671313970","flags":0,"ts_in_delta":1090,"sequence":147585,"symbol":"FCEU SI 20260615 PS"}
{"ts_recv":"2026-04-07T02:07:58.816547985Z","hd":{"ts_event":"2026-04-07T02:07:58.816532393Z","rtype":160,"publisher_id":101,"instrument_id":436},"action":"C","side":"A","price":"1.156180000","size":30,"channel_id":23,"order_id":"1775527678814936758","flags":0,"ts_in_delta":1090,"sequence":147585,"symbol":"FCEU SI 20260615 PS"}
{"ts_recv":"2026-04-07T02:07:58.816547985Z","hd":{"ts_event":"2026-04-07T02:07:58.816532393Z","rtype":160,"publisher_id":101,"instrument_id":436},"action":"A","side":"A","price":"1.156190000","size":30,"channel_id":23,"order_id":"1775527678816538162","flags":128,"ts_in_delta":1090,"sequence":147585,"symbol":"FCEU SI 20260615 PS"}
{"ts_recv":"2026-04-07T02:07:58.828285452Z","hd":{"ts_event":"2026-04-07T02:07:58.828264869Z","rtype":160,"publisher_id":101,"instrument_id":436},"action":"C","side":"B","price":"1.156090000","size":30,"channel_id":23,"order_id":"10998899715669615172","flags":0,"ts_in_delta":760,"sequence":147599,"symbol":"FCEU SI 20260615 PS"}
{"ts_recv":"2026-04-07T02:07:58.828285452Z","hd":{"ts_event":"2026-04-07T02:07:58.828264869Z","rtype":160,"publisher_id":101,"instrument_id":436},"action":"A","side":"B","price":"1.156110000","size":30,"channel_id":23,"order_id":"10998899715683046907","flags":0,"ts_in_delta":760,"sequence":147599,"symbol":"FCEU SI 20260615 PS"}
{"ts_recv":"2026-04-07T02:07:58.828285452Z","hd":{"ts_event":"2026-04-07T02:07:58.828264869Z","rtype":160,"publisher_id":101,"instrument_id":436},"action":"C","side":"A","price":"1.156190000","size":30,"channel_id":23,"order_id":"1775527678814839364","flags":0,"ts_in_delta":760,"sequence":147599,"symbol":"FCEU SI 20260615 PS"}
{"ts_recv":"2026-04-07T02:07:58.828285452Z","hd":{"ts_event":"2026-04-07T02:07:58.828264869Z","rtype":160,"publisher_id":101,"instrument_id":436},"action":"A","side":"A","price":"1.156210000","size":30,"channel_id":23,"order_id":"1775527678828271099","flags":128,"ts_in_delta":760,"sequence":147599,"symbol":"FCEU SI 20260615 PS"}
{"ts_recv":"2026-04-07T02:07:58.828347326Z","hd":{"ts_event":"2026-04-07T02:07:58.828331571Z","rtype":160,"publisher_id":101,"instrument_id":436},"action":"C","side":"B","price":"1.156090000","size":30,"channel_id":23,"order_id":"10998899715671313970","flags":0,"ts_in_delta":749,"sequence":147600,"symbol":"FCEU SI 20260615 PS"}
{"ts_recv":"2026-04-07T02:07:58.828347326Z","hd":{"ts_event":"2026-04-07T02:07:58.828331571Z","rtype":160,"publisher_id":101,"instrument_id":436},"action":"A","side":"B","price":"1.156100000","size":30,"channel_id":23,"order_id":"10998899715683113416","flags":0,"ts_in_delta":749,"sequence":147600,"symbol":"FCEU SI 20260615 PS"}
{"ts_recv":"2026-04-07T02:07:58.828347326Z","hd":{"ts_event":"2026-04-07T02:07:58.828331571Z","rtype":160,"publisher_id":101,"instrument_id":436},"action":"C","side":"A","price":"1.156190000","size":30,"channel_id":23,"order_id":"1775527678816538162","flags":0,"ts_in_delta":749,"sequence":147600,"symbol":"FCEU SI 20260615 PS"}
{"ts_recv":"2026-04-07T02:07:58.828347326Z","hd":{"ts_event":"2026-04-07T02:07:58.828331571Z","rtype":160,"publisher_id":101,"instrument_id":436},"action":"A","side":"A","price":"1.156200000","size":30,"channel_id":23,"order_id":"1775527678828337608","flags":128,"ts_in_delta":749,"sequence":147600,"symbol":"FCEU SI 20260615 PS"}
{"ts_recv":"2026-04-07T02:07:58.834100235Z","hd":{"ts_event":"2026-04-07T02:07:58.834083543Z","rtype":160,"publisher_id":101,"instrument_id":436},"action":"C","side":"B","price":"1.156100000","size":30,"channel_id":23,"order_id":"10998899715683113416","flags":0,"ts_in_delta":745,"sequence":147607,"symbol":"FCEU SI 20260615 PS"}
{"ts_recv":"2026-04-07T02:07:58.834100235Z","hd":{"ts_event":"2026-04-07T02:07:58.834083543Z","rtype":160,"publisher_id":101,"instrument_id":436},"action":"A","side":"B","price":"1.156110000","size":30,"channel_id":23,"order_id":"10998899715688865376","flags":0,"ts_in_delta":745,"sequence":147607,"symbol":"FCEU SI 20260615 PS"}
{"ts_recv":"2026-04-07T02:07:58.834100235Z","hd":{"ts_event":"2026-04-07T02:07:58.834083543Z","rtype":160,"publisher_id":101,"instrument_id":436},"action":"C","side":"A","price":"1.156200000","size":30,"channel_id":23,"order_id":"1775527678828337608","flags":0,"ts_in_delta":745,"sequence":147607,"symbol":"FCEU SI 20260615 PS"}
{"ts_recv":"2026-04-07T02:07:58.834100235Z","hd":{"ts_event":"2026-04-07T02:07:58.834083543Z","rtype":160,"publisher_id":101,"instrument_id":436},"action":"A","side":"A","price":"1.156210000","size":30,"channel_id":23,"order_id":"1775527678834089568","flags":128,"ts_in_delta":745,"sequence":147607,"symbol":"FCEU SI 20260615 PS"}
{"ts_recv":"2026-04-07T02:07:58.911801694Z","hd":{"ts_event":"2026-04-07T02:07:58.911782171Z","rtype":160,"publisher_id":101,"instrument_id":436},"action":"C","side":"B","price":"1.156110000","size":30,"channel_id":23,"order_id":"10998899715688865376","flags":0,"ts_in_delta":926,"sequence":147629,"symbol":"FCEU SI 20260615 PS"}
{"ts_recv":"2026-04-07T02:07:58.911801694Z","hd":{"ts_event":"2026-04-07T02:07:58.911782171Z","rtype":160,"publisher_id":101,"instrument_id":436},"action":"A","side":"B","price":"1.156120000","size":30,"channel_id":23,"order_id":"10998899715766564090","flags":0,"ts_in_delta":926,"sequence":147629,"symbol":"FCEU SI 20260615 PS"}
{"ts_recv":"2026-04-07T02:07:58.911801694Z","hd":{"ts_event":"2026-04-07T02:07:58.911782171Z","rtype":160,"publisher_id":101,"instrument_id":436},"action":"C","side":"A","price":"1.156210000","size":30,"channel_id":23,"order_id":"1775527678834089568","flags":0,"ts_in_delta":926,"sequence":147629,"symbol":"FCEU SI 20260615 PS"}
{"ts_recv":"2026-04-07T02:07:58.911801694Z","hd":{"ts_event":"2026-04-07T02:07:58.911782171Z","rtype":160,"publisher_id":101,"instrument_id":436},"action":"A","side":"A","price":"1.156220000","size":30,"channel_id":23,"order_id":"1775527678911788282","flags":128,"ts_in_delta":926,"sequence":147629,"symbol":"FCEU SI 20260615 PS"}
{"ts_recv":"2026-04-07T02:07:58.911852111Z","hd":{"ts_event":"2026-04-07T02:07:58.911831929Z","rtype":160,"publisher_id":101,"instrument_id":436},"action":"C","side":"B","price":"1.156110000","size":30,"channel_id":23,"order_id":"10998899715683046907","flags":0,"ts_in_delta":937,"sequence":147630,"symbol":"FCEU SI 20260615 PS"}
{"ts_recv":"2026-04-07T02:07:58.911852111Z","hd":{"ts_event":"2026-04-07T02:07:58.911831929Z","rtype":160,"publisher_id":101,"instrument_id":436},"action":"A","side":"B","price":"1.156130000","size":30,"channel_id":23,"order_id":"10998899715766613824","flags":0,"ts_in_delta":937,"sequence":147630,"symbol":"FCEU SI 20260615 PS"}
{"ts_recv":"2026-04-07T02:07:58.911852111Z","hd":{"ts_event":"2026-04-07T02:07:58.911831929Z","rtype":160,"publisher_id":101,"instrument_id":436},"action":"C","side":"A","price":"1.156210000","size":30,"channel_id":23,"order_id":"1775527678828271099","flags":0,"ts_in_delta":937,"sequence":147630,"symbol":"FCEU SI 20260615 PS"}
{"ts_recv":"2026-04-07T02:07:58.911852111Z","hd":{"ts_event":"2026-04-07T02:07:58.911831929Z","rtype":160,"publisher_id":101,"instrument_id":436},"action":"A","side":"A","price":"1.156230000","size":30,"channel_id":23,"order_id":"1775527678911838016","flags":128,"ts_in_delta":937,"sequence":147630,"symbol":"FCEU SI 20260615 PS"}
{"ts_recv":"2026-04-07T02:07:58.911879450Z","hd":{"ts_event":"2026-04-07T02:07:58.911863201Z","rtype":160,"publisher_id":101,"instrument_id":436},"action":"C","side":"B","price":"1.156120000","size":30,"channel_id":23,"order_id":"10998899715766564090","flags":0,"ts_in_delta":864,"sequence":147631,"symbol":"FCEU SI 20260615 PS"}
{"ts_recv":"2026-04-07T02:07:58.911879450Z","hd":{"ts_event":"2026-04-07T02:07:58.911863201Z","rtype":160,"publisher_id":101,"instrument_id":436},"action":"A","side":"B","price":"1.156130000","size":30,"channel_id":23,"order_id":"10998899715766645092","flags":0,"ts_in_delta":864,"sequence":147631,"symbol":"FCEU SI 20260615 PS"}
{"ts_recv":"2026-04-07T02:07:58.911879450Z","hd":{"ts_event":"2026-04-07T02:07:58.911863201Z","rtype":160,"publisher_id":101,"instrument_id":436},"action":"C","side":"A","price":"1.156220000","size":30,"channel_id":23,"order_id":"1775527678911788282","flags":0,"ts_in_delta":864,"sequence":147631,"symbol":"FCEU SI 20260615 PS"}
{"ts_recv":"2026-04-07T02:07:58.911879450Z","hd":{"ts_event":"2026-04-07T02:07:58.911863201Z","rtype":160,"publisher_id":101,"instrument_id":436},"action":"A","side":"A","price":"1.156230000","size":30,"channel_id":23,"order_id":"1775527678911869284","flags":128,"ts_in_delta":864,"sequence":147631,"symbol":"FCEU SI 20260615 PS"}
{"ts_recv":"2026-04-07T02:08:01.589331158Z","hd":{"ts_event":"2026-04-07T02:08:01.589310007Z","rtype":160,"publisher_id":101,"instrument_id":436},"action":"C","side":"B","price":"1.156130000","size":30,"channel_id":23,"order_id":"10998899715766645092","flags":0,"ts_in_delta":940,"sequence":147693,"symbol":"FCEU SI 20260615 PS"}
{"ts_recv":"2026-04-07T02:08:01.589331158Z","hd":{"ts_event":"2026-04-07T02:08:01.589310007Z","rtype":160,"publisher_id":101,"instrument_id":436},"action":"A","side":"B","price":"1.156120000","size":30,"channel_id":23,"order_id":"10998899718444091970","flags":0,"ts_in_delta":940,"sequence":147693,"symbol":"FCEU SI 20260615 PS"}
{"ts_recv":"2026-04-07T02:08:01.589331158Z","hd":{"ts_event":"2026-04-07T02:08:01.589310007Z","rtype":160,"publisher_id":101,"instrument_id":436},"action":"C","side":"A","price":"1.156230000","size":30,"channel_id":23,"order_id":"1775527678911869284","flags":0,"ts_in_delta":940,"sequence":147693,"symbol":"FCEU SI 20260615 PS"}
{"ts_recv":"2026-04-07T02:08:01.589331158Z","hd":{"ts_event":"2026-04-07T02:08:01.589310007Z","rtype":160,"publisher_id":101,"instrument_id":436},"action":"A","side":"A","price":"1.156220000","size":30,"channel_id":23,"order_id":"1775527681589316162","flags":128,"ts_in_delta":940,"sequence":147693,"symbol":"FCEU SI 20260615 PS"}
{"ts_recv":"2026-04-07T02:08:02.098938728Z","hd":{"ts_event":"2026-04-07T02:08:02.098913533Z","rtype":160,"publisher_id":101,"instrument_id":436},"action":"C","side":"B","price":"1.156120000","size":30,"channel_id":23,"order_id":"10998899718444091970","flags":0,"ts_in_delta":1439,"sequence":147700,"symbol":"FCEU SI 20260615 PS"}
{"ts_recv":"2026-04-07T02:08:02.098938728Z","hd":{"ts_event":"2026-04-07T02:08:02.098913533Z","rtype":160,"publisher_id":101,"instrument_id":436},"action":"A","side":"B","price":"1.156130000","size":30,"channel_id":23,"order_id":"10998899718953699842","flags":0,"ts_in_delta":1439,"sequence":147700,"symbol":"FCEU SI 20260615 PS"}
{"ts_recv":"2026-04-07T02:08:02.098938728Z","hd":{"ts_event":"2026-04-07T02:08:02.098913533Z","rtype":160,"publisher_id":101,"instrument_id":436},"action":"C","side":"A","price":"1.156220000","size":30,"channel_id":23,"order_id":"1775527681589316162","flags":0,"ts_in_delta":1439,"sequence":147700,"symbol":"FCEU SI 20260615 PS"}
{"ts_recv":"2026-04-07T02:08:02.098938728Z","hd":{"ts_event":"2026-04-07T02:08:02.098913533Z","rtype":160,"publisher_id":101,"instrument_id":436},"action":"A","side":"A","price":"1.156230000","size":30,"channel_id":23,"order_id":"1775527682098924034","flags":128,"ts_in_delta":1439,"sequence":147700,"symbol":"FCEU SI 20260615 PS"}
{"ts_recv":"2026-04-07T02:08:04.363527000Z","hd":{"ts_event":"2026-04-07T02:08:04.363500655Z","rtype":160,"publisher_id":101,"instrument_id":436},"action":"C","side":"B","price":"1.156130000","size":30,"channel_id":23,"order_id":"10998899718953699842","flags":0,"ts_in_delta":944,"sequence":147728,"symbol":"FCEU SI 20260615 PS"}
{"ts_recv":"2026-04-07T02:08:04.363527000Z","hd":{"ts_event":"2026-04-07T02:08:04.363500655Z","rtype":160,"publisher_id":101,"instrument_id":436},"action":"A","side":"B","price":"1.156140000","size":30,"channel_id":23,"order_id":"10998899721218287130","flags":0,"ts_in_delta":944,"sequence":147728,"symbol":"FCEU SI 20260615 PS"}
{"ts_recv":"2026-04-07T02:08:04.363527000Z","hd":{"ts_event":"2026-04-07T02:08:04.363500655Z","rtype":160,"publisher_id":101,"instrument_id":436},"action":"C","side":"A","price":"1.156230000","size":30,"channel_id":23,"order_id":"1775527682098924034","flags":0,"ts_in_delta":944,"sequence":147728,"symbol":"FCEU SI 20260615 PS"}
{"ts_recv":"2026-04-07T02:08:04.363527000Z","hd":{"ts_event":"2026-04-07T02:08:04.363500655Z","rtype":160,"publisher_id":101,"instrument_id":436},"action":"A","side":"A","price":"1.156240000","size":30,"channel_id":23,"order_id":"1775527684363511322","flags":128,"ts_in_delta":944,"sequence":147728,"symbol":"FCEU SI 20260615 PS"}
{"ts_recv":"2026-04-07T02:08:04.363609195Z","hd":{"ts_event":"2026-04-07T02:08:04.363586525Z","rtype":160,"publisher_id":101,"instrument_id":436},"action":"C","side":"B","price":"1.156130000","size":30,"channel_id":23,"order_id":"10998899715766613824","flags":0,"ts_in_delta":961,"sequence":147729,"symbol":"FCEU SI 20260615 PS"}
{"ts_recv":"2026-04-07T02:08:04.363609195Z","hd":{"ts_event":"2026-04-07T02:08:04.363586525Z","rtype":160,"publisher_id":101,"instrument_id":436},"action":"A","side":"B","price":"1.156150000","size":30,"channel_id":23,"order_id":"10998899721218368978","flags":0,"ts_in_delta":961,"sequence":147729,"symbol":"FCEU SI 20260615 PS"}
{"ts_recv":"2026-04-07T02:08:04.363609195Z","hd":{"ts_event":"2026-04-07T02:08:04.363586525Z","rtype":160,"publisher_id":101,"instrument_id":436},"action":"C","side":"A","price":"1.156230000","size":30,"channel_id":23,"order_id":"1775527678911838016","flags":0,"ts_in_delta":961,"sequence":147729,"symbol":"FCEU SI 20260615 PS"}
{"ts_recv":"2026-04-07T02:08:04.363609195Z","hd":{"ts_event":"2026-04-07T02:08:04.363586525Z","rtype":160,"publisher_id":101,"instrument_id":436},"action":"A","side":"A","price":"1.156250000","size":30,"channel_id":23,"order_id":"1775527684363593170","flags":128,"ts_in_delta":961,"sequence":147729,"symbol":"FCEU SI 20260615 PS"}
{"ts_recv":"2026-04-07T02:08:04.363616575Z","hd":{"ts_event":"2026-04-07T02:08:04.363593629Z","rtype":160,"publisher_id":101,"instrument_id":436},"action":"C","side":"B","price":"1.156140000","size":30,"channel_id":23,"order_id":"10998899721218287130","flags":0,"ts_in_delta":967,"sequence":147730,"symbol":"FCEU SI 20260615 PS"}
{"ts_recv":"2026-04-07T02:08:04.363616575Z","hd":{"ts_event":"2026-04-07T02:08:04.363593629Z","rtype":160,"publisher_id":101,"instrument_id":436},"action":"A","side":"B","price":"1.156150000","size":30,"channel_id":23,"order_id":"10998899721218381692","flags":0,"ts_in_delta":967,"sequence":147730,"symbol":"FCEU SI 20260615 PS"}
{"ts_recv":"2026-04-07T02:08:04.363616575Z","hd":{"ts_event":"2026-04-07T02:08:04.363593629Z","rtype":160,"publisher_id":101,"instrument_id":436},"action":"C","side":"A","price":"1.156240000","size":30,"channel_id":23,"order_id":"1775527684363511322","flags":0,"ts_in_delta":967,"sequence":147730,"symbol":"FCEU SI 20260615 PS"}
{"ts_recv":"2026-04-07T02:08:04.363616575Z","hd":{"ts_event":"2026-04-07T02:08:04.363593629Z","rtype":160,"publisher_id":101,"instrument_id":436},"action":"A","side":"A","price":"1.156250000","size":30,"channel_id":23,"order_id":"1775527684363605884","flags":128,"ts_in_delta":967,"sequence":147730,"symbol":"FCEU SI 20260615 PS"}
{"ts_recv":"2026-04-07T02:08:05.825699461Z","hd":{"ts_event":"2026-04-07T02:08:05.825678571Z","rtype":160,"publisher_id":101,"instrument_id":436},"action":"C","side":"B","price":"1.156150000","size":30,"channel_id":23,"order_id":"10998899721218381692","flags":0,"ts_in_delta":893,"sequence":147742,"symbol":"FCEU SI 20260615 PS"}
{"ts_recv":"2026-04-07T02:08:05.825699461Z","hd":{"ts_event":"2026-04-07T02:08:05.825678571Z","rtype":160,"publisher_id":101,"instrument_id":436},"action":"A","side":"B","price":"1.156140000","size":30,"channel_id":23,"order_id":"10998899722680460055","flags":0,"ts_in_delta":893,"sequence":147742,"symbol":"FCEU SI 20260615 PS"}
{"ts_recv":"2026-04-07T02:08:05.825699461Z","hd":{"ts_event":"2026-04-07T02:08:05.825678571Z","rtype":160,"publisher_id":101,"instrument_id":436},"action":"C","side":"A","price":"1.156250000","size":30,"channel_id":23,"order_id":"1775527684363605884","flags":0,"ts_in_delta":893,"sequence":147742,"symbol":"FCEU SI 20260615 PS"}
{"ts_recv":"2026-04-07T02:08:05.825699461Z","hd":{"ts_event":"2026-04-07T02:08:05.825678571Z","rtype":160,"publisher_id":101,"instrument_id":436},"action":"A","side":"A","price":"1.156240000","size":30,"channel_id":23,"order_id":"1775527685825684247","flags":128,"ts_in_delta":893,"sequence":147742,"symbol":"FCEU SI 20260615 PS"}
{"ts_recv":"2026-04-07T02:08:05.968670745Z","hd":{"ts_event":"2026-04-07T02:08:05.968643603Z","rtype":160,"publisher_id":101,"instrument_id":436},"action":"C","side":"B","price":"1.156150000","size":30,"channel_id":23,"order_id":"10998899721218368978","flags":0,"ts_in_delta":1372,"sequence":147751,"symbol":"FCEU SI 20260615 PS"}
{"ts_recv":"2026-04-07T02:08:05.968670745Z","hd":{"ts_event":"2026-04-07T02:08:05.968643603Z","rtype":160,"publisher_id":101,"instrument_id":436},"action":"A","side":"B","price":"1.156130000","size":30,"channel_id":23,"order_id":"10998899722823425966","flags":0,"ts_in_delta":1372,"sequence":147751,"symbol":"FCEU SI 20260615 PS"}
{"ts_recv":"2026-04-07T02:08:05.968670745Z","hd":{"ts_event":"2026-04-07T02:08:05.968643603Z","rtype":160,"publisher_id":101,"instrument_id":436},"action":"C","side":"A","price":"1.156250000","size":30,"channel_id":23,"order_id":"1775527684363593170","flags":0,"ts_in_delta":1372,"sequence":147751,"symbol":"FCEU SI 20260615 PS"}
{"ts_recv":"2026-04-07T02:08:05.968670745Z","hd":{"ts_event":"2026-04-07T02:08:05.968643603Z","rtype":160,"publisher_id":101,"instrument_id":436},"action":"A","side":"A","price":"1.156230000","size":30,"channel_id":23,"order_id":"1775527685968650158","flags":128,"ts_in_delta":1372,"sequence":147751,"symbol":"FCEU SI 20260615 PS"}
{"ts_recv":"2026-04-07T02:08:05.968757103Z","hd":{"ts_event":"2026-04-07T02:08:05.968739757Z","rtype":160,"publisher_id":101,"instrument_id":436},"action":"C","side":"B","price":"1.156140000","size":30,"channel_id":23,"order_id":"10998899722680460055","flags":0,"ts_in_delta":941,"sequence":147752,"symbol":"FCEU SI 20260615 PS"}
{"ts_recv":"2026-04-07T02:08:05.968757103Z","hd":{"ts_event":"2026-04-07T02:08:05.968739757Z","rtype":160,"publisher_id":101,"instrument_id":436},"action":"A","side":"B","price":"1.156130000","size":30,"channel_id":23,"order_id":"10998899722823521629","flags":0,"ts_in_delta":941,"sequence":147752,"symbol":"FCEU SI 20260615 PS"}
{"ts_recv":"2026-04-07T02:08:05.968757103Z","hd":{"ts_event":"2026-04-07T02:08:05.968739757Z","rtype":160,"publisher_id":101,"instrument_id":436},"action":"C","side":"A","price":"1.156240000","size":30,"channel_id":23,"order_id":"1775527685825684247","flags":0,"ts_in_delta":941,"sequence":147752,"symbol":"FCEU SI 20260615 PS"}
{"ts_recv":"2026-04-07T02:08:05.968757103Z","hd":{"ts_event":"2026-04-07T02:08:05.968739757Z","rtype":160,"publisher_id":101,"instrument_id":436},"action":"A","side":"A","price":"1.156230000","size":30,"channel_id":23,"order_id":"1775527685968745821","flags":128,"ts_in_delta":941,"sequence":147752,"symbol":"FCEU SI 20260615 PS"}
{"ts_recv":"2026-04-07T02:08:07.259684475Z","hd":{"ts_event":"2026-04-07T02:08:07.259655225Z","rtype":160,"publisher_id":101,"instrument_id":436},"action":"C","side":"B","price":"1.156130000","size":30,"channel_id":23,"order_id":"10998899722823425966","flags":0,"ts_in_delta":1483,"sequence":147765,"symbol":"FCEU SI 20260615 PS"}
{"ts_recv":"2026-04-07T02:08:07.259684475Z","hd":{"ts_event":"2026-04-07T02:08:07.259655225Z","rtype":160,"publisher_id":101,"instrument_id":436},"action":"A","side":"B","price":"1.156150000","size":30,"channel_id":23,"order_id":"10998899724114444414","flags":0,"ts_in_delta":1483,"sequence":147765,"symbol":"FCEU SI 20260615 PS"}
{"ts_recv":"2026-04-07T02:08:07.259684475Z","hd":{"ts_event":"2026-04-07T02:08:07.259655225Z","rtype":160,"publisher_id":101,"instrument_id":436},"action":"C","side":"A","price":"1.156230000","size":30,"channel_id":23,"order_id":"1775527685968650158","flags":0,"ts_in_delta":1483,"sequence":147765,"symbol":"FCEU SI 20260615 PS"}
{"ts_recv":"2026-04-07T02:08:07.259684475Z","hd":{"ts_event":"2026-04-07T02:08:07.259655225Z","rtype":160,"publisher_id":101,"instrument_id":436},"action":"A","side":"A","price":"1.156250000","size":30,"channel_id":23,"order_id":"1775527687259668606","flags":128,"ts_in_delta":1483,"sequence":147765,"symbol":"FCEU SI 20260615 PS"}
{"ts_recv":"2026-04-07T02:08:07.259782835Z","hd":{"ts_event":"2026-04-07T02:08:07.259767545Z","rtype":160,"publisher_id":101,"instrument_id":436},"action":"C","side":"B","price":"1.156130000","size":30,"channel_id":23,"order_id":"10998899722823521629","flags":0,"ts_in_delta":1131,"sequence":147766,"symbol":"FCEU SI 20260615 PS"}
{"ts_recv":"2026-04-07T02:08:07.259782835Z","hd":{"ts_event":"2026-04-07T02:08:07.259767545Z","rtype":160,"publisher_id":101,"instrument_id":436},"action":"A","side":"B","price":"1.156140000","size":30,"channel_id":23,"order_id":"10998899724114549383","flags":0,"ts_in_delta":1131,"sequence":147766,"symbol":"FCEU SI 20260615 PS"}
{"ts_recv":"2026-04-07T02:08:07.259782835Z","hd":{"ts_event":"2026-04-07T02:08:07.259767545Z","rtype":160,"publisher_id":101,"instrument_id":436},"action":"C","side":"A","price":"1.156230000","size":30,"channel_id":23,"order_id":"1775527685968745821","flags":0,"ts_in_delta":1131,"sequence":147766,"symbol":"FCEU SI 20260615 PS"}
{"ts_recv":"2026-04-07T02:08:07.259782835Z","hd":{"ts_event":"2026-04-07T02:08:07.259767545Z","rtype":160,"publisher_id":101,"instrument_id":436},"action":"A","side":"A","price":"1.156240000","size":30,"channel_id":23,"order_id":"1775527687259773575","flags":128,"ts_in_delta":1131,"sequence":147766,"symbol":"FCEU SI 20260615 PS"}
{"ts_recv":"2026-04-07T02:08:07.262380499Z","hd":{"ts_event":"2026-04-07T02:08:07.262363071Z","rtype":160,"publisher_id":101,"instrument_id":436},"action":"C","side":"B","price":"1.156140000","size":30,"channel_id":23,"order_id":"10998899724114549383","flags":0,"ts_in_delta":1010,"sequence":147771,"symbol":"FCEU SI 20260615 PS"}
{"ts_recv":"2026-04-07T02:08:07.262380499Z","hd":{"ts_event":"2026-04-07T02:08:07.262363071Z","rtype":160,"publisher_id":101,"instrument_id":436},"action":"A","side":"B","price":"1.156150000","size":30,"channel_id":23,"order_id":"10998899724117144979","flags":0,"ts_in_delta":1010,"sequence":147771,"symbol":"FCEU SI 20260615 PS"}
{"ts_recv":"2026-04-07T02:08:07.262380499Z","hd":{"ts_event":"2026-04-07T02:08:07.262363071Z","rtype":160,"publisher_id":101,"instrument_id":436},"action":"C","side":"A","price":"1.156240000","size":30,"channel_id":23,"order_id":"1775527687259773575","flags":0,"ts_in_delta":1010,"sequence":147771,"symbol":"FCEU SI 20260615 PS"}
{"ts_recv":"2026-04-07T02:08:07.262380499Z","hd":{"ts_event":"2026-04-07T02:08:07.262363071Z","rtype":160,"publisher_id":101,"instrument_id":436},"action":"A","side":"A","price":"1.156250000","size":30,"channel_id":23,"order_id":"1775527687262369171","flags":128,"ts_in_delta":1010,"sequence":147771,"symbol":"FCEU SI 20260615 PS"}
{"ts_recv":"2026-04-07T02:08:07.267233407Z","hd":{"ts_event":"2026-04-07T02:08:07.267215197Z","rtype":160,"publisher_id":101,"instrument_id":436},"action":"C","side":"B","price":"1.156150000","size":30,"channel_id":23,"order_id":"10998899724117144979","flags":0,"ts_in_delta":1017,"sequence":147775,"symbol":"FCEU SI 20260615 PS"}
{"ts_recv":"2026-04-07T02:08:07.267233407Z","hd":{"ts_event":"2026-04-07T02:08:07.267215197Z","rtype":160,"publisher_id":101,"instrument_id":436},"action":"A","side":"B","price":"1.156160000","size":30,"channel_id":23,"order_id":"10998899724121996626","flags":0,"ts_in_delta":1017,"sequence":147775,"symbol":"FCEU SI 20260615 PS"}
{"ts_recv":"2026-04-07T02:08:07.267233407Z","hd":{"ts_event":"2026-04-07T02:08:07.267215197Z","rtype":160,"publisher_id":101,"instrument_id":436},"action":"C","side":"A","price":"1.156250000","size":30,"channel_id":23,"order_id":"1775527687262369171","flags":0,"ts_in_delta":1017,"sequence":147775,"symbol":"FCEU SI 20260615 PS"}
{"ts_recv":"2026-04-07T02:08:07.267233407Z","hd":{"ts_event":"2026-04-07T02:08:07.267215197Z","rtype":160,"publisher_id":101,"instrument_id":436},"action":"A","side":"A","price":"1.156260000","size":30,"channel_id":23,"order_id":"1775527687267220818","flags":128,"ts_in_delta":1017,"sequence":147775,"symbol":"FCEU SI 20260615 PS"}
{"ts_recv":"2026-04-07T02:08:07.267285544Z","hd":{"ts_event":"2026-04-07T02:08:07.267265789Z","rtype":160,"publisher_id":101,"instrument_id":436},"action":"C","side":"B","price":"1.156150000","size":30,"channel_id":23,"order_id":"10998899724114444414","flags":0,"ts_in_delta":879,"sequence":147776,"symbol":"FCEU SI 20260615 PS"}
{"ts_recv":"2026-04-07T02:08:07.267285544Z","hd":{"ts_event":"2026-04-07T02:08:07.267265789Z","rtype":160,"publisher_id":101,"instrument_id":436},"action":"A","side":"B","price":"1.156170000","size":30,"channel_id":23,"order_id":"10998899724122047714","flags":0,"ts_in_delta":879,"sequence":147776,"symbol":"FCEU SI 20260615 PS"}
{"ts_recv":"2026-04-07T02:08:07.267285544Z","hd":{"ts_event":"2026-04-07T02:08:07.267265789Z","rtype":160,"publisher_id":101,"instrument_id":436},"action":"C","side":"A","price":"1.156250000","size":30,"channel_id":23,"order_id":"1775527687259668606","flags":0,"ts_in_delta":879,"sequence":147776,"symbol":"FCEU SI 20260615 PS"}
{"ts_recv":"2026-04-07T02:08:07.267285544Z","hd":{"ts_event":"2026-04-07T02:08:07.267265789Z","rtype":160,"publisher_id":101,"instrument_id":436},"action":"A","side":"A","price":"1.156270000","size":30,"channel_id":23,"order_id":"1775527687267271906","flags":128,"ts_in_delta":879,"sequence":147776,"symbol":"FCEU SI 20260615 PS"}
{"ts_recv":"2026-04-07T02:08:07.267314020Z","hd":{"ts_event":"2026-04-07T02:08:07.267294301Z","rtype":160,"publisher_id":101,"instrument_id":436},"action":"C","side":"B","price":"1.156160000","size":30,"channel_id":23,"order_id":"10998899724121996626","flags":0,"ts_in_delta":882,"sequence":147777,"symbol":"FCEU SI 20260615 PS"}
{"ts_recv":"2026-04-07T02:08:07.267314020Z","hd":{"ts_event":"2026-04-07T02:08:07.267294301Z","rtype":160,"publisher_id":101,"instrument_id":436},"action":"A","side":"B","price":"1.156180000","size":30,"channel_id":23,"order_id":"10998899724122076055","flags":0,"ts_in_delta":882,"sequence":147777,"symbol":"FCEU SI 20260615 PS"}
{"ts_recv":"2026-04-07T02:08:07.267314020Z","hd":{"ts_event":"2026-04-07T02:08:07.267294301Z","rtype":160,"publisher_id":101,"instrument_id":436},"action":"C","side":"A","price":"1.156260000","size":30,"channel_id":23,"order_id":"1775527687267220818","flags":0,"ts_in_delta":882,"sequence":147777,"symbol":"FCEU SI 20260615 PS"}
{"ts_recv":"2026-04-07T02:08:07.267314020Z","hd":{"ts_event":"2026-04-07T02:08:07.267294301Z","rtype":160,"publisher_id":101,"instrument_id":436},"action":"A","side":"A","price":"1.156280000","size":30,"channel_id":23,"order_id":"1775527687267300247","flags":128,"ts_in_delta":882,"sequence":147777,"symbol":"FCEU SI 20260615 PS"}
{"ts_recv":"2026-04-07T02:08:07.267368737Z","hd":{"ts_event":"2026-04-07T02:08:07.267352207Z","rtype":160,"publisher_id":101,"instrument_id":436},"action":"C","side":"B","price":"1.156180000","size":30,"channel_id":23,"order_id":"10998899724122076055","flags":0,"ts_in_delta":903,"sequence":147778,"symbol":"FCEU SI 20260615 PS"}
{"ts_recv":"2026-04-07T02:08:07.267368737Z","hd":{"ts_event":"2026-04-07T02:08:07.267352207Z","rtype":160,"publisher_id":101,"instrument_id":436},"action":"A","side":"B","price":"1.156170000","size":30,"channel_id":23,"order_id":"10998899724122133723","flags":0,"ts_in_delta":903,"sequence":147778,"symbol":"FCEU SI 20260615 PS"}
{"ts_recv":"2026-04-07T02:08:07.267368737Z","hd":{"ts_event":"2026-04-07T02:08:07.267352207Z","rtype":160,"publisher_id":101,"instrument_id":436},"action":"C","side":"A","price":"1.156280000","size":30,"channel_id":23,"order_id":"1775527687267300247","flags":0,"ts_in_delta":903,"sequence":147778,"symbol":"FCEU SI 20260615 PS"}
{"ts_recv":"2026-04-07T02:08:07.267368737Z","hd":{"ts_event":"2026-04-07T02:08:07.267352207Z","rtype":160,"publisher_id":101,"instrument_id":436},"action":"A","side":"A","price":"1.156270000","size":30,"channel_id":23,"order_id":"1775527687267357915","flags":128,"ts_in_delta":903,"sequence":147778,"symbol":"FCEU SI 20260615 PS"}
{"ts_recv":"2026-04-07T02:08:12.245913224Z","hd":{"ts_event":"2026-04-07T02:08:12.245892903Z","rtype":160,"publisher_id":101,"instrument_id":436},"action":"C","side":"B","price":"1.156170000","size":30,"channel_id":23,"order_id":"10998899724122133723","flags":0,"ts_in_delta":1287,"sequence":147889,"symbol":"FCEU SI 20260615 PS"}
{"ts_recv":"2026-04-07T02:08:12.245913224Z","hd":{"ts_event":"2026-04-07T02:08:12.245892903Z","rtype":160,"publisher_id":101,"instrument_id":436},"action":"A","side":"B","price":"1.156180000","size":30,"channel_id":23,"order_id":"10998899729100674776","flags":0,"ts_in_delta":1287,"sequence":147889,"symbol":"FCEU SI 20260615 PS"}
{"ts_recv":"2026-04-07T02:08:12.245913224Z","hd":{"ts_event":"2026-04-07T02:08:12.245892903Z","rtype":160,"publisher_id":101,"instrument_id":436},"action":"C","side":"A","price":"1.156270000","size":30,"channel_id":23,"order_id":"1775527687267357915","flags":0,"ts_in_delta":1287,"sequence":147889,"symbol":"FCEU SI 20260615 PS"}
{"ts_recv":"2026-04-07T02:08:12.245913224Z","hd":{"ts_event":"2026-04-07T02:08:12.245892903Z","rtype":160,"publisher_id":101,"instrument_id":436},"action":"A","side":"A","price":"1.156280000","size":30,"channel_id":23,"order_id":"1775527692245898968","flags":128,"ts_in_delta":1287,"sequence":147889,"symbol":"FCEU SI 20260615 PS"}
{"ts_recv":"2026-04-07T02:08:12.245964378Z","hd":{"ts_event":"2026-04-07T02:08:12.245943509Z","rtype":160,"publisher_id":101,"instrument_id":436},"action":"C","side":"B","price":"1.156170000","size":30,"channel_id":23,"order_id":"10998899724122047714","flags":0,"ts_in_delta":1351,"sequence":147890,"symbol":"FCEU SI 20260615 PS"}
{"ts_recv":"2026-04-07T02:08:12.245964378Z","hd":{"ts_event":"2026-04-07T02:08:12.245943509Z","rtype":160,"publisher_id":101,"instrument_id":436},"action":"A","side":"B","price":"1.156190000","size":30,"channel_id":23,"order_id":"10998899729100725407","flags":0,"ts_in_delta":1351,"sequence":147890,"symbol":"FCEU SI 20260615 PS"}
{"ts_recv":"2026-04-07T02:08:12.245964378Z","hd":{"ts_event":"2026-04-07T02:08:12.245943509Z","rtype":160,"publisher_id":101,"instrument_id":436},"action":"C","side":"A","price":"1.156270000","size":30,"channel_id":23,"order_id":"1775527687267271906","flags":0,"ts_in_delta":1351,"sequence":147890,"symbol":"FCEU SI 20260615 PS"}
{"ts_recv":"2026-04-07T02:08:12.245964378Z","hd":{"ts_event":"2026-04-07T02:08:12.245943509Z","rtype":160,"publisher_id":101,"instrument_id":436},"action":"A","side":"A","price":"1.156290000","size":30,"channel_id":23,"order_id":"1775527692245949599","flags":128,"ts_in_delta":1351,"sequence":147890,"symbol":"FCEU SI 20260615 PS"}
{"ts_recv":"2026-04-07T02:08:12.246017037Z","hd":{"ts_event":"2026-04-07T02:08:12.246000437Z","rtype":160,"publisher_id":101,"instrument_id":436},"action":"C","side":"B","price":"1.156180000","size":30,"channel_id":23,"order_id":"10998899729100674776","flags":0,"ts_in_delta":941,"sequence":147891,"symbol":"FCEU SI 20260615 PS"}
{"ts_recv":"2026-04-07T02:08:12.246017037Z","hd":{"ts_event":"2026-04-07T02:08:12.246000437Z","rtype":160,"publisher_id":101,"instrument_id":436},"action":"A","side":"B","price":"1.156190000","size":30,"channel_id":23,"order_id":"10998899729100782173","flags":0,"ts_in_delta":941,"sequence":147891,"symbol":"FCEU SI 20260615 PS"}
{"ts_recv":"2026-04-07T02:08:12.246017037Z","hd":{"ts_event":"2026-04-07T02:08:12.246000437Z","rtype":160,"publisher_id":101,"instrument_id":436},"action":"C","side":"A","price":"1.156280000","size":30,"channel_id":23,"order_id":"1775527692245898968","flags":0,"ts_in_delta":941,"sequence":147891,"symbol":"FCEU SI 20260615 PS"}
{"ts_recv":"2026-04-07T02:08:12.246017037Z","hd":{"ts_event":"2026-04-07T02:08:12.246000437Z","rtype":160,"publisher_id":101,"instrument_id":436},"action":"A","side":"A","price":"1.156290000","size":30,"channel_id":23,"order_id":"1775527692246006365","flags":128,"ts_in_delta":941,"sequence":147891,"symbol":"FCEU SI 20260615 PS"}
{"ts_recv":"2026-04-07T02:08:12.518915066Z","hd":{"ts_event":"2026-04-07T02:08:12.518896087Z","rtype":160,"publisher_id":101,"instrument_id":436},"action":"C","side":"B","price":"1.156190000","size":30,"channel_id":23,"order_id":"10998899729100782173","flags":0,"ts_in_delta":903,"sequence":147928,"symbol":"FCEU SI 20260615 PS"}
{"ts_recv":"2026-04-07T02:08:12.518915066Z","hd":{"ts_event":"2026-04-07T02:08:12.518896087Z","rtype":160,"publisher_id":101,"instrument_id":436},"action":"A","side":"B","price":"1.156200000","size":30,"channel_id":23,"order_id":"10998899729373677684","flags":0,"ts_in_delta":903,"sequence":147928,"symbol":"FCEU SI 20260615 PS"}
{"ts_recv":"2026-04-07T02:08:12.518915066Z","hd":{"ts_event":"2026-04-07T02:08:12.518896087Z","rtype":160,"publisher_id":101,"instrument_id":436},"action":"C","side":"A","price":"1.156290000","size":30,"channel_id":23,"order_id":"1775527692246006365","flags":0,"ts_in_delta":903,"sequence":147928,"symbol":"FCEU SI 20260615 PS"}
{"ts_recv":"2026-04-07T02:08:12.518915066Z","hd":{"ts_event":"2026-04-07T02:08:12.518896087Z","rtype":160,"publisher_id":101,"instrument_id":436},"action":"A","side":"A","price":"1.156300000","size":30,"channel_id":23,"order_id":"1775527692518901876","flags":128,"ts_in_delta":903,"sequence":147928,"symbol":"FCEU SI 20260615 PS"}
{"ts_recv":"2026-04-07T02:08:12.524484515Z","hd":{"ts_event":"2026-04-07T02:08:12.524462895Z","rtype":160,"publisher_id":101,"instrument_id":436},"action":"C","side":"B","price":"1.156190000","size":30,"channel_id":23,"order_id":"10998899729100725407","flags":0,"ts_in_delta":931,"sequence":147934,"symbol":"FCEU SI 20260615 PS"}
{"ts_recv":"2026-04-07T02:08:12.524484515Z","hd":{"ts_event":"2026-04-07T02:08:12.524462895Z","rtype":160,"publisher_id":101,"instrument_id":436},"action":"A","side":"B","price":"1.156220000","size":30,"channel_id":23,"order_id":"10998899729379244838","flags":0,"ts_in_delta":931,"sequence":147934,"symbol":"FCEU SI 20260615 PS"}
{"ts_recv":"2026-04-07T02:08:12.524484515Z","hd":{"ts_event":"2026-04-07T02:08:12.524462895Z","rtype":160,"publisher_id":101,"instrument_id":436},"action":"C","side":"A","price":"1.156290000","size":30,"channel_id":23,"order_id":"1775527692245949599","flags":0,"ts_in_delta":931,"sequence":147934,"symbol":"FCEU SI 20260615 PS"}
{"ts_recv":"2026-04-07T02:08:12.524484515Z","hd":{"ts_event":"2026-04-07T02:08:12.524462895Z","rtype":160,"publisher_id":101,"instrument_id":436},"action":"A","side":"A","price":"1.156320000","size":30,"channel_id":23,"order_id":"1775527692524469030","flags":128,"ts_in_delta":931,"sequence":147934,"symbol":"FCEU SI 20260615 PS"}
{"ts_recv":"2026-04-07T02:08:12.524543349Z","hd":{"ts_event":"2026-04-07T02:08:12.524525935Z","rtype":160,"publisher_id":101,"instrument_id":436},"action":"C","side":"B","price":"1.156200000","size":30,"channel_id":23,"order_id":"10998899729373677684","flags":0,"ts_in_delta":906,"sequence":147935,"symbol":"FCEU SI 20260615 PS"}
{"ts_recv":"2026-04-07T02:08:12.524543349Z","hd":{"ts_event":"2026-04-07T02:08:12.524525935Z","rtype":160,"publisher_id":101,"instrument_id":436},"action":"A","side":"B","price":"1.156220000","size":30,"channel_id":23,"order_id":"10998899729379307803","flags":0,"ts_in_delta":906,"sequence":147935,"symbol":"FCEU SI 20260615 PS"}
{"ts_recv":"2026-04-07T02:08:12.524543349Z","hd":{"ts_event":"2026-04-07T02:08:12.524525935Z","rtype":160,"publisher_id":101,"instrument_id":436},"action":"C","side":"A","price":"1.156300000","size":30,"channel_id":23,"order_id":"1775527692518901876","flags":0,"ts_in_delta":906,"sequence":147935,"symbol":"FCEU SI 20260615 PS"}
{"ts_recv":"2026-04-07T02:08:12.524543349Z","hd":{"ts_event":"2026-04-07T02:08:12.524525935Z","rtype":160,"publisher_id":101,"instrument_id":436},"action":"A","side":"A","price":"1.156320000","size":30,"channel_id":23,"order_id":"1775527692524531995","flags":128,"ts_in_delta":906,"sequence":147935,"symbol":"FCEU SI 20260615 PS"}
{"ts_recv":"2026-04-07T02:08:12.582112780Z","hd":{"ts_event":"2026-04-07T02:08:12.582098143Z","rtype":160,"publisher_id":101,"instrument_id":436},"action":"A","side":"B","price":"1.156100000","size":20,"channel_id":23,"order_id":"10998899729436880081","flags":128,"ts_in_delta":994,"sequence":147942,"symbol":"FCEU SI 20260615 PS"}
{"ts_recv":"2026-04-07T02:08:12.582174240Z","hd":{"ts_event":"2026-04-07T02:08:12.582160893Z","rtype":160,"publisher_id":101,"instrument_id":436},"action":"C","side":"B","price":"1.156000000","size":20,"channel_id":23,"order_id":"10998899695415791716","flags":128,"ts_in_delta":937,"sequence":147943,"symbol":"FCEU SI 20260615 PS"}
{"ts_recv":"2026-04-07T02:08:13.752976588Z","hd":{"ts_event":"2026-04-07T02:08:13.752956445Z","rtype":160,"publisher_id":101,"instrument_id":436},"action":"C","side":"B","price":"1.156220000","size":30,"channel_id":23,"order_id":"10998899729379307803","flags":0,"ts_in_delta":866,"sequence":147962,"symbol":"FCEU SI 20260615 PS"}
{"ts_recv":"2026-04-07T02:08:13.752976588Z","hd":{"ts_event":"2026-04-07T02:08:13.752956445Z","rtype":160,"publisher_id":101,"instrument_id":436},"action":"A","side":"B","price":"1.156210000","size":30,"channel_id":23,"order_id":"10998899730607738294","flags":0,"ts_in_delta":866,"sequence":147962,"symbol":"FCEU SI 20260615 PS"}
{"ts_recv":"2026-04-07T02:08:13.752976588Z","hd":{"ts_event":"2026-04-07T02:08:13.752956445Z","rtype":160,"publisher_id":101,"instrument_id":436},"action":"C","side":"A","price":"1.156320000","size":30,"channel_id":23,"order_id":"1775527692524531995","flags":0,"ts_in_delta":866,"sequence":147962,"symbol":"FCEU SI 20260615 PS"}
{"ts_recv":"2026-04-07T02:08:13.752976588Z","hd":{"ts_event":"2026-04-07T02:08:13.752956445Z","rtype":160,"publisher_id":101,"instrument_id":436},"action":"A","side":"A","price":"1.156310000","size":30,"channel_id":23,"order_id":"1775527693752962486","flags":128,"ts_in_delta":866,"sequence":147962,"symbol":"FCEU SI 20260615 PS"}
{"ts_recv":"2026-04-07T02:08:13.791404511Z","hd":{"ts_event":"2026-04-07T02:08:13.791384863Z","rtype":160,"publisher_id":101,"instrument_id":436},"action":"C","side":"B","price":"1.156210000","size":30,"channel_id":23,"order_id":"10998899730607738294","flags":0,"ts_in_delta":955,"sequence":147969,"symbol":"FCEU SI 20260615 PS"}
{"ts_recv":"2026-04-07T02:08:13.791404511Z","hd":{"ts_event":"2026-04-07T02:08:13.791384863Z","rtype":160,"publisher_id":101,"instrument_id":436},"action":"A","side":"B","price":"1.156190000","size":30,"channel_id":23,"order_id":"10998899730646166562","flags":0,"ts_in_delta":955,"sequence":147969,"symbol":"FCEU SI 20260615 PS"}
{"ts_recv":"2026-04-07T02:08:13.791404511Z","hd":{"ts_event":"2026-04-07T02:08:13.791384863Z","rtype":160,"publisher_id":101,"instrument_id":436},"action":"C","side":"A","price":"1.156310000","size":30,"channel_id":23,"order_id":"1775527693752962486","flags":0,"ts_in_delta":955,"sequence":147969,"symbol":"FCEU SI 20260615 PS"}
{"ts_recv":"2026-04-07T02:08:13.791404511Z","hd":{"ts_event":"2026-04-07T02:08:13.791384863Z","rtype":160,"publisher_id":101,"instrument_id":436},"action":"A","side":"A","price":"1.156290000","size":30,"channel_id":23,"order_id":"1775527693791390754","flags":128,"ts_in_delta":955,"sequence":147969,"symbol":"FCEU SI 20260615 PS"}
{"ts_recv":"2026-04-07T02:08:13.791450849Z","hd":{"ts_event":"2026-04-07T02:08:13.791435109Z","rtype":160,"publisher_id":101,"instrument_id":436},"action":"C","side":"B","price":"1.156220000","size":30,"channel_id":23,"order_id":"10998899729379244838","flags":0,"ts_in_delta":920,"sequence":147970,"symbol":"FCEU SI 20260615 PS"}
{"ts_recv":"2026-04-07T02:08:13.791450849Z","hd":{"ts_event":"2026-04-07T02:08:13.791435109Z","rtype":160,"publisher_id":101,"instrument_id":436},"action":"A","side":"B","price":"1.156200000","size":30,"channel_id":23,"order_id":"10998899730646216703","flags":0,"ts_in_delta":920,"sequence":147970,"symbol":"FCEU SI 20260615 PS"}
{"ts_recv":"2026-04-07T02:08:13.791450849Z","hd":{"ts_event":"2026-04-07T02:08:13.791435109Z","rtype":160,"publisher_id":101,"instrument_id":436},"action":"C","side":"A","price":"1.156320000","size":30,"channel_id":23,"order_id":"1775527692524469030","flags":0,"ts_in_delta":920,"sequence":147970,"symbol":"FCEU SI 20260615 PS"}
{"ts_recv":"2026-04-07T02:08:13.791450849Z","hd":{"ts_event":"2026-04-07T02:08:13.791435109Z","rtype":160,"publisher_id":101,"instrument_id":436},"action":"A","side":"A","price":"1.156300000","size":30,"channel_id":23,"order_id":"1775527693791440895","flags":128,"ts_in_delta":920,"sequence":147970,"symbol":"FCEU SI 20260615 PS"}
{"ts_recv":"2026-04-07T02:08:13.791482328Z","hd":{"ts_event":"2026-04-07T02:08:13.791464851Z","rtype":160,"publisher_id":101,"instrument_id":436},"action":"C","side":"B","price":"1.156190000","size":30,"channel_id":23,"order_id":"10998899730646166562","flags":0,"ts_in_delta":1257,"sequence":147971,"symbol":"FCEU SI 20260615 PS"}
{"ts_recv":"2026-04-07T02:08:13.791482328Z","hd":{"ts_event":"2026-04-07T02:08:13.791464851Z","rtype":160,"publisher_id":101,"instrument_id":436},"action":"A","side":"B","price":"1.156210000","size":30,"channel_id":23,"order_id":"10998899730646246462","flags":0,"ts_in_delta":1257,"sequence":147971,"symbol":"FCEU SI 20260615 PS"}
{"ts_recv":"2026-04-07T02:08:13.791482328Z","hd":{"ts_event":"2026-04-07T02:08:13.791464851Z","rtype":160,"publisher_id":101,"instrument_id":436},"action":"C","side":"A","price":"1.156290000","size":30,"channel_id":23,"order_id":"1775527693791390754","flags":0,"ts_in_delta":1257,"sequence":147971,"symbol":"FCEU SI 20260615 PS"}
{"ts_recv":"2026-04-07T02:08:13.791482328Z","hd":{"ts_event":"2026-04-07T02:08:13.791464851Z","rtype":160,"publisher_id":101,"instrument_id":436},"action":"A","side":"A","price":"1.156310000","size":30,"channel_id":23,"order_id":"1775527693791470654","flags":128,"ts_in_delta":1257,"sequence":147971,"symbol":"FCEU SI 20260615 PS"}
{"ts_recv":"2026-04-07T02:08:13.791537837Z","hd":{"ts_event":"2026-04-07T02:08:13.791520685Z","rtype":160,"publisher_id":101,"instrument_id":436},"action":"C","side":"B","price":"1.156210000","size":30,"channel_id":23,"order_id":"10998899730646246462","flags":0,"ts_in_delta":1117,"sequence":147972,"symbol":"FCEU SI 20260615 PS"}
{"ts_recv":"2026-04-07T02:08:13.791537837Z","hd":{"ts_event":"2026-04-07T02:08:13.791520685Z","rtype":160,"publisher_id":101,"instrument_id":436},"action":"A","side":"B","price":"1.156200000","size":30,"channel_id":23,"order_id":"10998899730646302319","flags":0,"ts_in_delta":1117,"sequence":147972,"symbol":"FCEU SI 20260615 PS"}
{"ts_recv":"2026-04-07T02:08:13.791537837Z","hd":{"ts_event":"2026-04-07T02:08:13.791520685Z","rtype":160,"publisher_id":101,"instrument_id":436},"action":"C","side":"A","price":"1.156310000","size":30,"channel_id":23,"order_id":"1775527693791470654","flags":0,"ts_in_delta":1117,"sequence":147972,"symbol":"FCEU SI 20260615 PS"}
{"ts_recv":"2026-04-07T02:08:13.791537837Z","hd":{"ts_event":"2026-04-07T02:08:13.791520685Z","rtype":160,"publisher_id":101,"instrument_id":436},"action":"A","side":"A","price":"1.156300000","size":30,"channel_id":23,"order_id":"1775527693791526511","flags":128,"ts_in_delta":1117,"sequence":147972,"symbol":"FCEU SI 20260615 PS"}
{"ts_recv":"2026-04-07T02:08:18.800818339Z","hd":{"ts_event":"2026-04-07T02:08:18.800797047Z","rtype":160,"publisher_id":101,"instrument_id":436},"action":"C","side":"B","price":"1.156200000","size":30,"channel_id":23,"order_id":"10998899730646302319","flags":0,"ts_in_delta":1090,"sequence":148048,"symbol":"FCEU SI 20260615 PS"}
{"ts_recv":"2026-04-07T02:08:18.800818339Z","hd":{"ts_event":"2026-04-07T02:08:18.800797047Z","rtype":160,"publisher_id":101,"instrument_id":436},"action":"A","side":"B","price":"1.156190000","size":30,"channel_id":23,"order_id":"10998899735655578709","flags":0,"ts_in_delta":1090,"sequence":148048,"symbol":"FCEU SI 20260615 PS"}
{"ts_recv":"2026-04-07T02:08:18.800818339Z","hd":{"ts_event":"2026-04-07T02:08:18.800797047Z","rtype":160,"publisher_id":101,"instrument_id":436},"action":"C","side":"A","price":"1.156300000","size":30,"channel_id":23,"order_id":"1775527693791526511","flags":0,"ts_in_delta":1090,"sequence":148048,"symbol":"FCEU SI 20260615 PS"}
{"ts_recv":"2026-04-07T02:08:18.800818339Z","hd":{"ts_event":"2026-04-07T02:08:18.800797047Z","rtype":160,"publisher_id":101,"instrument_id":436},"action":"A","side":"A","price":"1.156290000","size":30,"channel_id":23,"order_id":"1775527698800802901","flags":128,"ts_in_delta":1090,"sequence":148048,"symbol":"FCEU SI 20260615 PS"}
{"ts_recv":"2026-04-07T02:08:18.848747419Z","hd":{"ts_event":"2026-04-07T02:08:18.848729053Z","rtype":160,"publisher_id":101,"instrument_id":436},"action":"C","side":"B","price":"1.156190000","size":30,"channel_id":23,"order_id":"10998899735655578709","flags":0,"ts_in_delta":961,"sequence":148053,"symbol":"FCEU SI 20260615 PS"}
{"ts_recv":"2026-04-07T02:08:18.848747419Z","hd":{"ts_event":"2026-04-07T02:08:18.848729053Z","rtype":160,"publisher_id":101,"instrument_id":436},"action":"A","side":"B","price":"1.156200000","size":30,"channel_id":23,"order_id":"10998899735703510625","flags":0,"ts_in_delta":961,"sequence":148053,"symbol":"FCEU SI 20260615 PS"}
{"ts_recv":"2026-04-07T02:08:18.848747419Z","hd":{"ts_event":"2026-04-07T02:08:18.848729053Z","rtype":160,"publisher_id":101,"instrument_id":436},"action":"C","side":"A","price":"1.156290000","size":30,"channel_id":23,"order_id":"1775527698800802901","flags":0,"ts_in_delta":961,"sequence":148053,"symbol":"FCEU SI 20260615 PS"}
{"ts_recv":"2026-04-07T02:08:18.848747419Z","hd":{"ts_event":"2026-04-07T02:08:18.848729053Z","rtype":160,"publisher_id":101,"instrument_id":436},"action":"A","side":"A","price":"1.156300000","size":30,"channel_id":23,"order_id":"1775527698848734817","flags":128,"ts_in_delta":961,"sequence":148053,"symbol":"FCEU SI 20260615 PS"}
{"ts_recv":"2026-04-07T02:08:19.690672170Z","hd":{"ts_event":"2026-04-07T02:08:19.690651477Z","rtype":160,"publisher_id":101,"instrument_id":436},"action":"C","side":"B","price":"1.156200000","size":30,"channel_id":23,"order_id":"10998899735703510625","flags":0,"ts_in_delta":906,"sequence":148081,"symbol":"FCEU SI 20260615 PS"}
{"ts_recv":"2026-04-07T02:08:19.690672170Z","hd":{"ts_event":"2026-04-07T02:08:19.690651477Z","rtype":160,"publisher_id":101,"instrument_id":436},"action":"A","side":"B","price":"1.156210000","size":30,"channel_id":23,"order_id":"10998899736545432987","flags":0,"ts_in_delta":906,"sequence":148081,"symbol":"FCEU SI 20260615 PS"}
{"ts_recv":"2026-04-07T02:08:19.690672170Z","hd":{"ts_event":"2026-04-07T02:08:19.690651477Z","rtype":160,"publisher_id":101,"instrument_id":436},"action":"C","side":"A","price":"1.156300000","size":30,"channel_id":23,"order_id":"1775527698848734817","flags":0,"ts_in_delta":906,"sequence":148081,"symbol":"FCEU SI 20260615 PS"}
{"ts_recv":"2026-04-07T02:08:19.690672170Z","hd":{"ts_event":"2026-04-07T02:08:19.690651477Z","rtype":160,"publisher_id":101,"instrument_id":436},"action":"A","side":"A","price":"1.156310000","size":30,"channel_id":23,"order_id":"1775527699690657179","flags":128,"ts_in_delta":906,"sequence":148081,"symbol":"FCEU SI 20260615 PS"}
{"ts_recv":"2026-04-07T02:08:19.690730074Z","hd":{"ts_event":"2026-04-07T02:08:19.690710191Z","rtype":160,"publisher_id":101,"instrument_id":436},"action":"C","side":"B","price":"1.156200000","size":30,"channel_id":23,"order_id":"10998899730646216703","flags":0,"ts_in_delta":924,"sequence":148082,"symbol":"FCEU SI 20260615 PS"}
{"ts_recv":"2026-04-07T02:08:19.690730074Z","hd":{"ts_event":"2026-04-07T02:08:19.690710191Z","rtype":160,"publisher_id":101,"instrument_id":436},"action":"A","side":"B","price":"1.156220000","size":30,"channel_id":23,"order_id":"10998899736545491761","flags":0,"ts_in_delta":924,"sequence":148082,"symbol":"FCEU SI 20260615 PS"}
{"ts_recv":"2026-04-07T02:08:19.690730074Z","hd":{"ts_event":"2026-04-07T02:08:19.690710191Z","rtype":160,"publisher_id":101,"instrument_id":436},"action":"C","side":"A","price":"1.156300000","size":30,"channel_id":23,"order_id":"1775527693791440895","flags":0,"ts_in_delta":924,"sequence":148082,"symbol":"FCEU SI 20260615 PS"}
{"ts_recv":"2026-04-07T02:08:19.690730074Z","hd":{"ts_event":"2026-04-07T02:08:19.690710191Z","rtype":160,"publisher_id":101,"instrument_id":436},"action":"A","side":"A","price":"1.156320000","size":30,"channel_id":23,"order_id":"1775527699690715953","flags":128,"ts_in_delta":924,"sequence":148082,"symbol":"FCEU SI 20260615 PS"}
{"ts_recv":"2026-04-07T02:08:19.690753843Z","hd":{"ts_event":"2026-04-07T02:08:19.690735715Z","rtype":160,"publisher_id":101,"instrument_id":436},"action":"C","side":"B","price":"1.156210000","size":30,"channel_id":23,"order_id":"10998899736545432987","flags":0,"ts_in_delta":1051,"sequence":148083,"symbol":"FCEU SI 20260615 PS"}
{"ts_recv":"2026-04-07T02:08:19.690753843Z","hd":{"ts_event":"2026-04-07T02:08:19.690735715Z","rtype":160,"publisher_id":101,"instrument_id":436},"action":"A","side":"B","price":"1.156220000","size":30,"channel_id":23,"order_id":"10998899736545517667","flags":0,"ts_in_delta":1051,"sequence":148083,"symbol":"FCEU SI 20260615 PS"}
{"ts_recv":"2026-04-07T02:08:19.690753843Z","hd":{"ts_event":"2026-04-07T02:08:19.690735715Z","rtype":160,"publisher_id":101,"instrument_id":436},"action":"C","side":"A","price":"1.156310000","size":30,"channel_id":23,"order_id":"1775527699690657179","flags":0,"ts_in_delta":1051,"sequence":148083,"symbol":"FCEU SI 20260615 PS"}
{"ts_recv":"2026-04-07T02:08:19.690753843Z","hd":{"ts_event":"2026-04-07T02:08:19.690735715Z","rtype":160,"publisher_id":101,"instrument_id":436},"action":"A","side":"A","price":"1.156320000","size":30,"channel_id":23,"order_id":"1775527699690741859","flags":128,"ts_in_delta":1051,"sequence":148083,"symbol":"FCEU SI 20260615 PS"}
{"ts_recv":"2026-04-07T02:08:19.693098247Z","hd":{"ts_event":"2026-04-07T02:08:19.693084621Z","rtype":160,"publisher_id":101,"instrument_id":436},"action":"C","side":"A","price":"1.156400000","size":20,"channel_id":23,"order_id":"1775527660158118360","flags":128,"ts_in_delta":984,"sequence":148084,"symbol":"FCEU SI 20260615 PS"}
{"ts_recv":"2026-04-07T02:08:19.764602827Z","hd":{"ts_event":"2026-04-07T02:08:19.764590793Z","rtype":160,"publisher_id":101,"instrument_id":436},"action":"A","side":"A","price":"1.156500000","size":20,"channel_id":23,"order_id":"1775527699764596594","flags":128,"ts_in_delta":972,"sequence":148104,"symbol":"FCEU SI 20260615 PS"}
{"ts_recv":"2026-04-07T02:08:19.933410724Z","hd":{"ts_event":"2026-04-07T02:08:19.933391405Z","rtype":160,"publisher_id":101,"instrument_id":436},"action":"C","side":"B","price":"1.156220000","size":30,"channel_id":23,"order_id":"10998899736545517667","flags":0,"ts_in_delta":897,"sequence":148118,"symbol":"FCEU SI 20260615 PS"}
{"ts_recv":"2026-04-07T02:08:19.933410724Z","hd":{"ts_event":"2026-04-07T02:08:19.933391405Z","rtype":160,"publisher_id":101,"instrument_id":436},"action":"A","side":"B","price":"1.156230000","size":30,"channel_id":23,"order_id":"10998899736788173289","flags":0,"ts_in_delta":897,"sequence":148118,"symbol":"FCEU SI 20260615 PS"}
{"ts_recv":"2026-04-07T02:08:19.933410724Z","hd":{"ts_event":"2026-04-07T02:08:19.933391405Z","rtype":160,"publisher_id":101,"instrument_id":436},"action":"C","side":"A","price":"1.156320000","size":30,"channel_id":23,"order_id":"1775527699690741859","flags":0,"ts_in_delta":897,"sequence":148118,"symbol":"FCEU SI 20260615 PS"}
{"ts_recv":"2026-04-07T02:08:19.933410724Z","hd":{"ts_event":"2026-04-07T02:08:19.933391405Z","rtype":160,"publisher_id":101,"instrument_id":436},"action":"A","side":"A","price":"1.156330000","size":30,"channel_id":23,"order_id":"1775527699933397481","flags":128,"ts_in_delta":897,"sequence":148118,"symbol":"FCEU SI 20260615 PS"}
{"ts_recv":"2026-04-07T02:08:19.933463253Z","hd":{"ts_event":"2026-04-07T02:08:19.933445395Z","rtype":160,"publisher_id":101,"instrument_id":436},"action":"C","side":"B","price":"1.156220000","size":30,"channel_id":23,"order_id":"10998899736545491761","flags":0,"ts_in_delta":881,"sequence":148119,"symbol":"FCEU SI 20260615 PS"}
{"ts_recv":"2026-04-07T02:08:19.933463253Z","hd":{"ts_event":"2026-04-07T02:08:19.933445395Z","rtype":160,"publisher_id":101,"instrument_id":436},"action":"A","side":"B","price":"1.156240000","size":30,"channel_id":23,"order_id":"10998899736788227314","flags":0,"ts_in_delta":881,"sequence":148119,"symbol":"FCEU SI 20260615 PS"}
{"ts_recv":"2026-04-07T02:08:19.933463253Z","hd":{"ts_event":"2026-04-07T02:08:19.933445395Z","rtype":160,"publisher_id":101,"instrument_id":436},"action":"C","side":"A","price":"1.156320000","size":30,"channel_id":23,"order_id":"1775527699690715953","flags":0,"ts_in_delta":881,"sequence":148119,"symbol":"FCEU SI 20260615 PS"}
{"ts_recv":"2026-04-07T02:08:19.933463253Z","hd":{"ts_event":"2026-04-07T02:08:19.933445395Z","rtype":160,"publisher_id":101,"instrument_id":436},"action":"A","side":"A","price":"1.156340000","size":30,"channel_id":23,"order_id":"1775527699933451506","flags":128,"ts_in_delta":881,"sequence":148119,"symbol":"FCEU SI 20260615 PS"}
{"ts_recv":"2026-04-07T02:08:19.933472968Z","hd":{"ts_event":"2026-04-07T02:08:19.933455225Z","rtype":160,"publisher_id":101,"instrument_id":436},"action":"C","side":"B","price":"1.156230000","size":30,"channel_id":23,"order_id":"10998899736788173289","flags":0,"ts_in_delta":1039,"sequence":148120,"symbol":"FCEU SI 20260615 PS"}
{"ts_recv":"2026-04-07T02:08:19.933472968Z","hd":{"ts_event":"2026-04-07T02:08:19.933455225Z","rtype":160,"publisher_id":101,"instrument_id":436},"action":"A","side":"B","price":"1.156240000","size":30,"channel_id":23,"order_id":"10998899736788237063","flags":0,"ts_in_delta":1039,"sequence":148120,"symbol":"FCEU SI 20260615 PS"}
{"ts_recv":"2026-04-07T02:08:19.933472968Z","hd":{"ts_event":"2026-04-07T02:08:19.933455225Z","rtype":160,"publisher_id":101,"instrument_id":436},"action":"C","side":"A","price":"1.156330000","size":30,"channel_id":23,"order_id":"1775527699933397481","flags":0,"ts_in_delta":1039,"sequence":148120,"symbol":"FCEU SI 20260615 PS"}
{"ts_recv":"2026-04-07T02:08:19.933472968Z","hd":{"ts_event":"2026-04-07T02:08:19.933455225Z","rtype":160,"publisher_id":101,"instrument_id":436},"action":"A","side":"A","price":"1.156340000","size":30,"channel_id":23,"order_id":"1775527699933461255","flags":128,"ts_in_delta":1039,"sequence":148120,"symbol":"FCEU SI 20260615 PS"}
{"ts_recv":"2026-04-07T02:08:21.490989212Z","hd":{"ts_event":"2026-04-07T02:08:21.490969485Z","rtype":160,"publisher_id":101,"instrument_id":436},"action":"C","side":"B","price":"1.156240000","size":30,"channel_id":23,"order_id":"10998899736788237063","flags":0,"ts_in_delta":734,"sequence":148147,"symbol":"FCEU SI 20260615 PS"}
{"ts_recv":"2026-04-07T02:08:21.490989212Z","hd":{"ts_event":"2026-04-07T02:08:21.490969485Z","rtype":160,"publisher_id":101,"instrument_id":436},"action":"A","side":"B","price":"1.156230000","size":30,"channel_id":23,"order_id":"10998899738345751234","flags":0,"ts_in_delta":734,"sequence":148147,"symbol":"FCEU SI 20260615 PS"}
{"ts_recv":"2026-04-07T02:08:21.490989212Z","hd":{"ts_event":"2026-04-07T02:08:21.490969485Z","rtype":160,"publisher_id":101,"instrument_id":436},"action":"C","side":"A","price":"1.156340000","size":30,"channel_id":23,"order_id":"1775527699933461255","flags":0,"ts_in_delta":734,"sequence":148147,"symbol":"FCEU SI 20260615 PS"}
{"ts_recv":"2026-04-07T02:08:21.490989212Z","hd":{"ts_event":"2026-04-07T02:08:21.490969485Z","rtype":160,"publisher_id":101,"instrument_id":436},"action":"A","side":"A","price":"1.156330000","size":30,"channel_id":23,"order_id":"1775527701490975426","flags":128,"ts_in_delta":734,"sequence":148147,"symbol":"FCEU SI 20260615 PS"}
{"ts_recv":"2026-04-07T02:08:21.866995311Z","hd":{"ts_event":"2026-04-07T02:08:21.866970685Z","rtype":160,"publisher_id":101,"instrument_id":436},"action":"C","side":"B","price":"1.156230000","size":30,"channel_id":23,"order_id":"10998899738345751234","flags":0,"ts_in_delta":1116,"sequence":148156,"symbol":"FCEU SI 20260615 PS"}
{"ts_recv":"2026-04-07T02:08:21.866995311Z","hd":{"ts_event":"2026-04-07T02:08:21.866970685Z","rtype":160,"publisher_id":101,"instrument_id":436},"action":"A","side":"B","price":"1.156240000","size":30,"channel_id":23,"order_id":"10998899738721757206","flags":0,"ts_in_delta":1116,"sequence":148156,"symbol":"FCEU SI 20260615 PS"}
{"ts_recv":"2026-04-07T02:08:21.866995311Z","hd":{"ts_event":"2026-04-07T02:08:21.866970685Z","rtype":160,"publisher_id":101,"instrument_id":436},"action":"C","side":"A","price":"1.156330000","size":30,"channel_id":23,"order_id":"1775527701490975426","flags":0,"ts_in_delta":1116,"sequence":148156,"symbol":"FCEU SI 20260615 PS"}
{"ts_recv":"2026-04-07T02:08:21.866995311Z","hd":{"ts_event":"2026-04-07T02:08:21.866970685Z","rtype":160,"publisher_id":101,"instrument_id":436},"action":"A","side":"A","price":"1.156340000","size":30,"channel_id":23,"order_id":"1775527701866981398","flags":128,"ts_in_delta":1116,"sequence":148156,"symbol":"FCEU SI 20260615 PS"}
{"ts_recv":"2026-04-07T02:08:27.550943043Z","hd":{"ts_event":"2026-04-07T02:08:27.550921491Z","rtype":160,"publisher_id":101,"instrument_id":436},"action":"C","side":"B","price":"1.156240000","size":30,"channel_id":23,"order_id":"10998899738721757206","flags":0,"ts_in_delta":975,"sequence":148199,"symbol":"FCEU SI 20260615 PS"}
{"ts_recv":"2026-04-07T02:08:27.550943043Z","hd":{"ts_event":"2026-04-07T02:08:27.550921491Z","rtype":160,"publisher_id":101,"instrument_id":436},"action":"A","side":"B","price":"1.156250000","size":30,"channel_id":23,"order_id":"10998899744405703349","flags":0,"ts_in_delta":975,"sequence":148199,"symbol":"FCEU SI 20260615 PS"}
{"ts_recv":"2026-04-07T02:08:27.550943043Z","hd":{"ts_event":"2026-04-07T02:08:27.550921491Z","rtype":160,"publisher_id":101,"instrument_id":436},"action":"C","side":"A","price":"1.156340000","size":30,"channel_id":23,"order_id":"1775527701866981398","flags":0,"ts_in_delta":975,"sequence":148199,"symbol":"FCEU SI 20260615 PS"}
{"ts_recv":"2026-04-07T02:08:27.550943043Z","hd":{"ts_event":"2026-04-07T02:08:27.550921491Z","rtype":160,"publisher_id":101,"instrument_id":436},"action":"A","side":"A","price":"1.156350000","size":30,"channel_id":23,"order_id":"1775527707550927541","flags":128,"ts_in_delta":975,"sequence":148199,"symbol":"FCEU SI 20260615 PS"}
{"ts_recv":"2026-04-07T02:08:27.550992907Z","hd":{"ts_event":"2026-04-07T02:08:27.550974773Z","rtype":160,"publisher_id":101,"instrument_id":436},"action":"C","side":"B","price":"1.156240000","size":30,"channel_id":23,"order_id":"10998899736788227314","flags":0,"ts_in_delta":966,"sequence":148200,"symbol":"FCEU SI 20260615 PS"}
{"ts_recv":"2026-04-07T02:08:27.550992907Z","hd":{"ts_event":"2026-04-07T02:08:27.550974773Z","rtype":160,"publisher_id":101,"instrument_id":436},"action":"A","side":"B","price":"1.156260000","size":30,"channel_id":23,"order_id":"10998899744405756417","flags":0,"ts_in_delta":966,"sequence":148200,"symbol":"FCEU SI 20260615 PS"}
{"ts_recv":"2026-04-07T02:08:27.550992907Z","hd":{"ts_event":"2026-04-07T02:08:27.550974773Z","rtype":160,"publisher_id":101,"instrument_id":436},"action":"C","side":"A","price":"1.156340000","size":30,"channel_id":23,"order_id":"1775527699933451506","flags":0,"ts_in_delta":966,"sequence":148200,"symbol":"FCEU SI 20260615 PS"}
{"ts_recv":"2026-04-07T02:08:27.550992907Z","hd":{"ts_event":"2026-04-07T02:08:27.550974773Z","rtype":160,"publisher_id":101,"instrument_id":436},"action":"A","side":"A","price":"1.156360000","size":30,"channel_id":23,"order_id":"1775527707550980609","flags":128,"ts_in_delta":966,"sequence":148200,"symbol":"FCEU SI 20260615 PS"}
{"ts_recv":"2026-04-07T02:08:27.551055535Z","hd":{"ts_event":"2026-04-07T02:08:27.551035963Z","rtype":160,"publisher_id":101,"instrument_id":436},"action":"C","side":"B","price":"1.156250000","size":30,"channel_id":23,"order_id":"10998899744405703349","flags":0,"ts_in_delta":938,"sequence":148201,"symbol":"FCEU SI 20260615 PS"}
{"ts_recv":"2026-04-07T02:08:27.551055535Z","hd":{"ts_event":"2026-04-07T02:08:27.551035963Z","rtype":160,"publisher_id":101,"instrument_id":436},"action":"A","side":"B","price":"1.156260000","size":30,"channel_id":23,"order_id":"10998899744405817453","flags":0,"ts_in_delta":938,"sequence":148201,"symbol":"FCEU SI 20260615 PS"}
{"ts_recv":"2026-04-07T02:08:27.551055535Z","hd":{"ts_event":"2026-04-07T02:08:27.551035963Z","rtype":160,"publisher_id":101,"instrument_id":436},"action":"C","side":"A","price":"1.156350000","size":30,"channel_id":23,"order_id":"1775527707550927541","flags":0,"ts_in_delta":938,"sequence":148201,"symbol":"FCEU SI 20260615 PS"}
{"ts_recv":"2026-04-07T02:08:27.551055535Z","hd":{"ts_event":"2026-04-07T02:08:27.551035963Z","rtype":160,"publisher_id":101,"instrument_id":436},"action":"A","side":"A","price":"1.156360000","size":30,"channel_id":23,"order_id":"1775527707551041645","flags":128,"ts_in_delta":938,"sequence":148201,"symbol":"FCEU SI 20260615 PS"}
{"ts_recv":"2026-04-07T02:08:27.673156413Z","hd":{"ts_event":"2026-04-07T02:08:27.673134809Z","rtype":160,"publisher_id":101,"instrument_id":436},"action":"C","side":"B","price":"1.156260000","size":30,"channel_id":23,"order_id":"10998899744405817453","flags":0,"ts_in_delta":935,"sequence":148213,"symbol":"FCEU SI 20260615 PS"}
{"ts_recv":"2026-04-07T02:08:27.673156413Z","hd":{"ts_event":"2026-04-07T02:08:27.673134809Z","rtype":160,"publisher_id":101,"instrument_id":436},"action":"A","side":"B","price":"1.156270000","size":30,"channel_id":23,"order_id":"10998899744527916880","flags":0,"ts_in_delta":935,"sequence":148213,"symbol":"FCEU SI 20260615 PS"}
{"ts_recv":"2026-04-07T02:08:27.673156413Z","hd":{"ts_event":"2026-04-07T02:08:27.673134809Z","rtype":160,"publisher_id":101,"instrument_id":436},"action":"C","side":"A","price":"1.156360000","size":30,"channel_id":23,"order_id":"1775527707551041645","flags":0,"ts_in_delta":935,"sequence":148213,"symbol":"FCEU SI 20260615 PS"}
{"ts_recv":"2026-04-07T02:08:27.673156413Z","hd":{"ts_event":"2026-04-07T02:08:27.673134809Z","rtype":160,"publisher_id":101,"instrument_id":436},"action":"A","side":"A","price":"1.156370000","size":30,"channel_id":23,"order_id":"1775527707673141072","flags":128,"ts_in_delta":935,"sequence":148213,"symbol":"FCEU SI 20260615 PS"}
{"ts_recv":"2026-04-07T02:08:27.686875144Z","hd":{"ts_event":"2026-04-07T02:08:27.686855921Z","rtype":160,"publisher_id":101,"instrument_id":436},"action":"C","side":"B","price":"1.156260000","size":30,"channel_id":23,"order_id":"10998899744405756417","flags":0,"ts_in_delta":937,"sequence":148227,"symbol":"FCEU SI 20260615 PS"}
{"ts_recv":"2026-04-07T02:08:27.686875144Z","hd":{"ts_event":"2026-04-07T02:08:27.686855921Z","rtype":160,"publisher_id":101,"instrument_id":436},"action":"A","side":"B","price":"1.156280000","size":30,"channel_id":23,"order_id":"10998899744541637609","flags":0,"ts_in_delta":937,"sequence":148227,"symbol":"FCEU SI 20260615 PS"}
{"ts_recv":"2026-04-07T02:08:27.686875144Z","hd":{"ts_event":"2026-04-07T02:08:27.686855921Z","rtype":160,"publisher_id":101,"instrument_id":436},"action":"C","side":"A","price":"1.156360000","size":30,"channel_id":23,"order_id":"1775527707550980609","flags":0,"ts_in_delta":937,"sequence":148227,"symbol":"FCEU SI 20260615 PS"}
{"ts_recv":"2026-04-07T02:08:27.686875144Z","hd":{"ts_event":"2026-04-07T02:08:27.686855921Z","rtype":160,"publisher_id":101,"instrument_id":436},"action":"A","side":"A","price":"1.156380000","size":30,"channel_id":23,"order_id":"1775527707686861801","flags":128,"ts_in_delta":937,"sequence":148227,"symbol":"FCEU SI 20260615 PS"}
{"ts_recv":"2026-04-07T02:08:27.686931474Z","hd":{"ts_event":"2026-04-07T02:08:27.686915769Z","rtype":160,"publisher_id":101,"instrument_id":436},"action":"C","side":"B","price":"1.156270000","size":30,"channel_id":23,"order_id":"10998899744527916880","flags":0,"ts_in_delta":961,"sequence":148228,"symbol":"FCEU SI 20260615 PS"}
{"ts_recv":"2026-04-07T02:08:27.686931474Z","hd":{"ts_event":"2026-04-07T02:08:27.686915769Z","rtype":160,"publisher_id":101,"instrument_id":436},"action":"A","side":"B","price":"1.156280000","size":30,"channel_id":23,"order_id":"10998899744541697364","flags":0,"ts_in_delta":961,"sequence":148228,"symbol":"FCEU SI 20260615 PS"}
{"ts_recv":"2026-04-07T02:08:27.686931474Z","hd":{"ts_event":"2026-04-07T02:08:27.686915769Z","rtype":160,"publisher_id":101,"instrument_id":436},"action":"C","side":"A","price":"1.156370000","size":30,"channel_id":23,"order_id":"1775527707673141072","flags":0,"ts_in_delta":961,"sequence":148228,"symbol":"FCEU SI 20260615 PS"}
{"ts_recv":"2026-04-07T02:08:27.686931474Z","hd":{"ts_event":"2026-04-07T02:08:27.686915769Z","rtype":160,"publisher_id":101,"instrument_id":436},"action":"A","side":"A","price":"1.156380000","size":30,"channel_id":23,"order_id":"1775527707686921556","flags":128,"ts_in_delta":961,"sequence":148228,"symbol":"FCEU SI 20260615 PS"}
{"ts_recv":"2026-04-07T02:08:40.636701361Z","hd":{"ts_event":"2026-04-07T02:08:40.636679225Z","rtype":160,"publisher_id":101,"instrument_id":436},"action":"C","side":"B","price":"1.156280000","size":30,"channel_id":23,"order_id":"10998899744541697364","flags":0,"ts_in_delta":1239,"sequence":148405,"symbol":"FCEU SI 20260615 PS"}
{"ts_recv":"2026-04-07T02:08:40.636701361Z","hd":{"ts_event":"2026-04-07T02:08:40.636679225Z","rtype":160,"publisher_id":101,"instrument_id":436},"action":"A","side":"B","price":"1.156290000","size":30,"channel_id":23,"order_id":"10998899757491460853","flags":0,"ts_in_delta":1239,"sequence":148405,"symbol":"FCEU SI 20260615 PS"}
{"ts_recv":"2026-04-07T02:08:40.636701361Z","hd":{"ts_event":"2026-04-07T02:08:40.636679225Z","rtype":160,"publisher_id":101,"instrument_id":436},"action":"C","side":"A","price":"1.156380000","size":30,"channel_id":23,"order_id":"1775527707686921556","flags":0,"ts_in_delta":1239,"sequence":148405,"symbol":"FCEU SI 20260615 PS"}
{"ts_recv":"2026-04-07T02:08:40.636701361Z","hd":{"ts_event":"2026-04-07T02:08:40.636679225Z","rtype":160,"publisher_id":101,"instrument_id":436},"action":"A","side":"A","price":"1.156390000","size":30,"channel_id":23,"order_id":"1775527720636685045","flags":128,"ts_in_delta":1239,"sequence":148405,"symbol":"FCEU SI 20260615 PS"}
{"ts_recv":"2026-04-07T02:08:40.690587049Z","hd":{"ts_event":"2026-04-07T02:08:40.690572199Z","rtype":160,"publisher_id":101,"instrument_id":436},"action":"A","side":"B","price":"1.156200000","size":20,"channel_id":23,"order_id":"10998899757545354213","flags":128,"ts_in_delta":918,"sequence":148417,"symbol":"FCEU SI 20260615 PS"}
{"ts_recv":"2026-04-07T02:08:40.690638502Z","hd":{"ts_event":"2026-04-07T02:08:40.690625683Z","rtype":160,"publisher_id":101,"instrument_id":436},"action":"C","side":"B","price":"1.156100000","size":20,"channel_id":23,"order_id":"10998899729436880081","flags":128,"ts_in_delta":992,"sequence":148418,"symbol":"FCEU SI 20260615 PS"}
{"ts_recv":"2026-04-07T02:08:42.542611414Z","hd":{"ts_event":"2026-04-07T02:08:42.542580847Z","rtype":160,"publisher_id":101,"instrument_id":436},"action":"C","side":"B","price":"1.156280000","size":30,"channel_id":23,"order_id":"10998899744541637609","flags":0,"ts_in_delta":1458,"sequence":148439,"symbol":"FCEU SI 20260615 PS"}
{"ts_recv":"2026-04-07T02:08:42.542611414Z","hd":{"ts_event":"2026-04-07T02:08:42.542580847Z","rtype":160,"publisher_id":101,"instrument_id":436},"action":"A","side":"B","price":"1.156310000","size":30,"channel_id":23,"order_id":"10998899759397369494","flags":0,"ts_in_delta":1458,"sequence":148439,"symbol":"FCEU SI 20260615 PS"}
{"ts_recv":"2026-04-07T02:08:42.542611414Z","hd":{"ts_event":"2026-04-07T02:08:42.542580847Z","rtype":160,"publisher_id":101,"instrument_id":436},"action":"C","side":"A","price":"1.156380000","size":30,"channel_id":23,"order_id":"1775527707686861801","flags":0,"ts_in_delta":1458,"sequence":148439,"symbol":"FCEU SI 20260615 PS"}
{"ts_recv":"2026-04-07T02:08:42.542611414Z","hd":{"ts_event":"2026-04-07T02:08:42.542580847Z","rtype":160,"publisher_id":101,"instrument_id":436},"action":"A","side":"A","price":"1.156410000","size":30,"channel_id":23,"order_id":"1775527722542593686","flags":128,"ts_in_delta":1458,"sequence":148439,"symbol":"FCEU SI 20260615 PS"}
{"ts_recv":"2026-04-07T02:08:42.542722339Z","hd":{"ts_event":"2026-04-07T02:08:42.542706321Z","rtype":160,"publisher_id":101,"instrument_id":436},"action":"C","side":"B","price":"1.156290000","size":30,"channel_id":23,"order_id":"10998899757491460853","flags":0,"ts_in_delta":935,"sequence":148440,"symbol":"FCEU SI 20260615 PS"}
{"ts_recv":"2026-04-07T02:08:42.542722339Z","hd":{"ts_event":"2026-04-07T02:08:42.542706321Z","rtype":160,"publisher_id":101,"instrument_id":436},"action":"A","side":"B","price":"1.156300000","size":30,"channel_id":23,"order_id":"10998899759397488065","flags":0,"ts_in_delta":935,"sequence":148440,"symbol":"FCEU SI 20260615 PS"}
{"ts_recv":"2026-04-07T02:08:42.542722339Z","hd":{"ts_event":"2026-04-07T02:08:42.542706321Z","rtype":160,"publisher_id":101,"instrument_id":436},"action":"C","side":"A","price":"1.156390000","size":30,"channel_id":23,"order_id":"1775527720636685045","flags":0,"ts_in_delta":935,"sequence":148440,"symbol":"FCEU SI 20260615 PS"}
{"ts_recv":"2026-04-07T02:08:42.542722339Z","hd":{"ts_event":"2026-04-07T02:08:42.542706321Z","rtype":160,"publisher_id":101,"instrument_id":436},"action":"A","side":"A","price":"1.156400000","size":30,"channel_id":23,"order_id":"1775527722542712257","flags":128,"ts_in_delta":935,"sequence":148440,"symbol":"FCEU SI 20260615 PS"}
{"ts_recv":"2026-04-07T02:08:46.262764193Z","hd":{"ts_event":"2026-04-07T02:08:46.262747675Z","rtype":160,"publisher_id":101,"instrument_id":436},"action":"C","side":"B","price":"1.156300000","size":30,"channel_id":23,"order_id":"10998899759397488065","flags":0,"ts_in_delta":996,"sequence":148450,"symbol":"FCEU SI 20260615 PS"}
{"ts_recv":"2026-04-07T02:08:46.262764193Z","hd":{"ts_event":"2026-04-07T02:08:46.262747675Z","rtype":160,"publisher_id":101,"instrument_id":436},"action":"A","side":"B","price":"1.156310000","size":30,"channel_id":23,"order_id":"10998899763117529505","flags":0,"ts_in_delta":996,"sequence":148450,"symbol":"FCEU SI 20260615 PS"}
{"ts_recv":"2026-04-07T02:08:46.262764193Z","hd":{"ts_event":"2026-04-07T02:08:46.262747675Z","rtype":160,"publisher_id":101,"instrument_id":436},"action":"C","side":"A","price":"1.156400000","size":30,"channel_id":23,"order_id":"1775527722542712257","flags":0,"ts_in_delta":996,"sequence":148450,"symbol":"FCEU SI 20260615 PS"}
{"ts_recv":"2026-04-07T02:08:46.262764193Z","hd":{"ts_event":"2026-04-07T02:08:46.262747675Z","rtype":160,"publisher_id":101,"instrument_id":436},"action":"A","side":"A","price":"1.156410000","size":30,"channel_id":23,"order_id":"1775527726262753697","flags":128,"ts_in_delta":996,"sequence":148450,"symbol":"FCEU SI 20260615 PS"}
{"ts_recv":"2026-04-07T02:08:46.547101500Z","hd":{"ts_event":"2026-04-07T02:08:46.547088921Z","rtype":160,"publisher_id":101,"instrument_id":436},"action":"C","side":"A","price":"1.156500000","size":20,"channel_id":23,"order_id":"1775527699764596594","flags":128,"ts_in_delta":963,"sequence":148484,"symbol":"FCEU SI 20260615 PS"}
{"ts_recv":"2026-04-07T02:08:46.611337336Z","hd":{"ts_event":"2026-04-07T02:08:46.611322759Z","rtype":160,"publisher_id":101,"instrument_id":436},"action":"A","side":"A","price":"1.156600000","size":20,"channel_id":23,"order_id":"1775527726611328836","flags":128,"ts_in_delta":990,"sequence":148489,"symbol":"FCEU SI 20260615 PS"}
{"ts_recv":"2026-04-07T02:08:46.686212655Z","hd":{"ts_event":"2026-04-07T02:08:46.686191863Z","rtype":160,"publisher_id":101,"instrument_id":436},"action":"C","side":"B","price":"1.156310000","size":30,"channel_id":23,"order_id":"10998899763117529505","flags":0,"ts_in_delta":1080,"sequence":148499,"symbol":"FCEU SI 20260615 PS"}
{"ts_recv":"2026-04-07T02:08:46.686212655Z","hd":{"ts_event":"2026-04-07T02:08:46.686191863Z","rtype":160,"publisher_id":101,"instrument_id":436},"action":"A","side":"B","price":"1.156300000","size":30,"channel_id":23,"order_id":"10998899763540973884","flags":0,"ts_in_delta":1080,"sequence":148499,"symbol":"FCEU SI 20260615 PS"}
{"ts_recv":"2026-04-07T02:08:46.686212655Z","hd":{"ts_event":"2026-04-07T02:08:46.686191863Z","rtype":160,"publisher_id":101,"instrument_id":436},"action":"C","side":"A","price":"1.156410000","size":30,"channel_id":23,"order_id":"1775527726262753697","flags":0,"ts_in_delta":1080,"sequence":148499,"symbol":"FCEU SI 20260615 PS"}
{"ts_recv":"2026-04-07T02:08:46.686212655Z","hd":{"ts_event":"2026-04-07T02:08:46.686191863Z","rtype":160,"publisher_id":101,"instrument_id":436},"action":"A","side":"A","price":"1.156400000","size":30,"channel_id":23,"order_id":"1775527726686198076","flags":128,"ts_in_delta":1080,"sequence":148499,"symbol":"FCEU SI 20260615 PS"}
{"ts_recv":"2026-04-07T02:08:46.686294604Z","hd":{"ts_event":"2026-04-07T02:08:46.686274251Z","rtype":160,"publisher_id":101,"instrument_id":436},"action":"C","side":"B","price":"1.156300000","size":30,"channel_id":23,"order_id":"10998899763540973884","flags":0,"ts_in_delta":945,"sequence":148500,"symbol":"FCEU SI 20260615 PS"}
{"ts_recv":"2026-04-07T02:08:46.686294604Z","hd":{"ts_event":"2026-04-07T02:08:46.686274251Z","rtype":160,"publisher_id":101,"instrument_id":436},"action":"A","side":"B","price":"1.156290000","size":30,"channel_id":23,"order_id":"10998899763541056104","flags":0,"ts_in_delta":945,"sequence":148500,"symbol":"FCEU SI 20260615 PS"}
{"ts_recv":"2026-04-07T02:08:46.686294604Z","hd":{"ts_event":"2026-04-07T02:08:46.686274251Z","rtype":160,"publisher_id":101,"instrument_id":436},"action":"C","side":"A","price":"1.156400000","size":30,"channel_id":23,"order_id":"1775527726686198076","flags":0,"ts_in_delta":945,"sequence":148500,"symbol":"FCEU SI 20260615 PS"}
{"ts_recv":"2026-04-07T02:08:46.686294604Z","hd":{"ts_event":"2026-04-07T02:08:46.686274251Z","rtype":160,"publisher_id":101,"instrument_id":436},"action":"A","side":"A","price":"1.156390000","size":30,"channel_id":23,"order_id":"1775527726686280296","flags":128,"ts_in_delta":945,"sequence":148500,"symbol":"FCEU SI 20260615 PS"}
{"ts_recv":"2026-04-07T02:08:46.686361602Z","hd":{"ts_event":"2026-04-07T02:08:46.686344715Z","rtype":160,"publisher_id":101,"instrument_id":436},"action":"C","side":"B","price":"1.156290000","size":30,"channel_id":23,"order_id":"10998899763541056104","flags":0,"ts_in_delta":957,"sequence":148502,"symbol":"FCEU SI 20260615 PS"}
{"ts_recv":"2026-04-07T02:08:46.686361602Z","hd":{"ts_event":"2026-04-07T02:08:46.686344715Z","rtype":160,"publisher_id":101,"instrument_id":436},"action":"A","side":"B","price":"1.156300000","size":30,"channel_id":23,"order_id":"10998899763541126727","flags":0,"ts_in_delta":957,"sequence":148502,"symbol":"FCEU SI 20260615 PS"}
{"ts_recv":"2026-04-07T02:08:46.686361602Z","hd":{"ts_event":"2026-04-07T02:08:46.686344715Z","rtype":160,"publisher_id":101,"instrument_id":436},"action":"C","side":"A","price":"1.156390000","size":30,"channel_id":23,"order_id":"1775527726686280296","flags":0,"ts_in_delta":957,"sequence":148502,"symbol":"FCEU SI 20260615 PS"}
{"ts_recv":"2026-04-07T02:08:46.686361602Z","hd":{"ts_event":"2026-04-07T02:08:46.686344715Z","rtype":160,"publisher_id":101,"instrument_id":436},"action":"A","side":"A","price":"1.156400000","size":30,"channel_id":23,"order_id":"1775527726686350919","flags":128,"ts_in_delta":957,"sequence":148502,"symbol":"FCEU SI 20260615 PS"}
{"ts_recv":"2026-04-07T02:08:47.822665294Z","hd":{"ts_event":"2026-04-07T02:08:47.822645927Z","rtype":160,"publisher_id":101,"instrument_id":436},"action":"C","side":"B","price":"1.156310000","size":30,"channel_id":23,"order_id":"10998899759397369494","flags":0,"ts_in_delta":968,"sequence":148540,"symbol":"FCEU SI 20260615 PS"}
{"ts_recv":"2026-04-07T02:08:47.822665294Z","hd":{"ts_event":"2026-04-07T02:08:47.822645927Z","rtype":160,"publisher_id":101,"instrument_id":436},"action":"A","side":"B","price":"1.156290000","size":30,"channel_id":23,"order_id":"10998899764677427798","flags":0,"ts_in_delta":968,"sequence":148540,"symbol":"FCEU SI 20260615 PS"}
{"ts_recv":"2026-04-07T02:08:47.822665294Z","hd":{"ts_event":"2026-04-07T02:08:47.822645927Z","rtype":160,"publisher_id":101,"instrument_id":436},"action":"C","side":"A","price":"1.156410000","size":30,"channel_id":23,"order_id":"1775527722542593686","flags":0,"ts_in_delta":968,"sequence":148540,"symbol":"FCEU SI 20260615 PS"}
{"ts_recv":"2026-04-07T02:08:47.822665294Z","hd":{"ts_event":"2026-04-07T02:08:47.822645927Z","rtype":160,"publisher_id":101,"instrument_id":436},"action":"A","side":"A","price":"1.156390000","size":30,"channel_id":23,"order_id":"1775527727822651990","flags":128,"ts_in_delta":968,"sequence":148540,"symbol":"FCEU SI 20260615 PS"}
{"ts_recv":"2026-04-07T02:08:47.822751283Z","hd":{"ts_event":"2026-04-07T02:08:47.822735169Z","rtype":160,"publisher_id":101,"instrument_id":436},"action":"C","side":"B","price":"1.156300000","size":30,"channel_id":23,"order_id":"10998899763541126727","flags":0,"ts_in_delta":901,"sequence":148541,"symbol":"FCEU SI 20260615 PS"}
{"ts_recv":"2026-04-07T02:08:47.822751283Z","hd":{"ts_event":"2026-04-07T02:08:47.822735169Z","rtype":160,"publisher_id":101,"instrument_id":436},"action":"A","side":"B","price":"1.156290000","size":30,"channel_id":23,"order_id":"10998899764677516971","flags":0,"ts_in_delta":901,"sequence":148541,"symbol":"FCEU SI 20260615 PS"}
{"ts_recv":"2026-04-07T02:08:47.822751283Z","hd":{"ts_event":"2026-04-07T02:08:47.822735169Z","rtype":160,"publisher_id":101,"instrument_id":436},"action":"C","side":"A","price":"1.156400000","size":30,"channel_id":23,"order_id":"1775527726686350919","flags":0,"ts_in_delta":901,"sequence":148541,"symbol":"FCEU SI 20260615 PS"}
{"ts_recv":"2026-04-07T02:08:47.822751283Z","hd":{"ts_event":"2026-04-07T02:08:47.822735169Z","rtype":160,"publisher_id":101,"instrument_id":436},"action":"A","side":"A","price":"1.156390000","size":30,"channel_id":23,"order_id":"1775527727822741163","flags":128,"ts_in_delta":901,"sequence":148541,"symbol":"FCEU SI 20260615 PS"}
{"ts_recv":"2026-04-07T02:08:47.825301249Z","hd":{"ts_event":"2026-04-07T02:08:47.825278945Z","rtype":160,"publisher_id":101,"instrument_id":436},"action":"C","side":"B","price":"1.156290000","size":30,"channel_id":23,"order_id":"10998899764677516971","flags":0,"ts_in_delta":1359,"sequence":148542,"symbol":"FCEU SI 20260615 PS"}
{"ts_recv":"2026-04-07T02:08:47.825301249Z","hd":{"ts_event":"2026-04-07T02:08:47.825278945Z","rtype":160,"publisher_id":101,"instrument_id":436},"action":"A","side":"B","price":"1.156280000","size":30,"channel_id":23,"order_id":"10998899764680061186","flags":0,"ts_in_delta":1359,"sequence":148542,"symbol":"FCEU SI 20260615 PS"}
{"ts_recv":"2026-04-07T02:08:47.825301249Z","hd":{"ts_event":"2026-04-07T02:08:47.825278945Z","rtype":160,"publisher_id":101,"instrument_id":436},"action":"C","side":"A","price":"1.156390000","size":30,"channel_id":23,"order_id":"1775527727822741163","flags":0,"ts_in_delta":1359,"sequence":148542,"symbol":"FCEU SI 20260615 PS"}
{"ts_recv":"2026-04-07T02:08:47.825301249Z","hd":{"ts_event":"2026-04-07T02:08:47.825278945Z","rtype":160,"publisher_id":101,"instrument_id":436},"action":"A","side":"A","price":"1.156380000","size":30,"channel_id":23,"order_id":"1775527727825285378","flags":128,"ts_in_delta":1359,"sequence":148542,"symbol":"FCEU SI 20260615 PS"}
{"ts_recv":"2026-04-07T02:08:54.528632922Z","hd":{"ts_event":"2026-04-07T02:08:54.528611367Z","rtype":160,"publisher_id":101,"instrument_id":436},"action":"C","side":"B","price":"1.156290000","size":30,"channel_id":23,"order_id":"10998899764677427798","flags":0,"ts_in_delta":1230,"sequence":148700,"symbol":"FCEU SI 20260615 PS"}
{"ts_recv":"2026-04-07T02:08:54.528632922Z","hd":{"ts_event":"2026-04-07T02:08:54.528611367Z","rtype":160,"publisher_id":101,"instrument_id":436},"action":"A","side":"B","price":"1.156270000","size":30,"channel_id":23,"order_id":"10998899771383393359","flags":0,"ts_in_delta":1230,"sequence":148700,"symbol":"FCEU SI 20260615 PS"}
{"ts_recv":"2026-04-07T02:08:54.528632922Z","hd":{"ts_event":"2026-04-07T02:08:54.528611367Z","rtype":160,"publisher_id":101,"instrument_id":436},"action":"C","side":"A","price":"1.156390000","size":30,"channel_id":23,"order_id":"1775527727822651990","flags":0,"ts_in_delta":1230,"sequence":148700,"symbol":"FCEU SI 20260615 PS"}
{"ts_recv":"2026-04-07T02:08:54.528632922Z","hd":{"ts_event":"2026-04-07T02:08:54.528611367Z","rtype":160,"publisher_id":101,"instrument_id":436},"action":"A","side":"A","price":"1.156370000","size":30,"channel_id":23,"order_id":"1775527734528617551","flags":128,"ts_in_delta":1230,"sequence":148700,"symbol":"FCEU SI 20260615 PS"}
{"ts_recv":"2026-04-07T02:08:54.528716761Z","hd":{"ts_event":"2026-04-07T02:08:54.528697205Z","rtype":160,"publisher_id":101,"instrument_id":436},"action":"C","side":"B","price":"1.156280000","size":30,"channel_id":23,"order_id":"10998899764680061186","flags":0,"ts_in_delta":950,"sequence":148701,"symbol":"FCEU SI 20260615 PS"}
{"ts_recv":"2026-04-07T02:08:54.528716761Z","hd":{"ts_event":"2026-04-07T02:08:54.528697205Z","rtype":160,"publisher_id":101,"instrument_id":436},"action":"A","side":"B","price":"1.156270000","size":30,"channel_id":23,"order_id":"10998899771383478989","flags":0,"ts_in_delta":950,"sequence":148701,"symbol":"FCEU SI 20260615 PS"}
{"ts_recv":"2026-04-07T02:08:54.528716761Z","hd":{"ts_event":"2026-04-07T02:08:54.528697205Z","rtype":160,"publisher_id":101,"instrument_id":436},"action":"C","side":"A","price":"1.156380000","size":30,"channel_id":23,"order_id":"1775527727825285378","flags":0,"ts_in_delta":950,"sequence":148701,"symbol":"FCEU SI 20260615 PS"}
{"ts_recv":"2026-04-07T02:08:54.528716761Z","hd":{"ts_event":"2026-04-07T02:08:54.528697205Z","rtype":160,"publisher_id":101,"instrument_id":436},"action":"A","side":"A","price":"1.156370000","size":30,"channel_id":23,"order_id":"1775527734528703181","flags":128,"ts_in_delta":950,"sequence":148701,"symbol":"FCEU SI 20260615 PS"}
{"ts_recv":"2026-04-07T02:08:54.534455393Z","hd":{"ts_event":"2026-04-07T02:08:54.534435685Z","rtype":160,"publisher_id":101,"instrument_id":436},"action":"C","side":"B","price":"1.156270000","size":30,"channel_id":23,"order_id":"10998899771383478989","flags":0,"ts_in_delta":1266,"sequence":148704,"symbol":"FCEU SI 20260615 PS"}
{"ts_recv":"2026-04-07T02:08:54.534455393Z","hd":{"ts_event":"2026-04-07T02:08:54.534435685Z","rtype":160,"publisher_id":101,"instrument_id":436},"action":"A","side":"B","price":"1.156260000","size":30,"channel_id":23,"order_id":"10998899771389217074","flags":0,"ts_in_delta":1266,"sequence":148704,"symbol":"FCEU SI 20260615 PS"}
{"ts_recv":"2026-04-07T02:08:54.534455393Z","hd":{"ts_event":"2026-04-07T02:08:54.534435685Z","rtype":160,"publisher_id":101,"instrument_id":436},"action":"C","side":"A","price":"1.156370000","size":30,"channel_id":23,"order_id":"1775527734528703181","flags":0,"ts_in_delta":1266,"sequence":148704,"symbol":"FCEU SI 20260615 PS"}
{"ts_recv":"2026-04-07T02:08:54.534455393Z","hd":{"ts_event":"2026-04-07T02:08:54.534435685Z","rtype":160,"publisher_id":101,"instrument_id":436},"action":"A","side":"A","price":"1.156360000","size":30,"channel_id":23,"order_id":"1775527734534441266","flags":128,"ts_in_delta":1266,"sequence":148704,"symbol":"FCEU SI 20260615 PS"}
{"ts_recv":"2026-04-07T02:08:54.831526640Z","hd":{"ts_event":"2026-04-07T02:08:54.831500875Z","rtype":160,"publisher_id":101,"instrument_id":436},"action":"C","side":"B","price":"1.156270000","size":30,"channel_id":23,"order_id":"10998899771383393359","flags":0,"ts_in_delta":1676,"sequence":148716,"symbol":"FCEU SI 20260615 PS"}
{"ts_recv":"2026-04-07T02:08:54.831526640Z","hd":{"ts_event":"2026-04-07T02:08:54.831500875Z","rtype":160,"publisher_id":101,"instrument_id":436},"action":"A","side":"B","price":"1.156250000","size":30,"channel_id":23,"order_id":"10998899771686285156","flags":0,"ts_in_delta":1676,"sequence":148716,"symbol":"FCEU SI 20260615 PS"}
{"ts_recv":"2026-04-07T02:08:54.831526640Z","hd":{"ts_event":"2026-04-07T02:08:54.831500875Z","rtype":160,"publisher_id":101,"instrument_id":436},"action":"C","side":"A","price":"1.156370000","size":30,"channel_id":23,"order_id":"1775527734528617551","flags":0,"ts_in_delta":1676,"sequence":148716,"symbol":"FCEU SI 20260615 PS"}
{"ts_recv":"2026-04-07T02:08:54.831526640Z","hd":{"ts_event":"2026-04-07T02:08:54.831500875Z","rtype":160,"publisher_id":101,"instrument_id":436},"action":"A","side":"A","price":"1.156350000","size":30,"channel_id":23,"order_id":"1775527734831509348","flags":128,"ts_in_delta":1676,"sequence":148716,"symbol":"FCEU SI 20260615 PS"}
{"ts_recv":"2026-04-07T02:08:54.831638371Z","hd":{"ts_event":"2026-04-07T02:08:54.831620589Z","rtype":160,"publisher_id":101,"instrument_id":436},"action":"C","side":"B","price":"1.156260000","size":30,"channel_id":23,"order_id":"10998899771389217074","flags":0,"ts_in_delta":1294,"sequence":148717,"symbol":"FCEU SI 20260615 PS"}
{"ts_recv":"2026-04-07T02:08:54.831638371Z","hd":{"ts_event":"2026-04-07T02:08:54.831620589Z","rtype":160,"publisher_id":101,"instrument_id":436},"action":"A","side":"B","price":"1.156250000","size":30,"channel_id":23,"order_id":"10998899771686403457","flags":0,"ts_in_delta":1294,"sequence":148717,"symbol":"FCEU SI 20260615 PS"}
{"ts_recv":"2026-04-07T02:08:54.831638371Z","hd":{"ts_event":"2026-04-07T02:08:54.831620589Z","rtype":160,"publisher_id":101,"instrument_id":436},"action":"C","side":"A","price":"1.156360000","size":30,"channel_id":23,"order_id":"1775527734534441266","flags":0,"ts_in_delta":1294,"sequence":148717,"symbol":"FCEU SI 20260615 PS"}
{"ts_recv":"2026-04-07T02:08:54.831638371Z","hd":{"ts_event":"2026-04-07T02:08:54.831620589Z","rtype":160,"publisher_id":101,"instrument_id":436},"action":"A","side":"A","price":"1.156350000","size":30,"channel_id":23,"order_id":"1775527734831627649","flags":128,"ts_in_delta":1294,"sequence":148717,"symbol":"FCEU SI 20260615 PS"}
{"ts_recv":"2026-04-07T02:08:55.051288939Z","hd":{"ts_event":"2026-04-07T02:08:55.051270287Z","rtype":160,"publisher_id":101,"instrument_id":436},"action":"C","side":"B","price":"1.156250000","size":30,"channel_id":23,"order_id":"10998899771686403457","flags":0,"ts_in_delta":945,"sequence":148733,"symbol":"FCEU SI 20260615 PS"}
{"ts_recv":"2026-04-07T02:08:55.051288939Z","hd":{"ts_event":"2026-04-07T02:08:55.051270287Z","rtype":160,"publisher_id":101,"instrument_id":436},"action":"A","side":"B","price":"1.156260000","size":30,"channel_id":23,"order_id":"10998899771906052492","flags":0,"ts_in_delta":945,"sequence":148733,"symbol":"FCEU SI 20260615 PS"}
{"ts_recv":"2026-04-07T02:08:55.051288939Z","hd":{"ts_event":"2026-04-07T02:08:55.051270287Z","rtype":160,"publisher_id":101,"instrument_id":436},"action":"C","side":"A","price":"1.156350000","size":30,"channel_id":23,"order_id":"1775527734831627649","flags":0,"ts_in_delta":945,"sequence":148733,"symbol":"FCEU SI 20260615 PS"}
{"ts_recv":"2026-04-07T02:08:55.051288939Z","hd":{"ts_event":"2026-04-07T02:08:55.051270287Z","rtype":160,"publisher_id":101,"instrument_id":436},"action":"A","side":"A","price":"1.156360000","size":30,"channel_id":23,"order_id":"1775527735051276684","flags":128,"ts_in_delta":945,"sequence":148733,"symbol":"FCEU SI 20260615 PS"}
{"ts_recv":"2026-04-07T02:08:55.052089074Z","hd":{"ts_event":"2026-04-07T02:08:55.052067623Z","rtype":160,"publisher_id":101,"instrument_id":436},"action":"C","side":"B","price":"1.156250000","size":30,"channel_id":23,"order_id":"10998899771686285156","flags":0,"ts_in_delta":958,"sequence":148736,"symbol":"FCEU SI 20260615 PS"}
{"ts_recv":"2026-04-07T02:08:55.052089074Z","hd":{"ts_event":"2026-04-07T02:08:55.052067623Z","rtype":160,"publisher_id":101,"instrument_id":436},"action":"A","side":"B","price":"1.156270000","size":30,"channel_id":23,"order_id":"10998899771906849507","flags":0,"ts_in_delta":958,"sequence":148736,"symbol":"FCEU SI 20260615 PS"}
{"ts_recv":"2026-04-07T02:08:55.052089074Z","hd":{"ts_event":"2026-04-07T02:08:55.052067623Z","rtype":160,"publisher_id":101,"instrument_id":436},"action":"C","side":"A","price":"1.156350000","size":30,"channel_id":23,"order_id":"1775527734831509348","flags":0,"ts_in_delta":958,"sequence":148736,"symbol":"FCEU SI 20260615 PS"}
{"ts_recv":"2026-04-07T02:08:55.052089074Z","hd":{"ts_event":"2026-04-07T02:08:55.052067623Z","rtype":160,"publisher_id":101,"instrument_id":436},"action":"A","side":"A","price":"1.156370000","size":30,"channel_id":23,"order_id":"1775527735052073699","flags":128,"ts_in_delta":958,"sequence":148736,"symbol":"FCEU SI 20260615 PS"}
{"ts_recv":"2026-04-07T02:08:55.052145612Z","hd":{"ts_event":"2026-04-07T02:08:55.052129699Z","rtype":160,"publisher_id":101,"instrument_id":436},"action":"C","side":"B","price":"1.156260000","size":30,"channel_id":23,"order_id":"10998899771906052492","flags":0,"ts_in_delta":941,"sequence":148737,"symbol":"FCEU SI 20260615 PS"}
{"ts_recv":"2026-04-07T02:08:55.052145612Z","hd":{"ts_event":"2026-04-07T02:08:55.052129699Z","rtype":160,"publisher_id":101,"instrument_id":436},"action":"A","side":"B","price":"1.156270000","size":30,"channel_id":23,"order_id":"10998899771906911152","flags":0,"ts_in_delta":941,"sequence":148737,"symbol":"FCEU SI 20260615 PS"}
{"ts_recv":"2026-04-07T02:08:55.052145612Z","hd":{"ts_event":"2026-04-07T02:08:55.052129699Z","rtype":160,"publisher_id":101,"instrument_id":436},"action":"C","side":"A","price":"1.156360000","size":30,"channel_id":23,"order_id":"1775527735051276684","flags":0,"ts_in_delta":941,"sequence":148737,"symbol":"FCEU SI 20260615 PS"}
{"ts_recv":"2026-04-07T02:08:55.052145612Z","hd":{"ts_event":"2026-04-07T02:08:55.052129699Z","rtype":160,"publisher_id":101,"instrument_id":436},"action":"A","side":"A","price":"1.156370000","size":30,"channel_id":23,"order_id":"1775527735052135344","flags":128,"ts_in_delta":941,"sequence":148737,"symbol":"FCEU SI 20260615 PS"}
{"ts_recv":"2026-04-07T02:08:55.868074149Z","hd":{"ts_event":"2026-04-07T02:08:55.868053651Z","rtype":160,"publisher_id":101,"instrument_id":436},"action":"C","side":"B","price":"1.156270000","size":30,"channel_id":23,"order_id":"10998899771906911152","flags":0,"ts_in_delta":1772,"sequence":148760,"symbol":"FCEU SI 20260615 PS"}
{"ts_recv":"2026-04-07T02:08:55.868074149Z","hd":{"ts_event":"2026-04-07T02:08:55.868053651Z","rtype":160,"publisher_id":101,"instrument_id":436},"action":"A","side":"B","price":"1.156280000","size":30,"channel_id":23,"order_id":"10998899772722835637","flags":0,"ts_in_delta":1772,"sequence":148760,"symbol":"FCEU SI 20260615 PS"}
{"ts_recv":"2026-04-07T02:08:55.868074149Z","hd":{"ts_event":"2026-04-07T02:08:55.868053651Z","rtype":160,"publisher_id":101,"instrument_id":436},"action":"C","side":"A","price":"1.156370000","size":30,"channel_id":23,"order_id":"1775527735052135344","flags":0,"ts_in_delta":1772,"sequence":148760,"symbol":"FCEU SI 20260615 PS"}
{"ts_recv":"2026-04-07T02:08:55.868074149Z","hd":{"ts_event":"2026-04-07T02:08:55.868053651Z","rtype":160,"publisher_id":101,"instrument_id":436},"action":"A","side":"A","price":"1.156380000","size":30,"channel_id":23,"order_id":"1775527735868059829","flags":128,"ts_in_delta":1772,"sequence":148760,"symbol":"FCEU SI 20260615 PS"}
{"ts_recv":"2026-04-07T02:08:55.868128314Z","hd":{"ts_event":"2026-04-07T02:08:55.868108869Z","rtype":160,"publisher_id":101,"instrument_id":436},"action":"C","side":"B","price":"1.156270000","size":30,"channel_id":23,"order_id":"10998899771906849507","flags":0,"ts_in_delta":763,"sequence":148761,"symbol":"FCEU SI 20260615 PS"}
{"ts_recv":"2026-04-07T02:08:55.868128314Z","hd":{"ts_event":"2026-04-07T02:08:55.868108869Z","rtype":160,"publisher_id":101,"instrument_id":436},"action":"A","side":"B","price":"1.156290000","size":30,"channel_id":23,"order_id":"10998899772722890629","flags":0,"ts_in_delta":763,"sequence":148761,"symbol":"FCEU SI 20260615 PS"}
{"ts_recv":"2026-04-07T02:08:55.868128314Z","hd":{"ts_event":"2026-04-07T02:08:55.868108869Z","rtype":160,"publisher_id":101,"instrument_id":436},"action":"C","side":"A","price":"1.156370000","size":30,"channel_id":23,"order_id":"1775527735052073699","flags":0,"ts_in_delta":763,"sequence":148761,"symbol":"FCEU SI 20260615 PS"}
{"ts_recv":"2026-04-07T02:08:55.868128314Z","hd":{"ts_event":"2026-04-07T02:08:55.868108869Z","rtype":160,"publisher_id":101,"instrument_id":436},"action":"A","side":"A","price":"1.156390000","size":30,"channel_id":23,"order_id":"1775527735868114821","flags":128,"ts_in_delta":763,"sequence":148761,"symbol":"FCEU SI 20260615 PS"}
{"ts_recv":"2026-04-07T02:08:55.868151821Z","hd":{"ts_event":"2026-04-07T02:08:55.868135461Z","rtype":160,"publisher_id":101,"instrument_id":436},"action":"C","side":"B","price":"1.156280000","size":30,"channel_id":23,"order_id":"10998899772722835637","flags":0,"ts_in_delta":765,"sequence":148762,"symbol":"FCEU SI 20260615 PS"}
{"ts_recv":"2026-04-07T02:08:55.868151821Z","hd":{"ts_event":"2026-04-07T02:08:55.868135461Z","rtype":160,"publisher_id":101,"instrument_id":436},"action":"A","side":"B","price":"1.156290000","size":30,"channel_id":23,"order_id":"10998899772722917081","flags":0,"ts_in_delta":765,"sequence":148762,"symbol":"FCEU SI 20260615 PS"}
{"ts_recv":"2026-04-07T02:08:55.868151821Z","hd":{"ts_event":"2026-04-07T02:08:55.868135461Z","rtype":160,"publisher_id":101,"instrument_id":436},"action":"C","side":"A","price":"1.156380000","size":30,"channel_id":23,"order_id":"1775527735868059829","flags":0,"ts_in_delta":765,"sequence":148762,"symbol":"FCEU SI 20260615 PS"}
{"ts_recv":"2026-04-07T02:08:55.868151821Z","hd":{"ts_event":"2026-04-07T02:08:55.868135461Z","rtype":160,"publisher_id":101,"instrument_id":436},"action":"A","side":"A","price":"1.156390000","size":30,"channel_id":23,"order_id":"1775527735868141273","flags":128,"ts_in_delta":765,"sequence":148762,"symbol":"FCEU SI 20260615 PS"}
{"ts_recv":"2026-04-07T02:08:59.128361954Z","hd":{"ts_event":"2026-04-07T02:08:59.128334903Z","rtype":160,"publisher_id":101,"instrument_id":436},"action":"C","side":"B","price":"1.156290000","size":30,"channel_id":23,"order_id":"10998899772722917081","flags":0,"ts_in_delta":1720,"sequence":148797,"symbol":"FCEU SI 20260615 PS"}
{"ts_recv":"2026-04-07T02:08:59.128361954Z","hd":{"ts_event":"2026-04-07T02:08:59.128334903Z","rtype":160,"publisher_id":101,"instrument_id":436},"action":"A","side":"B","price":"1.156280000","size":30,"channel_id":23,"order_id":"10998899775983119526","flags":0,"ts_in_delta":1720,"sequence":148797,"symbol":"FCEU SI 20260615 PS"}
{"ts_recv":"2026-04-07T02:08:59.128361954Z","hd":{"ts_event":"2026-04-07T02:08:59.128334903Z","rtype":160,"publisher_id":101,"instrument_id":436},"action":"C","side":"A","price":"1.156390000","size":30,"channel_id":23,"order_id":"1775527735868141273","flags":0,"ts_in_delta":1720,"sequence":148797,"symbol":"FCEU SI 20260615 PS"}
{"ts_recv":"2026-04-07T02:08:59.128361954Z","hd":{"ts_event":"2026-04-07T02:08:59.128334903Z","rtype":160,"publisher_id":101,"instrument_id":436},"action":"A","side":"A","price":"1.156380000","size":30,"channel_id":23,"order_id":"1775527739128343718","flags":128,"ts_in_delta":1720,"sequence":148797,"symbol":"FCEU SI 20260615 PS"}
{"ts_recv":"2026-04-07T02:08:59.284149225Z","hd":{"ts_event":"2026-04-07T02:08:59.284129507Z","rtype":160,"publisher_id":101,"instrument_id":436},"action":"C","side":"B","price":"1.156280000","size":30,"channel_id":23,"order_id":"10998899775983119526","flags":0,"ts_in_delta":979,"sequence":148801,"symbol":"FCEU SI 20260615 PS"}
{"ts_recv":"2026-04-07T02:08:59.284149225Z","hd":{"ts_event":"2026-04-07T02:08:59.284129507Z","rtype":160,"publisher_id":101,"instrument_id":436},"action":"A","side":"B","price":"1.156260000","size":30,"channel_id":23,"order_id":"10998899776138911251","flags":0,"ts_in_delta":979,"sequence":148801,"symbol":"FCEU SI 20260615 PS"}
{"ts_recv":"2026-04-07T02:08:59.284149225Z","hd":{"ts_event":"2026-04-07T02:08:59.284129507Z","rtype":160,"publisher_id":101,"instrument_id":436},"action":"C","side":"A","price":"1.156380000","size":30,"channel_id":23,"order_id":"1775527739128343718","flags":0,"ts_in_delta":979,"sequence":148801,"symbol":"FCEU SI 20260615 PS"}
{"ts_recv":"2026-04-07T02:08:59.284149225Z","hd":{"ts_event":"2026-04-07T02:08:59.284129507Z","rtype":160,"publisher_id":101,"instrument_id":436},"action":"A","side":"A","price":"1.156360000","size":30,"channel_id":23,"order_id":"1775527739284135443","flags":128,"ts_in_delta":979,"sequence":148801,"symbol":"FCEU SI 20260615 PS"}
{"ts_recv":"2026-04-07T02:08:59.284220746Z","hd":{"ts_event":"2026-04-07T02:08:59.284201507Z","rtype":160,"publisher_id":101,"instrument_id":436},"action":"C","side":"B","price":"1.156290000","size":30,"channel_id":23,"order_id":"10998899772722890629","flags":0,"ts_in_delta":974,"sequence":148802,"symbol":"FCEU SI 20260615 PS"}
{"ts_recv":"2026-04-07T02:08:59.284220746Z","hd":{"ts_event":"2026-04-07T02:08:59.284201507Z","rtype":160,"publisher_id":101,"instrument_id":436},"action":"A","side":"B","price":"1.156270000","size":30,"channel_id":23,"order_id":"10998899776138983712","flags":0,"ts_in_delta":974,"sequence":148802,"symbol":"FCEU SI 20260615 PS"}
{"ts_recv":"2026-04-07T02:08:59.284220746Z","hd":{"ts_event":"2026-04-07T02:08:59.284201507Z","rtype":160,"publisher_id":101,"instrument_id":436},"action":"C","side":"A","price":"1.156390000","size":30,"channel_id":23,"order_id":"1775527735868114821","flags":0,"ts_in_delta":974,"sequence":148802,"symbol":"FCEU SI 20260615 PS"}
{"ts_recv":"2026-04-07T02:08:59.284220746Z","hd":{"ts_event":"2026-04-07T02:08:59.284201507Z","rtype":160,"publisher_id":101,"instrument_id":436},"action":"A","side":"A","price":"1.156370000","size":30,"channel_id":23,"order_id":"1775527739284207904","flags":128,"ts_in_delta":974,"sequence":148802,"symbol":"FCEU SI 20260615 PS"}
{"ts_recv":"2026-04-07T02:08:59.284233594Z","hd":{"ts_event":"2026-04-07T02:08:59.284203845Z","rtype":160,"publisher_id":101,"instrument_id":436},"action":"C","side":"B","price":"1.156260000","size":30,"channel_id":23,"order_id":"10998899776138911251","flags":0,"ts_in_delta":984,"sequence":148803,"symbol":"FCEU SI 20260615 PS"}
{"ts_recv":"2026-04-07T02:08:59.284233594Z","hd":{"ts_event":"2026-04-07T02:08:59.284203845Z","rtype":160,"publisher_id":101,"instrument_id":436},"action":"A","side":"B","price":"1.156280000","size":30,"channel_id":23,"order_id":"10998899776138993382","flags":0,"ts_in_delta":984,"sequence":148803,"symbol":"FCEU SI 20260615 PS"}
{"ts_recv":"2026-04-07T02:08:59.284233594Z","hd":{"ts_event":"2026-04-07T02:08:59.284203845Z","rtype":160,"publisher_id":101,"instrument_id":436},"action":"C","side":"A","price":"1.156360000","size":30,"channel_id":23,"order_id":"1775527739284135443","flags":0,"ts_in_delta":984,"sequence":148803,"symbol":"FCEU SI 20260615 PS"}
{"ts_recv":"2026-04-07T02:08:59.284233594Z","hd":{"ts_event":"2026-04-07T02:08:59.284203845Z","rtype":160,"publisher_id":101,"instrument_id":436},"action":"A","side":"A","price":"1.156380000","size":30,"channel_id":23,"order_id":"1775527739284217574","flags":128,"ts_in_delta":984,"sequence":148803,"symbol":"FCEU SI 20260615 PS"}
{"ts_recv":"2026-04-07T02:08:59.284291568Z","hd":{"ts_event":"2026-04-07T02:08:59.284274641Z","rtype":160,"publisher_id":101,"instrument_id":436},"action":"C","side":"B","price":"1.156280000","size":30,"channel_id":23,"order_id":"10998899776138993382","flags":0,"ts_in_delta":936,"sequence":148804,"symbol":"FCEU SI 20260615 PS"}
{"ts_recv":"2026-04-07T02:08:59.284291568Z","hd":{"ts_event":"2026-04-07T02:08:59.284274641Z","rtype":160,"publisher_id":101,"instrument_id":436},"action":"A","side":"B","price":"1.156270000","size":30,"channel_id":23,"order_id":"10998899776139056414","flags":0,"ts_in_delta":936,"sequence":148804,"symbol":"FCEU SI 20260615 PS"}
{"ts_recv":"2026-04-07T02:08:59.284291568Z","hd":{"ts_event":"2026-04-07T02:08:59.284274641Z","rtype":160,"publisher_id":101,"instrument_id":436},"action":"C","side":"A","price":"1.156380000","size":30,"channel_id":23,"order_id":"1775527739284217574","flags":0,"ts_in_delta":936,"sequence":148804,"symbol":"FCEU SI 20260615 PS"}
{"ts_recv":"2026-04-07T02:08:59.284291568Z","hd":{"ts_event":"2026-04-07T02:08:59.284274641Z","rtype":160,"publisher_id":101,"instrument_id":436},"action":"A","side":"A","price":"1.156370000","size":30,"channel_id":23,"order_id":"1775527739284280606","flags":128,"ts_in_delta":936,"sequence":148804,"symbol":"FCEU SI 20260615 PS"}
{"ts_recv":"2026-04-07T02:09:02.403448940Z","hd":{"ts_event":"2026-04-07T02:09:02.403429359Z","rtype":160,"publisher_id":101,"instrument_id":436},"action":"C","side":"B","price":"1.156270000","size":30,"channel_id":23,"order_id":"10998899776139056414","flags":0,"ts_in_delta":956,"sequence":148861,"symbol":"FCEU SI 20260615 PS"}
{"ts_recv":"2026-04-07T02:09:02.403448940Z","hd":{"ts_event":"2026-04-07T02:09:02.403429359Z","rtype":160,"publisher_id":101,"instrument_id":436},"action":"A","side":"B","price":"1.156260000","size":30,"channel_id":23,"order_id":"10998899779258211317","flags":0,"ts_in_delta":956,"sequence":148861,"symbol":"FCEU SI 20260615 PS"}
{"ts_recv":"2026-04-07T02:09:02.403448940Z","hd":{"ts_event":"2026-04-07T02:09:02.403429359Z","rtype":160,"publisher_id":101,"instrument_id":436},"action":"C","side":"A","price":"1.156370000","size":30,"channel_id":23,"order_id":"1775527739284280606","flags":0,"ts_in_delta":956,"sequence":148861,"symbol":"FCEU SI 20260615 PS"}
{"ts_recv":"2026-04-07T02:09:02.403448940Z","hd":{"ts_event":"2026-04-07T02:09:02.403429359Z","rtype":160,"publisher_id":101,"instrument_id":436},"action":"A","side":"A","price":"1.156360000","size":30,"channel_id":23,"order_id":"1775527742403435509","flags":128,"ts_in_delta":956,"sequence":148861,"symbol":"FCEU SI 20260615 PS"}
{"ts_recv":"2026-04-07T02:09:02.422841947Z","hd":{"ts_event":"2026-04-07T02:09:02.422821555Z","rtype":160,"publisher_id":101,"instrument_id":436},"action":"C","side":"B","price":"1.156260000","size":30,"channel_id":23,"order_id":"10998899779258211317","flags":0,"ts_in_delta":983,"sequence":148867,"symbol":"FCEU SI 20260615 PS"}
{"ts_recv":"2026-04-07T02:09:02.422841947Z","hd":{"ts_event":"2026-04-07T02:09:02.422821555Z","rtype":160,"publisher_id":101,"instrument_id":436},"action":"A","side":"B","price":"1.156250000","size":30,"channel_id":23,"order_id":"10998899779277603246","flags":0,"ts_in_delta":983,"sequence":148867,"symbol":"FCEU SI 20260615 PS"}
{"ts_recv":"2026-04-07T02:09:02.422841947Z","hd":{"ts_event":"2026-04-07T02:09:02.422821555Z","rtype":160,"publisher_id":101,"instrument_id":436},"action":"C","side":"A","price":"1.156360000","size":30,"channel_id":23,"order_id":"1775527742403435509","flags":0,"ts_in_delta":983,"sequence":148867,"symbol":"FCEU SI 20260615 PS"}
{"ts_recv":"2026-04-07T02:09:02.422841947Z","hd":{"ts_event":"2026-04-07T02:09:02.422821555Z","rtype":160,"publisher_id":101,"instrument_id":436},"action":"A","side":"A","price":"1.156350000","size":30,"channel_id":23,"order_id":"1775527742422827438","flags":128,"ts_in_delta":983,"sequence":148867,"symbol":"FCEU SI 20260615 PS"}
{"ts_recv":"2026-04-07T02:09:02.422898085Z","hd":{"ts_event":"2026-04-07T02:09:02.422879269Z","rtype":160,"publisher_id":101,"instrument_id":436},"action":"C","side":"B","price":"1.156270000","size":30,"channel_id":23,"order_id":"10998899776138983712","flags":0,"ts_in_delta":987,"sequence":148868,"symbol":"FCEU SI 20260615 PS"}
{"ts_recv":"2026-04-07T02:09:02.422898085Z","hd":{"ts_event":"2026-04-07T02:09:02.422879269Z","rtype":160,"publisher_id":101,"instrument_id":436},"action":"A","side":"B","price":"1.156250000","size":30,"channel_id":23,"order_id":"10998899779277660965","flags":0,"ts_in_delta":987,"sequence":148868,"symbol":"FCEU SI 20260615 PS"}
{"ts_recv":"2026-04-07T02:09:02.422898085Z","hd":{"ts_event":"2026-04-07T02:09:02.422879269Z","rtype":160,"publisher_id":101,"instrument_id":436},"action":"C","side":"A","price":"1.156370000","size":30,"channel_id":23,"order_id":"1775527739284207904","flags":0,"ts_in_delta":987,"sequence":148868,"symbol":"FCEU SI 20260615 PS"}
{"ts_recv":"2026-04-07T02:09:02.422898085Z","hd":{"ts_event":"2026-04-07T02:09:02.422879269Z","rtype":160,"publisher_id":101,"instrument_id":436},"action":"A","side":"A","price":"1.156350000","size":30,"channel_id":23,"order_id":"1775527742422885157","flags":128,"ts_in_delta":987,"sequence":148868,"symbol":"FCEU SI 20260615 PS"}
{"ts_recv":"2026-04-07T02:09:02.422953632Z","hd":{"ts_event":"2026-04-07T02:09:02.422934041Z","rtype":160,"publisher_id":101,"instrument_id":436},"action":"C","side":"B","price":"1.156250000","size":30,"channel_id":23,"order_id":"10998899779277603246","flags":0,"ts_in_delta":975,"sequence":148869,"symbol":"FCEU SI 20260615 PS"}
{"ts_recv":"2026-04-07T02:09:02.422953632Z","hd":{"ts_event":"2026-04-07T02:09:02.422934041Z","rtype":160,"publisher_id":101,"instrument_id":436},"action":"A","side":"B","price":"1.156240000","size":30,"channel_id":23,"order_id":"10998899779277715731","flags":0,"ts_in_delta":975,"sequence":148869,"symbol":"FCEU SI 20260615 PS"}
{"ts_recv":"2026-04-07T02:09:02.422953632Z","hd":{"ts_event":"2026-04-07T02:09:02.422934041Z","rtype":160,"publisher_id":101,"instrument_id":436},"action":"C","side":"A","price":"1.156350000","size":30,"channel_id":23,"order_id":"1775527742422827438","flags":0,"ts_in_delta":975,"sequence":148869,"symbol":"FCEU SI 20260615 PS"}
{"ts_recv":"2026-04-07T02:09:02.422953632Z","hd":{"ts_event":"2026-04-07T02:09:02.422934041Z","rtype":160,"publisher_id":101,"instrument_id":436},"action":"A","side":"A","price":"1.156340000","size":30,"channel_id":23,"order_id":"1775527742422939923","flags":128,"ts_in_delta":975,"sequence":148869,"symbol":"FCEU SI 20260615 PS"}
{"ts_recv":"2026-04-07T02:09:08.328347191Z","hd":{"ts_event":"2026-04-07T02:09:08.328328997Z","rtype":160,"publisher_id":101,"instrument_id":436},"action":"C","side":"B","price":"1.156240000","size":30,"channel_id":23,"order_id":"10998899779277715731","flags":0,"ts_in_delta":1224,"sequence":148922,"symbol":"FCEU SI 20260615 PS"}
{"ts_recv":"2026-04-07T02:09:08.328347191Z","hd":{"ts_event":"2026-04-07T02:09:08.328328997Z","rtype":160,"publisher_id":101,"instrument_id":436},"action":"A","side":"B","price":"1.156250000","size":30,"channel_id":23,"order_id":"10998899785183111032","flags":0,"ts_in_delta":1224,"sequence":148922,"symbol":"FCEU SI 20260615 PS"}
{"ts_recv":"2026-04-07T02:09:08.328347191Z","hd":{"ts_event":"2026-04-07T02:09:08.328328997Z","rtype":160,"publisher_id":101,"instrument_id":436},"action":"C","side":"A","price":"1.156340000","size":30,"channel_id":23,"order_id":"1775527742422939923","flags":0,"ts_in_delta":1224,"sequence":148922,"symbol":"FCEU SI 20260615 PS"}
{"ts_recv":"2026-04-07T02:09:08.328347191Z","hd":{"ts_event":"2026-04-07T02:09:08.328328997Z","rtype":160,"publisher_id":101,"instrument_id":436},"action":"A","side":"A","price":"1.156350000","size":30,"channel_id":23,"order_id":"1775527748328335224","flags":128,"ts_in_delta":1224,"sequence":148922,"symbol":"FCEU SI 20260615 PS"}
{"ts_recv":"2026-04-07T02:09:08.337934702Z","hd":{"ts_event":"2026-04-07T02:09:08.337914777Z","rtype":160,"publisher_id":101,"instrument_id":436},"action":"C","side":"B","price":"1.156250000","size":30,"channel_id":23,"order_id":"10998899785183111032","flags":0,"ts_in_delta":967,"sequence":148928,"symbol":"FCEU SI 20260615 PS"}
{"ts_recv":"2026-04-07T02:09:08.337934702Z","hd":{"ts_event":"2026-04-07T02:09:08.337914777Z","rtype":160,"publisher_id":101,"instrument_id":436},"action":"A","side":"B","price":"1.156260000","size":30,"channel_id":23,"order_id":"10998899785192696470","flags":0,"ts_in_delta":967,"sequence":148928,"symbol":"FCEU SI 20260615 PS"}
{"ts_recv":"2026-04-07T02:09:08.337934702Z","hd":{"ts_event":"2026-04-07T02:09:08.337914777Z","rtype":160,"publisher_id":101,"instrument_id":436},"action":"C","side":"A","price":"1.156350000","size":30,"channel_id":23,"order_id":"1775527748328335224","flags":0,"ts_in_delta":967,"sequence":148928,"symbol":"FCEU SI 20260615 PS"}
{"ts_recv":"2026-04-07T02:09:08.337934702Z","hd":{"ts_event":"2026-04-07T02:09:08.337914777Z","rtype":160,"publisher_id":101,"instrument_id":436},"action":"A","side":"A","price":"1.156360000","size":30,"channel_id":23,"order_id":"1775527748337920662","flags":128,"ts_in_delta":967,"sequence":148928,"symbol":"FCEU SI 20260615 PS"}
{"ts_recv":"2026-04-07T02:09:08.337988359Z","hd":{"ts_event":"2026-04-07T02:09:08.337967347Z","rtype":160,"publisher_id":101,"instrument_id":436},"action":"C","side":"B","price":"1.156250000","size":30,"channel_id":23,"order_id":"10998899779277660965","flags":0,"ts_in_delta":1180,"sequence":148929,"symbol":"FCEU SI 20260615 PS"}
{"ts_recv":"2026-04-07T02:09:08.337988359Z","hd":{"ts_event":"2026-04-07T02:09:08.337967347Z","rtype":160,"publisher_id":101,"instrument_id":436},"action":"A","side":"B","price":"1.156270000","size":30,"channel_id":23,"order_id":"10998899785192749034","flags":0,"ts_in_delta":1180,"sequence":148929,"symbol":"FCEU SI 20260615 PS"}
{"ts_recv":"2026-04-07T02:09:08.337988359Z","hd":{"ts_event":"2026-04-07T02:09:08.337967347Z","rtype":160,"publisher_id":101,"instrument_id":436},"action":"C","side":"A","price":"1.156350000","size":30,"channel_id":23,"order_id":"1775527742422885157","flags":0,"ts_in_delta":1180,"sequence":148929,"symbol":"FCEU SI 20260615 PS"}
{"ts_recv":"2026-04-07T02:09:08.337988359Z","hd":{"ts_event":"2026-04-07T02:09:08.337967347Z","rtype":160,"publisher_id":101,"instrument_id":436},"action":"A","side":"A","price":"1.156370000","size":30,"channel_id":23,"order_id":"1775527748337973226","flags":128,"ts_in_delta":1180,"sequence":148929,"symbol":"FCEU SI 20260615 PS"}
{"ts_recv":"2026-04-07T02:09:08.338042317Z","hd":{"ts_event":"2026-04-07T02:09:08.338025697Z","rtype":160,"publisher_id":101,"instrument_id":436},"action":"C","side":"B","price":"1.156260000","size":30,"channel_id":23,"order_id":"10998899785192696470","flags":0,"ts_in_delta":1131,"sequence":148930,"symbol":"FCEU SI 20260615 PS"}
{"ts_recv":"2026-04-07T02:09:08.338042317Z","hd":{"ts_event":"2026-04-07T02:09:08.338025697Z","rtype":160,"publisher_id":101,"instrument_id":436},"action":"A","side":"B","price":"1.156270000","size":30,"channel_id":23,"order_id":"10998899785192807391","flags":0,"ts_in_delta":1131,"sequence":148930,"symbol":"FCEU SI 20260615 PS"}
{"ts_recv":"2026-04-07T02:09:08.338042317Z","hd":{"ts_event":"2026-04-07T02:09:08.338025697Z","rtype":160,"publisher_id":101,"instrument_id":436},"action":"C","side":"A","price":"1.156360000","size":30,"channel_id":23,"order_id":"1775527748337920662","flags":0,"ts_in_delta":1131,"sequence":148930,"symbol":"FCEU SI 20260615 PS"}
{"ts_recv":"2026-04-07T02:09:08.338042317Z","hd":{"ts_event":"2026-04-07T02:09:08.338025697Z","rtype":160,"publisher_id":101,"instrument_id":436},"action":"A","side":"A","price":"1.156370000","size":30,"channel_id":23,"order_id":"1775527748338031583","flags":128,"ts_in_delta":1131,"sequence":148930,"symbol":"FCEU SI 20260615 PS"}
{"ts_recv":"2026-04-07T02:09:13.016960390Z","hd":{"ts_event":"2026-04-07T02:09:13.016938789Z","rtype":160,"publisher_id":101,"instrument_id":436},"action":"C","side":"B","price":"1.156270000","size":30,"channel_id":23,"order_id":"10998899785192807391","flags":0,"ts_in_delta":885,"sequence":149025,"symbol":"FCEU SI 20260615 PS"}
{"ts_recv":"2026-04-07T02:09:13.016960390Z","hd":{"ts_event":"2026-04-07T02:09:13.016938789Z","rtype":160,"publisher_id":101,"instrument_id":436},"action":"A","side":"B","price":"1.156280000","size":30,"channel_id":23,"order_id":"10998899789871721228","flags":0,"ts_in_delta":885,"sequence":149025,"symbol":"FCEU SI 20260615 PS"}
{"ts_recv":"2026-04-07T02:09:13.016960390Z","hd":{"ts_event":"2026-04-07T02:09:13.016938789Z","rtype":160,"publisher_id":101,"instrument_id":436},"action":"C","side":"A","price":"1.156370000","size":30,"channel_id":23,"order_id":"1775527748338031583","flags":0,"ts_in_delta":885,"sequence":149025,"symbol":"FCEU SI 20260615 PS"}
{"ts_recv":"2026-04-07T02:09:13.016960390Z","hd":{"ts_event":"2026-04-07T02:09:13.016938789Z","rtype":160,"publisher_id":101,"instrument_id":436},"action":"A","side":"A","price":"1.156380000","size":30,"channel_id":23,"order_id":"1775527753016945420","flags":128,"ts_in_delta":885,"sequence":149025,"symbol":"FCEU SI 20260615 PS"}
{"ts_recv":"2026-04-07T02:09:13.017022841Z","hd":{"ts_event":"2026-04-07T02:09:13.017001913Z","rtype":160,"publisher_id":101,"instrument_id":436},"action":"C","side":"B","price":"1.156270000","size":30,"channel_id":23,"order_id":"10998899785192749034","flags":0,"ts_in_delta":892,"sequence":149026,"symbol":"FCEU SI 20260615 PS"}
{"ts_recv":"2026-04-07T02:09:13.017022841Z","hd":{"ts_event":"2026-04-07T02:09:13.017001913Z","rtype":160,"publisher_id":101,"instrument_id":436},"action":"A","side":"B","price":"1.156290000","size":30,"channel_id":23,"order_id":"10998899789871783821","flags":0,"ts_in_delta":892,"sequence":149026,"symbol":"FCEU SI 20260615 PS"}
{"ts_recv":"2026-04-07T02:09:13.017022841Z","hd":{"ts_event":"2026-04-07T02:09:13.017001913Z","rtype":160,"publisher_id":101,"instrument_id":436},"action":"C","side":"A","price":"1.156370000","size":30,"channel_id":23,"order_id":"1775527748337973226","flags":0,"ts_in_delta":892,"sequence":149026,"symbol":"FCEU SI 20260615 PS"}
{"ts_recv":"2026-04-07T02:09:13.017022841Z","hd":{"ts_event":"2026-04-07T02:09:13.017001913Z","rtype":160,"publisher_id":101,"instrument_id":436},"action":"A","side":"A","price":"1.156390000","size":30,"channel_id":23,"order_id":"1775527753017008013","flags":128,"ts_in_delta":892,"sequence":149026,"symbol":"FCEU SI 20260615 PS"}
{"ts_recv":"2026-04-07T02:09:13.017042033Z","hd":{"ts_event":"2026-04-07T02:09:13.017025907Z","rtype":160,"publisher_id":101,"instrument_id":436},"action":"C","side":"B","price":"1.156280000","size":30,"channel_id":23,"order_id":"10998899789871721228","flags":0,"ts_in_delta":883,"sequence":149027,"symbol":"FCEU SI 20260615 PS"}
{"ts_recv":"2026-04-07T02:09:13.017042033Z","hd":{"ts_event":"2026-04-07T02:09:13.017025907Z","rtype":160,"publisher_id":101,"instrument_id":436},"action":"A","side":"B","price":"1.156290000","size":30,"channel_id":23,"order_id":"10998899789871807950","flags":0,"ts_in_delta":883,"sequence":149027,"symbol":"FCEU SI 20260615 PS"}
{"ts_recv":"2026-04-07T02:09:13.017042033Z","hd":{"ts_event":"2026-04-07T02:09:13.017025907Z","rtype":160,"publisher_id":101,"instrument_id":436},"action":"C","side":"A","price":"1.156380000","size":30,"channel_id":23,"order_id":"1775527753016945420","flags":0,"ts_in_delta":883,"sequence":149027,"symbol":"FCEU SI 20260615 PS"}
{"ts_recv":"2026-04-07T02:09:13.017042033Z","hd":{"ts_event":"2026-04-07T02:09:13.017025907Z","rtype":160,"publisher_id":101,"instrument_id":436},"action":"A","side":"A","price":"1.156390000","size":30,"channel_id":23,"order_id":"1775527753017032142","flags":128,"ts_in_delta":883,"sequence":149027,"symbol":"FCEU SI 20260615 PS"}
{"ts_recv":"2026-04-07T02:09:14.153973850Z","hd":{"ts_event":"2026-04-07T02:09:14.153954453Z","rtype":160,"publisher_id":101,"instrument_id":436},"action":"C","side":"B","price":"1.156290000","size":30,"channel_id":23,"order_id":"10998899789871807950","flags":0,"ts_in_delta":862,"sequence":149045,"symbol":"FCEU SI 20260615 PS"}
{"ts_recv":"2026-04-07T02:09:14.153973850Z","hd":{"ts_event":"2026-04-07T02:09:14.153954453Z","rtype":160,"publisher_id":101,"instrument_id":436},"action":"A","side":"B","price":"1.156280000","size":30,"channel_id":23,"order_id":"10998899791008736195","flags":0,"ts_in_delta":862,"sequence":149045,"symbol":"FCEU SI 20260615 PS"}
{"ts_recv":"2026-04-07T02:09:14.153973850Z","hd":{"ts_event":"2026-04-07T02:09:14.153954453Z","rtype":160,"publisher_id":101,"instrument_id":436},"action":"C","side":"A","price":"1.156390000","size":30,"channel_id":23,"order_id":"1775527753017032142","flags":0,"ts_in_delta":862,"sequence":149045,"symbol":"FCEU SI 20260615 PS"}
{"ts_recv":"2026-04-07T02:09:14.153973850Z","hd":{"ts_event":"2026-04-07T02:09:14.153954453Z","rtype":160,"publisher_id":101,"instrument_id":436},"action":"A","side":"A","price":"1.156380000","size":30,"channel_id":23,"order_id":"1775527754153960387","flags":128,"ts_in_delta":862,"sequence":149045,"symbol":"FCEU SI 20260615 PS"}
{"ts_recv":"2026-04-07T02:09:18.110305450Z","hd":{"ts_event":"2026-04-07T02:09:18.110284675Z","rtype":160,"publisher_id":101,"instrument_id":436},"action":"C","side":"B","price":"1.156280000","size":30,"channel_id":23,"order_id":"10998899791008736195","flags":0,"ts_in_delta":953,"sequence":149080,"symbol":"FCEU SI 20260615 PS"}
{"ts_recv":"2026-04-07T02:09:18.110305450Z","hd":{"ts_event":"2026-04-07T02:09:18.110284675Z","rtype":160,"publisher_id":101,"instrument_id":436},"action":"A","side":"B","price":"1.156270000","size":30,"channel_id":23,"order_id":"10998899794965066548","flags":0,"ts_in_delta":953,"sequence":149080,"symbol":"FCEU SI 20260615 PS"}
{"ts_recv":"2026-04-07T02:09:18.110305450Z","hd":{"ts_event":"2026-04-07T02:09:18.110284675Z","rtype":160,"publisher_id":101,"instrument_id":436},"action":"C","side":"A","price":"1.156380000","size":30,"channel_id":23,"order_id":"1775527754153960387","flags":0,"ts_in_delta":953,"sequence":149080,"symbol":"FCEU SI 20260615 PS"}
{"ts_recv":"2026-04-07T02:09:18.110305450Z","hd":{"ts_event":"2026-04-07T02:09:18.110284675Z","rtype":160,"publisher_id":101,"instrument_id":436},"action":"A","side":"A","price":"1.156370000","size":30,"channel_id":23,"order_id":"1775527758110290740","flags":128,"ts_in_delta":953,"sequence":149080,"symbol":"FCEU SI 20260615 PS"}
{"ts_recv":"2026-04-07T02:09:18.110362441Z","hd":{"ts_event":"2026-04-07T02:09:18.110344539Z","rtype":160,"publisher_id":101,"instrument_id":436},"action":"C","side":"B","price":"1.156290000","size":30,"channel_id":23,"order_id":"10998899789871783821","flags":0,"ts_in_delta":987,"sequence":149081,"symbol":"FCEU SI 20260615 PS"}
{"ts_recv":"2026-04-07T02:09:18.110362441Z","hd":{"ts_event":"2026-04-07T02:09:18.110344539Z","rtype":160,"publisher_id":101,"instrument_id":436},"action":"A","side":"B","price":"1.156270000","size":30,"channel_id":23,"order_id":"10998899794965126242","flags":0,"ts_in_delta":987,"sequence":149081,"symbol":"FCEU SI 20260615 PS"}
{"ts_recv":"2026-04-07T02:09:18.110362441Z","hd":{"ts_event":"2026-04-07T02:09:18.110344539Z","rtype":160,"publisher_id":101,"instrument_id":436},"action":"C","side":"A","price":"1.156390000","size":30,"channel_id":23,"order_id":"1775527753017008013","flags":0,"ts_in_delta":987,"sequence":149081,"symbol":"FCEU SI 20260615 PS"}
{"ts_recv":"2026-04-07T02:09:18.110362441Z","hd":{"ts_event":"2026-04-07T02:09:18.110344539Z","rtype":160,"publisher_id":101,"instrument_id":436},"action":"A","side":"A","price":"1.156370000","size":30,"channel_id":23,"order_id":"1775527758110350434","flags":128,"ts_in_delta":987,"sequence":149081,"symbol":"FCEU SI 20260615 PS"}
{"ts_recv":"2026-04-07T02:09:18.110410705Z","hd":{"ts_event":"2026-04-07T02:09:18.110388143Z","rtype":160,"publisher_id":101,"instrument_id":436},"action":"C","side":"B","price":"1.156270000","size":30,"channel_id":23,"order_id":"10998899794965066548","flags":0,"ts_in_delta":1462,"sequence":149082,"symbol":"FCEU SI 20260615 PS"}
{"ts_recv":"2026-04-07T02:09:18.110410705Z","hd":{"ts_event":"2026-04-07T02:09:18.110388143Z","rtype":160,"publisher_id":101,"instrument_id":436},"action":"A","side":"B","price":"1.156280000","size":30,"channel_id":23,"order_id":"10998899794965170125","flags":0,"ts_in_delta":1462,"sequence":149082,"symbol":"FCEU SI 20260615 PS"}
{"ts_recv":"2026-04-07T02:09:18.110410705Z","hd":{"ts_event":"2026-04-07T02:09:18.110388143Z","rtype":160,"publisher_id":101,"instrument_id":436},"action":"C","side":"A","price":"1.156370000","size":30,"channel_id":23,"order_id":"1775527758110290740","flags":0,"ts_in_delta":1462,"sequence":149082,"symbol":"FCEU SI 20260615 PS"}
{"ts_recv":"2026-04-07T02:09:18.110410705Z","hd":{"ts_event":"2026-04-07T02:09:18.110388143Z","rtype":160,"publisher_id":101,"instrument_id":436},"action":"A","side":"A","price":"1.156380000","size":30,"channel_id":23,"order_id":"1775527758110394317","flags":128,"ts_in_delta":1462,"sequence":149082,"symbol":"FCEU SI 20260615 PS"}
{"ts_recv":"2026-04-07T02:09:18.110491397Z","hd":{"ts_event":"2026-04-07T02:09:18.110475543Z","rtype":160,"publisher_id":101,"instrument_id":436},"action":"C","side":"B","price":"1.156280000","size":30,"channel_id":23,"order_id":"10998899794965170125","flags":0,"ts_in_delta":924,"sequence":149083,"symbol":"FCEU SI 20260615 PS"}
{"ts_recv":"2026-04-07T02:09:18.110491397Z","hd":{"ts_event":"2026-04-07T02:09:18.110475543Z","rtype":160,"publisher_id":101,"instrument_id":436},"action":"A","side":"B","price":"1.156270000","size":30,"channel_id":23,"order_id":"10998899794965257021","flags":0,"ts_in_delta":924,"sequence":149083,"symbol":"FCEU SI 20260615 PS"}
{"ts_recv":"2026-04-07T02:09:18.110491397Z","hd":{"ts_event":"2026-04-07T02:09:18.110475543Z","rtype":160,"publisher_id":101,"instrument_id":436},"action":"C","side":"A","price":"1.156380000","size":30,"channel_id":23,"order_id":"1775527758110394317","flags":0,"ts_in_delta":924,"sequence":149083,"symbol":"FCEU SI 20260615 PS"}
{"ts_recv":"2026-04-07T02:09:18.110491397Z","hd":{"ts_event":"2026-04-07T02:09:18.110475543Z","rtype":160,"publisher_id":101,"instrument_id":436},"action":"A","side":"A","price":"1.156370000","size":30,"channel_id":23,"order_id":"1775527758110481213","flags":128,"ts_in_delta":924,"sequence":149083,"symbol":"FCEU SI 20260615 PS"}
{"ts_recv":"2026-04-07T02:09:19.235151191Z","hd":{"ts_event":"2026-04-07T02:09:19.235125449Z","rtype":160,"publisher_id":101,"instrument_id":436},"action":"C","side":"B","price":"1.156270000","size":30,"channel_id":23,"order_id":"10998899794965126242","flags":0,"ts_in_delta":898,"sequence":149109,"symbol":"FCEU SI 20260615 PS"}
{"ts_recv":"2026-04-07T02:09:19.235151191Z","hd":{"ts_event":"2026-04-07T02:09:19.235125449Z","rtype":160,"publisher_id":101,"instrument_id":436},"action":"A","side":"B","price":"1.156290000","size":30,"channel_id":23,"order_id":"10998899796089911814","flags":0,"ts_in_delta":898,"sequence":149109,"symbol":"FCEU SI 20260615 PS"}
{"ts_recv":"2026-04-07T02:09:19.235151191Z","hd":{"ts_event":"2026-04-07T02:09:19.235125449Z","rtype":160,"publisher_id":101,"instrument_id":436},"action":"C","side":"A","price":"1.156370000","size":30,"channel_id":23,"order_id":"1775527758110350434","flags":0,"ts_in_delta":898,"sequence":149109,"symbol":"FCEU SI 20260615 PS"}
{"ts_recv":"2026-04-07T02:09:19.235151191Z","hd":{"ts_event":"2026-04-07T02:09:19.235125449Z","rtype":160,"publisher_id":101,"instrument_id":436},"action":"A","side":"A","price":"1.156390000","size":30,"channel_id":23,"order_id":"1775527759235136006","flags":128,"ts_in_delta":898,"sequence":149109,"symbol":"FCEU SI 20260615 PS"}
{"ts_recv":"2026-04-07T02:09:19.235220884Z","hd":{"ts_event":"2026-04-07T02:09:19.235200097Z","rtype":160,"publisher_id":101,"instrument_id":436},"action":"C","side":"B","price":"1.156290000","size":30,"channel_id":23,"order_id":"10998899796089911814","flags":0,"ts_in_delta":1070,"sequence":149110,"symbol":"FCEU SI 20260615 PS"}
{"ts_recv":"2026-04-07T02:09:19.235220884Z","hd":{"ts_event":"2026-04-07T02:09:19.235200097Z","rtype":160,"publisher_id":101,"instrument_id":436},"action":"A","side":"B","price":"1.156310000","size":30,"channel_id":23,"order_id":"10998899796089981998","flags":0,"ts_in_delta":1070,"sequence":149110,"symbol":"FCEU SI 20260615 PS"}
{"ts_recv":"2026-04-07T02:09:19.235220884Z","hd":{"ts_event":"2026-04-07T02:09:19.235200097Z","rtype":160,"publisher_id":101,"instrument_id":436},"action":"C","side":"A","price":"1.156390000","size":30,"channel_id":23,"order_id":"1775527759235136006","flags":0,"ts_in_delta":1070,"sequence":149110,"symbol":"FCEU SI 20260615 PS"}
{"ts_recv":"2026-04-07T02:09:19.235220884Z","hd":{"ts_event":"2026-04-07T02:09:19.235200097Z","rtype":160,"publisher_id":101,"instrument_id":436},"action":"A","side":"A","price":"1.156410000","size":30,"channel_id":23,"order_id":"1775527759235206190","flags":128,"ts_in_delta":1070,"sequence":149110,"symbol":"FCEU SI 20260615 PS"}
{"ts_recv":"2026-04-07T02:09:19.235230200Z","hd":{"ts_event":"2026-04-07T02:09:19.235213577Z","rtype":160,"publisher_id":101,"instrument_id":436},"action":"C","side":"B","price":"1.156270000","size":30,"channel_id":23,"order_id":"10998899794965257021","flags":0,"ts_in_delta":919,"sequence":149111,"symbol":"FCEU SI 20260615 PS"}
{"ts_recv":"2026-04-07T02:09:19.235230200Z","hd":{"ts_event":"2026-04-07T02:09:19.235213577Z","rtype":160,"publisher_id":101,"instrument_id":436},"action":"A","side":"B","price":"1.156280000","size":30,"channel_id":23,"order_id":"10998899796089995307","flags":0,"ts_in_delta":919,"sequence":149111,"symbol":"FCEU SI 20260615 PS"}
{"ts_recv":"2026-04-07T02:09:19.235230200Z","hd":{"ts_event":"2026-04-07T02:09:19.235213577Z","rtype":160,"publisher_id":101,"instrument_id":436},"action":"C","side":"A","price":"1.156370000","size":30,"channel_id":23,"order_id":"1775527758110481213","flags":0,"ts_in_delta":919,"sequence":149111,"symbol":"FCEU SI 20260615 PS"}
{"ts_recv":"2026-04-07T02:09:19.235230200Z","hd":{"ts_event":"2026-04-07T02:09:19.235213577Z","rtype":160,"publisher_id":101,"instrument_id":436},"action":"A","side":"A","price":"1.156380000","size":30,"channel_id":23,"order_id":"1775527759235219499","flags":128,"ts_in_delta":919,"sequence":149111,"symbol":"FCEU SI 20260615 PS"}
{"ts_recv":"2026-04-07T02:09:19.235272146Z","hd":{"ts_event":"2026-04-07T02:09:19.235254415Z","rtype":160,"publisher_id":101,"instrument_id":436},"action":"C","side":"B","price":"1.156310000","size":30,"channel_id":23,"order_id":"10998899796089981998","flags":0,"ts_in_delta":900,"sequence":149112,"symbol":"FCEU SI 20260615 PS"}
{"ts_recv":"2026-04-07T02:09:19.235272146Z","hd":{"ts_event":"2026-04-07T02:09:19.235254415Z","rtype":160,"publisher_id":101,"instrument_id":436},"action":"A","side":"B","price":"1.156290000","size":30,"channel_id":23,"order_id":"10998899796090036077","flags":0,"ts_in_delta":900,"sequence":149112,"symbol":"FCEU SI 20260615 PS"}
{"ts_recv":"2026-04-07T02:09:19.235272146Z","hd":{"ts_event":"2026-04-07T02:09:19.235254415Z","rtype":160,"publisher_id":101,"instrument_id":436},"action":"C","side":"A","price":"1.156410000","size":30,"channel_id":23,"order_id":"1775527759235206190","flags":0,"ts_in_delta":900,"sequence":149112,"symbol":"FCEU SI 20260615 PS"}
{"ts_recv":"2026-04-07T02:09:19.235272146Z","hd":{"ts_event":"2026-04-07T02:09:19.235254415Z","rtype":160,"publisher_id":101,"instrument_id":436},"action":"A","side":"A","price":"1.156390000","size":30,"channel_id":23,"order_id":"1775527759235260269","flags":128,"ts_in_delta":900,"sequence":149112,"symbol":"FCEU SI 20260615 PS"}
{"ts_recv":"2026-04-07T02:09:19.235296329Z","hd":{"ts_event":"2026-04-07T02:09:19.235279913Z","rtype":160,"publisher_id":101,"instrument_id":436},"action":"C","side":"B","price":"1.156280000","size":30,"channel_id":23,"order_id":"10998899796089995307","flags":0,"ts_in_delta":894,"sequence":149113,"symbol":"FCEU SI 20260615 PS"}
{"ts_recv":"2026-04-07T02:09:19.235296329Z","hd":{"ts_event":"2026-04-07T02:09:19.235279913Z","rtype":160,"publisher_id":101,"instrument_id":436},"action":"A","side":"B","price":"1.156290000","size":30,"channel_id":23,"order_id":"10998899796090061989","flags":0,"ts_in_delta":894,"sequence":149113,"symbol":"FCEU SI 20260615 PS"}
{"ts_recv":"2026-04-07T02:09:19.235296329Z","hd":{"ts_event":"2026-04-07T02:09:19.235279913Z","rtype":160,"publisher_id":101,"instrument_id":436},"action":"C","side":"A","price":"1.156380000","size":30,"channel_id":23,"order_id":"1775527759235219499","flags":0,"ts_in_delta":894,"sequence":149113,"symbol":"FCEU SI 20260615 PS"}
{"ts_recv":"2026-04-07T02:09:19.235296329Z","hd":{"ts_event":"2026-04-07T02:09:19.235279913Z","rtype":160,"publisher_id":101,"instrument_id":436},"action":"A","side":"A","price":"1.156390000","size":30,"channel_id":23,"order_id":"1775527759235286181","flags":128,"ts_in_delta":894,"sequence":149113,"symbol":"FCEU SI 20260615 PS"}
{"ts_recv":"2026-04-07T02:09:19.235356238Z","hd":{"ts_event":"2026-04-07T02:09:19.235337039Z","rtype":160,"publisher_id":101,"instrument_id":436},"action":"C","side":"B","price":"1.156290000","size":30,"channel_id":23,"order_id":"10998899796090061989","flags":0,"ts_in_delta":887,"sequence":149114,"symbol":"FCEU SI 20260615 PS"}
{"ts_recv":"2026-04-07T02:09:19.235356238Z","hd":{"ts_event":"2026-04-07T02:09:19.235337039Z","rtype":160,"publisher_id":101,"instrument_id":436},"action":"A","side":"B","price":"1.156280000","size":30,"channel_id":23,"order_id":"10998899796090118740","flags":0,"ts_in_delta":887,"sequence":149114,"symbol":"FCEU SI 20260615 PS"}
{"ts_recv":"2026-04-07T02:09:19.235356238Z","hd":{"ts_event":"2026-04-07T02:09:19.235337039Z","rtype":160,"publisher_id":101,"instrument_id":436},"action":"C","side":"A","price":"1.156390000","size":30,"channel_id":23,"order_id":"1775527759235286181","flags":0,"ts_in_delta":887,"sequence":149114,"symbol":"FCEU SI 20260615 PS"}
{"ts_recv":"2026-04-07T02:09:19.235356238Z","hd":{"ts_event":"2026-04-07T02:09:19.235337039Z","rtype":160,"publisher_id":101,"instrument_id":436},"action":"A","side":"A","price":"1.156380000","size":30,"channel_id":23,"order_id":"1775527759235342932","flags":128,"ts_in_delta":887,"sequence":149114,"symbol":"FCEU SI 20260615 PS"}
{"ts_recv":"2026-04-07T02:09:19.238554328Z","hd":{"ts_event":"2026-04-07T02:09:19.238536635Z","rtype":160,"publisher_id":101,"instrument_id":436},"action":"C","side":"B","price":"1.156280000","size":30,"channel_id":23,"order_id":"10998899796090118740","flags":0,"ts_in_delta":921,"sequence":149119,"symbol":"FCEU SI 20260615 PS"}
{"ts_recv":"2026-04-07T02:09:19.238554328Z","hd":{"ts_event":"2026-04-07T02:09:19.238536635Z","rtype":160,"publisher_id":101,"instrument_id":436},"action":"A","side":"B","price":"1.156290000","size":30,"channel_id":23,"order_id":"10998899796093318233","flags":0,"ts_in_delta":921,"sequence":149119,"symbol":"FCEU SI 20260615 PS"}
{"ts_recv":"2026-04-07T02:09:19.238554328Z","hd":{"ts_event":"2026-04-07T02:09:19.238536635Z","rtype":160,"publisher_id":101,"instrument_id":436},"action":"C","side":"A","price":"1.156380000","size":30,"channel_id":23,"order_id":"1775527759235342932","flags":0,"ts_in_delta":921,"sequence":149119,"symbol":"FCEU SI 20260615 PS"}
{"ts_recv":"2026-04-07T02:09:19.238554328Z","hd":{"ts_event":"2026-04-07T02:09:19.238536635Z","rtype":160,"publisher_id":101,"instrument_id":436},"action":"A","side":"A","price":"1.156390000","size":30,"channel_id":23,"order_id":"1775527759238542425","flags":128,"ts_in_delta":921,"sequence":149119,"symbol":"FCEU SI 20260615 PS"}
{"ts_recv":"2026-04-07T02:09:19.242067751Z","hd":{"ts_event":"2026-04-07T02:09:19.242048699Z","rtype":160,"publisher_id":101,"instrument_id":436},"action":"C","side":"B","price":"1.156290000","size":30,"channel_id":23,"order_id":"10998899796093318233","flags":0,"ts_in_delta":956,"sequence":149123,"symbol":"FCEU SI 20260615 PS"}
{"ts_recv":"2026-04-07T02:09:19.242067751Z","hd":{"ts_event":"2026-04-07T02:09:19.242048699Z","rtype":160,"publisher_id":101,"instrument_id":436},"action":"A","side":"B","price":"1.156300000","size":30,"channel_id":23,"order_id":"10998899796096830425","flags":0,"ts_in_delta":956,"sequence":149123,"symbol":"FCEU SI 20260615 PS"}
{"ts_recv":"2026-04-07T02:09:19.242067751Z","hd":{"ts_event":"2026-04-07T02:09:19.242048699Z","rtype":160,"publisher_id":101,"instrument_id":436},"action":"C","side":"A","price":"1.156390000","size":30,"channel_id":23,"order_id":"1775527759238542425","flags":0,"ts_in_delta":956,"sequence":149123,"symbol":"FCEU SI 20260615 PS"}
{"ts_recv":"2026-04-07T02:09:19.242067751Z","hd":{"ts_event":"2026-04-07T02:09:19.242048699Z","rtype":160,"publisher_id":101,"instrument_id":436},"action":"A","side":"A","price":"1.156400000","size":30,"channel_id":23,"order_id":"1775527759242054617","flags":128,"ts_in_delta":956,"sequence":149123,"symbol":"FCEU SI 20260615 PS"}
{"ts_recv":"2026-04-07T02:09:19.242119796Z","hd":{"ts_event":"2026-04-07T02:09:19.242100315Z","rtype":160,"publisher_id":101,"instrument_id":436},"action":"C","side":"B","price":"1.156290000","size":30,"channel_id":23,"order_id":"10998899796090036077","flags":0,"ts_in_delta":902,"sequence":149124,"symbol":"FCEU SI 20260615 PS"}
{"ts_recv":"2026-04-07T02:09:19.242119796Z","hd":{"ts_event":"2026-04-07T02:09:19.242100315Z","rtype":160,"publisher_id":101,"instrument_id":436},"action":"A","side":"B","price":"1.156310000","size":30,"channel_id":23,"order_id":"10998899796096882600","flags":0,"ts_in_delta":902,"sequence":149124,"symbol":"FCEU SI 20260615 PS"}
{"ts_recv":"2026-04-07T02:09:19.242119796Z","hd":{"ts_event":"2026-04-07T02:09:19.242100315Z","rtype":160,"publisher_id":101,"instrument_id":436},"action":"C","side":"A","price":"1.156390000","size":30,"channel_id":23,"order_id":"1775527759235260269","flags":0,"ts_in_delta":902,"sequence":149124,"symbol":"FCEU SI 20260615 PS"}
{"ts_recv":"2026-04-07T02:09:19.242119796Z","hd":{"ts_event":"2026-04-07T02:09:19.242100315Z","rtype":160,"publisher_id":101,"instrument_id":436},"action":"A","side":"A","price":"1.156410000","size":30,"channel_id":23,"order_id":"1775527759242106792","flags":128,"ts_in_delta":902,"sequence":149124,"symbol":"FCEU SI 20260615 PS"}
{"ts_recv":"2026-04-07T02:09:19.242127206Z","hd":{"ts_event":"2026-04-07T02:09:19.242107611Z","rtype":160,"publisher_id":101,"instrument_id":436},"action":"C","side":"B","price":"1.156300000","size":30,"channel_id":23,"order_id":"10998899796096830425","flags":0,"ts_in_delta":908,"sequence":149125,"symbol":"FCEU SI 20260615 PS"}
{"ts_recv":"2026-04-07T02:09:19.242127206Z","hd":{"ts_event":"2026-04-07T02:09:19.242107611Z","rtype":160,"publisher_id":101,"instrument_id":436},"action":"A","side":"B","price":"1.156310000","size":30,"channel_id":23,"order_id":"10998899796096892561","flags":0,"ts_in_delta":908,"sequence":149125,"symbol":"FCEU SI 20260615 PS"}
{"ts_recv":"2026-04-07T02:09:19.242127206Z","hd":{"ts_event":"2026-04-07T02:09:19.242107611Z","rtype":160,"publisher_id":101,"instrument_id":436},"action":"C","side":"A","price":"1.156400000","size":30,"channel_id":23,"order_id":"1775527759242054617","flags":0,"ts_in_delta":908,"sequence":149125,"symbol":"FCEU SI 20260615 PS"}
{"ts_recv":"2026-04-07T02:09:19.242127206Z","hd":{"ts_event":"2026-04-07T02:09:19.242107611Z","rtype":160,"publisher_id":101,"instrument_id":436},"action":"A","side":"A","price":"1.156410000","size":30,"channel_id":23,"order_id":"1775527759242116753","flags":128,"ts_in_delta":908,"sequence":149125,"symbol":"FCEU SI 20260615 PS"}
{"ts_recv":"2026-04-07T02:09:19.253110538Z","hd":{"ts_event":"2026-04-07T02:09:19.253094017Z","rtype":160,"publisher_id":101,"instrument_id":436},"action":"C","side":"B","price":"1.156310000","size":30,"channel_id":23,"order_id":"10998899796096892561","flags":0,"ts_in_delta":722,"sequence":149130,"symbol":"FCEU SI 20260615 PS"}
{"ts_recv":"2026-04-07T02:09:19.253110538Z","hd":{"ts_event":"2026-04-07T02:09:19.253094017Z","rtype":160,"publisher_id":101,"instrument_id":436},"action":"A","side":"B","price":"1.156320000","size":30,"channel_id":23,"order_id":"10998899796107875337","flags":0,"ts_in_delta":722,"sequence":149130,"symbol":"FCEU SI 20260615 PS"}
{"ts_recv":"2026-04-07T02:09:19.253110538Z","hd":{"ts_event":"2026-04-07T02:09:19.253094017Z","rtype":160,"publisher_id":101,"instrument_id":436},"action":"C","side":"A","price":"1.156410000","size":30,"channel_id":23,"order_id":"1775527759242116753","flags":0,"ts_in_delta":722,"sequence":149130,"symbol":"FCEU SI 20260615 PS"}
{"ts_recv":"2026-04-07T02:09:19.253110538Z","hd":{"ts_event":"2026-04-07T02:09:19.253094017Z","rtype":160,"publisher_id":101,"instrument_id":436},"action":"A","side":"A","price":"1.156420000","size":30,"channel_id":23,"order_id":"1775527759253099529","flags":128,"ts_in_delta":722,"sequence":149130,"symbol":"FCEU SI 20260615 PS"}
{"ts_recv":"2026-04-07T02:09:19.253160733Z","hd":{"ts_event":"2026-04-07T02:09:19.253142503Z","rtype":160,"publisher_id":101,"instrument_id":436},"action":"C","side":"B","price":"1.156310000","size":30,"channel_id":23,"order_id":"10998899796096882600","flags":0,"ts_in_delta":773,"sequence":149131,"symbol":"FCEU SI 20260615 PS"}
{"ts_recv":"2026-04-07T02:09:19.253160733Z","hd":{"ts_event":"2026-04-07T02:09:19.253142503Z","rtype":160,"publisher_id":101,"instrument_id":436},"action":"A","side":"B","price":"1.156330000","size":30,"channel_id":23,"order_id":"10998899796107924175","flags":0,"ts_in_delta":773,"sequence":149131,"symbol":"FCEU SI 20260615 PS"}
{"ts_recv":"2026-04-07T02:09:19.253160733Z","hd":{"ts_event":"2026-04-07T02:09:19.253142503Z","rtype":160,"publisher_id":101,"instrument_id":436},"action":"C","side":"A","price":"1.156410000","size":30,"channel_id":23,"order_id":"1775527759242106792","flags":0,"ts_in_delta":773,"sequence":149131,"symbol":"FCEU SI 20260615 PS"}
{"ts_recv":"2026-04-07T02:09:19.253160733Z","hd":{"ts_event":"2026-04-07T02:09:19.253142503Z","rtype":160,"publisher_id":101,"instrument_id":436},"action":"A","side":"A","price":"1.156430000","size":30,"channel_id":23,"order_id":"1775527759253148367","flags":128,"ts_in_delta":773,"sequence":149131,"symbol":"FCEU SI 20260615 PS"}
{"ts_recv":"2026-04-07T02:09:19.253170501Z","hd":{"ts_event":"2026-04-07T02:09:19.253150465Z","rtype":160,"publisher_id":101,"instrument_id":436},"action":"C","side":"B","price":"1.156320000","size":30,"channel_id":23,"order_id":"10998899796107875337","flags":0,"ts_in_delta":732,"sequence":149132,"symbol":"FCEU SI 20260615 PS"}
{"ts_recv":"2026-04-07T02:09:19.253170501Z","hd":{"ts_event":"2026-04-07T02:09:19.253150465Z","rtype":160,"publisher_id":101,"instrument_id":436},"action":"A","side":"B","price":"1.156330000","size":30,"channel_id":23,"order_id":"10998899796107933625","flags":0,"ts_in_delta":732,"sequence":149132,"symbol":"FCEU SI 20260615 PS"}
{"ts_recv":"2026-04-07T02:09:19.253170501Z","hd":{"ts_event":"2026-04-07T02:09:19.253150465Z","rtype":160,"publisher_id":101,"instrument_id":436},"action":"C","side":"A","price":"1.156420000","size":30,"channel_id":23,"order_id":"1775527759253099529","flags":0,"ts_in_delta":732,"sequence":149132,"symbol":"FCEU SI 20260615 PS"}
{"ts_recv":"2026-04-07T02:09:19.253170501Z","hd":{"ts_event":"2026-04-07T02:09:19.253150465Z","rtype":160,"publisher_id":101,"instrument_id":436},"action":"A","side":"A","price":"1.156430000","size":30,"channel_id":23,"order_id":"1775527759253157817","flags":128,"ts_in_delta":732,"sequence":149132,"symbol":"FCEU SI 20260615 PS"}
{"ts_recv":"2026-04-07T02:09:21.762649016Z","hd":{"ts_event":"2026-04-07T02:09:21.762629155Z","rtype":160,"publisher_id":101,"instrument_id":436},"action":"C","side":"B","price":"1.156330000","size":30,"channel_id":23,"order_id":"10998899796107924175","flags":0,"ts_in_delta":931,"sequence":149188,"symbol":"FCEU SI 20260615 PS"}
{"ts_recv":"2026-04-07T02:09:21.762649016Z","hd":{"ts_event":"2026-04-07T02:09:21.762629155Z","rtype":160,"publisher_id":101,"instrument_id":436},"action":"A","side":"B","price":"1.156350000","size":30,"channel_id":23,"order_id":"10998899798617411428","flags":0,"ts_in_delta":931,"sequence":149188,"symbol":"FCEU SI 20260615 PS"}
{"ts_recv":"2026-04-07T02:09:21.762649016Z","hd":{"ts_event":"2026-04-07T02:09:21.762629155Z","rtype":160,"publisher_id":101,"instrument_id":436},"action":"C","side":"A","price":"1.156430000","size":30,"channel_id":23,"order_id":"1775527759253148367","flags":0,"ts_in_delta":931,"sequence":149188,"symbol":"FCEU SI 20260615 PS"}
{"ts_recv":"2026-04-07T02:09:21.762649016Z","hd":{"ts_event":"2026-04-07T02:09:21.762629155Z","rtype":160,"publisher_id":101,"instrument_id":436},"action":"A","side":"A","price":"1.156450000","size":30,"channel_id":23,"order_id":"1775527761762635620","flags":128,"ts_in_delta":931,"sequence":149188,"symbol":"FCEU SI 20260615 PS"}
{"ts_recv":"2026-04-07T02:09:21.762718394Z","hd":{"ts_event":"2026-04-07T02:09:21.762700639Z","rtype":160,"publisher_id":101,"instrument_id":436},"action":"C","side":"B","price":"1.156330000","size":30,"channel_id":23,"order_id":"10998899796107933625","flags":0,"ts_in_delta":909,"sequence":149189,"symbol":"FCEU SI 20260615 PS"}
{"ts_recv":"2026-04-07T02:09:21.762718394Z","hd":{"ts_event":"2026-04-07T02:09:21.762700639Z","rtype":160,"publisher_id":101,"instrument_id":436},"action":"A","side":"B","price":"1.156340000","size":30,"channel_id":23,"order_id":"10998899798617482592","flags":0,"ts_in_delta":909,"sequence":149189,"symbol":"FCEU SI 20260615 PS"}
{"ts_recv":"2026-04-07T02:09:21.762718394Z","hd":{"ts_event":"2026-04-07T02:09:21.762700639Z","rtype":160,"publisher_id":101,"instrument_id":436},"action":"C","side":"A","price":"1.156430000","size":30,"channel_id":23,"order_id":"1775527759253157817","flags":0,"ts_in_delta":909,"sequence":149189,"symbol":"FCEU SI 20260615 PS"}
{"ts_recv":"2026-04-07T02:09:21.762718394Z","hd":{"ts_event":"2026-04-07T02:09:21.762700639Z","rtype":160,"publisher_id":101,"instrument_id":436},"action":"A","side":"A","price":"1.156440000","size":30,"channel_id":23,"order_id":"1775527761762706784","flags":128,"ts_in_delta":909,"sequence":149189,"symbol":"FCEU SI 20260615 PS"}
{"ts_recv":"2026-04-07T02:09:23.600291198Z","hd":{"ts_event":"2026-04-07T02:09:23.600260721Z","rtype":160,"publisher_id":101,"instrument_id":436},"action":"C","side":"B","price":"1.156350000","size":30,"channel_id":23,"order_id":"10998899798617411428","flags":0,"ts_in_delta":1742,"sequence":149229,"symbol":"FCEU SI 20260615 PS"}
{"ts_recv":"2026-04-07T02:09:23.600291198Z","hd":{"ts_event":"2026-04-07T02:09:23.600260721Z","rtype":160,"publisher_id":101,"instrument_id":436},"action":"A","side":"B","price":"1.156330000","size":30,"channel_id":23,"order_id":"10998899800455049482","flags":0,"ts_in_delta":1742,"sequence":149229,"symbol":"FCEU SI 20260615 PS"}
{"ts_recv":"2026-04-07T02:09:23.600291198Z","hd":{"ts_event":"2026-04-07T02:09:23.600260721Z","rtype":160,"publisher_id":101,"instrument_id":436},"action":"C","side":"A","price":"1.156450000","size":30,"channel_id":23,"order_id":"1775527761762635620","flags":0,"ts_in_delta":1742,"sequence":149229,"symbol":"FCEU SI 20260615 PS"}
{"ts_recv":"2026-04-07T02:09:23.600291198Z","hd":{"ts_event":"2026-04-07T02:09:23.600260721Z","rtype":160,"publisher_id":101,"instrument_id":436},"action":"A","side":"A","price":"1.156430000","size":30,"channel_id":23,"order_id":"1775527763600273674","flags":128,"ts_in_delta":1742,"sequence":149229,"symbol":"FCEU SI 20260615 PS"}
{"ts_recv":"2026-04-07T02:09:23.600398291Z","hd":{"ts_event":"2026-04-07T02:09:23.600381683Z","rtype":160,"publisher_id":101,"instrument_id":436},"action":"C","side":"B","price":"1.156340000","size":30,"channel_id":23,"order_id":"10998899798617482592","flags":0,"ts_in_delta":892,"sequence":149231,"symbol":"FCEU SI 20260615 PS"}
{"ts_recv":"2026-04-07T02:09:23.600398291Z","hd":{"ts_event":"2026-04-07T02:09:23.600381683Z","rtype":160,"publisher_id":101,"instrument_id":436},"action":"A","side":"B","price":"1.156330000","size":30,"channel_id":23,"order_id":"10998899800455163391","flags":0,"ts_in_delta":892,"sequence":149231,"symbol":"FCEU SI 20260615 PS"}
{"ts_recv":"2026-04-07T02:09:23.600398291Z","hd":{"ts_event":"2026-04-07T02:09:23.600381683Z","rtype":160,"publisher_id":101,"instrument_id":436},"action":"C","side":"A","price":"1.156440000","size":30,"channel_id":23,"order_id":"1775527761762706784","flags":0,"ts_in_delta":892,"sequence":149231,"symbol":"FCEU SI 20260615 PS"}
{"ts_recv":"2026-04-07T02:09:23.600398291Z","hd":{"ts_event":"2026-04-07T02:09:23.600381683Z","rtype":160,"publisher_id":101,"instrument_id":436},"action":"A","side":"A","price":"1.156430000","size":30,"channel_id":23,"order_id":"1775527763600387583","flags":128,"ts_in_delta":892,"sequence":149231,"symbol":"FCEU SI 20260615 PS"}
{"ts_recv":"2026-04-07T02:09:36.258268645Z","hd":{"ts_event":"2026-04-07T02:09:36.258247337Z","rtype":160,"publisher_id":101,"instrument_id":436},"action":"C","side":"B","price":"1.156330000","size":30,"channel_id":23,"order_id":"10998899800455049482","flags":0,"ts_in_delta":950,"sequence":149340,"symbol":"FCEU SI 20260615 PS"}
{"ts_recv":"2026-04-07T02:09:36.258268645Z","hd":{"ts_event":"2026-04-07T02:09:36.258247337Z","rtype":160,"publisher_id":101,"instrument_id":436},"action":"A","side":"B","price":"1.156350000","size":30,"channel_id":23,"order_id":"10998899813113029088","flags":0,"ts_in_delta":950,"sequence":149340,"symbol":"FCEU SI 20260615 PS"}
{"ts_recv":"2026-04-07T02:09:36.258268645Z","hd":{"ts_event":"2026-04-07T02:09:36.258247337Z","rtype":160,"publisher_id":101,"instrument_id":436},"action":"C","side":"A","price":"1.156430000","size":30,"channel_id":23,"order_id":"1775527763600273674","flags":0,"ts_in_delta":950,"sequence":149340,"symbol":"FCEU SI 20260615 PS"}
{"ts_recv":"2026-04-07T02:09:36.258268645Z","hd":{"ts_event":"2026-04-07T02:09:36.258247337Z","rtype":160,"publisher_id":101,"instrument_id":436},"action":"A","side":"A","price":"1.156450000","size":30,"channel_id":23,"order_id":"1775527776258253280","flags":128,"ts_in_delta":950,"sequence":149340,"symbol":"FCEU SI 20260615 PS"}
{"ts_recv":"2026-04-07T02:09:36.258329084Z","hd":{"ts_event":"2026-04-07T02:09:36.258313463Z","rtype":160,"publisher_id":101,"instrument_id":436},"action":"C","side":"B","price":"1.156330000","size":30,"channel_id":23,"order_id":"10998899800455163391","flags":0,"ts_in_delta":925,"sequence":149341,"symbol":"FCEU SI 20260615 PS"}
{"ts_recv":"2026-04-07T02:09:36.258329084Z","hd":{"ts_event":"2026-04-07T02:09:36.258313463Z","rtype":160,"publisher_id":101,"instrument_id":436},"action":"A","side":"B","price":"1.156340000","size":30,"channel_id":23,"order_id":"10998899813113095063","flags":0,"ts_in_delta":925,"sequence":149341,"symbol":"FCEU SI 20260615 PS"}
{"ts_recv":"2026-04-07T02:09:36.258329084Z","hd":{"ts_event":"2026-04-07T02:09:36.258313463Z","rtype":160,"publisher_id":101,"instrument_id":436},"action":"C","side":"A","price":"1.156430000","size":30,"channel_id":23,"order_id":"1775527763600387583","flags":0,"ts_in_delta":925,"sequence":149341,"symbol":"FCEU SI 20260615 PS"}
{"ts_recv":"2026-04-07T02:09:36.258329084Z","hd":{"ts_event":"2026-04-07T02:09:36.258313463Z","rtype":160,"publisher_id":101,"instrument_id":436},"action":"A","side":"A","price":"1.156440000","size":30,"channel_id":23,"order_id":"1775527776258319255","flags":128,"ts_in_delta":925,"sequence":149341,"symbol":"FCEU SI 20260615 PS"}
{"ts_recv":"2026-04-07T02:09:36.276405322Z","hd":{"ts_event":"2026-04-07T02:09:36.276386999Z","rtype":160,"publisher_id":101,"instrument_id":436},"action":"C","side":"B","price":"1.156340000","size":30,"channel_id":23,"order_id":"10998899813113095063","flags":0,"ts_in_delta":988,"sequence":149345,"symbol":"FCEU SI 20260615 PS"}
{"ts_recv":"2026-04-07T02:09:36.276405322Z","hd":{"ts_event":"2026-04-07T02:09:36.276386999Z","rtype":160,"publisher_id":101,"instrument_id":436},"action":"A","side":"B","price":"1.156350000","size":30,"channel_id":23,"order_id":"10998899813131168388","flags":0,"ts_in_delta":988,"sequence":149345,"symbol":"FCEU SI 20260615 PS"}
{"ts_recv":"2026-04-07T02:09:36.276405322Z","hd":{"ts_event":"2026-04-07T02:09:36.276386999Z","rtype":160,"publisher_id":101,"instrument_id":436},"action":"C","side":"A","price":"1.156440000","size":30,"channel_id":23,"order_id":"1775527776258319255","flags":0,"ts_in_delta":988,"sequence":149345,"symbol":"FCEU SI 20260615 PS"}
{"ts_recv":"2026-04-07T02:09:36.276405322Z","hd":{"ts_event":"2026-04-07T02:09:36.276386999Z","rtype":160,"publisher_id":101,"instrument_id":436},"action":"A","side":"A","price":"1.156450000","size":30,"channel_id":23,"order_id":"1775527776276392580","flags":128,"ts_in_delta":988,"sequence":149345,"symbol":"FCEU SI 20260615 PS"}
{"ts_recv":"2026-04-07T02:09:41.968506496Z","hd":{"ts_event":"2026-04-07T02:09:41.968485007Z","rtype":160,"publisher_id":101,"instrument_id":436},"action":"C","side":"B","price":"1.156350000","size":30,"channel_id":23,"order_id":"10998899813131168388","flags":0,"ts_in_delta":1173,"sequence":149447,"symbol":"FCEU SI 20260615 PS"}
{"ts_recv":"2026-04-07T02:09:41.968506496Z","hd":{"ts_event":"2026-04-07T02:09:41.968485007Z","rtype":160,"publisher_id":101,"instrument_id":436},"action":"A","side":"B","price":"1.156340000","size":30,"channel_id":23,"order_id":"10998899818823266869","flags":0,"ts_in_delta":1173,"sequence":149447,"symbol":"FCEU SI 20260615 PS"}
{"ts_recv":"2026-04-07T02:09:41.968506496Z","hd":{"ts_event":"2026-04-07T02:09:41.968485007Z","rtype":160,"publisher_id":101,"instrument_id":436},"action":"C","side":"A","price":"1.156450000","size":30,"channel_id":23,"order_id":"1775527776276392580","flags":0,"ts_in_delta":1173,"sequence":149447,"symbol":"FCEU SI 20260615 PS"}
{"ts_recv":"2026-04-07T02:09:41.968506496Z","hd":{"ts_event":"2026-04-07T02:09:41.968485007Z","rtype":160,"publisher_id":101,"instrument_id":436},"action":"A","side":"A","price":"1.156440000","size":30,"channel_id":23,"order_id":"1775527781968491061","flags":128,"ts_in_delta":1173,"sequence":149447,"symbol":"FCEU SI 20260615 PS"}
{"ts_recv":"2026-04-07T02:09:42.408812538Z","hd":{"ts_event":"2026-04-07T02:09:42.408788579Z","rtype":160,"publisher_id":101,"instrument_id":436},"action":"C","side":"B","price":"1.156340000","size":30,"channel_id":23,"order_id":"10998899818823266869","flags":0,"ts_in_delta":890,"sequence":149455,"symbol":"FCEU SI 20260615 PS"}
{"ts_recv":"2026-04-07T02:09:42.408812538Z","hd":{"ts_event":"2026-04-07T02:09:42.408788579Z","rtype":160,"publisher_id":101,"instrument_id":436},"action":"A","side":"B","price":"1.156350000","size":30,"channel_id":23,"order_id":"10998899819263575495","flags":0,"ts_in_delta":890,"sequence":149455,"symbol":"FCEU SI 20260615 PS"}
{"ts_recv":"2026-04-07T02:09:42.408812538Z","hd":{"ts_event":"2026-04-07T02:09:42.408788579Z","rtype":160,"publisher_id":101,"instrument_id":436},"action":"C","side":"A","price":"1.156440000","size":30,"channel_id":23,"order_id":"1775527781968491061","flags":0,"ts_in_delta":890,"sequence":149455,"symbol":"FCEU SI 20260615 PS"}
{"ts_recv":"2026-04-07T02:09:42.408812538Z","hd":{"ts_event":"2026-04-07T02:09:42.408788579Z","rtype":160,"publisher_id":101,"instrument_id":436},"action":"A","side":"A","price":"1.156450000","size":30,"channel_id":23,"order_id":"1775527782408799687","flags":128,"ts_in_delta":890,"sequence":149455,"symbol":"FCEU SI 20260615 PS"}
{"ts_recv":"2026-04-07T02:09:46.928235076Z","hd":{"ts_event":"2026-04-07T02:09:46.928212903Z","rtype":160,"publisher_id":101,"instrument_id":436},"action":"C","side":"B","price":"1.156350000","size":30,"channel_id":23,"order_id":"10998899813113029088","flags":0,"ts_in_delta":931,"sequence":149486,"symbol":"FCEU SI 20260615 PS"}
{"ts_recv":"2026-04-07T02:09:46.928235076Z","hd":{"ts_event":"2026-04-07T02:09:46.928212903Z","rtype":160,"publisher_id":101,"instrument_id":436},"action":"A","side":"B","price":"1.156370000","size":30,"channel_id":23,"order_id":"10998899823782995091","flags":0,"ts_in_delta":931,"sequence":149486,"symbol":"FCEU SI 20260615 PS"}
{"ts_recv":"2026-04-07T02:09:46.928235076Z","hd":{"ts_event":"2026-04-07T02:09:46.928212903Z","rtype":160,"publisher_id":101,"instrument_id":436},"action":"C","side":"A","price":"1.156450000","size":30,"channel_id":23,"order_id":"1775527776258253280","flags":0,"ts_in_delta":931,"sequence":149486,"symbol":"FCEU SI 20260615 PS"}
{"ts_recv":"2026-04-07T02:09:46.928235076Z","hd":{"ts_event":"2026-04-07T02:09:46.928212903Z","rtype":160,"publisher_id":101,"instrument_id":436},"action":"A","side":"A","price":"1.156470000","size":30,"channel_id":23,"order_id":"1775527786928219283","flags":128,"ts_in_delta":931,"sequence":149486,"symbol":"FCEU SI 20260615 PS"}
{"ts_recv":"2026-04-07T02:09:46.928313462Z","hd":{"ts_event":"2026-04-07T02:09:46.928294421Z","rtype":160,"publisher_id":101,"instrument_id":436},"action":"C","side":"B","price":"1.156350000","size":30,"channel_id":23,"order_id":"10998899819263575495","flags":0,"ts_in_delta":975,"sequence":149487,"symbol":"FCEU SI 20260615 PS"}
{"ts_recv":"2026-04-07T02:09:46.928313462Z","hd":{"ts_event":"2026-04-07T02:09:46.928294421Z","rtype":160,"publisher_id":101,"instrument_id":436},"action":"A","side":"B","price":"1.156360000","size":30,"channel_id":23,"order_id":"10998899823783076388","flags":0,"ts_in_delta":975,"sequence":149487,"symbol":"FCEU SI 20260615 PS"}
{"ts_recv":"2026-04-07T02:09:46.928313462Z","hd":{"ts_event":"2026-04-07T02:09:46.928294421Z","rtype":160,"publisher_id":101,"instrument_id":436},"action":"C","side":"A","price":"1.156450000","size":30,"channel_id":23,"order_id":"1775527782408799687","flags":0,"ts_in_delta":975,"sequence":149487,"symbol":"FCEU SI 20260615 PS"}
{"ts_recv":"2026-04-07T02:09:46.928313462Z","hd":{"ts_event":"2026-04-07T02:09:46.928294421Z","rtype":160,"publisher_id":101,"instrument_id":436},"action":"A","side":"A","price":"1.156460000","size":30,"channel_id":23,"order_id":"1775527786928300580","flags":128,"ts_in_delta":975,"sequence":149487,"symbol":"FCEU SI 20260615 PS"}
{"ts_recv":"2026-04-07T02:09:46.931651682Z","hd":{"ts_event":"2026-04-07T02:09:46.931632965Z","rtype":160,"publisher_id":101,"instrument_id":436},"action":"C","side":"B","price":"1.156360000","size":30,"channel_id":23,"order_id":"10998899823783076388","flags":0,"ts_in_delta":941,"sequence":149493,"symbol":"FCEU SI 20260615 PS"}
{"ts_recv":"2026-04-07T02:09:46.931651682Z","hd":{"ts_event":"2026-04-07T02:09:46.931632965Z","rtype":160,"publisher_id":101,"instrument_id":436},"action":"A","side":"B","price":"1.156370000","size":30,"channel_id":23,"order_id":"10998899823786414731","flags":0,"ts_in_delta":941,"sequence":149493,"symbol":"FCEU SI 20260615 PS"}
{"ts_recv":"2026-04-07T02:09:46.931651682Z","hd":{"ts_event":"2026-04-07T02:09:46.931632965Z","rtype":160,"publisher_id":101,"instrument_id":436},"action":"C","side":"A","price":"1.156460000","size":30,"channel_id":23,"order_id":"1775527786928300580","flags":0,"ts_in_delta":941,"sequence":149493,"symbol":"FCEU SI 20260615 PS"}
{"ts_recv":"2026-04-07T02:09:46.931651682Z","hd":{"ts_event":"2026-04-07T02:09:46.931632965Z","rtype":160,"publisher_id":101,"instrument_id":436},"action":"A","side":"A","price":"1.156470000","size":30,"channel_id":23,"order_id":"1775527786931638923","flags":128,"ts_in_delta":941,"sequence":149493,"symbol":"FCEU SI 20260615 PS"}
{"ts_recv":"2026-04-07T02:09:48.314871260Z","hd":{"ts_event":"2026-04-07T02:09:48.314851125Z","rtype":160,"publisher_id":101,"instrument_id":436},"action":"C","side":"B","price":"1.156370000","size":30,"channel_id":23,"order_id":"10998899823786414731","flags":0,"ts_in_delta":1057,"sequence":149549,"symbol":"FCEU SI 20260615 PS"}
{"ts_recv":"2026-04-07T02:09:48.314871260Z","hd":{"ts_event":"2026-04-07T02:09:48.314851125Z","rtype":160,"publisher_id":101,"instrument_id":436},"action":"A","side":"B","price":"1.156380000","size":30,"channel_id":23,"order_id":"10998899825169632578","flags":0,"ts_in_delta":1057,"sequence":149549,"symbol":"FCEU SI 20260615 PS"}
{"ts_recv":"2026-04-07T02:09:48.314871260Z","hd":{"ts_event":"2026-04-07T02:09:48.314851125Z","rtype":160,"publisher_id":101,"instrument_id":436},"action":"C","side":"A","price":"1.156470000","size":30,"channel_id":23,"order_id":"1775527786931638923","flags":0,"ts_in_delta":1057,"sequence":149549,"symbol":"FCEU SI 20260615 PS"}
{"ts_recv":"2026-04-07T02:09:48.314871260Z","hd":{"ts_event":"2026-04-07T02:09:48.314851125Z","rtype":160,"publisher_id":101,"instrument_id":436},"action":"A","side":"A","price":"1.156480000","size":30,"channel_id":23,"order_id":"1775527788314856770","flags":128,"ts_in_delta":1057,"sequence":149549,"symbol":"FCEU SI 20260615 PS"}
{"ts_recv":"2026-04-07T02:09:48.314933741Z","hd":{"ts_event":"2026-04-07T02:09:48.314903943Z","rtype":160,"publisher_id":101,"instrument_id":436},"action":"C","side":"B","price":"1.156370000","size":30,"channel_id":23,"order_id":"10998899823782995091","flags":0,"ts_in_delta":906,"sequence":149551,"symbol":"FCEU SI 20260615 PS"}
{"ts_recv":"2026-04-07T02:09:48.314933741Z","hd":{"ts_event":"2026-04-07T02:09:48.314903943Z","rtype":160,"publisher_id":101,"instrument_id":436},"action":"A","side":"B","price":"1.156390000","size":30,"channel_id":23,"order_id":"10998899825169695260","flags":0,"ts_in_delta":906,"sequence":149551,"symbol":"FCEU SI 20260615 PS"}
{"ts_recv":"2026-04-07T02:09:48.314933741Z","hd":{"ts_event":"2026-04-07T02:09:48.314903943Z","rtype":160,"publisher_id":101,"instrument_id":436},"action":"C","side":"A","price":"1.156470000","size":30,"channel_id":23,"order_id":"1775527786928219283","flags":0,"ts_in_delta":906,"sequence":149551,"symbol":"FCEU SI 20260615 PS"}
{"ts_recv":"2026-04-07T02:09:48.314933741Z","hd":{"ts_event":"2026-04-07T02:09:48.314903943Z","rtype":160,"publisher_id":101,"instrument_id":436},"action":"A","side":"A","price":"1.156490000","size":30,"channel_id":23,"order_id":"1775527788314919452","flags":128,"ts_in_delta":906,"sequence":149551,"symbol":"FCEU SI 20260615 PS"}
{"ts_recv":"2026-04-07T02:09:48.314992053Z","hd":{"ts_event":"2026-04-07T02:09:48.314975983Z","rtype":160,"publisher_id":101,"instrument_id":436},"action":"C","side":"B","price":"1.156380000","size":30,"channel_id":23,"order_id":"10998899825169632578","flags":0,"ts_in_delta":902,"sequence":149553,"symbol":"FCEU SI 20260615 PS"}
{"ts_recv":"2026-04-07T02:09:48.314992053Z","hd":{"ts_event":"2026-04-07T02:09:48.314975983Z","rtype":160,"publisher_id":101,"instrument_id":436},"action":"A","side":"B","price":"1.156390000","size":30,"channel_id":23,"order_id":"10998899825169757640","flags":0,"ts_in_delta":902,"sequence":149553,"symbol":"FCEU SI 20260615 PS"}
{"ts_recv":"2026-04-07T02:09:48.314992053Z","hd":{"ts_event":"2026-04-07T02:09:48.314975983Z","rtype":160,"publisher_id":101,"instrument_id":436},"action":"C","side":"A","price":"1.156480000","size":30,"channel_id":23,"order_id":"1775527788314856770","flags":0,"ts_in_delta":902,"sequence":149553,"symbol":"FCEU SI 20260615 PS"}
{"ts_recv":"2026-04-07T02:09:48.314992053Z","hd":{"ts_event":"2026-04-07T02:09:48.314975983Z","rtype":160,"publisher_id":101,"instrument_id":436},"action":"A","side":"A","price":"1.156490000","size":30,"channel_id":23,"order_id":"1775527788314981832","flags":128,"ts_in_delta":902,"sequence":149553,"symbol":"FCEU SI 20260615 PS"}
{"ts_recv":"2026-04-07T02:09:48.582807032Z","hd":{"ts_event":"2026-04-07T02:09:48.582786451Z","rtype":160,"publisher_id":101,"instrument_id":436},"action":"C","side":"B","price":"1.156390000","size":30,"channel_id":23,"order_id":"10998899825169757640","flags":0,"ts_in_delta":1058,"sequence":149575,"symbol":"FCEU SI 20260615 PS"}
{"ts_recv":"2026-04-07T02:09:48.582807032Z","hd":{"ts_event":"2026-04-07T02:09:48.582786451Z","rtype":160,"publisher_id":101,"instrument_id":436},"action":"A","side":"B","price":"1.156380000","size":30,"channel_id":23,"order_id":"10998899825437568021","flags":0,"ts_in_delta":1058,"sequence":149575,"symbol":"FCEU SI 20260615 PS"}
{"ts_recv":"2026-04-07T02:09:48.582807032Z","hd":{"ts_event":"2026-04-07T02:09:48.582786451Z","rtype":160,"publisher_id":101,"instrument_id":436},"action":"C","side":"A","price":"1.156490000","size":30,"channel_id":23,"order_id":"1775527788314981832","flags":0,"ts_in_delta":1058,"sequence":149575,"symbol":"FCEU SI 20260615 PS"}
{"ts_recv":"2026-04-07T02:09:48.582807032Z","hd":{"ts_event":"2026-04-07T02:09:48.582786451Z","rtype":160,"publisher_id":101,"instrument_id":436},"action":"A","side":"A","price":"1.156480000","size":30,"channel_id":23,"order_id":"1775527788582792213","flags":128,"ts_in_delta":1058,"sequence":149575,"symbol":"FCEU SI 20260615 PS"}
{"ts_recv":"2026-04-07T02:09:49.983624581Z","hd":{"ts_event":"2026-04-07T02:09:49.983603915Z","rtype":160,"publisher_id":101,"instrument_id":436},"action":"C","side":"B","price":"1.156390000","size":30,"channel_id":23,"order_id":"10998899825169695260","flags":0,"ts_in_delta":1089,"sequence":149597,"symbol":"FCEU SI 20260615 PS"}
{"ts_recv":"2026-04-07T02:09:49.983624581Z","hd":{"ts_event":"2026-04-07T02:09:49.983603915Z","rtype":160,"publisher_id":101,"instrument_id":436},"action":"A","side":"B","price":"1.156370000","size":30,"channel_id":23,"order_id":"10998899826838385828","flags":0,"ts_in_delta":1089,"sequence":149597,"symbol":"FCEU SI 20260615 PS"}
{"ts_recv":"2026-04-07T02:09:49.983624581Z","hd":{"ts_event":"2026-04-07T02:09:49.983603915Z","rtype":160,"publisher_id":101,"instrument_id":436},"action":"C","side":"A","price":"1.156490000","size":30,"channel_id":23,"order_id":"1775527788314919452","flags":0,"ts_in_delta":1089,"sequence":149597,"symbol":"FCEU SI 20260615 PS"}
{"ts_recv":"2026-04-07T02:09:49.983624581Z","hd":{"ts_event":"2026-04-07T02:09:49.983603915Z","rtype":160,"publisher_id":101,"instrument_id":436},"action":"A","side":"A","price":"1.156470000","size":30,"channel_id":23,"order_id":"1775527789983610020","flags":128,"ts_in_delta":1089,"sequence":149597,"symbol":"FCEU SI 20260615 PS"}
{"ts_recv":"2026-04-07T02:09:49.983746726Z","hd":{"ts_event":"2026-04-07T02:09:49.983728019Z","rtype":160,"publisher_id":101,"instrument_id":436},"action":"C","side":"B","price":"1.156380000","size":30,"channel_id":23,"order_id":"10998899825437568021","flags":0,"ts_in_delta":1092,"sequence":149598,"symbol":"FCEU SI 20260615 PS"}
{"ts_recv":"2026-04-07T02:09:49.983746726Z","hd":{"ts_event":"2026-04-07T02:09:49.983728019Z","rtype":160,"publisher_id":101,"instrument_id":436},"action":"A","side":"B","price":"1.156370000","size":30,"channel_id":23,"order_id":"10998899826838509990","flags":0,"ts_in_delta":1092,"sequence":149598,"symbol":"FCEU SI 20260615 PS"}
{"ts_recv":"2026-04-07T02:09:49.983746726Z","hd":{"ts_event":"2026-04-07T02:09:49.983728019Z","rtype":160,"publisher_id":101,"instrument_id":436},"action":"C","side":"A","price":"1.156480000","size":30,"channel_id":23,"order_id":"1775527788582792213","flags":0,"ts_in_delta":1092,"sequence":149598,"symbol":"FCEU SI 20260615 PS"}
{"ts_recv":"2026-04-07T02:09:49.983746726Z","hd":{"ts_event":"2026-04-07T02:09:49.983728019Z","rtype":160,"publisher_id":101,"instrument_id":436},"action":"A","side":"A","price":"1.156470000","size":30,"channel_id":23,"order_id":"1775527789983734182","flags":128,"ts_in_delta":1092,"sequence":149598,"symbol":"FCEU SI 20260615 PS"}
{"ts_recv":"2026-04-07T02:09:49.983844864Z","hd":{"ts_event":"2026-04-07T02:09:49.983825441Z","rtype":160,"publisher_id":101,"instrument_id":436},"action":"C","side":"B","price":"1.156370000","size":30,"channel_id":23,"order_id":"10998899826838509990","flags":0,"ts_in_delta":986,"sequence":149599,"symbol":"FCEU SI 20260615 PS"}
{"ts_recv":"2026-04-07T02:09:49.983844864Z","hd":{"ts_event":"2026-04-07T02:09:49.983825441Z","rtype":160,"publisher_id":101,"instrument_id":436},"action":"A","side":"B","price":"1.156360000","size":30,"channel_id":23,"order_id":"10998899826838607314","flags":0,"ts_in_delta":986,"sequence":149599,"symbol":"FCEU SI 20260615 PS"}
{"ts_recv":"2026-04-07T02:09:49.983844864Z","hd":{"ts_event":"2026-04-07T02:09:49.983825441Z","rtype":160,"publisher_id":101,"instrument_id":436},"action":"C","side":"A","price":"1.156470000","size":30,"channel_id":23,"order_id":"1775527789983734182","flags":0,"ts_in_delta":986,"sequence":149599,"symbol":"FCEU SI 20260615 PS"}
{"ts_recv":"2026-04-07T02:09:49.983844864Z","hd":{"ts_event":"2026-04-07T02:09:49.983825441Z","rtype":160,"publisher_id":101,"instrument_id":436},"action":"A","side":"A","price":"1.156460000","size":30,"channel_id":23,"order_id":"1775527789983831506","flags":128,"ts_in_delta":986,"sequence":149599,"symbol":"FCEU SI 20260615 PS"}
{"ts_recv":"2026-04-07T02:09:50.882289739Z","hd":{"ts_event":"2026-04-07T02:09:50.882269487Z","rtype":160,"publisher_id":101,"instrument_id":436},"action":"C","side":"B","price":"1.156360000","size":30,"channel_id":23,"order_id":"10998899826838607314","flags":0,"ts_in_delta":1016,"sequence":149615,"symbol":"FCEU SI 20260615 PS"}
{"ts_recv":"2026-04-07T02:09:50.882289739Z","hd":{"ts_event":"2026-04-07T02:09:50.882269487Z","rtype":160,"publisher_id":101,"instrument_id":436},"action":"A","side":"B","price":"1.156350000","size":30,"channel_id":23,"order_id":"10998899827737051419","flags":0,"ts_in_delta":1016,"sequence":149615,"symbol":"FCEU SI 20260615 PS"}
{"ts_recv":"2026-04-07T02:09:50.882289739Z","hd":{"ts_event":"2026-04-07T02:09:50.882269487Z","rtype":160,"publisher_id":101,"instrument_id":436},"action":"C","side":"A","price":"1.156460000","size":30,"channel_id":23,"order_id":"1775527789983831506","flags":0,"ts_in_delta":1016,"sequence":149615,"symbol":"FCEU SI 20260615 PS"}
{"ts_recv":"2026-04-07T02:09:50.882289739Z","hd":{"ts_event":"2026-04-07T02:09:50.882269487Z","rtype":160,"publisher_id":101,"instrument_id":436},"action":"A","side":"A","price":"1.156450000","size":30,"channel_id":23,"order_id":"1775527790882275611","flags":128,"ts_in_delta":1016,"sequence":149615,"symbol":"FCEU SI 20260615 PS"}
{"ts_recv":"2026-04-07T02:09:50.882343120Z","hd":{"ts_event":"2026-04-07T02:09:50.882324897Z","rtype":160,"publisher_id":101,"instrument_id":436},"action":"C","side":"B","price":"1.156370000","size":30,"channel_id":23,"order_id":"10998899826838385828","flags":0,"ts_in_delta":955,"sequence":149616,"symbol":"FCEU SI 20260615 PS"}
{"ts_recv":"2026-04-07T02:09:50.882343120Z","hd":{"ts_event":"2026-04-07T02:09:50.882324897Z","rtype":160,"publisher_id":101,"instrument_id":436},"action":"A","side":"B","price":"1.156350000","size":30,"channel_id":23,"order_id":"10998899827737106820","flags":0,"ts_in_delta":955,"sequence":149616,"symbol":"FCEU SI 20260615 PS"}
{"ts_recv":"2026-04-07T02:09:50.882343120Z","hd":{"ts_event":"2026-04-07T02:09:50.882324897Z","rtype":160,"publisher_id":101,"instrument_id":436},"action":"C","side":"A","price":"1.156470000","size":30,"channel_id":23,"order_id":"1775527789983610020","flags":0,"ts_in_delta":955,"sequence":149616,"symbol":"FCEU SI 20260615 PS"}
{"ts_recv":"2026-04-07T02:09:50.882343120Z","hd":{"ts_event":"2026-04-07T02:09:50.882324897Z","rtype":160,"publisher_id":101,"instrument_id":436},"action":"A","side":"A","price":"1.156450000","size":30,"channel_id":23,"order_id":"1775527790882331012","flags":128,"ts_in_delta":955,"sequence":149616,"symbol":"FCEU SI 20260615 PS"}
{"ts_recv":"2026-04-07T02:09:50.882367726Z","hd":{"ts_event":"2026-04-07T02:09:50.882348969Z","rtype":160,"publisher_id":101,"instrument_id":436},"action":"C","side":"B","price":"1.156350000","size":30,"channel_id":23,"order_id":"10998899827737051419","flags":0,"ts_in_delta":985,"sequence":149617,"symbol":"FCEU SI 20260615 PS"}
{"ts_recv":"2026-04-07T02:09:50.882367726Z","hd":{"ts_event":"2026-04-07T02:09:50.882348969Z","rtype":160,"publisher_id":101,"instrument_id":436},"action":"A","side":"B","price":"1.156360000","size":30,"channel_id":23,"order_id":"10998899827737130707","flags":0,"ts_in_delta":985,"sequence":149617,"symbol":"FCEU SI 20260615 PS"}
{"ts_recv":"2026-04-07T02:09:50.882367726Z","hd":{"ts_event":"2026-04-07T02:09:50.882348969Z","rtype":160,"publisher_id":101,"instrument_id":436},"action":"C","side":"A","price":"1.156450000","size":30,"channel_id":23,"order_id":"1775527790882275611","flags":0,"ts_in_delta":985,"sequence":149617,"symbol":"FCEU SI 20260615 PS"}
{"ts_recv":"2026-04-07T02:09:50.882367726Z","hd":{"ts_event":"2026-04-07T02:09:50.882348969Z","rtype":160,"publisher_id":101,"instrument_id":436},"action":"A","side":"A","price":"1.156460000","size":30,"channel_id":23,"order_id":"1775527790882354899","flags":128,"ts_in_delta":985,"sequence":149617,"symbol":"FCEU SI 20260615 PS"}
{"ts_recv":"2026-04-07T02:09:50.882424309Z","hd":{"ts_event":"2026-04-07T02:09:50.882407511Z","rtype":160,"publisher_id":101,"instrument_id":436},"action":"C","side":"B","price":"1.156360000","size":30,"channel_id":23,"order_id":"10998899827737130707","flags":0,"ts_in_delta":1118,"sequence":149618,"symbol":"FCEU SI 20260615 PS"}
{"ts_recv":"2026-04-07T02:09:50.882424309Z","hd":{"ts_event":"2026-04-07T02:09:50.882407511Z","rtype":160,"publisher_id":101,"instrument_id":436},"action":"A","side":"B","price":"1.156350000","size":30,"channel_id":23,"order_id":"10998899827737189210","flags":0,"ts_in_delta":1118,"sequence":149618,"symbol":"FCEU SI 20260615 PS"}
{"ts_recv":"2026-04-07T02:09:50.882424309Z","hd":{"ts_event":"2026-04-07T02:09:50.882407511Z","rtype":160,"publisher_id":101,"instrument_id":436},"action":"C","side":"A","price":"1.156460000","size":30,"channel_id":23,"order_id":"1775527790882354899","flags":0,"ts_in_delta":1118,"sequence":149618,"symbol":"FCEU SI 20260615 PS"}
{"ts_recv":"2026-04-07T02:09:50.882424309Z","hd":{"ts_event":"2026-04-07T02:09:50.882407511Z","rtype":160,"publisher_id":101,"instrument_id":436},"action":"A","side":"A","price":"1.156450000","size":30,"channel_id":23,"order_id":"1775527790882413402","flags":128,"ts_in_delta":1118,"sequence":149618,"symbol":"FCEU SI 20260615 PS"}
{"ts_recv":"2026-04-07T02:09:50.886948543Z","hd":{"ts_event":"2026-04-07T02:09:50.886928899Z","rtype":160,"publisher_id":101,"instrument_id":436},"action":"C","side":"B","price":"1.156350000","size":30,"channel_id":23,"order_id":"10998899827737189210","flags":0,"ts_in_delta":1099,"sequence":149624,"symbol":"FCEU SI 20260615 PS"}
{"ts_recv":"2026-04-07T02:09:50.886948543Z","hd":{"ts_event":"2026-04-07T02:09:50.886928899Z","rtype":160,"publisher_id":101,"instrument_id":436},"action":"A","side":"B","price":"1.156340000","size":30,"channel_id":23,"order_id":"10998899827741710286","flags":0,"ts_in_delta":1099,"sequence":149624,"symbol":"FCEU SI 20260615 PS"}
{"ts_recv":"2026-04-07T02:09:50.886948543Z","hd":{"ts_event":"2026-04-07T02:09:50.886928899Z","rtype":160,"publisher_id":101,"instrument_id":436},"action":"C","side":"A","price":"1.156450000","size":30,"channel_id":23,"order_id":"1775527790882413402","flags":0,"ts_in_delta":1099,"sequence":149624,"symbol":"FCEU SI 20260615 PS"}
{"ts_recv":"2026-04-07T02:09:50.886948543Z","hd":{"ts_event":"2026-04-07T02:09:50.886928899Z","rtype":160,"publisher_id":101,"instrument_id":436},"action":"A","side":"A","price":"1.156440000","size":30,"channel_id":23,"order_id":"1775527790886934478","flags":128,"ts_in_delta":1099,"sequence":149624,"symbol":"FCEU SI 20260615 PS"}
{"ts_recv":"2026-04-07T02:09:54.375210959Z","hd":{"ts_event":"2026-04-07T02:09:54.375192529Z","rtype":160,"publisher_id":101,"instrument_id":436},"action":"C","side":"B","price":"1.156340000","size":30,"channel_id":23,"order_id":"10998899827741710286","flags":0,"ts_in_delta":1080,"sequence":149666,"symbol":"FCEU SI 20260615 PS"}
{"ts_recv":"2026-04-07T02:09:54.375210959Z","hd":{"ts_event":"2026-04-07T02:09:54.375192529Z","rtype":160,"publisher_id":101,"instrument_id":436},"action":"A","side":"B","price":"1.156350000","size":30,"channel_id":23,"order_id":"10998899831229974336","flags":0,"ts_in_delta":1080,"sequence":149666,"symbol":"FCEU SI 20260615 PS"}
{"ts_recv":"2026-04-07T02:09:54.375210959Z","hd":{"ts_event":"2026-04-07T02:09:54.375192529Z","rtype":160,"publisher_id":101,"instrument_id":436},"action":"C","side":"A","price":"1.156440000","size":30,"channel_id":23,"order_id":"1775527790886934478","flags":0,"ts_in_delta":1080,"sequence":149666,"symbol":"FCEU SI 20260615 PS"}
{"ts_recv":"2026-04-07T02:09:54.375210959Z","hd":{"ts_event":"2026-04-07T02:09:54.375192529Z","rtype":160,"publisher_id":101,"instrument_id":436},"action":"A","side":"A","price":"1.156450000","size":30,"channel_id":23,"order_id":"1775527794375198528","flags":128,"ts_in_delta":1080,"sequence":149666,"symbol":"FCEU SI 20260615 PS"}
{"ts_recv":"2026-04-07T02:09:54.930947187Z","hd":{"ts_event":"2026-04-07T02:09:54.930916163Z","rtype":160,"publisher_id":101,"instrument_id":436},"action":"C","side":"B","price":"1.156350000","size":30,"channel_id":23,"order_id":"10998899827737106820","flags":0,"ts_in_delta":1887,"sequence":149676,"symbol":"FCEU SI 20260615 PS"}
{"ts_recv":"2026-04-07T02:09:54.930947187Z","hd":{"ts_event":"2026-04-07T02:09:54.930916163Z","rtype":160,"publisher_id":101,"instrument_id":436},"action":"A","side":"B","price":"1.156370000","size":30,"channel_id":23,"order_id":"10998899831785704845","flags":0,"ts_in_delta":1887,"sequence":149676,"symbol":"FCEU SI 20260615 PS"}
{"ts_recv":"2026-04-07T02:09:54.930947187Z","hd":{"ts_event":"2026-04-07T02:09:54.930916163Z","rtype":160,"publisher_id":101,"instrument_id":436},"action":"C","side":"A","price":"1.156450000","size":30,"channel_id":23,"order_id":"1775527790882331012","flags":0,"ts_in_delta":1887,"sequence":149676,"symbol":"FCEU SI 20260615 PS"}
{"ts_recv":"2026-04-07T02:09:54.930947187Z","hd":{"ts_event":"2026-04-07T02:09:54.930916163Z","rtype":160,"publisher_id":101,"instrument_id":436},"action":"A","side":"A","price":"1.156470000","size":30,"channel_id":23,"order_id":"1775527794930929037","flags":128,"ts_in_delta":1887,"sequence":149676,"symbol":"FCEU SI 20260615 PS"}
{"ts_recv":"2026-04-07T02:09:54.931035304Z","hd":{"ts_event":"2026-04-07T02:09:54.931019327Z","rtype":160,"publisher_id":101,"instrument_id":436},"action":"C","side":"B","price":"1.156350000","size":30,"channel_id":23,"order_id":"10998899831229974336","flags":0,"ts_in_delta":909,"sequence":149677,"symbol":"FCEU SI 20260615 PS"}
{"ts_recv":"2026-04-07T02:09:54.931035304Z","hd":{"ts_event":"2026-04-07T02:09:54.931019327Z","rtype":160,"publisher_id":101,"instrument_id":436},"action":"A","side":"B","price":"1.156360000","size":30,"channel_id":23,"order_id":"10998899831785800979","flags":0,"ts_in_delta":909,"sequence":149677,"symbol":"FCEU SI 20260615 PS"}
{"ts_recv":"2026-04-07T02:09:54.931035304Z","hd":{"ts_event":"2026-04-07T02:09:54.931019327Z","rtype":160,"publisher_id":101,"instrument_id":436},"action":"C","side":"A","price":"1.156450000","size":30,"channel_id":23,"order_id":"1775527794375198528","flags":0,"ts_in_delta":909,"sequence":149677,"symbol":"FCEU SI 20260615 PS"}
{"ts_recv":"2026-04-07T02:09:54.931035304Z","hd":{"ts_event":"2026-04-07T02:09:54.931019327Z","rtype":160,"publisher_id":101,"instrument_id":436},"action":"A","side":"A","price":"1.156460000","size":30,"channel_id":23,"order_id":"1775527794931025171","flags":128,"ts_in_delta":909,"sequence":149677,"symbol":"FCEU SI 20260615 PS"}
{"ts_recv":"2026-04-07T02:09:55.134710588Z","hd":{"ts_event":"2026-04-07T02:09:55.134693163Z","rtype":160,"publisher_id":101,"instrument_id":436},"action":"C","side":"B","price":"1.156360000","size":30,"channel_id":23,"order_id":"10998899831785800979","flags":0,"ts_in_delta":1045,"sequence":149683,"symbol":"FCEU SI 20260615 PS"}
{"ts_recv":"2026-04-07T02:09:55.134710588Z","hd":{"ts_event":"2026-04-07T02:09:55.134693163Z","rtype":160,"publisher_id":101,"instrument_id":436},"action":"A","side":"B","price":"1.156370000","size":30,"channel_id":23,"order_id":"10998899831989475035","flags":0,"ts_in_delta":1045,"sequence":149683,"symbol":"FCEU SI 20260615 PS"}
{"ts_recv":"2026-04-07T02:09:55.134710588Z","hd":{"ts_event":"2026-04-07T02:09:55.134693163Z","rtype":160,"publisher_id":101,"instrument_id":436},"action":"C","side":"A","price":"1.156460000","size":30,"channel_id":23,"order_id":"1775527794931025171","flags":0,"ts_in_delta":1045,"sequence":149683,"symbol":"FCEU SI 20260615 PS"}
{"ts_recv":"2026-04-07T02:09:55.134710588Z","hd":{"ts_event":"2026-04-07T02:09:55.134693163Z","rtype":160,"publisher_id":101,"instrument_id":436},"action":"A","side":"A","price":"1.156470000","size":30,"channel_id":23,"order_id":"1775527795134699227","flags":128,"ts_in_delta":1045,"sequence":149683,"symbol":"FCEU SI 20260615 PS"}
{"ts_recv":"2026-04-07T02:09:58.015741298Z","hd":{"ts_event":"2026-04-07T02:09:58.015720995Z","rtype":160,"publisher_id":101,"instrument_id":436},"action":"C","side":"B","price":"1.156370000","size":30,"channel_id":23,"order_id":"10998899831989475035","flags":0,"ts_in_delta":1040,"sequence":149710,"symbol":"FCEU SI 20260615 PS"}
{"ts_recv":"2026-04-07T02:09:58.015741298Z","hd":{"ts_event":"2026-04-07T02:09:58.015720995Z","rtype":160,"publisher_id":101,"instrument_id":436},"action":"A","side":"B","price":"1.156360000","size":30,"channel_id":23,"order_id":"10998899834870502390","flags":0,"ts_in_delta":1040,"sequence":149710,"symbol":"FCEU SI 20260615 PS"}
{"ts_recv":"2026-04-07T02:09:58.015741298Z","hd":{"ts_event":"2026-04-07T02:09:58.015720995Z","rtype":160,"publisher_id":101,"instrument_id":436},"action":"C","side":"A","price":"1.156470000","size":30,"channel_id":23,"order_id":"1775527795134699227","flags":0,"ts_in_delta":1040,"sequence":149710,"symbol":"FCEU SI 20260615 PS"}
{"ts_recv":"2026-04-07T02:09:58.015741298Z","hd":{"ts_event":"2026-04-07T02:09:58.015720995Z","rtype":160,"publisher_id":101,"instrument_id":436},"action":"A","side":"A","price":"1.156460000","size":30,"channel_id":23,"order_id":"1775527798015726582","flags":128,"ts_in_delta":1040,"sequence":149710,"symbol":"FCEU SI 20260615 PS"}
{"ts_recv":"2026-04-07T02:09:58.049917813Z","hd":{"ts_event":"2026-04-07T02:09:58.049898913Z","rtype":160,"publisher_id":101,"instrument_id":436},"action":"C","side":"B","price":"1.156370000","size":30,"channel_id":23,"order_id":"10998899831785704845","flags":0,"ts_in_delta":957,"sequence":149724,"symbol":"FCEU SI 20260615 PS"}
{"ts_recv":"2026-04-07T02:09:58.049917813Z","hd":{"ts_event":"2026-04-07T02:09:58.049898913Z","rtype":160,"publisher_id":101,"instrument_id":436},"action":"A","side":"B","price":"1.156350000","size":30,"channel_id":23,"order_id":"10998899834904680801","flags":0,"ts_in_delta":957,"sequence":149724,"symbol":"FCEU SI 20260615 PS"}
{"ts_recv":"2026-04-07T02:09:58.049917813Z","hd":{"ts_event":"2026-04-07T02:09:58.049898913Z","rtype":160,"publisher_id":101,"instrument_id":436},"action":"C","side":"A","price":"1.156470000","size":30,"channel_id":23,"order_id":"1775527794930929037","flags":0,"ts_in_delta":957,"sequence":149724,"symbol":"FCEU SI 20260615 PS"}
{"ts_recv":"2026-04-07T02:09:58.049917813Z","hd":{"ts_event":"2026-04-07T02:09:58.049898913Z","rtype":160,"publisher_id":101,"instrument_id":436},"action":"A","side":"A","price":"1.156450000","size":30,"channel_id":23,"order_id":"1775527798049904993","flags":128,"ts_in_delta":957,"sequence":149724,"symbol":"FCEU SI 20260615 PS"}
{"ts_recv":"2026-04-07T02:09:58.049979588Z","hd":{"ts_event":"2026-04-07T02:09:58.049961427Z","rtype":160,"publisher_id":101,"instrument_id":436},"action":"C","side":"B","price":"1.156360000","size":30,"channel_id":23,"order_id":"10998899834870502390","flags":0,"ts_in_delta":988,"sequence":149725,"symbol":"FCEU SI 20260615 PS"}
{"ts_recv":"2026-04-07T02:09:58.049979588Z","hd":{"ts_event":"2026-04-07T02:09:58.049961427Z","rtype":160,"publisher_id":101,"instrument_id":436},"action":"A","side":"B","price":"1.156350000","size":30,"channel_id":23,"order_id":"10998899834904743559","flags":0,"ts_in_delta":988,"sequence":149725,"symbol":"FCEU SI 20260615 PS"}
{"ts_recv":"2026-04-07T02:09:58.049979588Z","hd":{"ts_event":"2026-04-07T02:09:58.049961427Z","rtype":160,"publisher_id":101,"instrument_id":436},"action":"C","side":"A","price":"1.156460000","size":30,"channel_id":23,"order_id":"1775527798015726582","flags":0,"ts_in_delta":988,"sequence":149725,"symbol":"FCEU SI 20260615 PS"}
{"ts_recv":"2026-04-07T02:09:58.049979588Z","hd":{"ts_event":"2026-04-07T02:09:58.049961427Z","rtype":160,"publisher_id":101,"instrument_id":436},"action":"A","side":"A","price":"1.156450000","size":30,"channel_id":23,"order_id":"1775527798049967751","flags":128,"ts_in_delta":988,"sequence":149725,"symbol":"FCEU SI 20260615 PS"}
{"ts_recv":"2026-04-07T02:10:05.035082478Z","hd":{"ts_event":"2026-04-07T02:10:05.035060777Z","rtype":160,"publisher_id":101,"instrument_id":436},"action":"C","side":"B","price":"1.156350000","size":30,"channel_id":23,"order_id":"10998899834904680801","flags":0,"ts_in_delta":1001,"sequence":149839,"symbol":"FCEU SI 20260615 PS"}
{"ts_recv":"2026-04-07T02:10:05.035082478Z","hd":{"ts_event":"2026-04-07T02:10:05.035060777Z","rtype":160,"publisher_id":101,"instrument_id":436},"action":"A","side":"B","price":"1.156370000","size":30,"channel_id":23,"order_id":"10998899841889842790","flags":0,"ts_in_delta":1001,"sequence":149839,"symbol":"FCEU SI 20260615 PS"}
{"ts_recv":"2026-04-07T02:10:05.035082478Z","hd":{"ts_event":"2026-04-07T02:10:05.035060777Z","rtype":160,"publisher_id":101,"instrument_id":436},"action":"C","side":"A","price":"1.156450000","size":30,"channel_id":23,"order_id":"1775527798049904993","flags":0,"ts_in_delta":1001,"sequence":149839,"symbol":"FCEU SI 20260615 PS"}
{"ts_recv":"2026-04-07T02:10:05.035082478Z","hd":{"ts_event":"2026-04-07T02:10:05.035060777Z","rtype":160,"publisher_id":101,"instrument_id":436},"action":"A","side":"A","price":"1.156470000","size":30,"channel_id":23,"order_id":"1775527805035066982","flags":128,"ts_in_delta":1001,"sequence":149839,"symbol":"FCEU SI 20260615 PS"}
{"ts_recv":"2026-04-07T02:10:05.035143454Z","hd":{"ts_event":"2026-04-07T02:10:05.035125685Z","rtype":160,"publisher_id":101,"instrument_id":436},"action":"C","side":"B","price":"1.156370000","size":30,"channel_id":23,"order_id":"10998899841889842790","flags":0,"ts_in_delta":976,"sequence":149840,"symbol":"FCEU SI 20260615 PS"}
{"ts_recv":"2026-04-07T02:10:05.035143454Z","hd":{"ts_event":"2026-04-07T02:10:05.035125685Z","rtype":160,"publisher_id":101,"instrument_id":436},"action":"A","side":"B","price":"1.156390000","size":30,"channel_id":23,"order_id":"10998899841889907426","flags":0,"ts_in_delta":976,"sequence":149840,"symbol":"FCEU SI 20260615 PS"}
{"ts_recv":"2026-04-07T02:10:05.035143454Z","hd":{"ts_event":"2026-04-07T02:10:05.035125685Z","rtype":160,"publisher_id":101,"instrument_id":436},"action":"C","side":"A","price":"1.156470000","size":30,"channel_id":23,"order_id":"1775527805035066982","flags":0,"ts_in_delta":976,"sequence":149840,"symbol":"FCEU SI 20260615 PS"}
{"ts_recv":"2026-04-07T02:10:05.035143454Z","hd":{"ts_event":"2026-04-07T02:10:05.035125685Z","rtype":160,"publisher_id":101,"instrument_id":436},"action":"A","side":"A","price":"1.156490000","size":30,"channel_id":23,"order_id":"1775527805035131618","flags":128,"ts_in_delta":976,"sequence":149840,"symbol":"FCEU SI 20260615 PS"}
{"ts_recv":"2026-04-07T02:10:05.035155288Z","hd":{"ts_event":"2026-04-07T02:10:05.035137189Z","rtype":160,"publisher_id":101,"instrument_id":436},"action":"C","side":"B","price":"1.156350000","size":30,"channel_id":23,"order_id":"10998899834904743559","flags":0,"ts_in_delta":977,"sequence":149841,"symbol":"FCEU SI 20260615 PS"}
{"ts_recv":"2026-04-07T02:10:05.035155288Z","hd":{"ts_event":"2026-04-07T02:10:05.035137189Z","rtype":160,"publisher_id":101,"instrument_id":436},"action":"A","side":"B","price":"1.156360000","size":30,"channel_id":23,"order_id":"10998899841889918853","flags":0,"ts_in_delta":977,"sequence":149841,"symbol":"FCEU SI 20260615 PS"}
{"ts_recv":"2026-04-07T02:10:05.035155288Z","hd":{"ts_event":"2026-04-07T02:10:05.035137189Z","rtype":160,"publisher_id":101,"instrument_id":436},"action":"C","side":"A","price":"1.156450000","size":30,"channel_id":23,"order_id":"1775527798049967751","flags":0,"ts_in_delta":977,"sequence":149841,"symbol":"FCEU SI 20260615 PS"}
{"ts_recv":"2026-04-07T02:10:05.035155288Z","hd":{"ts_event":"2026-04-07T02:10:05.035137189Z","rtype":160,"publisher_id":101,"instrument_id":436},"action":"A","side":"A","price":"1.156460000","size":30,"channel_id":23,"order_id":"1775527805035143045","flags":128,"ts_in_delta":977,"sequence":149841,"symbol":"FCEU SI 20260615 PS"}
{"ts_recv":"2026-04-07T02:10:05.035193157Z","hd":{"ts_event":"2026-04-07T02:10:05.035177239Z","rtype":160,"publisher_id":101,"instrument_id":436},"action":"C","side":"B","price":"1.156390000","size":30,"channel_id":23,"order_id":"10998899841889907426","flags":0,"ts_in_delta":948,"sequence":149842,"symbol":"FCEU SI 20260615 PS"}
{"ts_recv":"2026-04-07T02:10:05.035193157Z","hd":{"ts_event":"2026-04-07T02:10:05.035177239Z","rtype":160,"publisher_id":101,"instrument_id":436},"action":"A","side":"B","price":"1.156370000","size":30,"channel_id":23,"order_id":"10998899841889959184","flags":0,"ts_in_delta":948,"sequence":149842,"symbol":"FCEU SI 20260615 PS"}
{"ts_recv":"2026-04-07T02:10:05.035193157Z","hd":{"ts_event":"2026-04-07T02:10:05.035177239Z","rtype":160,"publisher_id":101,"instrument_id":436},"action":"C","side":"A","price":"1.156490000","size":30,"channel_id":23,"order_id":"1775527805035131618","flags":0,"ts_in_delta":948,"sequence":149842,"symbol":"FCEU SI 20260615 PS"}
{"ts_recv":"2026-04-07T02:10:05.035193157Z","hd":{"ts_event":"2026-04-07T02:10:05.035177239Z","rtype":160,"publisher_id":101,"instrument_id":436},"action":"A","side":"A","price":"1.156470000","size":30,"channel_id":23,"order_id":"1775527805035183376","flags":128,"ts_in_delta":948,"sequence":149842,"symbol":"FCEU SI 20260615 PS"}
{"ts_recv":"2026-04-07T02:10:05.035232024Z","hd":{"ts_event":"2026-04-07T02:10:05.035216215Z","rtype":160,"publisher_id":101,"instrument_id":436},"action":"C","side":"B","price":"1.156360000","size":30,"channel_id":23,"order_id":"10998899841889918853","flags":0,"ts_in_delta":953,"sequence":149843,"symbol":"FCEU SI 20260615 PS"}
{"ts_recv":"2026-04-07T02:10:05.035232024Z","hd":{"ts_event":"2026-04-07T02:10:05.035216215Z","rtype":160,"publisher_id":101,"instrument_id":436},"action":"A","side":"B","price":"1.156370000","size":30,"channel_id":23,"order_id":"10998899841889997864","flags":0,"ts_in_delta":953,"sequence":149843,"symbol":"FCEU SI 20260615 PS"}
{"ts_recv":"2026-04-07T02:10:05.035232024Z","hd":{"ts_event":"2026-04-07T02:10:05.035216215Z","rtype":160,"publisher_id":101,"instrument_id":436},"action":"C","side":"A","price":"1.156460000","size":30,"channel_id":23,"order_id":"1775527805035143045","flags":0,"ts_in_delta":953,"sequence":149843,"symbol":"FCEU SI 20260615 PS"}
{"ts_recv":"2026-04-07T02:10:05.035232024Z","hd":{"ts_event":"2026-04-07T02:10:05.035216215Z","rtype":160,"publisher_id":101,"instrument_id":436},"action":"A","side":"A","price":"1.156470000","size":30,"channel_id":23,"order_id":"1775527805035222056","flags":128,"ts_in_delta":953,"sequence":149843,"symbol":"FCEU SI 20260615 PS"}
{"ts_recv":"2026-04-07T02:10:05.035289490Z","hd":{"ts_event":"2026-04-07T02:10:05.035270993Z","rtype":160,"publisher_id":101,"instrument_id":436},"action":"C","side":"B","price":"1.156370000","size":30,"channel_id":23,"order_id":"10998899841889997864","flags":0,"ts_in_delta":948,"sequence":149844,"symbol":"FCEU SI 20260615 PS"}
{"ts_recv":"2026-04-07T02:10:05.035289490Z","hd":{"ts_event":"2026-04-07T02:10:05.035270993Z","rtype":160,"publisher_id":101,"instrument_id":436},"action":"A","side":"B","price":"1.156360000","size":30,"channel_id":23,"order_id":"10998899841890052350","flags":0,"ts_in_delta":948,"sequence":149844,"symbol":"FCEU SI 20260615 PS"}
{"ts_recv":"2026-04-07T02:10:05.035289490Z","hd":{"ts_event":"2026-04-07T02:10:05.035270993Z","rtype":160,"publisher_id":101,"instrument_id":436},"action":"C","side":"A","price":"1.156470000","size":30,"channel_id":23,"order_id":"1775527805035222056","flags":0,"ts_in_delta":948,"sequence":149844,"symbol":"FCEU SI 20260615 PS"}
{"ts_recv":"2026-04-07T02:10:05.035289490Z","hd":{"ts_event":"2026-04-07T02:10:05.035270993Z","rtype":160,"publisher_id":101,"instrument_id":436},"action":"A","side":"A","price":"1.156460000","size":30,"channel_id":23,"order_id":"1775527805035276542","flags":128,"ts_in_delta":948,"sequence":149844,"symbol":"FCEU SI 20260615 PS"}
{"ts_recv":"2026-04-07T02:10:05.036443081Z","hd":{"ts_event":"2026-04-07T02:10:05.036423763Z","rtype":160,"publisher_id":101,"instrument_id":436},"action":"C","side":"B","price":"1.156360000","size":30,"channel_id":23,"order_id":"10998899841890052350","flags":0,"ts_in_delta":773,"sequence":149846,"symbol":"FCEU SI 20260615 PS"}
{"ts_recv":"2026-04-07T02:10:05.036443081Z","hd":{"ts_event":"2026-04-07T02:10:05.036423763Z","rtype":160,"publisher_id":101,"instrument_id":436},"action":"A","side":"B","price":"1.156370000","size":30,"channel_id":23,"order_id":"10998899841891205314","flags":0,"ts_in_delta":773,"sequence":149846,"symbol":"FCEU SI 20260615 PS"}
{"ts_recv":"2026-04-07T02:10:05.036443081Z","hd":{"ts_event":"2026-04-07T02:10:05.036423763Z","rtype":160,"publisher_id":101,"instrument_id":436},"action":"C","side":"A","price":"1.156460000","size":30,"channel_id":23,"order_id":"1775527805035276542","flags":0,"ts_in_delta":773,"sequence":149846,"symbol":"FCEU SI 20260615 PS"}
{"ts_recv":"2026-04-07T02:10:05.036443081Z","hd":{"ts_event":"2026-04-07T02:10:05.036423763Z","rtype":160,"publisher_id":101,"instrument_id":436},"action":"A","side":"A","price":"1.156470000","size":30,"channel_id":23,"order_id":"1775527805036429506","flags":128,"ts_in_delta":773,"sequence":149846,"symbol":"FCEU SI 20260615 PS"}
{"ts_recv":"2026-04-07T02:10:05.046259092Z","hd":{"ts_event":"2026-04-07T02:10:05.046240603Z","rtype":160,"publisher_id":101,"instrument_id":436},"action":"C","side":"B","price":"1.156370000","size":30,"channel_id":23,"order_id":"10998899841891205314","flags":0,"ts_in_delta":760,"sequence":149856,"symbol":"FCEU SI 20260615 PS"}
{"ts_recv":"2026-04-07T02:10:05.046259092Z","hd":{"ts_event":"2026-04-07T02:10:05.046240603Z","rtype":160,"publisher_id":101,"instrument_id":436},"action":"A","side":"B","price":"1.156380000","size":30,"channel_id":23,"order_id":"10998899841901022146","flags":0,"ts_in_delta":760,"sequence":149856,"symbol":"FCEU SI 20260615 PS"}
{"ts_recv":"2026-04-07T02:10:05.046259092Z","hd":{"ts_event":"2026-04-07T02:10:05.046240603Z","rtype":160,"publisher_id":101,"instrument_id":436},"action":"C","side":"A","price":"1.156470000","size":30,"channel_id":23,"order_id":"1775527805036429506","flags":0,"ts_in_delta":760,"sequence":149856,"symbol":"FCEU SI 20260615 PS"}
{"ts_recv":"2026-04-07T02:10:05.046259092Z","hd":{"ts_event":"2026-04-07T02:10:05.046240603Z","rtype":160,"publisher_id":101,"instrument_id":436},"action":"A","side":"A","price":"1.156480000","size":30,"channel_id":23,"order_id":"1775527805046246338","flags":128,"ts_in_delta":760,"sequence":149856,"symbol":"FCEU SI 20260615 PS"}
{"ts_recv":"2026-04-07T02:10:05.046320721Z","hd":{"ts_event":"2026-04-07T02:10:05.046300777Z","rtype":160,"publisher_id":101,"instrument_id":436},"action":"C","side":"B","price":"1.156380000","size":30,"channel_id":23,"order_id":"10998899841901022146","flags":0,"ts_in_delta":757,"sequence":149858,"symbol":"FCEU SI 20260615 PS"}
