{"ts_recv":"2026-04-07T00:00:00.246103535Z","hd":{"ts_event":"2026-04-07T00:00:00.246086711Z","rtype":160,"publisher_id":101,"instrument_id":436},"action":"R","side":"N","price":null,"size":0,"channel_id":23,"order_id":"0","flags":8,"ts_in_delta":0,"sequence":0,"symbol":"FCEU SI 20260615 PS"}
{"ts_recv":"2026-04-07T00:00:00.246103535Z","hd":{"ts_event":"2026-04-07T00:00:00.246086711Z","rtype":160,"publisher_id":101,"instrument_id":436},"action":"A","side":"B","price":"1.157500000","size":20,"channel_id":23,"order_id":"10998892037100869125","flags":128,"ts_in_delta":985,"sequence":81255,"symbol":"FCEU SI 20260615 PS"}
{"ts_recv":"2026-04-07T00:00:02.399346488Z","hd":{"ts_event":"2026-04-07T00:00:02.399330365Z","rtype":160,"publisher_id":101,"instrument_id":436},"action":"A","side":"B","price":"1.157600000","size":20,"channel_id":23,"order_id":"10998892039254112367","flags":128,"ts_in_delta":987,"sequence":81350,"symbol":"FCEU SI 20260615 PS"}
{"ts_recv":"2026-04-07T00:00:02.399364973Z","hd":{"ts_event":"2026-04-07T00:00:02.399352523Z","rtype":160,"publisher_id":101,"instrument_id":436},"action":"C","side":"B","price":"1.157500000","size":20,"channel_id":23,"order_id":"10998892037100869125","flags":128,"ts_in_delta":882,"sequence":81351,"symbol":"FCEU SI 20260615 PS"}
{"ts_recv":"2026-04-07T00:00:19.838579768Z","hd":{"ts_event":"2026-04-07T00:00:19.838565217Z","rtype":160,"publisher_id":101,"instrument_id":436},"action":"C","side":"B","price":"1.157600000","size":20,"channel_id":23,"order_id":"10998892039254112367","flags":128,"ts_in_delta":943,"sequence":81568,"symbol":"FCEU SI 20260615 PS"}
{"ts_recv":"2026-04-07T00:00:19.882661408Z","hd":{"ts_event":"2026-04-07T00:00:19.882644143Z","rtype":160,"publisher_id":101,"instrument_id":436},"action":"A","side":"B","price":"1.157500000","size":20,"channel_id":23,"order_id":"10998892056737426361","flags":128,"ts_in_delta":900,"sequence":81571,"symbol":"FCEU SI 20260615 PS"}
{"ts_recv":"2026-04-07T00:00:33.460507488Z","hd":{"ts_event":"2026-04-07T00:00:33.460493625Z","rtype":160,"publisher_id":101,"instrument_id":436},"action":"C","side":"B","price":"1.157500000","size":20,"channel_id":23,"order_id":"10998892056737426361","flags":128,"ts_in_delta":784,"sequence":81743,"symbol":"FCEU SI 20260615 PS"}
{"ts_recv":"2026-04-07T00:00:33.503274591Z","hd":{"ts_event":"2026-04-07T00:00:33.503261167Z","rtype":160,"publisher_id":101,"instrument_id":436},"action":"A","side":"B","price":"1.157500000","size":20,"channel_id":23,"order_id":"10998892070358042777","flags":128,"ts_in_delta":830,"sequence":81747,"symbol":"FCEU SI 20260615 PS"}
{"ts_recv":"2026-04-07T00:00:33.531215628Z","hd":{"ts_event":"2026-04-07T00:00:33.531199293Z","rtype":160,"publisher_id":101,"instrument_id":436},"action":"A","side":"A","price":"1.157900000","size":20,"channel_id":23,"order_id":"1775520033531204969","flags":128,"ts_in_delta":771,"sequence":81755,"symbol":"FCEU SI 20260615 PS"}
{"ts_recv":"2026-04-07T00:00:54.628932898Z","hd":{"ts_event":"2026-04-07T00:00:54.628919025Z","rtype":160,"publisher_id":101,"instrument_id":436},"action":"C","side":"B","price":"1.157500000","size":20,"channel_id":23,"order_id":"10998892070358042777","flags":128,"ts_in_delta":767,"sequence":81989,"symbol":"FCEU SI 20260615 PS"}
{"ts_recv":"2026-04-07T00:00:54.682446289Z","hd":{"ts_event":"2026-04-07T00:00:54.682427329Z","rtype":160,"publisher_id":101,"instrument_id":436},"action":"A","side":"B","price":"1.157500000","size":20,"channel_id":23,"order_id":"10998892091537209869","flags":128,"ts_in_delta":1508,"sequence":81993,"symbol":"FCEU SI 20260615 PS"}
{"ts_recv":"2026-04-07T00:01:09.482068482Z","hd":{"ts_event":"2026-04-07T00:01:09.482054823Z","rtype":160,"publisher_id":101,"instrument_id":436},"action":"C","side":"B","price":"1.157500000","size":20,"channel_id":23,"order_id":"10998892091537209869","flags":128,"ts_in_delta":881,"sequence":82136,"symbol":"FCEU SI 20260615 PS"}
{"ts_recv":"2026-04-07T00:01:09.525232416Z","hd":{"ts_event":"2026-04-07T00:01:09.525216191Z","rtype":160,"publisher_id":101,"instrument_id":436},"action":"A","side":"B","price":"1.157400000","size":20,"channel_id":23,"order_id":"10998892106379998147","flags":128,"ts_in_delta":960,"sequence":82143,"symbol":"FCEU SI 20260615 PS"}
{"ts_recv":"2026-04-07T00:01:11.365520031Z","hd":{"ts_event":"2026-04-07T00:01:11.365496697Z","rtype":160,"publisher_id":101,"instrument_id":436},"action":"A","side":"B","price":"1.157500000","size":20,"channel_id":23,"order_id":"10998892108220283376","flags":128,"ts_in_delta":1388,"sequence":82177,"symbol":"FCEU SI 20260615 PS"}
{"ts_recv":"2026-04-07T00:01:11.365533125Z","hd":{"ts_event":"2026-04-07T00:01:11.365520231Z","rtype":160,"publisher_id":101,"instrument_id":436},"action":"C","side":"B","price":"1.157400000","size":20,"channel_id":23,"order_id":"10998892106379998147","flags":128,"ts_in_delta":982,"sequence":82178,"symbol":"FCEU SI 20260615 PS"}
{"ts_recv":"2026-04-07T00:01:18.907823017Z","hd":{"ts_event":"2026-04-07T00:01:18.907798815Z","rtype":160,"publisher_id":101,"instrument_id":436},"action":"C","side":"B","price":"1.157500000","size":20,"channel_id":23,"order_id":"10998892108220283376","flags":128,"ts_in_delta":936,"sequence":82239,"symbol":"FCEU SI 20260615 PS"}
{"ts_recv":"2026-04-07T00:01:18.951389537Z","hd":{"ts_event":"2026-04-07T00:01:18.951366679Z","rtype":160,"publisher_id":101,"instrument_id":436},"action":"A","side":"B","price":"1.157400000","size":20,"channel_id":23,"order_id":"10998892115806153701","flags":128,"ts_in_delta":1308,"sequence":82241,"symbol":"FCEU SI 20260615 PS"}
{"ts_recv":"2026-04-07T00:01:19.218087232Z","hd":{"ts_event":"2026-04-07T00:01:19.218073601Z","rtype":160,"publisher_id":101,"instrument_id":436},"action":"A","side":"B","price":"1.157500000","size":20,"channel_id":23,"order_id":"10998892116072855677","flags":128,"ts_in_delta":927,"sequence":82245,"symbol":"FCEU SI 20260615 PS"}
{"ts_recv":"2026-04-07T00:01:19.218102914Z","hd":{"ts_event":"2026-04-07T00:01:19.218089927Z","rtype":160,"publisher_id":101,"instrument_id":436},"action":"C","side":"B","price":"1.157400000","size":20,"channel_id":23,"order_id":"10998892115806153701","flags":128,"ts_in_delta":887,"sequence":82246,"symbol":"FCEU SI 20260615 PS"}
{"ts_recv":"2026-04-07T00:01:24.217145350Z","hd":{"ts_event":"2026-04-07T00:01:24.217124685Z","rtype":160,"publisher_id":101,"instrument_id":436},"action":"C","side":"B","price":"1.157500000","size":20,"channel_id":23,"order_id":"10998892116072855677","flags":128,"ts_in_delta":1503,"sequence":82308,"symbol":"FCEU SI 20260615 PS"}
{"ts_recv":"2026-04-07T00:01:24.260115546Z","hd":{"ts_event":"2026-04-07T00:01:24.260096691Z","rtype":160,"publisher_id":101,"instrument_id":436},"action":"A","side":"B","price":"1.157400000","size":20,"channel_id":23,"order_id":"10998892121114883318","flags":128,"ts_in_delta":1213,"sequence":82310,"symbol":"FCEU SI 20260615 PS"}
{"ts_recv":"2026-04-07T00:01:35.706137267Z","hd":{"ts_event":"2026-04-07T00:01:35.706121441Z","rtype":160,"publisher_id":101,"instrument_id":436},"action":"A","side":"B","price":"1.157500000","size":20,"channel_id":23,"order_id":"10998892132560903343","flags":128,"ts_in_delta":877,"sequence":82394,"symbol":"FCEU SI 20260615 PS"}
{"ts_recv":"2026-04-07T00:01:35.706152634Z","hd":{"ts_event":"2026-04-07T00:01:35.706141153Z","rtype":160,"publisher_id":101,"instrument_id":436},"action":"C","side":"B","price":"1.157400000","size":20,"channel_id":23,"order_id":"10998892121114883318","flags":128,"ts_in_delta":871,"sequence":82395,"symbol":"FCEU SI 20260615 PS"}
{"ts_recv":"2026-04-07T00:01:42.196153530Z","hd":{"ts_event":"2026-04-07T00:01:42.196134249Z","rtype":160,"publisher_id":101,"instrument_id":436},"action":"C","side":"B","price":"1.157500000","size":20,"channel_id":23,"order_id":"10998892132560903343","flags":128,"ts_in_delta":841,"sequence":82422,"symbol":"FCEU SI 20260615 PS"}
{"ts_recv":"2026-04-07T00:01:42.239154107Z","hd":{"ts_event":"2026-04-07T00:01:42.239132597Z","rtype":160,"publisher_id":101,"instrument_id":436},"action":"A","side":"B","price":"1.157400000","size":20,"channel_id":23,"order_id":"10998892139093919353","flags":128,"ts_in_delta":856,"sequence":82423,"symbol":"FCEU SI 20260615 PS"}
{"ts_recv":"2026-04-07T00:01:51.125769991Z","hd":{"ts_event":"2026-04-07T00:01:51.125757303Z","rtype":160,"publisher_id":101,"instrument_id":436},"action":"C","side":"B","price":"1.157400000","size":20,"channel_id":23,"order_id":"10998892139093919353","flags":128,"ts_in_delta":851,"sequence":82501,"symbol":"FCEU SI 20260615 PS"}
{"ts_recv":"2026-04-07T00:01:51.151138470Z","hd":{"ts_event":"2026-04-07T00:01:51.151122233Z","rtype":160,"publisher_id":101,"instrument_id":436},"action":"A","side":"A","price":"1.157800000","size":20,"channel_id":23,"order_id":"1775520111151128144","flags":128,"ts_in_delta":831,"sequence":82509,"symbol":"FCEU SI 20260615 PS"}
{"ts_recv":"2026-04-07T00:01:51.151795134Z","hd":{"ts_event":"2026-04-07T00:01:51.151783473Z","rtype":160,"publisher_id":101,"instrument_id":436},"action":"C","side":"A","price":"1.157900000","size":20,"channel_id":23,"order_id":"1775520033531204969","flags":128,"ts_in_delta":851,"sequence":82512,"symbol":"FCEU SI 20260615 PS"}
{"ts_recv":"2026-04-07T00:01:51.256299496Z","hd":{"ts_event":"2026-04-07T00:01:51.256283193Z","rtype":160,"publisher_id":101,"instrument_id":436},"action":"A","side":"B","price":"1.157400000","size":20,"channel_id":23,"order_id":"10998892148111064998","flags":128,"ts_in_delta":970,"sequence":82525,"symbol":"FCEU SI 20260615 PS"}
{"ts_recv":"2026-04-07T00:02:02.042218207Z","hd":{"ts_event":"2026-04-07T00:02:02.042204649Z","rtype":160,"publisher_id":101,"instrument_id":436},"action":"C","side":"A","price":"1.157800000","size":20,"channel_id":23,"order_id":"1775520111151128144","flags":128,"ts_in_delta":887,"sequence":82609,"symbol":"FCEU SI 20260615 PS"}
{"ts_recv":"2026-04-07T00:02:02.084502711Z","hd":{"ts_event":"2026-04-07T00:02:02.084487611Z","rtype":160,"publisher_id":101,"instrument_id":436},"action":"A","side":"A","price":"1.157900000","size":20,"channel_id":23,"order_id":"1775520122084494086","flags":128,"ts_in_delta":903,"sequence":82613,"symbol":"FCEU SI 20260615 PS"}
{"ts_recv":"2026-04-07T00:02:16.249564241Z","hd":{"ts_event":"2026-04-07T00:02:16.249539521Z","rtype":160,"publisher_id":101,"instrument_id":436},"action":"A","side":"A","price":"1.157800000","size":20,"channel_id":23,"order_id":"1775520136249551178","flags":128,"ts_in_delta":987,"sequence":82713,"symbol":"FCEU SI 20260615 PS"}
{"ts_recv":"2026-04-07T00:02:16.249567267Z","hd":{"ts_event":"2026-04-07T00:02:16.249553949Z","rtype":160,"publisher_id":101,"instrument_id":436},"action":"C","side":"A","price":"1.157900000","size":20,"channel_id":23,"order_id":"1775520122084494086","flags":128,"ts_in_delta":741,"sequence":82714,"symbol":"FCEU SI 20260615 PS"}
{"ts_recv":"2026-04-07T00:02:21.221491988Z","hd":{"ts_event":"2026-04-07T00:02:21.221477827Z","rtype":160,"publisher_id":101,"instrument_id":436},"action":"C","side":"B","price":"1.157400000","size":20,"channel_id":23,"order_id":"10998892148111064998","flags":128,"ts_in_delta":1014,"sequence":82758,"symbol":"FCEU SI 20260615 PS"}
{"ts_recv":"2026-04-07T00:02:21.265258875Z","hd":{"ts_event":"2026-04-07T00:02:21.265243965Z","rtype":160,"publisher_id":101,"instrument_id":436},"action":"A","side":"B","price":"1.157300000","size":20,"channel_id":23,"order_id":"10998892178120025916","flags":128,"ts_in_delta":1078,"sequence":82761,"symbol":"FCEU SI 20260615 PS"}
{"ts_recv":"2026-04-07T00:02:22.131172364Z","hd":{"ts_event":"2026-04-07T00:02:22.131149851Z","rtype":160,"publisher_id":101,"instrument_id":436},"action":"A","side":"B","price":"1.157400000","size":20,"channel_id":23,"order_id":"10998892178985936642","flags":128,"ts_in_delta":1115,"sequence":82774,"symbol":"FCEU SI 20260615 PS"}
{"ts_recv":"2026-04-07T00:02:22.131179552Z","hd":{"ts_event":"2026-04-07T00:02:22.131166901Z","rtype":160,"publisher_id":101,"instrument_id":436},"action":"C","side":"B","price":"1.157300000","size":20,"channel_id":23,"order_id":"10998892178120025916","flags":128,"ts_in_delta":919,"sequence":82775,"symbol":"FCEU SI 20260615 PS"}
{"ts_recv":"2026-04-07T00:02:27.130959782Z","hd":{"ts_event":"2026-04-07T00:02:27.130946967Z","rtype":160,"publisher_id":101,"instrument_id":436},"action":"C","side":"B","price":"1.157400000","size":20,"channel_id":23,"order_id":"10998892178985936642","flags":128,"ts_in_delta":892,"sequence":82833,"symbol":"FCEU SI 20260615 PS"}
{"ts_recv":"2026-04-07T00:02:27.174918616Z","hd":{"ts_event":"2026-04-07T00:02:27.174903081Z","rtype":160,"publisher_id":101,"instrument_id":436},"action":"A","side":"B","price":"1.157300000","size":20,"channel_id":23,"order_id":"10998892184029685206","flags":128,"ts_in_delta":1019,"sequence":82838,"symbol":"FCEU SI 20260615 PS"}
{"ts_recv":"2026-04-07T00:02:30.864515985Z","hd":{"ts_event":"2026-04-07T00:02:30.864487765Z","rtype":160,"publisher_id":101,"instrument_id":436},"action":"A","side":"A","price":"1.157700000","size":20,"channel_id":23,"order_id":"1775520150864500785","flags":128,"ts_in_delta":1683,"sequence":82884,"symbol":"FCEU SI 20260615 PS"}
{"ts_recv":"2026-04-07T00:02:30.864576024Z","hd":{"ts_event":"2026-04-07T00:02:30.864562473Z","rtype":160,"publisher_id":101,"instrument_id":436},"action":"C","side":"A","price":"1.157800000","size":20,"channel_id":23,"order_id":"1775520136249551178","flags":128,"ts_in_delta":886,"sequence":82887,"symbol":"FCEU SI 20260615 PS"}
{"ts_recv":"2026-04-07T00:02:48.711287030Z","hd":{"ts_event":"2026-04-07T00:02:48.711262167Z","rtype":160,"publisher_id":101,"instrument_id":436},"action":"C","side":"A","price":"1.157700000","size":20,"channel_id":23,"order_id":"1775520150864500785","flags":128,"ts_in_delta":1331,"sequence":83010,"symbol":"FCEU SI 20260615 PS"}
{"ts_recv":"2026-04-07T00:02:48.753697064Z","hd":{"ts_event":"2026-04-07T00:02:48.753673187Z","rtype":160,"publisher_id":101,"instrument_id":436},"action":"A","side":"A","price":"1.157800000","size":20,"channel_id":23,"order_id":"1775520168753684086","flags":128,"ts_in_delta":1385,"sequence":83012,"symbol":"FCEU SI 20260615 PS"}
{"ts_recv":"2026-04-07T00:03:00.230134637Z","hd":{"ts_event":"2026-04-07T00:03:00.230118189Z","rtype":160,"publisher_id":101,"instrument_id":436},"action":"A","side":"B","price":"1.157400000","size":20,"channel_id":23,"order_id":"10998892217084900190","flags":128,"ts_in_delta":836,"sequence":83113,"symbol":"FCEU SI 20260615 PS"}
{"ts_recv":"2026-04-07T00:03:00.230204046Z","hd":{"ts_event":"2026-04-07T00:03:00.230191237Z","rtype":160,"publisher_id":101,"instrument_id":436},"action":"C","side":"B","price":"1.157300000","size":20,"channel_id":23,"order_id":"10998892184029685206","flags":128,"ts_in_delta":830,"sequence":83115,"symbol":"FCEU SI 20260615 PS"}
{"ts_recv":"2026-04-07T00:03:13.957319559Z","hd":{"ts_event":"2026-04-07T00:03:13.957305657Z","rtype":160,"publisher_id":101,"instrument_id":436},"action":"C","side":"B","price":"1.157400000","size":20,"channel_id":23,"order_id":"10998892217084900190","flags":128,"ts_in_delta":957,"sequence":83223,"symbol":"FCEU SI 20260615 PS"}
{"ts_recv":"2026-04-07T00:03:14.000312532Z","hd":{"ts_event":"2026-04-07T00:03:14.000296809Z","rtype":160,"publisher_id":101,"instrument_id":436},"action":"A","side":"B","price":"1.157300000","size":20,"channel_id":23,"order_id":"10998892230855079233","flags":128,"ts_in_delta":741,"sequence":83225,"symbol":"FCEU SI 20260615 PS"}
{"ts_recv":"2026-04-07T00:03:14.224182021Z","hd":{"ts_event":"2026-04-07T00:03:14.224159353Z","rtype":160,"publisher_id":101,"instrument_id":436},"action":"A","side":"B","price":"1.157400000","size":20,"channel_id":23,"order_id":"10998892231078946033","flags":128,"ts_in_delta":1318,"sequence":83227,"symbol":"FCEU SI 20260615 PS"}
{"ts_recv":"2026-04-07T00:03:14.224192880Z","hd":{"ts_event":"2026-04-07T00:03:14.224180231Z","rtype":160,"publisher_id":101,"instrument_id":436},"action":"C","side":"B","price":"1.157300000","size":20,"channel_id":23,"order_id":"10998892230855079233","flags":128,"ts_in_delta":940,"sequence":83228,"symbol":"FCEU SI 20260615 PS"}
{"ts_recv":"2026-04-07T00:03:32.571492967Z","hd":{"ts_event":"2026-04-07T00:03:32.571470167Z","rtype":160,"publisher_id":101,"instrument_id":436},"action":"C","side":"B","price":"1.157400000","size":20,"channel_id":23,"order_id":"10998892231078946033","flags":128,"ts_in_delta":1097,"sequence":83387,"symbol":"FCEU SI 20260615 PS"}
{"ts_recv":"2026-04-07T00:03:32.613758525Z","hd":{"ts_event":"2026-04-07T00:03:32.613742685Z","rtype":160,"publisher_id":101,"instrument_id":436},"action":"A","side":"B","price":"1.157300000","size":20,"channel_id":23,"order_id":"10998892249468524524","flags":128,"ts_in_delta":742,"sequence":83388,"symbol":"FCEU SI 20260615 PS"}
{"ts_recv":"2026-04-07T00:03:36.792140754Z","hd":{"ts_event":"2026-04-07T00:03:36.792126209Z","rtype":160,"publisher_id":101,"instrument_id":436},"action":"A","side":"B","price":"1.157400000","size":20,"channel_id":23,"order_id":"10998892253646908026","flags":128,"ts_in_delta":834,"sequence":83427,"symbol":"FCEU SI 20260615 PS"}
{"ts_recv":"2026-04-07T00:03:36.792661526Z","hd":{"ts_event":"2026-04-07T00:03:36.792648633Z","rtype":160,"publisher_id":101,"instrument_id":436},"action":"C","side":"B","price":"1.157300000","size":20,"channel_id":23,"order_id":"10998892249468524524","flags":128,"ts_in_delta":860,"sequence":83428,"symbol":"FCEU SI 20260615 PS"}
{"ts_recv":"2026-04-07T00:03:52.834178430Z","hd":{"ts_event":"2026-04-07T00:03:52.834165181Z","rtype":160,"publisher_id":101,"instrument_id":436},"action":"C","side":"B","price":"1.157400000","size":20,"channel_id":23,"order_id":"10998892253646908026","flags":128,"ts_in_delta":902,"sequence":83606,"symbol":"FCEU SI 20260615 PS"}
{"ts_recv":"2026-04-07T00:03:52.971619979Z","hd":{"ts_event":"2026-04-07T00:03:52.971604289Z","rtype":160,"publisher_id":101,"instrument_id":436},"action":"A","side":"B","price":"1.157400000","size":20,"channel_id":23,"order_id":"10998892269826386605","flags":128,"ts_in_delta":882,"sequence":83613,"symbol":"FCEU SI 20260615 PS"}
{"ts_recv":"2026-04-07T00:04:02.907360428Z","hd":{"ts_event":"2026-04-07T00:04:02.907348177Z","rtype":160,"publisher_id":101,"instrument_id":436},"action":"C","side":"B","price":"1.157400000","size":20,"channel_id":23,"order_id":"10998892269826386605","flags":128,"ts_in_delta":962,"sequence":83679,"symbol":"FCEU SI 20260615 PS"}
{"ts_recv":"2026-04-07T00:04:02.950619256Z","hd":{"ts_event":"2026-04-07T00:04:02.950603697Z","rtype":160,"publisher_id":101,"instrument_id":436},"action":"A","side":"B","price":"1.157300000","size":20,"channel_id":23,"order_id":"10998892279805385713","flags":128,"ts_in_delta":827,"sequence":83683,"symbol":"FCEU SI 20260615 PS"}
{"ts_recv":"2026-04-07T00:04:03.375130806Z","hd":{"ts_event":"2026-04-07T00:04:03.375115155Z","rtype":160,"publisher_id":101,"instrument_id":436},"action":"A","side":"B","price":"1.157400000","size":20,"channel_id":23,"order_id":"10998892280229897015","flags":128,"ts_in_delta":857,"sequence":83694,"symbol":"FCEU SI 20260615 PS"}
{"ts_recv":"2026-04-07T00:04:03.375186660Z","hd":{"ts_event":"2026-04-07T00:04:03.375173485Z","rtype":160,"publisher_id":101,"instrument_id":436},"action":"C","side":"B","price":"1.157300000","size":20,"channel_id":23,"order_id":"10998892279805385713","flags":128,"ts_in_delta":817,"sequence":83696,"symbol":"FCEU SI 20260615 PS"}
{"ts_recv":"2026-04-07T00:04:08.374284138Z","hd":{"ts_event":"2026-04-07T00:04:08.374266181Z","rtype":160,"publisher_id":101,"instrument_id":436},"action":"C","side":"B","price":"1.157400000","size":20,"channel_id":23,"order_id":"10998892280229897015","flags":128,"ts_in_delta":1244,"sequence":83745,"symbol":"FCEU SI 20260615 PS"}
{"ts_recv":"2026-04-07T00:04:08.416540677Z","hd":{"ts_event":"2026-04-07T00:04:08.416521327Z","rtype":160,"publisher_id":101,"instrument_id":436},"action":"A","side":"B","price":"1.157300000","size":20,"channel_id":23,"order_id":"10998892285271307753","flags":128,"ts_in_delta":826,"sequence":83746,"symbol":"FCEU SI 20260615 PS"}
{"ts_recv":"2026-04-07T00:04:11.861547125Z","hd":{"ts_event":"2026-04-07T00:04:11.861534235Z","rtype":160,"publisher_id":101,"instrument_id":436},"action":"A","side":"B","price":"1.157400000","size":20,"channel_id":23,"order_id":"10998892288716315804","flags":128,"ts_in_delta":879,"sequence":83780,"symbol":"FCEU SI 20260615 PS"}
{"ts_recv":"2026-04-07T00:04:11.861717083Z","hd":{"ts_event":"2026-04-07T00:04:11.861706065Z","rtype":160,"publisher_id":101,"instrument_id":436},"action":"C","side":"B","price":"1.157300000","size":20,"channel_id":23,"order_id":"10998892285271307753","flags":128,"ts_in_delta":884,"sequence":83783,"symbol":"FCEU SI 20260615 PS"}
{"ts_recv":"2026-04-07T00:04:56.860251247Z","hd":{"ts_event":"2026-04-07T00:04:56.860236819Z","rtype":160,"publisher_id":101,"instrument_id":436},"action":"C","side":"B","price":"1.157400000","size":20,"channel_id":23,"order_id":"10998892288716315804","flags":128,"ts_in_delta":824,"sequence":84073,"symbol":"FCEU SI 20260615 PS"}
{"ts_recv":"2026-04-07T00:04:56.978233304Z","hd":{"ts_event":"2026-04-07T00:04:56.978219509Z","rtype":160,"publisher_id":101,"instrument_id":436},"action":"A","side":"B","price":"1.157400000","size":20,"channel_id":23,"order_id":"10998892333833001281","flags":128,"ts_in_delta":950,"sequence":84081,"symbol":"FCEU SI 20260615 PS"}
{"ts_recv":"2026-04-07T00:05:01.977518307Z","hd":{"ts_event":"2026-04-07T00:05:01.977501703Z","rtype":160,"publisher_id":101,"instrument_id":436},"action":"C","side":"B","price":"1.157400000","size":20,"channel_id":23,"order_id":"10998892333833001281","flags":128,"ts_in_delta":743,"sequence":84146,"symbol":"FCEU SI 20260615 PS"}
{"ts_recv":"2026-04-07T00:05:02.052360047Z","hd":{"ts_event":"2026-04-07T00:05:02.052343785Z","rtype":160,"publisher_id":101,"instrument_id":436},"action":"A","side":"B","price":"1.157400000","size":20,"channel_id":23,"order_id":"10998892338907125731","flags":128,"ts_in_delta":1217,"sequence":84147,"symbol":"FCEU SI 20260615 PS"}
{"ts_recv":"2026-04-07T00:05:11.283024964Z","hd":{"ts_event":"2026-04-07T00:05:11.283011267Z","rtype":160,"publisher_id":101,"instrument_id":436},"action":"C","side":"B","price":"1.157400000","size":20,"channel_id":23,"order_id":"10998892338907125731","flags":128,"ts_in_delta":906,"sequence":84190,"symbol":"FCEU SI 20260615 PS"}
{"ts_recv":"2026-04-07T00:05:11.326151111Z","hd":{"ts_event":"2026-04-07T00:05:11.326137011Z","rtype":160,"publisher_id":101,"instrument_id":436},"action":"A","side":"B","price":"1.157300000","size":20,"channel_id":23,"order_id":"10998892348180918815","flags":128,"ts_in_delta":987,"sequence":84207,"symbol":"FCEU SI 20260615 PS"}
{"ts_recv":"2026-04-07T00:05:32.827439640Z","hd":{"ts_event":"2026-04-07T00:05:32.827423113Z","rtype":160,"publisher_id":101,"instrument_id":436},"action":"A","side":"B","price":"1.157400000","size":20,"channel_id":23,"order_id":"10998892369682205278","flags":128,"ts_in_delta":1055,"sequence":84343,"symbol":"FCEU SI 20260615 PS"}
{"ts_recv":"2026-04-07T00:05:32.827556133Z","hd":{"ts_event":"2026-04-07T00:05:32.827543699Z","rtype":160,"publisher_id":101,"instrument_id":436},"action":"C","side":"B","price":"1.157300000","size":20,"channel_id":23,"order_id":"10998892348180918815","flags":128,"ts_in_delta":866,"sequence":84345,"symbol":"FCEU SI 20260615 PS"}
{"ts_recv":"2026-04-07T00:05:48.976448757Z","hd":{"ts_event":"2026-04-07T00:05:48.976434767Z","rtype":160,"publisher_id":101,"instrument_id":436},"action":"C","side":"B","price":"1.157400000","size":20,"channel_id":23,"order_id":"10998892369682205278","flags":128,"ts_in_delta":878,"sequence":84523,"symbol":"FCEU SI 20260615 PS"}
{"ts_recv":"2026-04-07T00:05:49.019239663Z","hd":{"ts_event":"2026-04-07T00:05:49.019226463Z","rtype":160,"publisher_id":101,"instrument_id":436},"action":"A","side":"B","price":"1.157300000","size":20,"channel_id":23,"order_id":"10998892385874007989","flags":128,"ts_in_delta":899,"sequence":84533,"symbol":"FCEU SI 20260615 PS"}
{"ts_recv":"2026-04-07T00:05:49.306609227Z","hd":{"ts_event":"2026-04-07T00:05:49.306593413Z","rtype":160,"publisher_id":101,"instrument_id":436},"action":"A","side":"B","price":"1.157400000","size":20,"channel_id":23,"order_id":"10998892386161375247","flags":128,"ts_in_delta":878,"sequence":84557,"symbol":"FCEU SI 20260615 PS"}
{"ts_recv":"2026-04-07T00:05:49.306712549Z","hd":{"ts_event":"2026-04-07T00:05:49.306699115Z","rtype":160,"publisher_id":101,"instrument_id":436},"action":"C","side":"B","price":"1.157300000","size":20,"channel_id":23,"order_id":"10998892385874007989","flags":128,"ts_in_delta":1027,"sequence":84558,"symbol":"FCEU SI 20260615 PS"}
{"ts_recv":"2026-04-07T00:06:02.080780061Z","hd":{"ts_event":"2026-04-07T00:06:02.080764677Z","rtype":160,"publisher_id":101,"instrument_id":436},"action":"C","side":"A","price":"1.157800000","size":20,"channel_id":23,"order_id":"1775520168753684086","flags":128,"ts_in_delta":1018,"sequence":84668,"symbol":"FCEU SI 20260615 PS"}
{"ts_recv":"2026-04-07T00:06:02.123511273Z","hd":{"ts_event":"2026-04-07T00:06:02.123495815Z","rtype":160,"publisher_id":101,"instrument_id":436},"action":"A","side":"A","price":"1.157900000","size":20,"channel_id":23,"order_id":"1775520362123501958","flags":128,"ts_in_delta":1215,"sequence":84674,"symbol":"FCEU SI 20260615 PS"}
{"ts_recv":"2026-04-07T00:06:02.209265478Z","hd":{"ts_event":"2026-04-07T00:06:02.209243967Z","rtype":160,"publisher_id":101,"instrument_id":436},"action":"A","side":"B","price":"1.157500000","size":20,"channel_id":23,"order_id":"10998892399064031028","flags":128,"ts_in_delta":1040,"sequence":84681,"symbol":"FCEU SI 20260615 PS"}
{"ts_recv":"2026-04-07T00:06:02.209536877Z","hd":{"ts_event":"2026-04-07T00:06:02.209525831Z","rtype":160,"publisher_id":101,"instrument_id":436},"action":"C","side":"B","price":"1.157400000","size":20,"channel_id":23,"order_id":"10998892386161375247","flags":128,"ts_in_delta":1036,"sequence":84682,"symbol":"FCEU SI 20260615 PS"}
{"ts_recv":"2026-04-07T00:06:15.994885833Z","hd":{"ts_event":"2026-04-07T00:06:15.994871863Z","rtype":160,"publisher_id":101,"instrument_id":436},"action":"C","side":"B","price":"1.157500000","size":20,"channel_id":23,"order_id":"10998892399064031028","flags":128,"ts_in_delta":911,"sequence":84883,"symbol":"FCEU SI 20260615 PS"}
{"ts_recv":"2026-04-07T00:06:16.057920402Z","hd":{"ts_event":"2026-04-07T00:06:16.057907407Z","rtype":160,"publisher_id":101,"instrument_id":436},"action":"A","side":"B","price":"1.157500000","size":20,"channel_id":23,"order_id":"10998892412912689189","flags":128,"ts_in_delta":822,"sequence":84898,"symbol":"FCEU SI 20260615 PS"}
{"ts_recv":"2026-04-07T00:06:24.012107823Z","hd":{"ts_event":"2026-04-07T00:06:24.012088247Z","rtype":160,"publisher_id":101,"instrument_id":436},"action":"C","side":"B","price":"1.157500000","size":20,"channel_id":23,"order_id":"10998892412912689189","flags":128,"ts_in_delta":1223,"sequence":84987,"symbol":"FCEU SI 20260615 PS"}
{"ts_recv":"2026-04-07T00:06:24.055199680Z","hd":{"ts_event":"2026-04-07T00:06:24.055179035Z","rtype":160,"publisher_id":101,"instrument_id":436},"action":"A","side":"B","price":"1.157400000","size":20,"channel_id":23,"order_id":"10998892420909965944","flags":128,"ts_in_delta":1238,"sequence":84989,"symbol":"FCEU SI 20260615 PS"}
{"ts_recv":"2026-04-07T00:06:25.878281335Z","hd":{"ts_event":"2026-04-07T00:06:25.878260791Z","rtype":160,"publisher_id":101,"instrument_id":436},"action":"A","side":"B","price":"1.157500000","size":20,"channel_id":23,"order_id":"10998892422733045184","flags":128,"ts_in_delta":1490,"sequence":85004,"symbol":"FCEU SI 20260615 PS"}
{"ts_recv":"2026-04-07T00:06:25.878290151Z","hd":{"ts_event":"2026-04-07T00:06:25.878274315Z","rtype":160,"publisher_id":101,"instrument_id":436},"action":"C","side":"B","price":"1.157400000","size":20,"channel_id":23,"order_id":"10998892420909965944","flags":128,"ts_in_delta":950,"sequence":85005,"symbol":"FCEU SI 20260615 PS"}
{"ts_recv":"2026-04-07T00:06:30.878532773Z","hd":{"ts_event":"2026-04-07T00:06:30.878513303Z","rtype":160,"publisher_id":101,"instrument_id":436},"action":"C","side":"B","price":"1.157500000","size":20,"channel_id":23,"order_id":"10998892422733045184","flags":128,"ts_in_delta":769,"sequence":85054,"symbol":"FCEU SI 20260615 PS"}
{"ts_recv":"2026-04-07T00:06:30.921445770Z","hd":{"ts_event":"2026-04-07T00:06:30.921431399Z","rtype":160,"publisher_id":101,"instrument_id":436},"action":"A","side":"B","price":"1.157400000","size":20,"channel_id":23,"order_id":"10998892427776213283","flags":128,"ts_in_delta":832,"sequence":85058,"symbol":"FCEU SI 20260615 PS"}
{"ts_recv":"2026-04-07T00:06:36.782875121Z","hd":{"ts_event":"2026-04-07T00:06:36.782859187Z","rtype":160,"publisher_id":101,"instrument_id":436},"action":"A","side":"A","price":"1.157800000","size":20,"channel_id":23,"order_id":"1775520396782865009","flags":128,"ts_in_delta":884,"sequence":85103,"symbol":"FCEU SI 20260615 PS"}
{"ts_recv":"2026-04-07T00:06:36.783284800Z","hd":{"ts_event":"2026-04-07T00:06:36.783271191Z","rtype":160,"publisher_id":101,"instrument_id":436},"action":"C","side":"A","price":"1.157900000","size":20,"channel_id":23,"order_id":"1775520362123501958","flags":128,"ts_in_delta":1093,"sequence":85104,"symbol":"FCEU SI 20260615 PS"}
{"ts_recv":"2026-04-07T00:06:38.770615269Z","hd":{"ts_event":"2026-04-07T00:06:38.770602707Z","rtype":160,"publisher_id":101,"instrument_id":436},"action":"C","side":"B","price":"1.157400000","size":20,"channel_id":23,"order_id":"10998892427776213283","flags":128,"ts_in_delta":863,"sequence":85150,"symbol":"FCEU SI 20260615 PS"}
{"ts_recv":"2026-04-07T00:06:38.813291368Z","hd":{"ts_event":"2026-04-07T00:06:38.813277287Z","rtype":160,"publisher_id":101,"instrument_id":436},"action":"A","side":"B","price":"1.157300000","size":20,"channel_id":23,"order_id":"10998892435668058856","flags":128,"ts_in_delta":967,"sequence":85155,"symbol":"FCEU SI 20260615 PS"}
{"ts_recv":"2026-04-07T00:06:40.282224751Z","hd":{"ts_event":"2026-04-07T00:06:40.282202709Z","rtype":160,"publisher_id":101,"instrument_id":436},"action":"A","side":"B","price":"1.157400000","size":20,"channel_id":23,"order_id":"10998892437136989516","flags":128,"ts_in_delta":1348,"sequence":85171,"symbol":"FCEU SI 20260615 PS"}
{"ts_recv":"2026-04-07T00:06:40.282269385Z","hd":{"ts_event":"2026-04-07T00:06:40.282255883Z","rtype":160,"publisher_id":101,"instrument_id":436},"action":"C","side":"B","price":"1.157300000","size":20,"channel_id":23,"order_id":"10998892435668058856","flags":128,"ts_in_delta":948,"sequence":85173,"symbol":"FCEU SI 20260615 PS"}
{"ts_recv":"2026-04-07T00:07:02.102221667Z","hd":{"ts_event":"2026-04-07T00:07:02.102207499Z","rtype":160,"publisher_id":101,"instrument_id":436},"action":"C","side":"B","price":"1.157400000","size":20,"channel_id":23,"order_id":"10998892437136989516","flags":128,"ts_in_delta":1043,"sequence":85409,"symbol":"FCEU SI 20260615 PS"}
{"ts_recv":"2026-04-07T00:07:02.145322169Z","hd":{"ts_event":"2026-04-07T00:07:02.145306185Z","rtype":160,"publisher_id":101,"instrument_id":436},"action":"A","side":"B","price":"1.157300000","size":20,"channel_id":23,"order_id":"10998892459000088503","flags":128,"ts_in_delta":1075,"sequence":85411,"symbol":"FCEU SI 20260615 PS"}
{"ts_recv":"2026-04-07T00:07:02.363058401Z","hd":{"ts_event":"2026-04-07T00:07:02.363036367Z","rtype":160,"publisher_id":101,"instrument_id":436},"action":"A","side":"B","price":"1.157400000","size":20,"channel_id":23,"order_id":"10998892459217824292","flags":128,"ts_in_delta":1140,"sequence":85415,"symbol":"FCEU SI 20260615 PS"}
{"ts_recv":"2026-04-07T00:07:02.363064837Z","hd":{"ts_event":"2026-04-07T00:07:02.363052331Z","rtype":160,"publisher_id":101,"instrument_id":436},"action":"C","side":"B","price":"1.157300000","size":20,"channel_id":23,"order_id":"10998892459000088503","flags":128,"ts_in_delta":891,"sequence":85416,"symbol":"FCEU SI 20260615 PS"}
{"ts_recv":"2026-04-07T00:07:16.574532733Z","hd":{"ts_event":"2026-04-07T00:07:16.574518153Z","rtype":160,"publisher_id":101,"instrument_id":436},"action":"C","side":"B","price":"1.157400000","size":20,"channel_id":23,"order_id":"10998892459217824292","flags":128,"ts_in_delta":851,"sequence":85508,"symbol":"FCEU SI 20260615 PS"}
{"ts_recv":"2026-04-07T00:07:16.617508386Z","hd":{"ts_event":"2026-04-07T00:07:16.617492293Z","rtype":160,"publisher_id":101,"instrument_id":436},"action":"A","side":"B","price":"1.157300000","size":20,"channel_id":23,"order_id":"10998892473472274524","flags":128,"ts_in_delta":995,"sequence":85511,"symbol":"FCEU SI 20260615 PS"}
{"ts_recv":"2026-04-07T00:07:16.732511291Z","hd":{"ts_event":"2026-04-07T00:07:16.732489045Z","rtype":160,"publisher_id":101,"instrument_id":436},"action":"A","side":"B","price":"1.157400000","size":20,"channel_id":23,"order_id":"10998892473587275845","flags":128,"ts_in_delta":1125,"sequence":85516,"symbol":"FCEU SI 20260615 PS"}
{"ts_recv":"2026-04-07T00:07:16.732520929Z","hd":{"ts_event":"2026-04-07T00:07:16.732508987Z","rtype":160,"publisher_id":101,"instrument_id":436},"action":"C","side":"B","price":"1.157300000","size":20,"channel_id":23,"order_id":"10998892473472274524","flags":128,"ts_in_delta":1016,"sequence":85517,"symbol":"FCEU SI 20260615 PS"}
{"ts_recv":"2026-04-07T00:07:35.012896632Z","hd":{"ts_event":"2026-04-07T00:07:35.012883289Z","rtype":160,"publisher_id":101,"instrument_id":436},"action":"C","side":"B","price":"1.157400000","size":20,"channel_id":23,"order_id":"10998892473587275845","flags":128,"ts_in_delta":882,"sequence":85748,"symbol":"FCEU SI 20260615 PS"}
{"ts_recv":"2026-04-07T00:07:35.056535516Z","hd":{"ts_event":"2026-04-07T00:07:35.056520487Z","rtype":160,"publisher_id":101,"instrument_id":436},"action":"A","side":"B","price":"1.157300000","size":20,"channel_id":23,"order_id":"10998892491911302356","flags":128,"ts_in_delta":905,"sequence":85752,"symbol":"FCEU SI 20260615 PS"}
{"ts_recv":"2026-04-07T00:07:40.188729094Z","hd":{"ts_event":"2026-04-07T00:07:40.188713031Z","rtype":160,"publisher_id":101,"instrument_id":436},"action":"A","side":"B","price":"1.157400000","size":20,"channel_id":23,"order_id":"10998892497043495045","flags":128,"ts_in_delta":992,"sequence":85789,"symbol":"FCEU SI 20260615 PS"}
{"ts_recv":"2026-04-07T00:07:40.188930370Z","hd":{"ts_event":"2026-04-07T00:07:40.188918025Z","rtype":160,"publisher_id":101,"instrument_id":436},"action":"C","side":"B","price":"1.157300000","size":20,"channel_id":23,"order_id":"10998892491911302356","flags":128,"ts_in_delta":894,"sequence":85791,"symbol":"FCEU SI 20260615 PS"}
{"ts_recv":"2026-04-07T00:08:30.672891545Z","hd":{"ts_event":"2026-04-07T00:08:30.672876993Z","rtype":160,"publisher_id":101,"instrument_id":436},"action":"C","side":"A","price":"1.157800000","size":20,"channel_id":23,"order_id":"1775520396782865009","flags":128,"ts_in_delta":988,"sequence":86348,"symbol":"FCEU SI 20260615 PS"}
{"ts_recv":"2026-04-07T00:08:30.715734587Z","hd":{"ts_event":"2026-04-07T00:08:30.715716855Z","rtype":160,"publisher_id":101,"instrument_id":436},"action":"A","side":"A","price":"1.157900000","size":20,"channel_id":23,"order_id":"1775520510715722923","flags":128,"ts_in_delta":903,"sequence":86357,"symbol":"FCEU SI 20260615 PS"}
{"ts_recv":"2026-04-07T00:08:38.021582863Z","hd":{"ts_event":"2026-04-07T00:08:38.021566399Z","rtype":160,"publisher_id":101,"instrument_id":436},"action":"A","side":"B","price":"1.157500000","size":20,"channel_id":23,"order_id":"10998892554876348297","flags":128,"ts_in_delta":852,"sequence":86417,"symbol":"FCEU SI 20260615 PS"}
{"ts_recv":"2026-04-07T00:08:38.021604758Z","hd":{"ts_event":"2026-04-07T00:08:38.021593163Z","rtype":160,"publisher_id":101,"instrument_id":436},"action":"C","side":"B","price":"1.157400000","size":20,"channel_id":23,"order_id":"10998892497043495045","flags":128,"ts_in_delta":1047,"sequence":86418,"symbol":"FCEU SI 20260615 PS"}
{"ts_recv":"2026-04-07T00:08:44.224945281Z","hd":{"ts_event":"2026-04-07T00:08:44.224923701Z","rtype":160,"publisher_id":101,"instrument_id":436},"action":"C","side":"B","price":"1.157500000","size":20,"channel_id":23,"order_id":"10998892554876348297","flags":128,"ts_in_delta":1388,"sequence":86486,"symbol":"FCEU SI 20260615 PS"}
{"ts_recv":"2026-04-07T00:08:44.295952648Z","hd":{"ts_event":"2026-04-07T00:08:44.295931463Z","rtype":160,"publisher_id":101,"instrument_id":436},"action":"A","side":"B","price":"1.157500000","size":20,"channel_id":23,"order_id":"10998892561150718260","flags":128,"ts_in_delta":872,"sequence":86487,"symbol":"FCEU SI 20260615 PS"}
{"ts_recv":"2026-04-07T00:09:15.129257821Z","hd":{"ts_event":"2026-04-07T00:09:15.129244259Z","rtype":160,"publisher_id":101,"instrument_id":436},"action":"C","side":"B","price":"1.157500000","size":20,"channel_id":23,"order_id":"10998892561150718260","flags":128,"ts_in_delta":866,"sequence":86665,"symbol":"FCEU SI 20260615 PS"}
{"ts_recv":"2026-04-07T00:09:15.171733249Z","hd":{"ts_event":"2026-04-07T00:09:15.171716827Z","rtype":160,"publisher_id":101,"instrument_id":436},"action":"A","side":"B","price":"1.157400000","size":20,"channel_id":23,"order_id":"10998892592026499149","flags":128,"ts_in_delta":879,"sequence":86672,"symbol":"FCEU SI 20260615 PS"}
{"ts_recv":"2026-04-07T00:09:18.714879426Z","hd":{"ts_event":"2026-04-07T00:09:18.714863997Z","rtype":160,"publisher_id":101,"instrument_id":436},"action":"A","side":"B","price":"1.157500000","size":20,"channel_id":23,"order_id":"10998892595569645634","flags":128,"ts_in_delta":1061,"sequence":86708,"symbol":"FCEU SI 20260615 PS"}
{"ts_recv":"2026-04-07T00:09:18.714910467Z","hd":{"ts_event":"2026-04-07T00:09:18.714897743Z","rtype":160,"publisher_id":101,"instrument_id":436},"action":"C","side":"B","price":"1.157400000","size":20,"channel_id":23,"order_id":"10998892592026499149","flags":128,"ts_in_delta":1264,"sequence":86709,"symbol":"FCEU SI 20260615 PS"}
{"ts_recv":"2026-04-07T00:09:48.794116650Z","hd":{"ts_event":"2026-04-07T00:09:48.794101217Z","rtype":160,"publisher_id":101,"instrument_id":436},"action":"C","side":"A","price":"1.157900000","size":20,"channel_id":23,"order_id":"1775520510715722923","flags":128,"ts_in_delta":650,"sequence":86958,"symbol":"FCEU SI 20260615 PS"}
{"ts_recv":"2026-04-07T00:09:48.837174968Z","hd":{"ts_event":"2026-04-07T00:09:48.837158015Z","rtype":160,"publisher_id":101,"instrument_id":436},"action":"A","side":"A","price":"1.158000000","size":20,"channel_id":23,"order_id":"1775520588837164213","flags":128,"ts_in_delta":927,"sequence":86963,"symbol":"FCEU SI 20260615 PS"}
{"ts_recv":"2026-04-07T00:09:48.847190588Z","hd":{"ts_event":"2026-04-07T00:09:48.847175031Z","rtype":160,"publisher_id":101,"instrument_id":436},"action":"A","side":"B","price":"1.157600000","size":20,"channel_id":23,"order_id":"10998892625701956824","flags":128,"ts_in_delta":943,"sequence":86967,"symbol":"FCEU SI 20260615 PS"}
{"ts_recv":"2026-04-07T00:09:48.847228480Z","hd":{"ts_event":"2026-04-07T00:09:48.847215811Z","rtype":160,"publisher_id":101,"instrument_id":436},"action":"C","side":"B","price":"1.157500000","size":20,"channel_id":23,"order_id":"10998892595569645634","flags":128,"ts_in_delta":916,"sequence":86968,"symbol":"FCEU SI 20260615 PS"}
{"ts_recv":"2026-04-07T00:10:00.350857581Z","hd":{"ts_event":"2026-04-07T00:10:00.350844025Z","rtype":160,"publisher_id":101,"instrument_id":436},"action":"C","side":"B","price":"1.157600000","size":20,"channel_id":23,"order_id":"10998892625701956824","flags":128,"ts_in_delta":863,"sequence":87039,"symbol":"FCEU SI 20260615 PS"}
{"ts_recv":"2026-04-07T00:10:00.400624112Z","hd":{"ts_event":"2026-04-07T00:10:00.400610211Z","rtype":160,"publisher_id":101,"instrument_id":436},"action":"A","side":"B","price":"1.157600000","size":20,"channel_id":23,"order_id":"10998892637255392061","flags":128,"ts_in_delta":869,"sequence":87041,"symbol":"FCEU SI 20260615 PS"}
{"ts_recv":"2026-04-07T00:10:08.288968411Z","hd":{"ts_event":"2026-04-07T00:10:08.288954165Z","rtype":160,"publisher_id":101,"instrument_id":436},"action":"C","side":"B","price":"1.157600000","size":20,"channel_id":23,"order_id":"10998892637255392061","flags":128,"ts_in_delta":863,"sequence":87077,"symbol":"FCEU SI 20260615 PS"}
{"ts_recv":"2026-04-07T00:10:08.331605285Z","hd":{"ts_event":"2026-04-07T00:10:08.331589353Z","rtype":160,"publisher_id":101,"instrument_id":436},"action":"A","side":"B","price":"1.157500000","size":20,"channel_id":23,"order_id":"10998892645186371613","flags":128,"ts_in_delta":1009,"sequence":87080,"symbol":"FCEU SI 20260615 PS"}
{"ts_recv":"2026-04-07T00:10:08.564389468Z","hd":{"ts_event":"2026-04-07T00:10:08.564372429Z","rtype":160,"publisher_id":101,"instrument_id":436},"action":"A","side":"A","price":"1.157900000","size":20,"channel_id":23,"order_id":"1775520608564378726","flags":128,"ts_in_delta":1007,"sequence":87100,"symbol":"FCEU SI 20260615 PS"}
{"ts_recv":"2026-04-07T00:10:08.564407116Z","hd":{"ts_event":"2026-04-07T00:10:08.564393721Z","rtype":160,"publisher_id":101,"instrument_id":436},"action":"C","side":"A","price":"1.158000000","size":20,"channel_id":23,"order_id":"1775520588837164213","flags":128,"ts_in_delta":871,"sequence":87101,"symbol":"FCEU SI 20260615 PS"}
{"ts_recv":"2026-04-07T00:10:14.613276139Z","hd":{"ts_event":"2026-04-07T00:10:14.613253629Z","rtype":160,"publisher_id":101,"instrument_id":436},"action":"C","side":"B","price":"1.157500000","size":20,"channel_id":23,"order_id":"10998892645186371613","flags":128,"ts_in_delta":1300,"sequence":87170,"symbol":"FCEU SI 20260615 PS"}
{"ts_recv":"2026-04-07T00:10:14.656527471Z","hd":{"ts_event":"2026-04-07T00:10:14.656505801Z","rtype":160,"publisher_id":101,"instrument_id":436},"action":"A","side":"B","price":"1.157400000","size":20,"channel_id":23,"order_id":"10998892651511292244","flags":128,"ts_in_delta":1296,"sequence":87171,"symbol":"FCEU SI 20260615 PS"}
{"ts_recv":"2026-04-07T00:10:15.024457765Z","hd":{"ts_event":"2026-04-07T00:10:15.024430983Z","rtype":160,"publisher_id":101,"instrument_id":436},"action":"A","side":"B","price":"1.157500000","size":20,"channel_id":23,"order_id":"10998892651879221118","flags":128,"ts_in_delta":1300,"sequence":87174,"symbol":"FCEU SI 20260615 PS"}
{"ts_recv":"2026-04-07T00:10:15.024559821Z","hd":{"ts_event":"2026-04-07T00:10:15.024548257Z","rtype":160,"publisher_id":101,"instrument_id":436},"action":"C","side":"B","price":"1.157400000","size":20,"channel_id":23,"order_id":"10998892651511292244","flags":128,"ts_in_delta":901,"sequence":87175,"symbol":"FCEU SI 20260615 PS"}
{"ts_recv":"2026-04-07T00:10:20.713181639Z","hd":{"ts_event":"2026-04-07T00:10:20.713168375Z","rtype":160,"publisher_id":101,"instrument_id":436},"action":"C","side":"A","price":"1.157900000","size":20,"channel_id":23,"order_id":"1775520608564378726","flags":128,"ts_in_delta":1062,"sequence":87239,"symbol":"FCEU SI 20260615 PS"}
{"ts_recv":"2026-04-07T00:10:20.756630978Z","hd":{"ts_event":"2026-04-07T00:10:20.756615525Z","rtype":160,"publisher_id":101,"instrument_id":436},"action":"A","side":"A","price":"1.158000000","size":20,"channel_id":23,"order_id":"1775520620756621574","flags":128,"ts_in_delta":716,"sequence":87246,"symbol":"FCEU SI 20260615 PS"}
{"ts_recv":"2026-04-07T00:10:21.192320323Z","hd":{"ts_event":"2026-04-07T00:10:21.192301383Z","rtype":160,"publisher_id":101,"instrument_id":436},"action":"A","side":"B","price":"1.157600000","size":20,"channel_id":23,"order_id":"10998892658047088148","flags":128,"ts_in_delta":785,"sequence":87271,"symbol":"FCEU SI 20260615 PS"}
{"ts_recv":"2026-04-07T00:10:21.192327772Z","hd":{"ts_event":"2026-04-07T00:10:21.192315169Z","rtype":160,"publisher_id":101,"instrument_id":436},"action":"C","side":"B","price":"1.157500000","size":20,"channel_id":23,"order_id":"10998892651879221118","flags":128,"ts_in_delta":1035,"sequence":87272,"symbol":"FCEU SI 20260615 PS"}
{"ts_recv":"2026-04-07T00:10:30.463455294Z","hd":{"ts_event":"2026-04-07T00:10:30.463442463Z","rtype":160,"publisher_id":101,"instrument_id":436},"action":"C","side":"B","price":"1.157600000","size":20,"channel_id":23,"order_id":"10998892658047088148","flags":128,"ts_in_delta":861,"sequence":87360,"symbol":"FCEU SI 20260615 PS"}
{"ts_recv":"2026-04-07T00:10:30.507154214Z","hd":{"ts_event":"2026-04-07T00:10:30.507140891Z","rtype":160,"publisher_id":101,"instrument_id":436},"action":"A","side":"B","price":"1.157500000","size":20,"channel_id":23,"order_id":"10998892667361922785","flags":128,"ts_in_delta":654,"sequence":87364,"symbol":"FCEU SI 20260615 PS"}
{"ts_recv":"2026-04-07T00:10:35.506813607Z","hd":{"ts_event":"2026-04-07T00:10:35.506797059Z","rtype":160,"publisher_id":101,"instrument_id":436},"action":"A","side":"A","price":"1.157900000","size":20,"channel_id":23,"order_id":"1775520635506803077","flags":128,"ts_in_delta":1072,"sequence":87402,"symbol":"FCEU SI 20260615 PS"}
{"ts_recv":"2026-04-07T00:10:35.506949483Z","hd":{"ts_event":"2026-04-07T00:10:35.506937763Z","rtype":160,"publisher_id":101,"instrument_id":436},"action":"C","side":"A","price":"1.158000000","size":20,"channel_id":23,"order_id":"1775520620756621574","flags":128,"ts_in_delta":1196,"sequence":87403,"symbol":"FCEU SI 20260615 PS"}
{"ts_recv":"2026-04-07T00:10:38.879795997Z","hd":{"ts_event":"2026-04-07T00:10:38.879780523Z","rtype":160,"publisher_id":101,"instrument_id":436},"action":"A","side":"B","price":"1.157600000","size":20,"channel_id":23,"order_id":"10998892675734562237","flags":128,"ts_in_delta":849,"sequence":87445,"symbol":"FCEU SI 20260615 PS"}
{"ts_recv":"2026-04-07T00:10:38.879964780Z","hd":{"ts_event":"2026-04-07T00:10:38.879952379Z","rtype":160,"publisher_id":101,"instrument_id":436},"action":"C","side":"B","price":"1.157500000","size":20,"channel_id":23,"order_id":"10998892667361922785","flags":128,"ts_in_delta":851,"sequence":87447,"symbol":"FCEU SI 20260615 PS"}
{"ts_recv":"2026-04-07T00:10:39.001856294Z","hd":{"ts_event":"2026-04-07T00:10:39.001834895Z","rtype":160,"publisher_id":101,"instrument_id":436},"action":"C","side":"A","price":"1.157900000","size":20,"channel_id":23,"order_id":"1775520635506803077","flags":128,"ts_in_delta":1216,"sequence":87459,"symbol":"FCEU SI 20260615 PS"}
{"ts_recv":"2026-04-07T00:10:39.044939597Z","hd":{"ts_event":"2026-04-07T00:10:39.044924897Z","rtype":160,"publisher_id":101,"instrument_id":436},"action":"A","side":"A","price":"1.158100000","size":20,"channel_id":23,"order_id":"1775520639044930967","flags":128,"ts_in_delta":838,"sequence":87465,"symbol":"FCEU SI 20260615 PS"}
{"ts_recv":"2026-04-07T00:10:39.140518658Z","hd":{"ts_event":"2026-04-07T00:10:39.140505415Z","rtype":160,"publisher_id":101,"instrument_id":436},"action":"A","side":"A","price":"1.158000000","size":20,"channel_id":23,"order_id":"1775520639140511363","flags":128,"ts_in_delta":1168,"sequence":87474,"symbol":"FCEU SI 20260615 PS"}
{"ts_recv":"2026-04-07T00:10:39.140640949Z","hd":{"ts_event":"2026-04-07T00:10:39.140627917Z","rtype":160,"publisher_id":101,"instrument_id":436},"action":"C","side":"A","price":"1.158100000","size":20,"channel_id":23,"order_id":"1775520639044930967","flags":128,"ts_in_delta":978,"sequence":87476,"symbol":"FCEU SI 20260615 PS"}
{"ts_recv":"2026-04-07T00:10:50.670792885Z","hd":{"ts_event":"2026-04-07T00:10:50.670779279Z","rtype":160,"publisher_id":101,"instrument_id":436},"action":"C","side":"B","price":"1.157600000","size":20,"channel_id":23,"order_id":"10998892675734562237","flags":128,"ts_in_delta":1042,"sequence":87584,"symbol":"FCEU SI 20260615 PS"}
{"ts_recv":"2026-04-07T00:10:50.738629629Z","hd":{"ts_event":"2026-04-07T00:10:50.738615319Z","rtype":160,"publisher_id":101,"instrument_id":436},"action":"A","side":"B","price":"1.157600000","size":20,"channel_id":23,"order_id":"10998892687593397046","flags":128,"ts_in_delta":966,"sequence":87599,"symbol":"FCEU SI 20260615 PS"}
{"ts_recv":"2026-04-07T00:10:57.120254307Z","hd":{"ts_event":"2026-04-07T00:10:57.120241259Z","rtype":160,"publisher_id":101,"instrument_id":436},"action":"C","side":"B","price":"1.157600000","size":20,"channel_id":23,"order_id":"10998892687593397046","flags":128,"ts_in_delta":771,"sequence":87702,"symbol":"FCEU SI 20260615 PS"}
{"ts_recv":"2026-04-07T00:10:57.187209597Z","hd":{"ts_event":"2026-04-07T00:10:57.187195131Z","rtype":160,"publisher_id":101,"instrument_id":436},"action":"A","side":"B","price":"1.157600000","size":20,"channel_id":23,"order_id":"10998892694041976879","flags":128,"ts_in_delta":854,"sequence":87711,"symbol":"FCEU SI 20260615 PS"}
{"ts_recv":"2026-04-07T00:11:40.110226547Z","hd":{"ts_event":"2026-04-07T00:11:40.110212583Z","rtype":160,"publisher_id":101,"instrument_id":436},"action":"C","side":"B","price":"1.157600000","size":20,"channel_id":23,"order_id":"10998892694041976879","flags":128,"ts_in_delta":834,"sequence":88305,"symbol":"FCEU SI 20260615 PS"}
{"ts_recv":"2026-04-07T00:11:40.194826008Z","hd":{"ts_event":"2026-04-07T00:11:40.194809545Z","rtype":160,"publisher_id":101,"instrument_id":436},"action":"A","side":"B","price":"1.157600000","size":20,"channel_id":23,"order_id":"10998892737049591384","flags":128,"ts_in_delta":1003,"sequence":88317,"symbol":"FCEU SI 20260615 PS"}
{"ts_recv":"2026-04-07T00:11:45.194347894Z","hd":{"ts_event":"2026-04-07T00:11:45.194335263Z","rtype":160,"publisher_id":101,"instrument_id":436},"action":"C","side":"B","price":"1.157600000","size":20,"channel_id":23,"order_id":"10998892737049591384","flags":128,"ts_in_delta":1076,"sequence":88382,"symbol":"FCEU SI 20260615 PS"}
{"ts_recv":"2026-04-07T00:11:45.236939945Z","hd":{"ts_event":"2026-04-07T00:11:45.236919079Z","rtype":160,"publisher_id":101,"instrument_id":436},"action":"A","side":"B","price":"1.157500000","size":20,"channel_id":23,"order_id":"10998892742091705984","flags":128,"ts_in_delta":1293,"sequence":88383,"symbol":"FCEU SI 20260615 PS"}
{"ts_recv":"2026-04-07T00:11:54.205897339Z","hd":{"ts_event":"2026-04-07T00:11:54.205880705Z","rtype":160,"publisher_id":101,"instrument_id":436},"action":"A","side":"A","price":"1.157900000","size":20,"channel_id":23,"order_id":"1775520714205886764","flags":128,"ts_in_delta":862,"sequence":88433,"symbol":"FCEU SI 20260615 PS"}
{"ts_recv":"2026-04-07T00:11:54.206029958Z","hd":{"ts_event":"2026-04-07T00:11:54.206016437Z","rtype":160,"publisher_id":101,"instrument_id":436},"action":"C","side":"A","price":"1.158000000","size":20,"channel_id":23,"order_id":"1775520639140511363","flags":128,"ts_in_delta":868,"sequence":88434,"symbol":"FCEU SI 20260615 PS"}
{"ts_recv":"2026-04-07T00:12:12.025978109Z","hd":{"ts_event":"2026-04-07T00:12:12.025963899Z","rtype":160,"publisher_id":101,"instrument_id":436},"action":"C","side":"B","price":"1.157500000","size":20,"channel_id":23,"order_id":"10998892742091705984","flags":128,"ts_in_delta":881,"sequence":88600,"symbol":"FCEU SI 20260615 PS"}
{"ts_recv":"2026-04-07T00:12:12.094506533Z","hd":{"ts_event":"2026-04-07T00:12:12.094489389Z","rtype":160,"publisher_id":101,"instrument_id":436},"action":"A","side":"B","price":"1.157400000","size":20,"channel_id":23,"order_id":"10998892768949271458","flags":128,"ts_in_delta":995,"sequence":88605,"symbol":"FCEU SI 20260615 PS"}
{"ts_recv":"2026-04-07T00:12:17.489179045Z","hd":{"ts_event":"2026-04-07T00:12:17.489164267Z","rtype":160,"publisher_id":101,"instrument_id":436},"action":"A","side":"B","price":"1.157500000","size":20,"channel_id":23,"order_id":"10998892774343946055","flags":128,"ts_in_delta":793,"sequence":88680,"symbol":"FCEU SI 20260615 PS"}
{"ts_recv":"2026-04-07T00:12:17.489200458Z","hd":{"ts_event":"2026-04-07T00:12:17.489186251Z","rtype":160,"publisher_id":101,"instrument_id":436},"action":"C","side":"B","price":"1.157400000","size":20,"channel_id":23,"order_id":"10998892768949271458","flags":128,"ts_in_delta":1623,"sequence":88681,"symbol":"FCEU SI 20260615 PS"}
{"ts_recv":"2026-04-07T00:12:25.617236761Z","hd":{"ts_event":"2026-04-07T00:12:25.617222175Z","rtype":160,"publisher_id":101,"instrument_id":436},"action":"C","side":"B","price":"1.157500000","size":20,"channel_id":23,"order_id":"10998892774343946055","flags":128,"ts_in_delta":842,"sequence":88776,"symbol":"FCEU SI 20260615 PS"}
{"ts_recv":"2026-04-07T00:12:25.701490806Z","hd":{"ts_event":"2026-04-07T00:12:25.701475739Z","rtype":160,"publisher_id":101,"instrument_id":436},"action":"A","side":"B","price":"1.157500000","size":20,"channel_id":23,"order_id":"10998892782556257686","flags":128,"ts_in_delta":955,"sequence":88781,"symbol":"FCEU SI 20260615 PS"}
{"ts_recv":"2026-04-07T00:12:49.560144086Z","hd":{"ts_event":"2026-04-07T00:12:49.560129789Z","rtype":160,"publisher_id":101,"instrument_id":436},"action":"C","side":"A","price":"1.157900000","size":20,"channel_id":23,"order_id":"1775520714205886764","flags":128,"ts_in_delta":1028,"sequence":88991,"symbol":"FCEU SI 20260615 PS"}
{"ts_recv":"2026-04-07T00:12:49.603658093Z","hd":{"ts_event":"2026-04-07T00:12:49.603642213Z","rtype":160,"publisher_id":101,"instrument_id":436},"action":"A","side":"A","price":"1.158000000","size":20,"channel_id":23,"order_id":"1775520769603647875","flags":128,"ts_in_delta":829,"sequence":89000,"symbol":"FCEU SI 20260615 PS"}
{"ts_recv":"2026-04-07T00:12:49.604603135Z","hd":{"ts_event":"2026-04-07T00:12:49.604588049Z","rtype":160,"publisher_id":101,"instrument_id":436},"action":"A","side":"B","price":"1.157600000","size":20,"channel_id":23,"order_id":"10998892806459370051","flags":128,"ts_in_delta":833,"sequence":89001,"symbol":"FCEU SI 20260615 PS"}
{"ts_recv":"2026-04-07T00:12:49.604620745Z","hd":{"ts_event":"2026-04-07T00:12:49.604608557Z","rtype":160,"publisher_id":101,"instrument_id":436},"action":"C","side":"B","price":"1.157500000","size":20,"channel_id":23,"order_id":"10998892782556257686","flags":128,"ts_in_delta":846,"sequence":89002,"symbol":"FCEU SI 20260615 PS"}
{"ts_recv":"2026-04-07T00:13:59.606360732Z","hd":{"ts_event":"2026-04-07T00:13:59.606345163Z","rtype":160,"publisher_id":101,"instrument_id":436},"action":"C","side":"A","price":"1.158000000","size":20,"channel_id":23,"order_id":"1775520769603647875","flags":128,"ts_in_delta":809,"sequence":89770,"symbol":"FCEU SI 20260615 PS"}
{"ts_recv":"2026-04-07T00:13:59.649722602Z","hd":{"ts_event":"2026-04-07T00:13:59.649704357Z","rtype":160,"publisher_id":101,"instrument_id":436},"action":"A","side":"A","price":"1.158100000","size":20,"channel_id":23,"order_id":"1775520839649710795","flags":128,"ts_in_delta":806,"sequence":89773,"symbol":"FCEU SI 20260615 PS"}
{"ts_recv":"2026-04-07T00:13:59.689317674Z","hd":{"ts_event":"2026-04-07T00:13:59.689301947Z","rtype":160,"publisher_id":101,"instrument_id":436},"action":"A","side":"B","price":"1.157700000","size":20,"channel_id":23,"order_id":"10998892876544083484","flags":128,"ts_in_delta":630,"sequence":89779,"symbol":"FCEU SI 20260615 PS"}
{"ts_recv":"2026-04-07T00:13:59.689342248Z","hd":{"ts_event":"2026-04-07T00:13:59.689329345Z","rtype":160,"publisher_id":101,"instrument_id":436},"action":"C","side":"B","price":"1.157600000","size":20,"channel_id":23,"order_id":"10998892806459370051","flags":128,"ts_in_delta":653,"sequence":89780,"symbol":"FCEU SI 20260615 PS"}
{"ts_recv":"2026-04-07T00:14:07.509392433Z","hd":{"ts_event":"2026-04-07T00:14:07.509378773Z","rtype":160,"publisher_id":101,"instrument_id":436},"action":"C","side":"B","price":"1.157700000","size":20,"channel_id":23,"order_id":"10998892876544083484","flags":128,"ts_in_delta":885,"sequence":89867,"symbol":"FCEU SI 20260615 PS"}
{"ts_recv":"2026-04-07T00:14:07.552537708Z","hd":{"ts_event":"2026-04-07T00:14:07.552522309Z","rtype":160,"publisher_id":101,"instrument_id":436},"action":"A","side":"B","price":"1.157600000","size":20,"channel_id":23,"order_id":"10998892884407304258","flags":128,"ts_in_delta":893,"sequence":89875,"symbol":"FCEU SI 20260615 PS"}
{"ts_recv":"2026-04-07T00:14:08.663537811Z","hd":{"ts_event":"2026-04-07T00:14:08.663518511Z","rtype":160,"publisher_id":101,"instrument_id":436},"action":"A","side":"B","price":"1.157700000","size":20,"channel_id":23,"order_id":"10998892885518303461","flags":128,"ts_in_delta":1334,"sequence":89886,"symbol":"FCEU SI 20260615 PS"}
{"ts_recv":"2026-04-07T00:14:08.663543655Z","hd":{"ts_event":"2026-04-07T00:14:08.663528373Z","rtype":160,"publisher_id":101,"instrument_id":436},"action":"C","side":"B","price":"1.157600000","size":20,"channel_id":23,"order_id":"10998892884407304258","flags":128,"ts_in_delta":741,"sequence":89887,"symbol":"FCEU SI 20260615 PS"}
{"ts_recv":"2026-04-07T00:14:15.389135157Z","hd":{"ts_event":"2026-04-07T00:14:15.389121719Z","rtype":160,"publisher_id":101,"instrument_id":436},"action":"C","side":"B","price":"1.157700000","size":20,"channel_id":23,"order_id":"10998892885518303461","flags":128,"ts_in_delta":974,"sequence":89971,"symbol":"FCEU SI 20260615 PS"}
{"ts_recv":"2026-04-07T00:14:15.432747035Z","hd":{"ts_event":"2026-04-07T00:14:15.432724581Z","rtype":160,"publisher_id":101,"instrument_id":436},"action":"A","side":"B","price":"1.157600000","size":20,"channel_id":23,"order_id":"10998892892287511175","flags":128,"ts_in_delta":1406,"sequence":89976,"symbol":"FCEU SI 20260615 PS"}
{"ts_recv":"2026-04-07T00:14:17.939523520Z","hd":{"ts_event":"2026-04-07T00:14:17.939509991Z","rtype":160,"publisher_id":101,"instrument_id":436},"action":"A","side":"B","price":"1.157700000","size":20,"channel_id":23,"order_id":"10998892894794291647","flags":128,"ts_in_delta":806,"sequence":90008,"symbol":"FCEU SI 20260615 PS"}
{"ts_recv":"2026-04-07T00:14:17.939710181Z","hd":{"ts_event":"2026-04-07T00:14:17.939697511Z","rtype":160,"publisher_id":101,"instrument_id":436},"action":"C","side":"B","price":"1.157600000","size":20,"channel_id":23,"order_id":"10998892892287511175","flags":128,"ts_in_delta":802,"sequence":90010,"symbol":"FCEU SI 20260615 PS"}
{"ts_recv":"2026-04-07T00:14:22.939428440Z","hd":{"ts_event":"2026-04-07T00:14:22.939415555Z","rtype":160,"publisher_id":101,"instrument_id":436},"action":"C","side":"B","price":"1.157700000","size":20,"channel_id":23,"order_id":"10998892894794291647","flags":128,"ts_in_delta":967,"sequence":90086,"symbol":"FCEU SI 20260615 PS"}
{"ts_recv":"2026-04-07T00:14:22.982061098Z","hd":{"ts_event":"2026-04-07T00:14:22.982046327Z","rtype":160,"publisher_id":101,"instrument_id":436},"action":"A","side":"B","price":"1.157600000","size":20,"channel_id":23,"order_id":"10998892899836828050","flags":128,"ts_in_delta":928,"sequence":90088,"symbol":"FCEU SI 20260615 PS"}
{"ts_recv":"2026-04-07T00:14:27.202128120Z","hd":{"ts_event":"2026-04-07T00:14:27.202112543Z","rtype":160,"publisher_id":101,"instrument_id":436},"action":"A","side":"B","price":"1.157700000","size":20,"channel_id":23,"order_id":"10998892904056894523","flags":128,"ts_in_delta":897,"sequence":90116,"symbol":"FCEU SI 20260615 PS"}
{"ts_recv":"2026-04-07T00:14:27.202173906Z","hd":{"ts_event":"2026-04-07T00:14:27.202162963Z","rtype":160,"publisher_id":101,"instrument_id":436},"action":"C","side":"B","price":"1.157600000","size":20,"channel_id":23,"order_id":"10998892899836828050","flags":128,"ts_in_delta":867,"sequence":90117,"symbol":"FCEU SI 20260615 PS"}
{"ts_recv":"2026-04-07T00:14:53.128559608Z","hd":{"ts_event":"2026-04-07T00:14:53.128545381Z","rtype":160,"publisher_id":101,"instrument_id":436},"action":"C","side":"B","price":"1.157700000","size":20,"channel_id":23,"order_id":"10998892904056894523","flags":128,"ts_in_delta":827,"sequence":90372,"symbol":"FCEU SI 20260615 PS"}
{"ts_recv":"2026-04-07T00:14:53.176865559Z","hd":{"ts_event":"2026-04-07T00:14:53.176852085Z","rtype":160,"publisher_id":101,"instrument_id":436},"action":"A","side":"B","price":"1.157700000","size":20,"channel_id":23,"order_id":"10998892930031634026","flags":128,"ts_in_delta":812,"sequence":90383,"symbol":"FCEU SI 20260615 PS"}
{"ts_recv":"2026-04-07T00:15:08.333011987Z","hd":{"ts_event":"2026-04-07T00:15:08.332987539Z","rtype":160,"publisher_id":101,"instrument_id":436},"action":"C","side":"A","price":"1.158100000","size":20,"channel_id":23,"order_id":"1775520839649710795","flags":128,"ts_in_delta":1162,"sequence":90574,"symbol":"FCEU SI 20260615 PS"}
{"ts_recv":"2026-04-07T00:15:08.375623878Z","hd":{"ts_event":"2026-04-07T00:15:08.375600333Z","rtype":160,"publisher_id":101,"instrument_id":436},"action":"A","side":"A","price":"1.158200000","size":20,"channel_id":23,"order_id":"1775520908375611848","flags":128,"ts_in_delta":1144,"sequence":90575,"symbol":"FCEU SI 20260615 PS"}
{"ts_recv":"2026-04-07T00:15:15.506495603Z","hd":{"ts_event":"2026-04-07T00:15:15.506481151Z","rtype":160,"publisher_id":101,"instrument_id":436},"action":"A","side":"B","price":"1.157800000","size":20,"channel_id":23,"order_id":"10998892952361262855","flags":128,"ts_in_delta":768,"sequence":90631,"symbol":"FCEU SI 20260615 PS"}
{"ts_recv":"2026-04-07T00:15:15.506593733Z","hd":{"ts_event":"2026-04-07T00:15:15.506579905Z","rtype":160,"publisher_id":101,"instrument_id":436},"action":"C","side":"B","price":"1.157700000","size":20,"channel_id":23,"order_id":"10998892930031634026","flags":128,"ts_in_delta":847,"sequence":90633,"symbol":"FCEU SI 20260615 PS"}
{"ts_recv":"2026-04-07T00:15:26.928347546Z","hd":{"ts_event":"2026-04-07T00:15:26.928323367Z","rtype":160,"publisher_id":101,"instrument_id":436},"action":"C","side":"A","price":"1.158200000","size":20,"channel_id":23,"order_id":"1775520908375611848","flags":128,"ts_in_delta":1600,"sequence":90825,"symbol":"FCEU SI 20260615 PS"}
{"ts_recv":"2026-04-07T00:15:26.971131936Z","hd":{"ts_event":"2026-04-07T00:15:26.971114025Z","rtype":160,"publisher_id":101,"instrument_id":436},"action":"A","side":"A","price":"1.158300000","size":20,"channel_id":23,"order_id":"1775520926971120263","flags":128,"ts_in_delta":894,"sequence":90828,"symbol":"FCEU SI 20260615 PS"}
{"ts_recv":"2026-04-07T00:15:30.703135826Z","hd":{"ts_event":"2026-04-07T00:15:30.703120141Z","rtype":160,"publisher_id":101,"instrument_id":436},"action":"A","side":"A","price":"1.158200000","size":20,"channel_id":23,"order_id":"1775520930703126459","flags":128,"ts_in_delta":866,"sequence":90890,"symbol":"FCEU SI 20260615 PS"}
{"ts_recv":"2026-04-07T00:15:30.703187494Z","hd":{"ts_event":"2026-04-07T00:15:30.703174925Z","rtype":160,"publisher_id":101,"instrument_id":436},"action":"C","side":"A","price":"1.158300000","size":20,"channel_id":23,"order_id":"1775520926971120263","flags":128,"ts_in_delta":874,"sequence":90893,"symbol":"FCEU SI 20260615 PS"}
{"ts_recv":"2026-04-07T00:15:40.394529532Z","hd":{"ts_event":"2026-04-07T00:15:40.394516073Z","rtype":160,"publisher_id":101,"instrument_id":436},"action":"C","side":"A","price":"1.158200000","size":20,"channel_id":23,"order_id":"1775520930703126459","flags":128,"ts_in_delta":928,"sequence":90956,"symbol":"FCEU SI 20260615 PS"}
{"ts_recv":"2026-04-07T00:15:40.438818652Z","hd":{"ts_event":"2026-04-07T00:15:40.438801643Z","rtype":160,"publisher_id":101,"instrument_id":436},"action":"A","side":"A","price":"1.158300000","size":20,"channel_id":23,"order_id":"1775520940438807834","flags":128,"ts_in_delta":1015,"sequence":90958,"symbol":"FCEU SI 20260615 PS"}
{"ts_recv":"2026-04-07T00:15:43.530442050Z","hd":{"ts_event":"2026-04-07T00:15:43.530419025Z","rtype":160,"publisher_id":101,"instrument_id":436},"action":"A","side":"B","price":"1.157900000","size":20,"channel_id":23,"order_id":"10998892980385206029","flags":128,"ts_in_delta":680,"sequence":91010,"symbol":"FCEU SI 20260615 PS"}
{"ts_recv":"2026-04-07T00:15:43.530750733Z","hd":{"ts_event":"2026-04-07T00:15:43.530737485Z","rtype":160,"publisher_id":101,"instrument_id":436},"action":"C","side":"B","price":"1.157800000","size":20,"channel_id":23,"order_id":"10998892952361262855","flags":128,"ts_in_delta":602,"sequence":91011,"symbol":"FCEU SI 20260615 PS"}
{"ts_recv":"2026-04-07T00:15:48.530356741Z","hd":{"ts_event":"2026-04-07T00:15:48.530344217Z","rtype":160,"publisher_id":101,"instrument_id":436},"action":"C","side":"B","price":"1.157900000","size":20,"channel_id":23,"order_id":"10998892980385206029","flags":128,"ts_in_delta":782,"sequence":91099,"symbol":"FCEU SI 20260615 PS"}
{"ts_recv":"2026-04-07T00:15:48.573580426Z","hd":{"ts_event":"2026-04-07T00:15:48.573567037Z","rtype":160,"publisher_id":101,"instrument_id":436},"action":"A","side":"B","price":"1.157800000","size":20,"channel_id":23,"order_id":"10998892985428348830","flags":128,"ts_in_delta":800,"sequence":91101,"symbol":"FCEU SI 20260615 PS"}
{"ts_recv":"2026-04-07T00:15:58.640191925Z","hd":{"ts_event":"2026-04-07T00:15:58.640169639Z","rtype":160,"publisher_id":101,"instrument_id":436},"action":"A","side":"A","price":"1.158200000","size":20,"channel_id":23,"order_id":"1775520958640180594","flags":128,"ts_in_delta":820,"sequence":91201,"symbol":"FCEU SI 20260615 PS"}
{"ts_recv":"2026-04-07T00:15:58.640225462Z","hd":{"ts_event":"2026-04-07T00:15:58.640212297Z","rtype":160,"publisher_id":101,"instrument_id":436},"action":"C","side":"A","price":"1.158300000","size":20,"channel_id":23,"order_id":"1775520940438807834","flags":128,"ts_in_delta":841,"sequence":91203,"symbol":"FCEU SI 20260615 PS"}
{"ts_recv":"2026-04-07T00:16:04.125754428Z","hd":{"ts_event":"2026-04-07T00:16:04.125741209Z","rtype":160,"publisher_id":101,"instrument_id":436},"action":"C","side":"B","price":"1.157800000","size":20,"channel_id":23,"order_id":"10998892985428348830","flags":128,"ts_in_delta":907,"sequence":91296,"symbol":"FCEU SI 20260615 PS"}
{"ts_recv":"2026-04-07T00:16:04.168486204Z","hd":{"ts_event":"2026-04-07T00:16:04.168471673Z","rtype":160,"publisher_id":101,"instrument_id":436},"action":"A","side":"B","price":"1.157700000","size":20,"channel_id":23,"order_id":"10998893001023253530","flags":128,"ts_in_delta":844,"sequence":91302,"symbol":"FCEU SI 20260615 PS"}
{"ts_recv":"2026-04-07T00:16:20.161901279Z","hd":{"ts_event":"2026-04-07T00:16:20.161885573Z","rtype":160,"publisher_id":101,"instrument_id":436},"action":"A","side":"B","price":"1.157800000","size":20,"channel_id":23,"order_id":"10998893017016667987","flags":128,"ts_in_delta":994,"sequence":91408,"symbol":"FCEU SI 20260615 PS"}
{"ts_recv":"2026-04-07T00:16:20.161981363Z","hd":{"ts_event":"2026-04-07T00:16:20.161967783Z","rtype":160,"publisher_id":101,"instrument_id":436},"action":"C","side":"B","price":"1.157700000","size":20,"channel_id":23,"order_id":"10998893001023253530","flags":128,"ts_in_delta":856,"sequence":91409,"symbol":"FCEU SI 20260615 PS"}
{"ts_recv":"2026-04-07T00:16:27.144669151Z","hd":{"ts_event":"2026-04-07T00:16:27.144656541Z","rtype":160,"publisher_id":101,"instrument_id":436},"action":"C","side":"B","price":"1.157800000","size":20,"channel_id":23,"order_id":"10998893017016667987","flags":128,"ts_in_delta":846,"sequence":91447,"symbol":"FCEU SI 20260615 PS"}
{"ts_recv":"2026-04-07T00:16:27.187975548Z","hd":{"ts_event":"2026-04-07T00:16:27.187960663Z","rtype":160,"publisher_id":101,"instrument_id":436},"action":"A","side":"B","price":"1.157700000","size":20,"channel_id":23,"order_id":"10998893024042742847","flags":128,"ts_in_delta":862,"sequence":91451,"symbol":"FCEU SI 20260615 PS"}
{"ts_recv":"2026-04-07T00:16:34.981514908Z","hd":{"ts_event":"2026-04-07T00:16:34.981500327Z","rtype":160,"publisher_id":101,"instrument_id":436},"action":"A","side":"B","price":"1.157800000","size":20,"channel_id":23,"order_id":"10998893031836281959","flags":128,"ts_in_delta":1002,"sequence":91522,"symbol":"FCEU SI 20260615 PS"}
{"ts_recv":"2026-04-07T00:16:34.981601350Z","hd":{"ts_event":"2026-04-07T00:16:34.981588629Z","rtype":160,"publisher_id":101,"instrument_id":436},"action":"C","side":"B","price":"1.157700000","size":20,"channel_id":23,"order_id":"10998893024042742847","flags":128,"ts_in_delta":1041,"sequence":91523,"symbol":"FCEU SI 20260615 PS"}
{"ts_recv":"2026-04-07T00:16:56.511005737Z","hd":{"ts_event":"2026-04-07T00:16:56.510982875Z","rtype":160,"publisher_id":101,"instrument_id":436},"action":"C","side":"A","price":"1.158200000","size":20,"channel_id":23,"order_id":"1775520958640180594","flags":128,"ts_in_delta":1310,"sequence":91771,"symbol":"FCEU SI 20260615 PS"}
{"ts_recv":"2026-04-07T00:16:56.554574561Z","hd":{"ts_event":"2026-04-07T00:16:56.554549821Z","rtype":160,"publisher_id":101,"instrument_id":436},"action":"A","side":"A","price":"1.158300000","size":20,"channel_id":23,"order_id":"1775521016554561634","flags":128,"ts_in_delta":867,"sequence":91772,"symbol":"FCEU SI 20260615 PS"}
{"ts_recv":"2026-04-07T00:17:01.690431337Z","hd":{"ts_event":"2026-04-07T00:17:01.690414731Z","rtype":160,"publisher_id":101,"instrument_id":436},"action":"A","side":"A","price":"1.158200000","size":20,"channel_id":23,"order_id":"1775521021690421445","flags":128,"ts_in_delta":1042,"sequence":91833,"symbol":"FCEU SI 20260615 PS"}
{"ts_recv":"2026-04-07T00:17:01.690462193Z","hd":{"ts_event":"2026-04-07T00:17:01.690448939Z","rtype":160,"publisher_id":101,"instrument_id":436},"action":"C","side":"A","price":"1.158300000","size":20,"channel_id":23,"order_id":"1775521016554561634","flags":128,"ts_in_delta":851,"sequence":91834,"symbol":"FCEU SI 20260615 PS"}
{"ts_recv":"2026-04-07T00:17:30.460110055Z","hd":{"ts_event":"2026-04-07T00:17:30.460087047Z","rtype":160,"publisher_id":101,"instrument_id":436},"action":"C","side":"A","price":"1.158200000","size":20,"channel_id":23,"order_id":"1775521021690421445","flags":128,"ts_in_delta":1184,"sequence":92153,"symbol":"FCEU SI 20260615 PS"}
{"ts_recv":"2026-04-07T00:17:30.502709874Z","hd":{"ts_event":"2026-04-07T00:17:30.502691335Z","rtype":160,"publisher_id":101,"instrument_id":436},"action":"A","side":"A","price":"1.158300000","size":20,"channel_id":23,"order_id":"1775521050502702020","flags":128,"ts_in_delta":865,"sequence":92154,"symbol":"FCEU SI 20260615 PS"}
{"ts_recv":"2026-04-07T00:17:31.181998997Z","hd":{"ts_event":"2026-04-07T00:17:31.181982151Z","rtype":160,"publisher_id":101,"instrument_id":436},"action":"A","side":"B","price":"1.157900000","size":20,"channel_id":23,"order_id":"10998893088036764353","flags":128,"ts_in_delta":828,"sequence":92171,"symbol":"FCEU SI 20260615 PS"}
{"ts_recv":"2026-04-07T00:17:31.182269427Z","hd":{"ts_event":"2026-04-07T00:17:31.182255645Z","rtype":160,"publisher_id":101,"instrument_id":436},"action":"C","side":"B","price":"1.157800000","size":20,"channel_id":23,"order_id":"10998893031836281959","flags":128,"ts_in_delta":854,"sequence":92172,"symbol":"FCEU SI 20260615 PS"}
{"ts_recv":"2026-04-07T00:17:45.618062846Z","hd":{"ts_event":"2026-04-07T00:17:45.618048439Z","rtype":160,"publisher_id":101,"instrument_id":436},"action":"C","side":"B","price":"1.157900000","size":20,"channel_id":23,"order_id":"10998893088036764353","flags":128,"ts_in_delta":920,"sequence":92256,"symbol":"FCEU SI 20260615 PS"}
{"ts_recv":"2026-04-07T00:17:45.661417929Z","hd":{"ts_event":"2026-04-07T00:17:45.661401873Z","rtype":160,"publisher_id":101,"instrument_id":436},"action":"A","side":"B","price":"1.157800000","size":20,"channel_id":23,"order_id":"10998893102516184024","flags":128,"ts_in_delta":994,"sequence":92261,"symbol":"FCEU SI 20260615 PS"}
{"ts_recv":"2026-04-07T00:17:46.131423434Z","hd":{"ts_event":"2026-04-07T00:17:46.131399893Z","rtype":160,"publisher_id":101,"instrument_id":436},"action":"A","side":"A","price":"1.158200000","size":20,"channel_id":23,"order_id":"1775521066131411002","flags":128,"ts_in_delta":827,"sequence":92279,"symbol":"FCEU SI 20260615 PS"}
{"ts_recv":"2026-04-07T00:17:46.131551254Z","hd":{"ts_event":"2026-04-07T00:17:46.131537987Z","rtype":160,"publisher_id":101,"instrument_id":436},"action":"C","side":"A","price":"1.158300000","size":20,"channel_id":23,"order_id":"1775521050502702020","flags":128,"ts_in_delta":853,"sequence":92280,"symbol":"FCEU SI 20260615 PS"}
{"ts_recv":"2026-04-07T00:17:55.154208068Z","hd":{"ts_event":"2026-04-07T00:17:55.154186321Z","rtype":160,"publisher_id":101,"instrument_id":436},"action":"C","side":"B","price":"1.157800000","size":20,"channel_id":23,"order_id":"10998893102516184024","flags":128,"ts_in_delta":1217,"sequence":92359,"symbol":"FCEU SI 20260615 PS"}
{"ts_recv":"2026-04-07T00:17:55.197248385Z","hd":{"ts_event":"2026-04-07T00:17:55.197230773Z","rtype":160,"publisher_id":101,"instrument_id":436},"action":"A","side":"B","price":"1.157700000","size":20,"channel_id":23,"order_id":"10998893112052013486","flags":128,"ts_in_delta":812,"sequence":92361,"symbol":"FCEU SI 20260615 PS"}
{"ts_recv":"2026-04-07T00:17:56.091596781Z","hd":{"ts_event":"2026-04-07T00:17:56.091581801Z","rtype":160,"publisher_id":101,"instrument_id":436},"action":"A","side":"B","price":"1.157800000","size":20,"channel_id":23,"order_id":"10998893112946363617","flags":128,"ts_in_delta":841,"sequence":92382,"symbol":"FCEU SI 20260615 PS"}
{"ts_recv":"2026-04-07T00:17:56.091651053Z","hd":{"ts_event":"2026-04-07T00:17:56.091639183Z","rtype":160,"publisher_id":101,"instrument_id":436},"action":"C","side":"B","price":"1.157700000","size":20,"channel_id":23,"order_id":"10998893112052013486","flags":128,"ts_in_delta":824,"sequence":92383,"symbol":"FCEU SI 20260615 PS"}
{"ts_recv":"2026-04-07T00:18:01.090228236Z","hd":{"ts_event":"2026-04-07T00:18:01.090215145Z","rtype":160,"publisher_id":101,"instrument_id":436},"action":"C","side":"B","price":"1.157800000","size":20,"channel_id":23,"order_id":"10998893112946363617","flags":128,"ts_in_delta":999,"sequence":92464,"symbol":"FCEU SI 20260615 PS"}
{"ts_recv":"2026-04-07T00:18:01.133242518Z","hd":{"ts_event":"2026-04-07T00:18:01.133227647Z","rtype":160,"publisher_id":101,"instrument_id":436},"action":"A","side":"B","price":"1.157700000","size":20,"channel_id":23,"order_id":"10998893117988010356","flags":128,"ts_in_delta":681,"sequence":92471,"symbol":"FCEU SI 20260615 PS"}
{"ts_recv":"2026-04-07T00:18:15.097769226Z","hd":{"ts_event":"2026-04-07T00:18:15.097753907Z","rtype":160,"publisher_id":101,"instrument_id":436},"action":"A","side":"B","price":"1.157800000","size":20,"channel_id":23,"order_id":"10998893131952535813","flags":128,"ts_in_delta":831,"sequence":92632,"symbol":"FCEU SI 20260615 PS"}
{"ts_recv":"2026-04-07T00:18:15.097800981Z","hd":{"ts_event":"2026-04-07T00:18:15.097788167Z","rtype":160,"publisher_id":101,"instrument_id":436},"action":"C","side":"B","price":"1.157700000","size":20,"channel_id":23,"order_id":"10998893117988010356","flags":128,"ts_in_delta":822,"sequence":92633,"symbol":"FCEU SI 20260615 PS"}
{"ts_recv":"2026-04-07T00:18:27.863377858Z","hd":{"ts_event":"2026-04-07T00:18:27.863364007Z","rtype":160,"publisher_id":101,"instrument_id":436},"action":"C","side":"B","price":"1.157800000","size":20,"channel_id":23,"order_id":"10998893131952535813","flags":128,"ts_in_delta":1438,"sequence":92765,"symbol":"FCEU SI 20260615 PS"}
{"ts_recv":"2026-04-07T00:18:27.911257153Z","hd":{"ts_event":"2026-04-07T00:18:27.911243617Z","rtype":160,"publisher_id":101,"instrument_id":436},"action":"A","side":"B","price":"1.157700000","size":20,"channel_id":23,"order_id":"10998893144766025361","flags":128,"ts_in_delta":924,"sequence":92776,"symbol":"FCEU SI 20260615 PS"}
{"ts_recv":"2026-04-07T00:18:39.969435472Z","hd":{"ts_event":"2026-04-07T00:18:39.969419929Z","rtype":160,"publisher_id":101,"instrument_id":436},"action":"A","side":"B","price":"1.157800000","size":20,"channel_id":23,"order_id":"10998893156824201625","flags":128,"ts_in_delta":980,"sequence":92953,"symbol":"FCEU SI 20260615 PS"}
{"ts_recv":"2026-04-07T00:18:39.969473010Z","hd":{"ts_event":"2026-04-07T00:18:39.969461081Z","rtype":160,"publisher_id":101,"instrument_id":436},"action":"C","side":"B","price":"1.157700000","size":20,"channel_id":23,"order_id":"10998893144766025361","flags":128,"ts_in_delta":837,"sequence":92954,"symbol":"FCEU SI 20260615 PS"}
{"ts_recv":"2026-04-07T00:18:46.062945770Z","hd":{"ts_event":"2026-04-07T00:18:46.062922451Z","rtype":160,"publisher_id":101,"instrument_id":436},"action":"C","side":"B","price":"1.157800000","size":20,"channel_id":23,"order_id":"10998893156824201625","flags":128,"ts_in_delta":1089,"sequence":93001,"symbol":"FCEU SI 20260615 PS"}
{"ts_recv":"2026-04-07T00:18:46.106394114Z","hd":{"ts_event":"2026-04-07T00:18:46.106374233Z","rtype":160,"publisher_id":101,"instrument_id":436},"action":"A","side":"B","price":"1.157700000","size":20,"channel_id":23,"order_id":"10998893162961160791","flags":128,"ts_in_delta":890,"sequence":93003,"symbol":"FCEU SI 20260615 PS"}
{"ts_recv":"2026-04-07T00:19:05.927602369Z","hd":{"ts_event":"2026-04-07T00:19:05.927579657Z","rtype":160,"publisher_id":101,"instrument_id":436},"action":"A","side":"B","price":"1.157800000","size":20,"channel_id":23,"order_id":"10998893182782366192","flags":128,"ts_in_delta":1331,"sequence":93157,"symbol":"FCEU SI 20260615 PS"}
{"ts_recv":"2026-04-07T00:19:05.927619064Z","hd":{"ts_event":"2026-04-07T00:19:05.927605213Z","rtype":160,"publisher_id":101,"instrument_id":436},"action":"C","side":"B","price":"1.157700000","size":20,"channel_id":23,"order_id":"10998893162961160791","flags":128,"ts_in_delta":1273,"sequence":93158,"symbol":"FCEU SI 20260615 PS"}
{"ts_recv":"2026-04-07T00:19:26.633724251Z","hd":{"ts_event":"2026-04-07T00:19:26.633704303Z","rtype":160,"publisher_id":101,"instrument_id":436},"action":"C","side":"B","price":"1.157800000","size":20,"channel_id":23,"order_id":"10998893182782366192","flags":128,"ts_in_delta":1084,"sequence":93370,"symbol":"FCEU SI 20260615 PS"}
{"ts_recv":"2026-04-07T00:19:26.677398932Z","hd":{"ts_event":"2026-04-07T00:19:26.677384241Z","rtype":160,"publisher_id":101,"instrument_id":436},"action":"A","side":"B","price":"1.157700000","size":20,"channel_id":23,"order_id":"10998893203532165992","flags":128,"ts_in_delta":957,"sequence":93375,"symbol":"FCEU SI 20260615 PS"}
{"ts_recv":"2026-04-07T00:19:32.500767269Z","hd":{"ts_event":"2026-04-07T00:19:32.500753127Z","rtype":160,"publisher_id":101,"instrument_id":436},"action":"A","side":"B","price":"1.157800000","size":20,"channel_id":23,"order_id":"10998893209355534973","flags":128,"ts_in_delta":1035,"sequence":93446,"symbol":"FCEU SI 20260615 PS"}
{"ts_recv":"2026-04-07T00:19:32.500818700Z","hd":{"ts_event":"2026-04-07T00:19:32.500806701Z","rtype":160,"publisher_id":101,"instrument_id":436},"action":"C","side":"B","price":"1.157700000","size":20,"channel_id":23,"order_id":"10998893203532165992","flags":128,"ts_in_delta":950,"sequence":93447,"symbol":"FCEU SI 20260615 PS"}
{"ts_recv":"2026-04-07T00:19:37.798184426Z","hd":{"ts_event":"2026-04-07T00:19:37.798161595Z","rtype":160,"publisher_id":101,"instrument_id":436},"action":"C","side":"B","price":"1.157800000","size":20,"channel_id":23,"order_id":"10998893209355534973","flags":128,"ts_in_delta":1106,"sequence":93484,"symbol":"FCEU SI 20260615 PS"}
{"ts_recv":"2026-04-07T00:19:37.841579277Z","hd":{"ts_event":"2026-04-07T00:19:37.841562363Z","rtype":160,"publisher_id":101,"instrument_id":436},"action":"A","side":"B","price":"1.157700000","size":20,"channel_id":23,"order_id":"10998893214696344410","flags":128,"ts_in_delta":1117,"sequence":93486,"symbol":"FCEU SI 20260615 PS"}
{"ts_recv":"2026-04-07T00:19:57.992575840Z","hd":{"ts_event":"2026-04-07T00:19:57.992558143Z","rtype":160,"publisher_id":101,"instrument_id":436},"action":"A","side":"A","price":"1.158100000","size":20,"channel_id":23,"order_id":"1775521197992564472","flags":128,"ts_in_delta":871,"sequence":93640,"symbol":"FCEU SI 20260615 PS"}
{"ts_recv":"2026-04-07T00:19:57.992617694Z","hd":{"ts_event":"2026-04-07T00:19:57.992603935Z","rtype":160,"publisher_id":101,"instrument_id":436},"action":"C","side":"A","price":"1.158200000","size":20,"channel_id":23,"order_id":"1775521066131411002","flags":128,"ts_in_delta":839,"sequence":93641,"symbol":"FCEU SI 20260615 PS"}
{"ts_recv":"2026-04-07T00:19:58.064778939Z","hd":{"ts_event":"2026-04-07T00:19:58.064767073Z","rtype":160,"publisher_id":101,"instrument_id":436},"action":"C","side":"B","price":"1.157700000","size":20,"channel_id":23,"order_id":"10998893214696344410","flags":128,"ts_in_delta":849,"sequence":93653,"symbol":"FCEU SI 20260615 PS"}
{"ts_recv":"2026-04-07T00:19:58.147177953Z","hd":{"ts_event":"2026-04-07T00:19:58.147163687Z","rtype":160,"publisher_id":101,"instrument_id":436},"action":"A","side":"B","price":"1.157700000","size":20,"channel_id":23,"order_id":"10998893235001945235","flags":128,"ts_in_delta":989,"sequence":93667,"symbol":"FCEU SI 20260615 PS"}
{"ts_recv":"2026-04-07T00:20:05.028537681Z","hd":{"ts_event":"2026-04-07T00:20:05.028523957Z","rtype":160,"publisher_id":101,"instrument_id":436},"action":"C","side":"B","price":"1.157700000","size":20,"channel_id":23,"order_id":"10998893235001945235","flags":128,"ts_in_delta":847,"sequence":93717,"symbol":"FCEU SI 20260615 PS"}
{"ts_recv":"2026-04-07T00:20:05.071761119Z","hd":{"ts_event":"2026-04-07T00:20:05.071746133Z","rtype":160,"publisher_id":101,"instrument_id":436},"action":"A","side":"B","price":"1.157600000","size":20,"channel_id":23,"order_id":"10998893241926527943","flags":128,"ts_in_delta":846,"sequence":93724,"symbol":"FCEU SI 20260615 PS"}
{"ts_recv":"2026-04-07T00:20:13.917486530Z","hd":{"ts_event":"2026-04-07T00:20:13.917472633Z","rtype":160,"publisher_id":101,"instrument_id":436},"action":"A","side":"B","price":"1.157700000","size":20,"channel_id":23,"order_id":"10998893250772254665","flags":128,"ts_in_delta":801,"sequence":93803,"symbol":"FCEU SI 20260615 PS"}
{"ts_recv":"2026-04-07T00:20:13.917593132Z","hd":{"ts_event":"2026-04-07T00:20:13.917580653Z","rtype":160,"publisher_id":101,"instrument_id":436},"action":"C","side":"B","price":"1.157600000","size":20,"channel_id":23,"order_id":"10998893241926527943","flags":128,"ts_in_delta":823,"sequence":93804,"symbol":"FCEU SI 20260615 PS"}
{"ts_recv":"2026-04-07T00:20:21.314651199Z","hd":{"ts_event":"2026-04-07T00:20:21.314629339Z","rtype":160,"publisher_id":101,"instrument_id":436},"action":"C","side":"B","price":"1.157700000","size":20,"channel_id":23,"order_id":"10998893250772254665","flags":128,"ts_in_delta":1275,"sequence":93852,"symbol":"FCEU SI 20260615 PS"}
{"ts_recv":"2026-04-07T00:20:21.433280771Z","hd":{"ts_event":"2026-04-07T00:20:21.433264531Z","rtype":160,"publisher_id":101,"instrument_id":436},"action":"A","side":"B","price":"1.157600000","size":20,"channel_id":23,"order_id":"10998893258288048664","flags":128,"ts_in_delta":762,"sequence":93857,"symbol":"FCEU SI 20260615 PS"}
{"ts_recv":"2026-04-07T00:20:21.481811024Z","hd":{"ts_event":"2026-04-07T00:20:21.481789933Z","rtype":160,"publisher_id":101,"instrument_id":436},"action":"A","side":"B","price":"1.157700000","size":20,"channel_id":23,"order_id":"10998893258336576229","flags":128,"ts_in_delta":1332,"sequence":93858,"symbol":"FCEU SI 20260615 PS"}
{"ts_recv":"2026-04-07T00:20:21.481825223Z","hd":{"ts_event":"2026-04-07T00:20:21.481812351Z","rtype":160,"publisher_id":101,"instrument_id":436},"action":"C","side":"B","price":"1.157600000","size":20,"channel_id":23,"order_id":"10998893258288048664","flags":128,"ts_in_delta":911,"sequence":93859,"symbol":"FCEU SI 20260615 PS"}
{"ts_recv":"2026-04-07T00:20:57.950550147Z","hd":{"ts_event":"2026-04-07T00:20:57.950528533Z","rtype":160,"publisher_id":101,"instrument_id":436},"action":"C","side":"B","price":"1.157700000","size":20,"channel_id":23,"order_id":"10998893258336576229","flags":128,"ts_in_delta":800,"sequence":94085,"symbol":"FCEU SI 20260615 PS"}
{"ts_recv":"2026-04-07T00:20:58.009379642Z","hd":{"ts_event":"2026-04-07T00:20:58.009363797Z","rtype":160,"publisher_id":101,"instrument_id":436},"action":"A","side":"B","price":"1.157700000","size":20,"channel_id":23,"order_id":"10998893294864145864","flags":128,"ts_in_delta":863,"sequence":94096,"symbol":"FCEU SI 20260615 PS"}
{"ts_recv":"2026-04-07T00:21:07.024614034Z","hd":{"ts_event":"2026-04-07T00:21:07.024589235Z","rtype":160,"publisher_id":101,"instrument_id":436},"action":"C","side":"A","price":"1.158100000","size":20,"channel_id":23,"order_id":"1775521197992564472","flags":128,"ts_in_delta":1344,"sequence":94191,"symbol":"FCEU SI 20260615 PS"}
{"ts_recv":"2026-04-07T00:21:07.068274518Z","hd":{"ts_event":"2026-04-07T00:21:07.068257123Z","rtype":160,"publisher_id":101,"instrument_id":436},"action":"A","side":"A","price":"1.158200000","size":20,"channel_id":23,"order_id":"1775521267068263133","flags":128,"ts_in_delta":793,"sequence":94197,"symbol":"FCEU SI 20260615 PS"}
{"ts_recv":"2026-04-07T00:21:07.152503483Z","hd":{"ts_event":"2026-04-07T00:21:07.152485401Z","rtype":160,"publisher_id":101,"instrument_id":436},"action":"A","side":"B","price":"1.157800000","size":20,"channel_id":23,"order_id":"10998893304007270129","flags":128,"ts_in_delta":700,"sequence":94204,"symbol":"FCEU SI 20260615 PS"}
{"ts_recv":"2026-04-07T00:21:07.152558707Z","hd":{"ts_event":"2026-04-07T00:21:07.152546213Z","rtype":160,"publisher_id":101,"instrument_id":436},"action":"C","side":"B","price":"1.157700000","size":20,"channel_id":23,"order_id":"10998893294864145864","flags":128,"ts_in_delta":774,"sequence":94206,"symbol":"FCEU SI 20260615 PS"}
{"ts_recv":"2026-04-07T00:21:12.856400542Z","hd":{"ts_event":"2026-04-07T00:21:12.856386981Z","rtype":160,"publisher_id":101,"instrument_id":436},"action":"C","side":"B","price":"1.157800000","size":20,"channel_id":23,"order_id":"10998893304007270129","flags":128,"ts_in_delta":821,"sequence":94279,"symbol":"FCEU SI 20260615 PS"}
{"ts_recv":"2026-04-07T00:21:12.899285290Z","hd":{"ts_event":"2026-04-07T00:21:12.899270523Z","rtype":160,"publisher_id":101,"instrument_id":436},"action":"A","side":"B","price":"1.157700000","size":20,"channel_id":23,"order_id":"10998893309754052682","flags":128,"ts_in_delta":844,"sequence":94282,"symbol":"FCEU SI 20260615 PS"}
{"ts_recv":"2026-04-07T00:21:13.201361211Z","hd":{"ts_event":"2026-04-07T00:21:13.201345469Z","rtype":160,"publisher_id":101,"instrument_id":436},"action":"A","side":"A","price":"1.158100000","size":20,"channel_id":23,"order_id":"1775521273201351768","flags":128,"ts_in_delta":943,"sequence":94288,"symbol":"FCEU SI 20260615 PS"}
{"ts_recv":"2026-04-07T00:21:13.201518752Z","hd":{"ts_event":"2026-04-07T00:21:13.201507941Z","rtype":160,"publisher_id":101,"instrument_id":436},"action":"C","side":"A","price":"1.158200000","size":20,"channel_id":23,"order_id":"1775521267068263133","flags":128,"ts_in_delta":789,"sequence":94291,"symbol":"FCEU SI 20260615 PS"}
{"ts_recv":"2026-04-07T00:21:22.761968754Z","hd":{"ts_event":"2026-04-07T00:21:22.761955959Z","rtype":160,"publisher_id":101,"instrument_id":436},"action":"C","side":"B","price":"1.157700000","size":20,"channel_id":23,"order_id":"10998893309754052682","flags":128,"ts_in_delta":800,"sequence":94363,"symbol":"FCEU SI 20260615 PS"}
{"ts_recv":"2026-04-07T00:21:22.823178532Z","hd":{"ts_event":"2026-04-07T00:21:22.823163105Z","rtype":160,"publisher_id":101,"instrument_id":436},"action":"A","side":"B","price":"1.157700000","size":20,"channel_id":23,"order_id":"10998893319677944605","flags":128,"ts_in_delta":771,"sequence":94375,"symbol":"FCEU SI 20260615 PS"}
{"ts_recv":"2026-04-07T00:21:29.583229195Z","hd":{"ts_event":"2026-04-07T00:21:29.583214449Z","rtype":160,"publisher_id":101,"instrument_id":436},"action":"A","side":"B","price":"1.157800000","size":20,"channel_id":23,"order_id":"10998893326437996370","flags":128,"ts_in_delta":675,"sequence":94443,"symbol":"FCEU SI 20260615 PS"}
{"ts_recv":"2026-04-07T00:21:29.583271180Z","hd":{"ts_event":"2026-04-07T00:21:29.583258187Z","rtype":160,"publisher_id":101,"instrument_id":436},"action":"C","side":"B","price":"1.157700000","size":20,"channel_id":23,"order_id":"10998893319677944605","flags":128,"ts_in_delta":837,"sequence":94445,"symbol":"FCEU SI 20260615 PS"}
{"ts_recv":"2026-04-07T00:21:30.335493430Z","hd":{"ts_event":"2026-04-07T00:21:30.335471769Z","rtype":160,"publisher_id":101,"instrument_id":436},"action":"C","side":"A","price":"1.158100000","size":20,"channel_id":23,"order_id":"1775521273201351768","flags":128,"ts_in_delta":1092,"sequence":94452,"symbol":"FCEU SI 20260615 PS"}
{"ts_recv":"2026-04-07T00:21:30.379027101Z","hd":{"ts_event":"2026-04-07T00:21:30.379007177Z","rtype":160,"publisher_id":101,"instrument_id":436},"action":"A","side":"A","price":"1.158200000","size":20,"channel_id":23,"order_id":"1775521290379017869","flags":128,"ts_in_delta":984,"sequence":94454,"symbol":"FCEU SI 20260615 PS"}
{"ts_recv":"2026-04-07T00:21:51.889924657Z","hd":{"ts_event":"2026-04-07T00:21:51.889910053Z","rtype":160,"publisher_id":101,"instrument_id":436},"action":"C","side":"B","price":"1.157800000","size":20,"channel_id":23,"order_id":"10998893326437996370","flags":128,"ts_in_delta":875,"sequence":94565,"symbol":"FCEU SI 20260615 PS"}
{"ts_recv":"2026-04-07T00:21:51.933357505Z","hd":{"ts_event":"2026-04-07T00:21:51.933342323Z","rtype":160,"publisher_id":101,"instrument_id":436},"action":"A","side":"B","price":"1.157700000","size":20,"channel_id":23,"order_id":"10998893348788124047","flags":128,"ts_in_delta":875,"sequence":94573,"symbol":"FCEU SI 20260615 PS"}
{"ts_recv":"2026-04-07T00:21:55.232984022Z","hd":{"ts_event":"2026-04-07T00:21:55.232967227Z","rtype":160,"publisher_id":101,"instrument_id":436},"action":"A","side":"A","price":"1.158100000","size":20,"channel_id":23,"order_id":"1775521315232973882","flags":128,"ts_in_delta":877,"sequence":94608,"symbol":"FCEU SI 20260615 PS"}
{"ts_recv":"2026-04-07T00:21:55.233132462Z","hd":{"ts_event":"2026-04-07T00:21:55.233119409Z","rtype":160,"publisher_id":101,"instrument_id":436},"action":"C","side":"A","price":"1.158200000","size":20,"channel_id":23,"order_id":"1775521290379017869","flags":128,"ts_in_delta":894,"sequence":94609,"symbol":"FCEU SI 20260615 PS"}
{"ts_recv":"2026-04-07T00:21:56.933491654Z","hd":{"ts_event":"2026-04-07T00:21:56.933469499Z","rtype":160,"publisher_id":101,"instrument_id":436},"action":"C","side":"B","price":"1.157700000","size":20,"channel_id":23,"order_id":"10998893348788124047","flags":128,"ts_in_delta":1104,"sequence":94656,"symbol":"FCEU SI 20260615 PS"}
{"ts_recv":"2026-04-07T00:21:56.976299780Z","hd":{"ts_event":"2026-04-07T00:21:56.976276983Z","rtype":160,"publisher_id":101,"instrument_id":436},"action":"A","side":"B","price":"1.157600000","size":20,"channel_id":23,"order_id":"10998893353831063929","flags":128,"ts_in_delta":856,"sequence":94657,"symbol":"FCEU SI 20260615 PS"}
{"ts_recv":"2026-04-07T00:22:00.880991770Z","hd":{"ts_event":"2026-04-07T00:22:00.880976969Z","rtype":160,"publisher_id":101,"instrument_id":436},"action":"A","side":"B","price":"1.157700000","size":20,"channel_id":23,"order_id":"10998893357735759220","flags":128,"ts_in_delta":770,"sequence":94728,"symbol":"FCEU SI 20260615 PS"}
{"ts_recv":"2026-04-07T00:22:00.881103809Z","hd":{"ts_event":"2026-04-07T00:22:00.881090827Z","rtype":160,"publisher_id":101,"instrument_id":436},"action":"C","side":"B","price":"1.157600000","size":20,"channel_id":23,"order_id":"10998893353831063929","flags":128,"ts_in_delta":830,"sequence":94729,"symbol":"FCEU SI 20260615 PS"}
{"ts_recv":"2026-04-07T00:22:06.548588741Z","hd":{"ts_event":"2026-04-07T00:22:06.548566415Z","rtype":160,"publisher_id":101,"instrument_id":436},"action":"C","side":"B","price":"1.157700000","size":20,"channel_id":23,"order_id":"10998893357735759220","flags":128,"ts_in_delta":1066,"sequence":94781,"symbol":"FCEU SI 20260615 PS"}
{"ts_recv":"2026-04-07T00:22:06.591189351Z","hd":{"ts_event":"2026-04-07T00:22:06.591168549Z","rtype":160,"publisher_id":101,"instrument_id":436},"action":"A","side":"B","price":"1.157600000","size":20,"channel_id":23,"order_id":"10998893363445955412","flags":128,"ts_in_delta":1233,"sequence":94782,"symbol":"FCEU SI 20260615 PS"}
{"ts_recv":"2026-04-07T00:22:12.192174254Z","hd":{"ts_event":"2026-04-07T00:22:12.192159845Z","rtype":160,"publisher_id":101,"instrument_id":436},"action":"A","side":"B","price":"1.157700000","size":20,"channel_id":23,"order_id":"10998893369046941762","flags":128,"ts_in_delta":767,"sequence":94844,"symbol":"FCEU SI 20260615 PS"}
{"ts_recv":"2026-04-07T00:22:12.192259429Z","hd":{"ts_event":"2026-04-07T00:22:12.192246151Z","rtype":160,"publisher_id":101,"instrument_id":436},"action":"C","side":"B","price":"1.157600000","size":20,"channel_id":23,"order_id":"10998893363445955412","flags":128,"ts_in_delta":783,"sequence":94845,"symbol":"FCEU SI 20260615 PS"}
{"ts_recv":"2026-04-07T00:22:17.191182671Z","hd":{"ts_event":"2026-04-07T00:22:17.191170383Z","rtype":160,"publisher_id":101,"instrument_id":436},"action":"C","side":"B","price":"1.157700000","size":20,"channel_id":23,"order_id":"10998893369046941762","flags":128,"ts_in_delta":1042,"sequence":94872,"symbol":"FCEU SI 20260615 PS"}
{"ts_recv":"2026-04-07T00:22:17.234493960Z","hd":{"ts_event":"2026-04-07T00:22:17.234478771Z","rtype":160,"publisher_id":101,"instrument_id":436},"action":"A","side":"B","price":"1.157600000","size":20,"channel_id":23,"order_id":"10998893374089261427","flags":128,"ts_in_delta":806,"sequence":94874,"symbol":"FCEU SI 20260615 PS"}
{"ts_recv":"2026-04-07T00:22:26.867497206Z","hd":{"ts_event":"2026-04-07T00:22:26.867482935Z","rtype":160,"publisher_id":101,"instrument_id":436},"action":"A","side":"B","price":"1.157700000","size":20,"channel_id":23,"order_id":"10998893383722265323","flags":128,"ts_in_delta":956,"sequence":94938,"symbol":"FCEU SI 20260615 PS"}
{"ts_recv":"2026-04-07T00:22:26.867544358Z","hd":{"ts_event":"2026-04-07T00:22:26.867531805Z","rtype":160,"publisher_id":101,"instrument_id":436},"action":"C","side":"B","price":"1.157600000","size":20,"channel_id":23,"order_id":"10998893374089261427","flags":128,"ts_in_delta":954,"sequence":94940,"symbol":"FCEU SI 20260615 PS"}
{"ts_recv":"2026-04-07T00:22:35.061697839Z","hd":{"ts_event":"2026-04-07T00:22:35.061676453Z","rtype":160,"publisher_id":101,"instrument_id":436},"action":"C","side":"B","price":"1.157700000","size":20,"channel_id":23,"order_id":"10998893383722265323","flags":128,"ts_in_delta":1168,"sequence":94998,"symbol":"FCEU SI 20260615 PS"}
{"ts_recv":"2026-04-07T00:22:35.104351824Z","hd":{"ts_event":"2026-04-07T00:22:35.104330623Z","rtype":160,"publisher_id":101,"instrument_id":436},"action":"A","side":"B","price":"1.157600000","size":20,"channel_id":23,"order_id":"10998893391959117393","flags":128,"ts_in_delta":1342,"sequence":94999,"symbol":"FCEU SI 20260615 PS"}
{"ts_recv":"2026-04-07T00:22:37.241112120Z","hd":{"ts_event":"2026-04-07T00:22:37.241094155Z","rtype":160,"publisher_id":101,"instrument_id":436},"action":"A","side":"B","price":"1.157700000","size":20,"channel_id":23,"order_id":"10998893394095876569","flags":128,"ts_in_delta":1100,"sequence":95019,"symbol":"FCEU SI 20260615 PS"}
{"ts_recv":"2026-04-07T00:22:37.241115222Z","hd":{"ts_event":"2026-04-07T00:22:37.241100279Z","rtype":160,"publisher_id":101,"instrument_id":436},"action":"C","side":"B","price":"1.157600000","size":20,"channel_id":23,"order_id":"10998893391959117393","flags":128,"ts_in_delta":816,"sequence":95020,"symbol":"FCEU SI 20260615 PS"}
{"ts_recv":"2026-04-07T00:22:56.888487477Z","hd":{"ts_event":"2026-04-07T00:22:56.888462705Z","rtype":160,"publisher_id":101,"instrument_id":436},"action":"C","side":"B","price":"1.157700000","size":20,"channel_id":23,"order_id":"10998893394095876569","flags":128,"ts_in_delta":1428,"sequence":95128,"symbol":"FCEU SI 20260615 PS"}
{"ts_recv":"2026-04-07T00:22:56.931122684Z","hd":{"ts_event":"2026-04-07T00:22:56.931109495Z","rtype":160,"publisher_id":101,"instrument_id":436},"action":"A","side":"B","price":"1.157600000","size":20,"channel_id":23,"order_id":"10998893413785891432","flags":128,"ts_in_delta":893,"sequence":95133,"symbol":"FCEU SI 20260615 PS"}
{"ts_recv":"2026-04-07T00:23:01.341793652Z","hd":{"ts_event":"2026-04-07T00:23:01.341777189Z","rtype":160,"publisher_id":101,"instrument_id":436},"action":"A","side":"B","price":"1.157700000","size":20,"channel_id":23,"order_id":"10998893418196559775","flags":128,"ts_in_delta":1192,"sequence":95169,"symbol":"FCEU SI 20260615 PS"}
{"ts_recv":"2026-04-07T00:23:01.341812744Z","hd":{"ts_event":"2026-04-07T00:23:01.341801433Z","rtype":160,"publisher_id":101,"instrument_id":436},"action":"C","side":"B","price":"1.157600000","size":20,"channel_id":23,"order_id":"10998893413785891432","flags":128,"ts_in_delta":835,"sequence":95170,"symbol":"FCEU SI 20260615 PS"}
{"ts_recv":"2026-04-07T00:23:06.875878127Z","hd":{"ts_event":"2026-04-07T00:23:06.875854471Z","rtype":160,"publisher_id":101,"instrument_id":436},"action":"C","side":"B","price":"1.157700000","size":20,"channel_id":23,"order_id":"10998893418196559775","flags":128,"ts_in_delta":1227,"sequence":95207,"symbol":"FCEU SI 20260615 PS"}
{"ts_recv":"2026-04-07T00:23:06.920715726Z","hd":{"ts_event":"2026-04-07T00:23:06.920699945Z","rtype":160,"publisher_id":101,"instrument_id":436},"action":"A","side":"B","price":"1.157700000","size":20,"channel_id":23,"order_id":"10998893423775482140","flags":128,"ts_in_delta":1235,"sequence":95212,"symbol":"FCEU SI 20260615 PS"}
{"ts_recv":"2026-04-07T00:23:22.400714744Z","hd":{"ts_event":"2026-04-07T00:23:22.400700819Z","rtype":160,"publisher_id":101,"instrument_id":436},"action":"C","side":"B","price":"1.157700000","size":20,"channel_id":23,"order_id":"10998893423775482140","flags":128,"ts_in_delta":863,"sequence":95350,"symbol":"FCEU SI 20260615 PS"}
{"ts_recv":"2026-04-07T00:23:22.443968833Z","hd":{"ts_event":"2026-04-07T00:23:22.443954149Z","rtype":160,"publisher_id":101,"instrument_id":436},"action":"A","side":"B","price":"1.157600000","size":20,"channel_id":23,"order_id":"10998893439298735814","flags":128,"ts_in_delta":812,"sequence":95354,"symbol":"FCEU SI 20260615 PS"}
{"ts_recv":"2026-04-07T00:23:33.876783795Z","hd":{"ts_event":"2026-04-07T00:23:33.876759245Z","rtype":160,"publisher_id":101,"instrument_id":436},"action":"A","side":"B","price":"1.157700000","size":20,"channel_id":23,"order_id":"10998893450731545096","flags":128,"ts_in_delta":1512,"sequence":95420,"symbol":"FCEU SI 20260615 PS"}
{"ts_recv":"2026-04-07T00:23:33.876829320Z","hd":{"ts_event":"2026-04-07T00:23:33.876815353Z","rtype":160,"publisher_id":101,"instrument_id":436},"action":"C","side":"B","price":"1.157600000","size":20,"channel_id":23,"order_id":"10998893439298735814","flags":128,"ts_in_delta":878,"sequence":95422,"symbol":"FCEU SI 20260615 PS"}
{"ts_recv":"2026-04-07T00:23:38.876887855Z","hd":{"ts_event":"2026-04-07T00:23:38.876862671Z","rtype":160,"publisher_id":101,"instrument_id":436},"action":"C","side":"B","price":"1.157700000","size":20,"channel_id":23,"order_id":"10998893450731545096","flags":128,"ts_in_delta":1575,"sequence":95438,"symbol":"FCEU SI 20260615 PS"}
{"ts_recv":"2026-04-07T00:23:38.919290214Z","hd":{"ts_event":"2026-04-07T00:23:38.919268371Z","rtype":160,"publisher_id":101,"instrument_id":436},"action":"A","side":"B","price":"1.157600000","size":20,"channel_id":23,"order_id":"10998893455774055284","flags":128,"ts_in_delta":849,"sequence":95440,"symbol":"FCEU SI 20260615 PS"}
{"ts_recv":"2026-04-07T00:23:46.281356989Z","hd":{"ts_event":"2026-04-07T00:23:46.281341039Z","rtype":160,"publisher_id":101,"instrument_id":436},"action":"A","side":"A","price":"1.158000000","size":20,"channel_id":23,"order_id":"1775521426281346834","flags":128,"ts_in_delta":872,"sequence":95487,"symbol":"FCEU SI 20260615 PS"}
{"ts_recv":"2026-04-07T00:23:46.281431252Z","hd":{"ts_event":"2026-04-07T00:23:46.281417711Z","rtype":160,"publisher_id":101,"instrument_id":436},"action":"C","side":"A","price":"1.158100000","size":20,"channel_id":23,"order_id":"1775521315232973882","flags":128,"ts_in_delta":829,"sequence":95489,"symbol":"FCEU SI 20260615 PS"}
{"ts_recv":"2026-04-07T00:23:55.998540601Z","hd":{"ts_event":"2026-04-07T00:23:55.998527303Z","rtype":160,"publisher_id":101,"instrument_id":436},"action":"C","side":"B","price":"1.157600000","size":20,"channel_id":23,"order_id":"10998893455774055284","flags":128,"ts_in_delta":895,"sequence":95606,"symbol":"FCEU SI 20260615 PS"}
{"ts_recv":"2026-04-07T00:23:56.058217813Z","hd":{"ts_event":"2026-04-07T00:23:56.058201293Z","rtype":160,"publisher_id":101,"instrument_id":436},"action":"A","side":"B","price":"1.157600000","size":20,"channel_id":23,"order_id":"10998893472912982921","flags":128,"ts_in_delta":912,"sequence":95611,"symbol":"FCEU SI 20260615 PS"}
{"ts_recv":"2026-04-07T00:24:09.539022589Z","hd":{"ts_event":"2026-04-07T00:24:09.539010023Z","rtype":160,"publisher_id":101,"instrument_id":436},"action":"C","side":"B","price":"1.157600000","size":20,"channel_id":23,"order_id":"10998893472912982921","flags":128,"ts_in_delta":1056,"sequence":95706,"symbol":"FCEU SI 20260615 PS"}
{"ts_recv":"2026-04-07T00:24:09.582383887Z","hd":{"ts_event":"2026-04-07T00:24:09.582368579Z","rtype":160,"publisher_id":101,"instrument_id":436},"action":"A","side":"B","price":"1.157500000","size":20,"channel_id":23,"order_id":"10998893486437150551","flags":128,"ts_in_delta":892,"sequence":95713,"symbol":"FCEU SI 20260615 PS"}
{"ts_recv":"2026-04-07T00:24:13.332359464Z","hd":{"ts_event":"2026-04-07T00:24:13.332343505Z","rtype":160,"publisher_id":101,"instrument_id":436},"action":"A","side":"B","price":"1.157600000","size":20,"channel_id":23,"order_id":"10998893490187125453","flags":128,"ts_in_delta":1308,"sequence":95751,"symbol":"FCEU SI 20260615 PS"}
{"ts_recv":"2026-04-07T00:24:13.332379155Z","hd":{"ts_event":"2026-04-07T00:24:13.332364359Z","rtype":160,"publisher_id":101,"instrument_id":436},"action":"C","side":"B","price":"1.157500000","size":20,"channel_id":23,"order_id":"10998893486437150551","flags":128,"ts_in_delta":1039,"sequence":95752,"symbol":"FCEU SI 20260615 PS"}
{"ts_recv":"2026-04-07T00:24:20.632548017Z","hd":{"ts_event":"2026-04-07T00:24:20.632535183Z","rtype":160,"publisher_id":101,"instrument_id":436},"action":"C","side":"B","price":"1.157600000","size":20,"channel_id":23,"order_id":"10998893490187125453","flags":128,"ts_in_delta":939,"sequence":95806,"symbol":"FCEU SI 20260615 PS"}
{"ts_recv":"2026-04-07T00:24:20.675265404Z","hd":{"ts_event":"2026-04-07T00:24:20.675250399Z","rtype":160,"publisher_id":101,"instrument_id":436},"action":"A","side":"B","price":"1.157500000","size":20,"channel_id":23,"order_id":"10998893497530032907","flags":128,"ts_in_delta":702,"sequence":95808,"symbol":"FCEU SI 20260615 PS"}
{"ts_recv":"2026-04-07T00:24:21.655472728Z","hd":{"ts_event":"2026-04-07T00:24:21.655457449Z","rtype":160,"publisher_id":101,"instrument_id":436},"action":"A","side":"B","price":"1.157600000","size":20,"channel_id":23,"order_id":"10998893498510239508","flags":128,"ts_in_delta":967,"sequence":95817,"symbol":"FCEU SI 20260615 PS"}
{"ts_recv":"2026-04-07T00:24:21.655512954Z","hd":{"ts_event":"2026-04-07T00:24:21.655501009Z","rtype":160,"publisher_id":101,"instrument_id":436},"action":"C","side":"B","price":"1.157500000","size":20,"channel_id":23,"order_id":"10998893497530032907","flags":128,"ts_in_delta":888,"sequence":95818,"symbol":"FCEU SI 20260615 PS"}
{"ts_recv":"2026-04-07T00:24:27.714542870Z","hd":{"ts_event":"2026-04-07T00:24:27.714519255Z","rtype":160,"publisher_id":101,"instrument_id":436},"action":"C","side":"B","price":"1.157600000","size":20,"channel_id":23,"order_id":"10998893498510239508","flags":128,"ts_in_delta":1731,"sequence":95845,"symbol":"FCEU SI 20260615 PS"}
{"ts_recv":"2026-04-07T00:24:27.757480665Z","hd":{"ts_event":"2026-04-07T00:24:27.757458427Z","rtype":160,"publisher_id":101,"instrument_id":436},"action":"A","side":"B","price":"1.157500000","size":20,"channel_id":23,"order_id":"10998893504612246186","flags":128,"ts_in_delta":930,"sequence":95846,"symbol":"FCEU SI 20260615 PS"}
{"ts_recv":"2026-04-07T00:24:40.114397257Z","hd":{"ts_event":"2026-04-07T00:24:40.114381899Z","rtype":160,"publisher_id":101,"instrument_id":436},"action":"A","side":"B","price":"1.157600000","size":20,"channel_id":23,"order_id":"10998893516969163445","flags":128,"ts_in_delta":843,"sequence":95942,"symbol":"FCEU SI 20260615 PS"}
{"ts_recv":"2026-04-07T00:24:40.114416840Z","hd":{"ts_event":"2026-04-07T00:24:40.114404797Z","rtype":160,"publisher_id":101,"instrument_id":436},"action":"C","side":"B","price":"1.157500000","size":20,"channel_id":23,"order_id":"10998893504612246186","flags":128,"ts_in_delta":816,"sequence":95943,"symbol":"FCEU SI 20260615 PS"}
{"ts_recv":"2026-04-07T00:24:49.941336944Z","hd":{"ts_event":"2026-04-07T00:24:49.941324651Z","rtype":160,"publisher_id":101,"instrument_id":436},"action":"C","side":"B","price":"1.157600000","size":20,"channel_id":23,"order_id":"10998893516969163445","flags":128,"ts_in_delta":812,"sequence":95990,"symbol":"FCEU SI 20260615 PS"}
{"ts_recv":"2026-04-07T00:24:49.984283131Z","hd":{"ts_event":"2026-04-07T00:24:49.984268085Z","rtype":160,"publisher_id":101,"instrument_id":436},"action":"A","side":"B","price":"1.157500000","size":20,"channel_id":23,"order_id":"10998893526839050193","flags":128,"ts_in_delta":780,"sequence":95998,"symbol":"FCEU SI 20260615 PS"}
{"ts_recv":"2026-04-07T00:24:51.120723228Z","hd":{"ts_event":"2026-04-07T00:24:51.120699517Z","rtype":160,"publisher_id":101,"instrument_id":436},"action":"A","side":"B","price":"1.157600000","size":20,"channel_id":23,"order_id":"10998893527975486798","flags":128,"ts_in_delta":1160,"sequence":96009,"symbol":"FCEU SI 20260615 PS"}
{"ts_recv":"2026-04-07T00:24:51.120842830Z","hd":{"ts_event":"2026-04-07T00:24:51.120831007Z","rtype":160,"publisher_id":101,"instrument_id":436},"action":"C","side":"B","price":"1.157500000","size":20,"channel_id":23,"order_id":"10998893526839050193","flags":128,"ts_in_delta":943,"sequence":96011,"symbol":"FCEU SI 20260615 PS"}
{"ts_recv":"2026-04-07T00:25:00.745319966Z","hd":{"ts_event":"2026-04-07T00:25:00.745295889Z","rtype":160,"publisher_id":101,"instrument_id":436},"action":"C","side":"B","price":"1.157600000","size":20,"channel_id":23,"order_id":"10998893527975486798","flags":128,"ts_in_delta":1399,"sequence":96055,"symbol":"FCEU SI 20260615 PS"}
{"ts_recv":"2026-04-07T00:25:00.787914134Z","hd":{"ts_event":"2026-04-07T00:25:00.787892857Z","rtype":160,"publisher_id":101,"instrument_id":436},"action":"A","side":"B","price":"1.157500000","size":20,"channel_id":23,"order_id":"10998893537642679466","flags":128,"ts_in_delta":920,"sequence":96056,"symbol":"FCEU SI 20260615 PS"}
{"ts_recv":"2026-04-07T00:25:01.595885423Z","hd":{"ts_event":"2026-04-07T00:25:01.595872181Z","rtype":160,"publisher_id":101,"instrument_id":436},"action":"A","side":"B","price":"1.157600000","size":20,"channel_id":23,"order_id":"10998893538450654115","flags":128,"ts_in_delta":924,"sequence":96090,"symbol":"FCEU SI 20260615 PS"}
{"ts_recv":"2026-04-07T00:25:01.595905167Z","hd":{"ts_event":"2026-04-07T00:25:01.595894567Z","rtype":160,"publisher_id":101,"instrument_id":436},"action":"C","side":"B","price":"1.157500000","size":20,"channel_id":23,"order_id":"10998893537642679466","flags":128,"ts_in_delta":985,"sequence":96091,"symbol":"FCEU SI 20260615 PS"}
{"ts_recv":"2026-04-07T00:25:05.619207095Z","hd":{"ts_event":"2026-04-07T00:25:05.619190219Z","rtype":160,"publisher_id":101,"instrument_id":436},"action":"A","side":"A","price":"1.157900000","size":20,"channel_id":23,"order_id":"1775521505619196994","flags":128,"ts_in_delta":1177,"sequence":96156,"symbol":"FCEU SI 20260615 PS"}
{"ts_recv":"2026-04-07T00:25:05.619225304Z","hd":{"ts_event":"2026-04-07T00:25:05.619214435Z","rtype":160,"publisher_id":101,"instrument_id":436},"action":"C","side":"A","price":"1.158000000","size":20,"channel_id":23,"order_id":"1775521426281346834","flags":128,"ts_in_delta":840,"sequence":96157,"symbol":"FCEU SI 20260615 PS"}
{"ts_recv":"2026-04-07T00:25:06.595382112Z","hd":{"ts_event":"2026-04-07T00:25:06.595358967Z","rtype":160,"publisher_id":101,"instrument_id":436},"action":"C","side":"B","price":"1.157600000","size":20,"channel_id":23,"order_id":"10998893538450654115","flags":128,"ts_in_delta":1397,"sequence":96171,"symbol":"FCEU SI 20260615 PS"}
{"ts_recv":"2026-04-07T00:25:06.637826356Z","hd":{"ts_event":"2026-04-07T00:25:06.637804773Z","rtype":160,"publisher_id":101,"instrument_id":436},"action":"A","side":"B","price":"1.157500000","size":20,"channel_id":23,"order_id":"10998893543492591552","flags":128,"ts_in_delta":844,"sequence":96172,"symbol":"FCEU SI 20260615 PS"}
{"ts_recv":"2026-04-07T00:25:11.633322683Z","hd":{"ts_event":"2026-04-07T00:25:11.633302157Z","rtype":160,"publisher_id":101,"instrument_id":436},"action":"C","side":"A","price":"1.157900000","size":20,"channel_id":23,"order_id":"1775521505619196994","flags":128,"ts_in_delta":1639,"sequence":96239,"symbol":"FCEU SI 20260615 PS"}
{"ts_recv":"2026-04-07T00:25:11.676404045Z","hd":{"ts_event":"2026-04-07T00:25:11.676381567Z","rtype":160,"publisher_id":101,"instrument_id":436},"action":"A","side":"A","price":"1.158000000","size":20,"channel_id":23,"order_id":"1775521511676392245","flags":128,"ts_in_delta":1060,"sequence":96242,"symbol":"FCEU SI 20260615 PS"}
{"ts_recv":"2026-04-07T00:25:11.761470152Z","hd":{"ts_event":"2026-04-07T00:25:11.761447589Z","rtype":160,"publisher_id":101,"instrument_id":436},"action":"A","side":"B","price":"1.157600000","size":20,"channel_id":23,"order_id":"10998893548616234363","flags":128,"ts_in_delta":1325,"sequence":96251,"symbol":"FCEU SI 20260615 PS"}
{"ts_recv":"2026-04-07T00:25:11.761480642Z","hd":{"ts_event":"2026-04-07T00:25:11.761467315Z","rtype":160,"publisher_id":101,"instrument_id":436},"action":"C","side":"B","price":"1.157500000","size":20,"channel_id":23,"order_id":"10998893543492591552","flags":128,"ts_in_delta":1253,"sequence":96252,"symbol":"FCEU SI 20260615 PS"}
{"ts_recv":"2026-04-07T00:25:54.978223441Z","hd":{"ts_event":"2026-04-07T00:25:54.978209435Z","rtype":160,"publisher_id":101,"instrument_id":436},"action":"C","side":"B","price":"1.157600000","size":20,"channel_id":23,"order_id":"10998893548616234363","flags":128,"ts_in_delta":894,"sequence":96509,"symbol":"FCEU SI 20260615 PS"}
{"ts_recv":"2026-04-07T00:25:55.021869784Z","hd":{"ts_event":"2026-04-07T00:25:55.021846587Z","rtype":160,"publisher_id":101,"instrument_id":436},"action":"A","side":"B","price":"1.157500000","size":20,"channel_id":23,"order_id":"10998893591876633305","flags":128,"ts_in_delta":912,"sequence":96511,"symbol":"FCEU SI 20260615 PS"}
{"ts_recv":"2026-04-07T00:26:01.193362534Z","hd":{"ts_event":"2026-04-07T00:26:01.193347123Z","rtype":160,"publisher_id":101,"instrument_id":436},"action":"A","side":"B","price":"1.157600000","size":20,"channel_id":23,"order_id":"10998893598048128970","flags":128,"ts_in_delta":1131,"sequence":96581,"symbol":"FCEU SI 20260615 PS"}
{"ts_recv":"2026-04-07T00:26:01.193432219Z","hd":{"ts_event":"2026-04-07T00:26:01.193419579Z","rtype":160,"publisher_id":101,"instrument_id":436},"action":"C","side":"B","price":"1.157500000","size":20,"channel_id":23,"order_id":"10998893591876633305","flags":128,"ts_in_delta":976,"sequence":96584,"symbol":"FCEU SI 20260615 PS"}
{"ts_recv":"2026-04-07T00:27:16.507040612Z","hd":{"ts_event":"2026-04-07T00:27:16.507024561Z","rtype":160,"publisher_id":101,"instrument_id":436},"action":"C","side":"A","price":"1.158000000","size":20,"channel_id":23,"order_id":"1775521511676392245","flags":128,"ts_in_delta":803,"sequence":96994,"symbol":"FCEU SI 20260615 PS"}
{"ts_recv":"2026-04-07T00:27:16.550350375Z","hd":{"ts_event":"2026-04-07T00:27:16.550333015Z","rtype":160,"publisher_id":101,"instrument_id":436},"action":"A","side":"A","price":"1.158100000","size":20,"channel_id":23,"order_id":"1775521636550339205","flags":128,"ts_in_delta":1071,"sequence":97000,"symbol":"FCEU SI 20260615 PS"}
{"ts_recv":"2026-04-07T00:27:38.963276485Z","hd":{"ts_event":"2026-04-07T00:27:38.963260533Z","rtype":160,"publisher_id":101,"instrument_id":436},"action":"A","side":"A","price":"1.158000000","size":20,"channel_id":23,"order_id":"1775521658963266306","flags":128,"ts_in_delta":910,"sequence":97148,"symbol":"FCEU SI 20260615 PS"}
{"ts_recv":"2026-04-07T00:27:38.963292636Z","hd":{"ts_event":"2026-04-07T00:27:38.963280373Z","rtype":160,"publisher_id":101,"instrument_id":436},"action":"C","side":"A","price":"1.158100000","size":20,"channel_id":23,"order_id":"1775521636550339205","flags":128,"ts_in_delta":903,"sequence":97149,"symbol":"FCEU SI 20260615 PS"}
{"ts_recv":"2026-04-07T00:28:26.511166026Z","hd":{"ts_event":"2026-04-07T00:28:26.511150343Z","rtype":160,"publisher_id":101,"instrument_id":436},"action":"C","side":"B","price":"1.157600000","size":20,"channel_id":23,"order_id":"10998893598048128970","flags":128,"ts_in_delta":869,"sequence":97451,"symbol":"FCEU SI 20260615 PS"}
{"ts_recv":"2026-04-07T00:28:26.649471231Z","hd":{"ts_event":"2026-04-07T00:28:26.649450801Z","rtype":160,"publisher_id":101,"instrument_id":436},"action":"A","side":"B","price":"1.157600000","size":20,"channel_id":23,"order_id":"10998893743504232712","flags":128,"ts_in_delta":1015,"sequence":97458,"symbol":"FCEU SI 20260615 PS"}
{"ts_recv":"2026-04-07T00:28:43.834314180Z","hd":{"ts_event":"2026-04-07T00:28:43.834290507Z","rtype":160,"publisher_id":101,"instrument_id":436},"action":"C","side":"B","price":"1.157600000","size":20,"channel_id":23,"order_id":"10998893743504232712","flags":128,"ts_in_delta":1306,"sequence":97579,"symbol":"FCEU SI 20260615 PS"}
{"ts_recv":"2026-04-07T00:28:43.907269912Z","hd":{"ts_event":"2026-04-07T00:28:43.907249959Z","rtype":160,"publisher_id":101,"instrument_id":436},"action":"A","side":"B","price":"1.157600000","size":20,"channel_id":23,"order_id":"10998893760762037184","flags":128,"ts_in_delta":1311,"sequence":97580,"symbol":"FCEU SI 20260615 PS"}
{"ts_recv":"2026-04-07T00:28:51.085314443Z","hd":{"ts_event":"2026-04-07T00:28:51.085300953Z","rtype":160,"publisher_id":101,"instrument_id":436},"action":"C","side":"B","price":"1.157600000","size":20,"channel_id":23,"order_id":"10998893760762037184","flags":128,"ts_in_delta":845,"sequence":97621,"symbol":"FCEU SI 20260615 PS"}
{"ts_recv":"2026-04-07T00:28:51.127511810Z","hd":{"ts_event":"2026-04-07T00:28:51.127496273Z","rtype":160,"publisher_id":101,"instrument_id":436},"action":"A","side":"B","price":"1.157500000","size":20,"channel_id":23,"order_id":"10998893767982278595","flags":128,"ts_in_delta":793,"sequence":97623,"symbol":"FCEU SI 20260615 PS"}
{"ts_recv":"2026-04-07T00:28:57.054405948Z","hd":{"ts_event":"2026-04-07T00:28:57.054391963Z","rtype":160,"publisher_id":101,"instrument_id":436},"action":"A","side":"B","price":"1.157600000","size":20,"channel_id":23,"order_id":"10998893773909173517","flags":128,"ts_in_delta":849,"sequence":97660,"symbol":"FCEU SI 20260615 PS"}
{"ts_recv":"2026-04-07T00:28:57.054461978Z","hd":{"ts_event":"2026-04-07T00:28:57.054449589Z","rtype":160,"publisher_id":101,"instrument_id":436},"action":"C","side":"B","price":"1.157500000","size":20,"channel_id":23,"order_id":"10998893767982278595","flags":128,"ts_in_delta":834,"sequence":97662,"symbol":"FCEU SI 20260615 PS"}
{"ts_recv":"2026-04-07T00:29:16.596676460Z","hd":{"ts_event":"2026-04-07T00:29:16.596657223Z","rtype":160,"publisher_id":101,"instrument_id":436},"action":"C","side":"B","price":"1.157600000","size":20,"channel_id":23,"order_id":"10998893773909173517","flags":128,"ts_in_delta":1138,"sequence":97731,"symbol":"FCEU SI 20260615 PS"}
{"ts_recv":"2026-04-07T00:29:16.639137714Z","hd":{"ts_event":"2026-04-07T00:29:16.639116621Z","rtype":160,"publisher_id":101,"instrument_id":436},"action":"A","side":"B","price":"1.157500000","size":20,"channel_id":23,"order_id":"10998893793493903185","flags":128,"ts_in_delta":846,"sequence":97732,"symbol":"FCEU SI 20260615 PS"}
{"ts_recv":"2026-04-07T00:29:30.900167301Z","hd":{"ts_event":"2026-04-07T00:29:30.900152185Z","rtype":160,"publisher_id":101,"instrument_id":436},"action":"A","side":"B","price":"1.157600000","size":20,"channel_id":23,"order_id":"10998893807754933962","flags":128,"ts_in_delta":810,"sequence":97800,"symbol":"FCEU SI 20260615 PS"}
{"ts_recv":"2026-04-07T00:29:30.900314534Z","hd":{"ts_event":"2026-04-07T00:29:30.900302085Z","rtype":160,"publisher_id":101,"instrument_id":436},"action":"C","side":"B","price":"1.157500000","size":20,"channel_id":23,"order_id":"10998893793493903185","flags":128,"ts_in_delta":856,"sequence":97801,"symbol":"FCEU SI 20260615 PS"}
{"ts_recv":"2026-04-07T00:29:41.875389182Z","hd":{"ts_event":"2026-04-07T00:29:41.875375993Z","rtype":160,"publisher_id":101,"instrument_id":436},"action":"C","side":"B","price":"1.157600000","size":20,"channel_id":23,"order_id":"10998893807754933962","flags":128,"ts_in_delta":830,"sequence":97860,"symbol":"FCEU SI 20260615 PS"}
{"ts_recv":"2026-04-07T00:29:41.918678867Z","hd":{"ts_event":"2026-04-07T00:29:41.918664101Z","rtype":160,"publisher_id":101,"instrument_id":436},"action":"A","side":"B","price":"1.157500000","size":20,"channel_id":23,"order_id":"10998893818773446651","flags":128,"ts_in_delta":827,"sequence":97866,"symbol":"FCEU SI 20260615 PS"}
{"ts_recv":"2026-04-07T00:29:42.846349135Z","hd":{"ts_event":"2026-04-07T00:29:42.846332509Z","rtype":160,"publisher_id":101,"instrument_id":436},"action":"A","side":"B","price":"1.157600000","size":20,"channel_id":23,"order_id":"10998893819701114552","flags":128,"ts_in_delta":1211,"sequence":97890,"symbol":"FCEU SI 20260615 PS"}
{"ts_recv":"2026-04-07T00:29:42.846483344Z","hd":{"ts_event":"2026-04-07T00:29:42.846470473Z","rtype":160,"publisher_id":101,"instrument_id":436},"action":"C","side":"B","price":"1.157500000","size":20,"channel_id":23,"order_id":"10998893818773446651","flags":128,"ts_in_delta":877,"sequence":97891,"symbol":"FCEU SI 20260615 PS"}
{"ts_recv":"2026-04-07T00:29:47.845838374Z","hd":{"ts_event":"2026-04-07T00:29:47.845815565Z","rtype":160,"publisher_id":101,"instrument_id":436},"action":"C","side":"B","price":"1.157600000","size":20,"channel_id":23,"order_id":"10998893819701114552","flags":128,"ts_in_delta":1793,"sequence":97924,"symbol":"FCEU SI 20260615 PS"}
{"ts_recv":"2026-04-07T00:29:47.888175233Z","hd":{"ts_event":"2026-04-07T00:29:47.888159819Z","rtype":160,"publisher_id":101,"instrument_id":436},"action":"A","side":"B","price":"1.157500000","size":20,"channel_id":23,"order_id":"10998893824742941766","flags":128,"ts_in_delta":946,"sequence":97925,"symbol":"FCEU SI 20260615 PS"}
{"ts_recv":"2026-04-07T00:29:49.967674329Z","hd":{"ts_event":"2026-04-07T00:29:49.967656533Z","rtype":160,"publisher_id":101,"instrument_id":436},"action":"A","side":"B","price":"1.157600000","size":20,"channel_id":23,"order_id":"10998893826822442829","flags":128,"ts_in_delta":819,"sequence":97950,"symbol":"FCEU SI 20260615 PS"}
{"ts_recv":"2026-04-07T00:29:49.967690541Z","hd":{"ts_event":"2026-04-07T00:29:49.967679669Z","rtype":160,"publisher_id":101,"instrument_id":436},"action":"C","side":"B","price":"1.157500000","size":20,"channel_id":23,"order_id":"10998893824742941766","flags":128,"ts_in_delta":867,"sequence":97951,"symbol":"FCEU SI 20260615 PS"}
{"ts_recv":"2026-04-07T00:29:55.175756725Z","hd":{"ts_event":"2026-04-07T00:29:55.175742949Z","rtype":160,"publisher_id":101,"instrument_id":436},"action":"C","side":"B","price":"1.157600000","size":20,"channel_id":23,"order_id":"10998893826822442829","flags":128,"ts_in_delta":886,"sequence":97972,"symbol":"FCEU SI 20260615 PS"}
{"ts_recv":"2026-04-07T00:29:55.219815642Z","hd":{"ts_event":"2026-04-07T00:29:55.219801873Z","rtype":160,"publisher_id":101,"instrument_id":436},"action":"A","side":"B","price":"1.157500000","size":20,"channel_id":23,"order_id":"10998893832074584016","flags":128,"ts_in_delta":901,"sequence":97974,"symbol":"FCEU SI 20260615 PS"}
{"ts_recv":"2026-04-07T00:30:03.734203731Z","hd":{"ts_event":"2026-04-07T00:30:03.734185981Z","rtype":160,"publisher_id":101,"instrument_id":436},"action":"A","side":"A","price":"1.157900000","size":20,"channel_id":23,"order_id":"1775521803734193227","flags":128,"ts_in_delta":885,"sequence":98068,"symbol":"FCEU SI 20260615 PS"}
{"ts_recv":"2026-04-07T00:30:03.734267941Z","hd":{"ts_event":"2026-04-07T00:30:03.734254501Z","rtype":160,"publisher_id":101,"instrument_id":436},"action":"C","side":"A","price":"1.158000000","size":20,"channel_id":23,"order_id":"1775521658963266306","flags":128,"ts_in_delta":834,"sequence":98071,"symbol":"FCEU SI 20260615 PS"}
{"ts_recv":"2026-04-07T00:30:07.377306352Z","hd":{"ts_event":"2026-04-07T00:30:07.377290557Z","rtype":160,"publisher_id":101,"instrument_id":436},"action":"A","side":"B","price":"1.157600000","size":20,"channel_id":23,"order_id":"10998893844232072393","flags":128,"ts_in_delta":857,"sequence":98100,"symbol":"FCEU SI 20260615 PS"}
{"ts_recv":"2026-04-07T00:30:07.377448648Z","hd":{"ts_event":"2026-04-07T00:30:07.377436477Z","rtype":160,"publisher_id":101,"instrument_id":436},"action":"C","side":"B","price":"1.157500000","size":20,"channel_id":23,"order_id":"10998893832074584016","flags":128,"ts_in_delta":834,"sequence":98101,"symbol":"FCEU SI 20260615 PS"}
{"ts_recv":"2026-04-07T00:30:08.734005372Z","hd":{"ts_event":"2026-04-07T00:30:08.733991955Z","rtype":160,"publisher_id":101,"instrument_id":436},"action":"C","side":"A","price":"1.157900000","size":20,"channel_id":23,"order_id":"1775521803734193227","flags":128,"ts_in_delta":778,"sequence":98109,"symbol":"FCEU SI 20260615 PS"}
{"ts_recv":"2026-04-07T00:30:08.776364951Z","hd":{"ts_event":"2026-04-07T00:30:08.776350023Z","rtype":160,"publisher_id":101,"instrument_id":436},"action":"A","side":"A","price":"1.158000000","size":20,"channel_id":23,"order_id":"1775521808776355907","flags":128,"ts_in_delta":951,"sequence":98113,"symbol":"FCEU SI 20260615 PS"}
{"ts_recv":"2026-04-07T00:30:21.485892251Z","hd":{"ts_event":"2026-04-07T00:30:21.485869707Z","rtype":160,"publisher_id":101,"instrument_id":436},"action":"C","side":"B","price":"1.157600000","size":20,"channel_id":23,"order_id":"10998893844232072393","flags":128,"ts_in_delta":1254,"sequence":98185,"symbol":"FCEU SI 20260615 PS"}
{"ts_recv":"2026-04-07T00:30:21.565652892Z","hd":{"ts_event":"2026-04-07T00:30:21.565638199Z","rtype":160,"publisher_id":101,"instrument_id":436},"action":"A","side":"B","price":"1.157600000","size":20,"channel_id":23,"order_id":"10998893858420419880","flags":128,"ts_in_delta":1161,"sequence":98199,"symbol":"FCEU SI 20260615 PS"}
{"ts_recv":"2026-04-07T00:30:28.364815305Z","hd":{"ts_event":"2026-04-07T00:30:28.364801639Z","rtype":160,"publisher_id":101,"instrument_id":436},"action":"C","side":"B","price":"1.157600000","size":20,"channel_id":23,"order_id":"10998893858420419880","flags":128,"ts_in_delta":1127,"sequence":98244,"symbol":"FCEU SI 20260615 PS"}
{"ts_recv":"2026-04-07T00:30:28.408427841Z","hd":{"ts_event":"2026-04-07T00:30:28.408412393Z","rtype":160,"publisher_id":101,"instrument_id":436},"action":"A","side":"B","price":"1.157500000","size":20,"channel_id":23,"order_id":"10998893865263194552","flags":128,"ts_in_delta":883,"sequence":98246,"symbol":"FCEU SI 20260615 PS"}
{"ts_recv":"2026-04-07T00:31:00.733336207Z","hd":{"ts_event":"2026-04-07T00:31:00.733311451Z","rtype":160,"publisher_id":101,"instrument_id":436},"action":"A","side":"B","price":"1.157600000","size":20,"channel_id":23,"order_id":"10998893897588098321","flags":128,"ts_in_delta":920,"sequence":98502,"symbol":"FCEU SI 20260615 PS"}
{"ts_recv":"2026-04-07T00:31:00.733345753Z","hd":{"ts_event":"2026-04-07T00:31:00.733332603Z","rtype":160,"publisher_id":101,"instrument_id":436},"action":"C","side":"B","price":"1.157500000","size":20,"channel_id":23,"order_id":"10998893865263194552","flags":128,"ts_in_delta":932,"sequence":98503,"symbol":"FCEU SI 20260615 PS"}
{"ts_recv":"2026-04-07T00:31:12.922599538Z","hd":{"ts_event":"2026-04-07T00:31:12.922577689Z","rtype":160,"publisher_id":101,"instrument_id":436},"action":"C","side":"B","price":"1.157600000","size":20,"channel_id":23,"order_id":"10998893897588098321","flags":128,"ts_in_delta":1056,"sequence":98585,"symbol":"FCEU SI 20260615 PS"}
{"ts_recv":"2026-04-07T00:31:12.965660303Z","hd":{"ts_event":"2026-04-07T00:31:12.965638711Z","rtype":160,"publisher_id":101,"instrument_id":436},"action":"A","side":"B","price":"1.157500000","size":20,"channel_id":23,"order_id":"10998893909820425406","flags":128,"ts_in_delta":1159,"sequence":98586,"symbol":"FCEU SI 20260615 PS"}
{"ts_recv":"2026-04-07T00:31:16.805265134Z","hd":{"ts_event":"2026-04-07T00:31:16.805248417Z","rtype":160,"publisher_id":101,"instrument_id":436},"action":"A","side":"B","price":"1.157600000","size":20,"channel_id":23,"order_id":"10998893913660030943","flags":128,"ts_in_delta":976,"sequence":98608,"symbol":"FCEU SI 20260615 PS"}
{"ts_recv":"2026-04-07T00:31:16.805309284Z","hd":{"ts_event":"2026-04-07T00:31:16.805297461Z","rtype":160,"publisher_id":101,"instrument_id":436},"action":"C","side":"B","price":"1.157500000","size":20,"channel_id":23,"order_id":"10998893909820425406","flags":128,"ts_in_delta":816,"sequence":98610,"symbol":"FCEU SI 20260615 PS"}
{"ts_recv":"2026-04-07T00:31:29.957948298Z","hd":{"ts_event":"2026-04-07T00:31:29.957934373Z","rtype":160,"publisher_id":101,"instrument_id":436},"action":"C","side":"B","price":"1.157600000","size":20,"channel_id":23,"order_id":"10998893913660030943","flags":128,"ts_in_delta":847,"sequence":98715,"symbol":"FCEU SI 20260615 PS"}
{"ts_recv":"2026-04-07T00:31:30.041141496Z","hd":{"ts_event":"2026-04-07T00:31:30.041125923Z","rtype":160,"publisher_id":101,"instrument_id":436},"action":"A","side":"B","price":"1.157600000","size":20,"channel_id":23,"order_id":"10998893926895908210","flags":128,"ts_in_delta":834,"sequence":98719,"symbol":"FCEU SI 20260615 PS"}
{"ts_recv":"2026-04-07T00:31:52.071979512Z","hd":{"ts_event":"2026-04-07T00:31:52.071966155Z","rtype":160,"publisher_id":101,"instrument_id":436},"action":"C","side":"B","price":"1.157600000","size":20,"channel_id":23,"order_id":"10998893926895908210","flags":128,"ts_in_delta":895,"sequence":98870,"symbol":"FCEU SI 20260615 PS"}
{"ts_recv":"2026-04-07T00:31:52.114681872Z","hd":{"ts_event":"2026-04-07T00:31:52.114666617Z","rtype":160,"publisher_id":101,"instrument_id":436},"action":"A","side":"B","price":"1.157500000","size":20,"channel_id":23,"order_id":"10998893948969448368","flags":128,"ts_in_delta":702,"sequence":98886,"symbol":"FCEU SI 20260615 PS"}
{"ts_recv":"2026-04-07T00:31:53.089254405Z","hd":{"ts_event":"2026-04-07T00:31:53.089239329Z","rtype":160,"publisher_id":101,"instrument_id":436},"action":"A","side":"B","price":"1.157600000","size":20,"channel_id":23,"order_id":"10998893949944021031","flags":128,"ts_in_delta":896,"sequence":98916,"symbol":"FCEU SI 20260615 PS"}
{"ts_recv":"2026-04-07T00:31:53.089276599Z","hd":{"ts_event":"2026-04-07T00:31:53.089263989Z","rtype":160,"publisher_id":101,"instrument_id":436},"action":"C","side":"B","price":"1.157500000","size":20,"channel_id":23,"order_id":"10998893948969448368","flags":128,"ts_in_delta":900,"sequence":98917,"symbol":"FCEU SI 20260615 PS"}
{"ts_recv":"2026-04-07T00:32:01.105369028Z","hd":{"ts_event":"2026-04-07T00:32:01.105345879Z","rtype":160,"publisher_id":101,"instrument_id":436},"action":"C","side":"B","price":"1.157600000","size":20,"channel_id":23,"order_id":"10998893949944021031","flags":128,"ts_in_delta":1217,"sequence":98984,"symbol":"FCEU SI 20260615 PS"}
{"ts_recv":"2026-04-07T00:32:01.148368642Z","hd":{"ts_event":"2026-04-07T00:32:01.148346241Z","rtype":160,"publisher_id":101,"instrument_id":436},"action":"A","side":"B","price":"1.157500000","size":20,"channel_id":23,"order_id":"10998893958003132983","flags":128,"ts_in_delta":1375,"sequence":98985,"symbol":"FCEU SI 20260615 PS"}
{"ts_recv":"2026-04-07T00:32:03.772212844Z","hd":{"ts_event":"2026-04-07T00:32:03.772196395Z","rtype":160,"publisher_id":101,"instrument_id":436},"action":"A","side":"B","price":"1.157600000","size":20,"channel_id":23,"order_id":"10998893960626978372","flags":128,"ts_in_delta":1123,"sequence":99000,"symbol":"FCEU SI 20260615 PS"}
{"ts_recv":"2026-04-07T00:32:03.772276070Z","hd":{"ts_event":"2026-04-07T00:32:03.772262719Z","rtype":160,"publisher_id":101,"instrument_id":436},"action":"C","side":"B","price":"1.157500000","size":20,"channel_id":23,"order_id":"10998893958003132983","flags":128,"ts_in_delta":1027,"sequence":99001,"symbol":"FCEU SI 20260615 PS"}
{"ts_recv":"2026-04-07T00:32:08.772310339Z","hd":{"ts_event":"2026-04-07T00:32:08.772287043Z","rtype":160,"publisher_id":101,"instrument_id":436},"action":"C","side":"B","price":"1.157600000","size":20,"channel_id":23,"order_id":"10998893960626978372","flags":128,"ts_in_delta":1200,"sequence":99053,"symbol":"FCEU SI 20260615 PS"}
{"ts_recv":"2026-04-07T00:32:08.814538403Z","hd":{"ts_event":"2026-04-07T00:32:08.814518035Z","rtype":160,"publisher_id":101,"instrument_id":436},"action":"A","side":"B","price":"1.157500000","size":20,"channel_id":23,"order_id":"10998893965669304597","flags":128,"ts_in_delta":1296,"sequence":99054,"symbol":"FCEU SI 20260615 PS"}
{"ts_recv":"2026-04-07T00:32:10.888864245Z","hd":{"ts_event":"2026-04-07T00:32:10.888847459Z","rtype":160,"publisher_id":101,"instrument_id":436},"action":"A","side":"A","price":"1.157900000","size":20,"channel_id":23,"order_id":"1775521930888853645","flags":128,"ts_in_delta":783,"sequence":99080,"symbol":"FCEU SI 20260615 PS"}
{"ts_recv":"2026-04-07T00:32:10.889013322Z","hd":{"ts_event":"2026-04-07T00:32:10.889001049Z","rtype":160,"publisher_id":101,"instrument_id":436},"action":"C","side":"A","price":"1.158000000","size":20,"channel_id":23,"order_id":"1775521808776355907","flags":128,"ts_in_delta":653,"sequence":99081,"symbol":"FCEU SI 20260615 PS"}
{"ts_recv":"2026-04-07T00:32:14.903259004Z","hd":{"ts_event":"2026-04-07T00:32:14.903239181Z","rtype":160,"publisher_id":101,"instrument_id":436},"action":"C","side":"B","price":"1.157500000","size":20,"channel_id":23,"order_id":"10998893965669304597","flags":128,"ts_in_delta":881,"sequence":99164,"symbol":"FCEU SI 20260615 PS"}
{"ts_recv":"2026-04-07T00:32:14.946196125Z","hd":{"ts_event":"2026-04-07T00:32:14.946172331Z","rtype":160,"publisher_id":101,"instrument_id":436},"action":"A","side":"B","price":"1.157400000","size":20,"channel_id":23,"order_id":"10998893971800959238","flags":128,"ts_in_delta":1546,"sequence":99169,"symbol":"FCEU SI 20260615 PS"}
{"ts_recv":"2026-04-07T00:32:19.104636435Z","hd":{"ts_event":"2026-04-07T00:32:19.104611875Z","rtype":160,"publisher_id":101,"instrument_id":436},"action":"A","side":"B","price":"1.157500000","size":20,"channel_id":23,"order_id":"10998893975959401073","flags":128,"ts_in_delta":1687,"sequence":99208,"symbol":"FCEU SI 20260615 PS"}
{"ts_recv":"2026-04-07T00:32:19.104638816Z","hd":{"ts_event":"2026-04-07T00:32:19.104623235Z","rtype":160,"publisher_id":101,"instrument_id":436},"action":"C","side":"B","price":"1.157400000","size":20,"channel_id":23,"order_id":"10998893971800959238","flags":128,"ts_in_delta":927,"sequence":99209,"symbol":"FCEU SI 20260615 PS"}
{"ts_recv":"2026-04-07T00:32:28.539217242Z","hd":{"ts_event":"2026-04-07T00:32:28.539192517Z","rtype":160,"publisher_id":101,"instrument_id":436},"action":"C","side":"B","price":"1.157500000","size":20,"channel_id":23,"order_id":"10998893975959401073","flags":128,"ts_in_delta":1348,"sequence":99276,"symbol":"FCEU SI 20260615 PS"}
{"ts_recv":"2026-04-07T00:32:28.582319332Z","hd":{"ts_event":"2026-04-07T00:32:28.582297731Z","rtype":160,"publisher_id":101,"instrument_id":436},"action":"A","side":"B","price":"1.157400000","size":20,"channel_id":23,"order_id":"10998893985437084702","flags":128,"ts_in_delta":1116,"sequence":99278,"symbol":"FCEU SI 20260615 PS"}
{"ts_recv":"2026-04-07T00:32:32.517179842Z","hd":{"ts_event":"2026-04-07T00:32:32.517165631Z","rtype":160,"publisher_id":101,"instrument_id":436},"action":"A","side":"B","price":"1.157500000","size":20,"channel_id":23,"order_id":"10998893989371947428","flags":128,"ts_in_delta":649,"sequence":99360,"symbol":"FCEU SI 20260615 PS"}
{"ts_recv":"2026-04-07T00:32:32.517247508Z","hd":{"ts_event":"2026-04-07T00:32:32.517235179Z","rtype":160,"publisher_id":101,"instrument_id":436},"action":"C","side":"B","price":"1.157400000","size":20,"channel_id":23,"order_id":"10998893985437084702","flags":128,"ts_in_delta":967,"sequence":99363,"symbol":"FCEU SI 20260615 PS"}
{"ts_recv":"2026-04-07T00:33:24.408205381Z","hd":{"ts_event":"2026-04-07T00:33:24.408190931Z","rtype":160,"publisher_id":101,"instrument_id":436},"action":"C","side":"B","price":"1.157500000","size":20,"channel_id":23,"order_id":"10998893989371947428","flags":128,"ts_in_delta":1064,"sequence":99674,"symbol":"FCEU SI 20260615 PS"}
{"ts_recv":"2026-04-07T00:33:24.451135482Z","hd":{"ts_event":"2026-04-07T00:33:24.451117791Z","rtype":160,"publisher_id":101,"instrument_id":436},"action":"A","side":"B","price":"1.157400000","size":20,"channel_id":23,"order_id":"10998894041305899673","flags":128,"ts_in_delta":1067,"sequence":99676,"symbol":"FCEU SI 20260615 PS"}
{"ts_recv":"2026-04-07T00:33:34.592374505Z","hd":{"ts_event":"2026-04-07T00:33:34.592350129Z","rtype":160,"publisher_id":101,"instrument_id":436},"action":"A","side":"B","price":"1.157500000","size":20,"channel_id":23,"order_id":"10998894051447137500","flags":128,"ts_in_delta":1146,"sequence":99766,"symbol":"FCEU SI 20260615 PS"}
{"ts_recv":"2026-04-07T00:33:34.592384996Z","hd":{"ts_event":"2026-04-07T00:33:34.592370367Z","rtype":160,"publisher_id":101,"instrument_id":436},"action":"C","side":"B","price":"1.157400000","size":20,"channel_id":23,"order_id":"10998894041305899673","flags":128,"ts_in_delta":932,"sequence":99767,"symbol":"FCEU SI 20260615 PS"}
{"ts_recv":"2026-04-07T00:35:41.243776792Z","hd":{"ts_event":"2026-04-07T00:35:41.243760015Z","rtype":160,"publisher_id":101,"instrument_id":436},"action":"C","side":"B","price":"1.157500000","size":20,"channel_id":23,"order_id":"10998894051447137500","flags":128,"ts_in_delta":1039,"sequence":100595,"symbol":"FCEU SI 20260615 PS"}
{"ts_recv":"2026-04-07T00:35:41.307154104Z","hd":{"ts_event":"2026-04-07T00:35:41.307135595Z","rtype":160,"publisher_id":101,"instrument_id":436},"action":"A","side":"B","price":"1.157500000","size":20,"channel_id":23,"order_id":"10998894178161917798","flags":128,"ts_in_delta":882,"sequence":100604,"symbol":"FCEU SI 20260615 PS"}
{"ts_recv":"2026-04-07T00:36:06.114361076Z","hd":{"ts_event":"2026-04-07T00:36:06.114345929Z","rtype":160,"publisher_id":101,"instrument_id":436},"action":"C","side":"B","price":"1.157500000","size":20,"channel_id":23,"order_id":"10998894178161917798","flags":128,"ts_in_delta":831,"sequence":100745,"symbol":"FCEU SI 20260615 PS"}
{"ts_recv":"2026-04-07T00:36:06.157276531Z","hd":{"ts_event":"2026-04-07T00:36:06.157259461Z","rtype":160,"publisher_id":101,"instrument_id":436},"action":"A","side":"B","price":"1.157400000","size":20,"channel_id":23,"order_id":"10998894203012041684","flags":128,"ts_in_delta":833,"sequence":100750,"symbol":"FCEU SI 20260615 PS"}
{"ts_recv":"2026-04-07T00:36:08.611230736Z","hd":{"ts_event":"2026-04-07T00:36:08.611214553Z","rtype":160,"publisher_id":101,"instrument_id":436},"action":"A","side":"B","price":"1.157500000","size":20,"channel_id":23,"order_id":"10998894205465996930","flags":128,"ts_in_delta":848,"sequence":100777,"symbol":"FCEU SI 20260615 PS"}
{"ts_recv":"2026-04-07T00:36:08.611418857Z","hd":{"ts_event":"2026-04-07T00:36:08.611407291Z","rtype":160,"publisher_id":101,"instrument_id":436},"action":"C","side":"B","price":"1.157400000","size":20,"channel_id":23,"order_id":"10998894203012041684","flags":128,"ts_in_delta":840,"sequence":100779,"symbol":"FCEU SI 20260615 PS"}
{"ts_recv":"2026-04-07T00:36:18.224059303Z","hd":{"ts_event":"2026-04-07T00:36:18.224034859Z","rtype":160,"publisher_id":101,"instrument_id":436},"action":"C","side":"B","price":"1.157500000","size":20,"channel_id":23,"order_id":"10998894205465996930","flags":128,"ts_in_delta":900,"sequence":100835,"symbol":"FCEU SI 20260615 PS"}
{"ts_recv":"2026-04-07T00:36:18.267736764Z","hd":{"ts_event":"2026-04-07T00:36:18.267714197Z","rtype":160,"publisher_id":101,"instrument_id":436},"action":"A","side":"B","price":"1.157400000","size":20,"channel_id":23,"order_id":"10998894215122500980","flags":128,"ts_in_delta":1321,"sequence":100836,"symbol":"FCEU SI 20260615 PS"}
{"ts_recv":"2026-04-07T00:36:22.971413361Z","hd":{"ts_event":"2026-04-07T00:36:22.971395539Z","rtype":160,"publisher_id":101,"instrument_id":436},"action":"A","side":"A","price":"1.157800000","size":20,"channel_id":23,"order_id":"1775522182971401940","flags":128,"ts_in_delta":860,"sequence":100869,"symbol":"FCEU SI 20260615 PS"}
{"ts_recv":"2026-04-07T00:36:22.971636678Z","hd":{"ts_event":"2026-04-07T00:36:22.971622639Z","rtype":160,"publisher_id":101,"instrument_id":436},"action":"C","side":"A","price":"1.157900000","size":20,"channel_id":23,"order_id":"1775521930888853645","flags":128,"ts_in_delta":837,"sequence":100870,"symbol":"FCEU SI 20260615 PS"}
{"ts_recv":"2026-04-07T00:36:39.380237932Z","hd":{"ts_event":"2026-04-07T00:36:39.380221921Z","rtype":160,"publisher_id":101,"instrument_id":436},"action":"C","side":"B","price":"1.157400000","size":20,"channel_id":23,"order_id":"10998894215122500980","flags":128,"ts_in_delta":989,"sequence":100999,"symbol":"FCEU SI 20260615 PS"}
{"ts_recv":"2026-04-07T00:36:39.487376865Z","hd":{"ts_event":"2026-04-07T00:36:39.487354535Z","rtype":160,"publisher_id":101,"instrument_id":436},"action":"A","side":"B","price":"1.157300000","size":20,"channel_id":23,"order_id":"10998894236342141195","flags":128,"ts_in_delta":1244,"sequence":101013,"symbol":"FCEU SI 20260615 PS"}
{"ts_recv":"2026-04-07T00:36:52.184371218Z","hd":{"ts_event":"2026-04-07T00:36:52.184353027Z","rtype":160,"publisher_id":101,"instrument_id":436},"action":"A","side":"A","price":"1.157700000","size":20,"channel_id":23,"order_id":"1775522212184359578","flags":128,"ts_in_delta":1020,"sequence":101104,"symbol":"FCEU SI 20260615 PS"}
{"ts_recv":"2026-04-07T00:36:52.184389473Z","hd":{"ts_event":"2026-04-07T00:36:52.184375523Z","rtype":160,"publisher_id":101,"instrument_id":436},"action":"C","side":"A","price":"1.157800000","size":20,"channel_id":23,"order_id":"1775522182971401940","flags":128,"ts_in_delta":914,"sequence":101105,"symbol":"FCEU SI 20260615 PS"}
{"ts_recv":"2026-04-07T00:37:53.391493772Z","hd":{"ts_event":"2026-04-07T00:37:53.391465909Z","rtype":160,"publisher_id":101,"instrument_id":436},"action":"C","side":"B","price":"1.157300000","size":20,"channel_id":23,"order_id":"10998894236342141195","flags":128,"ts_in_delta":1311,"sequence":101582,"symbol":"FCEU SI 20260615 PS"}
{"ts_recv":"2026-04-07T00:37:53.434175825Z","hd":{"ts_event":"2026-04-07T00:37:53.434152579Z","rtype":160,"publisher_id":101,"instrument_id":436},"action":"A","side":"B","price":"1.157200000","size":20,"channel_id":23,"order_id":"10998894310288939352","flags":128,"ts_in_delta":919,"sequence":101583,"symbol":"FCEU SI 20260615 PS"}
{"ts_recv":"2026-04-07T00:38:08.783002606Z","hd":{"ts_event":"2026-04-07T00:38:08.782985281Z","rtype":160,"publisher_id":101,"instrument_id":436},"action":"A","side":"B","price":"1.157300000","size":20,"channel_id":23,"order_id":"10998894325637767567","flags":128,"ts_in_delta":892,"sequence":101667,"symbol":"FCEU SI 20260615 PS"}
{"ts_recv":"2026-04-07T00:38:08.783011999Z","hd":{"ts_event":"2026-04-07T00:38:08.783000489Z","rtype":160,"publisher_id":101,"instrument_id":436},"action":"C","side":"B","price":"1.157200000","size":20,"channel_id":23,"order_id":"10998894310288939352","flags":128,"ts_in_delta":857,"sequence":101668,"symbol":"FCEU SI 20260615 PS"}
{"ts_recv":"2026-04-07T00:38:29.078461603Z","hd":{"ts_event":"2026-04-07T00:38:29.078436333Z","rtype":160,"publisher_id":101,"instrument_id":436},"action":"C","side":"B","price":"1.157300000","size":20,"channel_id":23,"order_id":"10998894325637767567","flags":128,"ts_in_delta":1346,"sequence":101759,"symbol":"FCEU SI 20260615 PS"}
{"ts_recv":"2026-04-07T00:38:29.121817272Z","hd":{"ts_event":"2026-04-07T00:38:29.121801471Z","rtype":160,"publisher_id":101,"instrument_id":436},"action":"A","side":"B","price":"1.157200000","size":20,"channel_id":23,"order_id":"10998894345976583466","flags":128,"ts_in_delta":860,"sequence":101762,"symbol":"FCEU SI 20260615 PS"}
{"ts_recv":"2026-04-07T00:38:29.942407235Z","hd":{"ts_event":"2026-04-07T00:38:29.942389391Z","rtype":160,"publisher_id":101,"instrument_id":436},"action":"A","side":"B","price":"1.157300000","size":20,"channel_id":23,"order_id":"10998894346797171563","flags":128,"ts_in_delta":799,"sequence":101773,"symbol":"FCEU SI 20260615 PS"}
{"ts_recv":"2026-04-07T00:38:29.942416028Z","hd":{"ts_event":"2026-04-07T00:38:29.942402723Z","rtype":160,"publisher_id":101,"instrument_id":436},"action":"C","side":"B","price":"1.157200000","size":20,"channel_id":23,"order_id":"10998894345976583466","flags":128,"ts_in_delta":747,"sequence":101774,"symbol":"FCEU SI 20260615 PS"}
{"ts_recv":"2026-04-07T00:39:57.884760808Z","hd":{"ts_event":"2026-04-07T00:39:57.884745287Z","rtype":160,"publisher_id":101,"instrument_id":436},"action":"C","side":"B","price":"1.157300000","size":20,"channel_id":23,"order_id":"10998894346797171563","flags":128,"ts_in_delta":874,"sequence":102287,"symbol":"FCEU SI 20260615 PS"}
{"ts_recv":"2026-04-07T00:39:57.928741252Z","hd":{"ts_event":"2026-04-07T00:39:57.928724935Z","rtype":160,"publisher_id":101,"instrument_id":436},"action":"A","side":"B","price":"1.157200000","size":20,"channel_id":23,"order_id":"10998894434783506683","flags":128,"ts_in_delta":1000,"sequence":102290,"symbol":"FCEU SI 20260615 PS"}
{"ts_recv":"2026-04-07T00:39:57.997305822Z","hd":{"ts_event":"2026-04-07T00:39:57.997290689Z","rtype":160,"publisher_id":101,"instrument_id":436},"action":"A","side":"A","price":"1.157600000","size":20,"channel_id":23,"order_id":"1775522397997296637","flags":128,"ts_in_delta":974,"sequence":102303,"symbol":"FCEU SI 20260615 PS"}
{"ts_recv":"2026-04-07T00:39:57.997512904Z","hd":{"ts_event":"2026-04-07T00:39:57.997499031Z","rtype":160,"publisher_id":101,"instrument_id":436},"action":"C","side":"A","price":"1.157700000","size":20,"channel_id":23,"order_id":"1775522212184359578","flags":128,"ts_in_delta":1008,"sequence":102304,"symbol":"FCEU SI 20260615 PS"}
{"ts_recv":"2026-04-07T00:40:05.733794800Z","hd":{"ts_event":"2026-04-07T00:40:05.733771409Z","rtype":160,"publisher_id":101,"instrument_id":436},"action":"C","side":"A","price":"1.157600000","size":20,"channel_id":23,"order_id":"1775522397997296637","flags":128,"ts_in_delta":1164,"sequence":102406,"symbol":"FCEU SI 20260615 PS"}
{"ts_recv":"2026-04-07T00:40:05.777121486Z","hd":{"ts_event":"2026-04-07T00:40:05.777104523Z","rtype":160,"publisher_id":101,"instrument_id":436},"action":"A","side":"A","price":"1.157700000","size":20,"channel_id":23,"order_id":"1775522405777110790","flags":128,"ts_in_delta":1262,"sequence":102411,"symbol":"FCEU SI 20260615 PS"}
{"ts_recv":"2026-04-07T00:40:05.806906113Z","hd":{"ts_event":"2026-04-07T00:40:05.806890059Z","rtype":160,"publisher_id":101,"instrument_id":436},"action":"A","side":"B","price":"1.157300000","size":20,"channel_id":23,"order_id":"10998894442661672198","flags":128,"ts_in_delta":832,"sequence":102419,"symbol":"FCEU SI 20260615 PS"}
{"ts_recv":"2026-04-07T00:40:05.807000496Z","hd":{"ts_event":"2026-04-07T00:40:05.806987335Z","rtype":160,"publisher_id":101,"instrument_id":436},"action":"C","side":"B","price":"1.157200000","size":20,"channel_id":23,"order_id":"10998894434783506683","flags":128,"ts_in_delta":806,"sequence":102420,"symbol":"FCEU SI 20260615 PS"}
{"ts_recv":"2026-04-07T00:41:11.136358370Z","hd":{"ts_event":"2026-04-07T00:41:11.136339353Z","rtype":160,"publisher_id":101,"instrument_id":436},"action":"A","side":"B","price":"1.157400000","size":20,"channel_id":23,"order_id":"10998894507991121570","flags":128,"ts_in_delta":999,"sequence":102829,"symbol":"FCEU SI 20260615 PS"}
{"ts_recv":"2026-04-07T00:41:11.136368953Z","hd":{"ts_event":"2026-04-07T00:41:11.136355563Z","rtype":160,"publisher_id":101,"instrument_id":436},"action":"C","side":"B","price":"1.157300000","size":20,"channel_id":23,"order_id":"10998894442661672198","flags":128,"ts_in_delta":1008,"sequence":102830,"symbol":"FCEU SI 20260615 PS"}
{"ts_recv":"2026-04-07T00:41:11.206176015Z","hd":{"ts_event":"2026-04-07T00:41:11.206157947Z","rtype":160,"publisher_id":101,"instrument_id":436},"action":"C","side":"A","price":"1.157700000","size":20,"channel_id":23,"order_id":"1775522405777110790","flags":128,"ts_in_delta":909,"sequence":102831,"symbol":"FCEU SI 20260615 PS"}
{"ts_recv":"2026-04-07T00:41:11.249300545Z","hd":{"ts_event":"2026-04-07T00:41:11.249284831Z","rtype":160,"publisher_id":101,"instrument_id":436},"action":"A","side":"A","price":"1.157800000","size":20,"channel_id":23,"order_id":"1775522471249290730","flags":128,"ts_in_delta":848,"sequence":102837,"symbol":"FCEU SI 20260615 PS"}
{"ts_recv":"2026-04-07T00:43:03.556013558Z","hd":{"ts_event":"2026-04-07T00:43:03.555989511Z","rtype":160,"publisher_id":101,"instrument_id":436},"action":"C","side":"B","price":"1.157400000","size":20,"channel_id":23,"order_id":"10998894507991121570","flags":128,"ts_in_delta":1068,"sequence":103528,"symbol":"FCEU SI 20260615 PS"}
{"ts_recv":"2026-04-07T00:43:03.621377212Z","hd":{"ts_event":"2026-04-07T00:43:03.621351233Z","rtype":160,"publisher_id":101,"instrument_id":436},"action":"A","side":"B","price":"1.157400000","size":20,"channel_id":23,"order_id":"10998894620476138139","flags":128,"ts_in_delta":1121,"sequence":103529,"symbol":"FCEU SI 20260615 PS"}
{"ts_recv":"2026-04-07T00:43:32.262308141Z","hd":{"ts_event":"2026-04-07T00:43:32.262293485Z","rtype":160,"publisher_id":101,"instrument_id":436},"action":"C","side":"B","price":"1.157400000","size":20,"channel_id":23,"order_id":"10998894620476138139","flags":128,"ts_in_delta":931,"sequence":103708,"symbol":"FCEU SI 20260615 PS"}
{"ts_recv":"2026-04-07T00:43:32.304993013Z","hd":{"ts_event":"2026-04-07T00:43:32.304979357Z","rtype":160,"publisher_id":101,"instrument_id":436},"action":"A","side":"B","price":"1.157300000","size":20,"channel_id":23,"order_id":"10998894649159761179","flags":128,"ts_in_delta":818,"sequence":103712,"symbol":"FCEU SI 20260615 PS"}
{"ts_recv":"2026-04-07T00:43:41.707130901Z","hd":{"ts_event":"2026-04-07T00:43:41.707103793Z","rtype":160,"publisher_id":101,"instrument_id":436},"action":"A","side":"B","price":"1.157400000","size":20,"channel_id":23,"order_id":"10998894658561892495","flags":128,"ts_in_delta":1077,"sequence":103759,"symbol":"FCEU SI 20260615 PS"}
{"ts_recv":"2026-04-07T00:43:41.707155967Z","hd":{"ts_event":"2026-04-07T00:43:41.707143173Z","rtype":160,"publisher_id":101,"instrument_id":436},"action":"C","side":"B","price":"1.157300000","size":20,"channel_id":23,"order_id":"10998894649159761179","flags":128,"ts_in_delta":902,"sequence":103761,"symbol":"FCEU SI 20260615 PS"}
{"ts_recv":"2026-04-07T00:44:30.295765857Z","hd":{"ts_event":"2026-04-07T00:44:30.295750725Z","rtype":160,"publisher_id":101,"instrument_id":436},"action":"C","side":"B","price":"1.157400000","size":20,"channel_id":23,"order_id":"10998894658561892495","flags":128,"ts_in_delta":896,"sequence":103994,"symbol":"FCEU SI 20260615 PS"}
{"ts_recv":"2026-04-07T00:44:30.377387049Z","hd":{"ts_event":"2026-04-07T00:44:30.377370663Z","rtype":160,"publisher_id":101,"instrument_id":436},"action":"A","side":"B","price":"1.157400000","size":20,"channel_id":23,"order_id":"10998894707232152369","flags":128,"ts_in_delta":1009,"sequence":104000,"symbol":"FCEU SI 20260615 PS"}
{"ts_recv":"2026-04-07T00:44:37.759474975Z","hd":{"ts_event":"2026-04-07T00:44:37.759451615Z","rtype":160,"publisher_id":101,"instrument_id":436},"action":"C","side":"B","price":"1.157400000","size":20,"channel_id":23,"order_id":"10998894707232152369","flags":128,"ts_in_delta":1173,"sequence":104051,"symbol":"FCEU SI 20260615 PS"}
{"ts_recv":"2026-04-07T00:44:37.802080883Z","hd":{"ts_event":"2026-04-07T00:44:37.802059545Z","rtype":160,"publisher_id":101,"instrument_id":436},"action":"A","side":"B","price":"1.157300000","size":20,"channel_id":23,"order_id":"10998894714656846222","flags":128,"ts_in_delta":1238,"sequence":104052,"symbol":"FCEU SI 20260615 PS"}
{"ts_recv":"2026-04-07T00:44:37.850491330Z","hd":{"ts_event":"2026-04-07T00:44:37.850471615Z","rtype":160,"publisher_id":101,"instrument_id":436},"action":"A","side":"B","price":"1.157400000","size":20,"channel_id":23,"order_id":"10998894714705258189","flags":128,"ts_in_delta":964,"sequence":104053,"symbol":"FCEU SI 20260615 PS"}
{"ts_recv":"2026-04-07T00:44:37.850505875Z","hd":{"ts_event":"2026-04-07T00:44:37.850492267Z","rtype":160,"publisher_id":101,"instrument_id":436},"action":"C","side":"B","price":"1.157300000","size":20,"channel_id":23,"order_id":"10998894714656846222","flags":128,"ts_in_delta":1644,"sequence":104054,"symbol":"FCEU SI 20260615 PS"}
{"ts_recv":"2026-04-07T00:44:39.522468608Z","hd":{"ts_event":"2026-04-07T00:44:39.522448727Z","rtype":160,"publisher_id":101,"instrument_id":436},"action":"A","side":"A","price":"1.157700000","size":20,"channel_id":23,"order_id":"1775522679522457022","flags":128,"ts_in_delta":1074,"sequence":104072,"symbol":"FCEU SI 20260615 PS"}
{"ts_recv":"2026-04-07T00:44:39.522477900Z","hd":{"ts_event":"2026-04-07T00:44:39.522461471Z","rtype":160,"publisher_id":101,"instrument_id":436},"action":"C","side":"A","price":"1.157800000","size":20,"channel_id":23,"order_id":"1775522471249290730","flags":128,"ts_in_delta":1031,"sequence":104073,"symbol":"FCEU SI 20260615 PS"}
{"ts_recv":"2026-04-07T00:44:42.850757526Z","hd":{"ts_event":"2026-04-07T00:44:42.850738299Z","rtype":160,"publisher_id":101,"instrument_id":436},"action":"C","side":"B","price":"1.157400000","size":20,"channel_id":23,"order_id":"10998894714705258189","flags":128,"ts_in_delta":1596,"sequence":104095,"symbol":"FCEU SI 20260615 PS"}
{"ts_recv":"2026-04-07T00:44:42.892976537Z","hd":{"ts_event":"2026-04-07T00:44:42.892958963Z","rtype":160,"publisher_id":101,"instrument_id":436},"action":"A","side":"B","price":"1.157300000","size":20,"channel_id":23,"order_id":"10998894719747741371","flags":128,"ts_in_delta":1086,"sequence":104096,"symbol":"FCEU SI 20260615 PS"}
{"ts_recv":"2026-04-07T00:45:10.243701808Z","hd":{"ts_event":"2026-04-07T00:45:10.243684831Z","rtype":160,"publisher_id":101,"instrument_id":436},"action":"A","side":"B","price":"1.157400000","size":20,"channel_id":23,"order_id":"10998894747098466911","flags":128,"ts_in_delta":1432,"sequence":104268,"symbol":"FCEU SI 20260615 PS"}
{"ts_recv":"2026-04-07T00:45:10.243853565Z","hd":{"ts_event":"2026-04-07T00:45:10.243839761Z","rtype":160,"publisher_id":101,"instrument_id":436},"action":"C","side":"B","price":"1.157300000","size":20,"channel_id":23,"order_id":"10998894719747741371","flags":128,"ts_in_delta":1208,"sequence":104269,"symbol":"FCEU SI 20260615 PS"}
{"ts_recv":"2026-04-07T00:45:11.740904725Z","hd":{"ts_event":"2026-04-07T00:45:11.740879409Z","rtype":160,"publisher_id":101,"instrument_id":436},"action":"C","side":"A","price":"1.157700000","size":20,"channel_id":23,"order_id":"1775522679522457022","flags":128,"ts_in_delta":1401,"sequence":104280,"symbol":"FCEU SI 20260615 PS"}
{"ts_recv":"2026-04-07T00:45:11.784596630Z","hd":{"ts_event":"2026-04-07T00:45:11.784574699Z","rtype":160,"publisher_id":101,"instrument_id":436},"action":"A","side":"A","price":"1.157800000","size":20,"channel_id":23,"order_id":"1775522711784585715","flags":128,"ts_in_delta":1108,"sequence":104281,"symbol":"FCEU SI 20260615 PS"}
{"ts_recv":"2026-04-07T00:46:23.167481205Z","hd":{"ts_event":"2026-04-07T00:46:23.167457917Z","rtype":160,"publisher_id":101,"instrument_id":436},"action":"C","side":"B","price":"1.157400000","size":20,"channel_id":23,"order_id":"10998894747098466911","flags":128,"ts_in_delta":1337,"sequence":104746,"symbol":"FCEU SI 20260615 PS"}
{"ts_recv":"2026-04-07T00:46:23.210625390Z","hd":{"ts_event":"2026-04-07T00:46:23.210600091Z","rtype":160,"publisher_id":101,"instrument_id":436},"action":"A","side":"B","price":"1.157300000","size":20,"channel_id":23,"order_id":"10998894820065387055","flags":128,"ts_in_delta":872,"sequence":104753,"symbol":"FCEU SI 20260615 PS"}
{"ts_recv":"2026-04-07T00:46:25.350210784Z","hd":{"ts_event":"2026-04-07T00:46:25.350185181Z","rtype":160,"publisher_id":101,"instrument_id":436},"action":"A","side":"B","price":"1.157400000","size":20,"channel_id":23,"order_id":"10998894822204973836","flags":128,"ts_in_delta":1230,"sequence":104778,"symbol":"FCEU SI 20260615 PS"}
{"ts_recv":"2026-04-07T00:46:25.350214455Z","hd":{"ts_event":"2026-04-07T00:46:25.350198865Z","rtype":160,"publisher_id":101,"instrument_id":436},"action":"C","side":"B","price":"1.157300000","size":20,"channel_id":23,"order_id":"10998894820065387055","flags":128,"ts_in_delta":955,"sequence":104779,"symbol":"FCEU SI 20260615 PS"}
{"ts_recv":"2026-04-07T00:46:33.025829781Z","hd":{"ts_event":"2026-04-07T00:46:33.025816131Z","rtype":160,"publisher_id":101,"instrument_id":436},"action":"C","side":"B","price":"1.157400000","size":20,"channel_id":23,"order_id":"10998894822204973836","flags":128,"ts_in_delta":868,"sequence":104831,"symbol":"FCEU SI 20260615 PS"}
{"ts_recv":"2026-04-07T00:46:33.068590890Z","hd":{"ts_event":"2026-04-07T00:46:33.068576311Z","rtype":160,"publisher_id":101,"instrument_id":436},"action":"A","side":"B","price":"1.157300000","size":20,"channel_id":23,"order_id":"10998894829923357929","flags":128,"ts_in_delta":924,"sequence":104835,"symbol":"FCEU SI 20260615 PS"}
{"ts_recv":"2026-04-07T00:46:43.311373679Z","hd":{"ts_event":"2026-04-07T00:46:43.311359689Z","rtype":160,"publisher_id":101,"instrument_id":436},"action":"A","side":"B","price":"1.157400000","size":20,"channel_id":23,"order_id":"10998894840166141558","flags":128,"ts_in_delta":1264,"sequence":104891,"symbol":"FCEU SI 20260615 PS"}
{"ts_recv":"2026-04-07T00:46:43.311422729Z","hd":{"ts_event":"2026-04-07T00:46:43.311409649Z","rtype":160,"publisher_id":101,"instrument_id":436},"action":"C","side":"B","price":"1.157300000","size":20,"channel_id":23,"order_id":"10998894829923357929","flags":128,"ts_in_delta":928,"sequence":104893,"symbol":"FCEU SI 20260615 PS"}
{"ts_recv":"2026-04-07T00:46:54.595486243Z","hd":{"ts_event":"2026-04-07T00:46:54.595472889Z","rtype":160,"publisher_id":101,"instrument_id":436},"action":"C","side":"B","price":"1.157400000","size":20,"channel_id":23,"order_id":"10998894840166141558","flags":128,"ts_in_delta":978,"sequence":104941,"symbol":"FCEU SI 20260615 PS"}
{"ts_recv":"2026-04-07T00:46:54.639412276Z","hd":{"ts_event":"2026-04-07T00:46:54.639389559Z","rtype":160,"publisher_id":101,"instrument_id":436},"action":"A","side":"B","price":"1.157300000","size":20,"channel_id":23,"order_id":"10998894851494176365","flags":128,"ts_in_delta":857,"sequence":104944,"symbol":"FCEU SI 20260615 PS"}
{"ts_recv":"2026-04-07T00:47:25.997644775Z","hd":{"ts_event":"2026-04-07T00:47:25.997623527Z","rtype":160,"publisher_id":101,"instrument_id":436},"action":"A","side":"B","price":"1.157400000","size":20,"channel_id":23,"order_id":"10998894882852407539","flags":128,"ts_in_delta":1276,"sequence":105153,"symbol":"FCEU SI 20260615 PS"}
{"ts_recv":"2026-04-07T00:47:25.997658714Z","hd":{"ts_event":"2026-04-07T00:47:25.997646243Z","rtype":160,"publisher_id":101,"instrument_id":436},"action":"C","side":"B","price":"1.157300000","size":20,"channel_id":23,"order_id":"10998894851494176365","flags":128,"ts_in_delta":965,"sequence":105154,"symbol":"FCEU SI 20260615 PS"}
{"ts_recv":"2026-04-07T00:47:35.072647711Z","hd":{"ts_event":"2026-04-07T00:47:35.072634565Z","rtype":160,"publisher_id":101,"instrument_id":436},"action":"C","side":"B","price":"1.157400000","size":20,"channel_id":23,"order_id":"10998894882852407539","flags":128,"ts_in_delta":861,"sequence":105212,"symbol":"FCEU SI 20260615 PS"}
{"ts_recv":"2026-04-07T00:47:35.115403892Z","hd":{"ts_event":"2026-04-07T00:47:35.115389357Z","rtype":160,"publisher_id":101,"instrument_id":436},"action":"A","side":"B","price":"1.157300000","size":20,"channel_id":23,"order_id":"10998894891970171298","flags":128,"ts_in_delta":846,"sequence":105214,"symbol":"FCEU SI 20260615 PS"}
{"ts_recv":"2026-04-07T00:47:36.744144053Z","hd":{"ts_event":"2026-04-07T00:47:36.744131239Z","rtype":160,"publisher_id":101,"instrument_id":436},"action":"A","side":"B","price":"1.157400000","size":20,"channel_id":23,"order_id":"10998894893598913168","flags":128,"ts_in_delta":873,"sequence":105232,"symbol":"FCEU SI 20260615 PS"}
{"ts_recv":"2026-04-07T00:47:36.744189670Z","hd":{"ts_event":"2026-04-07T00:47:36.744178393Z","rtype":160,"publisher_id":101,"instrument_id":436},"action":"C","side":"B","price":"1.157300000","size":20,"channel_id":23,"order_id":"10998894891970171298","flags":128,"ts_in_delta":787,"sequence":105234,"symbol":"FCEU SI 20260615 PS"}
{"ts_recv":"2026-04-07T00:47:59.655736344Z","hd":{"ts_event":"2026-04-07T00:47:59.655722025Z","rtype":160,"publisher_id":101,"instrument_id":436},"action":"C","side":"B","price":"1.157400000","size":20,"channel_id":23,"order_id":"10998894893598913168","flags":128,"ts_in_delta":909,"sequence":105353,"symbol":"FCEU SI 20260615 PS"}
{"ts_recv":"2026-04-07T00:47:59.698781852Z","hd":{"ts_event":"2026-04-07T00:47:59.698760649Z","rtype":160,"publisher_id":101,"instrument_id":436},"action":"A","side":"B","price":"1.157300000","size":20,"channel_id":23,"order_id":"10998894916553547438","flags":128,"ts_in_delta":1162,"sequence":105354,"symbol":"FCEU SI 20260615 PS"}
{"ts_recv":"2026-04-07T00:48:03.738171071Z","hd":{"ts_event":"2026-04-07T00:48:03.738141175Z","rtype":160,"publisher_id":101,"instrument_id":436},"action":"A","side":"B","price":"1.157400000","size":20,"channel_id":23,"order_id":"10998894920592930994","flags":128,"ts_in_delta":1226,"sequence":105387,"symbol":"FCEU SI 20260615 PS"}
{"ts_recv":"2026-04-07T00:48:03.738174596Z","hd":{"ts_event":"2026-04-07T00:48:03.738150335Z","rtype":160,"publisher_id":101,"instrument_id":436},"action":"C","side":"B","price":"1.157300000","size":20,"channel_id":23,"order_id":"10998894916553547438","flags":128,"ts_in_delta":612,"sequence":105388,"symbol":"FCEU SI 20260615 PS"}
{"ts_recv":"2026-04-07T00:50:33.834910597Z","hd":{"ts_event":"2026-04-07T00:50:33.834893015Z","rtype":160,"publisher_id":101,"instrument_id":436},"action":"C","side":"B","price":"1.157400000","size":20,"channel_id":23,"order_id":"10998894920592930994","flags":128,"ts_in_delta":915,"sequence":106303,"symbol":"FCEU SI 20260615 PS"}
{"ts_recv":"2026-04-07T00:50:33.898601963Z","hd":{"ts_event":"2026-04-07T00:50:33.898583949Z","rtype":160,"publisher_id":101,"instrument_id":436},"action":"A","side":"B","price":"1.157400000","size":20,"channel_id":23,"order_id":"10998895070753366069","flags":128,"ts_in_delta":1051,"sequence":106316,"symbol":"FCEU SI 20260615 PS"}
{"ts_recv":"2026-04-07T00:52:55.937632682Z","hd":{"ts_event":"2026-04-07T00:52:55.937614573Z","rtype":160,"publisher_id":101,"instrument_id":436},"action":"C","side":"A","price":"1.157800000","size":20,"channel_id":23,"order_id":"1775522711784585715","flags":128,"ts_in_delta":870,"sequence":107242,"symbol":"FCEU SI 20260615 PS"}
{"ts_recv":"2026-04-07T00:52:55.978349023Z","hd":{"ts_event":"2026-04-07T00:52:55.978328525Z","rtype":160,"publisher_id":101,"instrument_id":436},"action":"A","side":"B","price":"1.157500000","size":20,"channel_id":23,"order_id":"10998895212833110406","flags":128,"ts_in_delta":654,"sequence":107251,"symbol":"FCEU SI 20260615 PS"}
{"ts_recv":"2026-04-07T00:52:55.978524142Z","hd":{"ts_event":"2026-04-07T00:52:55.978510209Z","rtype":160,"publisher_id":101,"instrument_id":436},"action":"C","side":"B","price":"1.157400000","size":20,"channel_id":23,"order_id":"10998895070753366069","flags":128,"ts_in_delta":710,"sequence":107252,"symbol":"FCEU SI 20260615 PS"}
{"ts_recv":"2026-04-07T00:52:55.981383944Z","hd":{"ts_event":"2026-04-07T00:52:55.981369591Z","rtype":160,"publisher_id":101,"instrument_id":436},"action":"A","side":"A","price":"1.157900000","size":20,"channel_id":23,"order_id":"1775523175981375356","flags":128,"ts_in_delta":647,"sequence":107255,"symbol":"FCEU SI 20260615 PS"}
{"ts_recv":"2026-04-07T00:53:06.976875243Z","hd":{"ts_event":"2026-04-07T00:53:06.976860225Z","rtype":160,"publisher_id":101,"instrument_id":436},"action":"C","side":"B","price":"1.157500000","size":20,"channel_id":23,"order_id":"10998895212833110406","flags":128,"ts_in_delta":796,"sequence":107341,"symbol":"FCEU SI 20260615 PS"}
{"ts_recv":"2026-04-07T00:53:07.019392982Z","hd":{"ts_event":"2026-04-07T00:53:07.019375423Z","rtype":160,"publisher_id":101,"instrument_id":436},"action":"A","side":"B","price":"1.157400000","size":20,"channel_id":23,"order_id":"10998895223874157541","flags":128,"ts_in_delta":820,"sequence":107350,"symbol":"FCEU SI 20260615 PS"}
{"ts_recv":"2026-04-07T00:53:10.968856749Z","hd":{"ts_event":"2026-04-07T00:53:10.968829695Z","rtype":160,"publisher_id":101,"instrument_id":436},"action":"A","side":"B","price":"1.157500000","size":20,"channel_id":23,"order_id":"10998895227823618790","flags":128,"ts_in_delta":1412,"sequence":107375,"symbol":"FCEU SI 20260615 PS"}
{"ts_recv":"2026-04-07T00:53:10.969188525Z","hd":{"ts_event":"2026-04-07T00:53:10.969176633Z","rtype":160,"publisher_id":101,"instrument_id":436},"action":"C","side":"B","price":"1.157400000","size":20,"channel_id":23,"order_id":"10998895223874157541","flags":128,"ts_in_delta":844,"sequence":107376,"symbol":"FCEU SI 20260615 PS"}
{"ts_recv":"2026-04-07T00:53:16.777240611Z","hd":{"ts_event":"2026-04-07T00:53:16.777215583Z","rtype":160,"publisher_id":101,"instrument_id":436},"action":"C","side":"B","price":"1.157500000","size":20,"channel_id":23,"order_id":"10998895227823618790","flags":128,"ts_in_delta":1422,"sequence":107434,"symbol":"FCEU SI 20260615 PS"}
{"ts_recv":"2026-04-07T00:53:16.819566816Z","hd":{"ts_event":"2026-04-07T00:53:16.819548247Z","rtype":160,"publisher_id":101,"instrument_id":436},"action":"A","side":"B","price":"1.157400000","size":20,"channel_id":23,"order_id":"10998895233674335052","flags":128,"ts_in_delta":913,"sequence":107435,"symbol":"FCEU SI 20260615 PS"}
{"ts_recv":"2026-04-07T00:53:33.548411768Z","hd":{"ts_event":"2026-04-07T00:53:33.548395381Z","rtype":160,"publisher_id":101,"instrument_id":436},"action":"A","side":"A","price":"1.157800000","size":20,"channel_id":23,"order_id":"1775523213548401319","flags":128,"ts_in_delta":590,"sequence":107511,"symbol":"FCEU SI 20260615 PS"}
{"ts_recv":"2026-04-07T00:53:33.548477874Z","hd":{"ts_event":"2026-04-07T00:53:33.548463895Z","rtype":160,"publisher_id":101,"instrument_id":436},"action":"C","side":"A","price":"1.157900000","size":20,"channel_id":23,"order_id":"1775523175981375356","flags":128,"ts_in_delta":820,"sequence":107514,"symbol":"FCEU SI 20260615 PS"}
{"ts_recv":"2026-04-07T00:53:37.761376813Z","hd":{"ts_event":"2026-04-07T00:53:37.761350413Z","rtype":160,"publisher_id":101,"instrument_id":436},"action":"A","side":"B","price":"1.157500000","size":20,"channel_id":23,"order_id":"10998895254616142353","flags":128,"ts_in_delta":950,"sequence":107550,"symbol":"FCEU SI 20260615 PS"}
{"ts_recv":"2026-04-07T00:53:37.761419243Z","hd":{"ts_event":"2026-04-07T00:53:37.761405145Z","rtype":160,"publisher_id":101,"instrument_id":436},"action":"C","side":"B","price":"1.157400000","size":20,"channel_id":23,"order_id":"10998895233674335052","flags":128,"ts_in_delta":860,"sequence":107552,"symbol":"FCEU SI 20260615 PS"}
{"ts_recv":"2026-04-07T00:53:52.608700466Z","hd":{"ts_event":"2026-04-07T00:53:52.608677813Z","rtype":160,"publisher_id":101,"instrument_id":436},"action":"C","side":"A","price":"1.157800000","size":20,"channel_id":23,"order_id":"1775523213548401319","flags":128,"ts_in_delta":1527,"sequence":107655,"symbol":"FCEU SI 20260615 PS"}
{"ts_recv":"2026-04-07T00:53:52.613773403Z","hd":{"ts_event":"2026-04-07T00:53:52.613759771Z","rtype":160,"publisher_id":101,"instrument_id":436},"action":"C","side":"B","price":"1.157500000","size":20,"channel_id":23,"order_id":"10998895254616142353","flags":128,"ts_in_delta":855,"sequence":107660,"symbol":"FCEU SI 20260615 PS"}
{"ts_recv":"2026-04-07T00:53:52.652249344Z","hd":{"ts_event":"2026-04-07T00:53:52.652230915Z","rtype":160,"publisher_id":101,"instrument_id":436},"action":"A","side":"A","price":"1.157900000","size":20,"channel_id":23,"order_id":"1775523232652238627","flags":128,"ts_in_delta":1051,"sequence":107663,"symbol":"FCEU SI 20260615 PS"}
{"ts_recv":"2026-04-07T00:53:52.673691842Z","hd":{"ts_event":"2026-04-07T00:53:52.673678169Z","rtype":160,"publisher_id":101,"instrument_id":436},"action":"A","side":"B","price":"1.157500000","size":20,"channel_id":23,"order_id":"10998895269528459819","flags":128,"ts_in_delta":822,"sequence":107669,"symbol":"FCEU SI 20260615 PS"}
{"ts_recv":"2026-04-07T00:54:02.312672245Z","hd":{"ts_event":"2026-04-07T00:54:02.312660435Z","rtype":160,"publisher_id":101,"instrument_id":436},"action":"C","side":"B","price":"1.157500000","size":20,"channel_id":23,"order_id":"10998895269528459819","flags":128,"ts_in_delta":791,"sequence":107729,"symbol":"FCEU SI 20260615 PS"}
{"ts_recv":"2026-04-07T00:54:02.356007207Z","hd":{"ts_event":"2026-04-07T00:54:02.355991743Z","rtype":160,"publisher_id":101,"instrument_id":436},"action":"A","side":"B","price":"1.157500000","size":20,"channel_id":23,"order_id":"10998895279210773613","flags":128,"ts_in_delta":953,"sequence":107732,"symbol":"FCEU SI 20260615 PS"}
{"ts_recv":"2026-04-07T00:54:27.673943410Z","hd":{"ts_event":"2026-04-07T00:54:27.673919827Z","rtype":160,"publisher_id":101,"instrument_id":436},"action":"C","side":"B","price":"1.157500000","size":20,"channel_id":23,"order_id":"10998895279210773613","flags":128,"ts_in_delta":1158,"sequence":107961,"symbol":"FCEU SI 20260615 PS"}
{"ts_recv":"2026-04-07T00:54:27.718026799Z","hd":{"ts_event":"2026-04-07T00:54:27.718004055Z","rtype":160,"publisher_id":101,"instrument_id":436},"action":"A","side":"B","price":"1.157400000","size":20,"channel_id":23,"order_id":"10998895304572790663","flags":128,"ts_in_delta":776,"sequence":107966,"symbol":"FCEU SI 20260615 PS"}
{"ts_recv":"2026-04-07T00:54:32.709938703Z","hd":{"ts_event":"2026-04-07T00:54:32.709923363Z","rtype":160,"publisher_id":101,"instrument_id":436},"action":"A","side":"B","price":"1.157500000","size":20,"channel_id":23,"order_id":"10998895309564705504","flags":128,"ts_in_delta":962,"sequence":107993,"symbol":"FCEU SI 20260615 PS"}
{"ts_recv":"2026-04-07T00:54:32.710188891Z","hd":{"ts_event":"2026-04-07T00:54:32.710175161Z","rtype":160,"publisher_id":101,"instrument_id":436},"action":"C","side":"B","price":"1.157400000","size":20,"channel_id":23,"order_id":"10998895304572790663","flags":128,"ts_in_delta":913,"sequence":107994,"symbol":"FCEU SI 20260615 PS"}
{"ts_recv":"2026-04-07T00:54:37.709568181Z","hd":{"ts_event":"2026-04-07T00:54:37.709547689Z","rtype":160,"publisher_id":101,"instrument_id":436},"action":"C","side":"B","price":"1.157500000","size":20,"channel_id":23,"order_id":"10998895309564705504","flags":128,"ts_in_delta":997,"sequence":108054,"symbol":"FCEU SI 20260615 PS"}
{"ts_recv":"2026-04-07T00:54:37.752951279Z","hd":{"ts_event":"2026-04-07T00:54:37.752933339Z","rtype":160,"publisher_id":101,"instrument_id":436},"action":"A","side":"B","price":"1.157400000","size":20,"channel_id":23,"order_id":"10998895314607715737","flags":128,"ts_in_delta":1531,"sequence":108056,"symbol":"FCEU SI 20260615 PS"}
{"ts_recv":"2026-04-07T00:54:40.661403406Z","hd":{"ts_event":"2026-04-07T00:54:40.661380535Z","rtype":160,"publisher_id":101,"instrument_id":436},"action":"A","side":"A","price":"1.157800000","size":20,"channel_id":23,"order_id":"1775523280661391418","flags":128,"ts_in_delta":1039,"sequence":108080,"symbol":"FCEU SI 20260615 PS"}
{"ts_recv":"2026-04-07T00:54:40.661464866Z","hd":{"ts_event":"2026-04-07T00:54:40.661451865Z","rtype":160,"publisher_id":101,"instrument_id":436},"action":"C","side":"A","price":"1.157900000","size":20,"channel_id":23,"order_id":"1775523232652238627","flags":128,"ts_in_delta":1003,"sequence":108081,"symbol":"FCEU SI 20260615 PS"}
{"ts_recv":"2026-04-07T00:54:54.187471115Z","hd":{"ts_event":"2026-04-07T00:54:54.187457335Z","rtype":160,"publisher_id":101,"instrument_id":436},"action":"C","side":"B","price":"1.157400000","size":20,"channel_id":23,"order_id":"10998895314607715737","flags":128,"ts_in_delta":901,"sequence":108224,"symbol":"FCEU SI 20260615 PS"}
{"ts_recv":"2026-04-07T00:54:54.233391424Z","hd":{"ts_event":"2026-04-07T00:54:54.233375619Z","rtype":160,"publisher_id":101,"instrument_id":436},"action":"A","side":"B","price":"1.157400000","size":20,"channel_id":23,"order_id":"10998895331088157741","flags":128,"ts_in_delta":1198,"sequence":108226,"symbol":"FCEU SI 20260615 PS"}
{"ts_recv":"2026-04-07T00:54:59.744811458Z","hd":{"ts_event":"2026-04-07T00:54:59.744797725Z","rtype":160,"publisher_id":101,"instrument_id":436},"action":"C","side":"B","price":"1.157400000","size":20,"channel_id":23,"order_id":"10998895331088157741","flags":128,"ts_in_delta":823,"sequence":108285,"symbol":"FCEU SI 20260615 PS"}
{"ts_recv":"2026-04-07T00:54:59.808361340Z","hd":{"ts_event":"2026-04-07T00:54:59.808346251Z","rtype":160,"publisher_id":101,"instrument_id":436},"action":"A","side":"B","price":"1.157400000","size":20,"channel_id":23,"order_id":"10998895336663128043","flags":128,"ts_in_delta":945,"sequence":108291,"symbol":"FCEU SI 20260615 PS"}
{"ts_recv":"2026-04-07T00:56:22.056636422Z","hd":{"ts_event":"2026-04-07T00:56:22.056619119Z","rtype":160,"publisher_id":101,"instrument_id":436},"action":"C","side":"B","price":"1.157400000","size":20,"channel_id":23,"order_id":"10998895336663128043","flags":128,"ts_in_delta":882,"sequence":108876,"symbol":"FCEU SI 20260615 PS"}
{"ts_recv":"2026-04-07T00:56:22.099473036Z","hd":{"ts_event":"2026-04-07T00:56:22.099454827Z","rtype":160,"publisher_id":101,"instrument_id":436},"action":"A","side":"B","price":"1.157300000","size":20,"channel_id":23,"order_id":"10998895418954237085","flags":128,"ts_in_delta":1153,"sequence":108883,"symbol":"FCEU SI 20260615 PS"}
{"ts_recv":"2026-04-07T00:56:23.295516744Z","hd":{"ts_event":"2026-04-07T00:56:23.295499775Z","rtype":160,"publisher_id":101,"instrument_id":436},"action":"A","side":"A","price":"1.157700000","size":20,"channel_id":23,"order_id":"1775523383295506127","flags":128,"ts_in_delta":862,"sequence":108939,"symbol":"FCEU SI 20260615 PS"}
{"ts_recv":"2026-04-07T00:56:23.295911294Z","hd":{"ts_event":"2026-04-07T00:56:23.295897871Z","rtype":160,"publisher_id":101,"instrument_id":436},"action":"C","side":"A","price":"1.157800000","size":20,"channel_id":23,"order_id":"1775523280661391418","flags":128,"ts_in_delta":860,"sequence":108940,"symbol":"FCEU SI 20260615 PS"}
{"ts_recv":"2026-04-07T00:56:53.329640306Z","hd":{"ts_event":"2026-04-07T00:56:53.329621159Z","rtype":160,"publisher_id":101,"instrument_id":436},"action":"A","side":"B","price":"1.157400000","size":20,"channel_id":23,"order_id":"10998895450184404299","flags":128,"ts_in_delta":820,"sequence":109198,"symbol":"FCEU SI 20260615 PS"}
{"ts_recv":"2026-04-07T00:56:53.329677683Z","hd":{"ts_event":"2026-04-07T00:56:53.329666189Z","rtype":160,"publisher_id":101,"instrument_id":436},"action":"C","side":"B","price":"1.157300000","size":20,"channel_id":23,"order_id":"10998895418954237085","flags":128,"ts_in_delta":953,"sequence":109199,"symbol":"FCEU SI 20260615 PS"}
{"ts_recv":"2026-04-07T00:56:59.636283552Z","hd":{"ts_event":"2026-04-07T00:56:59.636263423Z","rtype":160,"publisher_id":101,"instrument_id":436},"action":"C","side":"B","price":"1.157400000","size":20,"channel_id":23,"order_id":"10998895450184404299","flags":128,"ts_in_delta":1302,"sequence":109250,"symbol":"FCEU SI 20260615 PS"}
{"ts_recv":"2026-04-07T00:56:59.679595639Z","hd":{"ts_event":"2026-04-07T00:56:59.679574031Z","rtype":160,"publisher_id":101,"instrument_id":436},"action":"A","side":"B","price":"1.157300000","size":20,"channel_id":23,"order_id":"10998895456534361092","flags":128,"ts_in_delta":1553,"sequence":109251,"symbol":"FCEU SI 20260615 PS"}
{"ts_recv":"2026-04-07T00:58:56.014279429Z","hd":{"ts_event":"2026-04-07T00:58:56.014261753Z","rtype":160,"publisher_id":101,"instrument_id":436},"action":"C","side":"B","price":"1.157300000","size":20,"channel_id":23,"order_id":"10998895456534361092","flags":128,"ts_in_delta":871,"sequence":109961,"symbol":"FCEU SI 20260615 PS"}
{"ts_recv":"2026-04-07T00:58:56.081673916Z","hd":{"ts_event":"2026-04-07T00:58:56.081656507Z","rtype":160,"publisher_id":101,"instrument_id":436},"action":"A","side":"B","price":"1.157300000","size":20,"channel_id":23,"order_id":"10998895572936438261","flags":128,"ts_in_delta":1378,"sequence":109973,"symbol":"FCEU SI 20260615 PS"}
{"ts_recv":"2026-04-07T00:59:20.834055898Z","hd":{"ts_event":"2026-04-07T00:59:20.834041017Z","rtype":160,"publisher_id":101,"instrument_id":436},"action":"C","side":"B","price":"1.157300000","size":20,"channel_id":23,"order_id":"10998895572936438261","flags":128,"ts_in_delta":861,"sequence":110121,"symbol":"FCEU SI 20260615 PS"}
{"ts_recv":"2026-04-07T00:59:20.892431245Z","hd":{"ts_event":"2026-04-07T00:59:20.892414227Z","rtype":160,"publisher_id":101,"instrument_id":436},"action":"A","side":"B","price":"1.157300000","size":20,"channel_id":23,"order_id":"10998895597747196032","flags":128,"ts_in_delta":1007,"sequence":110132,"symbol":"FCEU SI 20260615 PS"}
{"ts_recv":"2026-04-07T00:59:59.054269484Z","hd":{"ts_event":"2026-04-07T00:59:59.054254873Z","rtype":160,"publisher_id":101,"instrument_id":436},"action":"C","side":"B","price":"1.157300000","size":20,"channel_id":23,"order_id":"10998895597747196032","flags":128,"ts_in_delta":814,"sequence":110325,"symbol":"FCEU SI 20260615 PS"}
{"ts_recv":"2026-04-07T00:59:59.141573575Z","hd":{"ts_event":"2026-04-07T00:59:59.141559291Z","rtype":160,"publisher_id":101,"instrument_id":436},"action":"A","side":"B","price":"1.157300000","size":20,"channel_id":23,"order_id":"10998895635996341018","flags":128,"ts_in_delta":1213,"sequence":110338,"symbol":"FCEU SI 20260615 PS"}
{"ts_recv":"2026-04-07T01:00:02.487601520Z","hd":{"ts_event":"2026-04-07T01:00:02.487583393Z","rtype":160,"publisher_id":101,"instrument_id":436},"action":"A","side":"A","price":"1.157600000","size":20,"channel_id":23,"order_id":"1775523602487589530","flags":128,"ts_in_delta":1154,"sequence":110412,"symbol":"FCEU SI 20260615 PS"}
{"ts_recv":"2026-04-07T01:00:02.487618815Z","hd":{"ts_event":"2026-04-07T01:00:02.487604695Z","rtype":160,"publisher_id":101,"instrument_id":436},"action":"C","side":"A","price":"1.157700000","size":20,"channel_id":23,"order_id":"1775523383295506127","flags":128,"ts_in_delta":942,"sequence":110413,"symbol":"FCEU SI 20260615 PS"}
{"ts_recv":"2026-04-07T01:00:02.611662097Z","hd":{"ts_event":"2026-04-07T01:00:02.611649065Z","rtype":160,"publisher_id":101,"instrument_id":436},"action":"C","side":"B","price":"1.157300000","size":20,"channel_id":23,"order_id":"10998895635996341018","flags":128,"ts_in_delta":1036,"sequence":110428,"symbol":"FCEU SI 20260615 PS"}
{"ts_recv":"2026-04-07T01:00:02.656879880Z","hd":{"ts_event":"2026-04-07T01:00:02.656865803Z","rtype":160,"publisher_id":101,"instrument_id":436},"action":"A","side":"B","price":"1.157100000","size":20,"channel_id":23,"order_id":"10998895639511647600","flags":128,"ts_in_delta":730,"sequence":110438,"symbol":"FCEU SI 20260615 PS"}
{"ts_recv":"2026-04-07T01:00:02.738247232Z","hd":{"ts_event":"2026-04-07T01:00:02.738233095Z","rtype":160,"publisher_id":101,"instrument_id":436},"action":"A","side":"A","price":"1.157500000","size":20,"channel_id":23,"order_id":"1775523602738239633","flags":128,"ts_in_delta":737,"sequence":110457,"symbol":"FCEU SI 20260615 PS"}
{"ts_recv":"2026-04-07T01:00:02.738723601Z","hd":{"ts_event":"2026-04-07T01:00:02.738709547Z","rtype":160,"publisher_id":101,"instrument_id":436},"action":"C","side":"A","price":"1.157600000","size":20,"channel_id":23,"order_id":"1775523602487589530","flags":128,"ts_in_delta":903,"sequence":110458,"symbol":"FCEU SI 20260615 PS"}
{"ts_recv":"2026-04-07T01:00:08.113349981Z","hd":{"ts_event":"2026-04-07T01:00:08.113336403Z","rtype":160,"publisher_id":101,"instrument_id":436},"action":"C","side":"A","price":"1.157500000","size":20,"channel_id":23,"order_id":"1775523602738239633","flags":128,"ts_in_delta":989,"sequence":110593,"symbol":"FCEU SI 20260615 PS"}
{"ts_recv":"2026-04-07T01:00:08.156235379Z","hd":{"ts_event":"2026-04-07T01:00:08.156220529Z","rtype":160,"publisher_id":101,"instrument_id":436},"action":"A","side":"A","price":"1.157600000","size":20,"channel_id":23,"order_id":"1775523608156226458","flags":128,"ts_in_delta":831,"sequence":110595,"symbol":"FCEU SI 20260615 PS"}
{"ts_recv":"2026-04-07T01:00:08.281474833Z","hd":{"ts_event":"2026-04-07T01:00:08.281460203Z","rtype":160,"publisher_id":101,"instrument_id":436},"action":"A","side":"B","price":"1.157200000","size":20,"channel_id":23,"order_id":"10998895645136242060","flags":128,"ts_in_delta":1220,"sequence":110599,"symbol":"FCEU SI 20260615 PS"}
{"ts_recv":"2026-04-07T01:00:08.281509883Z","hd":{"ts_event":"2026-04-07T01:00:08.281495711Z","rtype":160,"publisher_id":101,"instrument_id":436},"action":"C","side":"B","price":"1.157100000","size":20,"channel_id":23,"order_id":"10998895639511647600","flags":128,"ts_in_delta":1070,"sequence":110600,"symbol":"FCEU SI 20260615 PS"}
{"ts_recv":"2026-04-07T01:00:28.120916037Z","hd":{"ts_event":"2026-04-07T01:00:28.120891223Z","rtype":160,"publisher_id":101,"instrument_id":436},"action":"C","side":"A","price":"1.157600000","size":20,"channel_id":23,"order_id":"1775523608156226458","flags":128,"ts_in_delta":1485,"sequence":110846,"symbol":"FCEU SI 20260615 PS"}
{"ts_recv":"2026-04-07T01:00:28.163294934Z","hd":{"ts_event":"2026-04-07T01:00:28.163279943Z","rtype":160,"publisher_id":101,"instrument_id":436},"action":"A","side":"A","price":"1.157700000","size":20,"channel_id":23,"order_id":"1775523628163285955","flags":128,"ts_in_delta":880,"sequence":110852,"symbol":"FCEU SI 20260615 PS"}
{"ts_recv":"2026-04-07T01:00:28.174792996Z","hd":{"ts_event":"2026-04-07T01:00:28.174777417Z","rtype":160,"publisher_id":101,"instrument_id":436},"action":"A","side":"B","price":"1.157300000","size":20,"channel_id":23,"order_id":"10998895665029559038","flags":128,"ts_in_delta":865,"sequence":110855,"symbol":"FCEU SI 20260615 PS"}
{"ts_recv":"2026-04-07T01:00:28.175399174Z","hd":{"ts_event":"2026-04-07T01:00:28.175385863Z","rtype":160,"publisher_id":101,"instrument_id":436},"action":"C","side":"B","price":"1.157200000","size":20,"channel_id":23,"order_id":"10998895645136242060","flags":128,"ts_in_delta":693,"sequence":110857,"symbol":"FCEU SI 20260615 PS"}
{"ts_recv":"2026-04-07T01:00:50.057105230Z","hd":{"ts_event":"2026-04-07T01:00:50.057091393Z","rtype":160,"publisher_id":101,"instrument_id":436},"action":"C","side":"B","price":"1.157300000","size":20,"channel_id":23,"order_id":"10998895665029559038","flags":128,"ts_in_delta":872,"sequence":111107,"symbol":"FCEU SI 20260615 PS"}
{"ts_recv":"2026-04-07T01:00:50.124406172Z","hd":{"ts_event":"2026-04-07T01:00:50.124389847Z","rtype":160,"publisher_id":101,"instrument_id":436},"action":"A","side":"B","price":"1.157300000","size":20,"channel_id":23,"order_id":"10998895686979171860","flags":128,"ts_in_delta":1020,"sequence":111116,"symbol":"FCEU SI 20260615 PS"}
{"ts_recv":"2026-04-07T01:00:55.744238087Z","hd":{"ts_event":"2026-04-07T01:00:55.744213267Z","rtype":160,"publisher_id":101,"instrument_id":436},"action":"C","side":"B","price":"1.157300000","size":20,"channel_id":23,"order_id":"10998895686979171860","flags":128,"ts_in_delta":1243,"sequence":111221,"symbol":"FCEU SI 20260615 PS"}
{"ts_recv":"2026-04-07T01:00:55.787488328Z","hd":{"ts_event":"2026-04-07T01:00:55.787467665Z","rtype":160,"publisher_id":101,"instrument_id":436},"action":"A","side":"B","price":"1.157200000","size":20,"channel_id":23,"order_id":"10998895692642254602","flags":128,"ts_in_delta":937,"sequence":111222,"symbol":"FCEU SI 20260615 PS"}
{"ts_recv":"2026-04-07T01:01:02.441616904Z","hd":{"ts_event":"2026-04-07T01:01:02.441599289Z","rtype":160,"publisher_id":101,"instrument_id":436},"action":"A","side":"A","price":"1.157600000","size":20,"channel_id":23,"order_id":"1775523662441605601","flags":128,"ts_in_delta":1001,"sequence":111290,"symbol":"FCEU SI 20260615 PS"}
{"ts_recv":"2026-04-07T01:01:02.441635504Z","hd":{"ts_event":"2026-04-07T01:01:02.441621613Z","rtype":160,"publisher_id":101,"instrument_id":436},"action":"C","side":"A","price":"1.157700000","size":20,"channel_id":23,"order_id":"1775523628163285955","flags":128,"ts_in_delta":1027,"sequence":111291,"symbol":"FCEU SI 20260615 PS"}
{"ts_recv":"2026-04-07T01:01:12.116011185Z","hd":{"ts_event":"2026-04-07T01:01:12.115990005Z","rtype":160,"publisher_id":101,"instrument_id":436},"action":"C","side":"B","price":"1.157200000","size":20,"channel_id":23,"order_id":"10998895692642254602","flags":128,"ts_in_delta":1259,"sequence":111390,"symbol":"FCEU SI 20260615 PS"}
{"ts_recv":"2026-04-07T01:01:12.200303100Z","hd":{"ts_event":"2026-04-07T01:01:12.200287535Z","rtype":160,"publisher_id":101,"instrument_id":436},"action":"A","side":"B","price":"1.157200000","size":20,"channel_id":23,"order_id":"10998895709055069510","flags":128,"ts_in_delta":903,"sequence":111400,"symbol":"FCEU SI 20260615 PS"}
{"ts_recv":"2026-04-07T01:01:20.254907207Z","hd":{"ts_event":"2026-04-07T01:01:20.254894619Z","rtype":160,"publisher_id":101,"instrument_id":436},"action":"C","side":"B","price":"1.157200000","size":20,"channel_id":23,"order_id":"10998895709055069510","flags":128,"ts_in_delta":908,"sequence":111466,"symbol":"FCEU SI 20260615 PS"}
{"ts_recv":"2026-04-07T01:01:20.317329985Z","hd":{"ts_event":"2026-04-07T01:01:20.317313967Z","rtype":160,"publisher_id":101,"instrument_id":436},"action":"A","side":"B","price":"1.157200000","size":20,"channel_id":23,"order_id":"10998895717172095806","flags":128,"ts_in_delta":947,"sequence":111477,"symbol":"FCEU SI 20260615 PS"}
{"ts_recv":"2026-04-07T01:01:28.238651007Z","hd":{"ts_event":"2026-04-07T01:01:28.238623863Z","rtype":160,"publisher_id":101,"instrument_id":436},"action":"C","side":"A","price":"1.157600000","size":20,"channel_id":23,"order_id":"1775523662441605601","flags":128,"ts_in_delta":1252,"sequence":111563,"symbol":"FCEU SI 20260615 PS"}
{"ts_recv":"2026-04-07T01:01:28.281494378Z","hd":{"ts_event":"2026-04-07T01:01:28.281478073Z","rtype":160,"publisher_id":101,"instrument_id":436},"action":"A","side":"A","price":"1.157700000","size":20,"channel_id":23,"order_id":"1775523688281484136","flags":128,"ts_in_delta":827,"sequence":111569,"symbol":"FCEU SI 20260615 PS"}
{"ts_recv":"2026-04-07T01:01:28.338015221Z","hd":{"ts_event":"2026-04-07T01:01:28.337999471Z","rtype":160,"publisher_id":101,"instrument_id":436},"action":"A","side":"B","price":"1.157300000","size":20,"channel_id":23,"order_id":"10998895725192781269","flags":128,"ts_in_delta":952,"sequence":111581,"symbol":"FCEU SI 20260615 PS"}
{"ts_recv":"2026-04-07T01:01:28.338091495Z","hd":{"ts_event":"2026-04-07T01:01:28.338078797Z","rtype":160,"publisher_id":101,"instrument_id":436},"action":"C","side":"B","price":"1.157200000","size":20,"channel_id":23,"order_id":"10998895717172095806","flags":128,"ts_in_delta":914,"sequence":111582,"symbol":"FCEU SI 20260615 PS"}
{"ts_recv":"2026-04-07T01:01:58.477142726Z","hd":{"ts_event":"2026-04-07T01:01:58.477114371Z","rtype":160,"publisher_id":101,"instrument_id":436},"action":"A","side":"B","price":"1.157400000","size":20,"channel_id":23,"order_id":"10998895755331903325","flags":128,"ts_in_delta":1672,"sequence":111932,"symbol":"FCEU SI 20260615 PS"}
{"ts_recv":"2026-04-07T01:01:58.477146067Z","hd":{"ts_event":"2026-04-07T01:01:58.477128975Z","rtype":160,"publisher_id":101,"instrument_id":436},"action":"C","side":"B","price":"1.157300000","size":20,"channel_id":23,"order_id":"10998895725192781269","flags":128,"ts_in_delta":933,"sequence":111933,"symbol":"FCEU SI 20260615 PS"}
{"ts_recv":"2026-04-07T01:02:02.347104099Z","hd":{"ts_event":"2026-04-07T01:02:02.347080517Z","rtype":160,"publisher_id":101,"instrument_id":436},"action":"C","side":"A","price":"1.157700000","size":20,"channel_id":23,"order_id":"1775523688281484136","flags":128,"ts_in_delta":1360,"sequence":111960,"symbol":"FCEU SI 20260615 PS"}
{"ts_recv":"2026-04-07T01:02:02.390885587Z","hd":{"ts_event":"2026-04-07T01:02:02.390871129Z","rtype":160,"publisher_id":101,"instrument_id":436},"action":"A","side":"A","price":"1.157800000","size":20,"channel_id":23,"order_id":"1775523722390877179","flags":128,"ts_in_delta":892,"sequence":111963,"symbol":"FCEU SI 20260615 PS"}
{"ts_recv":"2026-04-07T01:02:06.033008064Z","hd":{"ts_event":"2026-04-07T01:02:06.032993913Z","rtype":160,"publisher_id":101,"instrument_id":436},"action":"C","side":"B","price":"1.157400000","size":20,"channel_id":23,"order_id":"10998895755331903325","flags":128,"ts_in_delta":990,"sequence":112000,"symbol":"FCEU SI 20260615 PS"}
{"ts_recv":"2026-04-07T01:02:06.084127198Z","hd":{"ts_event":"2026-04-07T01:02:06.084111891Z","rtype":160,"publisher_id":101,"instrument_id":436},"action":"A","side":"B","price":"1.157400000","size":20,"channel_id":23,"order_id":"10998895762938893733","flags":128,"ts_in_delta":868,"sequence":112005,"symbol":"FCEU SI 20260615 PS"}
{"ts_recv":"2026-04-07T01:02:25.484080524Z","hd":{"ts_event":"2026-04-07T01:02:25.484066059Z","rtype":160,"publisher_id":101,"instrument_id":436},"action":"C","side":"A","price":"1.157800000","size":20,"channel_id":23,"order_id":"1775523722390877179","flags":128,"ts_in_delta":1058,"sequence":112247,"symbol":"FCEU SI 20260615 PS"}
{"ts_recv":"2026-04-07T01:02:25.526584671Z","hd":{"ts_event":"2026-04-07T01:02:25.526566957Z","rtype":160,"publisher_id":101,"instrument_id":436},"action":"A","side":"A","price":"1.157900000","size":20,"channel_id":23,"order_id":"1775523745526573139","flags":128,"ts_in_delta":809,"sequence":112251,"symbol":"FCEU SI 20260615 PS"}
{"ts_recv":"2026-04-07T01:02:25.534940919Z","hd":{"ts_event":"2026-04-07T01:02:25.534925605Z","rtype":160,"publisher_id":101,"instrument_id":436},"action":"A","side":"B","price":"1.157500000","size":20,"channel_id":23,"order_id":"10998895782389707435","flags":128,"ts_in_delta":849,"sequence":112252,"symbol":"FCEU SI 20260615 PS"}
{"ts_recv":"2026-04-07T01:02:25.535078138Z","hd":{"ts_event":"2026-04-07T01:02:25.535064953Z","rtype":160,"publisher_id":101,"instrument_id":436},"action":"C","side":"B","price":"1.157400000","size":20,"channel_id":23,"order_id":"10998895762938893733","flags":128,"ts_in_delta":814,"sequence":112253,"symbol":"FCEU SI 20260615 PS"}
{"ts_recv":"2026-04-07T01:02:31.870901691Z","hd":{"ts_event":"2026-04-07T01:02:31.870889341Z","rtype":160,"publisher_id":101,"instrument_id":436},"action":"C","side":"B","price":"1.157500000","size":20,"channel_id":23,"order_id":"10998895782389707435","flags":128,"ts_in_delta":818,"sequence":112321,"symbol":"FCEU SI 20260615 PS"}
{"ts_recv":"2026-04-07T01:02:31.913393015Z","hd":{"ts_event":"2026-04-07T01:02:31.913378207Z","rtype":160,"publisher_id":101,"instrument_id":436},"action":"A","side":"B","price":"1.157400000","size":20,"channel_id":23,"order_id":"10998895788768160060","flags":128,"ts_in_delta":807,"sequence":112325,"symbol":"FCEU SI 20260615 PS"}
{"ts_recv":"2026-04-07T01:02:38.491241730Z","hd":{"ts_event":"2026-04-07T01:02:38.491225661Z","rtype":160,"publisher_id":101,"instrument_id":436},"action":"A","side":"B","price":"1.157500000","size":20,"channel_id":23,"order_id":"10998895795346007576","flags":128,"ts_in_delta":866,"sequence":112422,"symbol":"FCEU SI 20260615 PS"}
{"ts_recv":"2026-04-07T01:02:38.491485436Z","hd":{"ts_event":"2026-04-07T01:02:38.491472377Z","rtype":160,"publisher_id":101,"instrument_id":436},"action":"C","side":"B","price":"1.157400000","size":20,"channel_id":23,"order_id":"10998895788768160060","flags":128,"ts_in_delta":866,"sequence":112423,"symbol":"FCEU SI 20260615 PS"}
{"ts_recv":"2026-04-07T01:02:43.491637743Z","hd":{"ts_event":"2026-04-07T01:02:43.491617661Z","rtype":160,"publisher_id":101,"instrument_id":436},"action":"C","side":"B","price":"1.157500000","size":20,"channel_id":23,"order_id":"10998895795346007576","flags":128,"ts_in_delta":1139,"sequence":112470,"symbol":"FCEU SI 20260615 PS"}
{"ts_recv":"2026-04-07T01:02:43.534572859Z","hd":{"ts_event":"2026-04-07T01:02:43.534551451Z","rtype":160,"publisher_id":101,"instrument_id":436},"action":"A","side":"B","price":"1.157400000","size":20,"channel_id":23,"order_id":"10998895800389338359","flags":128,"ts_in_delta":853,"sequence":112471,"symbol":"FCEU SI 20260615 PS"}
{"ts_recv":"2026-04-07T01:02:46.675786909Z","hd":{"ts_event":"2026-04-07T01:02:46.675770719Z","rtype":160,"publisher_id":101,"instrument_id":436},"action":"A","side":"A","price":"1.157800000","size":20,"channel_id":23,"order_id":"1775523766675776980","flags":128,"ts_in_delta":993,"sequence":112508,"symbol":"FCEU SI 20260615 PS"}
{"ts_recv":"2026-04-07T01:02:46.675875839Z","hd":{"ts_event":"2026-04-07T01:02:46.675864225Z","rtype":160,"publisher_id":101,"instrument_id":436},"action":"C","side":"A","price":"1.157900000","size":20,"channel_id":23,"order_id":"1775523745526573139","flags":128,"ts_in_delta":885,"sequence":112509,"symbol":"FCEU SI 20260615 PS"}
{"ts_recv":"2026-04-07T01:03:04.140871077Z","hd":{"ts_event":"2026-04-07T01:03:04.140857525Z","rtype":160,"publisher_id":101,"instrument_id":436},"action":"C","side":"B","price":"1.157400000","size":20,"channel_id":23,"order_id":"10998895800389338359","flags":128,"ts_in_delta":855,"sequence":112680,"symbol":"FCEU SI 20260615 PS"}
{"ts_recv":"2026-04-07T01:03:04.209357255Z","hd":{"ts_event":"2026-04-07T01:03:04.209342697Z","rtype":160,"publisher_id":101,"instrument_id":436},"action":"A","side":"B","price":"1.157400000","size":20,"channel_id":23,"order_id":"10998895821064124435","flags":128,"ts_in_delta":684,"sequence":112692,"symbol":"FCEU SI 20260615 PS"}
{"ts_recv":"2026-04-07T01:03:37.205416602Z","hd":{"ts_event":"2026-04-07T01:03:37.205398175Z","rtype":160,"publisher_id":101,"instrument_id":436},"action":"A","side":"B","price":"1.157500000","size":20,"channel_id":23,"order_id":"10998895854060180332","flags":128,"ts_in_delta":850,"sequence":113020,"symbol":"FCEU SI 20260615 PS"}
{"ts_recv":"2026-04-07T01:03:37.205459516Z","hd":{"ts_event":"2026-04-07T01:03:37.205444883Z","rtype":160,"publisher_id":101,"instrument_id":436},"action":"C","side":"B","price":"1.157400000","size":20,"channel_id":23,"order_id":"10998895821064124435","flags":128,"ts_in_delta":953,"sequence":113021,"symbol":"FCEU SI 20260615 PS"}
{"ts_recv":"2026-04-07T01:03:37.562612503Z","hd":{"ts_event":"2026-04-07T01:03:37.562598587Z","rtype":160,"publisher_id":101,"instrument_id":436},"action":"C","side":"A","price":"1.157800000","size":20,"channel_id":23,"order_id":"1775523766675776980","flags":128,"ts_in_delta":887,"sequence":113029,"symbol":"FCEU SI 20260615 PS"}
{"ts_recv":"2026-04-07T01:03:37.605778898Z","hd":{"ts_event":"2026-04-07T01:03:37.605765241Z","rtype":160,"publisher_id":101,"instrument_id":436},"action":"A","side":"A","price":"1.157900000","size":20,"channel_id":23,"order_id":"1775523817605770982","flags":128,"ts_in_delta":637,"sequence":113035,"symbol":"FCEU SI 20260615 PS"}
{"ts_recv":"2026-04-07T01:03:44.673665567Z","hd":{"ts_event":"2026-04-07T01:03:44.673651745Z","rtype":160,"publisher_id":101,"instrument_id":436},"action":"C","side":"B","price":"1.157500000","size":20,"channel_id":23,"order_id":"10998895854060180332","flags":128,"ts_in_delta":644,"sequence":113104,"symbol":"FCEU SI 20260615 PS"}
{"ts_recv":"2026-04-07T01:03:44.717038525Z","hd":{"ts_event":"2026-04-07T01:03:44.717014335Z","rtype":160,"publisher_id":101,"instrument_id":436},"action":"A","side":"B","price":"1.157400000","size":20,"channel_id":23,"order_id":"10998895861571801319","flags":128,"ts_in_delta":1232,"sequence":113106,"symbol":"FCEU SI 20260615 PS"}
{"ts_recv":"2026-04-07T01:03:52.677489724Z","hd":{"ts_event":"2026-04-07T01:03:52.677473665Z","rtype":160,"publisher_id":101,"instrument_id":436},"action":"A","side":"B","price":"1.157500000","size":20,"channel_id":23,"order_id":"10998895869532255739","flags":128,"ts_in_delta":873,"sequence":113206,"symbol":"FCEU SI 20260615 PS"}
{"ts_recv":"2026-04-07T01:03:52.677622874Z","hd":{"ts_event":"2026-04-07T01:03:52.677610351Z","rtype":160,"publisher_id":101,"instrument_id":436},"action":"C","side":"B","price":"1.157400000","size":20,"channel_id":23,"order_id":"10998895861571801319","flags":128,"ts_in_delta":882,"sequence":113207,"symbol":"FCEU SI 20260615 PS"}
{"ts_recv":"2026-04-07T01:04:12.599433334Z","hd":{"ts_event":"2026-04-07T01:04:12.599418857Z","rtype":160,"publisher_id":101,"instrument_id":436},"action":"C","side":"B","price":"1.157500000","size":20,"channel_id":23,"order_id":"10998895869532255739","flags":128,"ts_in_delta":892,"sequence":113384,"symbol":"FCEU SI 20260615 PS"}
{"ts_recv":"2026-04-07T01:04:12.640524218Z","hd":{"ts_event":"2026-04-07T01:04:12.640504689Z","rtype":160,"publisher_id":101,"instrument_id":436},"action":"A","side":"A","price":"1.157800000","size":20,"channel_id":23,"order_id":"1775523852640513116","flags":128,"ts_in_delta":731,"sequence":113389,"symbol":"FCEU SI 20260615 PS"}
{"ts_recv":"2026-04-07T01:04:12.640600546Z","hd":{"ts_event":"2026-04-07T01:04:12.640588075Z","rtype":160,"publisher_id":101,"instrument_id":436},"action":"C","side":"A","price":"1.157900000","size":20,"channel_id":23,"order_id":"1775523817605770982","flags":128,"ts_in_delta":711,"sequence":113391,"symbol":"FCEU SI 20260615 PS"}
{"ts_recv":"2026-04-07T01:04:12.644009311Z","hd":{"ts_event":"2026-04-07T01:04:12.643995115Z","rtype":160,"publisher_id":101,"instrument_id":436},"action":"A","side":"B","price":"1.157400000","size":20,"channel_id":23,"order_id":"10998895889498777242","flags":128,"ts_in_delta":669,"sequence":113393,"symbol":"FCEU SI 20260615 PS"}
{"ts_recv":"2026-04-07T01:04:17.831187181Z","hd":{"ts_event":"2026-04-07T01:04:17.831168755Z","rtype":160,"publisher_id":101,"instrument_id":436},"action":"C","side":"A","price":"1.157800000","size":20,"channel_id":23,"order_id":"1775523852640513116","flags":128,"ts_in_delta":1220,"sequence":113455,"symbol":"FCEU SI 20260615 PS"}
{"ts_recv":"2026-04-07T01:04:17.874493869Z","hd":{"ts_event":"2026-04-07T01:04:17.874471611Z","rtype":160,"publisher_id":101,"instrument_id":436},"action":"A","side":"A","price":"1.157900000","size":20,"channel_id":23,"order_id":"1775523857874482479","flags":128,"ts_in_delta":1321,"sequence":113458,"symbol":"FCEU SI 20260615 PS"}
{"ts_recv":"2026-04-07T01:04:17.901212963Z","hd":{"ts_event":"2026-04-07T01:04:17.901197823Z","rtype":160,"publisher_id":101,"instrument_id":436},"action":"A","side":"B","price":"1.157500000","size":20,"channel_id":23,"order_id":"10998895894755979714","flags":128,"ts_in_delta":970,"sequence":113461,"symbol":"FCEU SI 20260615 PS"}
{"ts_recv":"2026-04-07T01:04:17.901297570Z","hd":{"ts_event":"2026-04-07T01:04:17.901285753Z","rtype":160,"publisher_id":101,"instrument_id":436},"action":"C","side":"B","price":"1.157400000","size":20,"channel_id":23,"order_id":"10998895889498777242","flags":128,"ts_in_delta":944,"sequence":113462,"symbol":"FCEU SI 20260615 PS"}
{"ts_recv":"2026-04-07T01:04:28.102442444Z","hd":{"ts_event":"2026-04-07T01:04:28.102429711Z","rtype":160,"publisher_id":101,"instrument_id":436},"action":"C","side":"B","price":"1.157500000","size":20,"channel_id":23,"order_id":"10998895894755979714","flags":128,"ts_in_delta":815,"sequence":113546,"symbol":"FCEU SI 20260615 PS"}
{"ts_recv":"2026-04-07T01:04:28.170278666Z","hd":{"ts_event":"2026-04-07T01:04:28.170263037Z","rtype":160,"publisher_id":101,"instrument_id":436},"action":"A","side":"B","price":"1.157500000","size":20,"channel_id":23,"order_id":"10998895905025044886","flags":128,"ts_in_delta":940,"sequence":113554,"symbol":"FCEU SI 20260615 PS"}
{"ts_recv":"2026-04-07T01:05:09.532038569Z","hd":{"ts_event":"2026-04-07T01:05:09.532023941Z","rtype":160,"publisher_id":101,"instrument_id":436},"action":"C","side":"B","price":"1.157500000","size":20,"channel_id":23,"order_id":"10998895905025044886","flags":128,"ts_in_delta":830,"sequence":113881,"symbol":"FCEU SI 20260615 PS"}
{"ts_recv":"2026-04-07T01:05:09.669090194Z","hd":{"ts_event":"2026-04-07T01:05:09.669073977Z","rtype":160,"publisher_id":101,"instrument_id":436},"action":"A","side":"B","price":"1.157500000","size":20,"channel_id":23,"order_id":"10998895946523855703","flags":128,"ts_in_delta":648,"sequence":113903,"symbol":"FCEU SI 20260615 PS"}
{"ts_recv":"2026-04-07T01:05:17.768143828Z","hd":{"ts_event":"2026-04-07T01:05:17.768130367Z","rtype":160,"publisher_id":101,"instrument_id":436},"action":"C","side":"B","price":"1.157500000","size":20,"channel_id":23,"order_id":"10998895946523855703","flags":128,"ts_in_delta":834,"sequence":114016,"symbol":"FCEU SI 20260615 PS"}
{"ts_recv":"2026-04-07T01:05:17.811200837Z","hd":{"ts_event":"2026-04-07T01:05:17.811186289Z","rtype":160,"publisher_id":101,"instrument_id":436},"action":"A","side":"B","price":"1.157400000","size":20,"channel_id":23,"order_id":"10998895954665967906","flags":128,"ts_in_delta":638,"sequence":114022,"symbol":"FCEU SI 20260615 PS"}
{"ts_recv":"2026-04-07T01:05:25.635206083Z","hd":{"ts_event":"2026-04-07T01:05:25.635188061Z","rtype":160,"publisher_id":101,"instrument_id":436},"action":"A","side":"A","price":"1.157800000","size":20,"channel_id":23,"order_id":"1775523925635194141","flags":128,"ts_in_delta":922,"sequence":114093,"symbol":"FCEU SI 20260615 PS"}
{"ts_recv":"2026-04-07T01:05:25.635259203Z","hd":{"ts_event":"2026-04-07T01:05:25.635246211Z","rtype":160,"publisher_id":101,"instrument_id":436},"action":"C","side":"A","price":"1.157900000","size":20,"channel_id":23,"order_id":"1775523857874482479","flags":128,"ts_in_delta":748,"sequence":114095,"symbol":"FCEU SI 20260615 PS"}
{"ts_recv":"2026-04-07T01:05:49.004491797Z","hd":{"ts_event":"2026-04-07T01:05:49.004477339Z","rtype":160,"publisher_id":101,"instrument_id":436},"action":"C","side":"B","price":"1.157400000","size":20,"channel_id":23,"order_id":"10998895954665967906","flags":128,"ts_in_delta":984,"sequence":114246,"symbol":"FCEU SI 20260615 PS"}
{"ts_recv":"2026-04-07T01:05:49.047696599Z","hd":{"ts_event":"2026-04-07T01:05:49.047680391Z","rtype":160,"publisher_id":101,"instrument_id":436},"action":"A","side":"B","price":"1.157300000","size":20,"channel_id":23,"order_id":"10998895985902462378","flags":128,"ts_in_delta":1425,"sequence":114249,"symbol":"FCEU SI 20260615 PS"}
{"ts_recv":"2026-04-07T01:05:52.809979900Z","hd":{"ts_event":"2026-04-07T01:05:52.809955881Z","rtype":160,"publisher_id":101,"instrument_id":436},"action":"A","side":"A","price":"1.157700000","size":20,"channel_id":23,"order_id":"1775523952809966619","flags":128,"ts_in_delta":1155,"sequence":114293,"symbol":"FCEU SI 20260615 PS"}
{"ts_recv":"2026-04-07T01:05:52.809991435Z","hd":{"ts_event":"2026-04-07T01:05:52.809978513Z","rtype":160,"publisher_id":101,"instrument_id":436},"action":"C","side":"A","price":"1.157800000","size":20,"channel_id":23,"order_id":"1775523925635194141","flags":128,"ts_in_delta":841,"sequence":114294,"symbol":"FCEU SI 20260615 PS"}
{"ts_recv":"2026-04-07T01:06:15.299387029Z","hd":{"ts_event":"2026-04-07T01:06:15.299362917Z","rtype":160,"publisher_id":101,"instrument_id":436},"action":"A","side":"B","price":"1.157400000","size":20,"channel_id":23,"order_id":"10998896012154149638","flags":128,"ts_in_delta":872,"sequence":114438,"symbol":"FCEU SI 20260615 PS"}
{"ts_recv":"2026-04-07T01:06:15.299435763Z","hd":{"ts_event":"2026-04-07T01:06:15.299422579Z","rtype":160,"publisher_id":101,"instrument_id":436},"action":"C","side":"B","price":"1.157300000","size":20,"channel_id":23,"order_id":"10998895985902462378","flags":128,"ts_in_delta":852,"sequence":114439,"symbol":"FCEU SI 20260615 PS"}
