{"ts_recv":"2026-04-07T02:05:32.306568119Z","hd":{"ts_event":"2026-04-07T02:05:32.306550807Z","rtype":160,"publisher_id":101,"instrument_id":436},"action":"A","side":"A","price":"1.156650000","size":30,"channel_id":23,"order_id":"1775527532306557114","flags":128,"ts_in_delta":750,"sequence":145037,"symbol":"FCEU SI 20260615 PS"}
{"ts_recv":"2026-04-07T02:05:32.306578532Z","hd":{"ts_event":"2026-04-07T02:05:32.306559697Z","rtype":160,"publisher_id":101,"instrument_id":436},"action":"C","side":"B","price":"1.156550000","size":30,"channel_id":23,"order_id":"10998899569161278028","flags":0,"ts_in_delta":932,"sequence":145038,"symbol":"FCEU SI 20260615 PS"}
{"ts_recv":"2026-04-07T02:05:32.306578532Z","hd":{"ts_event":"2026-04-07T02:05:32.306559697Z","rtype":160,"publisher_id":101,"instrument_id":436},"action":"A","side":"B","price":"1.156560000","size":30,"channel_id":23,"order_id":"10998899569161341495","flags":0,"ts_in_delta":932,"sequence":145038,"symbol":"FCEU SI 20260615 PS"}
{"ts_recv":"2026-04-07T02:05:32.306578532Z","hd":{"ts_event":"2026-04-07T02:05:32.306559697Z","rtype":160,"publisher_id":101,"instrument_id":436},"action":"C","side":"A","price":"1.156650000","size":30,"channel_id":23,"order_id":"1775527532306502220","flags":0,"ts_in_delta":932,"sequence":145038,"symbol":"FCEU SI 20260615 PS"}
{"ts_recv":"2026-04-07T02:05:32.306578532Z","hd":{"ts_event":"2026-04-07T02:05:32.306559697Z","rtype":160,"publisher_id":101,"instrument_id":436},"action":"A","side":"A","price":"1.156660000","size":30,"channel_id":23,"order_id":"1775527532306565687","flags":128,"ts_in_delta":932,"sequence":145038,"symbol":"FCEU SI 20260615 PS"}
{"ts_recv":"2026-04-07T02:05:32.306630132Z","hd":{"ts_event":"2026-04-07T02:05:32.306614801Z","rtype":160,"publisher_id":101,"instrument_id":436},"action":"C","side":"B","price":"1.156560000","size":30,"channel_id":23,"order_id":"10998899569161341495","flags":0,"ts_in_delta":1072,"sequence":145039,"symbol":"FCEU SI 20260615 PS"}
{"ts_recv":"2026-04-07T02:05:32.306630132Z","hd":{"ts_event":"2026-04-07T02:05:32.306614801Z","rtype":160,"publisher_id":101,"instrument_id":436},"action":"A","side":"B","price":"1.156550000","size":30,"channel_id":23,"order_id":"10998899569161396686","flags":0,"ts_in_delta":1072,"sequence":145039,"symbol":"FCEU SI 20260615 PS"}
{"ts_recv":"2026-04-07T02:05:32.306630132Z","hd":{"ts_event":"2026-04-07T02:05:32.306614801Z","rtype":160,"publisher_id":101,"instrument_id":436},"action":"C","side":"A","price":"1.156660000","size":30,"channel_id":23,"order_id":"1775527532306565687","flags":0,"ts_in_delta":1072,"sequence":145039,"symbol":"FCEU SI 20260615 PS"}
{"ts_recv":"2026-04-07T02:05:32.306630132Z","hd":{"ts_event":"2026-04-07T02:05:32.306614801Z","rtype":160,"publisher_id":101,"instrument_id":436},"action":"A","side":"A","price":"1.156650000","size":30,"channel_id":23,"order_id":"1775527532306620878","flags":128,"ts_in_delta":1072,"sequence":145039,"symbol":"FCEU SI 20260615 PS"}
{"ts_recv":"2026-04-07T02:05:32.312968844Z","hd":{"ts_event":"2026-04-07T02:05:32.312949859Z","rtype":160,"publisher_id":101,"instrument_id":436},"action":"C","side":"B","price":"1.156550000","size":30,"channel_id":23,"order_id":"10998899569161396686","flags":0,"ts_in_delta":921,"sequence":145042,"symbol":"FCEU SI 20260615 PS"}
{"ts_recv":"2026-04-07T02:05:32.312968844Z","hd":{"ts_event":"2026-04-07T02:05:32.312949859Z","rtype":160,"publisher_id":101,"instrument_id":436},"action":"A","side":"B","price":"1.156540000","size":30,"channel_id":23,"order_id":"10998899569167731552","flags":0,"ts_in_delta":921,"sequence":145042,"symbol":"FCEU SI 20260615 PS"}
{"ts_recv":"2026-04-07T02:05:32.312968844Z","hd":{"ts_event":"2026-04-07T02:05:32.312949859Z","rtype":160,"publisher_id":101,"instrument_id":436},"action":"C","side":"A","price":"1.156650000","size":30,"channel_id":23,"order_id":"1775527532306620878","flags":0,"ts_in_delta":921,"sequence":145042,"symbol":"FCEU SI 20260615 PS"}
{"ts_recv":"2026-04-07T02:05:32.312968844Z","hd":{"ts_event":"2026-04-07T02:05:32.312949859Z","rtype":160,"publisher_id":101,"instrument_id":436},"action":"A","side":"A","price":"1.156640000","size":30,"channel_id":23,"order_id":"1775527532312955744","flags":128,"ts_in_delta":921,"sequence":145042,"symbol":"FCEU SI 20260615 PS"}
{"ts_recv":"2026-04-07T02:05:32.317985589Z","hd":{"ts_event":"2026-04-07T02:05:32.317970833Z","rtype":160,"publisher_id":101,"instrument_id":436},"action":"C","side":"B","price":"1.156500000","size":20,"channel_id":23,"order_id":"10998899144657142423","flags":128,"ts_in_delta":854,"sequence":145050,"symbol":"FCEU SI 20260615 PS"}
{"ts_recv":"2026-04-07T02:05:32.361415777Z","hd":{"ts_event":"2026-04-07T02:05:32.361400503Z","rtype":160,"publisher_id":101,"instrument_id":436},"action":"A","side":"B","price":"1.156400000","size":20,"channel_id":23,"order_id":"10998899569216182573","flags":128,"ts_in_delta":879,"sequence":145056,"symbol":"FCEU SI 20260615 PS"}
{"ts_recv":"2026-04-07T02:05:33.624256137Z","hd":{"ts_event":"2026-04-07T02:05:33.624230629Z","rtype":160,"publisher_id":101,"instrument_id":436},"action":"C","side":"B","price":"1.156540000","size":30,"channel_id":23,"order_id":"10998899569167731552","flags":0,"ts_in_delta":1300,"sequence":145082,"symbol":"FCEU SI 20260615 PS"}
{"ts_recv":"2026-04-07T02:05:33.624256137Z","hd":{"ts_event":"2026-04-07T02:05:33.624230629Z","rtype":160,"publisher_id":101,"instrument_id":436},"action":"A","side":"B","price":"1.156550000","size":30,"channel_id":23,"order_id":"10998899570479017411","flags":0,"ts_in_delta":1300,"sequence":145082,"symbol":"FCEU SI 20260615 PS"}
{"ts_recv":"2026-04-07T02:05:33.624256137Z","hd":{"ts_event":"2026-04-07T02:05:33.624230629Z","rtype":160,"publisher_id":101,"instrument_id":436},"action":"C","side":"A","price":"1.156640000","size":30,"channel_id":23,"order_id":"1775527532312955744","flags":0,"ts_in_delta":1300,"sequence":145082,"symbol":"FCEU SI 20260615 PS"}
{"ts_recv":"2026-04-07T02:05:33.624256137Z","hd":{"ts_event":"2026-04-07T02:05:33.624230629Z","rtype":160,"publisher_id":101,"instrument_id":436},"action":"A","side":"A","price":"1.156650000","size":30,"channel_id":23,"order_id":"1775527533624241603","flags":128,"ts_in_delta":1300,"sequence":145082,"symbol":"FCEU SI 20260615 PS"}
{"ts_recv":"2026-04-07T02:05:45.802515261Z","hd":{"ts_event":"2026-04-07T02:05:45.802494263Z","rtype":160,"publisher_id":101,"instrument_id":436},"action":"C","side":"B","price":"1.156550000","size":30,"channel_id":23,"order_id":"10998899570479017411","flags":0,"ts_in_delta":993,"sequence":145204,"symbol":"FCEU SI 20260615 PS"}
{"ts_recv":"2026-04-07T02:05:45.802515261Z","hd":{"ts_event":"2026-04-07T02:05:45.802494263Z","rtype":160,"publisher_id":101,"instrument_id":436},"action":"A","side":"B","price":"1.156560000","size":30,"channel_id":23,"order_id":"10998899582657275859","flags":0,"ts_in_delta":993,"sequence":145204,"symbol":"FCEU SI 20260615 PS"}
{"ts_recv":"2026-04-07T02:05:45.802515261Z","hd":{"ts_event":"2026-04-07T02:05:45.802494263Z","rtype":160,"publisher_id":101,"instrument_id":436},"action":"C","side":"A","price":"1.156650000","size":30,"channel_id":23,"order_id":"1775527533624241603","flags":0,"ts_in_delta":993,"sequence":145204,"symbol":"FCEU SI 20260615 PS"}
{"ts_recv":"2026-04-07T02:05:45.802515261Z","hd":{"ts_event":"2026-04-07T02:05:45.802494263Z","rtype":160,"publisher_id":101,"instrument_id":436},"action":"A","side":"A","price":"1.156660000","size":30,"channel_id":23,"order_id":"1775527545802500051","flags":128,"ts_in_delta":993,"sequence":145204,"symbol":"FCEU SI 20260615 PS"}
{"ts_recv":"2026-04-07T02:05:45.954587112Z","hd":{"ts_event":"2026-04-07T02:05:45.954566797Z","rtype":160,"publisher_id":101,"instrument_id":436},"action":"C","side":"B","price":"1.156550000","size":30,"channel_id":23,"order_id":"10998899569161332922","flags":0,"ts_in_delta":935,"sequence":145223,"symbol":"FCEU SI 20260615 PS"}
{"ts_recv":"2026-04-07T02:05:45.954587112Z","hd":{"ts_event":"2026-04-07T02:05:45.954566797Z","rtype":160,"publisher_id":101,"instrument_id":436},"action":"A","side":"B","price":"1.156570000","size":30,"channel_id":23,"order_id":"10998899582809348524","flags":0,"ts_in_delta":935,"sequence":145223,"symbol":"FCEU SI 20260615 PS"}
{"ts_recv":"2026-04-07T02:05:45.954587112Z","hd":{"ts_event":"2026-04-07T02:05:45.954566797Z","rtype":160,"publisher_id":101,"instrument_id":436},"action":"C","side":"A","price":"1.156650000","size":30,"channel_id":23,"order_id":"1775527532306557114","flags":0,"ts_in_delta":935,"sequence":145223,"symbol":"FCEU SI 20260615 PS"}
{"ts_recv":"2026-04-07T02:05:45.954587112Z","hd":{"ts_event":"2026-04-07T02:05:45.954566797Z","rtype":160,"publisher_id":101,"instrument_id":436},"action":"A","side":"A","price":"1.156670000","size":30,"channel_id":23,"order_id":"1775527545954572716","flags":128,"ts_in_delta":935,"sequence":145223,"symbol":"FCEU SI 20260615 PS"}
{"ts_recv":"2026-04-07T02:05:45.954645132Z","hd":{"ts_event":"2026-04-07T02:05:45.954629179Z","rtype":160,"publisher_id":101,"instrument_id":436},"action":"C","side":"B","price":"1.156560000","size":30,"channel_id":23,"order_id":"10998899582657275859","flags":0,"ts_in_delta":923,"sequence":145224,"symbol":"FCEU SI 20260615 PS"}
{"ts_recv":"2026-04-07T02:05:45.954645132Z","hd":{"ts_event":"2026-04-07T02:05:45.954629179Z","rtype":160,"publisher_id":101,"instrument_id":436},"action":"A","side":"B","price":"1.156570000","size":30,"channel_id":23,"order_id":"10998899582809410829","flags":0,"ts_in_delta":923,"sequence":145224,"symbol":"FCEU SI 20260615 PS"}
{"ts_recv":"2026-04-07T02:05:45.954645132Z","hd":{"ts_event":"2026-04-07T02:05:45.954629179Z","rtype":160,"publisher_id":101,"instrument_id":436},"action":"C","side":"A","price":"1.156660000","size":30,"channel_id":23,"order_id":"1775527545802500051","flags":0,"ts_in_delta":923,"sequence":145224,"symbol":"FCEU SI 20260615 PS"}
{"ts_recv":"2026-04-07T02:05:45.954645132Z","hd":{"ts_event":"2026-04-07T02:05:45.954629179Z","rtype":160,"publisher_id":101,"instrument_id":436},"action":"A","side":"A","price":"1.156670000","size":30,"channel_id":23,"order_id":"1775527545954635021","flags":128,"ts_in_delta":923,"sequence":145224,"symbol":"FCEU SI 20260615 PS"}
{"ts_recv":"2026-04-07T02:05:54.107826399Z","hd":{"ts_event":"2026-04-07T02:05:54.107806029Z","rtype":160,"publisher_id":101,"instrument_id":436},"action":"C","side":"B","price":"1.156570000","size":30,"channel_id":23,"order_id":"10998899582809410829","flags":0,"ts_in_delta":911,"sequence":145298,"symbol":"FCEU SI 20260615 PS"}
{"ts_recv":"2026-04-07T02:05:54.107826399Z","hd":{"ts_event":"2026-04-07T02:05:54.107806029Z","rtype":160,"publisher_id":101,"instrument_id":436},"action":"A","side":"B","price":"1.156560000","size":30,"channel_id":23,"order_id":"10998899590962587931","flags":0,"ts_in_delta":911,"sequence":145298,"symbol":"FCEU SI 20260615 PS"}
{"ts_recv":"2026-04-07T02:05:54.107826399Z","hd":{"ts_event":"2026-04-07T02:05:54.107806029Z","rtype":160,"publisher_id":101,"instrument_id":436},"action":"C","side":"A","price":"1.156670000","size":30,"channel_id":23,"order_id":"1775527545954635021","flags":0,"ts_in_delta":911,"sequence":145298,"symbol":"FCEU SI 20260615 PS"}
{"ts_recv":"2026-04-07T02:05:54.107826399Z","hd":{"ts_event":"2026-04-07T02:05:54.107806029Z","rtype":160,"publisher_id":101,"instrument_id":436},"action":"A","side":"A","price":"1.156660000","size":30,"channel_id":23,"order_id":"1775527554107812123","flags":128,"ts_in_delta":911,"sequence":145298,"symbol":"FCEU SI 20260615 PS"}
{"ts_recv":"2026-04-07T02:05:54.107894018Z","hd":{"ts_event":"2026-04-07T02:05:54.107872211Z","rtype":160,"publisher_id":101,"instrument_id":436},"action":"C","side":"B","price":"1.156570000","size":30,"channel_id":23,"order_id":"10998899582809348524","flags":0,"ts_in_delta":907,"sequence":145299,"symbol":"FCEU SI 20260615 PS"}
{"ts_recv":"2026-04-07T02:05:54.107894018Z","hd":{"ts_event":"2026-04-07T02:05:54.107872211Z","rtype":160,"publisher_id":101,"instrument_id":436},"action":"A","side":"B","price":"1.156550000","size":30,"channel_id":23,"order_id":"10998899590962654389","flags":0,"ts_in_delta":907,"sequence":145299,"symbol":"FCEU SI 20260615 PS"}
{"ts_recv":"2026-04-07T02:05:54.107894018Z","hd":{"ts_event":"2026-04-07T02:05:54.107872211Z","rtype":160,"publisher_id":101,"instrument_id":436},"action":"C","side":"A","price":"1.156670000","size":30,"channel_id":23,"order_id":"1775527545954572716","flags":0,"ts_in_delta":907,"sequence":145299,"symbol":"FCEU SI 20260615 PS"}
{"ts_recv":"2026-04-07T02:05:54.107894018Z","hd":{"ts_event":"2026-04-07T02:05:54.107872211Z","rtype":160,"publisher_id":101,"instrument_id":436},"action":"A","side":"A","price":"1.156650000","size":30,"channel_id":23,"order_id":"1775527554107878581","flags":128,"ts_in_delta":907,"sequence":145299,"symbol":"FCEU SI 20260615 PS"}
{"ts_recv":"2026-04-07T02:05:54.107955647Z","hd":{"ts_event":"2026-04-07T02:05:54.107935125Z","rtype":160,"publisher_id":101,"instrument_id":436},"action":"C","side":"B","price":"1.156560000","size":30,"channel_id":23,"order_id":"10998899590962587931","flags":0,"ts_in_delta":910,"sequence":145300,"symbol":"FCEU SI 20260615 PS"}
{"ts_recv":"2026-04-07T02:05:54.107955647Z","hd":{"ts_event":"2026-04-07T02:05:54.107935125Z","rtype":160,"publisher_id":101,"instrument_id":436},"action":"A","side":"B","price":"1.156550000","size":30,"channel_id":23,"order_id":"10998899590962716746","flags":0,"ts_in_delta":910,"sequence":145300,"symbol":"FCEU SI 20260615 PS"}
{"ts_recv":"2026-04-07T02:05:54.107955647Z","hd":{"ts_event":"2026-04-07T02:05:54.107935125Z","rtype":160,"publisher_id":101,"instrument_id":436},"action":"C","side":"A","price":"1.156660000","size":30,"channel_id":23,"order_id":"1775527554107812123","flags":0,"ts_in_delta":910,"sequence":145300,"symbol":"FCEU SI 20260615 PS"}
{"ts_recv":"2026-04-07T02:05:54.107955647Z","hd":{"ts_event":"2026-04-07T02:05:54.107935125Z","rtype":160,"publisher_id":101,"instrument_id":436},"action":"A","side":"A","price":"1.156650000","size":30,"channel_id":23,"order_id":"1775527554107940938","flags":128,"ts_in_delta":910,"sequence":145300,"symbol":"FCEU SI 20260615 PS"}
{"ts_recv":"2026-04-07T02:05:54.121236561Z","hd":{"ts_event":"2026-04-07T02:05:54.121216427Z","rtype":160,"publisher_id":101,"instrument_id":436},"action":"C","side":"B","price":"1.156550000","size":30,"channel_id":23,"order_id":"10998899590962716746","flags":0,"ts_in_delta":900,"sequence":145312,"symbol":"FCEU SI 20260615 PS"}
{"ts_recv":"2026-04-07T02:05:54.121236561Z","hd":{"ts_event":"2026-04-07T02:05:54.121216427Z","rtype":160,"publisher_id":101,"instrument_id":436},"action":"A","side":"B","price":"1.156540000","size":30,"channel_id":23,"order_id":"10998899590975998024","flags":0,"ts_in_delta":900,"sequence":145312,"symbol":"FCEU SI 20260615 PS"}
{"ts_recv":"2026-04-07T02:05:54.121236561Z","hd":{"ts_event":"2026-04-07T02:05:54.121216427Z","rtype":160,"publisher_id":101,"instrument_id":436},"action":"C","side":"A","price":"1.156650000","size":30,"channel_id":23,"order_id":"1775527554107940938","flags":0,"ts_in_delta":900,"sequence":145312,"symbol":"FCEU SI 20260615 PS"}
{"ts_recv":"2026-04-07T02:05:54.121236561Z","hd":{"ts_event":"2026-04-07T02:05:54.121216427Z","rtype":160,"publisher_id":101,"instrument_id":436},"action":"A","side":"A","price":"1.156640000","size":30,"channel_id":23,"order_id":"1775527554121222216","flags":128,"ts_in_delta":900,"sequence":145312,"symbol":"FCEU SI 20260615 PS"}
{"ts_recv":"2026-04-07T02:05:59.146344060Z","hd":{"ts_event":"2026-04-07T02:05:59.146325649Z","rtype":160,"publisher_id":101,"instrument_id":436},"action":"C","side":"B","price":"1.156540000","size":30,"channel_id":23,"order_id":"10998899590975998024","flags":0,"ts_in_delta":938,"sequence":145383,"symbol":"FCEU SI 20260615 PS"}
{"ts_recv":"2026-04-07T02:05:59.146344060Z","hd":{"ts_event":"2026-04-07T02:05:59.146325649Z","rtype":160,"publisher_id":101,"instrument_id":436},"action":"A","side":"B","price":"1.156550000","size":30,"channel_id":23,"order_id":"10998899596001107536","flags":0,"ts_in_delta":938,"sequence":145383,"symbol":"FCEU SI 20260615 PS"}
{"ts_recv":"2026-04-07T02:05:59.146344060Z","hd":{"ts_event":"2026-04-07T02:05:59.146325649Z","rtype":160,"publisher_id":101,"instrument_id":436},"action":"C","side":"A","price":"1.156640000","size":30,"channel_id":23,"order_id":"1775527554121222216","flags":0,"ts_in_delta":938,"sequence":145383,"symbol":"FCEU SI 20260615 PS"}
{"ts_recv":"2026-04-07T02:05:59.146344060Z","hd":{"ts_event":"2026-04-07T02:05:59.146325649Z","rtype":160,"publisher_id":101,"instrument_id":436},"action":"A","side":"A","price":"1.156650000","size":30,"channel_id":23,"order_id":"1775527559146331728","flags":128,"ts_in_delta":938,"sequence":145383,"symbol":"FCEU SI 20260615 PS"}
{"ts_recv":"2026-04-07T02:05:59.283915637Z","hd":{"ts_event":"2026-04-07T02:05:59.283895083Z","rtype":160,"publisher_id":101,"instrument_id":436},"action":"C","side":"B","price":"1.156550000","size":30,"channel_id":23,"order_id":"10998899596001107536","flags":0,"ts_in_delta":982,"sequence":145397,"symbol":"FCEU SI 20260615 PS"}
{"ts_recv":"2026-04-07T02:05:59.283915637Z","hd":{"ts_event":"2026-04-07T02:05:59.283895083Z","rtype":160,"publisher_id":101,"instrument_id":436},"action":"A","side":"B","price":"1.156560000","size":30,"channel_id":23,"order_id":"10998899596138676871","flags":0,"ts_in_delta":982,"sequence":145397,"symbol":"FCEU SI 20260615 PS"}
{"ts_recv":"2026-04-07T02:05:59.283915637Z","hd":{"ts_event":"2026-04-07T02:05:59.283895083Z","rtype":160,"publisher_id":101,"instrument_id":436},"action":"C","side":"A","price":"1.156650000","size":30,"channel_id":23,"order_id":"1775527559146331728","flags":0,"ts_in_delta":982,"sequence":145397,"symbol":"FCEU SI 20260615 PS"}
{"ts_recv":"2026-04-07T02:05:59.283915637Z","hd":{"ts_event":"2026-04-07T02:05:59.283895083Z","rtype":160,"publisher_id":101,"instrument_id":436},"action":"A","side":"A","price":"1.156660000","size":30,"channel_id":23,"order_id":"1775527559283901063","flags":128,"ts_in_delta":982,"sequence":145397,"symbol":"FCEU SI 20260615 PS"}
{"ts_recv":"2026-04-07T02:06:01.013857763Z","hd":{"ts_event":"2026-04-07T02:06:01.013825363Z","rtype":160,"publisher_id":101,"instrument_id":436},"action":"C","side":"B","price":"1.156550000","size":30,"channel_id":23,"order_id":"10998899590962654389","flags":0,"ts_in_delta":1279,"sequence":145430,"symbol":"FCEU SI 20260615 PS"}
{"ts_recv":"2026-04-07T02:06:01.013857763Z","hd":{"ts_event":"2026-04-07T02:06:01.013825363Z","rtype":160,"publisher_id":101,"instrument_id":436},"action":"A","side":"B","price":"1.156570000","size":30,"channel_id":23,"order_id":"10998899597868607871","flags":0,"ts_in_delta":1279,"sequence":145430,"symbol":"FCEU SI 20260615 PS"}
{"ts_recv":"2026-04-07T02:06:01.013857763Z","hd":{"ts_event":"2026-04-07T02:06:01.013825363Z","rtype":160,"publisher_id":101,"instrument_id":436},"action":"C","side":"A","price":"1.156650000","size":30,"channel_id":23,"order_id":"1775527554107878581","flags":0,"ts_in_delta":1279,"sequence":145430,"symbol":"FCEU SI 20260615 PS"}
{"ts_recv":"2026-04-07T02:06:01.013857763Z","hd":{"ts_event":"2026-04-07T02:06:01.013825363Z","rtype":160,"publisher_id":101,"instrument_id":436},"action":"A","side":"A","price":"1.156670000","size":30,"channel_id":23,"order_id":"1775527561013832063","flags":128,"ts_in_delta":1279,"sequence":145430,"symbol":"FCEU SI 20260615 PS"}
{"ts_recv":"2026-04-07T02:06:01.013940027Z","hd":{"ts_event":"2026-04-07T02:06:01.013923135Z","rtype":160,"publisher_id":101,"instrument_id":436},"action":"C","side":"B","price":"1.156560000","size":30,"channel_id":23,"order_id":"10998899596138676871","flags":0,"ts_in_delta":1051,"sequence":145431,"symbol":"FCEU SI 20260615 PS"}
{"ts_recv":"2026-04-07T02:06:01.013940027Z","hd":{"ts_event":"2026-04-07T02:06:01.013923135Z","rtype":160,"publisher_id":101,"instrument_id":436},"action":"A","side":"B","price":"1.156570000","size":30,"channel_id":23,"order_id":"10998899597868704789","flags":0,"ts_in_delta":1051,"sequence":145431,"symbol":"FCEU SI 20260615 PS"}
{"ts_recv":"2026-04-07T02:06:01.013940027Z","hd":{"ts_event":"2026-04-07T02:06:01.013923135Z","rtype":160,"publisher_id":101,"instrument_id":436},"action":"C","side":"A","price":"1.156660000","size":30,"channel_id":23,"order_id":"1775527559283901063","flags":0,"ts_in_delta":1051,"sequence":145431,"symbol":"FCEU SI 20260615 PS"}
{"ts_recv":"2026-04-07T02:06:01.013940027Z","hd":{"ts_event":"2026-04-07T02:06:01.013923135Z","rtype":160,"publisher_id":101,"instrument_id":436},"action":"A","side":"A","price":"1.156670000","size":30,"channel_id":23,"order_id":"1775527561013928981","flags":128,"ts_in_delta":1051,"sequence":145431,"symbol":"FCEU SI 20260615 PS"}
{"ts_recv":"2026-04-07T02:06:01.026879120Z","hd":{"ts_event":"2026-04-07T02:06:01.026860019Z","rtype":160,"publisher_id":101,"instrument_id":436},"action":"C","side":"B","price":"1.156570000","size":30,"channel_id":23,"order_id":"10998899597868704789","flags":0,"ts_in_delta":914,"sequence":145441,"symbol":"FCEU SI 20260615 PS"}
{"ts_recv":"2026-04-07T02:06:01.026879120Z","hd":{"ts_event":"2026-04-07T02:06:01.026860019Z","rtype":160,"publisher_id":101,"instrument_id":436},"action":"A","side":"B","price":"1.156580000","size":30,"channel_id":23,"order_id":"10998899597881641574","flags":0,"ts_in_delta":914,"sequence":145441,"symbol":"FCEU SI 20260615 PS"}
{"ts_recv":"2026-04-07T02:06:01.026879120Z","hd":{"ts_event":"2026-04-07T02:06:01.026860019Z","rtype":160,"publisher_id":101,"instrument_id":436},"action":"C","side":"A","price":"1.156670000","size":30,"channel_id":23,"order_id":"1775527561013928981","flags":0,"ts_in_delta":914,"sequence":145441,"symbol":"FCEU SI 20260615 PS"}
{"ts_recv":"2026-04-07T02:06:01.026879120Z","hd":{"ts_event":"2026-04-07T02:06:01.026860019Z","rtype":160,"publisher_id":101,"instrument_id":436},"action":"A","side":"A","price":"1.156680000","size":30,"channel_id":23,"order_id":"1775527561026865766","flags":128,"ts_in_delta":914,"sequence":145441,"symbol":"FCEU SI 20260615 PS"}
{"ts_recv":"2026-04-07T02:06:01.657759891Z","hd":{"ts_event":"2026-04-07T02:06:01.657741187Z","rtype":160,"publisher_id":101,"instrument_id":436},"action":"C","side":"B","price":"1.156580000","size":30,"channel_id":23,"order_id":"10998899597881641574","flags":0,"ts_in_delta":1072,"sequence":145460,"symbol":"FCEU SI 20260615 PS"}
{"ts_recv":"2026-04-07T02:06:01.657759891Z","hd":{"ts_event":"2026-04-07T02:06:01.657741187Z","rtype":160,"publisher_id":101,"instrument_id":436},"action":"A","side":"B","price":"1.156570000","size":30,"channel_id":23,"order_id":"10998899598512523025","flags":0,"ts_in_delta":1072,"sequence":145460,"symbol":"FCEU SI 20260615 PS"}
{"ts_recv":"2026-04-07T02:06:01.657759891Z","hd":{"ts_event":"2026-04-07T02:06:01.657741187Z","rtype":160,"publisher_id":101,"instrument_id":436},"action":"C","side":"A","price":"1.156680000","size":30,"channel_id":23,"order_id":"1775527561026865766","flags":0,"ts_in_delta":1072,"sequence":145460,"symbol":"FCEU SI 20260615 PS"}
{"ts_recv":"2026-04-07T02:06:01.657759891Z","hd":{"ts_event":"2026-04-07T02:06:01.657741187Z","rtype":160,"publisher_id":101,"instrument_id":436},"action":"A","side":"A","price":"1.156670000","size":30,"channel_id":23,"order_id":"1775527561657747217","flags":128,"ts_in_delta":1072,"sequence":145460,"symbol":"FCEU SI 20260615 PS"}
{"ts_recv":"2026-04-07T02:06:09.893914424Z","hd":{"ts_event":"2026-04-07T02:06:09.893890139Z","rtype":160,"publisher_id":101,"instrument_id":436},"action":"C","side":"B","price":"1.156570000","size":30,"channel_id":23,"order_id":"10998899598512523025","flags":0,"ts_in_delta":1032,"sequence":145516,"symbol":"FCEU SI 20260615 PS"}
{"ts_recv":"2026-04-07T02:06:09.893914424Z","hd":{"ts_event":"2026-04-07T02:06:09.893890139Z","rtype":160,"publisher_id":101,"instrument_id":436},"action":"A","side":"B","price":"1.156580000","size":30,"channel_id":23,"order_id":"10998899606748672261","flags":0,"ts_in_delta":1032,"sequence":145516,"symbol":"FCEU SI 20260615 PS"}
{"ts_recv":"2026-04-07T02:06:09.893914424Z","hd":{"ts_event":"2026-04-07T02:06:09.893890139Z","rtype":160,"publisher_id":101,"instrument_id":436},"action":"C","side":"A","price":"1.156670000","size":30,"channel_id":23,"order_id":"1775527561657747217","flags":0,"ts_in_delta":1032,"sequence":145516,"symbol":"FCEU SI 20260615 PS"}
{"ts_recv":"2026-04-07T02:06:09.893914424Z","hd":{"ts_event":"2026-04-07T02:06:09.893890139Z","rtype":160,"publisher_id":101,"instrument_id":436},"action":"A","side":"A","price":"1.156680000","size":30,"channel_id":23,"order_id":"1775527569893896453","flags":128,"ts_in_delta":1032,"sequence":145516,"symbol":"FCEU SI 20260615 PS"}
{"ts_recv":"2026-04-07T02:06:10.537902411Z","hd":{"ts_event":"2026-04-07T02:06:10.537881097Z","rtype":160,"publisher_id":101,"instrument_id":436},"action":"C","side":"B","price":"1.156570000","size":30,"channel_id":23,"order_id":"10998899597868607871","flags":0,"ts_in_delta":897,"sequence":145531,"symbol":"FCEU SI 20260615 PS"}
{"ts_recv":"2026-04-07T02:06:10.537902411Z","hd":{"ts_event":"2026-04-07T02:06:10.537881097Z","rtype":160,"publisher_id":101,"instrument_id":436},"action":"A","side":"B","price":"1.156590000","size":30,"channel_id":23,"order_id":"10998899607392662928","flags":0,"ts_in_delta":897,"sequence":145531,"symbol":"FCEU SI 20260615 PS"}
{"ts_recv":"2026-04-07T02:06:10.537902411Z","hd":{"ts_event":"2026-04-07T02:06:10.537881097Z","rtype":160,"publisher_id":101,"instrument_id":436},"action":"C","side":"A","price":"1.156670000","size":30,"channel_id":23,"order_id":"1775527561013832063","flags":0,"ts_in_delta":897,"sequence":145531,"symbol":"FCEU SI 20260615 PS"}
{"ts_recv":"2026-04-07T02:06:10.537902411Z","hd":{"ts_event":"2026-04-07T02:06:10.537881097Z","rtype":160,"publisher_id":101,"instrument_id":436},"action":"A","side":"A","price":"1.156690000","size":30,"channel_id":23,"order_id":"1775527570537887120","flags":128,"ts_in_delta":897,"sequence":145531,"symbol":"FCEU SI 20260615 PS"}
{"ts_recv":"2026-04-07T02:06:10.537974077Z","hd":{"ts_event":"2026-04-07T02:06:10.537956867Z","rtype":160,"publisher_id":101,"instrument_id":436},"action":"C","side":"B","price":"1.156580000","size":30,"channel_id":23,"order_id":"10998899606748672261","flags":0,"ts_in_delta":907,"sequence":145532,"symbol":"FCEU SI 20260615 PS"}
{"ts_recv":"2026-04-07T02:06:10.537974077Z","hd":{"ts_event":"2026-04-07T02:06:10.537956867Z","rtype":160,"publisher_id":101,"instrument_id":436},"action":"A","side":"B","price":"1.156590000","size":30,"channel_id":23,"order_id":"10998899607392738639","flags":0,"ts_in_delta":907,"sequence":145532,"symbol":"FCEU SI 20260615 PS"}
{"ts_recv":"2026-04-07T02:06:10.537974077Z","hd":{"ts_event":"2026-04-07T02:06:10.537956867Z","rtype":160,"publisher_id":101,"instrument_id":436},"action":"C","side":"A","price":"1.156680000","size":30,"channel_id":23,"order_id":"1775527569893896453","flags":0,"ts_in_delta":907,"sequence":145532,"symbol":"FCEU SI 20260615 PS"}
{"ts_recv":"2026-04-07T02:06:10.537974077Z","hd":{"ts_event":"2026-04-07T02:06:10.537956867Z","rtype":160,"publisher_id":101,"instrument_id":436},"action":"A","side":"A","price":"1.156690000","size":30,"channel_id":23,"order_id":"1775527570537962831","flags":128,"ts_in_delta":907,"sequence":145532,"symbol":"FCEU SI 20260615 PS"}
{"ts_recv":"2026-04-07T02:06:10.544246092Z","hd":{"ts_event":"2026-04-07T02:06:10.544226303Z","rtype":160,"publisher_id":101,"instrument_id":436},"action":"C","side":"B","price":"1.156590000","size":30,"channel_id":23,"order_id":"10998899607392738639","flags":0,"ts_in_delta":924,"sequence":145536,"symbol":"FCEU SI 20260615 PS"}
{"ts_recv":"2026-04-07T02:06:10.544246092Z","hd":{"ts_event":"2026-04-07T02:06:10.544226303Z","rtype":160,"publisher_id":101,"instrument_id":436},"action":"A","side":"B","price":"1.156600000","size":30,"channel_id":23,"order_id":"10998899607399007699","flags":0,"ts_in_delta":924,"sequence":145536,"symbol":"FCEU SI 20260615 PS"}
{"ts_recv":"2026-04-07T02:06:10.544246092Z","hd":{"ts_event":"2026-04-07T02:06:10.544226303Z","rtype":160,"publisher_id":101,"instrument_id":436},"action":"C","side":"A","price":"1.156690000","size":30,"channel_id":23,"order_id":"1775527570537962831","flags":0,"ts_in_delta":924,"sequence":145536,"symbol":"FCEU SI 20260615 PS"}
{"ts_recv":"2026-04-07T02:06:10.544246092Z","hd":{"ts_event":"2026-04-07T02:06:10.544226303Z","rtype":160,"publisher_id":101,"instrument_id":436},"action":"A","side":"A","price":"1.156700000","size":30,"channel_id":23,"order_id":"1775527570544231891","flags":128,"ts_in_delta":924,"sequence":145536,"symbol":"FCEU SI 20260615 PS"}
{"ts_recv":"2026-04-07T02:06:10.548958025Z","hd":{"ts_event":"2026-04-07T02:06:10.548939957Z","rtype":160,"publisher_id":101,"instrument_id":436},"action":"C","side":"B","price":"1.156600000","size":30,"channel_id":23,"order_id":"10998899607399007699","flags":0,"ts_in_delta":931,"sequence":145538,"symbol":"FCEU SI 20260615 PS"}
{"ts_recv":"2026-04-07T02:06:10.548958025Z","hd":{"ts_event":"2026-04-07T02:06:10.548939957Z","rtype":160,"publisher_id":101,"instrument_id":436},"action":"A","side":"B","price":"1.156630000","size":30,"channel_id":23,"order_id":"10998899607403721734","flags":0,"ts_in_delta":931,"sequence":145538,"symbol":"FCEU SI 20260615 PS"}
{"ts_recv":"2026-04-07T02:06:10.548958025Z","hd":{"ts_event":"2026-04-07T02:06:10.548939957Z","rtype":160,"publisher_id":101,"instrument_id":436},"action":"C","side":"A","price":"1.156700000","size":30,"channel_id":23,"order_id":"1775527570544231891","flags":0,"ts_in_delta":931,"sequence":145538,"symbol":"FCEU SI 20260615 PS"}
{"ts_recv":"2026-04-07T02:06:10.548958025Z","hd":{"ts_event":"2026-04-07T02:06:10.548939957Z","rtype":160,"publisher_id":101,"instrument_id":436},"action":"A","side":"A","price":"1.156730000","size":30,"channel_id":23,"order_id":"1775527570548945926","flags":128,"ts_in_delta":931,"sequence":145538,"symbol":"FCEU SI 20260615 PS"}
{"ts_recv":"2026-04-07T02:06:10.549011015Z","hd":{"ts_event":"2026-04-07T02:06:10.548992449Z","rtype":160,"publisher_id":101,"instrument_id":436},"action":"C","side":"B","price":"1.156590000","size":30,"channel_id":23,"order_id":"10998899607392662928","flags":0,"ts_in_delta":896,"sequence":145539,"symbol":"FCEU SI 20260615 PS"}
{"ts_recv":"2026-04-07T02:06:10.549011015Z","hd":{"ts_event":"2026-04-07T02:06:10.548992449Z","rtype":160,"publisher_id":101,"instrument_id":436},"action":"A","side":"B","price":"1.156620000","size":30,"channel_id":23,"order_id":"10998899607403774161","flags":0,"ts_in_delta":896,"sequence":145539,"symbol":"FCEU SI 20260615 PS"}
{"ts_recv":"2026-04-07T02:06:10.549011015Z","hd":{"ts_event":"2026-04-07T02:06:10.548992449Z","rtype":160,"publisher_id":101,"instrument_id":436},"action":"C","side":"A","price":"1.156690000","size":30,"channel_id":23,"order_id":"1775527570537887120","flags":0,"ts_in_delta":896,"sequence":145539,"symbol":"FCEU SI 20260615 PS"}
{"ts_recv":"2026-04-07T02:06:10.549011015Z","hd":{"ts_event":"2026-04-07T02:06:10.548992449Z","rtype":160,"publisher_id":101,"instrument_id":436},"action":"A","side":"A","price":"1.156720000","size":30,"channel_id":23,"order_id":"1775527570548998353","flags":128,"ts_in_delta":896,"sequence":145539,"symbol":"FCEU SI 20260615 PS"}
{"ts_recv":"2026-04-07T02:06:10.549039453Z","hd":{"ts_event":"2026-04-07T02:06:10.549020629Z","rtype":160,"publisher_id":101,"instrument_id":436},"action":"C","side":"B","price":"1.156630000","size":30,"channel_id":23,"order_id":"10998899607403721734","flags":0,"ts_in_delta":907,"sequence":145540,"symbol":"FCEU SI 20260615 PS"}
{"ts_recv":"2026-04-07T02:06:10.549039453Z","hd":{"ts_event":"2026-04-07T02:06:10.549020629Z","rtype":160,"publisher_id":101,"instrument_id":436},"action":"A","side":"B","price":"1.156610000","size":30,"channel_id":23,"order_id":"10998899607403802535","flags":0,"ts_in_delta":907,"sequence":145540,"symbol":"FCEU SI 20260615 PS"}
{"ts_recv":"2026-04-07T02:06:10.549039453Z","hd":{"ts_event":"2026-04-07T02:06:10.549020629Z","rtype":160,"publisher_id":101,"instrument_id":436},"action":"C","side":"A","price":"1.156730000","size":30,"channel_id":23,"order_id":"1775527570548945926","flags":0,"ts_in_delta":907,"sequence":145540,"symbol":"FCEU SI 20260615 PS"}
{"ts_recv":"2026-04-07T02:06:10.549039453Z","hd":{"ts_event":"2026-04-07T02:06:10.549020629Z","rtype":160,"publisher_id":101,"instrument_id":436},"action":"A","side":"A","price":"1.156710000","size":30,"channel_id":23,"order_id":"1775527570549026727","flags":128,"ts_in_delta":907,"sequence":145540,"symbol":"FCEU SI 20260615 PS"}
{"ts_recv":"2026-04-07T02:06:10.549093733Z","hd":{"ts_event":"2026-04-07T02:06:10.549078641Z","rtype":160,"publisher_id":101,"instrument_id":436},"action":"C","side":"B","price":"1.156610000","size":30,"channel_id":23,"order_id":"10998899607403802535","flags":0,"ts_in_delta":879,"sequence":145541,"symbol":"FCEU SI 20260615 PS"}
{"ts_recv":"2026-04-07T02:06:10.549093733Z","hd":{"ts_event":"2026-04-07T02:06:10.549078641Z","rtype":160,"publisher_id":101,"instrument_id":436},"action":"A","side":"B","price":"1.156620000","size":30,"channel_id":23,"order_id":"10998899607403860111","flags":0,"ts_in_delta":879,"sequence":145541,"symbol":"FCEU SI 20260615 PS"}
{"ts_recv":"2026-04-07T02:06:10.549093733Z","hd":{"ts_event":"2026-04-07T02:06:10.549078641Z","rtype":160,"publisher_id":101,"instrument_id":436},"action":"C","side":"A","price":"1.156710000","size":30,"channel_id":23,"order_id":"1775527570549026727","flags":0,"ts_in_delta":879,"sequence":145541,"symbol":"FCEU SI 20260615 PS"}
{"ts_recv":"2026-04-07T02:06:10.549093733Z","hd":{"ts_event":"2026-04-07T02:06:10.549078641Z","rtype":160,"publisher_id":101,"instrument_id":436},"action":"A","side":"A","price":"1.156720000","size":30,"channel_id":23,"order_id":"1775527570549084303","flags":128,"ts_in_delta":879,"sequence":145541,"symbol":"FCEU SI 20260615 PS"}
{"ts_recv":"2026-04-07T02:06:10.582250406Z","hd":{"ts_event":"2026-04-07T02:06:10.582235051Z","rtype":160,"publisher_id":101,"instrument_id":436},"action":"A","side":"B","price":"1.156500000","size":20,"channel_id":23,"order_id":"10998899607437016903","flags":128,"ts_in_delta":946,"sequence":145551,"symbol":"FCEU SI 20260615 PS"}
{"ts_recv":"2026-04-07T02:06:10.582491577Z","hd":{"ts_event":"2026-04-07T02:06:10.582478591Z","rtype":160,"publisher_id":101,"instrument_id":436},"action":"C","side":"B","price":"1.156400000","size":20,"channel_id":23,"order_id":"10998899569216182573","flags":128,"ts_in_delta":815,"sequence":145552,"symbol":"FCEU SI 20260615 PS"}
{"ts_recv":"2026-04-07T02:06:13.752777582Z","hd":{"ts_event":"2026-04-07T02:06:13.752746529Z","rtype":160,"publisher_id":101,"instrument_id":436},"action":"C","side":"B","price":"1.156620000","size":30,"channel_id":23,"order_id":"10998899607403860111","flags":0,"ts_in_delta":1646,"sequence":145594,"symbol":"FCEU SI 20260615 PS"}
{"ts_recv":"2026-04-07T02:06:13.752777582Z","hd":{"ts_event":"2026-04-07T02:06:13.752746529Z","rtype":160,"publisher_id":101,"instrument_id":436},"action":"A","side":"B","price":"1.156610000","size":30,"channel_id":23,"order_id":"10998899610607536129","flags":0,"ts_in_delta":1646,"sequence":145594,"symbol":"FCEU SI 20260615 PS"}
{"ts_recv":"2026-04-07T02:06:13.752777582Z","hd":{"ts_event":"2026-04-07T02:06:13.752746529Z","rtype":160,"publisher_id":101,"instrument_id":436},"action":"C","side":"A","price":"1.156720000","size":30,"channel_id":23,"order_id":"1775527570549084303","flags":0,"ts_in_delta":1646,"sequence":145594,"symbol":"FCEU SI 20260615 PS"}
{"ts_recv":"2026-04-07T02:06:13.752777582Z","hd":{"ts_event":"2026-04-07T02:06:13.752746529Z","rtype":160,"publisher_id":101,"instrument_id":436},"action":"A","side":"A","price":"1.156710000","size":30,"channel_id":23,"order_id":"1775527573752760321","flags":128,"ts_in_delta":1646,"sequence":145594,"symbol":"FCEU SI 20260615 PS"}
{"ts_recv":"2026-04-07T02:06:13.758086531Z","hd":{"ts_event":"2026-04-07T02:06:13.758065155Z","rtype":160,"publisher_id":101,"instrument_id":436},"action":"C","side":"B","price":"1.156620000","size":30,"channel_id":23,"order_id":"10998899607403774161","flags":0,"ts_in_delta":1019,"sequence":145596,"symbol":"FCEU SI 20260615 PS"}
{"ts_recv":"2026-04-07T02:06:13.758086531Z","hd":{"ts_event":"2026-04-07T02:06:13.758065155Z","rtype":160,"publisher_id":101,"instrument_id":436},"action":"A","side":"B","price":"1.156600000","size":30,"channel_id":23,"order_id":"10998899610612846779","flags":0,"ts_in_delta":1019,"sequence":145596,"symbol":"FCEU SI 20260615 PS"}
{"ts_recv":"2026-04-07T02:06:13.758086531Z","hd":{"ts_event":"2026-04-07T02:06:13.758065155Z","rtype":160,"publisher_id":101,"instrument_id":436},"action":"C","side":"A","price":"1.156720000","size":30,"channel_id":23,"order_id":"1775527570548998353","flags":0,"ts_in_delta":1019,"sequence":145596,"symbol":"FCEU SI 20260615 PS"}
{"ts_recv":"2026-04-07T02:06:13.758086531Z","hd":{"ts_event":"2026-04-07T02:06:13.758065155Z","rtype":160,"publisher_id":101,"instrument_id":436},"action":"A","side":"A","price":"1.156700000","size":30,"channel_id":23,"order_id":"1775527573758070971","flags":128,"ts_in_delta":1019,"sequence":145596,"symbol":"FCEU SI 20260615 PS"}
{"ts_recv":"2026-04-07T02:06:13.758153651Z","hd":{"ts_event":"2026-04-07T02:06:13.758136847Z","rtype":160,"publisher_id":101,"instrument_id":436},"action":"C","side":"B","price":"1.156610000","size":30,"channel_id":23,"order_id":"10998899610607536129","flags":0,"ts_in_delta":990,"sequence":145597,"symbol":"FCEU SI 20260615 PS"}
{"ts_recv":"2026-04-07T02:06:13.758153651Z","hd":{"ts_event":"2026-04-07T02:06:13.758136847Z","rtype":160,"publisher_id":101,"instrument_id":436},"action":"A","side":"B","price":"1.156600000","size":30,"channel_id":23,"order_id":"10998899610612918628","flags":0,"ts_in_delta":990,"sequence":145597,"symbol":"FCEU SI 20260615 PS"}
{"ts_recv":"2026-04-07T02:06:13.758153651Z","hd":{"ts_event":"2026-04-07T02:06:13.758136847Z","rtype":160,"publisher_id":101,"instrument_id":436},"action":"C","side":"A","price":"1.156710000","size":30,"channel_id":23,"order_id":"1775527573752760321","flags":0,"ts_in_delta":990,"sequence":145597,"symbol":"FCEU SI 20260615 PS"}
{"ts_recv":"2026-04-07T02:06:13.758153651Z","hd":{"ts_event":"2026-04-07T02:06:13.758136847Z","rtype":160,"publisher_id":101,"instrument_id":436},"action":"A","side":"A","price":"1.156700000","size":30,"channel_id":23,"order_id":"1775527573758142820","flags":128,"ts_in_delta":990,"sequence":145597,"symbol":"FCEU SI 20260615 PS"}
{"ts_recv":"2026-04-07T02:06:13.916715983Z","hd":{"ts_event":"2026-04-07T02:06:13.916696727Z","rtype":160,"publisher_id":101,"instrument_id":436},"action":"C","side":"B","price":"1.156600000","size":30,"channel_id":23,"order_id":"10998899610612918628","flags":0,"ts_in_delta":1146,"sequence":145624,"symbol":"FCEU SI 20260615 PS"}
{"ts_recv":"2026-04-07T02:06:13.916715983Z","hd":{"ts_event":"2026-04-07T02:06:13.916696727Z","rtype":160,"publisher_id":101,"instrument_id":436},"action":"A","side":"B","price":"1.156590000","size":30,"channel_id":23,"order_id":"10998899610771478345","flags":0,"ts_in_delta":1146,"sequence":145624,"symbol":"FCEU SI 20260615 PS"}
{"ts_recv":"2026-04-07T02:06:13.916715983Z","hd":{"ts_event":"2026-04-07T02:06:13.916696727Z","rtype":160,"publisher_id":101,"instrument_id":436},"action":"C","side":"A","price":"1.156700000","size":30,"channel_id":23,"order_id":"1775527573758142820","flags":0,"ts_in_delta":1146,"sequence":145624,"symbol":"FCEU SI 20260615 PS"}
{"ts_recv":"2026-04-07T02:06:13.916715983Z","hd":{"ts_event":"2026-04-07T02:06:13.916696727Z","rtype":160,"publisher_id":101,"instrument_id":436},"action":"A","side":"A","price":"1.156690000","size":30,"channel_id":23,"order_id":"1775527573916702537","flags":128,"ts_in_delta":1146,"sequence":145624,"symbol":"FCEU SI 20260615 PS"}
{"ts_recv":"2026-04-07T02:06:13.926211684Z","hd":{"ts_event":"2026-04-07T02:06:13.926192393Z","rtype":160,"publisher_id":101,"instrument_id":436},"action":"C","side":"B","price":"1.156600000","size":30,"channel_id":23,"order_id":"10998899610612846779","flags":0,"ts_in_delta":977,"sequence":145633,"symbol":"FCEU SI 20260615 PS"}
{"ts_recv":"2026-04-07T02:06:13.926211684Z","hd":{"ts_event":"2026-04-07T02:06:13.926192393Z","rtype":160,"publisher_id":101,"instrument_id":436},"action":"A","side":"B","price":"1.156580000","size":30,"channel_id":23,"order_id":"10998899610780974070","flags":0,"ts_in_delta":977,"sequence":145633,"symbol":"FCEU SI 20260615 PS"}
{"ts_recv":"2026-04-07T02:06:13.926211684Z","hd":{"ts_event":"2026-04-07T02:06:13.926192393Z","rtype":160,"publisher_id":101,"instrument_id":436},"action":"C","side":"A","price":"1.156700000","size":30,"channel_id":23,"order_id":"1775527573758070971","flags":0,"ts_in_delta":977,"sequence":145633,"symbol":"FCEU SI 20260615 PS"}
{"ts_recv":"2026-04-07T02:06:13.926211684Z","hd":{"ts_event":"2026-04-07T02:06:13.926192393Z","rtype":160,"publisher_id":101,"instrument_id":436},"action":"A","side":"A","price":"1.156680000","size":30,"channel_id":23,"order_id":"1775527573926198262","flags":128,"ts_in_delta":977,"sequence":145633,"symbol":"FCEU SI 20260615 PS"}
{"ts_recv":"2026-04-07T02:06:13.926271071Z","hd":{"ts_event":"2026-04-07T02:06:13.926252105Z","rtype":160,"publisher_id":101,"instrument_id":436},"action":"C","side":"B","price":"1.156590000","size":30,"channel_id":23,"order_id":"10998899610771478345","flags":0,"ts_in_delta":1312,"sequence":145634,"symbol":"FCEU SI 20260615 PS"}
{"ts_recv":"2026-04-07T02:06:13.926271071Z","hd":{"ts_event":"2026-04-07T02:06:13.926252105Z","rtype":160,"publisher_id":101,"instrument_id":436},"action":"A","side":"B","price":"1.156580000","size":30,"channel_id":23,"order_id":"10998899610781033763","flags":0,"ts_in_delta":1312,"sequence":145634,"symbol":"FCEU SI 20260615 PS"}
{"ts_recv":"2026-04-07T02:06:13.926271071Z","hd":{"ts_event":"2026-04-07T02:06:13.926252105Z","rtype":160,"publisher_id":101,"instrument_id":436},"action":"C","side":"A","price":"1.156690000","size":30,"channel_id":23,"order_id":"1775527573916702537","flags":0,"ts_in_delta":1312,"sequence":145634,"symbol":"FCEU SI 20260615 PS"}
{"ts_recv":"2026-04-07T02:06:13.926271071Z","hd":{"ts_event":"2026-04-07T02:06:13.926252105Z","rtype":160,"publisher_id":101,"instrument_id":436},"action":"A","side":"A","price":"1.156680000","size":30,"channel_id":23,"order_id":"1775527573926257955","flags":128,"ts_in_delta":1312,"sequence":145634,"symbol":"FCEU SI 20260615 PS"}
{"ts_recv":"2026-04-07T02:06:24.128750449Z","hd":{"ts_event":"2026-04-07T02:06:24.128728459Z","rtype":160,"publisher_id":101,"instrument_id":436},"action":"C","side":"B","price":"1.156580000","size":30,"channel_id":23,"order_id":"10998899610781033763","flags":0,"ts_in_delta":893,"sequence":145750,"symbol":"FCEU SI 20260615 PS"}
{"ts_recv":"2026-04-07T02:06:24.128750449Z","hd":{"ts_event":"2026-04-07T02:06:24.128728459Z","rtype":160,"publisher_id":101,"instrument_id":436},"action":"A","side":"B","price":"1.156570000","size":30,"channel_id":23,"order_id":"10998899620983510313","flags":0,"ts_in_delta":893,"sequence":145750,"symbol":"FCEU SI 20260615 PS"}
{"ts_recv":"2026-04-07T02:06:24.128750449Z","hd":{"ts_event":"2026-04-07T02:06:24.128728459Z","rtype":160,"publisher_id":101,"instrument_id":436},"action":"C","side":"A","price":"1.156680000","size":30,"channel_id":23,"order_id":"1775527573926257955","flags":0,"ts_in_delta":893,"sequence":145750,"symbol":"FCEU SI 20260615 PS"}
{"ts_recv":"2026-04-07T02:06:24.128750449Z","hd":{"ts_event":"2026-04-07T02:06:24.128728459Z","rtype":160,"publisher_id":101,"instrument_id":436},"action":"A","side":"A","price":"1.156670000","size":30,"channel_id":23,"order_id":"1775527584128734505","flags":128,"ts_in_delta":893,"sequence":145750,"symbol":"FCEU SI 20260615 PS"}
{"ts_recv":"2026-04-07T02:06:24.128817830Z","hd":{"ts_event":"2026-04-07T02:06:24.128795775Z","rtype":160,"publisher_id":101,"instrument_id":436},"action":"C","side":"B","price":"1.156580000","size":30,"channel_id":23,"order_id":"10998899610780974070","flags":0,"ts_in_delta":897,"sequence":145751,"symbol":"FCEU SI 20260615 PS"}
{"ts_recv":"2026-04-07T02:06:24.128817830Z","hd":{"ts_event":"2026-04-07T02:06:24.128795775Z","rtype":160,"publisher_id":101,"instrument_id":436},"action":"A","side":"B","price":"1.156560000","size":30,"channel_id":23,"order_id":"10998899620983578081","flags":0,"ts_in_delta":897,"sequence":145751,"symbol":"FCEU SI 20260615 PS"}
{"ts_recv":"2026-04-07T02:06:24.128817830Z","hd":{"ts_event":"2026-04-07T02:06:24.128795775Z","rtype":160,"publisher_id":101,"instrument_id":436},"action":"C","side":"A","price":"1.156680000","size":30,"channel_id":23,"order_id":"1775527573926198262","flags":0,"ts_in_delta":897,"sequence":145751,"symbol":"FCEU SI 20260615 PS"}
{"ts_recv":"2026-04-07T02:06:24.128817830Z","hd":{"ts_event":"2026-04-07T02:06:24.128795775Z","rtype":160,"publisher_id":101,"instrument_id":436},"action":"A","side":"A","price":"1.156660000","size":30,"channel_id":23,"order_id":"1775527584128802273","flags":128,"ts_in_delta":897,"sequence":145751,"symbol":"FCEU SI 20260615 PS"}
{"ts_recv":"2026-04-07T02:06:24.128875674Z","hd":{"ts_event":"2026-04-07T02:06:24.128859371Z","rtype":160,"publisher_id":101,"instrument_id":436},"action":"C","side":"B","price":"1.156570000","size":30,"channel_id":23,"order_id":"10998899620983510313","flags":0,"ts_in_delta":911,"sequence":145752,"symbol":"FCEU SI 20260615 PS"}
{"ts_recv":"2026-04-07T02:06:24.128875674Z","hd":{"ts_event":"2026-04-07T02:06:24.128859371Z","rtype":160,"publisher_id":101,"instrument_id":436},"action":"A","side":"B","price":"1.156560000","size":30,"channel_id":23,"order_id":"10998899620983641317","flags":0,"ts_in_delta":911,"sequence":145752,"symbol":"FCEU SI 20260615 PS"}
{"ts_recv":"2026-04-07T02:06:24.128875674Z","hd":{"ts_event":"2026-04-07T02:06:24.128859371Z","rtype":160,"publisher_id":101,"instrument_id":436},"action":"C","side":"A","price":"1.156670000","size":30,"channel_id":23,"order_id":"1775527584128734505","flags":0,"ts_in_delta":911,"sequence":145752,"symbol":"FCEU SI 20260615 PS"}
{"ts_recv":"2026-04-07T02:06:24.128875674Z","hd":{"ts_event":"2026-04-07T02:06:24.128859371Z","rtype":160,"publisher_id":101,"instrument_id":436},"action":"A","side":"A","price":"1.156660000","size":30,"channel_id":23,"order_id":"1775527584128865509","flags":128,"ts_in_delta":911,"sequence":145752,"symbol":"FCEU SI 20260615 PS"}
{"ts_recv":"2026-04-07T02:06:24.141689343Z","hd":{"ts_event":"2026-04-07T02:06:24.141671581Z","rtype":160,"publisher_id":101,"instrument_id":436},"action":"C","side":"B","price":"1.156560000","size":30,"channel_id":23,"order_id":"10998899620983641317","flags":0,"ts_in_delta":712,"sequence":145759,"symbol":"FCEU SI 20260615 PS"}
{"ts_recv":"2026-04-07T02:06:24.141689343Z","hd":{"ts_event":"2026-04-07T02:06:24.141671581Z","rtype":160,"publisher_id":101,"instrument_id":436},"action":"A","side":"B","price":"1.156550000","size":30,"channel_id":23,"order_id":"10998899620996453426","flags":0,"ts_in_delta":712,"sequence":145759,"symbol":"FCEU SI 20260615 PS"}
{"ts_recv":"2026-04-07T02:06:24.141689343Z","hd":{"ts_event":"2026-04-07T02:06:24.141671581Z","rtype":160,"publisher_id":101,"instrument_id":436},"action":"C","side":"A","price":"1.156660000","size":30,"channel_id":23,"order_id":"1775527584128865509","flags":0,"ts_in_delta":712,"sequence":145759,"symbol":"FCEU SI 20260615 PS"}
{"ts_recv":"2026-04-07T02:06:24.141689343Z","hd":{"ts_event":"2026-04-07T02:06:24.141671581Z","rtype":160,"publisher_id":101,"instrument_id":436},"action":"A","side":"A","price":"1.156650000","size":30,"channel_id":23,"order_id":"1775527584141677618","flags":128,"ts_in_delta":712,"sequence":145759,"symbol":"FCEU SI 20260615 PS"}
{"ts_recv":"2026-04-07T02:06:24.152927401Z","hd":{"ts_event":"2026-04-07T02:06:24.152908131Z","rtype":160,"publisher_id":101,"instrument_id":436},"action":"C","side":"B","price":"1.156550000","size":30,"channel_id":23,"order_id":"10998899620996453426","flags":0,"ts_in_delta":906,"sequence":145762,"symbol":"FCEU SI 20260615 PS"}
{"ts_recv":"2026-04-07T02:06:24.152927401Z","hd":{"ts_event":"2026-04-07T02:06:24.152908131Z","rtype":160,"publisher_id":101,"instrument_id":436},"action":"A","side":"B","price":"1.156530000","size":30,"channel_id":23,"order_id":"10998899621007689970","flags":0,"ts_in_delta":906,"sequence":145762,"symbol":"FCEU SI 20260615 PS"}
{"ts_recv":"2026-04-07T02:06:24.152927401Z","hd":{"ts_event":"2026-04-07T02:06:24.152908131Z","rtype":160,"publisher_id":101,"instrument_id":436},"action":"C","side":"A","price":"1.156650000","size":30,"channel_id":23,"order_id":"1775527584141677618","flags":0,"ts_in_delta":906,"sequence":145762,"symbol":"FCEU SI 20260615 PS"}
{"ts_recv":"2026-04-07T02:06:24.152927401Z","hd":{"ts_event":"2026-04-07T02:06:24.152908131Z","rtype":160,"publisher_id":101,"instrument_id":436},"action":"A","side":"A","price":"1.156630000","size":30,"channel_id":23,"order_id":"1775527584152914162","flags":128,"ts_in_delta":906,"sequence":145762,"symbol":"FCEU SI 20260615 PS"}
{"ts_recv":"2026-04-07T02:06:24.152981366Z","hd":{"ts_event":"2026-04-07T02:06:24.152962411Z","rtype":160,"publisher_id":101,"instrument_id":436},"action":"C","side":"B","price":"1.156560000","size":30,"channel_id":23,"order_id":"10998899620983578081","flags":0,"ts_in_delta":1078,"sequence":145763,"symbol":"FCEU SI 20260615 PS"}
{"ts_recv":"2026-04-07T02:06:24.152981366Z","hd":{"ts_event":"2026-04-07T02:06:24.152962411Z","rtype":160,"publisher_id":101,"instrument_id":436},"action":"A","side":"B","price":"1.156530000","size":30,"channel_id":23,"order_id":"10998899621007744398","flags":0,"ts_in_delta":1078,"sequence":145763,"symbol":"FCEU SI 20260615 PS"}
{"ts_recv":"2026-04-07T02:06:24.152981366Z","hd":{"ts_event":"2026-04-07T02:06:24.152962411Z","rtype":160,"publisher_id":101,"instrument_id":436},"action":"C","side":"A","price":"1.156660000","size":30,"channel_id":23,"order_id":"1775527584128802273","flags":0,"ts_in_delta":1078,"sequence":145763,"symbol":"FCEU SI 20260615 PS"}
{"ts_recv":"2026-04-07T02:06:24.152981366Z","hd":{"ts_event":"2026-04-07T02:06:24.152962411Z","rtype":160,"publisher_id":101,"instrument_id":436},"action":"A","side":"A","price":"1.156630000","size":30,"channel_id":23,"order_id":"1775527584152968590","flags":128,"ts_in_delta":1078,"sequence":145763,"symbol":"FCEU SI 20260615 PS"}
{"ts_recv":"2026-04-07T02:06:24.153008997Z","hd":{"ts_event":"2026-04-07T02:06:24.152990135Z","rtype":160,"publisher_id":101,"instrument_id":436},"action":"C","side":"B","price":"1.156530000","size":30,"channel_id":23,"order_id":"10998899621007689970","flags":0,"ts_in_delta":898,"sequence":145764,"symbol":"FCEU SI 20260615 PS"}
{"ts_recv":"2026-04-07T02:06:24.153008997Z","hd":{"ts_event":"2026-04-07T02:06:24.152990135Z","rtype":160,"publisher_id":101,"instrument_id":436},"action":"A","side":"B","price":"1.156550000","size":30,"channel_id":23,"order_id":"10998899621007771884","flags":0,"ts_in_delta":898,"sequence":145764,"symbol":"FCEU SI 20260615 PS"}
{"ts_recv":"2026-04-07T02:06:24.153008997Z","hd":{"ts_event":"2026-04-07T02:06:24.152990135Z","rtype":160,"publisher_id":101,"instrument_id":436},"action":"C","side":"A","price":"1.156630000","size":30,"channel_id":23,"order_id":"1775527584152914162","flags":0,"ts_in_delta":898,"sequence":145764,"symbol":"FCEU SI 20260615 PS"}
{"ts_recv":"2026-04-07T02:06:24.153008997Z","hd":{"ts_event":"2026-04-07T02:06:24.152990135Z","rtype":160,"publisher_id":101,"instrument_id":436},"action":"A","side":"A","price":"1.156650000","size":30,"channel_id":23,"order_id":"1775527584152996076","flags":128,"ts_in_delta":898,"sequence":145764,"symbol":"FCEU SI 20260615 PS"}
{"ts_recv":"2026-04-07T02:06:24.153062809Z","hd":{"ts_event":"2026-04-07T02:06:24.153047697Z","rtype":160,"publisher_id":101,"instrument_id":436},"action":"C","side":"B","price":"1.156550000","size":30,"channel_id":23,"order_id":"10998899621007771884","flags":0,"ts_in_delta":868,"sequence":145765,"symbol":"FCEU SI 20260615 PS"}
{"ts_recv":"2026-04-07T02:06:24.153062809Z","hd":{"ts_event":"2026-04-07T02:06:24.153047697Z","rtype":160,"publisher_id":101,"instrument_id":436},"action":"A","side":"B","price":"1.156530000","size":30,"channel_id":23,"order_id":"10998899621007829368","flags":0,"ts_in_delta":868,"sequence":145765,"symbol":"FCEU SI 20260615 PS"}
{"ts_recv":"2026-04-07T02:06:24.153062809Z","hd":{"ts_event":"2026-04-07T02:06:24.153047697Z","rtype":160,"publisher_id":101,"instrument_id":436},"action":"C","side":"A","price":"1.156650000","size":30,"channel_id":23,"order_id":"1775527584152996076","flags":0,"ts_in_delta":868,"sequence":145765,"symbol":"FCEU SI 20260615 PS"}
{"ts_recv":"2026-04-07T02:06:24.153062809Z","hd":{"ts_event":"2026-04-07T02:06:24.153047697Z","rtype":160,"publisher_id":101,"instrument_id":436},"action":"A","side":"A","price":"1.156630000","size":30,"channel_id":23,"order_id":"1775527584153053560","flags":128,"ts_in_delta":868,"sequence":145765,"symbol":"FCEU SI 20260615 PS"}
{"ts_recv":"2026-04-07T02:06:27.684268408Z","hd":{"ts_event":"2026-04-07T02:06:27.684247173Z","rtype":160,"publisher_id":101,"instrument_id":436},"action":"C","side":"B","price":"1.156530000","size":30,"channel_id":23,"order_id":"10998899621007829368","flags":0,"ts_in_delta":888,"sequence":145813,"symbol":"FCEU SI 20260615 PS"}
{"ts_recv":"2026-04-07T02:06:27.684268408Z","hd":{"ts_event":"2026-04-07T02:06:27.684247173Z","rtype":160,"publisher_id":101,"instrument_id":436},"action":"A","side":"B","price":"1.156540000","size":30,"channel_id":23,"order_id":"10998899624539029032","flags":0,"ts_in_delta":888,"sequence":145813,"symbol":"FCEU SI 20260615 PS"}
{"ts_recv":"2026-04-07T02:06:27.684268408Z","hd":{"ts_event":"2026-04-07T02:06:27.684247173Z","rtype":160,"publisher_id":101,"instrument_id":436},"action":"C","side":"A","price":"1.156630000","size":30,"channel_id":23,"order_id":"1775527584153053560","flags":0,"ts_in_delta":888,"sequence":145813,"symbol":"FCEU SI 20260615 PS"}
{"ts_recv":"2026-04-07T02:06:27.684268408Z","hd":{"ts_event":"2026-04-07T02:06:27.684247173Z","rtype":160,"publisher_id":101,"instrument_id":436},"action":"A","side":"A","price":"1.156640000","size":30,"channel_id":23,"order_id":"1775527587684253224","flags":128,"ts_in_delta":888,"sequence":145813,"symbol":"FCEU SI 20260615 PS"}
{"ts_recv":"2026-04-07T02:06:27.685885089Z","hd":{"ts_event":"2026-04-07T02:06:27.685866551Z","rtype":160,"publisher_id":101,"instrument_id":436},"action":"C","side":"B","price":"1.156530000","size":30,"channel_id":23,"order_id":"10998899621007744398","flags":0,"ts_in_delta":901,"sequence":145814,"symbol":"FCEU SI 20260615 PS"}
{"ts_recv":"2026-04-07T02:06:27.685885089Z","hd":{"ts_event":"2026-04-07T02:06:27.685866551Z","rtype":160,"publisher_id":101,"instrument_id":436},"action":"A","side":"B","price":"1.156550000","size":30,"channel_id":23,"order_id":"10998899624540648608","flags":0,"ts_in_delta":901,"sequence":145814,"symbol":"FCEU SI 20260615 PS"}
{"ts_recv":"2026-04-07T02:06:27.685885089Z","hd":{"ts_event":"2026-04-07T02:06:27.685866551Z","rtype":160,"publisher_id":101,"instrument_id":436},"action":"C","side":"A","price":"1.156630000","size":30,"channel_id":23,"order_id":"1775527584152968590","flags":0,"ts_in_delta":901,"sequence":145814,"symbol":"FCEU SI 20260615 PS"}
{"ts_recv":"2026-04-07T02:06:27.685885089Z","hd":{"ts_event":"2026-04-07T02:06:27.685866551Z","rtype":160,"publisher_id":101,"instrument_id":436},"action":"A","side":"A","price":"1.156650000","size":30,"channel_id":23,"order_id":"1775527587685872800","flags":128,"ts_in_delta":901,"sequence":145814,"symbol":"FCEU SI 20260615 PS"}
{"ts_recv":"2026-04-07T02:06:27.685943247Z","hd":{"ts_event":"2026-04-07T02:06:27.685924895Z","rtype":160,"publisher_id":101,"instrument_id":436},"action":"C","side":"B","price":"1.156540000","size":30,"channel_id":23,"order_id":"10998899624539029032","flags":0,"ts_in_delta":890,"sequence":145815,"symbol":"FCEU SI 20260615 PS"}
{"ts_recv":"2026-04-07T02:06:27.685943247Z","hd":{"ts_event":"2026-04-07T02:06:27.685924895Z","rtype":160,"publisher_id":101,"instrument_id":436},"action":"A","side":"B","price":"1.156550000","size":30,"channel_id":23,"order_id":"10998899624540706835","flags":0,"ts_in_delta":890,"sequence":145815,"symbol":"FCEU SI 20260615 PS"}
{"ts_recv":"2026-04-07T02:06:27.685943247Z","hd":{"ts_event":"2026-04-07T02:06:27.685924895Z","rtype":160,"publisher_id":101,"instrument_id":436},"action":"C","side":"A","price":"1.156640000","size":30,"channel_id":23,"order_id":"1775527587684253224","flags":0,"ts_in_delta":890,"sequence":145815,"symbol":"FCEU SI 20260615 PS"}
{"ts_recv":"2026-04-07T02:06:27.685943247Z","hd":{"ts_event":"2026-04-07T02:06:27.685924895Z","rtype":160,"publisher_id":101,"instrument_id":436},"action":"A","side":"A","price":"1.156650000","size":30,"channel_id":23,"order_id":"1775527587685931027","flags":128,"ts_in_delta":890,"sequence":145815,"symbol":"FCEU SI 20260615 PS"}
{"ts_recv":"2026-04-07T02:06:29.521470723Z","hd":{"ts_event":"2026-04-07T02:06:29.521449375Z","rtype":160,"publisher_id":101,"instrument_id":436},"action":"C","side":"B","price":"1.156550000","size":30,"channel_id":23,"order_id":"10998899624540706835","flags":0,"ts_in_delta":1072,"sequence":145865,"symbol":"FCEU SI 20260615 PS"}
{"ts_recv":"2026-04-07T02:06:29.521470723Z","hd":{"ts_event":"2026-04-07T02:06:29.521449375Z","rtype":160,"publisher_id":101,"instrument_id":436},"action":"A","side":"B","price":"1.156560000","size":30,"channel_id":23,"order_id":"10998899626376231234","flags":0,"ts_in_delta":1072,"sequence":145865,"symbol":"FCEU SI 20260615 PS"}
{"ts_recv":"2026-04-07T02:06:29.521470723Z","hd":{"ts_event":"2026-04-07T02:06:29.521449375Z","rtype":160,"publisher_id":101,"instrument_id":436},"action":"C","side":"A","price":"1.156650000","size":30,"channel_id":23,"order_id":"1775527587685931027","flags":0,"ts_in_delta":1072,"sequence":145865,"symbol":"FCEU SI 20260615 PS"}
{"ts_recv":"2026-04-07T02:06:29.521470723Z","hd":{"ts_event":"2026-04-07T02:06:29.521449375Z","rtype":160,"publisher_id":101,"instrument_id":436},"action":"A","side":"A","price":"1.156660000","size":30,"channel_id":23,"order_id":"1775527589521455426","flags":128,"ts_in_delta":1072,"sequence":145865,"symbol":"FCEU SI 20260615 PS"}
{"ts_recv":"2026-04-07T02:06:29.529887723Z","hd":{"ts_event":"2026-04-07T02:06:29.529867173Z","rtype":160,"publisher_id":101,"instrument_id":436},"action":"C","side":"B","price":"1.156550000","size":30,"channel_id":23,"order_id":"10998899624540648608","flags":0,"ts_in_delta":986,"sequence":145868,"symbol":"FCEU SI 20260615 PS"}
{"ts_recv":"2026-04-07T02:06:29.529887723Z","hd":{"ts_event":"2026-04-07T02:06:29.529867173Z","rtype":160,"publisher_id":101,"instrument_id":436},"action":"A","side":"B","price":"1.156570000","size":30,"channel_id":23,"order_id":"10998899626384648911","flags":0,"ts_in_delta":986,"sequence":145868,"symbol":"FCEU SI 20260615 PS"}
{"ts_recv":"2026-04-07T02:06:29.529887723Z","hd":{"ts_event":"2026-04-07T02:06:29.529867173Z","rtype":160,"publisher_id":101,"instrument_id":436},"action":"C","side":"A","price":"1.156650000","size":30,"channel_id":23,"order_id":"1775527587685872800","flags":0,"ts_in_delta":986,"sequence":145868,"symbol":"FCEU SI 20260615 PS"}
{"ts_recv":"2026-04-07T02:06:29.529887723Z","hd":{"ts_event":"2026-04-07T02:06:29.529867173Z","rtype":160,"publisher_id":101,"instrument_id":436},"action":"A","side":"A","price":"1.156670000","size":30,"channel_id":23,"order_id":"1775527589529873103","flags":128,"ts_in_delta":986,"sequence":145868,"symbol":"FCEU SI 20260615 PS"}
{"ts_recv":"2026-04-07T02:06:29.529947325Z","hd":{"ts_event":"2026-04-07T02:06:29.529929667Z","rtype":160,"publisher_id":101,"instrument_id":436},"action":"C","side":"B","price":"1.156560000","size":30,"channel_id":23,"order_id":"10998899626376231234","flags":0,"ts_in_delta":882,"sequence":145869,"symbol":"FCEU SI 20260615 PS"}
{"ts_recv":"2026-04-07T02:06:29.529947325Z","hd":{"ts_event":"2026-04-07T02:06:29.529929667Z","rtype":160,"publisher_id":101,"instrument_id":436},"action":"A","side":"B","price":"1.156570000","size":30,"channel_id":23,"order_id":"10998899626384711820","flags":0,"ts_in_delta":882,"sequence":145869,"symbol":"FCEU SI 20260615 PS"}
{"ts_recv":"2026-04-07T02:06:29.529947325Z","hd":{"ts_event":"2026-04-07T02:06:29.529929667Z","rtype":160,"publisher_id":101,"instrument_id":436},"action":"C","side":"A","price":"1.156660000","size":30,"channel_id":23,"order_id":"1775527589521455426","flags":0,"ts_in_delta":882,"sequence":145869,"symbol":"FCEU SI 20260615 PS"}
{"ts_recv":"2026-04-07T02:06:29.529947325Z","hd":{"ts_event":"2026-04-07T02:06:29.529929667Z","rtype":160,"publisher_id":101,"instrument_id":436},"action":"A","side":"A","price":"1.156670000","size":30,"channel_id":23,"order_id":"1775527589529936012","flags":128,"ts_in_delta":882,"sequence":145869,"symbol":"FCEU SI 20260615 PS"}
{"ts_recv":"2026-04-07T02:06:35.167147022Z","hd":{"ts_event":"2026-04-07T02:06:35.167124609Z","rtype":160,"publisher_id":101,"instrument_id":436},"action":"C","side":"B","price":"1.156570000","size":30,"channel_id":23,"order_id":"10998899626384711820","flags":0,"ts_in_delta":955,"sequence":145945,"symbol":"FCEU SI 20260615 PS"}
{"ts_recv":"2026-04-07T02:06:35.167147022Z","hd":{"ts_event":"2026-04-07T02:06:35.167124609Z","rtype":160,"publisher_id":101,"instrument_id":436},"action":"A","side":"B","price":"1.156580000","size":30,"channel_id":23,"order_id":"10998899632021906498","flags":0,"ts_in_delta":955,"sequence":145945,"symbol":"FCEU SI 20260615 PS"}
{"ts_recv":"2026-04-07T02:06:35.167147022Z","hd":{"ts_event":"2026-04-07T02:06:35.167124609Z","rtype":160,"publisher_id":101,"instrument_id":436},"action":"C","side":"A","price":"1.156670000","size":30,"channel_id":23,"order_id":"1775527589529936012","flags":0,"ts_in_delta":955,"sequence":145945,"symbol":"FCEU SI 20260615 PS"}
{"ts_recv":"2026-04-07T02:06:35.167147022Z","hd":{"ts_event":"2026-04-07T02:06:35.167124609Z","rtype":160,"publisher_id":101,"instrument_id":436},"action":"A","side":"A","price":"1.156680000","size":30,"channel_id":23,"order_id":"1775527595167130690","flags":128,"ts_in_delta":955,"sequence":145945,"symbol":"FCEU SI 20260615 PS"}
{"ts_recv":"2026-04-07T02:06:48.434409740Z","hd":{"ts_event":"2026-04-07T02:06:48.434381399Z","rtype":160,"publisher_id":101,"instrument_id":436},"action":"C","side":"B","price":"1.156570000","size":30,"channel_id":23,"order_id":"10998899626384648911","flags":0,"ts_in_delta":1345,"sequence":146057,"symbol":"FCEU SI 20260615 PS"}
{"ts_recv":"2026-04-07T02:06:48.434409740Z","hd":{"ts_event":"2026-04-07T02:06:48.434381399Z","rtype":160,"publisher_id":101,"instrument_id":436},"action":"A","side":"B","price":"1.156590000","size":30,"channel_id":23,"order_id":"10998899645289166099","flags":0,"ts_in_delta":1345,"sequence":146057,"symbol":"FCEU SI 20260615 PS"}
{"ts_recv":"2026-04-07T02:06:48.434409740Z","hd":{"ts_event":"2026-04-07T02:06:48.434381399Z","rtype":160,"publisher_id":101,"instrument_id":436},"action":"C","side":"A","price":"1.156670000","size":30,"channel_id":23,"order_id":"1775527589529873103","flags":0,"ts_in_delta":1345,"sequence":146057,"symbol":"FCEU SI 20260615 PS"}
{"ts_recv":"2026-04-07T02:06:48.434409740Z","hd":{"ts_event":"2026-04-07T02:06:48.434381399Z","rtype":160,"publisher_id":101,"instrument_id":436},"action":"A","side":"A","price":"1.156690000","size":30,"channel_id":23,"order_id":"1775527608434390291","flags":128,"ts_in_delta":1345,"sequence":146057,"symbol":"FCEU SI 20260615 PS"}
{"ts_recv":"2026-04-07T02:06:48.434514582Z","hd":{"ts_event":"2026-04-07T02:06:48.434497509Z","rtype":160,"publisher_id":101,"instrument_id":436},"action":"C","side":"B","price":"1.156580000","size":30,"channel_id":23,"order_id":"10998899632021906498","flags":0,"ts_in_delta":1041,"sequence":146058,"symbol":"FCEU SI 20260615 PS"}
{"ts_recv":"2026-04-07T02:06:48.434514582Z","hd":{"ts_event":"2026-04-07T02:06:48.434497509Z","rtype":160,"publisher_id":101,"instrument_id":436},"action":"A","side":"B","price":"1.156590000","size":30,"channel_id":23,"order_id":"10998899645289279196","flags":0,"ts_in_delta":1041,"sequence":146058,"symbol":"FCEU SI 20260615 PS"}
{"ts_recv":"2026-04-07T02:06:48.434514582Z","hd":{"ts_event":"2026-04-07T02:06:48.434497509Z","rtype":160,"publisher_id":101,"instrument_id":436},"action":"C","side":"A","price":"1.156680000","size":30,"channel_id":23,"order_id":"1775527595167130690","flags":0,"ts_in_delta":1041,"sequence":146058,"symbol":"FCEU SI 20260615 PS"}
{"ts_recv":"2026-04-07T02:06:48.434514582Z","hd":{"ts_event":"2026-04-07T02:06:48.434497509Z","rtype":160,"publisher_id":101,"instrument_id":436},"action":"A","side":"A","price":"1.156690000","size":30,"channel_id":23,"order_id":"1775527608434503388","flags":128,"ts_in_delta":1041,"sequence":146058,"symbol":"FCEU SI 20260615 PS"}
{"ts_recv":"2026-04-07T02:06:59.860573788Z","hd":{"ts_event":"2026-04-07T02:06:59.860549623Z","rtype":160,"publisher_id":101,"instrument_id":436},"action":"C","side":"B","price":"1.156590000","size":30,"channel_id":23,"order_id":"10998899645289279196","flags":0,"ts_in_delta":937,"sequence":146134,"symbol":"FCEU SI 20260615 PS"}
{"ts_recv":"2026-04-07T02:06:59.860573788Z","hd":{"ts_event":"2026-04-07T02:06:59.860549623Z","rtype":160,"publisher_id":101,"instrument_id":436},"action":"A","side":"B","price":"1.156580000","size":30,"channel_id":23,"order_id":"10998899656715331950","flags":0,"ts_in_delta":937,"sequence":146134,"symbol":"FCEU SI 20260615 PS"}
{"ts_recv":"2026-04-07T02:06:59.860573788Z","hd":{"ts_event":"2026-04-07T02:06:59.860549623Z","rtype":160,"publisher_id":101,"instrument_id":436},"action":"C","side":"A","price":"1.156690000","size":30,"channel_id":23,"order_id":"1775527608434503388","flags":0,"ts_in_delta":937,"sequence":146134,"symbol":"FCEU SI 20260615 PS"}
{"ts_recv":"2026-04-07T02:06:59.860573788Z","hd":{"ts_event":"2026-04-07T02:06:59.860549623Z","rtype":160,"publisher_id":101,"instrument_id":436},"action":"A","side":"A","price":"1.156680000","size":30,"channel_id":23,"order_id":"1775527619860556142","flags":128,"ts_in_delta":937,"sequence":146134,"symbol":"FCEU SI 20260615 PS"}
{"ts_recv":"2026-04-07T02:06:59.868016826Z","hd":{"ts_event":"2026-04-07T02:06:59.867994637Z","rtype":160,"publisher_id":101,"instrument_id":436},"action":"C","side":"B","price":"1.156590000","size":30,"channel_id":23,"order_id":"10998899645289166099","flags":0,"ts_in_delta":925,"sequence":146136,"symbol":"FCEU SI 20260615 PS"}
{"ts_recv":"2026-04-07T02:06:59.868016826Z","hd":{"ts_event":"2026-04-07T02:06:59.867994637Z","rtype":160,"publisher_id":101,"instrument_id":436},"action":"A","side":"B","price":"1.156570000","size":30,"channel_id":23,"order_id":"10998899656722777047","flags":0,"ts_in_delta":925,"sequence":146136,"symbol":"FCEU SI 20260615 PS"}
{"ts_recv":"2026-04-07T02:06:59.868016826Z","hd":{"ts_event":"2026-04-07T02:06:59.867994637Z","rtype":160,"publisher_id":101,"instrument_id":436},"action":"C","side":"A","price":"1.156690000","size":30,"channel_id":23,"order_id":"1775527608434390291","flags":0,"ts_in_delta":925,"sequence":146136,"symbol":"FCEU SI 20260615 PS"}
{"ts_recv":"2026-04-07T02:06:59.868016826Z","hd":{"ts_event":"2026-04-07T02:06:59.867994637Z","rtype":160,"publisher_id":101,"instrument_id":436},"action":"A","side":"A","price":"1.156670000","size":30,"channel_id":23,"order_id":"1775527619868001239","flags":128,"ts_in_delta":925,"sequence":146136,"symbol":"FCEU SI 20260615 PS"}
{"ts_recv":"2026-04-07T02:06:59.868079607Z","hd":{"ts_event":"2026-04-07T02:06:59.868060435Z","rtype":160,"publisher_id":101,"instrument_id":436},"action":"C","side":"B","price":"1.156580000","size":30,"channel_id":23,"order_id":"10998899656715331950","flags":0,"ts_in_delta":923,"sequence":146137,"symbol":"FCEU SI 20260615 PS"}
{"ts_recv":"2026-04-07T02:06:59.868079607Z","hd":{"ts_event":"2026-04-07T02:06:59.868060435Z","rtype":160,"publisher_id":101,"instrument_id":436},"action":"A","side":"B","price":"1.156570000","size":30,"channel_id":23,"order_id":"10998899656722842392","flags":0,"ts_in_delta":923,"sequence":146137,"symbol":"FCEU SI 20260615 PS"}
{"ts_recv":"2026-04-07T02:06:59.868079607Z","hd":{"ts_event":"2026-04-07T02:06:59.868060435Z","rtype":160,"publisher_id":101,"instrument_id":436},"action":"C","side":"A","price":"1.156680000","size":30,"channel_id":23,"order_id":"1775527619860556142","flags":0,"ts_in_delta":923,"sequence":146137,"symbol":"FCEU SI 20260615 PS"}
{"ts_recv":"2026-04-07T02:06:59.868079607Z","hd":{"ts_event":"2026-04-07T02:06:59.868060435Z","rtype":160,"publisher_id":101,"instrument_id":436},"action":"A","side":"A","price":"1.156670000","size":30,"channel_id":23,"order_id":"1775527619868066584","flags":128,"ts_in_delta":923,"sequence":146137,"symbol":"FCEU SI 20260615 PS"}
{"ts_recv":"2026-04-07T02:06:59.873012269Z","hd":{"ts_event":"2026-04-07T02:06:59.872994449Z","rtype":160,"publisher_id":101,"instrument_id":436},"action":"C","side":"B","price":"1.156570000","size":30,"channel_id":23,"order_id":"10998899656722842392","flags":0,"ts_in_delta":944,"sequence":146139,"symbol":"FCEU SI 20260615 PS"}
{"ts_recv":"2026-04-07T02:06:59.873012269Z","hd":{"ts_event":"2026-04-07T02:06:59.872994449Z","rtype":160,"publisher_id":101,"instrument_id":436},"action":"A","side":"B","price":"1.156560000","size":30,"channel_id":23,"order_id":"10998899656727776236","flags":0,"ts_in_delta":944,"sequence":146139,"symbol":"FCEU SI 20260615 PS"}
{"ts_recv":"2026-04-07T02:06:59.873012269Z","hd":{"ts_event":"2026-04-07T02:06:59.872994449Z","rtype":160,"publisher_id":101,"instrument_id":436},"action":"C","side":"A","price":"1.156670000","size":30,"channel_id":23,"order_id":"1775527619868066584","flags":0,"ts_in_delta":944,"sequence":146139,"symbol":"FCEU SI 20260615 PS"}
{"ts_recv":"2026-04-07T02:06:59.873012269Z","hd":{"ts_event":"2026-04-07T02:06:59.872994449Z","rtype":160,"publisher_id":101,"instrument_id":436},"action":"A","side":"A","price":"1.156660000","size":30,"channel_id":23,"order_id":"1775527619873000428","flags":128,"ts_in_delta":944,"sequence":146139,"symbol":"FCEU SI 20260615 PS"}
{"ts_recv":"2026-04-07T02:06:59.873094648Z","hd":{"ts_event":"2026-04-07T02:06:59.873075737Z","rtype":160,"publisher_id":101,"instrument_id":436},"action":"C","side":"B","price":"1.156560000","size":30,"channel_id":23,"order_id":"10998899656727776236","flags":0,"ts_in_delta":931,"sequence":146140,"symbol":"FCEU SI 20260615 PS"}
{"ts_recv":"2026-04-07T02:06:59.873094648Z","hd":{"ts_event":"2026-04-07T02:06:59.873075737Z","rtype":160,"publisher_id":101,"instrument_id":436},"action":"A","side":"B","price":"1.156540000","size":30,"channel_id":23,"order_id":"10998899656727857441","flags":0,"ts_in_delta":931,"sequence":146140,"symbol":"FCEU SI 20260615 PS"}
{"ts_recv":"2026-04-07T02:06:59.873094648Z","hd":{"ts_event":"2026-04-07T02:06:59.873075737Z","rtype":160,"publisher_id":101,"instrument_id":436},"action":"C","side":"A","price":"1.156660000","size":30,"channel_id":23,"order_id":"1775527619873000428","flags":0,"ts_in_delta":931,"sequence":146140,"symbol":"FCEU SI 20260615 PS"}
{"ts_recv":"2026-04-07T02:06:59.873094648Z","hd":{"ts_event":"2026-04-07T02:06:59.873075737Z","rtype":160,"publisher_id":101,"instrument_id":436},"action":"A","side":"A","price":"1.156640000","size":30,"channel_id":23,"order_id":"1775527619873081633","flags":128,"ts_in_delta":931,"sequence":146140,"symbol":"FCEU SI 20260615 PS"}
{"ts_recv":"2026-04-07T02:06:59.873143452Z","hd":{"ts_event":"2026-04-07T02:06:59.873125549Z","rtype":160,"publisher_id":101,"instrument_id":436},"action":"C","side":"B","price":"1.156570000","size":30,"channel_id":23,"order_id":"10998899656722777047","flags":0,"ts_in_delta":1000,"sequence":146141,"symbol":"FCEU SI 20260615 PS"}
{"ts_recv":"2026-04-07T02:06:59.873143452Z","hd":{"ts_event":"2026-04-07T02:06:59.873125549Z","rtype":160,"publisher_id":101,"instrument_id":436},"action":"A","side":"B","price":"1.156550000","size":30,"channel_id":23,"order_id":"10998899656727907596","flags":0,"ts_in_delta":1000,"sequence":146141,"symbol":"FCEU SI 20260615 PS"}
{"ts_recv":"2026-04-07T02:06:59.873143452Z","hd":{"ts_event":"2026-04-07T02:06:59.873125549Z","rtype":160,"publisher_id":101,"instrument_id":436},"action":"C","side":"A","price":"1.156670000","size":30,"channel_id":23,"order_id":"1775527619868001239","flags":0,"ts_in_delta":1000,"sequence":146141,"symbol":"FCEU SI 20260615 PS"}
{"ts_recv":"2026-04-07T02:06:59.873143452Z","hd":{"ts_event":"2026-04-07T02:06:59.873125549Z","rtype":160,"publisher_id":101,"instrument_id":436},"action":"A","side":"A","price":"1.156650000","size":30,"channel_id":23,"order_id":"1775527619873131788","flags":128,"ts_in_delta":1000,"sequence":146141,"symbol":"FCEU SI 20260615 PS"}
{"ts_recv":"2026-04-07T02:06:59.873154111Z","hd":{"ts_event":"2026-04-07T02:06:59.873134667Z","rtype":160,"publisher_id":101,"instrument_id":436},"action":"C","side":"B","price":"1.156540000","size":30,"channel_id":23,"order_id":"10998899656727857441","flags":0,"ts_in_delta":917,"sequence":146142,"symbol":"FCEU SI 20260615 PS"}
{"ts_recv":"2026-04-07T02:06:59.873154111Z","hd":{"ts_event":"2026-04-07T02:06:59.873134667Z","rtype":160,"publisher_id":101,"instrument_id":436},"action":"A","side":"B","price":"1.156560000","size":30,"channel_id":23,"order_id":"10998899656727916706","flags":0,"ts_in_delta":917,"sequence":146142,"symbol":"FCEU SI 20260615 PS"}
{"ts_recv":"2026-04-07T02:06:59.873154111Z","hd":{"ts_event":"2026-04-07T02:06:59.873134667Z","rtype":160,"publisher_id":101,"instrument_id":436},"action":"C","side":"A","price":"1.156640000","size":30,"channel_id":23,"order_id":"1775527619873081633","flags":0,"ts_in_delta":917,"sequence":146142,"symbol":"FCEU SI 20260615 PS"}
{"ts_recv":"2026-04-07T02:06:59.873154111Z","hd":{"ts_event":"2026-04-07T02:06:59.873134667Z","rtype":160,"publisher_id":101,"instrument_id":436},"action":"A","side":"A","price":"1.156660000","size":30,"channel_id":23,"order_id":"1775527619873140898","flags":128,"ts_in_delta":917,"sequence":146142,"symbol":"FCEU SI 20260615 PS"}
{"ts_recv":"2026-04-07T02:06:59.873206180Z","hd":{"ts_event":"2026-04-07T02:06:59.873190887Z","rtype":160,"publisher_id":101,"instrument_id":436},"action":"C","side":"B","price":"1.156560000","size":30,"channel_id":23,"order_id":"10998899656727916706","flags":0,"ts_in_delta":962,"sequence":146143,"symbol":"FCEU SI 20260615 PS"}
{"ts_recv":"2026-04-07T02:06:59.873206180Z","hd":{"ts_event":"2026-04-07T02:06:59.873190887Z","rtype":160,"publisher_id":101,"instrument_id":436},"action":"A","side":"B","price":"1.156550000","size":30,"channel_id":23,"order_id":"10998899656727972491","flags":0,"ts_in_delta":962,"sequence":146143,"symbol":"FCEU SI 20260615 PS"}
{"ts_recv":"2026-04-07T02:06:59.873206180Z","hd":{"ts_event":"2026-04-07T02:06:59.873190887Z","rtype":160,"publisher_id":101,"instrument_id":436},"action":"C","side":"A","price":"1.156660000","size":30,"channel_id":23,"order_id":"1775527619873140898","flags":0,"ts_in_delta":962,"sequence":146143,"symbol":"FCEU SI 20260615 PS"}
{"ts_recv":"2026-04-07T02:06:59.873206180Z","hd":{"ts_event":"2026-04-07T02:06:59.873190887Z","rtype":160,"publisher_id":101,"instrument_id":436},"action":"A","side":"A","price":"1.156650000","size":30,"channel_id":23,"order_id":"1775527619873196683","flags":128,"ts_in_delta":962,"sequence":146143,"symbol":"FCEU SI 20260615 PS"}
{"ts_recv":"2026-04-07T02:07:02.857146540Z","hd":{"ts_event":"2026-04-07T02:07:02.857127089Z","rtype":160,"publisher_id":101,"instrument_id":436},"action":"C","side":"B","price":"1.156550000","size":30,"channel_id":23,"order_id":"10998899656727972491","flags":0,"ts_in_delta":1430,"sequence":146240,"symbol":"FCEU SI 20260615 PS"}
{"ts_recv":"2026-04-07T02:07:02.857146540Z","hd":{"ts_event":"2026-04-07T02:07:02.857127089Z","rtype":160,"publisher_id":101,"instrument_id":436},"action":"A","side":"B","price":"1.156540000","size":30,"channel_id":23,"order_id":"10998899659711908679","flags":0,"ts_in_delta":1430,"sequence":146240,"symbol":"FCEU SI 20260615 PS"}
{"ts_recv":"2026-04-07T02:07:02.857146540Z","hd":{"ts_event":"2026-04-07T02:07:02.857127089Z","rtype":160,"publisher_id":101,"instrument_id":436},"action":"C","side":"A","price":"1.156650000","size":30,"channel_id":23,"order_id":"1775527619873196683","flags":0,"ts_in_delta":1430,"sequence":146240,"symbol":"FCEU SI 20260615 PS"}
{"ts_recv":"2026-04-07T02:07:02.857146540Z","hd":{"ts_event":"2026-04-07T02:07:02.857127089Z","rtype":160,"publisher_id":101,"instrument_id":436},"action":"A","side":"A","price":"1.156640000","size":30,"channel_id":23,"order_id":"1775527622857132871","flags":128,"ts_in_delta":1430,"sequence":146240,"symbol":"FCEU SI 20260615 PS"}
{"ts_recv":"2026-04-07T02:07:02.873343453Z","hd":{"ts_event":"2026-04-07T02:07:02.873322969Z","rtype":160,"publisher_id":101,"instrument_id":436},"action":"C","side":"B","price":"1.156550000","size":30,"channel_id":23,"order_id":"10998899656727907596","flags":0,"ts_in_delta":906,"sequence":146253,"symbol":"FCEU SI 20260615 PS"}
{"ts_recv":"2026-04-07T02:07:02.873343453Z","hd":{"ts_event":"2026-04-07T02:07:02.873322969Z","rtype":160,"publisher_id":101,"instrument_id":436},"action":"A","side":"B","price":"1.156530000","size":30,"channel_id":23,"order_id":"10998899659728104683","flags":0,"ts_in_delta":906,"sequence":146253,"symbol":"FCEU SI 20260615 PS"}
{"ts_recv":"2026-04-07T02:07:02.873343453Z","hd":{"ts_event":"2026-04-07T02:07:02.873322969Z","rtype":160,"publisher_id":101,"instrument_id":436},"action":"C","side":"A","price":"1.156650000","size":30,"channel_id":23,"order_id":"1775527619873131788","flags":0,"ts_in_delta":906,"sequence":146253,"symbol":"FCEU SI 20260615 PS"}
{"ts_recv":"2026-04-07T02:07:02.873343453Z","hd":{"ts_event":"2026-04-07T02:07:02.873322969Z","rtype":160,"publisher_id":101,"instrument_id":436},"action":"A","side":"A","price":"1.156630000","size":30,"channel_id":23,"order_id":"1775527622873328875","flags":128,"ts_in_delta":906,"sequence":146253,"symbol":"FCEU SI 20260615 PS"}
{"ts_recv":"2026-04-07T02:07:02.873408231Z","hd":{"ts_event":"2026-04-07T02:07:02.873389057Z","rtype":160,"publisher_id":101,"instrument_id":436},"action":"C","side":"B","price":"1.156540000","size":30,"channel_id":23,"order_id":"10998899659711908679","flags":0,"ts_in_delta":740,"sequence":146254,"symbol":"FCEU SI 20260615 PS"}
{"ts_recv":"2026-04-07T02:07:02.873408231Z","hd":{"ts_event":"2026-04-07T02:07:02.873389057Z","rtype":160,"publisher_id":101,"instrument_id":436},"action":"A","side":"B","price":"1.156530000","size":30,"channel_id":23,"order_id":"10998899659728170798","flags":0,"ts_in_delta":740,"sequence":146254,"symbol":"FCEU SI 20260615 PS"}
{"ts_recv":"2026-04-07T02:07:02.873408231Z","hd":{"ts_event":"2026-04-07T02:07:02.873389057Z","rtype":160,"publisher_id":101,"instrument_id":436},"action":"C","side":"A","price":"1.156640000","size":30,"channel_id":23,"order_id":"1775527622857132871","flags":0,"ts_in_delta":740,"sequence":146254,"symbol":"FCEU SI 20260615 PS"}
{"ts_recv":"2026-04-07T02:07:02.873408231Z","hd":{"ts_event":"2026-04-07T02:07:02.873389057Z","rtype":160,"publisher_id":101,"instrument_id":436},"action":"A","side":"A","price":"1.156630000","size":30,"channel_id":23,"order_id":"1775527622873394990","flags":128,"ts_in_delta":740,"sequence":146254,"symbol":"FCEU SI 20260615 PS"}
{"ts_recv":"2026-04-07T02:07:02.976218582Z","hd":{"ts_event":"2026-04-07T02:07:02.976198233Z","rtype":160,"publisher_id":101,"instrument_id":436},"action":"C","side":"B","price":"1.156530000","size":30,"channel_id":23,"order_id":"10998899659728170798","flags":0,"ts_in_delta":1195,"sequence":146267,"symbol":"FCEU SI 20260615 PS"}
{"ts_recv":"2026-04-07T02:07:02.976218582Z","hd":{"ts_event":"2026-04-07T02:07:02.976198233Z","rtype":160,"publisher_id":101,"instrument_id":436},"action":"A","side":"B","price":"1.156520000","size":30,"channel_id":23,"order_id":"10998899659830980227","flags":0,"ts_in_delta":1195,"sequence":146267,"symbol":"FCEU SI 20260615 PS"}
{"ts_recv":"2026-04-07T02:07:02.976218582Z","hd":{"ts_event":"2026-04-07T02:07:02.976198233Z","rtype":160,"publisher_id":101,"instrument_id":436},"action":"C","side":"A","price":"1.156630000","size":30,"channel_id":23,"order_id":"1775527622873394990","flags":0,"ts_in_delta":1195,"sequence":146267,"symbol":"FCEU SI 20260615 PS"}
{"ts_recv":"2026-04-07T02:07:02.976218582Z","hd":{"ts_event":"2026-04-07T02:07:02.976198233Z","rtype":160,"publisher_id":101,"instrument_id":436},"action":"A","side":"A","price":"1.156620000","size":30,"channel_id":23,"order_id":"1775527622976204419","flags":128,"ts_in_delta":1195,"sequence":146267,"symbol":"FCEU SI 20260615 PS"}
{"ts_recv":"2026-04-07T02:07:02.978087777Z","hd":{"ts_event":"2026-04-07T02:07:02.978073247Z","rtype":160,"publisher_id":101,"instrument_id":436},"action":"C","side":"B","price":"1.156500000","size":20,"channel_id":23,"order_id":"10998899607437016903","flags":128,"ts_in_delta":801,"sequence":146268,"symbol":"FCEU SI 20260615 PS"}
{"ts_recv":"2026-04-07T02:07:02.996386142Z","hd":{"ts_event":"2026-04-07T02:07:02.996367007Z","rtype":160,"publisher_id":101,"instrument_id":436},"action":"C","side":"B","price":"1.156530000","size":30,"channel_id":23,"order_id":"10998899659728104683","flags":0,"ts_in_delta":1003,"sequence":146272,"symbol":"FCEU SI 20260615 PS"}
{"ts_recv":"2026-04-07T02:07:02.996386142Z","hd":{"ts_event":"2026-04-07T02:07:02.996367007Z","rtype":160,"publisher_id":101,"instrument_id":436},"action":"A","side":"B","price":"1.156510000","size":30,"channel_id":23,"order_id":"10998899659851148577","flags":0,"ts_in_delta":1003,"sequence":146272,"symbol":"FCEU SI 20260615 PS"}
{"ts_recv":"2026-04-07T02:07:02.996386142Z","hd":{"ts_event":"2026-04-07T02:07:02.996367007Z","rtype":160,"publisher_id":101,"instrument_id":436},"action":"C","side":"A","price":"1.156630000","size":30,"channel_id":23,"order_id":"1775527622873328875","flags":0,"ts_in_delta":1003,"sequence":146272,"symbol":"FCEU SI 20260615 PS"}
{"ts_recv":"2026-04-07T02:07:02.996386142Z","hd":{"ts_event":"2026-04-07T02:07:02.996367007Z","rtype":160,"publisher_id":101,"instrument_id":436},"action":"A","side":"A","price":"1.156610000","size":30,"channel_id":23,"order_id":"1775527622996372769","flags":128,"ts_in_delta":1003,"sequence":146272,"symbol":"FCEU SI 20260615 PS"}
{"ts_recv":"2026-04-07T02:07:02.996444553Z","hd":{"ts_event":"2026-04-07T02:07:02.996426721Z","rtype":160,"publisher_id":101,"instrument_id":436},"action":"C","side":"B","price":"1.156520000","size":30,"channel_id":23,"order_id":"10998899659830980227","flags":0,"ts_in_delta":915,"sequence":146273,"symbol":"FCEU SI 20260615 PS"}
{"ts_recv":"2026-04-07T02:07:02.996444553Z","hd":{"ts_event":"2026-04-07T02:07:02.996426721Z","rtype":160,"publisher_id":101,"instrument_id":436},"action":"A","side":"B","price":"1.156510000","size":30,"channel_id":23,"order_id":"10998899659851208470","flags":0,"ts_in_delta":915,"sequence":146273,"symbol":"FCEU SI 20260615 PS"}
{"ts_recv":"2026-04-07T02:07:02.996444553Z","hd":{"ts_event":"2026-04-07T02:07:02.996426721Z","rtype":160,"publisher_id":101,"instrument_id":436},"action":"C","side":"A","price":"1.156620000","size":30,"channel_id":23,"order_id":"1775527622976204419","flags":0,"ts_in_delta":915,"sequence":146273,"symbol":"FCEU SI 20260615 PS"}
{"ts_recv":"2026-04-07T02:07:02.996444553Z","hd":{"ts_event":"2026-04-07T02:07:02.996426721Z","rtype":160,"publisher_id":101,"instrument_id":436},"action":"A","side":"A","price":"1.156610000","size":30,"channel_id":23,"order_id":"1775527622996432662","flags":128,"ts_in_delta":915,"sequence":146273,"symbol":"FCEU SI 20260615 PS"}
{"ts_recv":"2026-04-07T02:07:03.021394215Z","hd":{"ts_event":"2026-04-07T02:07:03.021378957Z","rtype":160,"publisher_id":101,"instrument_id":436},"action":"A","side":"B","price":"1.156300000","size":20,"channel_id":23,"order_id":"10998899659876160814","flags":128,"ts_in_delta":930,"sequence":146276,"symbol":"FCEU SI 20260615 PS"}
{"ts_recv":"2026-04-07T02:07:03.064157396Z","hd":{"ts_event":"2026-04-07T02:07:03.064143193Z","rtype":160,"publisher_id":101,"instrument_id":436},"action":"A","side":"B","price":"1.156400000","size":20,"channel_id":23,"order_id":"10998899659918925230","flags":128,"ts_in_delta":1006,"sequence":146282,"symbol":"FCEU SI 20260615 PS"}
{"ts_recv":"2026-04-07T02:07:03.064181633Z","hd":{"ts_event":"2026-04-07T02:07:03.064168167Z","rtype":160,"publisher_id":101,"instrument_id":436},"action":"C","side":"B","price":"1.156300000","size":20,"channel_id":23,"order_id":"10998899659876160814","flags":128,"ts_in_delta":1028,"sequence":146283,"symbol":"FCEU SI 20260615 PS"}
{"ts_recv":"2026-04-07T02:07:04.253161441Z","hd":{"ts_event":"2026-04-07T02:07:04.253140883Z","rtype":160,"publisher_id":101,"instrument_id":436},"action":"C","side":"B","price":"1.156510000","size":30,"channel_id":23,"order_id":"10998899659851208470","flags":0,"ts_in_delta":973,"sequence":146315,"symbol":"FCEU SI 20260615 PS"}
{"ts_recv":"2026-04-07T02:07:04.253161441Z","hd":{"ts_event":"2026-04-07T02:07:04.253140883Z","rtype":160,"publisher_id":101,"instrument_id":436},"action":"A","side":"B","price":"1.156500000","size":30,"channel_id":23,"order_id":"10998899661107922597","flags":0,"ts_in_delta":973,"sequence":146315,"symbol":"FCEU SI 20260615 PS"}
{"ts_recv":"2026-04-07T02:07:04.253161441Z","hd":{"ts_event":"2026-04-07T02:07:04.253140883Z","rtype":160,"publisher_id":101,"instrument_id":436},"action":"C","side":"A","price":"1.156610000","size":30,"channel_id":23,"order_id":"1775527622996432662","flags":0,"ts_in_delta":973,"sequence":146315,"symbol":"FCEU SI 20260615 PS"}
{"ts_recv":"2026-04-07T02:07:04.253161441Z","hd":{"ts_event":"2026-04-07T02:07:04.253140883Z","rtype":160,"publisher_id":101,"instrument_id":436},"action":"A","side":"A","price":"1.156600000","size":30,"channel_id":23,"order_id":"1775527624253146789","flags":128,"ts_in_delta":973,"sequence":146315,"symbol":"FCEU SI 20260615 PS"}
{"ts_recv":"2026-04-07T02:07:04.377754016Z","hd":{"ts_event":"2026-04-07T02:07:04.377731185Z","rtype":160,"publisher_id":101,"instrument_id":436},"action":"C","side":"B","price":"1.156510000","size":30,"channel_id":23,"order_id":"10998899659851148577","flags":0,"ts_in_delta":1040,"sequence":146328,"symbol":"FCEU SI 20260615 PS"}
{"ts_recv":"2026-04-07T02:07:04.377754016Z","hd":{"ts_event":"2026-04-07T02:07:04.377731185Z","rtype":160,"publisher_id":101,"instrument_id":436},"action":"A","side":"B","price":"1.156490000","size":30,"channel_id":23,"order_id":"10998899661232513226","flags":0,"ts_in_delta":1040,"sequence":146328,"symbol":"FCEU SI 20260615 PS"}
{"ts_recv":"2026-04-07T02:07:04.377754016Z","hd":{"ts_event":"2026-04-07T02:07:04.377731185Z","rtype":160,"publisher_id":101,"instrument_id":436},"action":"C","side":"A","price":"1.156610000","size":30,"channel_id":23,"order_id":"1775527622996372769","flags":0,"ts_in_delta":1040,"sequence":146328,"symbol":"FCEU SI 20260615 PS"}
{"ts_recv":"2026-04-07T02:07:04.377754016Z","hd":{"ts_event":"2026-04-07T02:07:04.377731185Z","rtype":160,"publisher_id":101,"instrument_id":436},"action":"A","side":"A","price":"1.156590000","size":30,"channel_id":23,"order_id":"1775527624377737418","flags":128,"ts_in_delta":1040,"sequence":146328,"symbol":"FCEU SI 20260615 PS"}
{"ts_recv":"2026-04-07T02:07:04.377855894Z","hd":{"ts_event":"2026-04-07T02:07:04.377838149Z","rtype":160,"publisher_id":101,"instrument_id":436},"action":"C","side":"B","price":"1.156500000","size":30,"channel_id":23,"order_id":"10998899661107922597","flags":0,"ts_in_delta":974,"sequence":146329,"symbol":"FCEU SI 20260615 PS"}
{"ts_recv":"2026-04-07T02:07:04.377855894Z","hd":{"ts_event":"2026-04-07T02:07:04.377838149Z","rtype":160,"publisher_id":101,"instrument_id":436},"action":"A","side":"B","price":"1.156490000","size":30,"channel_id":23,"order_id":"10998899661232619932","flags":0,"ts_in_delta":974,"sequence":146329,"symbol":"FCEU SI 20260615 PS"}
{"ts_recv":"2026-04-07T02:07:04.377855894Z","hd":{"ts_event":"2026-04-07T02:07:04.377838149Z","rtype":160,"publisher_id":101,"instrument_id":436},"action":"C","side":"A","price":"1.156600000","size":30,"channel_id":23,"order_id":"1775527624253146789","flags":0,"ts_in_delta":974,"sequence":146329,"symbol":"FCEU SI 20260615 PS"}
{"ts_recv":"2026-04-07T02:07:04.377855894Z","hd":{"ts_event":"2026-04-07T02:07:04.377838149Z","rtype":160,"publisher_id":101,"instrument_id":436},"action":"A","side":"A","price":"1.156590000","size":30,"channel_id":23,"order_id":"1775527624377844124","flags":128,"ts_in_delta":974,"sequence":146329,"symbol":"FCEU SI 20260615 PS"}
{"ts_recv":"2026-04-07T02:07:27.207495886Z","hd":{"ts_event":"2026-04-07T02:07:27.207462607Z","rtype":160,"publisher_id":101,"instrument_id":436},"action":"C","side":"B","price":"1.156490000","size":30,"channel_id":23,"order_id":"10998899661232619932","flags":0,"ts_in_delta":1611,"sequence":146558,"symbol":"FCEU SI 20260615 PS"}
{"ts_recv":"2026-04-07T02:07:27.207495886Z","hd":{"ts_event":"2026-04-07T02:07:27.207462607Z","rtype":160,"publisher_id":101,"instrument_id":436},"action":"A","side":"B","price":"1.156480000","size":30,"channel_id":23,"order_id":"10998899684062251283","flags":0,"ts_in_delta":1611,"sequence":146558,"symbol":"FCEU SI 20260615 PS"}
{"ts_recv":"2026-04-07T02:07:27.207495886Z","hd":{"ts_event":"2026-04-07T02:07:27.207462607Z","rtype":160,"publisher_id":101,"instrument_id":436},"action":"C","side":"A","price":"1.156590000","size":30,"channel_id":23,"order_id":"1775527624377844124","flags":0,"ts_in_delta":1611,"sequence":146558,"symbol":"FCEU SI 20260615 PS"}
{"ts_recv":"2026-04-07T02:07:27.207495886Z","hd":{"ts_event":"2026-04-07T02:07:27.207462607Z","rtype":160,"publisher_id":101,"instrument_id":436},"action":"A","side":"A","price":"1.156580000","size":30,"channel_id":23,"order_id":"1775527647207475475","flags":128,"ts_in_delta":1611,"sequence":146558,"symbol":"FCEU SI 20260615 PS"}
{"ts_recv":"2026-04-07T02:07:27.207558306Z","hd":{"ts_event":"2026-04-07T02:07:27.207539313Z","rtype":160,"publisher_id":101,"instrument_id":436},"action":"C","side":"B","price":"1.156490000","size":30,"channel_id":23,"order_id":"10998899661232513226","flags":0,"ts_in_delta":970,"sequence":146559,"symbol":"FCEU SI 20260615 PS"}
{"ts_recv":"2026-04-07T02:07:27.207558306Z","hd":{"ts_event":"2026-04-07T02:07:27.207539313Z","rtype":160,"publisher_id":101,"instrument_id":436},"action":"A","side":"B","price":"1.156470000","size":30,"channel_id":23,"order_id":"10998899684062321653","flags":0,"ts_in_delta":970,"sequence":146559,"symbol":"FCEU SI 20260615 PS"}
{"ts_recv":"2026-04-07T02:07:27.207558306Z","hd":{"ts_event":"2026-04-07T02:07:27.207539313Z","rtype":160,"publisher_id":101,"instrument_id":436},"action":"C","side":"A","price":"1.156590000","size":30,"channel_id":23,"order_id":"1775527624377737418","flags":0,"ts_in_delta":970,"sequence":146559,"symbol":"FCEU SI 20260615 PS"}
{"ts_recv":"2026-04-07T02:07:27.207558306Z","hd":{"ts_event":"2026-04-07T02:07:27.207539313Z","rtype":160,"publisher_id":101,"instrument_id":436},"action":"A","side":"A","price":"1.156570000","size":30,"channel_id":23,"order_id":"1775527647207545845","flags":128,"ts_in_delta":970,"sequence":146559,"symbol":"FCEU SI 20260615 PS"}
{"ts_recv":"2026-04-07T02:07:27.207621748Z","hd":{"ts_event":"2026-04-07T02:07:27.207601885Z","rtype":160,"publisher_id":101,"instrument_id":436},"action":"C","side":"B","price":"1.156480000","size":30,"channel_id":23,"order_id":"10998899684062251283","flags":0,"ts_in_delta":948,"sequence":146560,"symbol":"FCEU SI 20260615 PS"}
{"ts_recv":"2026-04-07T02:07:27.207621748Z","hd":{"ts_event":"2026-04-07T02:07:27.207601885Z","rtype":160,"publisher_id":101,"instrument_id":436},"action":"A","side":"B","price":"1.156470000","size":30,"channel_id":23,"order_id":"10998899684062383643","flags":0,"ts_in_delta":948,"sequence":146560,"symbol":"FCEU SI 20260615 PS"}
{"ts_recv":"2026-04-07T02:07:27.207621748Z","hd":{"ts_event":"2026-04-07T02:07:27.207601885Z","rtype":160,"publisher_id":101,"instrument_id":436},"action":"C","side":"A","price":"1.156580000","size":30,"channel_id":23,"order_id":"1775527647207475475","flags":0,"ts_in_delta":948,"sequence":146560,"symbol":"FCEU SI 20260615 PS"}
{"ts_recv":"2026-04-07T02:07:27.207621748Z","hd":{"ts_event":"2026-04-07T02:07:27.207601885Z","rtype":160,"publisher_id":101,"instrument_id":436},"action":"A","side":"A","price":"1.156570000","size":30,"channel_id":23,"order_id":"1775527647207607835","flags":128,"ts_in_delta":948,"sequence":146560,"symbol":"FCEU SI 20260615 PS"}
{"ts_recv":"2026-04-07T02:07:27.411308598Z","hd":{"ts_event":"2026-04-07T02:07:27.411287453Z","rtype":160,"publisher_id":101,"instrument_id":436},"action":"A","side":"A","price":"1.156700000","size":20,"channel_id":23,"order_id":"1775527647411298233","flags":128,"ts_in_delta":1164,"sequence":146574,"symbol":"FCEU SI 20260615 PS"}
{"ts_recv":"2026-04-07T02:07:27.411329847Z","hd":{"ts_event":"2026-04-07T02:07:27.411315613Z","rtype":160,"publisher_id":101,"instrument_id":436},"action":"C","side":"A","price":"1.156800000","size":20,"channel_id":23,"order_id":"1775527312322261988","flags":128,"ts_in_delta":856,"sequence":146575,"symbol":"FCEU SI 20260615 PS"}
{"ts_recv":"2026-04-07T02:07:30.520635660Z","hd":{"ts_event":"2026-04-07T02:07:30.520609979Z","rtype":160,"publisher_id":101,"instrument_id":436},"action":"C","side":"B","price":"1.156470000","size":30,"channel_id":23,"order_id":"10998899684062383643","flags":0,"ts_in_delta":948,"sequence":146584,"symbol":"FCEU SI 20260615 PS"}
{"ts_recv":"2026-04-07T02:07:30.520635660Z","hd":{"ts_event":"2026-04-07T02:07:30.520609979Z","rtype":160,"publisher_id":101,"instrument_id":436},"action":"A","side":"B","price":"1.156460000","size":30,"channel_id":23,"order_id":"10998899687375392703","flags":0,"ts_in_delta":948,"sequence":146584,"symbol":"FCEU SI 20260615 PS"}
{"ts_recv":"2026-04-07T02:07:30.520635660Z","hd":{"ts_event":"2026-04-07T02:07:30.520609979Z","rtype":160,"publisher_id":101,"instrument_id":436},"action":"C","side":"A","price":"1.156570000","size":30,"channel_id":23,"order_id":"1775527647207607835","flags":0,"ts_in_delta":948,"sequence":146584,"symbol":"FCEU SI 20260615 PS"}
{"ts_recv":"2026-04-07T02:07:30.520635660Z","hd":{"ts_event":"2026-04-07T02:07:30.520609979Z","rtype":160,"publisher_id":101,"instrument_id":436},"action":"A","side":"A","price":"1.156560000","size":30,"channel_id":23,"order_id":"1775527650520616895","flags":128,"ts_in_delta":948,"sequence":146584,"symbol":"FCEU SI 20260615 PS"}
{"ts_recv":"2026-04-07T02:07:36.325068406Z","hd":{"ts_event":"2026-04-07T02:07:36.325033655Z","rtype":160,"publisher_id":101,"instrument_id":436},"action":"C","side":"B","price":"1.156460000","size":30,"channel_id":23,"order_id":"10998899687375392703","flags":0,"ts_in_delta":1295,"sequence":146621,"symbol":"FCEU SI 20260615 PS"}
{"ts_recv":"2026-04-07T02:07:36.325068406Z","hd":{"ts_event":"2026-04-07T02:07:36.325033655Z","rtype":160,"publisher_id":101,"instrument_id":436},"action":"A","side":"B","price":"1.156450000","size":30,"channel_id":23,"order_id":"10998899693179822931","flags":0,"ts_in_delta":1295,"sequence":146621,"symbol":"FCEU SI 20260615 PS"}
{"ts_recv":"2026-04-07T02:07:36.325068406Z","hd":{"ts_event":"2026-04-07T02:07:36.325033655Z","rtype":160,"publisher_id":101,"instrument_id":436},"action":"C","side":"A","price":"1.156560000","size":30,"channel_id":23,"order_id":"1775527650520616895","flags":0,"ts_in_delta":1295,"sequence":146621,"symbol":"FCEU SI 20260615 PS"}
{"ts_recv":"2026-04-07T02:07:36.325068406Z","hd":{"ts_event":"2026-04-07T02:07:36.325033655Z","rtype":160,"publisher_id":101,"instrument_id":436},"action":"A","side":"A","price":"1.156550000","size":30,"channel_id":23,"order_id":"1775527656325047123","flags":128,"ts_in_delta":1295,"sequence":146621,"symbol":"FCEU SI 20260615 PS"}
{"ts_recv":"2026-04-07T02:07:36.366057046Z","hd":{"ts_event":"2026-04-07T02:07:36.366029493Z","rtype":160,"publisher_id":101,"instrument_id":436},"action":"C","side":"B","price":"1.156470000","size":30,"channel_id":23,"order_id":"10998899684062321653","flags":0,"ts_in_delta":968,"sequence":146623,"symbol":"FCEU SI 20260615 PS"}
{"ts_recv":"2026-04-07T02:07:36.366057046Z","hd":{"ts_event":"2026-04-07T02:07:36.366029493Z","rtype":160,"publisher_id":101,"instrument_id":436},"action":"A","side":"B","price":"1.156440000","size":30,"channel_id":23,"order_id":"10998899693220816074","flags":0,"ts_in_delta":968,"sequence":146623,"symbol":"FCEU SI 20260615 PS"}
{"ts_recv":"2026-04-07T02:07:36.366057046Z","hd":{"ts_event":"2026-04-07T02:07:36.366029493Z","rtype":160,"publisher_id":101,"instrument_id":436},"action":"C","side":"A","price":"1.156570000","size":30,"channel_id":23,"order_id":"1775527647207545845","flags":0,"ts_in_delta":968,"sequence":146623,"symbol":"FCEU SI 20260615 PS"}
{"ts_recv":"2026-04-07T02:07:36.366057046Z","hd":{"ts_event":"2026-04-07T02:07:36.366029493Z","rtype":160,"publisher_id":101,"instrument_id":436},"action":"A","side":"A","price":"1.156540000","size":30,"channel_id":23,"order_id":"1775527656366040266","flags":128,"ts_in_delta":968,"sequence":146623,"symbol":"FCEU SI 20260615 PS"}
{"ts_recv":"2026-04-07T02:07:36.366129311Z","hd":{"ts_event":"2026-04-07T02:07:36.366107503Z","rtype":160,"publisher_id":101,"instrument_id":436},"action":"C","side":"B","price":"1.156450000","size":30,"channel_id":23,"order_id":"10998899693179822931","flags":0,"ts_in_delta":1002,"sequence":146624,"symbol":"FCEU SI 20260615 PS"}
{"ts_recv":"2026-04-07T02:07:36.366129311Z","hd":{"ts_event":"2026-04-07T02:07:36.366107503Z","rtype":160,"publisher_id":101,"instrument_id":436},"action":"A","side":"B","price":"1.156440000","size":30,"channel_id":23,"order_id":"10998899693220889341","flags":0,"ts_in_delta":1002,"sequence":146624,"symbol":"FCEU SI 20260615 PS"}
{"ts_recv":"2026-04-07T02:07:36.366129311Z","hd":{"ts_event":"2026-04-07T02:07:36.366107503Z","rtype":160,"publisher_id":101,"instrument_id":436},"action":"C","side":"A","price":"1.156550000","size":30,"channel_id":23,"order_id":"1775527656325047123","flags":0,"ts_in_delta":1002,"sequence":146624,"symbol":"FCEU SI 20260615 PS"}
{"ts_recv":"2026-04-07T02:07:36.366129311Z","hd":{"ts_event":"2026-04-07T02:07:36.366107503Z","rtype":160,"publisher_id":101,"instrument_id":436},"action":"A","side":"A","price":"1.156540000","size":30,"channel_id":23,"order_id":"1775527656366113533","flags":128,"ts_in_delta":1002,"sequence":146624,"symbol":"FCEU SI 20260615 PS"}
{"ts_recv":"2026-04-07T02:07:36.369046057Z","hd":{"ts_event":"2026-04-07T02:07:36.369027115Z","rtype":160,"publisher_id":101,"instrument_id":436},"action":"C","side":"B","price":"1.156440000","size":30,"channel_id":23,"order_id":"10998899693220889341","flags":0,"ts_in_delta":988,"sequence":146626,"symbol":"FCEU SI 20260615 PS"}
{"ts_recv":"2026-04-07T02:07:36.369046057Z","hd":{"ts_event":"2026-04-07T02:07:36.369027115Z","rtype":160,"publisher_id":101,"instrument_id":436},"action":"A","side":"B","price":"1.156430000","size":30,"channel_id":23,"order_id":"10998899693223808746","flags":0,"ts_in_delta":988,"sequence":146626,"symbol":"FCEU SI 20260615 PS"}
{"ts_recv":"2026-04-07T02:07:36.369046057Z","hd":{"ts_event":"2026-04-07T02:07:36.369027115Z","rtype":160,"publisher_id":101,"instrument_id":436},"action":"C","side":"A","price":"1.156540000","size":30,"channel_id":23,"order_id":"1775527656366113533","flags":0,"ts_in_delta":988,"sequence":146626,"symbol":"FCEU SI 20260615 PS"}
{"ts_recv":"2026-04-07T02:07:36.369046057Z","hd":{"ts_event":"2026-04-07T02:07:36.369027115Z","rtype":160,"publisher_id":101,"instrument_id":436},"action":"A","side":"A","price":"1.156530000","size":30,"channel_id":23,"order_id":"1775527656369032938","flags":128,"ts_in_delta":988,"sequence":146626,"symbol":"FCEU SI 20260615 PS"}
{"ts_recv":"2026-04-07T02:07:36.373738483Z","hd":{"ts_event":"2026-04-07T02:07:36.373720065Z","rtype":160,"publisher_id":101,"instrument_id":436},"action":"C","side":"B","price":"1.156430000","size":30,"channel_id":23,"order_id":"10998899693223808746","flags":0,"ts_in_delta":1023,"sequence":146635,"symbol":"FCEU SI 20260615 PS"}
{"ts_recv":"2026-04-07T02:07:36.373738483Z","hd":{"ts_event":"2026-04-07T02:07:36.373720065Z","rtype":160,"publisher_id":101,"instrument_id":436},"action":"A","side":"B","price":"1.156420000","size":30,"channel_id":23,"order_id":"10998899693228502056","flags":0,"ts_in_delta":1023,"sequence":146635,"symbol":"FCEU SI 20260615 PS"}
{"ts_recv":"2026-04-07T02:07:36.373738483Z","hd":{"ts_event":"2026-04-07T02:07:36.373720065Z","rtype":160,"publisher_id":101,"instrument_id":436},"action":"C","side":"A","price":"1.156530000","size":30,"channel_id":23,"order_id":"1775527656369032938","flags":0,"ts_in_delta":1023,"sequence":146635,"symbol":"FCEU SI 20260615 PS"}
{"ts_recv":"2026-04-07T02:07:36.373738483Z","hd":{"ts_event":"2026-04-07T02:07:36.373720065Z","rtype":160,"publisher_id":101,"instrument_id":436},"action":"A","side":"A","price":"1.156520000","size":30,"channel_id":23,"order_id":"1775527656373726248","flags":128,"ts_in_delta":1023,"sequence":146635,"symbol":"FCEU SI 20260615 PS"}
{"ts_recv":"2026-04-07T02:07:36.373791373Z","hd":{"ts_event":"2026-04-07T02:07:36.373774075Z","rtype":160,"publisher_id":101,"instrument_id":436},"action":"C","side":"B","price":"1.156440000","size":30,"channel_id":23,"order_id":"10998899693220816074","flags":0,"ts_in_delta":1002,"sequence":146636,"symbol":"FCEU SI 20260615 PS"}
{"ts_recv":"2026-04-07T02:07:36.373791373Z","hd":{"ts_event":"2026-04-07T02:07:36.373774075Z","rtype":160,"publisher_id":101,"instrument_id":436},"action":"A","side":"B","price":"1.156420000","size":30,"channel_id":23,"order_id":"10998899693228555881","flags":0,"ts_in_delta":1002,"sequence":146636,"symbol":"FCEU SI 20260615 PS"}
{"ts_recv":"2026-04-07T02:07:36.373791373Z","hd":{"ts_event":"2026-04-07T02:07:36.373774075Z","rtype":160,"publisher_id":101,"instrument_id":436},"action":"C","side":"A","price":"1.156540000","size":30,"channel_id":23,"order_id":"1775527656366040266","flags":0,"ts_in_delta":1002,"sequence":146636,"symbol":"FCEU SI 20260615 PS"}
{"ts_recv":"2026-04-07T02:07:36.373791373Z","hd":{"ts_event":"2026-04-07T02:07:36.373774075Z","rtype":160,"publisher_id":101,"instrument_id":436},"action":"A","side":"A","price":"1.156520000","size":30,"channel_id":23,"order_id":"1775527656373780073","flags":128,"ts_in_delta":1002,"sequence":146636,"symbol":"FCEU SI 20260615 PS"}
{"ts_recv":"2026-04-07T02:07:36.373817652Z","hd":{"ts_event":"2026-04-07T02:07:36.373799843Z","rtype":160,"publisher_id":101,"instrument_id":436},"action":"C","side":"B","price":"1.156420000","size":30,"channel_id":23,"order_id":"10998899693228502056","flags":0,"ts_in_delta":988,"sequence":146637,"symbol":"FCEU SI 20260615 PS"}
{"ts_recv":"2026-04-07T02:07:36.373817652Z","hd":{"ts_event":"2026-04-07T02:07:36.373799843Z","rtype":160,"publisher_id":101,"instrument_id":436},"action":"A","side":"B","price":"1.156430000","size":30,"channel_id":23,"order_id":"10998899693228581257","flags":0,"ts_in_delta":988,"sequence":146637,"symbol":"FCEU SI 20260615 PS"}
{"ts_recv":"2026-04-07T02:07:36.373817652Z","hd":{"ts_event":"2026-04-07T02:07:36.373799843Z","rtype":160,"publisher_id":101,"instrument_id":436},"action":"C","side":"A","price":"1.156520000","size":30,"channel_id":23,"order_id":"1775527656373726248","flags":0,"ts_in_delta":988,"sequence":146637,"symbol":"FCEU SI 20260615 PS"}
{"ts_recv":"2026-04-07T02:07:36.373817652Z","hd":{"ts_event":"2026-04-07T02:07:36.373799843Z","rtype":160,"publisher_id":101,"instrument_id":436},"action":"A","side":"A","price":"1.156530000","size":30,"channel_id":23,"order_id":"1775527656373805449","flags":128,"ts_in_delta":988,"sequence":146637,"symbol":"FCEU SI 20260615 PS"}
{"ts_recv":"2026-04-07T02:07:36.373877630Z","hd":{"ts_event":"2026-04-07T02:07:36.373858115Z","rtype":160,"publisher_id":101,"instrument_id":436},"action":"C","side":"B","price":"1.156430000","size":30,"channel_id":23,"order_id":"10998899693228581257","flags":0,"ts_in_delta":983,"sequence":146638,"symbol":"FCEU SI 20260615 PS"}
{"ts_recv":"2026-04-07T02:07:36.373877630Z","hd":{"ts_event":"2026-04-07T02:07:36.373858115Z","rtype":160,"publisher_id":101,"instrument_id":436},"action":"A","side":"B","price":"1.156420000","size":30,"channel_id":23,"order_id":"10998899693228639580","flags":0,"ts_in_delta":983,"sequence":146638,"symbol":"FCEU SI 20260615 PS"}
{"ts_recv":"2026-04-07T02:07:36.373877630Z","hd":{"ts_event":"2026-04-07T02:07:36.373858115Z","rtype":160,"publisher_id":101,"instrument_id":436},"action":"C","side":"A","price":"1.156530000","size":30,"channel_id":23,"order_id":"1775527656373805449","flags":0,"ts_in_delta":983,"sequence":146638,"symbol":"FCEU SI 20260615 PS"}
{"ts_recv":"2026-04-07T02:07:36.373877630Z","hd":{"ts_event":"2026-04-07T02:07:36.373858115Z","rtype":160,"publisher_id":101,"instrument_id":436},"action":"A","side":"A","price":"1.156520000","size":30,"channel_id":23,"order_id":"1775527656373863772","flags":128,"ts_in_delta":983,"sequence":146638,"symbol":"FCEU SI 20260615 PS"}
{"ts_recv":"2026-04-07T02:07:36.386857810Z","hd":{"ts_event":"2026-04-07T02:07:36.386844245Z","rtype":160,"publisher_id":101,"instrument_id":436},"action":"C","side":"B","price":"1.156400000","size":20,"channel_id":23,"order_id":"10998899659918925230","flags":128,"ts_in_delta":813,"sequence":146650,"symbol":"FCEU SI 20260615 PS"}
{"ts_recv":"2026-04-07T02:07:36.460871415Z","hd":{"ts_event":"2026-04-07T02:07:36.460851743Z","rtype":160,"publisher_id":101,"instrument_id":436},"action":"C","side":"B","price":"1.156420000","size":30,"channel_id":23,"order_id":"10998899693228639580","flags":0,"ts_in_delta":803,"sequence":146668,"symbol":"FCEU SI 20260615 PS"}
{"ts_recv":"2026-04-07T02:07:36.460871415Z","hd":{"ts_event":"2026-04-07T02:07:36.460851743Z","rtype":160,"publisher_id":101,"instrument_id":436},"action":"A","side":"B","price":"1.156410000","size":30,"channel_id":23,"order_id":"10998899693315633704","flags":0,"ts_in_delta":803,"sequence":146668,"symbol":"FCEU SI 20260615 PS"}
{"ts_recv":"2026-04-07T02:07:36.460871415Z","hd":{"ts_event":"2026-04-07T02:07:36.460851743Z","rtype":160,"publisher_id":101,"instrument_id":436},"action":"C","side":"A","price":"1.156520000","size":30,"channel_id":23,"order_id":"1775527656373863772","flags":0,"ts_in_delta":803,"sequence":146668,"symbol":"FCEU SI 20260615 PS"}
{"ts_recv":"2026-04-07T02:07:36.460871415Z","hd":{"ts_event":"2026-04-07T02:07:36.460851743Z","rtype":160,"publisher_id":101,"instrument_id":436},"action":"A","side":"A","price":"1.156510000","size":30,"channel_id":23,"order_id":"1775527656460857896","flags":128,"ts_in_delta":803,"sequence":146668,"symbol":"FCEU SI 20260615 PS"}
{"ts_recv":"2026-04-07T02:07:36.460932253Z","hd":{"ts_event":"2026-04-07T02:07:36.460914603Z","rtype":160,"publisher_id":101,"instrument_id":436},"action":"C","side":"B","price":"1.156410000","size":30,"channel_id":23,"order_id":"10998899693315633704","flags":0,"ts_in_delta":813,"sequence":146669,"symbol":"FCEU SI 20260615 PS"}
{"ts_recv":"2026-04-07T02:07:36.460932253Z","hd":{"ts_event":"2026-04-07T02:07:36.460914603Z","rtype":160,"publisher_id":101,"instrument_id":436},"action":"A","side":"B","price":"1.156400000","size":30,"channel_id":23,"order_id":"10998899693315696148","flags":0,"ts_in_delta":813,"sequence":146669,"symbol":"FCEU SI 20260615 PS"}
{"ts_recv":"2026-04-07T02:07:36.460932253Z","hd":{"ts_event":"2026-04-07T02:07:36.460914603Z","rtype":160,"publisher_id":101,"instrument_id":436},"action":"C","side":"A","price":"1.156510000","size":30,"channel_id":23,"order_id":"1775527656460857896","flags":0,"ts_in_delta":813,"sequence":146669,"symbol":"FCEU SI 20260615 PS"}
{"ts_recv":"2026-04-07T02:07:36.460932253Z","hd":{"ts_event":"2026-04-07T02:07:36.460914603Z","rtype":160,"publisher_id":101,"instrument_id":436},"action":"A","side":"A","price":"1.156500000","size":30,"channel_id":23,"order_id":"1775527656460920340","flags":128,"ts_in_delta":813,"sequence":146669,"symbol":"FCEU SI 20260615 PS"}
{"ts_recv":"2026-04-07T02:07:36.460979237Z","hd":{"ts_event":"2026-04-07T02:07:36.460962135Z","rtype":160,"publisher_id":101,"instrument_id":436},"action":"C","side":"B","price":"1.156420000","size":30,"channel_id":23,"order_id":"10998899693228555881","flags":0,"ts_in_delta":857,"sequence":146670,"symbol":"FCEU SI 20260615 PS"}
{"ts_recv":"2026-04-07T02:07:36.460979237Z","hd":{"ts_event":"2026-04-07T02:07:36.460962135Z","rtype":160,"publisher_id":101,"instrument_id":436},"action":"A","side":"B","price":"1.156400000","size":30,"channel_id":23,"order_id":"10998899693315743737","flags":0,"ts_in_delta":857,"sequence":146670,"symbol":"FCEU SI 20260615 PS"}
{"ts_recv":"2026-04-07T02:07:36.460979237Z","hd":{"ts_event":"2026-04-07T02:07:36.460962135Z","rtype":160,"publisher_id":101,"instrument_id":436},"action":"C","side":"A","price":"1.156520000","size":30,"channel_id":23,"order_id":"1775527656373780073","flags":0,"ts_in_delta":857,"sequence":146670,"symbol":"FCEU SI 20260615 PS"}
{"ts_recv":"2026-04-07T02:07:36.460979237Z","hd":{"ts_event":"2026-04-07T02:07:36.460962135Z","rtype":160,"publisher_id":101,"instrument_id":436},"action":"A","side":"A","price":"1.156500000","size":30,"channel_id":23,"order_id":"1775527656460967929","flags":128,"ts_in_delta":857,"sequence":146670,"symbol":"FCEU SI 20260615 PS"}
{"ts_recv":"2026-04-07T02:07:36.460989628Z","hd":{"ts_event":"2026-04-07T02:07:36.460968747Z","rtype":160,"publisher_id":101,"instrument_id":436},"action":"C","side":"B","price":"1.156400000","size":30,"channel_id":23,"order_id":"10998899693315696148","flags":0,"ts_in_delta":841,"sequence":146671,"symbol":"FCEU SI 20260615 PS"}
{"ts_recv":"2026-04-07T02:07:36.460989628Z","hd":{"ts_event":"2026-04-07T02:07:36.460968747Z","rtype":160,"publisher_id":101,"instrument_id":436},"action":"A","side":"B","price":"1.156410000","size":30,"channel_id":23,"order_id":"10998899693315751961","flags":0,"ts_in_delta":841,"sequence":146671,"symbol":"FCEU SI 20260615 PS"}
{"ts_recv":"2026-04-07T02:07:36.460989628Z","hd":{"ts_event":"2026-04-07T02:07:36.460968747Z","rtype":160,"publisher_id":101,"instrument_id":436},"action":"C","side":"A","price":"1.156500000","size":30,"channel_id":23,"order_id":"1775527656460920340","flags":0,"ts_in_delta":841,"sequence":146671,"symbol":"FCEU SI 20260615 PS"}
{"ts_recv":"2026-04-07T02:07:36.460989628Z","hd":{"ts_event":"2026-04-07T02:07:36.460968747Z","rtype":160,"publisher_id":101,"instrument_id":436},"action":"A","side":"A","price":"1.156510000","size":30,"channel_id":23,"order_id":"1775527656460976153","flags":128,"ts_in_delta":841,"sequence":146671,"symbol":"FCEU SI 20260615 PS"}
{"ts_recv":"2026-04-07T02:07:36.461043262Z","hd":{"ts_event":"2026-04-07T02:07:36.461026641Z","rtype":160,"publisher_id":101,"instrument_id":436},"action":"C","side":"B","price":"1.156410000","size":30,"channel_id":23,"order_id":"10998899693315751961","flags":0,"ts_in_delta":795,"sequence":146672,"symbol":"FCEU SI 20260615 PS"}
{"ts_recv":"2026-04-07T02:07:36.461043262Z","hd":{"ts_event":"2026-04-07T02:07:36.461026641Z","rtype":160,"publisher_id":101,"instrument_id":436},"action":"A","side":"B","price":"1.156400000","size":30,"channel_id":23,"order_id":"10998899693315808329","flags":0,"ts_in_delta":795,"sequence":146672,"symbol":"FCEU SI 20260615 PS"}
{"ts_recv":"2026-04-07T02:07:36.461043262Z","hd":{"ts_event":"2026-04-07T02:07:36.461026641Z","rtype":160,"publisher_id":101,"instrument_id":436},"action":"C","side":"A","price":"1.156510000","size":30,"channel_id":23,"order_id":"1775527656460976153","flags":0,"ts_in_delta":795,"sequence":146672,"symbol":"FCEU SI 20260615 PS"}
{"ts_recv":"2026-04-07T02:07:36.461043262Z","hd":{"ts_event":"2026-04-07T02:07:36.461026641Z","rtype":160,"publisher_id":101,"instrument_id":436},"action":"A","side":"A","price":"1.156500000","size":30,"channel_id":23,"order_id":"1775527656461032521","flags":128,"ts_in_delta":795,"sequence":146672,"symbol":"FCEU SI 20260615 PS"}
{"ts_recv":"2026-04-07T02:07:36.465539688Z","hd":{"ts_event":"2026-04-07T02:07:36.465522157Z","rtype":160,"publisher_id":101,"instrument_id":436},"action":"C","side":"B","price":"1.156400000","size":30,"channel_id":23,"order_id":"10998899693315808329","flags":0,"ts_in_delta":846,"sequence":146674,"symbol":"FCEU SI 20260615 PS"}
{"ts_recv":"2026-04-07T02:07:36.465539688Z","hd":{"ts_event":"2026-04-07T02:07:36.465522157Z","rtype":160,"publisher_id":101,"instrument_id":436},"action":"A","side":"B","price":"1.156390000","size":30,"channel_id":23,"order_id":"10998899693320303610","flags":0,"ts_in_delta":846,"sequence":146674,"symbol":"FCEU SI 20260615 PS"}
{"ts_recv":"2026-04-07T02:07:36.465539688Z","hd":{"ts_event":"2026-04-07T02:07:36.465522157Z","rtype":160,"publisher_id":101,"instrument_id":436},"action":"C","side":"A","price":"1.156500000","size":30,"channel_id":23,"order_id":"1775527656461032521","flags":0,"ts_in_delta":846,"sequence":146674,"symbol":"FCEU SI 20260615 PS"}
{"ts_recv":"2026-04-07T02:07:36.465539688Z","hd":{"ts_event":"2026-04-07T02:07:36.465522157Z","rtype":160,"publisher_id":101,"instrument_id":436},"action":"A","side":"A","price":"1.156490000","size":30,"channel_id":23,"order_id":"1775527656465527802","flags":128,"ts_in_delta":846,"sequence":146674,"symbol":"FCEU SI 20260615 PS"}
{"ts_recv":"2026-04-07T02:07:36.520065373Z","hd":{"ts_event":"2026-04-07T02:07:36.520044491Z","rtype":160,"publisher_id":101,"instrument_id":436},"action":"C","side":"B","price":"1.156400000","size":30,"channel_id":23,"order_id":"10998899693315743737","flags":0,"ts_in_delta":987,"sequence":146689,"symbol":"FCEU SI 20260615 PS"}
{"ts_recv":"2026-04-07T02:07:36.520065373Z","hd":{"ts_event":"2026-04-07T02:07:36.520044491Z","rtype":160,"publisher_id":101,"instrument_id":436},"action":"A","side":"B","price":"1.156380000","size":30,"channel_id":23,"order_id":"10998899693374826145","flags":0,"ts_in_delta":987,"sequence":146689,"symbol":"FCEU SI 20260615 PS"}
{"ts_recv":"2026-04-07T02:07:36.520065373Z","hd":{"ts_event":"2026-04-07T02:07:36.520044491Z","rtype":160,"publisher_id":101,"instrument_id":436},"action":"C","side":"A","price":"1.156500000","size":30,"channel_id":23,"order_id":"1775527656460967929","flags":0,"ts_in_delta":987,"sequence":146689,"symbol":"FCEU SI 20260615 PS"}
{"ts_recv":"2026-04-07T02:07:36.520065373Z","hd":{"ts_event":"2026-04-07T02:07:36.520044491Z","rtype":160,"publisher_id":101,"instrument_id":436},"action":"A","side":"A","price":"1.156480000","size":30,"channel_id":23,"order_id":"1775527656520050337","flags":128,"ts_in_delta":987,"sequence":146689,"symbol":"FCEU SI 20260615 PS"}
{"ts_recv":"2026-04-07T02:07:36.520128316Z","hd":{"ts_event":"2026-04-07T02:07:36.520110711Z","rtype":160,"publisher_id":101,"instrument_id":436},"action":"C","side":"B","price":"1.156390000","size":30,"channel_id":23,"order_id":"10998899693320303610","flags":0,"ts_in_delta":998,"sequence":146690,"symbol":"FCEU SI 20260615 PS"}
{"ts_recv":"2026-04-07T02:07:36.520128316Z","hd":{"ts_event":"2026-04-07T02:07:36.520110711Z","rtype":160,"publisher_id":101,"instrument_id":436},"action":"A","side":"B","price":"1.156380000","size":30,"channel_id":23,"order_id":"10998899693374892527","flags":0,"ts_in_delta":998,"sequence":146690,"symbol":"FCEU SI 20260615 PS"}
{"ts_recv":"2026-04-07T02:07:36.520128316Z","hd":{"ts_event":"2026-04-07T02:07:36.520110711Z","rtype":160,"publisher_id":101,"instrument_id":436},"action":"C","side":"A","price":"1.156490000","size":30,"channel_id":23,"order_id":"1775527656465527802","flags":0,"ts_in_delta":998,"sequence":146690,"symbol":"FCEU SI 20260615 PS"}
{"ts_recv":"2026-04-07T02:07:36.520128316Z","hd":{"ts_event":"2026-04-07T02:07:36.520110711Z","rtype":160,"publisher_id":101,"instrument_id":436},"action":"A","side":"A","price":"1.156480000","size":30,"channel_id":23,"order_id":"1775527656520116719","flags":128,"ts_in_delta":998,"sequence":146690,"symbol":"FCEU SI 20260615 PS"}
{"ts_recv":"2026-04-07T02:07:36.555368230Z","hd":{"ts_event":"2026-04-07T02:07:36.555353495Z","rtype":160,"publisher_id":101,"instrument_id":436},"action":"A","side":"B","price":"1.156200000","size":20,"channel_id":23,"order_id":"10998899693410135372","flags":128,"ts_in_delta":1055,"sequence":146694,"symbol":"FCEU SI 20260615 PS"}
{"ts_recv":"2026-04-07T02:07:36.561813260Z","hd":{"ts_event":"2026-04-07T02:07:36.561794483Z","rtype":160,"publisher_id":101,"instrument_id":436},"action":"C","side":"B","price":"1.156380000","size":30,"channel_id":23,"order_id":"10998899693374892527","flags":0,"ts_in_delta":1177,"sequence":146698,"symbol":"FCEU SI 20260615 PS"}
{"ts_recv":"2026-04-07T02:07:36.561813260Z","hd":{"ts_event":"2026-04-07T02:07:36.561794483Z","rtype":160,"publisher_id":101,"instrument_id":436},"action":"A","side":"B","price":"1.156370000","size":30,"channel_id":23,"order_id":"10998899693416576202","flags":0,"ts_in_delta":1177,"sequence":146698,"symbol":"FCEU SI 20260615 PS"}
{"ts_recv":"2026-04-07T02:07:36.561813260Z","hd":{"ts_event":"2026-04-07T02:07:36.561794483Z","rtype":160,"publisher_id":101,"instrument_id":436},"action":"C","side":"A","price":"1.156480000","size":30,"channel_id":23,"order_id":"1775527656520116719","flags":0,"ts_in_delta":1177,"sequence":146698,"symbol":"FCEU SI 20260615 PS"}
{"ts_recv":"2026-04-07T02:07:36.561813260Z","hd":{"ts_event":"2026-04-07T02:07:36.561794483Z","rtype":160,"publisher_id":101,"instrument_id":436},"action":"A","side":"A","price":"1.156470000","size":30,"channel_id":23,"order_id":"1775527656561800394","flags":128,"ts_in_delta":1177,"sequence":146698,"symbol":"FCEU SI 20260615 PS"}
{"ts_recv":"2026-04-07T02:07:36.572288246Z","hd":{"ts_event":"2026-04-07T02:07:36.572268857Z","rtype":160,"publisher_id":101,"instrument_id":436},"action":"C","side":"B","price":"1.156370000","size":30,"channel_id":23,"order_id":"10998899693416576202","flags":0,"ts_in_delta":1086,"sequence":146704,"symbol":"FCEU SI 20260615 PS"}
{"ts_recv":"2026-04-07T02:07:36.572288246Z","hd":{"ts_event":"2026-04-07T02:07:36.572268857Z","rtype":160,"publisher_id":101,"instrument_id":436},"action":"A","side":"B","price":"1.156360000","size":30,"channel_id":23,"order_id":"10998899693427050505","flags":0,"ts_in_delta":1086,"sequence":146704,"symbol":"FCEU SI 20260615 PS"}
{"ts_recv":"2026-04-07T02:07:36.572288246Z","hd":{"ts_event":"2026-04-07T02:07:36.572268857Z","rtype":160,"publisher_id":101,"instrument_id":436},"action":"C","side":"A","price":"1.156470000","size":30,"channel_id":23,"order_id":"1775527656561800394","flags":0,"ts_in_delta":1086,"sequence":146704,"symbol":"FCEU SI 20260615 PS"}
{"ts_recv":"2026-04-07T02:07:36.572288246Z","hd":{"ts_event":"2026-04-07T02:07:36.572268857Z","rtype":160,"publisher_id":101,"instrument_id":436},"action":"A","side":"A","price":"1.156460000","size":30,"channel_id":23,"order_id":"1775527656572274697","flags":128,"ts_in_delta":1086,"sequence":146704,"symbol":"FCEU SI 20260615 PS"}
{"ts_recv":"2026-04-07T02:07:36.572337341Z","hd":{"ts_event":"2026-04-07T02:07:36.572320345Z","rtype":160,"publisher_id":101,"instrument_id":436},"action":"C","side":"B","price":"1.156380000","size":30,"channel_id":23,"order_id":"10998899693374826145","flags":0,"ts_in_delta":972,"sequence":146705,"symbol":"FCEU SI 20260615 PS"}
{"ts_recv":"2026-04-07T02:07:36.572337341Z","hd":{"ts_event":"2026-04-07T02:07:36.572320345Z","rtype":160,"publisher_id":101,"instrument_id":436},"action":"A","side":"B","price":"1.156360000","size":30,"channel_id":23,"order_id":"10998899693427102006","flags":0,"ts_in_delta":972,"sequence":146705,"symbol":"FCEU SI 20260615 PS"}
{"ts_recv":"2026-04-07T02:07:36.572337341Z","hd":{"ts_event":"2026-04-07T02:07:36.572320345Z","rtype":160,"publisher_id":101,"instrument_id":436},"action":"C","side":"A","price":"1.156480000","size":30,"channel_id":23,"order_id":"1775527656520050337","flags":0,"ts_in_delta":972,"sequence":146705,"symbol":"FCEU SI 20260615 PS"}
{"ts_recv":"2026-04-07T02:07:36.572337341Z","hd":{"ts_event":"2026-04-07T02:07:36.572320345Z","rtype":160,"publisher_id":101,"instrument_id":436},"action":"A","side":"A","price":"1.156460000","size":30,"channel_id":23,"order_id":"1775527656572326198","flags":128,"ts_in_delta":972,"sequence":146705,"symbol":"FCEU SI 20260615 PS"}
{"ts_recv":"2026-04-07T02:07:36.572350765Z","hd":{"ts_event":"2026-04-07T02:07:36.572331257Z","rtype":160,"publisher_id":101,"instrument_id":436},"action":"C","side":"B","price":"1.156360000","size":30,"channel_id":23,"order_id":"10998899693427050505","flags":0,"ts_in_delta":954,"sequence":146706,"symbol":"FCEU SI 20260615 PS"}
{"ts_recv":"2026-04-07T02:07:36.572350765Z","hd":{"ts_event":"2026-04-07T02:07:36.572331257Z","rtype":160,"publisher_id":101,"instrument_id":436},"action":"A","side":"B","price":"1.156370000","size":30,"channel_id":23,"order_id":"10998899693427112889","flags":0,"ts_in_delta":954,"sequence":146706,"symbol":"FCEU SI 20260615 PS"}
{"ts_recv":"2026-04-07T02:07:36.572350765Z","hd":{"ts_event":"2026-04-07T02:07:36.572331257Z","rtype":160,"publisher_id":101,"instrument_id":436},"action":"C","side":"A","price":"1.156460000","size":30,"channel_id":23,"order_id":"1775527656572274697","flags":0,"ts_in_delta":954,"sequence":146706,"symbol":"FCEU SI 20260615 PS"}
{"ts_recv":"2026-04-07T02:07:36.572350765Z","hd":{"ts_event":"2026-04-07T02:07:36.572331257Z","rtype":160,"publisher_id":101,"instrument_id":436},"action":"A","side":"A","price":"1.156470000","size":30,"channel_id":23,"order_id":"1775527656572337081","flags":128,"ts_in_delta":954,"sequence":146706,"symbol":"FCEU SI 20260615 PS"}
{"ts_recv":"2026-04-07T02:07:36.572402772Z","hd":{"ts_event":"2026-04-07T02:07:36.572386893Z","rtype":160,"publisher_id":101,"instrument_id":436},"action":"C","side":"B","price":"1.156370000","size":30,"channel_id":23,"order_id":"10998899693427112889","flags":0,"ts_in_delta":1142,"sequence":146707,"symbol":"FCEU SI 20260615 PS"}
{"ts_recv":"2026-04-07T02:07:36.572402772Z","hd":{"ts_event":"2026-04-07T02:07:36.572386893Z","rtype":160,"publisher_id":101,"instrument_id":436},"action":"A","side":"B","price":"1.156360000","size":30,"channel_id":23,"order_id":"10998899693427168747","flags":0,"ts_in_delta":1142,"sequence":146707,"symbol":"FCEU SI 20260615 PS"}
{"ts_recv":"2026-04-07T02:07:36.572402772Z","hd":{"ts_event":"2026-04-07T02:07:36.572386893Z","rtype":160,"publisher_id":101,"instrument_id":436},"action":"C","side":"A","price":"1.156470000","size":30,"channel_id":23,"order_id":"1775527656572337081","flags":0,"ts_in_delta":1142,"sequence":146707,"symbol":"FCEU SI 20260615 PS"}
{"ts_recv":"2026-04-07T02:07:36.572402772Z","hd":{"ts_event":"2026-04-07T02:07:36.572386893Z","rtype":160,"publisher_id":101,"instrument_id":436},"action":"A","side":"A","price":"1.156460000","size":30,"channel_id":23,"order_id":"1775527656572392939","flags":128,"ts_in_delta":1142,"sequence":146707,"symbol":"FCEU SI 20260615 PS"}
{"ts_recv":"2026-04-07T02:07:36.927722627Z","hd":{"ts_event":"2026-04-07T02:07:36.927701057Z","rtype":160,"publisher_id":101,"instrument_id":436},"action":"C","side":"B","price":"1.156360000","size":30,"channel_id":23,"order_id":"10998899693427168747","flags":0,"ts_in_delta":1095,"sequence":146757,"symbol":"FCEU SI 20260615 PS"}
{"ts_recv":"2026-04-07T02:07:36.927722627Z","hd":{"ts_event":"2026-04-07T02:07:36.927701057Z","rtype":160,"publisher_id":101,"instrument_id":436},"action":"A","side":"B","price":"1.156350000","size":30,"channel_id":23,"order_id":"10998899693782483090","flags":0,"ts_in_delta":1095,"sequence":146757,"symbol":"FCEU SI 20260615 PS"}
{"ts_recv":"2026-04-07T02:07:36.927722627Z","hd":{"ts_event":"2026-04-07T02:07:36.927701057Z","rtype":160,"publisher_id":101,"instrument_id":436},"action":"C","side":"A","price":"1.156460000","size":30,"channel_id":23,"order_id":"1775527656572392939","flags":0,"ts_in_delta":1095,"sequence":146757,"symbol":"FCEU SI 20260615 PS"}
{"ts_recv":"2026-04-07T02:07:36.927722627Z","hd":{"ts_event":"2026-04-07T02:07:36.927701057Z","rtype":160,"publisher_id":101,"instrument_id":436},"action":"A","side":"A","price":"1.156450000","size":30,"channel_id":23,"order_id":"1775527656927707282","flags":128,"ts_in_delta":1095,"sequence":146757,"symbol":"FCEU SI 20260615 PS"}
{"ts_recv":"2026-04-07T02:07:36.932107643Z","hd":{"ts_event":"2026-04-07T02:07:36.932089821Z","rtype":160,"publisher_id":101,"instrument_id":436},"action":"C","side":"B","price":"1.156350000","size":30,"channel_id":23,"order_id":"10998899693782483090","flags":0,"ts_in_delta":1156,"sequence":146759,"symbol":"FCEU SI 20260615 PS"}
{"ts_recv":"2026-04-07T02:07:36.932107643Z","hd":{"ts_event":"2026-04-07T02:07:36.932089821Z","rtype":160,"publisher_id":101,"instrument_id":436},"action":"A","side":"B","price":"1.156340000","size":30,"channel_id":23,"order_id":"10998899693786871507","flags":0,"ts_in_delta":1156,"sequence":146759,"symbol":"FCEU SI 20260615 PS"}
{"ts_recv":"2026-04-07T02:07:36.932107643Z","hd":{"ts_event":"2026-04-07T02:07:36.932089821Z","rtype":160,"publisher_id":101,"instrument_id":436},"action":"C","side":"A","price":"1.156450000","size":30,"channel_id":23,"order_id":"1775527656927707282","flags":0,"ts_in_delta":1156,"sequence":146759,"symbol":"FCEU SI 20260615 PS"}
{"ts_recv":"2026-04-07T02:07:36.932107643Z","hd":{"ts_event":"2026-04-07T02:07:36.932089821Z","rtype":160,"publisher_id":101,"instrument_id":436},"action":"A","side":"A","price":"1.156440000","size":30,"channel_id":23,"order_id":"1775527656932095699","flags":128,"ts_in_delta":1156,"sequence":146759,"symbol":"FCEU SI 20260615 PS"}
{"ts_recv":"2026-04-07T02:07:36.932159281Z","hd":{"ts_event":"2026-04-07T02:07:36.932140963Z","rtype":160,"publisher_id":101,"instrument_id":436},"action":"C","side":"B","price":"1.156360000","size":30,"channel_id":23,"order_id":"10998899693427102006","flags":0,"ts_in_delta":973,"sequence":146760,"symbol":"FCEU SI 20260615 PS"}
{"ts_recv":"2026-04-07T02:07:36.932159281Z","hd":{"ts_event":"2026-04-07T02:07:36.932140963Z","rtype":160,"publisher_id":101,"instrument_id":436},"action":"A","side":"B","price":"1.156340000","size":30,"channel_id":23,"order_id":"10998899693786922636","flags":0,"ts_in_delta":973,"sequence":146760,"symbol":"FCEU SI 20260615 PS"}
{"ts_recv":"2026-04-07T02:07:36.932159281Z","hd":{"ts_event":"2026-04-07T02:07:36.932140963Z","rtype":160,"publisher_id":101,"instrument_id":436},"action":"C","side":"A","price":"1.156460000","size":30,"channel_id":23,"order_id":"1775527656572326198","flags":0,"ts_in_delta":973,"sequence":146760,"symbol":"FCEU SI 20260615 PS"}
{"ts_recv":"2026-04-07T02:07:36.932159281Z","hd":{"ts_event":"2026-04-07T02:07:36.932140963Z","rtype":160,"publisher_id":101,"instrument_id":436},"action":"A","side":"A","price":"1.156440000","size":30,"channel_id":23,"order_id":"1775527656932146828","flags":128,"ts_in_delta":973,"sequence":146760,"symbol":"FCEU SI 20260615 PS"}
{"ts_recv":"2026-04-07T02:07:36.932185876Z","hd":{"ts_event":"2026-04-07T02:07:36.932165653Z","rtype":160,"publisher_id":101,"instrument_id":436},"action":"C","side":"B","price":"1.156340000","size":30,"channel_id":23,"order_id":"10998899693786871507","flags":0,"ts_in_delta":982,"sequence":146761,"symbol":"FCEU SI 20260615 PS"}
{"ts_recv":"2026-04-07T02:07:36.932185876Z","hd":{"ts_event":"2026-04-07T02:07:36.932165653Z","rtype":160,"publisher_id":101,"instrument_id":436},"action":"A","side":"B","price":"1.156350000","size":30,"channel_id":23,"order_id":"10998899693786947837","flags":0,"ts_in_delta":982,"sequence":146761,"symbol":"FCEU SI 20260615 PS"}
{"ts_recv":"2026-04-07T02:07:36.932185876Z","hd":{"ts_event":"2026-04-07T02:07:36.932165653Z","rtype":160,"publisher_id":101,"instrument_id":436},"action":"C","side":"A","price":"1.156440000","size":30,"channel_id":23,"order_id":"1775527656932095699","flags":0,"ts_in_delta":982,"sequence":146761,"symbol":"FCEU SI 20260615 PS"}
{"ts_recv":"2026-04-07T02:07:36.932185876Z","hd":{"ts_event":"2026-04-07T02:07:36.932165653Z","rtype":160,"publisher_id":101,"instrument_id":436},"action":"A","side":"A","price":"1.156450000","size":30,"channel_id":23,"order_id":"1775527656932172029","flags":128,"ts_in_delta":982,"sequence":146761,"symbol":"FCEU SI 20260615 PS"}
{"ts_recv":"2026-04-07T02:07:36.932240094Z","hd":{"ts_event":"2026-04-07T02:07:36.932223381Z","rtype":160,"publisher_id":101,"instrument_id":436},"action":"C","side":"B","price":"1.156350000","size":30,"channel_id":23,"order_id":"10998899693786947837","flags":0,"ts_in_delta":978,"sequence":146762,"symbol":"FCEU SI 20260615 PS"}
{"ts_recv":"2026-04-07T02:07:36.932240094Z","hd":{"ts_event":"2026-04-07T02:07:36.932223381Z","rtype":160,"publisher_id":101,"instrument_id":436},"action":"A","side":"B","price":"1.156340000","size":30,"channel_id":23,"order_id":"10998899693787004814","flags":0,"ts_in_delta":978,"sequence":146762,"symbol":"FCEU SI 20260615 PS"}
{"ts_recv":"2026-04-07T02:07:36.932240094Z","hd":{"ts_event":"2026-04-07T02:07:36.932223381Z","rtype":160,"publisher_id":101,"instrument_id":436},"action":"C","side":"A","price":"1.156450000","size":30,"channel_id":23,"order_id":"1775527656932172029","flags":0,"ts_in_delta":978,"sequence":146762,"symbol":"FCEU SI 20260615 PS"}
{"ts_recv":"2026-04-07T02:07:36.932240094Z","hd":{"ts_event":"2026-04-07T02:07:36.932223381Z","rtype":160,"publisher_id":101,"instrument_id":436},"action":"A","side":"A","price":"1.156440000","size":30,"channel_id":23,"order_id":"1775527656932229006","flags":128,"ts_in_delta":978,"sequence":146762,"symbol":"FCEU SI 20260615 PS"}
{"ts_recv":"2026-04-07T02:07:37.022401085Z","hd":{"ts_event":"2026-04-07T02:07:37.022381741Z","rtype":160,"publisher_id":101,"instrument_id":436},"action":"C","side":"B","price":"1.156340000","size":30,"channel_id":23,"order_id":"10998899693787004814","flags":0,"ts_in_delta":1176,"sequence":146767,"symbol":"FCEU SI 20260615 PS"}
{"ts_recv":"2026-04-07T02:07:37.022401085Z","hd":{"ts_event":"2026-04-07T02:07:37.022381741Z","rtype":160,"publisher_id":101,"instrument_id":436},"action":"A","side":"B","price":"1.156330000","size":30,"channel_id":23,"order_id":"10998899693877163833","flags":0,"ts_in_delta":1176,"sequence":146767,"symbol":"FCEU SI 20260615 PS"}
{"ts_recv":"2026-04-07T02:07:37.022401085Z","hd":{"ts_event":"2026-04-07T02:07:37.022381741Z","rtype":160,"publisher_id":101,"instrument_id":436},"action":"C","side":"A","price":"1.156440000","size":30,"channel_id":23,"order_id":"1775527656932229006","flags":0,"ts_in_delta":1176,"sequence":146767,"symbol":"FCEU SI 20260615 PS"}
{"ts_recv":"2026-04-07T02:07:37.022401085Z","hd":{"ts_event":"2026-04-07T02:07:37.022381741Z","rtype":160,"publisher_id":101,"instrument_id":436},"action":"A","side":"A","price":"1.156430000","size":30,"channel_id":23,"order_id":"1775527657022388025","flags":128,"ts_in_delta":1176,"sequence":146767,"symbol":"FCEU SI 20260615 PS"}
{"ts_recv":"2026-04-07T02:07:37.027526942Z","hd":{"ts_event":"2026-04-07T02:07:37.027509217Z","rtype":160,"publisher_id":101,"instrument_id":436},"action":"C","side":"B","price":"1.156330000","size":30,"channel_id":23,"order_id":"10998899693877163833","flags":0,"ts_in_delta":1013,"sequence":146770,"symbol":"FCEU SI 20260615 PS"}
{"ts_recv":"2026-04-07T02:07:37.027526942Z","hd":{"ts_event":"2026-04-07T02:07:37.027509217Z","rtype":160,"publisher_id":101,"instrument_id":436},"action":"A","side":"B","price":"1.156310000","size":30,"channel_id":23,"order_id":"10998899693882290942","flags":0,"ts_in_delta":1013,"sequence":146770,"symbol":"FCEU SI 20260615 PS"}
{"ts_recv":"2026-04-07T02:07:37.027526942Z","hd":{"ts_event":"2026-04-07T02:07:37.027509217Z","rtype":160,"publisher_id":101,"instrument_id":436},"action":"C","side":"A","price":"1.156430000","size":30,"channel_id":23,"order_id":"1775527657022388025","flags":0,"ts_in_delta":1013,"sequence":146770,"symbol":"FCEU SI 20260615 PS"}
{"ts_recv":"2026-04-07T02:07:37.027526942Z","hd":{"ts_event":"2026-04-07T02:07:37.027509217Z","rtype":160,"publisher_id":101,"instrument_id":436},"action":"A","side":"A","price":"1.156410000","size":30,"channel_id":23,"order_id":"1775527657027515134","flags":128,"ts_in_delta":1013,"sequence":146770,"symbol":"FCEU SI 20260615 PS"}
{"ts_recv":"2026-04-07T02:07:37.027574326Z","hd":{"ts_event":"2026-04-07T02:07:37.027556103Z","rtype":160,"publisher_id":101,"instrument_id":436},"action":"C","side":"B","price":"1.156340000","size":30,"channel_id":23,"order_id":"10998899693786922636","flags":0,"ts_in_delta":1119,"sequence":146771,"symbol":"FCEU SI 20260615 PS"}
{"ts_recv":"2026-04-07T02:07:37.027574326Z","hd":{"ts_event":"2026-04-07T02:07:37.027556103Z","rtype":160,"publisher_id":101,"instrument_id":436},"action":"A","side":"B","price":"1.156320000","size":30,"channel_id":23,"order_id":"10998899693882338009","flags":0,"ts_in_delta":1119,"sequence":146771,"symbol":"FCEU SI 20260615 PS"}
{"ts_recv":"2026-04-07T02:07:37.027574326Z","hd":{"ts_event":"2026-04-07T02:07:37.027556103Z","rtype":160,"publisher_id":101,"instrument_id":436},"action":"C","side":"A","price":"1.156440000","size":30,"channel_id":23,"order_id":"1775527656932146828","flags":0,"ts_in_delta":1119,"sequence":146771,"symbol":"FCEU SI 20260615 PS"}
{"ts_recv":"2026-04-07T02:07:37.027574326Z","hd":{"ts_event":"2026-04-07T02:07:37.027556103Z","rtype":160,"publisher_id":101,"instrument_id":436},"action":"A","side":"A","price":"1.156420000","size":30,"channel_id":23,"order_id":"1775527657027562201","flags":128,"ts_in_delta":1119,"sequence":146771,"symbol":"FCEU SI 20260615 PS"}
{"ts_recv":"2026-04-07T02:07:37.027583756Z","hd":{"ts_event":"2026-04-07T02:07:37.027566675Z","rtype":160,"publisher_id":101,"instrument_id":436},"action":"C","side":"B","price":"1.156310000","size":30,"channel_id":23,"order_id":"10998899693882290942","flags":0,"ts_in_delta":986,"sequence":146772,"symbol":"FCEU SI 20260615 PS"}
{"ts_recv":"2026-04-07T02:07:37.027583756Z","hd":{"ts_event":"2026-04-07T02:07:37.027566675Z","rtype":160,"publisher_id":101,"instrument_id":436},"action":"A","side":"B","price":"1.156320000","size":30,"channel_id":23,"order_id":"10998899693882348303","flags":0,"ts_in_delta":986,"sequence":146772,"symbol":"FCEU SI 20260615 PS"}
{"ts_recv":"2026-04-07T02:07:37.027583756Z","hd":{"ts_event":"2026-04-07T02:07:37.027566675Z","rtype":160,"publisher_id":101,"instrument_id":436},"action":"C","side":"A","price":"1.156410000","size":30,"channel_id":23,"order_id":"1775527657027515134","flags":0,"ts_in_delta":986,"sequence":146772,"symbol":"FCEU SI 20260615 PS"}
{"ts_recv":"2026-04-07T02:07:37.027583756Z","hd":{"ts_event":"2026-04-07T02:07:37.027566675Z","rtype":160,"publisher_id":101,"instrument_id":436},"action":"A","side":"A","price":"1.156420000","size":30,"channel_id":23,"order_id":"1775527657027572495","flags":128,"ts_in_delta":986,"sequence":146772,"symbol":"FCEU SI 20260615 PS"}
{"ts_recv":"2026-04-07T02:07:37.027638720Z","hd":{"ts_event":"2026-04-07T02:07:37.027620071Z","rtype":160,"publisher_id":101,"instrument_id":436},"action":"C","side":"B","price":"1.156320000","size":30,"channel_id":23,"order_id":"10998899693882348303","flags":0,"ts_in_delta":970,"sequence":146774,"symbol":"FCEU SI 20260615 PS"}
{"ts_recv":"2026-04-07T02:07:37.027638720Z","hd":{"ts_event":"2026-04-07T02:07:37.027620071Z","rtype":160,"publisher_id":101,"instrument_id":436},"action":"A","side":"B","price":"1.156310000","size":30,"channel_id":23,"order_id":"10998899693882402814","flags":0,"ts_in_delta":970,"sequence":146774,"symbol":"FCEU SI 20260615 PS"}
{"ts_recv":"2026-04-07T02:07:37.027638720Z","hd":{"ts_event":"2026-04-07T02:07:37.027620071Z","rtype":160,"publisher_id":101,"instrument_id":436},"action":"C","side":"A","price":"1.156420000","size":30,"channel_id":23,"order_id":"1775527657027572495","flags":0,"ts_in_delta":970,"sequence":146774,"symbol":"FCEU SI 20260615 PS"}
{"ts_recv":"2026-04-07T02:07:37.027638720Z","hd":{"ts_event":"2026-04-07T02:07:37.027620071Z","rtype":160,"publisher_id":101,"instrument_id":436},"action":"A","side":"A","price":"1.156410000","size":30,"channel_id":23,"order_id":"1775527657027627006","flags":128,"ts_in_delta":970,"sequence":146774,"symbol":"FCEU SI 20260615 PS"}
{"ts_recv":"2026-04-07T02:07:37.032947191Z","hd":{"ts_event":"2026-04-07T02:07:37.032932347Z","rtype":160,"publisher_id":101,"instrument_id":436},"action":"C","side":"B","price":"1.156310000","size":30,"channel_id":23,"order_id":"10998899693882402814","flags":0,"ts_in_delta":852,"sequence":146776,"symbol":"FCEU SI 20260615 PS"}
{"ts_recv":"2026-04-07T02:07:37.032947191Z","hd":{"ts_event":"2026-04-07T02:07:37.032932347Z","rtype":160,"publisher_id":101,"instrument_id":436},"action":"C","side":"A","price":"1.156410000","size":30,"channel_id":23,"order_id":"1775527657027627006","flags":128,"ts_in_delta":852,"sequence":146776,"symbol":"FCEU SI 20260615 PS"}
{"ts_recv":"2026-04-07T02:07:37.046788710Z","hd":{"ts_event":"2026-04-07T02:07:37.046769179Z","rtype":160,"publisher_id":101,"instrument_id":436},"action":"C","side":"B","price":"1.156320000","size":30,"channel_id":23,"order_id":"10998899693882338009","flags":0,"ts_in_delta":801,"sequence":146785,"symbol":"FCEU SI 20260615 PS"}
{"ts_recv":"2026-04-07T02:07:37.046788710Z","hd":{"ts_event":"2026-04-07T02:07:37.046769179Z","rtype":160,"publisher_id":101,"instrument_id":436},"action":"A","side":"B","price":"1.156300000","size":30,"channel_id":23,"order_id":"10998899693901551203","flags":0,"ts_in_delta":801,"sequence":146785,"symbol":"FCEU SI 20260615 PS"}
{"ts_recv":"2026-04-07T02:07:37.046788710Z","hd":{"ts_event":"2026-04-07T02:07:37.046769179Z","rtype":160,"publisher_id":101,"instrument_id":436},"action":"C","side":"A","price":"1.156420000","size":30,"channel_id":23,"order_id":"1775527657027562201","flags":0,"ts_in_delta":801,"sequence":146785,"symbol":"FCEU SI 20260615 PS"}
{"ts_recv":"2026-04-07T02:07:37.046788710Z","hd":{"ts_event":"2026-04-07T02:07:37.046769179Z","rtype":160,"publisher_id":101,"instrument_id":436},"action":"A","side":"A","price":"1.156400000","size":30,"channel_id":23,"order_id":"1775527657046775395","flags":128,"ts_in_delta":801,"sequence":146785,"symbol":"FCEU SI 20260615 PS"}
{"ts_recv":"2026-04-07T02:07:37.069948053Z","hd":{"ts_event":"2026-04-07T02:07:37.069934483Z","rtype":160,"publisher_id":101,"instrument_id":436},"action":"A","side":"A","price":"1.156600000","size":20,"channel_id":23,"order_id":"1775527657069940684","flags":128,"ts_in_delta":660,"sequence":146797,"symbol":"FCEU SI 20260615 PS"}
{"ts_recv":"2026-04-07T02:07:37.070185085Z","hd":{"ts_event":"2026-04-07T02:07:37.070174249Z","rtype":160,"publisher_id":101,"instrument_id":436},"action":"C","side":"A","price":"1.156700000","size":20,"channel_id":23,"order_id":"1775527647411298233","flags":128,"ts_in_delta":719,"sequence":146798,"symbol":"FCEU SI 20260615 PS"}
{"ts_recv":"2026-04-07T02:07:37.211842290Z","hd":{"ts_event":"2026-04-07T02:07:37.211821743Z","rtype":160,"publisher_id":101,"instrument_id":436},"action":"C","side":"B","price":"1.156300000","size":30,"channel_id":23,"order_id":"10998899693901551203","flags":0,"ts_in_delta":894,"sequence":146836,"symbol":"FCEU SI 20260615 PS"}
{"ts_recv":"2026-04-07T02:07:37.211842290Z","hd":{"ts_event":"2026-04-07T02:07:37.211821743Z","rtype":160,"publisher_id":101,"instrument_id":436},"action":"A","side":"B","price":"1.156270000","size":30,"channel_id":23,"order_id":"10998899694066603459","flags":0,"ts_in_delta":894,"sequence":146836,"symbol":"FCEU SI 20260615 PS"}
{"ts_recv":"2026-04-07T02:07:37.211842290Z","hd":{"ts_event":"2026-04-07T02:07:37.211821743Z","rtype":160,"publisher_id":101,"instrument_id":436},"action":"C","side":"A","price":"1.156400000","size":30,"channel_id":23,"order_id":"1775527657046775395","flags":0,"ts_in_delta":894,"sequence":146836,"symbol":"FCEU SI 20260615 PS"}
{"ts_recv":"2026-04-07T02:07:37.211842290Z","hd":{"ts_event":"2026-04-07T02:07:37.211821743Z","rtype":160,"publisher_id":101,"instrument_id":436},"action":"A","side":"A","price":"1.156370000","size":30,"channel_id":23,"order_id":"1775527657211827651","flags":128,"ts_in_delta":894,"sequence":146836,"symbol":"FCEU SI 20260615 PS"}
{"ts_recv":"2026-04-07T02:07:37.333815385Z","hd":{"ts_event":"2026-04-07T02:07:37.333793745Z","rtype":160,"publisher_id":101,"instrument_id":436},"action":"C","side":"B","price":"1.156270000","size":30,"channel_id":23,"order_id":"10998899694066603459","flags":0,"ts_in_delta":1197,"sequence":146861,"symbol":"FCEU SI 20260615 PS"}
{"ts_recv":"2026-04-07T02:07:37.333815385Z","hd":{"ts_event":"2026-04-07T02:07:37.333793745Z","rtype":160,"publisher_id":101,"instrument_id":436},"action":"A","side":"B","price":"1.156250000","size":30,"channel_id":23,"order_id":"10998899694188575642","flags":0,"ts_in_delta":1197,"sequence":146861,"symbol":"FCEU SI 20260615 PS"}
{"ts_recv":"2026-04-07T02:07:37.333815385Z","hd":{"ts_event":"2026-04-07T02:07:37.333793745Z","rtype":160,"publisher_id":101,"instrument_id":436},"action":"C","side":"A","price":"1.156370000","size":30,"channel_id":23,"order_id":"1775527657211827651","flags":0,"ts_in_delta":1197,"sequence":146861,"symbol":"FCEU SI 20260615 PS"}
{"ts_recv":"2026-04-07T02:07:37.333815385Z","hd":{"ts_event":"2026-04-07T02:07:37.333793745Z","rtype":160,"publisher_id":101,"instrument_id":436},"action":"A","side":"A","price":"1.156350000","size":30,"channel_id":23,"order_id":"1775527657333799834","flags":128,"ts_in_delta":1197,"sequence":146861,"symbol":"FCEU SI 20260615 PS"}
{"ts_recv":"2026-04-07T02:07:37.391451353Z","hd":{"ts_event":"2026-04-07T02:07:37.391438195Z","rtype":160,"publisher_id":101,"instrument_id":436},"action":"A","side":"A","price":"1.156500000","size":20,"channel_id":23,"order_id":"1775527657391444082","flags":128,"ts_in_delta":834,"sequence":146869,"symbol":"FCEU SI 20260615 PS"}
{"ts_recv":"2026-04-07T02:07:37.391779857Z","hd":{"ts_event":"2026-04-07T02:07:37.391766763Z","rtype":160,"publisher_id":101,"instrument_id":436},"action":"C","side":"A","price":"1.156600000","size":20,"channel_id":23,"order_id":"1775527657069940684","flags":128,"ts_in_delta":955,"sequence":146870,"symbol":"FCEU SI 20260615 PS"}
{"ts_recv":"2026-04-07T02:07:38.033677846Z","hd":{"ts_event":"2026-04-07T02:07:38.033651147Z","rtype":160,"publisher_id":101,"instrument_id":436},"action":"A","side":"B","price":"1.156240000","size":30,"channel_id":23,"order_id":"10998899694888438291","flags":0,"ts_in_delta":1146,"sequence":146893,"symbol":"FCEU SI 20260615 PS"}
{"ts_recv":"2026-04-07T02:07:38.033677846Z","hd":{"ts_event":"2026-04-07T02:07:38.033651147Z","rtype":160,"publisher_id":101,"instrument_id":436},"action":"A","side":"A","price":"1.156340000","size":30,"channel_id":23,"order_id":"1775527658033662483","flags":128,"ts_in_delta":1146,"sequence":146893,"symbol":"FCEU SI 20260615 PS"}
{"ts_recv":"2026-04-07T02:07:38.496104423Z","hd":{"ts_event":"2026-04-07T02:07:38.496084247Z","rtype":160,"publisher_id":101,"instrument_id":436},"action":"C","side":"B","price":"1.156240000","size":30,"channel_id":23,"order_id":"10998899694888438291","flags":0,"ts_in_delta":1295,"sequence":146909,"symbol":"FCEU SI 20260615 PS"}
{"ts_recv":"2026-04-07T02:07:38.496104423Z","hd":{"ts_event":"2026-04-07T02:07:38.496084247Z","rtype":160,"publisher_id":101,"instrument_id":436},"action":"A","side":"B","price":"1.156230000","size":30,"channel_id":23,"order_id":"10998899695350865881","flags":0,"ts_in_delta":1295,"sequence":146909,"symbol":"FCEU SI 20260615 PS"}
{"ts_recv":"2026-04-07T02:07:38.496104423Z","hd":{"ts_event":"2026-04-07T02:07:38.496084247Z","rtype":160,"publisher_id":101,"instrument_id":436},"action":"C","side":"A","price":"1.156340000","size":30,"channel_id":23,"order_id":"1775527658033662483","flags":0,"ts_in_delta":1295,"sequence":146909,"symbol":"FCEU SI 20260615 PS"}
{"ts_recv":"2026-04-07T02:07:38.496104423Z","hd":{"ts_event":"2026-04-07T02:07:38.496084247Z","rtype":160,"publisher_id":101,"instrument_id":436},"action":"A","side":"A","price":"1.156330000","size":30,"channel_id":23,"order_id":"1775527658496090073","flags":128,"ts_in_delta":1295,"sequence":146909,"symbol":"FCEU SI 20260615 PS"}
{"ts_recv":"2026-04-07T02:07:38.496160776Z","hd":{"ts_event":"2026-04-07T02:07:38.496138429Z","rtype":160,"publisher_id":101,"instrument_id":436},"action":"C","side":"B","price":"1.156250000","size":30,"channel_id":23,"order_id":"10998899694188575642","flags":0,"ts_in_delta":1730,"sequence":146911,"symbol":"FCEU SI 20260615 PS"}
{"ts_recv":"2026-04-07T02:07:38.496160776Z","hd":{"ts_event":"2026-04-07T02:07:38.496138429Z","rtype":160,"publisher_id":101,"instrument_id":436},"action":"A","side":"B","price":"1.156230000","size":30,"channel_id":23,"order_id":"10998899695350924061","flags":0,"ts_in_delta":1730,"sequence":146911,"symbol":"FCEU SI 20260615 PS"}
{"ts_recv":"2026-04-07T02:07:38.496160776Z","hd":{"ts_event":"2026-04-07T02:07:38.496138429Z","rtype":160,"publisher_id":101,"instrument_id":436},"action":"C","side":"A","price":"1.156350000","size":30,"channel_id":23,"order_id":"1775527657333799834","flags":0,"ts_in_delta":1730,"sequence":146911,"symbol":"FCEU SI 20260615 PS"}
{"ts_recv":"2026-04-07T02:07:38.496160776Z","hd":{"ts_event":"2026-04-07T02:07:38.496138429Z","rtype":160,"publisher_id":101,"instrument_id":436},"action":"A","side":"A","price":"1.156330000","size":30,"channel_id":23,"order_id":"1775527658496148253","flags":128,"ts_in_delta":1730,"sequence":146911,"symbol":"FCEU SI 20260615 PS"}
{"ts_recv":"2026-04-07T02:07:38.496227543Z","hd":{"ts_event":"2026-04-07T02:07:38.496208663Z","rtype":160,"publisher_id":101,"instrument_id":436},"action":"C","side":"B","price":"1.156230000","size":30,"channel_id":23,"order_id":"10998899695350865881","flags":0,"ts_in_delta":1029,"sequence":146912,"symbol":"FCEU SI 20260615 PS"}
{"ts_recv":"2026-04-07T02:07:38.496227543Z","hd":{"ts_event":"2026-04-07T02:07:38.496208663Z","rtype":160,"publisher_id":101,"instrument_id":436},"action":"A","side":"B","price":"1.156220000","size":30,"channel_id":23,"order_id":"10998899695350990199","flags":0,"ts_in_delta":1029,"sequence":146912,"symbol":"FCEU SI 20260615 PS"}
{"ts_recv":"2026-04-07T02:07:38.496227543Z","hd":{"ts_event":"2026-04-07T02:07:38.496208663Z","rtype":160,"publisher_id":101,"instrument_id":436},"action":"C","side":"A","price":"1.156330000","size":30,"channel_id":23,"order_id":"1775527658496090073","flags":0,"ts_in_delta":1029,"sequence":146912,"symbol":"FCEU SI 20260615 PS"}
{"ts_recv":"2026-04-07T02:07:38.496227543Z","hd":{"ts_event":"2026-04-07T02:07:38.496208663Z","rtype":160,"publisher_id":101,"instrument_id":436},"action":"A","side":"A","price":"1.156320000","size":30,"channel_id":23,"order_id":"1775527658496214391","flags":128,"ts_in_delta":1029,"sequence":146912,"symbol":"FCEU SI 20260615 PS"}
{"ts_recv":"2026-04-07T02:07:38.505997491Z","hd":{"ts_event":"2026-04-07T02:07:38.505978513Z","rtype":160,"publisher_id":101,"instrument_id":436},"action":"C","side":"B","price":"1.156220000","size":30,"channel_id":23,"order_id":"10998899695350990199","flags":0,"ts_in_delta":892,"sequence":146917,"symbol":"FCEU SI 20260615 PS"}
{"ts_recv":"2026-04-07T02:07:38.505997491Z","hd":{"ts_event":"2026-04-07T02:07:38.505978513Z","rtype":160,"publisher_id":101,"instrument_id":436},"action":"A","side":"B","price":"1.156200000","size":30,"channel_id":23,"order_id":"10998899695360760269","flags":0,"ts_in_delta":892,"sequence":146917,"symbol":"FCEU SI 20260615 PS"}
{"ts_recv":"2026-04-07T02:07:38.505997491Z","hd":{"ts_event":"2026-04-07T02:07:38.505978513Z","rtype":160,"publisher_id":101,"instrument_id":436},"action":"C","side":"A","price":"1.156320000","size":30,"channel_id":23,"order_id":"1775527658496214391","flags":0,"ts_in_delta":892,"sequence":146917,"symbol":"FCEU SI 20260615 PS"}
{"ts_recv":"2026-04-07T02:07:38.505997491Z","hd":{"ts_event":"2026-04-07T02:07:38.505978513Z","rtype":160,"publisher_id":101,"instrument_id":436},"action":"A","side":"A","price":"1.156300000","size":30,"channel_id":23,"order_id":"1775527658505984461","flags":128,"ts_in_delta":892,"sequence":146917,"symbol":"FCEU SI 20260615 PS"}
{"ts_recv":"2026-04-07T02:07:38.506044851Z","hd":{"ts_event":"2026-04-07T02:07:38.506027009Z","rtype":160,"publisher_id":101,"instrument_id":436},"action":"C","side":"B","price":"1.156230000","size":30,"channel_id":23,"order_id":"10998899695350924061","flags":0,"ts_in_delta":862,"sequence":146918,"symbol":"FCEU SI 20260615 PS"}
{"ts_recv":"2026-04-07T02:07:38.506044851Z","hd":{"ts_event":"2026-04-07T02:07:38.506027009Z","rtype":160,"publisher_id":101,"instrument_id":436},"action":"A","side":"B","price":"1.156210000","size":30,"channel_id":23,"order_id":"10998899695360808495","flags":0,"ts_in_delta":862,"sequence":146918,"symbol":"FCEU SI 20260615 PS"}
{"ts_recv":"2026-04-07T02:07:38.506044851Z","hd":{"ts_event":"2026-04-07T02:07:38.506027009Z","rtype":160,"publisher_id":101,"instrument_id":436},"action":"C","side":"A","price":"1.156330000","size":30,"channel_id":23,"order_id":"1775527658496148253","flags":0,"ts_in_delta":862,"sequence":146918,"symbol":"FCEU SI 20260615 PS"}
{"ts_recv":"2026-04-07T02:07:38.506044851Z","hd":{"ts_event":"2026-04-07T02:07:38.506027009Z","rtype":160,"publisher_id":101,"instrument_id":436},"action":"A","side":"A","price":"1.156310000","size":30,"channel_id":23,"order_id":"1775527658506032687","flags":128,"ts_in_delta":862,"sequence":146918,"symbol":"FCEU SI 20260615 PS"}
{"ts_recv":"2026-04-07T02:07:38.506071023Z","hd":{"ts_event":"2026-04-07T02:07:38.506054125Z","rtype":160,"publisher_id":101,"instrument_id":436},"action":"C","side":"B","price":"1.156200000","size":30,"channel_id":23,"order_id":"10998899695360760269","flags":0,"ts_in_delta":860,"sequence":146919,"symbol":"FCEU SI 20260615 PS"}
{"ts_recv":"2026-04-07T02:07:38.506071023Z","hd":{"ts_event":"2026-04-07T02:07:38.506054125Z","rtype":160,"publisher_id":101,"instrument_id":436},"action":"A","side":"B","price":"1.156210000","size":30,"channel_id":23,"order_id":"10998899695360835763","flags":0,"ts_in_delta":860,"sequence":146919,"symbol":"FCEU SI 20260615 PS"}
{"ts_recv":"2026-04-07T02:07:38.506071023Z","hd":{"ts_event":"2026-04-07T02:07:38.506054125Z","rtype":160,"publisher_id":101,"instrument_id":436},"action":"C","side":"A","price":"1.156300000","size":30,"channel_id":23,"order_id":"1775527658505984461","flags":0,"ts_in_delta":860,"sequence":146919,"symbol":"FCEU SI 20260615 PS"}
{"ts_recv":"2026-04-07T02:07:38.506071023Z","hd":{"ts_event":"2026-04-07T02:07:38.506054125Z","rtype":160,"publisher_id":101,"instrument_id":436},"action":"A","side":"A","price":"1.156310000","size":30,"channel_id":23,"order_id":"1775527658506059955","flags":128,"ts_in_delta":860,"sequence":146919,"symbol":"FCEU SI 20260615 PS"}
{"ts_recv":"2026-04-07T02:07:38.506127661Z","hd":{"ts_event":"2026-04-07T02:07:38.506110565Z","rtype":160,"publisher_id":101,"instrument_id":436},"action":"C","side":"B","price":"1.156210000","size":30,"channel_id":23,"order_id":"10998899695360835763","flags":0,"ts_in_delta":868,"sequence":146920,"symbol":"FCEU SI 20260615 PS"}
{"ts_recv":"2026-04-07T02:07:38.506127661Z","hd":{"ts_event":"2026-04-07T02:07:38.506110565Z","rtype":160,"publisher_id":101,"instrument_id":436},"action":"A","side":"B","price":"1.156200000","size":30,"channel_id":23,"order_id":"10998899695360892246","flags":0,"ts_in_delta":868,"sequence":146920,"symbol":"FCEU SI 20260615 PS"}
{"ts_recv":"2026-04-07T02:07:38.506127661Z","hd":{"ts_event":"2026-04-07T02:07:38.506110565Z","rtype":160,"publisher_id":101,"instrument_id":436},"action":"C","side":"A","price":"1.156310000","size":30,"channel_id":23,"order_id":"1775527658506059955","flags":0,"ts_in_delta":868,"sequence":146920,"symbol":"FCEU SI 20260615 PS"}
{"ts_recv":"2026-04-07T02:07:38.506127661Z","hd":{"ts_event":"2026-04-07T02:07:38.506110565Z","rtype":160,"publisher_id":101,"instrument_id":436},"action":"A","side":"A","price":"1.156300000","size":30,"channel_id":23,"order_id":"1775527658506116438","flags":128,"ts_in_delta":868,"sequence":146920,"symbol":"FCEU SI 20260615 PS"}
{"ts_recv":"2026-04-07T02:07:38.517363991Z","hd":{"ts_event":"2026-04-07T02:07:38.517351123Z","rtype":160,"publisher_id":101,"instrument_id":436},"action":"C","side":"B","price":"1.156200000","size":20,"channel_id":23,"order_id":"10998899693410135372","flags":128,"ts_in_delta":1086,"sequence":146924,"symbol":"FCEU SI 20260615 PS"}
{"ts_recv":"2026-04-07T02:07:38.561023694Z","hd":{"ts_event":"2026-04-07T02:07:38.561009915Z","rtype":160,"publisher_id":101,"instrument_id":436},"action":"A","side":"B","price":"1.156000000","size":20,"channel_id":23,"order_id":"10998899695415791716","flags":128,"ts_in_delta":801,"sequence":146942,"symbol":"FCEU SI 20260615 PS"}
{"ts_recv":"2026-04-07T02:07:38.666087980Z","hd":{"ts_event":"2026-04-07T02:07:38.666068981Z","rtype":160,"publisher_id":101,"instrument_id":436},"action":"C","side":"B","price":"1.156200000","size":30,"channel_id":23,"order_id":"10998899695360892246","flags":0,"ts_in_delta":1035,"sequence":146962,"symbol":"FCEU SI 20260615 PS"}
{"ts_recv":"2026-04-07T02:07:38.666087980Z","hd":{"ts_event":"2026-04-07T02:07:38.666068981Z","rtype":160,"publisher_id":101,"instrument_id":436},"action":"A","side":"B","price":"1.156190000","size":30,"channel_id":23,"order_id":"10998899695520850454","flags":0,"ts_in_delta":1035,"sequence":146962,"symbol":"FCEU SI 20260615 PS"}
{"ts_recv":"2026-04-07T02:07:38.666087980Z","hd":{"ts_event":"2026-04-07T02:07:38.666068981Z","rtype":160,"publisher_id":101,"instrument_id":436},"action":"C","side":"A","price":"1.156300000","size":30,"channel_id":23,"order_id":"1775527658506116438","flags":0,"ts_in_delta":1035,"sequence":146962,"symbol":"FCEU SI 20260615 PS"}
{"ts_recv":"2026-04-07T02:07:38.666087980Z","hd":{"ts_event":"2026-04-07T02:07:38.666068981Z","rtype":160,"publisher_id":101,"instrument_id":436},"action":"A","side":"A","price":"1.156290000","size":30,"channel_id":23,"order_id":"1775527658666074646","flags":128,"ts_in_delta":1035,"sequence":146962,"symbol":"FCEU SI 20260615 PS"}
{"ts_recv":"2026-04-07T02:07:38.998125941Z","hd":{"ts_event":"2026-04-07T02:07:38.998105305Z","rtype":160,"publisher_id":101,"instrument_id":436},"action":"C","side":"B","price":"1.156210000","size":30,"channel_id":23,"order_id":"10998899695360808495","flags":0,"ts_in_delta":870,"sequence":146987,"symbol":"FCEU SI 20260615 PS"}
{"ts_recv":"2026-04-07T02:07:38.998125941Z","hd":{"ts_event":"2026-04-07T02:07:38.998105305Z","rtype":160,"publisher_id":101,"instrument_id":436},"action":"A","side":"B","price":"1.156180000","size":30,"channel_id":23,"order_id":"10998899695852887348","flags":0,"ts_in_delta":870,"sequence":146987,"symbol":"FCEU SI 20260615 PS"}
{"ts_recv":"2026-04-07T02:07:38.998125941Z","hd":{"ts_event":"2026-04-07T02:07:38.998105305Z","rtype":160,"publisher_id":101,"instrument_id":436},"action":"C","side":"A","price":"1.156310000","size":30,"channel_id":23,"order_id":"1775527658506032687","flags":0,"ts_in_delta":870,"sequence":146987,"symbol":"FCEU SI 20260615 PS"}
{"ts_recv":"2026-04-07T02:07:38.998125941Z","hd":{"ts_event":"2026-04-07T02:07:38.998105305Z","rtype":160,"publisher_id":101,"instrument_id":436},"action":"A","side":"A","price":"1.156280000","size":30,"channel_id":23,"order_id":"1775527658998111540","flags":128,"ts_in_delta":870,"sequence":146987,"symbol":"FCEU SI 20260615 PS"}
{"ts_recv":"2026-04-07T02:07:38.998182463Z","hd":{"ts_event":"2026-04-07T02:07:38.998166417Z","rtype":160,"publisher_id":101,"instrument_id":436},"action":"C","side":"B","price":"1.156190000","size":30,"channel_id":23,"order_id":"10998899695520850454","flags":0,"ts_in_delta":873,"sequence":146988,"symbol":"FCEU SI 20260615 PS"}
{"ts_recv":"2026-04-07T02:07:38.998182463Z","hd":{"ts_event":"2026-04-07T02:07:38.998166417Z","rtype":160,"publisher_id":101,"instrument_id":436},"action":"A","side":"B","price":"1.156180000","size":30,"channel_id":23,"order_id":"10998899695852948380","flags":0,"ts_in_delta":873,"sequence":146988,"symbol":"FCEU SI 20260615 PS"}
{"ts_recv":"2026-04-07T02:07:38.998182463Z","hd":{"ts_event":"2026-04-07T02:07:38.998166417Z","rtype":160,"publisher_id":101,"instrument_id":436},"action":"C","side":"A","price":"1.156290000","size":30,"channel_id":23,"order_id":"1775527658666074646","flags":0,"ts_in_delta":873,"sequence":146988,"symbol":"FCEU SI 20260615 PS"}
{"ts_recv":"2026-04-07T02:07:38.998182463Z","hd":{"ts_event":"2026-04-07T02:07:38.998166417Z","rtype":160,"publisher_id":101,"instrument_id":436},"action":"A","side":"A","price":"1.156280000","size":30,"channel_id":23,"order_id":"1775527658998172572","flags":128,"ts_in_delta":873,"sequence":146988,"symbol":"FCEU SI 20260615 PS"}
{"ts_recv":"2026-04-07T02:07:39.067450920Z","hd":{"ts_event":"2026-04-07T02:07:39.067429885Z","rtype":160,"publisher_id":101,"instrument_id":436},"action":"C","side":"B","price":"1.156180000","size":30,"channel_id":23,"order_id":"10998899695852948380","flags":0,"ts_in_delta":904,"sequence":147005,"symbol":"FCEU SI 20260615 PS"}
{"ts_recv":"2026-04-07T02:07:39.067450920Z","hd":{"ts_event":"2026-04-07T02:07:39.067429885Z","rtype":160,"publisher_id":101,"instrument_id":436},"action":"A","side":"B","price":"1.156170000","size":30,"channel_id":23,"order_id":"10998899695922211471","flags":0,"ts_in_delta":904,"sequence":147005,"symbol":"FCEU SI 20260615 PS"}
{"ts_recv":"2026-04-07T02:07:39.067450920Z","hd":{"ts_event":"2026-04-07T02:07:39.067429885Z","rtype":160,"publisher_id":101,"instrument_id":436},"action":"C","side":"A","price":"1.156280000","size":30,"channel_id":23,"order_id":"1775527658998172572","flags":0,"ts_in_delta":904,"sequence":147005,"symbol":"FCEU SI 20260615 PS"}
{"ts_recv":"2026-04-07T02:07:39.067450920Z","hd":{"ts_event":"2026-04-07T02:07:39.067429885Z","rtype":160,"publisher_id":101,"instrument_id":436},"action":"A","side":"A","price":"1.156270000","size":30,"channel_id":23,"order_id":"1775527659067435663","flags":128,"ts_in_delta":904,"sequence":147005,"symbol":"FCEU SI 20260615 PS"}
{"ts_recv":"2026-04-07T02:07:39.072086217Z","hd":{"ts_event":"2026-04-07T02:07:39.072070865Z","rtype":160,"publisher_id":101,"instrument_id":436},"action":"C","side":"B","price":"1.156170000","size":30,"channel_id":23,"order_id":"10998899695922211471","flags":0,"ts_in_delta":906,"sequence":147006,"symbol":"FCEU SI 20260615 PS"}
{"ts_recv":"2026-04-07T02:07:39.072086217Z","hd":{"ts_event":"2026-04-07T02:07:39.072070865Z","rtype":160,"publisher_id":101,"instrument_id":436},"action":"A","side":"B","price":"1.156180000","size":30,"channel_id":23,"order_id":"10998899695926852358","flags":0,"ts_in_delta":906,"sequence":147006,"symbol":"FCEU SI 20260615 PS"}
{"ts_recv":"2026-04-07T02:07:39.072086217Z","hd":{"ts_event":"2026-04-07T02:07:39.072070865Z","rtype":160,"publisher_id":101,"instrument_id":436},"action":"C","side":"A","price":"1.156270000","size":30,"channel_id":23,"order_id":"1775527659067435663","flags":0,"ts_in_delta":906,"sequence":147006,"symbol":"FCEU SI 20260615 PS"}
{"ts_recv":"2026-04-07T02:07:39.072086217Z","hd":{"ts_event":"2026-04-07T02:07:39.072070865Z","rtype":160,"publisher_id":101,"instrument_id":436},"action":"A","side":"A","price":"1.156280000","size":30,"channel_id":23,"order_id":"1775527659072076550","flags":128,"ts_in_delta":906,"sequence":147006,"symbol":"FCEU SI 20260615 PS"}
{"ts_recv":"2026-04-07T02:07:39.917651834Z","hd":{"ts_event":"2026-04-07T02:07:39.917629725Z","rtype":160,"publisher_id":101,"instrument_id":436},"action":"C","side":"B","price":"1.156180000","size":30,"channel_id":23,"order_id":"10998899695926852358","flags":0,"ts_in_delta":875,"sequence":147039,"symbol":"FCEU SI 20260615 PS"}
{"ts_recv":"2026-04-07T02:07:39.917651834Z","hd":{"ts_event":"2026-04-07T02:07:39.917629725Z","rtype":160,"publisher_id":101,"instrument_id":436},"action":"A","side":"B","price":"1.156170000","size":30,"channel_id":23,"order_id":"10998899696772411823","flags":0,"ts_in_delta":875,"sequence":147039,"symbol":"FCEU SI 20260615 PS"}
{"ts_recv":"2026-04-07T02:07:39.917651834Z","hd":{"ts_event":"2026-04-07T02:07:39.917629725Z","rtype":160,"publisher_id":101,"instrument_id":436},"action":"C","side":"A","price":"1.156280000","size":30,"channel_id":23,"order_id":"1775527659072076550","flags":0,"ts_in_delta":875,"sequence":147039,"symbol":"FCEU SI 20260615 PS"}
{"ts_recv":"2026-04-07T02:07:39.917651834Z","hd":{"ts_event":"2026-04-07T02:07:39.917629725Z","rtype":160,"publisher_id":101,"instrument_id":436},"action":"A","side":"A","price":"1.156270000","size":30,"channel_id":23,"order_id":"1775527659917636015","flags":128,"ts_in_delta":875,"sequence":147039,"symbol":"FCEU SI 20260615 PS"}
{"ts_recv":"2026-04-07T02:07:39.923107641Z","hd":{"ts_event":"2026-04-07T02:07:39.923088845Z","rtype":160,"publisher_id":101,"instrument_id":436},"action":"C","side":"B","price":"1.156180000","size":30,"channel_id":23,"order_id":"10998899695852887348","flags":0,"ts_in_delta":875,"sequence":147041,"symbol":"FCEU SI 20260615 PS"}
{"ts_recv":"2026-04-07T02:07:39.923107641Z","hd":{"ts_event":"2026-04-07T02:07:39.923088845Z","rtype":160,"publisher_id":101,"instrument_id":436},"action":"A","side":"B","price":"1.156160000","size":30,"channel_id":23,"order_id":"10998899696777870653","flags":0,"ts_in_delta":875,"sequence":147041,"symbol":"FCEU SI 20260615 PS"}
{"ts_recv":"2026-04-07T02:07:39.923107641Z","hd":{"ts_event":"2026-04-07T02:07:39.923088845Z","rtype":160,"publisher_id":101,"instrument_id":436},"action":"C","side":"A","price":"1.156280000","size":30,"channel_id":23,"order_id":"1775527658998111540","flags":0,"ts_in_delta":875,"sequence":147041,"symbol":"FCEU SI 20260615 PS"}
{"ts_recv":"2026-04-07T02:07:39.923107641Z","hd":{"ts_event":"2026-04-07T02:07:39.923088845Z","rtype":160,"publisher_id":101,"instrument_id":436},"action":"A","side":"A","price":"1.156260000","size":30,"channel_id":23,"order_id":"1775527659923094845","flags":128,"ts_in_delta":875,"sequence":147041,"symbol":"FCEU SI 20260615 PS"}
{"ts_recv":"2026-04-07T02:07:39.923164685Z","hd":{"ts_event":"2026-04-07T02:07:39.923148953Z","rtype":160,"publisher_id":101,"instrument_id":436},"action":"C","side":"B","price":"1.156170000","size":30,"channel_id":23,"order_id":"10998899696772411823","flags":0,"ts_in_delta":887,"sequence":147042,"symbol":"FCEU SI 20260615 PS"}
{"ts_recv":"2026-04-07T02:07:39.923164685Z","hd":{"ts_event":"2026-04-07T02:07:39.923148953Z","rtype":160,"publisher_id":101,"instrument_id":436},"action":"A","side":"B","price":"1.156160000","size":30,"channel_id":23,"order_id":"10998899696777930621","flags":0,"ts_in_delta":887,"sequence":147042,"symbol":"FCEU SI 20260615 PS"}
{"ts_recv":"2026-04-07T02:07:39.923164685Z","hd":{"ts_event":"2026-04-07T02:07:39.923148953Z","rtype":160,"publisher_id":101,"instrument_id":436},"action":"C","side":"A","price":"1.156270000","size":30,"channel_id":23,"order_id":"1775527659917636015","flags":0,"ts_in_delta":887,"sequence":147042,"symbol":"FCEU SI 20260615 PS"}
{"ts_recv":"2026-04-07T02:07:39.923164685Z","hd":{"ts_event":"2026-04-07T02:07:39.923148953Z","rtype":160,"publisher_id":101,"instrument_id":436},"action":"A","side":"A","price":"1.156260000","size":30,"channel_id":23,"order_id":"1775527659923154813","flags":128,"ts_in_delta":887,"sequence":147042,"symbol":"FCEU SI 20260615 PS"}
{"ts_recv":"2026-04-07T02:07:40.016414188Z","hd":{"ts_event":"2026-04-07T02:07:40.016383963Z","rtype":160,"publisher_id":101,"instrument_id":436},"action":"C","side":"B","price":"1.156160000","size":30,"channel_id":23,"order_id":"10998899696777930621","flags":0,"ts_in_delta":942,"sequence":147053,"symbol":"FCEU SI 20260615 PS"}
{"ts_recv":"2026-04-07T02:07:40.016414188Z","hd":{"ts_event":"2026-04-07T02:07:40.016383963Z","rtype":160,"publisher_id":101,"instrument_id":436},"action":"A","side":"B","price":"1.156150000","size":30,"channel_id":23,"order_id":"10998899696871171328","flags":0,"ts_in_delta":942,"sequence":147053,"symbol":"FCEU SI 20260615 PS"}
{"ts_recv":"2026-04-07T02:07:40.016414188Z","hd":{"ts_event":"2026-04-07T02:07:40.016383963Z","rtype":160,"publisher_id":101,"instrument_id":436},"action":"C","side":"A","price":"1.156260000","size":30,"channel_id":23,"order_id":"1775527659923154813","flags":0,"ts_in_delta":942,"sequence":147053,"symbol":"FCEU SI 20260615 PS"}
{"ts_recv":"2026-04-07T02:07:40.016414188Z","hd":{"ts_event":"2026-04-07T02:07:40.016383963Z","rtype":160,"publisher_id":101,"instrument_id":436},"action":"A","side":"A","price":"1.156250000","size":30,"channel_id":23,"order_id":"1775527660016395520","flags":128,"ts_in_delta":942,"sequence":147053,"symbol":"FCEU SI 20260615 PS"}
{"ts_recv":"2026-04-07T02:07:40.016499632Z","hd":{"ts_event":"2026-04-07T02:07:40.016479713Z","rtype":160,"publisher_id":101,"instrument_id":436},"action":"C","side":"B","price":"1.156150000","size":30,"channel_id":23,"order_id":"10998899696871171328","flags":0,"ts_in_delta":1172,"sequence":147054,"symbol":"FCEU SI 20260615 PS"}
{"ts_recv":"2026-04-07T02:07:40.016499632Z","hd":{"ts_event":"2026-04-07T02:07:40.016479713Z","rtype":160,"publisher_id":101,"instrument_id":436},"action":"A","side":"B","price":"1.156140000","size":30,"channel_id":23,"order_id":"10998899696871261510","flags":0,"ts_in_delta":1172,"sequence":147054,"symbol":"FCEU SI 20260615 PS"}
{"ts_recv":"2026-04-07T02:07:40.016499632Z","hd":{"ts_event":"2026-04-07T02:07:40.016479713Z","rtype":160,"publisher_id":101,"instrument_id":436},"action":"C","side":"A","price":"1.156250000","size":30,"channel_id":23,"order_id":"1775527660016395520","flags":0,"ts_in_delta":1172,"sequence":147054,"symbol":"FCEU SI 20260615 PS"}
{"ts_recv":"2026-04-07T02:07:40.016499632Z","hd":{"ts_event":"2026-04-07T02:07:40.016479713Z","rtype":160,"publisher_id":101,"instrument_id":436},"action":"A","side":"A","price":"1.156240000","size":30,"channel_id":23,"order_id":"1775527660016485702","flags":128,"ts_in_delta":1172,"sequence":147054,"symbol":"FCEU SI 20260615 PS"}
{"ts_recv":"2026-04-07T02:07:40.016555670Z","hd":{"ts_event":"2026-04-07T02:07:40.016540541Z","rtype":160,"publisher_id":101,"instrument_id":436},"action":"C","side":"B","price":"1.156140000","size":30,"channel_id":23,"order_id":"10998899696871261510","flags":0,"ts_in_delta":860,"sequence":147055,"symbol":"FCEU SI 20260615 PS"}
{"ts_recv":"2026-04-07T02:07:40.016555670Z","hd":{"ts_event":"2026-04-07T02:07:40.016540541Z","rtype":160,"publisher_id":101,"instrument_id":436},"action":"A","side":"B","price":"1.156150000","size":30,"channel_id":23,"order_id":"10998899696871322310","flags":0,"ts_in_delta":860,"sequence":147055,"symbol":"FCEU SI 20260615 PS"}
{"ts_recv":"2026-04-07T02:07:40.016555670Z","hd":{"ts_event":"2026-04-07T02:07:40.016540541Z","rtype":160,"publisher_id":101,"instrument_id":436},"action":"C","side":"A","price":"1.156240000","size":30,"channel_id":23,"order_id":"1775527660016485702","flags":0,"ts_in_delta":860,"sequence":147055,"symbol":"FCEU SI 20260615 PS"}
{"ts_recv":"2026-04-07T02:07:40.016555670Z","hd":{"ts_event":"2026-04-07T02:07:40.016540541Z","rtype":160,"publisher_id":101,"instrument_id":436},"action":"A","side":"A","price":"1.156250000","size":30,"channel_id":23,"order_id":"1775527660016546502","flags":128,"ts_in_delta":860,"sequence":147055,"symbol":"FCEU SI 20260615 PS"}
{"ts_recv":"2026-04-07T02:07:40.110563822Z","hd":{"ts_event":"2026-04-07T02:07:40.110545105Z","rtype":160,"publisher_id":101,"instrument_id":436},"action":"C","side":"B","price":"1.156160000","size":30,"channel_id":23,"order_id":"10998899696777870653","flags":0,"ts_in_delta":947,"sequence":147062,"symbol":"FCEU SI 20260615 PS"}
{"ts_recv":"2026-04-07T02:07:40.110563822Z","hd":{"ts_event":"2026-04-07T02:07:40.110545105Z","rtype":160,"publisher_id":101,"instrument_id":436},"action":"A","side":"B","price":"1.156140000","size":30,"channel_id":23,"order_id":"10998899696965327000","flags":0,"ts_in_delta":947,"sequence":147062,"symbol":"FCEU SI 20260615 PS"}
{"ts_recv":"2026-04-07T02:07:40.110563822Z","hd":{"ts_event":"2026-04-07T02:07:40.110545105Z","rtype":160,"publisher_id":101,"instrument_id":436},"action":"C","side":"A","price":"1.156260000","size":30,"channel_id":23,"order_id":"1775527659923094845","flags":0,"ts_in_delta":947,"sequence":147062,"symbol":"FCEU SI 20260615 PS"}
{"ts_recv":"2026-04-07T02:07:40.110563822Z","hd":{"ts_event":"2026-04-07T02:07:40.110545105Z","rtype":160,"publisher_id":101,"instrument_id":436},"action":"A","side":"A","price":"1.156240000","size":30,"channel_id":23,"order_id":"1775527660110551192","flags":128,"ts_in_delta":947,"sequence":147062,"symbol":"FCEU SI 20260615 PS"}
{"ts_recv":"2026-04-07T02:07:40.110634560Z","hd":{"ts_event":"2026-04-07T02:07:40.110616913Z","rtype":160,"publisher_id":101,"instrument_id":436},"action":"C","side":"B","price":"1.156150000","size":30,"channel_id":23,"order_id":"10998899696871322310","flags":0,"ts_in_delta":1100,"sequence":147063,"symbol":"FCEU SI 20260615 PS"}
{"ts_recv":"2026-04-07T02:07:40.110634560Z","hd":{"ts_event":"2026-04-07T02:07:40.110616913Z","rtype":160,"publisher_id":101,"instrument_id":436},"action":"A","side":"B","price":"1.156140000","size":30,"channel_id":23,"order_id":"10998899696965398557","flags":0,"ts_in_delta":1100,"sequence":147063,"symbol":"FCEU SI 20260615 PS"}
{"ts_recv":"2026-04-07T02:07:40.110634560Z","hd":{"ts_event":"2026-04-07T02:07:40.110616913Z","rtype":160,"publisher_id":101,"instrument_id":436},"action":"C","side":"A","price":"1.156250000","size":30,"channel_id":23,"order_id":"1775527660016546502","flags":0,"ts_in_delta":1100,"sequence":147063,"symbol":"FCEU SI 20260615 PS"}
{"ts_recv":"2026-04-07T02:07:40.110634560Z","hd":{"ts_event":"2026-04-07T02:07:40.110616913Z","rtype":160,"publisher_id":101,"instrument_id":436},"action":"A","side":"A","price":"1.156240000","size":30,"channel_id":23,"order_id":"1775527660110622749","flags":128,"ts_in_delta":1100,"sequence":147063,"symbol":"FCEU SI 20260615 PS"}
{"ts_recv":"2026-04-07T02:07:40.116678543Z","hd":{"ts_event":"2026-04-07T02:07:40.116658367Z","rtype":160,"publisher_id":101,"instrument_id":436},"action":"C","side":"B","price":"1.156140000","size":30,"channel_id":23,"order_id":"10998899696965398557","flags":0,"ts_in_delta":932,"sequence":147069,"symbol":"FCEU SI 20260615 PS"}
{"ts_recv":"2026-04-07T02:07:40.116678543Z","hd":{"ts_event":"2026-04-07T02:07:40.116658367Z","rtype":160,"publisher_id":101,"instrument_id":436},"action":"A","side":"B","price":"1.156130000","size":30,"channel_id":23,"order_id":"10998899696971440211","flags":0,"ts_in_delta":932,"sequence":147069,"symbol":"FCEU SI 20260615 PS"}
{"ts_recv":"2026-04-07T02:07:40.116678543Z","hd":{"ts_event":"2026-04-07T02:07:40.116658367Z","rtype":160,"publisher_id":101,"instrument_id":436},"action":"C","side":"A","price":"1.156240000","size":30,"channel_id":23,"order_id":"1775527660110622749","flags":0,"ts_in_delta":932,"sequence":147069,"symbol":"FCEU SI 20260615 PS"}
{"ts_recv":"2026-04-07T02:07:40.116678543Z","hd":{"ts_event":"2026-04-07T02:07:40.116658367Z","rtype":160,"publisher_id":101,"instrument_id":436},"action":"A","side":"A","price":"1.156230000","size":30,"channel_id":23,"order_id":"1775527660116664403","flags":128,"ts_in_delta":932,"sequence":147069,"symbol":"FCEU SI 20260615 PS"}
{"ts_recv":"2026-04-07T02:07:40.116727977Z","hd":{"ts_event":"2026-04-07T02:07:40.116708715Z","rtype":160,"publisher_id":101,"instrument_id":436},"action":"C","side":"B","price":"1.156140000","size":30,"channel_id":23,"order_id":"10998899696965327000","flags":0,"ts_in_delta":1075,"sequence":147070,"symbol":"FCEU SI 20260615 PS"}
{"ts_recv":"2026-04-07T02:07:40.116727977Z","hd":{"ts_event":"2026-04-07T02:07:40.116708715Z","rtype":160,"publisher_id":101,"instrument_id":436},"action":"A","side":"B","price":"1.156120000","size":30,"channel_id":23,"order_id":"10998899696971490503","flags":0,"ts_in_delta":1075,"sequence":147070,"symbol":"FCEU SI 20260615 PS"}
{"ts_recv":"2026-04-07T02:07:40.116727977Z","hd":{"ts_event":"2026-04-07T02:07:40.116708715Z","rtype":160,"publisher_id":101,"instrument_id":436},"action":"C","side":"A","price":"1.156240000","size":30,"channel_id":23,"order_id":"1775527660110551192","flags":0,"ts_in_delta":1075,"sequence":147070,"symbol":"FCEU SI 20260615 PS"}
{"ts_recv":"2026-04-07T02:07:40.116727977Z","hd":{"ts_event":"2026-04-07T02:07:40.116708715Z","rtype":160,"publisher_id":101,"instrument_id":436},"action":"A","side":"A","price":"1.156220000","size":30,"channel_id":23,"order_id":"1775527660116714695","flags":128,"ts_in_delta":1075,"sequence":147070,"symbol":"FCEU SI 20260615 PS"}
{"ts_recv":"2026-04-07T02:07:40.116738813Z","hd":{"ts_event":"2026-04-07T02:07:40.116723819Z","rtype":160,"publisher_id":101,"instrument_id":436},"action":"C","side":"B","price":"1.156130000","size":30,"channel_id":23,"order_id":"10998899696971440211","flags":0,"ts_in_delta":969,"sequence":147071,"symbol":"FCEU SI 20260615 PS"}
{"ts_recv":"2026-04-07T02:07:40.116738813Z","hd":{"ts_event":"2026-04-07T02:07:40.116723819Z","rtype":160,"publisher_id":101,"instrument_id":436},"action":"A","side":"B","price":"1.156120000","size":30,"channel_id":23,"order_id":"10998899696971505285","flags":0,"ts_in_delta":969,"sequence":147071,"symbol":"FCEU SI 20260615 PS"}
{"ts_recv":"2026-04-07T02:07:40.116738813Z","hd":{"ts_event":"2026-04-07T02:07:40.116723819Z","rtype":160,"publisher_id":101,"instrument_id":436},"action":"C","side":"A","price":"1.156230000","size":30,"channel_id":23,"order_id":"1775527660116664403","flags":0,"ts_in_delta":969,"sequence":147071,"symbol":"FCEU SI 20260615 PS"}
{"ts_recv":"2026-04-07T02:07:40.116738813Z","hd":{"ts_event":"2026-04-07T02:07:40.116723819Z","rtype":160,"publisher_id":101,"instrument_id":436},"action":"A","side":"A","price":"1.156220000","size":30,"channel_id":23,"order_id":"1775527660116729477","flags":128,"ts_in_delta":969,"sequence":147071,"symbol":"FCEU SI 20260615 PS"}
{"ts_recv":"2026-04-07T02:07:40.158126397Z","hd":{"ts_event":"2026-04-07T02:07:40.158112131Z","rtype":160,"publisher_id":101,"instrument_id":436},"action":"A","side":"A","price":"1.156400000","size":20,"channel_id":23,"order_id":"1775527660158118360","flags":128,"ts_in_delta":793,"sequence":147087,"symbol":"FCEU SI 20260615 PS"}
{"ts_recv":"2026-04-07T02:07:40.158740561Z","hd":{"ts_event":"2026-04-07T02:07:40.158727619Z","rtype":160,"publisher_id":101,"instrument_id":436},"action":"C","side":"A","price":"1.156500000","size":20,"channel_id":23,"order_id":"1775527657391444082","flags":128,"ts_in_delta":1008,"sequence":147088,"symbol":"FCEU SI 20260615 PS"}
{"ts_recv":"2026-04-07T02:07:40.162710785Z","hd":{"ts_event":"2026-04-07T02:07:40.162690321Z","rtype":160,"publisher_id":101,"instrument_id":436},"action":"C","side":"B","price":"1.156120000","size":30,"channel_id":23,"order_id":"10998899696971505285","flags":0,"ts_in_delta":753,"sequence":147099,"symbol":"FCEU SI 20260615 PS"}
{"ts_recv":"2026-04-07T02:07:40.162710785Z","hd":{"ts_event":"2026-04-07T02:07:40.162690321Z","rtype":160,"publisher_id":101,"instrument_id":436},"action":"A","side":"B","price":"1.156100000","size":30,"channel_id":23,"order_id":"10998899697017472004","flags":0,"ts_in_delta":753,"sequence":147099,"symbol":"FCEU SI 20260615 PS"}
{"ts_recv":"2026-04-07T02:07:40.162710785Z","hd":{"ts_event":"2026-04-07T02:07:40.162690321Z","rtype":160,"publisher_id":101,"instrument_id":436},"action":"C","side":"A","price":"1.156220000","size":30,"channel_id":23,"order_id":"1775527660116729477","flags":0,"ts_in_delta":753,"sequence":147099,"symbol":"FCEU SI 20260615 PS"}
{"ts_recv":"2026-04-07T02:07:40.162710785Z","hd":{"ts_event":"2026-04-07T02:07:40.162690321Z","rtype":160,"publisher_id":101,"instrument_id":436},"action":"A","side":"A","price":"1.156200000","size":30,"channel_id":23,"order_id":"1775527660162696196","flags":128,"ts_in_delta":753,"sequence":147099,"symbol":"FCEU SI 20260615 PS"}
{"ts_recv":"2026-04-07T02:07:40.162762562Z","hd":{"ts_event":"2026-04-07T02:07:40.162742815Z","rtype":160,"publisher_id":101,"instrument_id":436},"action":"C","side":"B","price":"1.156120000","size":30,"channel_id":23,"order_id":"10998899696971490503","flags":0,"ts_in_delta":750,"sequence":147100,"symbol":"FCEU SI 20260615 PS"}
{"ts_recv":"2026-04-07T02:07:40.162762562Z","hd":{"ts_event":"2026-04-07T02:07:40.162742815Z","rtype":160,"publisher_id":101,"instrument_id":436},"action":"A","side":"B","price":"1.156090000","size":30,"channel_id":23,"order_id":"10998899697017524499","flags":0,"ts_in_delta":750,"sequence":147100,"symbol":"FCEU SI 20260615 PS"}
{"ts_recv":"2026-04-07T02:07:40.162762562Z","hd":{"ts_event":"2026-04-07T02:07:40.162742815Z","rtype":160,"publisher_id":101,"instrument_id":436},"action":"C","side":"A","price":"1.156220000","size":30,"channel_id":23,"order_id":"1775527660116714695","flags":0,"ts_in_delta":750,"sequence":147100,"symbol":"FCEU SI 20260615 PS"}
{"ts_recv":"2026-04-07T02:07:40.162762562Z","hd":{"ts_event":"2026-04-07T02:07:40.162742815Z","rtype":160,"publisher_id":101,"instrument_id":436},"action":"A","side":"A","price":"1.156190000","size":30,"channel_id":23,"order_id":"1775527660162748691","flags":128,"ts_in_delta":750,"sequence":147100,"symbol":"FCEU SI 20260615 PS"}
{"ts_recv":"2026-04-07T02:07:40.162772484Z","hd":{"ts_event":"2026-04-07T02:07:40.162751781Z","rtype":160,"publisher_id":101,"instrument_id":436},"action":"C","side":"B","price":"1.156100000","size":30,"channel_id":23,"order_id":"10998899697017472004","flags":0,"ts_in_delta":748,"sequence":147101,"symbol":"FCEU SI 20260615 PS"}
{"ts_recv":"2026-04-07T02:07:40.162772484Z","hd":{"ts_event":"2026-04-07T02:07:40.162751781Z","rtype":160,"publisher_id":101,"instrument_id":436},"action":"A","side":"B","price":"1.156080000","size":30,"channel_id":23,"order_id":"10998899697017535180","flags":0,"ts_in_delta":748,"sequence":147101,"symbol":"FCEU SI 20260615 PS"}
{"ts_recv":"2026-04-07T02:07:40.162772484Z","hd":{"ts_event":"2026-04-07T02:07:40.162751781Z","rtype":160,"publisher_id":101,"instrument_id":436},"action":"C","side":"A","price":"1.156200000","size":30,"channel_id":23,"order_id":"1775527660162696196","flags":0,"ts_in_delta":748,"sequence":147101,"symbol":"FCEU SI 20260615 PS"}
{"ts_recv":"2026-04-07T02:07:40.162772484Z","hd":{"ts_event":"2026-04-07T02:07:40.162751781Z","rtype":160,"publisher_id":101,"instrument_id":436},"action":"A","side":"A","price":"1.156180000","size":30,"channel_id":23,"order_id":"1775527660162759372","flags":128,"ts_in_delta":748,"sequence":147101,"symbol":"FCEU SI 20260615 PS"}
{"ts_recv":"2026-04-07T02:07:40.789414212Z","hd":{"ts_event":"2026-04-07T02:07:40.789395037Z","rtype":160,"publisher_id":101,"instrument_id":436},"action":"C","side":"B","price":"1.156080000","size":30,"channel_id":23,"order_id":"10998899697017535180","flags":0,"ts_in_delta":982,"sequence":147165,"symbol":"FCEU SI 20260615 PS"}
{"ts_recv":"2026-04-07T02:07:40.789414212Z","hd":{"ts_event":"2026-04-07T02:07:40.789395037Z","rtype":160,"publisher_id":101,"instrument_id":436},"action":"A","side":"B","price":"1.156090000","size":30,"channel_id":23,"order_id":"10998899697644177301","flags":0,"ts_in_delta":982,"sequence":147165,"symbol":"FCEU SI 20260615 PS"}
{"ts_recv":"2026-04-07T02:07:40.789414212Z","hd":{"ts_event":"2026-04-07T02:07:40.789395037Z","rtype":160,"publisher_id":101,"instrument_id":436},"action":"C","side":"A","price":"1.156180000","size":30,"channel_id":23,"order_id":"1775527660162759372","flags":0,"ts_in_delta":982,"sequence":147165,"symbol":"FCEU SI 20260615 PS"}
{"ts_recv":"2026-04-07T02:07:40.789414212Z","hd":{"ts_event":"2026-04-07T02:07:40.789395037Z","rtype":160,"publisher_id":101,"instrument_id":436},"action":"A","side":"A","price":"1.156190000","size":30,"channel_id":23,"order_id":"1775527660789401493","flags":128,"ts_in_delta":982,"sequence":147165,"symbol":"FCEU SI 20260615 PS"}
{"ts_recv":"2026-04-07T02:07:44.381556345Z","hd":{"ts_event":"2026-04-07T02:07:44.381534363Z","rtype":160,"publisher_id":101,"instrument_id":436},"action":"C","side":"B","price":"1.156090000","size":30,"channel_id":23,"order_id":"10998899697644177301","flags":0,"ts_in_delta":1021,"sequence":147233,"symbol":"FCEU SI 20260615 PS"}
{"ts_recv":"2026-04-07T02:07:44.381556345Z","hd":{"ts_event":"2026-04-07T02:07:44.381534363Z","rtype":160,"publisher_id":101,"instrument_id":436},"action":"A","side":"B","price":"1.156100000","size":30,"channel_id":23,"order_id":"10998899701236316086","flags":0,"ts_in_delta":1021,"sequence":147233,"symbol":"FCEU SI 20260615 PS"}
{"ts_recv":"2026-04-07T02:07:44.381556345Z","hd":{"ts_event":"2026-04-07T02:07:44.381534363Z","rtype":160,"publisher_id":101,"instrument_id":436},"action":"C","side":"A","price":"1.156190000","size":30,"channel_id":23,"order_id":"1775527660789401493","flags":0,"ts_in_delta":1021,"sequence":147233,"symbol":"FCEU SI 20260615 PS"}
{"ts_recv":"2026-04-07T02:07:44.381556345Z","hd":{"ts_event":"2026-04-07T02:07:44.381534363Z","rtype":160,"publisher_id":101,"instrument_id":436},"action":"A","side":"A","price":"1.156200000","size":30,"channel_id":23,"order_id":"1775527664381540278","flags":128,"ts_in_delta":1021,"sequence":147233,"symbol":"FCEU SI 20260615 PS"}
{"ts_recv":"2026-04-07T02:07:44.381608666Z","hd":{"ts_event":"2026-04-07T02:07:44.381587087Z","rtype":160,"publisher_id":101,"instrument_id":436},"action":"C","side":"B","price":"1.156090000","size":30,"channel_id":23,"order_id":"10998899697017524499","flags":0,"ts_in_delta":946,"sequence":147234,"symbol":"FCEU SI 20260615 PS"}
{"ts_recv":"2026-04-07T02:07:44.381608666Z","hd":{"ts_event":"2026-04-07T02:07:44.381587087Z","rtype":160,"publisher_id":101,"instrument_id":436},"action":"A","side":"B","price":"1.156110000","size":30,"channel_id":23,"order_id":"10998899701236369212","flags":0,"ts_in_delta":946,"sequence":147234,"symbol":"FCEU SI 20260615 PS"}
{"ts_recv":"2026-04-07T02:07:44.381608666Z","hd":{"ts_event":"2026-04-07T02:07:44.381587087Z","rtype":160,"publisher_id":101,"instrument_id":436},"action":"C","side":"A","price":"1.156190000","size":30,"channel_id":23,"order_id":"1775527660162748691","flags":0,"ts_in_delta":946,"sequence":147234,"symbol":"FCEU SI 20260615 PS"}
{"ts_recv":"2026-04-07T02:07:44.381608666Z","hd":{"ts_event":"2026-04-07T02:07:44.381587087Z","rtype":160,"publisher_id":101,"instrument_id":436},"action":"A","side":"A","price":"1.156210000","size":30,"channel_id":23,"order_id":"1775527664381593404","flags":128,"ts_in_delta":946,"sequence":147234,"symbol":"FCEU SI 20260615 PS"}
{"ts_recv":"2026-04-07T02:07:44.381661564Z","hd":{"ts_event":"2026-04-07T02:07:44.381644079Z","rtype":160,"publisher_id":101,"instrument_id":436},"action":"C","side":"B","price":"1.156100000","size":30,"channel_id":23,"order_id":"10998899701236316086","flags":0,"ts_in_delta":973,"sequence":147235,"symbol":"FCEU SI 20260615 PS"}
{"ts_recv":"2026-04-07T02:07:44.381661564Z","hd":{"ts_event":"2026-04-07T02:07:44.381644079Z","rtype":160,"publisher_id":101,"instrument_id":436},"action":"A","side":"B","price":"1.156110000","size":30,"channel_id":23,"order_id":"10998899701236425670","flags":0,"ts_in_delta":973,"sequence":147235,"symbol":"FCEU SI 20260615 PS"}
{"ts_recv":"2026-04-07T02:07:44.381661564Z","hd":{"ts_event":"2026-04-07T02:07:44.381644079Z","rtype":160,"publisher_id":101,"instrument_id":436},"action":"C","side":"A","price":"1.156200000","size":30,"channel_id":23,"order_id":"1775527664381540278","flags":0,"ts_in_delta":973,"sequence":147235,"symbol":"FCEU SI 20260615 PS"}
{"ts_recv":"2026-04-07T02:07:44.381661564Z","hd":{"ts_event":"2026-04-07T02:07:44.381644079Z","rtype":160,"publisher_id":101,"instrument_id":436},"action":"A","side":"A","price":"1.156210000","size":30,"channel_id":23,"order_id":"1775527664381649862","flags":128,"ts_in_delta":973,"sequence":147235,"symbol":"FCEU SI 20260615 PS"}
{"ts_recv":"2026-04-07T02:07:46.363360714Z","hd":{"ts_event":"2026-04-07T02:07:46.363341049Z","rtype":160,"publisher_id":101,"instrument_id":436},"action":"C","side":"B","price":"1.156110000","size":30,"channel_id":23,"order_id":"10998899701236425670","flags":0,"ts_in_delta":980,"sequence":147313,"symbol":"FCEU SI 20260615 PS"}
{"ts_recv":"2026-04-07T02:07:46.363360714Z","hd":{"ts_event":"2026-04-07T02:07:46.363341049Z","rtype":160,"publisher_id":101,"instrument_id":436},"action":"A","side":"B","price":"1.156120000","size":30,"channel_id":23,"order_id":"10998899703218122424","flags":0,"ts_in_delta":980,"sequence":147313,"symbol":"FCEU SI 20260615 PS"}
{"ts_recv":"2026-04-07T02:07:46.363360714Z","hd":{"ts_event":"2026-04-07T02:07:46.363341049Z","rtype":160,"publisher_id":101,"instrument_id":436},"action":"C","side":"A","price":"1.156210000","size":30,"channel_id":23,"order_id":"1775527664381649862","flags":0,"ts_in_delta":980,"sequence":147313,"symbol":"FCEU SI 20260615 PS"}
{"ts_recv":"2026-04-07T02:07:46.363360714Z","hd":{"ts_event":"2026-04-07T02:07:46.363341049Z","rtype":160,"publisher_id":101,"instrument_id":436},"action":"A","side":"A","price":"1.156220000","size":30,"channel_id":23,"order_id":"1775527666363346616","flags":128,"ts_in_delta":980,"sequence":147313,"symbol":"FCEU SI 20260615 PS"}
{"ts_recv":"2026-04-07T02:07:46.365899121Z","hd":{"ts_event":"2026-04-07T02:07:46.365880063Z","rtype":160,"publisher_id":101,"instrument_id":436},"action":"C","side":"B","price":"1.156110000","size":30,"channel_id":23,"order_id":"10998899701236369212","flags":0,"ts_in_delta":1112,"sequence":147319,"symbol":"FCEU SI 20260615 PS"}
{"ts_recv":"2026-04-07T02:07:46.365899121Z","hd":{"ts_event":"2026-04-07T02:07:46.365880063Z","rtype":160,"publisher_id":101,"instrument_id":436},"action":"A","side":"B","price":"1.156130000","size":30,"channel_id":23,"order_id":"10998899703220662541","flags":0,"ts_in_delta":1112,"sequence":147319,"symbol":"FCEU SI 20260615 PS"}
{"ts_recv":"2026-04-07T02:07:46.365899121Z","hd":{"ts_event":"2026-04-07T02:07:46.365880063Z","rtype":160,"publisher_id":101,"instrument_id":436},"action":"C","side":"A","price":"1.156210000","size":30,"channel_id":23,"order_id":"1775527664381593404","flags":0,"ts_in_delta":1112,"sequence":147319,"symbol":"FCEU SI 20260615 PS"}
{"ts_recv":"2026-04-07T02:07:46.365899121Z","hd":{"ts_event":"2026-04-07T02:07:46.365880063Z","rtype":160,"publisher_id":101,"instrument_id":436},"action":"A","side":"A","price":"1.156230000","size":30,"channel_id":23,"order_id":"1775527666365886733","flags":128,"ts_in_delta":1112,"sequence":147319,"symbol":"FCEU SI 20260615 PS"}
{"ts_recv":"2026-04-07T02:07:46.365953762Z","hd":{"ts_event":"2026-04-07T02:07:46.365938911Z","rtype":160,"publisher_id":101,"instrument_id":436},"action":"C","side":"B","price":"1.156120000","size":30,"channel_id":23,"order_id":"10998899703218122424","flags":0,"ts_in_delta":946,"sequence":147320,"symbol":"FCEU SI 20260615 PS"}
{"ts_recv":"2026-04-07T02:07:46.365953762Z","hd":{"ts_event":"2026-04-07T02:07:46.365938911Z","rtype":160,"publisher_id":101,"instrument_id":436},"action":"A","side":"B","price":"1.156130000","size":30,"channel_id":23,"order_id":"10998899703220720174","flags":0,"ts_in_delta":946,"sequence":147320,"symbol":"FCEU SI 20260615 PS"}
{"ts_recv":"2026-04-07T02:07:46.365953762Z","hd":{"ts_event":"2026-04-07T02:07:46.365938911Z","rtype":160,"publisher_id":101,"instrument_id":436},"action":"C","side":"A","price":"1.156220000","size":30,"channel_id":23,"order_id":"1775527666363346616","flags":0,"ts_in_delta":946,"sequence":147320,"symbol":"FCEU SI 20260615 PS"}
{"ts_recv":"2026-04-07T02:07:46.365953762Z","hd":{"ts_event":"2026-04-07T02:07:46.365938911Z","rtype":160,"publisher_id":101,"instrument_id":436},"action":"A","side":"A","price":"1.156230000","size":30,"channel_id":23,"order_id":"1775527666365944366","flags":128,"ts_in_delta":946,"sequence":147320,"symbol":"FCEU SI 20260615 PS"}
{"ts_recv":"2026-04-07T02:07:56.829591671Z","hd":{"ts_event":"2026-04-07T02:07:56.829569527Z","rtype":160,"publisher_id":101,"instrument_id":436},"action":"C","side":"B","price":"1.156130000","size":30,"channel_id":23,"order_id":"10998899703220720174","flags":0,"ts_in_delta":895,"sequence":147480,"symbol":"FCEU SI 20260615 PS"}
{"ts_recv":"2026-04-07T02:07:56.829591671Z","hd":{"ts_event":"2026-04-07T02:07:56.829569527Z","rtype":160,"publisher_id":101,"instrument_id":436},"action":"A","side":"B","price":"1.156120000","size":30,"channel_id":23,"order_id":"10998899713684351018","flags":0,"ts_in_delta":895,"sequence":147480,"symbol":"FCEU SI 20260615 PS"}
{"ts_recv":"2026-04-07T02:07:56.829591671Z","hd":{"ts_event":"2026-04-07T02:07:56.829569527Z","rtype":160,"publisher_id":101,"instrument_id":436},"action":"C","side":"A","price":"1.156230000","size":30,"channel_id":23,"order_id":"1775527666365944366","flags":0,"ts_in_delta":895,"sequence":147480,"symbol":"FCEU SI 20260615 PS"}
{"ts_recv":"2026-04-07T02:07:56.829591671Z","hd":{"ts_event":"2026-04-07T02:07:56.829569527Z","rtype":160,"publisher_id":101,"instrument_id":436},"action":"A","side":"A","price":"1.156220000","size":30,"channel_id":23,"order_id":"1775527676829575210","flags":128,"ts_in_delta":895,"sequence":147480,"symbol":"FCEU SI 20260615 PS"}
{"ts_recv":"2026-04-07T02:07:56.829647955Z","hd":{"ts_event":"2026-04-07T02:07:56.829625765Z","rtype":160,"publisher_id":101,"instrument_id":436},"action":"C","side":"B","price":"1.156130000","size":30,"channel_id":23,"order_id":"10998899703220662541","flags":0,"ts_in_delta":940,"sequence":147481,"symbol":"FCEU SI 20260615 PS"}
{"ts_recv":"2026-04-07T02:07:56.829647955Z","hd":{"ts_event":"2026-04-07T02:07:56.829625765Z","rtype":160,"publisher_id":101,"instrument_id":436},"action":"A","side":"B","price":"1.156110000","size":30,"channel_id":23,"order_id":"10998899713684409058","flags":0,"ts_in_delta":940,"sequence":147481,"symbol":"FCEU SI 20260615 PS"}
{"ts_recv":"2026-04-07T02:07:56.829647955Z","hd":{"ts_event":"2026-04-07T02:07:56.829625765Z","rtype":160,"publisher_id":101,"instrument_id":436},"action":"C","side":"A","price":"1.156230000","size":30,"channel_id":23,"order_id":"1775527666365886733","flags":0,"ts_in_delta":940,"sequence":147481,"symbol":"FCEU SI 20260615 PS"}
{"ts_recv":"2026-04-07T02:07:56.829647955Z","hd":{"ts_event":"2026-04-07T02:07:56.829625765Z","rtype":160,"publisher_id":101,"instrument_id":436},"action":"A","side":"A","price":"1.156210000","size":30,"channel_id":23,"order_id":"1775527676829633250","flags":128,"ts_in_delta":940,"sequence":147481,"symbol":"FCEU SI 20260615 PS"}
{"ts_recv":"2026-04-07T02:07:56.829669804Z","hd":{"ts_event":"2026-04-07T02:07:56.829653477Z","rtype":160,"publisher_id":101,"instrument_id":436},"action":"C","side":"B","price":"1.156120000","size":30,"channel_id":23,"order_id":"10998899713684351018","flags":0,"ts_in_delta":945,"sequence":147482,"symbol":"FCEU SI 20260615 PS"}
{"ts_recv":"2026-04-07T02:07:56.829669804Z","hd":{"ts_event":"2026-04-07T02:07:56.829653477Z","rtype":160,"publisher_id":101,"instrument_id":436},"action":"A","side":"B","price":"1.156110000","size":30,"channel_id":23,"order_id":"10998899713684435359","flags":0,"ts_in_delta":945,"sequence":147482,"symbol":"FCEU SI 20260615 PS"}
{"ts_recv":"2026-04-07T02:07:56.829669804Z","hd":{"ts_event":"2026-04-07T02:07:56.829653477Z","rtype":160,"publisher_id":101,"instrument_id":436},"action":"C","side":"A","price":"1.156220000","size":30,"channel_id":23,"order_id":"1775527676829575210","flags":0,"ts_in_delta":945,"sequence":147482,"symbol":"FCEU SI 20260615 PS"}
{"ts_recv":"2026-04-07T02:07:56.829669804Z","hd":{"ts_event":"2026-04-07T02:07:56.829653477Z","rtype":160,"publisher_id":101,"instrument_id":436},"action":"A","side":"A","price":"1.156210000","size":30,"channel_id":23,"order_id":"1775527676829659551","flags":128,"ts_in_delta":945,"sequence":147482,"symbol":"FCEU SI 20260615 PS"}
{"ts_recv":"2026-04-07T02:07:56.833242253Z","hd":{"ts_event":"2026-04-07T02:07:56.833222167Z","rtype":160,"publisher_id":101,"instrument_id":436},"action":"C","side":"B","price":"1.156110000","size":30,"channel_id":23,"order_id":"10998899713684435359","flags":0,"ts_in_delta":941,"sequence":147486,"symbol":"FCEU SI 20260615 PS"}
{"ts_recv":"2026-04-07T02:07:56.833242253Z","hd":{"ts_event":"2026-04-07T02:07:56.833222167Z","rtype":160,"publisher_id":101,"instrument_id":436},"action":"A","side":"B","price":"1.156100000","size":30,"channel_id":23,"order_id":"10998899713688004107","flags":0,"ts_in_delta":941,"sequence":147486,"symbol":"FCEU SI 20260615 PS"}
{"ts_recv":"2026-04-07T02:07:56.833242253Z","hd":{"ts_event":"2026-04-07T02:07:56.833222167Z","rtype":160,"publisher_id":101,"instrument_id":436},"action":"C","side":"A","price":"1.156210000","size":30,"channel_id":23,"order_id":"1775527676829659551","flags":0,"ts_in_delta":941,"sequence":147486,"symbol":"FCEU SI 20260615 PS"}
{"ts_recv":"2026-04-07T02:07:56.833242253Z","hd":{"ts_event":"2026-04-07T02:07:56.833222167Z","rtype":160,"publisher_id":101,"instrument_id":436},"action":"A","side":"A","price":"1.156200000","size":30,"channel_id":23,"order_id":"1775527676833228299","flags":128,"ts_in_delta":941,"sequence":147486,"symbol":"FCEU SI 20260615 PS"}
{"ts_recv":"2026-04-07T02:07:57.063246097Z","hd":{"ts_event":"2026-04-07T02:07:57.063225763Z","rtype":160,"publisher_id":101,"instrument_id":436},"action":"C","side":"B","price":"1.156100000","size":30,"channel_id":23,"order_id":"10998899713688004107","flags":0,"ts_in_delta":1102,"sequence":147509,"symbol":"FCEU SI 20260615 PS"}
{"ts_recv":"2026-04-07T02:07:57.063246097Z","hd":{"ts_event":"2026-04-07T02:07:57.063225763Z","rtype":160,"publisher_id":101,"instrument_id":436},"action":"A","side":"B","price":"1.156090000","size":30,"channel_id":23,"order_id":"10998899713918007526","flags":0,"ts_in_delta":1102,"sequence":147509,"symbol":"FCEU SI 20260615 PS"}
{"ts_recv":"2026-04-07T02:07:57.063246097Z","hd":{"ts_event":"2026-04-07T02:07:57.063225763Z","rtype":160,"publisher_id":101,"instrument_id":436},"action":"C","side":"A","price":"1.156200000","size":30,"channel_id":23,"order_id":"1775527676833228299","flags":0,"ts_in_delta":1102,"sequence":147509,"symbol":"FCEU SI 20260615 PS"}
{"ts_recv":"2026-04-07T02:07:57.063246097Z","hd":{"ts_event":"2026-04-07T02:07:57.063225763Z","rtype":160,"publisher_id":101,"instrument_id":436},"action":"A","side":"A","price":"1.156190000","size":30,"channel_id":23,"order_id":"1775527677063231718","flags":128,"ts_in_delta":1102,"sequence":147509,"symbol":"FCEU SI 20260615 PS"}
{"ts_recv":"2026-04-07T02:07:57.063301260Z","hd":{"ts_event":"2026-04-07T02:07:57.063281177Z","rtype":160,"publisher_id":101,"instrument_id":436},"action":"C","side":"B","price":"1.156110000","size":30,"channel_id":23,"order_id":"10998899713684409058","flags":0,"ts_in_delta":1156,"sequence":147510,"symbol":"FCEU SI 20260615 PS"}
{"ts_recv":"2026-04-07T02:07:57.063301260Z","hd":{"ts_event":"2026-04-07T02:07:57.063281177Z","rtype":160,"publisher_id":101,"instrument_id":436},"action":"A","side":"B","price":"1.156090000","size":30,"channel_id":23,"order_id":"10998899713918063000","flags":0,"ts_in_delta":1156,"sequence":147510,"symbol":"FCEU SI 20260615 PS"}
{"ts_recv":"2026-04-07T02:07:57.063301260Z","hd":{"ts_event":"2026-04-07T02:07:57.063281177Z","rtype":160,"publisher_id":101,"instrument_id":436},"action":"C","side":"A","price":"1.156210000","size":30,"channel_id":23,"order_id":"1775527676829633250","flags":0,"ts_in_delta":1156,"sequence":147510,"symbol":"FCEU SI 20260615 PS"}
{"ts_recv":"2026-04-07T02:07:57.063301260Z","hd":{"ts_event":"2026-04-07T02:07:57.063281177Z","rtype":160,"publisher_id":101,"instrument_id":436},"action":"A","side":"A","price":"1.156190000","size":30,"channel_id":23,"order_id":"1775527677063287192","flags":128,"ts_in_delta":1156,"sequence":147510,"symbol":"FCEU SI 20260615 PS"}
{"ts_recv":"2026-04-07T02:07:57.063317004Z","hd":{"ts_event":"2026-04-07T02:07:57.063295909Z","rtype":160,"publisher_id":101,"instrument_id":436},"action":"C","side":"B","price":"1.156090000","size":30,"channel_id":23,"order_id":"10998899713918007526","flags":0,"ts_in_delta":854,"sequence":147511,"symbol":"FCEU SI 20260615 PS"}
{"ts_recv":"2026-04-07T02:07:57.063317004Z","hd":{"ts_event":"2026-04-07T02:07:57.063295909Z","rtype":160,"publisher_id":101,"instrument_id":436},"action":"A","side":"B","price":"1.156100000","size":30,"channel_id":23,"order_id":"10998899713918077696","flags":0,"ts_in_delta":854,"sequence":147511,"symbol":"FCEU SI 20260615 PS"}
{"ts_recv":"2026-04-07T02:07:57.063317004Z","hd":{"ts_event":"2026-04-07T02:07:57.063295909Z","rtype":160,"publisher_id":101,"instrument_id":436},"action":"C","side":"A","price":"1.156190000","size":30,"channel_id":23,"order_id":"1775527677063231718","flags":0,"ts_in_delta":854,"sequence":147511,"symbol":"FCEU SI 20260615 PS"}
{"ts_recv":"2026-04-07T02:07:57.063317004Z","hd":{"ts_event":"2026-04-07T02:07:57.063295909Z","rtype":160,"publisher_id":101,"instrument_id":436},"action":"A","side":"A","price":"1.156200000","size":30,"channel_id":23,"order_id":"1775527677063301888","flags":128,"ts_in_delta":854,"sequence":147511,"symbol":"FCEU SI 20260615 PS"}
{"ts_recv":"2026-04-07T02:07:57.063374954Z","hd":{"ts_event":"2026-04-07T02:07:57.063357191Z","rtype":160,"publisher_id":101,"instrument_id":436},"action":"C","side":"B","price":"1.156100000","size":30,"channel_id":23,"order_id":"10998899713918077696","flags":0,"ts_in_delta":930,"sequence":147512,"symbol":"FCEU SI 20260615 PS"}
{"ts_recv":"2026-04-07T02:07:57.063374954Z","hd":{"ts_event":"2026-04-07T02:07:57.063357191Z","rtype":160,"publisher_id":101,"instrument_id":436},"action":"A","side":"B","price":"1.156090000","size":30,"channel_id":23,"order_id":"10998899713918138921","flags":0,"ts_in_delta":930,"sequence":147512,"symbol":"FCEU SI 20260615 PS"}
{"ts_recv":"2026-04-07T02:07:57.063374954Z","hd":{"ts_event":"2026-04-07T02:07:57.063357191Z","rtype":160,"publisher_id":101,"instrument_id":436},"action":"C","side":"A","price":"1.156200000","size":30,"channel_id":23,"order_id":"1775527677063301888","flags":0,"ts_in_delta":930,"sequence":147512,"symbol":"FCEU SI 20260615 PS"}
{"ts_recv":"2026-04-07T02:07:57.063374954Z","hd":{"ts_event":"2026-04-07T02:07:57.063357191Z","rtype":160,"publisher_id":101,"instrument_id":436},"action":"A","side":"A","price":"1.156190000","size":30,"channel_id":23,"order_id":"1775527677063363113","flags":128,"ts_in_delta":930,"sequence":147512,"symbol":"FCEU SI 20260615 PS"}
{"ts_recv":"2026-04-07T02:07:57.275694954Z","hd":{"ts_event":"2026-04-07T02:07:57.275675683Z","rtype":160,"publisher_id":101,"instrument_id":436},"action":"C","side":"B","price":"1.156090000","size":30,"channel_id":23,"order_id":"10998899713918138921","flags":0,"ts_in_delta":757,"sequence":147533,"symbol":"FCEU SI 20260615 PS"}
{"ts_recv":"2026-04-07T02:07:57.275694954Z","hd":{"ts_event":"2026-04-07T02:07:57.275675683Z","rtype":160,"publisher_id":101,"instrument_id":436},"action":"A","side":"B","price":"1.156080000","size":30,"channel_id":23,"order_id":"10998899714130457599","flags":0,"ts_in_delta":757,"sequence":147533,"symbol":"FCEU SI 20260615 PS"}
{"ts_recv":"2026-04-07T02:07:57.275694954Z","hd":{"ts_event":"2026-04-07T02:07:57.275675683Z","rtype":160,"publisher_id":101,"instrument_id":436},"action":"C","side":"A","price":"1.156190000","size":30,"channel_id":23,"order_id":"1775527677063363113","flags":0,"ts_in_delta":757,"sequence":147533,"symbol":"FCEU SI 20260615 PS"}
{"ts_recv":"2026-04-07T02:07:57.275694954Z","hd":{"ts_event":"2026-04-07T02:07:57.275675683Z","rtype":160,"publisher_id":101,"instrument_id":436},"action":"A","side":"A","price":"1.156180000","size":30,"channel_id":23,"order_id":"1775527677275681791","flags":128,"ts_in_delta":757,"sequence":147533,"symbol":"FCEU SI 20260615 PS"}
